File: muestras/coffe_mate/Organic_05.txt
#Acq. time (s)=	10
#Accumulations=	1
#Range (cm-¹)=	100...2000
#Windows=	2
#Autofocus=	Off
#AutoExposure=	Off
#Spike filter=	Off
#Delay time (s)=	0
#Binning=	1
#Readout mode=	Signal
#DeNoise=	Off
#ICS correction=	Off
#Dark correction=	Off
#Inst. Process=	Off
#Instrument=	LabRAM HR Evol
#Detector=	Syncerity OE
#Objective=	x100_VIS
#Grating=	600 (500nm)
#ND Filter=	25%
#Laser=	633nm_Edge
#Hole=	49.98
#Range=	Visible
#Project=	Omar
#Sample=	20-06-23
#Site=	2
#Title=	Organic
#Remark=
#Date=	20.06.2023 11:54
#Acquired=	20.06.2023 11:54:33
101.054	108
103.621	108
106.187	104
108.752	120
111.317	106
113.881	112
116.443	94
119.005	106
121.566	106
124.126	114
126.685	104
129.243	118
131.801	106
134.356	116
136.911	110
139.466	102
142.021	108
144.574	114
147.125	112
149.676	110
152.227	114
154.776	116
157.325	114
159.873	98
162.419	102
164.966	116
167.51	108
170.055	118
172.598	120
175.141	98
177.682	114
180.222	112
182.763	104
185.302	106
187.839	110
190.376	104
192.914	120
195.449	106
197.983	106
200.517	110
203.05	110
205.582	110
208.113	108
210.643	108
213.173	116
215.701	106
218.229	120
220.756	110
223.282	106
225.808	118
228.331	110
230.855	112
233.378	112
235.898	110
238.419	120
240.94	114
243.458	112
245.977	110
248.495	116
251.011	112
253.527	118
256.041	114
258.555	126
261.068	122
263.58	116
266.092	110
268.603	130
271.112	114
273.62	120
276.129	116
278.636	116
281.142	120
283.647	118
286.152	114
288.655	118
291.158	124
293.66	112
296.161	116
298.661	120
301.161	114
303.66	122
306.158	128
308.655	116
311.15	120
313.645	116
316.14	114
318.634	124
321.125	114
323.618	110
326.109	122
328.598	104
331.088	126
333.576	122
336.064	118
338.55	130
341.037	124
343.521	130
346.005	114
348.489	122
350.971	114
353.453	128
355.933	130
358.414	120
360.893	114
363.371	126
365.848	122
368.325	112
370.801	116
373.275	122
375.75	132
378.223	126
380.695	128
383.167	124
385.638	114
388.108	116
390.577	118
393.044	120
395.512	128
397.979	128
400.444	122
402.909	128
405.374	130
407.836	126
410.299	116
412.76	126
415.221	128
417.681	128
420.141	128
422.598	116
425.057	132
427.513	118
429.968	126
432.422	112
434.878	118
437.33	108
439.783	124
442.234	122
444.685	126
447.134	124
449.583	120
452.032	138
454.479	126
456.926	120
459.372	118
461.817	114
464.261	130
466.705	120
469.147	128
471.588	132
474.029	136
476.47	126
478.909	112
481.347	122
483.785	136
486.221	128
488.657	132
491.092	124
493.527	120
495.96	126
498.393	128
500.824	126
503.255	136
505.686	128
508.115	110
510.543	110
512.972	132
515.399	124
517.825	116
520.25	130
522.674	124
525.097	140
527.52	122
529.942	120
532.364	136
534.784	118
537.204	124
539.623	120
542.041	118
544.457	122
546.874	112
549.289	114
551.705	120
554.118	128
556.531	126
558.943	124
561.355	130
563.766	102
566.175	122
568.585	124
570.992	122
573.399	114
575.807	126
578.212	122
580.617	128
583.022	126
585.425	108
587.827	126
590.229	114
592.63	124
595.03	134
597.43	126
599.829	118
602.226	104
604.623	122
607.02	118
609.414	110
611.808	114
614.202	120
616.596	110
618.988	136
621.378	110
623.769	116
626.159	126
628.548	124
630.936	118
633.324	128
635.71	136
638.096	116
640.481	122
642.866	112
645.248	118
647.63	118
650.013	128
652.394	114
654.773	130
657.154	128
659.532	116
661.91	120
664.286	126
666.663	124
669.038	124
671.412	122
673.786	116
676.159	126
678.532	114
680.903	120
683.274	122
685.644	126
688.014	114
690.381	128
692.749	132
695.116	128
697.481	122
699.846	120
702.211	108
704.574	124
706.938	124
709.299	112
711.661	110
714.021	116
716.381	116
718.739	122
721.097	128
723.455	114
725.811	126
728.167	112
730.521	134
732.875	128
735.23	128
737.582	118
739.934	126
742.285	120
744.635	110
746.985	122
749.332	128
751.68	104
754.028	112
756.374	116
758.72	110
761.065	112
763.408	128
765.752	122
768.095	102
770.436	122
772.777	118
775.116	114
777.456	112
779.794	116
782.133	124
784.469	116
786.805	112
789.141	112
791.476	120
793.809	122
796.142	126
798.476	116
800.807	122
803.138	110
805.468	112
807.797	112
810.125	124
812.453	114
814.78	116
817.106	114
819.432	116
821.757	132
824.08	120
826.403	118
828.726	122
831.048	116
833.368	124
835.688	110
838.007	108
840.326	116
842.644	116
844.96	108
847.276	130
849.592	124
851.906	102
854.221	116
856.534	114
858.846	108
861.157	126
863.469	116
865.779	124
868.088	124
870.396	120
872.704	120
875.011	116
877.318	110
879.623	116
881.928	114
884.232	120
886.536	120
888.837	114
891.139	120
893.44	112
895.741	124
898.039	112
900.339	116
902.637	114
904.933	120
907.231	122
909.526	114
911.821	106
914.115	130
916.408	106
918.701	112
920.993	132
923.283	116
925.573	120
927.864	118
930.153	122
932.441	112
934.728	108
937.014	110
939.3	126
941.585	112
943.87	108
946.154	112
948.437	112
950.719	110
952.999	106
955.28	122
957.56	110
959.84	114
962.117	108
964.395	102
966.671	108
968.948	120
971.223	96
973.498	116
975.771	114
978.045	110
980.317	112
982.588	110
984.86	118
987.13	114
989.399	104
991.667	116
993.937	116
996.204	122
998.47	106
1000.74	108
1003	108
1005.26	112
1007.53	114
1009.79	122
1012.05	114
1014.31	118
1016.57	120
1018.83	98
1021.09	112
1023.35	118
1025.61	106
1027.87	102
1030.12	116
1032.38	114
1034.63	110
1036.88	112
1039.14	120
1041.39	114
1043.64	104
1045.89	116
1048.14	112
1050.39	100
1052.64	102
1054.89	114
1057.14	106
1059.38	104
1061.63	122
1063.87	118
1066.12	98
1068.36	114
1070.6	108
1072.85	118
1075.09	104
1077.33	102
1079.57	104
1081.81	102
1084.05	120
1086.28	114
1088.52	120
1090.76	110
1092.99	106
1095.23	114
1097.46	110
1099.69	104
1101.93	102
1104.16	110
1106.39	114
1108.62	106
1110.85	104
1113.08	108
1115.31	120
1117.53	106
1119.76	94
1121.99	96
1124.21	100
1126.44	110
1128.66	114
1130.88	108
1133.11	106
1135.33	104
1137.55	112
1139.77	110
1141.99	94
1144.21	100
1146.43	106
1148.64	104
1150.86	104
1153.08	106
1155.29	92
1157.51	102
1159.72	108
1161.93	104
1164.14	102
1166.36	98
1168.57	112
1170.78	104
1172.99	110
1175.2	102
1177.4	114
1179.61	96
1181.82	106
1184.02	108
1186.23	106
1188.43	104
1190.64	104
1192.84	100
1195.04	116
1197.24	110
1199.45	102.05
1201.64	100.118
1203.84	113.205
1206.04	105.37
1208.24	114.453
1210.44	110.95
1212.64	98.3869
1214.83	105.952
1217.03	103.457
1219.22	101.55
1221.41	100.324
1223.61	100.449
1225.8	97.7297
1227.99	94.1406
1230.18	98.9388
1232.37	104.281
1234.56	96.7271
1236.75	99.2191
1238.94	99.9733
1241.13	101.161
1243.31	100.526
1245.5	105.223
1247.68	101.016
1249.87	103.21
1252.05	96.85
1254.24	99.5632
1256.42	98.9869
1258.6	104.16
1260.78	99.796
1262.96	104.53
1265.14	103.604
1267.32	98.6313
1269.5	92.3887
1271.67	99.0295
1273.85	105.797
1276.03	93.6384
1278.2	100.226
1280.38	93.4444
1282.55	105.901
1284.72	103.42
1286.9	103.524
1289.07	103.23
1291.24	102.265
1293.41	106.434
1295.58	102.622
1297.75	101.246
1299.92	102.59
1302.09	99.4473
1304.25	111.718
1306.42	98.2612
1308.46	104
1310.63	102
1312.81	100
1314.98	98
1317.16	92
1319.33	110
1321.5	94
1323.67	94
1325.85	102
1328.02	98
1330.19	112
1332.35	110
1334.52	96
1336.69	104
1338.86	96
1341.02	104
1343.19	92
1345.35	96
1347.52	106
1349.68	102
1351.84	100
1354	94
1356.17	100
1358.33	106
1360.49	98
1362.65	100
1364.8	102
1366.96	104
1369.12	104
1371.28	102
1373.43	94
1375.59	92
1377.74	100
1379.89	98
1382.05	106
1384.2	94
1386.35	102
1388.5	102
1390.65	100
1392.8	98
1394.95	96
1397.1	96
1399.25	98
1401.4	106
1403.54	86
1405.69	92
1407.83	98
1409.98	100
1412.12	106
1414.26	104
1416.4	88
1418.55	96
1420.69	92
1422.83	106
1424.97	106
1427.1	84
1429.24	94
1431.38	104
1433.52	104
1435.65	90
1437.79	88
1439.92	92
1442.06	94
1444.19	92
1446.32	98
1448.46	98
1450.59	98
1452.72	98
1454.85	100
1456.98	104
1459.11	80
1461.23	102
1463.36	100
1465.49	98
1467.61	104
1469.74	100
1471.86	100
1473.99	96
1476.11	96
1478.23	108
1480.36	98
1482.48	88
1484.6	108
1486.72	90
1488.84	110
1490.96	94
1493.07	98
1495.19	92
1497.31	94
1499.42	92
1501.54	102
1503.65	90
1505.77	92
1507.88	86
1509.99	100
1512.1	96
1514.22	98
1516.33	90
1518.44	94
1520.55	94
1522.65	90
1524.76	98
1526.87	84
1528.98	92
1531.08	70
1533.19	86
1535.29	92
1537.4	104
1539.5	92
1541.6	84
1543.7	94
1545.8	84
1547.91	88
1550.01	98
1552.11	92
1554.2	86
1556.3	90
1558.4	94
1560.5	104
1562.59	90
1564.69	94
1566.78	82
1568.88	98
1570.97	98
1573.06	84
1575.15	92
1577.25	88
1579.34	84
1581.43	88
1583.52	78
1585.6	78
1587.69	82
1589.78	92
1591.87	94
1593.95	82
1596.04	94
1598.12	86
1600.21	86
1602.29	88
1604.37	80
1606.46	92
1608.54	94
1610.62	92
1612.7	86
1614.78	84
1616.86	96
1618.94	78
1621.01	82
1623.09	84
1625.17	94
1627.24	86
1629.32	86
1631.39	88
1633.47	84
1635.54	94
1637.61	86
1639.68	92
1641.76	82
1643.83	98
1645.9	80
1647.96	88
1650.03	80
1652.1	88
1654.17	72
1656.24	86
1658.3	98
1660.37	84
1662.43	88
1664.5	96
1666.56	88
1668.62	70
1670.68	86
1672.75	76
1674.81	88
1676.87	76
1678.93	84
1680.99	84
1683.04	78
1685.1	88
1687.16	84
1689.21	82
1691.27	82
1693.33	76
1695.38	76
1697.43	86
1699.49	82
1701.54	76
1703.59	78
1705.64	86
1707.69	86
1709.74	72
1711.79	90
1713.84	80
1715.89	90
1717.94	78
1719.98	86
1722.03	80
1724.07	86
1726.12	76
1728.16	86
1730.21	90
1732.25	88
1734.29	80
1736.33	82
1738.37	80
1740.41	86
1742.45	88
1744.49	78
1746.53	80
1748.57	76
1750.61	82
1752.64	88
1754.68	82
1756.71	76
1758.75	78
1760.78	80
1762.82	68
1764.85	86
1766.88	90
1768.91	82
1770.94	84
1772.97	90
1775	80
1777.03	86
1779.06	74
1781.09	78
1783.12	78
1785.14	76
1787.17	82
1789.19	80
1791.22	84
1793.24	72
1795.27	76
1797.29	82
1799.31	80
1801.33	74
1803.35	80
1805.37	72
1807.39	74
1809.41	76
1811.43	82
1813.45	78
1815.46	80
1817.48	82
1819.5	78
1821.51	92
1823.53	82
1825.54	82
1827.55	78
1829.57	80
1831.58	86
1833.59	80
1835.6	74
1837.61	88
1839.62	72
1841.63	78
1843.64	74
1845.65	64
1847.65	78
1849.66	70
1851.66	74
1853.67	68
1855.67	80
1857.68	68
1859.68	78
1861.68	68
1863.69	76
1865.69	70
1867.69	76
1869.69	82
1871.69	78
1873.69	74
1875.69	72
1877.68	70
1879.68	76
1881.68	68
1883.67	66
1885.67	70
1887.66	78
1889.66	78
1891.65	74
1893.64	72
1895.64	58
1897.63	86
1899.62	76
1901.61	72
1903.6	70
1905.59	80
1907.58	74
1909.56	76
1911.55	82
1913.54	72
1915.53	72
1917.51	62
1919.5	68
1921.48	80
1923.46	70
1925.45	72
1927.43	82
1929.41	68
1931.39	76
1933.37	74
1935.35	80
1937.33	66
1939.31	68
1941.29	70
1943.27	72
1945.24	76
1947.22	68
1949.2	76
1951.17	64
1953.14	70
1955.12	74
1957.09	68
1959.06	74
1961.04	68
1963.01	78
1964.98	66
1966.95	68
1968.92	68
1970.89	80
1972.86	78
1974.82	66
1976.79	70
1978.76	64
1980.72	70
1982.69	86
1984.65	68
1986.62	68
1988.58	64
1990.54	68
1992.51	72
1994.47	76
1996.43	70
1998.39	58
1999.37	70