File: muestras/coffe_mate/Organic_08.txt
#Acq. time (s)=	10
#Accumulations=	1
#Range (cm-¹)=	100...2000
#Windows=	2
#Autofocus=	Off
#AutoExposure=	Off
#Spike filter=	Off
#Delay time (s)=	0
#Binning=	1
#Readout mode=	Signal
#DeNoise=	Off
#ICS correction=	Off
#Dark correction=	Off
#Inst. Process=	Off
#Instrument=	LabRAM HR Evol
#Detector=	Syncerity OE
#Objective=	x100_VIS
#Grating=	600 (500nm)
#ND Filter=	100%
#Laser=	633nm_Edge
#Hole=	100.021
#Range=	Visible
#Project=	Omar
#Sample=	20-06-23
#Site=	2
#Title=	Organic
#Remark=
#Date=	20.06.2023 11:57
#Acquired=	20.06.2023 11:57:19
101.054	744
103.621	806
106.187	772
108.752	786
111.317	792
113.881	804
116.443	790
119.005	746
121.566	766
124.126	766
126.685	752
129.243	774
131.801	792
134.356	812
136.911	790
139.466	788
142.021	752
144.574	774
147.125	746
149.676	760
152.227	782
154.776	768
157.325	760
159.873	740
162.419	732
164.966	770
167.51	802
170.055	770
172.598	780
175.141	782
177.682	760
180.222	752
182.763	754
185.302	770
187.839	782
190.376	778
192.914	754
195.449	762
197.983	786
200.517	812
203.05	766
205.582	804
208.113	780
210.643	798
213.173	794
215.701	856
218.229	782
220.756	812
223.282	796
225.808	822
228.331	782
230.855	830
233.378	810
235.898	800
238.419	834
240.94	806
243.458	824
245.977	792
248.495	822
251.011	804
253.527	820
256.041	800
258.555	786
261.068	824
263.58	770
266.092	782
268.603	822
271.112	802
273.62	828
276.129	796
278.636	806
281.142	826
283.647	790
286.152	832
288.655	828
291.158	810
293.66	864
296.161	788
298.661	786
301.161	816
303.66	826
306.158	822
308.655	860
311.15	822
313.645	818
316.14	830
318.634	844
321.125	870
323.618	850
326.109	818
328.598	856
331.088	826
333.576	854
336.064	834
338.55	860
341.037	810
343.521	864
346.005	824
348.489	804
350.971	814
353.453	828
355.933	860
358.414	830
360.893	784
363.371	860
365.848	858
368.325	848
370.801	852
373.275	818
375.75	828
378.223	828
380.695	840
383.167	832
385.638	870
388.108	820
390.577	814
393.044	816
395.512	828
397.979	810
400.444	838
402.909	868
405.374	790
407.836	842
410.299	840
412.76	828
415.221	838
417.681	874
420.141	900
422.598	850
425.057	864
427.513	836
429.968	850
432.422	868
434.878	868
437.33	860
439.783	880
442.234	852
444.685	850
447.134	864
449.583	866
452.032	852
454.479	876
456.926	852
459.372	874
461.817	860
464.261	864
466.705	856
469.147	832
471.588	838
474.029	826
476.47	858
478.909	890
481.347	904
483.785	858
486.221	864
488.657	866
491.092	898
493.527	878
495.96	864
498.393	838
500.824	892
503.255	860
505.686	864
508.115	878
510.543	862
512.972	868
515.399	858
517.825	870
520.25	828
522.674	858
525.097	844
527.52	860
529.942	824
532.364	812
534.784	826
537.204	832
539.623	840
542.041	800
544.457	832
546.874	830
549.289	854
551.705	852
554.118	818
556.531	802
558.943	838
561.355	826
563.766	810
566.175	842
568.585	860
570.992	810
573.399	818
575.807	810
578.212	872
580.617	822
583.022	858
585.425	826
587.827	838
590.229	842
592.63	826
595.03	834
597.43	834
599.829	858
602.226	854
604.623	806
607.02	834
609.414	838
611.808	860
614.202	838
616.596	816
618.988	828
621.378	876
623.769	838
626.159	846
628.548	834
630.936	860
633.324	820
635.71	820
638.096	830
640.481	852
642.866	840
645.248	846
647.63	792
650.013	868
652.394	810
654.773	822
657.154	834
659.532	838
661.91	826
664.286	848
666.663	864
669.038	858
671.412	812
673.786	834
676.159	830
678.532	826
680.903	800
683.274	814
685.644	822
688.014	766
690.381	830
692.749	848
695.116	834
697.481	830
699.846	828
702.211	810
704.574	816
706.938	824
709.299	846
711.661	856
714.021	786
716.381	830
718.739	824
721.097	814
723.455	836
725.811	838
728.167	788
730.521	812
732.875	816
735.23	828
737.582	818
739.934	814
742.285	826
744.635	806
746.985	832
749.332	802
751.68	804
754.028	810
756.374	814
758.72	814
761.065	824
763.408	824
765.752	804
768.095	824
770.436	806
772.777	814
775.116	812
777.456	818
779.794	822
782.133	794
784.469	802
786.805	804
789.141	804
791.476	782
793.809	802
796.142	766
798.476	816
800.807	788
803.138	848
805.468	810
807.797	748
810.125	746
812.453	820
814.78	810
817.106	814
819.432	818
821.757	804
824.08	796
826.403	806
828.726	788
831.048	820
833.368	784
835.688	826
838.007	844
840.326	812
842.644	804
844.96	814
847.276	810
849.592	806
851.906	820
854.221	850
856.534	774
858.846	840
861.157	814
863.469	820
865.779	778
868.088	818
870.396	798
872.704	812
875.011	802
877.318	786
879.623	768
881.928	804
884.232	780
886.536	810
888.837	780
891.139	756
893.44	766
895.741	778
898.039	798
900.339	774
902.637	766
904.933	786
907.231	762
909.526	788
911.821	798
914.115	782
916.408	774
918.701	766
920.993	764
923.283	788
925.573	776
927.864	782
930.153	734
932.441	796
934.728	786
937.014	768
939.3	780
941.585	764
943.87	764
946.154	756
948.437	782
950.719	792
952.999	800
955.28	760
957.56	742
959.84	776
962.117	766
964.395	810
966.671	756
968.948	752
971.223	796
973.498	736
975.771	756
978.045	784
980.317	776
982.588	756
984.86	766
987.13	734
989.399	770
991.667	760
993.937	776
996.204	766
998.47	720
1000.74	764
1003	750
1005.26	762
1007.53	708
1009.79	750
1012.05	756
1014.31	746
1016.57	774
1018.83	766
1021.09	760
1023.35	790
1025.61	736
1027.87	752
1030.12	734
1032.38	748
1034.63	778
1036.88	754
1039.14	748
1041.39	778
1043.64	786
1045.89	738
1048.14	750
1050.39	792
1052.64	816
1054.89	782
1057.14	758
1059.38	784
1061.63	806
1063.87	748
1066.12	776
1068.36	752
1070.6	772
1072.85	764
1075.09	766
1077.33	758
1079.57	796
1081.81	710
1084.05	758
1086.28	750
1088.52	762
1090.76	728
1092.99	762
1095.23	754
1097.46	722
1099.69	752
1101.93	736
1104.16	748
1106.39	726
1108.62	754
1110.85	724
1113.08	760
1115.31	724
1117.53	714
1119.76	730
1121.99	772
1124.21	750
1126.44	756
1128.66	746
1130.88	722
1133.11	718
1135.33	734
1137.55	734
1139.77	740
1141.99	716
1144.21	716
1146.43	724
1148.64	700
1150.86	716
1153.08	680
1155.29	722
1157.51	710
1159.72	696
1161.93	748
1164.14	700
1166.36	684
1168.57	740
1170.78	728
1172.99	698
1175.2	700
1177.4	672
1179.61	696
1181.82	710
1184.02	712
1186.23	676
1188.43	708
1190.64	712
1192.84	706
1195.04	710
1197.24	666
1199.45	669.94
1201.64	671.53
1203.84	675.475
1206.04	675.645
1208.24	659.524
1210.44	695.971
1212.64	689.798
1214.83	655.233
1217.03	667.629
1219.22	682.572
1221.41	688.016
1223.61	682.548
1225.8	651.711
1227.99	664.545
1230.18	654.345
1232.37	685.497
1234.56	658.25
1236.75	680.077
1238.94	662.449
1241.13	664.84
1243.31	658.33
1245.5	661.374
1247.68	663.945
1249.87	656.404
1252.05	667.703
1254.24	652.175
1256.42	668.023
1258.6	656.877
1260.78	657.514
1262.96	655.038
1265.14	660.422
1267.32	669.873
1269.5	647.5
1271.67	675.291
1273.85	666.203
1276.03	651.324
1278.2	658.36
1280.38	665.33
1282.55	663.286
1284.72	673.889
1286.9	660.691
1289.07	639.13
1291.24	672.857
1293.41	667.024
1295.58	702.548
1297.75	684.979
1299.92	670.85
1302.09	650.425
1304.25	657.603
1306.42	635.927
1308.46	660
1310.63	694
1312.81	616
1314.98	670
1317.16	642
1319.33	664
1321.5	632
1323.67	636
1325.85	668
1328.02	672
1330.19	646
1332.35	670
1334.52	652
1336.69	658
1338.86	618
1341.02	646
1343.19	652
1345.35	658
1347.52	618
1349.68	650
1351.84	648
1354	640
1356.17	618
1358.33	626
1360.49	602
1362.65	646
1364.8	628
1366.96	628
1369.12	636
1371.28	626
1373.43	630
1375.59	606
1377.74	638
1379.89	630
1382.05	596
1384.2	646
1386.35	610
1388.5	616
1390.65	624
1392.8	606
1394.95	622
1397.1	598
1399.25	560
1401.4	618
1403.54	566
1405.69	608
1407.83	624
1409.98	636
1412.12	604
1414.26	638
1416.4	626
1418.55	642
1420.69	628
1422.83	596
1424.97	630
1427.1	606
1429.24	610
1431.38	588
1433.52	646
1435.65	652
1437.79	652
1439.92	620
1442.06	626
1444.19	646
1446.32	614
1448.46	628
1450.59	620
1452.72	622
1454.85	634
1456.98	620
1459.11	594
1461.23	582
1463.36	614
1465.49	632
1467.61	612
1469.74	604
1471.86	602
1473.99	588
1476.11	588
1478.23	558
1480.36	602
1482.48	578
1484.6	564
1486.72	562
1488.84	570
1490.96	564
1493.07	560
1495.19	570
1497.31	572
1499.42	556
1501.54	558
1503.65	584
1505.77	584
1507.88	576
1509.99	568
1512.1	546
1514.22	564
1516.33	568
1518.44	564
1520.55	568
1522.65	550
1524.76	568
1526.87	548
1528.98	540
1531.08	534
1533.19	566
1535.29	546
1537.4	558
1539.5	530
1541.6	558
1543.7	532
1545.8	532
1547.91	522
1550.01	530
1552.11	536
1554.2	538
1556.3	538
1558.4	524
1560.5	536
1562.59	508
1564.69	524
1566.78	522
1568.88	524
1570.97	570
1573.06	540
1575.15	544
1577.25	528
1579.34	514
1581.43	542
1583.52	526
1585.6	550
1587.69	512
1589.78	526
1591.87	514
1593.95	570
1596.04	526
1598.12	530
1600.21	532
1602.29	504
1604.37	558
1606.46	512
1608.54	528
1610.62	526
1612.7	526
1614.78	500
1616.86	504
1618.94	526
1621.01	504
1623.09	508
1625.17	524
1627.24	532
1629.32	514
1631.39	500
1633.47	522
1635.54	494
1637.61	498
1639.68	504
1641.76	512
1643.83	522
1645.9	524
1647.96	512
1650.03	514
1652.1	518
1654.17	488
1656.24	510
1658.3	490
1660.37	512
1662.43	498
1664.5	508
1666.56	498
1668.62	500
1670.68	498
1672.75	506
1674.81	498
1676.87	492
1678.93	458
1680.99	478
1683.04	498
1685.1	470
1687.16	506
1689.21	490
1691.27	476
1693.33	476
1695.38	506
1697.43	498
1699.49	478
1701.54	488
1703.59	488
1705.64	496
1707.69	486
1709.74	494
1711.79	480
1713.84	480
1715.89	476
1717.94	462
1719.98	482
1722.03	480
1724.07	478
1726.12	484
1728.16	462
1730.21	460
1732.25	466
1734.29	462
1736.33	476
1738.37	452
1740.41	466
1742.45	470
1744.49	484
1746.53	450
1748.57	470
1750.61	454
1752.64	464
1754.68	474
1756.71	442
1758.75	456
1760.78	448
1762.82	454
1764.85	456
1766.88	458
1768.91	422
1770.94	438
1772.97	452
1775	438
1777.03	444
1779.06	460
1781.09	444
1783.12	436
1785.14	440
1787.17	440
1789.19	430
1791.22	442
1793.24	458
1795.27	450
1797.29	458
1799.31	430
1801.33	438
1803.35	444
1805.37	414
1807.39	446
1809.41	466
1811.43	444
1813.45	412
1815.46	444
1817.48	436
1819.5	442
1821.51	400
1823.53	432
1825.54	444
1827.55	458
1829.57	450
1831.58	448
1833.59	442
1835.6	422
1837.61	444
1839.62	416
1841.63	422
1843.64	418
1845.65	422
1847.65	406
1849.66	424
1851.66	412
1853.67	412
1855.67	424
1857.68	414
1859.68	412
1861.68	394
1863.69	416
1865.69	400
1867.69	404
1869.69	386
1871.69	406
1873.69	412
1875.69	382
1877.68	382
1879.68	420
1881.68	388
1883.67	388
1885.67	400
1887.66	402
1889.66	408
1891.65	412
1893.64	396
1895.64	398
1897.63	410
1899.62	412
1901.61	394
1903.6	416
1905.59	378
1907.58	404
1909.56	378
1911.55	382
1913.54	386
1915.53	370
1917.51	378
1919.5	408
1921.48	402
1923.46	386
1925.45	374
1927.43	362
1929.41	390
1931.39	374
1933.37	392
1935.35	406
1937.33	370
1939.31	358
1941.29	390
1943.27	378
1945.24	378
1947.22	364
1949.2	364
1951.17	390
1953.14	386
1955.12	368
1957.09	374
1959.06	378
1961.04	382
1963.01	360
1964.98	364
1966.95	366
1968.92	368
1970.89	364
1972.86	340
1974.82	356
1976.79	340
1978.76	350
1980.72	352
1982.69	342
1984.65	348
1986.62	354
1988.58	358
1990.54	348
1992.51	374
1994.47	354
1996.43	352
1998.39	344
1999.37	342