File: muestras/coffe_mate/Organic_11.txt
#Acq. time (s)=	15
#Accumulations=	1
#Range (cm-¹)=	100...2000
#Windows=	2
#Autofocus=	Off
#AutoExposure=	Off
#Spike filter=	Off
#Delay time (s)=	0
#Binning=	1
#Readout mode=	Signal
#DeNoise=	Off
#ICS correction=	Off
#Dark correction=	Off
#Inst. Process=	Off
#Instrument=	LabRAM HR Evol
#Detector=	Syncerity OE
#Objective=	x100_VIS
#Grating=	600 (500nm)
#ND Filter=	100%
#Laser=	633nm_Edge
#Hole=	100.021
#Range=	Visible
#Project=	Omar
#Sample=	20-06-23
#Site=	2
#Title=	Organic
#Remark=
#Date=	20.06.2023 12:03
#Acquired=	20.06.2023 12:03:20
101.054	1970
103.621	1990
106.187	1966
108.752	1966
111.317	1948
113.881	1930
116.443	1938
119.005	2000
121.566	1976
124.126	1950
126.685	1990
129.243	1980
131.801	2024
134.356	1944
136.911	2020
139.466	1996
142.021	1966
144.574	1930
147.125	2026
149.676	2022
152.227	1988
154.776	1982
157.325	1966
159.873	2004
162.419	1962
164.966	1962
167.51	2082
170.055	2014
172.598	1998
175.141	1970
177.682	2086
180.222	2056
182.763	2040
185.302	1998
187.839	2040
190.376	2074
192.914	2034
195.449	2054
197.983	2098
200.517	2072
203.05	2056
205.582	2102
208.113	2136
210.643	2058
213.173	2090
215.701	2140
218.229	2090
220.756	2072
223.282	2172
225.808	2128
228.331	2102
230.855	2124
233.378	2140
235.898	2100
238.419	2134
240.94	2058
243.458	2120
245.977	2150
248.495	2120
251.011	2164
253.527	2150
256.041	2164
258.555	2126
261.068	2146
263.58	2142
266.092	2096
268.603	2120
271.112	2080
273.62	2168
276.129	2088
278.636	2174
281.142	2110
283.647	2116
286.152	2184
288.655	2210
291.158	2132
293.66	2072
296.161	2194
298.661	2146
301.161	2122
303.66	2180
306.158	2222
308.655	2156
311.15	2184
313.645	2112
316.14	2200
318.634	2216
321.125	2178
323.618	2146
326.109	2220
328.598	2214
331.088	2166
333.576	2170
336.064	2182
338.55	2218
341.037	2174
343.521	2188
346.005	2218
348.489	2228
350.971	2196
353.453	2184
355.933	2184
358.414	2208
360.893	2198
363.371	2238
365.848	2238
368.325	2128
370.801	2218
373.275	2244
375.75	2220
378.223	2238
380.695	2172
383.167	2256
385.638	2174
388.108	2124
390.577	2210
393.044	2206
395.512	2172
397.979	2186
400.444	2242
402.909	2210
405.374	2232
407.836	2228
410.299	2248
412.76	2262
415.221	2280
417.681	2250
420.141	2274
422.598	2260
425.057	2260
427.513	2312
429.968	2332
432.422	2308
434.878	2304
437.33	2318
439.783	2278
442.234	2332
444.685	2264
447.134	2272
449.583	2258
452.032	2244
454.479	2258
456.926	2224
459.372	2288
461.817	2210
464.261	2256
466.705	2276
469.147	2332
471.588	2300
474.029	2354
476.47	2284
478.909	2280
481.347	2320
483.785	2332
486.221	2320
488.657	2298
491.092	2278
493.527	2274
495.96	2296
498.393	2250
500.824	2348
503.255	2302
505.686	2320
508.115	2308
510.543	2308
512.972	2294
515.399	2286
517.825	2244
520.25	2244
522.674	2256
525.097	2232
527.52	2226
529.942	2244
532.364	2222
534.784	2220
537.204	2272
539.623	2252
542.041	2242
544.457	2168
546.874	2186
549.289	2258
551.705	2248
554.118	2230
556.531	2274
558.943	2174
561.355	2204
563.766	2258
566.175	2196
568.585	2258
570.992	2172
573.399	2230
575.807	2184
578.212	2266
580.617	2274
583.022	2210
585.425	2192
587.827	2210
590.229	2286
592.63	2222
595.03	2208
597.43	2228
599.829	2242
602.226	2222
604.623	2190
607.02	2248
609.414	2222
611.808	2208
614.202	2210
616.596	2258
618.988	2208
621.378	2248
623.769	2244
626.159	2226
628.548	2284
630.936	2236
633.324	2272
635.71	2268
638.096	2192
640.481	2252
642.866	2282
645.248	2304
647.63	2278
650.013	2262
652.394	2240
654.773	2230
657.154	2182
659.532	2268
661.91	2246
664.286	2266
666.663	2260
669.038	2244
671.412	2276
673.786	2282
676.159	2248
678.532	2184
680.903	2246
683.274	2178
685.644	2266
688.014	2254
690.381	2198
692.749	2172
695.116	2206
697.481	2178
699.846	2192
702.211	2224
704.574	2182
706.938	2212
709.299	2214
711.661	2196
714.021	2200
716.381	2240
718.739	2212
721.097	2280
723.455	2180
725.811	2200
728.167	2202
730.521	2206
732.875	2172
735.23	2216
737.582	2198
739.934	2186
742.285	2176
744.635	2228
746.985	2132
749.332	2204
751.68	2192
754.028	2160
756.374	2166
758.72	2206
761.065	2184
763.408	2160
765.752	2094
768.095	2148
770.436	2170
772.777	2180
775.116	2160
777.456	2150
779.794	2134
782.133	2108
784.469	2150
786.805	2140
789.141	2088
791.476	2130
793.809	2130
796.142	2130
798.476	2160
800.807	2140
803.138	2140
805.468	2156
807.797	2136
810.125	2134
812.453	2056
814.78	2190
817.106	2122
819.432	2124
821.757	2160
824.08	2108
826.403	2134
828.726	2142
831.048	2122
833.368	2142
835.688	2126
838.007	2170
840.326	2140
842.644	2214
844.96	2164
847.276	2100
849.592	2186
851.906	2178
854.221	2166
856.534	2220
858.846	2120
861.157	2112
863.469	2178
865.779	2138
868.088	2140
870.396	2152
872.704	2178
875.011	2140
877.318	2104
879.623	2116
881.928	2126
884.232	2100
886.536	2074
888.837	2070
891.139	2128
893.44	2062
895.741	2088
898.039	2116
900.339	2098
902.637	2060
904.933	2028
907.231	2078
909.526	2066
911.821	2056
914.115	2052
916.408	2074
918.701	2056
920.993	2078
923.283	2054
925.573	2078
927.864	2030
930.153	2016
932.441	2088
934.728	2042
937.014	2032
939.3	2016
941.585	2092
943.87	2014
946.154	2084
948.437	2090
950.719	1998
952.999	2106
955.28	2034
957.56	1996
959.84	2010
962.117	2060
964.395	2020
966.671	2000
968.948	1990
971.223	2024
973.498	2054
975.771	2026
978.045	2064
980.317	2020
982.588	1914
984.86	2000
987.13	2038
989.399	2012
991.667	2020
993.937	2002
996.204	2042
998.47	1986
1000.74	1980
1003	1988
1005.26	1988
1007.53	2050
1009.79	1950
1012.05	1944
1014.31	1996
1016.57	1984
1018.83	1992
1021.09	1984
1023.35	2052
1025.61	2016
1027.87	2002
1030.12	2040
1032.38	2036
1034.63	2022
1036.88	1974
1039.14	1960
1041.39	1954
1043.64	2024
1045.89	2004
1048.14	1964
1050.39	1992
1052.64	1986
1054.89	2038
1057.14	2056
1059.38	2046
1061.63	1996
1063.87	2008
1066.12	1966
1068.36	1958
1070.6	1990
1072.85	1994
1075.09	1982
1077.33	1974
1079.57	1982
1081.81	2010
1084.05	1960
1086.28	1944
1088.52	1990
1090.76	1928
1092.99	1960
1095.23	1964
1097.46	2010
1099.69	1938
1101.93	1926
1104.16	1960
1106.39	1970
1108.62	1934
1110.85	1962
1113.08	1898
1115.31	1902
1117.53	1936
1119.76	1950
1121.99	1972
1124.21	1946
1126.44	1950
1128.66	1920
1130.88	1876
1133.11	1946
1135.33	1936
1137.55	1900
1139.77	1876
1141.99	1894
1144.21	1866
1146.43	1890
1148.64	1920
1150.86	1886
1153.08	1942
1155.29	1910
1157.51	1832
1159.72	1890
1161.93	1958
1164.14	1878
1166.36	1894
1168.57	1854
1170.78	1854
1172.99	1878
1175.2	1870
1177.4	1890
1179.61	1856
1181.82	1846
1184.02	1868
1186.23	1868
1188.43	1864
1190.64	1856
1192.84	1816
1195.04	1824
1197.24	1868
1199.45	1778.84
1201.64	1812.05
1203.84	1783.7
1206.04	1750.77
1208.24	1755.99
1210.44	1777.08
1212.64	1759.85
1214.83	1730.93
1217.03	1737.43
1219.22	1710.1
1221.41	1730.31
1223.61	1705.04
1225.8	1682.95
1227.99	1683.6
1230.18	1690.18
1232.37	1702.19
1234.56	1675.22
1236.75	1665.03
1238.94	1644.82
1241.13	1629.95
1243.31	1657.68
1245.5	1655.28
1247.68	1629
1249.87	1644.19
1252.05	1641.1
1254.24	1585.24
1256.42	1630.33
1258.6	1591.76
1260.78	1626.34
1262.96	1594.95
1265.14	1590.62
1267.32	1592.88
1269.5	1581.8
1271.67	1556.79
1273.85	1551.76
1276.03	1565.87
1278.2	1552.38
1280.38	1535.01
1282.55	1512.2
1284.72	1514.11
1286.9	1523.05
1289.07	1510.22
1291.24	1519.39
1293.41	1571.81
1295.58	1526.66
1297.75	1495.67
1299.92	1507.33
1302.09	1504.99
1304.25	1455.45
1306.42	1470.59
1308.46	1484
1310.63	1436
1312.81	1378
1314.98	1456
1317.16	1440
1319.33	1486
1321.5	1440
1323.67	1456
1325.85	1492
1328.02	1408
1330.19	1472
1332.35	1464
1334.52	1430
1336.69	1410
1338.86	1438
1341.02	1412
1343.19	1456
1345.35	1454
1347.52	1412
1349.68	1416
1351.84	1416
1354	1408
1356.17	1408
1358.33	1426
1360.49	1452
1362.65	1400
1364.8	1404
1366.96	1418
1369.12	1380
1371.28	1384
1373.43	1368
1375.59	1444
1377.74	1394
1379.89	1426
1382.05	1350
1384.2	1366
1386.35	1366
1388.5	1428
1390.65	1374
1392.8	1358
1394.95	1370
1397.1	1376
1399.25	1372
1401.4	1384
1403.54	1390
1405.69	1420
1407.83	1356
1409.98	1368
1412.12	1374
1414.26	1374
1416.4	1392
1418.55	1320
1420.69	1388
1422.83	1362
1424.97	1350
1427.1	1356
1429.24	1366
1431.38	1412
1433.52	1400
1435.65	1382
1437.79	1382
1439.92	1436
1442.06	1400
1444.19	1314
1446.32	1368
1448.46	1378
1450.59	1370
1452.72	1398
1454.85	1354
1456.98	1394
1459.11	1380
1461.23	1372
1463.36	1370
1465.49	1388
1467.61	1312
1469.74	1338
1471.86	1332
1473.99	1314
1476.11	1358
1478.23	1356
1480.36	1302
1482.48	1316
1484.6	1334
1486.72	1298
1488.84	1288
1490.96	1282
1493.07	1322
1495.19	1284
1497.31	1292
1499.42	1298
1501.54	1268
1503.65	1272
1505.77	1292
1507.88	1278
1509.99	1238
1512.1	1232
1514.22	1278
1516.33	1268
1518.44	1236
1520.55	1264
1522.65	1232
1524.76	1264
1526.87	1270
1528.98	1252
1531.08	1258
1533.19	1238
1535.29	1240
1537.4	1210
1539.5	1230
1541.6	1212
1543.7	1230
1545.8	1214
1547.91	1202
1550.01	1214
1552.11	1216
1554.2	1154
1556.3	1188
1558.4	1188
1560.5	1192
1562.59	1206
1564.69	1190
1566.78	1196
1568.88	1224
1570.97	1178
1573.06	1214
1575.15	1190
1577.25	1178
1579.34	1166
1581.43	1216
1583.52	1194
1585.6	1168
1587.69	1192
1589.78	1204
1591.87	1164
1593.95	1200
1596.04	1178
1598.12	1234
1600.21	1164
1602.29	1188
1604.37	1186
1606.46	1198
1608.54	1186
1610.62	1166
1612.7	1160
1614.78	1118
1616.86	1132
1618.94	1186
1621.01	1194
1623.09	1216
1625.17	1170
1627.24	1164
1629.32	1142
1631.39	1186
1633.47	1164
1635.54	1196
1637.61	1118
1639.68	1156
1641.76	1132
1643.83	1134
1645.9	1122
1647.96	1172
1650.03	1148
1652.1	1142
1654.17	1132
1656.24	1094
1658.3	1112
1660.37	1108
1662.43	1124
1664.5	1152
1666.56	1122
1668.62	1120
1670.68	1078
1672.75	1132
1674.81	1114
1676.87	1106
1678.93	1114
1680.99	1106
1683.04	1116
1685.1	1090
1687.16	1132
1689.21	1076
1691.27	1112
1693.33	1102
1695.38	1078
1697.43	1048
1699.49	1074
1701.54	1046
1703.59	1088
1705.64	1078
1707.69	1078
1709.74	1072
1711.79	1070
1713.84	1058
1715.89	1076
1717.94	1070
1719.98	970
1722.03	1070
1724.07	1080
1726.12	1026
1728.16	1028
1730.21	1066
1732.25	1042
1734.29	1032
1736.33	1004
1738.37	1038
1740.41	1046
1742.45	1048
1744.49	1032
1746.53	1046
1748.57	1016
1750.61	1028
1752.64	1036
1754.68	1040
1756.71	1026
1758.75	1036
1760.78	1040
1762.82	1010
1764.85	998
1766.88	1000
1768.91	994
1770.94	990
1772.97	1028
1775	1014
1777.03	1006
1779.06	1024
1781.09	964
1783.12	992
1785.14	984
1787.17	988
1789.19	1012
1791.22	988
1793.24	970
1795.27	1018
1797.29	952
1799.31	988
1801.33	996
1803.35	1004
1805.37	936
1807.39	970
1809.41	974
1811.43	962
1813.45	954
1815.46	1002
1817.48	994
1819.5	954
1821.51	958
1823.53	950
1825.54	968
1827.55	952
1829.57	942
1831.58	922
1833.59	970
1835.6	934
1837.61	932
1839.62	956
1841.63	942
1843.64	920
1845.65	898
1847.65	920
1849.66	946
1851.66	912
1853.67	910
1855.67	924
1857.68	898
1859.68	922
1861.68	886
1863.69	912
1865.69	892
1867.69	910
1869.69	894
1871.69	888
1873.69	898
1875.69	896
1877.68	898
1879.68	906
1881.68	836
1883.67	902
1885.67	866
1887.66	888
1889.66	892
1891.65	908
1893.64	892
1895.64	900
1897.63	844
1899.62	840
1901.61	868
1903.6	874
1905.59	848
1907.58	878
1909.56	840
1911.55	880
1913.54	874
1915.53	832
1917.51	844
1919.5	862
1921.48	846
1923.46	836
1925.45	828
1927.43	864
1929.41	836
1931.39	864
1933.37	844
1935.35	816
1937.33	834
1939.31	842
1941.29	838
1943.27	836
1945.24	848
1947.22	828
1949.2	806
1951.17	826
1953.14	820
1955.12	862
1957.09	806
1959.06	806
1961.04	826
1963.01	786
1964.98	848
1966.95	798
1968.92	822
1970.89	764
1972.86	794
1974.82	804
1976.79	788
1978.76	812
1980.72	802
1982.69	812
1984.65	808
1986.62	778
1988.58	802
1990.54	784
1992.51	790
1994.47	786
1996.43	758
1998.39	804
1999.37	758