File: muestras/coffe_mate/Organic_07.txt
#Acq. time (s)=	10
#Accumulations=	1
#Range (cm-¹)=	100...2000
#Windows=	2
#Autofocus=	Off
#AutoExposure=	Off
#Spike filter=	Off
#Delay time (s)=	0
#Binning=	1
#Readout mode=	Signal
#DeNoise=	Off
#ICS correction=	Off
#Dark correction=	Off
#Inst. Process=	Off
#Instrument=	LabRAM HR Evol
#Detector=	Syncerity OE
#Objective=	x100_VIS
#Grating=	600 (500nm)
#ND Filter=	100%
#Laser=	633nm_Edge
#Hole=	49.98
#Range=	Visible
#Project=	Omar
#Sample=	20-06-23
#Site=	2
#Title=	Organic
#Remark=
#Date=	20.06.2023 11:56
#Acquired=	20.06.2023 11:56:20
101.054	228
103.621	232
106.187	226
108.752	204
111.317	214
113.881	210
116.443	224
119.005	216
121.566	222
124.126	232
126.685	216
129.243	224
131.801	230
134.356	208
136.911	210
139.466	222
142.021	242
144.574	222
147.125	218
149.676	224
152.227	222
154.776	220
157.325	224
159.873	226
162.419	214
164.966	224
167.51	230
170.055	246
172.598	236
175.141	222
177.682	240
180.222	222
182.763	218
185.302	220
187.839	234
190.376	212
192.914	236
195.449	238
197.983	228
200.517	226
203.05	232
205.582	224
208.113	238
210.643	228
213.173	232
215.701	236
218.229	228
220.756	228
223.282	230
225.808	234
228.331	232
230.855	232
233.378	230
235.898	228
238.419	248
240.94	220
243.458	234
245.977	234
248.495	254
251.011	226
253.527	248
256.041	224
258.555	222
261.068	240
263.58	248
266.092	246
268.603	248
271.112	212
273.62	230
276.129	236
278.636	236
281.142	218
283.647	224
286.152	240
288.655	246
291.158	240
293.66	254
296.161	236
298.661	242
301.161	242
303.66	230
306.158	230
308.655	252
311.15	242
313.645	254
316.14	250
318.634	242
321.125	252
323.618	248
326.109	250
328.598	240
331.088	232
333.576	262
336.064	260
338.55	250
341.037	262
343.521	242
346.005	252
348.489	232
350.971	260
353.453	240
355.933	260
358.414	240
360.893	226
363.371	230
365.848	240
368.325	248
370.801	230
373.275	248
375.75	244
378.223	250
380.695	228
383.167	240
385.638	234
388.108	258
390.577	240
393.044	242
395.512	244
397.979	224
400.444	244
402.909	260
405.374	258
407.836	236
410.299	252
412.76	242
415.221	250
417.681	240
420.141	256
422.598	244
425.057	246
427.513	254
429.968	270
432.422	248
434.878	250
437.33	244
439.783	246
442.234	250
444.685	238
447.134	244
449.583	252
452.032	268
454.479	248
456.926	252
459.372	256
461.817	246
464.261	246
466.705	260
469.147	250
471.588	242
474.029	254
476.47	250
478.909	258
481.347	254
483.785	272
486.221	226
488.657	244
491.092	258
493.527	262
495.96	250
498.393	254
500.824	238
503.255	244
505.686	236
508.115	260
510.543	248
512.972	234
515.399	254
517.825	248
520.25	226
522.674	240
525.097	250
527.52	244
529.942	232
532.364	236
534.784	252
537.204	242
539.623	252
542.041	246
544.457	248
546.874	254
549.289	238
551.705	248
554.118	252
556.531	244
558.943	252
561.355	230
563.766	240
566.175	244
568.585	232
570.992	252
573.399	232
575.807	232
578.212	220
580.617	256
583.022	260
585.425	240
587.827	252
590.229	252
592.63	238
595.03	234
597.43	250
599.829	242
602.226	240
604.623	254
607.02	242
609.414	250
611.808	240
614.202	224
616.596	240
618.988	246
621.378	232
623.769	222
626.159	264
628.548	248
630.936	250
633.324	232
635.71	240
638.096	256
640.481	246
642.866	242
645.248	250
647.63	248
650.013	258
652.394	266
654.773	250
657.154	256
659.532	254
661.91	246
664.286	240
666.663	240
669.038	236
671.412	242
673.786	260
676.159	242
678.532	240
680.903	224
683.274	266
685.644	234
688.014	256
690.381	246
692.749	248
695.116	244
697.481	250
699.846	240
702.211	250
704.574	238
706.938	242
709.299	242
711.661	240
714.021	238
716.381	240
718.739	248
721.097	240
723.455	232
725.811	246
728.167	228
730.521	252
732.875	246
735.23	244
737.582	246
739.934	230
742.285	234
744.635	240
746.985	232
749.332	246
751.68	238
754.028	236
756.374	248
758.72	240
761.065	240
763.408	242
765.752	246
768.095	234
770.436	238
772.777	234
775.116	226
777.456	228
779.794	240
782.133	226
784.469	242
786.805	242
789.141	238
791.476	234
793.809	232
796.142	226
798.476	238
800.807	252
803.138	242
805.468	250
807.797	244
810.125	230
812.453	236
814.78	222
817.106	238
819.432	244
821.757	224
824.08	250
826.403	226
828.726	246
831.048	242
833.368	230
835.688	236
838.007	228
840.326	240
842.644	250
844.96	234
847.276	238
849.592	242
851.906	244
854.221	234
856.534	238
858.846	236
861.157	236
863.469	244
865.779	240
868.088	248
870.396	230
872.704	218
875.011	240
877.318	244
879.623	230
881.928	214
884.232	234
886.536	234
888.837	220
891.139	220
893.44	248
895.741	224
898.039	218
900.339	234
902.637	234
904.933	226
907.231	236
909.526	234
911.821	214
914.115	226
916.408	230
918.701	220
920.993	222
923.283	224
925.573	226
927.864	236
930.153	226
932.441	226
934.728	224
937.014	224
939.3	232
941.585	218
943.87	234
946.154	222
948.437	208
950.719	230
952.999	244
955.28	230
957.56	234
959.84	248
962.117	234
964.395	230
966.671	252
968.948	204
971.223	232
973.498	230
975.771	232
978.045	222
980.317	234
982.588	242
984.86	234
987.13	230
989.399	218
991.667	218
993.937	230
996.204	238
998.47	214
1000.74	204
1003	230
1005.26	232
1007.53	234
1009.79	220
1012.05	226
1014.31	212
1016.57	228
1018.83	230
1021.09	224
1023.35	228
1025.61	206
1027.87	234
1030.12	210
1032.38	232
1034.63	240
1036.88	230
1039.14	238
1041.39	218
1043.64	220
1045.89	228
1048.14	236
1050.39	218
1052.64	224
1054.89	212
1057.14	238
1059.38	232
1061.63	228
1063.87	218
1066.12	226
1068.36	234
1070.6	252
1072.85	228
1075.09	230
1077.33	226
1079.57	230
1081.81	224
1084.05	230
1086.28	222
1088.52	222
1090.76	212
1092.99	216
1095.23	222
1097.46	208
1099.69	220
1101.93	210
1104.16	226
1106.39	204
1108.62	968
1110.85	208
1113.08	220
1115.31	204
1117.53	222
1119.76	214
1121.99	216
1124.21	208
1126.44	224
1128.66	224
1130.88	224
1133.11	214
1135.33	208
1137.55	224
1139.77	208
1141.99	206
1144.21	202
1146.43	208
1148.64	200
1150.86	224
1153.08	214
1155.29	198
1157.51	204
1159.72	230
1161.93	216
1164.14	214
1166.36	220
1168.57	218
1170.78	206
1172.99	206
1175.2	200
1177.4	202
1179.61	188
1181.82	198
1184.02	200
1186.23	210
1188.43	204
1190.64	184
1192.84	206
1195.04	212
1197.24	212
1199.45	207.92
1201.64	203.92
1203.84	207.355
1206.04	199.74
1208.24	208.804
1210.44	193.262
1212.64	204.828
1214.83	206.48
1217.03	197.727
1219.22	206.806
1221.41	190.41
1223.61	201.998
1225.8	190.759
1227.99	193.033
1230.18	185.375
1232.37	185.7
1234.56	191.314
1236.75	190.459
1238.94	194.019
1241.13	193.577
1243.31	191.24
1245.5	194.965
1247.68	193.368
1249.87	204.996
1252.05	193.159
1254.24	203.705
1256.42	196.266
1258.6	205.721
1260.78	200.776
1262.96	196.749
1265.14	201.49
1267.32	198.394
1269.5	210.792
1271.67	205.74
1273.85	198.349
1276.03	193.41
1278.2	206.955
1280.38	204.063
1282.55	197.817
1284.72	209.309
1286.9	195.778
1289.07	198.46
1291.24	200.642
1293.41	202.268
1295.58	202.769
1297.75	195.409
1299.92	195.508
1302.09	184.461
1304.25	201.347
1306.42	205.415
1308.46	186
1310.63	188
1312.81	200
1314.98	192
1317.16	198
1319.33	172
1321.5	202
1323.67	192
1325.85	184
1328.02	192
1330.19	194
1332.35	182
1334.52	180
1336.69	200
1338.86	180
1341.02	196
1343.19	194
1345.35	196
1347.52	192
1349.68	204
1351.84	194
1354	186
1356.17	178
1358.33	200
1360.49	176
1362.65	200
1364.8	196
1366.96	180
1369.12	174
1371.28	210
1373.43	184
1375.59	180
1377.74	188
1379.89	196
1382.05	186
1384.2	194
1386.35	178
1388.5	174
1390.65	186
1392.8	174
1394.95	176
1397.1	178
1399.25	182
1401.4	174
1403.54	174
1405.69	202
1407.83	192
1409.98	170
1412.12	192
1414.26	178
1416.4	192
1418.55	158
1420.69	184
1422.83	178
1424.97	168
1427.1	172
1429.24	200
1431.38	176
1433.52	174
1435.65	198
1437.79	180
1439.92	192
1442.06	190
1444.19	188
1446.32	184
1448.46	190
1450.59	164
1452.72	192
1454.85	166
1456.98	178
1459.11	184
1461.23	196
1463.36	190
1465.49	164
1467.61	200
1469.74	172
1471.86	180
1473.99	168
1476.11	178
1478.23	188
1480.36	162
1482.48	174
1484.6	182
1486.72	182
1488.84	182
1490.96	174
1493.07	160
1495.19	158
1497.31	182
1499.42	188
1501.54	162
1503.65	168
1505.77	162
1507.88	170
1509.99	152
1512.1	166
1514.22	170
1516.33	174
1518.44	172
1520.55	178
1522.65	170
1524.76	174
1526.87	170
1528.98	162
1531.08	176
1533.19	174
1535.29	154
1537.4	168
1539.5	172
1541.6	170
1543.7	172
1545.8	170
1547.91	158
1550.01	162
1552.11	178
1554.2	176
1556.3	182
1558.4	162
1560.5	176
1562.59	156
1564.69	168
1566.78	170
1568.88	158
1570.97	172
1573.06	180
1575.15	150
1577.25	158
1579.34	152
1581.43	156
1583.52	162
1585.6	158
1587.69	166
1589.78	152
1591.87	170
1593.95	168
1596.04	148
1598.12	162
1600.21	164
1602.29	168
1604.37	146
1606.46	164
1608.54	154
1610.62	152
1612.7	160
1614.78	164
1616.86	170
1618.94	162
1621.01	168
1623.09	160
1625.17	160
1627.24	164
1629.32	168
1631.39	146
1633.47	166
1635.54	166
1637.61	160
1639.68	170
1641.76	144
1643.83	164
1645.9	180
1647.96	144
1650.03	158
1652.1	156
1654.17	152
1656.24	146
1658.3	154
1660.37	148
1662.43	148
1664.5	166
1666.56	154
1668.62	152
1670.68	154
1672.75	150
1674.81	172
1676.87	164
1678.93	152
1680.99	156
1683.04	156
1685.1	160
1687.16	160
1689.21	144
1691.27	154
1693.33	146
1695.38	154
1697.43	144
1699.49	142
1701.54	150
1703.59	160
1705.64	136
1707.69	168
1709.74	160
1711.79	144
1713.84	156
1715.89	136
1717.94	146
1719.98	130
1722.03	146
1724.07	156
1726.12	146
1728.16	148
1730.21	148
1732.25	152
1734.29	154
1736.33	150
1738.37	154
1740.41	156
1742.45	146
1744.49	150
1746.53	136
1748.57	136
1750.61	134
1752.64	142
1754.68	144
1756.71	146
1758.75	150
1760.78	142
1762.82	162
1764.85	142
1766.88	140
1768.91	146
1770.94	148
1772.97	150
1775	144
1777.03	132
1779.06	150
1781.09	138
1783.12	144
1785.14	138
1787.17	148
1789.19	144
1791.22	134
1793.24	148
1795.27	142
1797.29	128
1799.31	146
1801.33	132
1803.35	162
1805.37	136
1807.39	146
1809.41	142
1811.43	146
1813.45	144
1815.46	130
1817.48	140
1819.5	150
1821.51	142
1823.53	122
1825.54	126
1827.55	120
1829.57	132
1831.58	134
1833.59	146
1835.6	132
1837.61	134
1839.62	134
1841.63	130
1843.64	132
1845.65	130
1847.65	134
1849.66	130
1851.66	128
1853.67	126
1855.67	140
1857.68	134
1859.68	128
1861.68	132
1863.69	120
1865.69	136
1867.69	142
1869.69	130
1871.69	130
1873.69	132
1875.69	132
1877.68	118
1879.68	132
1881.68	134
1883.67	132
1885.67	142
1887.66	142
1889.66	124
1891.65	134
1893.64	126
1895.64	124
1897.63	130
1899.62	130
1901.61	126
1903.6	122
1905.59	118
1907.58	138
1909.56	106
1911.55	124
1913.54	120
1915.53	120
1917.51	122
1919.5	120
1921.48	126
1923.46	128
1925.45	116
1927.43	112
1929.41	110
1931.39	122
1933.37	130
1935.35	126
1937.33	124
1939.31	128
1941.29	114
1943.27	116
1945.24	112
1947.22	124
1949.2	122
1951.17	124
1953.14	129
1955.12	114
1957.09	122
1959.06	118
1961.04	128
1963.01	142
1964.98	114
1966.95	116
1968.92	130
1970.89	120
1972.86	112
1974.82	122
1976.79	118
1978.76	128
1980.72	108
1982.69	112
1984.65	112
1986.62	110
1988.58	126
1990.54	124
1992.51	112
1994.47	110
1996.43	116
1998.39	120
1999.37	112