File: muestras/coffe_mate/Organic_04.txt
#Acq. time (s)=	10
#Accumulations=	1
#Range (cm-¹)=	100...2000
#Windows=	2
#Autofocus=	Off
#AutoExposure=	Off
#Spike filter=	Off
#Delay time (s)=	0
#Binning=	1
#Readout mode=	Signal
#DeNoise=	Off
#ICS correction=	Off
#Dark correction=	Off
#Inst. Process=	Off
#Instrument=	LabRAM HR Evol
#Detector=	Syncerity OE
#Objective=	x100_VIS
#Grating=	600 (500nm)
#ND Filter=	25%
#Laser=	633nm_Edge
#Hole=	49.98
#Range=	Visible
#Project=	Omar
#Sample=	20-06-23
#Site=	2
#Title=	Organic
#Remark=
#Date=	20.06.2023 11:53
#Acquired=	20.06.2023 11:53:08
101.054	122
103.621	146
106.187	140
108.752	140
111.317	130
113.881	130
116.443	116
119.005	142
121.566	136
124.126	136
126.685	148
129.243	134
131.801	130
134.356	134
136.911	128
139.466	134
142.021	130
144.574	124
147.125	136
149.676	130
152.227	124
154.776	122
157.325	144
159.873	120
162.419	122
164.966	136
167.51	140
170.055	140
172.598	140
175.141	120
177.682	136
180.222	148
182.763	142
185.302	146
187.839	162
190.376	128
192.914	134
195.449	128
197.983	138
200.517	142
203.05	136
205.582	130
208.113	136
210.643	144
213.173	130
215.701	142
218.229	152
220.756	130
223.282	134
225.808	136
228.331	142
230.855	132
233.378	134
235.898	140
238.419	146
240.94	144
243.458	138
245.977	158
248.495	144
251.011	160
253.527	148
256.041	134
258.555	136
261.068	142
263.58	140
266.092	144
268.603	154
271.112	148
273.62	148
276.129	136
278.636	142
281.142	152
283.647	146
286.152	144
288.655	140
291.158	142
293.66	140
296.161	152
298.661	150
301.161	154
303.66	158
306.158	128
308.655	128
311.15	132
313.645	142
316.14	128
318.634	142
321.125	148
323.618	124
326.109	156
328.598	132
331.088	152
333.576	140
336.064	146
338.55	154
341.037	144
343.521	152
346.005	152
348.489	138
350.971	154
353.453	152
355.933	146
358.414	130
360.893	146
363.371	154
365.848	144
368.325	144
370.801	136
373.275	146
375.75	136
378.223	146
380.695	146
383.167	150
385.638	138
388.108	148
390.577	130
393.044	146
395.512	142
397.979	134
400.444	154
402.909	144
405.374	156
407.836	148
410.299	146
412.76	140
415.221	146
417.681	154
420.141	160
422.598	150
425.057	150
427.513	154
429.968	152
432.422	144
434.878	156
437.33	158
439.783	164
442.234	162
444.685	142
447.134	150
449.583	150
452.032	146
454.479	156
456.926	154
459.372	152
461.817	136
464.261	152
466.705	156
469.147	138
471.588	160
474.029	144
476.47	160
478.909	150
481.347	184
483.785	136
486.221	146
488.657	152
491.092	144
493.527	158
495.96	136
498.393	166
500.824	140
503.255	144
505.686	144
508.115	160
510.543	154
512.972	144
515.399	142
517.825	140
520.25	146
522.674	148
525.097	158
527.52	146
529.942	146
532.364	154
534.784	136
537.204	148
539.623	146
542.041	126
544.457	156
546.874	124
549.289	132
551.705	164
554.118	150
556.531	142
558.943	140
561.355	146
563.766	146
566.175	148
568.585	134
570.992	152
573.399	152
575.807	142
578.212	148
580.617	144
583.022	140
585.425	152
587.827	158
590.229	150
592.63	162
595.03	148
597.43	150
599.829	146
602.226	146
604.623	150
607.02	146
609.414	152
611.808	158
614.202	148
616.596	148
618.988	150
621.378	152
623.769	154
626.159	138
628.548	146
630.936	138
633.324	148
635.71	148
638.096	148
640.481	146
642.866	150
645.248	154
647.63	156
650.013	140
652.394	154
654.773	136
657.154	132
659.532	150
661.91	142
664.286	136
666.663	156
669.038	140
671.412	144
673.786	154
676.159	150
678.532	154
680.903	148
683.274	150
685.644	150
688.014	154
690.381	138
692.749	156
695.116	140
697.481	140
699.846	156
702.211	146
704.574	154
706.938	142
709.299	154
711.661	160
714.021	134
716.381	136
718.739	140
721.097	136
723.455	138
725.811	146
728.167	140
730.521	134
732.875	146
735.23	138
737.582	144
739.934	148
742.285	138
744.635	150
746.985	152
749.332	148
751.68	140
754.028	146
756.374	152
758.72	156
761.065	154
763.408	126
765.752	130
768.095	142
770.436	136
772.777	146
775.116	170
777.456	140
779.794	160
782.133	160
784.469	146
786.805	138
789.141	128
791.476	134
793.809	140
796.142	132
798.476	142
800.807	148
803.138	144
805.468	136
807.797	122
810.125	144
812.453	132
814.78	144
817.106	144
819.432	140
821.757	130
824.08	128
826.403	146
828.726	142
831.048	136
833.368	134
835.688	148
838.007	138
840.326	144
842.644	144
844.96	146
847.276	132
849.592	138
851.906	130
854.221	146
856.534	156
858.846	146
861.157	152
863.469	142
865.779	138
868.088	156
870.396	130
872.704	146
875.011	138
877.318	142
879.623	138
881.928	142
884.232	132
886.536	146
888.837	138
891.139	144
893.44	140
895.741	122
898.039	144
900.339	130
902.637	138
904.933	130
907.231	138
909.526	136
911.821	150
914.115	126
916.408	140
918.701	142
920.993	136
923.283	146
925.573	142
927.864	140
930.153	138
932.441	120
934.728	148
937.014	148
939.3	144
941.585	150
943.87	140
946.154	132
948.437	132
950.719	140
952.999	150
955.28	124
957.56	132
959.84	146
962.117	136
964.395	140
966.671	156
968.948	134
971.223	128
973.498	142
975.771	142
978.045	128
980.317	144
982.588	130
984.86	126
987.13	136
989.399	128
991.667	132
993.937	138
996.204	150
998.47	126
1000.74	142
1003	130
1005.26	130
1007.53	140
1009.79	138
1012.05	140
1014.31	130
1016.57	136
1018.83	136
1021.09	128
1023.35	132
1025.61	148
1027.87	124
1030.12	144
1032.38	138
1034.63	150
1036.88	138
1039.14	144
1041.39	138
1043.64	132
1045.89	132
1048.14	128
1050.39	132
1052.64	126
1054.89	132
1057.14	144
1059.38	136
1061.63	142
1063.87	136
1066.12	132
1068.36	130
1070.6	128
1072.85	148
1075.09	126
1077.33	148
1079.57	130
1081.81	132
1084.05	140
1086.28	142
1088.52	138
1090.76	124
1092.99	120
1095.23	128
1097.46	122
1099.69	126
1101.93	132
1104.16	130
1106.39	138
1108.62	142
1110.85	126
1113.08	134
1115.31	122
1117.53	120
1119.76	138
1121.99	142
1124.21	136
1126.44	134
1128.66	128
1130.88	130
1133.11	124
1135.33	142
1137.55	136
1139.77	120
1141.99	120
1144.21	130
1146.43	120
1148.64	130
1150.86	126
1153.08	128
1155.29	132
1157.51	140
1159.72	130
1161.93	124
1164.14	132
1166.36	126
1168.57	116
1170.78	126
1172.99	128
1175.2	124
1177.4	136
1179.61	124
1181.82	124
1184.02	124
1186.23	124
1188.43	120
1190.64	130
1192.84	140
1195.04	120
1197.24	120
1199.45	124.01
1201.64	116.02
1203.84	130.143
1206.04	132.61
1208.24	120.482
1210.44	116.981
1212.64	133.726
1214.83	118.641
1217.03	126.351
1219.22	129.026
1221.41	111
1223.61	129.13
1225.8	128.619
1227.99	130.466
1230.18	126.671
1232.37	117.849
1234.56	121.947
1236.75	122.865
1238.94	116.198
1241.13	118.913
1243.31	116.334
1245.5	114.25
1247.68	119.588
1249.87	115.564
1252.05	112.066
1254.24	121.443
1256.42	117.763
1258.6	121.625
1260.78	114.87
1262.96	112.421
1265.14	128.88
1267.32	124.331
1269.5	108.481
1271.67	118.28
1273.85	124.947
1276.03	118.891
1278.2	117.403
1280.38	120.797
1282.55	114.997
1284.72	110.075
1286.9	117.442
1289.07	125.259
1291.24	117.668
1293.41	124.38
1295.58	123.325
1297.75	113.962
1299.92	123.71
1302.09	119.712
1304.25	129.139
1306.42	108.065
1308.46	116
1310.63	120
1312.81	112
1314.98	104
1317.16	124
1319.33	108
1321.5	118
1323.67	120
1325.85	124
1328.02	122
1330.19	116
1332.35	118
1334.52	114
1336.69	118
1338.86	120
1341.02	110
1343.19	114
1345.35	124
1347.52	118
1349.68	120
1351.84	118
1354	118
1356.17	116
1358.33	130
1360.49	116
1362.65	110
1364.8	116
1366.96	120
1369.12	126
1371.28	108
1373.43	106
1375.59	106
1377.74	124
1379.89	122
1382.05	106
1384.2	106
1386.35	104
1388.5	106
1390.65	110
1392.8	106
1394.95	108
1397.1	104
1399.25	118
1401.4	114
1403.54	124
1405.69	108
1407.83	110
1409.98	110
1412.12	120
1414.26	114
1416.4	112
1418.55	106
1420.69	114
1422.83	106
1424.97	110
1427.1	106
1429.24	106
1431.38	118
1433.52	114
1435.65	118
1437.79	108
1439.92	122
1442.06	118
1444.19	106
1446.32	106
1448.46	112
1450.59	126
1452.72	116
1454.85	122
1456.98	110
1459.11	114
1461.23	110
1463.36	116
1465.49	118
1467.61	112
1469.74	110
1471.86	106
1473.99	116
1476.11	100
1478.23	118
1480.36	114
1482.48	112
1484.6	118
1486.72	102
1488.84	108
1490.96	96
1493.07	114
1495.19	114
1497.31	114
1499.42	108
1501.54	100
1503.65	94
1505.77	118
1507.88	106
1509.99	102
1512.1	96
1514.22	104
1516.33	104
1518.44	108
1520.55	88
1522.65	114
1524.76	98
1526.87	102
1528.98	98
1531.08	108
1533.19	98
1535.29	112
1537.4	114
1539.5	102
1541.6	106
1543.7	100
1545.8	106
1547.91	100
1550.01	96
1552.11	102
1554.2	100
1556.3	96
1558.4	100
1560.5	100
1562.59	112
1564.69	98
1566.78	92
1568.88	108
1570.97	90
1573.06	104
1575.15	102
1577.25	94
1579.34	106
1581.43	98
1583.52	104
1585.6	94
1587.69	98
1589.78	98
1591.87	106
1593.95	104
1596.04	98
1598.12	96
1600.21	98
1602.29	120
1604.37	104
1606.46	104
1608.54	106
1610.62	96
1612.7	96
1614.78	110
1616.86	106
1618.94	114
1621.01	110
1623.09	100
1625.17	106
1627.24	108
1629.32	90
1631.39	102
1633.47	94
1635.54	104
1637.61	100
1639.68	104
1641.76	100
1643.83	88
1645.9	94
1647.96	88
1650.03	98
1652.1	92
1654.17	100
1656.24	104
1658.3	90
1660.37	100
1662.43	112
1664.5	92
1666.56	90
1668.62	104
1670.68	98
1672.75	84
1674.81	96
1676.87	100
1678.93	96
1680.99	96
1683.04	110
1685.1	88
1687.16	96
1689.21	102
1691.27	100
1693.33	92
1695.38	98
1697.43	102
1699.49	96
1701.54	98
1703.59	96
1705.64	100
1707.69	102
1709.74	96
1711.79	92
1713.84	90
1715.89	92
1717.94	98
1719.98	90
1722.03	108
1724.07	96
1726.12	98
1728.16	96
1730.21	100
1732.25	92
1734.29	84
1736.33	104
1738.37	94
1740.41	92
1742.45	100
1744.49	80
1746.53	90
1748.57	90
1750.61	92
1752.64	92
1754.68	90
1756.71	100
1758.75	82
1760.78	92
1762.82	94
1764.85	94
1766.88	88
1768.91	88
1770.94	86
1772.97	86
1775	98
1777.03	88
1779.06	96
1781.09	94
1783.12	96
1785.14	94
1787.17	90
1789.19	108
1791.22	94
1793.24	96
1795.27	84
1797.29	86
1799.31	98
1801.33	90
1803.35	96
1805.37	90
1807.39	90
1809.41	90
1811.43	86
1813.45	90
1815.46	100
1817.48	96
1819.5	92
1821.51	90
1823.53	84
1825.54	90
1827.55	90
1829.57	78
1831.58	84
1833.59	84
1835.6	84
1837.61	80
1839.62	82
1841.63	94
1843.64	90
1845.65	90
1847.65	78
1849.66	96
1851.66	84
1853.67	84
1855.67	82
1857.68	90
1859.68	86
1861.68	92
1863.69	92
1865.69	86
1867.69	76
1869.69	88
1871.69	80
1873.69	78
1875.69	84
1877.68	84
1879.68	68
1881.68	92
1883.67	82
1885.67	80
1887.66	86
1889.66	84
1891.65	90
1893.64	92
1895.64	98
1897.63	72
1899.62	84
1901.61	90
1903.6	80
1905.59	82
1907.58	88
1909.56	80
1911.55	76
1913.54	78
1915.53	92
1917.51	82
1919.5	80
1921.48	84
1923.46	80
1925.45	80
1927.43	84
1929.41	82
1931.39	78
1933.37	88
1935.35	82
1937.33	90
1939.31	84
1941.29	88
1943.27	82
1945.24	78
1947.22	78
1949.2	80
1951.17	84
1953.14	81
1955.12	80
1957.09	82
1959.06	84
1961.04	78
1963.01	74
1964.98	70
1966.95	78
1968.92	86
1970.89	84
1972.86	74
1974.82	70
1976.79	74
1978.76	84
1980.72	72
1982.69	82
1984.65	78
1986.62	92
1988.58	66
1990.54	78
1992.51	80
1994.47	74
1996.43	80
1998.39	62
1999.37	68