File: muestras/coffe_mate/Organic_09.txt
#Acq. time (s)=	15
#Accumulations=	1
#Range (cm-¹)=	100...2000
#Windows=	2
#Autofocus=	Off
#AutoExposure=	Off
#Spike filter=	Off
#Delay time (s)=	0
#Binning=	1
#Readout mode=	Signal
#DeNoise=	Off
#ICS correction=	Off
#Dark correction=	Off
#Inst. Process=	Off
#Instrument=	LabRAM HR Evol
#Detector=	Syncerity OE
#Objective=	x100_VIS
#Grating=	600 (500nm)
#ND Filter=	100%
#Laser=	633nm_Edge
#Hole=	100.021
#Range=	Visible
#Project=	Omar
#Sample=	20-06-23
#Site=	2
#Title=	Organic
#Remark=
#Date=	20.06.2023 11:58
#Acquired=	20.06.2023 11:58:14
101.054	1008
103.621	1010
106.187	1018
108.752	984
111.317	970
113.881	972
116.443	972
119.005	948
121.566	984
124.126	962
126.685	964
129.243	982
131.801	970
134.356	982
136.911	976
139.466	972
142.021	980
144.574	988
147.125	1006
149.676	1014
152.227	986
154.776	998
157.325	972
159.873	988
162.419	972
164.966	996
167.51	1004
170.055	976
172.598	974
175.141	960
177.682	966
180.222	1010
182.763	974
185.302	960
187.839	976
190.376	978
192.914	1022
195.449	992
197.983	1006
200.517	1070
203.05	1006
205.582	1030
208.113	1008
210.643	1014
213.173	1054
215.701	996
218.229	1028
220.756	1020
223.282	1052
225.808	1036
228.331	992
230.855	1014
233.378	1000
235.898	972
238.419	1066
240.94	1020
243.458	1006
245.977	1046
248.495	1012
251.011	1020
253.527	1034
256.041	1014
258.555	986
261.068	1046
263.58	976
266.092	1052
268.603	968
271.112	1026
273.62	1016
276.129	1052
278.636	1030
281.142	1020
283.647	1048
286.152	1016
288.655	1082
291.158	1068
293.66	1074
296.161	1076
298.661	1052
301.161	1062
303.66	1044
306.158	1042
308.655	1044
311.15	1064
313.645	1032
316.14	1076
318.634	1044
321.125	1026
323.618	1070
326.109	1058
328.598	1034
331.088	1082
333.576	1080
336.064	1074
338.55	1074
341.037	1074
343.521	1086
346.005	1026
348.489	1046
350.971	1098
353.453	1040
355.933	1088
358.414	1076
360.893	1058
363.371	1082
365.848	1042
368.325	1068
370.801	1074
373.275	1048
375.75	1088
378.223	1066
380.695	1022
383.167	1028
385.638	1088
388.108	1022
390.577	1062
393.044	1064
395.512	1056
397.979	1040
400.444	1062
402.909	1060
405.374	1072
407.836	1068
410.299	1066
412.76	1054
415.221	1090
417.681	1088
420.141	1078
422.598	1098
425.057	1092
427.513	1084
429.968	1068
432.422	1058
434.878	1068
437.33	1110
439.783	1118
442.234	1086
444.685	1088
447.134	1116
449.583	1084
452.032	1124
454.479	1062
456.926	1066
459.372	1116
461.817	1088
464.261	1098
466.705	1090
469.147	1106
471.588	1098
474.029	1122
476.47	1122
478.909	1128
481.347	1100
483.785	1128
486.221	1112
488.657	1128
491.092	1104
493.527	1092
495.96	1080
498.393	1076
500.824	1102
503.255	1108
505.686	1110
508.115	1068
510.543	1116
512.972	1094
515.399	1134
517.825	1116
520.25	1096
522.674	1072
525.097	1050
527.52	1054
529.942	1142
532.364	1090
534.784	1098
537.204	1044
539.623	1086
542.041	1090
544.457	1068
546.874	1046
549.289	1072
551.705	1080
554.118	1066
556.531	1062
558.943	1054
561.355	1060
563.766	1058
566.175	1090
568.585	1046
570.992	1092
573.399	1074
575.807	1038
578.212	1070
580.617	1084
583.022	1012
585.425	1078
587.827	1050
590.229	1046
592.63	1076
595.03	1074
597.43	1082
599.829	1042
602.226	1044
604.623	1046
607.02	1078
609.414	1062
611.808	1028
614.202	1080
616.596	1060
618.988	1064
621.378	1122
623.769	1046
626.159	1116
628.548	1046
630.936	1106
633.324	1088
635.71	1108
638.096	1102
640.481	1044
642.866	1068
645.248	1084
647.63	1076
650.013	1060
652.394	1086
654.773	1064
657.154	1082
659.532	1108
661.91	1068
664.286	1096
666.663	1078
669.038	1050
671.412	1076
673.786	1050
676.159	1066
678.532	1046
680.903	1050
683.274	1056
685.644	1046
688.014	1032
690.381	1082
692.749	1078
695.116	1046
697.481	1094
699.846	1080
702.211	1058
704.574	1096
706.938	1006
709.299	1082
711.661	1048
714.021	1062
716.381	1048
718.739	1056
721.097	1046
723.455	1086
725.811	1094
728.167	1072
730.521	1050
732.875	1046
735.23	1060
737.582	1038
739.934	1002
742.285	1010
744.635	1028
746.985	1044
749.332	1038
751.68	1040
754.028	1048
756.374	1034
758.72	1012
761.065	1034
763.408	1036
765.752	1010
768.095	1044
770.436	1022
772.777	1052
775.116	1030
777.456	1024
779.794	1026
782.133	978
784.469	1022
786.805	1044
789.141	984
791.476	1046
793.809	1000
796.142	1002
798.476	1030
800.807	1042
803.138	1014
805.468	984
807.797	1012
810.125	1020
812.453	984
814.78	1042
817.106	1000
819.432	992
821.757	1016
824.08	992
826.403	1046
828.726	1032
831.048	1034
833.368	978
835.688	1012
838.007	1014
840.326	1042
842.644	1000
844.96	1022
847.276	1040
849.592	1028
851.906	1046
854.221	1036
856.534	1806
858.846	1066
861.157	1022
863.469	1034
865.779	1042
868.088	1062
870.396	978
872.704	1048
875.011	1004
877.318	1034
879.623	1042
881.928	1032
884.232	974
886.536	996
888.837	1018
891.139	1000
893.44	1008
895.741	1026
898.039	1024
900.339	1002
902.637	1006
904.933	988
907.231	1006
909.526	1016
911.821	1012
914.115	1002
916.408	1040
918.701	986
920.993	976
923.283	1008
925.573	982
927.864	1002
930.153	1006
932.441	990
934.728	1000
937.014	1010
939.3	960
941.585	1008
943.87	996
946.154	962
948.437	1000
950.719	926
952.999	982
955.28	956
957.56	968
959.84	996
962.117	964
964.395	960
966.671	992
968.948	994
971.223	956
973.498	992
975.771	984
978.045	972
980.317	954
982.588	950
984.86	924
987.13	1012
989.399	968
991.667	994
993.937	926
996.204	978
998.47	918
1000.74	990
1003	958
1005.26	962
1007.53	942
1009.79	924
1012.05	956
1014.31	954
1016.57	940
1018.83	948
1021.09	1004
1023.35	990
1025.61	976
1027.87	978
1030.12	922
1032.38	992
1034.63	938
1036.88	956
1039.14	984
1041.39	942
1043.64	968
1045.89	976
1048.14	970
1050.39	962
1052.64	940
1054.89	970
1057.14	972
1059.38	986
1061.63	990
1063.87	978
1066.12	948
1068.36	984
1070.6	974
1072.85	970
1075.09	954
1077.33	944
1079.57	1018
1081.81	966
1084.05	968
1086.28	962
1088.52	924
1090.76	954
1092.99	926
1095.23	950
1097.46	954
1099.69	928
1101.93	936
1104.16	910
1106.39	918
1108.62	968
1110.85	948
1113.08	962
1115.31	922
1117.53	938
1119.76	944
1121.99	942
1124.21	954
1126.44	928
1128.66	952
1130.88	916
1133.11	890
1135.33	914
1137.55	942
1139.77	906
1141.99	922
1144.21	908
1146.43	926
1148.64	928
1150.86	926
1153.08	874
1155.29	944
1157.51	898
1159.72	922
1161.93	902
1164.14	860
1166.36	882
1168.57	918
1170.78	910
1172.99	888
1175.2	900
1177.4	870
1179.61	918
1181.82	880
1184.02	886
1186.23	902
1188.43	892
1190.64	856
1192.84	882
1195.04	864
1197.24	820
1199.45	842.06
1201.64	877.407
1203.84	836.452
1206.04	883.474
1208.24	853.326
1210.44	875.214
1212.64	843.113
1214.83	828.669
1217.03	805.684
1219.22	834.412
1221.41	841.144
1223.61	854.348
1225.8	828.559
1227.99	826.696
1230.18	827.15
1232.37	850.28
1234.56	835.882
1236.75	839.02
1238.94	833.829
1241.13	840.723
1243.31	826.049
1245.5	841.509
1247.68	826.632
1249.87	834.902
1252.05	818.197
1254.24	830.622
1256.42	832.294
1258.6	854.254
1260.78	856.744
1262.96	822.899
1265.14	828.698
1267.32	838.699
1269.5	846.958
1271.67	834.816
1273.85	847.26
1276.03	854.738
1278.2	826.842
1280.38	833.335
1282.55	833.572
1284.72	841.065
1286.9	824.233
1289.07	827.571
1291.24	831.15
1293.41	837.562
1295.58	867.537
1297.75	854.823
1299.92	854.396
1302.09	809.665
1304.25	810.074
1306.42	837.163
1308.46	824
1310.63	810
1312.81	802
1314.98	822
1317.16	818
1319.33	842
1321.5	792
1323.67	802
1325.85	780
1328.02	816
1330.19	820
1332.35	794
1334.52	802
1336.69	796
1338.86	826
1341.02	848
1343.19	810
1345.35	802
1347.52	828
1349.68	784
1351.84	824
1354	824
1356.17	810
1358.33	802
1360.49	774
1362.65	808
1364.8	766
1366.96	794
1369.12	768
1371.28	798
1373.43	760
1375.59	736
1377.74	788
1379.89	796
1382.05	794
1384.2	812
1386.35	782
1388.5	814
1390.65	776
1392.8	770
1394.95	758
1397.1	796
1399.25	788
1401.4	770
1403.54	790
1405.69	800
1407.83	752
1409.98	758
1412.12	762
1414.26	740
1416.4	776
1418.55	810
1420.69	796
1422.83	806
1424.97	740
1427.1	764
1429.24	758
1431.38	790
1433.52	784
1435.65	792
1437.79	778
1439.92	816
1442.06	812
1444.19	766
1446.32	788
1448.46	774
1450.59	790
1452.72	790
1454.85	766
1456.98	778
1459.11	750
1461.23	786
1463.36	750
1465.49	760
1467.61	742
1469.74	772
1471.86	744
1473.99	788
1476.11	740
1478.23	736
1480.36	732
1482.48	726
1484.6	712
1486.72	710
1488.84	732
1490.96	724
1493.07	730
1495.19	712
1497.31	734
1499.42	734
1501.54	728
1503.65	734
1505.77	714
1507.88	720
1509.99	698
1512.1	710
1514.22	722
1516.33	708
1518.44	704
1520.55	718
1522.65	674
1524.76	690
1526.87	722
1528.98	692
1531.08	704
1533.19	680
1535.29	696
1537.4	700
1539.5	684
1541.6	714
1543.7	718
1545.8	668
1547.91	674
1550.01	678
1552.11	664
1554.2	658
1556.3	660
1558.4	678
1560.5	682
1562.59	654
1564.69	644
1566.78	684
1568.88	674
1570.97	684
1573.06	664
1575.15	672
1577.25	658
1579.34	656
1581.43	662
1583.52	648
1585.6	646
1587.69	672
1589.78	654
1591.87	654
1593.95	654
1596.04	658
1598.12	674
1600.21	654
1602.29	652
1604.37	616
1606.46	638
1608.54	618
1610.62	662
1612.7	670
1614.78	638
1616.86	628
1618.94	624
1621.01	674
1623.09	658
1625.17	658
1627.24	670
1629.32	658
1631.39	642
1633.47	634
1635.54	650
1637.61	634
1639.68	642
1641.76	620
1643.83	604
1645.9	644
1647.96	674
1650.03	628
1652.1	648
1654.17	644
1656.24	642
1658.3	666
1660.37	608
1662.43	606
1664.5	618
1666.56	638
1668.62	618
1670.68	616
1672.75	630
1674.81	598
1676.87	594
1678.93	618
1680.99	582
1683.04	608
1685.1	602
1687.16	608
1689.21	614
1691.27	608
1693.33	622
1695.38	628
1697.43	616
1699.49	578
1701.54	572
1703.59	586
1705.64	612
1707.69	562
1709.74	580
1711.79	602
1713.84	582
1715.89	608
1717.94	576
1719.98	598
1722.03	578
1724.07	578
1726.12	596
1728.16	590
1730.21	586
1732.25	572
1734.29	590
1736.33	602
1738.37	564
1740.41	566
1742.45	590
1744.49	582
1746.53	560
1748.57	616
1750.61	580
1752.64	590
1754.68	552
1756.71	554
1758.75	558
1760.78	560
1762.82	560
1764.85	588
1766.88	602
1768.91	548
1770.94	556
1772.97	588
1775	554
1777.03	580
1779.06	584
1781.09	578
1783.12	570
1785.14	584
1787.17	568
1789.19	552
1791.22	562
1793.24	574
1795.27	558
1797.29	556
1799.31	566
1801.33	574
1803.35	552
1805.37	532
1807.39	560
1809.41	530
1811.43	532
1813.45	544
1815.46	526
1817.48	536
1819.5	516
1821.51	572
1823.53	536
1825.54	528
1827.55	530
1829.57	530
1831.58	524
1833.59	492
1835.6	512
1837.61	538
1839.62	532
1841.63	514
1843.64	500
1845.65	512
1847.65	508
1849.66	504
1851.66	534
1853.67	506
1855.67	526
1857.68	522
1859.68	504
1861.68	520
1863.69	514
1865.69	526
1867.69	502
1869.69	508
1871.69	512
1873.69	474
1875.69	488
1877.68	522
1879.68	494
1881.68	526
1883.67	540
1885.67	468
1887.66	510
1889.66	504
1891.65	498
1893.64	502
1895.64	476
1897.63	486
1899.62	476
1901.61	498
1903.6	480
1905.59	470
1907.58	492
1909.56	502
1911.55	510
1913.54	482
1915.53	464
1917.51	498
1919.5	486
1921.48	504
1923.46	480
1925.45	494
1927.43	478
1929.41	478
1931.39	498
1933.37	478
1935.35	468
1937.33	492
1939.31	452
1941.29	454
1943.27	464
1945.24	478
1947.22	510
1949.2	478
1951.17	506
1953.14	467
1955.12	458
1957.09	494
1959.06	462
1961.04	466
1963.01	462
1964.98	432
1966.95	456
1968.92	446
1970.89	454
1972.86	454
1974.82	410
1976.79	432
1978.76	454
1980.72	476
1982.69	434
1984.65	452
1986.62	458
1988.58	444
1990.54	430
1992.51	434
1994.47	448
1996.43	454
1998.39	454
1999.37	472