File: muestras/coffe_mate/Organic_06.txt
#Acq. time (s)=	10
#Accumulations=	1
#Range (cm-¹)=	100...2000
#Windows=	2
#Autofocus=	Off
#AutoExposure=	Off
#Spike filter=	Off
#Delay time (s)=	0
#Binning=	1
#Readout mode=	Signal
#DeNoise=	Off
#ICS correction=	Off
#Dark correction=	Off
#Inst. Process=	Off
#Instrument=	LabRAM HR Evol
#Detector=	Syncerity OE
#Objective=	x100_VIS
#Grating=	600 (500nm)
#ND Filter=	50%
#Laser=	633nm_Edge
#Hole=	49.98
#Range=	Visible
#Project=	Omar
#Sample=	20-06-23
#Site=	2
#Title=	Organic
#Remark=
#Date=	20.06.2023 11:55
#Acquired=	20.06.2023 11:55:34
101.054	166
103.621	152
106.187	148
108.752	140
111.317	156
113.881	158
116.443	156
119.005	160
121.566	148
124.126	154
126.685	154
129.243	158
131.801	152
134.356	138
136.911	144
139.466	158
142.021	152
144.574	162
147.125	152
149.676	150
152.227	158
154.776	168
157.325	146
159.873	154
162.419	156
164.966	160
167.51	146
170.055	150
172.598	146
175.141	162
177.682	158
180.222	146
182.763	166
185.302	176
187.839	154
190.376	142
192.914	148
195.449	150
197.983	174
200.517	168
203.05	154
205.582	156
208.113	166
210.643	142
213.173	158
215.701	160
218.229	162
220.756	158
223.282	150
225.808	170
228.331	168
230.855	166
233.378	162
235.898	162
238.419	164
240.94	148
243.458	150
245.977	158
248.495	172
251.011	172
253.527	166
256.041	160
258.555	164
261.068	150
263.58	166
266.092	162
268.603	158
271.112	168
273.62	180
276.129	182
278.636	154
281.142	150
283.647	168
286.152	176
288.655	170
291.158	172
293.66	164
296.161	144
298.661	166
301.161	178
303.66	174
306.158	158
308.655	156
311.15	166
313.645	160
316.14	178
318.634	164
321.125	154
323.618	170
326.109	168
328.598	158
331.088	162
333.576	152
336.064	176
338.55	168
341.037	172
343.521	156
346.005	156
348.489	158
350.971	174
353.453	162
355.933	180
358.414	170
360.893	160
363.371	182
365.848	170
368.325	170
370.801	172
373.275	178
375.75	160
378.223	170
380.695	164
383.167	182
385.638	168
388.108	160
390.577	162
393.044	174
395.512	160
397.979	176
400.444	168
402.909	160
405.374	162
407.836	148
410.299	190
412.76	152
415.221	168
417.681	172
420.141	184
422.598	176
425.057	176
427.513	186
429.968	170
432.422	162
434.878	168
437.33	176
439.783	180
442.234	170
444.685	178
447.134	176
449.583	172
452.032	170
454.479	184
456.926	174
459.372	158
461.817	160
464.261	164
466.705	152
469.147	176
471.588	168
474.029	176
476.47	184
478.909	162
481.347	172
483.785	164
486.221	156
488.657	164
491.092	178
493.527	176
495.96	168
498.393	172
500.824	166
503.255	176
505.686	162
508.115	172
510.543	168
512.972	164
515.399	180
517.825	180
520.25	168
522.674	186
525.097	172
527.52	172
529.942	168
532.364	184
534.784	174
537.204	166
539.623	176
542.041	176
544.457	168
546.874	166
549.289	164
551.705	168
554.118	152
556.531	164
558.943	168
561.355	168
563.766	158
566.175	178
568.585	162
570.992	172
573.399	168
575.807	170
578.212	158
580.617	148
583.022	176
585.425	166
587.827	158
590.229	166
592.63	170
595.03	170
597.43	158
599.829	184
602.226	164
604.623	182
607.02	166
609.414	176
611.808	164
614.202	164
616.596	164
618.988	166
621.378	158
623.769	166
626.159	172
628.548	172
630.936	166
633.324	172
635.71	168
638.096	152
640.481	170
642.866	168
645.248	178
647.63	174
650.013	174
652.394	164
654.773	178
657.154	174
659.532	176
661.91	184
664.286	168
666.663	168
669.038	176
671.412	166
673.786	176
676.159	168
678.532	174
680.903	172
683.274	160
685.644	174
688.014	158
690.381	180
692.749	174
695.116	172
697.481	168
699.846	154
702.211	158
704.574	162
706.938	188
709.299	166
711.661	182
714.021	168
716.381	166
718.739	158
721.097	162
723.455	162
725.811	154
728.167	176
730.521	158
732.875	174
735.23	182
737.582	176
739.934	154
742.285	154
744.635	162
746.985	164
749.332	170
751.68	162
754.028	172
756.374	166
758.72	152
761.065	166
763.408	162
765.752	160
768.095	162
770.436	162
772.777	168
775.116	176
777.456	164
779.794	168
782.133	158
784.469	174
786.805	146
789.141	166
791.476	158
793.809	160
796.142	160
798.476	164
800.807	168
803.138	160
805.468	152
807.797	168
810.125	168
812.453	172
814.78	170
817.106	142
819.432	178
821.757	150
824.08	168
826.403	160
828.726	146
831.048	162
833.368	160
835.688	164
838.007	182
840.326	150
842.644	166
844.96	174
847.276	174
849.592	152
851.906	158
854.221	168
856.534	162
858.846	156
861.157	162
863.469	174
865.779	170
868.088	160
870.396	164
872.704	162
875.011	164
877.318	158
879.623	158
881.928	162
884.232	160
886.536	148
888.837	152
891.139	154
893.44	152
895.741	162
898.039	158
900.339	176
902.637	170
904.933	152
907.231	170
909.526	152
911.821	140
914.115	160
916.408	154
918.701	152
920.993	150
923.283	152
925.573	170
927.864	162
930.153	162
932.441	166
934.728	166
937.014	154
939.3	144
941.585	164
943.87	158
946.154	154
948.437	154
950.719	160
952.999	172
955.28	162
957.56	150
959.84	150
962.117	154
964.395	156
966.671	144
968.948	144
971.223	154
973.498	148
975.771	168
978.045	134
980.317	138
982.588	166
984.86	144
987.13	142
989.399	142
991.667	150
993.937	150
996.204	148
998.47	148
1000.74	158
1003	142
1005.26	178
1007.53	156
1009.79	164
1012.05	152
1014.31	136
1016.57	144
1018.83	162
1021.09	140
1023.35	156
1025.61	156
1027.87	150
1030.12	146
1032.38	150
1034.63	136
1036.88	156
1039.14	160
1041.39	154
1043.64	160
1045.89	142
1048.14	148
1050.39	142
1052.64	148
1054.89	144
1057.14	154
1059.38	144
1061.63	150
1063.87	162
1066.12	154
1068.36	164
1070.6	152
1072.85	170
1075.09	148
1077.33	146
1079.57	146
1081.81	166
1084.05	156
1086.28	158
1088.52	140
1090.76	148
1092.99	146
1095.23	156
1097.46	154
1099.69	152
1101.93	164
1104.16	150
1106.39	152
1108.62	148
1110.85	138
1113.08	146
1115.31	150
1117.53	144
1119.76	154
1121.99	136
1124.21	144
1126.44	148
1128.66	146
1130.88	144
1133.11	140
1135.33	136
1137.55	150
1139.77	154
1141.99	152
1144.21	132
1146.43	140
1148.64	154
1150.86	144
1153.08	144
1155.29	148
1157.51	146
1159.72	144
1161.93	146
1164.14	152
1166.36	154
1168.57	140
1170.78	146
1172.99	136
1175.2	150
1177.4	146
1179.61	146
1181.82	144
1184.02	148
1186.23	146
1188.43	136
1190.64	138
1192.84	132
1195.04	156
1197.24	138
1199.45	143.99
1201.64	135.999
1203.84	133.978
1206.04	128.555
1208.24	135.586
1210.44	131.346
1212.64	138.185
1214.83	139.082
1217.03	131.903
1219.22	142.15
1221.41	136.101
1223.61	137.996
1225.8	131.431
1227.99	131.567
1230.18	127.789
1232.37	125.39
1234.56	140.727
1236.75	137.24
1238.94	128.217
1241.13	139.552
1243.31	136.952
1245.5	139.192
1247.68	135.927
1249.87	138.282
1252.05	139.443
1254.24	131.192
1256.42	132.055
1258.6	131.709
1260.78	131.87
1262.96	133.649
1265.14	135.936
1267.32	138.75
1269.5	137.191
1271.67	136.68
1273.85	136.207
1276.03	136.014
1278.2	131.616
1280.38	125.163
1282.55	133.357
1284.72	133.515
1286.9	129.728
1289.07	127.791
1291.24	130.125
1293.41	138.432
1295.58	135.312
1297.75	121.576
1299.92	134.29
1302.09	126.821
1304.25	126.474
1306.42	128.024
1308.46	130
1310.63	146
1312.81	128
1314.98	130
1317.16	140
1319.33	130
1321.5	122
1323.67	140
1325.85	136
1328.02	128
1330.19	140
1332.35	128
1334.52	140
1336.69	120
1338.86	130
1341.02	122
1343.19	126
1345.35	130
1347.52	130
1349.68	142
1351.84	128
1354	124
1356.17	120
1358.33	124
1360.49	122
1362.65	130
1364.8	112
1366.96	120
1369.12	116
1371.28	128
1373.43	128
1375.59	134
1377.74	120
1379.89	126
1382.05	136
1384.2	120
1386.35	140
1388.5	122
1390.65	136
1392.8	132
1394.95	120
1397.1	128
1399.25	134
1401.4	124
1403.54	110
1405.69	136
1407.83	122
1409.98	122
1412.12	126
1414.26	118
1416.4	114
1418.55	130
1420.69	132
1422.83	116
1424.97	110
1427.1	120
1429.24	122
1431.38	126
1433.52	130
1435.65	124
1437.79	138
1439.92	126
1442.06	106
1444.19	134
1446.32	124
1448.46	124
1450.59	124
1452.72	126
1454.85	122
1456.98	114
1459.11	124
1461.23	130
1463.36	128
1465.49	124
1467.61	126
1469.74	128
1471.86	126
1473.99	130
1476.11	108
1478.23	124
1480.36	116
1482.48	116
1484.6	124
1486.72	118
1488.84	118
1490.96	122
1493.07	126
1495.19	132
1497.31	104
1499.42	114
1501.54	122
1503.65	118
1505.77	124
1507.88	122
1509.99	104
1512.1	110
1514.22	106
1516.33	120
1518.44	116
1520.55	118
1522.65	114
1524.76	110
1526.87	118
1528.98	126
1531.08	106
1533.19	116
1535.29	118
1537.4	114
1539.5	124
1541.6	104
1543.7	112
1545.8	116
1547.91	104
1550.01	112
1552.11	116
1554.2	112
1556.3	126
1558.4	112
1560.5	104
1562.59	116
1564.69	118
1566.78	96
1568.88	122
1570.97	116
1573.06	120
1575.15	118
1577.25	106
1579.34	106
1581.43	114
1583.52	124
1585.6	106
1587.69	118
1589.78	112
1591.87	106
1593.95	124
1596.04	114
1598.12	116
1600.21	118
1602.29	112
1604.37	106
1606.46	110
1608.54	100
1610.62	126
1612.7	110
1614.78	104
1616.86	114
1618.94	100
1621.01	112
1623.09	94
1625.17	116
1627.24	106
1629.32	122
1631.39	112
1633.47	108
1635.54	120
1637.61	112
1639.68	116
1641.76	116
1643.83	104
1645.9	110
1647.96	110
1650.03	112
1652.1	114
1654.17	116
1656.24	114
1658.3	110
1660.37	96
1662.43	118
1664.5	96
1666.56	112
1668.62	104
1670.68	98
1672.75	102
1674.81	114
1676.87	102
1678.93	102
1680.99	106
1683.04	104
1685.1	106
1687.16	112
1689.21	106
1691.27	110
1693.33	102
1695.38	106
1697.43	110
1699.49	114
1701.54	100
1703.59	106
1705.64	106
1707.69	100
1709.74	98
1711.79	114
1713.84	108
1715.89	96
1717.94	102
1719.98	100
1722.03	100
1724.07	98
1726.12	94
1728.16	100
1730.21	90
1732.25	106
1734.29	86
1736.33	96
1738.37	94
1740.41	102
1742.45	90
1744.49	98
1746.53	96
1748.57	112
1750.61	94
1752.64	100
1754.68	100
1756.71	92
1758.75	98
1760.78	108
1762.82	110
1764.85	92
1766.88	102
1768.91	110
1770.94	106
1772.97	110
1775	108
1777.03	100
1779.06	114
1781.09	100
1783.12	94
1785.14	94
1787.17	88
1789.19	92
1791.22	102
1793.24	100
1795.27	92
1797.29	102
1799.31	102
1801.33	96
1803.35	106
1805.37	106
1807.39	90
1809.41	88
1811.43	98
1813.45	92
1815.46	92
1817.48	92
1819.5	100
1821.51	102
1823.53	90
1825.54	90
1827.55	92
1829.57	100
1831.58	86
1833.59	106
1835.6	96
1837.61	104
1839.62	96
1841.63	102
1843.64	96
1845.65	102
1847.65	88
1849.66	84
1851.66	100
1853.67	82
1855.67	98
1857.68	96
1859.68	94
1861.68	88
1863.69	86
1865.69	88
1867.69	90
1869.69	100
1871.69	92
1873.69	98
1875.69	94
1877.68	86
1879.68	90
1881.68	96
1883.67	92
1885.67	80
1887.66	80
1889.66	92
1891.65	88
1893.64	88
1895.64	86
1897.63	86
1899.62	98
1901.61	86
1903.6	90
1905.59	100
1907.58	84
1909.56	94
1911.55	92
1913.54	84
1915.53	86
1917.51	100
1919.5	88
1921.48	96
1923.46	86
1925.45	84
1927.43	100
1929.41	76
1931.39	92
1933.37	80
1935.35	90
1937.33	76
1939.31	88
1941.29	82
1943.27	84
1945.24	88
1947.22	80
1949.2	92
1951.17	90
1953.14	88
1955.12	86
1957.09	86
1959.06	98
1961.04	94
1963.01	92
1964.98	80
1966.95	88
1968.92	80
1970.89	72
1972.86	92
1974.82	86
1976.79	74
1978.76	76
1980.72	82
1982.69	86
1984.65	96
1986.62	72
1988.58	74
1990.54	88
1992.51	90
1994.47	74
1996.43	78
1998.39	94
1999.37	84