File: muestras/coffe_mate/Organic_03.txt
#Acq. time (s)=	10
#Accumulations=	1
#Range (cm-¹)=	100...2000
#Windows=	2
#Autofocus=	Off
#AutoExposure=	Off
#Spike filter=	Off
#Delay time (s)=	0
#Binning=	1
#Readout mode=	Signal
#DeNoise=	Off
#ICS correction=	Off
#Dark correction=	Off
#Inst. Process=	Off
#Instrument=	LabRAM HR Evol
#Detector=	Syncerity OE
#Objective=	x100_VIS
#Grating=	600 (500nm)
#ND Filter=	25%
#Laser=	633nm_Edge
#Hole=	24.99
#Range=	Visible
#Project=	Omar
#Sample=	20-06-23
#Site=	2
#Title=	Organic
#Remark=
#Date=	20.06.2023 11:52
#Acquired=	20.06.2023 11:52:10
101.054	44
103.621	54
106.187	56
108.752	50
111.317	60
113.881	38
116.443	48
119.005	64
121.566	48
124.126	44
126.685	50
129.243	52
131.801	50
134.356	42
136.911	48
139.466	52
142.021	56
144.574	52
147.125	62
149.676	54
152.227	56
154.776	50
157.325	52
159.873	48
162.419	46
164.966	54
167.51	48
170.055	46
172.598	46
175.141	50
177.682	54
180.222	48
182.763	52
185.302	48
187.839	52
190.376	46
192.914	54
195.449	44
197.983	40
200.517	50
203.05	46
205.582	60
208.113	54
210.643	54
213.173	48
215.701	56
218.229	50
220.756	50
223.282	48
225.808	50
228.331	56
230.855	52
233.378	56
235.898	54
238.419	54
240.94	62
243.458	50
245.977	42
248.495	56
251.011	48
253.527	62
256.041	46
258.555	40
261.068	46
263.58	48
266.092	58
268.603	54
271.112	46
273.62	52
276.129	58
278.636	48
281.142	52
283.647	52
286.152	50
288.655	54
291.158	44
293.66	52
296.161	52
298.661	60
301.161	50
303.66	58
306.158	48
308.655	56
311.15	56
313.645	56
316.14	48
318.634	58
321.125	44
323.618	56
326.109	54
328.598	62
331.088	50
333.576	52
336.064	60
338.55	60
341.037	54
343.521	52
346.005	54
348.489	54
350.971	56
353.453	54
355.933	46
358.414	46
360.893	58
363.371	60
365.848	54
368.325	56
370.801	58
373.275	60
375.75	56
378.223	62
380.695	50
383.167	62
385.638	42
388.108	60
390.577	52
393.044	56
395.512	56
397.979	56
400.444	56
402.909	50
405.374	54
407.836	58
410.299	56
412.76	48
415.221	56
417.681	58
420.141	52
422.598	42
425.057	54
427.513	60
429.968	60
432.422	54
434.878	52
437.33	54
439.783	56
442.234	56
444.685	46
447.134	58
449.583	56
452.032	50
454.479	46
456.926	54
459.372	42
461.817	58
464.261	56
466.705	52
469.147	54
471.588	50
474.029	46
476.47	60
478.909	56
481.347	52
483.785	50
486.221	50
488.657	52
491.092	58
493.527	54
495.96	50
498.393	62
500.824	46
503.255	66
505.686	54
508.115	52
510.543	66
512.972	56
515.399	52
517.825	46
520.25	60
522.674	46
525.097	42
527.52	54
529.942	52
532.364	50
534.784	54
537.204	60
539.623	50
542.041	62
544.457	46
546.874	48
549.289	50
551.705	54
554.118	60
556.531	56
558.943	64
561.355	54
563.766	62
566.175	56
568.585	60
570.992	52
573.399	54
575.807	48
578.212	62
580.617	52
583.022	54
585.425	62
587.827	54
590.229	58
592.63	54
595.03	60
597.43	62
599.829	62
602.226	44
604.623	52
607.02	56
609.414	50
611.808	52
614.202	50
616.596	54
618.988	58
621.378	48
623.769	56
626.159	44
628.548	52
630.936	54
633.324	56
635.71	50
638.096	56
640.481	50
642.866	70
645.248	50
647.63	60
650.013	52
652.394	54
654.773	64
657.154	58
659.532	62
661.91	54
664.286	58
666.663	52
669.038	58
671.412	60
673.786	50
676.159	56
678.532	52
680.903	54
683.274	62
685.644	48
688.014	52
690.381	50
692.749	62
695.116	56
697.481	52
699.846	50
702.211	60
704.574	54
706.938	48
709.299	52
711.661	56
714.021	52
716.381	50
718.739	58
721.097	58
723.455	56
725.811	60
728.167	62
730.521	56
732.875	62
735.23	56
737.582	60
739.934	62
742.285	62
744.635	50
746.985	54
749.332	64
751.68	58
754.028	48
756.374	46
758.72	50
761.065	46
763.408	66
765.752	52
768.095	58
770.436	58
772.777	50
775.116	46
777.456	62
779.794	52
782.133	56
784.469	58
786.805	50
789.141	64
791.476	48
793.809	46
796.142	48
798.476	46
800.807	50
803.138	64
805.468	54
807.797	54
810.125	56
812.453	62
814.78	60
817.106	44
819.432	56
821.757	58
824.08	58
826.403	48
828.726	56
831.048	52
833.368	44
835.688	50
838.007	50
840.326	54
842.644	56
844.96	52
847.276	52
849.592	46
851.906	52
854.221	54
856.534	58
858.846	48
861.157	56
863.469	50
865.779	50
868.088	52
870.396	46
872.704	58
875.011	46
877.318	60
879.623	40
881.928	46
884.232	52
886.536	56
888.837	50
891.139	48
893.44	42
895.741	50
898.039	54
900.339	58
902.637	58
904.933	52
907.231	54
909.526	48
911.821	56
914.115	58
916.408	58
918.701	46
920.993	50
923.283	58
925.573	52
927.864	44
930.153	46
932.441	58
934.728	46
937.014	48
939.3	54
941.585	54
943.87	46
946.154	60
948.437	56
950.719	60
952.999	52
955.28	48
957.56	56
959.84	50
962.117	50
964.395	50
966.671	48
968.948	54
971.223	42
973.498	54
975.771	58
978.045	54
980.317	56
982.588	50
984.86	52
987.13	44
989.399	54
991.667	54
993.937	44
996.204	52
998.47	48
1000.74	58
1003	54
1005.26	48
1007.53	52
1009.79	48
1012.05	44
1014.31	62
1016.57	60
1018.83	54
1021.09	58
1023.35	54
1025.61	50
1027.87	52
1030.12	62
1032.38	54
1034.63	50
1036.88	54
1039.14	48
1041.39	44
1043.64	50
1045.89	56
1048.14	50
1050.39	64
1052.64	56
1054.89	56
1057.14	54
1059.38	52
1061.63	62
1063.87	58
1066.12	52
1068.36	56
1070.6	54
1072.85	52
1075.09	52
1077.33	46
1079.57	50
1081.81	54
1084.05	52
1086.28	60
1088.52	48
1090.76	54
1092.99	54
1095.23	60
1097.46	54
1099.69	52
1101.93	48
1104.16	52
1106.39	58
1108.62	48
1110.85	46
1113.08	44
1115.31	52
1117.53	58
1119.76	40
1121.99	44
1124.21	46
1126.44	46
1128.66	42
1130.88	52
1133.11	56
1135.33	40
1137.55	54
1139.77	50
1141.99	44
1144.21	56
1146.43	48
1148.64	50
1150.86	56
1153.08	46
1155.29	52
1157.51	46
1159.72	52
1161.93	46
1164.14	52
1166.36	46
1168.57	48
1170.78	46
1172.99	60
1175.2	48
1177.4	46
1179.61	46
1181.82	46
1184.02	52
1186.23	52
1188.43	48
1190.64	54
1192.84	52
1195.04	54
1197.24	46
1199.45	47.95
1201.64	48
1203.84	54.0242
1206.04	47.5195
1208.24	51.3937
1210.44	49.4394
1212.64	45.0892
1214.83	48.043
1217.03	43.5145
1219.22	45.438
1221.41	38.2514
1223.61	47.7734
1225.8	51.9902
1227.99	45.7247
1230.18	43.9665
1232.37	47.6081
1234.56	38.6
1236.75	46.6939
1238.94	42.7222
1241.13	42.46
1243.31	44.9057
1245.5	46.4652
1247.68	45.33
1249.87	45.442
1252.05	46.3656
1254.24	44.3076
1256.42	48.479
1258.6	44.2709
1260.78	44.118
1262.96	47.2279
1265.14	44
1267.32	48.356
1269.5	44.6603
1271.67	45.7164
1273.85	46.3928
1276.03	43.0363
1278.2	45.6842
1280.38	47.1232
1282.55	51.6292
1284.72	45.7199
1286.9	41.17
1289.07	44.3599
1291.24	44.93
1293.41	42.916
1295.58	47.755
1297.75	45.3612
1299.92	51.2704
1302.09	42.1518
1304.25	44.3337
1306.42	43.373
1308.46	46
1310.63	42
1312.81	44
1314.98	46
1317.16	46
1319.33	36
1321.5	46
1323.67	42
1325.85	46
1328.02	44
1330.19	48
1332.35	44
1334.52	50
1336.69	36
1338.86	40
1341.02	44
1343.19	46
1345.35	48
1347.52	38
1349.68	36
1351.84	48
1354	44
1356.17	50
1358.33	54
1360.49	36
1362.65	46
1364.8	50
1366.96	42
1369.12	54
1371.28	44
1373.43	44
1375.59	40
1377.74	44
1379.89	40
1382.05	38
1384.2	54
1386.35	48
1388.5	40
1390.65	42
1392.8	46
1394.95	42
1397.1	52
1399.25	48
1401.4	44
1403.54	38
1405.69	44
1407.83	40
1409.98	44
1412.12	44
1414.26	42
1416.4	36
1418.55	48
1420.69	48
1422.83	42
1424.97	34
1427.1	46
1429.24	42
1431.38	32
1433.52	40
1435.65	44
1437.79	46
1439.92	34
1442.06	52
1444.19	46
1446.32	38
1448.46	40
1450.59	46
1452.72	46
1454.85	48
1456.98	38
1459.11	44
1461.23	44
1463.36	46
1465.49	42
1467.61	48
1469.74	50
1471.86	42
1473.99	46
1476.11	44
1478.23	40
1480.36	48
1482.48	48
1484.6	50
1486.72	46
1488.84	44
1490.96	44
1493.07	50
1495.19	44
1497.31	38
1499.42	40
1501.54	46
1503.65	46
1505.77	38
1507.88	46
1509.99	38
1512.1	38
1514.22	42
1516.33	46
1518.44	44
1520.55	48
1522.65	44
1524.76	46
1526.87	46
1528.98	42
1531.08	44
1533.19	46
1535.29	40
1537.4	46
1539.5	40
1541.6	42
1543.7	50
1545.8	48
1547.91	46
1550.01	48
1552.11	42
1554.2	42
1556.3	52
1558.4	54
1560.5	44
1562.59	42
1564.69	36
1566.78	36
1568.88	48
1570.97	40
1573.06	50
1575.15	50
1577.25	36
1579.34	42
1581.43	44
1583.52	36
1585.6	44
1587.69	38
1589.78	44
1591.87	42
1593.95	42
1596.04	44
1598.12	38
1600.21	52
1602.29	34
1604.37	42
1606.46	34
1608.54	42
1610.62	52
1612.7	38
1614.78	54
1616.86	44
1618.94	42
1621.01	46
1623.09	46
1625.17	42
1627.24	34
1629.32	46
1631.39	44
1633.47	42
1635.54	44
1637.61	44
1639.68	44
1641.76	48
1643.83	46
1645.9	44
1647.96	48
1650.03	54
1652.1	50
1654.17	40
1656.24	44
1658.3	46
1660.37	48
1662.43	38
1664.5	40
1666.56	44
1668.62	42
1670.68	48
1672.75	36
1674.81	40
1676.87	46
1678.93	46
1680.99	46
1683.04	42
1685.1	40
1687.16	44
1689.21	52
1691.27	44
1693.33	40
1695.38	44
1697.43	46
1699.49	42
1701.54	50
1703.59	40
1705.64	40
1707.69	38
1709.74	46
1711.79	32
1713.84	42
1715.89	42
1717.94	40
1719.98	44
1722.03	52
1724.07	44
1726.12	38
1728.16	38
1730.21	48
1732.25	48
1734.29	42
1736.33	42
1738.37	40
1740.41	44
1742.45	1270
1744.49	44
1746.53	44
1748.57	36
1750.61	40
1752.64	46
1754.68	40
1756.71	48
1758.75	36
1760.78	38
1762.82	48
1764.85	36
1766.88	36
1768.91	50
1770.94	34
1772.97	38
1775	48
1777.03	44
1779.06	42
1781.09	44
1783.12	42
1785.14	40
1787.17	40
1789.19	42
1791.22	40
1793.24	48
1795.27	46
1797.29	30
1799.31	42
1801.33	44
1803.35	34
1805.37	44
1807.39	36
1809.41	52
1811.43	50
1813.45	46
1815.46	42
1817.48	34
1819.5	44
1821.51	38
1823.53	36
1825.54	46
1827.55	44
1829.57	44
1831.58	44
1833.59	42
1835.6	48
1837.61	42
1839.62	42
1841.63	40
1843.64	46
1845.65	44
1847.65	40
1849.66	46
1851.66	50
1853.67	38
1855.67	32
1857.68	36
1859.68	50
1861.68	42
1863.69	42
1865.69	42
1867.69	44
1869.69	42
1871.69	44
1873.69	42
1875.69	34
1877.68	42
1879.68	32
1881.68	38
1883.67	48
1885.67	36
1887.66	48
1889.66	44
1891.65	38
1893.64	46
1895.64	38
1897.63	34
1899.62	34
1901.61	40
1903.6	38
1905.59	38
1907.58	46
1909.56	34
1911.55	40
1913.54	38
1915.53	38
1917.51	42
1919.5	38
1921.48	38
1923.46	38
1925.45	44
1927.43	34
1929.41	36
1931.39	44
1933.37	38
1935.35	32
1937.33	48
1939.31	42
1941.29	40
1943.27	38
1945.24	42
1947.22	40
1949.2	40
1951.17	40
1953.14	36
1955.12	40
1957.09	36
1959.06	40
1961.04	46
1963.01	44
1964.98	32
1966.95	36
1968.92	34
1970.89	48
1972.86	38
1974.82	38
1976.79	32
1978.76	46
1980.72	36
1982.69	44
1984.65	36
1986.62	38
1988.58	34
1990.54	42
1992.51	48
1994.47	42
1996.43	30
1998.39	32
1999.37	36