File: muestras/coffe_mate/Organic_16.txt
#Acq. time (s)=	15
#Accumulations=	1
#Range (cm-¹)=	100...2000
#Windows=	2
#Autofocus=	Off
#AutoExposure=	Off
#Spike filter=	Off
#Delay time (s)=	0
#Binning=	1
#Readout mode=	Signal
#DeNoise=	Off
#ICS correction=	Off
#Dark correction=	Off
#Inst. Process=	Off
#Instrument=	LabRAM HR Evol
#Detector=	Syncerity OE
#Objective=	x100_VIS
#Grating=	600 (500nm)
#ND Filter=	100%
#Laser=	633nm_Edge
#Hole=	100.021
#Range=	Visible
#Project=	Omar
#Sample=	20-06-23
#Site=	2
#Title=	Organic
#Remark=
#Date=	20.06.2023 12:10
#Acquired=	20.06.2023 12:10:13
101.054	64535
103.621	64535
106.187	64535
108.752	64535
111.317	64535
113.881	64535
116.443	64535
119.005	64535
121.566	64535
124.126	64535
126.685	64535
129.243	64535
131.801	64535
134.356	64535
136.911	64535
139.466	64535
142.021	64535
144.574	64535
147.125	64535
149.676	64535
152.227	64535
154.776	64535
157.325	64535
159.873	64535
162.419	64535
164.966	64535
167.51	64535
170.055	64535
172.598	64535
175.141	64535
177.682	64535
180.222	64535
182.763	64535
185.302	64535
187.839	64535
190.376	64535
192.914	64535
195.449	64535
197.983	64535
200.517	64535
203.05	64535
205.582	64535
208.113	64535
210.643	64535
213.173	64535
215.701	64535
218.229	64535
220.756	64535
223.282	64535
225.808	64535
228.331	64535
230.855	64535
233.378	64535
235.898	64535
238.419	64535
240.94	64535
243.458	64535
245.977	64535
248.495	64535
251.011	64535
253.527	64535
256.041	64535
258.555	64535
261.068	64535
263.58	64535
266.092	64535
268.603	64535
271.112	64535
273.62	64535
276.129	64535
278.636	64535
281.142	64535
283.647	64535
286.152	64535
288.655	64535
291.158	64535
293.66	64535
296.161	64535
298.661	64535
301.161	64535
303.66	64535
306.158	64535
308.655	64535
311.15	64535
313.645	64535
316.14	64535
318.634	64535
321.125	64535
323.618	64535
326.109	64535
328.598	64535
331.088	64535
333.576	64535
336.064	64535
338.55	64535
341.037	64535
343.521	64535
346.005	64535
348.489	64535
350.971	64535
353.453	64535
355.933	64535
358.414	64535
360.893	64535
363.371	64535
365.848	64535
368.325	64535
370.801	64535
373.275	64535
375.75	64535
378.223	64535
380.695	64535
383.167	64535
385.638	64535
388.108	64535
390.577	64535
393.044	64535
395.512	64535
397.979	64535
400.444	64535
402.909	64535
405.374	64535
407.836	64535
410.299	64535
412.76	64535
415.221	64535
417.681	64535
420.141	64535
422.598	64535
425.057	64535
427.513	64535
429.968	64535
432.422	64535
434.878	64535
437.33	64535
439.783	64535
442.234	64535
444.685	64535
447.134	64535
449.583	64535
452.032	64535
454.479	64535
456.926	64535
459.372	64535
461.817	64535
464.261	64535
466.705	64535
469.147	64535
471.588	64535
474.029	64535
476.47	64535
478.909	64535
481.347	64535
483.785	64535
486.221	64535
488.657	64535
491.092	64535
493.527	64535
495.96	64535
498.393	64535
500.824	64535
503.255	64535
505.686	64535
508.115	64535
510.543	64535
512.972	64535
515.399	64535
517.825	64535
520.25	64535
522.674	64535
525.097	64535
527.52	64535
529.942	64535
532.364	64535
534.784	64535
537.204	64535
539.623	64535
542.041	64535
544.457	64535
546.874	64535
549.289	64535
551.705	64535
554.118	64535
556.531	64535
558.943	64535
561.355	64535
563.766	64535
566.175	64535
568.585	64535
570.992	64535
573.399	64535
575.807	64535
578.212	64535
580.617	64535
583.022	64535
585.425	64535
587.827	64535
590.229	64535
592.63	64535
595.03	64535
597.43	64535
599.829	64535
602.226	64535
604.623	64535
607.02	64535
609.414	64535
611.808	64535
614.202	64535
616.596	64535
618.988	64535
621.378	64535
623.769	64535
626.159	64535
628.548	64535
630.936	64535
633.324	64535
635.71	64535
638.096	64535
640.481	64535
642.866	64535
645.248	64535
647.63	64535
650.013	64535
652.394	64535
654.773	64535
657.154	64535
659.532	64535
661.91	64535
664.286	64535
666.663	64535
669.038	64535
671.412	64535
673.786	64535
676.159	64535
678.532	64535
680.903	64535
683.274	64535
685.644	64535
688.014	64535
690.381	64535
692.749	64535
695.116	64535
697.481	64535
699.846	64535
702.211	64535
704.574	64535
706.938	64535
709.299	64535
711.661	64535
714.021	64535
716.381	64535
718.739	64535
721.097	64535
723.455	64535
725.811	64535
728.167	64535
730.521	64535
732.875	64535
735.23	64535
737.582	64535
739.934	64535
742.285	64535
744.635	64535
746.985	64535
749.332	64535
751.68	64535
754.028	64535
756.374	64535
758.72	64535
761.065	64535
763.408	64535
765.752	64535
768.095	64535
770.436	64535
772.777	64535
775.116	64535
777.456	64535
779.794	64535
782.133	64535
784.469	64535
786.805	64535
789.141	64535
791.476	64535
793.809	64535
796.142	64535
798.476	64535
800.807	64535
803.138	64535
805.468	64535
807.797	64535
810.125	64535
812.453	64535
814.78	64535
817.106	64535
819.432	64535
821.757	64535
824.08	64535
826.403	64535
828.726	64535
831.048	64535
833.368	64535
835.688	64535
838.007	64535
840.326	64535
842.644	64535
844.96	64535
847.276	64535
849.592	64535
851.906	64535
854.221	64535
856.534	64535
858.846	64535
861.157	64535
863.469	64535
865.779	64535
868.088	64535
870.396	64535
872.704	64535
875.011	64535
877.318	64535
879.623	64535
881.928	64535
884.232	64535
886.536	64535
888.837	64535
891.139	64535
893.44	64535
895.741	64535
898.039	64535
900.339	64535
902.637	64535
904.933	64535
907.231	64535
909.526	64535
911.821	64535
914.115	64535
916.408	64535
918.701	64535
920.993	64535
923.283	64535
925.573	64535
927.864	64535
930.153	64535
932.441	64535
934.728	64535
937.014	64535
939.3	64535
941.585	64535
943.87	64535
946.154	64535
948.437	64535
950.719	64535
952.999	64535
955.28	64535
957.56	64535
959.84	64535
962.117	64535
964.395	64535
966.671	64535
968.948	64535
971.223	64535
973.498	64535
975.771	64535
978.045	64535
980.317	64535
982.588	64535
984.86	64535
987.13	64535
989.399	64535
991.667	64535
993.937	64535
996.204	64535
998.47	64535
1000.74	64535
1003	64535
1005.26	64535
1007.53	64535
1009.79	64535
1012.05	64535
1014.31	64535
1016.57	64535
1018.83	64535
1021.09	64535
1023.35	64535
1025.61	64535
1027.87	64535
1030.12	64535
1032.38	64535
1034.63	64535
1036.88	64535
1039.14	64535
1041.39	64535
1043.64	64535
1045.89	64535
1048.14	64535
1050.39	64535
1052.64	64535
1054.89	64535
1057.14	64535
1059.38	64535
1061.63	64535
1063.87	64535
1066.12	64535
1068.36	64535
1070.6	64535
1072.85	64535
1075.09	64535
1077.33	64535
1079.57	64535
1081.81	64535
1084.05	64535
1086.28	64535
1088.52	64535
1090.76	64535
1092.99	64535
1095.23	64535
1097.46	64535
1099.69	64535
1101.93	64535
1104.16	64535
1106.39	64535
1108.62	64535
1110.85	64535
1113.08	64535
1115.31	64535
1117.53	64535
1119.76	64535
1121.99	64535
1124.21	64535
1126.44	64535
1128.66	64535
1130.88	64535
1133.11	64535
1135.33	64535
1137.55	64535
1139.77	64535
1141.99	64535
1144.21	64535
1146.43	64535
1148.64	64535
1150.86	64535
1153.08	64535
1155.29	64535
1157.51	64535
1159.72	64535
1161.93	64535
1164.14	64535
1166.36	64535
1168.57	64535
1170.78	64535
1172.99	64535
1175.2	64535
1177.4	64535
1179.61	64535
1181.82	64535
1184.02	64535
1186.23	64535
1188.43	64535
1190.64	64535
1192.84	64296
1195.04	64218
1197.24	64124
1199.45	64222
1201.64	63773.8
1203.84	63339.3
1206.04	62813.7
1208.24	62207.1
1210.44	62223.8
1212.64	61690.1
1214.83	61473
1217.03	60705.5
1219.22	60803.5
1221.41	60358.6
1223.61	59907.2
1225.8	59450.1
1227.99	59261
1230.18	59077.5
1232.37	58595.4
1234.56	58397.8
1236.75	57893.3
1238.94	57871.3
1241.13	57232.6
1243.31	57387.9
1245.5	56947
1247.68	56519.8
1249.87	56434.9
1252.05	56159.1
1254.24	56038.4
1256.42	55619.7
1258.6	55459.2
1260.78	55161.7
1262.96	54804.2
1265.14	54572.5
1267.32	54302.4
1269.5	54046.7
1271.67	53780.1
1273.85	53697.6
1276.03	53232.4
1278.2	52969.3
1280.38	52738.6
1282.55	52516.3
1284.72	52139.6
1286.9	51863.1
1289.07	51445.6
1291.24	51223.3
1293.41	50896.9
1295.58	50616.7
1297.75	50257.7
1299.92	49982.6
1302.09	49758.9
1304.25	49295.1
1306.42	49164.2
1308.46	48604
1310.63	48554
1312.81	48730
1314.98	48690
1317.16	48510
1319.33	48642
1321.5	48404
1323.67	48358
1325.85	48290
1328.02	48122
1330.19	47982
1332.35	48368
1334.52	48222
1336.69	47884
1338.86	48078
1341.02	47754
1343.19	47724
1345.35	47672
1347.52	47546
1349.68	47656
1351.84	47564
1354	47506
1356.17	47464
1358.33	47592
1360.49	47492
1362.65	47404
1364.8	47550
1366.96	47242
1369.12	47306
1371.28	47306
1373.43	46994
1375.59	47390
1377.74	46818
1379.89	47038
1382.05	47114
1384.2	47318
1386.35	47072
1388.5	46962
1390.65	46706
1392.8	46852
1394.95	46728
1397.1	46546
1399.25	46636
1401.4	46628
1403.54	46706
1405.69	46412
1407.83	46554
1409.98	46640
1412.12	46376
1414.26	46242
1416.4	46196
1418.55	45780
1420.69	46028
1422.83	46034
1424.97	46028
1427.1	45720
1429.24	45842
1431.38	45696
1433.52	45694
1435.65	45426
1437.79	45392
1439.92	45490
1442.06	45514
1444.19	45510
1446.32	45578
1448.46	45500
1450.59	45230
1452.72	45366
1454.85	45528
1456.98	45338
1459.11	44982
1461.23	45124
1463.36	45114
1465.49	44952
1467.61	45186
1469.74	45098
1471.86	44866
1473.99	44956
1476.11	44700
1478.23	44490
1480.36	44684
1482.48	44488
1484.6	44486
1486.72	44564
1488.84	44198
1490.96	44430
1493.07	44256
1495.19	43930
1497.31	44274
1499.42	43878
1501.54	43900
1503.65	43672
1505.77	43628
1507.88	43752
1509.99	43414
1512.1	43312
1514.22	43262
1516.33	43040
1518.44	43268
1520.55	43008
1522.65	42838
1524.76	42688
1526.87	42708
1528.98	42570
1531.08	42402
1533.19	42356
1535.29	42170
1537.4	41898
1539.5	41954
1541.6	41498
1543.7	41852
1545.8	41580
1547.91	41700
1550.01	41352
1552.11	41320
1554.2	41236
1556.3	41318
1558.4	40706
1560.5	40928
1562.59	40808
1564.69	40876
1566.78	40528
1568.88	40338
1570.97	40506
1573.06	40686
1575.15	40514
1577.25	40106
1579.34	40328
1581.43	39990
1583.52	40264
1585.6	40286
1587.69	40234
1589.78	40146
1591.87	40144
1593.95	39878
1596.04	40036
1598.12	40044
1600.21	39930
1602.29	39876
1604.37	39802
1606.46	39818
1608.54	39310
1610.62	39722
1612.7	39474
1614.78	39432
1616.86	39544
1618.94	39446
1621.01	39360
1623.09	38880
1625.17	39062
1627.24	38980
1629.32	38852
1631.39	38744
1633.47	38460
1635.54	38642
1637.61	38572
1639.68	38380
1641.76	38516
1643.83	38102
1645.9	37988
1647.96	37736
1650.03	37716
1652.1	37880
1654.17	37734
1656.24	37648
1658.3	37528
1660.37	37250
1662.43	37120
1664.5	37368
1666.56	36984
1668.62	37072
1670.68	36758
1672.75	36826
1674.81	36494
1676.87	36456
1678.93	36536
1680.99	36284
1683.04	36206
1685.1	35840
1687.16	35980
1689.21	35764
1691.27	35656
1693.33	35840
1695.38	35628
1697.43	35224
1699.49	35308
1701.54	35066
1703.59	34990
1705.64	34886
1707.69	34922
1709.74	34728
1711.79	34768
1713.84	34830
1715.89	34386
1717.94	34268
1719.98	34272
1722.03	34188
1724.07	33894
1726.12	33760
1728.16	33816
1730.21	33616
1732.25	33640
1734.29	33478
1736.33	33556
1738.37	33088
1740.41	33336
1742.45	33064
1744.49	33182
1746.53	32976
1748.57	33012
1750.61	32730
1752.64	33022
1754.68	32594
1756.71	32748
1758.75	32566
1760.78	32432
1762.82	32382
1764.85	32558
1766.88	32364
1768.91	32418
1770.94	32262
1772.97	32190
1775	32068
1777.03	32116
1779.06	32084
1781.09	31572
1783.12	31562
1785.14	31746
1787.17	31588
1789.19	31624
1791.22	31546
1793.24	31514
1795.27	31396
1797.29	31218
1799.31	31176
1801.33	31060
1803.35	30914
1805.37	30664
1807.39	30656
1809.41	30504
1811.43	30526
1813.45	30378
1815.46	30296
1817.48	30264
1819.5	30140
1821.51	30086
1823.53	29984
1825.54	29738
1827.55	29508
1829.57	29514
1831.58	29566
1833.59	29106
1835.6	29124
1837.61	29332
1839.62	29332
1841.63	28882
1843.64	28696
1845.65	28486
1847.65	28790
1849.66	28264
1851.66	28448
1853.67	28204
1855.67	28300
1857.68	28154
1859.68	27942
1861.68	28002
1863.69	27798
1865.69	27826
1867.69	27466
1869.69	27640
1871.69	27418
1873.69	27480
1875.69	27400
1877.68	27172
1879.68	27226
1881.68	27084
1883.67	27000
1885.67	26806
1887.66	26622
1889.66	26876
1891.65	26726
1893.64	26718
1895.64	26614
1897.63	26400
1899.62	26600
1901.61	26402
1903.6	26232
1905.59	26438
1907.58	26094
1909.56	26080
1911.55	25832
1913.54	26032
1915.53	25914
1917.51	25884
1919.5	25678
1921.48	25614
1923.46	25650
1925.45	25424
1927.43	25666
1929.41	25442
1931.39	25420
1933.37	25240
1935.35	25138
1937.33	24956
1939.31	24982
1941.29	24954
1943.27	24806
1945.24	24894
1947.22	24546
1949.2	24544
1951.17	24424
1953.14	24330
1955.12	24312
1957.09	24118
1959.06	24108
1961.04	23968
1963.01	23996
1964.98	23726
1966.95	23798
1968.92	23510
1970.89	23368
1972.86	23482
1974.82	23536
1976.79	23420
1978.76	23150
1980.72	23198
1982.69	23140
1984.65	22988
1986.62	22862
1988.58	22926
1990.54	22884
1992.51	22640
1994.47	22588
1996.43	22448
1998.39	22704
1999.37	22338