File: muestras/coffe_mate/Organic_15.txt
#Acq. time (s)=	15
#Accumulations=	1
#Range (cm-¹)=	100...2000
#Windows=	2
#Autofocus=	Off
#AutoExposure=	Off
#Spike filter=	Off
#Delay time (s)=	0
#Binning=	1
#Readout mode=	Signal
#DeNoise=	Off
#ICS correction=	Off
#Dark correction=	Off
#Inst. Process=	Off
#Instrument=	LabRAM HR Evol
#Detector=	Syncerity OE
#Objective=	x100_VIS
#Grating=	600 (500nm)
#ND Filter=	100%
#Laser=	633nm_Edge
#Hole=	100.021
#Range=	Visible
#Project=	Omar
#Sample=	20-06-23
#Site=	2
#Title=	Organic
#Remark=
#Date=	20.06.2023 12:07
#Acquired=	20.06.2023 12:07:11
101.054	1090
103.621	1064
106.187	1084
108.752	1074
111.317	1094
113.881	1064
116.443	1066
119.005	1082
121.566	1054
124.126	1066
126.685	1082
129.243	1038
131.801	1066
134.356	1088
136.911	1092
139.466	1092
142.021	1076
144.574	1114
147.125	1092
149.676	1104
152.227	1112
154.776	1072
157.325	1072
159.873	1052
162.419	1078
164.966	1056
167.51	1072
170.055	1036
172.598	1048
175.141	1112
177.682	1052
180.222	1074
182.763	1056
185.302	1080
187.839	1030
190.376	1072
192.914	1056
195.449	1074
197.983	1120
200.517	1142
203.05	1070
205.582	1076
208.113	1108
210.643	1086
213.173	1084
215.701	1134
218.229	1156
220.756	1122
223.282	1130
225.808	1136
228.331	1126
230.855	1108
233.378	1126
235.898	1148
238.419	1146
240.94	1144
243.458	1162
245.977	1120
248.495	1078
251.011	1128
253.527	1128
256.041	1166
258.555	1106
261.068	1144
263.58	1140
266.092	1142
268.603	1150
271.112	1150
273.62	1122
276.129	1146
278.636	1076
281.142	1146
283.647	1116
286.152	1144
288.655	1150
291.158	1164
293.66	1090
296.161	1122
298.661	1156
301.161	1140
303.66	1148
306.158	1160
308.655	1146
311.15	1206
313.645	1198
316.14	1190
318.634	1174
321.125	1144
323.618	1158
326.109	1134
328.598	1190
331.088	1178
333.576	1146
336.064	1160
338.55	1152
341.037	1148
343.521	1168
346.005	1118
348.489	1154
350.971	1126
353.453	1170
355.933	1196
358.414	1204
360.893	1182
363.371	1162
365.848	1156
368.325	1148
370.801	1178
373.275	1180
375.75	1182
378.223	1190
380.695	1138
383.167	1128
385.638	1178
388.108	1148
390.577	1114
393.044	1156
395.512	1142
397.979	1154
400.444	1160
402.909	1140
405.374	1196
407.836	1182
410.299	1190
412.76	1200
415.221	1156
417.681	1186
420.141	1170
422.598	1178
425.057	1236
427.513	1228
429.968	1250
432.422	1226
434.878	1198
437.33	1262
439.783	1180
442.234	1204
444.685	1244
447.134	1184
449.583	1168
452.032	1158
454.479	1202
456.926	1194
459.372	1202
461.817	1190
464.261	1148
466.705	1162
469.147	1168
471.588	1202
474.029	1212
476.47	1288
478.909	1234
481.347	1236
483.785	1220
486.221	1222
488.657	1180
491.092	1252
493.527	1226
495.96	1242
498.393	1202
500.824	1222
503.255	1224
505.686	1194
508.115	1198
510.543	1222
512.972	1222
515.399	1192
517.825	1206
520.25	1220
522.674	1152
525.097	1156
527.52	1216
529.942	1186
532.364	1180
534.784	1202
537.204	1160
539.623	1214
542.041	1180
544.457	1196
546.874	1176
549.289	1176
551.705	1260
554.118	1178
556.531	1194
558.943	1184
561.355	1148
563.766	1168
566.175	1186
568.585	1166
570.992	1188
573.399	1170
575.807	1198
578.212	1150
580.617	1190
583.022	1162
585.425	1172
587.827	1170
590.229	1164
592.63	1152
595.03	1184
597.43	1170
599.829	1170
602.226	1172
604.623	1162
607.02	1158
609.414	1158
611.808	1174
614.202	1172
616.596	1168
618.988	1198
621.378	1206
623.769	1170
626.159	1196
628.548	1210
630.936	1174
633.324	1168
635.71	1200
638.096	1194
640.481	1206
642.866	1228
645.248	1148
647.63	1246
650.013	1218
652.394	1210
654.773	1218
657.154	1198
659.532	1190
661.91	1198
664.286	1198
666.663	1192
669.038	1158
671.412	1172
673.786	1164
676.159	1182
678.532	1160
680.903	1176
683.274	1162
685.644	1132
688.014	1168
690.381	1110
692.749	1154
695.116	1126
697.481	1160
699.846	1154
702.211	1182
704.574	1194
706.938	1148
709.299	1190
711.661	1162
714.021	1150
716.381	1160
718.739	1212
721.097	1174
723.455	1130
725.811	1132
728.167	1174
730.521	1174
732.875	1160
735.23	1144
737.582	1162
739.934	1186
742.285	1206
744.635	1138
746.985	1156
749.332	1106
751.68	1160
754.028	1172
756.374	1128
758.72	1150
761.065	1110
763.408	1118
765.752	1114
768.095	1136
770.436	1160
772.777	1144
775.116	1156
777.456	1098
779.794	1158
782.133	1114
784.469	1142
786.805	1160
789.141	1100
791.476	1126
793.809	1090
796.142	1126
798.476	1098
800.807	1130
803.138	1146
805.468	1096
807.797	1134
810.125	1148
812.453	1130
814.78	1128
817.106	1136
819.432	1106
821.757	1116
824.08	1090
826.403	1136
828.726	1088
831.048	1132
833.368	1114
835.688	1178
838.007	1148
840.326	1150
842.644	1160
844.96	1118
847.276	1180
849.592	1220
851.906	1128
854.221	1166
856.534	1152
858.846	1182
861.157	1168
863.469	1146
865.779	1150
868.088	1112
870.396	1156
872.704	1122
875.011	1168
877.318	1158
879.623	1118
881.928	1170
884.232	1134
886.536	1144
888.837	1102
891.139	1158
893.44	1104
895.741	1132
898.039	1130
900.339	1138
902.637	1112
904.933	1106
907.231	1090
909.526	1138
911.821	1104
914.115	1148
916.408	1114
918.701	1098
920.993	1086
923.283	1146
925.573	1086
927.864	1146
930.153	1100
932.441	1094
934.728	1132
937.014	1086
939.3	1076
941.585	1076
943.87	1080
946.154	1128
948.437	1104
950.719	1052
952.999	1076
955.28	1034
957.56	1130
959.84	1072
962.117	1038
964.395	1050
966.671	1066
968.948	1096
971.223	1086
973.498	1068
975.771	1088
978.045	1082
980.317	1104
982.588	1036
984.86	1020
987.13	1070
989.399	1046
991.667	1052
993.937	1084
996.204	1076
998.47	1050
1000.74	1044
1003	1086
1005.26	1054
1007.53	1116
1009.79	1066
1012.05	1060
1014.31	1060
1016.57	1070
1018.83	1060
1021.09	1080
1023.35	1064
1025.61	1064
1027.87	1078
1030.12	1058
1032.38	1062
1034.63	1056
1036.88	1066
1039.14	1052
1041.39	1054
1043.64	1080
1045.89	1114
1048.14	1064
1050.39	1074
1052.64	1056
1054.89	1060
1057.14	1106
1059.38	1098
1061.63	1056
1063.87	1086
1066.12	1122
1068.36	1064
1070.6	1044
1072.85	1074
1075.09	1084
1077.33	1104
1079.57	1040
1081.81	1102
1084.05	1080
1086.28	1072
1088.52	1054
1090.76	1034
1092.99	1046
1095.23	1064
1097.46	1036
1099.69	1014
1101.93	1062
1104.16	1076
1106.39	1058
1108.62	1028
1110.85	1022
1113.08	1040
1115.31	1024
1117.53	1030
1119.76	1046
1121.99	1028
1124.21	1052
1126.44	1030
1128.66	1068
1130.88	1066
1133.11	1056
1135.33	1022
1137.55	1000
1139.77	1028
1141.99	1026
1144.21	1008
1146.43	1024
1148.64	1004
1150.86	1022
1153.08	1020
1155.29	1026
1157.51	1028
1159.72	1056
1161.93	974
1164.14	1028
1166.36	988
1168.57	1016
1170.78	1012
1172.99	1010
1175.2	958
1177.4	968
1179.61	984
1181.82	1008
1184.02	1006
1186.23	926
1188.43	990
1190.64	982
1192.84	954
1195.04	980
1197.24	982
1199.45	970.17
1201.64	960.004
1203.84	954.393
1206.04	961.613
1208.24	952.522
1210.44	960
1212.64	943.089
1214.83	946.897
1217.03	953.633
1219.22	952.168
1221.41	946.647
1223.61	941.431
1225.8	939.991
1227.99	947.806
1230.18	966.927
1232.37	932.185
1234.56	960.759
1236.75	966.123
1238.94	972.536
1241.13	964.703
1243.31	943.34
1245.5	974.692
1247.68	951.183
1249.87	980.88
1252.05	979.743
1254.24	955.042
1256.42	954.529
1258.6	980.266
1260.78	972.664
1262.96	986.91
1265.14	971.718
1267.32	971.919
1269.5	971.91
1271.67	975.133
1273.85	967.19
1276.03	941.633
1278.2	964.408
1280.38	975.33
1282.55	958.632
1284.72	980.374
1286.9	965.073
1289.07	996.979
1291.24	987.191
1293.41	996.6
1295.58	1033.25
1297.75	968.799
1299.92	983.49
1302.09	998.712
1304.25	977.701
1306.42	1006.8
1308.46	942
1310.63	976
1312.81	964
1314.98	962
1317.16	970
1319.33	988
1321.5	950
1323.67	976
1325.85	956
1328.02	992
1330.19	980
1332.35	930
1334.52	958
1336.69	926
1338.86	996
1341.02	962
1343.19	970
1345.35	950
1347.52	950
1349.68	930
1351.84	910
1354	972
1356.17	928
1358.33	932
1360.49	916
1362.65	918
1364.8	934
1366.96	962
1369.12	924
1371.28	946
1373.43	908
1375.59	926
1377.74	928
1379.89	920
1382.05	916
1384.2	908
1386.35	962
1388.5	916
1390.65	900
1392.8	944
1394.95	914
1397.1	912
1399.25	914
1401.4	918
1403.54	916
1405.69	874
1407.83	872
1409.98	874
1412.12	924
1414.26	894
1416.4	898
1418.55	948
1420.69	906
1422.83	890
1424.97	882
1427.1	948
1429.24	894
1431.38	910
1433.52	938
1435.65	908
1437.79	926
1439.92	928
1442.06	916
1444.19	886
1446.32	946
1448.46	886
1450.59	944
1452.72	918
1454.85	902
1456.98	918
1459.11	908
1461.23	910
1463.36	922
1465.49	902
1467.61	906
1469.74	878
1471.86	866
1473.99	918
1476.11	884
1478.23	834
1480.36	838
1482.48	874
1484.6	856
1486.72	854
1488.84	878
1490.96	862
1493.07	848
1495.19	842
1497.31	864
1499.42	828
1501.54	856
1503.65	826
1505.77	894
1507.88	836
1509.99	826
1512.1	850
1514.22	846
1516.33	846
1518.44	858
1520.55	862
1522.65	848
1524.76	822
1526.87	810
1528.98	800
1531.08	802
1533.19	764
1535.29	838
1537.4	824
1539.5	788
1541.6	826
1543.7	810
1545.8	802
1547.91	772
1550.01	804
1552.11	776
1554.2	770
1556.3	828
1558.4	782
1560.5	794
1562.59	832
1564.69	792
1566.78	816
1568.88	792
1570.97	768
1573.06	770
1575.15	790
1577.25	762
1579.34	790
1581.43	786
1583.52	768
1585.6	772
1587.69	758
1589.78	764
1591.87	752
1593.95	776
1596.04	772
1598.12	788
1600.21	764
1602.29	772
1604.37	782
1606.46	760
1608.54	772
1610.62	792
1612.7	768
1614.78	770
1616.86	764
1618.94	792
1621.01	780
1623.09	764
1625.17	756
1627.24	778
1629.32	774
1631.39	764
1633.47	778
1635.54	750
1637.61	732
1639.68	754
1641.76	762
1643.83	768
1645.9	762
1647.96	748
1650.03	772
1652.1	754
1654.17	772
1656.24	778
1658.3	764
1660.37	722
1662.43	704
1664.5	734
1666.56	738
1668.62	758
1670.68	752
1672.75	740
1674.81	758
1676.87	714
1678.93	740
1680.99	712
1683.04	762
1685.1	736
1687.16	712
1689.21	740
1691.27	700
1693.33	738
1695.38	720
1697.43	726
1699.49	712
1701.54	710
1703.59	718
1705.64	714
1707.69	700
1709.74	718
1711.79	698
1713.84	704
1715.89	704
1717.94	716
1719.98	670
1722.03	708
1724.07	676
1726.12	708
1728.16	704
1730.21	682
1732.25	710
1734.29	690
1736.33	690
1738.37	692
1740.41	710
1742.45	688
1744.49	718
1746.53	682
1748.57	686
1750.61	688
1752.64	658
1754.68	686
1756.71	662
1758.75	698
1760.78	666
1762.82	656
1764.85	686
1766.88	668
1768.91	666
1770.94	658
1772.97	684
1775	676
1777.03	666
1779.06	702
1781.09	690
1783.12	700
1785.14	660
1787.17	640
1789.19	664
1791.22	684
1793.24	632
1795.27	664
1797.29	648
1799.31	672
1801.33	674
1803.35	642
1805.37	654
1807.39	630
1809.41	690
1811.43	656
1813.45	634
1815.46	638
1817.48	634
1819.5	642
1821.51	626
1823.53	610
1825.54	628
1827.55	636
1829.57	664
1831.58	626
1833.59	628
1835.6	596
1837.61	606
1839.62	598
1841.63	596
1843.64	620
1845.65	598
1847.65	624
1849.66	620
1851.66	616
1853.67	590
1855.67	598
1857.68	602
1859.68	596
1861.68	596
1863.69	588
1865.69	610
1867.69	598
1869.69	576
1871.69	626
1873.69	564
1875.69	602
1877.68	614
1879.68	614
1881.68	550
1883.67	626
1885.67	580
1887.66	600
1889.66	598
1891.65	598
1893.64	578
1895.64	588
1897.63	590
1899.62	594
1901.61	578
1903.6	578
1905.59	592
1907.58	572
1909.56	548
1911.55	610
1913.54	568
1915.53	570
1917.51	576
1919.5	580
1921.48	594
1923.46	582
1925.45	600
1927.43	584
1929.41	580
1931.39	582
1933.37	588
1935.35	584
1937.33	556
1939.31	556
1941.29	558
1943.27	556
1945.24	548
1947.22	554
1949.2	554
1951.17	548
1953.14	547
1955.12	546
1957.09	546
1959.06	576
1961.04	534
1963.01	528
1964.98	552
1966.95	538
1968.92	534
1970.89	512
1972.86	530
1974.82	544
1976.79	546
1978.76	538
1980.72	536
1982.69	514
1984.65	534
1986.62	540
1988.58	546
1990.54	518
1992.51	512
1994.47	546
1996.43	528
1998.39	516
1999.37	534