File: muestras/goma/CO_07.txt
#Acq. time (s)=	15
#Accumulations=	3
#Range (cm-¹)=	50...1300
#Windows=	2
#Autofocus=	Off
#AutoExposure=	Off
#Spike filter=	Multiple accum.
#Delay time (s)=	0
#Binning=	1
#Readout mode=	Signal
#DeNoise=	Off
#ICS correction=	Off
#Dark correction=	Off
#Inst. Process=	Off
#Instrument=	LabRAM HR Evol
#Detector=	Syncerity OE
#Objective=	x100_VIS
#Grating=	600 (500nm)
#ND Filter=	10%
#Laser=	633nm_Edge
#Hole=	100.021
#Range=	Visible
#Project=	Omar
#Sample=	CM
#Site=	11-05-23
#Title=	CO
#Remark=	ch1
#Date=	11.05.2023 16:23
#Acquired=	11.05.2023 16:23:33
50.1258	2128
51.4176	2134
52.7092	2130
54.0021	2226
55.2932	2498
56.5841	2855
57.8748	3459
59.1669	4146
60.4572	4583
61.7472	4824
63.0371	4970
64.3283	4936
65.6177	4999
66.907	5000
68.196	5047
69.4848	5038
70.7734	5065
72.0633	5055
73.3515	5134
74.6395	5123
75.9272	5136
77.2148	5246
78.5021	5212
79.7892	5221
81.0761	5230
82.3644	5202
83.6509	5270
84.9371	5274
86.2232	5274
87.5091	5254
88.7947	5338
90.0802	5318
91.3654	5373
92.6504	5377
93.9352	5388
95.2198	5475
96.5042	5447
97.7884	5463
99.0724	5470
100.356	5498
101.64	5529
102.923	5542
104.206	5566
105.489	5626
106.772	5624
108.054	5675
109.337	5649
110.619	5684
111.901	5721
113.182	5700
114.464	5736
115.745	5759
117.024	5754
118.305	5801
119.586	5755
120.866	5802
122.147	5851
123.426	5823
124.706	5860
125.986	5896
127.264	5881
128.543	5916
129.822	5968
131.101	5932
132.379	6089
133.657	5972
134.934	5996
136.212	6071
137.49	6067
138.767	6055
140.043	6066
141.32	6170
142.597	6081
143.873	6136
145.148	6166
146.425	6151
147.701	6181
148.977	6111
150.251	6161
151.526	6191
152.801	6202
154.075	6270
155.35	6208
156.624	6276
157.897	6223
159.171	6347
160.445	6267
161.717	6281
162.991	6293
164.264	6362
165.536	6401
166.809	6404
168.081	6390
169.353	6373
170.625	6369
171.895	6432
173.167	6386
174.437	6464
175.709	6403
176.98	6486
178.25	6480
179.521	6533
180.79	6510
182.06	6507
183.329	6544
184.599	6579
185.867	6564
187.137	6622
188.405	6643
189.674	6696
190.942	6690
192.21	6667
193.477	6818
194.746	6766
196.012	6789
197.279	6813
198.547	6837
199.813	6840
201.08	6887
202.346	6841
203.613	6866
204.878	6922
206.143	6883
207.409	7045
208.674	7068
209.938	6934
211.204	6966
212.468	6997
213.732	7052
214.997	7036
216.26	7111
217.523	7056
218.788	7174
220.051	7184
221.313	7149
222.577	7216
223.839	7187
225.101	7285
226.363	7199
227.626	7279
228.887	7248
230.149	7361
231.41	7371
232.672	7399
233.932	7298
235.193	7413
236.453	7318
237.714	7465
238.974	7458
240.233	7453
241.493	7482
242.752	7476
244.011	7545
245.271	7586
246.529	7456
247.788	7473
249.046	7517
250.304	7563
251.561	7527
252.819	7561
254.076	7613
255.333	7581
256.591	7545
257.848	7616
259.105	7559
260.361	7638
261.617	7613
262.873	7650
264.128	7669
265.384	7604
266.639	7662
267.894	7637
269.149	7600
270.404	7634
271.658	7676
272.912	7699
274.166	7712
275.42	7689
276.674	7674
277.927	7760
279.18	7746
280.433	7775
281.686	7767
282.939	7824
284.19	7819
285.442	7881
286.694	7847
287.946	7867
289.197	7922
290.449	7883
291.7	7925
292.951	8008
294.2	8057
295.451	8073
296.701	8118
297.951	8045
299.201	8089
300.451	8194
301.699	8130
302.949	8196
304.198	8132
305.447	8163
306.696	8136
307.943	8139
309.191	8227
310.439	8205
311.687	8213
312.933	8220
314.181	8315
315.428	8229
316.676	8270
317.921	8315
319.168	8284
320.414	8256
321.659	8297
322.905	8334
324.151	8341
325.396	8335
326.641	8258
327.887	8355
329.13	8303
330.375	8358
331.62	8346
332.863	8254
334.108	8360
335.35	8434
336.594	8425
337.837	8506
339.08	8406
340.323	8433
341.565	8414
342.808	8522
344.049	8463
345.292	8507
346.533	8520
347.775	8460
349.016	8539
350.257	8513
351.497	8462
352.739	8569
353.979	8524
355.219	8572
356.459	8575
357.699	8611
358.938	8616
360.178	8661
361.417	8603
362.657	8695
363.895	8612
365.133	8637
366.372	8634
367.609	8618
368.848	8564
370.085	8691
371.322	8630
372.561	8626
373.797	8644
375.033	8635
376.271	8639
377.507	8607
378.743	8652
379.98	8624
381.215	8669
382.45	8667
383.686	8642
384.921	8715
386.156	8604
387.39	8697
388.626	8598
389.86	8757
391.093	8683
392.327	8670
393.562	8672
394.795	8682
396.028	8674
397.261	8874
398.493	8745
399.727	8787
400.959	8882
402.191	8806
403.423	8781
404.655	8932
405.886	8874
407.119	8896
408.35	8948
409.581	8935
410.811	8910
412.042	8942
413.272	8973
414.502	9030
415.732	8997
416.963	9028
418.192	9014
419.421	9070
420.65	9106
421.879	9125
423.108	9121
424.336	9156
425.565	9239
426.793	9141
428.02	9138
429.248	9150
430.476	9186
431.703	9177
432.93	9124
434.157	9203
435.383	9159
436.61	9116
437.836	9221
439.062	9199
440.287	9207
441.512	9206
442.738	9179
443.963	9271
445.188	9141
446.413	9160
447.638	9094
448.863	9200
450.087	9094
451.31	9154
452.534	9121
453.757	9139
454.981	9129
456.204	9147
457.427	9091
458.649	9149
459.872	9143
461.094	9121
462.317	9118
463.539	9083
464.759	9150
465.981	9124
467.203	9152
468.424	9186
469.644	9138
470.865	9116
472.086	9185
473.306	9157
474.525	9143
475.746	9245
476.966	9212
478.184	9174
479.404	9173
480.623	9192
481.841	9279
483.06	9202
484.279	9236
485.496	9237
486.715	9165
487.932	9236
489.15	9191
490.368	9260
491.584	9267
492.802	9199
494.017	9286
495.235	9253
496.45	9333
497.667	9196
498.883	9300
500.098	9235
501.315	9303
502.529	9220
503.745	9231
504.959	9224
506.174	9215
507.388	9252
508.603	9296
509.817	9182
511.031	9197
512.244	9194
513.457	9202
514.671	9231
515.884	9231
517.097	9170
518.309	9181
519.523	9155
520.734	9126
521.946	9112
523.158	9155
524.37	9153
525.58	9134
526.793	9172
528.003	9138
529.213	9052
530.425	9116
531.635	8995
532.845	9121
534.056	9008
535.265	9005
536.474	9049
537.685	9110
538.893	9038
540.102	9033
541.31	9065
542.52	9052
543.728	8967
544.936	9018
546.143	9010
547.351	8948
548.56	8969
549.767	8896
550.973	9011
552.18	8978
553.387	9045
554.594	8948
555.8	8966
557.006	8972
558.212	9003
559.418	8991
560.623	8984
561.828	8890
563.035	8935
564.239	8906
565.444	8903
566.648	8914
567.853	9006
569.057	8927
570.26	8979
571.464	8973
572.667	8945
573.871	8943
575.074	8948
576.277	8913
577.479	8923
578.682	9010
579.884	8948
581.086	8895
582.288	8855
583.49	9009
584.691	8901
585.893	8937
587.094	8861
588.295	8888
589.496	8973
590.696	8970
591.897	8879
593.095	8959
594.296	8869
595.495	8894
596.695	8901
597.894	8877
599.094	8847
600.293	8936
601.49	8908
602.689	8868
603.888	8844
605.086	8834
606.284	8945
607.482	8937
608.678	8845
609.876	8896
611.073	8919
612.27	8884
613.466	8943
614.663	8924
615.859	8905
617.056	8879
618.251	8957
619.447	8902
620.643	8941
621.837	8883
623.032	8870
624.228	8881
625.423	8969
626.616	8884
627.811	8816
629.004	8959
630.199	8919
631.393	8921
632.585	8926
633.779	8990
634.973	8966
636.165	8880
637.358	8916
638.55	8845
639.743	8947
640.934	8897
642.126	8880
643.319	8907
644.509	8976
645.701	8828
646.892	8918
648.083	8909
649.273	8872
650.464	8847
651.654	8847
652.845	8874
654.034	8777
655.224	8793
656.413	8872
657.602	8807
658.792	8803
659.98	8856
661.169	8787
662.357	8816
663.547	8797
664.734	8757
665.921	8767
667.11	8723
668.297	8745
669.484	8725
670.672	8720
671.858	8664
673.044	8764
674.232	8675
675.418	8652
676.603	8716
677.79	8686
678.976	8611
680.161	8685
681.347	8655
682.532	8523
683.716	8547
684.901	8579
686.086	8579
687.27	8515
688.454	8557
689.638	8604
690.821	8515
692.006	8416
693.189	8526
694.372	8437
695.555	8435
696.737	8453
697.919	8543
699.103	8448
700.285	8560
701.467	8430
702.648	8333
703.83	8452
705.011	8360
706.192	8459
707.373	8424
708.553	8382
709.734	8381
710.916	8376
712.096	8381
713.276	8393
714.455	8435
715.635	8409
716.814	8385
717.994	8397
719.173	8346
720.351	8361
721.53	8392
722.709	8317
723.887	8366
725.065	8404
726.243	8347
727.419	8413
728.597	8219
729.774	8364
730.951	8291
732.128	8289
733.305	8324
734.482	8285
735.658	8274
736.834	8266
738.01	8245
739.185	8287
740.361	8209
741.536	8141
742.711	8235
743.887	8226
745.06	8242
746.235	8189
747.41	8189
748.584	8152
749.758	8145
750.931	8135
752.105	8070
753.278	8167
754.452	8073
755.624	8061
756.797	8053
757.97	8077
759.141	8125
760.314	7981
761.486	8009
762.659	8033
763.829	8076
765.001	7995
766.173	8012
767.343	7878
768.514	7940
769.684	7989
770.855	7958
772.026	7972
773.195	7955
774.365	7920
775.534	7833
776.704	7870
777.874	7805
779.042	7775
780.212	7893
781.38	7891
782.549	7817
783.716	7793
784.885	7766
786.052	7790
787.221	7753
788.388	7800
789.556	7799
790.722	7772
791.89	7780
793.056	7708
794.223	7819
795.389	7724
796.554	7778
797.721	7699
798.886	7769
800.053	7744
801.218	7671
802.382	7713
803.548	7687
804.712	7652
805.877	7649
807.042	7698
808.206	7621
809.369	7654
810.534	7611
811.697	7614
812.86	7629
814.025	7675
815.187	7639
816.35	7617
817.512	7649
818.676	7630
819.837	7643
820.999	7660
822.161	7596
823.324	7606
824.485	7604
825.646	7574
826.807	7534
827.967	7638
829.129	7564
830.29	7530
831.45	7569
832.61	7577
833.77	7612
834.929	7559
836.089	7504
837.249	7525
838.408	7574
839.567	7543
840.726	7542
841.885	7506
843.043	7548
844.201	7583
845.359	7564
846.517	7545
847.675	7498
848.832	7445
849.989	7514
851.146	7544
852.303	7422
853.46	7469
854.617	7490
855.773	7434
856.929	7488
858.085	7441
859.241	7461
860.397	7488
861.552	7491
862.708	7338
863.863	7377
865.018	7402
866.171	7381
867.326	7386
868.48	7356
869.634	7340
870.788	7296
871.942	7299
873.096	7309
874.248	7343
875.402	7273
876.555	7296
877.708	7246
878.861	7248
880.012	7233
881.164	7250
882.317	7222
883.469	7207
884.619	7111
885.771	7162
886.923	7147
888.074	7111
889.224	7090
890.375	7066
891.526	7008
892.675	7090
893.826	7081
894.976	7076
896.125	6984
897.275	7013
898.424	7004
899.573	6875
900.722	6914
901.871	6950
903.019	6977
904.168	6937
905.315	6905
906.464	6944
907.611	6953
908.759	6845
909.907	6855
911.054	6905
912.201	6890
913.348	6920
914.495	6898
915.641	6827
916.788	6900
917.933	6798
919.08	6840
920.225	6849
921.371	6808
922.516	6758
923.66	6708
924.806	6808
925.95	6758
927.096	6789
928.24	6820
929.383	6814
930.528	6767
931.671	6723
932.816	6720
933.959	6671
935.102	6747
936.246	6694
937.388	6684
938.53	6725
939.674	6759
940.816	6760
941.957	6743
943.099	6676
944.242	6736
945.383	6635
946.524	6675
947.665	6668
948.807	6640
949.947	6681
951.088	6691
952.228	6668
953.369	6674
954.509	6638
955.649	6550
956.788	6675
957.927	6678
959.067	6617
960.207	6618
961.346	6642
962.484	6535
963.623	6550
964.761	6564
965.899	6594
967.037	6566
968.174	6564
969.312	6592
970.449	6547
971.587	6459
972.725	6588
973.862	6545
974.998	6533
976.135	6501
977.271	6483
978.407	6520
979.543	6465
980.679	6479
981.815	6444
982.949	6475
984.084	6463
985.219	6468
986.354	6456
987.489	6467
988.624	6384
989.758	6391
990.892	6385
992.026	6354
993.16	6353
994.294	6274
995.426	6389
996.559	6331
997.693	6255
998.826	6363
999.959	6372
1001.09	6338
1002.22	6282
1003.35	6285
1004.49	6298
1005.62	6270
1006.75	6248
1007.88	6262
1009.01	6266
1010.14	6262
1011.27	6287
1012.4	6192
1013.54	6201
1014.67	6200
1015.79	6256
1016.93	6294
1018.06	6198
1019.18	6214
1020.31	6192
1021.44	6150
1022.57	6208
1023.7	6117
1024.83	6205
1025.96	6206
1027.09	6120
1028.21	6122
1029.34	6144
1030.47	6181
1031.6	6140
1032.72	6169
1033.85	6164
1034.98	6128
1036.1	6104
1037.23	6138
1038.36	6100
1039.48	6089
1040.61	6124
1041.73	6133
1042.86	6089
1043.99	6060
1045.11	6096
1046.24	6140
1047.36	6111
1048.48	6102
1049.61	6060
1050.73	6144
1051.86	6065
1052.98	6066
1054.11	6025
1055.23	6033
1056.35	6069
1057.48	6011
1058.6	6078
1059.72	6036
1060.84	6055
1061.97	5989
1063.09	6020
1064.21	5995
1065.33	6002
1066.46	5962
1067.58	5959
1068.7	5987
1069.82	5955
1070.94	5948
1072.06	5842
1073.18	5937
1074.3	5950
1075.42	5827
1076.54	5882
1077.66	5869
1078.78	5896
1079.9	5869
1081.02	5873
1082.14	5882
1083.26	5873
1084.38	5806
1085.5	5804
1086.61	5828
1087.73	5748
1088.85	5758
1089.97	5710
1091.09	5721
1092.2	5674
1093.32	5743
1094.44	5671
1095.55	5692
1096.67	5717
1097.79	5742
1098.9	5660
1100.02	5658
1101.14	5604
1102.25	5619
1103.37	5641
1104.48	5627
1105.6	5616
1106.71	5617
1107.83	5584
1108.94	5548
1110.06	5611
1111.17	5605
1112.29	5566
1113.4	5563
1114.52	5534
1115.63	5530
1116.74	5561
1117.86	5517.09
1118.97	5505.18
1120.08	5454.27
1121.2	5478.36
1122.31	5509.45
1123.42	5504.55
1124.53	5514.64
1125.64	5555.73
1126.76	5534.82
1127.87	5544.91
1128.98	5566
1130.09	5549.09
1131.2	5535.18
1132.31	5517.27
1133.42	5592.36
1134.53	5544.46
1135.65	5550.55
1136.75	5539.64
1137.87	5482.73
1138.98	5588.82
1140.08	5513.91
1141.19	5572
1142.3	5512.09
1143.41	5529.18
1144.52	5680.27
1145.63	5680.37
1146.74	5664.46
1147.85	5539.55
1148.96	5494.64
1150.06	5545.73
1151.17	5564.82
1152.28	5524.2
1153.39	5495.03
1154.5	5564.56
1155.6	5529.33
1156.71	5494.3
1157.82	5588.45
1158.92	5538.57
1160.03	5577.67
1161.14	5586.08
1162.24	5565.39
1163.35	5594.12
1164.45	5552.68
1165.56	5571.86
1166.66	5569.43
1167.77	5513.26
1168.88	5582.89
1169.98	5579.84
1171.08	5583.65
1172.19	5576.16
1173.29	5594.87
1174.4	5511.21
1175.5	5542.63
1176.6	5579.77
1177.71	5563.72
1178.81	5540.99
1179.91	5567.41
1181.02	5557
1182.12	5530.53
1183.22	5569.54
1184.33	5511.41
1185.43	5465.22
1186.53	5489.4
1187.63	5517.12
1188.73	5514.86
1189.84	5496.24
1190.94	5482.58
1192.04	5438.23
1193.14	5461.6
1194.24	5480.89
1195.34	5493.88
1196.44	5498.34
1197.54	5472.63
1198.64	5444.84
1199.74	5430.31
1200.84	5445.52
1201.94	5435.46
1203.04	5408.04
1204.14	5425.06
1205.24	5452.63
1206.34	5419.2
1207.44	5415.79
1208.54	5416.84
1209.63	5409.39
1210.73	5384.12
1211.83	5386.48
1212.93	5363.69
1214.03	5379.72
1215.12	5358.68
1216.22	5319.67
1217.32	5348.1
1218.42	5340.19
1219.51	5298.96
1220.61	5333.37
1221.71	5313.37
1222.8	5289.37
1223.9	5309.92
1224.99	5312.4
1226.09	5327.06
1227.18	5282.78
1228.28	5301.82
1229.38	5312.41
1230.47	5264.92
1231.57	5246.18
1232.66	5284.42
1233.75	5289.86
1234.85	5302.43
1235.94	5268.79
1237.04	5274.61
1238.13	5278.66
1239.22	5238.83
1240.32	5234.52
1241.41	5215.65
1242.5	5237.94
1243.6	5230.73
1244.69	5199.73
1245.78	5198.2
1246.87	5219.02
1247.97	5234.98
1249.06	5248.37
1250.15	5247.86
1251.24	5192.45
1252.34	5182.67
1253.43	5201.57
1254.52	5216.99
1255.61	5189.5
1256.7	5201.19
1257.79	5223.96
1258.88	5203.84
1259.97	5174.77
1261.06	5192.59
1262.15	5158.22
1263.24	5191.82
1264.33	5173.49
1265.18	5176.43
1266.28	5187.46
1267.37	5122.49
1268.47	5173.52
1269.56	5139.55
1270.65	5169.58
1271.75	5182.61
1272.84	5175.64
1273.94	5181.67
1275.03	5143.7
1276.12	5210.73
1277.21	5136.76
1278.31	5100.79
1279.4	5091.82
1280.49	5083.85
1281.58	5066.88
1282.68	5119.91
1283.77	5140.94
1284.86	5100.97
1285.95	5114
1287.04	5078.03
1288.13	5170.06
1289.23	5086.09
1290.32	5096.12
1291.41	5067.15
1292.5	5045.18
1293.59	5107.21
1294.68	5029.24
1295.77	5044.27
1296.86	5049.3
1297.95	5009.33
1299.04	5007.36