File: muestras/goma/CO_09.txt
#Acq. time (s)=	15
#Accumulations=	3
#Range (cm-¹)=	50...1300
#Windows=	2
#Autofocus=	Off
#AutoExposure=	Off
#Spike filter=	Multiple accum.
#Delay time (s)=	0
#Binning=	1
#Readout mode=	Signal
#DeNoise=	Off
#ICS correction=	Off
#Dark correction=	Off
#Inst. Process=	Off
#Instrument=	LabRAM HR Evol
#Detector=	Syncerity OE
#Objective=	x100_VIS
#Grating=	600 (500nm)
#ND Filter=	50%
#Laser=	633nm_Edge
#Hole=	100.021
#Range=	Visible
#Project=	Omar
#Sample=	CM
#Site=	11-05-23
#Title=	CO
#Remark=	ch1
#Date=	11.05.2023 16:27
#Acquired=	11.05.2023 16:27:32
50.1258	10071
51.4176	10104
52.7092	10299
54.0021	10657
55.2932	11575
56.5841	13376
57.8748	15940
59.1669	18724
60.4572	20799
61.7472	21984
63.0371	22504
64.3283	22617
65.6177	22558
66.907	22680
68.196	22871
69.4848	23036
70.7734	23179
72.0633	23288
73.3515	23344
74.6395	23414
75.9272	23479
77.2148	23599
78.5021	23778
79.7892	23855
81.0761	24025
82.3644	24035
83.6509	24167
84.9371	24173
86.2232	24280
87.5091	24207
88.7947	24380
90.0802	24459
91.3654	24571
92.6504	24708
93.9352	24754
95.2198	24889
96.5042	24943
97.7884	25139
99.0724	25205
100.356	25338
101.64	25537
102.923	25624
104.206	25618
105.489	25818
106.772	25827
108.054	25970
109.337	25981
110.619	26040
111.901	26181
113.182	26211
114.464	26302
115.745	26507
117.024	26536
118.305	26586
119.586	26569
120.866	26729
122.147	26743
123.426	26826
124.706	27161
125.986	27204
127.264	27184
128.543	27377
129.822	27430
131.101	27485
132.379	27529
133.657	27715
134.934	27779
136.212	27851
137.49	28032
138.767	27939
140.043	28160
141.32	28038
142.597	28229
143.873	28288
145.148	28200
146.425	28388
147.701	28398
148.977	28530
150.251	28488
151.526	28529
152.801	28553
154.075	28841
155.35	28829
156.624	28820
157.897	29040
159.171	29150
160.445	29157
161.717	29342
162.991	29275
164.264	29573
165.536	29472
166.809	29497
168.081	29630
169.353	29634
170.625	29723
171.895	29906
173.167	29832
174.437	30049
175.709	30093
176.98	30090
178.25	30168
179.521	30196
180.79	30388
182.06	30364
183.329	30693
184.599	30677
185.867	30692
187.137	30834
188.405	30994
189.674	31132
190.942	31355
192.21	31254
193.477	31363
194.746	31290
196.012	31529
197.279	31533
198.547	31582
199.813	31803
201.08	31991
202.346	31972
203.613	32036
204.878	32117
206.143	32367
207.409	32350
208.674	32535
209.938	32625
211.204	32593
212.468	32796
213.732	32923
214.997	32935
216.26	32980
217.523	33280
218.788	33258
220.051	33330
221.313	33381
222.577	33412
223.839	33605
225.101	33830
226.363	33803
227.626	33879
228.887	34223
230.149	34218
231.41	34327
232.672	34380
233.932	34580
235.193	34803
236.453	34850
237.714	34771
238.974	34874
240.233	35010
241.493	34915
242.752	35189
244.011	35282
245.271	35326
246.529	35268
247.788	35518
249.046	35573
250.304	35460
251.561	35462
252.819	35647
254.076	35653
255.333	35655
256.591	35692
257.848	35621
259.105	35709
260.361	35987
261.617	35828
262.873	35822
264.128	35849
265.384	36039
266.639	36110
267.894	35928
269.149	36113
270.404	36269
271.658	36064
272.912	36429
274.166	36306
275.42	36219
276.674	36393
277.927	36633
279.18	36680
280.433	36915
281.686	36650
282.939	37053
284.19	37161
285.442	37150
286.694	37382
287.946	37521
289.197	37529
290.449	37782
291.7	37716
292.951	37935
294.2	37969
295.451	37976
296.701	38032
297.951	38412
299.201	38388
300.451	38477
301.699	38564
302.949	38610
304.198	38686
305.447	38713
306.696	38967
307.943	38783
309.191	38725
310.439	38964
311.687	39097
312.933	39209
314.181	39088
315.428	39089
316.676	39208
317.921	39338
319.168	39439
320.414	39155
321.659	39323
322.905	39443
324.151	39396
325.396	39606
326.641	39460
327.887	39617
329.13	39764
330.375	39799
331.62	39798
332.863	39980
334.108	39898
335.35	40053
336.594	40106
337.837	40121
339.08	40126
340.323	40346
341.565	40395
342.808	40454
344.049	40547
345.292	40726
346.533	40846
347.775	40913
349.016	40897
350.257	40912
351.497	40823
352.739	40934
353.979	41078
355.219	41016
356.459	41296
357.699	41084
358.938	41185
360.178	41303
361.417	41412
362.657	41312
363.895	41473
365.133	41438
366.372	41432
367.609	41444
368.848	41206
370.085	41335
371.322	41373
372.561	41339
373.797	41410
375.033	41206
376.271	41271
377.507	41389
378.743	41385
379.98	41355
381.215	41244
382.45	41448
383.686	41483
384.921	41427
386.156	41411
387.39	41469
388.626	41575
389.86	41511
391.093	41757
392.327	41736
393.562	41770
394.795	41733
396.028	41999
397.261	42042
398.493	41995
399.727	42219
400.959	42379
402.191	42354
403.423	42531
404.655	42666
405.886	42782
407.119	42764
408.35	42975
409.581	43117
410.811	43317
412.042	43158
413.272	43382
414.502	43501
415.732	43515
416.963	43781
418.192	43793
419.421	43724
420.65	43833
421.879	43847
423.108	44035
424.336	44129
425.565	44070
426.793	43999
428.02	44206
429.248	44439
430.476	44308
431.703	44462
432.93	44400
434.157	44273
435.383	44244
436.61	44377
437.836	44494
439.062	44406
440.287	44290
441.512	44454
442.738	44380
443.963	44489
445.188	44396
446.413	44472
447.638	44319
448.863	44193
450.087	44214
451.31	44227
452.534	44279
453.757	44304
454.981	44285
456.204	44271
457.427	44331
458.649	44177
459.872	44259
461.094	44266
462.317	44244
463.539	44307
464.759	43965
465.981	44222
467.203	44512
468.424	44390
469.644	44284
470.865	44427
472.086	44339
473.306	44420
474.525	44586
475.746	44555
476.966	44698
478.184	44531
479.404	44645
480.623	44784
481.841	44780
483.06	44756
484.279	44829
485.496	44811
486.715	44626
487.932	44633
489.15	44907
490.368	44978
491.584	45089
492.802	45055
494.017	44925
495.235	45124
496.45	45162
497.667	45079
498.883	45140
500.098	45033
501.315	45105
502.529	45054
503.745	44936
504.959	45113
506.174	44961
507.388	45130
508.603	44904
509.817	44894
511.031	44846
512.244	44588
513.457	44714
514.671	44838
515.884	44737
517.097	44719
518.309	44626
519.523	44604
520.734	44302
521.946	44446
523.158	44617
524.37	44481
525.58	44369
526.793	44433
528.003	44417
529.213	44377
530.425	44385
531.635	44308
532.845	44099
534.056	44220
535.265	44159
536.474	44104
537.685	43901
538.893	43943
540.102	44071
541.31	44025
542.52	43896
543.728	43713
544.936	43991
546.143	44115
547.351	43845
548.56	43886
549.767	43803
550.973	43955
552.18	43999
553.387	44090
554.594	43826
555.8	43919
557.006	43841
558.212	43814
559.418	43863
560.623	43645
561.828	43909
563.035	43766
564.239	43892
565.444	43756
566.648	43850
567.853	43853
569.057	43753
570.26	43754
571.464	43753
572.667	43717
573.871	43518
575.074	43803
576.277	43881
577.479	43852
578.682	43783
579.884	43749
581.086	43624
582.288	43667
583.49	43637
584.691	43778
585.893	43740
587.094	43727
588.295	43714
589.496	43785
590.696	43601
591.897	43675
593.095	43674
594.296	43541
595.495	43463
596.695	43566
597.894	43363
599.094	43576
600.293	43657
601.49	43618
602.689	43769
603.888	43734
605.086	43698
606.284	43646
607.482	43821
608.678	43661
609.876	43762
611.073	43618
612.27	43616
613.466	43730
614.663	43548
615.859	43749
617.056	43754
618.251	43735
619.447	43675
620.643	43864
621.837	43748
623.032	43733
624.228	43744
625.423	43832
626.616	43877
627.811	43647
629.004	43748
630.199	43663
631.393	43846
632.585	43763
633.779	43643
634.973	44080
636.165	43764
637.358	43677
638.55	43800
639.743	43828
640.934	43838
642.126	43784
643.319	43729
644.509	43745
645.701	43614
646.892	43636
648.083	43483
649.273	43581
650.464	43522
651.654	43439
652.845	43607
654.034	43570
655.224	43349
656.413	43470
657.602	43175
658.792	43342
659.98	43298
661.169	43215
662.357	43131
663.547	42980
664.734	43033
665.921	42918
667.11	42690
668.297	42908
669.484	42788
670.672	42655
671.858	42699
673.044	42715
674.232	42677
675.418	42590
676.603	42347
677.79	42553
678.976	42577
680.161	42273
681.347	42296
682.532	42104
683.716	42030
684.901	42017
686.086	42008
687.27	41799
688.454	41956
689.638	41851
690.821	41775
692.006	41930
693.189	41932
694.372	41844
695.555	41669
696.737	41788
697.919	41380
699.103	41572
700.285	41603
701.467	41614
702.648	41309
703.83	41239
705.011	41306
706.192	41311
707.373	41348
708.553	41339
709.734	41515
710.916	41248
712.096	41238
713.276	41228
714.455	41064
715.635	41160
716.814	41184
717.994	41047
719.173	40942
720.351	41025
721.53	40974
722.709	40947
723.887	40782
725.065	40888
726.243	40836
727.419	40780
728.597	40819
729.774	40682
730.951	40691
732.128	40660
733.305	40650
734.482	40456
735.658	40657
736.834	40455
738.01	40449
739.185	40452
740.361	40459
741.536	40347
742.711	40250
743.887	40164
745.06	40175
746.235	39984
747.41	40023
748.584	39866
749.758	39830
750.931	39634
752.105	39776
753.278	39727
754.452	39556
755.624	39509
756.797	39464
757.97	39534
759.141	39454
760.314	39554
761.486	39463
762.659	39217
763.829	39208
765.001	39293
766.173	39131
767.343	38990
768.514	39062
769.684	38997
770.855	38889
772.026	38932
773.195	38710
774.365	38601
775.534	38638
776.704	38628
777.874	38514
779.042	38507
780.212	38286
781.38	38202
782.549	38393
783.716	38326
784.885	38240
786.052	38234
787.221	38201
788.388	38087
789.556	38024
790.722	38095
791.89	37910
793.056	37907
794.223	37774
795.389	37831
796.554	37720
797.721	37857
798.886	37763
800.053	37757
801.218	37632
802.382	37544
803.548	37779
804.712	37509
805.877	37375
807.042	37413
808.206	37380
809.369	37372
810.534	37528
811.697	37376
812.86	37524
814.025	37382
815.187	37398
816.35	37358
817.512	37310
818.676	37360
819.837	37223
820.999	37166
822.161	37060
823.324	37093
824.485	37174
825.646	37308
826.807	37214
827.967	36970
829.129	37041
830.29	37141
831.45	36915
832.61	37057
833.77	37123
834.929	36983
836.089	36985
837.249	36831
838.408	36912
839.567	37025
840.726	36843
841.885	36916
843.043	36740
844.201	36815
845.359	36746
846.517	36697
847.675	36651
848.832	36684
849.989	36585
851.146	36529
852.303	36514
853.46	36433
854.617	36558
855.773	36417
856.929	36262
858.085	36233
859.241	36282
860.397	36185
861.552	36011
862.708	36089
863.863	36094
865.018	35939
866.171	35934
867.326	35937
868.48	35684
869.634	35692
870.788	35815
871.942	35881
873.096	35713
874.248	35633
875.402	35648
876.555	35474
877.708	35463
878.861	35258
880.012	35177
881.164	35160
882.317	34933
883.469	34839
884.619	34738
885.771	34837
886.923	34738
888.074	34739
889.224	34567
890.375	34450
891.526	34360
892.675	34516
893.826	34203
894.976	34263
896.125	34019
897.275	34070
898.424	34000
899.573	34053
900.722	33889
901.871	33888
903.019	33822
904.168	33880
905.315	33584
906.464	33721
907.611	33525
908.759	33505
909.907	33447
911.054	33414
912.201	33442
913.348	33346
914.495	33250
915.641	33171
916.788	33037
917.933	33230
919.08	33312
920.225	33178
921.371	33170
922.516	32973
923.66	33013
924.806	33003
925.95	32929
927.096	32879
928.24	32829
929.383	32708
930.528	32802
931.671	32821
932.816	32745
933.959	32704
935.102	32593
936.246	32502
937.388	32502
938.53	32806
939.674	32441
940.816	32331
941.957	32406
943.099	32477
944.242	32297
945.383	32298
946.524	32324
947.665	32291
948.807	32296
949.947	32265
951.088	32150
952.228	32105
953.369	32117
954.509	32198
955.649	32102
956.788	32033
957.927	32100
959.067	31890
960.207	31856
961.346	31879
962.484	31753
963.623	31746
964.761	31623
965.899	31789
967.037	31690
968.174	31596
969.312	31641
970.449	31653
971.587	31556
972.725	31640
973.862	31555
974.998	31458
976.135	31492
977.271	31452
978.407	31324
979.543	31103
980.679	31268
981.815	31120
982.949	31144
984.084	31059
985.219	30936
986.354	30983
987.489	31058
988.624	30855
989.758	30872
990.892	30756
992.026	30683
993.16	30559
994.294	30652
995.426	30550
996.559	30645
997.693	30467
998.826	30316
999.959	30404
1001.09	30342
1002.22	30461
1003.35	30193
1004.49	30140
1005.62	30221
1006.75	30159
1007.88	30290
1009.01	30024
1010.14	30072
1011.27	29927
1012.4	30001
1013.54	29938
1014.67	29901
1015.79	29858
1016.93	29986
1018.06	29848
1019.18	29822
1020.31	29778
1021.44	29827
1022.57	29688
1023.7	29776
1024.83	29713
1025.96	29733
1027.09	29718
1028.21	29494
1029.34	29574
1030.47	29632
1031.6	29617
1032.72	29490
1033.85	29461
1034.98	29493
1036.1	29498
1037.23	29509
1038.36	29449
1039.48	29310
1040.61	29370
1041.73	29576
1042.86	29404
1043.99	29413
1045.11	29455
1046.24	29157
1047.36	29154
1048.48	29311
1049.61	29385
1050.73	29286
1051.86	29072
1052.98	29173
1054.11	28952
1055.23	29042
1056.35	28927
1057.48	28927
1058.6	29054
1059.72	28832
1060.84	28924
1061.97	28680
1063.09	28557
1064.21	28659
1065.33	28579
1066.46	28622
1067.58	28500
1068.7	28532
1069.82	28360
1070.94	28400
1072.06	28408
1073.18	28389
1074.3	28273
1075.42	28240
1076.54	28199
1077.66	28122
1078.78	28060
1079.9	28031
1081.02	27966
1082.14	27937
1083.26	27728
1084.38	27798
1085.5	27676
1086.61	27621
1087.73	27675
1088.85	27350
1089.97	27646
1091.09	27473
1092.2	27335
1093.32	27236
1094.44	27287
1095.55	27110
1096.67	27075
1097.79	27005
1098.9	27036
1100.02	26934
1101.14	26878
1102.25	26892
1103.37	26846
1104.48	26753
1105.6	26665
1106.71	26744
1107.83	26792
1108.94	26490
1110.06	26705
1111.17	26486
1112.29	26595
1113.4	26485
1114.52	26427
1115.63	26337
1116.74	26228
1117.86	26272.3
1118.97	26159.7
1120.08	26346.1
1121.2	26265.4
1122.31	26115.8
1123.42	26153.1
1124.53	26248.5
1125.64	26217.8
1126.76	26150.2
1127.87	26165.5
1128.98	26119.9
1130.09	26096.2
1131.2	26092.6
1132.31	26056.9
1133.42	26076.3
1134.53	25887.6
1135.65	26065
1136.75	25981.3
1137.87	25911.7
1138.98	25906
1140.08	25941.4
1141.19	25856.7
1142.3	25809.1
1143.41	26065.4
1144.52	25701.8
1145.63	25789.1
1146.74	25805.5
1147.85	25916.8
1148.96	25783.2
1150.06	25752.5
1151.17	25844.9
1152.28	25856.2
1153.39	25698.9
1154.5	25858.7
1155.6	25931.4
1156.71	25515.1
1157.82	25798.2
1158.92	25679.4
1160.03	25681.7
1161.14	25621
1162.24	25564.1
1163.35	25623
1164.45	25555.4
1165.56	25563.2
1166.66	25426.2
1167.77	25403
1168.88	25394.2
1169.98	25260.1
1171.08	25312.4
1172.19	25314.1
1173.29	25271.8
1174.4	25276.5
1175.5	25319.2
1176.6	25107.9
1177.71	25168.7
1178.81	25053.3
1179.91	25021.1
1181.02	24823.8
1182.12	24869.2
1183.22	24927.5
1184.33	24839
1185.43	24707.3
1186.53	24805.2
1187.63	24716.3
1188.73	24690.5
1189.84	24770
1190.94	24596.1
1192.04	24550.3
1193.14	24448.6
1194.24	24541.8
1195.34	24407.3
1196.44	24264.2
1197.54	24291
1198.64	24337.9
1199.74	24257.6
1200.84	24120.5
1201.94	24001.8
1203.04	24033.7
1204.14	24025.7
1205.24	23969
1206.34	23906.2
1207.44	23946.9
1208.54	23813.9
1209.63	23760.7
1210.73	23726.9
1211.83	23767.8
1212.93	23637.8
1214.03	23653.2
1215.12	23525.2
1216.22	23455.4
1217.32	23432.4
1218.42	23395.8
1219.51	23393.5
1220.61	23335.5
1221.71	23276.4
1222.8	23167.2
1223.9	23221.2
1224.99	23176.6
1226.09	23134.6
1227.18	23112.7
1228.28	23096.5
1229.38	23062.8
1230.47	22980.8
1231.57	22945.7
1232.66	23012.2
1233.75	22880.2
1234.85	22842
1235.94	22788.1
1237.04	22798
1238.13	22815.6
1239.22	22755.4
1240.32	22634.4
1241.41	22681.4
1242.5	22718.7
1243.6	22649.6
1244.69	22642.8
1245.78	22586.4
1246.87	22566
1247.97	22614.3
1249.06	22442
1250.15	22433.2
1251.24	22459.5
1252.34	22439.1
1253.43	22474.6
1254.52	22393.5
1255.61	22400.1
1256.7	22411.7
1257.79	22467
1258.88	22351.2
1259.97	22256.2
1261.06	22314.6
1262.15	22250.1
1263.24	22231
1264.33	22131
1265.18	22144.4
1266.28	22183.3
1267.37	22118.2
1268.47	22028.1
1269.56	22107
1270.65	21986.9
1271.75	22006.8
1272.84	22074.7
1273.94	21954.5
1275.03	22036.4
1276.12	21990.3
1277.21	21986.2
1278.31	21814.1
1279.4	22108
1280.49	21901.9
1281.58	21778.8
1282.68	21923.6
1283.77	21724.5
1284.86	21777.4
1285.95	21788.3
1287.04	21681.2
1288.13	21629.1
1289.23	21679
1290.32	21653.9
1291.41	21697.8
1292.5	21659.6
1293.59	21676.5
1294.68	21470.4
1295.77	21666.3
1296.86	21528.2
1297.95	21460.1
1299.04	21367