File: muestras/goma/CO_03.txt
#Acq. time (s)=	15
#Accumulations=	3
#Range (cm-¹)=	50...1300
#Windows=	2
#Autofocus=	Off
#AutoExposure=	Off
#Spike filter=	Multiple accum.
#Delay time (s)=	0
#Binning=	1
#Readout mode=	Signal
#DeNoise=	Off
#ICS correction=	Off
#Dark correction=	Off
#Inst. Process=	Off
#Instrument=	LabRAM HR Evol
#Detector=	Syncerity OE
#Objective=	x100_VIS
#Grating=	600 (500nm)
#ND Filter=	5%
#Laser=	633nm_Edge
#Hole=	150.001
#Range=	Visible
#Project=	Omar
#Sample=	CM
#Site=	11-05-23
#Title=	CO
#Remark=	ch1
#Date=	11.05.2023 16:19
#Acquired=	11.05.2023 16:19:28
50.1258	5799
51.4176	5836
52.7092	6000
54.0021	6441
55.2932	7277
56.5841	8724
57.8748	10886
59.1669	13118
60.4572	14889
61.7472	15855
63.0371	16428
64.3283	16409
65.6177	16410
66.907	16537
68.196	16541
69.4848	16799
70.7734	16875
72.0633	16837
73.3515	16911
74.6395	17177
75.9272	17065
77.2148	17339
78.5021	17187
79.7892	17328
81.0761	17477
82.3644	17480
83.6509	17365
84.9371	17444
86.2232	17454
87.5091	17472
88.7947	17571
90.0802	17638
91.3654	17778
92.6504	17818
93.9352	17983
95.2198	17867
96.5042	17911
97.7884	18064
99.0724	18223
100.356	18183
101.64	18454
102.923	18469
104.206	18337
105.489	18419
106.772	18512
108.054	18418
109.337	18631
110.619	18663
111.901	18759
113.182	18789
114.464	18865
115.745	18881
117.024	18929
118.305	19015
119.586	18966
120.866	18970
122.147	19010
123.426	19163
124.706	19306
125.986	19312
127.264	19318
128.543	19349
129.822	19280
131.101	19443
132.379	19465
133.657	19593
134.934	19584
136.212	19548
137.49	19727
138.767	19738
140.043	19763
141.32	19721
142.597	19849
143.873	19823
145.148	19907
146.425	19838
147.701	19912
148.977	20181
150.251	20020
151.526	20246
152.801	20145
154.075	20285
155.35	20250
156.624	20293
157.897	20373
159.171	20382
160.445	20486
161.717	20512
162.991	20484
164.264	20508
165.536	20536
166.809	20681
168.081	20676
169.353	20749
170.625	20705
171.895	20659
173.167	20704
174.437	20776
175.709	20852
176.98	20816
178.25	20904
179.521	20848
180.79	21016
182.06	21045
183.329	21107
184.599	21127
185.867	21121
187.137	21324
188.405	21262
189.674	21271
190.942	21410
192.21	21415
193.477	21516
194.746	21599
196.012	21685
197.279	21604
198.547	21760
199.813	21829
201.08	21932
202.346	21948
203.613	21977
204.878	22110
206.143	22245
207.409	22115
208.674	22226
209.938	22225
211.204	22268
212.468	22238
213.732	22333
214.997	22407
216.26	22430
217.523	22391
218.788	22579
220.051	22632
221.313	22554
222.577	22796
223.839	22812
225.101	22904
226.363	22842
227.626	22913
228.887	22874
230.149	22998
231.41	23079
232.672	23120
233.932	23201
235.193	23272
236.453	23359
237.714	23411
238.974	23358
240.233	23517
241.493	23417
242.752	23567
244.011	23633
245.271	23575
246.529	23813
247.788	23739
249.046	23761
250.304	23803
251.561	23821
252.819	23903
254.076	23822
255.333	23876
256.591	23805
257.848	23860
259.105	23729
260.361	23827
261.617	23903
262.873	23737
264.128	23928
265.384	23944
266.639	23785
267.894	23858
269.149	23878
270.404	23872
271.658	23887
272.912	24011
274.166	23890
275.42	23926
276.674	24029
277.927	23878
279.18	24109
280.433	24121
281.686	24197
282.939	24152
284.19	24413
285.442	24275
286.694	24376
287.946	24466
289.197	24579
290.449	24685
291.7	24756
292.951	24558
294.2	24849
295.451	25002
296.701	25005
297.951	24948
299.201	25077
300.451	24976
301.699	25147
302.949	25300
304.198	25247
305.447	25291
306.696	25320
307.943	25173
309.191	25470
310.439	25497
311.687	25283
312.933	25353
314.181	25415
315.428	25441
316.676	25466
317.921	25562
319.168	25554
320.414	25498
321.659	25459
322.905	25561
324.151	25457
325.396	25631
326.641	25702
327.887	25499
329.13	25576
330.375	25651
331.62	25649
332.863	25729
334.108	25736
335.35	25663
336.594	25633
337.837	25867
339.08	25803
340.323	25926
341.565	25848
342.808	25841
344.049	25843
345.292	25973
346.533	25975
347.775	25867
349.016	26061
350.257	25953
351.497	26132
352.739	26186
353.979	26088
355.219	26082
356.459	26185
357.699	26068
358.938	26226
360.178	26341
361.417	26388
362.657	26226
363.895	26313
365.133	26379
366.372	26389
367.609	26394
368.848	26292
370.085	26289
371.322	26277
372.561	26123
373.797	26246
375.033	26141
376.271	26146
377.507	26143
378.743	26167
379.98	26236
381.215	26140
382.45	26216
383.686	26188
384.921	26158
386.156	26105
387.39	26238
388.626	26197
389.86	26228
391.093	26346
392.327	26187
393.562	26377
394.795	26302
396.028	26347
397.261	26370
398.493	26382
399.727	26432
400.959	26482
402.191	26495
403.423	26614
404.655	26792
405.886	26703
407.119	26801
408.35	26923
409.581	26808
410.811	26883
412.042	26818
413.272	27101
414.502	27065
415.732	27258
416.963	27145
418.192	27280
419.421	27455
420.65	27291
421.879	27382
423.108	27345
424.336	27445
425.565	27447
426.793	27287
428.02	27572
429.248	27511
430.476	27665
431.703	27573
432.93	27529
434.157	27537
435.383	27657
436.61	27476
437.836	27533
439.062	27612
440.287	27489
441.512	27521
442.738	27522
443.963	27595
445.188	27394
446.413	27522
447.638	27408
448.863	27504
450.087	27410
451.31	27330
452.534	27384
453.757	27166
454.981	27286
456.204	27217
457.427	27294
458.649	27366
459.872	27217
461.094	27317
462.317	27275
463.539	27290
464.759	27278
465.981	27247
467.203	27253
468.424	27345
469.644	27291
470.865	27266
472.086	27263
473.306	27342
474.525	27362
475.746	27430
476.966	27331
478.184	27318
479.404	27444
480.623	27228
481.841	27276
483.06	27523
484.279	27521
485.496	27514
486.715	27341
487.932	27407
489.15	27425
490.368	27488
491.584	27611
492.802	27655
494.017	27460
495.235	27412
496.45	27528
497.667	27484
498.883	27531
500.098	27518
501.315	27498
502.529	27501
503.745	27426
504.959	27658
506.174	27513
507.388	27565
508.603	27377
509.817	27350
511.031	27263
512.244	27304
513.457	27335
514.671	27183
515.884	27186
517.097	27344
518.309	27253
519.523	27083
520.734	27095
521.946	27002
523.158	27014
524.37	27141
525.58	27069
526.793	27012
528.003	27031
529.213	26946
530.425	26835
531.635	26857
532.845	26919
534.056	26880
535.265	26753
536.474	26700
537.685	26785
538.893	26620
540.102	26700
541.31	26614
542.52	26653
543.728	26633
544.936	26643
546.143	26704
547.351	26507
548.56	26436
549.767	26452
550.973	26432
552.18	26546
553.387	26740
554.594	26530
555.8	26546
557.006	26558
558.212	26379
559.418	26547
560.623	26465
561.828	26482
563.035	26364
564.239	26402
565.444	26456
566.648	26495
567.853	26489
569.057	26428
570.26	26483
571.464	26321
572.667	26336
573.871	26314
575.074	26457
576.277	26327
577.479	26391
578.682	26398
579.884	26422
581.086	26366
582.288	26205
583.49	26396
584.691	26202
585.893	26265
587.094	26109
588.295	26241
589.496	26409
590.696	26172
591.897	26051
593.095	26244
594.296	26266
595.495	26274
596.695	26264
597.894	26180
599.094	26280
600.293	26158
601.49	26280
602.689	26205
603.888	26300
605.086	26263
606.284	26097
607.482	26260
608.678	26188
609.876	26100
611.073	26261
612.27	26077
613.466	26235
614.663	26246
615.859	26232
617.056	26336
618.251	26271
619.447	26288
620.643	26272
621.837	26221
623.032	26110
624.228	26261
625.423	26247
626.616	26423
627.811	26240
629.004	26317
630.199	26282
631.393	26243
632.585	26314
633.779	26303
634.973	26438
636.165	26245
637.358	26178
638.55	26091
639.743	26220
640.934	26240
642.126	26324
643.319	26141
644.509	26172
645.701	26172
646.892	26139
648.083	26124
649.273	26190
650.464	26108
651.654	25978
652.845	26028
654.034	25981
655.224	26051
656.413	25687
657.602	26017
658.792	26042
659.98	25889
661.169	25911
662.357	25910
663.547	25733
664.734	25793
665.921	25730
667.11	25697
668.297	25615
669.484	25703
670.672	25585
671.858	25553
673.044	25424
674.232	25558
675.418	25617
676.603	25484
677.79	25414
678.976	25477
680.161	25225
681.347	25310
682.532	25258
683.716	25189
684.901	25221
686.086	25199
687.27	25248
688.454	25041
689.638	24998
690.821	25170
692.006	25011
693.189	25067
694.372	24893
695.555	24958
696.737	24979
697.919	24823
699.103	24827
700.285	24891
701.467	24887
702.648	24715
703.83	24829
705.011	24822
706.192	24764
707.373	24691
708.553	24623
709.734	24735
710.916	24718
712.096	24635
713.276	24664
714.455	24749
715.635	24611
716.814	24583
717.994	24534
719.173	24627
720.351	24477
721.53	24585
722.709	24620
723.887	24367
725.065	24470
726.243	24387
727.419	24497
728.597	24412
729.774	24250
730.951	24297
732.128	24315
733.305	24411
734.482	24312
735.658	24363
736.834	24341
738.01	24285
739.185	24249
740.361	24228
741.536	24221
742.711	24220
743.887	24243
745.06	24000
746.235	24051
747.41	23947
748.584	23925
749.758	23916
750.931	23779
752.105	23920
753.278	23923
754.452	23672
755.624	23671
756.797	23736
757.97	23602
759.141	23745
760.314	23630
761.486	23466
762.659	23594
763.829	23496
765.001	23595
766.173	23512
767.343	23323
768.514	23534
769.684	23314
770.855	23426
772.026	23388
773.195	23145
774.365	23292
775.534	23299
776.704	23181
777.874	23187
779.042	23170
780.212	23117
781.38	23083
782.549	23111
783.716	22957
784.885	22918
786.052	22925
787.221	22923
788.388	23015
789.556	22910
790.722	22832
791.89	22934
793.056	22889
794.223	22818
795.389	22733
796.554	22698
797.721	22684
798.886	22608
800.053	22611
801.218	22737
802.382	22614
803.548	22619
804.712	22542
805.877	22487
807.042	22572
808.206	22471
809.369	22686
810.534	22485
811.697	22519
812.86	22471
814.025	22495
815.187	22451
816.35	22426
817.512	22488
818.676	22517
819.837	22348
820.999	22358
822.161	22557
823.324	22497
824.485	22306
825.646	22322
826.807	22305
827.967	22246
829.129	22351
830.29	22352
831.45	22276
832.61	22264
833.77	22260
834.929	22294
836.089	22330
837.249	22137
838.408	22462
839.567	22205
840.726	22262
841.885	22250
843.043	22275
844.201	22195
845.359	22050
846.517	22318
847.675	22356
848.832	22069
849.989	22142
851.146	22131
852.303	22091
853.46	22063
854.617	22054
855.773	21995
856.929	21962
858.085	22103
859.241	21834
860.397	21996
861.552	21976
862.708	21862
863.863	21720
865.018	21747
866.171	21829
867.326	21879
868.48	21626
869.634	21697
870.788	21698
871.942	21543
873.096	21685
874.248	21493
875.402	21561
876.555	21474
877.708	21438
878.861	21366
880.012	21448
881.164	21212
882.317	21286
883.469	21242
884.619	21192
885.771	21289
886.923	21133
888.074	21097
889.224	21014
890.375	20936
891.526	21078
892.675	20991
893.826	20912
894.976	20805
896.125	20836
897.275	20814
898.424	20694
899.573	20652
900.722	20731
901.871	20808
903.019	20694
904.168	20663
905.315	20462
906.464	20663
907.611	20431
908.759	20342
909.907	20355
911.054	20426
912.201	20477
913.348	20297
914.495	20255
915.641	20259
916.788	20272
917.933	20317
919.08	20184
920.225	20133
921.371	20238
922.516	20197
923.66	20092
924.806	20026
925.95	20104
927.096	20039
928.24	19974
929.383	19971
930.528	20107
931.671	20032
932.816	19956
933.959	19976
935.102	19907
936.246	19931
937.388	19923
938.53	19986
939.674	19876
940.816	19931
941.957	19872
943.099	19903
944.242	19760
945.383	19793
946.524	19801
947.665	19894
948.807	19752
949.947	19842
951.088	19841
952.228	19720
953.369	19752
954.509	19783
955.649	19665
956.788	19705
957.927	19632
959.067	19748
960.207	19660
961.346	19561
962.484	19751
963.623	19540
964.761	19523
965.899	19455
967.037	19615
968.174	19524
969.312	19512
970.449	19539
971.587	19471
972.725	19426
973.862	19471
974.998	19406
976.135	19386
977.271	19401
978.407	19313
979.543	19269
980.679	19225
981.815	19105
982.949	19260
984.084	19208
985.219	19189
986.354	19056
987.489	18983
988.624	18988
989.758	19067
990.892	18954
992.026	19078
993.16	18986
994.294	19084
995.426	18867
996.559	18971
997.693	18873
998.826	18855
999.959	18838
1001.09	18825
1002.22	18940
1003.35	18771
1004.49	18612
1005.62	18681
1006.75	18676
1007.88	18742
1009.01	18683
1010.14	18750
1011.27	18675
1012.4	18555
1013.54	18531
1014.67	18668
1015.79	18563
1016.93	18492
1018.06	18684
1019.18	18537
1020.31	18393
1021.44	18495
1022.57	18509
1023.7	18440
1024.83	18413
1025.96	18430
1027.09	18406
1028.21	18448
1029.34	18407
1030.47	18341
1031.6	18356
1032.72	18374
1033.85	18356
1034.98	18366
1036.1	18339
1037.23	18259
1038.36	18339
1039.48	18441
1040.61	18271
1041.73	18391
1042.86	18297
1043.99	18458
1045.11	18223
1046.24	18251
1047.36	18161
1048.48	18239
1049.61	18309
1050.73	18207
1051.86	18225
1052.98	18213
1054.11	18144
1055.23	18150
1056.35	18140
1057.48	18107
1058.6	18099
1059.72	18105
1060.84	18040
1061.97	18042
1063.09	17947
1064.21	17986
1065.33	18021
1066.46	17984
1067.58	17951
1068.7	17846
1069.82	17879
1070.94	17788
1072.06	17914
1073.18	17886
1074.3	17744
1075.42	17671
1076.54	17830
1077.66	17856
1078.78	17704
1079.9	17541
1081.02	17472
1082.14	17474
1083.26	17477
1084.38	17458
1085.5	17396
1086.61	17316
1087.73	17366
1088.85	17368
1089.97	17299
1091.09	17334
1092.2	17170
1093.32	17212
1094.44	17182
1095.55	17126
1096.67	17094
1097.79	17026
1098.9	17016
1100.02	16985
1101.14	16971
1102.25	16966
1103.37	16919
1104.48	16823
1105.6	16875
1106.71	16906
1107.83	16862
1108.94	16856
1110.06	16758
1111.17	16828
1112.29	16718
1113.4	16742
1114.52	16726
1115.63	16627
1116.74	16713
1117.86	16546.7
1118.97	16559.4
1120.08	16524.1
1121.2	16560.8
1122.31	16536.5
1123.42	16399.2
1124.53	16396.9
1125.64	16418.6
1126.76	16318.3
1127.87	16318
1128.98	16168.7
1130.09	16332.4
1131.2	16202.1
1132.31	16154.8
1133.42	16209.5
1134.53	16158.2
1135.65	16095.9
1136.75	16007.6
1137.87	16005.3
1138.98	16022
1140.08	15955.7
1141.19	15952.4
1142.3	15905.1
1143.41	15996.8
1144.52	15898.5
1145.63	15926.2
1146.74	15885.9
1147.85	15764.6
1148.96	15798.3
1150.06	15743
1151.17	15789.7
1152.28	15677.2
1153.39	15726.8
1154.5	15637.2
1155.6	15656.2
1156.71	15566.7
1157.82	15401.2
1158.92	15397.1
1160.03	15403.3
1161.14	15204.5
1162.24	15302.8
1163.35	15348.1
1164.45	15113.3
1165.56	15159.9
1166.66	15099.8
1167.77	15112.4
1168.88	15011.4
1169.98	14878
1171.08	14871.7
1172.19	14782.9
1173.29	14857.9
1174.4	14726.1
1175.5	14720.1
1176.6	14655.6
1177.71	14524.3
1178.81	14540.5
1179.91	14423.9
1181.02	14360.3
1182.12	14465
1183.22	14291.7
1184.33	14217.8
1185.43	14209
1186.53	14195.9
1187.63	14110.8
1188.73	14093.8
1189.84	14022.3
1190.94	13928.3
1192.04	13899.2
1193.14	13773.4
1194.24	13750
1195.34	13784
1196.44	13639.5
1197.54	13667.4
1198.64	13562.8
1199.74	13491.1
1200.84	13456.2
1201.94	13352.8
1203.04	13420.6
1204.14	13341.1
1205.24	13354.5
1206.34	13267
1207.44	13200
1208.54	13160.9
1209.63	13142.7
1210.73	13088.9
1211.83	13024.5
1212.93	12968.9
1214.03	12911.9
1215.12	12867.7
1216.22	12780.6
1217.32	12829.4
1218.42	12794
1219.51	12756.5
1220.61	12701.7
1221.71	12678.9
1222.8	12593.3
1223.9	12586.2
1224.99	12560.9
1226.09	12535.4
1227.18	12453.2
1228.28	12493.2
1229.38	12464.7
1230.47	12340.9
1231.57	12329.7
1232.66	12317.2
1233.75	12309.9
1234.85	12290.1
1235.94	12171.6
1237.04	12213.2
1238.13	12174
1239.22	12135.5
1240.32	12099.7
1241.41	12111.8
1242.5	12027.9
1243.6	12040.1
1244.69	11995.4
1245.78	11975.5
1246.87	11981.2
1247.97	12005.2
1249.06	11948.1
1250.15	11956.7
1251.24	11944.7
1252.34	11920.6
1253.43	11862.4
1254.52	11912.8
1255.61	11856.2
1256.7	11858.8
1257.79	11860.7
1258.88	11841.8
1259.97	11795.9
1261.06	11797.2
1262.15	11794.3
1263.24	11811.2
1264.33	11797.7
1265.18	11794.7
1266.28	11755.7
1267.37	11719.7
1268.47	11753.7
1269.56	11788.7
1270.65	11668.7
1271.75	11678.6
1272.84	11694.6
1273.94	11632.6
1275.03	11545.6
1276.12	11599.6
1277.21	11502.6
1278.31	11483.6
1279.4	11631.5
1280.49	11501.5
1281.58	11513.5
1282.68	11501.5
1283.77	11374.5
1284.86	11320.5
1285.95	11386.5
1287.04	11410.4
1288.13	11248.4
1289.23	11294.4
1290.32	11274.4
1291.41	11188.4
1292.5	11270.4
1293.59	11190.4
1294.68	11165.3
1295.77	11168.3
1296.86	11149.3
1297.95	11033.3
1299.04	11154.3