File: muestras/goma/CO_11.txt
#Acq. time (s)=	15
#Accumulations=	3
#Range (cm-¹)=	50...1300
#Windows=	2
#Autofocus=	Off
#AutoExposure=	Off
#Spike filter=	Multiple accum.
#Delay time (s)=	0
#Binning=	1
#Readout mode=	Signal
#DeNoise=	Off
#ICS correction=	Off
#Dark correction=	Off
#Inst. Process=	Off
#Instrument=	LabRAM HR Evol
#Detector=	Syncerity OE
#Objective=	x100_VIS
#Grating=	600 (500nm)
#ND Filter=	50%
#Laser=	633nm_Edge
#Hole=	100.021
#Range=	Visible
#Project=	Omar
#Sample=	CM
#Site=	11-05-23
#Title=	CO
#Remark=	ch1
#Date=	11.05.2023 16:32
#Acquired=	11.05.2023 16:32:58
50.1258	9754
51.4176	9677
52.7092	9921
54.0021	10266
55.2932	11167
56.5841	12857
57.8748	15426
59.1669	18173
60.4572	20296
61.7472	21684
63.0371	21984
64.3283	22288
65.6177	22324
66.907	22289
68.196	22335
69.4848	22579
70.7734	22731
72.0633	22710
73.3515	22989
74.6395	23125
75.9272	23196
77.2148	23141
78.5021	23329
79.7892	23462
81.0761	23596
82.3644	23676
83.6509	23708
84.9371	23746
86.2232	23899
87.5091	23946
88.7947	24087
90.0802	24123
91.3654	24162
92.6504	24301
93.9352	24396
95.2198	24568
96.5042	24696
97.7884	24820
99.0724	24892
100.356	25092
101.64	25250
102.923	25153
104.206	25356
105.489	25376
106.772	25598
108.054	25623
109.337	25615
110.619	25850
111.901	25853
113.182	25893
114.464	26006
115.745	26071
117.024	26210
118.305	26227
119.586	26326
120.866	26484
122.147	26498
123.426	26661
124.706	26747
125.986	27056
127.264	26995
128.543	27089
129.822	27200
131.101	27507
132.379	27503
133.657	27664
134.934	27839
136.212	27977
137.49	28286
138.767	28551
140.043	28733
141.32	28845
142.597	28619
143.873	28590
145.148	28279
146.425	28489
147.701	28340
148.977	28442
150.251	28383
151.526	28421
152.801	28526
154.075	28647
155.35	28626
156.624	28683
157.897	28844
159.171	28968
160.445	29037
161.717	28946
162.991	29117
164.264	29224
165.536	29286
166.809	29323
168.081	29293
169.353	29687
170.625	29578
171.895	29684
173.167	29668
174.437	29833
175.709	29764
176.98	29891
178.25	29890
179.521	30025
180.79	30062
182.06	30210
183.329	30240
184.599	30402
185.867	30552
187.137	30591
188.405	30740
189.674	30791
190.942	31017
192.21	30952
193.477	31193
194.746	31373
196.012	31347
197.279	31539
198.547	31600
199.813	31663
201.08	31838
202.346	31808
203.613	31918
204.878	32122
206.143	32219
207.409	32218
208.674	32349
209.938	32474
211.204	32509
212.468	32695
213.732	32714
214.997	32733
216.26	32734
217.523	33097
218.788	33146
220.051	33283
221.313	33351
222.577	33435
223.839	33637
225.101	33682
226.363	33707
227.626	33629
228.887	33979
230.149	34024
231.41	34063
232.672	34173
233.932	34295
235.193	34582
236.453	34605
237.714	34748
238.974	34863
240.233	34852
241.493	34898
242.752	35078
244.011	35301
245.271	35236
246.529	35264
247.788	35331
249.046	35423
250.304	35548
251.561	35396
252.819	35563
254.076	35522
255.333	35582
256.591	35549
257.848	35627
259.105	35516
260.361	35799
261.617	35672
262.873	35934
264.128	36231
265.384	35825
266.639	35899
267.894	35968
269.149	35993
270.404	35929
271.658	36027
272.912	36153
274.166	36334
275.42	36342
276.674	36341
277.927	36418
279.18	36710
280.433	36713
281.686	36755
282.939	36878
284.19	37100
285.442	37271
286.694	37159
287.946	37497
289.197	37601
290.449	37535
291.7	37814
292.951	37836
294.2	37780
295.451	38110
296.701	38215
297.951	38470
299.201	38465
300.451	38660
301.699	38596
302.949	38716
304.198	38779
305.447	38875
306.696	38779
307.943	38943
309.191	39018
310.439	39187
311.687	39104
312.933	39010
314.181	39191
315.428	39342
316.676	39393
317.921	39355
319.168	39472
320.414	39382
321.659	39628
322.905	39577
324.151	39623
325.396	39654
326.641	39814
327.887	39780
329.13	39751
330.375	39816
331.62	39851
332.863	40078
334.108	40012
335.35	40231
336.594	40241
337.837	40206
339.08	40501
340.323	40356
341.565	40634
342.808	40572
344.049	40698
345.292	40712
346.533	40796
347.775	40838
349.016	41090
350.257	40854
351.497	40915
352.739	41098
353.979	41195
355.219	41292
356.459	41216
357.699	41450
358.938	41447
360.178	41444
361.417	41494
362.657	41518
363.895	41600
365.133	41538
366.372	41378
367.609	41626
368.848	41593
370.085	41557
371.322	41742
372.561	41570
373.797	41597
375.033	41653
376.271	41484
377.507	41515
378.743	41583
379.98	41494
381.215	41676
382.45	41652
383.686	41678
384.921	41742
386.156	41747
387.39	41887
388.626	42011
389.86	42007
391.093	42049
392.327	42104
393.562	42042
394.795	42289
396.028	42409
397.261	42312
398.493	42508
399.727	42433
400.959	42559
402.191	42659
403.423	42817
404.655	43014
405.886	43044
407.119	43117
408.35	43338
409.581	43352
410.811	43485
412.042	43494
413.272	43589
414.502	43559
415.732	43863
416.963	43933
418.192	43893
419.421	44247
420.65	44312
421.879	44251
423.108	44418
424.336	44431
425.565	44481
426.793	44396
428.02	44566
429.248	44826
430.476	44776
431.703	44864
432.93	44912
434.157	44496
435.383	44783
436.61	44770
437.836	44770
439.062	44786
440.287	44690
441.512	44580
442.738	44690
443.963	44744
445.188	44785
446.413	44565
447.638	44710
448.863	44637
450.087	44542
451.31	44797
452.534	44820
453.757	44572
454.981	44854
456.204	44668
457.427	44793
458.649	44667
459.872	44750
461.094	44661
462.317	44564
463.539	44609
464.759	44739
465.981	44663
467.203	44696
468.424	44803
469.644	44869
470.865	44868
472.086	44819
473.306	44952
474.525	44928
475.746	45054
476.966	45035
478.184	45062
479.404	45170
480.623	45010
481.841	45018
483.06	45314
484.279	45449
485.496	45562
486.715	45286
487.932	45412
489.15	45500
490.368	45520
491.584	45421
492.802	45468
494.017	45465
495.235	45541
496.45	45648
497.667	45589
498.883	45568
500.098	45720
501.315	45746
502.529	45457
503.745	45726
504.959	45660
506.174	45517
507.388	45528
508.603	45423
509.817	45529
511.031	45386
512.244	45331
513.457	45215
514.671	45505
515.884	45552
517.097	45286
518.309	45461
519.523	45210
520.734	45120
521.946	45366
523.158	45183
524.37	44930
525.58	44925
526.793	44906
528.003	44878
529.213	44996
530.425	44832
531.635	44718
532.845	44771
534.056	44630
535.265	44660
536.474	44657
537.685	44622
538.893	44560
540.102	44494
541.31	44625
542.52	44675
543.728	44508
544.936	44513
546.143	44586
547.351	44504
548.56	44595
549.767	44418
550.973	44453
552.18	44353
553.387	44426
554.594	44435
555.8	44266
557.006	44404
558.212	44454
559.418	44486
560.623	44434
561.828	44422
563.035	44398
564.239	44360
565.444	44448
566.648	44430
567.853	44436
569.057	44225
570.26	44370
571.464	44348
572.667	44515
573.871	44227
575.074	44315
576.277	44549
577.479	44403
578.682	44391
579.884	44215
581.086	44136
582.288	44221
583.49	44349
584.691	44296
585.893	44354
587.094	44279
588.295	44340
589.496	44254
590.696	44145
591.897	43905
593.095	44262
594.296	44124
595.495	44267
596.695	44197
597.894	44270
599.094	44202
600.293	44331
601.49	44117
602.689	44402
603.888	44422
605.086	44351
606.284	44415
607.482	44166
608.678	44252
609.876	44200
611.073	44488
612.27	44390
613.466	44343
614.663	44311
615.859	44355
617.056	44216
618.251	44342
619.447	44350
620.643	44293
621.837	44360
623.032	44487
624.228	44380
625.423	44393
626.616	44454
627.811	44394
629.004	44617
630.199	44474
631.393	44581
632.585	44615
633.779	44611
634.973	44411
636.165	44547
637.358	44450
638.55	44503
639.743	44627
640.934	44375
642.126	44515
643.319	44324
644.509	44470
645.701	44514
646.892	44309
648.083	44238
649.273	44411
650.464	44169
651.654	44261
652.845	44002
654.034	44154
655.224	44242
656.413	43909
657.602	44124
658.792	44045
659.98	43864
661.169	43810
662.357	43753
663.547	43438
664.734	43762
665.921	43690
667.11	43582
668.297	43573
669.484	43487
670.672	43346
671.858	43682
673.044	43235
674.232	43091
675.418	43023
676.603	43378
677.79	43024
678.976	43114
680.161	42945
681.347	42849
682.532	42726
683.716	42660
684.901	42871
686.086	42732
687.27	42593
688.454	42649
689.638	42465
690.821	42499
692.006	42453
693.189	42258
694.372	42348
695.555	42332
696.737	42216
697.919	42207
699.103	42344
700.285	42067
701.467	42029
702.648	42211
703.83	42074
705.011	42060
706.192	42078
707.373	41909
708.553	41970
709.734	41880
710.916	41718
712.096	41864
713.276	41963
714.455	41664
715.635	41834
716.814	41650
717.994	41812
719.173	41658
720.351	41712
721.53	41680
722.709	41733
723.887	41625
725.065	41401
726.243	41506
727.419	41381
728.597	41415
729.774	41520
730.951	41363
732.128	41245
733.305	41321
734.482	41293
735.658	41151
736.834	41169
738.01	41044
739.185	40832
740.361	40941
741.536	41048
742.711	40889
743.887	40881
745.06	40702
746.235	40700
747.41	40693
748.584	40750
749.758	40466
750.931	40469
752.105	40465
753.278	40421
754.452	40220
755.624	40265
756.797	40093
757.97	40056
759.141	40066
760.314	39976
761.486	39886
762.659	40113
763.829	39823
765.001	39691
766.173	39607
767.343	39528
768.514	39521
769.684	39556
770.855	39446
772.026	39285
773.195	39145
774.365	39386
775.534	39062
776.704	39157
777.874	38937
779.042	39110
780.212	38966
781.38	38995
782.549	38751
783.716	38822
784.885	38736
786.052	38765
787.221	38783
788.388	38840
789.556	38493
790.722	38431
791.89	38514
793.056	38119
794.223	38374
795.389	38402
796.554	38305
797.721	38358
798.886	38192
800.053	38234
801.218	38041
802.382	38122
803.548	38193
804.712	38054
805.877	38095
807.042	38064
808.206	38098
809.369	37937
810.534	37970
811.697	38024
812.86	37986
814.025	37940
815.187	38159
816.35	37763
817.512	37908
818.676	37609
819.837	37775
820.999	37675
822.161	37730
823.324	37547
824.485	37754
825.646	37740
826.807	37761
827.967	37677
829.129	37581
830.29	37605
831.45	37657
832.61	37529
833.77	37449
834.929	37423
836.089	37384
837.249	37567
838.408	37260
839.567	37286
840.726	37306
841.885	37215
843.043	37205
844.201	37143
845.359	37162
846.517	37153
847.675	37105
848.832	36987
849.989	37071
851.146	36996
852.303	36838
853.46	36790
854.617	36917
855.773	37097
856.929	36816
858.085	36754
859.241	36815
860.397	36593
861.552	36478
862.708	36315
863.863	36437
865.018	36395
866.171	36357
867.326	36308
868.48	36265
869.634	36130
870.788	36232
871.942	36194
873.096	35954
874.248	36065
875.402	36107
876.555	35918
877.708	35828
878.861	35903
880.012	35777
881.164	35675
882.317	35623
883.469	35402
884.619	35205
885.771	35304
886.923	35056
888.074	34972
889.224	34971
890.375	34741
891.526	34791
892.675	34580
893.826	34627
894.976	34717
896.125	34581
897.275	34580
898.424	34372
899.573	34346
900.722	34305
901.871	34188
903.019	34180
904.168	34035
905.315	33873
906.464	33946
907.611	33887
908.759	33836
909.907	33644
911.054	33801
912.201	33683
913.348	33486
914.495	33440
915.641	33502
916.788	33427
917.933	33330
919.08	33511
920.225	33316
921.371	33324
922.516	33214
923.66	33253
924.806	33141
925.95	33081
927.096	33029
928.24	32977
929.383	33147
930.528	32926
931.671	32960
932.816	33011
933.959	32809
935.102	32832
936.246	32807
937.388	32859
938.53	32819
939.674	32832
940.816	32651
941.957	32638
943.099	32561
944.242	32577
945.383	32550
946.524	32508
947.665	32462
948.807	32375
949.947	32636
951.088	32444
952.228	32467
953.369	32402
954.509	32413
955.649	32252
956.788	32354
957.927	32104
959.067	32150
960.207	32063
961.346	32104
962.484	32094
963.623	32019
964.761	32063
965.899	32075
967.037	31938
968.174	31847
969.312	31694
970.449	31710
971.587	31852
972.725	31692
973.862	31682
974.998	31450
976.135	31501
977.271	31517
978.407	31392
979.543	31179
980.679	31284
981.815	31170
982.949	31029
984.084	31047
985.219	31237
986.354	31039
987.489	31010
988.624	30871
989.758	30860
990.892	30819
992.026	30838
993.16	30696
994.294	30656
995.426	30740
996.559	30698
997.693	30730
998.826	30510
999.959	30510
1001.09	30430
1002.22	30419
1003.35	30414
1004.49	30181
1005.62	30219
1006.75	30124
1007.88	30206
1009.01	30230
1010.14	29923
1011.27	30153
1012.4	29987
1013.54	30034
1014.67	29975
1015.79	29947
1016.93	29842
1018.06	29902
1019.18	29790
1020.31	29957
1021.44	29854
1022.57	29701
1023.7	29817
1024.83	29677
1025.96	29585
1027.09	29559
1028.21	29688
1029.34	29546
1030.47	29518
1031.6	29444
1032.72	29548
1033.85	29385
1034.98	29487
1036.1	29443
1037.23	29354
1038.36	29368
1039.48	29307
1040.61	29283
1041.73	29304
1042.86	29197
1043.99	29448
1045.11	29358
1046.24	29311
1047.36	29166
1048.48	29123
1049.61	29210
1050.73	29108
1051.86	29017
1052.98	28968
1054.11	28954
1055.23	28955
1056.35	28991
1057.48	28860
1058.6	28673
1059.72	28779
1060.84	28655
1061.97	28714
1063.09	28698
1064.21	28540
1065.33	28540
1066.46	28466
1067.58	28538
1068.7	28360
1069.82	28213
1070.94	28172
1072.06	28164
1073.18	28163
1074.3	28103
1075.42	28051
1076.54	27985
1077.66	27943
1078.78	27846
1079.9	27815
1081.02	27731
1082.14	27881
1083.26	27609
1084.38	27529
1085.5	27532
1086.61	27438
1087.73	27494
1088.85	27357
1089.97	27345
1091.09	27357
1092.2	27082
1093.32	27081
1094.44	26966
1095.55	26857
1096.67	26817
1097.79	26795
1098.9	26848
1100.02	26748
1101.14	26794
1102.25	26490
1103.37	26549
1104.48	26352
1105.6	26440
1106.71	26493
1107.83	26410
1108.94	26238
1110.06	26321
1111.17	26248
1112.29	26112
1113.4	26189
1114.52	26085
1115.63	26140
1116.74	26049
1117.86	25951.7
1118.97	25972.4
1120.08	25846
1121.2	25839.7
1122.31	25784.4
1123.42	25920.1
1124.53	25692.8
1125.64	25726.4
1126.76	25748.1
1127.87	25735.8
1128.98	25636.5
1130.09	25458.1
1131.2	25465.8
1132.31	25512.5
1133.42	25648.2
1134.53	25357.9
1135.65	25505.5
1136.75	25362.2
1137.87	25337.9
1138.98	25356.6
1140.08	25367.3
1141.19	25401.9
1142.3	25283.6
1143.41	25230.3
1144.52	25158
1145.63	25094.6
1146.74	25080.3
1147.85	25058
1148.96	25111.7
1150.06	25077.4
1151.17	24919
1152.28	25000.7
1153.39	24966.7
1154.5	24930.1
1155.6	24805.2
1156.71	24829.4
1157.82	24920.3
1158.92	24728.9
1160.03	24711.7
1161.14	24586
1162.24	24584.7
1163.35	24438.5
1164.45	24437.3
1165.56	24349.5
1166.66	24348.4
1167.77	24412.4
1168.88	24267.3
1169.98	24235
1171.08	24138.5
1172.19	24143.6
1173.29	24100.7
1174.4	24038.1
1175.5	23864.3
1176.6	23887.4
1177.71	23824.3
1178.81	23763.4
1179.91	23710.6
1181.02	23578.2
1182.12	23599.6
1183.22	23583.3
1184.33	23409.1
1185.43	23377.9
1186.53	23327.5
1187.63	23319.7
1188.73	23320.8
1189.84	23283.1
1190.94	23109.2
1192.04	23094.1
1193.14	22980.2
1194.24	22913
1195.34	22941.2
1196.44	22851.7
1197.54	22703.8
1198.64	22697.5
1199.74	22695.9
1200.84	22549.3
1201.94	22501.6
1203.04	22433.4
1204.14	22326.8
1205.24	22347.3
1206.34	22288.9
1207.44	22147.1
1208.54	22126.3
1209.63	22120.3
1210.73	22029.6
1211.83	21998.2
1212.93	21905.1
1214.03	21814.2
1215.12	21740.8
1216.22	21703.9
1217.32	21653.3
1218.42	21611.3
1219.51	21606.6
1220.61	21589.9
1221.71	21513.1
1222.8	21426.4
1223.9	21387.3
1224.99	21391.9
1226.09	21222.8
1227.18	21248.3
1228.28	21259.2
1229.38	21169.4
1230.47	21095.8
1231.57	21160.4
1232.66	21039.8
1233.75	21040.1
1234.85	20999.7
1235.94	20985.9
1237.04	20917.4
1238.13	20865.1
1239.22	20763.5
1240.32	20710
1241.41	20787.5
1242.5	20797.3
1243.6	20654.7
1244.69	20621.7
1245.78	20601.1
1246.87	20592.4
1247.97	20629.4
1249.06	20606.6
1250.15	20514.6
1251.24	20475.9
1252.34	20418.7
1253.43	20323.8
1254.52	20402.9
1255.61	20375.3
1256.7	20326.3
1257.79	20401.1
1258.88	20314.9
1259.97	20281.3
1261.06	20267.3
1262.15	20324.6
1263.24	20263.3
1264.33	20212.2
1265.18	20278
1266.28	20177.5
1267.37	20357.1
1268.47	20198.6
1269.56	20104.2
1270.65	20152.8
1271.75	20057.3
1272.84	19941.9
1273.94	19945.4
1275.03	20011
1276.12	19867.5
1277.21	19947.1
1278.31	19845.7
1279.4	19898.2
1280.49	19800.8
1281.58	19782.3
1282.68	19651.9
1283.77	19607.5
1284.86	19629
1285.95	19568.6
1287.04	19538.1
1288.13	19631.7
1289.23	19529.2
1290.32	19504.8
1291.41	19428.4
1292.5	19508.9
1293.59	19505.5
1294.68	19297
1295.77	19227.6
1296.86	19332.2
1297.95	19222.7
1299.04	19202.3