File: muestras/goma/CO_14.txt
#Acq. time (s)=	15
#Accumulations=	3
#Range (cm-¹)=	50...1300
#Windows=	2
#Autofocus=	Off
#AutoExposure=	Off
#Spike filter=	Multiple accum.
#Delay time (s)=	0
#Binning=	1
#Readout mode=	Signal
#DeNoise=	Off
#ICS correction=	Off
#Dark correction=	Off
#Inst. Process=	Off
#Instrument=	LabRAM HR Evol
#Detector=	Syncerity OE
#Objective=	x100_VIS
#Grating=	600 (500nm)
#ND Filter=	10%
#Laser=	633nm_Edge
#Hole=	100.021
#Range=	Visible
#Project=	Omar
#Sample=	CM
#Site=	11-05-23
#Title=	CO
#Remark=	ch1
#Date=	11.05.2023 16:38
#Acquired=	11.05.2023 16:38:34
50.1258	1338
51.4176	1330
52.7092	1424
54.0021	1454
55.2932	1488
56.5841	1807
57.8748	2097
59.1669	2450
60.4572	2806
61.7472	2950
63.0371	3008
64.3283	2994
65.6177	3078
66.907	3000
68.196	3059
69.4848	3078
70.7734	3100
72.0633	3106
73.3515	3191
74.6395	3155
75.9272	3182
77.2148	3238
78.5021	3181
79.7892	3220
81.0761	3233
82.3644	3182
83.6509	3252
84.9371	3225
86.2232	3254
87.5091	3246
88.7947	3324
90.0802	3320
91.3654	3310
92.6504	3398
93.9352	3326
95.2198	3336
96.5042	3404
97.7884	3394
99.0724	3439
100.356	3394
101.64	3458
102.923	3455
104.206	3421
105.489	3490
106.772	3482
108.054	3496
109.337	3526
110.619	3552
111.901	3542
113.182	3531
114.464	3528
115.745	3607
117.024	3554
118.305	3588
119.586	3612
120.866	3628
122.147	3640
123.426	3670
124.706	3640
125.986	3660
127.264	3704
128.543	3685
129.822	3740
131.101	3770
132.379	3734
133.657	3769
134.934	3791
136.212	3840
137.49	3896
138.767	3922
140.043	3956
141.32	3946
142.597	3961
143.873	3944
145.148	3867
146.425	3940
147.701	3856
148.977	3897
150.251	3910
151.526	3863
152.801	3902
154.075	3964
155.35	3985
156.624	3890
157.897	3932
159.171	3984
160.445	3960
161.717	3968
162.991	3928
164.264	4006
165.536	4046
166.809	4012
168.081	3940
169.353	4124
170.625	4056
171.895	4024
173.167	4036
174.437	4096
175.709	4100
176.98	4120
178.25	4135
179.521	4120
180.79	4068
182.06	4179
183.329	4188
184.599	4147
185.867	4199
187.137	4232
188.405	4219
189.674	4196
190.942	4245
192.21	4282
193.477	4248
194.746	4300
196.012	4292
197.279	4309
198.547	4326
199.813	4314
201.08	4338
202.346	4398
203.613	4368
204.878	4413
206.143	4424
207.409	4436
208.674	4422
209.938	4449
211.204	4477
212.468	4472
213.732	4476
214.997	4528
216.26	4531
217.523	4510
218.788	4602
220.051	4562
221.313	4602
222.577	4566
223.839	4608
225.101	4628
226.363	4600
227.626	4566
228.887	4669
230.149	4630
231.41	4713
232.672	4714
233.932	4736
235.193	4668
236.453	4701
237.714	4700
238.974	4760
240.233	4786
241.493	4854
242.752	4826
244.011	4861
245.271	4880
246.529	4880
247.788	4876
249.046	4861
250.304	4841
251.561	4836
252.819	4904
254.076	4828
255.333	4910
256.591	4920
257.848	4929
259.105	4892
260.361	4884
261.617	4888
262.873	4915
264.128	4914
265.384	4946
266.639	4896
267.894	4910
269.149	4876
270.404	5008
271.658	4953
272.912	4968
274.166	4920
275.42	5019
276.674	4976
277.927	4998
279.18	5042
280.433	5034
281.686	5078
282.939	5040
284.19	5018
285.442	5136
286.694	5128
287.946	5126
289.197	5150
290.449	5134
291.7	5149
292.951	5259
294.2	5214
295.451	5160
296.701	5269
297.951	5238
299.201	5245
300.451	5272
301.699	5300
302.949	5288
304.198	5361
305.447	5294
306.696	5314
307.943	5278
309.191	5408
310.439	5342
311.687	5326
312.933	5352
314.181	5385
315.428	5431
316.676	5420
317.921	5394
319.168	5368
320.414	5410
321.659	5462
322.905	5414
324.151	5378
325.396	5467
326.641	5438
327.887	5415
329.13	5492
330.375	5448
331.62	5528
332.863	5513
334.108	5406
335.35	5503
336.594	5489
337.837	5516
339.08	5520
340.323	5548
341.565	5558
342.808	5614
344.049	5550
345.292	5564
346.533	5578
347.775	5574
349.016	5582
350.257	5586
351.497	5601
352.739	5634
353.979	5592
355.219	5682
356.459	5613
357.699	5683
358.938	5675
360.178	5682
361.417	5690
362.657	5653
363.895	5725
365.133	5672
366.372	5647
367.609	5730
368.848	5720
370.085	5723
371.322	5697
372.561	5714
373.797	5652
375.033	5656
376.271	5705
377.507	5696
378.743	5746
379.98	5670
381.215	5754
382.45	5717
383.686	5690
384.921	5712
386.156	5766
387.39	5750
388.626	5752
389.86	5824
391.093	5786
392.327	5804
393.562	5768
394.795	5809
396.028	5771
397.261	5792
398.493	5808
399.727	5890
400.959	5896
402.191	5857
403.423	5796
404.655	5876
405.886	5957
407.119	5896
408.35	5967
409.581	5957
410.811	6021
412.042	5937
413.272	6028
414.502	5988
415.732	6009
416.963	6043
418.192	6018
419.421	6107
420.65	6047
421.879	6045
423.108	6030
424.336	6083
425.565	6094
426.793	6089
428.02	6105
429.248	6132
430.476	6135
431.703	6129
432.93	6213
434.157	6134
435.383	6085
436.61	6182
437.836	6086
439.062	6182
440.287	6153
441.512	6140
442.738	6143
443.963	6143
445.188	6134
446.413	6171
447.638	6154
448.863	6125
450.087	6182
451.31	6137
452.534	6185
453.757	6096
454.981	6149
456.204	6202
457.427	6122
458.649	6136
459.872	6137
461.094	6152
462.317	6113
463.539	6120
464.759	6117
465.981	6087
467.203	6167
468.424	6171
469.644	6158
470.865	6090
472.086	6132
473.306	6193
474.525	6154
475.746	6226
476.966	6195
478.184	6228
479.404	6165
480.623	6177
481.841	6232
483.06	6186
484.279	6128
485.496	6226
486.715	6253
487.932	6236
489.15	6268
490.368	6192
491.584	6244
492.802	6270
494.017	6296
495.235	6220
496.45	6249
497.667	6200
498.883	6214
500.098	6294
501.315	6242
502.529	6172
503.745	6256
504.959	6267
506.174	6303
507.388	6245
508.603	6276
509.817	6254
511.031	6268
512.244	6245
513.457	6262
514.671	6178
515.884	6223
517.097	6228
518.309	6227
519.523	6170
520.734	6189
521.946	6204
523.158	6244
524.37	6194
525.58	6128
526.793	6205
528.003	6212
529.213	6151
530.425	6160
531.635	6088
532.845	6111
534.056	6087
535.265	6155
536.474	6167
537.685	6145
538.893	6115
540.102	6051
541.31	6122
542.52	6114
543.728	6064
544.936	6060
546.143	6093
547.351	6137
548.56	6046
549.767	6128
550.973	6074
552.18	6065
553.387	6160
554.594	6076
555.8	6139
557.006	6092
558.212	6072
559.418	6101
560.623	6060
561.828	6059
563.035	6120
564.239	6040
565.444	6124
566.648	6084
567.853	6090
569.057	6062
570.26	6106
571.464	6082
572.667	6040
573.871	6074
575.074	6081
576.277	6047
577.479	5986
578.682	6064
579.884	6046
581.086	6081
582.288	6059
583.49	6089
584.691	6020
585.893	6073
587.094	6027
588.295	5968
589.496	6108
590.696	6043
591.897	6068
593.095	6093
594.296	6080
595.495	6119
596.695	6098
597.894	6054
599.094	6059
600.293	6055
601.49	6077
602.689	6065
603.888	6049
605.086	5984
606.284	6014
607.482	6076
608.678	6036
609.876	6134
611.073	6104
612.27	6090
613.466	6077
614.663	6044
615.859	6085
617.056	6149
618.251	6070
619.447	6164
620.643	6000
621.837	6058
623.032	6096
624.228	6094
625.423	6143
626.616	6088
627.811	6070
629.004	6102
630.199	6122
631.393	6118
632.585	6102
633.779	6154
634.973	6062
636.165	6133
637.358	6158
638.55	6092
639.743	6168
640.934	6154
642.126	6110
643.319	6158
644.509	6122
645.701	6133
646.892	6077
648.083	6090
649.273	6062
650.464	6052
651.654	6070
652.845	6081
654.034	6104
655.224	6075
656.413	6106
657.602	6022
658.792	6037
659.98	6010
661.169	6014
662.357	6008
663.547	5981
664.734	6018
665.921	5996
667.11	5961
668.297	5998
669.484	6010
670.672	5974
671.858	5967
673.044	5961
674.232	5918
675.418	5936
676.603	5952
677.79	5882
678.976	5933
680.161	5897
681.347	5864
682.532	5922
683.716	5888
684.901	5894
686.086	5851
687.27	5858
688.454	5854
689.638	5849
690.821	5750
692.006	5812
693.189	5842
694.372	5832
695.555	5840
696.737	5782
697.919	5834
699.103	5802
700.285	5758
701.467	5787
702.648	5773
703.83	5757
705.011	5790
706.192	5754
707.373	5820
708.553	5752
709.734	5771
710.916	5771
712.096	5745
713.276	5767
714.455	5722
715.635	5802
716.814	5726
717.994	5726
719.173	5743
720.351	5694
721.53	5718
722.709	5763
723.887	5736
725.065	5701
726.243	5700
727.419	5720
728.597	5657
729.774	5698
730.951	5694
732.128	5666
733.305	5661
734.482	5632
735.658	5673
736.834	5678
738.01	5740
739.185	5634
740.361	5637
741.536	5609
742.711	5668
743.887	5588
745.06	5642
746.235	5504
747.41	5609
748.584	5541
749.758	5575
750.931	5486
752.105	5526
753.278	5516
754.452	5593
755.624	5412
756.797	5552
757.97	5528
759.141	5398
760.314	5508
761.486	5436
762.659	5469
763.829	5521
765.001	5441
766.173	5427
767.343	5416
768.514	5420
769.684	5434
770.855	5412
772.026	5411
773.195	5374
774.365	5398
775.534	5352
776.704	5433
777.874	5393
779.042	5296
780.212	5338
781.38	5342
782.549	5416
783.716	5411
784.885	5312
786.052	5338
787.221	5296
788.388	5353
789.556	5314
790.722	5329
791.89	5247
793.056	5301
794.223	5249
795.389	5200
796.554	5341
797.721	5318
798.886	5226
800.053	5282
801.218	5264
802.382	5223
803.548	5282
804.712	5201
805.877	5252
807.042	5225
808.206	5203
809.369	5194
810.534	5180
811.697	5213
812.86	5192
814.025	5236
815.187	5145
816.35	5189
817.512	5209
818.676	5124
819.837	5190
820.999	5189
822.161	5186
823.324	5199
824.485	5154
825.646	5234
826.807	5178
827.967	5156
829.129	5125
830.29	5180
831.45	5126
832.61	5162
833.77	5076
834.929	5170
836.089	5146
837.249	5181
838.408	5140
839.567	5134
840.726	5122
841.885	5066
843.043	5120
844.201	5141
845.359	5097
846.517	5118
847.675	5104
848.832	5062
849.989	5060
851.146	5072
852.303	5122
853.46	5071
854.617	5040
855.773	5058
856.929	5034
858.085	5064
859.241	4990
860.397	5026
861.552	5091
862.708	5041
863.863	5020
865.018	5018
866.171	5030
867.326	5065
868.48	4996
869.634	4960
870.788	4963
871.942	5008
873.096	5018
874.248	5004
875.402	4929
876.555	4954
877.708	4985
878.861	4972
880.012	4939
881.164	4923
882.317	4868
883.469	4862
884.619	4857
885.771	4859
886.923	4840
888.074	4820
889.224	4828
890.375	4794
891.526	4799
892.675	4768
893.826	4809
894.976	4722
896.125	4735
897.275	4746
898.424	4758
899.573	4723
900.722	4671
901.871	4713
903.019	4696
904.168	4628
905.315	4683
906.464	4718
907.611	4625
908.759	4638
909.907	4614
911.054	4646
912.201	4643
913.348	4592
914.495	4685
915.641	4626
916.788	4583
917.933	4610
919.08	4566
920.225	4599
921.371	4582
922.516	4586
923.66	4581
924.806	4593
925.95	4548
927.096	4556.5
928.24	4555
929.383	4569
930.528	4503
931.671	4542
932.816	4488
933.959	4534
935.102	4464
936.246	4498
937.388	4505
938.53	4534
939.674	4531
940.816	4456
941.957	4472
943.099	4462
944.242	4502
945.383	4449
946.524	4445
947.665	4474
948.807	4448
949.947	4422
951.088	4426
952.228	4479
953.369	4447
954.509	4484
955.649	4420
956.788	4424
957.927	4457
959.067	4368
960.207	4409
961.346	4398
962.484	4394
963.623	4399
964.761	4386
965.899	4395
967.037	4409
968.174	4383
969.312	4336
970.449	4348
971.587	4365
972.725	4383
973.862	4341
974.998	4374
976.135	4326
977.271	4350
978.407	4328
979.543	4324
980.679	4323
981.815	4314
982.949	4298
984.084	4293
985.219	4283
986.354	4293
987.489	4266
988.624	4252
989.758	4187
990.892	4280
992.026	4209
993.16	4214
994.294	4266
995.426	4232
996.559	4196
997.693	4212
998.826	4262
999.959	4112
1001.09	4182
1002.22	4191
1003.35	4186
1004.49	4167
1005.62	4140
1006.75	4164
1007.88	4146
1009.01	4104
1010.14	4172
1011.27	4093
1012.4	4162
1013.54	4122
1014.67	4084
1015.79	4132
1016.93	4103
1018.06	4048
1019.18	4117
1020.31	4099
1021.44	4122
1022.57	4100
1023.7	4074
1024.83	4118
1025.96	4082
1027.09	4082
1028.21	4058
1029.34	4047
1030.47	4049
1031.6	4050
1032.72	4032
1033.85	4047
1034.98	4055
1036.1	4027
1037.23	4004
1038.36	3982
1039.48	4088
1040.61	3998
1041.73	4054
1042.86	4078
1043.99	4014
1045.11	4007
1046.24	4013
1047.36	4053
1048.48	4033
1049.61	4017
1050.73	3972
1051.86	4020
1052.98	3993
1054.11	4010
1055.23	3996
1056.35	3970
1057.48	3979
1058.6	3962
1059.72	3990
1060.84	3956
1061.97	3934
1063.09	3938
1064.21	3918
1065.33	3910
1066.46	3955
1067.58	3927
1068.7	3923
1069.82	3910
1070.94	3849
1072.06	3830
1073.18	3908
1074.3	3889
1075.42	3865
1076.54	3843
1077.66	3838
1078.78	3867
1079.9	3845
1081.02	3797
1082.14	3797
1083.26	3824
1084.38	3782
1085.5	3821
1086.61	3722
1087.73	3764
1088.85	3754
1089.97	3728
1091.09	3710
1092.2	3710
1093.32	3708
1094.44	3737
1095.55	3749
1096.67	3697
1097.79	3696
1098.9	3682
1100.02	3691
1101.14	3666
1102.25	3645
1103.37	3678
1104.48	3674
1105.6	3584
1106.71	3595
1107.83	3652
1108.94	3612
1110.06	3628
1111.17	3556
1112.29	3543
1113.4	3676
1114.52	3582
1115.63	3568
1116.74	3632
1117.86	3603.07
1118.97	3514.14
1120.08	3565.21
1121.2	3573.29
1122.31	3543.36
1123.42	3564.43
1124.53	3559.5
1125.64	3508.57
1126.76	3525.64
1127.87	3540.72
1128.98	3556.79
1130.09	3553.86
1131.2	3585.93
1132.31	3598
1133.42	3567.07
1134.53	3540.15
1135.65	3608.22
1136.75	3481.29
1137.87	3530.36
1138.98	3546.43
1140.08	3499.5
1141.19	3513.58
1142.3	3522.65
1143.41	3512.72
1144.52	3506.79
1145.63	3535.86
1146.74	3528.93
1147.85	3456.01
1148.96	3557.08
1150.06	3525.15
1151.17	3463.22
1152.28	3512.29
1153.39	3549.36
1154.5	3530.44
1155.6	3527.51
1156.71	3473.58
1157.82	3477.65
1158.92	3538.72
1160.03	3477.79
1161.14	3468.86
1162.24	3456.94
1163.35	3469.01
1164.45	3469.08
1165.56	3535.15
1166.66	3412.22
1167.77	3421.29
1168.88	3506.37
1169.98	3486.44
1171.08	3502.51
1172.19	3465.58
1173.29	3409.65
1174.4	3474.72
1175.5	3422.8
1176.6	3461.87
1177.71	3448.94
1178.81	3436.01
1179.91	3406.08
1181.02	3359.15
1182.12	3422.23
1183.22	3431.3
1184.33	3357.37
1185.43	3390.44
1186.53	3359.51
1187.63	3359.58
1188.73	3386.66
1189.84	3339.73
1190.94	3377.8
1192.04	3327.87
1193.14	3372.94
1194.24	3335.01
1195.34	3361.08
1196.44	3337.16
1197.54	3364.23
1198.64	3331.3
1199.74	3339.37
1200.84	3291.44
1201.94	3338.51
1203.04	3333.59
1204.14	3302.66
1205.24	3291.73
1206.34	3306.8
1207.44	3249.87
1208.54	3280.94
1209.63	3273.02
1210.73	3259.09
1211.83	3263.16
1212.93	3283.23
1214.03	3246.3
1215.12	3293.37
1216.22	3212.45
1217.32	3212.52
1218.42	3244.59
1219.51	3239.66
1220.61	3222.73
1221.71	3171.8
1222.8	3240.88
1223.9	3142.95
1224.99	3225.02
1226.09	3215.09
1227.18	3205.16
1228.28	3193.23
1229.38	3189.3
1230.47	3225.38
1231.57	3195.45
1232.66	3194.52
1233.75	3145.59
1234.85	3120.66
1235.94	3193.73
1237.04	3136.81
1238.13	3160.88
1239.22	3161.95
1240.32	3180.02
1241.41	3141.09
1242.5	3159.16
1243.6	3169.24
1244.69	3112.31
1245.78	3141.38
1246.87	3128.45
1247.97	3123.52
1249.06	3118.59
1250.15	3101.67
1251.24	3163.74
1252.34	3131.81
1253.43	3178.88
1254.52	3151.95
1255.61	3147.02
1256.7	3132.1
1257.79	3095.17
1258.88	3122.24
1259.97	3101.31
1261.06	3094.38
1262.15	3157.45
1263.24	3135.53
1264.33	3160.6
1265.18	3268.12
1266.28	4445.18
1267.37	4450.23
1268.47	3109.29
1269.56	3104.35
1270.65	3111.41
1271.75	3100.47
1272.84	3035.53
1273.94	3104.59
1275.03	3065.65
1276.12	3100.71
1277.21	3105.76
1278.31	3060.82
1279.4	3131.88
1280.49	3052.94
1281.58	3106
1282.68	3079.06
1283.77	3112.12
1284.86	3113.18
1285.95	3046.23
1287.04	3113.29
1288.13	3110.35
1289.23	3017.41
1290.32	2994.47
1291.41	3065.53
1292.5	3056.59
1293.59	3047.65
1294.68	3064.71
1295.77	3023.76
1296.86	2980.82
1297.95	3027.88
1299.04	3032.94