File: muestras/tallo/1/Organic_04.txt
#Acq. time (s)=	10
#Accumulations=	1
#Range (cm-¹)=	100...3000
#Windows=	3
#Autofocus=	Off
#AutoExposure=	Off
#Spike filter=	Off
#Delay time (s)=	0
#Binning=	1
#Readout mode=	Signal
#DeNoise=	Off
#ICS correction=	Off
#Dark correction=	Off
#Inst. Process=	Off
#Instrument=	LabRAM HR Evol
#Detector=	Syncerity OE
#Objective=	x100_VIS
#Grating=	600 (500nm)
#ND Filter=	5%
#Laser=	633nm_Edge
#Hole=	74.97
#Range=	Visible
#Project=	Omar
#Sample=	26-06-23
#Site=	1
#Title=	Organic
#Remark=
#Date=	26.06.2023 15:52
#Acquired=	26.06.2023 15:52:17
101.018	2394
103.586	2392
106.152	2342
108.717	2422
111.281	2310
113.845	2338
116.407	2380
118.969	2362
121.53	2376
124.09	2356
126.649	2364
129.207	2380
131.765	2354
134.321	2428
136.877	2398
139.432	2428
141.985	2426
144.538	2358
147.09	2366
149.641	2388
152.191	2422
154.741	2372
157.289	2442
159.837	2316
162.385	2334
164.93	2336
167.476	2408
170.019	2332
172.562	2404
175.105	2390
177.646	2380
180.188	2342
182.727	2344
185.266	2358
187.804	2372
190.342	2396
192.878	2434
195.413	2372
197.948	2422
200.481	2344
203.014	2374
205.546	2432
208.077	2398
210.608	2444
213.137	2418
215.666	2382
218.194	2460
220.721	2396
223.247	2450
225.772	2432
228.295	2450
230.819	2456
233.342	2392
235.864	2404
238.384	2440
240.904	2402
243.423	2430
245.941	2440
248.46	2420
250.975	2402
253.492	2406
256.006	2436
258.519	2430
261.033	2414
263.545	2458
266.057	2468
268.567	2414
271.076	2390
273.585	2316
276.094	2452
278.601	2430
281.107	2406
283.612	2408
286.116	2436
288.62	2442
291.123	2406
293.625	2484
296.126	2516
298.626	2476
301.126	2454
303.625	2450
306.122	2454
308.62	2472
311.114	2484
313.61	2464
316.105	2454
318.599	2478
321.09	2536
323.583	2498
326.073	2524
328.563	2486
331.053	2470
333.541	2422
336.029	2496
338.515	2484
341.001	2550
343.486	2512
345.97	2496
348.453	2500
350.936	2524
353.418	2508
355.898	2568
358.378	2536
360.858	2504
363.336	2496
365.813	2542
368.29	2482
370.766	2560
373.241	2560
375.715	2550
378.188	2602
380.66	2594
383.132	2590
385.603	2548
388.072	2570
390.541	2556
393.01	2570
395.477	2520
397.943	2570
400.409	2598
402.875	2636
405.338	2640
407.802	2594
410.263	2672
412.725	2594
415.185	2674
417.646	2686
420.104	2700
422.564	2732
425.02	2700
427.477	2762
429.933	2730
432.388	2752
434.841	2704
437.294	2788
439.748	2780
442.199	2806
444.65	2778
447.1	2778
449.549	2698
451.997	2726
454.445	2788
456.891	2800
459.337	2768
461.782	2760
464.227	2748
466.669	2756
469.112	2906
471.554	2888
473.995	2876
476.434	2848
478.874	2884
481.312	2880
483.749	2888
486.186	2918
488.622	2870
491.057	2928
493.491	2908
495.925	2934
498.357	2974
500.789	2990
503.221	3006
505.65	3000
508.079	2990
510.509	3052
512.936	3044
515.363	2994
517.789	2988
520.214	3048
522.638	3064
525.062	3084
527.485	3098
529.907	3088
532.328	3166
534.748	3132
537.168	3110
539.587	3102
542.005	3100
544.423	3046
546.838	3114
549.254	3192
551.669	3230
554.082	3214
556.496	3230
558.909	3246
561.319	3206
563.731	3296
566.14	3360
568.549	3268
570.957	3304
573.364	3272
575.771	3382
578.177	3408
580.581	3416
582.987	3480
585.39	3422
587.792	3440
590.193	3522
592.594	3498
594.996	3530
597.395	3554
599.793	3574
602.191	3636
604.588	3642
606.984	3636
609.378	3698
611.773	3800
614.167	3806
616.56	3800
618.953	3838
621.343	3884
623.734	4008
626.124	3948
628.512	4066
630.901	3922
633.289	4036
635.675	4082
638.061	4108
640.446	4238
642.831	4144
645.213	4214
647.595	4204
649.978	4316
652.359	4360
654.738	4346
657.117	4474
659.497	4352
661.875	4476
664.252	4450
666.628	4566
669.003	4444
671.378	4586
673.751	4580
676.124	4684
678.497	4732
680.868	4754
683.239	4786
685.609	4926
687.977	4802
690.346	4954
692.714	4906
695.081	5028
697.446	5026
699.812	5002
702.175	5040
704.539	5154
706.901	5232
709.264	5256
711.625	5294
713.986	5338
716.345	5344
718.705	5474
721.062	5480
723.419	5520
725.775	5618
728.132	5670
730.487	5634
732.841	5754
735.194	5888
737.546	5786
739.898	5906
742.249	5996
744.599	5950
746.949	6006
749.298	6078
751.646	6120
753.993	6228
756.34	6296
758.684	6286
761.029	6318
763.374	6394
765.716	6448
768.059	6484
770.401	6562
772.741	6582
775.082	6770
777.421	6698
779.76	6762
782.097	6734
784.434	6910
786.771	6936
789.106	6886
791.44	7046
793.775	7126
796.108	7242
798.44	7258
800.771	7312
803.102	7406
805.432	7488
807.761	7500
810.09	7506
812.417	7744
814.744	7698
817.071	7808
819.396	7888
821.721	7896
824.045	7940
826.367	7988
828.69	8262
831.012	8270
833.332	8268
835.653	8308
837.972	8560
840.29	8472
842.609	8574
844.925	8610
847.242	8740
849.557	8860
851.871	8856
854.186	8954
856.498	8956
858.81	9160
861.122	9138
863.434	9168
865.744	9280
868.053	9282
870.361	9356
872.669	9362
874.976	9548
877.282	9544
879.588	9670
881.893	9646
884.197	9720
886.5	9782
888.802	9710
891.104	9734
893.405	9852
895.706	9918
898.004	9948
900.303	10114
902.6	10062
904.898	10098
907.194	10092
909.49	10094
911.785	10220
914.08	10216
916.372	10266
918.666	10386
920.957	10442
923.248	10552
925.538	10598
927.828	10634
930.118	10594
932.406	10684
934.693	10748
936.979	10804
939.265	11112
941.55	11022
943.835	11128
946.118	11244
948.401	11182
950.682	11180
952.964	11214
955.245	11338
957.525	11514
959.803	11392
962.082	11454
964.36	11618
966.636	11614
968.913	11486
971.188	11609
973.463	11676
975.736	11718
978.009	11738
980.282	11640
982.554	11684
984.824	11800
987.095	11792
989.364	11880
991.633	11826
993.9	11956
996.167	11898
998.434	11944
1000.7	11900
1002.96	12078
1005.23	11954
1007.49	11992
1009.76	12190
1012.02	12008
1014.28	12128
1016.54	12288
1018.8	12222
1021.06	12140
1023.32	12110
1025.57	12272
1027.83	12378
1030.09	12314
1032.34	12404
1034.6	12476
1036.85	12570
1039.1	12450
1041.35	12424
1043.61	12454
1045.86	12632
1048.11	12588
1050.36	12600
1052.61	12550
1054.85	12782
1057.1	12690
1059.35	12522
1061.59	12672
1063.84	12676
1066.08	12478
1068.33	12596
1070.57	12588
1072.81	12578
1075.05	12550
1077.29	12582
1079.53	12396
1081.77	12496
1084.01	12428
1086.25	12440
1088.48	12526
1090.72	12436
1092.96	12374
1095.19	12182
1097.43	12270
1099.66	12188
1101.89	12166
1104.12	12188
1106.35	12210
1108.59	12154
1110.81	12094
1113.04	12064
1115.27	12194
1117.5	11874
1119.73	11950
1121.95	12026
1124.18	11866
1126.4	12060
1128.63	11888
1130.85	11846
1133.07	11936
1135.29	11878
1137.51	11842
1139.73	11840
1141.95	11806
1144.17	11762
1146.39	11748
1148.61	11792
1150.82	11758
1153.04	11806
1155.26	11708
1157.47	11624
1159.68	11708
1161.9	11688
1164.11	11572
1166.32	11566
1168.53	11510
1170.74	11388
1172.95	11448
1175.16	11380
1177.37	11294
1179.58	11242
1181.78	11174
1183.99	11108
1186.19	10996
1188.4	10884
1190.6	10840
1192.8	10864
1195.01	10794
1197.21	10698.5
1199.41	10628.2
1201.61	10647.8
1203.81	10513.6
1206.01	10502.5
1208.2	10475.4
1210.4	10381.1
1212.6	10204.1
1214.8	10163.7
1216.99	10135.8
1219.18	10243
1221.38	9990.6
1223.57	9959.72
1225.76	9969.65
1227.96	9893.47
1230.15	9904.94
1232.34	9859.16
1234.53	9717.55
1236.71	9757.97
1238.9	9642.93
1241.09	9586.6
1243.28	9500.04
1245.46	9416.97
1247.65	9470.56
1249.83	9432.46
1252.02	9438.77
1254.2	9302.96
1256.38	9270.91
1258.56	9231.8
1260.74	9182.62
1262.92	9175.05
1265.1	9155.47
1267.28	9135.2
1269.46	9054.92
1271.64	9029.78
1273.82	8892.18
1275.99	8935.64
1278.17	8903.34
1280.34	8878.18
1282.52	8787.71
1284.69	8736.75
1286.86	8740.13
1289.03	8645.63
1291.21	8603
1293.38	8505.18
1295.55	8590.83
1297.71	8438.98
1299.88	8434.39
1302.05	8421.29
1304.22	8383.35
1306.38	8346.14
1308.43	8194
1310.61	8202
1312.78	8062
1314.96	8070
1317.13	8028
1319.3	8038
1321.48	7892
1323.65	7956
1325.82	7728
1327.99	7708
1330.16	7632
1332.33	7720
1334.5	7652
1336.66	7626
1338.83	7408
1341	7414
1343.16	7304
1345.33	7402
1347.49	7316
1349.65	7302
1351.82	7294
1353.98	7218
1356.14	7056
1358.3	7076
1360.46	7114
1362.62	6948
1364.78	7040
1366.94	6818
1369.09	6872
1371.25	6880
1373.41	6728
1375.56	6726
1377.72	6740
1379.87	6762
1382.02	6676
1384.17	6608
1386.33	6640
1388.48	6594
1390.63	6504
1392.78	6478
1394.93	6380
1397.07	6434
1399.22	6468
1401.37	6374
1403.52	6222
1405.66	6190
1407.81	6198
1409.95	6250
1412.09	6190
1414.24	6178
1416.38	6122
1418.52	6094
1420.66	6108
1422.8	5982
1424.94	5994
1427.08	5966
1429.22	5824
1431.35	5934
1433.49	5848
1435.63	5858
1437.76	5788
1439.9	5828
1442.03	5702
1444.17	5626
1446.3	5722
1448.43	5670
1450.56	5656
1452.69	5594
1454.82	5714
1456.95	5566
1459.08	5536
1461.21	5554
1463.34	5514
1465.46	5458
1467.59	5444
1469.71	5446
1471.84	5400
1473.96	5358
1476.08	5360
1478.21	5294
1480.33	5410
1482.45	5380
1484.57	5288
1486.69	5274
1488.81	5192
1490.93	5272
1493.05	5200
1495.16	5168
1497.28	5198
1499.4	5066
1501.51	5114
1503.63	5108
1505.74	5040
1507.85	5138
1509.97	5002
1512.08	5008
1514.19	4926
1516.3	5008
1518.41	4858
1520.52	4844
1522.63	4972
1524.73	4872
1526.84	4798
1528.95	4852
1531.06	4758
1533.16	4742
1535.26	4662
1537.37	4730
1539.47	4782
1541.57	4706
1543.68	4740
1545.78	4662
1547.88	4648
1549.98	4574
1552.08	4578
1554.18	4582
1556.27	4532
1558.37	4660
1560.47	4528
1562.56	4494
1564.66	4592
1566.75	4490
1568.85	4480
1570.94	4458
1573.03	4462
1575.13	4422
1577.22	4512
1579.31	4416
1581.4	4284
1583.49	4408
1585.58	4368
1587.66	4394
1589.75	4376
1591.84	4394
1593.93	4346
1596.01	4290
1598.1	4332
1600.18	4272
1602.26	4262
1604.35	4356
1606.43	4284
1608.51	4238
1610.59	4292
1612.67	4244
1614.75	4250
1616.83	4332
1618.91	4146
1620.99	4208
1623.06	4170
1625.14	4238
1627.21	4224
1629.29	4198
1631.36	4150
1633.44	4232
1635.51	4094
1637.58	4214
1639.66	4128
1641.73	4146
1643.8	4114
1645.87	4036
1647.94	4052
1650	4092
1652.07	4104
1654.14	4174
1656.21	4016
1658.27	4012
1660.34	3968
1662.4	3960
1664.47	3932
1666.53	3932
1668.59	3954
1670.66	3900
1672.72	3914
1674.78	3892
1676.84	3914
1678.9	3886
1680.96	3798
1683.01	3872
1685.07	3814
1687.13	3850
1689.19	3864
1691.24	3828
1693.3	3796
1695.35	3786
1697.4	3780
1699.46	3760
1701.51	3734
1703.56	3734
1705.61	3808
1707.66	3728
1709.71	3684
1711.76	3700
1713.81	3674
1715.86	3682
1717.91	3638
1719.95	3708
1722	3564
1724.04	3714
1726.09	3712
1728.13	3650
1730.18	3570
1732.22	3560
1734.26	3626
1736.3	3678
1738.34	3588
1740.38	3576
1742.42	3620
1744.46	3600
1746.5	3562
1748.54	3508
1750.58	3534
1752.61	3596
1754.65	3530
1756.68	3616
1758.72	3520
1760.75	3470
1762.79	3522
1764.82	3478
1766.85	3486
1768.88	3532
1770.91	3434
1772.94	3484
1774.97	3464
1777	3630
1779.03	3466
1781.06	3472
1783.09	3462
1785.11	3462
1787.14	3418
1789.16	3442
1791.19	3482
1793.21	3450
1795.23	3376
1797.26	3450
1799.28	3430
1801.3	3392
1803.32	3430
1805.34	3466
1807.36	3398
1809.38	3366
1811.4	3416
1813.42	3314
1815.43	3346
1817.45	3368
1819.47	3344
1821.48	3304
1823.49	3286
1825.51	3362
1827.52	3324
1829.54	3342
1831.55	3284
1833.56	3328
1835.57	3232
1837.58	3266
1839.59	3264
1841.6	3230
1843.61	3254
1845.61	3258
1847.62	3196
1849.63	3224
1851.63	3276
1853.64	3212
1855.64	3286
1857.65	3192
1859.65	3200
1861.65	3202
1863.65	3230
1865.66	3136
1867.66	3174
1869.66	3226
1871.66	3162
1873.66	3114
1875.65	3176
1877.65	3202
1879.65	3174
1881.65	3160
1883.64	3162
1885.64	3104
1887.63	3162
1889.63	3150
1891.62	3158
1893.61	3174
1895.6	3110
1897.6	3088
1899.59	3196
1901.58	3142
1903.57	3134
1905.56	3108
1907.54	3172
1909.53	3112
1911.52	3128
1913.51	3068
1915.49	3134
1917.48	3162
1919.46	3088
1921.45	3072
1923.43	3166
1925.41	3094
1927.4	3052
1929.38	3048
1931.36	3150
1933.34	3102
1935.32	3078
1937.3	3164
1939.28	3068
1941.26	3052
1943.23	3102
1945.21	3078
1947.19	3088
1949.16	3022
1951.14	3016
1953.11	3092
1955.09	3034
1957.06	3040
1959.03	3002
1961	3016
1962.98	3014
1964.95	2926
1966.92	2984
1968.89	2988
1970.85	2980
1972.82	3044
1974.79	2976
1976.76	2974
1978.73	2994
1980.69	3016
1982.66	3008
1984.62	2968
1986.59	3022
1988.55	2960
1990.51	2948
1992.47	2986
1994.44	2918
1996.4	2998
1998.36	2948
2000.32	3036
2002.28	2964
2004.24	2928
2006.19	2920
2008.15	2904
2010.11	2904
2012.06	2916
2014.02	2952
2015.98	2910
2017.93	2972
2019.88	2898
2021.84	2966
2023.79	2876
2025.74	2878
2027.69	2944
2029.65	2906
2031.6	2866
2033.55	2892
2035.5	2962
2037.44	2868
2039.39	2870
2041.34	2882
2043.29	2902
2045.23	2902
2047.18	2880
2049.12	2866
2051.07	2886
2053.01	2854
2054.95	2818
2056.9	2856
2058.84	2942
2060.78	2820
2062.72	2844
2064.66	2832
2066.6	2854
2068.54	2842
2070.48	2872
2072.42	2868
2074.35	2842
2076.29	2838
2078.23	2850
2080.16	2838
2082.1	2774
2084.03	2836
2085.96	2846
2087.9	2854
2089.83	2798
2091.76	2796
2093.69	2850
2095.62	2834
2097.55	2818
2099.48	2818
2101.41	2730
2103.34	2802
2105.27	2768
2107.2	2792
2109.12	2804
2111.05	2836
2112.98	2808
2114.9	2844
2116.82	2766
2118.75	2804
2120.67	2768
2122.59	2800
2124.52	2766
2126.44	2762
2128.36	2756
2130.28	2764
2132.2	2764
2134.12	2780
2136.04	2708
2137.95	2742
2139.87	2724
2141.79	2782
2143.7	2728
2145.62	2717.76
2147.53	2717.69
2149.45	2728
2151.36	2665.71
2153.28	2680.91
2155.19	2715.39
2157.1	2683.85
2159.01	2731.5
2160.92	2684.28
2162.83	2668.76
2164.74	2666.15
2166.65	2654.44
2168.56	2633.54
2170.47	2651.75
2172.38	2651.38
2174.28	2617.41
2176.19	2619.74
2178.09	2626.04
2180	2611.51
2181.9	2586.43
2183.81	2580.57
2185.71	2597.26
2187.61	2551.77
2189.52	2610.72
2191.42	2575.75
2193.32	2625.78
2195.22	2593.55
2197.12	2606.17
2199.02	2576.33
2200.92	2595.08
2202.82	2555.98
2204.71	2557.55
2206.61	2506.08
2208.51	2578.28
2210.4	2509.49
2212.3	2525.26
2214.19	2563.98
2216.09	2513.81
2217.98	2527.95
2219.87	2534.74
2221.77	2547.06
2223.66	2521.13
2225.55	2514.57
2227.44	2494.37
2229.33	2553.88
2231.22	2504.81
2233.11	2515.99
2235	2471.43
2236.88	2513.39
2238.77	2466.83
2240.66	2505.4
2242.07	2554
2243.97	2442
2245.87	2534
2247.76	2426
2249.65	2482
2251.55	2450
2253.44	2456
2255.33	2488
2257.22	2504
2259.12	2464
2261.01	2524
2262.9	2436
2264.78	2504
2266.67	2440
2268.56	2428
2270.45	2446
2272.34	2450
2274.22	2448
2276.11	2478
2277.99	2442
2279.88	2390
2281.76	2432
2283.65	2454
2285.53	2400
2287.41	2408
2289.3	2388
2291.18	2410
2293.06	2376
2294.94	2350
2296.82	2386
2298.7	2346
2300.58	2340
2302.46	2356
2304.33	2320
2306.21	2346
2308.09	2346
2309.96	2308
2311.84	2394
2313.71	2366
2315.59	2358
2317.46	2298
2319.33	2346
2321.21	2334
2323.08	2356
2324.95	2298
2326.82	2334
2328.69	2318
2330.56	2250
2332.43	2266
2334.3	2266
2336.17	2284
2338.03	2306
2339.9	2304
2341.77	2264
2343.63	2322
2345.5	2262
2347.36	2286
2349.23	2274
2351.09	2242
2352.95	2228
2354.82	2306
2356.68	2260
2358.54	2210
2360.4	2172
2362.26	2234
2364.12	2256
2365.98	2182
2367.84	2216
2369.7	2190
2371.56	2174
2373.41	2212
2375.27	2170
2377.12	2196
2378.98	2196
2380.84	2232
2382.69	2148
2384.54	2174
2386.4	2120
2388.25	2134
2390.1	2154
2391.95	2134
2393.8	2144
2395.65	2116
2397.5	2158
2399.35	2154
2401.2	2176
2403.05	2134
2404.9	2110
2406.75	2106
2408.59	2092
2410.44	2086
2412.28	2042
2414.13	2096
2415.97	2032
2417.82	2038
2419.66	2122
2421.5	2024
2423.35	2044
2425.19	2042
2427.03	2032
2428.87	2072
2430.71	2026
2432.55	2040
2434.39	1980
2436.23	1968
2438.06	1986
2439.9	1954
2441.74	1988
2443.57	1988
2445.41	1936
2447.24	2002
2449.08	1960
2450.91	1940
2452.75	1928
2454.58	1938
2456.41	1964
2458.24	1922
2460.08	1966
2461.91	1892
2463.74	1896
2465.57	1942
2467.4	1886
2469.22	1892
2471.05	1850
2472.88	1904
2474.71	1872
2476.53	1870
2478.36	1900
2480.19	1876
2482.01	1838
2483.83	1898
2485.66	1848
2487.48	1812
2489.3	1812
2491.13	1872
2492.95	1810
2494.77	1838
2496.59	1792
2498.41	1784
2500.23	1792
2502.05	1804
2503.87	1762
2505.68	1776
2507.5	1754
2509.32	1792
2511.14	1800
2512.95	1774
2514.77	1786
2516.58	1708
2518.39	1778
2520.21	1742
2522.02	1730
2523.83	1716
2525.65	1708
2527.46	1736
2529.27	1702
2531.08	1680
2532.89	1690
2534.7	1674
2536.51	1678
2538.32	1668
2540.12	1704
2541.93	1646
2543.74	1632
2545.54	1662
2547.35	1628
2549.15	1632
2550.96	1642
2552.76	1616
2554.56	1664
2556.37	1638
2558.17	1630
2559.97	1592
2561.77	1622
2563.58	1582
2565.38	1564
2567.18	1572
2568.97	1584
2570.77	1576
2572.57	1532
2574.37	1564
2576.17	1582
2577.96	1532
2579.76	1520
2581.55	1514
2583.35	1554
2585.14	1532
2586.94	1532
2588.73	1534
2590.52	1518
2592.32	1496
2594.11	1518
2595.9	1512
2597.69	1500
2599.48	1486
2601.27	1482
2603.06	1490
2604.85	1492
2606.64	1484
2608.42	1472
2610.21	1514
2612	1458
2613.78	1458
2615.57	1438
2617.36	1418
2619.14	1456
2620.92	1436
2622.71	1438
2624.49	1446
2626.27	1458
2628.05	1400
2629.84	1350
2631.62	1440
2633.4	1394
2635.18	1380
2636.96	1388
2638.74	1344
2640.51	1388
2642.29	1372
2644.07	1354
2645.85	1350
2647.62	1316
2649.4	1312
2651.17	1334
2652.95	1334
2654.72	1322
2656.5	1330
2658.27	1308
2660.04	1290
2661.81	1298
2663.58	1316
2665.35	1352
2667.13	1308
2668.9	1328
2670.66	1308
2672.43	1284
2674.2	1268
2675.97	1276
2677.74	1230
2679.5	1230
2681.27	1310
2683.04	1284
2684.8	1260
2686.57	1232
2688.33	1250
2690.09	1282
2691.86	1200
2693.62	1232
2695.38	1198
2697.15	1230
2698.91	1238
2700.67	1224
2702.43	1194
2704.19	1184
2705.95	1194
2707.7	1182
2709.46	1168
2711.22	1174
2712.98	1178
2714.73	1182
2716.49	1146
2718.25	1164
2720	1108
2721.76	1158
2723.51	1164
2725.26	1124
2727.02	1136
2728.77	1136
2730.52	1134
2732.27	1112
2734.02	1140
2735.77	1152
2737.52	1094
2739.27	1122
2741.02	1100
2742.77	1090
2744.52	1086
2746.27	1094
2748.01	1088
2749.76	1094
2751.51	1046
2753.25	1064
2755	1064
2756.74	1038
2758.48	1034
2760.23	1054
2761.97	1050
2763.71	1016
2765.45	996
2767.19	1070
2768.94	1048
2770.68	1030
2772.42	1028
2774.16	1038
2775.89	1000
2777.63	1014
2779.37	990
2781.11	996
2782.84	980
2784.58	976
2786.32	1020
2788.05	1024
2789.79	964
2791.52	998
2793.25	984
2794.99	962
2796.72	992
2798.45	968
2800.18	982
2801.92	978
2803.65	962
2805.38	970
2807.11	952
2808.84	968
2810.57	936
2812.29	948
2814.02	902
2815.75	966
2817.47	948
2819.2	942
2820.93	900
2822.65	930
2824.38	880
2826.1	920
2827.82	958
2829.55	898
2831.27	910
2832.99	910
2834.71	916
2836.44	912
2838.16	914
2839.88	912
2841.6	874
2843.32	846
2845.03	858
2846.75	902
2848.47	878
2850.19	874
2851.9	872
2853.62	874
2855.34	840
2857.05	802
2858.77	860
2860.48	834
2862.19	832
2863.91	850
2865.62	830
2867.33	822
2869.04	846
2870.76	836
2872.47	856
2874.18	814
2875.89	836
2877.6	792
2879.31	818
2881.01	836
2882.72	822
2884.43	818
2886.14	804
2887.84	816
2889.55	792
2891.25	788
2892.96	788
2894.66	770
2896.37	770
2898.07	790
2899.77	786
2901.48	784
2903.18	762
2904.88	740
2906.58	768
2908.28	782
2909.98	776
2911.68	770
2913.38	752
2915.08	778
2916.78	754
2918.47	744
2920.17	768
2921.87	750
2923.56	758
2925.26	780
2926.95	754
2928.65	730
2930.34	758
2932.04	748
2933.73	764
2935.42	728
2937.11	732
2938.81	744
2940.5	766
2942.19	704
2943.88	732
2945.57	756
2947.26	724
2948.95	694
2950.64	736
2952.32	708
2954.01	702
2955.7	678
2957.38	728
2959.07	704
2960.75	674
2962.44	680
2964.12	682
2965.81	668
2967.49	696
2969.17	688
2970.86	698
2972.54	694
2974.22	698
2975.9	668
2977.58	682
2979.26	662
2980.94	684
2982.62	676
2984.3	642
2985.98	666
2987.66	632
2989.33	636
2991.01	648
2992.69	648
2994.36	670
2996.04	644
2997.71	668
2999.39	634