File: muestras/tallo/1/Organic_18.txt
#Acq. time (s)=	10
#Accumulations=	1
#Range (cm-¹)=	100...3000
#Windows=	3
#Autofocus=	Off
#AutoExposure=	Off
#Spike filter=	Off
#Delay time (s)=	0
#Binning=	1
#Readout mode=	Signal
#DeNoise=	Off
#ICS correction=	Off
#Dark correction=	Off
#Inst. Process=	Off
#Instrument=	LabRAM HR Evol
#Detector=	Syncerity OE
#Objective=	x100_VIS
#Grating=	600 (500nm)
#ND Filter=	5%
#Laser=	633nm_Edge
#Hole=	74.97
#Range=	Visible
#Project=	Omar
#Sample=	26-06-23
#Site=	1
#Title=	Organic
#Remark=
#Date=	26.06.2023 16:06
#Acquired=	26.06.2023 16:06:22
101.018	1414
103.586	1374
106.152	1408
108.717	1424
111.281	1376
113.845	1372
116.407	1374
118.969	1422
121.53	1412
124.09	1376
126.649	1424
129.207	1390
131.765	1422
134.321	1410
136.877	1436
139.432	1424
141.985	1400
144.538	1390
147.09	1398
149.641	1322
152.191	1402
154.741	1422
157.289	1382
159.837	1410
162.385	1370
164.93	1362
167.476	1440
170.019	1436
172.562	1338
175.105	1358
177.646	1362
180.188	1350
182.727	1364
185.266	1366
187.804	1362
190.342	1408
192.878	1394
195.413	1398
197.948	1410
200.481	1360
203.014	1374
205.546	1400
208.077	1400
210.608	1432
213.137	1424
215.666	1422
218.194	1410
220.721	1364
223.247	1408
225.772	1440
228.295	1408
230.819	1422
233.342	1442
235.864	1426
238.384	1458
240.904	1442
243.423	1386
245.941	1418
248.46	1492
250.975	1414
253.492	1470
256.006	1454
258.519	1452
261.033	1460
263.545	1420
266.057	1416
268.567	1414
271.076	1406
273.585	1432
276.094	1398
278.601	1418
281.107	1404
283.612	1422
286.116	1452
288.62	1438
291.123	1396
293.625	1430
296.126	1460
298.626	1432
301.126	1490
303.625	1456
306.122	1498
308.62	1432
311.114	1492
313.61	1420
316.105	1436
318.599	1456
321.09	1462
323.583	1464
326.073	1396
328.563	1400
331.053	1464
333.541	1526
336.029	1454
338.515	1434
341.001	1446
343.486	1474
345.97	1470
348.453	1454
350.936	1422
353.418	1460
355.898	1450
358.378	1442
360.858	1474
363.336	1464
365.813	1512
368.29	1456
370.766	1504
373.241	1438
375.715	1460
378.188	1458
380.66	1462
383.132	1456
385.603	1490
388.072	1494
390.541	1488
393.01	1566
395.477	1482
397.943	1528
400.409	1498
402.875	1464
405.338	1550
407.802	1528
410.263	1490
412.725	1508
415.185	1578
417.646	1546
420.104	1556
422.564	1592
425.02	1532
427.477	1574
429.933	1548
432.388	1634
434.841	1558
437.294	1536
439.748	1552
442.199	1608
444.65	1604
447.1	1592
449.549	1580
451.997	1588
454.445	1600
456.891	1608
459.337	1560
461.782	1602
464.227	1572
466.669	1598
469.112	1574
471.554	1600
473.995	1618
476.434	1620
478.874	1648
481.312	1616
483.749	1620
486.186	1668
488.622	1624
491.057	1680
493.491	1634
495.925	1680
498.357	1684
500.789	1688
503.221	1684
505.65	1752
508.079	1660
510.509	1700
512.936	1670
515.363	1694
517.789	1716
520.214	1692
522.638	1690
525.062	1686
527.485	1736
529.907	1740
532.328	1726
534.748	1706
537.168	1704
539.587	1738
542.005	1750
544.423	1768
546.838	1726
549.254	1788
551.669	1810
554.082	1812
556.496	1778
558.909	1772
561.319	1778
563.731	1830
566.14	1808
568.549	1844
570.957	1760
573.364	1806
575.771	1824
578.177	1854
580.581	1840
582.987	1866
585.39	1902
587.792	1858
590.193	1858
592.594	1888
594.996	1884
597.395	1942
599.793	1868
602.191	1922
604.588	1982
606.984	1936
609.378	1928
611.773	1984
614.167	1934
616.56	2010
618.953	2030
621.343	2046
623.734	2040
626.124	2000
628.512	2086
630.901	2078
633.289	2090
635.675	2078
638.061	2192
640.446	2098
642.831	2196
645.213	2146
647.595	2180
649.978	2286
652.359	2166
654.738	2238
657.117	2238
659.497	2226
661.875	2230
664.252	2226
666.628	2250
669.003	2362
671.378	2304
673.751	2314
676.124	2352
678.497	2318
680.868	2384
683.239	2396
685.609	2406
687.977	2414
690.346	2426
692.714	2360
695.081	2462
697.446	2448
699.812	2424
702.175	2504
704.539	2510
706.901	2526
709.264	2502
711.625	2612
713.986	2596
716.345	2578
718.705	2598
721.062	2628
723.419	2578
725.775	2666
728.132	2718
730.487	2716
732.841	2742
735.194	2688
737.546	2792
739.898	2804
742.249	2804
744.599	2830
746.949	2856
749.298	2854
751.646	2812
753.993	2896
756.34	2868
758.684	2962
761.029	2950
763.374	2906
765.716	2962
768.059	3036
770.401	3044
772.741	3128
775.082	3066
777.421	3070
779.76	3096
782.097	3108
784.434	3130
786.771	3152
789.106	3140
791.44	3216
793.775	3260
796.108	3278
798.44	3308
800.771	3338
803.102	3390
805.432	3412
807.761	3462
810.09	3400
812.417	3482
814.744	3490
817.071	3564
819.396	3552
821.721	3504
824.045	3648
826.367	3578
828.69	3662
831.012	3740
833.332	3728
835.653	3686
837.972	3824
840.29	3806
842.609	3920
844.925	3832
847.242	3872
849.557	3892
851.871	4024
854.186	3930
856.498	4004
858.81	4088
861.122	4088
863.434	4070
865.744	4110
868.053	4064
870.361	4134
872.669	4110
874.976	4138
877.282	4150
879.588	4242
881.893	4264
884.197	4282
886.5	4308
888.802	4244
891.104	4298
893.405	4402
895.706	4282
898.004	4386
900.303	4326
902.6	4356
904.898	4502
907.194	4462
909.49	4324
911.785	4538
914.08	4464
916.372	4490
918.666	4538
920.957	4628
923.248	4526
925.538	4680
927.828	4638
930.118	4698
932.406	4626
934.693	4750
936.979	4724
939.265	4782
941.55	4760
943.835	4790
946.118	4828
948.401	4934
950.682	4892
952.964	4898
955.245	4868
957.525	4952
959.803	4924
962.082	4964
964.36	5062
966.636	5066
968.913	5070
971.188	5097
973.463	5136
975.736	5162
978.009	5184
980.282	5166
982.554	5280
984.824	5074
987.095	5228
989.364	5188
991.633	5256
993.9	5322
996.167	5216
998.434	5316
1000.7	5334
1002.96	5286
1005.23	5340
1007.49	5278
1009.76	5480
1012.02	5422
1014.28	5208
1016.54	5408
1018.8	5408
1021.06	5394
1023.32	5412
1025.57	5402
1027.83	5582
1030.09	5540
1032.34	5518
1034.6	5424
1036.85	5582
1039.1	5542
1041.35	5500
1043.61	5574
1045.86	5680
1048.11	5638
1050.36	5618
1052.61	5538
1054.85	5684
1057.1	5692
1059.35	5730
1061.59	5610
1063.84	5714
1066.08	5634
1068.33	5672
1070.57	5780
1072.81	5730
1075.05	5726
1077.29	5688
1079.53	5698
1081.77	5766
1084.01	5600
1086.25	5688
1088.48	5602
1090.72	5662
1092.96	5596
1095.19	5664
1097.43	5590
1099.66	5658
1101.89	5674
1104.12	5548
1106.35	5638
1108.59	5578
1110.81	5528
1113.04	5614
1115.27	5536
1117.5	5580
1119.73	5486
1121.95	5610
1124.18	5430
1126.4	5522
1128.63	5564
1130.85	5574
1133.07	5526
1135.29	5470
1137.51	5428
1139.73	5526
1141.95	5534
1144.17	5494
1146.39	5524
1148.61	5496
1150.82	5456
1153.04	5408
1155.26	5488
1157.47	5446
1159.68	5428
1161.9	5448
1164.11	5472
1166.32	5480
1168.53	5410
1170.74	5390
1172.95	5314
1175.16	5322
1177.37	5330
1179.58	5334
1181.78	5250
1183.99	5234
1186.19	5232
1188.4	5200
1190.6	5216
1192.8	5066
1195.01	5158
1197.21	5089.99
1199.41	5022.7
1201.61	5040.49
1203.81	5039.02
1206.01	5066.07
1208.2	4995.15
1210.4	4961.43
1212.6	4982.75
1214.8	4996.68
1216.99	4900.21
1219.18	4866.38
1221.38	4809.02
1223.57	4838.79
1225.76	4791.63
1227.96	4762.13
1230.15	4817.09
1232.34	4784.12
1234.53	4746.57
1236.71	4713.38
1238.9	4722.03
1241.09	4650.38
1243.28	4640.9
1245.46	4624.15
1247.65	4644.31
1249.83	4605.18
1252.02	4641.59
1254.2	4640.22
1256.38	4525.85
1258.56	4496.26
1260.74	4523.88
1262.92	4502.87
1265.1	4532.56
1267.28	4520.53
1269.46	4476.6
1271.64	4467.08
1273.82	4415.13
1275.99	4430.35
1278.17	4446.87
1280.34	4370.96
1282.52	4375.87
1284.69	4290.19
1286.86	4275.66
1289.03	4310.7
1291.21	4306.6
1293.38	4310.47
1295.55	4269.3
1297.71	4230.45
1299.88	4254.4
1302.05	4229.84
1304.22	4197.34
1306.38	4164.41
1308.43	4124
1310.61	4174
1312.78	4030
1314.96	4008
1317.13	4050
1319.3	3994
1321.48	4012
1323.65	3984
1325.82	3962
1327.99	3932
1330.16	3942
1332.33	3890
1334.5	3886
1336.66	3828
1338.83	3800
1341	3778
1343.16	3778
1345.33	3790
1347.49	3776
1349.65	3728
1351.82	3758
1353.98	3644
1356.14	3658
1358.3	3650
1360.46	3648
1362.62	3588
1364.78	3670
1366.94	3542
1369.09	3592
1371.25	3530
1373.41	3548
1375.56	3550
1377.72	3488
1379.87	3456
1382.02	3408
1384.17	3482
1386.33	3470
1388.48	3432
1390.63	3364
1392.78	3436
1394.93	3350
1397.07	3314
1399.22	3308
1401.37	3398
1403.52	3334
1405.66	3252
1407.81	3226
1409.95	3254
1412.09	3314
1414.24	3234
1416.38	3260
1418.52	3252
1420.66	3152
1422.8	3142
1424.94	3196
1427.08	3182
1429.22	3122
1431.35	3112
1433.49	3120
1435.63	3118
1437.76	3124
1439.9	3080
1442.03	3074
1444.17	3052
1446.3	3048
1448.43	2998
1450.56	2992
1452.69	3028
1454.82	3006
1456.95	3034
1459.08	2964
1461.21	3004
1463.34	2972
1465.46	2946
1467.59	2922
1469.71	2930
1471.84	2942
1473.96	2934
1476.08	2904
1478.21	2912
1480.33	2826
1482.45	2872
1484.57	2906
1486.69	2828
1488.81	2888
1490.93	2848
1493.05	2826
1495.16	2860
1497.28	2758
1499.4	2762
1501.51	2754
1503.63	2798
1505.74	2724
1507.85	2688
1509.97	2704
1512.08	2702
1514.19	2716
1516.3	2722
1518.41	2686
1520.52	2658
1522.63	2684
1524.73	2658
1526.84	2688
1528.95	2608
1531.06	2696
1533.16	2608
1535.26	2710
1537.37	2516
1539.47	2600
1541.57	2540
1543.68	2550
1545.78	2586
1547.88	2542
1549.98	2530
1552.08	2598
1554.18	2594
1556.27	2530
1558.37	2530
1560.47	2572
1562.56	2480
1564.66	2472
1566.75	2450
1568.85	2482
1570.94	2516
1573.03	2422
1575.13	2466
1577.22	2416
1579.31	2422
1581.4	2472
1583.49	2456
1585.58	2408
1587.66	2388
1589.75	2416
1591.84	2418
1593.93	2376
1596.01	2424
1598.1	2430
1600.18	2360
1602.26	2400
1604.35	2376
1606.43	2346
1608.51	2354
1610.59	2358
1612.67	2390
1614.75	2332
1616.83	2358
1618.91	2370
1620.99	2324
1623.06	2340
1625.14	2318
1627.21	2350
1629.29	2292
1631.36	2304
1633.44	2352
1635.51	2298
1637.58	2330
1639.66	2266
1641.73	2278
1643.8	2328
1645.87	2282
1647.94	2262
1650	2238
1652.07	2248
1654.14	2232
1656.21	2236
1658.27	2244
1660.34	2156
1662.4	2290
1664.47	2192
1666.53	2176
1668.59	2158
1670.66	2186
1672.72	2158
1674.78	2116
1676.84	2174
1678.9	2190
1680.96	2110
1683.01	2102
1685.07	2094
1687.13	2120
1689.19	2182
1691.24	2086
1693.3	2126
1695.35	2134
1697.4	2116
1699.46	2068
1701.51	2086
1703.56	2132
1705.61	2050
1707.66	2134
1709.71	2114
1711.76	2072
1713.81	2072
1715.86	2030
1717.91	2030
1719.95	1960
1722	2042
1724.04	2022
1726.09	1992
1728.13	2062
1730.18	1998
1732.22	1986
1734.26	1992
1736.3	2002
1738.34	2026
1740.38	2000
1742.42	2016
1744.46	1988
1746.5	1954
1748.54	1992
1750.58	1970
1752.61	1990
1754.65	1892
1756.68	2022
1758.72	1930
1760.75	1994
1762.79	1970
1764.82	1912
1766.85	1906
1768.88	1956
1770.91	1928
1772.94	1944
1774.97	1924
1777	1918
1779.03	1926
1781.06	1934
1783.09	1956
1785.11	1998
1787.14	1908
1789.16	1896
1791.19	1910
1793.21	1916
1795.23	1890
1797.26	1858
1799.28	1950
1801.3	1888
1803.32	1930
1805.34	1860
1807.36	1830
1809.38	1906
1811.4	1862
1813.42	1812
1815.43	1798
1817.45	1844
1819.47	1854
1821.48	1836
1823.49	1790
1825.51	1810
1827.52	1890
1829.54	1850
1831.55	1864
1833.56	1840
1835.57	1812
1837.58	1814
1839.59	1840
1841.6	1826
1843.61	1808
1845.61	1854
1847.62	1804
1849.63	1822
1851.63	1758
1853.64	1818
1855.64	1754
1857.65	1772
1859.65	1766
1861.65	1764
1863.65	1780
1865.66	1810
1867.66	1740
1869.66	1764
1871.66	1706
1873.66	1778
1875.65	1762
1877.65	1678
1879.65	1734
1881.65	1762
1883.64	1710
1885.64	1712
1887.63	1704
1889.63	1744
1891.62	1720
1893.61	1666
1895.6	1728
1897.6	1730
1899.59	1690
1901.58	1644
1903.57	1698
1905.56	1714
1907.54	1730
1909.53	1720
1911.52	1684
1913.51	1646
1915.49	1698
1917.48	1704
1919.46	1690
1921.45	1664
1923.43	1670
1925.41	1668
1927.4	1692
1929.38	1712
1931.36	1684
1933.34	1644
1935.32	1682
1937.3	1622
1939.28	1678
1941.26	1666
1943.23	1684
1945.21	1680
1947.19	1654
1949.16	1678
1951.14	1658
1953.11	1712
1955.09	1650
1957.06	1692
1959.03	1632
1961	1628
1962.98	1668
1964.95	1672
1966.92	1668
1968.89	1618
1970.85	1594
1972.82	1606
1974.79	1620
1976.76	1604
1978.73	1614
1980.69	1590
1982.66	1570
1984.62	1610
1986.59	1606
1988.55	1562
1990.51	1602
1992.47	1620
1994.44	1610
1996.4	1572
1998.36	1584
2000.32	1632
2002.28	1608
2004.24	1582
2006.19	1596
2008.15	1614
2010.11	1550
2012.06	1574
2014.02	1614
2015.98	1582
2017.93	1580
2019.88	1586
2021.84	1572
2023.79	1590
2025.74	1554
2027.69	1588
2029.65	1566
2031.6	1568
2033.55	1586
2035.5	1570
2037.44	1544
2039.39	1518
2041.34	1542
2043.29	1538
2045.23	1514
2047.18	1562
2049.12	1520
2051.07	1548
2053.01	1518
2054.95	1546
2056.9	1552
2058.84	1518
2060.78	1530
2062.72	1488
2064.66	1526
2066.6	1496
2068.54	1554
2070.48	1508
2072.42	1500
2074.35	1500
2076.29	1496
2078.23	1504
2080.16	1526
2082.1	1512
2084.03	1524
2085.96	1516
2087.9	1510
2089.83	1452
2091.76	1478
2093.69	1486
2095.62	1460
2097.55	1478
2099.48	1492
2101.41	1462
2103.34	1514
2105.27	1450
2107.2	1464
2109.12	1496
2111.05	1478
2112.98	1472
2114.9	1410
2116.82	1470
2118.75	1470
2120.67	1442
2122.59	1432
2124.52	1456
2126.44	1408
2128.36	1488
2130.28	1438
2132.2	1438
2134.12	1420
2136.04	1436
2137.95	1440
2139.87	1458
2141.79	1468
2143.7	1462
2145.62	1422.08
2147.53	1419.47
2149.45	1465.35
2151.36	1414.63
2153.28	1436.33
2155.19	1410.06
2157.1	2799.53
2159.01	1586.04
2160.92	1415.49
2162.83	1422.87
2164.74	1436.87
2166.65	1410.79
2168.56	1401.98
2170.47	1388.19
2172.38	1378.9
2174.28	1375.45
2176.19	1384.45
2178.09	1418.69
2180	1376.03
2181.9	1378.16
2183.81	1381.81
2185.71	1368.55
2187.61	1343.37
2189.52	1342.08
2191.42	1362.36
2193.32	1366.93
2195.22	1393.17
2197.12	1378.43
2199.02	1359.99
2200.92	1366.23
2202.82	1345.23
2204.71	1366.57
2206.61	1357.03
2208.51	1364.95
2210.4	1323.8
2212.3	1347.98
2214.19	1373.32
2216.09	1359.29
2217.98	1355.65
2219.87	1350.25
2221.77	1361.81
2223.66	1344.22
2225.55	1374.52
2227.44	1332.86
2229.33	1329.45
2231.22	1345.5
2233.11	1341.01
2235	1350.21
2236.88	1370.81
2238.77	1381.8
2240.66	1338.5
2242.07	1354
2243.97	1326
2245.87	1346
2247.76	1334
2249.65	1340
2251.55	1332
2253.44	1358
2255.33	1308
2257.22	1332
2259.12	1304
2261.01	1308
2262.9	1312
2264.78	1330
2266.67	1334
2268.56	1322
2270.45	1336
2272.34	1340
2274.22	1316
2276.11	1318
2277.99	1350
2279.88	1288
2281.76	1314
2283.65	1236
2285.53	1322
2287.41	1310
2289.3	1294
2291.18	1292
2293.06	1270
2294.94	1306
2296.82	1282
2298.7	1288
2300.58	1286
2302.46	1242
2304.33	1248
2306.21	1288
2308.09	1268
2309.96	1282
2311.84	1242
2313.71	1268
2315.59	1262
2317.46	1266
2319.33	1278
2321.21	1238
2323.08	1230
2324.95	1228
2326.82	1242
2328.69	1228
2330.56	1202
2332.43	1244
2334.3	1240
2336.17	1260
2338.03	1230
2339.9	1238
2341.77	1260
2343.63	1232
2345.5	1194
2347.36	1220
2349.23	1210
2351.09	1198
2352.95	1218
2354.82	1192
2356.68	1260
2358.54	1196
2360.4	1184
2362.26	1188
2364.12	1158
2365.98	1236
2367.84	1206
2369.7	1152
2371.56	1204
2373.41	1156
2375.27	1142
2377.12	1182
2378.98	1210
2380.84	1172
2382.69	1148
2384.54	1166
2386.4	1166
2388.25	1176
2390.1	1140
2391.95	1194
2393.8	1156
2395.65	1152
2397.5	1140
2399.35	1128
2401.2	1144
2403.05	1156
2404.9	1150
2406.75	1158
2408.59	1142
2410.44	1130
2412.28	1152
2414.13	1150
2415.97	1082
2417.82	1136
2419.66	1124
2421.5	1114
2423.35	1164
2425.19	1114
2427.03	1084
2428.87	1140
2430.71	1130
2432.55	1132
2434.39	1110
2436.23	1094
2438.06	1034
2439.9	1084
2441.74	1066
2443.57	1066
2445.41	1060
2447.24	1106
2449.08	1066
2450.91	1082
2452.75	1064
2454.58	1034
2456.41	1040
2458.24	1032
2460.08	1034
2461.91	1070
2463.74	1030
2465.57	1064
2467.4	1050
2469.22	1020
2471.05	1024
2472.88	1050
2474.71	1066
2476.53	1060
2478.36	1012
2480.19	1060
2482.01	1048
2483.83	1048
2485.66	1038
2487.48	1008
2489.3	1010
2491.13	1032
2492.95	1036
2494.77	978
2496.59	1020
2498.41	992
2500.23	992
2502.05	1020
2503.87	968
2505.68	982
2507.5	988
2509.32	992
2511.14	988
2512.95	996
2514.77	988
2516.58	938
2518.39	980
2520.21	924
2522.02	974
2523.83	972
2525.65	980
2527.46	986
2529.27	962
2531.08	944
2532.89	968
2534.7	916
2536.51	944
2538.32	940
2540.12	938
2541.93	932
2543.74	926
2545.54	980
2547.35	932
2549.15	908
2550.96	900
2552.76	910
2554.56	894
2556.37	906
2558.17	922
2559.97	914
2561.77	900
2563.58	882
2565.38	904
2567.18	908
2568.97	958
2570.77	910
2572.57	864
2574.37	890
2576.17	858
2577.96	880
2579.76	872
2581.55	868
2583.35	900
2585.14	866
2586.94	858
2588.73	862
2590.52	884
2592.32	850
2594.11	840
2595.9	882
2597.69	840
2599.48	836
2601.27	836
2603.06	852
2604.85	852
2606.64	828
2608.42	842
2610.21	856
2612	830
2613.78	830
2615.57	842
2617.36	786
2619.14	856
2620.92	844
2622.71	814
2624.49	794
2626.27	820
2628.05	810
2629.84	788
2631.62	794
2633.4	816
2635.18	814
2636.96	810
2638.74	770
2640.51	804
2642.29	768
2644.07	752
2645.85	788
2647.62	778
2649.4	788
2651.17	766
2652.95	794
2654.72	782
2656.5	760
2658.27	748
2660.04	754
2661.81	750
2663.58	774
2665.35	744
2667.13	702
2668.9	756
2670.66	774
2672.43	762
2674.2	754
2675.97	758
2677.74	746
2679.5	716
2681.27	706
2683.04	772
2684.8	716
2686.57	748
2688.33	730
2690.09	730
2691.86	734
2693.62	716
2695.38	702
2697.15	694
2698.91	752
2700.67	718
2702.43	716
2704.19	704
2705.95	704
2707.7	686
2709.46	676
2711.22	686
2712.98	678
2714.73	696
2716.49	664
2718.25	722
2720	688
2721.76	692
2723.51	658
2725.26	664
2727.02	648
2728.77	664
2730.52	668
2732.27	672
2734.02	670
2735.77	648
2737.52	644
2739.27	670
2741.02	636
2742.77	648
2744.52	674
2746.27	640
2748.01	660
2749.76	654
2751.51	622
2753.25	642
2755	648
2756.74	630
2758.48	628
2760.23	636
2761.97	654
2763.71	614
2765.45	602
2767.19	640
2768.94	634
2770.68	602
2772.42	626
2774.16	640
2775.89	620
2777.63	612
2779.37	602
2781.11	612
2782.84	596
2784.58	590
2786.32	582
2788.05	608
2789.79	608
2791.52	618
2793.25	594
2794.99	598
2796.72	588
2798.45	606
2800.18	566
2801.92	610
2803.65	597
2805.38	574
2807.11	592
2808.84	602
2810.57	594
2812.29	596
2814.02	576
2815.75	550
2817.47	582
2819.2	586
2820.93	566
2822.65	546
2824.38	586
2826.1	574
2827.82	562
2829.55	520
2831.27	574
2832.99	560
2834.71	556
2836.44	554
2838.16	552
2839.88	556
2841.6	546
2843.32	548
2845.03	544
2846.75	516
2848.47	536
2850.19	514
2851.9	506
2853.62	530
2855.34	510
2857.05	522
2858.77	534
2860.48	514
2862.19	516
2863.91	504
2865.62	530
2867.33	514
2869.04	510
2870.76	498
2872.47	494
2874.18	502
2875.89	504
2877.6	512
2879.31	504
2881.01	510
2882.72	502
2884.43	494
2886.14	490
2887.84	500
2889.55	480
2891.25	478
2892.96	480
2894.66	484
2896.37	494
2898.07	480
2899.77	468
2901.48	474
2903.18	480
2904.88	478
2906.58	472
2908.28	496
2909.98	500
2911.68	476
2913.38	478
2915.08	468
2916.78	478
2918.47	474
2920.17	466
2921.87	470
2923.56	472
2925.26	466
2926.95	464
2928.65	468
2930.34	448
2932.04	458
2933.73	454
2935.42	454
2937.11	466
2938.81	442
2940.5	452
2942.19	450
2943.88	468
2945.57	460
2947.26	452
2948.95	436
2950.64	436
2952.32	444
2954.01	462
2955.7	416
2957.38	438
2959.07	424
2960.75	454
2962.44	414
2964.12	430
2965.81	460
2967.49	436
2969.17	432
2970.86	422
2972.54	422
2974.22	426
2975.9	404
2977.58	422
2979.26	426
2980.94	390
2982.62	426
2984.3	418
2985.98	422
2987.66	418
2989.33	382
2991.01	404
2992.69	424
2994.36	378
2996.04	416
2997.71	398
2999.39	412