File: muestras/tallo/1/Organic_17.txt
#Acq. time (s)=	10
#Accumulations=	1
#Range (cm-¹)=	100...3000
#Windows=	3
#Autofocus=	Off
#AutoExposure=	Off
#Spike filter=	Off
#Delay time (s)=	0
#Binning=	1
#Readout mode=	Signal
#DeNoise=	Off
#ICS correction=	Off
#Dark correction=	Off
#Inst. Process=	Off
#Instrument=	LabRAM HR Evol
#Detector=	Syncerity OE
#Objective=	x100_VIS
#Grating=	600 (500nm)
#ND Filter=	5%
#Laser=	633nm_Edge
#Hole=	74.97
#Range=	Visible
#Project=	Omar
#Sample=	26-06-23
#Site=	1
#Title=	Organic
#Remark=
#Date=	26.06.2023 16:05
#Acquired=	26.06.2023 16:05:27
101.018	1420
103.586	1406
106.152	1418
108.717	1450
111.281	1386
113.845	1466
116.407	1414
118.969	1412
121.53	1438
124.09	1454
126.649	1432
129.207	1448
131.765	1434
134.321	1434
136.877	1476
139.432	1434
141.985	1430
144.538	1436
147.09	1430
149.641	1422
152.191	1424
154.741	1414
157.289	1446
159.837	1442
162.385	1438
164.93	1440
167.476	1446
170.019	1460
172.562	1472
175.105	1418
177.646	1410
180.188	1420
182.727	1474
185.266	1456
187.804	1410
190.342	1408
192.878	1416
195.413	1450
197.948	1390
200.481	1422
203.014	1412
205.546	1458
208.077	1416
210.608	1392
213.137	1398
215.666	1406
218.194	1424
220.721	1436
223.247	1402
225.772	1430
228.295	1412
230.819	1450
233.342	1440
235.864	1484
238.384	1488
240.904	1494
243.423	1448
245.941	1480
248.46	1450
250.975	1460
253.492	1410
256.006	1454
258.519	1476
261.033	1474
263.545	1386
266.057	1412
268.567	1468
271.076	1438
273.585	1460
276.094	1454
278.601	1400
281.107	1458
283.612	1438
286.116	1440
288.62	1482
291.123	1458
293.625	1494
296.126	1436
298.626	1432
301.126	1466
303.625	1486
306.122	1502
308.62	1502
311.114	1504
313.61	1476
316.105	1494
318.599	1504
321.09	1438
323.583	1472
326.073	1506
328.563	1514
331.053	1438
333.541	1514
336.029	1452
338.515	1508
341.001	1488
343.486	1482
345.97	1496
348.453	1472
350.936	1490
353.418	1478
355.898	1500
358.378	1496
360.858	1514
363.336	1482
365.813	1518
368.29	1470
370.766	1548
373.241	1502
375.715	1490
378.188	1522
380.66	1512
383.132	1486
385.603	1516
388.072	1504
390.541	1524
393.01	1508
395.477	1544
397.943	1534
400.409	1532
402.875	1530
405.338	1504
407.802	1522
410.263	1562
412.725	1592
415.185	1598
417.646	1542
420.104	1574
422.564	1616
425.02	1566
427.477	1594
429.933	1602
432.388	1600
434.841	1618
437.294	1608
439.748	1594
442.199	1636
444.65	1586
447.1	1612
449.549	1676
451.997	1644
454.445	1628
456.891	1638
459.337	1636
461.782	1636
464.227	1652
466.669	1624
469.112	1676
471.554	1634
473.995	1610
476.434	1638
478.874	1644
481.312	1698
483.749	1636
486.186	1658
488.622	1660
491.057	1728
493.491	1680
495.925	1762
498.357	1714
500.789	1748
503.221	1774
505.65	1730
508.079	1748
510.509	1728
512.936	1678
515.363	1748
517.789	1722
520.214	1720
522.638	1780
525.062	1728
527.485	1774
529.907	1764
532.328	1706
534.748	1802
537.168	1796
539.587	1768
542.005	1780
544.423	1844
546.838	1778
549.254	1794
551.669	1798
554.082	1796
556.496	1836
558.909	1810
561.319	1856
563.731	1868
566.14	1812
568.549	1826
570.957	1860
573.364	1800
575.771	1878
578.177	1822
580.581	1914
582.987	1908
585.39	1896
587.792	1944
590.193	1938
592.594	1932
594.996	1922
597.395	1956
599.793	1942
602.191	1966
604.588	2004
606.984	2014
609.378	2012
611.773	2014
614.167	1994
616.56	2080
618.953	2094
621.343	2096
623.734	2106
626.124	2120
628.512	2082
630.901	2166
633.289	2164
635.675	2204
638.061	2178
640.446	2246
642.831	2182
645.213	2192
647.595	2266
649.978	2282
652.359	2282
654.738	2328
657.117	2402
659.497	2310
661.875	2312
664.252	2328
666.628	2374
669.003	2330
671.378	2420
673.751	2418
676.124	2454
678.497	2466
680.868	2470
683.239	2472
685.609	2468
687.977	2490
690.346	2532
692.714	2502
695.081	2606
697.446	2574
699.812	2524
702.175	2608
704.539	2612
706.901	2604
709.264	2686
711.625	2650
713.986	2722
716.345	2740
718.705	2762
721.062	2758
723.419	2854
725.775	2780
728.132	2776
730.487	2864
732.841	2876
735.194	2840
737.546	2898
739.898	2904
742.249	2878
744.599	2938
746.949	3012
749.298	2954
751.646	2944
753.993	3034
756.34	3020
758.684	3068
761.029	3118
763.374	3118
765.716	3092
768.059	3144
770.401	3142
772.741	3158
775.082	3274
777.421	3212
779.76	3252
782.097	3318
784.434	3264
786.771	3310
789.106	3324
791.44	3332
793.775	3400
796.108	3422
798.44	3404
800.771	3498
803.102	3534
805.432	3452
807.761	3594
810.09	3560
812.417	3620
814.744	3630
817.071	3730
819.396	3776
821.721	3752
824.045	3740
826.367	3762
828.69	3786
831.012	3864
833.332	3926
835.653	3960
837.972	3888
840.29	3992
842.609	3970
844.925	4032
847.242	4066
849.557	4072
851.871	4072
854.186	4116
856.498	4220
858.81	4150
861.122	4120
863.434	4202
865.744	4242
868.053	4250
870.361	4306
872.669	4376
874.976	4410
877.282	4378
879.588	4404
881.893	4354
884.197	4426
886.5	4466
888.802	4480
891.104	4544
893.405	4530
895.706	4570
898.004	4622
900.303	4566
902.6	4622
904.898	4588
907.194	4588
909.49	4606
911.785	4706
914.08	4762
916.372	4662
918.666	4806
920.957	4782
923.248	4784
925.538	4880
927.828	4838
930.118	4922
932.406	4892
934.693	4964
936.979	4942
939.265	4912
941.55	4918
943.835	4994
946.118	5020
948.401	5066
950.682	5100
952.964	5156
955.245	5172
957.525	5166
959.803	5332
962.082	5302
964.36	5164
966.636	5202
968.913	5344
971.188	5311
973.463	5324
975.736	5324
978.009	5400
980.282	5326
982.554	5416
984.824	5358
987.095	5426
989.364	5460
991.633	5432
993.9	5454
996.167	5572
998.434	5516
1000.7	5554
1002.96	5566
1005.23	5602
1007.49	5562
1009.76	5584
1012.02	5584
1014.28	5600
1016.54	5646
1018.8	5596
1021.06	5646
1023.32	5708
1025.57	5718
1027.83	5658
1030.09	5728
1032.34	5644
1034.6	5722
1036.85	5820
1039.1	5830
1041.35	5852
1043.61	5890
1045.86	5866
1048.11	5900
1050.36	5834
1052.61	5864
1054.85	5944
1057.1	5966
1059.35	5948
1061.59	6018
1063.84	5904
1066.08	6016
1068.33	6012
1070.57	5944
1072.81	5962
1075.05	5970
1077.29	6028
1079.53	5916
1081.77	5902
1084.01	5922
1086.25	5972
1088.48	5916
1090.72	5780
1092.96	5910
1095.19	5832
1097.43	5892
1099.66	5866
1101.89	5798
1104.12	5842
1106.35	5916
1108.59	5736
1110.81	5846
1113.04	5876
1115.27	5816
1117.5	5800
1119.73	5726
1121.95	5796
1124.18	5754
1126.4	5754
1128.63	5786
1130.85	5818
1133.07	5718
1135.29	5800
1137.51	5716
1139.73	5704
1141.95	5750
1144.17	5710
1146.39	5722
1148.61	5772
1150.82	5702
1153.04	5642
1155.26	5706
1157.47	5666
1159.68	5646
1161.9	5754
1164.11	5676
1166.32	5598
1168.53	5556
1170.74	5528
1172.95	5634
1175.16	5562
1177.37	5468
1179.58	5504
1181.78	5476
1183.99	5444
1186.19	5430
1188.4	5476
1190.6	5398
1192.8	5368
1195.01	5450
1197.21	5345.65
1199.41	5330.4
1201.61	5276.03
1203.81	5304.38
1206.01	5212.18
1208.2	5158.78
1210.4	5131.11
1212.6	5189.67
1214.8	5107.4
1216.99	5103.54
1219.18	5033.21
1221.38	5076.92
1223.57	5003.46
1225.76	4972.3
1227.96	4977.34
1230.15	4965.35
1232.34	4964.56
1234.53	4924.3
1236.71	4911.74
1238.9	4836.13
1241.09	4886.94
1243.28	4828.35
1245.46	4821.19
1247.65	4790.65
1249.83	4782.85
1252.02	4766.53
1254.2	4755.78
1256.38	4753.4
1258.56	4729.05
1260.74	4727.08
1262.92	4692.49
1265.1	4681.84
1267.28	4659.44
1269.46	4639.15
1271.64	4616.9
1273.82	4588.81
1275.99	4601.38
1278.17	4527.71
1280.34	4553.51
1282.52	4552.29
1284.69	4442.45
1286.86	4557.14
1289.03	4443.7
1291.21	4454.28
1293.38	4469.41
1295.55	4440.9
1297.71	4485.14
1299.88	4377.88
1302.05	4302.09
1304.22	4376.26
1306.38	4368.1
1308.43	4324
1310.61	4302
1312.78	4260
1314.96	4262
1317.13	4238
1319.3	4228
1321.48	4134
1323.65	4108
1325.82	4126
1327.99	4128
1330.16	4036
1332.33	4080
1334.5	4028
1336.66	3988
1338.83	3996
1341	3968
1343.16	3916
1345.33	3880
1347.49	3866
1349.65	3780
1351.82	3898
1353.98	3746
1356.14	3770
1358.3	3764
1360.46	3810
1362.62	3712
1364.78	3762
1366.94	3718
1369.09	3650
1371.25	3620
1373.41	3620
1375.56	3636
1377.72	3558
1379.87	3656
1382.02	3632
1384.17	3574
1386.33	3548
1388.48	3530
1390.63	3504
1392.78	3574
1394.93	3462
1397.07	3436
1399.22	3426
1401.37	3422
1403.52	3464
1405.66	3386
1407.81	3410
1409.95	3398
1412.09	3336
1414.24	3402
1416.38	3328
1418.52	3332
1420.66	3378
1422.8	3274
1424.94	3250
1427.08	3324
1429.22	3220
1431.35	3218
1433.49	3266
1435.63	3226
1437.76	3250
1439.9	3180
1442.03	3132
1444.17	3104
1446.3	3164
1448.43	3188
1450.56	3096
1452.69	3092
1454.82	3066
1456.95	3026
1459.08	3062
1461.21	3036
1463.34	3064
1465.46	3042
1467.59	3020
1469.71	3014
1471.84	3016
1473.96	2964
1476.08	2960
1478.21	2978
1480.33	2960
1482.45	3056
1484.57	2944
1486.69	2998
1488.81	2920
1490.93	2988
1493.05	2930
1495.16	2872
1497.28	2876
1499.4	2838
1501.51	2894
1503.63	2870
1505.74	2824
1507.85	2852
1509.97	2862
1512.08	2824
1514.19	2838
1516.3	2786
1518.41	2778
1520.52	2770
1522.63	2774
1524.73	2726
1526.84	2746
1528.95	2740
1531.06	2684
1533.16	2708
1535.26	2760
1537.37	2662
1539.47	2696
1541.57	2670
1543.68	2668
1545.78	2606
1547.88	2656
1549.98	2622
1552.08	2632
1554.18	2608
1556.27	2630
1558.37	2586
1560.47	2572
1562.56	2618
1564.66	2518
1566.75	2538
1568.85	2520
1570.94	2572
1573.03	2542
1575.13	2464
1577.22	2520
1579.31	2510
1581.4	2486
1583.49	2484
1585.58	2466
1587.66	2554
1589.75	2496
1591.84	2512
1593.93	2488
1596.01	2450
1598.1	2490
1600.18	2478
1602.26	2494
1604.35	2524
1606.43	2452
1608.51	2432
1610.59	2416
1612.67	2456
1614.75	2400
1616.83	2428
1618.91	2456
1620.99	2346
1623.06	2406
1625.14	2392
1627.21	2386
1629.29	2388
1631.36	2378
1633.44	2368
1635.51	2380
1637.58	2404
1639.66	2354
1641.73	2376
1643.8	2330
1645.87	2308
1647.94	2366
1650	2290
1652.07	2306
1654.14	2334
1656.21	2338
1658.27	2294
1660.34	2234
1662.4	2318
1664.47	2256
1666.53	2270
1668.59	2304
1670.66	2250
1672.72	2232
1674.78	2210
1676.84	2230
1678.9	2256
1680.96	2248
1683.01	2256
1685.07	2208
1687.13	2208
1689.19	2168
1691.24	2170
1693.3	2200
1695.35	2162
1697.4	2142
1699.46	2130
1701.51	2154
1703.56	2238
1705.61	2148
1707.66	2122
1709.71	2178
1711.76	2126
1713.81	2062
1715.86	2128
1717.91	2126
1719.95	2060
1722	2086
1724.04	2070
1726.09	2054
1728.13	2108
1730.18	2046
1732.22	2032
1734.26	2120
1736.3	2088
1738.34	2084
1740.38	2068
1742.42	2020
1744.46	2022
1746.5	2016
1748.54	2036
1750.58	1962
1752.61	2010
1754.65	2040
1756.68	2050
1758.72	2026
1760.75	2062
1762.79	1996
1764.82	2020
1766.85	2002
1768.88	2036
1770.91	1958
1772.94	2042
1774.97	2002
1777	2026
1779.03	2050
1781.06	2014
1783.09	2032
1785.11	1958
1787.14	1982
1789.16	2008
1791.19	1988
1793.21	1970
1795.23	1944
1797.26	1966
1799.28	1948
1801.3	1930
1803.32	1912
1805.34	1886
1807.36	1908
1809.38	1926
1811.4	1974
1813.42	1970
1815.43	1904
1817.45	1920
1819.47	1914
1821.48	1884
1823.49	1894
1825.51	1926
1827.52	1900
1829.54	1902
1831.55	1934
1833.56	1872
1835.57	1888
1837.58	1836
1839.59	1854
1841.6	1876
1843.61	1880
1845.61	1860
1847.62	1856
1849.63	1824
1851.63	1860
1853.64	1868
1855.64	1846
1857.65	1860
1859.65	1884
1861.65	1786
1863.65	1770
1865.66	1804
1867.66	1824
1869.66	1844
1871.66	1810
1873.66	1756
1875.65	1776
1877.65	1744
1879.65	1788
1881.65	1814
1883.64	1810
1885.64	1764
1887.63	1756
1889.63	1734
1891.62	1780
1893.61	1788
1895.6	1758
1897.6	1762
1899.59	1786
1901.58	1780
1903.57	1776
1905.56	1740
1907.54	1776
1909.53	1744
1911.52	1784
1913.51	1742
1915.49	1754
1917.48	1810
1919.46	1776
1921.45	1758
1923.43	1710
1925.41	1744
1927.4	1782
1929.38	1720
1931.36	1744
1933.34	1686
1935.32	1728
1937.3	1694
1939.28	1714
1941.26	1754
1943.23	1738
1945.21	1728
1947.19	1670
1949.16	1688
1951.14	1674
1953.11	1740
1955.09	1702
1957.06	1762
1959.03	1678
1961	1730
1962.98	1702
1964.95	1672
1966.92	1702
1968.89	1708
1970.85	1678
1972.82	1640
1974.79	1656
1976.76	1684
1978.73	1668
1980.69	1686
1982.66	1648
1984.62	1694
1986.59	1652
1988.55	1642
1990.51	1662
1992.47	1654
1994.44	1648
1996.4	1672
1998.36	1616
2000.32	1650
2002.28	1606
2004.24	1626
2006.19	1604
2008.15	1638
2010.11	1588
2012.06	1604
2014.02	1636
2015.98	1654
2017.93	1598
2019.88	1590
2021.84	1604
2023.79	1598
2025.74	1560
2027.69	1576
2029.65	1626
2031.6	1636
2033.55	1558
2035.5	1578
2037.44	1596
2039.39	1552
2041.34	1636
2043.29	1616
2045.23	1614
2047.18	1570
2049.12	1578
2051.07	1574
2053.01	1570
2054.95	1596
2056.9	1590
2058.84	1584
2060.78	1578
2062.72	1574
2064.66	1604
2066.6	1578
2068.54	1598
2070.48	1552
2072.42	1576
2074.35	1556
2076.29	1550
2078.23	1562
2080.16	1532
2082.1	1542
2084.03	1544
2085.96	1562
2087.9	1558
2089.83	1550
2091.76	1548
2093.69	1586
2095.62	1566
2097.55	1534
2099.48	1520
2101.41	1544
2103.34	1540
2105.27	1528
2107.2	1518
2109.12	1542
2111.05	1524
2112.98	1528
2114.9	1528
2116.82	1554
2118.75	1510
2120.67	1510
2122.59	1536
2124.52	1564
2126.44	1514
2128.36	1468
2130.28	1522
2132.2	1516
2134.12	1470
2136.04	1506
2137.95	1436
2139.87	1494
2141.79	1464
2143.7	1474
2145.62	1468.06
2147.53	1510.87
2149.45	1501.03
2151.36	1465.13
2153.28	1489.35
2155.19	1468.27
2157.1	1469.07
2159.01	1433.19
2160.92	1404.47
2162.83	1416.59
2164.74	1454.03
2166.65	1428.8
2168.56	1474.67
2170.47	1449.08
2172.38	1439.88
2174.28	1429.25
2176.19	1441.45
2178.09	1419.56
2180	1405.69
2181.9	1413.17
2183.81	1414.06
2185.71	1416.06
2187.61	1416.08
2189.52	1417.7
2191.42	1409.14
2193.32	1410.05
2195.22	1399.77
2197.12	1440.05
2199.02	1399.02
2200.92	1391.31
2202.82	1400.33
2204.71	1383.2
2206.61	1395.36
2208.51	1430.03
2210.4	1653.17
2212.3	2244.52
2214.19	2205.73
2216.09	1401.05
2217.98	1407.47
2219.87	1378.21
2221.77	1387.08
2223.66	1432.76
2225.55	1383.17
2227.44	1378.24
2229.33	1393.91
2231.22	1383.47
2233.11	1402.46
2235	1402.81
2236.88	1407.58
2238.77	1406.12
2240.66	1394.37
2242.07	1384
2243.97	1390
2245.87	1394
2247.76	1406
2249.65	1362
2251.55	1394
2253.44	1418
2255.33	1352
2257.22	1382
2259.12	1380
2261.01	1378
2262.9	1386
2264.78	1340
2266.67	1362
2268.56	1356
2270.45	1340
2272.34	1380
2274.22	1386
2276.11	1378
2277.99	1374
2279.88	1348
2281.76	1294
2283.65	1368
2285.53	1326
2287.41	1322
2289.3	1364
2291.18	1290
2293.06	1282
2294.94	1332
2296.82	1272
2298.7	1330
2300.58	1330
2302.46	1306
2304.33	1352
2306.21	1344
2308.09	1286
2309.96	1298
2311.84	1310
2313.71	1286
2315.59	1320
2317.46	1338
2319.33	1304
2321.21	1292
2323.08	1272
2324.95	1292
2326.82	1332
2328.69	1294
2330.56	1240
2332.43	1272
2334.3	1302
2336.17	1282
2338.03	1264
2339.9	1278
2341.77	1276
2343.63	1278
2345.5	1252
2347.36	1274
2349.23	1270
2351.09	1282
2352.95	1252
2354.82	1262
2356.68	1216
2358.54	1248
2360.4	1224
2362.26	1250
2364.12	1244
2365.98	1222
2367.84	1230
2369.7	1252
2371.56	1200
2373.41	1216
2375.27	1216
2377.12	1226
2378.98	1256
2380.84	1176
2382.69	1246
2384.54	1216
2386.4	1222
2388.25	1216
2390.1	1194
2391.95	1224
2393.8	1220
2395.65	1200
2397.5	1172
2399.35	1198
2401.2	1152
2403.05	1186
2404.9	1158
2406.75	1184
2408.59	1156
2410.44	1174
2412.28	1156
2414.13	1154
2415.97	1174
2417.82	1142
2419.66	1176
2421.5	1148
2423.35	1148
2425.19	1114
2427.03	1114
2428.87	1148
2430.71	1124
2432.55	1132
2434.39	1108
2436.23	1128
2438.06	1102
2439.9	1116
2441.74	1122
2443.57	1128
2445.41	1122
2447.24	1108
2449.08	1136
2450.91	1120
2452.75	1104
2454.58	1118
2456.41	1100
2458.24	1080
2460.08	1090
2461.91	1088
2463.74	1126
2465.57	1104
2467.4	1062
2469.22	1082
2471.05	1102
2472.88	1076
2474.71	1084
2476.53	1088
2478.36	1076
2480.19	1066
2482.01	1078
2483.83	1036
2485.66	1048
2487.48	1052
2489.3	1076
2491.13	1114
2492.95	1052
2494.77	1072
2496.59	988
2498.41	1062
2500.23	1044
2502.05	1004
2503.87	1038
2505.68	1030
2507.5	1008
2509.32	992
2511.14	1016
2512.95	1000
2514.77	1040
2516.58	996
2518.39	972
2520.21	1002
2522.02	972
2523.83	1022
2525.65	1000
2527.46	958
2529.27	962
2531.08	998
2532.89	984
2534.7	1004
2536.51	972
2538.32	1004
2540.12	952
2541.93	968
2543.74	950
2545.54	974
2547.35	960
2549.15	1012
2550.96	956
2552.76	912
2554.56	928
2556.37	950
2558.17	926
2559.97	940
2561.77	942
2563.58	952
2565.38	970
2567.18	942
2568.97	906
2570.77	934
2572.57	898
2574.37	930
2576.17	930
2577.96	910
2579.76	906
2581.55	910
2583.35	908
2585.14	886
2586.94	890
2588.73	888
2590.52	872
2592.32	874
2594.11	860
2595.9	850
2597.69	880
2599.48	848
2601.27	848
2603.06	860
2604.85	852
2606.64	882
2608.42	826
2610.21	886
2612	870
2613.78	854
2615.57	856
2617.36	832
2619.14	816
2620.92	846
2622.71	828
2624.49	862
2626.27	836
2628.05	860
2629.84	820
2631.62	798
2633.4	870
2635.18	820
2636.96	788
2638.74	834
2640.51	800
2642.29	822
2644.07	834
2645.85	828
2647.62	772
2649.4	770
2651.17	818
2652.95	786
2654.72	774
2656.5	784
2658.27	782
2660.04	788
2661.81	794
2663.58	808
2665.35	754
2667.13	796
2668.9	768
2670.66	762
2672.43	752
2674.2	754
2675.97	782
2677.74	760
2679.5	766
2681.27	752
2683.04	768
2684.8	728
2686.57	762
2688.33	736
2690.09	756
2691.86	750
2693.62	710
2695.38	714
2697.15	726
2698.91	754
2700.67	758
2702.43	714
2704.19	712
2705.95	734
2707.7	726
2709.46	712
2711.22	694
2712.98	710
2714.73	742
2716.49	740
2718.25	724
2720	708
2721.76	658
2723.51	706
2725.26	712
2727.02	746
2728.77	692
2730.52	668
2732.27	710
2734.02	696
2735.77	674
2737.52	700
2739.27	664
2741.02	670
2742.77	658
2744.52	690
2746.27	678
2748.01	646
2749.76	672
2751.51	658
2753.25	676
2755	656
2756.74	656
2758.48	666
2760.23	652
2761.97	658
2763.71	642
2765.45	636
2767.19	610
2768.94	638
2770.68	630
2772.42	622
2774.16	610
2775.89	616
2777.63	612
2779.37	630
2781.11	620
2782.84	634
2784.58	620
2786.32	588
2788.05	592
2789.79	622
2791.52	608
2793.25	634
2794.99	614
2796.72	612
2798.45	602
2800.18	612
2801.92	590
2803.65	607
2805.38	612
2807.11	612
2808.84	582
2810.57	606
2812.29	576
2814.02	580
2815.75	552
2817.47	558
2819.2	578
2820.93	570
2822.65	600
2824.38	560
2826.1	538
2827.82	598
2829.55	550
2831.27	552
2832.99	582
2834.71	564
2836.44	574
2838.16	556
2839.88	562
2841.6	564
2843.32	558
2845.03	552
2846.75	574
2848.47	564
2850.19	532
2851.9	570
2853.62	536
2855.34	538
2857.05	544
2858.77	546
2860.48	568
2862.19	546
2863.91	548
2865.62	518
2867.33	538
2869.04	508
2870.76	552
2872.47	538
2874.18	516
2875.89	516
2877.6	532
2879.31	480
2881.01	536
2882.72	510
2884.43	502
2886.14	492
2887.84	510
2889.55	532
2891.25	520
2892.96	520
2894.66	494
2896.37	486
2898.07	498
2899.77	512
2901.48	518
2903.18	492
2904.88	474
2906.58	474
2908.28	458
2909.98	490
2911.68	464
2913.38	474
2915.08	496
2916.78	520
2918.47	500
2920.17	472
2921.87	458
2923.56	470
2925.26	478
2926.95	482
2928.65	468
2930.34	464
2932.04	476
2933.73	442
2935.42	440
2937.11	456
2938.81	458
2940.5	446
2942.19	466
2943.88	448
2945.57	470
2947.26	472
2948.95	448
2950.64	456
2952.32	480
2954.01	428
2955.7	442
2957.38	430
2959.07	446
2960.75	470
2962.44	458
2964.12	418
2965.81	460
2967.49	424
2969.17	438
2970.86	428
2972.54	448
2974.22	430
2975.9	420
2977.58	444
2979.26	422
2980.94	446
2982.62	442
2984.3	428
2985.98	406
2987.66	410
2989.33	444
2991.01	416
2992.69	420
2994.36	400
2996.04	410
2997.71	418
2999.39	408