File: muestras/tallo/1/Organic_19.txt
#Acq. time (s)=	10
#Accumulations=	1
#Range (cm-¹)=	100...3000
#Windows=	3
#Autofocus=	Off
#AutoExposure=	Off
#Spike filter=	Off
#Delay time (s)=	0
#Binning=	1
#Readout mode=	Signal
#DeNoise=	Off
#ICS correction=	Off
#Dark correction=	Off
#Inst. Process=	Off
#Instrument=	LabRAM HR Evol
#Detector=	Syncerity OE
#Objective=	x100_VIS
#Grating=	600 (500nm)
#ND Filter=	5%
#Laser=	633nm_Edge
#Hole=	74.97
#Range=	Visible
#Project=	Omar
#Sample=	26-06-23
#Site=	1
#Title=	Organic
#Remark=
#Date=	26.06.2023 16:07
#Acquired=	26.06.2023 16:07:17
101.018	1382
103.586	1352
106.152	1400
108.717	1396
111.281	1386
113.845	1436
116.407	1312
118.969	1352
121.53	1366
124.09	1388
126.649	1400
129.207	1348
131.765	1406
134.321	1324
136.877	1418
139.432	1380
141.985	1422
144.538	1372
147.09	1364
149.641	1362
152.191	1340
154.741	1336
157.289	1350
159.837	1350
162.385	1364
164.93	1346
167.476	1376
170.019	1376
172.562	1354
175.105	1310
177.646	1382
180.188	1360
182.727	1368
185.266	1378
187.804	1336
190.342	1394
192.878	1324
195.413	1370
197.948	1398
200.481	1352
203.014	1376
205.546	1360
208.077	1368
210.608	1370
213.137	1392
215.666	1368
218.194	1400
220.721	1414
223.247	1318
225.772	1392
228.295	1406
230.819	1372
233.342	1396
235.864	1374
238.384	1412
240.904	1418
243.423	1382
245.941	1346
248.46	1436
250.975	1424
253.492	1384
256.006	1404
258.519	1346
261.033	1364
263.545	1394
266.057	1416
268.567	1372
271.076	1396
273.585	1372
276.094	1384
278.601	1394
281.107	1400
283.612	1378
286.116	1398
288.62	1430
291.123	1448
293.625	1384
296.126	1396
298.626	1326
301.126	1436
303.625	1448
306.122	1400
308.62	1390
311.114	1500
313.61	1422
316.105	1420
318.599	1416
321.09	1452
323.583	1412
326.073	1434
328.563	1432
331.053	1432
333.541	1438
336.029	1436
338.515	1420
341.001	1420
343.486	1424
345.97	1440
348.453	1428
350.936	1420
353.418	1436
355.898	1426
358.378	1460
360.858	1416
363.336	1446
365.813	1428
368.29	1462
370.766	1464
373.241	1440
375.715	1438
378.188	1418
380.66	1414
383.132	1430
385.603	1470
388.072	1438
390.541	1438
393.01	1448
395.477	1426
397.943	1402
400.409	1490
402.875	1440
405.338	1498
407.802	1436
410.263	1480
412.725	1520
415.185	1520
417.646	1464
420.104	1516
422.564	1500
425.02	1590
427.477	1568
429.933	1526
432.388	1488
434.841	1558
437.294	1556
439.748	1502
442.199	1584
444.65	1546
447.1	1590
449.549	1572
451.997	1538
454.445	1556
456.891	1522
459.337	1516
461.782	1578
464.227	1538
466.669	1572
469.112	1598
471.554	1566
473.995	1556
476.434	1574
478.874	1584
481.312	1550
483.749	1602
486.186	1632
488.622	1634
491.057	1606
493.491	1624
495.925	1652
498.357	1630
500.789	1586
503.221	1638
505.65	1628
508.079	1656
510.509	1686
512.936	1680
515.363	1648
517.789	1704
520.214	1670
522.638	1616
525.062	1656
527.485	1670
529.907	1644
532.328	1690
534.748	1672
537.168	1680
539.587	1678
542.005	1672
544.423	1708
546.838	1710
549.254	1702
551.669	1716
554.082	1746
556.496	1742
558.909	1704
561.319	1754
563.731	1728
566.14	1730
568.549	1760
570.957	1782
573.364	1742
575.771	1788
578.177	1774
580.581	1776
582.987	1778
585.39	1812
587.792	1804
590.193	1852
592.594	1862
594.996	1830
597.395	1864
599.793	1854
602.191	1864
604.588	1894
606.984	1900
609.378	1934
611.773	1950
614.167	1940
616.56	1916
618.953	1948
621.343	1964
623.734	1988
626.124	2010
628.512	2016
630.901	2076
633.289	2020
635.675	2006
638.061	2050
640.446	2076
642.831	2102
645.213	2054
647.595	2132
649.978	2190
652.359	2152
654.738	2128
657.117	2130
659.497	2212
661.875	2238
664.252	2194
666.628	2216
669.003	2184
671.378	2258
673.751	2270
676.124	2284
678.497	2230
680.868	2280
683.239	2350
685.609	2336
687.977	2278
690.346	2332
692.714	2334
695.081	2322
697.446	2414
699.812	2452
702.175	2414
704.539	2464
706.901	2486
709.264	2524
711.625	2464
713.986	2506
716.345	2528
718.705	2592
721.062	2530
723.419	2574
725.775	2606
728.132	2588
730.487	2656
732.841	2626
735.194	2684
737.546	2716
739.898	2658
742.249	2682
744.599	2746
746.949	2722
749.298	2750
751.646	2858
753.993	2792
756.34	2778
758.684	2872
761.029	2856
763.374	2866
765.716	2924
768.059	2932
770.401	2920
772.741	2956
775.082	2962
777.421	2952
779.76	2996
782.097	2982
784.434	3062
786.771	3088
789.106	3072
791.44	3134
793.775	3216
796.108	3138
798.44	3140
800.771	3194
803.102	3200
805.432	3238
807.761	3246
810.09	3244
812.417	3296
814.744	3342
817.071	3372
819.396	3340
821.721	3436
824.045	3500
826.367	3484
828.69	3526
831.012	3592
833.332	3556
835.653	3568
837.972	3642
840.29	3634
842.609	3662
844.925	3730
847.242	3660
849.557	3752
851.871	3790
854.186	3874
856.498	3874
858.81	3878
861.122	3848
863.434	3936
865.744	3812
868.053	3924
870.361	3972
872.669	3958
874.976	4044
877.282	4044
879.588	4004
881.893	3978
884.197	4084
886.5	4088
888.802	4024
891.104	4178
893.405	4102
895.706	4192
898.004	4138
900.303	4236
902.6	4242
904.898	4242
907.194	4216
909.49	4226
911.785	4272
914.08	4270
916.372	4384
918.666	4406
920.957	4384
923.248	4408
925.538	4386
927.828	4456
930.118	4488
932.406	4468
934.693	4540
936.979	4546
939.265	4496
941.55	4570
943.835	4560
946.118	4634
948.401	4588
950.682	4676
952.964	4650
955.245	4742
957.525	4686
959.803	4840
962.082	4838
964.36	4846
966.636	4772
968.913	4848
971.188	4961
973.463	4872
975.736	4858
978.009	4838
980.282	4914
982.554	4936
984.824	4962
987.095	4942
989.364	4960
991.633	5056
993.9	4956
996.167	5044
998.434	4992
1000.7	5088
1002.96	5104
1005.23	4992
1007.49	5088
1009.76	5076
1012.02	5180
1014.28	5144
1016.54	5148
1018.8	5170
1021.06	5148
1023.32	5254
1025.57	5160
1027.83	5246
1030.09	5228
1032.34	5326
1034.6	5260
1036.85	5386
1039.1	5338
1041.35	5294
1043.61	5342
1045.86	5394
1048.11	5358
1050.36	5354
1052.61	5438
1054.85	5424
1057.1	5338
1059.35	5358
1061.59	5382
1063.84	5528
1066.08	5374
1068.33	5516
1070.57	5472
1072.81	5388
1075.05	5438
1077.29	5498
1079.53	5490
1081.77	5474
1084.01	5382
1086.25	5526
1088.48	5384
1090.72	5496
1092.96	5368
1095.19	5358
1097.43	5346
1099.66	5476
1101.89	5408
1104.12	5344
1106.35	5404
1108.59	5346
1110.81	5320
1113.04	5370
1115.27	5358
1117.5	5360
1119.73	5346
1121.95	5284
1124.18	5308
1126.4	5278
1128.63	5310
1130.85	5302
1133.07	5324
1135.29	5358
1137.51	5268
1139.73	5312
1141.95	5252
1144.17	5292
1146.39	5228
1148.61	5270
1150.82	5244
1153.04	5192
1155.26	5244
1157.47	5244
1159.68	5222
1161.9	5182
1164.11	5246
1166.32	5142
1168.53	5186
1170.74	5146
1172.95	5154
1175.16	5170
1177.37	5122
1179.58	5012
1181.78	5108
1183.99	5010
1186.19	5050
1188.4	5016
1190.6	4954
1192.8	4936
1195.01	4876
1197.21	4930.69
1199.41	4882.58
1201.61	4878.9
1203.81	4877.95
1206.01	4829.91
1208.2	4812.23
1210.4	4729.13
1212.6	4764.38
1214.8	4702.3
1216.99	4713.54
1219.18	4708.14
1221.38	4706.88
1223.57	4645.94
1225.76	4591.22
1227.96	4598.25
1230.15	4595.8
1232.34	4568.4
1234.53	4544.27
1236.71	4548.61
1238.9	4515.4
1241.09	4484.22
1243.28	4426.4
1245.46	4438.24
1247.65	4434.2
1249.83	4442.69
1252.02	4416.81
1254.2	4399.52
1256.38	4380.37
1258.56	4376.78
1260.74	4330.09
1262.92	4302.22
1265.1	4314.53
1267.28	4326.15
1269.46	4273.45
1271.64	4278.8
1273.82	4191.02
1275.99	4287.16
1278.17	4250.78
1280.34	4193.73
1282.52	4184.45
1284.69	4213.62
1286.86	4246.14
1289.03	4134.59
1291.21	4142.68
1293.38	4152.84
1295.55	4037.96
1297.71	4085.03
1299.88	4103.45
1302.05	4062.73
1304.22	3972.74
1306.38	4004.7
1308.43	3970
1310.61	3944
1312.78	3970
1314.96	3814
1317.13	3904
1319.3	3908
1321.48	3884
1323.65	3842
1325.82	3778
1327.99	3832
1330.16	3766
1332.33	3732
1334.5	3768
1336.66	3724
1338.83	3686
1341	3678
1343.16	3612
1345.33	3606
1347.49	3558
1349.65	3532
1351.82	3564
1353.98	3596
1356.14	3554
1358.3	3558
1360.46	3416
1362.62	3460
1364.78	3404
1366.94	3510
1369.09	3400
1371.25	3400
1373.41	3430
1375.56	3344
1377.72	3376
1379.87	3304
1382.02	3372
1384.17	3364
1386.33	3364
1388.48	3252
1390.63	3250
1392.78	3274
1394.93	3244
1397.07	3208
1399.22	3168
1401.37	3208
1403.52	3150
1405.66	3148
1407.81	3142
1409.95	3124
1412.09	3096
1414.24	3118
1416.38	3138
1418.52	3108
1420.66	3054
1422.8	3102
1424.94	3022
1427.08	3046
1429.22	2994
1431.35	3038
1433.49	2962
1435.63	2940
1437.76	2972
1439.9	2932
1442.03	2932
1444.17	2976
1446.3	2964
1448.43	2926
1450.56	2922
1452.69	2922
1454.82	2818
1456.95	2932
1459.08	2872
1461.21	2910
1463.34	2878
1465.46	2830
1467.59	2824
1469.71	2806
1471.84	2852
1473.96	2860
1476.08	2798
1478.21	2832
1480.33	2748
1482.45	2796
1484.57	2764
1486.69	2762
1488.81	2822
1490.93	2744
1493.05	2706
1495.16	2660
1497.28	2696
1499.4	2748
1501.51	2682
1503.63	2672
1505.74	2652
1507.85	2680
1509.97	2674
1512.08	2632
1514.19	2616
1516.3	2608
1518.41	2642
1520.52	2672
1522.63	2552
1524.73	2604
1526.84	2560
1528.95	2606
1531.06	2550
1533.16	2462
1535.26	2524
1537.37	2550
1539.47	2526
1541.57	2458
1543.68	2476
1545.78	2506
1547.88	2468
1549.98	2424
1552.08	2436
1554.18	2444
1556.27	2456
1558.37	2440
1560.47	2432
1562.56	2380
1564.66	2400
1566.75	2410
1568.85	2416
1570.94	2438
1573.03	2332
1575.13	2334
1577.22	2398
1579.31	2372
1581.4	2302
1583.49	2374
1585.58	2370
1587.66	2328
1589.75	2352
1591.84	2284
1593.93	2312
1596.01	2278
1598.1	2326
1600.18	2286
1602.26	2258
1604.35	2268
1606.43	2354
1608.51	2304
1610.59	2278
1612.67	2306
1614.75	2310
1616.83	2254
1618.91	2294
1620.99	2248
1623.06	2252
1625.14	2270
1627.21	2242
1629.29	2240
1631.36	2248
1633.44	2208
1635.51	2210
1637.58	2244
1639.66	2240
1641.73	2228
1643.8	2214
1645.87	2204
1647.94	2162
1650	2212
1652.07	2162
1654.14	2142
1656.21	2168
1658.27	2186
1660.34	2126
1662.4	2138
1664.47	2090
1666.53	2154
1668.59	2104
1670.66	2118
1672.72	2138
1674.78	2096
1676.84	2124
1678.9	2090
1680.96	2098
1683.01	2052
1685.07	2086
1687.13	2026
1689.19	2004
1691.24	2026
1693.3	2020
1695.35	2038
1697.4	2032
1699.46	2044
1701.51	2000
1703.56	1992
1705.61	2014
1707.66	2042
1709.71	2000
1711.76	1972
1713.81	2018
1715.86	2006
1717.91	1970
1719.95	1972
1722	1968
1724.04	1974
1726.09	1952
1728.13	1998
1730.18	1972
1732.22	2002
1734.26	1980
1736.3	1914
1738.34	1914
1740.38	1936
1742.42	1912
1744.46	1866
1746.5	1898
1748.54	1902
1750.58	1942
1752.61	1902
1754.65	1876
1756.68	1904
1758.72	1854
1760.75	1874
1762.79	1870
1764.82	1894
1766.85	1836
1768.88	1886
1770.91	1872
1772.94	1888
1774.97	1882
1777	1866
1779.03	1884
1781.06	1846
1783.09	1882
1785.11	1890
1787.14	1842
1789.16	1862
1791.19	1874
1793.21	1922
1795.23	1856
1797.26	1796
1799.28	1818
1801.3	1834
1803.32	1836
1805.34	1824
1807.36	1806
1809.38	1782
1811.4	1788
1813.42	1784
1815.43	1826
1817.45	1828
1819.47	1784
1821.48	1798
1823.49	1824
1825.51	1754
1827.52	1776
1829.54	1758
1831.55	1824
1833.56	1770
1835.57	1774
1837.58	1756
1839.59	1772
1841.6	1746
1843.61	1800
1845.61	1726
1847.62	1726
1849.63	1682
1851.63	1736
1853.64	1692
1855.64	1696
1857.65	1760
1859.65	1738
1861.65	1720
1863.65	1718
1865.66	1712
1867.66	1712
1869.66	1724
1871.66	1712
1873.66	1734
1875.65	1654
1877.65	1678
1879.65	1684
1881.65	1660
1883.64	1660
1885.64	1672
1887.63	1660
1889.63	1674
1891.62	1652
1893.61	1658
1895.6	1624
1897.6	1604
1899.59	1698
1901.58	1650
1903.57	1654
1905.56	1654
1907.54	1662
1909.53	1698
1911.52	1648
1913.51	1704
1915.49	1624
1917.48	1650
1919.46	1640
1921.45	1644
1923.43	1592
1925.41	1668
1927.4	1630
1929.38	1622
1931.36	1662
1933.34	1618
1935.32	1582
1937.3	1632
1939.28	1616
1941.26	1584
1943.23	1622
1945.21	1674
1947.19	1624
1949.16	1578
1951.14	1604
1953.11	1564
1955.09	1606
1957.06	1562
1959.03	1598
1961	1608
1962.98	1594
1964.95	1562
1966.92	1504
1968.89	1566
1970.85	1620
1972.82	1592
1974.79	1562
1976.76	1550
1978.73	1570
1980.69	1514
1982.66	1530
1984.62	1572
1986.59	1576
1988.55	1538
1990.51	1560
1992.47	1546
1994.44	1558
1996.4	1586
1998.36	1538
2000.32	1534
2002.28	1550
2004.24	1566
2006.19	1512
2008.15	1544
2010.11	1502
2012.06	1528
2014.02	1522
2015.98	1512
2017.93	1462
2019.88	1548
2021.84	1536
2023.79	1528
2025.74	1512
2027.69	1508
2029.65	1554
2031.6	1530
2033.55	1496
2035.5	1474
2037.44	1514
2039.39	1472
2041.34	1492
2043.29	1516
2045.23	1470
2047.18	1502
2049.12	1486
2051.07	1470
2053.01	1556
2054.95	1514
2056.9	1478
2058.84	1474
2060.78	1464
2062.72	1474
2064.66	1490
2066.6	1504
2068.54	1470
2070.48	1464
2072.42	1402
2074.35	1480
2076.29	1438
2078.23	1478
2080.16	1504
2082.1	1484
2084.03	1456
2085.96	1418
2087.9	1456
2089.83	1422
2091.76	1432
2093.69	1426
2095.62	1424
2097.55	1418
2099.48	1414
2101.41	1416
2103.34	1436
2105.27	1412
2107.2	1408
2109.12	1428
2111.05	1462
2112.98	1418
2114.9	1416
2116.82	1390
2118.75	1370
2120.67	1408
2122.59	1424
2124.52	1378
2126.44	1444
2128.36	1394
2130.28	1424
2132.2	1438
2134.12	1398
2136.04	1392
2137.95	1414
2139.87	1330
2141.79	1414
2143.7	1378
2145.62	1399.96
2147.53	1395.7
2149.45	1350.61
2151.36	1421.32
2153.28	1392.07
2155.19	1375.61
2157.1	1346.58
2159.01	1369.13
2160.92	1333.96
2162.83	1362.89
2164.74	1322.81
2166.65	1369.46
2168.56	1361.48
2170.47	1344.05
2172.38	1312.27
2174.28	1361.02
2176.19	1367.61
2178.09	1328.3
2180	1338.89
2181.9	1318.68
2183.81	1332.34
2185.71	1329.85
2187.61	1303.62
2189.52	1343.26
2191.42	1327.07
2193.32	1318.01
2195.22	1329.73
2197.12	1318
2199.02	1272.29
2200.92	1323.43
2202.82	1293.57
2204.71	1308.93
2206.61	1308.34
2208.51	1308.13
2210.4	1299.14
2212.3	1279.92
2214.19	1329.02
2216.09	1321.77
2217.98	1285.7
2219.87	1303.37
2221.77	1303.8
2223.66	1289.58
2225.55	1288.13
2227.44	1311.75
2229.33	1305.79
2231.22	1324.56
2233.11	1252.57
2235	1281.78
2236.88	1285.07
2238.77	1287.96
2240.66	1314.73
2242.07	1286
2243.97	1318
2245.87	1316
2247.76	1310
2249.65	1266
2251.55	1310
2253.44	1256
2255.33	1246
2257.22	1284
2259.12	1292
2261.01	1268
2262.9	1292
2264.78	1278
2266.67	1290
2268.56	1284
2270.45	1264
2272.34	1256
2274.22	1298
2276.11	1252
2277.99	1280
2279.88	1252
2281.76	1270
2283.65	1270
2285.53	1260
2287.41	1280
2289.3	1210
2291.18	1246
2293.06	1262
2294.94	1242
2296.82	1256
2298.7	1226
2300.58	1254
2302.46	1248
2304.33	1218
2306.21	1258
2308.09	1230
2309.96	1188
2311.84	1248
2313.71	1224
2315.59	1224
2317.46	1232
2319.33	1226
2321.21	1192
2323.08	1210
2324.95	1228
2326.82	1222
2328.69	1168
2330.56	1182
2332.43	1174
2334.3	1212
2336.17	1182
2338.03	1190
2339.9	1216
2341.77	1184
2343.63	1158
2345.5	1178
2347.36	1144
2349.23	1142
2351.09	1182
2352.95	1174
2354.82	1168
2356.68	1180
2358.54	1194
2360.4	1170
2362.26	1158
2364.12	1150
2365.98	1174
2367.84	1118
2369.7	1166
2371.56	1154
2373.41	1154
2375.27	1166
2377.12	1156
2378.98	1136
2380.84	1136
2382.69	1130
2384.54	1136
2386.4	1116
2388.25	1112
2390.1	1120
2391.95	1156
2393.8	1098
2395.65	1142
2397.5	1116
2399.35	1122
2401.2	1122
2403.05	1114
2404.9	1114
2406.75	1106
2408.59	1108
2410.44	1086
2412.28	1080
2414.13	1072
2415.97	1088
2417.82	1098
2419.66	1062
2421.5	1050
2423.35	1098
2425.19	1116
2427.03	1074
2428.87	1096
2430.71	1088
2432.55	1060
2434.39	1088
2436.23	1050
2438.06	1040
2439.9	1038
2441.74	1064
2443.57	1064
2445.41	1024
2447.24	1034
2449.08	1062
2450.91	1034
2452.75	1036
2454.58	1058
2456.41	1024
2458.24	1030
2460.08	1042
2461.91	1074
2463.74	1060
2465.57	1026
2467.4	986
2469.22	1010
2471.05	1024
2472.88	994
2474.71	992
2476.53	990
2478.36	1024
2480.19	1020
2482.01	1004
2483.83	994
2485.66	1002
2487.48	976
2489.3	964
2491.13	1018
2492.95	956
2494.77	986
2496.59	988
2498.41	962
2500.23	946
2502.05	986
2503.87	956
2505.68	918
2507.5	960
2509.32	956
2511.14	952
2512.95	994
2514.77	926
2516.58	918
2518.39	950
2520.21	944
2522.02	926
2523.83	928
2525.65	942
2527.46	930
2529.27	914
2531.08	942
2532.89	912
2534.7	940
2536.51	922
2538.32	914
2540.12	930
2541.93	872
2543.74	892
2545.54	916
2547.35	902
2549.15	890
2550.96	860
2552.76	868
2554.56	876
2556.37	902
2558.17	912
2559.97	888
2561.77	850
2563.58	896
2565.38	874
2567.18	880
2568.97	856
2570.77	890
2572.57	884
2574.37	846
2576.17	836
2577.96	830
2579.76	840
2581.55	844
2583.35	852
2585.14	876
2586.94	844
2588.73	846
2590.52	832
2592.32	844
2594.11	846
2595.9	840
2597.69	824
2599.48	834
2601.27	790
2603.06	802
2604.85	828
2606.64	814
2608.42	814
2610.21	818
2612	840
2613.78	788
2615.57	784
2617.36	774
2619.14	796
2620.92	786
2622.71	796
2624.49	802
2626.27	794
2628.05	770
2629.84	804
2631.62	778
2633.4	758
2635.18	794
2636.96	754
2638.74	750
2640.51	798
2642.29	802
2644.07	798
2645.85	744
2647.62	776
2649.4	762
2651.17	734
2652.95	736
2654.72	778
2656.5	776
2658.27	728
2660.04	752
2661.81	726
2663.58	736
2665.35	722
2667.13	720
2668.9	716
2670.66	734
2672.43	730
2674.2	718
2675.97	750
2677.74	710
2679.5	712
2681.27	712
2683.04	680
2684.8	706
2686.57	692
2688.33	694
2690.09	726
2691.86	700
2693.62	692
2695.38	700
2697.15	718
2698.91	688
2700.67	672
2702.43	726
2704.19	712
2705.95	706
2707.7	660
2709.46	688
2711.22	656
2712.98	678
2714.73	690
2716.49	664
2718.25	674
2720	656
2721.76	680
2723.51	642
2725.26	690
2727.02	656
2728.77	658
2730.52	638
2732.27	638
2734.02	642
2735.77	634
2737.52	636
2739.27	652
2741.02	628
2742.77	652
2744.52	636
2746.27	594
2748.01	644
2749.76	664
2751.51	618
2753.25	646
2755	640
2756.74	612
2758.48	620
2760.23	554
2761.97	600
2763.71	598
2765.45	594
2767.19	624
2768.94	598
2770.68	596
2772.42	618
2774.16	630
2775.89	596
2777.63	616
2779.37	582
2781.11	580
2782.84	584
2784.58	602
2786.32	598
2788.05	590
2789.79	590
2791.52	598
2793.25	574
2794.99	552
2796.72	570
2798.45	588
2800.18	576
2801.92	604
2803.65	559
2805.38	592
2807.11	574
2808.84	578
2810.57	548
2812.29	556
2814.02	546
2815.75	562
2817.47	536
2819.2	544
2820.93	558
2822.65	552
2824.38	524
2826.1	516
2827.82	534
2829.55	544
2831.27	516
2832.99	538
2834.71	520
2836.44	526
2838.16	532
2839.88	528
2841.6	534
2843.32	500
2845.03	502
2846.75	532
2848.47	540
2850.19	516
2851.9	548
2853.62	548
2855.34	516
2857.05	530
2858.77	512
2860.48	520
2862.19	500
2863.91	504
2865.62	516
2867.33	500
2869.04	516
2870.76	504
2872.47	494
2874.18	490
2875.89	492
2877.6	502
2879.31	496
2881.01	492
2882.72	486
2884.43	478
2886.14	490
2887.84	482
2889.55	482
2891.25	484
2892.96	476
2894.66	478
2896.37	496
2898.07	486
2899.77	484
2901.48	466
2903.18	478
2904.88	470
2906.58	472
2908.28	460
2909.98	480
2911.68	476
2913.38	446
2915.08	458
2916.78	426
2918.47	468
2920.17	458
2921.87	424
2923.56	472
2925.26	440
2926.95	460
2928.65	448
2930.34	452
2932.04	426
2933.73	484
2935.42	432
2937.11	446
2938.81	418
2940.5	428
2942.19	446
2943.88	454
2945.57	406
2947.26	442
2948.95	428
2950.64	468
2952.32	430
2954.01	432
2955.7	444
2957.38	438
2959.07	454
2960.75	450
2962.44	442
2964.12	448
2965.81	422
2967.49	420
2969.17	424
2970.86	424
2972.54	436
2974.22	420
2975.9	396
2977.58	426
2979.26	408
2980.94	392
2982.62	410
2984.3	390
2985.98	394
2987.66	404
2989.33	388
2991.01	408
2992.69	396
2994.36	402
2996.04	418
2997.71	382
2999.39	378