File: muestras/tallo/1/Organic_16.txt
#Acq. time (s)=	10
#Accumulations=	1
#Range (cm-¹)=	100...3000
#Windows=	3
#Autofocus=	Off
#AutoExposure=	Off
#Spike filter=	Off
#Delay time (s)=	0
#Binning=	1
#Readout mode=	Signal
#DeNoise=	Off
#ICS correction=	Off
#Dark correction=	Off
#Inst. Process=	Off
#Instrument=	LabRAM HR Evol
#Detector=	Syncerity OE
#Objective=	x100_VIS
#Grating=	600 (500nm)
#ND Filter=	5%
#Laser=	633nm_Edge
#Hole=	74.97
#Range=	Visible
#Project=	Omar
#Sample=	26-06-23
#Site=	1
#Title=	Organic
#Remark=
#Date=	26.06.2023 16:04
#Acquired=	26.06.2023 16:04:33
101.018	1428
103.586	1500
106.152	1472
108.717	1434
111.281	1480
113.845	1474
116.407	1416
118.969	1442
121.53	1464
124.09	1440
126.649	1462
129.207	1484
131.765	1408
134.321	1498
136.877	1496
139.432	1444
141.985	1454
144.538	1450
147.09	1492
149.641	1474
152.191	1442
154.741	1492
157.289	1464
159.837	1462
162.385	1444
164.93	1454
167.476	1468
170.019	1432
172.562	1400
175.105	1446
177.646	1456
180.188	1482
182.727	1486
185.266	1450
187.804	1452
190.342	1418
192.878	1428
195.413	1412
197.948	1450
200.481	1478
203.014	1454
205.546	1442
208.077	1434
210.608	1490
213.137	1422
215.666	1516
218.194	1464
220.721	1468
223.247	1422
225.772	1494
228.295	1478
230.819	1520
233.342	1538
235.864	1508
238.384	1512
240.904	1474
243.423	1514
245.941	1496
248.46	1498
250.975	1474
253.492	1480
256.006	1476
258.519	1490
261.033	1476
263.545	1470
266.057	1470
268.567	1492
271.076	1446
273.585	1484
276.094	1458
278.601	1506
281.107	1502
283.612	1480
286.116	1498
288.62	1454
291.123	1498
293.625	1498
296.126	1498
298.626	1522
301.126	1530
303.625	1482
306.122	1518
308.62	1506
311.114	1508
313.61	1488
316.105	1564
318.599	1504
321.09	1546
323.583	1520
326.073	1522
328.563	1552
331.053	1552
333.541	1506
336.029	1542
338.515	1514
341.001	1556
343.486	1496
345.97	1470
348.453	1562
350.936	1500
353.418	1542
355.898	1546
358.378	1562
360.858	1518
363.336	1562
365.813	1536
368.29	1554
370.766	1580
373.241	1556
375.715	1554
378.188	1514
380.66	1536
383.132	1520
385.603	1516
388.072	1552
390.541	1564
393.01	1496
395.477	1562
397.943	1554
400.409	1584
402.875	1592
405.338	1582
407.802	1594
410.263	1586
412.725	1612
415.185	1610
417.646	1620
420.104	1616
422.564	1658
425.02	1666
427.477	1674
429.933	1620
432.388	1636
434.841	1652
437.294	1674
439.748	1622
442.199	1644
444.65	1670
447.1	1690
449.549	1656
451.997	1696
454.445	1660
456.891	1736
459.337	1656
461.782	1672
464.227	1668
466.669	1708
469.112	1692
471.554	1644
473.995	1750
476.434	1654
478.874	1658
481.312	1774
483.749	1730
486.186	1758
488.622	1772
491.057	1768
493.491	1776
495.925	1788
498.357	1754
500.789	1756
503.221	1776
505.65	1768
508.079	1822
510.509	1824
512.936	1736
515.363	1792
517.789	1772
520.214	1778
522.638	1766
525.062	1780
527.485	1848
529.907	1828
532.328	1852
534.748	1796
537.168	1858
539.587	1770
542.005	1882
544.423	1870
546.838	1876
549.254	1830
551.669	1864
554.082	1926
556.496	1878
558.909	1912
561.319	1882
563.731	1856
566.14	1940
568.549	1906
570.957	1864
573.364	2000
575.771	1962
578.177	1938
580.581	1948
582.987	1942
585.39	1962
587.792	1968
590.193	2000
592.594	1980
594.996	2002
597.395	2048
599.793	2066
602.191	2008
604.588	2072
606.984	2078
609.378	2108
611.773	2088
614.167	2118
616.56	2114
618.953	2120
621.343	2128
623.734	2146
626.124	2228
628.512	2212
630.901	2204
633.289	2220
635.675	2222
638.061	2270
640.446	2244
642.831	2298
645.213	2326
647.595	2360
649.978	2362
652.359	2400
654.738	2352
657.117	2402
659.497	2356
661.875	2402
664.252	2446
666.628	2460
669.003	2462
671.378	2510
673.751	2512
676.124	2508
678.497	2476
680.868	2550
683.239	2506
685.609	2568
687.977	2568
690.346	2576
692.714	2634
695.081	2688
697.446	2580
699.812	2702
702.175	2712
704.539	2710
706.901	2730
709.264	2750
711.625	2784
713.986	2740
716.345	2792
718.705	2822
721.062	2800
723.419	2918
725.775	2884
728.132	2868
730.487	2934
732.841	2916
735.194	2996
737.546	3002
739.898	3000
742.249	3040
744.599	3140
746.949	3090
749.298	3160
751.646	3170
753.993	3122
756.34	3152
758.684	3242
761.029	3208
763.374	3256
765.716	3292
768.059	3256
770.401	3294
772.741	3314
775.082	3404
777.421	3350
779.76	3434
782.097	3358
784.434	3406
786.771	3506
789.106	3450
791.44	3454
793.775	3462
796.108	3518
798.44	3596
800.771	3660
803.102	3624
805.432	3670
807.761	3692
810.09	3648
812.417	3794
814.744	3720
817.071	3808
819.396	3790
821.721	3852
824.045	3896
826.367	3942
828.69	3998
831.012	3986
833.332	4018
835.653	4098
837.972	4110
840.29	4110
842.609	4082
844.925	4190
847.242	4290
849.557	4216
851.871	4344
854.186	4362
856.498	4426
858.81	4422
861.122	4424
863.434	4424
865.744	4470
868.053	4536
870.361	4454
872.669	4554
874.976	4574
877.282	4584
879.588	4614
881.893	4616
884.197	4608
886.5	4622
888.802	4726
891.104	4666
893.405	4768
895.706	4776
898.004	4796
900.303	4810
902.6	4808
904.898	4874
907.194	4840
909.49	4858
911.785	4870
914.08	4918
916.372	4862
918.666	4924
920.957	4998
923.248	4996
925.538	5102
927.828	5020
930.118	5236
932.406	5130
934.693	5142
936.979	5174
939.265	5220
941.55	5168
943.835	5268
946.118	5276
948.401	5366
950.682	5400
952.964	5418
955.245	5390
957.525	5450
959.803	5418
962.082	5422
964.36	5440
966.636	5474
968.913	5562
971.188	5625
973.463	5608
975.736	5630
978.009	5610
980.282	5650
982.554	5788
984.824	5690
987.095	5710
989.364	5752
991.633	5732
993.9	5820
996.167	5724
998.434	5780
1000.7	5802
1002.96	5790
1005.23	5750
1007.49	5790
1009.76	5752
1012.02	5814
1014.28	5880
1016.54	5824
1018.8	5820
1021.06	5960
1023.32	5834
1025.57	5944
1027.83	5936
1030.09	5916
1032.34	6054
1034.6	6136
1036.85	6114
1039.1	6092
1041.35	6176
1043.61	6100
1045.86	6070
1048.11	6116
1050.36	6232
1052.61	6148
1054.85	6178
1057.1	6136
1059.35	6242
1061.59	6306
1063.84	6232
1066.08	6168
1068.33	6196
1070.57	6156
1072.81	6190
1075.05	6264
1077.29	6166
1079.53	6202
1081.77	6080
1084.01	6216
1086.25	6170
1088.48	6104
1090.72	6168
1092.96	6108
1095.19	6082
1097.43	6100
1099.66	6168
1101.89	6106
1104.12	6136
1106.35	6082
1108.59	5990
1110.81	6054
1113.04	6074
1115.27	6074
1117.5	6028
1119.73	6092
1121.95	6002
1124.18	6026
1126.4	6050
1128.63	5946
1130.85	6008
1133.07	5938
1135.29	5962
1137.51	6040
1139.73	5936
1141.95	5986
1144.17	6006
1146.39	5974
1148.61	5948
1150.82	5970
1153.04	6048
1155.26	5946
1157.47	6002
1159.68	5922
1161.9	5816
1164.11	5920
1166.32	5854
1168.53	5962
1170.74	5806
1172.95	5776
1175.16	5848
1177.37	5836
1179.58	5828
1181.78	5734
1183.99	5696
1186.19	5702
1188.4	5658
1190.6	5638
1192.8	5594
1195.01	5490
1197.21	5585.02
1199.41	5448.46
1201.61	5454.87
1203.81	5401.28
1206.01	5391.61
1208.2	5444.01
1210.4	5334.15
1212.6	5391.46
1214.8	5303.37
1216.99	5384.42
1219.18	5306.67
1221.38	5212.75
1223.57	5230.94
1225.76	5199.6
1227.96	5152.07
1230.15	5130.56
1232.34	5203.8
1234.53	5108.06
1236.71	5083.44
1238.9	5048.06
1241.09	5122.3
1243.28	5014.08
1245.46	4982.76
1247.65	4957.14
1249.83	4961.79
1252.02	5007.48
1254.2	4955.04
1256.38	4949.05
1258.56	4926.8
1260.74	4898.67
1262.92	4878.26
1265.1	4879.97
1267.28	4848.49
1269.46	4825.62
1271.64	4878.4
1273.82	4786.88
1275.99	4747.73
1278.17	4755.11
1280.34	4685.74
1282.52	4749.51
1284.69	4693.97
1286.86	4703.41
1289.03	4690.56
1291.21	4610.75
1293.38	4557.86
1295.55	4639.7
1297.71	4614.69
1299.88	4516.42
1302.05	4601.58
1304.22	4496.84
1306.38	4464.03
1308.43	4552
1310.61	4442
1312.78	4448
1314.96	4434
1317.13	4308
1319.3	4330
1321.48	4310
1323.65	4312
1325.82	4226
1327.99	4202
1330.16	4226
1332.33	4196
1334.5	4168
1336.66	4236
1338.83	4102
1341	4110
1343.16	3972
1345.33	4130
1347.49	3964
1349.65	3956
1351.82	4004
1353.98	3878
1356.14	3894
1358.3	3930
1360.46	3856
1362.62	3888
1364.78	3900
1366.94	3890
1369.09	3786
1371.25	3788
1373.41	3736
1375.56	3710
1377.72	3696
1379.87	3782
1382.02	3732
1384.17	3694
1386.33	3702
1388.48	3658
1390.63	3594
1392.78	3598
1394.93	3626
1397.07	3580
1399.22	3572
1401.37	3586
1403.52	3494
1405.66	3480
1407.81	3592
1409.95	3502
1412.09	3564
1414.24	3542
1416.38	3440
1418.52	3444
1420.66	3426
1422.8	3370
1424.94	3396
1427.08	3342
1429.22	3408
1431.35	3366
1433.49	3332
1435.63	3326
1437.76	3314
1439.9	3304
1442.03	3388
1444.17	3288
1446.3	3332
1448.43	3280
1450.56	3232
1452.69	3202
1454.82	3290
1456.95	3256
1459.08	3214
1461.21	3184
1463.34	3192
1465.46	3168
1467.59	3172
1469.71	3116
1471.84	3076
1473.96	3086
1476.08	3134
1478.21	3076
1480.33	3040
1482.45	3072
1484.57	3068
1486.69	3084
1488.81	3018
1490.93	2996
1493.05	3076
1495.16	3046
1497.28	3024
1499.4	3028
1501.51	2982
1503.63	2934
1505.74	2884
1507.85	2968
1509.97	2944
1512.08	2902
1514.19	2892
1516.3	2856
1518.41	2912
1520.52	2862
1522.63	2942
1524.73	2884
1526.84	2864
1528.95	2846
1531.06	2836
1533.16	2824
1535.26	2810
1537.37	2854
1539.47	2804
1541.57	2712
1543.68	2692
1545.78	2750
1547.88	2718
1549.98	2724
1552.08	2676
1554.18	2606
1556.27	2678
1558.37	2694
1560.47	2728
1562.56	2676
1564.66	2620
1566.75	2690
1568.85	2648
1570.94	2588
1573.03	2628
1575.13	2644
1577.22	2662
1579.31	2588
1581.4	2600
1583.49	2554
1585.58	2592
1587.66	2600
1589.75	2580
1591.84	2542
1593.93	2530
1596.01	2576
1598.1	2576
1600.18	2520
1602.26	2554
1604.35	2548
1606.43	2510
1608.51	2562
1610.59	2542
1612.67	2474
1614.75	2496
1616.83	2536
1618.91	2552
1620.99	2552
1623.06	2484
1625.14	2496
1627.21	2430
1629.29	2494
1631.36	2460
1633.44	2516
1635.51	2456
1637.58	2434
1639.66	2434
1641.73	2460
1643.8	2444
1645.87	2440
1647.94	2418
1650	2400
1652.07	2392
1654.14	2368
1656.21	2360
1658.27	2354
1660.34	2370
1662.4	2354
1664.47	2416
1666.53	2374
1668.59	2422
1670.66	2326
1672.72	2310
1674.78	2304
1676.84	2306
1678.9	2264
1680.96	2286
1683.01	2350
1685.07	2292
1687.13	2240
1689.19	2220
1691.24	2270
1693.3	2288
1695.35	2280
1697.4	2272
1699.46	2240
1701.51	2184
1703.56	2172
1705.61	2148
1707.66	2204
1709.71	2156
1711.76	2216
1713.81	2210
1715.86	2176
1717.91	2196
1719.95	2142
1722	2138
1724.04	2152
1726.09	2160
1728.13	2186
1730.18	2164
1732.22	2124
1734.26	2152
1736.3	2122
1738.34	2034
1740.38	2130
1742.42	2066
1744.46	2104
1746.5	2088
1748.54	2084
1750.58	2076
1752.61	2050
1754.65	2138
1756.68	2146
1758.72	2094
1760.75	2070
1762.79	2016
1764.82	2094
1766.85	2022
1768.88	2052
1770.91	2048
1772.94	2064
1774.97	2054
1777	2084
1779.03	2090
1781.06	2032
1783.09	2048
1785.11	2054
1787.14	2090
1789.16	2034
1791.19	2056
1793.21	2028
1795.23	2018
1797.26	2022
1799.28	2036
1801.3	1986
1803.32	2052
1805.34	2040
1807.36	1980
1809.38	1990
1811.4	1982
1813.42	1982
1815.43	1960
1817.45	2048
1819.47	1972
1821.48	1976
1823.49	1988
1825.51	1962
1827.52	1932
1829.54	1934
1831.55	1956
1833.56	1932
1835.57	1902
1837.58	1940
1839.59	1990
1841.6	1904
1843.61	1882
1845.61	1894
1847.62	1904
1849.63	1906
1851.63	1920
1853.64	1880
1855.64	1896
1857.65	1866
1859.65	1842
1861.65	1886
1863.65	1854
1865.66	1878
1867.66	1862
1869.66	1852
1871.66	1854
1873.66	1902
1875.65	1866
1877.65	1902
1879.65	1902
1881.65	1862
1883.64	1804
1885.64	1838
1887.63	1896
1889.63	1848
1891.62	1800
1893.61	1820
1895.6	1858
1897.6	1878
1899.59	1828
1901.58	1832
1903.57	1848
1905.56	1810
1907.54	1856
1909.53	1848
1911.52	1770
1913.51	1792
1915.49	1850
1917.48	1820
1919.46	1816
1921.45	1772
1923.43	1808
1925.41	1770
1927.4	1780
1929.38	1826
1931.36	1792
1933.34	1800
1935.32	1790
1937.3	1774
1939.28	1788
1941.26	1778
1943.23	1760
1945.21	1800
1947.19	1812
1949.16	1790
1951.14	1806
1953.11	1756
1955.09	1744
1957.06	1792
1959.03	1712
1961	1742
1962.98	1714
1964.95	1744
1966.92	1710
1968.89	1758
1970.85	1732
1972.82	1718
1974.79	1746
1976.76	1740
1978.73	1720
1980.69	1696
1982.66	1748
1984.62	1722
1986.59	1702
1988.55	1748
1990.51	1766
1992.47	1700
1994.44	1666
1996.4	1702
1998.36	1676
2000.32	1716
2002.28	1714
2004.24	1698
2006.19	1746
2008.15	1728
2010.11	1690
2012.06	1718
2014.02	1710
2015.98	1676
2017.93	1700
2019.88	1720
2021.84	1654
2023.79	1698
2025.74	1680
2027.69	1648
2029.65	1650
2031.6	1660
2033.55	1644
2035.5	1668
2037.44	1646
2039.39	1672
2041.34	1670
2043.29	1652
2045.23	1644
2047.18	1650
2049.12	1596
2051.07	1630
2053.01	1634
2054.95	1656
2056.9	1648
2058.84	1648
2060.78	1640
2062.72	1606
2064.66	1650
2066.6	1602
2068.54	1666
2070.48	1682
2072.42	1580
2074.35	1688
2076.29	1598
2078.23	1668
2080.16	1580
2082.1	1622
2084.03	1616
2085.96	1602
2087.9	1588
2089.83	1588
2091.76	1592
2093.69	1596
2095.62	1610
2097.55	1576
2099.48	1594
2101.41	1574
2103.34	1584
2105.27	1582
2107.2	1560
2109.12	1574
2111.05	1566
2112.98	1544
2114.9	1568
2116.82	1614
2118.75	1608
2120.67	1588
2122.59	1520
2124.52	1572
2126.44	1606
2128.36	1574
2130.28	1554
2132.2	1596
2134.12	1520
2136.04	1638
2137.95	1578
2139.87	1540
2141.79	1552
2143.7	1574
2145.62	1547.82
2147.53	1554.19
2149.45	1523.85
2151.36	1493.79
2153.28	1537.35
2155.19	1559.2
2157.1	1479.85
2159.01	1491.24
2160.92	1513.51
2162.83	1514.9
2164.74	1475.43
2166.65	1504.74
2168.56	1499.26
2170.47	1494.52
2172.38	1493.95
2174.28	1456.33
2176.19	1473.18
2178.09	1472.52
2180	1439.29
2181.9	1473.38
2183.81	1468.52
2185.71	1475.57
2187.61	1485.26
2189.52	1497.15
2191.42	1468.84
2193.32	1471.9
2195.22	1460.85
2197.12	1472.58
2199.02	1452.89
2200.92	1452.76
2202.82	1468.04
2204.71	1443.96
2206.61	1447.39
2208.51	1455.76
2210.4	1440.39
2212.3	1437.75
2214.19	1425.63
2216.09	1440.59
2217.98	1448.23
2219.87	1449.07
2221.77	1430.68
2223.66	1439.76
2225.55	1461.05
2227.44	1441.4
2229.33	1430.63
2231.22	1449.46
2233.11	1423.44
2235	1438.29
2236.88	1412.43
2238.77	1421.54
2240.66	1453.1
2242.07	1426
2243.97	1434
2245.87	1438
2247.76	1468
2249.65	1432
2251.55	1450
2253.44	1418
2255.33	1470
2257.22	1398
2259.12	1444
2261.01	1420
2262.9	1412
2264.78	1408
2266.67	1408
2268.56	1390
2270.45	1406
2272.34	1434
2274.22	1426
2276.11	1350
2277.99	1396
2279.88	1398
2281.76	1402
2283.65	1386
2285.53	1356
2287.41	1354
2289.3	1374
2291.18	1406
2293.06	1372
2294.94	1348
2296.82	1374
2298.7	1390
2300.58	1340
2302.46	1332
2304.33	1376
2306.21	1384
2308.09	1350
2309.96	1362
2311.84	1334
2313.71	1330
2315.59	1338
2317.46	1332
2319.33	1370
2321.21	1300
2323.08	1296
2324.95	1346
2326.82	1372
2328.69	1308
2330.56	1296
2332.43	1328
2334.3	1288
2336.17	1338
2338.03	1300
2339.9	1314
2341.77	1284
2343.63	1312
2345.5	1290
2347.36	1280
2349.23	1292
2351.09	1318
2352.95	1310
2354.82	1294
2356.68	1304
2358.54	1272
2360.4	1282
2362.26	1240
2364.12	1290
2365.98	1274
2367.84	1292
2369.7	1256
2371.56	1290
2373.41	1236
2375.27	1270
2377.12	1220
2378.98	1252
2380.84	1260
2382.69	1228
2384.54	1242
2386.4	1246
2388.25	1230
2390.1	1292
2391.95	1258
2393.8	1270
2395.65	1226
2397.5	1240
2399.35	1240
2401.2	1224
2403.05	1198
2404.9	1192
2406.75	1176
2408.59	1236
2410.44	1172
2412.28	1220
2414.13	1208
2415.97	1146
2417.82	1196
2419.66	1224
2421.5	1206
2423.35	1178
2425.19	1178
2427.03	1186
2428.87	1184
2430.71	1184
2432.55	1178
2434.39	1190
2436.23	1156
2438.06	1172
2439.9	1128
2441.74	1154
2443.57	1168
2445.41	1176
2447.24	1184
2449.08	1144
2450.91	1142
2452.75	1130
2454.58	1172
2456.41	1166
2458.24	1114
2460.08	1120
2461.91	1168
2463.74	1124
2465.57	1152
2467.4	1138
2469.22	1144
2471.05	1128
2472.88	1080
2474.71	1166
2476.53	1114
2478.36	1084
2480.19	1062
2482.01	1100
2483.83	1150
2485.66	1042
2487.48	1088
2489.3	1102
2491.13	1098
2492.95	1088
2494.77	1050
2496.59	1088
2498.41	1028
2500.23	1066
2502.05	1084
2503.87	1048
2505.68	1084
2507.5	1042
2509.32	1066
2511.14	1038
2512.95	1020
2514.77	1066
2516.58	1012
2518.39	1066
2520.21	1008
2522.02	1012
2523.83	1052
2525.65	1026
2527.46	1002
2529.27	1032
2531.08	998
2532.89	1016
2534.7	994
2536.51	992
2538.32	1006
2540.12	1048
2541.93	1016
2543.74	1028
2545.54	980
2547.35	1004
2549.15	976
2550.96	1020
2552.76	990
2554.56	980
2556.37	964
2558.17	988
2559.97	944
2561.77	974
2563.58	980
2565.38	948
2567.18	956
2568.97	942
2570.77	980
2572.57	970
2574.37	926
2576.17	946
2577.96	960
2579.76	924
2581.55	904
2583.35	920
2585.14	916
2586.94	922
2588.73	926
2590.52	916
2592.32	932
2594.11	912
2595.9	926
2597.69	930
2599.48	898
2601.27	932
2603.06	896
2604.85	862
2606.64	862
2608.42	872
2610.21	900
2612	880
2613.78	906
2615.57	880
2617.36	874
2619.14	888
2620.92	862
2622.71	864
2624.49	854
2626.27	864
2628.05	848
2629.84	866
2631.62	854
2633.4	806
2635.18	824
2636.96	836
2638.74	840
2640.51	820
2642.29	850
2644.07	838
2645.85	844
2647.62	824
2649.4	822
2651.17	830
2652.95	812
2654.72	832
2656.5	810
2658.27	806
2660.04	842
2661.81	798
2663.58	830
2665.35	784
2667.13	810
2668.9	810
2670.66	786
2672.43	794
2674.2	770
2675.97	760
2677.74	804
2679.5	770
2681.27	778
2683.04	766
2684.8	782
2686.57	784
2688.33	782
2690.09	746
2691.86	758
2693.62	758
2695.38	746
2697.15	764
2698.91	750
2700.67	768
2702.43	744
2704.19	744
2705.95	742
2707.7	714
2709.46	708
2711.22	740
2712.98	738
2714.73	734
2716.49	732
2718.25	720
2720	748
2721.76	738
2723.51	724
2725.26	692
2727.02	710
2728.77	698
2730.52	704
2732.27	712
2734.02	706
2735.77	694
2737.52	698
2739.27	704
2741.02	678
2742.77	696
2744.52	698
2746.27	666
2748.01	660
2749.76	690
2751.51	694
2753.25	694
2755	676
2756.74	700
2758.48	648
2760.23	674
2761.97	664
2763.71	664
2765.45	690
2767.19	658
2768.94	650
2770.68	626
2772.42	624
2774.16	656
2775.89	664
2777.63	610
2779.37	650
2781.11	622
2782.84	654
2784.58	634
2786.32	636
2788.05	642
2789.79	626
2791.52	608
2793.25	642
2794.99	632
2796.72	606
2798.45	618
2800.18	616
2801.92	600
2803.65	616
2805.38	604
2807.11	594
2808.84	598
2810.57	638
2812.29	602
2814.02	596
2815.75	604
2817.47	598
2819.2	578
2820.93	598
2822.65	578
2824.38	570
2826.1	582
2827.82	608
2829.55	584
2831.27	570
2832.99	602
2834.71	580
2836.44	534
2838.16	568
2839.88	570
2841.6	588
2843.32	562
2845.03	560
2846.75	560
2848.47	564
2850.19	574
2851.9	560
2853.62	538
2855.34	552
2857.05	554
2858.77	532
2860.48	542
2862.19	536
2863.91	544
2865.62	580
2867.33	548
2869.04	520
2870.76	510
2872.47	546
2874.18	554
2875.89	564
2877.6	530
2879.31	532
2881.01	514
2882.72	514
2884.43	548
2886.14	534
2887.84	538
2889.55	560
2891.25	512
2892.96	502
2894.66	508
2896.37	528
2898.07	520
2899.77	492
2901.48	526
2903.18	532
2904.88	514
2906.58	494
2908.28	498
2909.98	504
2911.68	506
2913.38	498
2915.08	512
2916.78	482
2918.47	484
2920.17	494
2921.87	466
2923.56	516
2925.26	494
2926.95	488
2928.65	470
2930.34	480
2932.04	522
2933.73	466
2935.42	504
2937.11	484
2938.81	476
2940.5	494
2942.19	466
2943.88	502
2945.57	476
2947.26	486
2948.95	446
2950.64	470
2952.32	460
2954.01	464
2955.7	498
2957.38	468
2959.07	466
2960.75	456
2962.44	458
2964.12	460
2965.81	452
2967.49	450
2969.17	416
2970.86	456
2972.54	436
2974.22	430
2975.9	436
2977.58	466
2979.26	458
2980.94	438
2982.62	408
2984.3	406
2985.98	434
2987.66	454
2989.33	430
2991.01	430
2992.69	434
2994.36	426
2996.04	442
2997.71	440
2999.39	428