File: muestras/tallo/1/Organic_09.txt
#Acq. time (s)=	10
#Accumulations=	1
#Range (cm-¹)=	100...3000
#Windows=	3
#Autofocus=	Off
#AutoExposure=	Off
#Spike filter=	Off
#Delay time (s)=	0
#Binning=	1
#Readout mode=	Signal
#DeNoise=	Off
#ICS correction=	Off
#Dark correction=	Off
#Inst. Process=	Off
#Instrument=	LabRAM HR Evol
#Detector=	Syncerity OE
#Objective=	x100_VIS
#Grating=	600 (500nm)
#ND Filter=	5%
#Laser=	633nm_Edge
#Hole=	74.97
#Range=	Visible
#Project=	Omar
#Sample=	26-06-23
#Site=	1
#Title=	Organic
#Remark=
#Date=	26.06.2023 15:57
#Acquired=	26.06.2023 15:57:06
101.018	1828
103.586	1772
106.152	1804
108.717	1838
111.281	1842
113.845	1778
116.407	1856
118.969	1822
121.53	1822
124.09	1814
126.649	1806
129.207	1824
131.765	1796
134.321	1834
136.877	1814
139.432	1778
141.985	1888
144.538	1868
147.09	1790
149.641	1862
152.191	1802
154.741	1778
157.289	1814
159.837	1802
162.385	1802
164.93	1760
167.476	1794
170.019	1850
172.562	1834
175.105	1836
177.646	1744
180.188	1808
182.727	1802
185.266	1772
187.804	1816
190.342	1798
192.878	1828
195.413	1756
197.948	1812
200.481	1794
203.014	1830
205.546	1824
208.077	1814
210.608	1800
213.137	1826
215.666	1826
218.194	1832
220.721	1848
223.247	1776
225.772	1830
228.295	1812
230.819	1854
233.342	1856
235.864	1814
238.384	1828
240.904	1886
243.423	1882
245.941	1828
248.46	1824
250.975	1874
253.492	1856
256.006	1878
258.519	1810
261.033	1846
263.545	1852
266.057	1854
268.567	1830
271.076	1822
273.585	1790
276.094	1814
278.601	1836
281.107	1844
283.612	1822
286.116	1860
288.62	1866
291.123	1866
293.625	1860
296.126	1880
298.626	1826
301.126	1850
303.625	1878
306.122	1852
308.62	1910
311.114	1906
313.61	1854
316.105	1876
318.599	1910
321.09	1906
323.583	1924
326.073	1896
328.563	1916
331.053	1888
333.541	1888
336.029	1878
338.515	1930
341.001	1864
343.486	1888
345.97	1928
348.453	1922
350.936	1918
353.418	1886
355.898	1926
358.378	1930
360.858	1910
363.336	1954
365.813	1978
368.29	1936
370.766	1890
373.241	1918
375.715	1952
378.188	1888
380.66	1904
383.132	1940
385.603	1902
388.072	1938
390.541	1924
393.01	1964
395.477	1938
397.943	1938
400.409	1926
402.875	1984
405.338	1956
407.802	1996
410.263	1948
412.725	2032
415.185	1998
417.646	2062
420.104	2048
422.564	2042
425.02	2096
427.477	2034
429.933	2122
432.388	2106
434.841	2080
437.294	2120
439.748	2100
442.199	2100
444.65	2108
447.1	2046
449.549	2072
451.997	2064
454.445	2086
456.891	2136
459.337	2174
461.782	2108
464.227	2116
466.669	2092
469.112	2140
471.554	2116
473.995	2172
476.434	2128
478.874	2152
481.312	2140
483.749	2200
486.186	2202
488.622	2222
491.057	2238
493.491	2212
495.925	2226
498.357	2246
500.789	2198
503.221	2238
505.65	2248
508.079	2224
510.509	2230
512.936	2286
515.363	2258
517.789	2312
520.214	2280
522.638	2274
525.062	2308
527.485	2258
529.907	2322
532.328	2340
534.748	2382
537.168	2306
539.587	2336
542.005	2384
544.423	2372
546.838	2428
549.254	2390
551.669	2402
554.082	2342
556.496	2462
558.909	2436
561.319	2398
563.731	2428
566.14	2498
568.549	2498
570.957	2506
573.364	2482
575.771	2546
578.177	2492
580.581	2560
582.987	2582
585.39	2580
587.792	2600
590.193	2642
592.594	2664
594.996	2684
597.395	2674
599.793	2728
602.191	2684
604.588	2708
606.984	2676
609.378	2776
611.773	2822
614.167	2846
616.56	2810
618.953	2832
621.343	2914
623.734	2920
626.124	2988
628.512	2972
630.901	2998
633.289	3092
635.675	2992
638.061	3006
640.446	3146
642.831	3150
645.213	3166
647.595	3206
649.978	3204
652.359	3156
654.738	3232
657.117	3272
659.497	3292
661.875	3266
664.252	3278
666.628	3392
669.003	3332
671.378	3386
673.751	3406
676.124	3470
678.497	3498
680.868	3582
683.239	3502
685.609	3512
687.977	3536
690.346	3572
692.714	3662
695.081	3662
697.446	3654
699.812	3604
702.175	3682
704.539	3656
706.901	3768
709.264	3838
711.625	3868
713.986	3918
716.345	3910
718.705	3964
721.062	4078
723.419	3970
725.775	4026
728.132	4060
730.487	4132
732.841	4190
735.194	4214
737.546	4282
739.898	4312
742.249	4246
744.599	4372
746.949	4356
749.298	4432
751.646	4450
753.993	4432
756.34	4440
758.684	4574
761.029	4582
763.374	4576
765.716	4640
768.059	4684
770.401	4748
772.741	4690
775.082	4784
777.421	4740
779.76	4746
782.097	4942
784.434	4918
786.771	4948
789.106	4944
791.44	5022
793.775	5120
796.108	5102
798.44	5122
800.771	5252
803.102	5190
805.432	5262
807.761	5364
810.09	5472
812.417	5456
814.744	5474
817.071	5508
819.396	5642
821.721	5560
824.045	5710
826.367	5774
828.69	5810
831.012	5860
833.332	5814
835.653	5904
837.972	5952
840.29	6002
842.609	6032
844.925	6198
847.242	6142
849.557	6238
851.871	6232
854.186	6356
856.498	6396
858.81	6460
861.122	6416
863.434	6444
865.744	6452
868.053	6622
870.361	6650
872.669	6674
874.976	6636
877.282	6666
879.588	6734
881.893	6826
884.197	6818
886.5	6742
888.802	6866
891.104	6850
893.405	6968
895.706	6924
898.004	7016
900.303	7070
902.6	7146
904.898	7068
907.194	7168
909.49	7154
911.785	7176
914.08	7134
916.372	7294
918.666	7312
920.957	7404
923.248	7426
925.538	7470
927.828	7486
930.118	7498
932.406	7586
934.693	7636
936.979	7708
939.265	7668
941.55	7608
943.835	7760
946.118	7824
948.401	7760
950.682	7814
952.964	7810
955.245	8076
957.525	8022
959.803	8072
962.082	8010
964.36	8042
966.636	8074
968.913	8088
971.188	8218
973.463	8284
975.736	8278
978.009	8228
980.282	8336
982.554	8344
984.824	8354
987.095	8332
989.364	8384
991.633	8408
993.9	8376
996.167	8420
998.434	8538
1000.7	8548
1002.96	8436
1005.23	8504
1007.49	8576
1009.76	8490
1012.02	8456
1014.28	8680
1016.54	8614
1018.8	8694
1021.06	8674
1023.32	8636
1025.57	8688
1027.83	8802
1030.09	8754
1032.34	8640
1034.6	8794
1036.85	8898
1039.1	8756
1041.35	8800
1043.61	8938
1045.86	8844
1048.11	8914
1050.36	8850
1052.61	8986
1054.85	8952
1057.1	8976
1059.35	8962
1061.59	9050
1063.84	9114
1066.08	8972
1068.33	8946
1070.57	8880
1072.81	8974
1075.05	9014
1077.29	9018
1079.53	8948
1081.77	8978
1084.01	8884
1086.25	8922
1088.48	8882
1090.72	8946
1092.96	8796
1095.19	8858
1097.43	8924
1099.66	8750
1101.89	8670
1104.12	8754
1106.35	8644
1108.59	8886
1110.81	8698
1113.04	8610
1115.27	8714
1117.5	8602
1119.73	8628
1121.95	8684
1124.18	8584
1126.4	8576
1128.63	8642
1130.85	8526
1133.07	8612
1135.29	8486
1137.51	8500
1139.73	8558
1141.95	8442
1144.17	8488
1146.39	8508
1148.61	8494
1150.82	8480
1153.04	8402
1155.26	8518
1157.47	8466
1159.68	8376
1161.9	8454
1164.11	8384
1166.32	8248
1168.53	8292
1170.74	8298
1172.95	8228
1175.16	8234
1177.37	8146
1179.58	8102
1181.78	8144
1183.99	8130
1186.19	7932
1188.4	7908
1190.6	7962
1192.8	7716
1195.01	7792
1197.21	7807.83
1199.41	7648.67
1201.61	7664.1
1203.81	7639.52
1206.01	7595.28
1208.2	7608.44
1210.4	7589.68
1212.6	7577.47
1214.8	7517.76
1216.99	7478.34
1219.18	7429.54
1221.38	7264.92
1223.57	7348.21
1225.76	7253.18
1227.96	7216.68
1230.15	7171.07
1232.34	7103.29
1234.53	7116.65
1236.71	7163.22
1238.9	7151.75
1241.09	7044.14
1243.28	7002.7
1245.46	7017.66
1247.65	6937.96
1249.83	6916.21
1252.02	6913.6
1254.2	6877.57
1256.38	6804.45
1258.56	6873.92
1260.74	6808.42
1262.92	6744.41
1265.1	6720.5
1267.28	6692.34
1269.46	6690.94
1271.64	6640.66
1273.82	6596.95
1275.99	6638.21
1278.17	6572.57
1280.34	6575.48
1282.52	6520.96
1284.69	6509.78
1286.86	6477.37
1289.03	6430.58
1291.21	6367.69
1293.38	6346.35
1295.55	6302.55
1297.71	6303.72
1299.88	6361.46
1302.05	6275.92
1304.22	6234.35
1306.38	6177.54
1308.43	6140
1310.61	6168
1312.78	6044
1314.96	6002
1317.13	6026
1319.3	5990
1321.48	5944
1323.65	5952
1325.82	5854
1327.99	5824
1330.16	5778
1332.33	5706
1334.5	5718
1336.66	5678
1338.83	5712
1341	5576
1343.16	5538
1345.33	5540
1347.49	5518
1349.65	5512
1351.82	5414
1353.98	5356
1356.14	5290
1358.3	5372
1360.46	5210
1362.62	5284
1364.78	5222
1366.94	5202
1369.09	5142
1371.25	5202
1373.41	5138
1375.56	5058
1377.72	5094
1379.87	5000
1382.02	5072
1384.17	4990
1386.33	4944
1388.48	4928
1390.63	4962
1392.78	4966
1394.93	4932
1397.07	4798
1399.22	4898
1401.37	4892
1403.52	4836
1405.66	4794
1407.81	4724
1409.95	4644
1412.09	4756
1414.24	4648
1416.38	4640
1418.52	4558
1420.66	4594
1422.8	4548
1424.94	4554
1427.08	4492
1429.22	4466
1431.35	4520
1433.49	4460
1435.63	4440
1437.76	4408
1439.9	4422
1442.03	4378
1444.17	4312
1446.3	4340
1448.43	4350
1450.56	4298
1452.69	4292
1454.82	4346
1456.95	4256
1459.08	4250
1461.21	4206
1463.34	4242
1465.46	4250
1467.59	4208
1469.71	4144
1471.84	4256
1473.96	4160
1476.08	4138
1478.21	4170
1480.33	4204
1482.45	4098
1484.57	4038
1486.69	4062
1488.81	4100
1490.93	4024
1493.05	4100
1495.16	3986
1497.28	3986
1499.4	3954
1501.51	3926
1503.63	3920
1505.74	3854
1507.85	3898
1509.97	3906
1512.08	3824
1514.19	3854
1516.3	3742
1518.41	3826
1520.52	3716
1522.63	3734
1524.73	3782
1526.84	3726
1528.95	3614
1531.06	3730
1533.16	3624
1535.26	3670
1537.37	3722
1539.47	3700
1541.57	3608
1543.68	3558
1545.78	3580
1547.88	3586
1549.98	3634
1552.08	3568
1554.18	3494
1556.27	3510
1558.37	3492
1560.47	3404
1562.56	3418
1564.66	3420
1566.75	3422
1568.85	3456
1570.94	3432
1573.03	3478
1575.13	3436
1577.22	3308
1579.31	3412
1581.4	3392
1583.49	3442
1585.58	3414
1587.66	3410
1589.75	3318
1591.84	3314
1593.93	3314
1596.01	3296
1598.1	3338
1600.18	3316
1602.26	3272
1604.35	3412
1606.43	3210
1608.51	3294
1610.59	3284
1612.67	3302
1614.75	3302
1616.83	3298
1618.91	3290
1620.99	3324
1623.06	3142
1625.14	3252
1627.21	3258
1629.29	3194
1631.36	3214
1633.44	3280
1635.51	3170
1637.58	3208
1639.66	3094
1641.73	3196
1643.8	3134
1645.87	3122
1647.94	3072
1650	3120
1652.07	3210
1654.14	3092
1656.21	3068
1658.27	3076
1660.34	3114
1662.4	3032
1664.47	3048
1666.53	3054
1668.59	3042
1670.66	3014
1672.72	3010
1674.78	3102
1676.84	3024
1678.9	2956
1680.96	3038
1683.01	3000
1685.07	2928
1687.13	3000
1689.19	2972
1691.24	2964
1693.3	2906
1695.35	2944
1697.4	2966
1699.46	2844
1701.51	2880
1703.56	2858
1705.61	2868
1707.66	2842
1709.71	2848
1711.76	2852
1713.81	2870
1715.86	2830
1717.91	2836
1719.95	2844
1722	2818
1724.04	2822
1726.09	2878
1728.13	2776
1730.18	2764
1732.22	2750
1734.26	2820
1736.3	2774
1738.34	2746
1740.38	2832
1742.42	2716
1744.46	2746
1746.5	2712
1748.54	2750
1750.58	2790
1752.61	2676
1754.65	2756
1756.68	2782
1758.72	2712
1760.75	2736
1762.79	2686
1764.82	2656
1766.85	2716
1768.88	2712
1770.91	2706
1772.94	2656
1774.97	2678
1777	2652
1779.03	2672
1781.06	2628
1783.09	2642
1785.11	2654
1787.14	2646
1789.16	2668
1791.19	2690
1793.21	2716
1795.23	2646
1797.26	2616
1799.28	2588
1801.3	2594
1803.32	2566
1805.34	2584
1807.36	2620
1809.38	2620
1811.4	2604
1813.42	2602
1815.43	2584
1817.45	2604
1819.47	2536
1821.48	2624
1823.49	2626
1825.51	2566
1827.52	2514
1829.54	2548
1831.55	2572
1833.56	2568
1835.57	2572
1837.58	2508
1839.59	2514
1841.6	2458
1843.61	2552
1845.61	2520
1847.62	2450
1849.63	2484
1851.63	2448
1853.64	2460
1855.64	2520
1857.65	2454
1859.65	2464
1861.65	2430
1863.65	2434
1865.66	2416
1867.66	2456
1869.66	2460
1871.66	2446
1873.66	2454
1875.65	2488
1877.65	2432
1879.65	2412
1881.65	2488
1883.64	2442
1885.64	2454
1887.63	2414
1889.63	2394
1891.62	2428
1893.61	2362
1895.6	2362
1897.6	2406
1899.59	2334
1901.58	2412
1903.57	2370
1905.56	2400
1907.54	2380
1909.53	2348
1911.52	2396
1913.51	2360
1915.49	2362
1917.48	2380
1919.46	2358
1921.45	2418
1923.43	2360
1925.41	2318
1927.4	2342
1929.38	2366
1931.36	2430
1933.34	2304
1935.32	2340
1937.3	2316
1939.28	2342
1941.26	2298
1943.23	2372
1945.21	2318
1947.19	2362
1949.16	2328
1951.14	2308
1953.11	2378
1955.09	2296
1957.06	2274
1959.03	2278
1961	2274
1962.98	2270
1964.95	2324
1966.92	2288
1968.89	2286
1970.85	2318
1972.82	2326
1974.79	2226
1976.76	2218
1978.73	2238
1980.69	2310
1982.66	2270
1984.62	2312
1986.59	2274
1988.55	2286
1990.51	2294
1992.47	2212
1994.44	2760
1996.4	2258
1998.36	2202
2000.32	2276
2002.28	2248
2004.24	2302
2006.19	2304
2008.15	2220
2010.11	2246
2012.06	2190
2014.02	2180
2015.98	2214
2017.93	2254
2019.88	2232
2021.84	2230
2023.79	2210
2025.74	2170
2027.69	2214
2029.65	2238
2031.6	2214
2033.55	2208
2035.5	2160
2037.44	2270
2039.39	2200
2041.34	2154
2043.29	2168
2045.23	2186
2047.18	2206
2049.12	2230
2051.07	2198
2053.01	2226
2054.95	2152
2056.9	2236
2058.84	2164
2060.78	2222
2062.72	2134
2064.66	2190
2066.6	2214
2068.54	2138
2070.48	2222
2072.42	2156
2074.35	2150
2076.29	2172
2078.23	2180
2080.16	2154
2082.1	2080
2084.03	2072
2085.96	2174
2087.9	2170
2089.83	2100
2091.76	2100
2093.69	2138
2095.62	2118
2097.55	2064
2099.48	2154
2101.41	2090
2103.34	2152
2105.27	2108
2107.2	2080
2109.12	2140
2111.05	2068
2112.98	2150
2114.9	2082
2116.82	2102
2118.75	2084
2120.67	2102
2122.59	2170
2124.52	2112
2126.44	2092
2128.36	2086
2130.28	2078
2132.2	2062
2134.12	2050
2136.04	2116
2137.95	2046
2139.87	2030
2141.79	2064
2143.7	2122
2145.62	2035.96
2147.53	2037.17
2149.45	2050.24
2151.36	2060.6
2153.28	2072.56
2155.19	2061.89
2157.1	2015.98
2159.01	2003.55
2160.92	2000.12
2162.83	1993.58
2164.74	1985.14
2166.65	2008.93
2168.56	2000.72
2170.47	2011.66
2172.38	1972.71
2174.28	1973.3
2176.19	1981.03
2178.09	1985.43
2180	1954.08
2181.9	2001.32
2183.81	2003.73
2185.71	1978.28
2187.61	1929.71
2189.52	1955.85
2191.42	1946.62
2193.32	1941.69
2195.22	1949.44
2197.12	1929.04
2199.02	1936.11
2200.92	1911.77
2202.82	1924.47
2204.71	1917.86
2206.61	1906.81
2208.51	1948.27
2210.4	1948.76
2212.3	1940.14
2214.19	1929.08
2216.09	1902.18
2217.98	1955.12
2219.87	1894.83
2221.77	1924.38
2223.66	1943.73
2225.55	1915.22
2227.44	1920.42
2229.33	1916.19
2231.22	1933.77
2233.11	1916.57
2235	1932.96
2236.88	1946.2
2238.77	1918.94
2240.66	1945.89
2242.07	1904
2243.97	1910
2245.87	1862
2247.76	1888
2249.65	1838
2251.55	1918
2253.44	1936
2255.33	1958
2257.22	1850
2259.12	1924
2261.01	1866
2262.9	1880
2264.78	1874
2266.67	1860
2268.56	1852
2270.45	1910
2272.34	1892
2274.22	1858
2276.11	1826
2277.99	1840
2279.88	1840
2281.76	1820
2283.65	1852
2285.53	1840
2287.41	1800
2289.3	1808
2291.18	1772
2293.06	1828
2294.94	1836
2296.82	1836
2298.7	1780
2300.58	1794
2302.46	1832
2304.33	1748
2306.21	1790
2308.09	1860
2309.96	1866
2311.84	1772
2313.71	1768
2315.59	1728
2317.46	1800
2319.33	1798
2321.21	1792
2323.08	1812
2324.95	1758
2326.82	1752
2328.69	1742
2330.56	1744
2332.43	1754
2334.3	1762
2336.17	1734
2338.03	1686
2339.9	1778
2341.77	1738
2343.63	1774
2345.5	1748
2347.36	1714
2349.23	1676
2351.09	1762
2352.95	1726
2354.82	1692
2356.68	1728
2358.54	1724
2360.4	1700
2362.26	1752
2364.12	1690
2365.98	1674
2367.84	1712
2369.7	1754
2371.56	1652
2373.41	1706
2375.27	1712
2377.12	1664
2378.98	1680
2380.84	1662
2382.69	1676
2384.54	1690
2386.4	1684
2388.25	1614
2390.1	1656
2391.95	1666
2393.8	1618
2395.65	1658
2397.5	1628
2399.35	1636
2401.2	1604
2403.05	1642
2404.9	1598
2406.75	1656
2408.59	1630
2410.44	1628
2412.28	1600
2414.13	1568
2415.97	1568
2417.82	1628
2419.66	1578
2421.5	1574
2423.35	1570
2425.19	1586
2427.03	1550
2428.87	1570
2430.71	1580
2432.55	1588
2434.39	1550
2436.23	1550
2438.06	1510
2439.9	1520
2441.74	1556
2443.57	1524
2445.41	1488
2447.24	1486
2449.08	1502
2450.91	1540
2452.75	1508
2454.58	1504
2456.41	1494
2458.24	1510
2460.08	1550
2461.91	1504
2463.74	1478
2465.57	1468
2467.4	1440
2469.22	1492
2471.05	1466
2472.88	1506
2474.71	1494
2476.53	1470
2478.36	1412
2480.19	1430
2482.01	1492
2483.83	1442
2485.66	1454
2487.48	1424
2489.3	1422
2491.13	1384
2492.95	1458
2494.77	1426
2496.59	1454
2498.41	1394
2500.23	1410
2502.05	1428
2503.87	1412
2505.68	1440
2507.5	1392
2509.32	1448
2511.14	1376
2512.95	1362
2514.77	1362
2516.58	1372
2518.39	1340
2520.21	1362
2522.02	1310
2523.83	1366
2525.65	1344
2527.46	1330
2529.27	1298
2531.08	1328
2532.89	1322
2534.7	1334
2536.51	1280
2538.32	1298
2540.12	1298
2541.93	1298
2543.74	1306
2545.54	1312
2547.35	1272
2549.15	1252
2550.96	1280
2552.76	1310
2554.56	1266
2556.37	1248
2558.17	1282
2559.97	1268
2561.77	1252
2563.58	1270
2565.38	1260
2567.18	1272
2568.97	1262
2570.77	1236
2572.57	1246
2574.37	1210
2576.17	1214
2577.96	1220
2579.76	1210
2581.55	1202
2583.35	1192
2585.14	1188
2586.94	1196
2588.73	1192
2590.52	1194
2592.32	1184
2594.11	1162
2595.9	1196
2597.69	1146
2599.48	1174
2601.27	1158
2603.06	1184
2604.85	1134
2606.64	1172
2608.42	1186
2610.21	1168
2612	1150
2613.78	1112
2615.57	1156
2617.36	1114
2619.14	1146
2620.92	1104
2622.71	1100
2624.49	1112
2626.27	1128
2628.05	1106
2629.84	1076
2631.62	1092
2633.4	1100
2635.18	1132
2636.96	1058
2638.74	1038
2640.51	1050
2642.29	1056
2644.07	1034
2645.85	1084
2647.62	1054
2649.4	1084
2651.17	1060
2652.95	1008
2654.72	1072
2656.5	1024
2658.27	1042
2660.04	1026
2661.81	1058
2663.58	1012
2665.35	1034
2667.13	1026
2668.9	976
2670.66	1010
2672.43	992
2674.2	1026
2675.97	1000
2677.74	980
2679.5	1028
2681.27	996
2683.04	978
2684.8	972
2686.57	984
2688.33	988
2690.09	1000
2691.86	996
2693.62	948
2695.38	972
2697.15	988
2698.91	992
2700.67	962
2702.43	962
2704.19	974
2705.95	946
2707.7	936
2709.46	940
2711.22	938
2712.98	946
2714.73	930
2716.49	918
2718.25	912
2720	906
2721.76	942
2723.51	914
2725.26	904
2727.02	930
2728.77	902
2730.52	946
2732.27	888
2734.02	858
2735.77	912
2737.52	878
2739.27	898
2741.02	862
2742.77	866
2744.52	844
2746.27	872
2748.01	858
2749.76	846
2751.51	856
2753.25	818
2755	866
2756.74	848
2758.48	844
2760.23	850
2761.97	844
2763.71	844
2765.45	840
2767.19	850
2768.94	860
2770.68	838
2772.42	806
2774.16	828
2775.89	840
2777.63	818
2779.37	778
2781.11	832
2782.84	810
2784.58	832
2786.32	770
2788.05	804
2789.79	806
2791.52	796
2793.25	776
2794.99	788
2796.72	798
2798.45	786
2800.18	786
2801.92	770
2803.65	775
2805.38	774
2807.11	776
2808.84	784
2810.57	760
2812.29	778
2814.02	746
2815.75	752
2817.47	784
2819.2	730
2820.93	736
2822.65	752
2824.38	750
2826.1	756
2827.82	750
2829.55	746
2831.27	754
2832.99	710
2834.71	670
2836.44	750
2838.16	734
2839.88	730
2841.6	698
2843.32	718
2845.03	720
2846.75	676
2848.47	688
2850.19	690
2851.9	686
2853.62	696
2855.34	674
2857.05	676
2858.77	690
2860.48	662
2862.19	678
2863.91	678
2865.62	664
2867.33	660
2869.04	666
2870.76	694
2872.47	650
2874.18	654
2875.89	640
2877.6	646
2879.31	664
2881.01	658
2882.72	662
2884.43	644
2886.14	648
2887.84	630
2889.55	648
2891.25	652
2892.96	674
2894.66	626
2896.37	622
2898.07	636
2899.77	634
2901.48	638
2903.18	636
2904.88	576
2906.58	610
2908.28	630
2909.98	624
2911.68	618
2913.38	636
2915.08	628
2916.78	642
2918.47	636
2920.17	606
2921.87	628
2923.56	596
2925.26	612
2926.95	608
2928.65	606
2930.34	598
2932.04	604
2933.73	604
2935.42	600
2937.11	590
2938.81	618
2940.5	588
2942.19	588
2943.88	590
2945.57	602
2947.26	588
2948.95	598
2950.64	572
2952.32	586
2954.01	598
2955.7	580
2957.38	550
2959.07	582
2960.75	566
2962.44	564
2964.12	544
2965.81	558
2967.49	564
2969.17	554
2970.86	576
2972.54	560
2974.22	532
2975.9	554
2977.58	560
2979.26	568
2980.94	544
2982.62	524
2984.3	548
2985.98	538
2987.66	562
2989.33	546
2991.01	524
2992.69	516
2994.36	528
2996.04	534
2997.71	524
2999.39	520