File: muestras/tallo/1/Organic_14.txt
#Acq. time (s)=	10
#Accumulations=	1
#Range (cm-¹)=	100...3000
#Windows=	3
#Autofocus=	Off
#AutoExposure=	Off
#Spike filter=	Off
#Delay time (s)=	0
#Binning=	1
#Readout mode=	Signal
#DeNoise=	Off
#ICS correction=	Off
#Dark correction=	Off
#Inst. Process=	Off
#Instrument=	LabRAM HR Evol
#Detector=	Syncerity OE
#Objective=	x100_VIS
#Grating=	600 (500nm)
#ND Filter=	5%
#Laser=	633nm_Edge
#Hole=	74.97
#Range=	Visible
#Project=	Omar
#Sample=	26-06-23
#Site=	1
#Title=	Organic
#Remark=
#Date=	26.06.2023 16:02
#Acquired=	26.06.2023 16:02:41
101.018	1520
103.586	1552
106.152	1550
108.717	1568
111.281	1532
113.845	1572
116.407	1518
118.969	1548
121.53	1500
124.09	1582
126.649	1518
129.207	1532
131.765	1538
134.321	1536
136.877	1558
139.432	1548
141.985	1548
144.538	1530
147.09	1546
149.641	1538
152.191	1518
154.741	1512
157.289	1546
159.837	1524
162.385	1528
164.93	1536
167.476	1534
170.019	1470
172.562	1500
175.105	1546
177.646	1554
180.188	1472
182.727	1508
185.266	1470
187.804	1514
190.342	1490
192.878	1578
195.413	1494
197.948	1558
200.481	1486
203.014	1554
205.546	1476
208.077	1568
210.608	1578
213.137	1542
215.666	1560
218.194	1514
220.721	1552
223.247	1600
225.772	1586
228.295	1546
230.819	1518
233.342	1538
235.864	1596
238.384	1618
240.904	1566
243.423	1552
245.941	1556
248.46	1532
250.975	1570
253.492	1532
256.006	1526
258.519	1564
261.033	1600
263.545	1586
266.057	1588
268.567	1528
271.076	1532
273.585	1554
276.094	1562
278.601	1552
281.107	1562
283.612	1550
286.116	1538
288.62	1544
291.123	1570
293.625	1588
296.126	1572
298.626	1598
301.126	1588
303.625	1616
306.122	1554
308.62	1624
311.114	1664
313.61	1604
316.105	1570
318.599	1594
321.09	1568
323.583	1630
326.073	1544
328.563	1588
331.053	1618
333.541	1628
336.029	1580
338.515	1566
341.001	1560
343.486	1634
345.97	1622
348.453	1610
350.936	1582
353.418	1580
355.898	1590
358.378	1580
360.858	1666
363.336	1636
365.813	1628
368.29	1630
370.766	1624
373.241	1574
375.715	1644
378.188	1642
380.66	1586
383.132	1622
385.603	1554
388.072	1628
390.541	1618
393.01	1644
395.477	1658
397.943	1664
400.409	1664
402.875	1650
405.338	1690
407.802	1660
410.263	1670
412.725	1676
415.185	1700
417.646	1640
420.104	1678
422.564	1726
425.02	1724
427.477	1754
429.933	1722
432.388	1796
434.841	1796
437.294	1784
439.748	1796
442.199	1688
444.65	1798
447.1	1728
449.549	1738
451.997	1784
454.445	1750
456.891	1754
459.337	1758
461.782	1740
464.227	1754
466.669	2036
469.112	2146
471.554	1738
473.995	1774
476.434	1730
478.874	1796
481.312	1794
483.749	1782
486.186	1798
488.622	1832
491.057	1854
493.491	1864
495.925	1804
498.357	1804
500.789	1884
503.221	1852
505.65	1888
508.079	1826
510.509	1854
512.936	1898
515.363	1870
517.789	1868
520.214	1836
522.638	1872
525.062	1910
527.485	1866
529.907	1944
532.328	1892
534.748	1918
537.168	1936
539.587	1944
542.005	1924
544.423	1920
546.838	1904
549.254	1944
551.669	1980
554.082	2012
556.496	2004
558.909	1988
561.319	1982
563.731	2046
566.14	2016
568.549	2038
570.957	2098
573.364	2066
575.771	2042
578.177	2026
580.581	2070
582.987	2108
585.39	2076
587.792	2116
590.193	2110
592.594	2130
594.996	2098
597.395	2156
599.793	2192
602.191	2188
604.588	2204
606.984	2166
609.378	2228
611.773	2194
614.167	2206
616.56	2252
618.953	2302
621.343	2302
623.734	2402
626.124	2332
628.512	2426
630.901	2356
633.289	2376
635.675	2364
638.061	2456
640.446	2442
642.831	2466
645.213	2516
647.595	2490
649.978	2498
652.359	2490
654.738	2530
657.117	2602
659.497	2578
661.875	2598
664.252	2558
666.628	2646
669.003	2618
671.378	2632
673.751	2720
676.124	2668
678.497	2684
680.868	2708
683.239	2732
685.609	2744
687.977	2748
690.346	2740
692.714	2794
695.081	2836
697.446	2832
699.812	2858
702.175	2886
704.539	2928
706.901	2972
709.264	2944
711.625	3010
713.986	3080
716.345	3056
718.705	3048
721.062	3064
723.419	3090
725.775	3208
728.132	3172
730.487	3228
732.841	3242
735.194	3210
737.546	3294
739.898	3266
742.249	3250
744.599	3326
746.949	3324
749.298	3426
751.646	3376
753.993	3390
756.34	3434
758.684	3526
761.029	3432
763.374	3428
765.716	3522
768.059	3578
770.401	3560
772.741	3612
775.082	3604
777.421	3652
779.76	3674
782.097	3686
784.434	3710
786.771	3788
789.106	3744
791.44	3866
793.775	3866
796.108	3856
798.44	3908
800.771	3920
803.102	3978
805.432	4066
807.761	4072
810.09	4136
812.417	4102
814.744	4126
817.071	4234
819.396	4180
821.721	4292
824.045	4268
826.367	4306
828.69	4438
831.012	4444
833.332	4476
835.653	4462
837.972	4542
840.29	4530
842.609	4564
844.925	4626
847.242	4678
849.557	4766
851.871	4736
854.186	4734
856.498	4754
858.81	4780
861.122	4834
863.434	4926
865.744	4852
868.053	4860
870.361	4986
872.669	5038
874.976	4942
877.282	5012
879.588	5056
881.893	5034
884.197	5152
886.5	5190
888.802	5164
891.104	5290
893.405	5210
895.706	5280
898.004	5220
900.303	5234
902.6	5294
904.898	5264
907.194	5304
909.49	5270
911.785	5412
914.08	5320
916.372	5392
918.666	5432
920.957	5484
923.248	5580
925.538	5546
927.828	5590
930.118	5592
932.406	5608
934.693	5724
936.979	5744
939.265	5700
941.55	5714
943.835	5698
946.118	5756
948.401	5818
950.682	5874
952.964	6002
955.245	5932
957.525	5958
959.803	5968
962.082	6138
964.36	6056
966.636	6062
968.913	6086
971.188	6190
973.463	6028
975.736	6164
978.009	6230
980.282	6262
982.554	6266
984.824	6170
987.095	6296
989.364	6258
991.633	6254
993.9	6256
996.167	6336
998.434	6376
1000.7	6420
1002.96	6400
1005.23	6404
1007.49	6394
1009.76	6382
1012.02	6402
1014.28	6492
1016.54	6434
1018.8	6534
1021.06	6394
1023.32	6506
1025.57	6512
1027.83	6560
1030.09	6594
1032.34	6614
1034.6	6582
1036.85	6586
1039.1	6610
1041.35	6702
1043.61	6654
1045.86	6698
1048.11	6746
1050.36	6822
1052.61	6738
1054.85	6688
1057.1	6722
1059.35	6750
1061.59	6762
1063.84	6858
1066.08	6810
1068.33	6820
1070.57	6746
1072.81	6788
1075.05	6800
1077.29	6784
1079.53	6702
1081.77	6742
1084.01	6740
1086.25	6760
1088.48	6676
1090.72	6704
1092.96	6638
1095.19	6642
1097.43	6690
1099.66	6666
1101.89	6622
1104.12	6678
1106.35	6702
1108.59	6708
1110.81	6624
1113.04	6604
1115.27	6740
1117.5	6494
1119.73	6682
1121.95	6582
1124.18	6520
1126.4	6532
1128.63	6532
1130.85	6496
1133.07	6514
1135.29	6586
1137.51	6520
1139.73	6448
1141.95	6640
1144.17	6550
1146.39	6420
1148.61	6488
1150.82	6498
1153.04	6486
1155.26	6428
1157.47	6476
1159.68	6434
1161.9	6372
1164.11	6426
1166.32	6438
1168.53	6434
1170.74	6368
1172.95	6336
1175.16	6406
1177.37	6212
1179.58	6248
1181.78	6230
1183.99	6188
1186.19	6190
1188.4	6084
1190.6	5992
1192.8	6078
1195.01	6028
1197.21	5996.93
1199.41	5990.49
1201.61	5891.11
1203.81	5961.95
1206.01	5816.8
1208.2	5839.32
1210.4	5858.49
1212.6	5821.21
1214.8	5781.98
1216.99	5785.62
1219.18	5754.17
1221.38	5660.8
1223.57	5613.77
1225.76	5638.98
1227.96	5533.47
1230.15	5653.24
1232.34	5575.42
1234.53	5602.57
1236.71	5554.91
1238.9	5501.3
1241.09	5489.96
1243.28	5447.31
1245.46	5442.74
1247.65	5417.45
1249.83	5430.4
1252.02	5408.58
1254.2	5387.96
1256.38	5355.38
1258.56	5355.6
1260.74	5328.79
1262.92	5293.94
1265.1	5228.54
1267.28	5291.63
1269.46	5274.54
1271.64	5237.18
1273.82	5192.22
1275.99	5212.61
1278.17	5164.47
1280.34	5120.54
1282.52	5102.55
1284.69	5087.97
1286.86	5077.06
1289.03	5024.48
1291.21	5083.36
1293.38	5065.58
1295.55	5003.58
1297.71	5022.19
1299.88	4944.15
1302.05	4938.64
1304.22	4866.46
1306.38	4907.37
1308.43	4894
1310.61	4804
1312.78	4672
1314.96	4756
1317.13	4712
1319.3	4680
1321.48	4674
1323.65	4778
1325.82	4572
1327.99	4544
1330.16	4626
1332.33	4592
1334.5	4586
1336.66	4550
1338.83	4442
1341	4414
1343.16	4408
1345.33	4414
1347.49	4276
1349.65	4386
1351.82	4360
1353.98	4260
1356.14	4208
1358.3	4262
1360.46	4242
1362.62	4172
1364.78	4204
1366.94	4126
1369.09	4150
1371.25	4048
1373.41	4102
1375.56	4014
1377.72	4142
1379.87	4044
1382.02	4042
1384.17	4012
1386.33	3970
1388.48	3886
1390.63	3916
1392.78	3930
1394.93	3858
1397.07	3856
1399.22	3908
1401.37	3896
1403.52	3928
1405.66	3860
1407.81	3808
1409.95	3818
1412.09	3698
1414.24	3700
1416.38	3740
1418.52	3766
1420.66	3614
1422.8	3644
1424.94	3590
1427.08	3688
1429.22	3686
1431.35	4178
1433.49	3558
1435.63	3656
1437.76	3542
1439.9	3600
1442.03	3518
1444.17	3530
1446.3	3402
1448.43	3528
1450.56	3468
1452.69	3480
1454.82	3458
1456.95	3548
1459.08	3484
1461.21	3376
1463.34	3396
1465.46	3468
1467.59	3324
1469.71	3422
1471.84	3394
1473.96	3332
1476.08	3298
1478.21	3380
1480.33	3352
1482.45	3304
1484.57	3356
1486.69	3248
1488.81	3238
1490.93	3316
1493.05	3254
1495.16	3274
1497.28	3240
1499.4	3270
1501.51	3144
1503.63	3214
1505.74	3158
1507.85	3170
1509.97	3192
1512.08	3146
1514.19	3134
1516.3	3130
1518.41	3044
1520.52	3036
1522.63	3048
1524.73	3062
1526.84	3040
1528.95	3054
1531.06	3044
1533.16	2994
1535.26	2970
1537.37	2988
1539.47	2952
1541.57	3026
1543.68	2948
1545.78	2894
1547.88	2930
1549.98	2946
1552.08	2882
1554.18	2888
1556.27	2906
1558.37	2838
1560.47	2792
1562.56	2840
1564.66	2804
1566.75	2840
1568.85	2818
1570.94	2806
1573.03	2824
1575.13	2828
1577.22	2762
1579.31	2800
1581.4	2820
1583.49	2778
1585.58	2790
1587.66	2738
1589.75	2782
1591.84	2778
1593.93	2726
1596.01	2746
1598.1	2688
1600.18	2706
1602.26	2722
1604.35	2722
1606.43	2730
1608.51	2782
1610.59	2636
1612.67	2750
1614.75	2690
1616.83	2692
1618.91	2666
1620.99	2654
1623.06	2616
1625.14	2648
1627.21	2694
1629.29	2690
1631.36	2620
1633.44	2642
1635.51	2666
1637.58	2672
1639.66	2638
1641.73	2600
1643.8	2576
1645.87	2570
1647.94	2588
1650	2612
1652.07	2576
1654.14	2546
1656.21	2578
1658.27	2594
1660.34	2486
1662.4	2558
1664.47	2532
1666.53	2514
1668.59	2504
1670.66	2442
1672.72	2438
1674.78	2466
1676.84	2480
1678.9	2508
1680.96	2426
1683.01	2400
1685.07	2412
1687.13	2470
1689.19	2384
1691.24	2436
1693.3	2378
1695.35	2416
1697.4	2406
1699.46	2342
1701.51	2444
1703.56	2398
1705.61	2412
1707.66	2352
1709.71	2378
1711.76	2326
1713.81	2338
1715.86	2380
1717.91	2370
1719.95	2238
1722	2330
1724.04	2310
1726.09	2370
1728.13	2300
1730.18	2234
1732.22	2302
1734.26	2278
1736.3	2294
1738.34	2316
1740.38	2308
1742.42	2278
1744.46	2244
1746.5	2262
1748.54	2266
1750.58	2230
1752.61	2210
1754.65	2274
1756.68	2250
1758.72	2242
1760.75	2238
1762.79	2268
1764.82	2238
1766.85	2224
1768.88	2276
1770.91	2262
1772.94	2160
1774.97	2168
1777	2206
1779.03	2250
1781.06	2248
1783.09	2208
1785.11	2166
1787.14	2116
1789.16	2188
1791.19	2184
1793.21	2166
1795.23	2210
1797.26	2180
1799.28	2128
1801.3	2184
1803.32	2144
1805.34	2132
1807.36	2108
1809.38	2074
1811.4	2198
1813.42	2138
1815.43	2136
1817.45	2170
1819.47	2068
1821.48	2106
1823.49	2130
1825.51	2034
1827.52	2074
1829.54	2084
1831.55	2108
1833.56	2070
1835.57	2094
1837.58	2064
1839.59	2064
1841.6	2072
1843.61	2076
1845.61	2056
1847.62	2062
1849.63	2076
1851.63	2002
1853.64	2020
1855.64	1996
1857.65	1974
1859.65	2064
1861.65	1990
1863.65	1964
1865.66	2032
1867.66	2000
1869.66	1978
1871.66	2020
1873.66	1966
1875.65	1946
1877.65	1978
1879.65	1918
1881.65	1972
1883.64	1994
1885.64	1978
1887.63	1958
1889.63	1950
1891.62	2006
1893.61	2024
1895.6	1976
1897.6	1932
1899.59	1984
1901.58	1926
1903.57	1988
1905.56	1976
1907.54	1920
1909.53	1970
1911.52	1968
1913.51	1966
1915.49	1976
1917.48	1938
1919.46	1916
1921.45	1974
1923.43	1920
1925.41	1884
1927.4	1914
1929.38	1906
1931.36	1914
1933.34	1952
1935.32	1900
1937.3	1860
1939.28	1938
1941.26	1864
1943.23	1966
1945.21	1876
1947.19	1906
1949.16	1908
1951.14	1886
1953.11	1906
1955.09	1872
1957.06	1906
1959.03	1878
1961	1888
1962.98	1950
1964.95	1928
1966.92	1882
1968.89	1870
1970.85	1808
1972.82	1912
1974.79	1910
1976.76	1830
1978.73	1842
1980.69	1856
1982.66	1794
1984.62	1868
1986.59	1790
1988.55	1872
1990.51	1892
1992.47	1816
1994.44	1804
1996.4	1794
1998.36	1854
2000.32	1896
2002.28	1822
2004.24	1816
2006.19	1784
2008.15	1840
2010.11	1782
2012.06	1824
2014.02	1820
2015.98	1766
2017.93	1784
2019.88	1768
2021.84	1812
2023.79	1790
2025.74	1800
2027.69	1798
2029.65	1804
2031.6	1842
2033.55	1800
2035.5	1748
2037.44	1768
2039.39	1766
2041.34	1762
2043.29	1754
2045.23	1762
2047.18	1770
2049.12	1796
2051.07	1742
2053.01	1776
2054.95	1794
2056.9	1804
2058.84	1792
2060.78	1758
2062.72	1726
2064.66	1718
2066.6	1728
2068.54	1754
2070.48	1708
2072.42	1740
2074.35	1780
2076.29	1748
2078.23	1760
2080.16	1746
2082.1	1750
2084.03	1688
2085.96	1780
2087.9	1750
2089.83	1696
2091.76	1742
2093.69	1680
2095.62	1680
2097.55	1734
2099.48	1754
2101.41	1690
2103.34	1672
2105.27	1736
2107.2	1682
2109.12	1700
2111.05	1692
2112.98	1682
2114.9	1654
2116.82	1722
2118.75	1696
2120.67	1652
2122.59	1692
2124.52	1636
2126.44	1704
2128.36	1684
2130.28	1686
2132.2	1702
2134.12	1710
2136.04	1654
2137.95	1676
2139.87	1640
2141.79	1628
2143.7	1684
2145.62	1669.96
2147.53	1657.03
2149.45	1621.39
2151.36	1631.77
2153.28	1610.24
2155.19	1610.7
2157.1	1623.13
2159.01	1640.74
2160.92	1592.71
2162.83	1607.83
2164.74	1584.08
2166.65	1602.07
2168.56	1602.93
2170.47	1588.63
2172.38	1588.7
2174.28	1597.5
2176.19	1634.27
2178.09	1605.92
2180	1618.34
2181.9	1586.06
2183.81	1580.74
2185.71	1571.63
2187.61	1573.41
2189.52	1564.67
2191.42	1574.94
2193.32	1588.28
2195.22	1557.42
2197.12	1581.89
2199.02	1555.36
2200.92	1566.63
2202.82	1558.01
2204.71	1550.31
2206.61	1561.56
2208.51	1563.4
2210.4	1550.21
2212.3	1572.31
2214.19	1561.16
2216.09	1543.2
2217.98	1554.29
2219.87	1517.73
2221.77	1537.69
2223.66	1530.16
2225.55	1558.82
2227.44	1556.41
2229.33	1536.25
2231.22	1557.83
2233.11	1527.48
2235	1534.62
2236.88	1529.78
2238.77	1540.99
2240.66	1522.9
2242.07	1538
2243.97	1580
2245.87	1540
2247.76	1538
2249.65	1562
2251.55	1506
2253.44	1544
2255.33	1506
2257.22	1496
2259.12	1494
2261.01	1520
2262.9	1506
2264.78	1520
2266.67	1528
2268.56	1504
2270.45	1536
2272.34	1552
2274.22	1502
2276.11	1510
2277.99	1540
2279.88	1498
2281.76	1454
2283.65	1492
2285.53	1476
2287.41	1498
2289.3	1482
2291.18	1502
2293.06	1452
2294.94	1464
2296.82	1506
2298.7	1502
2300.58	1466
2302.46	1426
2304.33	1456
2306.21	1454
2308.09	1434
2309.96	1400
2311.84	1434
2313.71	1418
2315.59	1446
2317.46	1448
2319.33	1420
2321.21	1438
2323.08	1462
2324.95	1436
2326.82	1476
2328.69	1470
2330.56	1464
2332.43	1406
2334.3	1406
2336.17	1392
2338.03	1362
2339.9	1434
2341.77	1432
2343.63	1440
2345.5	1378
2347.36	1450
2349.23	1374
2351.09	1350
2352.95	1420
2354.82	1400
2356.68	1382
2358.54	1434
2360.4	1384
2362.26	1414
2364.12	1376
2365.98	1358
2367.84	1406
2369.7	1330
2371.56	1386
2373.41	1404
2375.27	1328
2377.12	1358
2378.98	1350
2380.84	1364
2382.69	1390
2384.54	1322
2386.4	1366
2388.25	1346
2390.1	1306
2391.95	1340
2393.8	1290
2395.65	1304
2397.5	1320
2399.35	1296
2401.2	1318
2403.05	1334
2404.9	1288
2406.75	1230
2408.59	1330
2410.44	1324
2412.28	1318
2414.13	1282
2415.97	1250
2417.82	1266
2419.66	1290
2421.5	1310
2423.35	1280
2425.19	1264
2427.03	1242
2428.87	1302
2430.71	1276
2432.55	1250
2434.39	1260
2436.23	1214
2438.06	1276
2439.9	1238
2441.74	1230
2443.57	1262
2445.41	1210
2447.24	1198
2449.08	1284
2450.91	1268
2452.75	1224
2454.58	1220
2456.41	1236
2458.24	1210
2460.08	1210
2461.91	1228
2463.74	1216
2465.57	1240
2467.4	1216
2469.22	1234
2471.05	1144
2472.88	1190
2474.71	1158
2476.53	1212
2478.36	1192
2480.19	1208
2482.01	1214
2483.83	1188
2485.66	1230
2487.48	1194
2489.3	1150
2491.13	1180
2492.95	1166
2494.77	1140
2496.59	1150
2498.41	1182
2500.23	1124
2502.05	1142
2503.87	1172
2505.68	1114
2507.5	1142
2509.32	1100
2511.14	1146
2512.95	1126
2514.77	1084
2516.58	1096
2518.39	1116
2520.21	1116
2522.02	1124
2523.83	1076
2525.65	1108
2527.46	1086
2529.27	1066
2531.08	1088
2532.89	1100
2534.7	1122
2536.51	1090
2538.32	1082
2540.12	1038
2541.93	1092
2543.74	1076
2545.54	1068
2547.35	1034
2549.15	1052
2550.96	1040
2552.76	1046
2554.56	1024
2556.37	1036
2558.17	1036
2559.97	1012
2561.77	1014
2563.58	1020
2565.38	1012
2567.18	1044
2568.97	1022
2570.77	980
2572.57	1016
2574.37	1002
2576.17	1014
2577.96	1006
2579.76	974
2581.55	988
2583.35	980
2585.14	938
2586.94	962
2588.73	1040
2590.52	988
2592.32	970
2594.11	970
2595.9	940
2597.69	978
2599.48	984
2601.27	934
2603.06	930
2604.85	970
2606.64	936
2608.42	948
2610.21	950
2612	920
2613.78	938
2615.57	962
2617.36	922
2619.14	952
2620.92	944
2622.71	916
2624.49	940
2626.27	932
2628.05	892
2629.84	874
2631.62	884
2633.4	918
2635.18	946
2636.96	910
2638.74	914
2640.51	868
2642.29	884
2644.07	906
2645.85	850
2647.62	908
2649.4	888
2651.17	904
2652.95	854
2654.72	876
2656.5	842
2658.27	866
2660.04	828
2661.81	850
2663.58	868
2665.35	848
2667.13	864
2668.9	852
2670.66	844
2672.43	826
2674.2	840
2675.97	836
2677.74	816
2679.5	840
2681.27	820
2683.04	800
2684.8	842
2686.57	828
2688.33	818
2690.09	816
2691.86	796
2693.62	794
2695.38	772
2697.15	780
2698.91	814
2700.67	806
2702.43	808
2704.19	802
2705.95	796
2707.7	806
2709.46	786
2711.22	774
2712.98	800
2714.73	774
2716.49	786
2718.25	788
2720	800
2721.76	748
2723.51	746
2725.26	800
2727.02	710
2728.77	750
2730.52	736
2732.27	736
2734.02	752
2735.77	764
2737.52	718
2739.27	726
2741.02	708
2742.77	718
2744.52	720
2746.27	714
2748.01	696
2749.76	724
2751.51	736
2753.25	708
2755	694
2756.74	696
2758.48	724
2760.23	710
2761.97	706
2763.71	702
2765.45	724
2767.19	724
2768.94	682
2770.68	706
2772.42	694
2774.16	640
2775.89	636
2777.63	690
2779.37	646
2781.11	674
2782.84	676
2784.58	670
2786.32	648
2788.05	674
2789.79	676
2791.52	696
2793.25	710
2794.99	664
2796.72	670
2798.45	632
2800.18	632
2801.92	674
2803.65	641
2805.38	640
2807.11	646
2808.84	624
2810.57	664
2812.29	636
2814.02	642
2815.75	648
2817.47	632
2819.2	626
2820.93	626
2822.65	636
2824.38	596
2826.1	618
2827.82	608
2829.55	616
2831.27	578
2832.99	596
2834.71	610
2836.44	606
2838.16	606
2839.88	574
2841.6	604
2843.32	614
2845.03	580
2846.75	600
2848.47	598
2850.19	564
2851.9	580
2853.62	612
2855.34	580
2857.05	580
2858.77	606
2860.48	580
2862.19	580
2863.91	580
2865.62	574
2867.33	568
2869.04	568
2870.76	574
2872.47	582
2874.18	564
2875.89	562
2877.6	578
2879.31	556
2881.01	562
2882.72	564
2884.43	582
2886.14	566
2887.84	522
2889.55	510
2891.25	544
2892.96	550
2894.66	546
2896.37	524
2898.07	540
2899.77	524
2901.48	530
2903.18	510
2904.88	542
2906.58	530
2908.28	546
2909.98	496
2911.68	524
2913.38	498
2915.08	518
2916.78	518
2918.47	516
2920.17	546
2921.87	514
2923.56	518
2925.26	504
2926.95	514
2928.65	530
2930.34	502
2932.04	508
2933.73	518
2935.42	498
2937.11	504
2938.81	494
2940.5	496
2942.19	482
2943.88	494
2945.57	502
2947.26	492
2948.95	500
2950.64	462
2952.32	492
2954.01	486
2955.7	500
2957.38	474
2959.07	492
2960.75	494
2962.44	484
2964.12	494
2965.81	476
2967.49	490
2969.17	502
2970.86	472
2972.54	484
2974.22	484
2975.9	482
2977.58	468
2979.26	462
2980.94	454
2982.62	488
2984.3	444
2985.98	448
2987.66	462
2989.33	464
2991.01	472
2992.69	454
2994.36	450
2996.04	462
2997.71	454
2999.39	466