File: muestras/tallo/1/Organic_20.txt
#Acq. time (s)=	10
#Accumulations=	1
#Range (cm-¹)=	100...3000
#Windows=	3
#Autofocus=	Off
#AutoExposure=	Off
#Spike filter=	Off
#Delay time (s)=	0
#Binning=	1
#Readout mode=	Signal
#DeNoise=	Off
#ICS correction=	Off
#Dark correction=	Off
#Inst. Process=	Off
#Instrument=	LabRAM HR Evol
#Detector=	Syncerity OE
#Objective=	x100_VIS
#Grating=	600 (500nm)
#ND Filter=	5%
#Laser=	633nm_Edge
#Hole=	74.97
#Range=	Visible
#Project=	Omar
#Sample=	26-06-23
#Site=	1
#Title=	Organic
#Remark=
#Date=	26.06.2023 16:09
#Acquired=	26.06.2023 16:09:45
101.018	1442
103.586	1430
106.152	1376
108.717	1364
111.281	1398
113.845	1366
116.407	1428
118.969	1394
121.53	1418
124.09	1394
126.649	1422
129.207	1398
131.765	1428
134.321	1440
136.877	1370
139.432	1430
141.985	1362
144.538	1370
147.09	1380
149.641	1410
152.191	1382
154.741	1370
157.289	1392
159.837	1462
162.385	1380
164.93	1404
167.476	1414
170.019	1388
172.562	1392
175.105	1410
177.646	1364
180.188	1390
182.727	1412
185.266	1382
187.804	1412
190.342	1430
192.878	1382
195.413	1406
197.948	1438
200.481	1444
203.014	1424
205.546	1414
208.077	1448
210.608	1390
213.137	1406
215.666	1442
218.194	1406
220.721	1450
223.247	1412
225.772	1462
228.295	1428
230.819	1388
233.342	1434
235.864	1450
238.384	1358
240.904	1450
243.423	1472
245.941	1482
248.46	1468
250.975	1448
253.492	1440
256.006	1458
258.519	1414
261.033	1400
263.545	1446
266.057	1398
268.567	1476
271.076	1422
273.585	1424
276.094	1418
278.601	1434
281.107	1414
283.612	1418
286.116	1420
288.62	1428
291.123	1436
293.625	1464
296.126	1466
298.626	1468
301.126	1486
303.625	1448
306.122	1468
308.62	1428
311.114	1512
313.61	1484
316.105	1436
318.599	1518
321.09	1460
323.583	1450
326.073	1460
328.563	1496
331.053	1524
333.541	1416
336.029	1486
338.515	1496
341.001	1502
343.486	1518
345.97	1490
348.453	1492
350.936	1476
353.418	1498
355.898	1438
358.378	1518
360.858	1548
363.336	1456
365.813	1514
368.29	1498
370.766	1482
373.241	1458
375.715	1484
378.188	1458
380.66	1500
383.132	1500
385.603	1532
388.072	1518
390.541	1510
393.01	1504
395.477	1522
397.943	1516
400.409	1518
402.875	1498
405.338	1538
407.802	1534
410.263	1556
412.725	1620
415.185	1568
417.646	1558
420.104	1586
422.564	1564
425.02	1580
427.477	1550
429.933	1570
432.388	1626
434.841	1582
437.294	1612
439.748	1576
442.199	1600
444.65	1598
447.1	1574
449.549	1606
451.997	1600
454.445	1594
456.891	1624
459.337	1610
461.782	1626
464.227	1588
466.669	1582
469.112	1642
471.554	1618
473.995	1632
476.434	1656
478.874	1612
481.312	1654
483.749	1586
486.186	1654
488.622	1612
491.057	1682
493.491	1632
495.925	1688
498.357	1704
500.789	1690
503.221	1692
505.65	1666
508.079	1692
510.509	1690
512.936	1724
515.363	1704
517.789	1698
520.214	1714
522.638	1742
525.062	1682
527.485	1666
529.907	1700
532.328	1718
534.748	1730
537.168	1710
539.587	1698
542.005	1720
544.423	1728
546.838	1780
549.254	1752
551.669	1756
554.082	1766
556.496	1738
558.909	1728
561.319	1764
563.731	1760
566.14	1766
568.549	1772
570.957	1776
573.364	1792
575.771	1814
578.177	1808
580.581	1768
582.987	1856
585.39	1862
587.792	1846
590.193	1850
592.594	1908
594.996	1868
597.395	1850
599.793	1854
602.191	1842
604.588	1932
606.984	1894
609.378	1924
611.773	1860
614.167	1952
616.56	1988
618.953	1994
621.343	1970
623.734	2004
626.124	2014
628.512	2060
630.901	2034
633.289	2038
635.675	2126
638.061	2096
640.446	2098
642.831	2118
645.213	2134
647.595	2176
649.978	2182
652.359	2148
654.738	2182
657.117	2172
659.497	2198
661.875	2224
664.252	2294
666.628	2230
669.003	2190
671.378	2238
673.751	2182
676.124	2234
678.497	2236
680.868	2330
683.239	2276
685.609	2258
687.977	2304
690.346	2306
692.714	2384
695.081	2348
697.446	2370
699.812	2366
702.175	2388
704.539	2510
706.901	2414
709.264	2536
711.625	2470
713.986	2506
716.345	2498
718.705	2516
721.062	2572
723.419	2596
725.775	2608
728.132	2644
730.487	2588
732.841	2660
735.194	2668
737.546	2618
739.898	2686
742.249	2716
744.599	2692
746.949	2688
749.298	2758
751.646	2808
753.993	2798
756.34	2784
758.684	2784
761.029	2852
763.374	2816
765.716	2826
768.059	2860
770.401	2880
772.741	2918
775.082	2856
777.421	3018
779.76	2980
782.097	2970
784.434	3004
786.771	3060
789.106	3008
791.44	3048
793.775	3054
796.108	3114
798.44	3136
800.771	3142
803.102	3168
805.432	3168
807.761	3170
810.09	3192
812.417	3276
814.744	3234
817.071	3268
819.396	3336
821.721	3346
824.045	3338
826.367	3350
828.69	3398
831.012	3446
833.332	3566
835.653	3478
837.972	3516
840.29	3492
842.609	3584
844.925	3616
847.242	3674
849.557	3628
851.871	3678
854.186	3650
856.498	3750
858.81	3756
861.122	3746
863.434	3848
865.744	3854
868.053	3826
870.361	3854
872.669	3912
874.976	3884
877.282	3974
879.588	3968
881.893	3986
884.197	4032
886.5	3992
888.802	3934
891.104	4030
893.405	4054
895.706	4118
898.004	4070
900.303	4096
902.6	4192
904.898	4144
907.194	4084
909.49	4100
911.785	4180
914.08	4238
916.372	4172
918.666	4312
920.957	4308
923.248	4248
925.538	4302
927.828	4388
930.118	4390
932.406	4314
934.693	4400
936.979	4360
939.265	4392
941.55	4500
943.835	4508
946.118	4468
948.401	4550
950.682	4554
952.964	4612
955.245	4592
957.525	4662
959.803	4630
962.082	4714
964.36	4676
966.636	4668
968.913	4748
971.188	4707
973.463	4752
975.736	4748
978.009	4796
980.282	4818
982.554	4826
984.824	4856
987.095	4812
989.364	4838
991.633	4922
993.9	4968
996.167	4858
998.434	4956
1000.7	4916
1002.96	5002
1005.23	4954
1007.49	5040
1009.76	4984
1012.02	5076
1014.28	5086
1016.54	5012
1018.8	4958
1021.06	5004
1023.32	5026
1025.57	5064
1027.83	5192
1030.09	5190
1032.34	5122
1034.6	5168
1036.85	5118
1039.1	5190
1041.35	5222
1043.61	5168
1045.86	5218
1048.11	5204
1050.36	5278
1052.61	5258
1054.85	5272
1057.1	5208
1059.35	5286
1061.59	5306
1063.84	5368
1066.08	5290
1068.33	5262
1070.57	5316
1072.81	5388
1075.05	5362
1077.29	5404
1079.53	5348
1081.77	5382
1084.01	5332
1086.25	5332
1088.48	5340
1090.72	5268
1092.96	5222
1095.19	5232
1097.43	5276
1099.66	5286
1101.89	5246
1104.12	5256
1106.35	5206
1108.59	5326
1110.81	5296
1113.04	5160
1115.27	5184
1117.5	5160
1119.73	5260
1121.95	5178
1124.18	5198
1126.4	5170
1128.63	5110
1130.85	5164
1133.07	5262
1135.29	5184
1137.51	5182
1139.73	5104
1141.95	5112
1144.17	5160
1146.39	5158
1148.61	5226
1150.82	5144
1153.04	5136
1155.26	5108
1157.47	5134
1159.68	5188
1161.9	5086
1164.11	5050
1166.32	5066
1168.53	5150
1170.74	5116
1172.95	4970
1175.16	4984
1177.37	5002
1179.58	5006
1181.78	4996
1183.99	4956
1186.19	4958
1188.4	4922
1190.6	4950
1192.8	4800
1195.01	4898
1197.21	4795.97
1199.41	4837.48
1201.61	4802.7
1203.81	4766.08
1206.01	4726.89
1208.2	4670.7
1210.4	4651.77
1212.6	4617.37
1214.8	4664.28
1216.99	4525.18
1219.18	4594.54
1221.38	4491.55
1223.57	4527.42
1225.76	4468.9
1227.96	4454.87
1230.15	4465.22
1232.34	4524.45
1234.53	4456.29
1236.71	4404.06
1238.9	4371.09
1241.09	4370.13
1243.28	4416.88
1245.46	4326.61
1247.65	4350.28
1249.83	4305.64
1252.02	4351.61
1254.2	4221.3
1256.38	4281.58
1258.56	4276.52
1260.74	4220.11
1262.92	4189.52
1265.1	4209.98
1267.28	4181.5
1269.46	4162.96
1271.64	4119.84
1273.82	4127.38
1275.99	4144.53
1278.17	4083.49
1280.34	4087.96
1282.52	4033.45
1284.69	4041.92
1286.86	4111.34
1289.03	3969.08
1291.21	4008.58
1293.38	4018.63
1295.55	3925.45
1297.71	3933.63
1299.88	3922.11
1302.05	3931.01
1304.22	3903.28
1306.38	3887.02
1308.43	3848
1310.61	3814
1312.78	3824
1314.96	3744
1317.13	3742
1319.3	3682
1321.48	3720
1323.65	3728
1325.82	3662
1327.99	3602
1330.16	3608
1332.33	3630
1334.5	3596
1336.66	3656
1338.83	3572
1341	3596
1343.16	3596
1345.33	3488
1347.49	3542
1349.65	3516
1351.82	3418
1353.98	3424
1356.14	3402
1358.3	3420
1360.46	3428
1362.62	3396
1364.78	3312
1366.94	3346
1369.09	3366
1371.25	3270
1373.41	3326
1375.56	3210
1377.72	3296
1379.87	3292
1382.02	3260
1384.17	3222
1386.33	3314
1388.48	3216
1390.63	3196
1392.78	3094
1394.93	3160
1397.07	3108
1399.22	3118
1401.37	3166
1403.52	3096
1405.66	3038
1407.81	3114
1409.95	3100
1412.09	3128
1414.24	2974
1416.38	3014
1418.52	2930
1420.66	3046
1422.8	2938
1424.94	2960
1427.08	2978
1429.22	2894
1431.35	2880
1433.49	2952
1435.63	2934
1437.76	2860
1439.9	2940
1442.03	2870
1444.17	2814
1446.3	2788
1448.43	2858
1450.56	2838
1452.69	2818
1454.82	2822
1456.95	2766
1459.08	2810
1461.21	2772
1463.34	2780
1465.46	2784
1467.59	2802
1469.71	2758
1471.84	2838
1473.96	2714
1476.08	2728
1478.21	2778
1480.33	2786
1482.45	2738
1484.57	2694
1486.69	2618
1488.81	2676
1490.93	2658
1493.05	2676
1495.16	2638
1497.28	2628
1499.4	2614
1501.51	2638
1503.63	2594
1505.74	2586
1507.85	2660
1509.97	2556
1512.08	2560
1514.19	2562
1516.3	2524
1518.41	2550
1520.52	2496
1522.63	2512
1524.73	2504
1526.84	2476
1528.95	2488
1531.06	2458
1533.16	2480
1535.26	2434
1537.37	2520
1539.47	2412
1541.57	2406
1543.68	2470
1545.78	2444
1547.88	2430
1549.98	2412
1552.08	2408
1554.18	2374
1556.27	2396
1558.37	2400
1560.47	2358
1562.56	2338
1564.66	2398
1566.75	2336
1568.85	2316
1570.94	2350
1573.03	2340
1575.13	2306
1577.22	2314
1579.31	2318
1581.4	2338
1583.49	2292
1585.58	2304
1587.66	2310
1589.75	2274
1591.84	2340
1593.93	2324
1596.01	2218
1598.1	2296
1600.18	2262
1602.26	2234
1604.35	2230
1606.43	2244
1608.51	2268
1610.59	2200
1612.67	2242
1614.75	2236
1616.83	2220
1618.91	2188
1620.99	2274
1623.06	2200
1625.14	2222
1627.21	2164
1629.29	2160
1631.36	2220
1633.44	2212
1635.51	2188
1637.58	2170
1639.66	2128
1641.73	2188
1643.8	2182
1645.87	2184
1647.94	2118
1650	2118
1652.07	2122
1654.14	2160
1656.21	2126
1658.27	2084
1660.34	2064
1662.4	2034
1664.47	2130
1666.53	2058
1668.59	2098
1670.66	2034
1672.72	2046
1674.78	1978
1676.84	2058
1678.9	2060
1680.96	2060
1683.01	2062
1685.07	2020
1687.13	1964
1689.19	1974
1691.24	2008
1693.3	2018
1695.35	2008
1697.4	2004
1699.46	1962
1701.51	1970
1703.56	1968
1705.61	1970
1707.66	1962
1709.71	1972
1711.76	1944
1713.81	1906
1715.86	1912
1717.91	1946
1719.95	1988
1722	1938
1724.04	1896
1726.09	1918
1728.13	1906
1730.18	1906
1732.22	1906
1734.26	1852
1736.3	1908
1738.34	1908
1740.38	1916
1742.42	1912
1744.46	1926
1746.5	1874
1748.54	1920
1750.58	1848
1752.61	1882
1754.65	1858
1756.68	1864
1758.72	1860
1760.75	1856
1762.79	1838
1764.82	1808
1766.85	1930
1768.88	1830
1770.91	1850
1772.94	1864
1774.97	1878
1777	1840
1779.03	1860
1781.06	1816
1783.09	1834
1785.11	1864
1787.14	1778
1789.16	1828
1791.19	1790
1793.21	1804
1795.23	1834
1797.26	1816
1799.28	1778
1801.3	1782
1803.32	1816
1805.34	1804
1807.36	1780
1809.38	1784
1811.4	1762
1813.42	1790
1815.43	1844
1817.45	1742
1819.47	1710
1821.48	1752
1823.49	1780
1825.51	1734
1827.52	1742
1829.54	1728
1831.55	1736
1833.56	1746
1835.57	1766
1837.58	1728
1839.59	1732
1841.6	1690
1843.61	1698
1845.61	1676
1847.62	1734
1849.63	1674
1851.63	1722
1853.64	1688
1855.64	1670
1857.65	1672
1859.65	1728
1861.65	1704
1863.65	1656
1865.66	1700
1867.66	1672
1869.66	1654
1871.66	1638
1873.66	1640
1875.65	1700
1877.65	1632
1879.65	1646
1881.65	1642
1883.64	1648
1885.64	1646
1887.63	1602
1889.63	1656
1891.62	1654
1893.61	1614
1895.6	1652
1897.6	1630
1899.59	1656
1901.58	1628
1903.57	1668
1905.56	1638
1907.54	1624
1909.53	1578
1911.52	1568
1913.51	1662
1915.49	1626
1917.48	1638
1919.46	1654
1921.45	1620
1923.43	1594
1925.41	1572
1927.4	1618
1929.38	1624
1931.36	1606
1933.34	1574
1935.32	1566
1937.3	1584
1939.28	1620
1941.26	1590
1943.23	1630
1945.21	1628
1947.19	1532
1949.16	1586
1951.14	1532
1953.11	1574
1955.09	1588
1957.06	1552
1959.03	1600
1961	1564
1962.98	1562
1964.95	1488
1966.92	1564
1968.89	1532
1970.85	1540
1972.82	1558
1974.79	1534
1976.76	1528
1978.73	1566
1980.69	1532
1982.66	1544
1984.62	1508
1986.59	1516
1988.55	1520
1990.51	1530
1992.47	1526
1994.44	1530
1996.4	1550
1998.36	1500
2000.32	1548
2002.28	1468
2004.24	1502
2006.19	1494
2008.15	1488
2010.11	1496
2012.06	1482
2014.02	1498
2015.98	1468
2017.93	1482
2019.88	1494
2021.84	1510
2023.79	1458
2025.74	1476
2027.69	1472
2029.65	1490
2031.6	1478
2033.55	1482
2035.5	1502
2037.44	1448
2039.39	1454
2041.34	1486
2043.29	1486
2045.23	1486
2047.18	1488
2049.12	1454
2051.07	1436
2053.01	1456
2054.95	1472
2056.9	1406
2058.84	1454
2060.78	1516
2062.72	1426
2064.66	1442
2066.6	1424
2068.54	1424
2070.48	1460
2072.42	1440
2074.35	1462
2076.29	1398
2078.23	1442
2080.16	1406
2082.1	1440
2084.03	1416
2085.96	1406
2087.9	1446
2089.83	1392
2091.76	1418
2093.69	1380
2095.62	1376
2097.55	1382
2099.48	1368
2101.41	1410
2103.34	1410
2105.27	1396
2107.2	1388
2109.12	1394
2111.05	1362
2112.98	1402
2114.9	1380
2116.82	1398
2118.75	1370
2120.67	1370
2122.59	1426
2124.52	1382
2126.44	1436
2128.36	1410
2130.28	1380
2132.2	1362
2134.12	1336
2136.04	1348
2137.95	1326
2139.87	1356
2141.79	1334
2143.7	1374
2145.62	1351.86
2147.53	1340.92
2149.45	1388.47
2151.36	1336.44
2153.28	1348.13
2155.19	1331.04
2157.1	1320.17
2159.01	1295.4
2160.92	1332.05
2162.83	1341.93
2164.74	1348.9
2166.65	1336.57
2168.56	1300.15
2170.47	1308.51
2172.38	1307.37
2174.28	1289.65
2176.19	1286.27
2178.09	1336.45
2180	1276.42
2181.9	1284.86
2183.81	1273.45
2185.71	1289.34
2187.61	1289.5
2189.52	1283.76
2191.42	1271.87
2193.32	1278.93
2195.22	1283.53
2197.12	1272.82
2199.02	1264.46
2200.92	1261.28
2202.82	1269.11
2204.71	1255.77
2206.61	1262.77
2208.51	1268.16
2210.4	1278.23
2212.3	1248.72
2214.19	1236.14
2216.09	1252.87
2217.98	1268.48
2219.87	1251.02
2221.77	1253.23
2223.66	1228.02
2225.55	1259.45
2227.44	1236.22
2229.33	1276.29
2231.22	1278.59
2233.11	1255.32
2235	1240.48
2236.88	1250.7
2238.77	1234.53
2240.66	1257.63
2242.07	1286
2243.97	1234
2245.87	1270
2247.76	1224
2249.65	1244
2251.55	1250
2253.44	1218
2255.33	1238
2257.22	1246
2259.12	1252
2261.01	1232
2262.9	1218
2264.78	1238
2266.67	1218
2268.56	1204
2270.45	1202
2272.34	1210
2274.22	1228
2276.11	1234
2277.99	1204
2279.88	1256
2281.76	1214
2283.65	1254
2285.53	1218
2287.41	1190
2289.3	1142
2291.18	1194
2293.06	1204
2294.94	1164
2296.82	1194
2298.7	1148
2300.58	1198
2302.46	1202
2304.33	1184
2306.21	1172
2308.09	1144
2309.96	1216
2311.84	1138
2313.71	1170
2315.59	1174
2317.46	1166
2319.33	1160
2321.21	1162
2323.08	1176
2324.95	1132
2326.82	1142
2328.69	1156
2330.56	1126
2332.43	1124
2334.3	1172
2336.17	1182
2338.03	1216
2339.9	1140
2341.77	1140
2343.63	1114
2345.5	1148
2347.36	1130
2349.23	1132
2351.09	1150
2352.95	1154
2354.82	1100
2356.68	1194
2358.54	1122
2360.4	1134
2362.26	1114
2364.12	1128
2365.98	1130
2367.84	1090
2369.7	1124
2371.56	1114
2373.41	1118
2375.27	1118
2377.12	1108
2378.98	1116
2380.84	1096
2382.69	1078
2384.54	1118
2386.4	1084
2388.25	1064
2390.1	1106
2391.95	1102
2393.8	1078
2395.65	1052
2397.5	1082
2399.35	1100
2401.2	1056
2403.05	1072
2404.9	1060
2406.75	1048
2408.59	1092
2410.44	1044
2412.28	1080
2414.13	1044
2415.97	1026
2417.82	1048
2419.66	1038
2421.5	1032
2423.35	1064
2425.19	1020
2427.03	1016
2428.87	1034
2430.71	1034
2432.55	1036
2434.39	996
2436.23	1000
2438.06	1022
2439.9	992
2441.74	980
2443.57	1014
2445.41	1000
2447.24	992
2449.08	1000
2450.91	1020
2452.75	1032
2454.58	966
2456.41	986
2458.24	980
2460.08	990
2461.91	970
2463.74	974
2465.57	976
2467.4	984
2469.22	988
2471.05	972
2472.88	932
2474.71	1010
2476.53	954
2478.36	974
2480.19	968
2482.01	966
2483.83	950
2485.66	962
2487.48	946
2489.3	960
2491.13	966
2492.95	934
2494.77	894
2496.59	932
2498.41	916
2500.23	948
2502.05	900
2503.87	956
2505.68	922
2507.5	958
2509.32	934
2511.14	912
2512.95	926
2514.77	916
2516.58	874
2518.39	898
2520.21	934
2522.02	878
2523.83	902
2525.65	922
2527.46	896
2529.27	862
2531.08	902
2532.89	872
2534.7	874
2536.51	858
2538.32	854
2540.12	884
2541.93	846
2543.74	876
2545.54	854
2547.35	856
2549.15	826
2550.96	844
2552.76	900
2554.56	860
2556.37	852
2558.17	854
2559.97	880
2561.77	850
2563.58	858
2565.38	812
2567.18	824
2568.97	832
2570.77	842
2572.57	814
2574.37	830
2576.17	840
2577.96	818
2579.76	824
2581.55	788
2583.35	792
2585.14	812
2586.94	806
2588.73	838
2590.52	830
2592.32	854
2594.11	806
2595.9	816
2597.69	790
2599.48	790
2601.27	766
2603.06	766
2604.85	778
2606.64	774
2608.42	774
2610.21	794
2612	772
2613.78	752
2615.57	752
2617.36	766
2619.14	764
2620.92	758
2622.71	734
2624.49	770
2626.27	762
2628.05	750
2629.84	776
2631.62	720
2633.4	756
2635.18	762
2636.96	770
2638.74	730
2640.51	708
2642.29	740
2644.07	728
2645.85	736
2647.62	726
2649.4	710
2651.17	746
2652.95	734
2654.72	690
2656.5	722
2658.27	682
2660.04	712
2661.81	734
2663.58	732
2665.35	702
2667.13	734
2668.9	702
2670.66	710
2672.43	686
2674.2	702
2675.97	690
2677.74	722
2679.5	682
2681.27	706
2683.04	700
2684.8	702
2686.57	692
2688.33	714
2690.09	682
2691.86	682
2693.62	648
2695.38	688
2697.15	714
2698.91	670
2700.67	674
2702.43	678
2704.19	654
2705.95	658
2707.7	664
2709.46	658
2711.22	638
2712.98	678
2714.73	622
2716.49	652
2718.25	664
2720	686
2721.76	646
2723.51	652
2725.26	660
2727.02	640
2728.77	628
2730.52	616
2732.27	626
2734.02	646
2735.77	636
2737.52	646
2739.27	616
2741.02	628
2742.77	628
2744.52	628
2746.27	620
2748.01	598
2749.76	612
2751.51	592
2753.25	602
2755	574
2756.74	594
2758.48	610
2760.23	602
2761.97	578
2763.71	604
2765.45	576
2767.19	586
2768.94	578
2770.68	594
2772.42	548
2774.16	578
2775.89	578
2777.63	570
2779.37	564
2781.11	584
2782.84	584
2784.58	584
2786.32	548
2788.05	572
2789.79	564
2791.52	564
2793.25	542
2794.99	574
2796.72	550
2798.45	542
2800.18	582
2801.92	564
2803.65	546
2805.38	516
2807.11	544
2808.84	516
2810.57	560
2812.29	560
2814.02	520
2815.75	554
2817.47	534
2819.2	550
2820.93	544
2822.65	538
2824.38	540
2826.1	520
2827.82	522
2829.55	520
2831.27	508
2832.99	534
2834.71	508
2836.44	494
2838.16	492
2839.88	504
2841.6	496
2843.32	514
2845.03	512
2846.75	490
2848.47	504
2850.19	498
2851.9	508
2853.62	498
2855.34	540
2857.05	496
2858.77	514
2860.48	474
2862.19	500
2863.91	522
2865.62	500
2867.33	486
2869.04	482
2870.76	498
2872.47	472
2874.18	494
2875.89	498
2877.6	474
2879.31	464
2881.01	476
2882.72	470
2884.43	494
2886.14	466
2887.84	482
2889.55	432
2891.25	486
2892.96	464
2894.66	470
2896.37	472
2898.07	480
2899.77	446
2901.48	484
2903.18	436
2904.88	444
2906.58	442
2908.28	444
2909.98	460
2911.68	434
2913.38	436
2915.08	450
2916.78	428
2918.47	432
2920.17	450
2921.87	428
2923.56	464
2925.26	428
2926.95	432
2928.65	440
2930.34	442
2932.04	432
2933.73	426
2935.42	426
2937.11	430
2938.81	464
2940.5	418
2942.19	432
2943.88	430
2945.57	438
2947.26	434
2948.95	396
2950.64	438
2952.32	430
2954.01	418
2955.7	430
2957.38	402
2959.07	434
2960.75	428
2962.44	432
2964.12	434
2965.81	404
2967.49	406
2969.17	404
2970.86	406
2972.54	440
2974.22	402
2975.9	410
2977.58	388
2979.26	406
2980.94	394
2982.62	402
2984.3	406
2985.98	400
2987.66	390
2989.33	394
2991.01	404
2992.69	390
2994.36	392
2996.04	400
2997.71	406
2999.39	368