File: muestras/tallo/1/Organic_03.txt
#Acq. time (s)=	10
#Accumulations=	1
#Range (cm-¹)=	100...3000
#Windows=	3
#Autofocus=	Off
#AutoExposure=	Off
#Spike filter=	Off
#Delay time (s)=	0
#Binning=	1
#Readout mode=	Signal
#DeNoise=	Off
#ICS correction=	Off
#Dark correction=	Off
#Inst. Process=	Off
#Instrument=	LabRAM HR Evol
#Detector=	Syncerity OE
#Objective=	x100_VIS
#Grating=	600 (500nm)
#ND Filter=	5%
#Laser=	633nm_Edge
#Hole=	74.97
#Range=	Visible
#Project=	Omar
#Sample=	26-06-23
#Site=	1
#Title=	Organic
#Remark=
#Date=	26.06.2023 15:51
#Acquired=	26.06.2023 15:51:11
101.018	2602
103.586	2670
106.152	2608
108.717	2640
111.281	2656
113.845	2620
116.407	2670
118.969	2590
121.53	2622
124.09	2636
126.649	2688
129.207	2616
131.765	2668
134.321	2656
136.877	2666
139.432	2612
141.985	2636
144.538	2618
147.09	2588
149.641	2602
152.191	2656
154.741	2662
157.289	2666
159.837	2664
162.385	2658
164.93	2640
167.476	2600
170.019	2612
172.562	2570
175.105	2634
177.646	2606
180.188	2632
182.727	2656
185.266	2628
187.804	2664
190.342	2640
192.878	2576
195.413	2656
197.948	2634
200.481	2590
203.014	2670
205.546	2622
208.077	2690
210.608	2700
213.137	2648
215.666	2630
218.194	2622
220.721	2696
223.247	2678
225.772	2692
228.295	2674
230.819	2622
233.342	2696
235.864	2656
238.384	2682
240.904	2692
243.423	2684
245.941	2736
248.46	2678
250.975	2672
253.492	2688
256.006	2670
258.519	2682
261.033	2770
263.545	2654
266.057	2662
268.567	2706
271.076	2638
273.585	2688
276.094	2678
278.601	2650
281.107	2642
283.612	2636
286.116	2660
288.62	2704
291.123	2688
293.625	2686
296.126	2722
298.626	2686
301.126	2728
303.625	2772
306.122	2752
308.62	2702
311.114	2764
313.61	2742
316.105	2756
318.599	2766
321.09	2734
323.583	2762
326.073	2804
328.563	2734
331.053	2754
333.541	2690
336.029	2756
338.515	2818
341.001	2722
343.486	2824
345.97	2792
348.453	2876
350.936	2756
353.418	2802
355.898	2794
358.378	2842
360.858	2766
363.336	2810
365.813	2860
368.29	2784
370.766	2858
373.241	2788
375.715	2852
378.188	2854
380.66	2804
383.132	2792
385.603	2834
388.072	2796
390.541	2864
393.01	2832
395.477	2880
397.943	2866
400.409	2844
402.875	2844
405.338	2902
407.802	2856
410.263	2982
412.725	2944
415.185	2928
417.646	2964
420.104	2926
422.564	2948
425.02	2986
427.477	2992
429.933	3080
432.388	3022
434.841	3052
437.294	3042
439.748	3084
442.199	3078
444.65	3040
447.1	3058
449.549	3098
451.997	3078
454.445	3088
456.891	3076
459.337	3040
461.782	3034
464.227	3060
466.669	3126
469.112	3110
471.554	3158
473.995	3206
476.434	3160
478.874	3150
481.312	3188
483.749	3204
486.186	3196
488.622	3194
491.057	3220
493.491	3298
495.925	3210
498.357	3276
500.789	3324
503.221	3296
505.65	3356
508.079	3280
510.509	3336
512.936	3318
515.363	3366
517.789	3324
520.214	3370
522.638	3458
525.062	3358
527.485	3340
529.907	3430
532.328	3380
534.748	3448
537.168	3492
539.587	3522
542.005	3476
544.423	3436
546.838	3468
549.254	3488
551.669	3440
554.082	3562
556.496	3584
558.909	3582
561.319	3650
563.731	3570
566.14	3608
568.549	3608
570.957	3688
573.364	3718
575.771	3768
578.177	3790
580.581	3764
582.987	3780
585.39	3828
587.792	3894
590.193	3850
592.594	3890
594.996	3982
597.395	3956
599.793	3932
602.191	3920
604.588	4056
606.984	4024
609.378	4044
611.773	4172
614.167	4144
616.56	4238
618.953	4190
621.343	4258
623.734	4312
626.124	4366
628.512	4398
630.901	4468
633.289	4528
635.675	4522
638.061	4628
640.446	4648
642.831	4634
645.213	4646
647.595	4684
649.978	4806
652.359	4738
654.738	4786
657.117	4862
659.497	4896
661.875	4796
664.252	5060
666.628	5026
669.003	5024
671.378	5114
673.751	5140
676.124	5128
678.497	5090
680.868	5254
683.239	5236
685.609	5276
687.977	5234
690.346	5418
692.714	5414
695.081	5536
697.446	5542
699.812	5552
702.175	5644
704.539	5714
706.901	5694
709.264	5872
711.625	5866
713.986	5976
716.345	5990
718.705	6054
721.062	6128
723.419	6146
725.775	6152
728.132	6306
730.487	6394
732.841	6288
735.194	6448
737.546	6458
739.898	6516
742.249	6636
744.599	6662
746.949	6668
749.298	6778
751.646	6870
753.993	6860
756.34	6890
758.684	7084
761.029	7046
763.374	7162
765.716	7198
768.059	7130
770.401	7254
772.741	7366
775.082	7464
777.421	7514
779.76	7516
782.097	7496
784.434	7670
786.771	7648
789.106	7788
791.44	7860
793.775	7976
796.108	7946
798.44	7950
800.771	8266
803.102	8156
805.432	8344
807.761	8432
810.09	8376
812.417	8560
814.744	8578
817.071	8648
819.396	8756
821.721	8932
824.045	8980
826.367	9076
828.69	9052
831.012	9206
833.332	9180
835.653	9290
837.972	9548
840.29	9500
842.609	9614
844.925	9708
847.242	9742
849.557	9864
851.871	9928
854.186	9914
856.498	10042
858.81	10210
861.122	10294
863.434	10326
865.744	10304
868.053	10484
870.361	10436
872.669	10484
874.976	10686
877.282	10670
879.588	10728
881.893	10752
884.197	10796
886.5	10948
888.802	10878
891.104	11024
893.405	11108
895.706	11046
898.004	11168
900.303	11052
902.6	11264
904.898	11326
907.194	11440
909.49	11408
911.785	11506
914.08	11498
916.372	11574
918.666	11632
920.957	11658
923.248	11780
925.538	11756
927.828	11950
930.118	12054
932.406	11938
934.693	12054
936.979	12076
939.265	12216
941.55	12258
943.835	12272
946.118	12474
948.401	12522
950.682	12420
952.964	12470
955.245	12576
957.525	12632
959.803	12712
962.082	12812
964.36	12930
966.636	12858
968.913	12952
971.188	13006
973.463	13014
975.736	13142
978.009	13096
980.282	13124
982.554	13024
984.824	13110
987.095	13224
989.364	13174
991.633	13336
993.9	13424
996.167	13304
998.434	13346
1000.7	13338
1002.96	13462
1005.23	13554
1007.49	13344
1009.76	13542
1012.02	13508
1014.28	13516
1016.54	13572
1018.8	13676
1021.06	13604
1023.32	13644
1025.57	13840
1027.83	13814
1030.09	13722
1032.34	13796
1034.6	13760
1036.85	13834
1039.1	13938
1041.35	13878
1043.61	14074
1045.86	14028
1048.11	14082
1050.36	14074
1052.61	13988
1054.85	14032
1057.1	13998
1059.35	13982
1061.59	14102
1063.84	14176
1066.08	14212
1068.33	13882
1070.57	14054
1072.81	14148
1075.05	13962
1077.29	14068
1079.53	13914
1081.77	14004
1084.01	13916
1086.25	14004
1088.48	13810
1090.72	13824
1092.96	13814
1095.19	13782
1097.43	13612
1099.66	13716
1101.89	13620
1104.12	13502
1106.35	13570
1108.59	13604
1110.81	13464
1113.04	13440
1115.27	13322
1117.5	13302
1119.73	13316
1121.95	13436
1124.18	13336
1126.4	13134
1128.63	13164
1130.85	13384
1133.07	13294
1135.29	13268
1137.51	13220
1139.73	13184
1141.95	13268
1144.17	13142
1146.39	13176
1148.61	13070
1150.82	13074
1153.04	12940
1155.26	12960
1157.47	12984
1159.68	12854
1161.9	12890
1164.11	12884
1166.32	12814
1168.53	12766
1170.74	12754
1172.95	12642
1175.16	12538
1177.37	12506
1179.58	12576
1181.78	12518
1183.99	12236
1186.19	12364
1188.4	12100
1190.6	12170
1192.8	11922
1195.01	11970
1197.21	11794.8
1199.41	11886.5
1201.61	11675.2
1203.81	11585.7
1206.01	11620.1
1208.2	11537.9
1210.4	11467.5
1212.6	11423.5
1214.8	11291.2
1216.99	11371.2
1219.18	11152.9
1221.38	11130.7
1223.57	11094.8
1225.76	11070.8
1227.96	10901.2
1230.15	10840.8
1232.34	10826.5
1234.53	10761.2
1236.71	10668.7
1238.9	10680.2
1241.09	10550.7
1243.28	10570.5
1245.46	10436.5
1247.65	10361.4
1249.83	10304.6
1252.02	10345.4
1254.2	10336.9
1256.38	10192.1
1258.56	10151.3
1260.74	10071.2
1262.92	10049.1
1265.1	9931.17
1267.28	9986.62
1269.46	9886.5
1271.64	9881.39
1273.82	9810.49
1275.99	9743.2
1278.17	9654.39
1280.34	9672.77
1282.52	9594.99
1284.69	9516.65
1286.86	9433.29
1289.03	9489.32
1291.21	9431.1
1293.38	9364.24
1295.55	9327.31
1297.71	9293.89
1299.88	9133.9
1302.05	9130.91
1304.22	9023.28
1306.38	8944.48
1308.43	9068
1310.61	8778
1312.78	8838
1314.96	8910
1317.13	8788
1319.3	8654
1321.48	8534
1323.65	8468
1325.82	8494
1327.99	8470
1330.16	8458
1332.33	8290
1334.5	8326
1336.66	8208
1338.83	8168
1341	8016
1343.16	7998
1345.33	7956
1347.49	7782
1349.65	7874
1351.82	7812
1353.98	7738
1356.14	7810
1358.3	7674
1360.46	7546
1362.62	7616
1364.78	7484
1366.94	7498
1369.09	7342
1371.25	7540
1373.41	7392
1375.56	7422
1377.72	7238
1379.87	7184
1382.02	7196
1384.17	7090
1386.33	7106
1388.48	7102
1390.63	7036
1392.78	6982
1394.93	6966
1397.07	6938
1399.22	6866
1401.37	6862
1403.52	6816
1405.66	6788
1407.81	6708
1409.95	6660
1412.09	6726
1414.24	6658
1416.38	6616
1418.52	6578
1420.66	6504
1422.8	6452
1424.94	6480
1427.08	6426
1429.22	6364
1431.35	6372
1433.49	6306
1435.63	6290
1437.76	6234
1439.9	6222
1442.03	6098
1444.17	6200
1446.3	6174
1448.43	6128
1450.56	6162
1452.69	6038
1454.82	6010
1456.95	6040
1459.08	6076
1461.21	5988
1463.34	5942
1465.46	5938
1467.59	5894
1469.71	5854
1471.84	5736
1473.96	5844
1476.08	5924
1478.21	5810
1480.33	5792
1482.45	5680
1484.57	5700
1486.69	5660
1488.81	5646
1490.93	5660
1493.05	5632
1495.16	5680
1497.28	5536
1499.4	5574
1501.51	5572
1503.63	5492
1505.74	5492
1507.85	5482
1509.97	5468
1512.08	5438
1514.19	5348
1516.3	5312
1518.41	5368
1520.52	5316
1522.63	5290
1524.73	5326
1526.84	5240
1528.95	5208
1531.06	5240
1533.16	5182
1535.26	5116
1537.37	5030
1539.47	5052
1541.57	5042
1543.68	4994
1545.78	5038
1547.88	4920
1549.98	5044
1552.08	4938
1554.18	4974
1556.27	4972
1558.37	4894
1560.47	4982
1562.56	4880
1564.66	4808
1566.75	4852
1568.85	4818
1570.94	4842
1573.03	4750
1575.13	4802
1577.22	4734
1579.31	4808
1581.4	4698
1583.49	4916
1585.58	4692
1587.66	4760
1589.75	4704
1591.84	4652
1593.93	4636
1596.01	4736
1598.1	4642
1600.18	4670
1602.26	4620
1604.35	4602
1606.43	4672
1608.51	4618
1610.59	4540
1612.67	4554
1614.75	4538
1616.83	4540
1618.91	4556
1620.99	4646
1623.06	4516
1625.14	4524
1627.21	4442
1629.29	4450
1631.36	4386
1633.44	4418
1635.51	4442
1637.58	4438
1639.66	4416
1641.73	4404
1643.8	4404
1645.87	4492
1647.94	4406
1650	4334
1652.07	4342
1654.14	4354
1656.21	4330
1658.27	4314
1660.34	4306
1662.4	4214
1664.47	4334
1666.53	4238
1668.59	4266
1670.66	4208
1672.72	4164
1674.78	4154
1676.84	4248
1678.9	4158
1680.96	4194
1683.01	4164
1685.07	4166
1687.13	4168
1689.19	4168
1691.24	3990
1693.3	4108
1695.35	4148
1697.4	4016
1699.46	4082
1701.51	3998
1703.56	4044
1705.61	3998
1707.66	3968
1709.71	3970
1711.76	3990
1713.81	3996
1715.86	3982
1717.91	3902
1719.95	3950
1722	3828
1724.04	3914
1726.09	3946
1728.13	3850
1730.18	3914
1732.22	3848
1734.26	3902
1736.3	3872
1738.34	3884
1740.38	3886
1742.42	3864
1744.46	3906
1746.5	3866
1748.54	3866
1750.58	3896
1752.61	3836
1754.65	3860
1756.68	3832
1758.72	3756
1760.75	3738
1762.79	3758
1764.82	3860
1766.85	3764
1768.88	3828
1770.91	3776
1772.94	3760
1774.97	3834
1777	3708
1779.03	3726
1781.06	3688
1783.09	3738
1785.11	3778
1787.14	3746
1789.16	3710
1791.19	3732
1793.21	3788
1795.23	3772
1797.26	3668
1799.28	3694
1801.3	3826
1803.32	3650
1805.34	3710
1807.36	3726
1809.38	3730
1811.4	3670
1813.42	3684
1815.43	3688
1817.45	3584
1819.47	3528
1821.48	3570
1823.49	3592
1825.51	3634
1827.52	3590
1829.54	3658
1831.55	3606
1833.56	3606
1835.57	3580
1837.58	3538
1839.59	3550
1841.6	3444
1843.61	3514
1845.61	3558
1847.62	3542
1849.63	3496
1851.63	3522
1853.64	3524
1855.64	3444
1857.65	3502
1859.65	3444
1861.65	3508
1863.65	3442
1865.66	3460
1867.66	3484
1869.66	3418
1871.66	3414
1873.66	3432
1875.65	3412
1877.65	3416
1879.65	3482
1881.65	3516
1883.64	3360
1885.64	3432
1887.63	3380
1889.63	3460
1891.62	3406
1893.61	3382
1895.6	3344
1897.6	3370
1899.59	3390
1901.58	3364
1903.57	3372
1905.56	3330
1907.54	3402
1909.53	3334
1911.52	3338
1913.51	3354
1915.49	3352
1917.48	3418
1919.46	3368
1921.45	3266
1923.43	3430
1925.41	3300
1927.4	3320
1929.38	3374
1931.36	3338
1933.34	3278
1935.32	3302
1937.3	3338
1939.28	3286
1941.26	3296
1943.23	3382
1945.21	3320
1947.19	3350
1949.16	3258
1951.14	3326
1953.11	3362
1955.09	3298
1957.06	3280
1959.03	3280
1961	3302
1962.98	3256
1964.95	3202
1966.92	3262
1968.89	3280
1970.85	3298
1972.82	3224
1974.79	3274
1976.76	3248
1978.73	3266
1980.69	3208
1982.66	3222
1984.62	3168
1986.59	3252
1988.55	3150
1990.51	3274
1992.47	3222
1994.44	3186
1996.4	3244
1998.36	3246
2000.32	3202
2002.28	3172
2004.24	3200
2006.19	3156
2008.15	3208
2010.11	3280
2012.06	3110
2014.02	3166
2015.98	3192
2017.93	3166
2019.88	3198
2021.84	3192
2023.79	3192
2025.74	3190
2027.69	3120
2029.65	3136
2031.6	3168
2033.55	3120
2035.5	3140
2037.44	3168
2039.39	3146
2041.34	3136
2043.29	3130
2045.23	3096
2047.18	3100
2049.12	3120
2051.07	3088
2053.01	3134
2054.95	3134
2056.9	3098
2058.84	3164
2060.78	3110
2062.72	3088
2064.66	3138
2066.6	3092
2068.54	3054
2070.48	3086
2072.42	3032
2074.35	3062
2076.29	3086
2078.23	3068
2080.16	3028
2082.1	3026
2084.03	3038
2085.96	3070
2087.9	3042
2089.83	3068
2091.76	3038
2093.69	3046
2095.62	3002
2097.55	3108
2099.48	3064
2101.41	2990
2103.34	3050
2105.27	3072
2107.2	3056
2109.12	3008
2111.05	3042
2112.98	3006
2114.9	3058
2116.82	3012
2118.75	3048
2120.67	2978
2122.59	2958
2124.52	3008
2126.44	2980
2128.36	2958
2130.28	2996
2132.2	2958
2134.12	3010
2136.04	2998
2137.95	2966
2139.87	2992
2141.79	2966
2143.7	2936
2145.62	2935.55
2147.53	2938.35
2149.45	2864.53
2151.36	2942.79
2153.28	2978.94
2155.19	2902.7
2157.1	2907.63
2159.01	2876.75
2160.92	2911.12
2162.83	2834.44
2164.74	2857.41
2166.65	2847.05
2168.56	2870.22
2170.47	2836.05
2172.38	2824.18
2174.28	2873.99
2176.19	2879.95
2178.09	2800.44
2180	2842.25
2181.9	2790.94
2183.81	2819.06
2185.71	2796.94
2187.61	2755.02
2189.52	2749.31
2191.42	2760.12
2193.32	2772.79
2195.22	2743.93
2197.12	2787.17
2199.02	2776.74
2200.92	2729.53
2202.82	2757.54
2204.71	2744.37
2206.61	2707.21
2208.51	2767.79
2210.4	2770.4
2212.3	2778.5
2214.19	2758.83
2216.09	2726.53
2217.98	2708.17
2219.87	2696.32
2221.77	2734.98
2223.66	2723.52
2225.55	2700.58
2227.44	2711.46
2229.33	2711.74
2231.22	2733.33
2233.11	2706.3
2235	2727.59
2236.88	2693.57
2238.77	2705.46
2240.66	2694.77
2242.07	2666
2243.97	2712
2245.87	2692
2247.76	2674
2249.65	2754
2251.55	2714
2253.44	2676
2255.33	2724
2257.22	2624
2259.12	2738
2261.01	2712
2262.9	2658
2264.78	2694
2266.67	2580
2268.56	2616
2270.45	2690
2272.34	2656
2274.22	2630
2276.11	2590
2277.99	2646
2279.88	2670
2281.76	2566
2283.65	2620
2285.53	2620
2287.41	2586
2289.3	2528
2291.18	2624
2293.06	2602
2294.94	2578
2296.82	2600
2298.7	2570
2300.58	2514
2302.46	2552
2304.33	2528
2306.21	2596
2308.09	2542
2309.96	2546
2311.84	2572
2313.71	2548
2315.59	2522
2317.46	2484
2319.33	2414
2321.21	2498
2323.08	2488
2324.95	2492
2326.82	2440
2328.69	2474
2330.56	2522
2332.43	2468
2334.3	2508
2336.17	2420
2338.03	2464
2339.9	2420
2341.77	2520
2343.63	2474
2345.5	2440
2347.36	2428
2349.23	2434
2351.09	2444
2352.95	2430
2354.82	2412
2356.68	2442
2358.54	2444
2360.4	2358
2362.26	2406
2364.12	2412
2365.98	2364
2367.84	2380
2369.7	2396
2371.56	2370
2373.41	2362
2375.27	2364
2377.12	2326
2378.98	2334
2380.84	2284
2382.69	2302
2384.54	2334
2386.4	2334
2388.25	2294
2390.1	2280
2391.95	2322
2393.8	2310
2395.65	2272
2397.5	2266
2399.35	2266
2401.2	2274
2403.05	2232
2404.9	2216
2406.75	2202
2408.59	2310
2410.44	2228
2412.28	2226
2414.13	2212
2415.97	2252
2417.82	2216
2419.66	2170
2421.5	2220
2423.35	2182
2425.19	2176
2427.03	2130
2428.87	2176
2430.71	2222
2432.55	2206
2434.39	2178
2436.23	2144
2438.06	2140
2439.9	2100
2441.74	2140
2443.57	2130
2445.41	2126
2447.24	2082
2449.08	2094
2450.91	2046
2452.75	2074
2454.58	2118
2456.41	2074
2458.24	2104
2460.08	2110
2461.91	2084
2463.74	2018
2465.57	2046
2467.4	2032
2469.22	2034
2471.05	2056
2472.88	2012
2474.71	2014
2476.53	2012
2478.36	2028
2480.19	2008
2482.01	2002
2483.83	1964
2485.66	2022
2487.48	1970
2489.3	1978
2491.13	1952
2492.95	1956
2494.77	1976
2496.59	1942
2498.41	1884
2500.23	1944
2502.05	1942
2503.87	1896
2505.68	1894
2507.5	1946
2509.32	1880
2511.14	1834
2512.95	1930
2514.77	1850
2516.58	1838
2518.39	1850
2520.21	1860
2522.02	1872
2523.83	1842
2525.65	1850
2527.46	1830
2529.27	1868
2531.08	1842
2532.89	1818
2534.7	1848
2536.51	1800
2538.32	1760
2540.12	1806
2541.93	1772
2543.74	1788
2545.54	1742
2547.35	1742
2549.15	1774
2550.96	1760
2552.76	1778
2554.56	1778
2556.37	1780
2558.17	1760
2559.97	1672
2561.77	1704
2563.58	1682
2565.38	1716
2567.18	1678
2568.97	1696
2570.77	1726
2572.57	1694
2574.37	1678
2576.17	1696
2577.96	1700
2579.76	1652
2581.55	1682
2583.35	1658
2585.14	1644
2586.94	1668
2588.73	1604
2590.52	1626
2592.32	1550
2594.11	1582
2595.9	1602
2597.69	1558
2599.48	1612
2601.27	1598
2603.06	1598
2604.85	1612
2606.64	1536
2608.42	1552
2610.21	1540
2612	1520
2613.78	1538
2615.57	1526
2617.36	1574
2619.14	1486
2620.92	1518
2622.71	1512
2624.49	1510
2626.27	1542
2628.05	1512
2629.84	1474
2631.62	1446
2633.4	1468
2635.18	1428
2636.96	1458
2638.74	1420
2640.51	1468
2642.29	1400
2644.07	1442
2645.85	1488
2647.62	1446
2649.4	1406
2651.17	1396
2652.95	1392
2654.72	1404
2656.5	1420
2658.27	1390
2660.04	1388
2661.81	1392
2663.58	1412
2665.35	1444
2667.13	1398
2668.9	1370
2670.66	1376
2672.43	1358
2674.2	1360
2675.97	1324
2677.74	1348
2679.5	1332
2681.27	1332
2683.04	1344
2684.8	1334
2686.57	1320
2688.33	1316
2690.09	1296
2691.86	1298
2693.62	1290
2695.38	1332
2697.15	1298
2698.91	1320
2700.67	1276
2702.43	1294
2704.19	1286
2705.95	1286
2707.7	1224
2709.46	1272
2711.22	1282
2712.98	1282
2714.73	1190
2716.49	1256
2718.25	1266
2720	1264
2721.76	1244
2723.51	1242
2725.26	1240
2727.02	1198
2728.77	1176
2730.52	1198
2732.27	1182
2734.02	1216
2735.77	1224
2737.52	1186
2739.27	1168
2741.02	1170
2742.77	1126
2744.52	1176
2746.27	1118
2748.01	1180
2749.76	1174
2751.51	1178
2753.25	1164
2755	1158
2756.74	1122
2758.48	1124
2760.23	1122
2761.97	1108
2763.71	1064
2765.45	1140
2767.19	1084
2768.94	1122
2770.68	1074
2772.42	1068
2774.16	1094
2775.89	1092
2777.63	1106
2779.37	1086
2781.11	1100
2782.84	1050
2784.58	1082
2786.32	1086
2788.05	1098
2789.79	1078
2791.52	1028
2793.25	1068
2794.99	1072
2796.72	1028
2798.45	1056
2800.18	1044
2801.92	1018
2803.65	1027
2805.38	1040
2807.11	1022
2808.84	1010
2810.57	1012
2812.29	986
2814.02	1018
2815.75	1014
2817.47	1042
2819.2	1014
2820.93	962
2822.65	1000
2824.38	982
2826.1	996
2827.82	984
2829.55	1000
2831.27	962
2832.99	978
2834.71	952
2836.44	976
2838.16	950
2839.88	940
2841.6	956
2843.32	954
2845.03	926
2846.75	920
2848.47	940
2850.19	898
2851.9	922
2853.62	924
2855.34	916
2857.05	908
2858.77	892
2860.48	876
2862.19	888
2863.91	874
2865.62	848
2867.33	858
2869.04	874
2870.76	882
2872.47	844
2874.18	882
2875.89	896
2877.6	846
2879.31	868
2881.01	868
2882.72	830
2884.43	858
2886.14	856
2887.84	836
2889.55	792
2891.25	824
2892.96	862
2894.66	824
2896.37	804
2898.07	846
2899.77	810
2901.48	804
2903.18	832
2904.88	826
2906.58	828
2908.28	812
2909.98	830
2911.68	812
2913.38	832
2915.08	816
2916.78	816
2918.47	822
2920.17	816
2921.87	820
2923.56	806
2925.26	814
2926.95	816
2928.65	778
2930.34	806
2932.04	776
2933.73	784
2935.42	776
2937.11	802
2938.81	778
2940.5	740
2942.19	772
2943.88	788
2945.57	772
2947.26	792
2948.95	744
2950.64	778
2952.32	734
2954.01	764
2955.7	740
2957.38	754
2959.07	748
2960.75	756
2962.44	758
2964.12	712
2965.81	728
2967.49	738
2969.17	700
2970.86	734
2972.54	670
2974.22	702
2975.9	678
2977.58	700
2979.26	732
2980.94	724
2982.62	702
2984.3	724
2985.98	704
2987.66	708
2989.33	690
2991.01	700
2992.69	676
2994.36	706
2996.04	696
2997.71	698
2999.39	664