File: muestras/tallo/1/Organic_08.txt
#Acq. time (s)=	10
#Accumulations=	1
#Range (cm-¹)=	100...3000
#Windows=	3
#Autofocus=	Off
#AutoExposure=	Off
#Spike filter=	Off
#Delay time (s)=	0
#Binning=	1
#Readout mode=	Signal
#DeNoise=	Off
#ICS correction=	Off
#Dark correction=	Off
#Inst. Process=	Off
#Instrument=	LabRAM HR Evol
#Detector=	Syncerity OE
#Objective=	x100_VIS
#Grating=	600 (500nm)
#ND Filter=	5%
#Laser=	633nm_Edge
#Hole=	74.97
#Range=	Visible
#Project=	Omar
#Sample=	26-06-23
#Site=	1
#Title=	Organic
#Remark=
#Date=	26.06.2023 15:56
#Acquired=	26.06.2023 15:56:08
101.018	1914
103.586	1864
106.152	1838
108.717	1882
111.281	1840
113.845	1872
116.407	1814
118.969	1864
121.53	1904
124.09	1838
126.649	1826
129.207	1856
131.765	1870
134.321	1862
136.877	1868
139.432	1904
141.985	1920
144.538	1844
147.09	1864
149.641	1858
152.191	1860
154.741	1944
157.289	1898
159.837	1872
162.385	1868
164.93	1878
167.476	1860
170.019	1876
172.562	1872
175.105	1824
177.646	1844
180.188	1814
182.727	1862
185.266	1884
187.804	1918
190.342	1870
192.878	1860
195.413	1882
197.948	1814
200.481	1862
203.014	1918
205.546	1918
208.077	1870
210.608	1914
213.137	1900
215.666	1868
218.194	1914
220.721	1838
223.247	1836
225.772	1864
228.295	1910
230.819	1896
233.342	1914
235.864	1882
238.384	1874
240.904	1926
243.423	1884
245.941	1922
248.46	1932
250.975	1924
253.492	1900
256.006	1936
258.519	1928
261.033	1892
263.545	1932
266.057	1922
268.567	1914
271.076	1892
273.585	1876
276.094	1874
278.601	1902
281.107	1886
283.612	1910
286.116	1936
288.62	1918
291.123	1932
293.625	1940
296.126	1924
298.626	1930
301.126	1974
303.625	1954
306.122	1888
308.62	1942
311.114	2012
313.61	1914
316.105	1944
318.599	1954
321.09	1938
323.583	1936
326.073	1910
328.563	1956
331.053	1984
333.541	1962
336.029	1980
338.515	1936
341.001	2010
343.486	2016
345.97	1984
348.453	1952
350.936	1974
353.418	2008
355.898	2028
358.378	1986
360.858	2000
363.336	1974
365.813	1974
368.29	1994
370.766	2032
373.241	2044
375.715	1998
378.188	2042
380.66	1926
383.132	2018
385.603	2004
388.072	1998
390.541	2060
393.01	1996
395.477	1970
397.943	1998
400.409	2018
402.875	2056
405.338	2068
407.802	2038
410.263	2062
412.725	2082
415.185	2084
417.646	2112
420.104	2074
422.564	2200
425.02	2170
427.477	2174
429.933	2170
432.388	2216
434.841	2128
437.294	2202
439.748	2136
442.199	2210
444.65	2138
447.1	2196
449.549	2140
451.997	2210
454.445	2126
456.891	2162
459.337	2190
461.782	2192
464.227	2202
466.669	2192
469.112	2184
471.554	2168
473.995	2236
476.434	2252
478.874	2268
481.312	2254
483.749	2214
486.186	2312
488.622	2330
491.057	2314
493.491	2338
495.925	2266
498.357	2352
500.789	2314
503.221	2324
505.65	2398
508.079	2346
510.509	2324
512.936	2362
515.363	2412
517.789	2348
520.214	2392
522.638	2454
525.062	2446
527.485	2416
529.907	2404
532.328	2414
534.748	2382
537.168	2432
539.587	2428
542.005	2432
544.423	2460
546.838	2530
549.254	2500
551.669	2460
554.082	2492
556.496	2524
558.909	2506
561.319	2560
563.731	2558
566.14	2542
568.549	2572
570.957	2688
573.364	2624
575.771	2666
578.177	2590
580.581	2678
582.987	2726
585.39	2664
587.792	2666
590.193	2714
592.594	2738
594.996	2814
597.395	2768
599.793	2838
602.191	2824
604.588	2804
606.984	2934
609.378	2966
611.773	2934
614.167	2922
616.56	2996
618.953	2906
621.343	2994
623.734	3004
626.124	3074
628.512	3104
630.901	3118
633.289	3136
635.675	3146
638.061	3244
640.446	3182
642.831	3196
645.213	3290
647.595	3300
649.978	3328
652.359	3426
654.738	3420
657.117	3424
659.497	3426
661.875	3472
664.252	3446
666.628	3470
669.003	3588
671.378	3560
673.751	3634
676.124	3620
678.497	3664
680.868	3642
683.239	3674
685.609	3682
687.977	3722
690.346	3730
692.714	3808
695.081	3814
697.446	3850
699.812	3844
702.175	3898
704.539	3966
706.901	3950
709.264	4030
711.625	3986
713.986	4062
716.345	4112
718.705	4162
721.062	4166
723.419	4230
725.775	4308
728.132	4310
730.487	4336
732.841	4364
735.194	4362
737.546	4484
739.898	4452
742.249	4484
744.599	4530
746.949	4550
749.298	4698
751.646	4660
753.993	4666
756.34	4786
758.684	4770
761.029	4764
763.374	4836
765.716	4904
768.059	4976
770.401	4978
772.741	4970
775.082	5062
777.421	5048
779.76	5154
782.097	5168
784.434	5244
786.771	5280
789.106	5202
791.44	5342
793.775	5384
796.108	5430
798.44	5514
800.771	5492
803.102	5568
805.432	5592
807.761	5636
810.09	5716
812.417	5844
814.744	5932
817.071	5904
819.396	5932
821.721	6138
824.045	6100
826.367	6096
828.69	6118
831.012	6220
833.332	6232
835.653	6262
837.972	6338
840.29	6474
842.609	6440
844.925	6440
847.242	6538
849.557	6574
851.871	6674
854.186	6626
856.498	6792
858.81	6836
861.122	6730
863.434	6956
865.744	6880
868.053	6968
870.361	7100
872.669	7072
874.976	7126
877.282	7076
879.588	7192
881.893	7278
884.197	7162
886.5	7386
888.802	7238
891.104	7320
893.405	7396
895.706	7442
898.004	7542
900.303	7456
902.6	7678
904.898	7502
907.194	7576
909.49	7718
911.785	7574
914.08	7672
916.372	7798
918.666	7752
920.957	7790
923.248	7790
925.538	7886
927.828	7848
930.118	8042
932.406	8058
934.693	8098
936.979	8218
939.265	8078
941.55	8188
943.835	8274
946.118	8238
948.401	8420
950.682	8358
952.964	8412
955.245	8550
957.525	8444
959.803	8446
962.082	8480
964.36	8740
966.636	8684
968.913	8592
971.188	8691
973.463	8746
975.736	8708
978.009	8736
980.282	8724
982.554	8842
984.824	8896
987.095	8836
989.364	8830
991.633	8850
993.9	8884
996.167	8890
998.434	9080
1000.7	9136
1002.96	8956
1005.23	9006
1007.49	9074
1009.76	8972
1012.02	9090
1014.28	9140
1016.54	9078
1018.8	9218
1021.06	9200
1023.32	9136
1025.57	9286
1027.83	9244
1030.09	9342
1032.34	9364
1034.6	9420
1036.85	9336
1039.1	9416
1041.35	9312
1043.61	9490
1045.86	9526
1048.11	9346
1050.36	9440
1052.61	9568
1054.85	9480
1057.1	9676
1059.35	9526
1061.59	9492
1063.84	9472
1066.08	9568
1068.33	9592
1070.57	9450
1072.81	9502
1075.05	9418
1077.29	9540
1079.53	9486
1081.77	9536
1084.01	9400
1086.25	9382
1088.48	9386
1090.72	9262
1092.96	9340
1095.19	9394
1097.43	9356
1099.66	9322
1101.89	9262
1104.12	9206
1106.35	9366
1108.59	9324
1110.81	9258
1113.04	9198
1115.27	9110
1117.5	9146
1119.73	9108
1121.95	9120
1124.18	9166
1126.4	9126
1128.63	9036
1130.85	9056
1133.07	9106
1135.29	9052
1137.51	9092
1139.73	8942
1141.95	9066
1144.17	9012
1146.39	8890
1148.61	9086
1150.82	8950
1153.04	8872
1155.26	8914
1157.47	13772
1159.68	9086
1161.9	8778
1164.11	8768
1166.32	8816
1168.53	8740
1170.74	8750
1172.95	8934
1175.16	8650
1177.37	8806
1179.58	8514
1181.78	8548
1183.99	8410
1186.19	8442
1188.4	8506
1190.6	8356
1192.8	8328
1195.01	8290
1197.21	8171.92
1199.41	8123.71
1201.61	8094.04
1203.81	8138.11
1206.01	8113.14
1208.2	7998.99
1210.4	7896.58
1212.6	7789.6
1214.8	7799.71
1216.99	7875.22
1219.18	7769.68
1221.38	7774.59
1223.57	7673.23
1225.76	7628.21
1227.96	7589.98
1230.15	7595.04
1232.34	7548.67
1234.53	7567.18
1236.71	7500.85
1238.9	7445.96
1241.09	7418.45
1243.28	7434.59
1245.46	7330.17
1247.65	7322.96
1249.83	7301.36
1252.02	7225.67
1254.2	7191.27
1256.38	7257.3
1258.56	7179.88
1260.74	7109.43
1262.92	7069.3
1265.1	7074.28
1267.28	7073.16
1269.46	7037.87
1271.64	6977.27
1273.82	7030.55
1275.99	6931.81
1278.17	6953.34
1280.34	6892.08
1282.52	6830.66
1284.69	6731.79
1286.86	6754.58
1289.03	6746.09
1291.21	6726.64
1293.38	6618.18
1295.55	6651.18
1297.71	6620.8
1299.88	6679.06
1302.05	6546.93
1304.22	6443.09
1306.38	6507.16
1308.43	6446
1310.61	6460
1312.78	6354
1314.96	6302
1317.13	6278
1319.3	6294
1321.48	6232
1323.65	6154
1325.82	6210
1327.99	6112
1330.16	6050
1332.33	6030
1334.5	6060
1336.66	6008
1338.83	5914
1341	5940
1343.16	5820
1345.33	5792
1347.49	5812
1349.65	5732
1351.82	5732
1353.98	5644
1356.14	5626
1358.3	5574
1360.46	5518
1362.62	5572
1364.78	5484
1366.94	5482
1369.09	5452
1371.25	5344
1373.41	5434
1375.56	5324
1377.72	5308
1379.87	5298
1382.02	5254
1384.17	5242
1386.33	5248
1388.48	5076
1390.63	5136
1392.78	5210
1394.93	5110
1397.07	5086
1399.22	5050
1401.37	5030
1403.52	5040
1405.66	4922
1407.81	4966
1409.95	4972
1412.09	4844
1414.24	4810
1416.38	4816
1418.52	4880
1420.66	4808
1422.8	4772
1424.94	4688
1427.08	4728
1429.22	4826
1431.35	4740
1433.49	4754
1435.63	4556
1437.76	4520
1439.9	4540
1442.03	4606
1444.17	4534
1446.3	4580
1448.43	4568
1450.56	4500
1452.69	4574
1454.82	4382
1456.95	4462
1459.08	4466
1461.21	4352
1463.34	4404
1465.46	4304
1467.59	4318
1469.71	4324
1471.84	4316
1473.96	4308
1476.08	4264
1478.21	4334
1480.33	4260
1482.45	4244
1484.57	4284
1486.69	4204
1488.81	4194
1490.93	4260
1493.05	4196
1495.16	4086
1497.28	4158
1499.4	4144
1501.51	4166
1503.63	4036
1505.74	4012
1507.85	4026
1509.97	3990
1512.08	3986
1514.19	4052
1516.3	3996
1518.41	3874
1520.52	4010
1522.63	3954
1524.73	3960
1526.84	3902
1528.95	3906
1531.06	3800
1533.16	3844
1535.26	3854
1537.37	3770
1539.47	3860
1541.57	3786
1543.68	3692
1545.78	3758
1547.88	3702
1549.98	3706
1552.08	3660
1554.18	3682
1556.27	3658
1558.37	3736
1560.47	3710
1562.56	3636
1564.66	3590
1566.75	3634
1568.85	3610
1570.94	3540
1573.03	3556
1575.13	3596
1577.22	3556
1579.31	3498
1581.4	3548
1583.49	3574
1585.58	3508
1587.66	3552
1589.75	3482
1591.84	3490
1593.93	3456
1596.01	3482
1598.1	3436
1600.18	3406
1602.26	3392
1604.35	3488
1606.43	3478
1608.51	3354
1610.59	3420
1612.67	3410
1614.75	3364
1616.83	3402
1618.91	3412
1620.99	3392
1623.06	3320
1625.14	3356
1627.21	3400
1629.29	3362
1631.36	3302
1633.44	3340
1635.51	3354
1637.58	3330
1639.66	3254
1641.73	3318
1643.8	3322
1645.87	3344
1647.94	3260
1650	3230
1652.07	3248
1654.14	3294
1656.21	3228
1658.27	3216
1660.34	3240
1662.4	3222
1664.47	3182
1666.53	3132
1668.59	3144
1670.66	3188
1672.72	3152
1674.78	3092
1676.84	3112
1678.9	3070
1680.96	3132
1683.01	3130
1685.07	3110
1687.13	3120
1689.19	3096
1691.24	3106
1693.3	2964
1695.35	3038
1697.4	3032
1699.46	3044
1701.51	3016
1703.56	3080
1705.61	2996
1707.66	2976
1709.71	2912
1711.76	2982
1713.81	3046
1715.86	2954
1717.91	2958
1719.95	2884
1722	2988
1724.04	2956
1726.09	2928
1728.13	2946
1730.18	2930
1732.22	2884
1734.26	2888
1736.3	2894
1738.34	2910
1740.38	2940
1742.42	2926
1744.46	2864
1746.5	2854
1748.54	2824
1750.58	2830
1752.61	2816
1754.65	2838
1756.68	2852
1758.72	2840
1760.75	2868
1762.79	2828
1764.82	2810
1766.85	2820
1768.88	2816
1770.91	2844
1772.94	2738
1774.97	2822
1777	2834
1779.03	2770
1781.06	2800
1783.09	2774
1785.11	2750
1787.14	2736
1789.16	2776
1791.19	2750
1793.21	2860
1795.23	2758
1797.26	2718
1799.28	2754
1801.3	2782
1803.32	2722
1805.34	2740
1807.36	2770
1809.38	2678
1811.4	2686
1813.42	2712
1815.43	2704
1817.45	2652
1819.47	2708
1821.48	2662
1823.49	2660
1825.51	2698
1827.52	2654
1829.54	2628
1831.55	2662
1833.56	2672
1835.57	2600
1837.58	2694
1839.59	2584
1841.6	2656
1843.61	2568
1845.61	2606
1847.62	2584
1849.63	2564
1851.63	2568
1853.64	2606
1855.64	2608
1857.65	2600
1859.65	2608
1861.65	2594
1863.65	2514
1865.66	2538
1867.66	2510
1869.66	2564
1871.66	2536
1873.66	2568
1875.65	2562
1877.65	2472
1879.65	2542
1881.65	2506
1883.64	2544
1885.64	2520
1887.63	2436
1889.63	2538
1891.62	2468
1893.61	2538
1895.6	2532
1897.6	2508
1899.59	2478
1901.58	2490
1903.57	2556
1905.56	2522
1907.54	2558
1909.53	2514
1911.52	2528
1913.51	2490
1915.49	2482
1917.48	2486
1919.46	2506
1921.45	2510
1923.43	2440
1925.41	2532
1927.4	2426
1929.38	2460
1931.36	2404
1933.34	2434
1935.32	2426
1937.3	2478
1939.28	2486
1941.26	2428
1943.23	2472
1945.21	2420
1947.19	2428
1949.16	2380
1951.14	2390
1953.11	2422
1955.09	2466
1957.06	2372
1959.03	2410
1961	2398
1962.98	2406
1964.95	2376
1966.92	2388
1968.89	2370
1970.85	2376
1972.82	2332
1974.79	2386
1976.76	2378
1978.73	2374
1980.69	2396
1982.66	2368
1984.62	2392
1986.59	2442
1988.55	2346
1990.51	2346
1992.47	2360
1994.44	2344
1996.4	2362
1998.36	2360
2000.32	2388
2002.28	2346
2004.24	2372
2006.19	2290
2008.15	2364
2010.11	2348
2012.06	2342
2014.02	2312
2015.98	2362
2017.93	2326
2019.88	2332
2021.84	2374
2023.79	2324
2025.74	2332
2027.69	2306
2029.65	2314
2031.6	2306
2033.55	2308
2035.5	2322
2037.44	2304
2039.39	2332
2041.34	2266
2043.29	2266
2045.23	2308
2047.18	2292
2049.12	2240
2051.07	2266
2053.01	2252
2054.95	2324
2056.9	2250
2058.84	2296
2060.78	2280
2062.72	2280
2064.66	2218
2066.6	2258
2068.54	2242
2070.48	2242
2072.42	2246
2074.35	2234
2076.29	2256
2078.23	2220
2080.16	2242
2082.1	2244
2084.03	2254
2085.96	2192
2087.9	2254
2089.83	2212
2091.76	2228
2093.69	2208
2095.62	2262
2097.55	2244
2099.48	2248
2101.41	2082
2103.34	2236
2105.27	2192
2107.2	2242
2109.12	2186
2111.05	2194
2112.98	2202
2114.9	2220
2116.82	2194
2118.75	2192
2120.67	2216
2122.59	2186
2124.52	2174
2126.44	2202
2128.36	2136
2130.28	2190
2132.2	2168
2134.12	2186
2136.04	2140
2137.95	2150
2139.87	2128
2141.79	2144
2143.7	2138
2145.62	2128.06
2147.53	2181.64
2149.45	2149.03
2151.36	2192.52
2153.28	2182.67
2155.19	2129.36
2157.1	2089.13
2159.01	2089.48
2160.92	2108.78
2162.83	2086.83
2164.74	2113.34
2166.65	2067.82
2168.56	2070.06
2170.47	2077.11
2172.38	2101.31
2174.28	2058.71
2176.19	2093.63
2178.09	2095.41
2180	2103.85
2181.9	2069.88
2183.81	2073.32
2185.71	2027.69
2187.61	2089.83
2189.52	2050.45
2191.42	2027.02
2193.32	2081.78
2195.22	2040.96
2197.12	2021.49
2199.02	2042.4
2200.92	2052.12
2202.82	2049.95
2204.71	2032.18
2206.61	2036.76
2208.51	2040.52
2210.4	2035.64
2212.3	2018.43
2214.19	2037.11
2216.09	2087.44
2217.98	2026.18
2219.87	2028.02
2221.77	2028.1
2223.66	1995.94
2225.55	2008.11
2227.44	2002.39
2229.33	2024.19
2231.22	2021.81
2233.11	2027.94
2235	2016.57
2236.88	2017.72
2238.77	1979.84
2240.66	2012.05
2242.07	1966
2243.97	1962
2245.87	1988
2247.76	1990
2249.65	2020
2251.55	1996
2253.44	1990
2255.33	1984
2257.22	1946
2259.12	2000
2261.01	1956
2262.9	1964
2264.78	1986
2266.67	1936
2268.56	1938
2270.45	2004
2272.34	1998
2274.22	2010
2276.11	1958
2277.99	1930
2279.88	1958
2281.76	1958
2283.65	1986
2285.53	1954
2287.41	1912
2289.3	1944
2291.18	1936
2293.06	1944
2294.94	1918
2296.82	1964
2298.7	1918
2300.58	1894
2302.46	1912
2304.33	1900
2306.21	1848
2308.09	1938
2309.96	1900
2311.84	1926
2313.71	1872
2315.59	1944
2317.46	1882
2319.33	1854
2321.21	1850
2323.08	1880
2324.95	1860
2326.82	1854
2328.69	1862
2330.56	1878
2332.43	1800
2334.3	1864
2336.17	1854
2338.03	1806
2339.9	1836
2341.77	1790
2343.63	1802
2345.5	1784
2347.36	1848
2349.23	1808
2351.09	1796
2352.95	1824
2354.82	1830
2356.68	1858
2358.54	1746
2360.4	1838
2362.26	1724
2364.12	1784
2365.98	1746
2367.84	1754
2369.7	1822
2371.56	1764
2373.41	1748
2375.27	1726
2377.12	1774
2378.98	1760
2380.84	1778
2382.69	1714
2384.54	1734
2386.4	1778
2388.25	1708
2390.1	1696
2391.95	1712
2393.8	1778
2395.65	1710
2397.5	1696
2399.35	1696
2401.2	1712
2403.05	1714
2404.9	1682
2406.75	1690
2408.59	1672
2410.44	1666
2412.28	1676
2414.13	1694
2415.97	1662
2417.82	1694
2419.66	1636
2421.5	1630
2423.35	1654
2425.19	1674
2427.03	1626
2428.87	1632
2430.71	1638
2432.55	1626
2434.39	1644
2436.23	1628
2438.06	1622
2439.9	1668
2441.74	1626
2443.57	1636
2445.41	1614
2447.24	1590
2449.08	1608
2450.91	1582
2452.75	1630
2454.58	1568
2456.41	1574
2458.24	1594
2460.08	1522
2461.91	1584
2463.74	1544
2465.57	1568
2467.4	1558
2469.22	1528
2471.05	1508
2472.88	1560
2474.71	1540
2476.53	1562
2478.36	1504
2480.19	1550
2482.01	1504
2483.83	1498
2485.66	1464
2487.48	1440
2489.3	1488
2491.13	1482
2492.95	1454
2494.77	1448
2496.59	1402
2498.41	1470
2500.23	1444
2502.05	1470
2503.87	1420
2505.68	1458
2507.5	1418
2509.32	1434
2511.14	1462
2512.95	1400
2514.77	1420
2516.58	1360
2518.39	1374
2520.21	1428
2522.02	1400
2523.83	1418
2525.65	1440
2527.46	1402
2529.27	1364
2531.08	1396
2532.89	1384
2534.7	1394
2536.51	1344
2538.32	1344
2540.12	1376
2541.93	1370
2543.74	1354
2545.54	1380
2547.35	1384
2549.15	1380
2550.96	1370
2552.76	1336
2554.56	1326
2556.37	1310
2558.17	1354
2559.97	1330
2561.77	1352
2563.58	1316
2565.38	1364
2567.18	1328
2568.97	1322
2570.77	1272
2572.57	1268
2574.37	1240
2576.17	1284
2577.96	1276
2579.76	1258
2581.55	1264
2583.35	1280
2585.14	1256
2586.94	1220
2588.73	1288
2590.52	1264
2592.32	1254
2594.11	1238
2595.9	1212
2597.69	1194
2599.48	1240
2601.27	1186
2603.06	1212
2604.85	1184
2606.64	1200
2608.42	1188
2610.21	1208
2612	1208
2613.78	1206
2615.57	1176
2617.36	1204
2619.14	1156
2620.92	1200
2622.71	1132
2624.49	1176
2626.27	1186
2628.05	1148
2629.84	1134
2631.62	1162
2633.4	1134
2635.18	1130
2636.96	1132
2638.74	1112
2640.51	1112
2642.29	1116
2644.07	1100
2645.85	1122
2647.62	1098
2649.4	1074
2651.17	1082
2652.95	1130
2654.72	1072
2656.5	1118
2658.27	1078
2660.04	1092
2661.81	1054
2663.58	1108
2665.35	1070
2667.13	1076
2668.9	1050
2670.66	1062
2672.43	1034
2674.2	1040
2675.97	1044
2677.74	1092
2679.5	1030
2681.27	1048
2683.04	1030
2684.8	1018
2686.57	1032
2688.33	1054
2690.09	1016
2691.86	982
2693.62	1010
2695.38	1030
2697.15	1020
2698.91	988
2700.67	998
2702.43	968
2704.19	962
2705.95	1018
2707.7	988
2709.46	980
2711.22	966
2712.98	964
2714.73	984
2716.49	976
2718.25	954
2720	968
2721.76	952
2723.51	924
2725.26	944
2727.02	940
2728.77	932
2730.52	892
2732.27	944
2734.02	934
2735.77	942
2737.52	938
2739.27	918
2741.02	884
2742.77	916
2744.52	922
2746.27	920
2748.01	894
2749.76	914
2751.51	930
2753.25	870
2755	900
2756.74	908
2758.48	894
2760.23	906
2761.97	840
2763.71	874
2765.45	860
2767.19	852
2768.94	862
2770.68	900
2772.42	840
2774.16	846
2775.89	848
2777.63	854
2779.37	818
2781.11	790
2782.84	874
2784.58	810
2786.32	860
2788.05	858
2789.79	844
2791.52	786
2793.25	830
2794.99	828
2796.72	816
2798.45	828
2800.18	814
2801.92	818
2803.65	795
2805.38	804
2807.11	810
2808.84	790
2810.57	826
2812.29	782
2814.02	796
2815.75	770
2817.47	780
2819.2	802
2820.93	788
2822.65	786
2824.38	800
2826.1	788
2827.82	756
2829.55	786
2831.27	760
2832.99	738
2834.71	756
2836.44	760
2838.16	744
2839.88	758
2841.6	756
2843.32	740
2845.03	736
2846.75	720
2848.47	740
2850.19	738
2851.9	716
2853.62	730
2855.34	742
2857.05	734
2858.77	700
2860.48	668
2862.19	710
2863.91	706
2865.62	684
2867.33	694
2869.04	674
2870.76	688
2872.47	678
2874.18	690
2875.89	706
2877.6	688
2879.31	692
2881.01	680
2882.72	652
2884.43	666
2886.14	636
2887.84	650
2889.55	638
2891.25	634
2892.96	692
2894.66	666
2896.37	696
2898.07	680
2899.77	680
2901.48	692
2903.18	626
2904.88	648
2906.58	668
2908.28	642
2909.98	646
2911.68	646
2913.38	662
2915.08	660
2916.78	636
2918.47	652
2920.17	632
2921.87	618
2923.56	646
2925.26	630
2926.95	634
2928.65	624
2930.34	614
2932.04	618
2933.73	618
2935.42	624
2937.11	616
2938.81	596
2940.5	600
2942.19	648
2943.88	636
2945.57	618
2947.26	588
2948.95	574
2950.64	598
2952.32	608
2954.01	596
2955.7	588
2957.38	586
2959.07	594
2960.75	586
2962.44	594
2964.12	594
2965.81	566
2967.49	586
2969.17	590
2970.86	570
2972.54	582
2974.22	588
2975.9	552
2977.58	562
2979.26	552
2980.94	588
2982.62	608
2984.3	528
2985.98	544
2987.66	512
2989.33	546
2991.01	554
2992.69	570
2994.36	510
2996.04	552
2997.71	544
2999.39	548