File: muestras/tallo/1/Organic_07.txt
#Acq. time (s)=	10
#Accumulations=	1
#Range (cm-¹)=	100...3000
#Windows=	3
#Autofocus=	Off
#AutoExposure=	Off
#Spike filter=	Off
#Delay time (s)=	0
#Binning=	1
#Readout mode=	Signal
#DeNoise=	Off
#ICS correction=	Off
#Dark correction=	Off
#Inst. Process=	Off
#Instrument=	LabRAM HR Evol
#Detector=	Syncerity OE
#Objective=	x100_VIS
#Grating=	600 (500nm)
#ND Filter=	5%
#Laser=	633nm_Edge
#Hole=	74.97
#Range=	Visible
#Project=	Omar
#Sample=	26-06-23
#Site=	1
#Title=	Organic
#Remark=
#Date=	26.06.2023 15:55
#Acquired=	26.06.2023 15:55:12
101.018	2008
103.586	2002
106.152	1976
108.717	2030
111.281	1966
113.845	1932
116.407	1924
118.969	1992
121.53	1998
124.09	1962
126.649	1968
129.207	1984
131.765	1988
134.321	1926
136.877	1984
139.432	2020
141.985	2002
144.538	2002
147.09	1946
149.641	1974
152.191	1974
154.741	1966
157.289	1966
159.837	1938
162.385	1980
164.93	1970
167.476	1938
170.019	2020
172.562	1946
175.105	2016
177.646	1958
180.188	1978
182.727	1938
185.266	2058
187.804	1960
190.342	1948
192.878	1982
195.413	2024
197.948	1992
200.481	1972
203.014	2018
205.546	1932
208.077	1994
210.608	1966
213.137	1998
215.666	2014
218.194	2002
220.721	2038
223.247	2042
225.772	1986
228.295	1992
230.819	1982
233.342	2018
235.864	1972
238.384	2000
240.904	1984
243.423	1980
245.941	2068
248.46	2014
250.975	2010
253.492	2030
256.006	2026
258.519	1990
261.033	2064
263.545	1966
266.057	2006
268.567	1964
271.076	2006
273.585	2054
276.094	1964
278.601	1970
281.107	2000
283.612	2002
286.116	1970
288.62	2020
291.123	2028
293.625	2084
296.126	2038
298.626	2084
301.126	2006
303.625	2068
306.122	2032
308.62	2068
311.114	2054
313.61	2102
316.105	2052
318.599	2042
321.09	2046
323.583	2086
326.073	2044
328.563	2144
331.053	2028
333.541	2062
336.029	2110
338.515	2060
341.001	2096
343.486	2026
345.97	2144
348.453	2068
350.936	2116
353.418	2070
355.898	2132
358.378	2102
360.858	2104
363.336	2094
365.813	2144
368.29	2122
370.766	2130
373.241	2126
375.715	2112
378.188	2132
380.66	2076
383.132	2130
385.603	2116
388.072	2104
390.541	2062
393.01	2070
395.477	2114
397.943	2156
400.409	2186
402.875	2150
405.338	2104
407.802	2150
410.263	2150
412.725	2228
415.185	2222
417.646	2202
420.104	2242
422.564	2244
425.02	2218
427.477	2264
429.933	2236
432.388	2288
434.841	2240
437.294	2252
439.748	2300
442.199	2342
444.65	2272
447.1	2300
449.549	2322
451.997	2308
454.445	2340
456.891	2302
459.337	2330
461.782	2312
464.227	2344
466.669	2324
469.112	2320
471.554	2330
473.995	2348
476.434	2314
478.874	2302
481.312	2350
483.749	2402
486.186	2446
488.622	2394
491.057	2466
493.491	2456
495.925	2466
498.357	2456
500.789	2508
503.221	2490
505.65	2454
508.079	2450
510.509	2474
512.936	2484
515.363	2478
517.789	2544
520.214	2534
522.638	2578
525.062	2514
527.485	2608
529.907	2604
532.328	2540
534.748	2476
537.168	2568
539.587	2624
542.005	2592
544.423	2566
546.838	2648
549.254	2592
551.669	2668
554.082	2672
556.496	2650
558.909	2688
561.319	2706
563.731	2722
566.14	2710
568.549	2806
570.957	2764
573.364	2766
575.771	2782
578.177	2870
580.581	2760
582.987	2848
585.39	2826
587.792	2836
590.193	2828
592.594	2920
594.996	2888
597.395	2974
599.793	2946
602.191	2978
604.588	2996
606.984	3020
609.378	3058
611.773	3084
614.167	3086
616.56	3100
618.953	3084
621.343	3230
623.734	3200
626.124	3212
628.512	3268
630.901	3392
633.289	3330
635.675	3404
638.061	3410
640.446	3428
642.831	3466
645.213	3486
647.595	3544
649.978	3538
652.359	3574
654.738	3586
657.117	3592
659.497	3640
661.875	3632
664.252	3670
666.628	3696
669.003	3734
671.378	3722
673.751	3760
676.124	3780
678.497	3858
680.868	3864
683.239	3900
685.609	3974
687.977	3984
690.346	3998
692.714	4052
695.081	4076
697.446	4052
699.812	4140
702.175	4090
704.539	4140
706.901	4240
709.264	4310
711.625	4254
713.986	4424
716.345	4414
718.705	4390
721.062	4514
723.419	4460
725.775	4520
728.132	4508
730.487	4600
732.841	4662
735.194	4672
737.546	4708
739.898	4740
742.249	4824
744.599	4722
746.949	4890
749.298	4896
751.646	4996
753.993	5000
756.34	5010
758.684	5108
761.029	5102
763.374	5148
765.716	5274
768.059	5168
770.401	5318
772.741	5278
775.082	5356
777.421	5390
779.76	5340
782.097	5490
784.434	5522
786.771	5576
789.106	5574
791.44	5712
793.775	5768
796.108	5854
798.44	5866
800.771	5844
803.102	5986
805.432	5996
807.761	6100
810.09	6076
812.417	6088
814.744	6132
817.071	6200
819.396	6312
821.721	6384
824.045	6370
826.367	6476
828.69	6526
831.012	6724
833.332	6612
835.653	6750
837.972	6756
840.29	6816
842.609	6868
844.925	6952
847.242	6922
849.557	7006
851.871	7114
854.186	7062
856.498	7270
858.81	7254
861.122	7308
863.434	7364
865.744	7408
868.053	7424
870.361	7604
872.669	7504
874.976	7530
877.282	7494
879.588	7618
881.893	7698
884.197	7676
886.5	7744
888.802	7776
891.104	7812
893.405	7916
895.706	7888
898.004	7906
900.303	8032
902.6	8064
904.898	7972
907.194	8174
909.49	8192
911.785	8150
914.08	8146
916.372	8166
918.666	8322
920.957	8448
923.248	8262
925.538	8502
927.828	8518
930.118	8614
932.406	8502
934.693	8724
936.979	8616
939.265	8756
941.55	8734
943.835	8864
946.118	8782
948.401	8848
950.682	8984
952.964	8946
955.245	9018
957.525	9014
959.803	9134
962.082	9170
964.36	9190
966.636	9206
968.913	9190
971.188	9225
973.463	9292
975.736	9478
978.009	9386
980.282	9380
982.554	9470
984.824	9410
987.095	9462
989.364	9636
991.633	9516
993.9	9542
996.167	9618
998.434	9570
1000.7	9580
1002.96	9550
1005.23	9592
1007.49	9506
1009.76	9704
1012.02	9726
1014.28	9670
1016.54	9732
1018.8	9780
1021.06	9726
1023.32	9828
1025.57	9870
1027.83	9962
1030.09	9898
1032.34	9902
1034.6	9988
1036.85	10022
1039.1	10054
1041.35	10082
1043.61	10008
1045.86	10082
1048.11	10100
1050.36	10108
1052.61	10222
1054.85	10060
1057.1	10166
1059.35	10054
1061.59	10248
1063.84	10148
1066.08	10176
1068.33	10204
1070.57	10192
1072.81	10178
1075.05	10068
1077.29	10076
1079.53	10120
1081.77	10118
1084.01	9972
1086.25	9934
1088.48	10182
1090.72	9960
1092.96	9946
1095.19	9882
1097.43	9996
1099.66	9972
1101.89	9988
1104.12	9888
1106.35	9914
1108.59	9900
1110.81	9708
1113.04	9784
1115.27	9760
1117.5	9720
1119.73	9634
1121.95	9708
1124.18	9760
1126.4	9666
1128.63	9760
1130.85	9746
1133.07	9630
1135.29	9534
1137.51	9538
1139.73	9542
1141.95	9542
1144.17	9486
1146.39	9582
1148.61	9538
1150.82	9542
1153.04	9486
1155.26	9442
1157.47	9468
1159.68	9402
1161.9	9386
1164.11	9356
1166.32	9442
1168.53	9308
1170.74	9288
1172.95	9106
1175.16	9216
1177.37	9226
1179.58	9112
1181.78	8932
1183.99	9016
1186.19	9008
1188.4	8918
1190.6	8842
1192.8	8748
1195.01	8756
1197.21	8690.76
1199.41	8748.52
1201.61	8703.24
1203.81	8585.13
1206.01	8438.79
1208.2	8526.76
1210.4	8431.36
1212.6	8338.67
1214.8	8311.82
1216.99	8224.55
1219.18	8333.09
1221.38	8228.25
1223.57	8117.74
1225.76	8199.41
1227.96	8175.11
1230.15	8065.57
1232.34	8007.46
1234.53	7893.58
1236.71	7919.43
1238.9	7910.04
1241.09	7820.9
1243.28	7847.89
1245.46	7860.14
1247.65	7761.63
1249.83	7747.39
1252.02	7649.72
1254.2	7706.73
1256.38	7614.72
1258.56	7612.53
1260.74	7559.51
1262.92	7504.69
1265.1	7505.58
1267.28	7483.05
1269.46	7463.3
1271.64	7442.66
1273.82	7383.5
1275.99	7360.99
1278.17	7280.14
1280.34	7261.54
1282.52	7221.71
1284.69	7132.63
1286.86	7148.85
1289.03	7095.73
1291.21	7084.35
1293.38	7116.98
1295.55	6954.56
1297.71	7051.01
1299.88	6962.22
1302.05	6871.68
1304.22	6882.49
1306.38	6837.51
1308.43	6924
1310.61	6812
1312.78	6742
1314.96	6724
1317.13	6730
1319.3	6576
1321.48	6664
1323.65	6566
1325.82	6466
1327.99	6432
1330.16	6418
1332.33	6418
1334.5	6320
1336.66	6234
1338.83	6242
1341	6232
1343.16	6162
1345.33	6110
1347.49	6134
1349.65	6116
1351.82	6062
1353.98	5980
1356.14	5866
1358.3	5822
1360.46	5834
1362.62	5832
1364.78	5770
1366.94	5734
1369.09	5740
1371.25	5672
1373.41	5652
1375.56	5640
1377.72	5592
1379.87	5640
1382.02	5610
1384.17	5558
1386.33	5614
1388.48	5526
1390.63	5420
1392.78	5430
1394.93	5366
1397.07	5336
1399.22	5326
1401.37	5322
1403.52	5274
1405.66	5336
1407.81	5268
1409.95	5168
1412.09	5204
1414.24	5106
1416.38	5094
1418.52	5108
1420.66	5030
1422.8	5046
1424.94	5002
1427.08	5012
1429.22	4954
1431.35	4868
1433.49	4860
1435.63	4846
1437.76	4826
1439.9	4882
1442.03	4858
1444.17	4792
1446.3	4792
1448.43	4752
1450.56	4704
1452.69	4676
1454.82	4758
1456.95	4722
1459.08	4618
1461.21	4652
1463.34	4588
1465.46	4662
1467.59	4606
1469.71	4572
1471.84	4500
1473.96	4582
1476.08	4474
1478.21	4494
1480.33	4484
1482.45	4462
1484.57	4406
1486.69	4440
1488.81	4348
1490.93	4358
1493.05	4390
1495.16	4444
1497.28	4414
1499.4	4306
1501.51	4352
1503.63	4370
1505.74	4210
1507.85	4246
1509.97	4244
1512.08	4164
1514.19	4258
1516.3	4230
1518.41	4076
1520.52	4152
1522.63	4094
1524.73	4112
1526.84	4174
1528.95	4090
1531.06	4042
1533.16	4016
1535.26	4068
1537.37	4016
1539.47	3982
1541.57	4010
1543.68	3900
1545.78	3950
1547.88	3916
1549.98	3876
1552.08	3880
1554.18	3932
1556.27	3918
1558.37	3894
1560.47	3820
1562.56	3766
1564.66	3838
1566.75	3792
1568.85	3772
1570.94	3756
1573.03	3748
1575.13	3700
1577.22	3708
1579.31	3772
1581.4	3738
1583.49	3712
1585.58	3740
1587.66	3616
1589.75	3704
1591.84	3670
1593.93	3648
1596.01	3732
1598.1	3718
1600.18	3626
1602.26	3606
1604.35	3644
1606.43	3654
1608.51	3528
1610.59	3604
1612.67	3614
1614.75	3620
1616.83	3574
1618.91	3550
1620.99	3612
1623.06	3514
1625.14	3474
1627.21	3474
1629.29	3580
1631.36	3484
1633.44	3542
1635.51	3546
1637.58	3494
1639.66	3480
1641.73	3468
1643.8	3454
1645.87	3436
1647.94	3554
1650	3434
1652.07	3420
1654.14	3452
1656.21	3498
1658.27	3398
1660.34	3358
1662.4	3310
1664.47	3370
1666.53	3366
1668.59	3284
1670.66	3296
1672.72	3384
1674.78	3316
1676.84	3256
1678.9	3264
1680.96	3360
1683.01	3270
1685.07	3216
1687.13	3270
1689.19	3202
1691.24	3188
1693.3	3126
1695.35	3204
1697.4	3134
1699.46	3166
1701.51	3188
1703.56	3134
1705.61	3170
1707.66	3154
1709.71	3086
1711.76	3098
1713.81	3040
1715.86	3144
1717.91	3100
1719.95	3076
1722	3070
1724.04	3100
1726.09	3130
1728.13	3068
1730.18	3026
1732.22	3026
1734.26	3084
1736.3	3068
1738.34	3010
1740.38	3114
1742.42	2938
1744.46	3052
1746.5	2948
1748.54	3022
1750.58	3072
1752.61	2980
1754.65	2982
1756.68	2992
1758.72	3030
1760.75	2930
1762.79	2928
1764.82	2948
1766.85	2896
1768.88	3008
1770.91	2962
1772.94	2916
1774.97	2938
1777	2976
1779.03	2950
1781.06	2912
1783.09	2876
1785.11	2954
1787.14	2844
1789.16	2876
1791.19	2950
1793.21	2890
1795.23	2924
1797.26	2880
1799.28	2862
1801.3	2864
1803.32	2868
1805.34	2838
1807.36	2854
1809.38	2864
1811.4	2808
1813.42	2882
1815.43	2810
1817.45	2818
1819.47	2864
1821.48	2846
1823.49	2794
1825.51	2790
1827.52	2768
1829.54	2836
1831.55	2744
1833.56	2794
1835.57	2728
1837.58	2754
1839.59	2802
1841.6	2778
1843.61	2682
1845.61	2678
1847.62	2714
1849.63	2762
1851.63	2698
1853.64	2754
1855.64	2754
1857.65	2624
1859.65	2704
1861.65	2710
1863.65	2664
1865.66	2674
1867.66	2612
1869.66	2708
1871.66	2690
1873.66	2596
1875.65	2638
1877.65	2612
1879.65	2682
1881.65	2632
1883.64	2596
1885.64	2634
1887.63	2608
1889.63	2634
1891.62	2686
1893.61	2566
1895.6	2614
1897.6	2592
1899.59	2602
1901.58	2652
1903.57	2666
1905.56	2604
1907.54	2628
1909.53	2620
1911.52	2650
1913.51	2622
1915.49	2652
1917.48	2556
1919.46	2640
1921.45	2620
1923.43	2616
1925.41	2600
1927.4	2582
1929.38	2568
1931.36	2578
1933.34	2666
1935.32	2562
1937.3	2610
1939.28	2512
1941.26	2574
1943.23	2548
1945.21	2584
1947.19	2568
1949.16	2592
1951.14	2508
1953.11	2574
1955.09	2484
1957.06	2564
1959.03	2534
1961	2560
1962.98	2548
1964.95	2510
1966.92	2526
1968.89	2552
1970.85	2490
1972.82	2450
1974.79	2478
1976.76	2450
1978.73	2516
1980.69	2532
1982.66	2548
1984.62	2456
1986.59	2486
1988.55	2500
1990.51	2462
1992.47	2482
1994.44	2484
1996.4	2494
1998.36	2476
2000.32	2406
2002.28	2416
2004.24	2470
2006.19	2476
2008.15	2492
2010.11	2444
2012.06	2500
2014.02	2422
2015.98	2468
2017.93	2454
2019.88	2440
2021.84	2436
2023.79	2436
2025.74	2430
2027.69	2476
2029.65	2418
2031.6	2470
2033.55	2466
2035.5	2434
2037.44	2360
2039.39	2394
2041.34	2382
2043.29	2360
2045.23	2398
2047.18	2424
2049.12	2416
2051.07	2416
2053.01	2398
2054.95	2448
2056.9	2402
2058.84	2400
2060.78	2434
2062.72	2372
2064.66	2322
2066.6	2420
2068.54	2446
2070.48	2364
2072.42	2338
2074.35	2452
2076.29	2378
2078.23	2360
2080.16	2340
2082.1	2296
2084.03	2368
2085.96	2340
2087.9	2362
2089.83	2386
2091.76	2298
2093.69	2354
2095.62	2420
2097.55	2386
2099.48	2360
2101.41	2344
2103.34	2366
2105.27	2298
2107.2	2332
2109.12	2368
2111.05	2314
2112.98	2324
2114.9	2358
2116.82	2348
2118.75	2336
2120.67	2320
2122.59	2248
2124.52	2278
2126.44	2244
2128.36	2292
2130.28	2254
2132.2	2288
2134.12	2304
2136.04	2294
2137.95	2262
2139.87	2314
2141.79	2296
2143.7	2234
2145.62	2254.02
2147.53	2215.91
2149.45	2213.94
2151.36	2256.44
2153.28	2253.93
2155.19	2230.77
2157.1	2223.22
2159.01	2257.16
2160.92	2231.41
2162.83	2222.32
2164.74	2224.89
2166.65	2151.6
2168.56	2172.5
2170.47	2209.17
2172.38	2214.33
2174.28	2152.99
2176.19	2147.74
2178.09	2218.46
2180	2173.28
2181.9	2155.6
2183.81	2177.45
2185.71	2185.9
2187.61	2163.88
2189.52	2183.15
2191.42	2167.73
2193.32	2154.04
2195.22	2139.04
2197.12	2156.51
2199.02	2157.6
2200.92	2140.76
2202.82	2109.44
2204.71	2138.5
2206.61	2135.63
2208.51	2115.09
2210.4	2167.94
2212.3	2133.29
2214.19	2107.52
2216.09	2129.3
2217.98	2115.06
2219.87	2124.69
2221.77	2132.31
2223.66	2144.69
2225.55	2122.71
2227.44	2131.81
2229.33	2087.28
2231.22	2129.41
2233.11	2095.43
2235	2108.12
2236.88	2111.24
2238.77	2082.73
2240.66	2108.01
2242.07	2102
2243.97	2092
2245.87	2112
2247.76	2086
2249.65	2038
2251.55	2140
2253.44	2080
2255.33	2114
2257.22	2022
2259.12	2066
2261.01	2106
2262.9	2078
2264.78	2060
2266.67	2054
2268.56	2062
2270.45	2094
2272.34	2046
2274.22	1984
2276.11	2058
2277.99	2026
2279.88	2060
2281.76	2104
2283.65	2032
2285.53	1980
2287.41	2024
2289.3	2002
2291.18	2040
2293.06	2010
2294.94	2034
2296.82	2004
2298.7	1980
2300.58	1978
2302.46	2016
2304.33	2014
2306.21	1988
2308.09	2010
2309.96	1998
2311.84	1930
2313.71	1976
2315.59	1968
2317.46	1992
2319.33	2010
2321.21	1974
2323.08	1968
2324.95	1982
2326.82	1976
2328.69	1942
2330.56	1980
2332.43	1898
2334.3	1944
2336.17	1910
2338.03	1936
2339.9	1930
2341.77	1932
2343.63	1896
2345.5	1948
2347.36	1862
2349.23	1882
2351.09	1890
2352.95	1890
2354.82	1882
2356.68	1894
2358.54	1840
2360.4	1944
2362.26	1874
2364.12	1894
2365.98	1862
2367.84	1842
2369.7	1874
2371.56	1866
2373.41	1860
2375.27	1822
2377.12	1846
2378.98	1874
2380.84	1836
2382.69	1852
2384.54	1828
2386.4	1852
2388.25	1810
2390.1	1806
2391.95	1832
2393.8	1802
2395.65	1768
2397.5	1792
2399.35	1784
2401.2	1766
2403.05	1778
2404.9	1750
2406.75	1786
2408.59	1798
2410.44	1716
2412.28	1758
2414.13	1704
2415.97	1716
2417.82	1718
2419.66	1686
2421.5	1704
2423.35	1750
2425.19	1708
2427.03	1792
2428.87	1690
2430.71	1704
2432.55	1706
2434.39	1646
2436.23	1686
2438.06	1678
2439.9	1644
2441.74	1710
2443.57	1724
2445.41	1700
2447.24	1672
2449.08	1668
2450.91	1680
2452.75	1646
2454.58	1662
2456.41	1602
2458.24	1650
2460.08	1658
2461.91	1600
2463.74	1638
2465.57	1590
2467.4	1602
2469.22	1648
2471.05	1626
2472.88	1600
2474.71	1614
2476.53	1612
2478.36	1590
2480.19	1570
2482.01	1582
2483.83	1614
2485.66	1584
2487.48	1568
2489.3	1590
2491.13	1618
2492.95	1566
2494.77	1568
2496.59	1512
2498.41	1536
2500.23	1526
2502.05	1552
2503.87	1534
2505.68	1510
2507.5	1500
2509.32	1508
2511.14	1522
2512.95	1524
2514.77	1492
2516.58	1514
2518.39	1486
2520.21	1484
2522.02	1486
2523.83	1440
2525.65	1442
2527.46	1468
2529.27	1470
2531.08	1492
2532.89	1428
2534.7	1422
2536.51	1426
2538.32	1422
2540.12	1436
2541.93	1426
2543.74	1398
2545.54	1406
2547.35	1384
2549.15	1402
2550.96	1402
2552.76	1352
2554.56	1428
2556.37	1414
2558.17	1404
2559.97	1380
2561.77	1338
2563.58	1368
2565.38	1404
2567.18	1334
2568.97	1332
2570.77	1322
2572.57	1340
2574.37	1310
2576.17	1376
2577.96	1332
2579.76	1316
2581.55	1330
2583.35	1322
2585.14	1310
2586.94	1330
2588.73	1310
2590.52	1294
2592.32	1318
2594.11	1298
2595.9	1324
2597.69	1302
2599.48	1292
2601.27	1312
2603.06	1238
2604.85	1276
2606.64	1274
2608.42	1254
2610.21	1234
2612	1240
2613.78	1238
2615.57	1232
2617.36	1218
2619.14	1212
2620.92	1264
2622.71	1218
2624.49	1168
2626.27	1206
2628.05	1180
2629.84	1232
2631.62	1230
2633.4	1196
2635.18	1188
2636.96	1186
2638.74	1162
2640.51	1174
2642.29	1136
2644.07	1146
2645.85	1174
2647.62	1114
2649.4	1160
2651.17	1180
2652.95	1158
2654.72	1110
2656.5	1120
2658.27	1162
2660.04	1108
2661.81	1130
2663.58	1138
2665.35	1140
2667.13	1098
2668.9	1150
2670.66	1108
2672.43	1098
2674.2	1100
2675.97	1116
2677.74	1078
2679.5	1082
2681.27	1100
2683.04	1066
2684.8	1084
2686.57	1044
2688.33	1072
2690.09	1064
2691.86	1048
2693.62	1040
2695.38	1036
2697.15	1048
2698.91	1036
2700.67	1044
2702.43	1060
2704.19	1032
2705.95	998
2707.7	1020
2709.46	1024
2711.22	1012
2712.98	984
2714.73	1008
2716.49	984
2718.25	1016
2720	1004
2721.76	1012
2723.51	998
2725.26	992
2727.02	946
2728.77	966
2730.52	970
2732.27	990
2734.02	972
2735.77	974
2737.52	942
2739.27	958
2741.02	946
2742.77	974
2744.52	932
2746.27	938
2748.01	924
2749.76	922
2751.51	922
2753.25	930
2755	944
2756.74	918
2758.48	924
2760.23	890
2761.97	918
2763.71	894
2765.45	866
2767.19	916
2768.94	940
2770.68	918
2772.42	904
2774.16	876
2775.89	906
2777.63	860
2779.37	878
2781.11	878
2782.84	878
2784.58	854
2786.32	836
2788.05	896
2789.79	818
2791.52	820
2793.25	876
2794.99	922
2796.72	838
2798.45	862
2800.18	872
2801.92	832
2803.65	846
2805.38	854
2807.11	846
2808.84	832
2810.57	796
2812.29	822
2814.02	816
2815.75	812
2817.47	798
2819.2	792
2820.93	804
2822.65	784
2824.38	804
2826.1	830
2827.82	796
2829.55	764
2831.27	770
2832.99	818
2834.71	784
2836.44	816
2838.16	774
2839.88	806
2841.6	798
2843.32	768
2845.03	756
2846.75	764
2848.47	766
2850.19	750
2851.9	722
2853.62	770
2855.34	744
2857.05	766
2858.77	756
2860.48	746
2862.19	748
2863.91	736
2865.62	714
2867.33	724
2869.04	754
2870.76	730
2872.47	702
2874.18	694
2875.89	702
2877.6	734
2879.31	690
2881.01	740
2882.72	686
2884.43	732
2886.14	682
2887.84	722
2889.55	692
2891.25	692
2892.96	680
2894.66	708
2896.37	686
2898.07	688
2899.77	682
2901.48	678
2903.18	654
2904.88	692
2906.58	702
2908.28	668
2909.98	708
2911.68	638
2913.38	680
2915.08	642
2916.78	668
2918.47	646
2920.17	674
2921.87	652
2923.56	634
2925.26	668
2926.95	648
2928.65	660
2930.34	640
2932.04	644
2933.73	640
2935.42	640
2937.11	652
2938.81	644
2940.5	654
2942.19	650
2943.88	614
2945.57	604
2947.26	646
2948.95	608
2950.64	622
2952.32	620
2954.01	614
2955.7	630
2957.38	608
2959.07	618
2960.75	610
2962.44	594
2964.12	616
2965.81	608
2967.49	626
2969.17	616
2970.86	628
2972.54	618
2974.22	598
2975.9	564
2977.58	592
2979.26	562
2980.94	616
2982.62	596
2984.3	622
2985.98	588
2987.66	578
2989.33	556
2991.01	556
2992.69	566
2994.36	560
2996.04	598
2997.71	570
2999.39	554