File: muestras/tallo/1/Organic_13.txt
#Acq. time (s)=	10
#Accumulations=	1
#Range (cm-¹)=	100...3000
#Windows=	3
#Autofocus=	Off
#AutoExposure=	Off
#Spike filter=	Off
#Delay time (s)=	0
#Binning=	1
#Readout mode=	Signal
#DeNoise=	Off
#ICS correction=	Off
#Dark correction=	Off
#Inst. Process=	Off
#Instrument=	LabRAM HR Evol
#Detector=	Syncerity OE
#Objective=	x100_VIS
#Grating=	600 (500nm)
#ND Filter=	5%
#Laser=	633nm_Edge
#Hole=	74.97
#Range=	Visible
#Project=	Omar
#Sample=	26-06-23
#Site=	1
#Title=	Organic
#Remark=
#Date=	26.06.2023 16:01
#Acquired=	26.06.2023 16:01:46
101.018	1622
103.586	1574
106.152	1588
108.717	1588
111.281	1580
113.845	1570
116.407	1534
118.969	1570
121.53	1536
124.09	1550
126.649	1598
129.207	1576
131.765	1616
134.321	1580
136.877	1552
139.432	1544
141.985	1576
144.538	1596
147.09	1568
149.641	1598
152.191	1544
154.741	1542
157.289	1584
159.837	1548
162.385	1602
164.93	1588
167.476	1550
170.019	1586
172.562	1568
175.105	1524
177.646	1596
180.188	1590
182.727	1534
185.266	1546
187.804	1570
190.342	1572
192.878	1596
195.413	1558
197.948	1574
200.481	1562
203.014	1586
205.546	1632
208.077	1580
210.608	1542
213.137	1576
215.666	1548
218.194	1586
220.721	1600
223.247	1602
225.772	1580
228.295	1648
230.819	1624
233.342	1534
235.864	1578
238.384	1644
240.904	1620
243.423	1598
245.941	1616
248.46	1598
250.975	1634
253.492	1614
256.006	1642
258.519	1598
261.033	1616
263.545	1608
266.057	1586
268.567	1616
271.076	1560
273.585	1630
276.094	1618
278.601	1628
281.107	1596
283.612	1584
286.116	1602
288.62	1614
291.123	1634
293.625	1640
296.126	1624
298.626	1696
301.126	1622
303.625	1614
306.122	1632
308.62	1604
311.114	1650
313.61	1674
316.105	1646
318.599	1654
321.09	1596
323.583	1658
326.073	1620
328.563	1636
331.053	1630
333.541	1620
336.029	1640
338.515	1642
341.001	1674
343.486	1636
345.97	1676
348.453	1644
350.936	1684
353.418	1648
355.898	1652
358.378	1676
360.858	1618
363.336	1672
365.813	1638
368.29	1684
370.766	1670
373.241	1672
375.715	1636
378.188	1678
380.66	1636
383.132	1656
385.603	1684
388.072	1664
390.541	1680
393.01	1650
395.477	1674
397.943	1714
400.409	1722
402.875	1690
405.338	1746
407.802	1762
410.263	1732
412.725	1684
415.185	1698
417.646	1710
420.104	1732
422.564	1768
425.02	1794
427.477	1782
429.933	1778
432.388	1782
434.841	1808
437.294	1756
439.748	1832
442.199	1808
444.65	1808
447.1	1788
449.549	1730
451.997	1744
454.445	1816
456.891	1840
459.337	1812
461.782	1824
464.227	1810
466.669	1826
469.112	1870
471.554	1794
473.995	1814
476.434	1824
478.874	1862
481.312	1852
483.749	1820
486.186	1910
488.622	1898
491.057	1894
493.491	1888
495.925	1938
498.357	1936
500.789	1946
503.221	1916
505.65	1924
508.079	1884
510.509	1920
512.936	1936
515.363	1968
517.789	1922
520.214	1930
522.638	1970
525.062	1950
527.485	1960
529.907	2026
532.328	1946
534.748	2012
537.168	1960
539.587	1982
542.005	1998
544.423	1994
546.838	2050
549.254	2030
551.669	2018
554.082	2040
556.496	2042
558.909	2064
561.319	2062
563.731	2128
566.14	2062
568.549	2086
570.957	2068
573.364	2116
575.771	2162
578.177	2146
580.581	2206
582.987	2154
585.39	2160
587.792	2198
590.193	2212
592.594	2216
594.996	2140
597.395	2238
599.793	2312
602.191	2264
604.588	2318
606.984	2274
609.378	2310
611.773	2390
614.167	2338
616.56	2370
618.953	2344
621.343	2430
623.734	2448
626.124	2418
628.512	2480
630.901	2468
633.289	2456
635.675	2534
638.061	2474
640.446	2580
642.831	2588
645.213	2684
647.595	2624
649.978	2634
652.359	2660
654.738	2680
657.117	2640
659.497	2736
661.875	2720
664.252	2744
666.628	2736
669.003	2754
671.378	2786
673.751	2790
676.124	2804
678.497	2830
680.868	2836
683.239	2842
685.609	2942
687.977	2908
690.346	2912
692.714	2868
695.081	2964
697.446	2974
699.812	3012
702.175	3056
704.539	3114
706.901	3112
709.264	3124
711.625	3128
713.986	3120
716.345	3230
718.705	3154
721.062	3250
723.419	3230
725.775	3262
728.132	3300
730.487	3308
732.841	3366
735.194	3394
737.546	3392
739.898	3306
742.249	3420
744.599	3464
746.949	3546
749.298	3530
751.646	3624
753.993	3594
756.34	3576
758.684	3616
761.029	3612
763.374	3694
765.716	3702
768.059	3782
770.401	3742
772.741	3774
775.082	3814
777.421	3770
779.76	3868
782.097	3942
784.434	3912
786.771	3992
789.106	3988
791.44	4042
793.775	4046
796.108	4024
798.44	4178
800.771	4142
803.102	4142
805.432	4306
807.761	4236
810.09	4210
812.417	4316
814.744	4416
817.071	4470
819.396	4414
821.721	4422
824.045	4528
826.367	4598
828.69	4672
831.012	4548
833.332	4662
835.653	4664
837.972	4716
840.29	4750
842.609	4774
844.925	4868
847.242	4858
849.557	4978
851.871	4974
854.186	5052
856.498	5050
858.81	5196
861.122	5140
863.434	5120
865.744	5164
868.053	5166
870.361	5296
872.669	5214
874.976	5282
877.282	5262
879.588	5338
881.893	5424
884.197	5442
886.5	5496
888.802	5462
891.104	5396
893.405	5514
895.706	5496
898.004	5576
900.303	5532
902.6	5624
904.898	5598
907.194	5592
909.49	5652
911.785	5656
914.08	5730
916.372	5688
918.666	5774
920.957	5850
923.248	5786
925.538	5828
927.828	5834
930.118	5900
932.406	5880
934.693	5952
936.979	6030
939.265	5952
941.55	6058
943.835	6076
946.118	6086
948.401	6182
950.682	6168
952.964	6136
955.245	6260
957.525	6310
959.803	6314
962.082	6318
964.36	6340
966.636	6308
968.913	6340
971.188	6455
973.463	6476
975.736	6612
978.009	6588
980.282	6544
982.554	6600
984.824	6562
987.095	6638
989.364	6620
991.633	6628
993.9	6598
996.167	6710
998.434	6620
1000.7	6692
1002.96	6768
1005.23	6724
1007.49	6768
1009.76	6772
1012.02	6652
1014.28	6872
1016.54	6756
1018.8	6866
1021.06	6846
1023.32	6868
1025.57	6920
1027.83	7016
1030.09	6948
1032.34	6884
1034.6	7024
1036.85	7038
1039.1	6896
1041.35	7020
1043.61	7100
1045.86	7020
1048.11	6994
1050.36	7082
1052.61	7110
1054.85	7168
1057.1	7162
1059.35	7054
1061.59	7146
1063.84	7224
1066.08	7090
1068.33	7242
1070.57	7178
1072.81	7154
1075.05	7116
1077.29	7178
1079.53	7154
1081.77	7122
1084.01	7156
1086.25	7126
1088.48	6978
1090.72	7086
1092.96	7192
1095.19	6974
1097.43	7060
1099.66	6930
1101.89	7080
1104.12	6920
1106.35	6930
1108.59	6890
1110.81	6966
1113.04	7014
1115.27	6996
1117.5	6964
1119.73	6934
1121.95	6918
1124.18	6786
1126.4	6860
1128.63	6862
1130.85	6932
1133.07	6892
1135.29	6892
1137.51	6852
1139.73	6884
1141.95	6858
1144.17	6760
1146.39	6850
1148.61	6792
1150.82	6760
1153.04	6904
1155.26	6772
1157.47	6754
1159.68	6772
1161.9	6676
1164.11	6730
1166.32	6696
1168.53	6674
1170.74	6610
1172.95	6656
1175.16	6596
1177.37	6600
1179.58	6548
1181.78	6672
1183.99	6548
1186.19	6432
1188.4	6420
1190.6	6336
1192.8	6410
1195.01	6284
1197.21	6270.61
1199.41	6248.12
1201.61	6161.98
1203.81	6076.01
1206.01	6090.95
1208.2	6083.8
1210.4	6107.39
1212.6	6141.72
1214.8	6045.23
1216.99	6082.51
1219.18	5956.63
1221.38	5948.19
1223.57	5964.06
1225.76	5918.84
1227.96	5839.82
1230.15	5779.1
1232.34	5874.85
1234.53	5807.95
1236.71	5769.95
1238.9	5731.49
1241.09	5676.39
1243.28	5697.63
1245.46	5718.4
1247.65	5674.33
1249.83	5643.66
1252.02	5638.49
1254.2	5622.72
1256.38	5632.41
1258.56	5601.4
1260.74	5499.24
1262.92	5526.82
1265.1	5482.41
1267.28	5491.93
1269.46	5470.59
1271.64	5422.77
1273.82	5394.98
1275.99	5380.53
1278.17	5376.02
1280.34	5370
1282.52	5364.34
1284.69	5336.56
1286.86	5258.86
1289.03	5253.93
1291.21	5203.59
1293.38	5290.91
1295.55	5211.31
1297.71	5223.3
1299.88	5124.24
1302.05	5149.34
1304.22	5104.32
1306.38	5125.39
1308.43	5018
1310.61	5044
1312.78	4986
1314.96	5112
1317.13	4928
1319.3	4828
1321.48	4872
1323.65	4848
1325.82	4796
1327.99	4748
1330.16	4806
1332.33	4804
1334.5	4640
1336.66	4692
1338.83	4628
1341	4594
1343.16	4540
1345.33	4526
1347.49	4644
1349.65	4436
1351.82	4400
1353.98	4476
1356.14	4448
1358.3	4468
1360.46	4336
1362.62	4374
1364.78	4338
1366.94	4312
1369.09	4366
1371.25	4254
1373.41	4188
1375.56	4306
1377.72	4176
1379.87	4222
1382.02	4186
1384.17	4172
1386.33	4102
1388.48	4072
1390.63	4048
1392.78	4076
1394.93	4004
1397.07	4028
1399.22	3974
1401.37	3970
1403.52	3956
1405.66	3992
1407.81	3936
1409.95	3900
1412.09	3934
1414.24	3846
1416.38	3888
1418.52	3794
1420.66	3856
1422.8	3774
1424.94	3740
1427.08	3742
1429.22	3718
1431.35	3700
1433.49	3740
1435.63	3650
1437.76	3780
1439.9	3704
1442.03	3714
1444.17	3646
1446.3	3600
1448.43	3638
1450.56	3634
1452.69	3626
1454.82	3542
1456.95	3560
1459.08	3542
1461.21	3558
1463.34	3538
1465.46	3572
1467.59	3570
1469.71	3502
1471.84	3438
1473.96	3440
1476.08	3400
1478.21	3470
1480.33	3422
1482.45	3406
1484.57	3430
1486.69	3414
1488.81	3408
1490.93	3274
1493.05	3364
1495.16	3278
1497.28	3314
1499.4	3292
1501.51	3352
1503.63	3302
1505.74	3242
1507.85	3266
1509.97	3260
1512.08	3230
1514.19	3234
1516.3	3262
1518.41	3170
1520.52	3186
1522.63	3168
1524.73	3212
1526.84	3130
1528.95	3190
1531.06	3188
1533.16	3166
1535.26	3100
1537.37	3080
1539.47	3116
1541.57	3006
1543.68	3072
1545.78	3054
1547.88	3028
1549.98	3020
1552.08	2992
1554.18	3012
1556.27	3000
1558.37	2948
1560.47	2896
1562.56	2912
1564.66	2882
1566.75	2928
1568.85	2916
1570.94	2874
1573.03	2896
1575.13	2884
1577.22	2948
1579.31	2832
1581.4	2854
1583.49	2910
1585.58	2874
1587.66	2856
1589.75	2850
1591.84	2834
1593.93	2790
1596.01	2878
1598.1	2804
1600.18	2798
1602.26	2788
1604.35	2832
1606.43	2772
1608.51	2796
1610.59	2786
1612.67	2796
1614.75	2798
1616.83	2774
1618.91	2766
1620.99	2796
1623.06	2738
1625.14	2758
1627.21	2722
1629.29	2706
1631.36	2702
1633.44	2758
1635.51	2766
1637.58	2738
1639.66	2678
1641.73	2700
1643.8	2630
1645.87	2620
1647.94	2672
1650	2600
1652.07	2636
1654.14	2642
1656.21	2608
1658.27	2608
1660.34	2622
1662.4	2602
1664.47	2536
1666.53	2580
1668.59	2566
1670.66	2578
1672.72	2590
1674.78	2550
1676.84	2514
1678.9	2492
1680.96	2566
1683.01	2552
1685.07	2534
1687.13	2484
1689.19	2550
1691.24	2524
1693.3	2524
1695.35	2510
1697.4	2450
1699.46	2456
1701.51	2458
1703.56	2460
1705.61	2500
1707.66	2398
1709.71	2412
1711.76	2322
1713.81	2374
1715.86	2424
1717.91	2388
1719.95	2378
1722	2414
1724.04	2394
1726.09	2400
1728.13	2370
1730.18	2426
1732.22	2316
1734.26	2406
1736.3	2340
1738.34	2342
1740.38	2344
1742.42	2364
1744.46	2370
1746.5	2318
1748.54	2306
1750.58	2306
1752.61	2334
1754.65	2254
1756.68	2284
1758.72	2290
1760.75	2316
1762.79	2360
1764.82	2326
1766.85	2276
1768.88	2304
1770.91	2242
1772.94	2294
1774.97	2284
1777	2306
1779.03	2280
1781.06	2224
1783.09	2286
1785.11	2260
1787.14	2284
1789.16	2274
1791.19	2214
1793.21	2226
1795.23	2230
1797.26	2246
1799.28	2290
1801.3	2280
1803.32	2182
1805.34	2224
1807.36	2260
1809.38	2210
1811.4	2184
1813.42	2178
1815.43	2182
1817.45	2154
1819.47	2240
1821.48	2140
1823.49	2100
1825.51	2152
1827.52	2154
1829.54	2156
1831.55	2146
1833.56	2132
1835.57	2132
1837.58	2128
1839.59	2126
1841.6	2140
1843.61	2106
1845.61	2124
1847.62	2066
1849.63	2106
1851.63	2116
1853.64	2036
1855.64	2178
1857.65	2108
1859.65	2062
1861.65	2086
1863.65	2104
1865.66	2000
1867.66	2102
1869.66	2108
1871.66	2036
1873.66	2046
1875.65	2032
1877.65	2024
1879.65	2052
1881.65	1976
1883.64	2068
1885.64	2018
1887.63	2080
1889.63	2036
1891.62	2038
1893.61	2040
1895.6	2040
1897.6	2004
1899.59	1994
1901.58	1978
1903.57	1996
1905.56	2058
1907.54	1990
1909.53	2016
1911.52	1972
1913.51	2026
1915.49	1986
1917.48	1996
1919.46	1976
1921.45	2050
1923.43	1962
1925.41	2036
1927.4	1974
1929.38	1970
1931.36	1986
1933.34	1956
1935.32	1972
1937.3	1942
1939.28	1990
1941.26	1990
1943.23	1978
1945.21	1984
1947.19	1926
1949.16	1938
1951.14	1970
1953.11	1960
1955.09	1990
1957.06	1958
1959.03	1922
1961	1926
1962.98	1914
1964.95	1940
1966.92	1922
1968.89	1962
1970.85	1876
1972.82	1886
1974.79	1880
1976.76	1878
1978.73	1934
1980.69	1960
1982.66	1912
1984.62	1878
1986.59	1896
1988.55	1922
1990.51	1944
1992.47	1852
1994.44	1888
1996.4	1876
1998.36	1880
2000.32	1906
2002.28	1934
2004.24	1894
2006.19	1884
2008.15	1836
2010.11	1874
2012.06	1878
2014.02	1876
2015.98	1858
2017.93	1824
2019.88	1914
2021.84	1882
2023.79	1816
2025.74	1838
2027.69	1902
2029.65	1876
2031.6	1804
2033.55	1852
2035.5	1872
2037.44	1844
2039.39	1892
2041.34	1794
2043.29	1864
2045.23	1884
2047.18	1828
2049.12	1816
2051.07	1838
2053.01	1816
2054.95	1810
2056.9	1870
2058.84	1794
2060.78	1832
2062.72	1814
2064.66	1838
2066.6	1814
2068.54	1802
2070.48	1744
2072.42	1778
2074.35	1802
2076.29	1766
2078.23	1796
2080.16	1800
2082.1	1802
2084.03	1806
2085.96	1818
2087.9	1776
2089.83	1798
2091.76	1786
2093.69	1750
2095.62	1846
2097.55	1786
2099.48	1732
2101.41	1796
2103.34	1726
2105.27	1732
2107.2	1796
2109.12	1752
2111.05	1710
2112.98	1750
2114.9	1776
2116.82	1778
2118.75	1740
2120.67	1770
2122.59	1806
2124.52	1746
2126.44	1732
2128.36	1706
2130.28	1716
2132.2	1736
2134.12	1720
2136.04	1748
2137.95	1732
2139.87	1760
2141.79	1770
2143.7	1672
2145.62	1706.08
2147.53	1741.45
2149.45	1711
2151.36	1725.09
2153.28	1672.45
2155.19	1713.59
2157.1	1697.02
2159.01	1703.53
2160.92	1698.04
2162.83	1690.61
2164.74	1664.08
2166.65	1636.16
2168.56	1633.96
2170.47	1670.31
2172.38	1679.56
2174.28	1619.44
2176.19	1655.63
2178.09	1668.64
2180	1641.91
2181.9	1647.52
2183.81	1651.63
2185.71	1663.85
2187.61	1599.93
2189.52	1661.69
2191.42	1630.1
2193.32	1645.54
2195.22	1598.04
2197.12	1639.24
2199.02	1624.26
2200.92	1630.8
2202.82	1594.12
2204.71	1631.57
2206.61	1607.91
2208.51	1606.19
2210.4	1583.89
2212.3	1597.79
2214.19	1623.33
2216.09	1630.71
2217.98	1592.89
2219.87	1590.56
2221.77	1575.34
2223.66	1611.66
2225.55	1616.52
2227.44	1603.54
2229.33	1591.53
2231.22	1595.04
2233.11	1629.38
2235	1614.72
2236.88	1606.27
2238.77	1569.39
2240.66	1615.56
2242.07	1592
2243.97	1614
2245.87	1554
2247.76	1620
2249.65	1604
2251.55	1618
2253.44	1596
2255.33	1612
2257.22	1580
2259.12	1608
2261.01	1548
2262.9	1584
2264.78	1538
2266.67	1560
2268.56	1556
2270.45	1606
2272.34	1550
2274.22	1532
2276.11	1526
2277.99	1526
2279.88	1542
2281.76	1566
2283.65	1518
2285.53	1584
2287.41	1580
2289.3	1514
2291.18	1500
2293.06	1546
2294.94	1532
2296.82	1562
2298.7	1488
2300.58	1534
2302.46	1538
2304.33	1508
2306.21	1464
2308.09	1520
2309.96	1488
2311.84	1568
2313.71	1468
2315.59	1482
2317.46	1538
2319.33	1486
2321.21	1478
2323.08	1498
2324.95	1466
2326.82	1442
2328.69	1480
2330.56	1504
2332.43	1468
2334.3	1486
2336.17	1482
2338.03	1482
2339.9	1434
2341.77	1410
2343.63	1462
2345.5	1442
2347.36	1476
2349.23	1436
2351.09	1406
2352.95	1436
2354.82	1458
2356.68	1430
2358.54	1426
2360.4	1466
2362.26	1432
2364.12	1450
2365.98	1440
2367.84	1422
2369.7	1392
2371.56	1424
2373.41	1388
2375.27	1370
2377.12	1410
2378.98	1378
2380.84	1390
2382.69	1416
2384.54	1420
2386.4	1370
2388.25	1378
2390.1	1396
2391.95	1348
2393.8	1350
2395.65	1414
2397.5	1368
2399.35	1366
2401.2	1334
2403.05	1340
2404.9	1360
2406.75	1364
2408.59	1360
2410.44	1332
2412.28	1330
2414.13	1320
2415.97	1318
2417.82	1362
2419.66	1290
2421.5	1316
2423.35	1326
2425.19	1354
2427.03	1312
2428.87	1318
2430.71	1342
2432.55	1256
2434.39	1254
2436.23	1292
2438.06	1294
2439.9	1272
2441.74	1314
2443.57	1288
2445.41	1274
2447.24	1258
2449.08	1286
2450.91	1246
2452.75	1256
2454.58	1294
2456.41	1242
2458.24	1282
2460.08	1268
2461.91	1256
2463.74	1236
2465.57	1264
2467.4	1234
2469.22	1264
2471.05	1266
2472.88	1250
2474.71	1216
2476.53	1186
2478.36	1256
2480.19	1210
2482.01	1252
2483.83	1206
2485.66	1192
2487.48	1218
2489.3	1192
2491.13	1226
2492.95	1198
2494.77	1184
2496.59	1236
2498.41	1210
2500.23	1164
2502.05	1196
2503.87	1200
2505.68	1182
2507.5	1164
2509.32	1184
2511.14	1172
2512.95	1172
2514.77	1172
2516.58	1118
2518.39	1170
2520.21	1138
2522.02	1142
2523.83	1136
2525.65	1124
2527.46	1126
2529.27	1106
2531.08	1096
2532.89	1116
2534.7	1080
2536.51	1116
2538.32	1100
2540.12	1140
2541.93	1088
2543.74	1100
2545.54	1116
2547.35	1092
2549.15	1108
2550.96	1096
2552.76	1128
2554.56	1078
2556.37	1026
2558.17	1044
2559.97	1070
2561.77	1052
2563.58	1058
2565.38	1020
2567.18	1028
2568.97	1066
2570.77	1044
2572.57	1044
2574.37	1012
2576.17	1026
2577.96	1014
2579.76	1024
2581.55	1006
2583.35	1062
2585.14	1014
2586.94	1048
2588.73	1022
2590.52	1014
2592.32	1022
2594.11	992
2595.9	1024
2597.69	980
2599.48	978
2601.27	1002
2603.06	996
2604.85	1008
2606.64	978
2608.42	958
2610.21	998
2612	960
2613.78	996
2615.57	960
2617.36	978
2619.14	976
2620.92	952
2622.71	960
2624.49	948
2626.27	938
2628.05	952
2629.84	924
2631.62	954
2633.4	922
2635.18	946
2636.96	910
2638.74	918
2640.51	942
2642.29	910
2644.07	924
2645.85	912
2647.62	910
2649.4	892
2651.17	910
2652.95	894
2654.72	890
2656.5	902
2658.27	866
2660.04	852
2661.81	896
2663.58	922
2665.35	910
2667.13	858
2668.9	824
2670.66	900
2672.43	864
2674.2	876
2675.97	880
2677.74	888
2679.5	834
2681.27	852
2683.04	818
2684.8	848
2686.57	832
2688.33	850
2690.09	844
2691.86	820
2693.62	810
2695.38	812
2697.15	832
2698.91	862
2700.67	774
2702.43	806
2704.19	796
2705.95	830
2707.7	806
2709.46	814
2711.22	816
2712.98	796
2714.73	754
2716.49	784
2718.25	806
2720	780
2721.76	778
2723.51	776
2725.26	780
2727.02	776
2728.77	792
2730.52	762
2732.27	770
2734.02	774
2735.77	778
2737.52	778
2739.27	758
2741.02	762
2742.77	742
2744.52	730
2746.27	714
2748.01	744
2749.76	730
2751.51	732
2753.25	736
2755	736
2756.74	756
2758.48	768
2760.23	728
2761.97	724
2763.71	726
2765.45	742
2767.19	724
2768.94	720
2770.68	748
2772.42	724
2774.16	704
2775.89	712
2777.63	708
2779.37	708
2781.11	706
2782.84	708
2784.58	704
2786.32	688
2788.05	718
2789.79	680
2791.52	704
2793.25	696
2794.99	698
2796.72	692
2798.45	686
2800.18	646
2801.92	708
2803.65	681
2805.38	660
2807.11	668
2808.84	674
2810.57	676
2812.29	662
2814.02	670
2815.75	646
2817.47	676
2819.2	652
2820.93	656
2822.65	642
2824.38	632
2826.1	634
2827.82	652
2829.55	658
2831.27	652
2832.99	624
2834.71	630
2836.44	622
2838.16	652
2839.88	616
2841.6	646
2843.32	612
2845.03	638
2846.75	614
2848.47	618
2850.19	624
2851.9	620
2853.62	608
2855.34	584
2857.05	602
2858.77	596
2860.48	578
2862.19	572
2863.91	626
2865.62	596
2867.33	582
2869.04	608
2870.76	578
2872.47	610
2874.18	594
2875.89	584
2877.6	618
2879.31	582
2881.01	594
2882.72	596
2884.43	554
2886.14	634
2887.84	562
2889.55	548
2891.25	544
2892.96	590
2894.66	546
2896.37	572
2898.07	574
2899.77	564
2901.48	568
2903.18	550
2904.88	546
2906.58	548
2908.28	542
2909.98	534
2911.68	522
2913.38	560
2915.08	536
2916.78	508
2918.47	554
2920.17	542
2921.87	546
2923.56	534
2925.26	530
2926.95	528
2928.65	524
2930.34	532
2932.04	522
2933.73	556
2935.42	510
2937.11	538
2938.81	528
2940.5	542
2942.19	508
2943.88	486
2945.57	536
2947.26	526
2948.95	530
2950.64	542
2952.32	492
2954.01	528
2955.7	506
2957.38	464
2959.07	502
2960.75	482
2962.44	506
2964.12	472
2965.81	490
2967.49	488
2969.17	496
2970.86	480
2972.54	486
2974.22	496
2975.9	462
2977.58	474
2979.26	464
2980.94	468
2982.62	494
2984.3	478
2985.98	468
2987.66	466
2989.33	458
2991.01	462
2992.69	492
2994.36	462
2996.04	456
2997.71	448
2999.39	486