File: muestras/tallo/1/Organic_11.txt
#Acq. time (s)=	10
#Accumulations=	1
#Range (cm-¹)=	100...3000
#Windows=	3
#Autofocus=	Off
#AutoExposure=	Off
#Spike filter=	Off
#Delay time (s)=	0
#Binning=	1
#Readout mode=	Signal
#DeNoise=	Off
#ICS correction=	Off
#Dark correction=	Off
#Inst. Process=	Off
#Instrument=	LabRAM HR Evol
#Detector=	Syncerity OE
#Objective=	x100_VIS
#Grating=	600 (500nm)
#ND Filter=	5%
#Laser=	633nm_Edge
#Hole=	74.97
#Range=	Visible
#Project=	Omar
#Sample=	26-06-23
#Site=	1
#Title=	Organic
#Remark=
#Date=	26.06.2023 15:59
#Acquired=	26.06.2023 15:59:52
101.018	1744
103.586	1680
106.152	1756
108.717	1714
111.281	1730
113.845	1680
116.407	1724
118.969	1722
121.53	1744
124.09	1716
126.649	1694
129.207	1702
131.765	1744
134.321	1712
136.877	1718
139.432	1766
141.985	1694
144.538	1704
147.09	1662
149.641	1658
152.191	1706
154.741	1722
157.289	1684
159.837	1682
162.385	1722
164.93	1694
167.476	1710
170.019	1674
172.562	1680
175.105	1712
177.646	1672
180.188	1680
182.727	1698
185.266	1602
187.804	1682
190.342	1684
192.878	1760
195.413	1688
197.948	1686
200.481	1718
203.014	1708
205.546	1676
208.077	1694
210.608	1726
213.137	1740
215.666	1722
218.194	1736
220.721	1726
223.247	1712
225.772	1728
228.295	1752
230.819	1796
233.342	1754
235.864	1736
238.384	1700
240.904	1746
243.423	1774
245.941	1758
248.46	1756
250.975	1736
253.492	1734
256.006	1734
258.519	1698
261.033	1750
263.545	1784
266.057	1720
268.567	1776
271.076	1746
273.585	1682
276.094	1742
278.601	1728
281.107	1666
283.612	1724
286.116	1758
288.62	1752
291.123	1736
293.625	1766
296.126	1718
298.626	1798
301.126	1738
303.625	1744
306.122	1766
308.62	1792
311.114	1826
313.61	1794
316.105	1756
318.599	1768
321.09	1826
323.583	1764
326.073	1806
328.563	1748
331.053	1816
333.541	1752
336.029	1774
338.515	1780
341.001	1808
343.486	1806
345.97	1786
348.453	1798
350.936	1804
353.418	1830
355.898	1772
358.378	1838
360.858	1840
363.336	1802
365.813	1814
368.29	1830
370.766	1786
373.241	1792
375.715	1846
378.188	1822
380.66	1792
383.132	1860
385.603	1814
388.072	1872
390.541	1802
393.01	1790
395.477	1858
397.943	1838
400.409	1884
402.875	1856
405.338	1920
407.802	1866
410.263	1876
412.725	1900
415.185	1870
417.646	1934
420.104	1936
422.564	1912
425.02	1930
427.477	1962
429.933	2002
432.388	1938
434.841	1900
437.294	1996
439.748	2000
442.199	1990
444.65	1950
447.1	1998
449.549	1978
451.997	1998
454.445	2022
456.891	1968
459.337	1982
461.782	1994
464.227	2004
466.669	2036
469.112	1970
471.554	1974
473.995	2056
476.434	2046
478.874	2034
481.312	2042
483.749	2000
486.186	2050
488.622	2088
491.057	2024
493.491	2062
495.925	2130
498.357	2044
500.789	2090
503.221	2126
505.65	2112
508.079	2134
510.509	2176
512.936	2204
515.363	2106
517.789	2148
520.214	2128
522.638	2140
525.062	2164
527.485	2222
529.907	2206
532.328	2156
534.748	2176
537.168	2216
539.587	2144
542.005	2194
544.423	2204
546.838	2234
549.254	2272
551.669	2286
554.082	2230
556.496	2298
558.909	2256
561.319	2274
563.731	2288
566.14	2268
568.549	2260
570.957	2324
573.364	2306
575.771	2334
578.177	2312
580.581	2366
582.987	2370
585.39	2438
587.792	2378
590.193	2500
592.594	2426
594.996	2420
597.395	2398
599.793	2456
602.191	2474
604.588	2580
606.984	2490
609.378	2496
611.773	2528
614.167	2564
616.56	2566
618.953	2610
621.343	2678
623.734	2698
626.124	2732
628.512	2720
630.901	2742
633.289	2734
635.675	2828
638.061	2784
640.446	2832
642.831	2802
645.213	2862
647.595	2862
649.978	2856
652.359	2932
654.738	2988
657.117	2930
659.497	2964
661.875	2990
664.252	2998
666.628	3080
669.003	3038
671.378	3020
673.751	3100
676.124	3056
678.497	3178
680.868	3166
683.239	3234
685.609	3224
687.977	3258
690.346	3266
692.714	3262
695.081	3334
697.446	3294
699.812	3366
702.175	3348
704.539	3350
706.901	3404
709.264	3444
711.625	3494
713.986	3552
716.345	3558
718.705	3560
721.062	3596
723.419	3632
725.775	3670
728.132	3690
730.487	3684
732.841	3730
735.194	3718
737.546	3796
739.898	3832
742.249	3862
744.599	3868
746.949	3910
749.298	3980
751.646	3898
753.993	4058
756.34	4038
758.684	4120
761.029	4122
763.374	4128
765.716	4156
768.059	4238
770.401	4178
772.741	4304
775.082	4210
777.421	4438
779.76	4308
782.097	4372
784.434	4410
786.771	4428
789.106	4508
791.44	4554
793.775	4548
796.108	4616
798.44	4610
800.771	4750
803.102	4658
805.432	4702
807.761	4850
810.09	4796
812.417	4812
814.744	4902
817.071	5004
819.396	5026
821.721	4928
824.045	5124
826.367	5104
828.69	5204
831.012	5216
833.332	5322
835.653	5290
837.972	5358
840.29	5440
842.609	5460
844.925	5554
847.242	5574
849.557	5484
851.871	5576
854.186	5556
856.498	5696
858.81	5626
861.122	5648
863.434	5742
865.744	5820
868.053	5894
870.361	5884
872.669	5820
874.976	5974
877.282	5892
879.588	6050
881.893	6032
884.197	6096
886.5	6086
888.802	6130
891.104	6064
893.405	6114
895.706	6186
898.004	6232
900.303	6198
902.6	6292
904.898	6290
907.194	6298
909.49	6400
911.785	6404
914.08	6438
916.372	6338
918.666	6578
920.957	6536
923.248	6624
925.538	6620
927.828	6622
930.118	6556
932.406	6638
934.693	6720
936.979	6720
939.265	6742
941.55	6886
943.835	6936
946.118	6804
948.401	6982
950.682	6994
952.964	7022
955.245	7098
957.525	7160
959.803	7130
962.082	7154
964.36	7174
966.636	7176
968.913	7246
971.188	7264
973.463	7168
975.736	7354
978.009	7348
980.282	7396
982.554	7408
984.824	7368
987.095	7424
989.364	7448
991.633	7440
993.9	7584
996.167	7492
998.434	7426
1000.7	7456
1002.96	7506
1005.23	7486
1007.49	7564
1009.76	7578
1012.02	7658
1014.28	7664
1016.54	7718
1018.8	7812
1021.06	7662
1023.32	7720
1025.57	7776
1027.83	7766
1030.09	7856
1032.34	7788
1034.6	7886
1036.85	7958
1039.1	7880
1041.35	7858
1043.61	7914
1045.86	7846
1048.11	7878
1050.36	7994
1052.61	7956
1054.85	7882
1057.1	7978
1059.35	8016
1061.59	7948
1063.84	8062
1066.08	8040
1068.33	8080
1070.57	8072
1072.81	8094
1075.05	8068
1077.29	8004
1079.53	7930
1081.77	7966
1084.01	8066
1086.25	7912
1088.48	7962
1090.72	7862
1092.96	7808
1095.19	7772
1097.43	7860
1099.66	7810
1101.89	7770
1104.12	7810
1106.35	7722
1108.59	7824
1110.81	7898
1113.04	7768
1115.27	7776
1117.5	7700
1119.73	7728
1121.95	7596
1124.18	7806
1126.4	7786
1128.63	7720
1130.85	7686
1133.07	7704
1135.29	7548
1137.51	7696
1139.73	7748
1141.95	7558
1144.17	7634
1146.39	7674
1148.61	7582
1150.82	7628
1153.04	7562
1155.26	7644
1157.47	7580
1159.68	7578
1161.9	7602
1164.11	7548
1166.32	7492
1168.53	7412
1170.74	7484
1172.95	7246
1175.16	7348
1177.37	7290
1179.58	7238
1181.78	7350
1183.99	7244
1186.19	7196
1188.4	7188
1190.6	7140
1192.8	7124
1195.01	7076
1197.21	7046.87
1199.41	6925.36
1201.61	6907.48
1203.81	6947.82
1206.01	6796.44
1208.2	6825.94
1210.4	6861.61
1212.6	6798.54
1214.8	6792.38
1216.99	6645.95
1219.18	6668.06
1221.38	6622.12
1223.57	6582.53
1225.76	6613.2
1227.96	6531.25
1230.15	6518.16
1232.34	6439.59
1234.53	6389.41
1236.71	6400.56
1238.9	6391.13
1241.09	6338.37
1243.28	6324
1245.46	6233.49
1247.65	6244.15
1249.83	6248.99
1252.02	6236.78
1254.2	6227.56
1256.38	6193.68
1258.56	6156.27
1260.74	6155.39
1262.92	6103.59
1265.1	6087.92
1267.28	6064.89
1269.46	6023.7
1271.64	6026.94
1273.82	6004.42
1275.99	5954.08
1278.17	5992.39
1280.34	5869.38
1282.52	5859.65
1284.69	5902.4
1286.86	5844.2
1289.03	5846.3
1291.21	5753.01
1293.38	5738.7
1295.55	5775.9
1297.71	5629.44
1299.88	5649.29
1302.05	5593.18
1304.22	5638.88
1306.38	5627.13
1308.43	5576
1310.61	5530
1312.78	5496
1314.96	5450
1317.13	5524
1319.3	5394
1321.48	5336
1323.65	5352
1325.82	5288
1327.99	5212
1330.16	5274
1332.33	5202
1334.5	5222
1336.66	5098
1338.83	5056
1341	5056
1343.16	5088
1345.33	5042
1347.49	4902
1349.65	4960
1351.82	4918
1353.98	4912
1356.14	4858
1358.3	4800
1360.46	4778
1362.62	4754
1364.78	4728
1366.94	4728
1369.09	4700
1371.25	4740
1373.41	4608
1375.56	4640
1377.72	4676
1379.87	4550
1382.02	4564
1384.17	4456
1386.33	4534
1388.48	4468
1390.63	4500
1392.78	4412
1394.93	4498
1397.07	4398
1399.22	4416
1401.37	4374
1403.52	4378
1405.66	4388
1407.81	4316
1409.95	4244
1412.09	4246
1414.24	4220
1416.38	4148
1418.52	4260
1420.66	4238
1422.8	4100
1424.94	4206
1427.08	4120
1429.22	4194
1431.35	4114
1433.49	4106
1435.63	4034
1437.76	4054
1439.9	4066
1442.03	4058
1444.17	4030
1446.3	3946
1448.43	4004
1450.56	4010
1452.69	3968
1454.82	3940
1456.95	3830
1459.08	3888
1461.21	3842
1463.34	3884
1465.46	3902
1467.59	3830
1469.71	3866
1471.84	3846
1473.96	3792
1476.08	3766
1478.21	3748
1480.33	3780
1482.45	3750
1484.57	3770
1486.69	3640
1488.81	3724
1490.93	3712
1493.05	3690
1495.16	3606
1497.28	3654
1499.4	3632
1501.51	3616
1503.63	3592
1505.74	3546
1507.85	3574
1509.97	3508
1512.08	3594
1514.19	3568
1516.3	3520
1518.41	3462
1520.52	3430
1522.63	3496
1524.73	3488
1526.84	3392
1528.95	3442
1531.06	3464
1533.16	3356
1535.26	3460
1537.37	3350
1539.47	3270
1541.57	3342
1543.68	3386
1545.78	3328
1547.88	3266
1549.98	3312
1552.08	3278
1554.18	3240
1556.27	3282
1558.37	3244
1560.47	3280
1562.56	3208
1564.66	3206
1566.75	3218
1568.85	3158
1570.94	3168
1573.03	3120
1575.13	3202
1577.22	3098
1579.31	3126
1581.4	3092
1583.49	3056
1585.58	3072
1587.66	3128
1589.75	3178
1591.84	3094
1593.93	3074
1596.01	3048
1598.1	3092
1600.18	3052
1602.26	3080
1604.35	3120
1606.43	3084
1608.51	3102
1610.59	3032
1612.67	3002
1614.75	3052
1616.83	3038
1618.91	3002
1620.99	2980
1623.06	3024
1625.14	3008
1627.21	2956
1629.29	3030
1631.36	2966
1633.44	2968
1635.51	2872
1637.58	2934
1639.66	2922
1641.73	2928
1643.8	2908
1645.87	2912
1647.94	2860
1650	2938
1652.07	2888
1654.14	2858
1656.21	2894
1658.27	2810
1660.34	2816
1662.4	2782
1664.47	2804
1666.53	2850
1668.59	2830
1670.66	2908
1672.72	2808
1674.78	2808
1676.84	2772
1678.9	2752
1680.96	2762
1683.01	2722
1685.07	2814
1687.13	2784
1689.19	2702
1691.24	2676
1693.3	2666
1695.35	2680
1697.4	2678
1699.46	2708
1701.51	2702
1703.56	2594
1705.61	2628
1707.66	2672
1709.71	2670
1711.76	2638
1713.81	2636
1715.86	2632
1717.91	2584
1719.95	2558
1722	2622
1724.04	2586
1726.09	2556
1728.13	2584
1730.18	2598
1732.22	2598
1734.26	2554
1736.3	2572
1738.34	2550
1740.38	2590
1742.42	2542
1744.46	2576
1746.5	2520
1748.54	2526
1750.58	2568
1752.61	2544
1754.65	2484
1756.68	2610
1758.72	2538
1760.75	2504
1762.79	2488
1764.82	2496
1766.85	2474
1768.88	2458
1770.91	2438
1772.94	2562
1774.97	2452
1777	2496
1779.03	2498
1781.06	2470
1783.09	2466
1785.11	2482
1787.14	2498
1789.16	2458
1791.19	2446
1793.21	2452
1795.23	2426
1797.26	2398
1799.28	2440
1801.3	2426
1803.32	2462
1805.34	2398
1807.36	2470
1809.38	2372
1811.4	2390
1813.42	2376
1815.43	2414
1817.45	2396
1819.47	2350
1821.48	2364
1823.49	2350
1825.51	2334
1827.52	2374
1829.54	2422
1831.55	2284
1833.56	2320
1835.57	2346
1837.58	2338
1839.59	2312
1841.6	2304
1843.61	2272
1845.61	2372
1847.62	2258
1849.63	2324
1851.63	2318
1853.64	2250
1855.64	2256
1857.65	2326
1859.65	2276
1861.65	2210
1863.65	2242
1865.66	2260
1867.66	2236
1869.66	2236
1871.66	2256
1873.66	2276
1875.65	2258
1877.65	2170
1879.65	2224
1881.65	2224
1883.64	2202
1885.64	2170
1887.63	2192
1889.63	2204
1891.62	2260
1893.61	2256
1895.6	2222
1897.6	2174
1899.59	2158
1901.58	2236
1903.57	2198
1905.56	2186
1907.54	2228
1909.53	2190
1911.52	2154
1913.51	2158
1915.49	2144
1917.48	2138
1919.46	2182
1921.45	2180
1923.43	2214
1925.41	2168
1927.4	2160
1929.38	2194
1931.36	2174
1933.34	2162
1935.32	2136
1937.3	2144
1939.28	2160
1941.26	2140
1943.23	2176
1945.21	2112
1947.19	2140
1949.16	2072
1951.14	2144
1953.11	2120
1955.09	2092
1957.06	2130
1959.03	2150
1961	2074
1962.98	2154
1964.95	2122
1966.92	2056
1968.89	2160
1970.85	2140
1972.82	2110
1974.79	2122
1976.76	2116
1978.73	2080
1980.69	2110
1982.66	2108
1984.62	2082
1986.59	2114
1988.55	2106
1990.51	2042
1992.47	2048
1994.44	2050
1996.4	2072
1998.36	2082
2000.32	2106
2002.28	2068
2004.24	2020
2006.19	2068
2008.15	2048
2010.11	2034
2012.06	2062
2014.02	1990
2015.98	2060
2017.93	2076
2019.88	2032
2021.84	1976
2023.79	2010
2025.74	2070
2027.69	2048
2029.65	2000
2031.6	2074
2033.55	2030
2035.5	2020
2037.44	2016
2039.39	2034
2041.34	2052
2043.29	2006
2045.23	2010
2047.18	2014
2049.12	1992
2051.07	1998
2053.01	2004
2054.95	2018
2056.9	1976
2058.84	1930
2060.78	1992
2062.72	1982
2064.66	1990
2066.6	2018
2068.54	1944
2070.48	1978
2072.42	1968
2074.35	1942
2076.29	1912
2078.23	1962
2080.16	1948
2082.1	1954
2084.03	2016
2085.96	1914
2087.9	1948
2089.83	1976
2091.76	1924
2093.69	1932
2095.62	1948
2097.55	1946
2099.48	1920
2101.41	1956
2103.34	1954
2105.27	1972
2107.2	1928
2109.12	1956
2111.05	1942
2112.98	1920
2114.9	1952
2116.82	1948
2118.75	1926
2120.67	1958
2122.59	1948
2124.52	1926
2126.44	1880
2128.36	1856
2130.28	1838
2132.2	1864
2134.12	1916
2136.04	1840
2137.95	1886
2139.87	1916
2141.79	1870
2143.7	1914
2145.62	1877.89
2147.53	1901.9
2149.45	1888.23
2151.36	1850
2153.28	1859.89
2155.19	1812.21
2157.1	1844.21
2159.01	1879.21
2160.92	1849.41
2162.83	1887.62
2164.74	1878.59
2166.65	1852.53
2168.56	1826.08
2170.47	1815.74
2172.38	1807.5
2174.28	1815.22
2176.19	1801.91
2178.09	1823.11
2180	1829.11
2181.9	1793.1
2183.81	1804.63
2185.71	1762.25
2187.61	1764.59
2189.52	1791.96
2191.42	1811.59
2193.32	1773.53
2195.22	1801.47
2197.12	1788.22
2199.02	1794
2200.92	1770.12
2202.82	1768.92
2204.71	1770.74
2206.61	1750.28
2208.51	1734.89
2210.4	1770.36
2212.3	1744.31
2214.19	1759.69
2216.09	1794.15
2217.98	1763.66
2219.87	1778.95
2221.77	1758.22
2223.66	1747.97
2225.55	1758.05
2227.44	1751.32
2229.33	1769.17
2231.22	1753.66
2233.11	1738.62
2235	1723.97
2236.88	1731.31
2238.77	1748.14
2240.66	1754.04
2242.07	1712
2243.97	1746
2245.87	1742
2247.76	1744
2249.65	1710
2251.55	1734
2253.44	1698
2255.33	1728
2257.22	1714
2259.12	1736
2261.01	1748
2262.9	1708
2264.78	1710
2266.67	1708
2268.56	1660
2270.45	1632
2272.34	1656
2274.22	1728
2276.11	1698
2277.99	1676
2279.88	1676
2281.76	1666
2283.65	1684
2285.53	1700
2287.41	1646
2289.3	1624
2291.18	1670
2293.06	1666
2294.94	1682
2296.82	1650
2298.7	1680
2300.58	1662
2302.46	1650
2304.33	1676
2306.21	1596
2308.09	1656
2309.96	1632
2311.84	1682
2313.71	1630
2315.59	1676
2317.46	1596
2319.33	1614
2321.21	1604
2323.08	1582
2324.95	1620
2326.82	1586
2328.69	1578
2330.56	1606
2332.43	1614
2334.3	1608
2336.17	1628
2338.03	1610
2339.9	1596
2341.77	1590
2343.63	1590
2345.5	1554
2347.36	1574
2349.23	1642
2351.09	1538
2352.95	1602
2354.82	1552
2356.68	1584
2358.54	1510
2360.4	1534
2362.26	1572
2364.12	1570
2365.98	1518
2367.84	1580
2369.7	1570
2371.56	1566
2373.41	1574
2375.27	1514
2377.12	1466
2378.98	1504
2380.84	1566
2382.69	1536
2384.54	1514
2386.4	1474
2388.25	1458
2390.1	1446
2391.95	1510
2393.8	1416
2395.65	1452
2397.5	1484
2399.35	1448
2401.2	1472
2403.05	1444
2404.9	1446
2406.75	1490
2408.59	1474
2410.44	1470
2412.28	1430
2414.13	1446
2415.97	1458
2417.82	1412
2419.66	1440
2421.5	1408
2423.35	1422
2425.19	1464
2427.03	1438
2428.87	1438
2430.71	1444
2432.55	1380
2434.39	1412
2436.23	1416
2438.06	1400
2439.9	1390
2441.74	1364
2443.57	1388
2445.41	1450
2447.24	1324
2449.08	1428
2450.91	1402
2452.75	1366
2454.58	1356
2456.41	1410
2458.24	1374
2460.08	1370
2461.91	1356
2463.74	1368
2465.57	1354
2467.4	1346
2469.22	1326
2471.05	1332
2472.88	1306
2474.71	1344
2476.53	1328
2478.36	1310
2480.19	1338
2482.01	1298
2483.83	1288
2485.66	1286
2487.48	1278
2489.3	1284
2491.13	1334
2492.95	1268
2494.77	1314
2496.59	1310
2498.41	1236
2500.23	1266
2502.05	1278
2503.87	1256
2505.68	1248
2507.5	1272
2509.32	1196
2511.14	1244
2512.95	1304
2514.77	1250
2516.58	1268
2518.39	1210
2520.21	1182
2522.02	1246
2523.83	1208
2525.65	1186
2527.46	1210
2529.27	1208
2531.08	1210
2532.89	1200
2534.7	1230
2536.51	1186
2538.32	1204
2540.12	1212
2541.93	1214
2543.74	1212
2545.54	1168
2547.35	1178
2549.15	1196
2550.96	1194
2552.76	1194
2554.56	1152
2556.37	1188
2558.17	1148
2559.97	1134
2561.77	1150
2563.58	1142
2565.38	1156
2567.18	1100
2568.97	1134
2570.77	1122
2572.57	1108
2574.37	1136
2576.17	1110
2577.96	1110
2579.76	1094
2581.55	1102
2583.35	1138
2585.14	1094
2586.94	1084
2588.73	1096
2590.52	1098
2592.32	1086
2594.11	1096
2595.9	1142
2597.69	1028
2599.48	1048
2601.27	1068
2603.06	1050
2604.85	1044
2606.64	1056
2608.42	1056
2610.21	1072
2612	1018
2613.78	1062
2615.57	1030
2617.36	1044
2619.14	992
2620.92	1068
2622.71	1004
2624.49	1004
2626.27	1012
2628.05	998
2629.84	998
2631.62	980
2633.4	1008
2635.18	1030
2636.96	1000
2638.74	1020
2640.51	968
2642.29	1028
2644.07	980
2645.85	952
2647.62	972
2649.4	958
2651.17	928
2652.95	940
2654.72	970
2656.5	972
2658.27	950
2660.04	928
2661.81	934
2663.58	946
2665.35	930
2667.13	928
2668.9	944
2670.66	908
2672.43	942
2674.2	936
2675.97	944
2677.74	912
2679.5	962
2681.27	902
2683.04	936
2684.8	934
2686.57	910
2688.33	882
2690.09	890
2691.86	888
2693.62	920
2695.38	936
2697.15	888
2698.91	884
2700.67	894
2702.43	900
2704.19	878
2705.95	840
2707.7	856
2709.46	884
2711.22	880
2712.98	864
2714.73	884
2716.49	898
2718.25	838
2720	858
2721.76	840
2723.51	832
2725.26	818
2727.02	828
2728.77	836
2730.52	846
2732.27	820
2734.02	838
2735.77	838
2737.52	814
2739.27	844
2741.02	834
2742.77	804
2744.52	808
2746.27	816
2748.01	788
2749.76	764
2751.51	830
2753.25	788
2755	806
2756.74	792
2758.48	802
2760.23	758
2761.97	798
2763.71	778
2765.45	762
2767.19	792
2768.94	784
2770.68	776
2772.42	778
2774.16	748
2775.89	748
2777.63	742
2779.37	736
2781.11	754
2782.84	768
2784.58	736
2786.32	714
2788.05	740
2789.79	750
2791.52	740
2793.25	746
2794.99	722
2796.72	728
2798.45	728
2800.18	718
2801.92	708
2803.65	733
2805.38	718
2807.11	734
2808.84	692
2810.57	710
2812.29	714
2814.02	708
2815.75	678
2817.47	664
2819.2	694
2820.93	704
2822.65	682
2824.38	716
2826.1	720
2827.82	704
2829.55	708
2831.27	692
2832.99	630
2834.71	706
2836.44	658
2838.16	670
2839.88	698
2841.6	666
2843.32	664
2845.03	670
2846.75	650
2848.47	690
2850.19	662
2851.9	678
2853.62	636
2855.34	650
2857.05	650
2858.77	614
2860.48	636
2862.19	614
2863.91	634
2865.62	610
2867.33	600
2869.04	634
2870.76	600
2872.47	614
2874.18	612
2875.89	608
2877.6	598
2879.31	590
2881.01	632
2882.72	610
2884.43	594
2886.14	610
2887.84	626
2889.55	602
2891.25	604
2892.96	618
2894.66	612
2896.37	608
2898.07	576
2899.77	596
2901.48	604
2903.18	570
2904.88	564
2906.58	564
2908.28	596
2909.98	582
2911.68	610
2913.38	592
2915.08	562
2916.78	572
2918.47	564
2920.17	580
2921.87	552
2923.56	590
2925.26	574
2926.95	542
2928.65	560
2930.34	544
2932.04	524
2933.73	576
2935.42	544
2937.11	540
2938.81	550
2940.5	540
2942.19	544
2943.88	530
2945.57	544
2947.26	554
2948.95	532
2950.64	532
2952.32	532
2954.01	546
2955.7	548
2957.38	528
2959.07	516
2960.75	528
2962.44	530
2964.12	508
2965.81	534
2967.49	508
2969.17	520
2970.86	526
2972.54	506
2974.22	518
2975.9	512
2977.58	518
2979.26	526
2980.94	494
2982.62	500
2984.3	518
2985.98	480
2987.66	492
2989.33	484
2991.01	474
2992.69	472
2994.36	468
2996.04	490
2997.71	478
2999.39	470