File: muestras/tallo/1/Organic_21.txt
#Acq. time (s)=	10
#Accumulations=	1
#Range (cm-¹)=	100...3000
#Windows=	3
#Autofocus=	Off
#AutoExposure=	Off
#Spike filter=	Off
#Delay time (s)=	0
#Binning=	1
#Readout mode=	Signal
#DeNoise=	Off
#ICS correction=	Off
#Dark correction=	Off
#Inst. Process=	Off
#Instrument=	LabRAM HR Evol
#Detector=	Syncerity OE
#Objective=	x100_VIS
#Grating=	600 (500nm)
#ND Filter=	25%
#Laser=	633nm_Edge
#Hole=	100.021
#Range=	Visible
#Project=	Omar
#Sample=	26-06-23
#Site=	1
#Title=	Organic
#Remark=
#Date=	26.06.2023 16:14
#Acquired=	26.06.2023 16:14:57
101.018	41046
103.586	41014
106.152	41252
108.717	41338
111.281	41554
113.845	41966
116.407	41670
118.969	42006
121.53	42288
124.09	42356
126.649	42450
129.207	42674
131.765	42880
134.321	43154
136.877	43294
139.432	43196
141.985	43656
144.538	43602
147.09	43756
149.641	43878
152.191	43876
154.741	43996
157.289	44082
159.837	44434
162.385	44790
164.93	44812
167.476	44736
170.019	44864
172.562	44804
175.105	45182
177.646	45114
180.188	44956
182.727	45462
185.266	45534
187.804	45636
190.342	45768
192.878	46364
195.413	46496
197.948	46716
200.481	47038
203.014	47050
205.546	47378
208.077	47490
210.608	47676
213.137	47866
215.666	48208
218.194	48376
220.721	48664
223.247	48828
225.772	48918
228.295	49336
230.819	49602
233.342	49824
235.864	49954
238.384	50352
240.904	50396
243.423	50694
245.941	50868
248.46	51164
250.975	51132
253.492	51378
256.006	51812
258.519	51466
261.033	51544
263.545	51966
266.057	52014
268.567	51936
271.076	51600
273.585	52256
276.094	52072
278.601	52616
281.107	52562
283.612	53056
286.116	53136
288.62	53500
291.123	54052
293.625	54228
296.126	54162
298.626	54468
301.126	55020
303.625	55454
306.122	55344
308.62	55792
311.114	56170
313.61	56124
316.105	56612
318.599	56618
321.09	56660
323.583	56988
326.073	56868
328.563	57034
331.053	57348
333.541	57572
336.029	57564
338.515	57862
341.001	58102
343.486	58676
345.97	58824
348.453	59064
350.936	59194
353.418	59502
355.898	59586
358.378	59584
360.858	60018
363.336	60374
365.813	60396
368.29	60582
370.766	60886
373.241	60922
375.715	60918
378.188	60630
380.66	61116
383.132	61206
385.603	61318
388.072	61528
390.541	61546
393.01	62072
395.477	62030
397.943	62324
400.409	62592
402.875	63200
405.338	63514
407.802	63970
410.263	64368
412.725	64496
415.185	64535
417.646	64535
420.104	64535
422.564	64535
425.02	64535
427.477	64535
429.933	64535
432.388	64535
434.841	64535
437.294	64535
439.748	64535
442.199	64535
444.65	64535
447.1	64535
449.549	64535
451.997	64535
454.445	64535
456.891	64535
459.337	64535
461.782	64535
464.227	64535
466.669	64535
469.112	64535
471.554	64535
473.995	64535
476.434	64535
478.874	64535
481.312	64535
483.749	64535
486.186	64535
488.622	64535
491.057	64535
493.491	64535
495.925	64535
498.357	64535
500.789	64535
503.221	64535
505.65	64535
508.079	64535
510.509	64535
512.936	64535
515.363	64535
517.789	64535
520.214	64535
522.638	64535
525.062	64535
527.485	64535
529.907	64535
532.328	64535
534.748	64535
537.168	64535
539.587	64535
542.005	64535
544.423	64535
546.838	64535
549.254	64535
551.669	64535
554.082	64535
556.496	64535
558.909	64535
561.319	64535
563.731	64535
566.14	64535
568.549	64535
570.957	64535
573.364	64535
575.771	64535
578.177	64535
580.581	64535
582.987	64535
585.39	64535
587.792	64535
590.193	64535
592.594	64535
594.996	64535
597.395	64535
599.793	64535
602.191	64535
604.588	64535
606.984	64535
609.378	64535
611.773	64535
614.167	64535
616.56	64535
618.953	64535
621.343	64535
623.734	64535
626.124	64535
628.512	64535
630.901	64535
633.289	64535
635.675	64535
638.061	64535
640.446	64535
642.831	64535
645.213	64535
647.595	64535
649.978	64535
652.359	64535
654.738	64535
657.117	64535
659.497	64535
661.875	64535
664.252	64535
666.628	64535
669.003	64535
671.378	64535
673.751	64535
676.124	64535
678.497	64535
680.868	64535
683.239	64535
685.609	64535
687.977	64535
690.346	64535
692.714	64535
695.081	64535
697.446	64535
699.812	64535
702.175	64535
704.539	64535
706.901	64535
709.264	64535
711.625	64535
713.986	64535
716.345	64535
718.705	64535
721.062	64535
723.419	64535
725.775	64535
728.132	64535
730.487	64535
732.841	64535
735.194	64535
737.546	64535
739.898	64535
742.249	64535
744.599	64535
746.949	64535
749.298	64535
751.646	64535
753.993	64535
756.34	64535
758.684	64535
761.029	64535
763.374	64535
765.716	64535
768.059	64535
770.401	64535
772.741	64535
775.082	64535
777.421	64535
779.76	64535
782.097	64535
784.434	64535
786.771	64535
789.106	64535
791.44	64535
793.775	64535
796.108	64535
798.44	64535
800.771	64535
803.102	64535
805.432	64535
807.761	64535
810.09	64535
812.417	64535
814.744	64535
817.071	64535
819.396	64535
821.721	64535
824.045	64535
826.367	64535
828.69	64535
831.012	64535
833.332	64535
835.653	64535
837.972	64535
840.29	64535
842.609	64535
844.925	64535
847.242	64535
849.557	64535
851.871	64535
854.186	64535
856.498	64535
858.81	64535
861.122	64535
863.434	64535
865.744	64535
868.053	64535
870.361	64535
872.669	64535
874.976	64535
877.282	64535
879.588	64535
881.893	64535
884.197	64535
886.5	64535
888.802	64535
891.104	64535
893.405	64535
895.706	64535
898.004	64535
900.303	64535
902.6	64535
904.898	64535
907.194	64535
909.49	64535
911.785	64535
914.08	64535
916.372	64535
918.666	64535
920.957	64535
923.248	64535
925.538	64535
927.828	64535
930.118	64535
932.406	64535
934.693	64535
936.979	64535
939.265	64535
941.55	64535
943.835	64535
946.118	64535
948.401	64535
950.682	64535
952.964	64535
955.245	64535
957.525	64535
959.803	64535
962.082	64535
964.36	64535
966.636	64535
968.913	64535
971.188	64535
973.463	64535
975.736	64535
978.009	64535
980.282	64535
982.554	64535
984.824	64535
987.095	64535
989.364	64535
991.633	64535
993.9	64535
996.167	64535
998.434	64535
1000.7	64535
1002.96	64535
1005.23	64535
1007.49	64535
1009.76	64535
1012.02	64535
1014.28	64535
1016.54	64535
1018.8	64535
1021.06	64535
1023.32	64535
1025.57	64535
1027.83	64535
1030.09	64535
1032.34	64535
1034.6	64535
1036.85	64535
1039.1	64535
1041.35	64535
1043.61	64535
1045.86	64535
1048.11	64535
1050.36	64535
1052.61	64535
1054.85	64535
1057.1	64535
1059.35	64535
1061.59	64535
1063.84	64535
1066.08	64535
1068.33	64535
1070.57	64535
1072.81	64535
1075.05	64535
1077.29	64535
1079.53	64535
1081.77	64535
1084.01	64535
1086.25	64535
1088.48	64535
1090.72	64535
1092.96	64535
1095.19	64535
1097.43	64535
1099.66	64535
1101.89	64535
1104.12	64535
1106.35	64535
1108.59	64535
1110.81	64535
1113.04	64535
1115.27	64535
1117.5	64535
1119.73	64535
1121.95	64535
1124.18	64535
1126.4	64535
1128.63	64535
1130.85	64535
1133.07	64535
1135.29	64535
1137.51	64535
1139.73	64535
1141.95	64535
1144.17	64535
1146.39	64535
1148.61	64535
1150.82	64535
1153.04	64535
1155.26	64535
1157.47	64535
1159.68	64535
1161.9	64535
1164.11	64535
1166.32	64535
1168.53	64535
1170.74	64535
1172.95	64535
1175.16	64535
1177.37	64535
1179.58	64535
1181.78	64535
1183.99	64535
1186.19	64535
1188.4	64535
1190.6	64535
1192.8	64535
1195.01	64535
1197.21	64535
1199.41	64535
1201.61	64535
1203.81	64535
1206.01	64535
1208.2	64535
1210.4	64535
1212.6	64535
1214.8	64535
1216.99	64535
1219.18	64535
1221.38	64535
1223.57	64535
1225.76	64535
1227.96	64535
1230.15	64535
1232.34	64535
1234.53	64535
1236.71	64535
1238.9	64535
1241.09	64535
1243.28	64535
1245.46	64535
1247.65	64535
1249.83	64535
1252.02	64535
1254.2	64535
1256.38	64535
1258.56	64535
1260.74	64535
1262.92	64535
1265.1	64535
1267.28	64535
1269.46	64535
1271.64	64535
1273.82	64535
1275.99	64535
1278.17	64535
1280.34	64535
1282.52	64535
1284.69	64535
1286.86	64535
1289.03	64535
1291.21	64535
1293.38	64535
1295.55	64535
1297.71	64535
1299.88	64535
1302.05	64535
1304.22	64535
1306.38	64535
1308.43	64535
1310.61	64535
1312.78	64535
1314.96	64535
1317.13	64535
1319.3	64535
1321.48	64535
1323.65	64535
1325.82	64535
1327.99	64535
1330.16	64535
1332.33	64535
1334.5	64535
1336.66	64535
1338.83	64535
1341	64535
1343.16	64535
1345.33	64535
1347.49	64535
1349.65	64535
1351.82	64535
1353.98	64535
1356.14	64535
1358.3	64535
1360.46	64535
1362.62	64535
1364.78	64535
1366.94	64535
1369.09	64535
1371.25	64535
1373.41	64535
1375.56	64535
1377.72	64535
1379.87	64535
1382.02	64535
1384.17	64535
1386.33	64535
1388.48	64535
1390.63	64535
1392.78	64535
1394.93	64535
1397.07	64535
1399.22	64535
1401.37	64535
1403.52	64535
1405.66	64535
1407.81	64535
1409.95	64535
1412.09	64535
1414.24	64535
1416.38	64535
1418.52	64535
1420.66	64535
1422.8	64535
1424.94	64535
1427.08	64535
1429.22	64535
1431.35	64535
1433.49	64535
1435.63	64535
1437.76	64535
1439.9	64535
1442.03	64535
1444.17	64535
1446.3	64535
1448.43	64535
1450.56	64535
1452.69	64535
1454.82	64535
1456.95	64535
1459.08	64535
1461.21	64535
1463.34	64535
1465.46	64535
1467.59	64535
1469.71	64535
1471.84	64535
1473.96	64535
1476.08	64535
1478.21	64535
1480.33	64535
1482.45	64535
1484.57	64535
1486.69	64535
1488.81	64535
1490.93	64535
1493.05	64535
1495.16	64535
1497.28	64535
1499.4	64535
1501.51	64535
1503.63	64535
1505.74	64535
1507.85	64535
1509.97	64535
1512.08	64535
1514.19	64535
1516.3	64535
1518.41	64535
1520.52	64535
1522.63	64535
1524.73	64535
1526.84	64535
1528.95	64535
1531.06	64535
1533.16	64535
1535.26	64535
1537.37	64535
1539.47	64535
1541.57	64535
1543.68	64535
1545.78	64535
1547.88	64535
1549.98	64535
1552.08	64535
1554.18	64535
1556.27	64535
1558.37	64535
1560.47	64535
1562.56	64535
1564.66	64535
1566.75	64535
1568.85	64535
1570.94	64535
1573.03	64535
1575.13	64535
1577.22	64535
1579.31	64535
1581.4	64535
1583.49	64535
1585.58	64535
1587.66	64535
1589.75	64535
1591.84	64535
1593.93	64535
1596.01	64535
1598.1	64535
1600.18	64535
1602.26	64535
1604.35	64535
1606.43	64535
1608.51	64535
1610.59	64535
1612.67	64535
1614.75	64535
1616.83	64535
1618.91	64535
1620.99	64535
1623.06	64535
1625.14	64535
1627.21	64535
1629.29	64535
1631.36	64535
1633.44	64535
1635.51	64535
1637.58	64535
1639.66	64535
1641.73	64535
1643.8	64535
1645.87	64535
1647.94	64535
1650	64535
1652.07	64535
1654.14	64535
1656.21	64535
1658.27	64535
1660.34	64535
1662.4	64535
1664.47	64535
1666.53	64535
1668.59	64535
1670.66	64535
1672.72	64535
1674.78	64535
1676.84	64535
1678.9	64535
1680.96	64535
1683.01	64535
1685.07	64535
1687.13	64535
1689.19	64535
1691.24	64535
1693.3	64535
1695.35	64535
1697.4	64535
1699.46	64535
1701.51	64535
1703.56	64535
1705.61	64535
1707.66	64535
1709.71	64535
1711.76	64535
1713.81	64535
1715.86	64535
1717.91	64535
1719.95	64535
1722	64535
1724.04	64535
1726.09	64535
1728.13	64535
1730.18	64535
1732.22	64535
1734.26	64535
1736.3	64535
1738.34	64535
1740.38	64535
1742.42	64535
1744.46	64535
1746.5	64535
1748.54	64535
1750.58	64535
1752.61	64535
1754.65	64535
1756.68	64535
1758.72	64535
1760.75	64535
1762.79	64535
1764.82	64535
1766.85	64535
1768.88	64535
1770.91	64535
1772.94	64535
1774.97	64535
1777	64535
1779.03	64535
1781.06	64535
1783.09	64535
1785.11	64535
1787.14	64535
1789.16	64535
1791.19	64535
1793.21	64535
1795.23	64535
1797.26	64535
1799.28	64535
1801.3	64535
1803.32	64535
1805.34	64535
1807.36	64535
1809.38	64535
1811.4	64535
1813.42	64535
1815.43	64535
1817.45	64535
1819.47	64535
1821.48	64535
1823.49	64535
1825.51	64535
1827.52	64535
1829.54	64535
1831.55	64535
1833.56	64535
1835.57	64535
1837.58	64535
1839.59	64535
1841.6	64535
1843.61	64535
1845.61	64535
1847.62	64535
1849.63	64535
1851.63	64535
1853.64	64535
1855.64	64535
1857.65	64535
1859.65	64535
1861.65	64535
1863.65	64535
1865.66	64535
1867.66	64535
1869.66	64535
1871.66	64535
1873.66	64535
1875.65	64535
1877.65	64535
1879.65	64535
1881.65	64535
1883.64	64535
1885.64	64535
1887.63	64535
1889.63	64535
1891.62	64535
1893.61	64535
1895.6	64535
1897.6	64535
1899.59	64535
1901.58	64535
1903.57	64535
1905.56	64535
1907.54	64535
1909.53	64535
1911.52	64535
1913.51	64535
1915.49	64535
1917.48	64535
1919.46	64535
1921.45	64535
1923.43	64535
1925.41	64535
1927.4	64535
1929.38	64535
1931.36	64535
1933.34	64535
1935.32	64535
1937.3	64535
1939.28	64535
1941.26	64535
1943.23	64535
1945.21	64535
1947.19	64535
1949.16	64535
1951.14	64535
1953.11	64535
1955.09	64535
1957.06	64535
1959.03	64535
1961	64535
1962.98	64535
1964.95	64535
1966.92	64535
1968.89	64535
1970.85	64535
1972.82	64535
1974.79	64535
1976.76	64535
1978.73	64535
1980.69	64535
1982.66	64535
1984.62	64535
1986.59	64535
1988.55	64535
1990.51	64535
1992.47	64535
1994.44	64535
1996.4	64535
1998.36	64535
2000.32	64535
2002.28	64535
2004.24	64535
2006.19	64535
2008.15	64535
2010.11	64535
2012.06	64535
2014.02	64535
2015.98	64535
2017.93	64535
2019.88	64535
2021.84	64535
2023.79	64535
2025.74	64535
2027.69	64535
2029.65	64535
2031.6	64535
2033.55	64535
2035.5	64535
2037.44	64535
2039.39	64535
2041.34	64535
2043.29	64535
2045.23	64535
2047.18	64535
2049.12	64535
2051.07	64535
2053.01	64535
2054.95	64535
2056.9	64535
2058.84	64535
2060.78	64535
2062.72	64535
2064.66	64535
2066.6	64535
2068.54	64535
2070.48	64535
2072.42	64535
2074.35	64535
2076.29	64535
2078.23	64535
2080.16	64535
2082.1	64535
2084.03	64535
2085.96	64535
2087.9	64535
2089.83	64535
2091.76	64535
2093.69	64535
2095.62	64535
2097.55	64535
2099.48	64535
2101.41	64535
2103.34	64535
2105.27	64535
2107.2	64535
2109.12	64535
2111.05	64535
2112.98	64535
2114.9	64535
2116.82	64535
2118.75	64535
2120.67	64535
2122.59	64535
2124.52	64535
2126.44	64535
2128.36	64535
2130.28	64535
2132.2	64535
2134.12	64535
2136.04	64535
2137.95	64535
2139.87	64535
2141.79	64535
2143.7	64535
2145.62	64535
2147.53	64535
2149.45	64535
2151.36	64535
2153.28	64535
2155.19	64535
2157.1	64535
2159.01	64535
2160.92	64535
2162.83	64535
2164.74	64535
2166.65	64535
2168.56	64535
2170.47	64535
2172.38	64535
2174.28	64535
2176.19	64535
2178.09	64535
2180	64535
2181.9	64535
2183.81	64535
2185.71	64535
2187.61	64535
2189.52	64535
2191.42	64535
2193.32	64535
2195.22	64535
2197.12	64535
2199.02	64535
2200.92	64535
2202.82	64535
2204.71	64535
2206.61	64535
2208.51	64535
2210.4	64535
2212.3	64535
2214.19	64535
2216.09	64535
2217.98	64535
2219.87	64535
2221.77	64535
2223.66	64535
2225.55	64535
2227.44	64535
2229.33	64535
2231.22	64535
2233.11	64535
2235	64535
2236.88	64535
2238.77	64526.1
2240.66	64535
2242.07	64535
2243.97	64535
2245.87	64535
2247.76	64535
2249.65	64535
2251.55	64535
2253.44	64516
2255.33	64222
2257.22	64014
2259.12	63868
2261.01	64220
2262.9	63868
2264.78	64176
2266.67	63992
2268.56	63754
2270.45	63716
2272.34	63576
2274.22	63508
2276.11	63270
2277.99	63282
2279.88	62926
2281.76	62930
2283.65	62686
2285.53	63112
2287.41	62722
2289.3	62340
2291.18	62746
2293.06	62470
2294.94	62502
2296.82	62316
2298.7	61792
2300.58	61750
2302.46	61532
2304.33	61524
2306.21	61374
2308.09	61714
2309.96	61436
2311.84	61496
2313.71	61382
2315.59	61014
2317.46	61350
2319.33	60880
2321.21	61000
2323.08	60664
2324.95	60630
2326.82	60664
2328.69	60290
2330.56	60458
2332.43	60170
2334.3	60446
2336.17	60180
2338.03	60028
2339.9	59942
2341.77	59920
2343.63	59542
2345.5	59948
2347.36	59542
2349.23	59464
2351.09	59442
2352.95	59710
2354.82	59090
2356.68	59394
2358.54	59156
2360.4	59470
2362.26	58902
2364.12	58692
2365.98	58920
2367.84	58570
2369.7	58646
2371.56	58322
2373.41	58388
2375.27	58424
2377.12	58228
2378.98	57970
2380.84	57916
2382.69	57818
2384.54	57630
2386.4	57534
2388.25	57612
2390.1	57570
2391.95	57690
2393.8	57240
2395.65	56972
2397.5	57054
2399.35	57108
2401.2	57022
2403.05	56678
2404.9	56454
2406.75	56428
2408.59	56196
2410.44	56342
2412.28	55870
2414.13	55684
2415.97	55932
2417.82	55718
2419.66	55806
2421.5	55520
2423.35	55580
2425.19	55658
2427.03	55098
2428.87	55070
2430.71	55044
2432.55	54762
2434.39	54940
2436.23	54990
2438.06	54632
2439.9	54800
2441.74	54406
2443.57	54518
2445.41	54020
2447.24	54230
2449.08	54256
2450.91	54182
2452.75	53796
2454.58	53950
2456.41	53770
2458.24	53448
2460.08	53588
2461.91	53240
2463.74	53250
2465.57	53508
2467.4	53020
2469.22	53366
2471.05	53020
2472.88	52692
2474.71	52988
2476.53	52746
2478.36	52496
2480.19	52274
2482.01	52420
2483.83	52412
2485.66	52300
2487.48	51910
2489.3	52026
2491.13	51860
2492.95	51512
2494.77	51448
2496.59	51210
2498.41	51290
2500.23	50982
2502.05	50980
2503.87	50838
2505.68	50606
2507.5	51014
2509.32	50750
2511.14	50618
2512.95	50272
2514.77	50506
2516.58	50116
2518.39	50210
2520.21	50052
2522.02	49918
2523.83	49482
2525.65	49672
2527.46	49346
2529.27	49204
2531.08	49248
2532.89	49016
2534.7	49242
2536.51	49140
2538.32	48476
2540.12	48714
2541.93	48584
2543.74	48468
2545.54	48554
2547.35	47850
2549.15	48040
2550.96	48090
2552.76	47982
2554.56	47742
2556.37	47720
2558.17	47500
2559.97	47552
2561.77	47304
2563.58	47162
2565.38	47292
2567.18	46868
2568.97	47014
2570.77	46588
2572.57	46746
2574.37	46686
2576.17	46670
2577.96	46134
2579.76	46466
2581.55	45914
2583.35	45900
2585.14	45830
2586.94	45882
2588.73	45718
2590.52	45388
2592.32	45594
2594.11	45460
2595.9	45284
2597.69	45184
2599.48	44996
2601.27	44806
2603.06	44832
2604.85	44770
2606.64	44662
2608.42	44426
2610.21	44480
2612	44242
2613.78	44114
2615.57	44046
2617.36	43860
2619.14	43866
2620.92	43874
2622.71	43504
2624.49	43380
2626.27	43454
2628.05	43494
2629.84	43232
2631.62	43184
2633.4	43022
2635.18	42808
2636.96	42566
2638.74	42716
2640.51	42556
2642.29	42322
2644.07	42284
2645.85	41984
2647.62	41834
2649.4	41740
2651.17	41758
2652.95	41764
2654.72	41812
2656.5	41520
2658.27	41518
2660.04	41442
2661.81	41270
2663.58	41266
2665.35	40974
2667.13	40740
2668.9	40788
2670.66	40978
2672.43	40952
2674.2	40570
2675.97	40806
2677.74	40456
2679.5	40628
2681.27	40088
2683.04	40126
2684.8	40032
2686.57	40138
2688.33	40120
2690.09	40018
2691.86	39572
2693.62	39684
2695.38	39894
2697.15	39468
2698.91	39262
2700.67	39048
2702.43	39150
2704.19	39086
2705.95	38734
2707.7	38552
2709.46	39112
2711.22	38514
2712.98	38410
2714.73	38068
2716.49	38166
2718.25	38354
2720	37798
2721.76	37848
2723.51	37898
2725.26	37700
2727.02	37680
2728.77	37568
2730.52	37030
2732.27	37182
2734.02	37320
2735.77	37274
2737.52	36950
2739.27	36714
2741.02	36792
2742.77	36768
2744.52	36556
2746.27	36506
2748.01	36504
2749.76	36520
2751.51	36356
2753.25	36342
2755	36082
2756.74	35916
2758.48	35710
2760.23	35892
2761.97	35868
2763.71	35686
2765.45	35462
2767.19	35400
2768.94	35390
2770.68	35158
2772.42	35002
2774.16	35308
2775.89	35002
2777.63	34848
2779.37	34856
2781.11	34690
2782.84	34644
2784.58	34454
2786.32	34272
2788.05	34270
2789.79	34270
2791.52	33962
2793.25	34098
2794.99	33802
2796.72	34130
2798.45	33820
2800.18	33912
2801.92	33796
2803.65	33583
2805.38	33552
2807.11	33440
2808.84	33432
2810.57	33334
2812.29	33022
2814.02	33048
2815.75	32800
2817.47	32834
2819.2	32690
2820.93	32660
2822.65	32596
2824.38	32662
2826.1	32204
2827.82	32188
2829.55	32118
2831.27	32070
2832.99	32058
2834.71	31866
2836.44	31904
2838.16	31888
2839.88	31478
2841.6	31274
2843.32	31336
2845.03	31176
2846.75	31244
2848.47	31090
2850.19	31134
2851.9	30900
2853.62	30758
2855.34	30830
2857.05	30522
2858.77	30622
2860.48	30514
2862.19	30290
2863.91	30218
2865.62	30134
2867.33	30062
2869.04	30012
2870.76	29866
2872.47	29898
2874.18	29870
2875.89	29638
2877.6	29736
2879.31	29654
2881.01	29394
2882.72	29384
2884.43	29448
2886.14	29328
2887.84	29180
2889.55	29170
2891.25	28792
2892.96	29084
2894.66	28618
2896.37	28814
2898.07	28498
2899.77	28600
2901.48	28576
2903.18	28594
2904.88	28512
2906.58	28458
2908.28	28404
2909.98	28494
2911.68	28154
2913.38	28324
2915.08	28058
2916.78	28174
2918.47	27900
2920.17	27968
2921.87	27848
2923.56	27636
2925.26	27870
2926.95	27664
2928.65	27780
2930.34	27522
2932.04	27552
2933.73	27340
2935.42	27304
2937.11	27336
2938.81	27388
2940.5	27136
2942.19	27254
2943.88	27036
2945.57	26876
2947.26	26902
2948.95	26898
2950.64	26894
2952.32	26586
2954.01	26658
2955.7	26628
2957.38	26390
2959.07	26554
2960.75	26482
2962.44	26258
2964.12	26302
2965.81	26198
2967.49	26102
2969.17	26248
2970.86	26160
2972.54	25802
2974.22	25588
2975.9	25978
2977.58	25876
2979.26	25594
2980.94	25408
2982.62	25274
2984.3	25182
2985.98	25252
2987.66	25020
2989.33	25224
2991.01	25104
2992.69	25072
2994.36	25156
2996.04	24842
2997.71	24694
2999.39	24680