File: muestras/tallo/1/Organic_06.txt
#Acq. time (s)=	10
#Accumulations=	1
#Range (cm-¹)=	100...3000
#Windows=	3
#Autofocus=	Off
#AutoExposure=	Off
#Spike filter=	Off
#Delay time (s)=	0
#Binning=	1
#Readout mode=	Signal
#DeNoise=	Off
#ICS correction=	Off
#Dark correction=	Off
#Inst. Process=	Off
#Instrument=	LabRAM HR Evol
#Detector=	Syncerity OE
#Objective=	x100_VIS
#Grating=	600 (500nm)
#ND Filter=	5%
#Laser=	633nm_Edge
#Hole=	74.97
#Range=	Visible
#Project=	Omar
#Sample=	26-06-23
#Site=	1
#Title=	Organic
#Remark=
#Date=	26.06.2023 15:54
#Acquired=	26.06.2023 15:54:18
101.018	2076
103.586	2032
106.152	2074
108.717	2130
111.281	2074
113.845	2012
116.407	2076
118.969	2130
121.53	2096
124.09	2060
126.649	2098
129.207	2080
131.765	2050
134.321	2058
136.877	2070
139.432	2138
141.985	2062
144.538	2114
147.09	2056
149.641	2092
152.191	2048
154.741	2046
157.289	2082
159.837	2078
162.385	2104
164.93	2074
167.476	2044
170.019	2044
172.562	2072
175.105	2048
177.646	2044
180.188	2076
182.727	2046
185.266	1988
187.804	2008
190.342	2092
192.878	2054
195.413	2118
197.948	2100
200.481	2090
203.014	2050
205.546	2106
208.077	2062
210.608	2082
213.137	2078
215.666	2030
218.194	2094
220.721	2140
223.247	2108
225.772	2090
228.295	2090
230.819	2098
233.342	2088
235.864	2162
238.384	2098
240.904	2128
243.423	2110
245.941	2166
248.46	2132
250.975	2124
253.492	2086
256.006	2164
258.519	2086
261.033	2060
263.545	2142
266.057	2088
268.567	2094
271.076	2144
273.585	2118
276.094	2126
278.601	2150
281.107	2132
283.612	2158
286.116	2124
288.62	2088
291.123	2118
293.625	2112
296.126	2134
298.626	2158
301.126	2124
303.625	2108
306.122	2178
308.62	2258
311.114	2192
313.61	2164
316.105	2172
318.599	2170
321.09	2218
323.583	2210
326.073	2224
328.563	2206
331.053	2184
333.541	2216
336.029	2158
338.515	2196
341.001	2228
343.486	2182
345.97	2210
348.453	2126
350.936	2260
353.418	2158
355.898	2180
358.378	2212
360.858	2210
363.336	2246
365.813	2230
368.29	2200
370.766	2170
373.241	2228
375.715	2254
378.188	2228
380.66	2206
383.132	2232
385.603	2204
388.072	2226
390.541	2192
393.01	2234
395.477	2236
397.943	2250
400.409	2246
402.875	2246
405.338	2258
407.802	2258
410.263	2360
412.725	2340
415.185	2300
417.646	2336
420.104	2358
422.564	2364
425.02	2328
427.477	2370
429.933	2404
432.388	2364
434.841	2404
437.294	2422
439.748	2380
442.199	2400
444.65	2414
447.1	2414
449.549	2406
451.997	2472
454.445	2458
456.891	2454
459.337	2452
461.782	2450
464.227	2474
466.669	2470
469.112	2406
471.554	2444
473.995	2450
476.434	2458
478.874	2472
481.312	2434
483.749	2496
486.186	2524
488.622	2566
491.057	2544
493.491	2556
495.925	2528
498.357	2584
500.789	2586
503.221	2624
505.65	2570
508.079	2596
510.509	2614
512.936	2650
515.363	2642
517.789	2646
520.214	2704
522.638	2668
525.062	2706
527.485	2634
529.907	2670
532.328	2700
534.748	2666
537.168	2732
539.587	2698
542.005	2772
544.423	2746
546.838	2678
549.254	2782
551.669	2760
554.082	2832
556.496	2732
558.909	2848
561.319	2836
563.731	2866
566.14	2910
568.549	2894
570.957	2888
573.364	2926
575.771	2936
578.177	2976
580.581	2936
582.987	3042
585.39	2928
587.792	3086
590.193	3070
592.594	3020
594.996	3096
597.395	3078
599.793	3072
602.191	3188
604.588	3170
606.984	3250
609.378	3196
611.773	3182
614.167	3292
616.56	3232
618.953	3348
621.343	3372
623.734	3396
626.124	3394
628.512	3462
630.901	3508
633.289	3472
635.675	3538
638.061	3578
640.446	3582
642.831	3684
645.213	3672
647.595	3704
649.978	3702
652.359	3740
654.738	3764
657.117	3808
659.497	3856
661.875	3918
664.252	3836
666.628	3964
669.003	3896
671.378	3994
673.751	3940
676.124	3930
678.497	3960
680.868	4062
683.239	4068
685.609	4092
687.977	4170
690.346	4158
692.714	4284
695.081	4266
697.446	4224
699.812	4398
702.175	4354
704.539	4496
706.901	4408
709.264	4608
711.625	4580
713.986	4602
716.345	4628
718.705	4642
721.062	4768
723.419	4816
725.775	4798
728.132	4810
730.487	5042
732.841	4944
735.194	5072
737.546	5070
739.898	5070
742.249	5100
744.599	5232
746.949	5154
749.298	5180
751.646	5292
753.993	5462
756.34	5382
758.684	5336
761.029	5394
763.374	5450
765.716	5464
768.059	5574
770.401	5698
772.741	5730
775.082	5698
777.421	5822
779.76	5798
782.097	5792
784.434	5840
786.771	5928
789.106	5942
791.44	5972
793.775	6042
796.108	6062
798.44	6220
800.771	6282
803.102	6266
805.432	6332
807.761	6452
810.09	6528
812.417	6574
814.744	6548
817.071	6650
819.396	6764
821.721	6710
824.045	6898
826.367	6892
828.69	6990
831.012	6976
833.332	7100
835.653	7092
837.972	7112
840.29	7268
842.609	7292
844.925	7300
847.242	7464
849.557	7514
851.871	7516
854.186	7590
856.498	7636
858.81	7802
861.122	7746
863.434	7770
865.744	7918
868.053	7880
870.361	7944
872.669	8056
874.976	8226
877.282	8030
879.588	8138
881.893	8216
884.197	8160
886.5	8280
888.802	8322
891.104	8378
893.405	8352
895.706	8476
898.004	8544
900.303	8648
902.6	8496
904.898	8538
907.194	8706
909.49	8824
911.785	8866
914.08	8760
916.372	8888
918.666	8846
920.957	8882
923.248	8926
925.538	9078
927.828	9004
930.118	9136
932.406	9236
934.693	9198
936.979	9292
939.265	9344
941.55	9362
943.835	9376
946.118	9432
948.401	9574
950.682	9522
952.964	9636
955.245	9714
957.525	9686
959.803	9832
962.082	9750
964.36	9698
966.636	9864
968.913	9906
971.188	9959
973.463	9894
975.736	10000
978.009	9986
980.282	9966
982.554	10068
984.824	10130
987.095	9972
989.364	9978
991.633	10028
993.9	10232
996.167	10294
998.434	10306
1000.7	10132
1002.96	10280
1005.23	10256
1007.49	10168
1009.76	10320
1012.02	10334
1014.28	10286
1016.54	10336
1018.8	10354
1021.06	10368
1023.32	10388
1025.57	10496
1027.83	10522
1030.09	10560
1032.34	10544
1034.6	10698
1036.85	10546
1039.1	10724
1041.35	10708
1043.61	10682
1045.86	10784
1048.11	10722
1050.36	10704
1052.61	10864
1054.85	10728
1057.1	10868
1059.35	10804
1061.59	10662
1063.84	10834
1066.08	10940
1068.33	10784
1070.57	10776
1072.81	10784
1075.05	10776
1077.29	10884
1079.53	10760
1081.77	10682
1084.01	10736
1086.25	10728
1088.48	10686
1090.72	10544
1092.96	10520
1095.19	10538
1097.43	10632
1099.66	10566
1101.89	10472
1104.12	10382
1106.35	10338
1108.59	10328
1110.81	10460
1113.04	10318
1115.27	10424
1117.5	10308
1119.73	10484
1121.95	10332
1124.18	10336
1126.4	10264
1128.63	10294
1130.85	10202
1133.07	10306
1135.29	10260
1137.51	10172
1139.73	10122
1141.95	10172
1144.17	10058
1146.39	10056
1148.61	10092
1150.82	10110
1153.04	10114
1155.26	10210
1157.47	10066
1159.68	9978
1161.9	10056
1164.11	10028
1166.32	9842
1168.53	10012
1170.74	9832
1172.95	9838
1175.16	9748
1177.37	9766
1179.58	9638
1181.78	9650
1183.99	9560
1186.19	9668
1188.4	9542
1190.6	9338
1192.8	9308
1195.01	9376
1197.21	9290.79
1199.41	9300.53
1201.61	9197.16
1203.81	9129.84
1206.01	8968.36
1208.2	8941.45
1210.4	9001.73
1212.6	8893.51
1214.8	8807.09
1216.99	8793.42
1219.18	8751.56
1221.38	8751.44
1223.57	8706.42
1225.76	8583.16
1227.96	8660.21
1230.15	8549.63
1232.34	8481.3
1234.53	8473.21
1236.71	8440.14
1238.9	8362.05
1241.09	8369.55
1243.28	8260.04
1245.46	8328.33
1247.65	8142.31
1249.83	8176.62
1252.02	8171.91
1254.2	8152.17
1256.38	8044.47
1258.56	8042.31
1260.74	8037.84
1262.92	7958.44
1265.1	7913.96
1267.28	7931.72
1269.46	7901.18
1271.64	7840.72
1273.82	7764.86
1275.99	7792.03
1278.17	7728.03
1280.34	7699.76
1282.52	7722.66
1284.69	7580.16
1286.86	7640.74
1289.03	7581.06
1291.21	7468.12
1293.38	7450.82
1295.55	7426.26
1297.71	7405.07
1299.88	7360.78
1302.05	7319.51
1304.22	7399.05
1306.38	7191.47
1308.43	7084
1310.61	7160
1312.78	7120
1314.96	7006
1317.13	6896
1319.3	6990
1321.48	6856
1323.65	6872
1325.82	6854
1327.99	6828
1330.16	6748
1332.33	6638
1334.5	6690
1336.66	6628
1338.83	6540
1341	6434
1343.16	6446
1345.33	6410
1347.49	6436
1349.65	6400
1351.82	6358
1353.98	6232
1356.14	6210
1358.3	6166
1360.46	6144
1362.62	6136
1364.78	6014
1366.94	5984
1369.09	6086
1371.25	5922
1373.41	5872
1375.56	5950
1377.72	5820
1379.87	5970
1382.02	5814
1384.17	5842
1386.33	5838
1388.48	5674
1390.63	5708
1392.78	5792
1394.93	5710
1397.07	5622
1399.22	5590
1401.37	5604
1403.52	5566
1405.66	5450
1407.81	5498
1409.95	5416
1412.09	5418
1414.24	5388
1416.38	5360
1418.52	5362
1420.66	5306
1422.8	5350
1424.94	5220
1427.08	5200
1429.22	5278
1431.35	5328
1433.49	5216
1435.63	5090
1437.76	5110
1439.9	5054
1442.03	5108
1444.17	4976
1446.3	4978
1448.43	4956
1450.56	5060
1452.69	4952
1454.82	4852
1456.95	4884
1459.08	4902
1461.21	4950
1463.34	4876
1465.46	4804
1467.59	4832
1469.71	4850
1471.84	4804
1473.96	4758
1476.08	4658
1478.21	4756
1480.33	4648
1482.45	4704
1484.57	4698
1486.69	4646
1488.81	4610
1490.93	4696
1493.05	4564
1495.16	4566
1497.28	4524
1499.4	4518
1501.51	4586
1503.63	4462
1505.74	4482
1507.85	4500
1509.97	4506
1512.08	4454
1514.19	4382
1516.3	4356
1518.41	4380
1520.52	4322
1522.63	4276
1524.73	4272
1526.84	4246
1528.95	4268
1531.06	4214
1533.16	4256
1535.26	4174
1537.37	4218
1539.47	4132
1541.57	4128
1543.68	4060
1545.78	4090
1547.88	4134
1549.98	4134
1552.08	4078
1554.18	4090
1556.27	4050
1558.37	3986
1560.47	3996
1562.56	3996
1564.66	3998
1566.75	4000
1568.85	3978
1570.94	3896
1573.03	3846
1575.13	3820
1577.22	3922
1579.31	3894
1581.4	3912
1583.49	3874
1585.58	3902
1587.66	3832
1589.75	3870
1591.84	3884
1593.93	3886
1596.01	3792
1598.1	3800
1600.18	3794
1602.26	3838
1604.35	3828
1606.43	3776
1608.51	3750
1610.59	3812
1612.67	3776
1614.75	3792
1616.83	3758
1618.91	3794
1620.99	3762
1623.06	3746
1625.14	3670
1627.21	3672
1629.29	3720
1631.36	3652
1633.44	3698
1635.51	3668
1637.58	3620
1639.66	3636
1641.73	3622
1643.8	3650
1645.87	3602
1647.94	3550
1650	3538
1652.07	3578
1654.14	3576
1656.21	3580
1658.27	3598
1660.34	3538
1662.4	3510
1664.47	3502
1666.53	3478
1668.59	3406
1670.66	3524
1672.72	3414
1674.78	3438
1676.84	3416
1678.9	3366
1680.96	3380
1683.01	3380
1685.07	3366
1687.13	3408
1689.19	3426
1691.24	3380
1693.3	3348
1695.35	3302
1697.4	3308
1699.46	3280
1701.51	3278
1703.56	3302
1705.61	3294
1707.66	3210
1709.71	3266
1711.76	3282
1713.81	3304
1715.86	3264
1717.91	3256
1719.95	3208
1722	3226
1724.04	3204
1726.09	3250
1728.13	3126
1730.18	3292
1732.22	3172
1734.26	3190
1736.3	3210
1738.34	3120
1740.38	3190
1742.42	3166
1744.46	3178
1746.5	3150
1748.54	3154
1750.58	3126
1752.61	3164
1754.65	3122
1756.68	3128
1758.72	3066
1760.75	3126
1762.79	3084
1764.82	3092
1766.85	3132
1768.88	3096
1770.91	3108
1772.94	3122
1774.97	3132
1777	3080
1779.03	3050
1781.06	3060
1783.09	3012
1785.11	3082
1787.14	3062
1789.16	3040
1791.19	2996
1793.21	3108
1795.23	3050
1797.26	3044
1799.28	3022
1801.3	3074
1803.32	2964
1805.34	2930
1807.36	2948
1809.38	3006
1811.4	2914
1813.42	3020
1815.43	2970
1817.45	2946
1819.47	2984
1821.48	2896
1823.49	2928
1825.51	2966
1827.52	2918
1829.54	2942
1831.55	2946
1833.56	2838
1835.57	2920
1837.58	2910
1839.59	2924
1841.6	2878
1843.61	2878
1845.61	2860
1847.62	2894
1849.63	2898
1851.63	2884
1853.64	2868
1855.64	2808
1857.65	2854
1859.65	2846
1861.65	2866
1863.65	2774
1865.66	2786
1867.66	2790
1869.66	2800
1871.66	2798
1873.66	2814
1875.65	2754
1877.65	2864
1879.65	2790
1881.65	2792
1883.64	2824
1885.64	2766
1887.63	2832
1889.63	2762
1891.62	2778
1893.61	2714
1895.6	2742
1897.6	2744
1899.59	2754
1901.58	2662
1903.57	2732
1905.56	2754
1907.54	2752
1909.53	2772
1911.52	2750
1913.51	2740
1915.49	2722
1917.48	2658
1919.46	2744
1921.45	2750
1923.43	2730
1925.41	2778
1927.4	2732
1929.38	2706
1931.36	2638
1933.34	2680
1935.32	2680
1937.3	2708
1939.28	2670
1941.26	2750
1943.23	2704
1945.21	2666
1947.19	2630
1949.16	2680
1951.14	2654
1953.11	2668
1955.09	2676
1957.06	2606
1959.03	2668
1961	2700
1962.98	2702
1964.95	2638
1966.92	2610
1968.89	2654
1970.85	2698
1972.82	2574
1974.79	2666
1976.76	2612
1978.73	2648
1980.69	2614
1982.66	2624
1984.62	2614
1986.59	2626
1988.55	2618
1990.51	2600
1992.47	2632
1994.44	2576
1996.4	2562
1998.36	2606
2000.32	2612
2002.28	2566
2004.24	2646
2006.19	2558
2008.15	2608
2010.11	2528
2012.06	2566
2014.02	2572
2015.98	2562
2017.93	2512
2019.88	2572
2021.84	2578
2023.79	2572
2025.74	2588
2027.69	2602
2029.65	2606
2031.6	2528
2033.55	2540
2035.5	2494
2037.44	2516
2039.39	2552
2041.34	2524
2043.29	2564
2045.23	2500
2047.18	2466
2049.12	2508
2051.07	2494
2053.01	2574
2054.95	2530
2056.9	2490
2058.84	2560
2060.78	2510
2062.72	2486
2064.66	2492
2066.6	2494
2068.54	2514
2070.48	2506
2072.42	2450
2074.35	2508
2076.29	2462
2078.23	2486
2080.16	2450
2082.1	2472
2084.03	2518
2085.96	2488
2087.9	2486
2089.83	2468
2091.76	2450
2093.69	2530
2095.62	2462
2097.55	2464
2099.48	2460
2101.41	2440
2103.34	2434
2105.27	2498
2107.2	2504
2109.12	2374
2111.05	2346
2112.98	2458
2114.9	2434
2116.82	2450
2118.75	2436
2120.67	2414
2122.59	2456
2124.52	2364
2126.44	2456
2128.36	2410
2130.28	2396
2132.2	2340
2134.12	2370
2136.04	2440
2137.95	2422
2139.87	2392
2141.79	2372
2143.7	2364
2145.62	2363.86
2147.53	2343.71
2149.45	2396.73
2151.36	2353.09
2153.28	2340.91
2155.19	2383.55
2157.1	2358.23
2159.01	2342.78
2160.92	2311.57
2162.83	2362.96
2164.74	2321.97
2166.65	2304.6
2168.56	2341.57
2170.47	2344.46
2172.38	2319.44
2174.28	2304.19
2176.19	2275.83
2178.09	2302.77
2180	2288.13
2181.9	2290.47
2183.81	2304.96
2185.71	2295.21
2187.61	2246.04
2189.52	2275.27
2191.42	2271.81
2193.32	2251.32
2195.22	2286.71
2197.12	2258.73
2199.02	2245.35
2200.92	2273.87
2202.82	2257.18
2204.71	2265.77
2206.61	2203.46
2208.51	2228.61
2210.4	2216.22
2212.3	2231.36
2214.19	2235.74
2216.09	2235.14
2217.98	2224.46
2219.87	2230.1
2221.77	2209.71
2223.66	2229.1
2225.55	2183.38
2227.44	2207.92
2229.33	2204.39
2231.22	2175.97
2233.11	2227.6
2235	2196.46
2236.88	2231
2238.77	2194.35
2240.66	2203.92
2242.07	2240
2243.97	2172
2245.87	2234
2247.76	2176
2249.65	2122
2251.55	2182
2253.44	2204
2255.33	2206
2257.22	2202
2259.12	2220
2261.01	2210
2262.9	2230
2264.78	2176
2266.67	2196
2268.56	2166
2270.45	2158
2272.34	2170
2274.22	2170
2276.11	2114
2277.99	2142
2279.88	2154
2281.76	2138
2283.65	2168
2285.53	2112
2287.41	2112
2289.3	2166
2291.18	2100
2293.06	2168
2294.94	2126
2296.82	2108
2298.7	2110
2300.58	2104
2302.46	2074
2304.33	2136
2306.21	2070
2308.09	2038
2309.96	2110
2311.84	2084
2313.71	2066
2315.59	2104
2317.46	2092
2319.33	2040
2321.21	2068
2323.08	2022
2324.95	2018
2326.82	2042
2328.69	2068
2330.56	1994
2332.43	2030
2334.3	2040
2336.17	2010
2338.03	2030
2339.9	2002
2341.77	1996
2343.63	2048
2345.5	2052
2347.36	2010
2349.23	2016
2351.09	2030
2352.95	1996
2354.82	1998
2356.68	1956
2358.54	1972
2360.4	1952
2362.26	2022
2364.12	1992
2365.98	1940
2367.84	1960
2369.7	1998
2371.56	1952
2373.41	1930
2375.27	1898
2377.12	1860
2378.98	1956
2380.84	1924
2382.69	1914
2384.54	1892
2386.4	1898
2388.25	1926
2390.1	1930
2391.95	1850
2393.8	1876
2395.65	1898
2397.5	1908
2399.35	1900
2401.2	1842
2403.05	1818
2404.9	1874
2406.75	1850
2408.59	1826
2410.44	1894
2412.28	1892
2414.13	1834
2415.97	1828
2417.82	1786
2419.66	1814
2421.5	1818
2423.35	1798
2425.19	1820
2427.03	1774
2428.87	1778
2430.71	1786
2432.55	1778
2434.39	1762
2436.23	1758
2438.06	1742
2439.9	1752
2441.74	1786
2443.57	1788
2445.41	1762
2447.24	1732
2449.08	1718
2450.91	1778
2452.75	1742
2454.58	1744
2456.41	1730
2458.24	1694
2460.08	1730
2461.91	1644
2463.74	1708
2465.57	1676
2467.4	1714
2469.22	1656
2471.05	1660
2472.88	1680
2474.71	1666
2476.53	1682
2478.36	1678
2480.19	1708
2482.01	1608
2483.83	1692
2485.66	1622
2487.48	1650
2489.3	1638
2491.13	1648
2492.95	1634
2494.77	1614
2496.59	1630
2498.41	1600
2500.23	1594
2502.05	1598
2503.87	1610
2505.68	1574
2507.5	1606
2509.32	1570
2511.14	1524
2512.95	1558
2514.77	1590
2516.58	1558
2518.39	1560
2520.21	1576
2522.02	1534
2523.83	1518
2525.65	1522
2527.46	1548
2529.27	1524
2531.08	1500
2532.89	1506
2534.7	1510
2536.51	1470
2538.32	1504
2540.12	1550
2541.93	1536
2543.74	1446
2545.54	1482
2547.35	1502
2549.15	1490
2550.96	1480
2552.76	1452
2554.56	1448
2556.37	1428
2558.17	1452
2559.97	1450
2561.77	1442
2563.58	1404
2565.38	1412
2567.18	1410
2568.97	1468
2570.77	1376
2572.57	1462
2574.37	1382
2576.17	1378
2577.96	1408
2579.76	1376
2581.55	1380
2583.35	1356
2585.14	1342
2586.94	1358
2588.73	1370
2590.52	1346
2592.32	1366
2594.11	1362
2595.9	1322
2597.69	1312
2599.48	1316
2601.27	1330
2603.06	1272
2604.85	1290
2606.64	1292
2608.42	1288
2610.21	1324
2612	1330
2613.78	1302
2615.57	1264
2617.36	1266
2619.14	1282
2620.92	1332
2622.71	1286
2624.49	1254
2626.27	1236
2628.05	1284
2629.84	1252
2631.62	1228
2633.4	1218
2635.18	1252
2636.96	1202
2638.74	1204
2640.51	1226
2642.29	1214
2644.07	1184
2645.85	1210
2647.62	1188
2649.4	1188
2651.17	1176
2652.95	1212
2654.72	1198
2656.5	1204
2658.27	1164
2660.04	1168
2661.81	1142
2663.58	1124
2665.35	1186
2667.13	1162
2668.9	1160
2670.66	1152
2672.43	1146
2674.2	1088
2675.97	1128
2677.74	1160
2679.5	1132
2681.27	1164
2683.04	1116
2684.8	1118
2686.57	1126
2688.33	1146
2690.09	1132
2691.86	1138
2693.62	1124
2695.38	1126
2697.15	1090
2698.91	1138
2700.67	1078
2702.43	1052
2704.19	1050
2705.95	1084
2707.7	1078
2709.46	1030
2711.22	1056
2712.98	1050
2714.73	1062
2716.49	1066
2718.25	1030
2720	1054
2721.76	1078
2723.51	1042
2725.26	1024
2727.02	1042
2728.77	1000
2730.52	1026
2732.27	1038
2734.02	1024
2735.77	982
2737.52	990
2739.27	974
2741.02	956
2742.77	1024
2744.52	948
2746.27	1006
2748.01	974
2749.76	966
2751.51	948
2753.25	980
2755	936
2756.74	996
2758.48	948
2760.23	976
2761.97	948
2763.71	934
2765.45	948
2767.19	960
2768.94	932
2770.68	926
2772.42	938
2774.16	914
2775.89	918
2777.63	924
2779.37	920
2781.11	882
2782.84	896
2784.58	918
2786.32	912
2788.05	880
2789.79	886
2791.52	846
2793.25	882
2794.99	872
2796.72	862
2798.45	858
2800.18	876
2801.92	892
2803.65	852
2805.38	854
2807.11	858
2808.84	848
2810.57	836
2812.29	860
2814.02	888
2815.75	880
2817.47	886
2819.2	848
2820.93	834
2822.65	870
2824.38	816
2826.1	806
2827.82	798
2829.55	836
2831.27	818
2832.99	832
2834.71	838
2836.44	806
2838.16	808
2839.88	786
2841.6	820
2843.32	832
2845.03	752
2846.75	776
2848.47	792
2850.19	770
2851.9	808
2853.62	796
2855.34	784
2857.05	736
2858.77	780
2860.48	770
2862.19	760
2863.91	762
2865.62	740
2867.33	764
2869.04	748
2870.76	740
2872.47	740
2874.18	748
2875.89	722
2877.6	726
2879.31	756
2881.01	734
2882.72	718
2884.43	746
2886.14	720
2887.84	710
2889.55	782
2891.25	754
2892.96	714
2894.66	738
2896.37	702
2898.07	710
2899.77	712
2901.48	732
2903.18	708
2904.88	680
2906.58	692
2908.28	734
2909.98	710
2911.68	674
2913.38	688
2915.08	684
2916.78	664
2918.47	706
2920.17	690
2921.87	692
2923.56	694
2925.26	698
2926.95	684
2928.65	652
2930.34	656
2932.04	620
2933.73	678
2935.42	644
2937.11	682
2938.81	656
2940.5	640
2942.19	662
2943.88	632
2945.57	674
2947.26	664
2948.95	668
2950.64	652
2952.32	674
2954.01	634
2955.7	640
2957.38	594
2959.07	638
2960.75	646
2962.44	638
2964.12	616
2965.81	616
2967.49	594
2969.17	630
2970.86	628
2972.54	634
2974.22	614
2975.9	612
2977.58	638
2979.26	594
2980.94	586
2982.62	612
2984.3	600
2985.98	590
2987.66	596
2989.33	602
2991.01	598
2992.69	614
2994.36	614
2996.04	570
2997.71	586
2999.39	570