File: muestras/tallo/1/Organic_15.txt
#Acq. time (s)=	10
#Accumulations=	1
#Range (cm-¹)=	100...3000
#Windows=	3
#Autofocus=	Off
#AutoExposure=	Off
#Spike filter=	Off
#Delay time (s)=	0
#Binning=	1
#Readout mode=	Signal
#DeNoise=	Off
#ICS correction=	Off
#Dark correction=	Off
#Inst. Process=	Off
#Instrument=	LabRAM HR Evol
#Detector=	Syncerity OE
#Objective=	x100_VIS
#Grating=	600 (500nm)
#ND Filter=	5%
#Laser=	633nm_Edge
#Hole=	74.97
#Range=	Visible
#Project=	Omar
#Sample=	26-06-23
#Site=	1
#Title=	Organic
#Remark=
#Date=	26.06.2023 16:03
#Acquired=	26.06.2023 16:03:38
101.018	1476
103.586	1472
106.152	1452
108.717	1512
111.281	1462
113.845	1508
116.407	1548
118.969	1508
121.53	1498
124.09	1494
126.649	1516
129.207	1520
131.765	1492
134.321	1486
136.877	1520
139.432	1524
141.985	1492
144.538	1522
147.09	1546
149.641	1492
152.191	1504
154.741	1502
157.289	1476
159.837	1504
162.385	1482
164.93	1506
167.476	1490
170.019	1506
172.562	1478
175.105	1512
177.646	1492
180.188	1436
182.727	1458
185.266	1480
187.804	1490
190.342	1470
192.878	1458
195.413	1516
197.948	1466
200.481	1516
203.014	1516
205.546	1512
208.077	1528
210.608	1514
213.137	1536
215.666	1472
218.194	1536
220.721	1532
223.247	1466
225.772	1524
228.295	1508
230.819	1480
233.342	1534
235.864	1580
238.384	1532
240.904	1508
243.423	1556
245.941	1512
248.46	1518
250.975	1518
253.492	1482
256.006	1514
258.519	1572
261.033	1548
263.545	1518
266.057	1466
268.567	1484
271.076	1516
273.585	1484
276.094	1504
278.601	1496
281.107	1536
283.612	1534
286.116	1550
288.62	1504
291.123	1524
293.625	1530
296.126	1524
298.626	1562
301.126	1530
303.625	1514
306.122	1556
308.62	1560
311.114	1558
313.61	1580
316.105	1582
318.599	1564
321.09	1516
323.583	1558
326.073	1538
328.563	1482
331.053	1550
333.541	1536
336.029	1520
338.515	1540
341.001	1600
343.486	1568
345.97	1600
348.453	1602
350.936	1590
353.418	1606
355.898	1610
358.378	1574
360.858	1556
363.336	1598
365.813	1564
368.29	1600
370.766	1608
373.241	1626
375.715	1562
378.188	1556
380.66	1570
383.132	1562
385.603	1600
388.072	1548
390.541	1598
393.01	1558
395.477	1520
397.943	1566
400.409	1606
402.875	1598
405.338	1628
407.802	1654
410.263	1612
412.725	1616
415.185	1640
417.646	1724
420.104	1668
422.564	1662
425.02	1710
427.477	1678
429.933	1714
432.388	1716
434.841	1694
437.294	1738
439.748	1704
442.199	1706
444.65	1718
447.1	1670
449.549	1708
451.997	1728
454.445	1762
456.891	1708
459.337	1728
461.782	1716
464.227	1712
466.669	1732
469.112	1714
471.554	1732
473.995	1738
476.434	1744
478.874	1742
481.312	1768
483.749	1756
486.186	1754
488.622	1806
491.057	1748
493.491	1784
495.925	1818
498.357	1818
500.789	1820
503.221	1828
505.65	1860
508.079	1794
510.509	1834
512.936	1778
515.363	1828
517.789	1872
520.214	1826
522.638	1812
525.062	1850
527.485	1886
529.907	1842
532.328	1882
534.748	1834
537.168	1876
539.587	1938
542.005	1846
544.423	1846
546.838	1904
549.254	1882
551.669	1884
554.082	1868
556.496	1976
558.909	1932
561.319	1906
563.731	1980
566.14	1998
568.549	1928
570.957	1970
573.364	2018
575.771	1998
578.177	2062
580.581	2032
582.987	2028
585.39	2072
587.792	2102
590.193	2118
592.594	2104
594.996	2024
597.395	2048
599.793	2162
602.191	2144
604.588	2128
606.984	2112
609.378	2120
611.773	2140
614.167	2182
616.56	2210
618.953	2228
621.343	2284
623.734	2244
626.124	2270
628.512	2320
630.901	2298
633.289	2316
635.675	2326
638.061	2330
640.446	2354
642.831	2384
645.213	2426
647.595	2456
649.978	2440
652.359	2510
654.738	2452
657.117	2488
659.497	2488
661.875	2534
664.252	2508
666.628	2584
669.003	2516
671.378	2596
673.751	2556
676.124	2532
678.497	2602
680.868	2674
683.239	2720
685.609	2610
687.977	2642
690.346	2696
692.714	2660
695.081	2722
697.446	2788
699.812	2784
702.175	2810
704.539	2876
706.901	2852
709.264	2804
711.625	2946
713.986	2876
716.345	2894
718.705	2946
721.062	2968
723.419	3012
725.775	3012
728.132	3050
730.487	3066
732.841	3038
735.194	3104
737.546	3172
739.898	3174
742.249	3204
744.599	3242
746.949	3246
749.298	3222
751.646	3248
753.993	3222
756.34	3246
758.684	3346
761.029	3304
763.374	3342
765.716	3420
768.059	3450
770.401	3482
772.741	3428
775.082	3432
777.421	3486
779.76	3498
782.097	3542
784.434	3564
786.771	3620
789.106	3586
791.44	3680
793.775	3690
796.108	3690
798.44	3786
800.771	3708
803.102	3840
805.432	3820
807.761	3826
810.09	3902
812.417	3920
814.744	4014
817.071	3996
819.396	4052
821.721	4096
824.045	4170
826.367	4106
828.69	4178
831.012	4132
833.332	4300
835.653	4278
837.972	4346
840.29	4310
842.609	4382
844.925	4314
847.242	4394
849.557	4392
851.871	4542
854.186	4466
856.498	4592
858.81	4558
861.122	4528
863.434	4748
865.744	4614
868.053	4662
870.361	4740
872.669	4722
874.976	4694
877.282	4794
879.588	4844
881.893	4808
884.197	4926
886.5	4878
888.802	4900
891.104	4888
893.405	4968
895.706	4952
898.004	4948
900.303	4972
902.6	5108
904.898	4962
907.194	5056
909.49	5132
911.785	5070
914.08	5136
916.372	5138
918.666	5212
920.957	5234
923.248	5122
925.538	5312
927.828	5288
930.118	5380
932.406	5390
934.693	5374
936.979	5450
939.265	5382
941.55	5402
943.835	5538
946.118	5580
948.401	5592
950.682	5582
952.964	5682
955.245	5662
957.525	5706
959.803	5718
962.082	5728
964.36	5718
966.636	5800
968.913	5900
971.188	5889
973.463	5914
975.736	5834
978.009	5948
980.282	5968
982.554	6034
984.824	6038
987.095	5978
989.364	5936
991.633	6034
993.9	5976
996.167	5976
998.434	6028
1000.7	6054
1002.96	6004
1005.23	6142
1007.49	6044
1009.76	6156
1012.02	6168
1014.28	6144
1016.54	6120
1018.8	6234
1021.06	6204
1023.32	6274
1025.57	6140
1027.83	6234
1030.09	6340
1032.34	6176
1034.6	6264
1036.85	6300
1039.1	6246
1041.35	6338
1043.61	6370
1045.86	6354
1048.11	6436
1050.36	6518
1052.61	6506
1054.85	6432
1057.1	6482
1059.35	6490
1061.59	6564
1063.84	6448
1066.08	6502
1068.33	6418
1070.57	6404
1072.81	6462
1075.05	6456
1077.29	6450
1079.53	6408
1081.77	6470
1084.01	6440
1086.25	6446
1088.48	6490
1090.72	6532
1092.96	6358
1095.19	6432
1097.43	6344
1099.66	6478
1101.89	6504
1104.12	6380
1106.35	6326
1108.59	6402
1110.81	6254
1113.04	6366
1115.27	6280
1117.5	6252
1119.73	6264
1121.95	6300
1124.18	6266
1126.4	6218
1128.63	6200
1130.85	6260
1133.07	6328
1135.29	6196
1137.51	6250
1139.73	6266
1141.95	6286
1144.17	6226
1146.39	6276
1148.61	6238
1150.82	6298
1153.04	6132
1155.26	6182
1157.47	6236
1159.68	6226
1161.9	6154
1164.11	6198
1166.32	6142
1168.53	6106
1170.74	6098
1172.95	6126
1175.16	6092
1177.37	5978
1179.58	6010
1181.78	5934
1183.99	5946
1186.19	5904
1188.4	5826
1190.6	5828
1192.8	5882
1195.01	5706
1197.21	5756.99
1199.41	5756.93
1201.61	5832.46
1203.81	5688.63
1206.01	5685.29
1208.2	5642.06
1210.4	5572.28
1212.6	5579.31
1214.8	5653.14
1216.99	5448.95
1219.18	5562.82
1221.38	5457.62
1223.57	5423.7
1225.76	5411.1
1227.96	5380.4
1230.15	5358.58
1232.34	5280.85
1234.53	5234.09
1236.71	5287.46
1238.9	5260.93
1241.09	5251.97
1243.28	5226.21
1245.46	5275.36
1247.65	5195.59
1249.83	5216.44
1252.02	5157.23
1254.2	5160.17
1256.38	5138.65
1258.56	5109.42
1260.74	5152.73
1262.92	5063.56
1265.1	5012.49
1267.28	5079.6
1269.46	5054.81
1271.64	5042.3
1273.82	5006.9
1275.99	4930.36
1278.17	4963.44
1280.34	4927.94
1282.52	4886.63
1284.69	4862.69
1286.86	4865.35
1289.03	4849.33
1291.21	4828.77
1293.38	4846.72
1295.55	4746.92
1297.71	4707.13
1299.88	4708.44
1302.05	4727.27
1304.22	4639.62
1306.38	4735.51
1308.43	4624
1310.61	4662
1312.78	4572
1314.96	4568
1317.13	4502
1319.3	4514
1321.48	4466
1323.65	4520
1325.82	4418
1327.99	4440
1330.16	4416
1332.33	4392
1334.5	4316
1336.66	4282
1338.83	4328
1341	4256
1343.16	4244
1345.33	4248
1347.49	4236
1349.65	4118
1351.82	4146
1353.98	4126
1356.14	4166
1358.3	4120
1360.46	3958
1362.62	4094
1364.78	4006
1366.94	4076
1369.09	4004
1371.25	4018
1373.41	3978
1375.56	3888
1377.72	3932
1379.87	3874
1382.02	3844
1384.17	3884
1386.33	3888
1388.48	3868
1390.63	3796
1392.78	3738
1394.93	3734
1397.07	3784
1399.22	3696
1401.37	3654
1403.52	3698
1405.66	3702
1407.81	3688
1409.95	3664
1412.09	3618
1414.24	3678
1416.38	3648
1418.52	3494
1420.66	3538
1422.8	3484
1424.94	3590
1427.08	3442
1429.22	3488
1431.35	3440
1433.49	3432
1435.63	3366
1437.76	3392
1439.9	3344
1442.03	3422
1444.17	3418
1446.3	3336
1448.43	3396
1450.56	3280
1452.69	3338
1454.82	3286
1456.95	3340
1459.08	3246
1461.21	3324
1463.34	3338
1465.46	3240
1467.59	3220
1469.71	3274
1471.84	3264
1473.96	3262
1476.08	3128
1478.21	3200
1480.33	3220
1482.45	3206
1484.57	3174
1486.69	3202
1488.81	3138
1490.93	3220
1493.05	3116
1495.16	3160
1497.28	3126
1499.4	3100
1501.51	3094
1503.63	3054
1505.74	3014
1507.85	3008
1509.97	3028
1512.08	3066
1514.19	2944
1516.3	2984
1518.41	2952
1520.52	2882
1522.63	2986
1524.73	2942
1526.84	2890
1528.95	2944
1531.06	2882
1533.16	2968
1535.26	2900
1537.37	2870
1539.47	2848
1541.57	2834
1543.68	2814
1545.78	2768
1547.88	2822
1549.98	2812
1552.08	2760
1554.18	2810
1556.27	2772
1558.37	2812
1560.47	2774
1562.56	2768
1564.66	2768
1566.75	2792
1568.85	2694
1570.94	2752
1573.03	2682
1575.13	2632
1577.22	2738
1579.31	2656
1581.4	2746
1583.49	2734
1585.58	2660
1587.66	2724
1589.75	2664
1591.84	2640
1593.93	2612
1596.01	2604
1598.1	2634
1600.18	2660
1602.26	2632
1604.35	2614
1606.43	2618
1608.51	2622
1610.59	2586
1612.67	2590
1614.75	2562
1616.83	2612
1618.91	2572
1620.99	2548
1623.06	2548
1625.14	2554
1627.21	2524
1629.29	2570
1631.36	2544
1633.44	2524
1635.51	2542
1637.58	2516
1639.66	2568
1641.73	2510
1643.8	2456
1645.87	2464
1647.94	2540
1650	2416
1652.07	2446
1654.14	2504
1656.21	2476
1658.27	2480
1660.34	2446
1662.4	2428
1664.47	2400
1666.53	2420
1668.59	2404
1670.66	2406
1672.72	2396
1674.78	2354
1676.84	2414
1678.9	2382
1680.96	2330
1683.01	2358
1685.07	2322
1687.13	2372
1689.19	2384
1691.24	2356
1693.3	2288
1695.35	2354
1697.4	2330
1699.46	2316
1701.51	2278
1703.56	2266
1705.61	2240
1707.66	2246
1709.71	2254
1711.76	2290
1713.81	2304
1715.86	2248
1717.91	2244
1719.95	2246
1722	2268
1724.04	2234
1726.09	2210
1728.13	2236
1730.18	2180
1732.22	2166
1734.26	2180
1736.3	2164
1738.34	2176
1740.38	2192
1742.42	2178
1744.46	2150
1746.5	2194
1748.54	2178
1750.58	2172
1752.61	2132
1754.65	2166
1756.68	2162
1758.72	2172
1760.75	2140
1762.79	2216
1764.82	2162
1766.85	2154
1768.88	2152
1770.91	2140
1772.94	2122
1774.97	2190
1777	2170
1779.03	2102
1781.06	2142
1783.09	2098
1785.11	2146
1787.14	2086
1789.16	2134
1791.19	2076
1793.21	2068
1795.23	2024
1797.26	2108
1799.28	2076
1801.3	2082
1803.32	2094
1805.34	2054
1807.36	2092
1809.38	2062
1811.4	2088
1813.42	2100
1815.43	2048
1817.45	1984
1819.47	2032
1821.48	2040
1823.49	1996
1825.51	2072
1827.52	2032
1829.54	2032
1831.55	1952
1833.56	1954
1835.57	2038
1837.58	2026
1839.59	1930
1841.6	1984
1843.61	1994
1845.61	2000
1847.62	1978
1849.63	2030
1851.63	1952
1853.64	1960
1855.64	1914
1857.65	1932
1859.65	1980
1861.65	1930
1863.65	1950
1865.66	1916
1867.66	1896
1869.66	1944
1871.66	1940
1873.66	1912
1875.65	1888
1877.65	1950
1879.65	1944
1881.65	1920
1883.64	1910
1885.64	1958
1887.63	1836
1889.63	1860
1891.62	1964
1893.61	1870
1895.6	1896
1897.6	1888
1899.59	1876
1901.58	1924
1903.57	1916
1905.56	1884
1907.54	1840
1909.53	1870
1911.52	1894
1913.51	1822
1915.49	1900
1917.48	1886
1919.46	1860
1921.45	1830
1923.43	1864
1925.41	1840
1927.4	1834
1929.38	1876
1931.36	1812
1933.34	1850
1935.32	1812
1937.3	1872
1939.28	1858
1941.26	1834
1943.23	1826
1945.21	1814
1947.19	1854
1949.16	1790
1951.14	1836
1953.11	1844
1955.09	1782
1957.06	1790
1959.03	1822
1961	1850
1962.98	1800
1964.95	1790
1966.92	1754
1968.89	1800
1970.85	1800
1972.82	1770
1974.79	1836
1976.76	1784
1978.73	1784
1980.69	1758
1982.66	1772
1984.62	1802
1986.59	1764
1988.55	1788
1990.51	1740
1992.47	1826
1994.44	1786
1996.4	1786
1998.36	1710
2000.32	1758
2002.28	1740
2004.24	1734
2006.19	1752
2008.15	1786
2010.11	1746
2012.06	1792
2014.02	1784
2015.98	1698
2017.93	1760
2019.88	1744
2021.84	1718
2023.79	1714
2025.74	1712
2027.69	1718
2029.65	1730
2031.6	1758
2033.55	1728
2035.5	1718
2037.44	1748
2039.39	1672
2041.34	1684
2043.29	1718
2045.23	1726
2047.18	1710
2049.12	1708
2051.07	1682
2053.01	1714
2054.95	1718
2056.9	1694
2058.84	1630
2060.78	1678
2062.72	1726
2064.66	1644
2066.6	1640
2068.54	1710
2070.48	1694
2072.42	1732
2074.35	1714
2076.29	1676
2078.23	1670
2080.16	1710
2082.1	1652
2084.03	1676
2085.96	1664
2087.9	1666
2089.83	1616
2091.76	1650
2093.69	1666
2095.62	1652
2097.55	1636
2099.48	1608
2101.41	1606
2103.34	1648
2105.27	1636
2107.2	1628
2109.12	1650
2111.05	1664
2112.98	1626
2114.9	1594
2116.82	1670
2118.75	1634
2120.67	1586
2122.59	1634
2124.52	1592
2126.44	1622
2128.36	1608
2130.28	1638
2132.2	1580
2134.12	1592
2136.04	1610
2137.95	1620
2139.87	1624
2141.79	1598
2143.7	1634
2145.62	1635.57
2147.53	1562.28
2149.45	1591.68
2151.36	1575.81
2153.28	1574.32
2155.19	1622.42
2157.1	1538.25
2159.01	1552.5
2160.92	1576.35
2162.83	1562.57
2164.74	1536.76
2166.65	1565.98
2168.56	1514.52
2170.47	1560.35
2172.38	1572.03
2174.28	1498.25
2176.19	1548.92
2178.09	1570.09
2180	1532.45
2181.9	1545.33
2183.81	1525.14
2185.71	1530.29
2187.61	1525.63
2189.52	1517.27
2191.42	1506.61
2193.32	1525.91
2195.22	1487.88
2197.12	1534.96
2199.02	1514.78
2200.92	1486.77
2202.82	1494.35
2204.71	1525.94
2206.61	1520.45
2208.51	1506.18
2210.4	1457.58
2212.3	1500.08
2214.19	1509.14
2216.09	1507.88
2217.98	1488.07
2219.87	1468.47
2221.77	1499.41
2223.66	1495.93
2225.55	1461.55
2227.44	1489.17
2229.33	1485.03
2231.22	1496.29
2233.11	1519.33
2235	1491.33
2236.88	1515.81
2238.77	1484.42
2240.66	1452.19
2242.07	1480
2243.97	1480
2245.87	1520
2247.76	1446
2249.65	1454
2251.55	1462
2253.44	1472
2255.33	1502
2257.22	1444
2259.12	1468
2261.01	1452
2262.9	1500
2264.78	1452
2266.67	1492
2268.56	1472
2270.45	1412
2272.34	1420
2274.22	1410
2276.11	1450
2277.99	1446
2279.88	1418
2281.76	1424
2283.65	1448
2285.53	1470
2287.41	1414
2289.3	1438
2291.18	1484
2293.06	1414
2294.94	1428
2296.82	1408
2298.7	1380
2300.58	1442
2302.46	1418
2304.33	1448
2306.21	1348
2308.09	1416
2309.96	1424
2311.84	1390
2313.71	1360
2315.59	1380
2317.46	1360
2319.33	1346
2321.21	1394
2323.08	1354
2324.95	1368
2326.82	1330
2328.69	1342
2330.56	1382
2332.43	1358
2334.3	1376
2336.17	1408
2338.03	1322
2339.9	1362
2341.77	1390
2343.63	1356
2345.5	1330
2347.36	1350
2349.23	1376
2351.09	1344
2352.95	1330
2354.82	1316
2356.68	1294
2358.54	1318
2360.4	1346
2362.26	1354
2364.12	1320
2365.98	1308
2367.84	1354
2369.7	1324
2371.56	1304
2373.41	1326
2375.27	1328
2377.12	1330
2378.98	1302
2380.84	1300
2382.69	1352
2384.54	1282
2386.4	1340
2388.25	1234
2390.1	1284
2391.95	1288
2393.8	1274
2395.65	1242
2397.5	1298
2399.35	1282
2401.2	1300
2403.05	1290
2404.9	1260
2406.75	1288
2408.59	1284
2410.44	1250
2412.28	1268
2414.13	1256
2415.97	1222
2417.82	1256
2419.66	1244
2421.5	1194
2423.35	1252
2425.19	1246
2427.03	1170
2428.87	1192
2430.71	1188
2432.55	1196
2434.39	1190
2436.23	1208
2438.06	1232
2439.9	1188
2441.74	1194
2443.57	1192
2445.41	1260
2447.24	1184
2449.08	1200
2450.91	1182
2452.75	1120
2454.58	1174
2456.41	1206
2458.24	1220
2460.08	1198
2461.91	1184
2463.74	1180
2465.57	1220
2467.4	1122
2469.22	1170
2471.05	1170
2472.88	1134
2474.71	1182
2476.53	1128
2478.36	1148
2480.19	1098
2482.01	1134
2483.83	1142
2485.66	1082
2487.48	1146
2489.3	1088
2491.13	1136
2492.95	1134
2494.77	1102
2496.59	1134
2498.41	1104
2500.23	1104
2502.05	1074
2503.87	1068
2505.68	1068
2507.5	1096
2509.32	1080
2511.14	1006
2512.95	1060
2514.77	1066
2516.58	1040
2518.39	1084
2520.21	1076
2522.02	1038
2523.83	1090
2525.65	1070
2527.46	1052
2529.27	1036
2531.08	1032
2532.89	1034
2534.7	1060
2536.51	1006
2538.32	1004
2540.12	1038
2541.93	1030
2543.74	988
2545.54	1094
2547.35	1020
2549.15	1024
2550.96	1002
2552.76	990
2554.56	1004
2556.37	1036
2558.17	986
2559.97	1008
2561.77	970
2563.58	938
2565.38	988
2567.18	956
2568.97	990
2570.77	978
2572.57	972
2574.37	960
2576.17	962
2577.96	980
2579.76	968
2581.55	944
2583.35	974
2585.14	930
2586.94	954
2588.73	934
2590.52	920
2592.32	958
2594.11	908
2595.9	900
2597.69	938
2599.48	948
2601.27	910
2603.06	914
2604.85	896
2606.64	922
2608.42	926
2610.21	876
2612	902
2613.78	916
2615.57	902
2617.36	868
2619.14	904
2620.92	914
2622.71	858
2624.49	888
2626.27	908
2628.05	874
2629.84	880
2631.62	864
2633.4	852
2635.18	880
2636.96	850
2638.74	862
2640.51	818
2642.29	830
2644.07	858
2645.85	836
2647.62	818
2649.4	846
2651.17	856
2652.95	852
2654.72	830
2656.5	814
2658.27	792
2660.04	836
2661.81	832
2663.58	852
2665.35	822
2667.13	806
2668.9	806
2670.66	822
2672.43	820
2674.2	858
2675.97	776
2677.74	810
2679.5	772
2681.27	802
2683.04	752
2684.8	810
2686.57	820
2688.33	764
2690.09	772
2691.86	804
2693.62	772
2695.38	756
2697.15	768
2698.91	788
2700.67	762
2702.43	786
2704.19	766
2705.95	758
2707.7	774
2709.46	774
2711.22	768
2712.98	754
2714.73	748
2716.49	772
2718.25	752
2720	772
2721.76	742
2723.51	708
2725.26	756
2727.02	774
2728.77	744
2730.52	708
2732.27	754
2734.02	708
2735.77	732
2737.52	736
2739.27	686
2741.02	726
2742.77	722
2744.52	708
2746.27	684
2748.01	700
2749.76	742
2751.51	698
2753.25	694
2755	706
2756.74	678
2758.48	650
2760.23	672
2761.97	684
2763.71	696
2765.45	668
2767.19	692
2768.94	664
2770.68	658
2772.42	640
2774.16	658
2775.89	684
2777.63	652
2779.37	644
2781.11	660
2782.84	668
2784.58	684
2786.32	660
2788.05	676
2789.79	640
2791.52	658
2793.25	628
2794.99	636
2796.72	630
2798.45	626
2800.18	624
2801.92	632
2803.65	640
2805.38	604
2807.11	604
2808.84	624
2810.57	634
2812.29	614
2814.02	638
2815.75	608
2817.47	596
2819.2	604
2820.93	618
2822.65	584
2824.38	620
2826.1	574
2827.82	622
2829.55	634
2831.27	616
2832.99	612
2834.71	598
2836.44	616
2838.16	592
2839.88	594
2841.6	604
2843.32	570
2845.03	564
2846.75	598
2848.47	562
2850.19	580
2851.9	568
2853.62	572
2855.34	582
2857.05	564
2858.77	576
2860.48	580
2862.19	572
2863.91	582
2865.62	534
2867.33	546
2869.04	544
2870.76	548
2872.47	556
2874.18	564
2875.89	524
2877.6	512
2879.31	536
2881.01	538
2882.72	518
2884.43	540
2886.14	558
2887.84	516
2889.55	520
2891.25	560
2892.96	546
2894.66	504
2896.37	506
2898.07	516
2899.77	522
2901.48	526
2903.18	538
2904.88	484
2906.58	498
2908.28	512
2909.98	504
2911.68	496
2913.38	528
2915.08	514
2916.78	500
2918.47	484
2920.17	508
2921.87	502
2923.56	510
2925.26	528
2926.95	540
2928.65	522
2930.34	516
2932.04	492
2933.73	510
2935.42	530
2937.11	502
2938.81	480
2940.5	462
2942.19	490
2943.88	472
2945.57	486
2947.26	478
2948.95	492
2950.64	488
2952.32	502
2954.01	492
2955.7	454
2957.38	486
2959.07	494
2960.75	490
2962.44	492
2964.12	458
2965.81	482
2967.49	492
2969.17	484
2970.86	432
2972.54	474
2974.22	464
2975.9	452
2977.58	458
2979.26	434
2980.94	470
2982.62	442
2984.3	432
2985.98	442
2987.66	446
2989.33	432
2991.01	462
2992.69	446
2994.36	440
2996.04	434
2997.71	418
2999.39	428