File: muestras/tallo/1/Organic_05.txt
#Acq. time (s)=	10
#Accumulations=	1
#Range (cm-¹)=	100...3000
#Windows=	3
#Autofocus=	Off
#AutoExposure=	Off
#Spike filter=	Off
#Delay time (s)=	0
#Binning=	1
#Readout mode=	Signal
#DeNoise=	Off
#ICS correction=	Off
#Dark correction=	Off
#Inst. Process=	Off
#Instrument=	LabRAM HR Evol
#Detector=	Syncerity OE
#Objective=	x100_VIS
#Grating=	600 (500nm)
#ND Filter=	5%
#Laser=	633nm_Edge
#Hole=	74.97
#Range=	Visible
#Project=	Omar
#Sample=	26-06-23
#Site=	1
#Title=	Organic
#Remark=
#Date=	26.06.2023 15:53
#Acquired=	26.06.2023 15:53:15
101.018	2236
103.586	2232
106.152	2206
108.717	2228
111.281	2188
113.845	2206
116.407	2188
118.969	2264
121.53	2232
124.09	2190
126.649	2236
129.207	2230
131.765	2186
134.321	2218
136.877	2248
139.432	2234
141.985	2208
144.538	2204
147.09	2198
149.641	2218
152.191	2250
154.741	2222
157.289	2180
159.837	2224
162.385	2178
164.93	2196
167.476	2222
170.019	2216
172.562	2204
175.105	2224
177.646	2186
180.188	2248
182.727	2202
185.266	2212
187.804	2156
190.342	2202
192.878	2176
195.413	2150
197.948	2230
200.481	2190
203.014	2248
205.546	2224
208.077	2210
210.608	2206
213.137	2272
215.666	2142
218.194	2196
220.721	2210
223.247	2232
225.772	2218
228.295	2176
230.819	2198
233.342	2292
235.864	2274
238.384	2316
240.904	2298
243.423	2246
245.941	2310
248.46	2228
250.975	2242
253.492	2300
256.006	2270
258.519	2202
261.033	2286
263.545	2252
266.057	2210
268.567	2242
271.076	2234
273.585	2256
276.094	2214
278.601	2260
281.107	2252
283.612	2284
286.116	2234
288.62	2240
291.123	2310
293.625	2284
296.126	2292
298.626	2304
301.126	2304
303.625	2316
306.122	2326
308.62	2314
311.114	2316
313.61	2300
316.105	2246
318.599	2330
321.09	2332
323.583	2302
326.073	2354
328.563	2366
331.053	2286
333.541	2286
336.029	2266
338.515	2326
341.001	2306
343.486	2374
345.97	2352
348.453	2358
350.936	2352
353.418	2352
355.898	2346
358.378	2348
360.858	2344
363.336	2376
365.813	2348
368.29	2362
370.766	2404
373.241	2396
375.715	2378
378.188	2344
380.66	2328
383.132	2342
385.603	2374
388.072	2354
390.541	2370
393.01	2392
395.477	2408
397.943	2340
400.409	2322
402.875	2424
405.338	2416
407.802	2412
410.263	2476
412.725	2520
415.185	2432
417.646	2510
420.104	2476
422.564	2460
425.02	2556
427.477	2516
429.933	2570
432.388	2574
434.841	2570
437.294	2542
439.748	2528
442.199	2556
444.65	2588
447.1	2540
449.549	2626
451.997	2570
454.445	2556
456.891	2606
459.337	2604
461.782	2596
464.227	2580
466.669	2592
469.112	2590
471.554	2596
473.995	2668
476.434	2630
478.874	2746
481.312	2614
483.749	2670
486.186	2610
488.622	2642
491.057	2680
493.491	2800
495.925	2798
498.357	2750
500.789	2798
503.221	2826
505.65	2768
508.079	2784
510.509	2804
512.936	2816
515.363	2846
517.789	2804
520.214	2814
522.638	2866
525.062	2868
527.485	2790
529.907	2846
532.328	2946
534.748	2882
537.168	2856
539.587	2920
542.005	2896
544.423	2904
546.838	3006
549.254	2954
551.669	2974
554.082	2930
556.496	3008
558.909	2988
561.319	3042
563.731	3044
566.14	3054
568.549	3044
570.957	3118
573.364	3088
575.771	3064
578.177	3218
580.581	3150
582.987	3186
585.39	3178
587.792	3236
590.193	3256
592.594	3246
594.996	3302
597.395	3356
599.793	3360
602.191	3304
604.588	3422
606.984	3388
609.378	3414
611.773	3406
614.167	3546
616.56	3572
618.953	3606
621.343	3662
623.734	3680
626.124	3702
628.512	3670
630.901	3744
633.289	3822
635.675	3772
638.061	3780
640.446	3896
642.831	3924
645.213	3904
647.595	3964
649.978	3964
652.359	4082
654.738	4104
657.117	4072
659.497	4074
661.875	4174
664.252	4236
666.628	4188
669.003	4168
671.378	4206
673.751	4260
676.124	4298
678.497	4348
680.868	4434
683.239	4456
685.609	4476
687.977	4566
690.346	4486
692.714	4600
695.081	4618
697.446	4668
699.812	4656
702.175	4682
704.539	4792
706.901	4746
709.264	4810
711.625	4896
713.986	4938
716.345	5044
718.705	5082
721.062	5024
723.419	5108
725.775	5160
728.132	5230
730.487	5270
732.841	5330
735.194	5400
737.546	5404
739.898	5466
742.249	5452
744.599	5610
746.949	5588
749.298	5630
751.646	5596
753.993	5690
756.34	5734
758.684	5760
761.029	5904
763.374	5834
765.716	5902
768.059	6034
770.401	5966
772.741	6084
775.082	6192
777.421	6110
779.76	6198
782.097	6330
784.434	6350
786.771	6404
789.106	6442
791.44	6482
793.775	6496
796.108	6540
798.44	6678
800.771	6714
803.102	6848
805.432	6936
807.761	6882
810.09	6984
812.417	7114
814.744	7138
817.071	7146
819.396	7290
821.721	7264
824.045	7322
826.367	7516
828.69	7586
831.012	7496
833.332	7690
835.653	7582
837.972	7758
840.29	7884
842.609	7920
844.925	8024
847.242	8114
849.557	8160
851.871	8106
854.186	8134
856.498	8266
858.81	8314
861.122	8386
863.434	8408
865.744	8520
868.053	8592
870.361	8596
872.669	8672
874.976	8654
877.282	8784
879.588	8804
881.893	8868
884.197	8912
886.5	8860
888.802	9028
891.104	9022
893.405	9004
895.706	9036
898.004	9184
900.303	9272
902.6	9280
904.898	9198
907.194	9324
909.49	9340
911.785	9382
914.08	9370
916.372	9548
918.666	9452
920.957	9598
923.248	9656
925.538	9826
927.828	9782
930.118	9740
932.406	9774
934.693	10032
936.979	9972
939.265	10020
941.55	10120
943.835	10044
946.118	10154
948.401	10304
950.682	10308
952.964	10360
955.245	10322
957.525	10452
959.803	10350
962.082	10518
964.36	10650
966.636	10678
968.913	10568
971.188	10686
973.463	10752
975.736	10722
978.009	10742
980.282	10856
982.554	10894
984.824	10812
987.095	10846
989.364	10846
991.633	10958
993.9	10982
996.167	10984
998.434	11154
1000.7	11028
1002.96	11006
1005.23	11004
1007.49	11176
1009.76	11084
1012.02	11180
1014.28	11272
1016.54	11074
1018.8	11254
1021.06	11214
1023.32	11312
1025.57	11334
1027.83	11260
1030.09	11334
1032.34	11444
1034.6	11426
1036.85	11380
1039.1	11470
1041.35	11484
1043.61	11486
1045.86	11696
1048.11	11556
1050.36	11756
1052.61	11534
1054.85	11536
1057.1	11610
1059.35	11674
1061.59	11612
1063.84	11730
1066.08	11680
1068.33	11606
1070.57	11590
1072.81	11636
1075.05	11700
1077.29	11576
1079.53	11638
1081.77	11502
1084.01	11436
1086.25	11464
1088.48	11528
1090.72	11380
1092.96	11292
1095.19	11470
1097.43	11424
1099.66	11328
1101.89	11298
1104.12	11372
1106.35	11254
1108.59	11208
1110.81	11204
1113.04	11030
1115.27	11186
1117.5	11138
1119.73	11086
1121.95	11216
1124.18	11024
1126.4	11070
1128.63	11076
1130.85	11010
1133.07	11006
1135.29	10956
1137.51	10934
1139.73	11004
1141.95	10848
1144.17	10938
1146.39	10848
1148.61	10960
1150.82	10902
1153.04	10858
1155.26	10832
1157.47	10786
1159.68	10822
1161.9	10684
1164.11	10642
1166.32	10590
1168.53	10664
1170.74	10578
1172.95	10474
1175.16	10522
1177.37	10540
1179.58	10398
1181.78	10230
1183.99	10318
1186.19	10264
1188.4	10258
1190.6	10044
1192.8	10142
1195.01	9922
1197.21	9963.59
1199.41	9817.05
1201.61	9889.43
1203.81	9786.35
1206.01	9672.34
1208.2	9641.92
1210.4	9515.47
1212.6	9530.3
1214.8	9511.64
1216.99	9452.03
1219.18	9419.11
1221.38	9270.59
1223.57	9226.15
1225.76	9207.93
1227.96	9169.75
1230.15	9138.69
1232.34	9097.48
1234.53	9086.18
1236.71	8960.11
1238.9	8964.3
1241.09	8943.2
1243.28	8830
1245.46	8770.69
1247.65	8788.79
1249.83	8719.37
1252.02	8758.71
1254.2	8740.27
1256.38	8673.99
1258.56	8605.87
1260.74	8609.95
1262.92	8532.61
1265.1	8489.34
1267.28	8445.93
1269.46	8389.04
1271.64	8327
1273.82	8376.05
1275.99	8227.54
1278.17	8234.64
1280.34	8261.78
1282.52	8117.05
1284.69	8084.95
1286.86	8041.9
1289.03	8122.11
1291.21	7958.79
1293.38	7966.63
1295.55	7911
1297.71	7978.59
1299.88	7850.48
1302.05	7782.33
1304.22	7711.52
1306.38	7694.58
1308.43	7664
1310.61	7632
1312.78	7636
1314.96	7532
1317.13	7402
1319.3	7416
1321.48	7308
1323.65	7284
1325.82	7208
1327.99	7196
1330.16	7210
1332.33	7096
1334.5	7080
1336.66	6908
1338.83	7076
1341	6880
1343.16	6914
1345.33	6926
1347.49	6790
1349.65	6798
1351.82	6680
1353.98	6674
1356.14	6690
1358.3	6544
1360.46	6488
1362.62	6564
1364.78	6452
1366.94	6510
1369.09	6362
1371.25	6456
1373.41	6404
1375.56	6252
1377.72	6396
1379.87	6264
1382.02	6180
1384.17	6170
1386.33	6134
1388.48	6106
1390.63	6078
1392.78	6064
1394.93	5908
1397.07	5918
1399.22	5940
1401.37	5920
1403.52	5952
1405.66	5864
1407.81	5806
1409.95	5818
1412.09	5752
1414.24	5702
1416.38	5708
1418.52	5672
1420.66	5662
1422.8	5634
1424.94	5600
1427.08	5560
1429.22	5502
1431.35	5456
1433.49	5446
1435.63	5404
1437.76	5346
1439.9	5426
1442.03	5362
1444.17	5340
1446.3	5460
1448.43	5334
1450.56	5280
1452.69	5242
1454.82	5280
1456.95	5280
1459.08	5252
1461.21	5182
1463.34	5152
1465.46	5110
1467.59	5090
1469.71	4994
1471.84	5098
1473.96	5074
1476.08	5076
1478.21	5060
1480.33	5050
1482.45	4964
1484.57	4978
1486.69	4994
1488.81	4932
1490.93	4920
1493.05	4852
1495.16	4860
1497.28	4954
1499.4	4858
1501.51	4778
1503.63	4752
1505.74	4794
1507.85	4704
1509.97	4826
1512.08	4700
1514.19	4550
1516.3	4654
1518.41	4668
1520.52	4636
1522.63	4618
1524.73	4548
1526.84	4524
1528.95	4616
1531.06	4458
1533.16	4406
1535.26	4422
1537.37	4466
1539.47	4360
1541.57	4362
1543.68	4354
1545.78	4464
1547.88	4352
1549.98	4316
1552.08	4346
1554.18	4282
1556.27	4198
1558.37	4342
1560.47	4220
1562.56	4236
1564.66	4216
1566.75	4188
1568.85	4246
1570.94	4192
1573.03	4166
1575.13	4134
1577.22	4094
1579.31	4164
1581.4	4110
1583.49	4138
1585.58	4138
1587.66	4120
1589.75	4072
1591.84	4038
1593.93	4082
1596.01	4010
1598.1	4104
1600.18	4020
1602.26	4024
1604.35	4068
1606.43	4016
1608.51	4022
1610.59	3950
1612.67	3974
1614.75	4048
1616.83	3952
1618.91	3960
1620.99	3948
1623.06	3974
1625.14	3930
1627.21	3876
1629.29	3918
1631.36	3892
1633.44	3942
1635.51	3842
1637.58	3846
1639.66	3842
1641.73	3832
1643.8	3832
1645.87	3894
1647.94	3808
1650	3844
1652.07	3808
1654.14	3754
1656.21	3774
1658.27	3756
1660.34	3642
1662.4	3724
1664.47	3746
1666.53	3730
1668.59	3758
1670.66	3708
1672.72	3642
1674.78	3664
1676.84	3696
1678.9	3638
1680.96	3664
1683.01	3658
1685.07	3610
1687.13	3616
1689.19	3570
1691.24	3566
1693.3	3496
1695.35	3506
1697.4	3560
1699.46	3614
1701.51	3558
1703.56	3496
1705.61	3426
1707.66	3534
1709.71	3454
1711.76	3414
1713.81	3434
1715.86	3480
1717.91	3366
1719.95	3328
1722	3448
1724.04	3502
1726.09	3426
1728.13	3384
1730.18	3334
1732.22	3390
1734.26	3446
1736.3	3402
1738.34	3432
1740.38	3432
1742.42	3372
1744.46	3328
1746.5	3368
1748.54	3356
1750.58	3288
1752.61	3312
1754.65	3380
1756.68	3262
1758.72	3376
1760.75	3298
1762.79	3292
1764.82	3276
1766.85	3270
1768.88	3246
1770.91	3312
1772.94	3270
1774.97	3272
1777	3316
1779.03	3280
1781.06	3246
1783.09	3250
1785.11	3258
1787.14	3226
1789.16	3316
1791.19	3256
1793.21	3234
1795.23	3252
1797.26	3238
1799.28	3246
1801.3	3228
1803.32	3186
1805.34	3166
1807.36	3194
1809.38	3140
1811.4	3194
1813.42	3164
1815.43	3144
1817.45	3094
1819.47	3194
1821.48	3104
1823.49	3166
1825.51	3088
1827.52	3168
1829.54	3090
1831.55	3144
1833.56	3080
1835.57	3030
1837.58	3120
1839.59	3126
1841.6	3090
1843.61	3102
1845.61	3072
1847.62	3028
1849.63	3044
1851.63	3052
1853.64	3034
1855.64	3050
1857.65	3024
1859.65	2998
1861.65	3010
1863.65	3020
1865.66	3004
1867.66	3000
1869.66	2980
1871.66	2964
1873.66	3036
1875.65	2914
1877.65	2948
1879.65	2956
1881.65	2994
1883.64	2994
1885.64	2950
1887.63	2902
1889.63	2990
1891.62	2976
1893.61	2906
1895.6	2924
1897.6	2870
1899.59	2984
1901.58	2884
1903.57	2918
1905.56	2900
1907.54	2924
1909.53	2972
1911.52	2832
1913.51	2892
1915.49	2920
1917.48	2882
1919.46	2850
1921.45	2872
1923.43	2934
1925.41	2996
1927.4	2850
1929.38	2876
1931.36	2904
1933.34	2840
1935.32	2870
1937.3	2888
1939.28	2832
1941.26	2832
1943.23	2864
1945.21	2830
1947.19	2886
1949.16	2866
1951.14	2812
1953.11	2880
1955.09	2796
1957.06	2848
1959.03	2830
1961	2852
1962.98	2800
1964.95	2796
1966.92	2792
1968.89	2734
1970.85	2796
1972.82	2856
1974.79	2780
1976.76	2728
1978.73	2754
1980.69	2794
1982.66	2828
1984.62	2742
1986.59	2744
1988.55	2824
1990.51	2762
1992.47	2720
1994.44	2856
1996.4	2784
1998.36	2744
2000.32	2760
2002.28	2724
2004.24	2672
2006.19	2752
2008.15	2756
2010.11	2792
2012.06	2746
2014.02	2816
2015.98	2784
2017.93	2750
2019.88	2752
2021.84	2716
2023.79	2800
2025.74	2692
2027.69	2728
2029.65	2736
2031.6	2682
2033.55	2714
2035.5	2734
2037.44	2694
2039.39	2710
2041.34	2688
2043.29	2716
2045.23	2644
2047.18	2724
2049.12	2672
2051.07	2694
2053.01	2704
2054.95	2762
2056.9	2644
2058.84	2686
2060.78	2652
2062.72	2658
2064.66	2604
2066.6	2664
2068.54	2690
2070.48	2646
2072.42	2610
2074.35	2640
2076.29	2610
2078.23	2582
2080.16	2626
2082.1	2644
2084.03	2620
2085.96	2594
2087.9	2638
2089.83	2594
2091.76	2622
2093.69	2632
2095.62	2648
2097.55	2650
2099.48	2586
2101.41	2668
2103.34	2634
2105.27	2594
2107.2	2600
2109.12	2586
2111.05	2608
2112.98	2566
2114.9	2588
2116.82	2544
2118.75	2614
2120.67	2584
2122.59	2586
2124.52	2502
2126.44	2608
2128.36	2578
2130.28	2582
2132.2	2574
2134.12	2536
2136.04	2526
2137.95	2542
2139.87	2490
2141.79	2560
2143.7	2556
2145.62	2515.66
2147.53	2516.78
2149.45	2509.8
2151.36	2517.5
2153.28	2496.59
2155.19	2454.44
2157.1	2526.04
2159.01	2515.07
2160.92	2468.52
2162.83	2459.6
2164.74	2473.38
2166.65	2473.62
2168.56	2405.18
2170.47	2445.68
2172.38	2461.02
2174.28	2461.26
2176.19	2444.61
2178.09	2405.6
2180	2416.35
2181.9	2381.45
2183.81	2444.47
2185.71	2409.29
2187.61	2404.11
2189.52	2423.26
2191.42	2412.81
2193.32	2391.68
2195.22	2409.07
2197.12	2388.54
2199.02	2376.16
2200.92	2400.74
2202.82	2367.31
2204.71	2397.42
2206.61	2416.57
2208.51	2404.54
2210.4	2406.48
2212.3	2382.93
2214.19	2376.82
2216.09	2353.93
2217.98	2374
2219.87	2384.91
2221.77	2348.89
2223.66	2378.8
2225.55	2353.6
2227.44	2372.49
2229.33	2311.25
2231.22	2399.89
2233.11	2359.73
2235	2380.31
2236.88	2340.67
2238.77	2342.23
2240.66	2343.64
2242.07	2366
2243.97	2396
2245.87	2378
2247.76	2292
2249.65	2326
2251.55	2340
2253.44	2310
2255.33	2334
2257.22	2378
2259.12	2382
2261.01	2288
2262.9	2298
2264.78	2236
2266.67	2334
2268.56	2314
2270.45	2312
2272.34	2292
2274.22	2340
2276.11	2282
2277.99	2240
2279.88	2286
2281.76	2300
2283.65	2320
2285.53	2286
2287.41	2314
2289.3	2298
2291.18	2252
2293.06	2236
2294.94	2268
2296.82	2266
2298.7	2240
2300.58	2238
2302.46	2210
2304.33	2276
2306.21	2224
2308.09	2240
2309.96	2218
2311.84	2216
2313.71	2274
2315.59	2236
2317.46	2168
2319.33	2176
2321.21	2182
2323.08	2186
2324.95	2148
2326.82	2130
2328.69	2140
2330.56	2112
2332.43	2204
2334.3	2164
2336.17	2092
2338.03	2122
2339.9	2112
2341.77	2168
2343.63	2142
2345.5	2084
2347.36	2120
2349.23	2066
2351.09	2060
2352.95	2098
2354.82	2106
2356.68	2160
2358.54	2058
2360.4	2068
2362.26	2044
2364.12	2090
2365.98	2036
2367.84	2042
2369.7	2016
2371.56	2018
2373.41	2034
2375.27	2004
2377.12	2090
2378.98	2080
2380.84	2052
2382.69	2056
2384.54	2058
2386.4	2018
2388.25	2062
2390.1	1948
2391.95	1978
2393.8	2038
2395.65	1980
2397.5	1988
2399.35	2006
2401.2	2006
2403.05	1978
2404.9	1988
2406.75	1976
2408.59	1942
2410.44	1956
2412.28	1938
2414.13	1964
2415.97	1906
2417.82	1912
2419.66	1918
2421.5	1902
2423.35	1934
2425.19	1926
2427.03	1904
2428.87	1922
2430.71	1886
2432.55	1868
2434.39	1930
2436.23	1888
2438.06	1864
2439.9	1862
2441.74	1822
2443.57	1866
2445.41	1868
2447.24	1878
2449.08	1884
2450.91	1860
2452.75	1822
2454.58	1830
2456.41	1814
2458.24	1844
2460.08	1836
2461.91	1826
2463.74	1816
2465.57	1734
2467.4	1738
2469.22	1750
2471.05	1774
2472.88	1774
2474.71	1770
2476.53	1804
2478.36	1782
2480.19	1812
2482.01	1744
2483.83	1712
2485.66	1772
2487.48	1738
2489.3	1716
2491.13	1728
2492.95	1696
2494.77	1746
2496.59	1712
2498.41	1740
2500.23	1702
2502.05	1702
2503.87	1672
2505.68	1666
2507.5	1686
2509.32	1658
2511.14	1674
2512.95	1636
2514.77	1688
2516.58	1646
2518.39	1696
2520.21	1610
2522.02	1620
2523.83	1608
2525.65	1636
2527.46	1626
2529.27	1538
2531.08	1632
2532.89	1634
2534.7	1544
2536.51	1554
2538.32	1556
2540.12	1584
2541.93	1556
2543.74	1600
2545.54	1572
2547.35	1540
2549.15	1536
2550.96	1520
2552.76	1538
2554.56	1512
2556.37	1530
2558.17	1536
2559.97	1504
2561.77	1516
2563.58	1528
2565.38	1486
2567.18	1520
2568.97	1490
2570.77	1498
2572.57	1496
2574.37	1474
2576.17	1416
2577.96	1456
2579.76	1460
2581.55	1462
2583.35	1452
2585.14	1424
2586.94	1430
2588.73	1472
2590.52	1406
2592.32	1458
2594.11	1404
2595.9	1372
2597.69	1400
2599.48	1392
2601.27	1384
2603.06	1376
2604.85	1404
2606.64	1348
2608.42	1398
2610.21	1388
2612	1364
2613.78	1390
2615.57	1352
2617.36	1374
2619.14	1376
2620.92	1314
2622.71	1330
2624.49	1318
2626.27	1316
2628.05	1296
2629.84	1316
2631.62	1304
2633.4	1276
2635.18	1302
2636.96	1282
2638.74	1258
2640.51	1248
2642.29	1290
2644.07	1268
2645.85	1258
2647.62	1292
2649.4	1266
2651.17	1244
2652.95	1296
2654.72	1248
2656.5	1232
2658.27	1258
2660.04	1238
2661.81	1202
2663.58	1238
2665.35	1240
2667.13	1210
2668.9	1180
2670.66	1188
2672.43	1198
2674.2	1206
2675.97	1230
2677.74	1138
2679.5	1202
2681.27	1200
2683.04	1178
2684.8	1204
2686.57	1176
2688.33	1146
2690.09	1162
2691.86	1134
2693.62	1186
2695.38	1180
2697.15	1176
2698.91	1108
2700.67	1138
2702.43	1102
2704.19	1154
2705.95	1126
2707.7	1134
2709.46	1098
2711.22	1096
2712.98	1076
2714.73	1118
2716.49	1118
2718.25	1114
2720	1114
2721.76	1136
2723.51	1064
2725.26	1104
2727.02	1080
2728.77	1060
2730.52	1040
2732.27	1032
2734.02	1096
2735.77	1062
2737.52	1042
2739.27	1036
2741.02	1022
2742.77	1046
2744.52	1046
2746.27	1008
2748.01	1010
2749.76	1034
2751.51	984
2753.25	994
2755	984
2756.74	1004
2758.48	982
2760.23	1032
2761.97	990
2763.71	976
2765.45	986
2767.19	986
2768.94	1000
2770.68	996
2772.42	1000
2774.16	962
2775.89	972
2777.63	950
2779.37	966
2781.11	966
2782.84	948
2784.58	956
2786.32	944
2788.05	930
2789.79	932
2791.52	940
2793.25	918
2794.99	920
2796.72	954
2798.45	988
2800.18	896
2801.92	948
2803.65	918
2805.38	876
2807.11	936
2808.84	924
2810.57	878
2812.29	926
2814.02	880
2815.75	892
2817.47	912
2819.2	868
2820.93	878
2822.65	836
2824.38	860
2826.1	878
2827.82	890
2829.55	868
2831.27	852
2832.99	884
2834.71	852
2836.44	838
2838.16	886
2839.88	858
2841.6	842
2843.32	810
2845.03	834
2846.75	848
2848.47	814
2850.19	816
2851.9	816
2853.62	828
2855.34	790
2857.05	814
2858.77	814
2860.48	814
2862.19	810
2863.91	790
2865.62	784
2867.33	810
2869.04	772
2870.76	768
2872.47	778
2874.18	780
2875.89	804
2877.6	754
2879.31	798
2881.01	786
2882.72	740
2884.43	776
2886.14	720
2887.84	748
2889.55	784
2891.25	750
2892.96	784
2894.66	730
2896.37	760
2898.07	762
2899.77	732
2901.48	750
2903.18	760
2904.88	756
2906.58	778
2908.28	750
2909.98	710
2911.68	724
2913.38	686
2915.08	722
2916.78	732
2918.47	734
2920.17	748
2921.87	690
2923.56	668
2925.26	722
2926.95	700
2928.65	706
2930.34	682
2932.04	710
2933.73	690
2935.42	700
2937.11	704
2938.81	700
2940.5	692
2942.19	690
2943.88	690
2945.57	682
2947.26	694
2948.95	668
2950.64	672
2952.32	672
2954.01	680
2955.7	680
2957.38	656
2959.07	644
2960.75	650
2962.44	672
2964.12	646
2965.81	660
2967.49	648
2969.17	650
2970.86	678
2972.54	644
2974.22	656
2975.9	638
2977.58	656
2979.26	624
2980.94	606
2982.62	640
2984.3	630
2985.98	624
2987.66	632
2989.33	608
2991.01	622
2992.69	624
2994.36	610
2996.04	614
2997.71	626
2999.39	604