File: muestras/tallo/1/Organic_10.txt
#Acq. time (s)=	10
#Accumulations=	1
#Range (cm-¹)=	100...3000
#Windows=	3
#Autofocus=	Off
#AutoExposure=	Off
#Spike filter=	Off
#Delay time (s)=	0
#Binning=	1
#Readout mode=	Signal
#DeNoise=	Off
#ICS correction=	Off
#Dark correction=	Off
#Inst. Process=	Off
#Instrument=	LabRAM HR Evol
#Detector=	Syncerity OE
#Objective=	x100_VIS
#Grating=	600 (500nm)
#ND Filter=	5%
#Laser=	633nm_Edge
#Hole=	74.97
#Range=	Visible
#Project=	Omar
#Sample=	26-06-23
#Site=	1
#Title=	Organic
#Remark=
#Date=	26.06.2023 15:58
#Acquired=	26.06.2023 15:58:02
101.018	1724
103.586	1770
106.152	1744
108.717	1722
111.281	1668
113.845	1740
116.407	1706
118.969	1784
121.53	1772
124.09	1762
126.649	1760
129.207	1752
131.765	1796
134.321	1750
136.877	1714
139.432	1764
141.985	1710
144.538	1762
147.09	1730
149.641	1758
152.191	1794
154.741	1760
157.289	1752
159.837	1722
162.385	1702
164.93	1786
167.476	1726
170.019	1736
172.562	1796
175.105	1742
177.646	1744
180.188	1692
182.727	1736
185.266	1722
187.804	1710
190.342	1780
192.878	1726
195.413	1734
197.948	1702
200.481	1750
203.014	1762
205.546	1756
208.077	1750
210.608	1754
213.137	1754
215.666	1716
218.194	1748
220.721	1750
223.247	1788
225.772	1708
228.295	1782
230.819	1740
233.342	1766
235.864	1832
238.384	1770
240.904	1778
243.423	1804
245.941	1786
248.46	1798
250.975	1796
253.492	1762
256.006	1796
258.519	1748
261.033	1728
263.545	1764
266.057	1778
268.567	1752
271.076	1758
273.585	1776
276.094	1728
278.601	1804
281.107	1814
283.612	1784
286.116	1790
288.62	1814
291.123	1852
293.625	1826
296.126	1792
298.626	1792
301.126	1820
303.625	1748
306.122	1854
308.62	1786
311.114	1852
313.61	1836
316.105	1812
318.599	1818
321.09	1848
323.583	1790
326.073	1870
328.563	1818
331.053	1794
333.541	1792
336.029	1852
338.515	1768
341.001	1806
343.486	1752
345.97	1862
348.453	1854
350.936	1806
353.418	1834
355.898	1784
358.378	1840
360.858	1896
363.336	1886
365.813	1864
368.29	1866
370.766	1874
373.241	1814
375.715	1830
378.188	1894
380.66	1876
383.132	1860
385.603	1802
388.072	1838
390.541	1876
393.01	1818
395.477	1822
397.943	1904
400.409	1826
402.875	1856
405.338	1884
407.802	1872
410.263	1952
412.725	1916
415.185	1950
417.646	1964
420.104	1976
422.564	2014
425.02	2014
427.477	2004
429.933	1984
432.388	2000
434.841	1954
437.294	1982
439.748	2010
442.199	1986
444.65	2024
447.1	2006
449.549	1994
451.997	1996
454.445	2028
456.891	2028
459.337	2008
461.782	2048
464.227	2026
466.669	2026
469.112	2144
471.554	2126
473.995	2060
476.434	2112
478.874	2090
481.312	2072
483.749	2100
486.186	2132
488.622	2126
491.057	2106
493.491	2186
495.925	2152
498.357	2160
500.789	2150
503.221	2178
505.65	2146
508.079	2292
510.509	2208
512.936	2172
515.363	2190
517.789	2206
520.214	2172
522.638	2156
525.062	2176
527.485	2184
529.907	2250
532.328	2214
534.748	2218
537.168	2246
539.587	2286
542.005	2266
544.423	2258
546.838	2294
549.254	2264
551.669	2300
554.082	2294
556.496	2366
558.909	2320
561.319	2374
563.731	2352
566.14	2376
568.549	2390
570.957	2390
573.364	2390
575.771	2390
578.177	2462
580.581	2476
582.987	2444
585.39	2522
587.792	2508
590.193	2546
592.594	2564
594.996	2566
597.395	2538
599.793	2524
602.191	2590
604.588	2614
606.984	2608
609.378	2608
611.773	2628
614.167	2674
616.56	2706
618.953	2784
621.343	2754
623.734	2746
626.124	2810
628.512	2798
630.901	2818
633.289	2852
635.675	2912
638.061	2916
640.446	2890
642.831	2956
645.213	3002
647.595	3046
649.978	3062
652.359	3104
654.738	3062
657.117	3094
659.497	3144
661.875	3146
664.252	3158
666.628	3200
669.003	3236
671.378	3204
673.751	3210
676.124	3268
678.497	3292
680.868	3316
683.239	3334
685.609	3360
687.977	3322
690.346	3356
692.714	3458
695.081	3442
697.446	3462
699.812	3496
702.175	3510
704.539	3530
706.901	3598
709.264	3568
711.625	3638
713.986	3654
716.345	3792
718.705	3736
721.062	3814
723.419	3804
725.775	3764
728.132	3892
730.487	3924
732.841	3986
735.194	3958
737.546	4066
739.898	3924
742.249	4004
744.599	4084
746.949	4126
749.298	4124
751.646	4162
753.993	4140
756.34	4126
758.684	4308
761.029	4308
763.374	4294
765.716	4478
768.059	4458
770.401	4478
772.741	4486
775.082	4506
777.421	4562
779.76	4640
782.097	4628
784.434	4632
786.771	4622
789.106	4638
791.44	4814
793.775	4792
796.108	4802
798.44	4858
800.771	4880
803.102	5088
805.432	5002
807.761	5090
810.09	5132
812.417	5126
814.744	5280
817.071	5240
819.396	5296
821.721	5274
824.045	5354
826.367	5438
828.69	5436
831.012	5528
833.332	5622
835.653	5550
837.972	5718
840.29	5610
842.609	5664
844.925	5706
847.242	5816
849.557	5968
851.871	5904
854.186	5940
856.498	5944
858.81	6038
861.122	5988
863.434	6118
865.744	6218
868.053	6204
870.361	6278
872.669	6356
874.976	6370
877.282	6348
879.588	6364
881.893	6432
884.197	6410
886.5	6386
888.802	6488
891.104	6504
893.405	6456
895.706	6604
898.004	6568
900.303	6562
902.6	6598
904.898	6570
907.194	6792
909.49	6760
911.785	6742
914.08	6796
916.372	6890
918.666	6954
920.957	6982
923.248	7010
925.538	6980
927.828	6998
930.118	7070
932.406	7016
934.693	7048
936.979	7266
939.265	7306
941.55	7252
943.835	7346
946.118	7226
948.401	7414
950.682	7372
952.964	7484
955.245	7576
957.525	7534
959.803	7508
962.082	7576
964.36	7582
966.636	7698
968.913	7618
971.188	7737
973.463	7638
975.736	7728
978.009	7910
980.282	7950
982.554	7932
984.824	7836
987.095	7892
989.364	8000
991.633	7880
993.9	7922
996.167	7912
998.434	7914
1000.7	8022
1002.96	8082
1005.23	8038
1007.49	8028
1009.76	8068
1012.02	8084
1014.28	8110
1016.54	8100
1018.8	8118
1021.06	8170
1023.32	8162
1025.57	8208
1027.83	8284
1030.09	8304
1032.34	8298
1034.6	8356
1036.85	8344
1039.1	8350
1041.35	8342
1043.61	8474
1045.86	8448
1048.11	8516
1050.36	8466
1052.61	8482
1054.85	8556
1057.1	8472
1059.35	8498
1061.59	8442
1063.84	8436
1066.08	8576
1068.33	8524
1070.57	8578
1072.81	8620
1075.05	8568
1077.29	8484
1079.53	8406
1081.77	8456
1084.01	8474
1086.25	8396
1088.48	8422
1090.72	8362
1092.96	8362
1095.19	8420
1097.43	8290
1099.66	8294
1101.89	8308
1104.12	8344
1106.35	8176
1108.59	8300
1110.81	8264
1113.04	8166
1115.27	8172
1117.5	8194
1119.73	8238
1121.95	8226
1124.18	8154
1126.4	8198
1128.63	8198
1130.85	8104
1133.07	8130
1135.29	8242
1137.51	8032
1139.73	7974
1141.95	8152
1144.17	8138
1146.39	8010
1148.61	8114
1150.82	8068
1153.04	8110
1155.26	8000
1157.47	7868
1159.68	8058
1161.9	7918
1164.11	8028
1166.32	7796
1168.53	7982
1170.74	7900
1172.95	7876
1175.16	7712
1177.37	7844
1179.58	7666
1181.78	7640
1183.99	7650
1186.19	7664
1188.4	7552
1190.6	7476
1192.8	7434
1195.01	7454
1197.21	7409.17
1199.41	7382.08
1201.61	7363.44
1203.81	7290.64
1206.01	7220.7
1208.2	7167.36
1210.4	7133.98
1212.6	7165.91
1214.8	7035.28
1216.99	7059.79
1219.18	6973.54
1221.38	6983.24
1223.57	6905.96
1225.76	6943
1227.96	6860.08
1230.15	6790.88
1232.34	6760.32
1234.53	6781.5
1236.71	6817.18
1238.9	6699.22
1241.09	6707.72
1243.28	6708.76
1245.46	6688.78
1247.65	6593.53
1249.83	6597.64
1252.02	6541.24
1254.2	6590.77
1256.38	6475.98
1258.56	6481.88
1260.74	6461.98
1262.92	6466.11
1265.1	6409.42
1267.28	6406.92
1269.46	6357.81
1271.64	6297.44
1273.82	6309.95
1275.99	6239.96
1278.17	6230.61
1280.34	6206.21
1282.52	6192.32
1284.69	6179.93
1286.86	6124
1289.03	6097.04
1291.21	6100.05
1293.38	6083.45
1295.55	6010.17
1297.71	5995.45
1299.88	5978.35
1302.05	5907.35
1304.22	5893.53
1306.38	5833.82
1308.43	5844
1310.61	5722
1312.78	5802
1314.96	5762
1317.13	5762
1319.3	5688
1321.48	5566
1323.65	5640
1325.82	5614
1327.99	5574
1330.16	5626
1332.33	5490
1334.5	5328
1336.66	5380
1338.83	5288
1341	5320
1343.16	5158
1345.33	5298
1347.49	5216
1349.65	5198
1351.82	5176
1353.98	5088
1356.14	5136
1358.3	5076
1360.46	5020
1362.62	4992
1364.78	4960
1366.94	4990
1369.09	4976
1371.25	4912
1373.41	4888
1375.56	4844
1377.72	4806
1379.87	4856
1382.02	4698
1384.17	4846
1386.33	4770
1388.48	4728
1390.63	4624
1392.78	4638
1394.93	4658
1397.07	4650
1399.22	4616
1401.37	4518
1403.52	4656
1405.66	4556
1407.81	4548
1409.95	4528
1412.09	4420
1414.24	4468
1416.38	4390
1418.52	4400
1420.66	4362
1422.8	4336
1424.94	4330
1427.08	4300
1429.22	4246
1431.35	4258
1433.49	4308
1435.63	4236
1437.76	4186
1439.9	4200
1442.03	4230
1444.17	4132
1446.3	4206
1448.43	4102
1450.56	4108
1452.69	4146
1454.82	4150
1456.95	4076
1459.08	4146
1461.21	4054
1463.34	4058
1465.46	3958
1467.59	3984
1469.71	4046
1471.84	3890
1473.96	3988
1476.08	3930
1478.21	3916
1480.33	3906
1482.45	3946
1484.57	3932
1486.69	3826
1488.81	3896
1490.93	3776
1493.05	3826
1495.16	3790
1497.28	3784
1499.4	3744
1501.51	3828
1503.63	3744
1505.74	3714
1507.85	3712
1509.97	3638
1512.08	3698
1514.19	3678
1516.3	3684
1518.41	3548
1520.52	3578
1522.63	3614
1524.73	3594
1526.84	3542
1528.95	3598
1531.06	3534
1533.16	3508
1535.26	3534
1537.37	3530
1539.47	3438
1541.57	3378
1543.68	3478
1545.78	3402
1547.88	3398
1549.98	3424
1552.08	3466
1554.18	3466
1556.27	3346
1558.37	3418
1560.47	3406
1562.56	3368
1564.66	3356
1566.75	3392
1568.85	3364
1570.94	3362
1573.03	3260
1575.13	3324
1577.22	3296
1579.31	3242
1581.4	3256
1583.49	3224
1585.58	3212
1587.66	3196
1589.75	3282
1591.84	3224
1593.93	3220
1596.01	3132
1598.1	3230
1600.18	3218
1602.26	3196
1604.35	3186
1606.43	3122
1608.51	3146
1610.59	3164
1612.67	3098
1614.75	3150
1616.83	3116
1618.91	3096
1620.99	3110
1623.06	3020
1625.14	3154
1627.21	3100
1629.29	3088
1631.36	3112
1633.44	3046
1635.51	2974
1637.58	3070
1639.66	3030
1641.73	3066
1643.8	3024
1645.87	2986
1647.94	2972
1650	3022
1652.07	3066
1654.14	3056
1656.21	3032
1658.27	2938
1660.34	2912
1662.4	2900
1664.47	2950
1666.53	2992
1668.59	2976
1670.66	2900
1672.72	2896
1674.78	2922
1676.84	2864
1678.9	2878
1680.96	2850
1683.01	2844
1685.07	2800
1687.13	2852
1689.19	2874
1691.24	2806
1693.3	2754
1695.35	2812
1697.4	2780
1699.46	2750
1701.51	2796
1703.56	2714
1705.61	2792
1707.66	2778
1709.71	2780
1711.76	2814
1713.81	2708
1715.86	2722
1717.91	2646
1719.95	2686
1722	2702
1724.04	2716
1726.09	2730
1728.13	2706
1730.18	2680
1732.22	2742
1734.26	2688
1736.3	2688
1738.34	2666
1740.38	2610
1742.42	2736
1744.46	2622
1746.5	2650
1748.54	2610
1750.58	2652
1752.61	2616
1754.65	2580
1756.68	2618
1758.72	2572
1760.75	2580
1762.79	2594
1764.82	2530
1766.85	2598
1768.88	2566
1770.91	2578
1772.94	2596
1774.97	2590
1777	2552
1779.03	2514
1781.06	2578
1783.09	2560
1785.11	2542
1787.14	2526
1789.16	2626
1791.19	2596
1793.21	2498
1795.23	2520
1797.26	2530
1799.28	2552
1801.3	2496
1803.32	2544
1805.34	2486
1807.36	2464
1809.38	2484
1811.4	2450
1813.42	2502
1815.43	2516
1817.45	2440
1819.47	2468
1821.48	2506
1823.49	2406
1825.51	2472
1827.52	2464
1829.54	2424
1831.55	2394
1833.56	2398
1835.57	2368
1837.58	2378
1839.59	2430
1841.6	2396
1843.61	2430
1845.61	2356
1847.62	2356
1849.63	2382
1851.63	2382
1853.64	2328
1855.64	2328
1857.65	2326
1859.65	2356
1861.65	2370
1863.65	2342
1865.66	2292
1867.66	2354
1869.66	2300
1871.66	2372
1873.66	2326
1875.65	2356
1877.65	2288
1879.65	2356
1881.65	2328
1883.64	2320
1885.64	2286
1887.63	2272
1889.63	2364
1891.62	2286
1893.61	2286
1895.6	2248
1897.6	2290
1899.59	2314
1901.58	2354
1903.57	2264
1905.56	2316
1907.54	2332
1909.53	2266
1911.52	2310
1913.51	2226
1915.49	2258
1917.48	2246
1919.46	2322
1921.45	2288
1923.43	2240
1925.41	2292
1927.4	2230
1929.38	2268
1931.36	2276
1933.34	2226
1935.32	2230
1937.3	2258
1939.28	2246
1941.26	2204
1943.23	2238
1945.21	2240
1947.19	2254
1949.16	2264
1951.14	2254
1953.11	2276
1955.09	2232
1957.06	2226
1959.03	2216
1961	2198
1962.98	2218
1964.95	2232
1966.92	2196
1968.89	2144
1970.85	2202
1972.82	2178
1974.79	2164
1976.76	2202
1978.73	2206
1980.69	2216
1982.66	2126
1984.62	2246
1986.59	2172
1988.55	2210
1990.51	2150
1992.47	2178
1994.44	2150
1996.4	2198
1998.36	2134
2000.32	2182
2002.28	2172
2004.24	2150
2006.19	2154
2008.15	2168
2010.11	2140
2012.06	2102
2014.02	2154
2015.98	2122
2017.93	2156
2019.88	2118
2021.84	2142
2023.79	2078
2025.74	2128
2027.69	2158
2029.65	2128
2031.6	2146
2033.55	2066
2035.5	2150
2037.44	2128
2039.39	2060
2041.34	2100
2043.29	2096
2045.23	2092
2047.18	2074
2049.12	2094
2051.07	2146
2053.01	2036
2054.95	2092
2056.9	2046
2058.84	2074
2060.78	2010
2062.72	2068
2064.66	2054
2066.6	2020
2068.54	2060
2070.48	2076
2072.42	2042
2074.35	2090
2076.29	2016
2078.23	2002
2080.16	2064
2082.1	2008
2084.03	2118
2085.96	2052
2087.9	2054
2089.83	2056
2091.76	2042
2093.69	2096
2095.62	2010
2097.55	2010
2099.48	2094
2101.41	1972
2103.34	2000
2105.27	2054
2107.2	1976
2109.12	2000
2111.05	2014
2112.98	1988
2114.9	1978
2116.82	1986
2118.75	2000
2120.67	2006
2122.59	1984
2124.52	2006
2126.44	2014
2128.36	1992
2130.28	2000
2132.2	1960
2134.12	2038
2136.04	2012
2137.95	1992
2139.87	1958
2141.79	1946
2143.7	1980
2145.62	1951.87
2147.53	1990.92
2149.45	1957.6
2151.36	1945.47
2153.28	1937.11
2155.19	1936.26
2157.1	1939.01
2159.01	1959.66
2160.92	1917.03
2162.83	1931.72
2164.74	1936.87
2166.65	1929.99
2168.56	1910.47
2170.47	1916.61
2172.38	1869.09
2174.28	1876.5
2176.19	1922.92
2178.09	1869.3
2180	1860.15
2181.9	1928.13
2183.81	1873.09
2185.71	1898.6
2187.61	1917.18
2189.52	1890.1
2191.42	1852.44
2193.32	1827.05
2195.22	1847.27
2197.12	1846.95
2199.02	1895.03
2200.92	1841.36
2202.82	1862.5
2204.71	1839.45
2206.61	1843.74
2208.51	1866.3
2210.4	1849.07
2212.3	1833.18
2214.19	1842.87
2216.09	1826.15
2217.98	1858.76
2219.87	1841.76
2221.77	1832.64
2223.66	1836.82
2225.55	1834.95
2227.44	1839.9
2229.33	1844.02
2231.22	1820.49
2233.11	1837.11
2235	1856.78
2236.88	1832.44
2238.77	1825.53
2240.66	1804.12
2242.07	1808
2243.97	1796
2245.87	1842
2247.76	1830
2249.65	1814
2251.55	1856
2253.44	1860
2255.33	1854
2257.22	1810
2259.12	1824
2261.01	1830
2262.9	1774
2264.78	1802
2266.67	1804
2268.56	1732
2270.45	1732
2272.34	1796
2274.22	1764
2276.11	1762
2277.99	1768
2279.88	1700
2281.76	1782
2283.65	1782
2285.53	1786
2287.41	1814
2289.3	1786
2291.18	1746
2293.06	1776
2294.94	1764
2296.82	1726
2298.7	1698
2300.58	1728
2302.46	1704
2304.33	1752
2306.21	1760
2308.09	1766
2309.96	1754
2311.84	1748
2313.71	1732
2315.59	1730
2317.46	1738
2319.33	1690
2321.21	1688
2323.08	1716
2324.95	1694
2326.82	1692
2328.69	1726
2330.56	1678
2332.43	1688
2334.3	1760
2336.17	1692
2338.03	1698
2339.9	1698
2341.77	1642
2343.63	1652
2345.5	1638
2347.36	1642
2349.23	1658
2351.09	1648
2352.95	1644
2354.82	1656
2356.68	1646
2358.54	1620
2360.4	1650
2362.26	1636
2364.12	1650
2365.98	1662
2367.84	1638
2369.7	1606
2371.56	1604
2373.41	1614
2375.27	1640
2377.12	1646
2378.98	1616
2380.84	1570
2382.69	1592
2384.54	1604
2386.4	1602
2388.25	1624
2390.1	1592
2391.95	1622
2393.8	1572
2395.65	1570
2397.5	1558
2399.35	1540
2401.2	1560
2403.05	1588
2404.9	1538
2406.75	1548
2408.59	1562
2410.44	1570
2412.28	1530
2414.13	1554
2415.97	1550
2417.82	1548
2419.66	1486
2421.5	1480
2423.35	1492
2425.19	1508
2427.03	1508
2428.87	1490
2430.71	1472
2432.55	1488
2434.39	1478
2436.23	1458
2438.06	1490
2439.9	1452
2441.74	1458
2443.57	1490
2445.41	1458
2447.24	1422
2449.08	1478
2450.91	1466
2452.75	1428
2454.58	1432
2456.41	1434
2458.24	1378
2460.08	1454
2461.91	1418
2463.74	1422
2465.57	1412
2467.4	1392
2469.22	1428
2471.05	1382
2472.88	1448
2474.71	1384
2476.53	1420
2478.36	1404
2480.19	1396
2482.01	1344
2483.83	1370
2485.66	1382
2487.48	1404
2489.3	1394
2491.13	1350
2492.95	1338
2494.77	1314
2496.59	1330
2498.41	1372
2500.23	1342
2502.05	1372
2503.87	1330
2505.68	1320
2507.5	1326
2509.32	1292
2511.14	1320
2512.95	1290
2514.77	1340
2516.58	1274
2518.39	1282
2520.21	1312
2522.02	1308
2523.83	1270
2525.65	1306
2527.46	1270
2529.27	1256
2531.08	1302
2532.89	1234
2534.7	1232
2536.51	1262
2538.32	1288
2540.12	1260
2541.93	1282
2543.74	1248
2545.54	1196
2547.35	1216
2549.15	1256
2550.96	1220
2552.76	1192
2554.56	1226
2556.37	1214
2558.17	1210
2559.97	1206
2561.77	1208
2563.58	1196
2565.38	1208
2567.18	1188
2568.97	1210
2570.77	1204
2572.57	1178
2574.37	1156
2576.17	1202
2577.96	1208
2579.76	1140
2581.55	1208
2583.35	1154
2585.14	1162
2586.94	1154
2588.73	1100
2590.52	1168
2592.32	1162
2594.11	1138
2595.9	1168
2597.69	1150
2599.48	1166
2601.27	1164
2603.06	1158
2604.85	1164
2606.64	1118
2608.42	1134
2610.21	1156
2612	1118
2613.78	1108
2615.57	1092
2617.36	1074
2619.14	1074
2620.92	1080
2622.71	1090
2624.49	1066
2626.27	1048
2628.05	1072
2629.84	1050
2631.62	1046
2633.4	1038
2635.18	1024
2636.96	1038
2638.74	1042
2640.51	1032
2642.29	998
2644.07	1040
2645.85	1028
2647.62	1054
2649.4	1002
2651.17	1038
2652.95	1010
2654.72	974
2656.5	998
2658.27	1012
2660.04	998
2661.81	1002
2663.58	976
2665.35	1032
2667.13	986
2668.9	1004
2670.66	982
2672.43	932
2674.2	998
2675.97	974
2677.74	958
2679.5	954
2681.27	982
2683.04	920
2684.8	962
2686.57	950
2688.33	946
2690.09	946
2691.86	918
2693.62	960
2695.38	912
2697.15	916
2698.91	908
2700.67	928
2702.43	944
2704.19	938
2705.95	918
2707.7	900
2709.46	916
2711.22	924
2712.98	906
2714.73	874
2716.49	942
2718.25	856
2720	900
2721.76	850
2723.51	872
2725.26	840
2727.02	888
2728.77	864
2730.52	858
2732.27	864
2734.02	860
2735.77	854
2737.52	824
2739.27	872
2741.02	874
2742.77	862
2744.52	822
2746.27	836
2748.01	826
2749.76	830
2751.51	818
2753.25	850
2755	816
2756.74	840
2758.48	832
2760.23	812
2761.97	830
2763.71	816
2765.45	800
2767.19	800
2768.94	802
2770.68	782
2772.42	830
2774.16	770
2775.89	804
2777.63	804
2779.37	776
2781.11	784
2782.84	778
2784.58	752
2786.32	718
2788.05	764
2789.79	770
2791.52	762
2793.25	794
2794.99	756
2796.72	766
2798.45	768
2800.18	766
2801.92	766
2803.65	744
2805.38	746
2807.11	748
2808.84	738
2810.57	716
2812.29	748
2814.02	736
2815.75	742
2817.47	766
2819.2	740
2820.93	744
2822.65	738
2824.38	710
2826.1	684
2827.82	694
2829.55	704
2831.27	734
2832.99	694
2834.71	720
2836.44	666
2838.16	706
2839.88	690
2841.6	732
2843.32	694
2845.03	680
2846.75	680
2848.47	672
2850.19	654
2851.9	652
2853.62	656
2855.34	660
2857.05	626
2858.77	674
2860.48	634
2862.19	628
2863.91	656
2865.62	648
2867.33	678
2869.04	636
2870.76	656
2872.47	652
2874.18	664
2875.89	660
2877.6	686
2879.31	644
2881.01	656
2882.72	604
2884.43	622
2886.14	632
2887.84	632
2889.55	626
2891.25	612
2892.96	592
2894.66	620
2896.37	604
2898.07	616
2899.77	612
2901.48	618
2903.18	626
2904.88	604
2906.58	642
2908.28	606
2909.98	590
2911.68	616
2913.38	606
2915.08	588
2916.78	614
2918.47	588
2920.17	612
2921.87	612
2923.56	570
2925.26	600
2926.95	610
2928.65	580
2930.34	580
2932.04	578
2933.73	594
2935.42	606
2937.11	570
2938.81	580
2940.5	590
2942.19	578
2943.88	558
2945.57	550
2947.26	562
2948.95	564
2950.64	556
2952.32	538
2954.01	566
2955.7	560
2957.38	556
2959.07	572
2960.75	564
2962.44	522
2964.12	558
2965.81	540
2967.49	532
2969.17	538
2970.86	536
2972.54	512
2974.22	522
2975.9	526
2977.58	522
2979.26	524
2980.94	502
2982.62	548
2984.3	508
2985.98	542
2987.66	520
2989.33	524
2991.01	518
2992.69	518
2994.36	508
2996.04	498
2997.71	522
2999.39	530