File: muestras/tallo/1/Organic_12.txt
#Acq. time (s)=	10
#Accumulations=	1
#Range (cm-¹)=	100...3000
#Windows=	3
#Autofocus=	Off
#AutoExposure=	Off
#Spike filter=	Off
#Delay time (s)=	0
#Binning=	1
#Readout mode=	Signal
#DeNoise=	Off
#ICS correction=	Off
#Dark correction=	Off
#Inst. Process=	Off
#Instrument=	LabRAM HR Evol
#Detector=	Syncerity OE
#Objective=	x100_VIS
#Grating=	600 (500nm)
#ND Filter=	5%
#Laser=	633nm_Edge
#Hole=	74.97
#Range=	Visible
#Project=	Omar
#Sample=	26-06-23
#Site=	1
#Title=	Organic
#Remark=
#Date=	26.06.2023 16:00
#Acquired=	26.06.2023 16:00:51
101.018	1576
103.586	1622
106.152	1632
108.717	1630
111.281	1604
113.845	1692
116.407	1598
118.969	1588
121.53	1640
124.09	1614
126.649	1636
129.207	1606
131.765	2782
134.321	1598
136.877	1674
139.432	1634
141.985	1642
144.538	1622
147.09	1634
149.641	1600
152.191	1584
154.741	1628
157.289	1626
159.837	1584
162.385	1576
164.93	1556
167.476	1630
170.019	1610
172.562	1580
175.105	1626
177.646	1604
180.188	1630
182.727	1552
185.266	1590
187.804	1624
190.342	1578
192.878	1618
195.413	1632
197.948	1626
200.481	1652
203.014	1644
205.546	1654
208.077	1594
210.608	1652
213.137	1592
215.666	1666
218.194	1672
220.721	1604
223.247	1624
225.772	1652
228.295	1628
230.819	1630
233.342	1636
235.864	1694
238.384	1674
240.904	1660
243.423	1676
245.941	1678
248.46	1670
250.975	1644
253.492	1684
256.006	1670
258.519	1676
261.033	1636
263.545	1680
266.057	1618
268.567	1632
271.076	1618
273.585	1610
276.094	1672
278.601	1612
281.107	1610
283.612	1666
286.116	1686
288.62	1650
291.123	1616
293.625	1606
296.126	1708
298.626	1682
301.126	1660
303.625	1700
306.122	1694
308.62	1702
311.114	1664
313.61	1690
316.105	1670
318.599	1664
321.09	1712
323.583	1644
326.073	1702
328.563	1764
331.053	1708
333.541	1686
336.029	1710
338.515	1692
341.001	1690
343.486	1718
345.97	1702
348.453	1692
350.936	1682
353.418	1716
355.898	1720
358.378	1768
360.858	1760
363.336	1700
365.813	1744
368.29	1702
370.766	1740
373.241	1714
375.715	1770
378.188	1730
380.66	1744
383.132	1746
385.603	1750
388.072	1750
390.541	1726
393.01	1736
395.477	1730
397.943	1764
400.409	1812
402.875	1780
405.338	1760
407.802	1834
410.263	1758
412.725	1804
415.185	1856
417.646	1766
420.104	1826
422.564	1794
425.02	1814
427.477	1850
429.933	1792
432.388	1872
434.841	1810
437.294	1846
439.748	1850
442.199	1858
444.65	1892
447.1	1910
449.549	1884
451.997	1868
454.445	1854
456.891	1896
459.337	1874
461.782	1852
464.227	1872
466.669	1868
469.112	1910
471.554	1918
473.995	1958
476.434	1932
478.874	1900
481.312	1958
483.749	1942
486.186	1926
488.622	1908
491.057	1988
493.491	1992
495.925	2006
498.357	1966
500.789	1940
503.221	2046
505.65	2028
508.079	2012
510.509	2044
512.936	2078
515.363	1998
517.789	2018
520.214	2012
522.638	2018
525.062	2084
527.485	1980
529.907	2070
532.328	2004
534.748	2062
537.168	2056
539.587	2064
542.005	2100
544.423	2070
546.838	2156
549.254	2100
551.669	2098
554.082	2074
556.496	2174
558.909	2166
561.319	2162
563.731	2102
566.14	2200
568.549	2236
570.957	2164
573.364	2192
575.771	2222
578.177	2280
580.581	2252
582.987	2262
585.39	2326
587.792	2322
590.193	2282
592.594	2336
594.996	2342
597.395	2350
599.793	2354
602.191	2354
604.588	2330
606.984	2362
609.378	2396
611.773	2404
614.167	2448
616.56	2428
618.953	2508
621.343	2458
623.734	2540
626.124	2628
628.512	2568
630.901	2574
633.289	2626
635.675	2604
638.061	2660
640.446	2666
642.831	2666
645.213	2706
647.595	2776
649.978	2766
652.359	2784
654.738	2780
657.117	2810
659.497	2788
661.875	2846
664.252	2810
666.628	2874
669.003	2866
671.378	2938
673.751	2918
676.124	2856
678.497	2970
680.868	2986
683.239	2990
685.609	2942
687.977	3044
690.346	3082
692.714	3090
695.081	3088
697.446	3120
699.812	3108
702.175	3120
704.539	3124
706.901	3200
709.264	3268
711.625	3220
713.986	3288
716.345	3402
718.705	3336
721.062	3408
723.419	3382
725.775	3432
728.132	3444
730.487	3482
732.841	3578
735.194	3588
737.546	3580
739.898	3672
742.249	3630
744.599	3610
746.949	3662
749.298	3624
751.646	3714
753.993	3732
756.34	3774
758.684	3840
761.029	3846
763.374	3888
765.716	3930
768.059	3936
770.401	3902
772.741	3966
775.082	4008
777.421	4036
779.76	4068
782.097	4104
784.434	4104
786.771	4122
789.106	4210
791.44	4212
793.775	4216
796.108	4294
798.44	4358
800.771	4356
803.102	4322
805.432	4418
807.761	4490
810.09	4550
812.417	4546
814.744	4590
817.071	4634
819.396	4654
821.721	4734
824.045	4738
826.367	4760
828.69	4852
831.012	4860
833.332	4926
835.653	4996
837.972	4980
840.29	5100
842.609	5126
844.925	5112
847.242	5180
849.557	5066
851.871	5224
854.186	5292
856.498	5270
858.81	5286
861.122	5322
863.434	5378
865.744	5414
868.053	5514
870.361	5452
872.669	5524
874.976	5510
877.282	5696
879.588	5558
881.893	5528
884.197	5626
886.5	5578
888.802	5688
891.104	5664
893.405	5786
895.706	5752
898.004	5910
900.303	5888
902.6	5946
904.898	5826
907.194	5852
909.49	6024
911.785	5936
914.08	6028
916.372	6022
918.666	6080
920.957	6060
923.248	6036
925.538	6256
927.828	6238
930.118	6240
932.406	6220
934.693	6312
936.979	6366
939.265	6314
941.55	6384
943.835	6436
946.118	6534
948.401	6592
950.682	6552
952.964	6494
955.245	6698
957.525	6564
959.803	6630
962.082	6702
964.36	6790
966.636	6744
968.913	6838
971.188	6714
973.463	6806
975.736	6776
978.009	6918
980.282	6992
982.554	6848
984.824	6906
987.095	7030
989.364	6916
991.633	6880
993.9	7092
996.167	7060
998.434	7048
1000.7	7034
1002.96	7056
1005.23	7004
1007.49	7138
1009.76	7166
1012.02	7148
1014.28	7146
1016.54	7082
1018.8	7248
1021.06	7162
1023.32	7132
1025.57	7206
1027.83	7236
1030.09	7326
1032.34	7258
1034.6	7428
1036.85	7438
1039.1	7362
1041.35	7478
1043.61	7350
1045.86	7390
1048.11	7446
1050.36	7384
1052.61	7486
1054.85	7302
1057.1	7484
1059.35	7502
1061.59	7620
1063.84	7422
1066.08	7546
1068.33	7540
1070.57	7508
1072.81	7590
1075.05	7598
1077.29	7510
1079.53	7502
1081.77	7478
1084.01	7418
1086.25	7462
1088.48	7390
1090.72	7378
1092.96	7406
1095.19	7458
1097.43	7324
1099.66	7342
1101.89	7346
1104.12	7342
1106.35	7380
1108.59	7418
1110.81	7270
1113.04	7278
1115.27	7240
1117.5	7150
1119.73	7198
1121.95	7256
1124.18	7230
1126.4	7300
1128.63	7206
1130.85	7174
1133.07	7228
1135.29	7246
1137.51	7178
1139.73	7126
1141.95	7198
1144.17	7188
1146.39	7156
1148.61	7232
1150.82	7044
1153.04	7234
1155.26	7048
1157.47	7098
1159.68	6982
1161.9	6988
1164.11	7044
1166.32	7082
1168.53	6956
1170.74	7000
1172.95	6996
1175.16	6900
1177.37	6956
1179.58	6842
1181.78	6758
1183.99	6762
1186.19	6770
1188.4	6754
1190.6	6748
1192.8	6608
1195.01	6478
1197.21	6566.45
1199.41	6513.2
1201.61	6485.97
1203.81	6465.32
1206.01	6461.21
1208.2	6420.39
1210.4	6327.99
1212.6	6373.51
1214.8	6214.58
1216.99	6333.48
1219.18	6313.19
1221.38	6199.87
1223.57	6220.92
1225.76	6190.2
1227.96	6158.29
1230.15	6143.37
1232.34	6076.23
1234.53	6057.06
1236.71	6043.63
1238.9	6040.05
1241.09	6031.02
1243.28	5907.27
1245.46	5932.12
1247.65	5897.08
1249.83	5944.21
1252.02	5881.27
1254.2	5854.78
1256.38	5851.5
1258.56	5769.49
1260.74	5782.33
1262.92	5754.52
1265.1	5770.03
1267.28	5712.46
1269.46	5713.36
1271.64	5644.42
1273.82	5695.54
1275.99	5563.75
1278.17	5623.58
1280.34	5594.96
1282.52	5560.85
1284.69	5529.46
1286.86	5474.77
1289.03	5412.04
1291.21	5425.23
1293.38	5412.1
1295.55	5403.74
1297.71	5440.73
1299.88	5357.08
1302.05	5334.38
1304.22	5273.46
1306.38	5268.12
1308.43	5222
1310.61	5280
1312.78	5166
1314.96	5166
1317.13	5084
1319.3	5066
1321.48	5056
1323.65	5076
1325.82	4990
1327.99	5008
1330.16	4966
1332.33	4872
1334.5	4840
1336.66	4862
1338.83	4818
1341	4798
1343.16	4774
1345.33	4630
1347.49	4674
1349.65	4718
1351.82	4682
1353.98	4654
1356.14	4650
1358.3	4608
1360.46	4562
1362.62	4550
1364.78	4494
1366.94	4544
1369.09	4456
1371.25	4412
1373.41	4424
1375.56	4458
1377.72	4366
1379.87	4374
1382.02	4306
1384.17	4334
1386.33	4344
1388.48	4334
1390.63	4262
1392.78	4234
1394.93	4186
1397.07	4194
1399.22	4200
1401.37	4146
1403.52	4118
1405.66	4100
1407.81	4106
1409.95	4134
1412.09	3986
1414.24	4028
1416.38	4008
1418.52	3896
1420.66	3952
1422.8	3928
1424.94	4000
1427.08	3912
1429.22	3898
1431.35	3950
1433.49	3878
1435.63	3848
1437.76	3804
1439.9	3740
1442.03	3834
1444.17	3808
1446.3	3800
1448.43	3816
1450.56	3762
1452.69	3800
1454.82	3720
1456.95	3712
1459.08	3806
1461.21	3666
1463.34	3684
1465.46	3598
1467.59	3606
1469.71	3622
1471.84	3556
1473.96	3554
1476.08	3586
1478.21	3572
1480.33	3548
1482.45	3564
1484.57	3522
1486.69	3524
1488.81	3444
1490.93	3522
1493.05	3506
1495.16	3510
1497.28	3438
1499.4	3478
1501.51	3464
1503.63	3338
1505.74	3354
1507.85	3374
1509.97	3416
1512.08	3390
1514.19	3348
1516.3	3332
1518.41	3336
1520.52	3250
1522.63	3288
1524.73	3262
1526.84	3280
1528.95	3256
1531.06	3200
1533.16	3266
1535.26	3258
1537.37	3232
1539.47	3158
1541.57	3224
1543.68	3088
1545.78	3180
1547.88	3142
1549.98	3142
1552.08	3104
1554.18	3082
1556.27	3088
1558.37	3050
1560.47	3048
1562.56	3046
1564.66	3090
1566.75	2976
1568.85	3020
1570.94	3088
1573.03	2998
1575.13	2954
1577.22	2968
1579.31	3086
1581.4	2984
1583.49	3008
1585.58	2992
1587.66	2994
1589.75	2902
1591.84	3006
1593.93	2870
1596.01	2934
1598.1	2904
1600.18	2958
1602.26	2894
1604.35	2864
1606.43	2900
1608.51	2890
1610.59	2884
1612.67	2836
1614.75	2896
1616.83	2820
1618.91	2856
1620.99	2862
1623.06	2866
1625.14	2818
1627.21	2782
1629.29	2838
1631.36	2826
1633.44	2838
1635.51	2820
1637.58	2748
1639.66	2834
1641.73	2760
1643.8	2782
1645.87	2826
1647.94	2750
1650	2784
1652.07	2750
1654.14	2714
1656.21	2732
1658.27	2728
1660.34	2722
1662.4	2730
1664.47	2706
1666.53	2608
1668.59	2714
1670.66	2680
1672.72	2680
1674.78	2684
1676.84	2688
1678.9	2678
1680.96	2684
1683.01	2574
1685.07	2630
1687.13	2654
1689.19	2582
1691.24	2580
1693.3	2566
1695.35	2564
1697.4	2562
1699.46	2524
1701.51	2554
1703.56	2504
1705.61	2530
1707.66	2500
1709.71	2498
1711.76	2510
1713.81	2486
1715.86	2480
1717.91	2488
1719.95	2478
1722	2488
1724.04	2450
1726.09	2468
1728.13	2472
1730.18	2478
1732.22	2472
1734.26	2490
1736.3	2392
1738.34	2426
1740.38	2462
1742.42	2412
1744.46	2362
1746.5	2414
1748.54	2392
1750.58	2416
1752.61	2408
1754.65	2450
1756.68	2384
1758.72	2346
1760.75	2390
1762.79	2366
1764.82	2366
1766.85	2294
1768.88	2380
1770.91	2368
1772.94	2382
1774.97	2370
1777	2354
1779.03	2332
1781.06	2358
1783.09	2350
1785.11	2344
1787.14	2370
1789.16	2328
1791.19	2318
1793.21	2356
1795.23	2274
1797.26	2266
1799.28	2214
1801.3	2286
1803.32	2266
1805.34	2338
1807.36	2270
1809.38	2234
1811.4	2256
1813.42	2204
1815.43	2248
1817.45	2256
1819.47	2222
1821.48	2300
1823.49	2282
1825.51	2260
1827.52	2258
1829.54	2196
1831.55	2242
1833.56	2180
1835.57	2240
1837.58	2238
1839.59	2220
1841.6	2196
1843.61	2194
1845.61	2216
1847.62	2136
1849.63	2198
1851.63	2214
1853.64	2140
1855.64	2132
1857.65	2152
1859.65	2100
1861.65	2182
1863.65	2110
1865.66	2120
1867.66	2146
1869.66	2126
1871.66	2134
1873.66	2136
1875.65	2150
1877.65	2072
1879.65	2092
1881.65	2098
1883.64	2086
1885.64	2092
1887.63	2116
1889.63	2104
1891.62	2124
1893.61	2078
1895.6	2012
1897.6	2098
1899.59	2068
1901.58	2060
1903.57	2070
1905.56	2098
1907.54	2076
1909.53	2102
1911.52	2128
1913.51	2068
1915.49	2066
1917.48	2100
1919.46	2094
1921.45	2116
1923.43	2078
1925.41	2048
1927.4	2136
1929.38	2078
1931.36	2072
1933.34	2044
1935.32	2066
1937.3	2042
1939.28	2064
1941.26	2060
1943.23	2032
1945.21	2070
1947.19	1996
1949.16	1998
1951.14	2040
1953.11	1998
1955.09	1994
1957.06	2046
1959.03	2018
1961	1988
1962.98	2012
1964.95	2022
1966.92	1970
1968.89	2004
1970.85	2014
1972.82	1952
1974.79	1964
1976.76	1962
1978.73	1956
1980.69	1930
1982.66	1982
1984.62	1992
1986.59	1966
1988.55	2010
1990.51	1972
1992.47	1992
1994.44	1908
1996.4	1950
1998.36	1980
2000.32	1990
2002.28	1978
2004.24	1896
2006.19	1950
2008.15	1972
2010.11	1948
2012.06	1936
2014.02	1912
2015.98	1922
2017.93	1950
2019.88	1922
2021.84	1966
2023.79	1914
2025.74	1948
2027.69	1944
2029.65	1958
2031.6	1930
2033.55	1932
2035.5	1928
2037.44	1924
2039.39	1992
2041.34	1840
2043.29	1926
2045.23	1928
2047.18	1880
2049.12	1912
2051.07	1914
2053.01	1904
2054.95	1892
2056.9	1854
2058.84	1880
2060.78	1902
2062.72	1880
2064.66	1876
2066.6	1906
2068.54	1886
2070.48	1888
2072.42	1862
2074.35	1908
2076.29	1900
2078.23	1846
2080.16	1856
2082.1	1842
2084.03	1858
2085.96	1846
2087.9	1842
2089.83	1898
2091.76	1778
2093.69	1848
2095.62	1870
2097.55	1850
2099.48	1824
2101.41	1856
2103.34	1838
2105.27	1848
2107.2	1844
2109.12	1808
2111.05	1850
2112.98	1796
2114.9	1826
2116.82	1840
2118.75	1780
2120.67	1808
2122.59	1848
2124.52	1794
2126.44	1830
2128.36	1824
2130.28	1762
2132.2	1816
2134.12	1804
2136.04	1798
2137.95	1770
2139.87	1804
2141.79	1820
2143.7	1756
2145.62	1803.76
2147.53	1774.98
2149.45	1758.53
2151.36	1765.14
2153.28	1779.49
2155.19	1790.26
2157.1	1790.94
2159.01	1781.51
2160.92	1771.84
2162.83	1770.91
2164.74	1729.58
2166.65	1687.35
2168.56	1732.12
2170.47	1715.09
2172.38	1729.34
2174.28	1726.8
2176.19	1734.18
2178.09	1702.21
2180	1735.9
2181.9	1699.12
2183.81	1713.47
2185.71	1705.1
2187.61	1711.2
2189.52	1718.25
2191.42	1676.2
2193.32	1673.06
2195.22	1704.87
2197.12	1689.16
2199.02	1694.09
2200.92	1692.09
2202.82	1669.53
2204.71	1660.55
2206.61	1707.43
2208.51	1653.31
2210.4	1687.66
2212.3	1674.25
2214.19	1686.2
2216.09	1703.77
2217.98	1635.93
2219.87	1678.06
2221.77	1648.69
2223.66	1641.09
2225.55	1671.59
2227.44	1662.61
2229.33	1698.53
2231.22	1681.48
2233.11	1672.17
2235	1655.69
2236.88	1671.61
2238.77	1705.7
2240.66	1680.86
2242.07	1626
2243.97	1710
2245.87	1648
2247.76	1706
2249.65	1646
2251.55	1688
2253.44	1640
2255.33	1678
2257.22	1676
2259.12	1674
2261.01	1650
2262.9	1648
2264.78	1648
2266.67	1654
2268.56	1652
2270.45	1594
2272.34	1660
2274.22	1612
2276.11	1596
2277.99	1626
2279.88	1628
2281.76	1598
2283.65	1602
2285.53	1610
2287.41	1610
2289.3	1612
2291.18	1620
2293.06	1672
2294.94	1564
2296.82	1574
2298.7	1558
2300.58	1598
2302.46	1560
2304.33	1576
2306.21	1588
2308.09	1604
2309.96	1532
2311.84	1538
2313.71	1546
2315.59	1598
2317.46	1526
2319.33	1562
2321.21	1542
2323.08	1580
2324.95	1536
2326.82	1570
2328.69	1614
2330.56	1514
2332.43	1538
2334.3	1578
2336.17	1576
2338.03	1516
2339.9	1512
2341.77	1476
2343.63	1488
2345.5	1548
2347.36	1504
2349.23	1486
2351.09	1470
2352.95	1512
2354.82	1520
2356.68	1498
2358.54	1500
2360.4	1572
2362.26	1468
2364.12	1508
2365.98	1460
2367.84	1440
2369.7	1428
2371.56	1472
2373.41	1458
2375.27	1464
2377.12	1474
2378.98	1470
2380.84	1468
2382.69	1406
2384.54	1454
2386.4	1464
2388.25	1438
2390.1	1432
2391.95	1460
2393.8	1442
2395.65	1410
2397.5	1374
2399.35	1390
2401.2	1424
2403.05	1380
2404.9	1432
2406.75	1422
2408.59	1366
2410.44	1448
2412.28	1422
2414.13	1372
2415.97	1380
2417.82	1404
2419.66	1384
2421.5	1380
2423.35	1374
2425.19	1362
2427.03	1342
2428.87	1372
2430.71	1358
2432.55	1330
2434.39	1424
2436.23	1328
2438.06	1376
2439.9	1334
2441.74	1362
2443.57	1352
2445.41	1324
2447.24	1336
2449.08	1328
2450.91	1348
2452.75	1336
2454.58	1334
2456.41	1338
2458.24	1328
2460.08	1286
2461.91	1306
2463.74	1342
2465.57	1300
2467.4	1296
2469.22	1298
2471.05	1264
2472.88	1296
2474.71	1260
2476.53	1278
2478.36	1272
2480.19	1250
2482.01	1280
2483.83	1232
2485.66	1238
2487.48	1262
2489.3	1210
2491.13	1214
2492.95	1212
2494.77	1224
2496.59	1258
2498.41	1166
2500.23	1220
2502.05	1240
2503.87	1246
2505.68	1194
2507.5	1238
2509.32	1180
2511.14	1216
2512.95	1150
2514.77	1188
2516.58	1220
2518.39	1166
2520.21	1188
2522.02	1250
2523.83	1198
2525.65	1164
2527.46	1142
2529.27	1174
2531.08	1188
2532.89	1162
2534.7	1150
2536.51	1140
2538.32	1140
2540.12	1184
2541.93	1142
2543.74	1126
2545.54	1122
2547.35	1176
2549.15	1164
2550.96	1148
2552.76	1070
2554.56	1130
2556.37	1070
2558.17	1110
2559.97	1132
2561.77	1100
2563.58	1068
2565.38	1108
2567.18	1052
2568.97	1102
2570.77	1100
2572.57	1082
2574.37	1110
2576.17	1084
2577.96	1028
2579.76	1056
2581.55	1012
2583.35	1052
2585.14	1082
2586.94	1046
2588.73	1022
2590.52	1050
2592.32	1038
2594.11	1072
2595.9	1036
2597.69	1038
2599.48	1030
2601.27	1022
2603.06	1026
2604.85	1042
2606.64	1016
2608.42	996
2610.21	1034
2612	1024
2613.78	968
2615.57	984
2617.36	998
2619.14	996
2620.92	1024
2622.71	984
2624.49	984
2626.27	1032
2628.05	958
2629.84	962
2631.62	998
2633.4	994
2635.18	954
2636.96	946
2638.74	948
2640.51	966
2642.29	932
2644.07	976
2645.85	980
2647.62	914
2649.4	916
2651.17	974
2652.95	926
2654.72	902
2656.5	904
2658.27	896
2660.04	902
2661.81	904
2663.58	916
2665.35	902
2667.13	928
2668.9	934
2670.66	912
2672.43	890
2674.2	878
2675.97	932
2677.74	890
2679.5	890
2681.27	872
2683.04	884
2684.8	920
2686.57	862
2688.33	838
2690.09	880
2691.86	884
2693.62	854
2695.38	892
2697.15	876
2698.91	812
2700.67	804
2702.43	840
2704.19	888
2705.95	822
2707.7	844
2709.46	850
2711.22	838
2712.98	832
2714.73	818
2716.49	824
2718.25	848
2720	854
2721.76	832
2723.51	820
2725.26	862
2727.02	788
2728.77	850
2730.52	816
2732.27	838
2734.02	806
2735.77	810
2737.52	784
2739.27	800
2741.02	788
2742.77	782
2744.52	778
2746.27	762
2748.01	738
2749.76	772
2751.51	766
2753.25	770
2755	760
2756.74	774
2758.48	774
2760.23	762
2761.97	766
2763.71	754
2765.45	730
2767.19	760
2768.94	740
2770.68	724
2772.42	768
2774.16	744
2775.89	792
2777.63	726
2779.37	728
2781.11	688
2782.84	706
2784.58	720
2786.32	706
2788.05	718
2789.79	706
2791.52	680
2793.25	722
2794.99	700
2796.72	694
2798.45	694
2800.18	690
2801.92	724
2803.65	701
2805.38	694
2807.11	678
2808.84	684
2810.57	662
2812.29	686
2814.02	664
2815.75	696
2817.47	676
2819.2	660
2820.93	688
2822.65	664
2824.38	668
2826.1	664
2827.82	616
2829.55	644
2831.27	656
2832.99	680
2834.71	608
2836.44	642
2838.16	636
2839.88	632
2841.6	652
2843.32	646
2845.03	634
2846.75	656
2848.47	638
2850.19	630
2851.9	624
2853.62	622
2855.34	602
2857.05	608
2858.77	602
2860.48	606
2862.19	618
2863.91	604
2865.62	596
2867.33	580
2869.04	602
2870.76	570
2872.47	628
2874.18	594
2875.89	592
2877.6	570
2879.31	580
2881.01	582
2882.72	598
2884.43	600
2886.14	590
2887.84	556
2889.55	554
2891.25	582
2892.96	570
2894.66	552
2896.37	566
2898.07	560
2899.77	548
2901.48	572
2903.18	558
2904.88	558
2906.58	572
2908.28	542
2909.98	572
2911.68	564
2913.38	592
2915.08	538
2916.78	538
2918.47	536
2920.17	562
2921.87	546
2923.56	550
2925.26	562
2926.95	556
2928.65	562
2930.34	532
2932.04	520
2933.73	560
2935.42	554
2937.11	556
2938.81	542
2940.5	538
2942.19	560
2943.88	524
2945.57	542
2947.26	504
2948.95	536
2950.64	528
2952.32	514
2954.01	522
2955.7	528
2957.38	544
2959.07	544
2960.75	500
2962.44	498
2964.12	506
2965.81	520
2967.49	518
2969.17	504
2970.86	500
2972.54	526
2974.22	472
2975.9	524
2977.58	500
2979.26	496
2980.94	478
2982.62	482
2984.3	488
2985.98	466
2987.66	476
2989.33	446
2991.01	484
2992.69	474
2994.36	454
2996.04	480
2997.71	486
2999.39	490