File: muestras/magnetita2/roy_mg_r2_04.txt
#Acq. time (s)=	25
#Accumulations=	3
#Range (cm-¹)=	100...4000
#Windows=	3
#Autofocus=	Off
#AutoExposure=	Off
#Spike filter=	Multiple accum.
#Delay time (s)=	0
#Binning=	1
#Readout mode=	Signal
#DeNoise=	Off
#ICS correction=	Off
#Dark correction=	Off
#Inst. Process=	Off
#Instrument=	LabRAM HR Evol
#Detector=	Syncerity OE
#Objective=	x100_VIS
#Grating=	600 (500nm)
#ND Filter=	10%
#Laser=	532nm_Edge
#Hole=	150.001
#Range=	Visible
#Project=	Omar
#Sample=
#Site=	02-05-23
#Title=	roy_mg_r2
#Remark=
#Date=	02.05.2023 17:32
#Acquired=	02.05.2023 17:32:13
101.414	7083
105.083	7181.47
108.751	7331.95
112.417	7508.42
116.08	7485.89
119.743	7569.37
123.405	7501.84
127.065	7474.31
130.724	7493.79
134.38	7486.26
138.036	7715.73
141.691	7659.21
145.342	7779.68
148.994	7801.16
152.642	7853.63
156.291	7846.1
159.936	7851.58
163.583	7911.05
167.225	7933.52
170.868	7917
174.508	7876.47
178.149	7952.94
181.786	8003.42
185.421	8060.89
189.057	8047.36
192.69	8055.84
196.321	8088.31
199.953	8187.79
203.581	8140.26
207.208	8226.73
210.834	8210.21
214.458	8106.68
218.081	8190.15
221.702	8168.63
225.324	8198.1
228.943	8152.57
232.56	8205.05
236.175	8167.52
239.79	8187.99
243.4	8327.47
247.012	8299.94
250.622	8402.42
254.23	8438.89
257.838	8473.36
261.444	8474.83
265.048	8503.31
268.649	8528.78
272.251	8393.26
275.851	8440.73
279.447	8400.2
283.045	8381.68
286.641	8441.15
290.233	8416.62
293.827	8483.1
297.416	8439.57
301.007	8486.04
304.594	8572.52
308.182	8650.99
311.766	8630.46
315.351	8681.94
318.932	8745.41
322.512	8719.88
326.093	8734.36
329.67	8640.83
333.246	8681.31
336.822	8776.78
340.395	8598.25
343.967	8714.73
347.538	8687.2
351.106	8716.67
354.674	8724.15
358.24	8760.62
361.805	8735.09
365.37	8724.57
368.933	8839.04
372.493	8855.52
376.05	8876.99
379.608	8817.46
383.165	8940.94
386.72	8983.41
390.274	9034.88
393.826	8946.36
397.377	9055.83
400.925	9155.3
404.473	9112.78
408.02	9014.25
411.566	9091.72
415.108	9009.2
418.651	9038.67
422.19	8958.14
425.73	8978.62
429.269	8996.09
432.804	9201.56
436.34	8999.04
439.873	9027.51
443.404	9115.99
446.936	9155.46
450.465	9205.93
453.994	9236.41
457.52	9337.88
461.044	9323.35
464.569	9425.83
468.091	9407.3
471.612	9456.77
475.131	9538.25
478.648	9586.72
482.165	9580.19
485.682	9451.67
489.195	9462.14
492.708	9548.61
496.219	9433.09
499.728	9500.56
503.236	9453.04
506.743	9484.51
510.249	9511.98
513.751	9493.46
517.254	9497.93
520.755	9568.4
524.256	9564.88
527.755	9604.35
531.252	9603.82
534.746	9712.3
538.241	9689.77
541.734	9675.24
545.225	9792.72
548.715	9859.19
552.203	9870.67
555.691	9874.14
559.178	9892.61
562.661	9851.09
566.143	9963.56
569.626	9901.03
573.106	9819.51
576.586	9913.98
580.063	9866.45
583.538	9894.93
587.014	9967.4
590.487	9864.87
593.959	9941.35
597.429	9996.82
600.9	9886.29
604.367	9990.77
607.834	9948.24
611.299	9918.71
614.762	10082.2
618.224	10124.7
621.685	10216.1
625.145	10205.6
628.603	10164.1
632.06	10318.6
635.516	10331
638.97	10309.5
642.423	10407
645.875	10472.5
649.323	10449.9
652.773	10448.4
656.22	10470.9
659.667	10398.3
663.11	10465.8
666.554	10424.3
669.994	10549.8
673.436	10479.2
676.876	10410.7
680.312	10450.2
683.75	10472.7
687.184	10387.1
690.618	10396.6
694.05	10440.1
697.48	10459.6
700.911	10529
704.338	10495.5
707.764	10585
711.191	10535.4
714.615	10513.9
718.037	10573.4
721.458	10653.9
724.878	10609.3
728.299	10635.8
731.716	10787.3
735.132	10631.8
738.546	10681.2
741.959	10620.7
745.371	10677.2
748.782	10678.7
752.192	10657.1
755.6	10720.6
759.005	10730.1
762.41	10581.6
765.814	10717
769.217	10573.5
772.619	10643
776.017	10668.4
779.417	10707.9
782.814	10691.4
786.209	10741.9
789.604	10711.3
792.996	10763.8
796.389	10573.3
799.779	10634.8
803.169	10761.2
806.556	10649.7
809.943	10840.2
813.328	10793.7
816.713	10718.1
820.094	10747.6
823.475	10848.1
826.856	10811.5
830.234	10873
833.611	10844.5
836.986	10823
840.361	10917.4
843.734	10961.9
847.107	10994.4
850.478	11031.9
853.847	10935.3
857.215	10956.8
860.581	10903.3
863.947	10995.8
867.309	10995.2
870.671	11091.7
874.033	11073.2
877.393	11014.6
880.752	10983.1
884.11	10944.6
887.465	11042.1
890.82	11005.5
894.174	10973
897.525	10927.5
900.876	11051
904.226	10970.4
907.573	11149.9
910.921	11060.4
914.266	11154.9
917.611	11054.3
920.953	11188.8
924.294	11188.3
927.635	11225.8
930.973	11174.2
934.31	11248.7
937.648	11261.2
940.983	11358.6
944.316	11331.1
947.648	11382.6
950.981	11306.1
954.31	11376.5
957.639	11403
960.966	11472.5
964.292	11403
967.616	11535.4
970.939	11502.9
974.262	11436.4
977.582	11502.9
980.902	11433.3
984.219	11467.8
987.536	11449.3
990.852	11488.8
994.166	11411.2
997.48	11400.7
1000.79	11473.2
1004.1	11511.6
1007.41	11437.1
1010.72	11383.6
1014.02	11397.1
1017.33	11464.5
1020.63	11506
1023.94	11533.5
1027.24	11535
1030.54	11557.4
1033.84	11502.9
1037.13	11591.4
1040.43	11769.9
1043.73	11533.3
1047.02	11669.8
1050.31	11787.3
1053.6	11685.7
1056.89	11763.2
1060.18	11838.7
1063.47	11864.2
1066.75	11812.6
1070.04	11936.1
1073.32	12014.6
1076.6	12056.1
1079.88	11892.5
1083.16	12021
1086.44	11976.5
1089.72	11977
1092.99	11937.4
1096.27	12014.9
1099.54	11950.4
1102.82	11981.9
1106.08	11852.3
1109.35	12019.8
1112.62	11955.3
1115.89	12067.7
1119.16	11999.2
1122.42	11927.7
1125.68	11971.2
1128.94	11993.6
1132.2	11878.1
1135.46	11993.6
1138.72	12016.1
1141.98	12024.5
1145.23	12079
1148.49	12071.5
1151.74	12077
1154.99	12150.4
1158.24	12154.9
1161.49	12120.4
1164.74	12265.8
1167.99	12283.3
1171.23	12367.8
1174.48	12423.3
1177.72	12445.7
1180.96	12524.2
1184.2	12675.7
1187.44	12574.2
1190.68	12627.6
1193.91	12621.1
1197.15	12696.6
1200.38	12721.1
1203.62	12560.5
1206.85	12725
1210.08	12761.5
1213.31	12636
1216.54	12846.4
1219.76	12864.9
1222.99	12818.4
1226.21	12761.8
1229.43	12924.3
1232.66	12998.8
1235.88	12820.3
1239.1	12880.7
1242.31	12890.2
1245.53	12987.7
1248.75	12808.2
1251.96	12951.6
1255.17	12983.1
1258.39	12930.6
1261.6	12996.1
1264.8	13093.5
1268.01	13124
1271.22	13195.5
1274.43	13251.9
1277.63	13247.4
1280.83	13281.9
1284.04	13392.4
1287.23	13413.8
1290.43	13406.3
1293.63	13376.8
1296.83	13502.3
1300.03	13457.7
1303.22	13608.2
1306.41	13678.7
1309.61	13706.2
1312.8	13785.6
1315.99	13727.1
1319.17	13921.6
1322.36	13907
1325.55	13724.5
1328.73	13816
1331.92	13822
1335.1	13743.9
1338.28	13836.4
1341.46	13878.9
1344.64	13918.4
1347.81	13888.8
1350.99	13841.3
1354.17	13847.8
1357.34	13727.3
1360.51	13878.7
1363.68	13776.2
1366.85	13800.7
1370.02	13885.2
1373.19	13899.6
1376.35	13715.1
1379.52	13876.6
1382.68	13875
1385.85	13958.5
1389.01	14013
1392.17	13940.5
1395.33	13978.9
1398.49	13995.4
1401.64	14116.9
1404.8	14096.4
1407.95	14040.8
1411.11	14186.3
1414.26	14092.8
1417.41	14163.3
1420.56	14062.7
1423.71	14213.2
1426.85	14152.7
1430	14239.2
1433.14	14323.6
1436.29	14153.1
1439.43	14351.6
1442.57	14210
1445.71	14305.5
1448.85	14168
1451.99	14168.5
1455.12	14194.9
1458.26	14115.4
1461.39	14221.9
1464.52	14146.4
1467.66	14294.8
1470.79	14141.3
1473.92	14224.8
1477.04	14155.3
1480.17	14181.7
1483.29	14224.2
1486.42	14126.7
1489.54	14177.1
1492.67	14245.6
1495.78	14379.1
1498.91	14318.6
1502.02	14309
1505.14	14439.5
1508.26	14546
1511.37	14548.5
1514.49	14556.9
1517.6	14587.4
1520.71	14666.9
1523.82	14729.4
1526.93	14843.8
1530.04	14900.3
1533.14	14958.8
1536.25	15016.3
1539.35	15134.7
1542.46	15040.2
1545.56	15241.7
1548.66	15163.1
1551.76	15361.6
1554.86	15334.1
1557.95	15361.6
1561.05	15200
1564.14	15306.5
1567.24	15254
1570.33	15279.5
1573.42	15242.9
1576.51	15288.4
1579.6	15298.9
1582.69	15228.4
1585.77	15204.8
1588.86	15030.3
1591.94	15218.8
1595.03	15077.2
1598.11	15023.7
1601.19	15096.2
1604.27	14940.7
1607.35	15067.1
1610.42	14742.6
1613.5	14831.1
1616.57	14716.6
1619.65	14698
1622.72	14690.5
1625.79	14565
1628.86	14629.5
1631.93	14579.9
1635	14563.4
1638.07	14505.9
1641.13	14468.3
1644.2	14383.8
1647.26	14385.5
1650.32	14497.5
1653.38	14396
1656.44	14211.8
1659.5	14422.4
1662.56	14318.9
1665.62	14255.3
1668.67	14241.5
1671.72	14323.2
1674.78	14206.9
1677.83	14173.1
1680.88	14194.9
1683.93	14234.9
1686.98	14127.5
1690.03	14096.9
1693.07	14151.5
1696.12	14150.2
1699.16	14044.4
1702.2	14017.4
1705.24	13995.8
1708.28	14002.8
1711.32	13932.9
1714.36	13843.7
1717.4	13811.9
1720.43	13865.1
1723.47	13873.6
1726.5	13759.4
1729.53	13759.6
1732.56	13776.6
1735.59	13683
1738.62	13719.3
1741.65	13684.8
1744.68	13712.9
1747.7	13612.8
1750.73	13675.5
1753.75	13640.5
1756.77	13630.9
1759.79	13623.8
1762.81	13672.9
1765.83	13711.6
1768.85	13676.6
1771.87	13683.5
1774.88	13731.7
1777.9	13757.1
1780.91	13625
1783.92	13682
1786.93	13755.6
1789.94	13723.2
1792.95	13720.3
1795.95	13702.8
1798.96	13786.1
1801.05	13735.7
1804.06	13644
1807.08	13806.3
1810.1	13807.6
1813.11	13809.8
1816.12	13710.1
1819.14	13705.4
1822.15	13756.7
1825.16	13788
1828.17	13778.2
1831.17	13769.5
1834.18	13758.8
1837.19	13675.1
1840.19	13758.4
1843.19	13817.6
1846.2	13776.9
1849.2	13754.2
1852.2	13654.5
1855.2	13714.8
1858.19	13573
1861.19	13530.3
1864.19	13635.6
1867.18	13623.9
1870.17	13611.2
1873.16	13555.4
1876.15	13679.7
1879.14	13682
1882.13	13625.3
1885.12	13622.6
1888.11	13572.8
1891.09	13654.1
1894.08	13603.8
1897.06	13683.5
1900.04	13689.3
1903.02	13659
1906	13658.7
1908.98	13823.4
1911.96	13747.1
1914.94	13683.8
1917.91	13777.6
1920.89	13694.3
1923.86	13737
1926.83	13772.7
1929.8	13789.4
1932.77	13787.1
1935.74	13748.8
1938.71	13865.6
1941.68	13785.3
1944.64	13717
1947.61	13778.7
1950.57	13811.4
1953.53	13684.1
1956.49	13581.8
1959.46	13634.6
1962.41	13592.3
1965.37	13641
1968.33	13680.7
1971.29	13713.4
1974.24	13668.1
1977.19	13579.9
1980.15	13656.6
1983.1	13551.3
1986.05	13606
1989	13592.7
1991.95	13567.4
1994.89	13580.1
1997.84	13566.9
2000.78	13536.6
2003.73	13578.3
2006.67	13581
2009.61	13495.7
2012.55	13563.4
2015.49	13505.2
2018.43	13571.9
2021.37	13610.6
2024.3	13647.3
2027.24	13535
2030.17	13594.7
2033.11	13605.4
2036.04	13624.2
2038.97	13631.9
2041.9	13576.6
2044.83	13703.3
2047.76	13590
2050.68	13530.7
2053.61	13546.5
2056.53	13542.2
2059.46	13627.9
2062.38	13553.6
2065.3	13597.3
2068.22	13583
2071.14	13597.7
2074.06	13544.5
2076.98	13528.2
2079.89	13442.9
2082.81	13484.6
2085.72	13396.3
2088.63	13448
2091.54	13543.7
2094.45	13385.5
2097.36	13496.2
2100.27	13315.9
2103.18	13323.6
2106.09	13356.3
2108.99	13319
2111.9	13300.8
2114.8	13337.5
2117.7	13340.2
2120.6	13329.9
2123.5	13272.6
2126.4	13215.3
2129.3	13260
2132.19	13264.8
2135.09	13262.5
2137.99	13308.2
2140.88	13379.9
2143.77	13214.6
2146.66	13281.3
2149.55	13299.1
2152.44	13323.8
2155.33	13377.5
2158.22	13304.2
2161.1	13307.9
2163.99	13337.6
2166.88	13458.3
2169.76	13286.1
2172.64	13375.8
2175.52	13402.5
2178.4	13341.2
2181.28	13324.9
2184.16	13342.6
2187.03	13410.3
2189.91	13399.1
2192.78	13316.8
2195.66	13319.5
2198.53	13289.2
2201.4	13281.9
2204.27	13338.6
2207.14	13166.4
2210.01	13224.1
2212.88	13247.8
2215.74	13173.5
2218.61	13134.2
2221.47	13151.9
2224.34	13056.6
2227.2	13011.4
2230.06	13036.1
2232.92	12924.8
2235.78	12880.5
2238.64	12928.2
2241.49	12830.9
2244.35	12846.7
2247.2	12811.4
2250.06	12850.1
2252.91	12780.8
2255.76	12812.5
2258.61	12718.2
2261.46	12800.9
2264.31	12738.7
2267.16	12702.4
2270.01	12769.1
2272.85	12700.8
2275.7	12661.5
2278.54	12701.2
2281.38	12689.9
2284.22	12642.7
2287.06	12769.4
2289.9	12776.1
2292.74	12772.8
2295.58	12698.5
2298.41	12847.2
2301.25	12885
2304.09	12811.7
2306.92	12846.4
2309.75	12888.1
2312.58	12934.8
2315.41	12948.5
2318.24	12821.2
2321.07	12942
2323.9	12868.7
2326.72	12836.4
2329.55	12818.1
2332.37	12887.8
2335.19	12779.5
2338.02	12849.3
2340.84	12842
2343.66	12782.7
2346.47	12883.4
2349.29	12770.1
2352.11	12731.8
2354.93	12812.5
2357.74	12744.3
2360.55	12784
2363.37	12653.7
2366.18	12563.4
2368.99	12609.1
2371.8	12619.8
2374.61	12437.5
2377.42	12576.3
2380.22	12483
2383.03	12539.7
2385.83	12552.4
2388.64	12492.1
2391.44	12510.8
2394.24	12429.6
2397.04	12431.3
2399.84	12442
2402.64	12467.7
2405.44	12575.4
2408.23	12544.1
2411.03	12376.8
2413.82	12501.6
2416.62	12451.3
2419.41	12364
2422.2	12321.7
2424.99	12377.4
2427.78	12453.1
2430.57	12472.9
2433.36	12467.6
2436.14	12505.3
2438.93	12462
2441.71	12592.7
2444.5	12546.4
2447.28	12534.1
2450.06	12619.9
2452.84	12688.6
2455.62	12708.3
2458.4	12636
2461.18	12548.7
2463.95	12611.4
2466.73	12613.2
2469.5	12720.9
2472.28	12618.6
2475.05	12613.3
2477.82	12674
2480.59	12760.7
2483.36	12688.4
2486.13	12731.2
2488.9	12652.9
2491.66	12756.6
2494.43	12666.3
2497.19	12655
2499.96	12741.7
2502.72	12612.4
2505.48	12663.2
2508.24	12558.9
2511	12562.6
2513.76	12569.3
2516.52	12576
2519.28	12499.7
2522.03	12457.5
2524.79	12525.2
2527.54	12400.9
2530.29	12521.6
2533.04	12481.3
2535.8	12426
2538.54	12435.7
2541.29	12445.5
2544.04	12456.2
2546.79	12439.9
2549.53	12366.6
2552.28	12493.3
2555.02	12569
2557.77	12393.8
2560.51	12443.5
2563.25	12422.2
2565.99	12387.9
2568.73	12509.6
2571.47	12422.3
2574.2	12417
2576.94	12465.8
2579.67	12500.5
2582.41	12449.2
2585.14	12609.9
2587.87	12410.6
2590.6	12520.3
2593.33	12539
2596.06	12650.8
2598.79	12607.5
2601.52	12695.2
2604.24	12674.9
2606.97	12663.6
2609.7	12705.3
2612.42	12754.1
2615.14	12660.8
2617.86	12626.5
2620.58	12753.2
2623.3	12828.9
2626.02	12807.6
2628.74	12846.3
2631.45	12845.1
2634.17	12721.8
2636.88	12746.5
2639.6	12745.2
2642.31	12824.9
2645.02	12788.6
2647.73	12727.4
2650.44	12736.1
2653.15	12796.8
2655.86	12781.5
2658.57	12763.2
2661.27	12699.9
2663.98	12742.6
2666.68	12646.4
2669.38	12834.1
2672.09	12685.8
2674.79	12670.5
2677.49	12704.2
2680.19	12649.9
2682.89	12614.6
2685.58	12655.9
2688.28	12707.1
2690.98	12681.8
2693.67	12702.5
2696.36	12728.2
2699.05	12607.9
2701.75	12669.7
2704.44	12712.4
2707.13	12600.1
2709.82	12681.8
2712.5	12599.5
2715.19	12665.2
2717.88	12688.9
2720.56	12694.7
2723.25	12598.4
2725.93	12642.1
2728.61	12710.8
2731.29	12610.5
2733.97	12624.2
2736.65	12776
2739.33	12691.7
2742.01	12788.4
2744.68	12715.1
2747.36	12772.8
2750.03	12771.5
2752.71	12725.2
2755.38	12758
2758.05	12818.7
2760.72	12700.4
2763.39	12862.1
2766.06	12836.8
2768.73	12800.5
2771.39	12790.2
2774.06	12925
2776.72	12919.7
2779.39	12911.4
2782.05	12881.1
2784.72	12919.8
2787.38	12931.5
2790.04	12985.3
2792.7	12964
2795.35	12935.7
2798.01	12892.4
2800.67	12977.1
2803.32	12928.8
2805.98	12867.5
2808.63	12883.3
2811.29	12788
2813.94	12921.7
2816.59	12789.4
2819.24	12878.1
2821.89	12979.8
2824.53	12909.6
2827.18	12900.3
2829.83	12897
2832.47	12877.7
2835.12	12906.4
2837.76	12980.1
2840.4	12984.8
2843.04	12999.6
2845.69	12876.3
2848.33	12932
2850.96	13038.7
2853.6	13013.4
2856.24	12965.1
2858.87	12907.8
2861.51	13028.6
2864.14	12915.3
2866.78	12936
2869.41	13016.7
2872.04	13028.4
2874.67	13024.1
2877.3	13076.9
2879.93	13023.6
2882.56	13088.3
2885.18	12999
2887.81	12922.7
2890.43	13039.4
2893.06	12957.1
2895.68	12975.9
2898.3	12995.6
2900.93	13029.3
2903.55	13087
2906.17	13015.7
2908.78	12954.4
2911.4	12978.2
2914.02	12938.9
2916.63	13013.6
2919.25	13015.3
2921.86	12985
2924.48	12961.7
2927.09	12957.4
2929.7	12914.2
2932.31	12917.9
2934.92	12967.6
2937.53	12916.3
2940.13	12877
2942.74	12913.7
2945.35	12892.5
2947.95	12893.2
2950.55	12996.9
2953.16	12871.8
2955.76	12819.5
2958.36	12945.6
2960.96	12883.4
2963.56	12896.3
2966.16	12786.6
2968.76	12793.9
2971.35	12774.6
2973.95	12737.5
2976.54	12789.5
2979.14	12779.5
2981.73	12818.8
2984.32	12782.8
2986.91	12791
2989.5	12745.6
2992.09	12752.5
2994.68	12711.8
2997.27	12707.8
2999.85	12709.6
3002.44	12688.9
3005.02	12689.4
3007.61	12730.8
3010.19	12632.4
3012.77	12691.5
3015.35	12687.3
3017.93	12666.3
3020.51	12688.8
3023.09	12660.1
3025.67	12684.7
3028.25	12637.3
3030.82	12600.7
3033.4	12657
3035.97	12684.9
3038.54	12579.9
3041.12	12613.3
3043.69	12637.9
3046.26	12608.8
3048.83	12628.1
3051.4	12617.9
3053.96	12605.2
3056.53	12608.5
3059.1	12535.2
3061.66	12601.1
3064.23	12552.4
3066.79	12633.9
3069.35	12571.7
3071.91	12577.3
3074.47	12542.8
3077.03	12596.2
3079.59	12474.2
3082.15	12536.3
3083.52	12553
3086.08	12497.3
3088.65	12505.7
3091.22	12584
3093.79	12500.3
3096.35	12452.7
3098.92	12565
3101.48	12537.3
3104.04	12515.7
3106.6	12516
3109.16	12498.3
3111.72	12513.7
3114.28	12478
3116.84	12479.3
3119.4	12571.7
3121.95	12542
3124.51	12571.3
3127.06	12471.7
3129.62	12519
3132.17	12610.3
3134.72	12641.7
3137.27	12592
3139.82	12680.3
3142.37	12541.7
3144.92	12624
3147.47	12713.3
3150.01	12568.7
3152.56	12500
3155.1	12636.3
3157.65	12735.7
3160.19	12640
3162.73	12563.3
3165.28	12509.7
3167.81	12624
3170.35	12594.3
3172.89	12534.7
3175.43	12646
3177.97	12514.3
3180.5	12600.7
3183.04	12566
3185.57	12560.3
3188.11	12507.7
3190.64	12438
3193.17	12428.3
3195.7	12538.7
3198.23	12579
3200.76	12393.3
3203.29	12420.7
3205.82	12365
3208.35	12383.3
3210.87	12220.7
3213.4	12309
3215.92	12252.3
3218.44	12259.7
3220.97	12252
3223.49	12288.3
3226.01	12279.7
3228.53	12250
3231.05	12251.4
3233.56	12241.7
3236.08	12234
3238.6	12212.4
3241.11	12218.7
3243.63	12209
3246.14	12152.4
3248.65	12133.7
3251.17	12093
3253.68	12118.4
3256.19	12184.7
3258.7	12188
3261.21	12149.4
3263.71	12055.7
3266.22	12235
3268.73	12135.4
3271.23	12122.7
3273.74	12110
3276.24	12174.4
3278.74	12179.7
3281.24	12153
3283.74	12147.4
3286.24	12245.7
3288.74	12157
3291.24	12193.4
3293.74	12191.7
3296.23	12175
3298.73	12318.4
3301.23	12209.7
3303.72	12283
3306.21	12166.4
3308.71	12245.7
3311.2	12230
3313.69	12260.4
3316.18	12186.7
3318.67	12195
3321.15	12172.4
3323.64	12137.7
3326.13	12213
3328.61	12123.4
3331.1	12114.7
3333.58	12115
3336.07	12100.4
3338.55	12038.7
3341.03	12075
3343.51	12033.4
3345.99	12063.7
3348.47	12063
3350.95	12018.4
3353.42	12006.7
3355.9	11950
3358.38	12051.4
3360.85	11963.7
3363.32	11964
3365.8	11807.4
3368.27	11886.7
3370.74	11818
3373.21	11894.4
3375.68	11961.7
3378.15	11844
3380.62	11795.4
3383.08	11715.7
3385.55	11819
3388.02	11782.4
3390.48	11789.7
3392.94	11833
3395.41	11750.4
3397.87	11807.7
3400.33	11773
3402.79	11791.4
3405.25	11891.7
3407.71	11869
3410.17	11812.4
3412.62	11820.7
3415.08	11745
3417.54	11776.4
3419.99	11832.7
3422.44	11873
3424.9	11845.4
3427.35	11872.7
3429.8	11873
3432.25	11853.4
3434.7	11976.7
3437.15	11897
3439.6	11948.4
3442.04	11981.7
3444.49	11953
3446.94	11965.4
3449.38	11965.7
3451.82	11911
3454.27	11949.4
3456.71	12023.7
3459.15	12068
3461.59	11963.4
3464.03	11986.7
3466.47	11948
3468.91	11884.4
3471.34	11834.7
3473.78	11983
3476.22	11979.4
3478.65	11972.7
3481.08	11918
3483.52	11929.4
3485.95	11798.7
3488.38	11871
3490.81	11902.4
3493.24	11795.7
3495.67	11747
3498.1	11744.4
3500.53	11685.7
3502.95	11716
3505.38	11638.4
3507.8	11721.7
3510.23	11656
3512.65	11599.4
3515.07	11547.7
3517.5	11446
3519.92	11524.4
3522.34	11490.7
3524.76	11481
3527.17	11471.4
3529.59	11419.7
3532.01	11466
3534.42	11412.4
3536.84	11305.7
3539.25	11355
3541.67	11388.4
3544.08	11352.7
3546.49	11347
3548.9	11343.4
3551.31	11400.7
3553.72	11319
3556.13	11331.4
3558.54	11288.7
3560.95	11349
3563.35	11327.4
3565.76	11352.7
3568.16	11312
3570.57	11365.4
3572.97	11444.7
3575.37	11478
3577.77	11351.4
3580.17	11422.7
3582.57	11461
3584.97	11392.4
3587.37	11464.7
3589.77	11532
3592.17	11438.4
3594.56	11525.7
3596.96	11412
3599.35	11531.4
3601.74	11499.7
3604.14	11476
3606.53	11425.4
3608.92	11658.7
3611.31	11571
3613.7	11523.4
3616.09	11453.7
3618.47	11457
3620.86	11451.4
3623.25	11621.7
3625.63	11425
3628.02	11458.4
3630.4	11467.7
3632.78	11450
3635.17	11488.4
3637.55	11377.7
3639.93	11409
3642.31	11412.4
3644.69	11433.7
3647.06	11392
3649.44	11358.4
3651.82	11347.7
3654.2	11281
3656.57	11217.4
3658.94	11217.7
3661.32	11152
3663.69	11198.4
3666.06	11175.7
3668.43	11095
3670.8	11080.4
3673.17	11101.7
3675.54	11119
3677.91	10975.4
3680.28	11009.7
3682.64	10937
3685.01	10908.4
3687.37	10994.7
3689.74	11077
3692.1	10984.4
3694.46	10879.7
3696.82	10923
3699.18	10916.4
3701.54	10943.7
3703.9	10944
3706.26	10849.4
3708.62	10931.7
3710.98	10880
3713.33	10912.4
3715.69	10914.7
3718.04	10952
3720.4	10919.4
3722.75	10940.7
3725.1	10913
3727.45	10861.4
3729.8	11019.7
3732.15	10980
3734.5	10935.4
3736.85	11010.7
3739.2	11021
3741.54	10962.4
3743.89	10919.7
3746.23	10995.1
3748.58	11082.4
3750.92	11093.7
3753.27	10976.1
3755.61	11067.4
3757.95	11055.7
3760.29	11070.1
3762.63	11054.4
3764.97	11027.7
3767.3	11053.1
3769.64	11092.4
3771.98	11152.7
3774.32	11039.1
3776.65	11053.4
3778.99	11058.7
3781.32	10901.1
3783.65	11033.4
3785.98	11004.7
3788.31	10855.1
3790.64	10959.4
3792.97	11009.7
3795.3	10811.1
3797.63	10826.4
3799.96	10850.7
3802.28	10764.1
3804.61	10801.4
3806.93	10683.7
3809.26	10727.1
3811.58	10622.4
3813.9	10644.7
3816.23	10644.1
3818.55	10650.4
3820.87	10674.7
3823.19	10643.1
3825.51	10541.4
3827.82	10598.7
3830.14	10556.1
3832.46	10588.4
3834.77	10583.7
3837.09	10437.1
3839.4	10445.4
3841.72	10410.7
3844.03	10463.1
3846.34	10340.4
3848.65	10500.7
3850.96	10428.1
3853.27	10409.4
3855.58	10352.7
3857.89	10407.1
3860.2	10419.4
3862.5	10377.7
3864.81	10400.1
3867.11	10396.4
3869.42	10507.7
3871.72	10454.1
3874.02	10473.4
3876.33	10447.7
3878.63	10447.1
3880.93	10461.4
3883.23	10429.7
3885.53	10459.1
3887.82	10569.4
3890.12	10511.7
3892.42	10535.1
3894.72	10471.4
3897.01	10540.7
3899.3	10528.1
3901.6	10446.4
3903.89	10491.7
3906.18	10520.1
3908.47	10532.4
3910.76	10480.7
3913.05	10483.1
3915.34	10476.4
3917.63	10498.7
3919.92	10507.1
3922.21	10454.4
3924.49	10414.7
3926.78	10424.1
3929.06	10431.4
3931.35	10452.7
3933.63	10318.1
3935.91	10391.4
3938.19	10404.7
3940.47	10353.1
3942.75	10393.4
3945.03	10412.7
3947.31	10280.1
3949.59	10316.4
3951.87	10247.7
3954.14	10336.1
3956.42	10231.4
3958.69	10197.7
3960.97	10117.1
3963.24	10250.4
3965.51	10124.7
3967.79	10185.1
3970.06	10160.4
3972.33	10139.7
3974.6	10011.1
3976.87	9981.4
3979.13	10078.7
3981.4	10005.1
3983.67	10067.4
3985.93	9945.73
3988.2	9961.07
3990.46	9951.4
3992.73	9992.73
3994.99	10008.1
3997.25	10028.4
3999.51	9963.73