File: muestras/magnetita2/roy_mg_r2_02.txt
#Acq. time (s)=	25
#Accumulations=	3
#Range (cm-¹)=	100...4000
#Windows=	3
#Autofocus=	Off
#AutoExposure=	Off
#Spike filter=	Multiple accum.
#Delay time (s)=	0
#Binning=	1
#Readout mode=	Signal
#DeNoise=	Off
#ICS correction=	Off
#Dark correction=	Off
#Inst. Process=	Off
#Instrument=	LabRAM HR Evol
#Detector=	Syncerity OE
#Objective=	x100_VIS
#Grating=	600 (500nm)
#ND Filter=	1%
#Laser=	532nm_Edge
#Hole=	150.001
#Range=	Visible
#Project=	Omar
#Sample=
#Site=	02-05-23
#Title=	roy_mg_r2
#Remark=
#Date=	02.05.2023 17:20
#Acquired=	02.05.2023 17:20:24
101.414	250
105.083	250.716
108.751	243.432
112.417	254.149
116.08	263.865
119.743	261.581
123.405	242.297
127.065	263.013
130.724	244.729
134.38	258.446
138.036	262.162
141.691	276.878
145.342	260.594
148.994	267.31
152.642	267.027
156.291	268.743
159.936	276.459
163.583	272.175
167.225	273.891
170.868	272.608
174.508	270.324
178.149	281.04
181.786	280.756
185.421	278.472
189.057	284.188
192.69	282.905
196.321	296.621
199.953	259.337
203.581	274.053
207.208	278.769
210.834	271.486
214.458	285.202
218.081	274.918
221.702	274.634
225.324	280.35
228.943	290.066
232.56	286.783
236.175	281.499
239.79	279.215
243.4	271.931
247.012	280.647
250.622	288.364
254.23	294.08
257.838	286.796
261.444	280.512
265.048	283.228
268.649	278.944
272.251	315.661
275.851	300.377
279.447	302.093
283.045	287.809
286.641	299.525
290.233	282.242
293.827	294.958
297.416	291.674
301.007	299.39
304.594	292.106
308.182	296.823
311.766	317.539
315.351	296.255
318.932	301.971
322.512	304.687
326.093	307.403
329.67	296.12
333.246	307.836
336.822	305.552
340.395	316.268
343.967	301.984
347.538	315.701
351.106	314.417
354.674	311.133
358.24	304.849
361.805	307.565
365.37	308.281
368.933	308.998
372.493	308.714
376.05	296.43
379.608	303.146
383.165	321.862
386.72	314.579
390.274	322.295
393.826	321.011
397.377	307.727
400.925	315.443
404.473	317.159
408.02	307.876
411.566	311.592
415.108	306.308
418.651	312.024
422.19	309.74
425.73	301.457
429.269	312.173
432.804	319.889
436.34	312.605
439.873	326.321
443.404	312.038
446.936	320.754
450.465	312.47
453.994	321.186
457.52	321.902
461.044	327.618
464.569	339.335
468.091	334.051
471.612	336.767
475.131	330.483
478.648	320.199
482.165	313.916
485.682	323.632
489.195	334.348
492.708	323.064
496.219	331.78
499.728	323.496
503.236	361.213
506.743	328.929
510.249	318.645
513.751	325.361
517.254	318.077
520.755	327.794
524.256	334.51
527.755	331.226
531.252	338.942
534.746	328.658
538.241	326.375
541.734	320.091
545.225	327.807
548.715	345.523
552.203	340.239
555.691	344.955
559.178	357.672
562.661	322.388
566.143	337.104
569.626	341.82
573.106	324.536
576.586	333.253
580.063	314.969
583.538	333.685
587.014	329.401
590.487	351.117
593.959	344.833
597.429	348.55
600.9	326.266
604.367	328.982
607.834	335.698
611.299	333.414
614.762	362.131
618.224	348.847
621.685	326.563
625.145	348.279
628.603	338.995
632.06	367.711
635.516	339.428
638.97	352.144
642.423	365.86
645.875	354.576
649.323	363.292
652.773	358.009
656.22	367.725
659.667	345.441
663.11	362.157
666.554	365.873
669.994	345.59
673.436	358.306
676.876	369.022
680.312	365.738
683.75	361.454
687.184	360.17
690.618	344.887
694.05	354.603
697.48	370.319
700.911	356.035
704.338	375.751
707.764	357.468
711.191	369.184
714.615	336.9
718.037	356.616
721.458	354.332
724.878	353.048
728.299	355.765
731.716	367.481
735.132	351.197
738.546	351.913
741.959	345.629
745.371	354.346
748.782	371.062
752.192	368.778
755.6	354.494
759.005	366.21
762.41	350.926
765.814	340.643
769.217	346.359
772.619	342.075
776.017	359.791
779.417	355.507
782.814	344.224
786.209	329.94
789.604	341.656
792.996	332.372
796.389	343.088
799.779	347.805
803.169	339.521
806.556	350.237
809.943	349.953
813.328	356.669
816.713	370.385
820.094	353.102
823.475	351.818
826.856	347.534
830.234	341.25
833.611	353.966
836.986	367.683
840.361	346.399
843.734	349.115
847.107	357.831
850.478	342.547
853.847	365.263
857.215	358.98
860.581	363.696
863.947	355.412
867.309	366.128
870.671	347.844
874.033	351.561
877.393	364.277
880.752	366.993
884.11	359.709
887.465	353.425
890.82	354.142
894.174	353.858
897.525	367.574
900.876	415.29
904.226	361.006
907.573	360.722
910.921	362.439
914.266	352.155
917.611	355.871
920.953	352.587
924.294	373.303
927.635	370.02
930.973	371.736
934.31	362.452
937.648	343.168
940.983	351.884
944.316	369.6
947.648	360.317
950.981	358.033
954.31	369.749
957.639	367.465
960.966	382.181
964.292	357.898
967.616	356.614
970.939	357.33
974.262	366.046
977.582	369.762
980.902	361.478
984.219	372.195
987.536	374.911
990.852	360.627
994.166	354.343
997.48	350.059
1000.79	346.776
1004.1	355.492
1007.41	348.208
1010.72	357.924
1014.02	354.64
1017.33	370.357
1020.63	368.073
1023.94	364.789
1027.24	372.505
1030.54	354.221
1033.84	337.937
1037.13	353.654
1040.43	348.37
1043.73	341.086
1047.02	356.802
1050.31	370.518
1053.6	386.235
1056.89	380.951
1060.18	362.667
1063.47	370.383
1066.75	369.099
1070.04	366.815
1073.32	376.532
1076.6	368.248
1079.88	372.964
1083.16	358.68
1086.44	374.396
1089.72	370.113
1092.99	375.829
1096.27	356.545
1099.54	365.261
1102.82	354.977
1106.08	366.693
1109.35	363.41
1112.62	364.126
1115.89	359.842
1119.16	362.558
1122.42	369.274
1125.68	358.991
1128.94	347.707
1132.2	353.423
1135.46	366.139
1138.72	376.855
1141.98	364.572
1145.23	364.288
1148.49	348.004
1151.74	357.72
1154.99	351.436
1158.24	360.152
1161.49	370.869
1164.74	362.585
1167.99	348.301
1171.23	369.017
1174.48	376.733
1177.72	356.45
1180.96	361.166
1184.2	350.882
1187.44	365.598
1190.68	362.314
1193.91	373.03
1197.15	360.747
1200.38	372.463
1203.62	355.179
1206.85	361.895
1210.08	372.611
1213.31	365.328
1216.54	376.044
1219.76	389.76
1222.99	354.476
1226.21	373.192
1229.43	370.909
1232.66	354.625
1235.88	370.341
1239.1	376.057
1242.31	351.773
1245.53	366.489
1248.75	363.206
1251.96	351.922
1255.17	373.638
1258.39	363.354
1261.6	367.07
1264.8	365.787
1268.01	360.503
1271.22	377.219
1274.43	378.935
1277.63	366.651
1280.83	366.367
1284.04	372.084
1287.23	364.8
1290.43	378.516
1293.63	369.232
1296.83	380.948
1300.03	361.665
1303.22	365.381
1306.41	363.097
1309.61	369.813
1312.8	379.529
1315.99	367.245
1319.17	384.962
1322.36	376.678
1325.55	365.394
1328.73	366.11
1331.92	373.326
1335.1	368.543
1338.28	375.259
1341.46	365.975
1344.64	389.691
1347.81	367.407
1350.99	374.124
1354.17	513.84
1357.34	373.556
1360.51	365.272
1363.68	374.988
1366.85	370.704
1370.02	357.421
1373.19	363.137
1376.35	380.853
1379.52	370.569
1382.68	369.285
1385.85	362.002
1389.01	381.718
1392.17	369.434
1395.33	363.15
1398.49	376.866
1401.64	377.582
1404.8	378.299
1407.95	393.015
1411.11	381.731
1414.26	372.447
1417.41	371.163
1420.56	361.88
1423.71	379.596
1426.85	366.312
1430	379.028
1433.14	371.744
1436.29	381.46
1439.43	367.177
1442.57	377.893
1445.71	372.609
1448.85	377.325
1451.99	374.041
1455.12	396.758
1458.26	363.474
1461.39	354.19
1464.52	367.906
1467.66	351.622
1470.79	397.339
1473.92	376.055
1477.04	358.771
1480.17	376.487
1483.29	367.203
1486.42	368.919
1489.54	355.636
1492.67	363.352
1495.78	377.068
1498.91	350.784
1502.02	364.5
1505.14	339.217
1508.26	380.933
1511.37	380.649
1514.49	360.365
1517.6	375.081
1520.71	351.797
1523.82	382.514
1526.93	378.23
1530.04	366.946
1533.14	366.662
1536.25	367.378
1539.35	368.095
1542.46	383.811
1545.56	376.527
1548.66	386.243
1551.76	360.959
1554.86	380.676
1557.95	373.392
1561.05	372.108
1564.14	352.824
1567.24	366.54
1570.33	369.256
1573.42	375.973
1576.51	357.689
1579.6	372.405
1582.69	371.121
1585.77	365.837
1588.86	350.554
1591.94	361.27
1595.03	366.986
1598.11	365.702
1601.19	357.418
1604.27	372.134
1607.35	378.851
1610.42	355.567
1613.5	376.283
1616.57	358.999
1619.65	349.715
1622.72	371.432
1625.79	342.148
1628.86	363.864
1631.93	366.58
1635	380.296
1638.07	376.012
1641.13	379.729
1644.2	378.445
1647.26	363.211
1650.32	362.492
1653.38	374.91
1656.44	369.502
1659.5	388.706
1662.56	348.04
1665.62	372.458
1668.67	363.179
1671.72	363.843
1674.78	377.63
1677.83	380.145
1680.88	370.316
1683.93	378.812
1686.98	373.722
1690.03	380.143
1693.07	371.415
1696.12	368.537
1699.16	367.668
1702.2	361.502
1705.24	370.621
1708.28	363.001
1711.32	357.873
1714.36	361.96
1717.4	359.291
1720.43	355.6
1723.47	358.946
1726.5	358.433
1729.53	355.897
1732.56	350.734
1735.59	357.303
1738.62	358.537
1741.65	353.61
1744.68	352.619
1747.7	361.547
1750.73	355.228
1753.75	354.054
1756.77	354.515
1759.79	356.984
1762.81	349.949
1765.83	339.37
1768.85	351.107
1771.87	348.525
1774.88	351.368
1777.9	355.08
1780.91	356.81
1783.92	353.428
1786.93	355.315
1789.94	347.616
1792.95	347.144
1795.95	349.589
1798.96	342.412
1801.05	357.332
1804.06	349.159
1807.08	344.986
1810.1	368.813
1813.11	357.641
1816.12	348.468
1819.14	342.295
1822.15	365.122
1825.16	347.949
1828.17	345.777
1831.17	350.604
1834.18	339.431
1837.19	350.258
1840.19	354.085
1843.19	358.913
1846.2	349.74
1849.2	358.567
1852.2	342.394
1855.2	357.221
1858.19	342.049
1861.19	356.876
1864.19	336.703
1867.18	339.53
1870.17	347.358
1873.16	361.185
1876.15	335.012
1879.14	346.839
1882.13	333.666
1885.12	355.494
1888.11	347.321
1891.09	338.148
1894.08	345.966
1897.06	343.783
1900.04	333.601
1903.02	355.419
1906	349.236
1908.98	347.054
1911.96	337.871
1914.94	343.689
1917.91	363.507
1920.89	340.324
1923.86	330.142
1926.83	328.96
1929.8	352.777
1932.77	353.595
1935.74	349.413
1938.71	333.23
1941.68	332.048
1944.64	350.865
1947.61	340.683
1950.57	334.501
1953.53	354.318
1956.49	344.136
1959.46	346.954
1962.41	345.771
1965.37	332.589
1968.33	341.406
1971.29	337.224
1974.24	334.042
1977.19	330.859
1980.15	333.677
1983.1	326.495
1986.05	339.312
1989	341.13
1991.95	336.948
1994.89	338.765
1997.84	338.583
2000.78	336.4
2003.73	336.218
2006.67	332.036
2009.61	342.853
2012.55	340.671
2015.49	342.489
2018.43	322.306
2021.37	331.124
2024.3	343.942
2027.24	340.759
2030.17	318.577
2033.11	332.394
2036.04	338.212
2038.97	326.03
2041.9	342.847
2044.83	324.665
2047.76	328.483
2050.68	321.3
2053.61	328.118
2056.53	332.935
2059.46	329.753
2062.38	326.571
2065.3	332.388
2068.22	325.206
2071.14	330.024
2074.06	331.841
2076.98	334.659
2079.89	326.477
2082.81	325.294
2085.72	334.112
2088.63	313.929
2091.54	321.747
2094.45	339.565
2097.36	320.382
2100.27	334.2
2103.18	322.018
2106.09	323.835
2108.99	306.653
2111.9	316.47
2114.8	324.288
2117.7	319.106
2120.6	318.923
2123.5	321.741
2126.4	311.559
2129.3	309.376
2132.19	333.194
2135.09	320.012
2137.99	322.829
2140.88	308.647
2143.77	336.464
2146.66	313.282
2149.55	312.1
2152.44	308.917
2155.33	333.735
2158.22	313.553
2161.1	318.37
2163.99	322.188
2166.88	327.006
2169.76	316.823
2172.64	330.641
2175.52	323.458
2178.4	312.276
2181.28	333.094
2184.16	324.911
2187.03	328.729
2189.91	324.547
2192.78	319.364
2195.66	334.182
2198.53	319
2201.4	326.817
2204.27	333.635
2207.14	303.452
2210.01	309.27
2212.88	301.088
2215.74	309.905
2218.61	319.723
2221.47	298.541
2224.34	303.358
2227.2	311.176
2230.06	294.993
2232.92	294.811
2235.78	300.629
2238.64	305.446
2241.49	305.264
2244.35	280.082
2247.2	302.899
2250.06	303.717
2252.91	303.535
2255.76	285.352
2258.61	297.17
2261.46	322.987
2264.31	290.805
2267.16	287.623
2270.01	297.44
2272.85	294.258
2275.7	303.076
2278.54	281.893
2281.38	296.711
2284.22	303.529
2287.06	294.346
2289.9	296.164
2292.74	296.981
2295.58	297.799
2298.41	292.617
2301.25	286.434
2304.09	313.252
2306.92	295.07
2309.75	286.887
2312.58	291.705
2315.41	296.522
2318.24	301.34
2321.07	286.158
2323.9	288.975
2326.72	295.793
2329.55	300.611
2332.37	306.428
2335.19	294.246
2338.02	309.064
2340.84	272.881
2343.66	285.699
2346.47	287.516
2349.29	283.334
2352.11	290.152
2354.93	294.969
2357.74	285.787
2360.55	298.605
2363.37	283.422
2366.18	282.24
2368.99	288.057
2371.8	282.875
2374.61	274.693
2377.42	280.51
2380.22	284.328
2383.03	284.146
2385.83	277.963
2388.64	291.781
2391.44	290.599
2394.24	280.416
2397.04	291.234
2399.84	272.051
2402.64	279.869
2405.44	285.687
2408.23	286.504
2411.03	260.322
2413.82	275.14
2416.62	273.957
2419.41	275.775
2422.2	286.593
2424.99	271.41
2427.78	287.228
2430.57	280.045
2433.36	271.863
2436.14	260.681
2438.93	284.498
2441.71	278.316
2444.5	271.134
2447.28	270.951
2450.06	280.769
2452.84	273.587
2455.62	265.404
2458.4	295.222
2461.18	269.039
2463.95	275.857
2466.73	278.675
2469.5	290.492
2472.28	275.31
2475.05	289.128
2477.82	277.945
2480.59	283.763
2483.36	269.581
2486.13	279.398
2488.9	271.216
2491.66	288.033
2494.43	272.851
2497.19	274.669
2499.96	273.486
2502.72	267.304
2505.48	273.122
2508.24	269.939
2511	263.757
2513.76	266.574
2516.52	265.392
2519.28	264.21
2522.03	265.027
2524.79	280.845
2527.54	260.663
2530.29	256.48
2533.04	269.298
2535.8	268.116
2538.54	270.933
2541.29	268.751
2544.04	262.568
2546.79	257.386
2549.53	256.204
2552.28	253.021
2555.02	250.839
2557.77	259.657
2560.51	253.474
2563.25	243.292
2565.99	259.109
2568.73	263.927
2571.47	266.745
2574.2	274.562
2576.94	246.38
2579.67	263.198
2582.41	268.015
2585.14	261.833
2587.87	267.651
2590.6	271.468
2593.33	267.286
2596.06	248.103
2598.79	259.921
2601.52	266.739
2604.24	266.556
2606.97	256.374
2609.7	263.192
2612.42	257.009
2615.14	239.827
2617.86	255.645
2620.58	261.462
2623.3	266.28
2626.02	255.097
2628.74	264.915
2631.45	257.733
2634.17	261.55
2636.88	254.368
2639.6	260.186
2642.31	256.003
2645.02	252.821
2647.73	251.638
2650.44	251.456
2653.15	261.274
2655.86	259.091
2658.57	252.909
2661.27	251.727
2663.98	248.544
2666.68	256.362
2669.38	254.18
2672.09	249.997
2674.79	242.815
2677.49	246.632
2680.19	257.45
2682.89	260.268
2685.58	256.085
2688.28	241.903
2690.98	244.721
2693.67	264.538
2696.36	257.356
2699.05	260.174
2701.75	242.991
2704.44	246.809
2707.13	247.626
2709.82	250.444
2712.5	251.262
2715.19	254.079
2717.88	244.897
2720.56	234.715
2723.25	243.532
2725.93	247.35
2728.61	232.167
2731.29	241.985
2733.97	247.803
2736.65	250.62
2739.33	253.438
2742.01	241.256
2744.68	239.073
2747.36	241.891
2750.03	257.709
2752.71	252.526
2755.38	260.344
2758.05	236.161
2760.72	246.979
2763.39	252.797
2766.06	236.614
2768.73	247.432
2771.39	232.25
2774.06	253.067
2776.72	264.885
2779.39	249.703
2782.05	259.52
2784.72	246.338
2787.38	249.155
2790.04	254.973
2792.7	241.791
2795.35	250.608
2798.01	242.426
2800.67	232.244
2803.32	237.061
2805.98	252.879
2808.63	228.697
2811.29	251.514
2813.94	254.332
2816.59	226.149
2819.24	257.967
2821.89	244.785
2824.53	242.602
2827.18	230.42
2829.83	240.238
2832.47	236.055
2835.12	235.873
2837.76	257.69
2840.4	245.508
2843.04	239.326
2845.69	252.143
2848.33	243.961
2850.96	237.779
2853.6	241.596
2856.24	252.414
2858.87	247.232
2861.51	245.049
2864.14	246.867
2866.78	241.684
2869.41	238.502
2872.04	249.32
2874.67	242.137
2877.3	243.955
2879.93	233.773
2882.56	244.59
2885.18	247.408
2887.81	242.226
2890.43	234.043
2893.06	256.861
2895.68	244.678
2898.3	251.496
2900.93	252.314
2903.55	240.131
2906.17	240.949
2908.78	243.767
2911.4	241.584
2914.02	248.402
2916.63	240.219
2919.25	240.037
2921.86	248.855
2924.48	241.672
2927.09	230.49
2929.7	237.308
2932.31	249.125
2934.92	239.943
2937.53	243.761
2940.13	234.578
2942.74	228.396
2945.35	236.213
2947.95	235.031
2950.55	226.849
2953.16	223.644
2955.76	220.562
2958.36	226.496
2960.96	221.815
2963.56	213.542
2966.16	232.993
2968.76	215.773
2971.35	218.873
2973.95	225.252
2976.54	221.984
2979.14	230.079
2981.73	215.752
2984.32	234.144
2986.91	223.649
2989.5	227.888
2992.09	212.654
2994.68	207.232
2997.27	219.733
2999.85	229.173
3002.44	212.609
3005.02	210
3007.61	216.728
3010.19	216.623
3012.77	209.127
3015.35	218.896
3017.93	216.184
3020.51	213.817
3023.09	218.386
3025.67	218.817
3028.25	205.879
3030.82	210.517
3033.4	210.34
3035.97	215.805
3038.54	209.232
3041.12	212.859
3043.69	217.663
3046.26	209.925
3048.83	213.629
3051.4	214.022
3053.96	203.779
3056.53	211.076
3059.1	212.694
3061.66	217.355
3064.23	211.81
3066.79	210.584
3069.35	218.56
3071.91	207.571
3074.47	208.379
3077.03	192.199
3079.59	206.904
3082.15	203.19
3083.52	199.741
3086.08	214.708
3088.65	204.675
3091.22	201.643
3093.79	203.61
3096.35	206.578
3098.92	202.545
3101.48	209.512
3104.04	217.48
3106.6	215.447
3109.16	209.414
3111.72	203.382
3114.28	210.349
3116.84	210.317
3119.4	202.284
3121.95	207.251
3124.51	190.219
3127.06	205.186
3129.62	208.154
3132.17	205.121
3134.72	196.088
3137.27	190.056
3139.82	209.023
3142.37	204.99
3144.92	215.958
3147.47	200.925
3150.01	196.893
3152.56	206.86
3155.1	207.827
3157.65	210.795
3160.19	213.762
3162.73	197.73
3165.28	208.697
3167.81	204.664
3170.35	203.632
3172.89	203.599
3175.43	210.566
3177.97	204.534
3180.5	199.501
3183.04	206.469
3185.57	209.436
3188.11	206.403
3190.64	204.371
3193.17	196.338
3195.7	207.306
3198.23	193.273
3200.76	209.24
3203.29	202.208
3205.82	193.175
3208.35	195.142
3210.87	207.11
3213.4	204.077
3215.92	201.045
3218.44	208.012
3220.97	203.979
3223.49	201.947
3226.01	193.914
3228.53	198.882
3231.05	196.849
3233.56	200.816
3236.08	203.784
3238.6	189.751
3241.11	199.718
3243.63	192.686
3246.14	197.653
3248.65	194.621
3251.17	198.588
3253.68	203.555
3256.19	194.523
3258.7	194.49
3261.21	197.458
3263.71	192.425
3266.22	199.392
3268.73	194.36
3271.23	198.327
3273.74	183.294
3276.24	194.262
3278.74	191.229
3281.24	192.197
3283.74	198.164
3286.24	200.131
3288.74	196.099
3291.24	198.066
3293.74	185.034
3296.23	200.001
3298.73	201.968
3301.23	193.936
3303.72	202.903
3306.21	203.87
3308.71	198.838
3311.2	192.805
3313.69	192.773
3316.18	191.74
3318.67	199.707
3321.15	200.675
3323.64	196.642
3326.13	207.61
3328.61	192.577
3331.1	191.544
3333.58	194.512
3336.07	190.479
3338.55	186.446
3341.03	185.414
3343.51	192.381
3345.99	191.349
3348.47	197.316
3350.95	190.283
3353.42	186.251
3355.9	192.218
3358.38	179.186
3360.85	195.153
3363.32	192.12
3365.8	191.088
3368.27	179.055
3370.74	190.022
3373.21	188.99
3375.68	192.957
3378.15	180.925
3380.62	188.892
3383.08	187.859
3385.55	186.827
3388.02	194.794
3390.48	179.762
3392.94	193.729
3395.41	178.696
3397.87	184.664
3400.33	185.631
3402.79	179.598
3405.25	181.566
3407.71	173.533
3410.17	186.501
3412.62	181.468
3415.08	183.435
3417.54	196.403
3419.99	176.37
3422.44	182.338
3424.9	194.305
3427.35	192.272
3429.8	188.24
3432.25	187.207
3434.7	179.174
3437.15	167.142
3439.6	182.109
3442.04	186.077
3444.49	192.044
3446.94	179.011
3449.38	178.979
3451.82	181.946
3454.27	181.914
3456.71	195.881
3459.15	184.848
3461.59	177.816
3464.03	181.783
3466.47	181.75
3468.91	181.718
3471.34	184.685
3473.78	185.653
3476.22	173.62
3478.65	177.587
3481.08	185.555
3483.52	178.522
3485.95	183.49
3488.38	169.457
3490.81	188.424
3493.24	185.392
3495.67	179.359
3498.1	184.326
3500.53	178.294
3502.95	177.261
3505.38	189.229
3507.8	176.196
3510.23	173.163
3512.65	170.131
3515.07	169.098
3517.5	181.066
3519.92	164.033
3522.34	181
3524.76	180.968
3527.17	178.935
3529.59	164.902
3532.01	170.87
3534.42	174.837
3536.84	162.805
3539.25	170.772
3541.67	172.739
3544.08	173.707
3546.49	168.674
3548.9	173.642
3551.31	166.609
3553.72	171.576
3556.13	169.544
3558.54	164.511
3560.95	174.478
3563.35	165.446
3565.76	168.413
3568.16	177.381
3570.57	168.348
3572.97	179.315
3575.37	170.283
3577.77	168.25
3580.17	170.218
3582.57	170.185
3584.97	171.152
3587.37	168.12
3589.77	162.087
3592.17	174.054
3594.56	172.022
3596.96	167.989
3599.35	171.957
3601.74	161.924
3604.14	168.891
3606.53	167.859
3608.92	166.826
3611.31	169.794
3613.7	171.761
3616.09	168.728
3618.47	163.696
3620.86	159.663
3623.25	171.63
3625.63	163.598
3628.02	170.565
3630.4	159.533
3632.78	166.5
3635.17	162.467
3637.55	166.435
3639.93	163.402
3642.31	161.37
3644.69	178.337
3647.06	171.304
3649.44	166.272
3651.82	161.239
3654.2	163.206
3656.57	143.174
3658.94	162.141
3661.32	154.109
3663.69	159.076
3666.06	160.043
3668.43	170.011
3670.8	158.978
3673.17	150.946
3675.54	151.913
3677.91	169.88
3680.28	164.848
3682.64	163.815
3685.01	156.782
3687.37	158.75
3689.74	155.717
3692.1	157.685
3694.46	160.652
3696.82	167.619
3699.18	162.587
3701.54	152.554
3703.9	150.522
3706.26	164.489
3708.62	159.456
3710.98	156.424
3713.33	160.391
3715.69	154.358
3718.04	152.326
3720.4	156.293
3722.75	146.261
3725.1	165.228
3727.45	157.195
3729.8	142.163
3732.15	154.13
3734.5	162.098
3736.85	154.065
3739.2	149.032
3741.54	160
3743.89	153.967
3746.23	150.934
3748.58	147.902
3750.92	155.869
3753.27	142.837
3755.61	158.804
3757.95	151.771
3760.29	149.739
3762.63	137.706
3764.97	147.674
3767.3	159.641
3769.64	157.608
3771.98	160.576
3774.32	147.543
3776.65	150.51
3778.99	155.478
3781.32	148.445
3783.65	151.413
3785.98	156.38
3788.31	152.347
3790.64	153.315
3792.97	145.282
3795.3	147.25
3797.63	142.217
3799.96	144.184
3802.28	147.152
3804.61	143.119
3806.93	148.086
3809.26	149.054
3811.58	135.021
3813.9	150.989
3816.23	151.956
3818.55	134.923
3820.87	151.891
3823.19	147.858
3825.51	139.826
3827.82	130.793
3830.14	142.76
3832.46	148.728
3834.77	148.695
3837.09	146.663
3839.4	133.63
3841.72	150.597
3844.03	144.565
3846.34	140.532
3848.65	143.499
3850.96	147.467
3853.27	141.434
3855.58	138.402
3857.89	146.369
3860.2	138.336
3862.5	153.304
3864.81	142.271
3867.11	140.238
3869.42	147.206
3871.72	133.173
3874.02	137.141
3876.33	145.108
3878.63	136.075
3880.93	152.043
3883.23	142.01
3885.53	139.978
3887.82	125.945
3890.12	140.912
3892.42	149.88
3894.72	137.847
3897.01	133.814
3899.3	137.782
3901.6	143.749
3903.89	135.717
3906.18	145.684
3908.47	137.651
3910.76	135.619
3913.05	144.586
3915.34	144.554
3917.63	136.521
3919.92	140.488
3922.21	146.456
3924.49	136.423
3926.78	135.391
3929.06	132.358
3931.35	135.325
3933.63	137.293
3935.91	137.26
3938.19	144.227
3940.47	128.195
3942.75	141.162
3945.03	137.13
3947.31	129.097
3949.59	133.064
3951.87	138.032
3954.14	130.999
3956.42	136.966
3958.69	129.934
3960.97	136.901
3963.24	133.869
3965.51	137.836
3967.79	125.803
3970.06	127.771
3972.33	132.738
3974.6	139.706
3976.87	126.673
3979.13	134.64
3981.4	132.608
3983.67	130.575
3985.93	131.542
3988.2	122.51
3990.46	129.477
3992.73	134.445
3994.99	138.412
3997.25	128.379
3999.51	126.347