File: muestras/magnetita2/roy_mg_r2_01.txt
#Acq. time (s)=	25
#Accumulations=	3
#Range (cm-¹)=	100...4000
#Windows=	3
#Autofocus=	Off
#AutoExposure=	Off
#Spike filter=	Multiple accum.
#Delay time (s)=	0
#Binning=	1
#Readout mode=	Signal
#DeNoise=	Off
#ICS correction=	Off
#Dark correction=	Off
#Inst. Process=	Off
#Instrument=	LabRAM HR Evol
#Detector=	Syncerity OE
#Objective=	x100_VIS
#Grating=	600 (500nm)
#ND Filter=	25%
#Laser=	532nm_Edge
#Hole=	150.001
#Range=	Visible
#Project=	Omar
#Sample=
#Site=	02-05-23
#Title=	roy_mg_r2
#Remark=
#Date=	02.05.2023 17:10
#Acquired=	02.05.2023 17:10:49
101.414	848
105.083	885.594
108.751	942.188
112.417	903.781
116.08	926.375
119.743	950.969
123.405	912.563
127.065	922.157
130.724	872.75
134.38	891.344
138.036	876.938
141.691	931.532
145.342	905.126
148.994	929.719
152.642	900.313
156.291	925.907
159.936	925.501
163.583	935.095
167.225	908.688
170.868	910.282
174.508	918.876
178.149	943.47
181.786	919.064
185.421	937.657
189.057	934.251
192.69	935.845
196.321	914.439
199.953	934.033
203.581	950.627
207.208	930.22
210.834	944.814
214.458	945.408
218.081	955.002
221.702	937.596
225.324	941.189
228.943	958.783
232.56	921.377
236.175	970.971
239.79	952.565
243.4	954.158
247.012	967.752
250.622	967.346
254.23	970.94
257.838	964.534
261.444	978.127
265.048	1019.72
268.649	969.315
272.251	964.909
275.851	966.503
279.447	992.096
283.045	1022.69
286.641	991.284
290.233	956.878
293.827	959.472
297.416	972.065
301.007	997.659
304.594	989.253
308.182	992.847
311.766	980.441
315.351	982.034
318.932	981.628
322.512	993.222
326.093	992.816
329.67	994.41
333.246	1036
336.822	997.597
340.395	972.191
343.967	967.785
347.538	964.379
351.106	975.972
354.674	977.566
358.24	1008.16
361.805	983.754
365.37	993.348
368.933	983.942
372.493	995.535
376.05	1001.13
379.608	992.723
383.165	1013.32
386.72	994.911
390.274	1028.5
393.826	1019.1
397.377	1027.69
400.925	1026.29
404.473	1026.88
408.02	1006.47
411.566	1006.07
415.108	1018.66
418.651	1048.25
422.19	1039.85
425.73	993.442
429.269	1029.04
432.804	1015.63
436.34	1041.22
439.873	1036.82
443.404	1040.41
446.936	1042.01
450.465	1030.6
453.994	1047.19
457.52	1051.79
461.044	1067.38
464.569	1081.97
468.091	1066.57
471.612	1076.16
475.131	1075.76
478.648	1077.35
482.165	1089.94
485.682	1080.54
489.195	1075.13
492.708	1098.72
496.219	1086.32
499.728	1071.91
503.236	1082.51
506.743	1103.1
510.249	1078.69
513.751	1089.29
517.254	1095.88
520.755	1099.48
524.256	1086.07
527.755	1079.66
531.252	1093.26
534.746	1111.85
538.241	1137.44
541.734	1139.04
545.225	1118.63
548.715	1098.23
552.203	1149.82
555.691	1143.41
559.178	1129.01
562.661	1148.6
566.143	1173.19
569.626	1143.79
573.106	1151.38
576.586	1155.98
580.063	1160.57
583.538	1164.16
587.014	1158.76
590.487	1171.35
593.959	1162.94
597.429	1183.54
600.9	1191.13
604.367	1188.73
607.834	1188.32
611.299	1187.91
614.762	1173.51
618.224	1196.1
621.685	1200.7
625.145	1221.29
628.603	1234.88
632.06	1242.48
635.516	1264.07
638.97	1258.66
642.423	1233.26
645.875	1255.85
649.323	1275.45
652.773	1264.04
656.22	1244.63
659.667	1255.23
663.11	1264.82
666.554	1278.42
669.994	1260.01
673.436	1264.6
676.876	1256.2
680.312	1258.79
683.75	1285.38
687.184	1248.98
690.618	1281.57
694.05	1270.17
697.48	1258.76
700.911	1254.35
704.338	1267.95
707.764	1312.54
711.191	1276.13
714.615	1256.73
718.037	1296.32
721.458	1298.92
724.878	1310.51
728.299	1297.1
731.716	1296.7
735.132	1311.29
738.546	1302.88
741.959	1302.48
745.371	1307.07
748.782	1276.67
752.192	1318.26
755.6	1323.85
759.005	1303.45
762.41	1273.04
765.814	1328.64
769.217	1316.23
772.619	1289.82
776.017	1317.42
779.417	1322.01
782.814	1292.6
786.209	1339.2
789.604	1363.79
792.996	1332.39
796.389	1330.98
799.779	1299.57
803.169	1325.17
806.556	1343.76
809.943	1301.35
813.328	1337.95
816.713	1324.54
820.094	1323.14
823.475	1380.73
826.856	1344.32
830.234	1324.92
833.611	1340.51
836.986	1358.11
840.361	1358.7
843.734	1354.29
847.107	1348.89
850.478	1336.48
853.847	1359.07
857.215	1366.67
860.581	1350.26
863.947	1330.86
867.309	1360.45
870.671	1360.04
874.033	1377.64
877.393	1362.23
880.752	1369.82
884.11	1386.42
887.465	1329.01
890.82	1356.61
894.174	1368.2
897.525	1378.79
900.876	1367.39
904.226	1373.98
907.573	1367.58
910.921	1391.17
914.266	1379.76
917.611	1375.36
920.953	1400.95
924.294	1361.54
927.635	1393.14
930.973	1381.73
934.31	1394.33
937.648	1418.92
940.983	1403.51
944.316	1402.11
947.648	1399.7
950.981	1435.29
954.31	1406.89
957.639	1457.48
960.966	1414.08
964.292	1411.67
967.616	1422.26
970.939	1431.86
974.262	1425.45
977.582	1408.04
980.902	1407.64
984.219	1430.23
987.536	1430.83
990.852	1448.42
994.166	1433.01
997.48	1410.61
1000.79	1446.2
1004.1	1431.8
1007.41	1431.39
1010.72	1466.98
1014.02	1437.58
1017.33	1464.17
1020.63	1460.76
1023.94	1448.36
1027.24	1441.95
1030.54	1494.55
1033.84	1464.14
1037.13	1484.73
1040.43	1491.33
1043.73	1498.92
1047.02	1479.51
1050.31	1510.11
1053.6	1480.7
1056.89	1489.3
1060.18	1530.89
1063.47	1515.48
1066.75	1541.08
1070.04	1547.67
1073.32	1512.27
1076.6	1521.86
1079.88	1500.45
1083.16	1563.05
1086.44	1563.64
1089.72	1563.23
1092.99	1547.83
1096.27	1573.42
1099.54	1563.02
1102.82	1599.61
1106.08	1599.2
1109.35	1577.8
1112.62	1547.39
1115.89	1593.98
1119.16	1563.58
1122.42	1595.17
1125.68	1567.77
1128.94	1562.36
1132.2	1594.95
1135.46	1589.55
1138.72	1588.14
1141.98	1616.74
1145.23	1611.33
1148.49	1620.92
1151.74	1614.52
1154.99	1632.11
1158.24	1624.7
1161.49	1615.3
1164.74	1649.89
1167.99	1652.49
1171.23	1688.08
1174.48	1697.67
1177.72	1697.27
1180.96	1662.86
1184.2	1706.45
1187.44	1727.05
1190.68	1713.64
1193.91	1752.24
1197.15	1710.83
1200.38	1772.42
1203.62	1751.02
1206.85	1756.61
1210.08	1764.21
1213.31	1738.8
1216.54	1760.39
1219.76	1712.99
1222.99	1756.58
1226.21	1741.17
1229.43	1765.77
1232.66	1809.36
1235.88	1783.96
1239.1	1819.55
1242.31	1759.14
1245.53	1829.74
1248.75	1854.33
1251.96	1790.92
1255.17	1884.52
1258.39	1820.11
1261.6	1853.71
1264.8	1857.3
1268.01	1861.89
1271.22	1910.49
1274.43	1875.08
1277.63	1884.67
1280.83	1917.27
1284.04	1902.86
1287.23	1924.46
1290.43	1914.05
1293.63	1953.64
1296.83	1961.24
1300.03	1953.83
1303.22	2003.43
1306.41	1991.02
1309.61	2010.61
1312.8	2017.21
1315.99	1986.8
1319.17	2014.39
1322.36	2005.99
1325.55	2034.58
1328.73	2032.18
1331.92	2050.27
1335.1	2024.36
1338.28	2082.96
1341.46	2074.55
1344.64	2072.15
1347.81	2050.74
1350.99	2013.33
1354.17	2049.93
1357.34	2068.52
1360.51	2019.11
1363.68	2050.71
1366.85	2040.3
1370.02	2101.9
1373.19	2006.49
1376.35	2057.08
1379.52	2044.68
1382.68	2072.27
1385.85	2095.86
1389.01	2083.46
1392.17	2044.05
1395.33	2099.65
1398.49	2041.24
1401.64	2104.83
1404.8	2054.43
1407.95	2117.02
1411.11	2094.61
1414.26	2108.21
1417.41	2114.8
1420.56	2081.4
1423.71	2115.99
1426.85	2131.58
1430	2116.18
1433.14	2122.77
1436.29	2140.37
1439.43	2123.96
1442.57	2135.55
1445.71	2127.15
1448.85	2137.74
1451.99	2145.33
1455.12	2152.93
1458.26	2111.52
1461.39	2110.12
1464.52	2168.71
1467.66	2160.3
1470.79	2159.9
1473.92	2186.49
1477.04	2180.08
1480.17	2157.68
1483.29	2189.27
1486.42	2178.87
1489.54	2210.46
1492.67	2187.05
1495.78	2163.65
1498.91	2219.24
1502.02	2231.84
1505.14	2253.43
1508.26	2246.02
1511.37	2276.62
1514.49	2306.21
1517.6	2296.8
1520.71	2311.4
1523.82	2309.99
1526.93	2358.59
1530.04	2328.18
1533.14	2349.77
1536.25	2364.37
1539.35	2367.96
1542.46	2366.55
1545.56	2397.15
1548.66	2437.74
1551.76	2435.34
1554.86	2441.93
1557.95	2418.52
1561.05	2413.12
1564.14	2447.71
1567.24	2429.3
1570.33	2430.9
1573.42	2382.49
1576.51	2413.09
1579.6	2388.68
1582.69	2420.27
1585.77	2366.87
1588.86	2393.46
1591.94	2387.06
1595.03	2371.65
1598.11	2371.24
1601.19	2368.84
1604.27	2328.43
1607.35	2348.02
1610.42	2274.62
1613.5	2297.21
1616.57	2248.81
1619.65	2240.4
1622.72	2283.99
1625.79	2218.59
1628.86	2175.18
1631.93	2235.77
1635	2217.37
1638.07	2154.96
1641.13	2151.56
1644.2	2123.15
1647.26	2121.44
1650.32	2153.95
1653.38	2092.94
1656.44	2109.83
1659.5	2095.42
1662.56	2101.44
1665.62	2067.04
1668.67	2052.4
1671.72	2052.05
1674.78	2060.53
1677.83	2066.69
1680.88	2037.93
1683.93	2052.77
1686.98	2062.19
1690.03	2029.83
1693.07	2031.63
1696.12	2005.46
1699.16	2012.49
1702.2	2001.28
1705.24	2018.85
1708.28	2005.02
1711.32	2033.2
1714.36	2024.86
1717.4	2022.63
1720.43	1996.98
1723.47	2017.92
1726.5	1980.03
1729.53	1993.27
1732.56	2008.33
1735.59	2003.1
1738.62	1984.92
1741.65	1988.7
1744.68	1984.28
1747.7	2001.04
1750.73	1965.86
1753.75	1992.88
1756.77	1977.35
1759.79	1982.86
1762.81	1991.34
1765.83	2003.67
1768.85	1993.16
1771.87	1989.4
1774.88	1998.18
1777.9	2001.12
1780.91	1976.96
1783.92	2001.36
1786.93	2015.16
1789.94	2001.14
1792.95	2022.13
1795.95	1994.1
1798.96	2020.62
1801.05	2003.34
1804.06	2045.14
1807.08	2018.94
1810.1	2035.74
1813.11	1982.54
1816.12	1994.34
1819.14	2037.14
1822.15	2003.94
1825.16	2077.75
1828.17	2011.55
1831.17	2032.35
1834.18	2048.15
1837.19	2044.95
1840.19	2042.75
1843.19	1964.55
1846.2	2020.35
1849.2	2038.15
1852.2	2039.95
1855.2	2044.75
1858.19	1983.56
1861.19	2020.36
1864.19	2049.16
1867.18	2005.96
1870.17	2032.76
1873.16	2008.56
1876.15	2034.36
1879.14	1996.16
1882.13	2037.96
1885.12	2034.76
1888.11	2025.56
1891.09	2057.37
1894.08	2049.47
1897.06	2035.56
1900.04	2048.66
1903.02	2072.76
1906	2050.86
1908.98	2111.96
1911.96	2038.06
1914.94	2058.16
1917.91	2117.26
1920.89	2068.36
1923.86	2092.46
1926.83	2109.56
1929.8	2119.66
1932.77	2107.76
1935.74	2104.86
1938.71	2078.96
1941.68	2101.06
1944.64	2083.16
1947.61	2115.25
1950.57	2091.35
1953.53	2095.45
1956.49	2075.55
1959.46	2111.65
1962.41	2100.75
1965.37	2113.85
1968.33	2059.95
1971.29	2105.05
1974.24	2094.15
1977.19	2054.25
1980.15	2122.35
1983.1	2129.45
1986.05	2139.55
1989	2118.65
1991.95	2132.75
1994.89	2086.85
1997.84	2084.94
2000.78	2087.04
2003.73	2107.14
2006.67	2152.24
2009.61	2105.34
2012.55	2153.44
2015.49	2136.54
2018.43	2100.64
2021.37	2081.74
2024.3	2135.84
2027.24	2113.94
2030.17	2096.04
2033.11	2127.14
2036.04	2120.24
2038.97	2150.34
2041.9	2104.44
2044.83	2137.54
2047.76	2130.63
2050.68	2173.73
2053.61	2171.83
2056.53	2174.93
2059.46	2140.03
2062.38	2151.13
2065.3	2107.23
2068.22	2151.33
2071.14	2125.43
2074.06	2186.53
2076.98	2166.63
2079.89	2143.73
2082.81	2182.83
2085.72	2149.93
2088.63	2167.03
2091.54	2188.13
2094.45	2115.23
2097.36	2102.32
2100.27	2112.42
2103.18	2160.52
2106.09	2165.62
2108.99	2166.72
2111.9	2142.82
2114.8	2176.92
2117.7	2149.02
2120.6	2146.12
2123.5	2170.22
2126.4	2133.32
2129.3	2177.42
2132.19	2126.52
2135.09	2193.62
2137.99	2166.72
2140.88	2119.82
2143.77	2179.92
2146.66	2152.01
2149.55	2168.11
2152.44	2179.21
2155.33	2178.31
2158.22	2202.41
2161.1	2192.51
2163.99	2206.61
2166.88	2188.71
2169.76	2264.81
2172.64	2185.91
2175.52	2209.01
2178.4	2237.11
2181.28	2209.21
2184.16	2171.31
2187.03	2231.41
2189.91	2143.51
2192.78	2226.61
2195.66	2198.7
2198.53	2209.8
2201.4	2205.9
2204.27	2182
2207.14	2194.1
2210.01	2241.2
2212.88	2177.3
2215.74	2200.4
2218.61	2158.5
2221.47	2175.6
2224.34	2158.7
2227.2	2196.8
2230.06	2172.9
2232.92	2143
2235.78	2193.1
2238.64	2161.2
2241.49	2161.3
2244.35	2143.39
2247.2	2169.49
2250.06	2185.59
2252.91	2099.69
2255.76	2163.79
2258.61	2157.89
2261.46	2135.99
2264.31	2163.09
2267.16	2154.19
2270.01	2138.29
2272.85	2152.39
2275.7	2114.49
2278.54	2153.59
2281.38	2162.69
2284.22	2158.79
2287.06	2201.89
2289.9	2166.99
2292.74	2179.08
2295.58	2169.18
2298.41	2199.28
2301.25	2202.38
2304.09	2222.48
2306.92	2204.58
2309.75	2224.68
2312.58	2223.78
2315.41	2197.88
2318.24	2195.98
2321.07	2210.08
2323.9	2221.18
2326.72	2240.28
2329.55	2270.38
2332.37	2210.48
2335.19	2203.58
2338.02	2221.68
2340.84	2206.77
2343.66	2238.87
2346.47	2244.97
2349.29	2181.07
2352.11	2155.17
2354.93	2218.27
2357.74	2223.37
2360.55	2233.47
2363.37	2193.57
2366.18	2251.67
2368.99	2242.77
2371.8	2189.87
2374.61	2233.97
2377.42	2210.07
2380.22	2238.17
2383.03	2208.27
2385.83	2206.37
2388.64	2188.46
2391.44	2219.56
2394.24	2204.66
2397.04	2202.76
2399.84	2239.86
2402.64	2211.96
2405.44	2209.06
2408.23	2177.16
2411.03	2199.26
2413.82	2197.36
2416.62	2253.46
2419.41	2249.56
2422.2	2257.66
2424.99	2195.76
2427.78	2253.86
2430.57	2243.96
2433.36	2216.06
2436.14	2192.15
2438.93	2242.25
2441.71	2263.35
2444.5	2258.45
2447.28	2276.55
2450.06	2262.65
2452.84	2226.75
2455.62	2298.85
2458.4	2300.95
2461.18	2286.05
2463.95	2277.15
2466.73	2312.25
2469.5	2328.35
2472.28	2327.45
2475.05	2251.55
2477.82	2291.65
2480.59	2349.75
2483.36	2298.84
2486.13	2345.94
2488.9	2365.04
2491.66	2373.14
2494.43	2320.24
2497.19	2272.34
2499.96	2292.44
2502.72	2282.54
2505.48	2304.64
2508.24	2260.74
2511	2303.84
2513.76	2336.94
2516.52	2312.04
2519.28	2329.14
2522.03	2285.24
2524.79	2308.34
2527.54	2335.44
2530.29	2293.53
2533.04	2279.63
2535.8	2295.73
2538.54	2310.83
2541.29	2287.93
2544.04	2313.03
2546.79	2290.13
2549.53	2304.23
2552.28	2304.33
2555.02	2286.43
2557.77	2350.53
2560.51	2314.63
2563.25	2368.73
2565.99	2316.83
2568.73	2344.93
2571.47	2311.03
2574.2	2378.13
2576.94	2313.22
2579.67	2339.32
2582.41	2337.42
2585.14	2329.52
2587.87	2385.62
2590.6	2343.72
2593.33	2357.82
2596.06	2363.92
2598.79	2376.02
2601.52	2394.12
2604.24	2380.22
2606.97	2400.32
2609.7	2422.42
2612.42	2428.52
2615.14	2465.62
2617.86	2436.72
2620.58	2436.82
2623.3	2434.91
2626.02	2463.01
2628.74	2389.11
2631.45	2435.21
2634.17	2427.31
2636.88	2453.41
2639.6	2466.51
2642.31	2455.61
2645.02	2439.71
2647.73	2459.81
2650.44	2470.91
2653.15	2434.01
2655.86	2474.11
2658.57	2471.21
2661.27	2494.31
2663.98	2480.41
2666.68	2418.5
2669.38	2446.6
2672.09	2481.7
2674.79	2449.8
2677.49	2507.9
2680.19	2473
2682.89	2459.1
2685.58	2476.7
2688.28	2482.3
2690.98	2489.4
2693.67	2471.5
2696.36	2529.6
2699.05	2485.7
2701.75	2478.8
2704.44	2543.9
2707.13	2502
2709.82	2506.1
2712.5	2452.2
2715.19	2498.29
2717.88	2492.39
2720.56	2492.49
2723.25	2472.59
2725.93	2496.69
2728.61	2511.79
2731.29	2486.89
2733.97	2500.99
2736.65	2512.09
2739.33	2508.19
2742.01	2477.29
2744.68	2534.39
2747.36	2531.49
2750.03	2493.59
2752.71	2569.69
2755.38	2566.79
2758.05	2564.89
2760.72	2579.98
2763.39	2554.08
2766.06	2542.18
2768.73	2582.28
2771.39	2574.38
2774.06	2556.48
2776.72	2592.58
2779.39	2585.68
2782.05	2658.78
2784.72	2600.88
2787.38	2566.98
2790.04	2663.08
2792.7	2626.18
2795.35	2616.28
2798.01	2621.38
2800.67	2576.48
2803.32	2561.58
2805.98	2645.67
2808.63	2547.77
2811.29	2611.87
2813.94	2641.97
2816.59	2640.07
2819.24	2648.17
2821.89	2620.27
2824.53	2624.37
2827.18	2642.47
2829.83	2641.57
2832.47	2626.67
2835.12	2634.77
2837.76	2593.87
2840.4	2618.97
2843.04	2653.07
2845.69	2599.17
2848.33	2661.27
2850.96	2643.36
2853.6	2688.46
2856.24	2627.56
2858.87	2611.66
2861.51	2665.76
2864.14	2708.86
2866.78	2677.96
2869.41	2685.06
2872.04	2672.16
2874.67	2646.26
2877.3	2632.36
2879.93	2688.46
2882.56	2700.56
2885.18	2707.66
2887.81	2652.76
2890.43	2681.86
2893.06	2672.96
2895.68	2699.05
2898.3	2665.15
2900.93	2663.25
2903.55	2651.35
2906.17	2689.45
2908.78	2733.55
2911.4	2651.65
2914.02	2705.75
2916.63	2665.85
2919.25	2731.95
2921.86	2733.05
2924.48	2700.15
2927.09	2734.25
2929.7	2716.35
2932.31	2724.45
2934.92	2703.55
2937.53	2718.65
2940.13	2712.74
2942.74	2704.84
2945.35	2724.94
2947.95	2679.04
2950.55	2723.14
2953.16	2748.05
2955.76	2665.82
2958.36	2688.5
2960.96	2691.42
2963.56	2688.46
2966.16	2708.48
2968.76	2704.73
2971.35	2693.5
2973.95	2702.3
2976.54	2724.16
2979.14	2667.7
2981.73	2699.93
2984.32	2729.55
2986.91	2737.14
2989.5	2731.29
2992.09	2723.29
2994.68	2721.11
2997.27	2733.54
2999.85	2721.14
3002.44	2731.96
3005.02	2726.19
3007.61	2696.95
3010.19	2711.17
3012.77	2733.78
3015.35	2753.69
3017.93	2755.94
3020.51	2757.27
3023.09	2731.05
3025.67	2743.48
3028.25	2747.88
3030.82	2751.49
3033.4	2749.19
3035.97	2744.84
3038.54	2740.04
3041.12	2767.83
3043.69	2738.06
3046.26	2725.7
3048.83	2779.94
3051.4	2783.53
3053.96	2735.2
3056.53	2756.86
3059.1	2757.81
3061.66	2789.32
3064.23	2730.69
3066.79	2739.31
3069.35	2717.66
3071.91	2789.62
3074.47	2722.5
3077.03	2742.43
3079.59	2739.15
3082.15	2737.58
3083.52	2740.99
3086.08	2746.06
3088.65	2777.12
3091.22	2793.19
3093.79	2784.26
3096.35	2757.32
3098.92	2723.39
3101.48	2792.46
3104.04	2778.52
3106.6	2765.59
3109.16	2776.66
3111.72	2767.72
3114.28	2737.79
3116.84	2772.86
3119.4	2767.92
3121.95	2773.99
3124.51	2783.06
3127.06	2784.12
3129.62	2781.19
3132.17	2866.26
3134.72	2773.32
3137.27	2838.39
3139.82	2829.46
3142.37	2802.52
3144.92	2797.59
3147.47	2784.66
3150.01	2766.72
3152.56	2814.79
3155.1	2813.86
3157.65	2793.92
3160.19	2768.99
3162.73	2817.06
3165.28	2816.13
3167.81	2791.19
3170.35	2765.26
3172.89	2869.33
3175.43	2725.39
3177.97	2841.46
3180.5	2817.53
3183.04	2806.59
3185.57	2808.66
3188.11	2822.73
3190.64	2840.79
3193.17	2769.86
3195.7	2755.93
3198.23	2792.99
3200.76	2803.06
3203.29	2761.13
3205.82	2771.19
3208.35	2804.26
3210.87	2760.33
3213.4	2768.39
3215.92	2782.46
3218.44	2747.53
3220.97	2718.59
3223.49	2744.66
3226.01	2738.73
3228.53	2739.79
3231.05	2790.86
3233.56	2783.93
3236.08	2738
3238.6	2739.06
3241.11	2753.13
3243.63	2731.2
3246.14	2733.26
3248.65	2734.33
3251.17	2779.4
3253.68	2739.46
3256.19	2746.53
3258.7	2745.6
3261.21	2780.66
3263.71	2751.73
3266.22	2761.8
3268.73	2774.86
3271.23	2743.93
3273.74	2749
3276.24	2739.06
3278.74	2764.13
3281.24	2775.2
3283.74	2756.26
3286.24	2720.33
3288.74	2766.4
3291.24	2807.46
3293.74	2724.53
3296.23	2779.6
3298.73	2780.66
3301.23	2816.73
3303.72	2716.8
3306.21	2776.86
3308.71	2739.93
3311.2	2781
3313.69	2812.06
3316.18	2776.13
3318.67	2810.2
3321.15	2762.27
3323.64	2827.33
3326.13	2792.4
3328.61	2831.47
3331.1	2782.53
3333.58	2815.6
3336.07	2773.67
3338.55	2756.73
3341.03	2763.8
3343.51	2803.87
3345.99	2766.93
3348.47	2760
3350.95	2770.07
3353.42	2772.13
3355.9	2735.2
3358.38	2696.27
3360.85	2715.33
3363.32	2780.4
3365.8	2753.47
3368.27	2716.53
3370.74	2753.6
3373.21	2740.67
3375.68	2768.73
3378.15	2781.8
3380.62	2767.87
3383.08	2715.93
3385.55	2703
3388.02	2745.07
3390.48	2694.13
3392.94	2760.2
3395.41	2733.27
3397.87	2761.34
3400.33	2740.4
3402.79	2752.47
3405.25	2741.54
3407.71	2758.6
3410.17	2779.67
3412.62	2791.74
3415.08	2787.8
3417.54	2769.87
3419.99	2789.94
3422.44	2750
3424.9	2773.07
3427.35	2773.14
3429.8	2764.2
3432.25	2784.27
3434.7	2744.34
3437.15	2750.4
3439.6	2698.47
3442.04	2814.54
3444.49	2784.6
3446.94	2802.67
3449.38	2782.74
3451.82	2790.8
3454.27	2824.87
3456.71	2802.94
3459.15	2791
3461.59	2812.07
3464.03	2824.14
3466.47	2817.2
3468.91	2807.27
3471.34	2789.34
3473.78	2826.41
3476.22	2785.47
3478.65	2808.54
3481.08	2788.61
3483.52	2825.67
3485.95	2783.74
3488.38	2803.81
3490.81	2790.87
3493.24	2823.94
3495.67	2772.01
3498.1	2802.07
3500.53	2774.14
3502.95	2787.21
3505.38	2782.27
3507.8	2750.34
3510.23	2760.41
3512.65	2764.47
3515.07	2741.54
3517.5	2752.61
3519.92	2761.67
3522.34	2732.74
3524.76	2729.81
3527.17	2700.87
3529.59	2696.94
3532.01	2686.01
3534.42	2714.07
3536.84	2703.14
3539.25	2717.21
3541.67	2663.27
3544.08	2759.34
3546.49	2674.41
3548.9	2649.48
3551.31	2712.54
3553.72	2689.61
3556.13	2727.68
3558.54	2739.74
3560.95	2725.81
3563.35	2743.88
3565.76	2704.94
3568.16	2712.01
3570.57	2761.08
3572.97	2739.14
3575.37	2737.21
3577.77	2718.28
3580.17	2738.34
3582.57	2770.41
3584.97	2740.48
3587.37	2771.54
3589.77	2779.61
3592.17	2808.68
3594.56	2772.74
3596.96	2734.81
3599.35	2824.88
3601.74	2753.94
3604.14	2758.01
3606.53	2763.08
3608.92	2803.14
3611.31	2805.21
3613.7	2758.28
3616.09	2813.34
3618.47	2779.41
3620.86	2727.48
3623.25	2787.54
3625.63	2777.61
3628.02	2757.68
3630.4	2789.75
3632.78	2747.81
3635.17	2739.88
3637.55	2775.95
3639.93	2780.01
3642.31	2795.08
3644.69	2821.15
3647.06	2782.21
3649.44	2718.28
3651.82	2738.35
3654.2	2760.41
3656.57	2750.48
3658.94	2738.55
3661.32	2742.61
3663.69	2723.68
3666.06	2718.75
3668.43	2748.81
3670.8	2728.88
3673.17	2712.95
3675.54	2715.01
3677.91	2719.08
3680.28	2717.15
3682.64	2717.21
3685.01	2749.28
3687.37	2719.35
3689.74	2725.41
3692.1	2729.48
3694.46	2713.55
3696.82	2691.61
3699.18	2677.68
3701.54	2684.75
3703.9	2725.82
3706.26	2717.88
3708.62	2711.95
3710.98	2696.02
3713.33	2717.08
3715.69	2711.15
3718.04	2706.22
3720.4	2698.28
3722.75	2700.35
3725.1	2745.42
3727.45	2743.48
3729.8	2704.55
3732.15	2676.62
3734.5	2771.68
3736.85	2760.75
3739.2	2741.82
3741.54	2766.88
3743.89	2725.95
3746.23	2764.02
3748.58	2793.08
3750.92	2778.15
3753.27	2725.22
3755.61	2725.28
3757.95	2799.35
3760.29	2791.42
3762.63	2764.48
3764.97	2769.55
3767.3	2807.62
3769.64	2790.68
3771.98	2810.75
3774.32	2757.82
3776.65	2793.89
3778.99	2779.95
3781.32	2803.02
3783.65	2760.09
3785.98	2773.15
3788.31	2774.22
3790.64	2756.29
3792.97	2770.35
3795.3	2744.42
3797.63	2727.49
3799.96	2698.55
3802.28	2734.62
3804.61	2708.69
3806.93	2731.75
3809.26	2689.82
3811.58	2736.89
3813.9	2700.95
3816.23	2729.02
3818.55	2727.09
3820.87	2680.15
3823.19	2710.22
3825.51	2701.29
3827.82	2697.35
3830.14	2681.42
3832.46	2667.49
3834.77	2659.55
3837.09	2677.62
3839.4	2646.69
3841.72	2665.75
3844.03	2678.82
3846.34	2626.89
3848.65	2678.96
3850.96	2658.02
3853.27	2659.09
3855.58	2650.16
3857.89	2696.22
3860.2	2652.29
3862.5	2644.36
3864.81	2682.42
3867.11	2697.49
3869.42	2684.56
3871.72	2660.62
3874.02	2652.69
3876.33	2678.76
3878.63	2709.82
3880.93	2674.89
3883.23	2661.96
3885.53	2682.02
3887.82	2660.09
3890.12	2677.16
3892.42	2696.22
3894.72	2731.29
3897.01	2670.36
3899.3	2730.42
3901.6	2694.49
3903.89	2723.56
3906.18	2732.62
3908.47	2730.69
3910.76	2737.76
3913.05	2708.82
3915.34	2696.89
3917.63	2703.96
3919.92	2716.02
3922.21	2731.09
3924.49	2706.16
3926.78	2733.23
3929.06	2676.29
3931.35	2705.36
3933.63	2706.43
3935.91	2678.49
3938.19	2685.56
3940.47	2672.63
3942.75	2726.69
3945.03	2664.76
3947.31	2708.83
3949.59	2692.89
3951.87	2671.96
3954.14	2695.03
3956.42	2708.09
3958.69	2709.16
3960.97	2662.23
3963.24	2641.29
3965.51	2607.36
3967.79	2671.43
3970.06	2619.49
3972.33	2654.56
3974.6	2619.63
3976.87	2643.69
3979.13	2629.76
3981.4	2615.83
3983.67	2627.89
3985.93	2597.96
3988.2	2646.03
3990.46	2603.09
3992.73	2558.16
3994.99	2634.23
3997.25	2652.3
3999.51	2670.36