File: muestras/magnetita2/roy_mg_r2_03.txt
#Acq. time (s)=	25
#Accumulations=	3
#Range (cm-¹)=	100...4000
#Windows=	3
#Autofocus=	Off
#AutoExposure=	Off
#Spike filter=	Multiple accum.
#Delay time (s)=	0
#Binning=	1
#Readout mode=	Signal
#DeNoise=	Off
#ICS correction=	Off
#Dark correction=	Off
#Inst. Process=	Off
#Instrument=	LabRAM HR Evol
#Detector=	Syncerity OE
#Objective=	x100_VIS
#Grating=	600 (500nm)
#ND Filter=	5%
#Laser=	532nm_Edge
#Hole=	150.001
#Range=	Visible
#Project=	Omar
#Sample=
#Site=	02-05-23
#Title=	roy_mg_r2
#Remark=
#Date=	02.05.2023 17:26
#Acquired=	02.05.2023 17:26:07
101.414	1001
105.083	1019.65
108.751	1034.3
112.417	1054.94
116.08	1061.59
119.743	1055.24
123.405	1061.89
127.065	1047.54
130.724	1032.19
134.38	1035.83
138.036	1062.48
141.691	1069.13
145.342	1075.78
148.994	1063.43
152.642	1051.08
156.291	1065.72
159.936	1069.37
163.583	1070.02
167.225	1077.67
170.868	1064.32
174.508	1076.97
178.149	1081.61
181.786	1088.26
185.421	1094.91
189.057	1079.56
192.69	1094.21
196.321	1081.85
199.953	1105.5
203.581	1094.15
207.208	1087.8
210.834	1094.45
214.458	1071.1
218.081	1084.74
221.702	1051.39
225.324	1093.04
228.943	1095.69
232.56	1088.34
236.175	1091.99
239.79	1105.63
243.4	1087.28
247.012	1132.93
250.622	1131.58
254.23	1128.23
257.838	1130.88
261.444	1097.52
265.048	1099.17
268.649	1107.82
272.251	1103.47
275.851	1112.12
279.447	1126.76
283.045	1092.41
286.641	1110.06
290.233	1086.71
293.827	1118.36
297.416	1098.01
301.007	1132.65
304.594	1139.3
308.182	1149.95
311.766	1154.6
315.351	1136.25
318.932	1145.9
322.512	1146.54
326.093	1126.19
329.67	1137.84
333.246	1125.49
336.822	1127.14
340.395	1160.78
343.967	1134.43
347.538	1118.08
351.106	1117.73
354.674	1150.38
358.24	1126.03
361.805	1146.67
365.37	1175.32
368.933	1124.97
372.493	1146.62
376.05	1151.27
379.608	1177.92
383.165	1113.56
386.72	1174.21
390.274	1175.86
393.826	1152.51
397.377	1199.16
400.925	1165.81
404.473	1188.45
408.02	1158.1
411.566	1183.75
415.108	1168.4
418.651	1129.05
422.19	1142.69
425.73	1151.34
429.269	1143.99
432.804	1146.64
436.34	1135.29
439.873	1147.94
443.404	1164.58
446.936	1138.23
450.465	1176.88
453.994	1192.53
457.52	1206.18
461.044	1169.83
464.569	1173.47
468.091	1191.12
471.612	1174.77
475.131	1193.42
478.648	1238.07
482.165	1214.72
485.682	1211.36
489.195	1186.01
492.708	1188.66
496.219	1200.31
499.728	1233.96
503.236	1185.6
506.743	1205.25
510.249	1217.9
513.751	1193.55
517.254	1197.2
520.755	1205.85
524.256	1210.49
527.755	1197.14
531.252	1191.79
534.746	1209.44
538.241	1215.09
541.734	1211.74
545.225	1239.38
548.715	1214.03
552.203	1224.68
555.691	1221.33
559.178	1283.98
562.661	1234.63
566.143	1217.27
569.626	1207.92
573.106	1220.57
576.586	1229.22
580.063	1187.87
583.538	1235.51
587.014	1221.16
590.487	1263.81
593.959	1260.46
597.429	1209.11
600.9	1230.76
604.367	1207.4
607.834	1262.05
611.299	1263.7
614.762	1269.35
618.224	1240
621.685	1254.65
625.145	1266.29
628.603	1229.94
632.06	1298.59
635.516	1283.24
638.97	1290.89
642.423	1288.53
645.875	1278.18
649.323	1260.83
652.773	1297.48
656.22	1297.13
659.667	1275.78
663.11	1337.42
666.554	1300.07
669.994	1332.72
673.436	1284.37
676.876	1323.02
680.312	1327.67
683.75	1318.31
687.184	1272.96
690.618	1304.61
694.05	1288.26
697.48	1294.91
700.911	1294.56
704.338	1264.2
707.764	1317.85
711.191	1285.5
714.615	1304.15
718.037	1295.8
721.458	1267.44
724.878	1285.09
728.299	1299.74
731.716	1282.39
735.132	1277.04
738.546	1305.69
741.959	1284.33
745.371	1295.98
748.782	1298.63
752.192	1281.28
755.6	1260.93
759.005	1275.58
762.41	1264.22
765.814	1308.87
769.217	1268.52
772.619	1270.17
776.017	1273.82
779.417	1266.47
782.814	1262.11
786.209	1261.76
789.604	1274.41
792.996	1274.06
796.389	1283.71
799.779	1252.35
803.169	1288
806.556	1268.65
809.943	1266.3
813.328	1279.95
816.713	1316.6
820.094	1278.24
823.475	1253.89
826.856	1289.54
830.234	1297.19
833.611	1267.84
836.986	1283.49
840.361	1299.13
843.734	1311.78
847.107	1284.43
850.478	1299.08
853.847	1313.73
857.215	1285.38
860.581	1259.02
863.947	1272.67
867.309	1252.32
870.671	1294.97
874.033	1271.62
877.393	1288.26
880.752	1269.91
884.11	1293.56
887.465	1292.21
890.82	1305.86
894.174	1316.51
897.525	1274.15
900.876	1289.8
904.226	1303.45
907.573	1304.1
910.921	1288.75
914.266	1312.4
917.611	1296.04
920.953	1258.69
924.294	1282.34
927.635	1292.99
930.973	1266.64
934.31	1329.29
937.648	1296.93
940.983	1298.58
944.316	1331.23
947.648	1296.88
950.981	1302.53
954.31	1298.17
957.639	1313.82
960.966	1340.47
964.292	1322.12
967.616	1342.77
970.939	1295.42
974.262	1325.06
977.582	1308.71
980.902	1333.36
984.219	1319.01
987.536	1287.66
990.852	1317.31
994.166	1331.95
997.48	1322.6
1000.79	1323.25
1004.1	1333.9
1007.41	1303.55
1010.72	1291.19
1014.02	1302.84
1017.33	1315.49
1020.63	1294.14
1023.94	1316.79
1027.24	1325.44
1030.54	1339.08
1033.84	1328.73
1037.13	1327.38
1040.43	1346.03
1043.73	1322.68
1047.02	1310.33
1050.31	1376.97
1053.6	1395.62
1056.89	1355.27
1060.18	1382.92
1063.47	1356.57
1066.75	1359.22
1070.04	1377.86
1073.32	1369.51
1076.6	1370.16
1079.88	1387.81
1083.16	1367.46
1086.44	1396.1
1089.72	1408.75
1092.99	1386.4
1096.27	1365.05
1099.54	1415.7
1102.82	1402.35
1106.08	1407.99
1109.35	1400.64
1112.62	1373.29
1115.89	1350.94
1119.16	1417.59
1122.42	1365.24
1125.68	1343.88
1128.94	1400.53
1132.2	1344.18
1135.46	1355.83
1138.72	1367.48
1141.98	1369.13
1145.23	1355.77
1148.49	1388.42
1151.74	1410.07
1154.99	1375.72
1158.24	1400.37
1161.49	1401.01
1164.74	1392.66
1167.99	1401.31
1171.23	1389.96
1174.48	1443.61
1177.72	1434.26
1180.96	1456.9
1184.2	1434.55
1187.44	1439.2
1190.68	1440.85
1193.91	1470.5
1197.15	1479.15
1200.38	1499.79
1203.62	1486.44
1206.85	1451.09
1210.08	1489.74
1213.31	1454.39
1216.54	1448.03
1219.76	1478.68
1222.99	1489.33
1226.21	1463.98
1229.43	1463.63
1232.66	1466.28
1235.88	1481.92
1239.1	1509.57
1242.31	1496.22
1245.53	1473.87
1248.75	1514.52
1251.96	1484.17
1255.17	1541.81
1258.39	1526.46
1261.6	1519.11
1264.8	1500.76
1268.01	1525.41
1271.22	1543.06
1274.43	1537.7
1277.63	1530.35
1280.83	1547
1284.04	1576.65
1287.23	1546.3
1290.43	1524.94
1293.63	1584.59
1296.83	1573.24
1300.03	1583.89
1303.22	1584.54
1306.41	1599.19
1309.61	1580.83
1312.8	1587.48
1315.99	1603.13
1319.17	1609.78
1322.36	1604.43
1325.55	1620.08
1328.73	1625.72
1331.92	1610.37
1335.1	1639.02
1338.28	1648.67
1341.46	1641.32
1344.64	1684.97
1347.81	1646.61
1350.99	1633.26
1354.17	1631.91
1357.34	1623.56
1360.51	1608.21
1363.68	1601.85
1366.85	1633.5
1370.02	1627.15
1373.19	1629.8
1376.35	1665.45
1379.52	1632.1
1382.68	1642.74
1385.85	1635.39
1389.01	1628.04
1392.17	1648.69
1395.33	1650.34
1398.49	1642.99
1401.64	1646.63
1404.8	1631.28
1407.95	1636.93
1411.11	1641.58
1414.26	1624.23
1417.41	1620.88
1420.56	1666.52
1423.71	1649.17
1426.85	1618.82
1430	1624.47
1433.14	1676.12
1436.29	1640.76
1439.43	1588.41
1442.57	1602.06
1445.71	1632.71
1448.85	1642.36
1451.99	1600.01
1455.12	1650.65
1458.26	1635.3
1461.39	1586.95
1464.52	1648.6
1467.66	1608.25
1470.79	1667.9
1473.92	1650.54
1477.04	1592.19
1480.17	1615.84
1483.29	1631.49
1486.42	1583.14
1489.54	1592.79
1492.67	1583.43
1495.78	1633.08
1498.91	1599.73
1502.02	1611.38
1505.14	1668.03
1508.26	1612.67
1511.37	1647.32
1514.49	1637.97
1517.6	1606.62
1520.71	1678.27
1523.82	1682.92
1526.93	1680.56
1530.04	1698.21
1533.14	1722.86
1536.25	1685.51
1539.35	1716.16
1542.46	1720.81
1545.56	1746.45
1548.66	1719.1
1551.76	1723.75
1554.86	1743.4
1557.95	1703.05
1561.05	1757.69
1564.14	1746.34
1567.24	1708.99
1570.33	1730.64
1573.42	1796.29
1576.51	1750.94
1579.6	1758.58
1582.69	1742.23
1585.77	1700.88
1588.86	1721.53
1591.94	1746.18
1595.03	1718.83
1598.11	1672.47
1601.19	1677.12
1604.27	1722.77
1607.35	1690.42
1610.42	1670.07
1613.5	1663.72
1616.57	1655.36
1619.65	1652.01
1622.72	1625.66
1625.79	1637.31
1628.86	1624.96
1631.93	1614.6
1635	1611.25
1638.07	1559.9
1641.13	1585.55
1644.2	1618.2
1647.26	1557.24
1650.32	1536.6
1653.38	1538.73
1656.44	1515.9
1659.5	1541.78
1662.56	1471.22
1665.62	1530.8
1668.67	1482.31
1671.72	1506.51
1674.78	1484.55
1677.83	1500.63
1680.88	1468.74
1683.93	1473.94
1686.98	1462.83
1690.03	1447.42
1693.07	1445.07
1696.12	1452.57
1699.16	1408.15
1702.2	1442.48
1705.24	1435.31
1708.28	1421.35
1711.32	1427.07
1714.36	1415.98
1717.4	1401
1720.43	1414.47
1723.47	1415.49
1726.5	1398.79
1729.53	1396.73
1732.56	1394.49
1735.59	1405.06
1738.62	1388.13
1741.65	1375.75
1744.68	1374.41
1747.7	1361.07
1750.73	1388.84
1753.75	1368.88
1756.77	1347.66
1759.79	1376.59
1762.81	1381.81
1765.83	1359.36
1768.85	1380.01
1771.87	1351.78
1774.88	1355.09
1777.9	1358.76
1780.91	1362.52
1783.92	1380.11
1786.93	1359.69
1789.94	1379.37
1792.95	1331.1
1795.95	1342.74
1798.96	1354.54
1801.05	1362.75
1804.06	1374.85
1807.08	1366.96
1810.1	1351.07
1813.11	1368.17
1816.12	1347.28
1819.14	1345.39
1822.15	1368.49
1825.16	1341.6
1828.17	1336.7
1831.17	1337.81
1834.18	1339.92
1837.19	1308.02
1840.19	1332.13
1843.19	1357.24
1846.2	1365.34
1849.2	1328.45
1852.2	1343.56
1855.2	1353.66
1858.19	1346.77
1861.19	1330.87
1864.19	1338.98
1867.18	1333.09
1870.17	1343.19
1873.16	1322.3
1876.15	1324.41
1879.14	1319.51
1882.13	1316.62
1885.12	1328.73
1888.11	1296.83
1891.09	1312.94
1894.08	1337.86
1897.06	1329.78
1900.04	1344.7
1903.02	1340.62
1906	1346.54
1908.98	1322.46
1911.96	1343.38
1914.94	1318.3
1917.91	1331.22
1920.89	1327.14
1923.86	1332.06
1926.83	1354.98
1929.8	1321.9
1932.77	1326.82
1935.74	1321.74
1938.71	1343.66
1941.68	1348.58
1944.64	1296.5
1947.61	1322.42
1950.57	1330.34
1953.53	1300.26
1956.49	1355.18
1959.46	1335.1
1962.41	1259.02
1965.37	1315.95
1968.33	1316.87
1971.29	1316.79
1974.24	1310.71
1977.19	1295.63
1980.15	1305.55
1983.1	1306.47
1986.05	1260.39
1989	1289.31
1991.95	1289.23
1994.89	1290.15
1997.84	1315.07
2000.78	1270.99
2003.73	1285.91
2006.67	1288.83
2009.61	1279.75
2012.55	1296.67
2015.49	1290.59
2018.43	1294.51
2021.37	1285.43
2024.3	1288.35
2027.24	1272.27
2030.17	1305.19
2033.11	1269.11
2036.04	1253.03
2038.97	1299.95
2041.9	1288.87
2044.83	1268.79
2047.76	1275.71
2050.68	1271.63
2053.61	1288.55
2056.53	1266.47
2059.46	1276.39
2062.38	1295.31
2065.3	1251.23
2068.22	1291.15
2071.14	1285.07
2074.06	1246.99
2076.98	1256.92
2079.89	1280.84
2082.81	1270.76
2085.72	1266.68
2088.63	1231.6
2091.54	1267.52
2094.45	1247.44
2097.36	1260.36
2100.27	1244.28
2103.18	1241.2
2106.09	1241.12
2108.99	1254.04
2111.9	1216.96
2114.8	1250.88
2117.7	1235.8
2120.6	1248.72
2123.5	1246.64
2126.4	1219.56
2129.3	1226.48
2132.19	1216.4
2135.09	1229.32
2137.99	1239.24
2140.88	1223.16
2143.77	1248.08
2146.66	1236
2149.55	1209.92
2152.44	1236.84
2155.33	1192.76
2158.22	1201.68
2161.1	1210.6
2163.99	1217.52
2166.88	1223.44
2169.76	1240.36
2172.64	1248.28
2175.52	1205.2
2178.4	1218.12
2181.28	1217.04
2184.16	1250.96
2187.03	1195.88
2189.91	1246.81
2192.78	1208.73
2195.66	1223.65
2198.53	1225.57
2201.4	1217.49
2204.27	1208.41
2207.14	1214.33
2210.01	1210.25
2212.88	1203.17
2215.74	1178.09
2218.61	1203.01
2221.47	1194.93
2224.34	1181.85
2227.2	1183.77
2230.06	1191.69
2232.92	1166.61
2235.78	1157.53
2238.64	1162.45
2241.49	1134.37
2244.35	1178.29
2247.2	1155.21
2250.06	1176.13
2252.91	1141.05
2255.76	1139.97
2258.61	1123.89
2261.46	1119.81
2264.31	1137.73
2267.16	1162.65
2270.01	1140.57
2272.85	1164.49
2275.7	1137.41
2278.54	1160.33
2281.38	1149.25
2284.22	1141.17
2287.06	1141.09
2289.9	1131.01
2292.74	1165.93
2295.58	1151.85
2298.41	1119.77
2301.25	1155.7
2304.09	1176.62
2306.92	1150.54
2309.75	1141.46
2312.58	1162.38
2315.41	1137.3
2318.24	1141.22
2321.07	1157.14
2323.9	1124.06
2326.72	1133.98
2329.55	1157.9
2332.37	1122.82
2335.19	1152.74
2338.02	1103.66
2340.84	1131.58
2343.66	1151.5
2346.47	1110.42
2349.29	1123.34
2352.11	1150.26
2354.93	1117.18
2357.74	1104.1
2360.55	1130.02
2363.37	1107.94
2366.18	1116.86
2368.99	1116.78
2371.8	1107.7
2374.61	1110.62
2377.42	1082.54
2380.22	1085.46
2383.03	1103.38
2385.83	1127.3
2388.64	1095.22
2391.44	1101.14
2394.24	1082.06
2397.04	1074.98
2399.84	1066.9
2402.64	1051.82
2405.44	1074.74
2408.23	1066.67
2411.03	1041.59
2413.82	1112.51
2416.62	1055.43
2419.41	1085.35
2422.2	1092.27
2424.99	1103.19
2427.78	1066.11
2430.57	1097.03
2433.36	1093.95
2436.14	1082.87
2438.93	1073.79
2441.71	1068.71
2444.5	1075.63
2447.28	1091.55
2450.06	1089.47
2452.84	1070.39
2455.62	1075.31
2458.4	1094.23
2461.18	1087.15
2463.95	1085.07
2466.73	1033.99
2469.5	1099.91
2472.28	1103.83
2475.05	1113.75
2477.82	1084.67
2480.59	1077.59
2483.36	1092.51
2486.13	1114.43
2488.9	1087.35
2491.66	1087.27
2494.43	1061.19
2497.19	1056.11
2499.96	1060.03
2502.72	1076.95
2505.48	1073.87
2508.24	1092.79
2511	1039.71
2513.76	1067.64
2516.52	1061.56
2519.28	1068.48
2522.03	1053.4
2524.79	1063.32
2527.54	1072.24
2530.29	1051.16
2533.04	1071.08
2535.8	1070
2538.54	1055.92
2541.29	1038.84
2544.04	1040.76
2546.79	1039.68
2549.53	1048.6
2552.28	1047.52
2555.02	1047.44
2557.77	1048.36
2560.51	1047.28
2563.25	1047.2
2565.99	1067.12
2568.73	1009.04
2571.47	1032.96
2574.2	1050.88
2576.94	1046.8
2579.67	1047.72
2582.41	1022.64
2585.14	1037.56
2587.87	1015.48
2590.6	1050.4
2593.33	1033.32
2596.06	1025.24
2598.79	1027.16
2601.52	1057.08
2604.24	1070
2606.97	1053.92
2609.7	1052.84
2612.42	1054.76
2615.14	1047.68
2617.86	1032.6
2620.58	1029.53
2623.3	1056.45
2626.02	1028.37
2628.74	1052.29
2631.45	1030.21
2634.17	1035.13
2636.88	1018.05
2639.6	1038.97
2642.31	1054.89
2645.02	1047.81
2647.73	1049.73
2650.44	1049.65
2653.15	1046.57
2655.86	1026.49
2658.57	1013.41
2661.27	1045.33
2663.98	1062.25
2666.68	1065.17
2669.38	1056.09
2672.09	1048.01
2674.79	1045.93
2677.49	1025.85
2680.19	1027.77
2682.89	1028.69
2685.58	1018.61
2688.28	1040.53
2690.98	1013.45
2693.67	1022.37
2696.36	1018.29
2699.05	1039.21
2701.75	1022.13
2704.44	1020.05
2707.13	1005.97
2709.82	1014.89
2712.5	1034.81
2715.19	1029.73
2717.88	1027.65
2720.56	990.575
2723.25	1004.49
2725.93	988.415
2728.61	1007.34
2731.29	1032.26
2733.97	1024.18
2736.65	1020.1
2739.33	1038.02
2742.01	998.937
2744.68	995.857
2747.36	1028.78
2750.03	1000.7
2752.71	990.618
2755.38	1012.54
2758.05	1020.46
2760.72	1021.38
2763.39	1019.3
2766.06	1025.22
2768.73	1020.14
2771.39	1009.06
2774.06	1010.98
2776.72	1016.9
2779.39	995.82
2782.05	1035.74
2784.72	1027.66
2787.38	1038.58
2790.04	1013.5
2792.7	1018.42
2795.35	1040.34
2798.01	1027.26
2800.67	1025.18
2803.32	1033.1
2805.98	997.023
2808.63	1007.94
2811.29	1019.86
2813.94	1002.78
2816.59	1023.7
2819.24	992.624
2821.89	964.544
2824.53	1021.46
2827.18	1022.39
2829.83	1006.31
2832.47	1037.23
2835.12	984.146
2837.76	1020.07
2840.4	978.986
2843.04	1025.91
2845.69	1000.83
2848.33	1009.75
2850.96	994.667
2853.6	1001.59
2856.24	1008.51
2858.87	1017.43
2861.51	1019.35
2864.14	1018.27
2866.78	1033.19
2869.41	991.109
2872.04	1026.03
2874.67	1027.95
2877.3	1045.87
2879.93	1028.79
2882.56	1047.71
2885.18	1011.63
2887.81	1062.55
2890.43	1052.47
2893.06	1047.39
2895.68	994.312
2898.3	1042.23
2900.93	1008.15
2903.55	1001.07
2906.17	1020.99
2908.78	1038.91
2911.4	1059.83
2914.02	1030.75
2916.63	1001.67
2919.25	1014.59
2921.86	999.514
2924.48	1028.43
2927.09	1011.35
2929.7	994.275
2932.31	1013.2
2934.92	999.116
2937.53	1006.04
2940.13	1011.96
2942.74	983.876
2945.35	977.797
2947.95	950.717
2950.55	1010.64
2953.16	988.298
2955.76	995.305
2958.36	981.173
2960.96	978.086
2963.56	967.335
2966.16	963.538
2968.76	959.69
2971.35	937.068
2973.95	975.845
2976.54	930.5
2979.14	942.014
2981.73	952.298
2984.32	950.931
2986.91	920.122
2989.5	958.582
2992.09	922.96
2994.68	927.425
2997.27	930.687
2999.85	926.513
3002.44	912.361
3005.02	921.135
3007.61	924.422
3010.19	928.146
3012.77	923.252
3015.35	910.276
3017.93	917.818
3020.51	911.323
3023.09	895.883
3025.67	902.144
3028.25	920.494
3030.82	911.595
3033.4	904.189
3035.97	905.747
3038.54	900.701
3041.12	897.573
3043.69	881.67
3046.26	896.005
3048.83	874.748
3051.4	898.534
3053.96	903.155
3056.53	890.4
3059.1	895.614
3061.66	895.368
3064.23	908.23
3066.79	897.154
3069.35	884.508
3071.91	894.311
3074.47	909.21
3077.03	873.195
3079.59	883.871
3082.15	901.834
3083.52	881.596
3086.08	889.257
3088.65	868.919
3091.22	880.58
3093.79	887.241
3096.35	895.902
3098.92	870.564
3101.48	886.225
3104.04	878.886
3106.6	891.547
3109.16	867.209
3111.72	852.87
3114.28	864.531
3116.84	876.192
3119.4	879.854
3121.95	883.515
3124.51	889.176
3127.06	865.837
3129.62	874.499
3132.17	885.16
3134.72	851.821
3137.27	873.482
3139.82	891.143
3142.37	887.805
3144.92	860.466
3147.47	874.127
3150.01	877.788
3152.56	868.45
3155.1	872.111
3157.65	877.772
3160.19	871.433
3162.73	907.095
3165.28	875.756
3167.81	845.417
3170.35	890.078
3172.89	877.74
3175.43	869.401
3177.97	881.062
3180.5	876.723
3183.04	866.385
3185.57	869.046
3188.11	853.707
3190.64	863.368
3193.17	868.029
3195.7	842.691
3198.23	853.352
3200.76	865.013
3203.29	855.674
3205.82	873.336
3208.35	846.997
3210.87	844.658
3213.4	846.319
3215.92	847.981
3218.44	850.642
3220.97	853.303
3223.49	835.964
3226.01	862.625
3228.53	831.287
3231.05	846.948
3233.56	829.609
3236.08	850.271
3238.6	809.932
3241.11	844.593
3243.63	822.254
3246.14	831.915
3248.65	830.577
3251.17	837.238
3253.68	826.899
3256.19	837.56
3258.7	833.222
3261.21	832.883
3263.71	846.544
3266.22	817.205
3268.73	872.867
3271.23	845.528
3273.74	827.189
3276.24	859.85
3278.74	833.512
3281.24	850.173
3283.74	824.834
3286.24	843.495
3288.74	846.156
3291.24	837.818
3293.74	845.479
3296.23	855.14
3298.73	838.801
3301.23	825.463
3303.72	853.124
3306.21	830.785
3308.71	857.446
3311.2	851.108
3313.69	846.769
3316.18	837.43
3318.67	872.091
3321.15	834.753
3323.64	855.414
3326.13	859.075
3328.61	819.736
3331.1	840.398
3333.58	836.059
3336.07	832.72
3338.55	834.381
3341.03	805.042
3343.51	835.704
3345.99	820.365
3348.47	830.026
3350.95	853.687
3353.42	814.349
3355.9	821.01
3358.38	824.671
3360.85	816.332
3363.32	801.994
3365.8	820.655
3368.27	835.316
3370.74	808.977
3373.21	774.639
3375.68	807.3
3378.15	798.961
3380.62	814.622
3383.08	809.284
3385.55	800.945
3388.02	805.606
3390.48	805.267
3392.94	803.928
3395.41	778.59
3397.87	804.251
3400.33	822.912
3402.79	818.573
3405.25	798.235
3407.71	811.896
3410.17	814.557
3412.62	787.218
3415.08	800.88
3417.54	789.541
3419.99	803.202
3422.44	800.863
3424.9	785.525
3427.35	807.186
3429.8	819.847
3432.25	804.508
3434.7	776.17
3437.15	799.831
3439.6	781.492
3442.04	793.153
3444.49	810.814
3446.94	817.476
3449.38	822.137
3451.82	838.798
3454.27	803.459
3456.71	798.121
3459.15	799.782
3461.59	824.443
3464.03	824.104
3466.47	804.766
3468.91	804.427
3471.34	821.088
3473.78	792.749
3476.22	798.411
3478.65	767.072
3481.08	836.733
3483.52	780.394
3485.95	820.056
3488.38	763.717
3490.81	793.378
3493.24	792.039
3495.67	788.7
3498.1	770.362
3500.53	787.023
3502.95	804.684
3505.38	770.345
3507.8	768.007
3510.23	777.668
3512.65	748.329
3515.07	756.99
3517.5	773.652
3519.92	756.313
3522.34	756.974
3524.76	757.635
3527.17	761.297
3529.59	768.958
3532.01	757.619
3534.42	752.28
3536.84	763.942
3539.25	754.603
3541.67	740.264
3544.08	743.925
3546.49	753.587
3548.9	727.248
3551.31	755.909
3553.72	766.57
3556.13	774.231
3558.54	746.893
3560.95	761.554
3563.35	765.215
3565.76	756.876
3568.16	732.538
3570.57	734.199
3572.97	764.86
3575.37	767.521
3577.77	730.183
3580.17	737.844
3582.57	767.505
3584.97	745.166
3587.37	752.828
3589.77	769.489
3592.17	760.15
3594.56	748.811
3596.96	745.473
3599.35	753.134
3601.74	740.795
3604.14	745.456
3606.53	736.117
3608.92	751.779
3611.31	748.44
3613.7	745.101
3616.09	756.762
3618.47	767.424
3620.86	725.085
3623.25	764.746
3625.63	740.407
3628.02	722.069
3630.4	753.73
3632.78	761.391
3635.17	752.052
3637.55	725.714
3639.93	745.375
3642.31	707.036
3644.69	745.697
3647.06	734.359
3649.44	748.02
3651.82	727.681
3654.2	751.342
3656.57	706.003
3658.94	715.665
3661.32	707.326
3663.69	726.987
3666.06	708.648
3668.43	727.31
3670.8	713.971
3673.17	736.632
3675.54	723.293
3677.91	710.955
3680.28	703.616
3682.64	692.277
3685.01	700.938
3687.37	716.6
3689.74	692.261
3692.1	677.922
3694.46	700.583
3696.82	743.245
3699.18	752.906
3701.54	677.567
3703.9	701.228
3706.26	681.889
3708.62	710.551
3710.98	676.212
3713.33	701.873
3715.69	690.534
3718.04	678.196
3720.4	694.857
3722.75	688.518
3725.1	671.179
3727.45	708.841
3729.8	715.502
3732.15	692.163
3734.5	705.824
3736.85	694.486
3739.2	712.147
3741.54	693.808
3743.89	690.469
3746.23	701.13
3748.58	717.792
3750.92	707.453
3753.27	708.114
3755.61	683.775
3757.95	711.437
3760.29	698.098
3762.63	703.759
3764.97	695.42
3767.3	711.082
3769.64	680.743
3771.98	687.404
3774.32	703.065
3776.65	685.727
3778.99	686.388
3781.32	657.049
3783.65	682.71
3785.98	703.372
3788.31	678.033
3790.64	695.694
3792.97	683.355
3795.3	675.016
3797.63	669.678
3799.96	680.339
3802.28	681
3804.61	665.661
3806.93	648.323
3809.26	679.984
3811.58	662.645
3813.9	644.306
3816.23	665.968
3818.55	661.629
3820.87	656.29
3823.19	669.951
3825.51	641.613
3827.82	662.274
3830.14	666.935
3832.46	639.596
3834.77	648.258
3837.09	645.919
3839.4	640.58
3841.72	626.241
3844.03	660.902
3846.34	638.564
3848.65	645.225
3850.96	625.886
3853.27	621.547
3855.58	622.209
3857.89	621.87
3860.2	646.531
3862.5	626.192
3864.81	633.854
3867.11	652.515
3869.42	643.176
3871.72	636.837
3874.02	650.499
3876.33	641.16
3878.63	618.821
3880.93	630.482
3883.23	633.144
3885.53	640.805
3887.82	641.466
3890.12	619.127
3892.42	638.788
3894.72	655.45
3897.01	644.111
3899.3	633.772
3901.6	627.433
3903.89	631.095
3906.18	639.756
3908.47	639.417
3910.76	612.078
3913.05	634.74
3915.34	629.401
3917.63	638.062
3919.92	639.723
3922.21	644.385
3924.49	621.046
3926.78	655.707
3929.06	622.368
3931.35	653.03
3933.63	635.691
3935.91	641.352
3938.19	641.013
3940.47	616.674
3942.75	607.336
3945.03	624.997
3947.31	616.658
3949.59	615.319
3951.87	607.981
3954.14	617.642
3956.42	581.303
3958.69	631.964
3960.97	624.626
3963.24	615.287
3965.51	608.948
3967.79	600.609
3970.06	602.271
3972.33	615.932
3974.6	610.593
3976.87	595.254
3979.13	580.916
3981.4	610.577
3983.67	592.238
3985.93	604.899
3988.2	588.56
3990.46	586.222
3992.73	587.883
3994.99	598.544
3997.25	578.205
3999.51	590.867