File: muestras/magnetita2/roy_mg_r2_05.txt
#Acq. time (s)=	25
#Accumulations=	3
#Range (cm-¹)=	100...4000
#Windows=	3
#Autofocus=	Off
#AutoExposure=	Off
#Spike filter=	Multiple accum.
#Delay time (s)=	0
#Binning=	1
#Readout mode=	Signal
#DeNoise=	Off
#ICS correction=	Off
#Dark correction=	Off
#Inst. Process=	Off
#Instrument=	LabRAM HR Evol
#Detector=	Syncerity OE
#Objective=	x100_VIS
#Grating=	600 (500nm)
#ND Filter=	25%
#Laser=	532nm_Edge
#Hole=	150.001
#Range=	Visible
#Project=	Omar
#Sample=
#Site=	02-05-23
#Title=	roy_mg_r2
#Remark=
#Date=	02.05.2023 17:38
#Acquired=	02.05.2023 17:38:05
101.414	828
105.083	853.797
108.751	889.594
112.417	896.391
116.08	901.188
119.743	864.985
123.405	888.782
127.065	860.579
130.724	881.377
134.38	880.174
138.036	866.971
141.691	905.768
145.342	893.565
148.994	881.362
152.642	889.159
156.291	902.956
159.936	903.753
163.583	894.55
167.225	890.347
170.868	898.144
174.508	930.941
178.149	878.738
181.786	894.535
185.421	897.333
189.057	896.13
192.69	898.927
196.321	902.724
199.953	929.521
203.581	923.318
207.208	938.115
210.834	906.912
214.458	919.709
218.081	905.506
221.702	920.303
225.324	905.1
228.943	956.897
232.56	1029.69
236.175	929.491
239.79	918.289
243.4	946.086
247.012	940.883
250.622	937.68
254.23	952.477
257.838	937.274
261.444	975.071
265.048	954.868
268.649	960.665
272.251	951.462
275.851	908.259
279.447	938.056
283.045	939.853
286.641	943.65
290.233	969.448
293.827	917.245
297.416	942.042
301.007	967.839
304.594	974.636
308.182	961.433
311.766	966.23
315.351	954.027
318.932	944.824
322.512	983.621
326.093	966.418
329.67	943.215
333.246	944.012
336.822	950.809
340.395	951.606
343.967	980.404
347.538	954.201
351.106	945.998
354.674	969.795
358.24	970.592
361.805	963.389
365.37	950.186
368.933	972.983
372.493	950.78
376.05	993.577
379.608	998.374
383.165	986.171
386.72	1008.97
390.274	1027.77
393.826	1021.56
397.377	996.359
400.925	993.157
404.473	983.954
408.02	994.751
411.566	980.548
415.108	1001.34
418.651	1026.14
422.19	971.939
425.73	982.736
429.269	997.533
432.804	1025.33
436.34	1003.13
439.873	1013.92
443.404	1008.72
446.936	980.518
450.465	1037.32
453.994	1067.11
457.52	995.91
461.044	1043.71
464.569	1070.5
468.091	1043.3
471.612	1068.1
475.131	1047.9
478.648	1050.69
482.165	1055.49
485.682	1087.29
489.195	1068.08
492.708	1031.88
496.219	1085.68
499.728	1046.47
503.236	1087.27
506.743	1060.07
510.249	1060.87
513.751	1080.66
517.254	1036.46
520.755	1050.26
524.256	1079.05
527.755	1079.85
531.252	1108.65
534.746	1085.45
538.241	1077.24
541.734	1129.04
545.225	1074.84
548.715	1100.63
552.203	1108.43
555.691	1110.23
559.178	1138.02
562.661	1111.82
566.143	1166.62
569.626	1122.42
573.106	1130.21
576.586	1125.01
580.063	1148.81
583.538	1136.6
587.014	1158.4
590.487	1164.2
593.959	1150
597.429	1144.79
600.9	1148.59
604.367	1143.39
607.834	1154.18
611.299	1126.98
614.762	1175.78
618.224	1187.57
621.685	1189.37
625.145	1186.17
628.603	1192.97
632.06	1208.76
635.516	1223.56
638.97	1240.36
642.423	1219.15
645.875	1232.95
649.323	1221.75
652.773	1208.55
656.22	1237.34
659.667	1245.14
663.11	1225.94
666.554	1255.73
669.994	1246.53
673.436	1288.33
676.876	1203.12
680.312	1235.92
683.75	1257.72
687.184	1266.52
690.618	1242.31
694.05	1248.11
697.48	1231.91
700.911	1241.7
704.338	1253.5
707.764	1279.3
711.191	1260.1
714.615	1254.89
718.037	1262.69
721.458	1249.49
724.878	1245.28
728.299	1299.08
731.716	1275.88
735.132	1312.67
738.546	1296.47
741.959	1296.27
745.371	1278.07
748.782	1264.86
752.192	1277.66
755.6	1278.46
759.005	1286.25
762.41	1270.05
765.814	1275.85
769.217	1276.65
772.619	1297.44
776.017	1275.24
779.417	1261.04
782.814	1295.83
786.209	1316.63
789.604	1300.43
792.996	1273.23
796.389	1273.02
799.779	1269.82
803.169	1301.62
806.556	1277.41
809.943	1292.21
813.328	1289.01
816.713	1343.8
820.094	1305.6
823.475	1332.4
826.856	1320.2
830.234	1281.99
833.611	1285.79
836.986	1309.59
840.361	1344.38
843.734	1338.18
847.107	1329.98
850.478	1330.78
853.847	1328.57
857.215	1336.37
860.581	1338.17
863.947	1328.96
867.309	1335.76
870.671	1354.56
874.033	1305.35
877.393	1337.15
880.752	1308.95
884.11	1375.75
887.465	1349.54
890.82	1349.34
894.174	1326.14
897.525	1310.93
900.876	1344.73
904.226	1377.53
907.573	1342.33
910.921	1355.12
914.266	1380.92
917.611	1318.72
920.953	1358.51
924.294	1363.31
927.635	1407.11
930.973	1378.9
934.31	1373.7
937.648	1403.5
940.983	1405.3
944.316	1392.09
947.648	1411.89
950.981	1368.69
954.31	1402.48
957.639	1406.28
960.966	1382.08
964.292	1392.88
967.616	1385.67
970.939	1381.47
974.262	1429.27
977.582	1419.06
980.902	1435.86
984.219	1414.66
987.536	1402.46
990.852	1449.25
994.166	1439.05
997.48	1427.85
1000.79	1384.64
1004.1	1450.44
1007.41	1451.24
1010.72	1425.03
1014.02	1425.83
1017.33	1440.63
1020.63	1464.43
1023.94	1433.22
1027.24	1440.02
1030.54	1428.82
1033.84	1433.61
1037.13	1493.41
1040.43	1467.21
1043.73	1477.01
1047.02	1463.8
1050.31	1493.6
1053.6	1482.4
1056.89	1507.19
1060.18	1485.99
1063.47	1493.79
1066.75	1501.58
1070.04	1483.38
1073.32	1551.18
1076.6	1528.98
1079.88	1545.77
1083.16	1554.57
1086.44	1537.37
1089.72	1512.16
1092.99	1509.96
1096.27	1579.76
1099.54	1559.56
1102.82	1549.35
1106.08	1541.15
1109.35	1571.95
1112.62	1551.74
1115.89	1561.54
1119.16	1603.34
1122.42	1582.13
1125.68	1577.93
1128.94	1565.73
1132.2	1579.53
1135.46	1602.32
1138.72	1608.12
1141.98	1623.92
1145.23	1587.71
1148.49	1620.51
1151.74	1613.31
1154.99	1663.11
1158.24	1633.9
1161.49	1625.7
1164.74	1628.5
1167.99	1631.29
1171.23	1705.09
1174.48	1704.89
1177.72	1668.68
1180.96	1680.48
1184.2	1708.28
1187.44	1725.08
1190.68	1756.87
1193.91	1739.67
1197.15	1737.47
1200.38	1755.26
1203.62	1746.06
1206.85	1795.86
1210.08	1744.66
1213.31	1762.45
1216.54	1768.25
1219.76	1764.05
1222.99	1778.84
1226.21	1785.64
1229.43	1788.44
1232.66	1812.23
1235.88	1826.03
1239.1	1795.83
1242.31	1804.63
1245.53	1834.42
1248.75	1818.22
1251.96	1837.02
1255.17	1850.81
1258.39	1839.61
1261.6	1862.41
1264.8	1858.21
1268.01	1860
1271.22	1903.8
1274.43	1912.6
1277.63	1921.39
1280.83	1934.19
1284.04	1926.99
1287.23	1927.79
1290.43	1902.58
1293.63	1954.38
1296.83	1989.18
1300.03	1968.97
1303.22	1986.77
1306.41	2023.57
1309.61	2027.36
1312.8	2018.16
1315.99	2005.96
1319.17	2048.76
1322.36	2022.55
1325.55	2034.35
1328.73	2063.15
1331.92	2047.94
1335.1	2048.74
1338.28	2096.54
1341.46	2087.34
1344.64	2064.13
1347.81	2055.93
1350.99	2069.73
1354.17	2053.52
1357.34	2093.32
1360.51	2079.12
1363.68	2056.91
1366.85	2069.71
1370.02	2102.51
1373.19	2056.31
1376.35	2103.1
1379.52	2060.9
1382.68	2063.7
1385.85	2079.49
1389.01	2089.29
1392.17	2089.09
1395.33	2078.89
1398.49	2107.68
1401.64	2089.48
1404.8	2064.28
1407.95	2168.07
1411.11	2104.87
1414.26	2145.67
1417.41	2141.47
1420.56	2134.26
1423.71	2118.06
1426.85	2138.86
1430	2142.65
1433.14	2145.45
1436.29	2173.25
1439.43	2122.04
1442.57	2138.84
1445.71	2177.64
1448.85	2135.44
1451.99	2156.23
1455.12	2128.03
1458.26	2202.83
1461.39	2202.62
1464.52	2146.42
1467.66	2167.22
1470.79	2187.02
1473.92	2161.81
1477.04	2157.61
1480.17	2179.41
1483.29	2200.2
1486.42	2219
1489.54	2242.8
1492.67	2206.59
1495.78	2219.39
1498.91	2194.19
1502.02	2258.99
1505.14	2264.78
1508.26	2274.58
1511.37	2273.38
1514.49	2319.17
1517.6	2300.97
1520.71	2356.77
1523.82	2274.57
1526.93	2366.36
1530.04	2403.16
1533.14	2386.96
1536.25	2404.75
1539.35	2390.55
1542.46	2410.35
1545.56	2403.14
1548.66	2426.94
1551.76	2464.74
1554.86	2424.54
1557.95	2410.33
1561.05	2423.13
1564.14	2431.93
1567.24	2476.72
1570.33	2482.52
1573.42	2444.32
1576.51	2402.12
1579.6	2427.91
1582.69	2447.71
1585.77	2466.51
1588.86	2408.3
1591.94	2384.1
1595.03	2404.9
1598.11	2401.69
1601.19	2403.49
1604.27	2375.29
1607.35	2377.09
1610.42	2327.88
1613.5	2330.68
1616.57	2300.48
1619.65	2294.27
1622.72	2268.07
1625.79	2234.87
1628.86	2242.67
1631.93	2211.46
1635	2157.26
1638.07	2161.06
1641.13	2163.85
1644.2	2202.65
1647.26	2164.2
1650.32	2177.7
1653.38	2176.45
1656.44	2122.73
1659.5	2104.97
1662.56	2104.42
1665.62	2070.38
1668.67	2091.65
1671.72	2064.81
1674.78	2114.71
1677.83	2116
1680.88	2122.36
1683.93	2098.16
1686.98	2086.27
1690.03	2076.11
1693.07	2068.22
1696.12	2065.46
1699.16	2060.36
1702.2	2066.4
1705.24	2036.63
1708.28	2016.04
1711.32	2071.4
1714.36	2027.38
1717.4	2048.37
1720.43	2038.51
1723.47	2021.87
1726.5	2055.01
1729.53	2055.91
1732.56	2045.88
1735.59	2054.12
1738.62	2023
1741.65	1994.97
1744.68	2034.67
1747.7	2027.36
1750.73	2013.33
1753.75	2045.89
1756.77	1987.21
1759.79	2015.05
1762.81	2003.65
1765.83	2021.1
1768.85	2032.03
1771.87	2047.47
1774.88	2049.14
1777.9	2053.69
1780.91	2019.9
1783.92	2059.96
1786.93	2035.19
1789.94	2047.73
1792.95	2058.04
1795.95	2029.35
1798.96	2023.91
1801.05	2063.04
1804.06	2049.05
1807.08	2042.07
1810.1	2042.08
1813.11	2014.1
1816.12	2032.11
1819.14	2084.13
1822.15	2067.14
1825.16	2056.16
1828.17	2063.17
1831.17	2036.19
1834.18	2004.2
1837.19	2082.22
1840.19	2069.23
1843.19	2077.25
1846.2	2056.26
1849.2	2049.28
1852.2	2075.3
1855.2	2012.31
1858.19	2080.33
1861.19	2094.34
1864.19	2089.36
1867.18	2082.37
1870.17	2067.39
1873.16	2045.4
1876.15	2068.42
1879.14	2076.43
1882.13	2093.45
1885.12	2073.46
1888.11	2068.48
1891.09	2080.49
1894.08	2073.86
1897.06	2067.23
1900.04	2083.6
1903.02	2083.97
1906	2109.34
1908.98	2112.71
1911.96	2125.08
1914.94	2123.45
1917.91	2145.82
1920.89	2119.19
1923.86	2101.56
1926.83	2142.93
1929.8	2115.3
1932.77	2149.67
1935.74	2144.04
1938.71	2141.41
1941.68	2144.78
1944.64	2121.15
1947.61	2161.52
1950.57	2130.89
1953.53	2144.26
1956.49	2151.63
1959.46	2137
1962.41	2162.37
1965.37	2155.74
1968.33	2120.11
1971.29	2094.48
1974.24	2187.85
1977.19	2153.22
1980.15	2125.59
1983.1	2169.96
1986.05	2141.33
1989	2159.7
1991.95	2171.07
1994.89	2153.44
1997.84	2172.81
2000.78	2150.18
2003.73	2206.55
2006.67	2138.92
2009.61	2182.29
2012.55	2189.66
2015.49	2193.03
2018.43	2196.4
2021.37	2160.76
2024.3	2195.13
2027.24	2187.5
2030.17	2197.87
2033.11	2197.24
2036.04	2156.61
2038.97	2188.98
2041.9	2185.35
2044.83	2165.72
2047.76	2201.09
2050.68	2223.46
2053.61	2255.83
2056.53	2235.2
2059.46	2249.57
2062.38	2207.94
2065.3	2182.31
2068.22	2233.68
2071.14	2178.05
2074.06	2211.42
2076.98	2189.79
2079.89	2130.16
2082.81	2226.53
2085.72	2202.9
2088.63	2231.27
2091.54	2214.64
2094.45	2202.01
2097.36	2161.38
2100.27	2195.75
2103.18	2214.12
2106.09	2219.49
2108.99	2208.86
2111.9	2208.23
2114.8	2195.6
2117.7	2237.97
2120.6	2182.34
2123.5	2266.71
2126.4	2172.08
2129.3	2205.45
2132.19	2194.82
2135.09	2217.19
2137.99	2253.56
2140.88	2231.93
2143.77	2163.3
2146.66	2214.67
2149.55	2199.04
2152.44	2233.41
2155.33	2243.77
2158.22	2257.14
2161.1	2213.51
2163.99	2304.88
2166.88	2256.25
2169.76	2249.62
2172.64	2231.99
2175.52	2233.36
2178.4	2247.73
2181.28	2281.1
2184.16	2245.47
2187.03	2249.84
2189.91	2277.21
2192.78	2282.58
2195.66	2272.95
2198.53	2281.32
2201.4	2273.69
2204.27	2254.06
2207.14	2262.43
2210.01	2251.8
2212.88	2240.17
2215.74	2249.54
2218.61	2212.91
2221.47	2266.28
2224.34	2251.65
2227.2	2237.02
2230.06	2254.39
2232.92	2212.76
2235.78	2211.13
2238.64	2188.5
2241.49	2247.87
2244.35	2214.24
2247.2	2221.61
2250.06	2183.98
2252.91	2178.35
2255.76	2238.72
2258.61	2213.09
2261.46	2250.46
2264.31	2233.83
2267.16	2228.2
2270.01	2192.57
2272.85	2224.94
2275.7	2228.31
2278.54	2241.68
2281.38	2248.05
2284.22	2279.42
2287.06	2256.79
2289.9	2230.15
2292.74	2245.52
2295.58	2263.89
2298.41	2227.26
2301.25	2263.63
2304.09	2259
2306.92	2280.37
2309.75	2258.74
2312.58	2256.11
2315.41	2288.48
2318.24	2276.85
2321.07	2289.22
2323.9	2286.59
2326.72	2295.96
2329.55	2316.33
2332.37	2280.7
2335.19	2319.07
2338.02	2279.44
2340.84	2322.81
2343.66	2308.18
2346.47	2306.55
2349.29	2305.92
2352.11	2279.29
2354.93	2269.66
2357.74	2353.03
2360.55	2294.4
2363.37	2274.77
2366.18	2301.14
2368.99	2308.51
2371.8	2304.88
2374.61	2294.25
2377.42	2290.62
2380.22	2278.99
2383.03	2276.36
2385.83	2259.73
2388.64	2284.1
2391.44	2300.47
2394.24	2314.84
2397.04	2282.21
2399.84	2301.58
2402.64	2290.95
2405.44	2312.32
2408.23	2260.69
2411.03	2299.06
2413.82	2279.43
2416.62	2305.8
2419.41	2267.17
2422.2	2312.53
2424.99	2317.9
2427.78	2294.27
2430.57	2329.64
2433.36	2344.01
2436.14	2342.38
2438.93	2302.75
2441.71	2379.12
2444.5	2333.49
2447.28	2389.86
2450.06	2363.23
2452.84	2359.6
2455.62	2374.97
2458.4	2376.34
2461.18	2363.71
2463.95	2396.08
2466.73	2419.45
2469.5	2412.82
2472.28	2399.19
2475.05	2392.56
2477.82	2420.93
2480.59	2408.3
2483.36	2373.67
2486.13	2433.04
2488.9	2375.41
2491.66	2419.78
2494.43	2403.15
2497.19	2350.52
2499.96	2444.89
2502.72	2421.26
2505.48	2406.63
2508.24	2426
2511	2381.37
2513.76	2418.74
2516.52	2418.11
2519.28	2385.48
2522.03	2379.85
2524.79	2407.22
2527.54	2393.59
2530.29	2416.96
2533.04	2423.33
2535.8	2425.7
2538.54	2427.07
2541.29	2413.44
2544.04	2374.81
2546.79	2406.18
2549.53	2415.55
2552.28	2408.92
2555.02	2430.28
2557.77	2446.65
2560.51	2429.02
2563.25	2442.39
2565.99	2429.76
2568.73	2420.13
2571.47	2421.5
2574.2	2436.87
2576.94	2445.24
2579.67	2473.61
2582.41	2451.98
2585.14	2492.35
2587.87	2478.72
2590.6	2535.09
2593.33	2526.46
2596.06	2526.83
2598.79	2474.2
2601.52	2480.57
2604.24	2556.94
2606.97	2558.31
2609.7	2538.68
2612.42	2544.05
2615.14	2502.42
2617.86	2543.79
2620.58	2580.16
2623.3	2552.53
2626.02	2570.9
2628.74	2556.27
2631.45	2565.64
2634.17	2589.01
2636.88	2549.38
2639.6	2559.75
2642.31	2574.12
2645.02	2566.49
2647.73	2612.86
2650.44	2601.23
2653.15	2559.6
2655.86	2596.97
2658.57	2587.34
2661.27	2594.71
2663.98	2581.08
2666.68	2542.45
2669.38	2572.82
2672.09	2590.19
2674.79	2590.56
2677.49	2590.93
2680.19	2571.29
2682.89	2585.66
2685.58	2601.53
2688.28	2592.4
2690.98	2580.77
2693.67	2607.14
2696.36	2603.51
2699.05	2643.88
2701.75	2584.25
2704.44	2605.62
2707.13	2635.99
2709.82	2673.36
2712.5	2622.73
2715.19	2608.1
2717.88	2597.47
2720.56	2635.84
2723.25	2607.21
2725.93	2632.58
2728.61	2632.95
2731.29	2628.32
2733.97	2652.69
2736.65	2641.06
2739.33	2647.43
2742.01	2691.8
2744.68	2696.17
2747.36	2675.54
2750.03	2684.91
2752.71	2675.28
2755.38	2641.65
2758.05	2653.02
2760.72	2644.39
2763.39	2716.76
2766.06	2689.13
2768.73	2692.5
2771.39	2791.87
2774.06	2680.24
2776.72	2700.61
2779.39	2724.98
2782.05	2735.35
2784.72	2715.72
2787.38	2740.09
2790.04	2744.46
2792.7	2749.83
2795.35	2716.2
2798.01	2743.57
2800.67	2744.94
2803.32	2734.31
2805.98	2747.68
2808.63	2779.04
2811.29	2727.41
2813.94	2801.78
2816.59	2795.15
2819.24	2762.52
2821.89	2797.89
2824.53	2801.26
2827.18	2732.63
2829.83	2785
2832.47	2763.37
2835.12	2750.74
2837.76	2797.11
2840.4	2783.48
2843.04	2763.85
2845.69	2766.22
2848.33	2804.59
2850.96	2789.96
2853.6	2790.33
2856.24	2789.7
2858.87	2793.07
2861.51	2789.44
2864.14	2828.81
2866.78	2864.18
2869.41	2849.55
2872.04	2771.92
2874.67	2820.29
2877.3	2806.66
2879.93	2845.03
2882.56	2779.4
2885.18	2818.77
2887.81	2850.14
2890.43	2842.51
2893.06	2896.88
2895.68	2871.25
2898.3	2838.62
2900.93	2853.99
2903.55	2880.36
2906.17	2862.73
2908.78	2834.1
2911.4	2835.47
2914.02	2825.84
2916.63	2855.21
2919.25	2841.58
2921.86	2869.95
2924.48	2851.32
2927.09	2869.69
2929.7	2866.05
2932.31	2855.42
2934.92	2854.79
2937.53	2833.16
2940.13	2861.53
2942.74	2831.9
2945.35	2846.27
2947.95	2852.64
2950.55	2865.01
2953.16	2828.57
2955.76	2884.63
2958.36	2874.53
2960.96	2832.2
2963.56	2831.47
2966.16	2848.84
2968.76	2843.05
2971.35	2897.64
2973.95	2869.46
2976.54	2897.59
2979.14	2888.51
2981.73	2880.51
2984.32	2894.71
2986.91	2847.56
2989.5	2899.61
2992.09	2884.93
2994.68	2888.87
2997.27	2888.89
2999.85	2874.37
3002.44	2895.9
3005.02	2894.27
3007.61	2922.84
3010.19	2902.07
3012.77	2899.21
3015.35	2940.2
3017.93	2890.36
3020.51	2928.54
3023.09	2876.98
3025.67	2961.62
3028.25	2901.26
3030.82	2901.86
3033.4	2932.85
3035.97	2885.55
3038.54	2947.2
3041.12	2914.91
3043.69	2929
3046.26	2924.94
3048.83	2895.43
3051.4	2961.88
3053.96	2940.14
3056.53	2921.28
3059.1	2947.25
3061.66	2939.41
3064.23	2944.39
3066.79	2956.8
3069.35	2849.76
3071.91	2911.31
3074.47	2914.72
3077.03	2938.21
3079.59	2886.05
3082.15	2935.48
3083.52	2919.02
3086.08	2970.23
3088.65	2978.45
3091.22	2956.66
3093.79	2951.87
3096.35	2956.08
3098.92	2948.29
3101.48	2952.5
3104.04	2952.71
3106.6	2936.93
3109.16	2887.14
3111.72	2986.35
3114.28	2943.56
3116.84	2966.77
3119.4	2893.98
3121.95	2935.19
3124.51	2973.41
3127.06	2965.62
3129.62	2966.83
3132.17	2952.04
3134.72	2963.25
3137.27	2948.46
3139.82	2974.67
3142.37	2943.88
3144.92	2936.1
3147.47	2972.31
3150.01	2987.52
3152.56	2979.73
3155.1	3004.94
3157.65	3000.15
3160.19	2983.36
3162.73	2957.58
3165.28	2996.79
3167.81	2980
3170.35	3004.21
3172.89	2956.42
3175.43	2975.63
3177.97	2984.84
3180.5	2997.05
3183.04	2949.27
3185.57	2943.48
3188.11	3001.69
3190.64	3007.9
3193.17	2933.11
3195.7	2992.32
3198.23	2970.53
3200.76	2973.75
3203.29	2961.96
3205.82	2925.17
3208.35	2966.38
3210.87	2912.59
3213.4	2955.8
3215.92	2960.01
3218.44	2916.22
3220.97	2937.44
3223.49	2919.65
3226.01	2988.86
3228.53	2912.07
3231.05	2924.28
3233.56	2907.49
3236.08	2939.7
3238.6	2873.92
3241.11	2916.13
3243.63	2910.34
3246.14	2929.55
3248.65	2934.76
3251.17	2952.97
3253.68	2907.18
3256.19	2913.39
3258.7	2915.61
3261.21	2888.82
3263.71	2962.03
3266.22	2937.24
3268.73	2932.45
3271.23	2929.66
3273.74	2933.87
3276.24	2944.09
3278.74	2944.3
3281.24	2898.51
3283.74	2938.72
3286.24	2944.93
3288.74	2943.14
3291.24	2959.35
3293.74	2918.56
3296.23	2927.78
3298.73	2914.99
3301.23	2979.2
3303.72	2956.41
3306.21	2957.62
3308.71	2985.83
3311.2	2968.04
3313.69	2964.26
3316.18	2954.47
3318.67	2954.68
3321.15	2990.89
3323.64	2961.1
3326.13	2962.31
3328.61	2936.52
3331.1	2949.73
3333.58	2955.95
3336.07	2955.16
3338.55	2966.37
3341.03	2908.58
3343.51	2934.79
3345.99	2927
3348.47	2970.21
3350.95	2957.43
3353.42	2937.64
3355.9	2939.85
3358.38	2923.06
3360.85	2903.27
3363.32	2939.48
3365.8	2962.69
3368.27	2930.9
3370.74	2908.12
3373.21	2901.33
3375.68	2939.54
3378.15	2873.75
3380.62	2900.96
3383.08	2885.17
3385.55	2856.38
3388.02	2901.6
3390.48	2880.81
3392.94	2910.02
3395.41	2939.23
3397.87	2930.44
3400.33	2947.65
3402.79	2947.86
3405.25	2917.07
3407.71	2931.29
3410.17	2850.5
3412.62	2926.71
3415.08	2916.92
3417.54	2933.13
3419.99	2935.34
3422.44	2907.55
3424.9	2911.77
3427.35	2974.98
3429.8	2956.19
3432.25	2975.4
3434.7	2933.61
3437.15	2950.82
3439.6	2959.03
3442.04	2981.24
3444.49	2976.46
3446.94	3017.67
3449.38	2957.88
3451.82	2993.09
3454.27	2979.3
3456.71	2984.51
3459.15	2988.72
3461.59	2979.94
3464.03	3011.15
3466.47	2987.36
3468.91	3016.57
3471.34	2999.78
3473.78	3001.99
3476.22	2992.2
3478.65	3012.41
3481.08	2991.63
3483.52	2958.84
3485.95	2992.05
3488.38	2996.26
3490.81	3004.47
3493.24	2993.68
3495.67	2911.89
3498.1	2939.11
3500.53	2932.32
3502.95	2918.53
3505.38	2964.74
3507.8	2899.95
3510.23	2893.16
3512.65	2855.37
3515.07	2900.58
3517.5	2979.8
3519.92	2864.01
3522.34	2876.22
3524.76	2893.43
3527.17	2892.64
3529.59	2864.85
3532.01	2859.06
3534.42	2901.28
3536.84	2879.49
3539.25	2872.7
3541.67	2948.91
3544.08	2902.12
3546.49	2926.33
3548.9	2880.54
3551.31	2909.75
3553.72	2894.97
3556.13	2851.18
3558.54	2880.39
3560.95	2867.6
3563.35	2850.81
3565.76	2938.02
3568.16	2898.23
3570.57	2909.45
3572.97	2907.66
3575.37	2900.87
3577.77	2954.08
3580.17	2925.29
3582.57	2929.5
3584.97	2904.71
3587.37	2968.92
3589.77	2978.14
3592.17	2982.35
3594.56	2943.56
3596.96	2936.77
3599.35	2966.98
3601.74	2986.19
3604.14	2960.4
3606.53	2970.62
3608.92	2974.83
3611.31	2977.04
3613.7	2950.25
3616.09	2927.46
3618.47	2960.67
3620.86	2949.88
3623.25	2991.09
3625.63	2967.31
3628.02	2942.52
3630.4	2955.73
3632.78	2970.94
3635.17	2973.15
3637.55	2956.36
3639.93	2977.57
3642.31	2974.79
3644.69	2919
3647.06	2982.21
3649.44	2927.42
3651.82	2949.63
3654.2	2965.84
3656.57	2924.05
3658.94	2916.27
3661.32	2895.48
3663.69	2881.69
3666.06	2931.9
3668.43	2905.11
3670.8	2884.32
3673.17	2867.53
3675.54	2949.74
3677.91	2887.96
3680.28	2880.17
3682.64	2948.38
3685.01	2816.59
3687.37	2893.8
3689.74	2901.01
3692.1	2886.22
3694.46	2887.44
3696.82	2875.65
3699.18	2893.86
3701.54	2867.07
3703.9	2862.28
3706.26	2893.49
3708.62	2858.7
3710.98	2869.91
3713.33	2878.13
3715.69	2887.34
3718.04	2857.55
3720.4	2878.76
3722.75	2886.97
3725.1	2890.18
3727.45	2905.39
3729.8	2880.6
3732.15	2904.82
3734.5	2937.03
3736.85	2950.24
3739.2	2948.45
3741.54	2950.66
3743.89	2913.87
3746.23	2942.08
3748.58	2948.3
3750.92	2916.51
3753.27	2944.72
3755.61	2949.93
3757.95	2943.14
3760.29	2915.35
3762.63	2968.56
3764.97	2937.78
3767.3	2911.99
3769.64	2937.2
3771.98	2973.41
3774.32	2910.62
3776.65	2964.83
3778.99	2941.04
3781.32	2954.25
3783.65	2923.47
3785.98	2910.68
3788.31	2922.89
3790.64	2922.1
3792.97	2892.31
3795.3	2939.52
3797.63	2923.73
3799.96	2893.95
3802.28	2923.16
3804.61	2898.37
3806.93	2883.58
3809.26	2899.79
3811.58	2898
3813.9	2893.21
3816.23	2855.42
3818.55	2912.64
3820.87	2806.85
3823.19	2806.06
3825.51	2889.27
3827.82	2837.48
3830.14	2841.69
3832.46	2885.9
3834.77	2849.12
3837.09	2869.33
3839.4	2838.54
3841.72	2774.75
3844.03	2860.96
3846.34	2835.17
3848.65	2805.38
3850.96	2857.59
3853.27	2822.81
3855.58	2859.02
3857.89	2823.23
3860.2	2874.44
3862.5	2806.65
3864.81	2807.86
3867.11	2852.07
3869.42	2851.29
3871.72	2863.5
3874.02	2865.71
3876.33	2869.92
3878.63	2867.13
3880.93	2848.34
3883.23	2872.55
3885.53	2891.76
3887.82	2910.98
3890.12	2849.19
3892.42	2888.4
3894.72	2896.61
3897.01	2883.82
3899.3	2911.03
3901.6	2886.24
3903.89	2907.46
3906.18	2895.67
3908.47	2924.88
3910.76	2887.09
3913.05	2917.3
3915.34	2919.51
3917.63	2949.72
3919.92	2910.93
3922.21	2917.15
3924.49	2873.36
3926.78	2822.57
3929.06	2838.78
3931.35	2868.99
3933.63	2907.2
3935.91	2907.41
3938.19	2902.63
3940.47	2861.84
3942.75	2884.05
3945.03	2861.26
3947.31	2843.47
3949.59	2882.68
3951.87	2866.89
3954.14	2892.1
3956.42	2861.32
3958.69	2874.53
3960.97	2858.74
3963.24	2844.95
3965.51	2852.16
3967.79	2837.37
3970.06	2814.58
3972.33	2786.8
3974.6	2823.01
3976.87	2825.22
3979.13	2821.43
3981.4	2824.64
3983.67	2814.85
3985.93	2784.06
3988.2	2791.27
3990.46	2772.49
3992.73	2827.7
3994.99	2838.91
3997.25	2828.12
3999.51	2834.33