File: muestras/ins/In2S3-_5_5_03.txt
#Acq. time (s)=	25
#Accumulations=	6
#Range (cm-¹)=	50...450
#Windows=	1
#Autofocus=	Off
#AutoExposure=	Off
#Spike filter=	Multiple accum.
#Delay time (s)=	0
#Binning=	1
#Readout mode=	Signal
#DeNoise=	Off
#ICS correction=	Off
#Dark correction=	Off
#Inst. Process=	Off
#Instrument=	LabRAM HR Evol
#Detector=	Syncerity OE
#Objective=	x100_VIS_LWD
#Grating=	600 (500nm)
#ND Filter=	100%
#Laser=	633nm_Edge
#Hole=	100.021
#Range=	Visible
#Project=	Antony
#Sample=	In2S3-5.1
#Site=	23_03_2023
#Title=	In2S3-_5_5
#Remark=
#Date=	28.03.2023 10:39
#Acquired=	28.03.2023 10:39:19
50.2258	378
51.5191	374.4
52.8106	375.6
54.102	376.8
55.3931	400.4
56.6855	500
57.9762	673.6
59.2667	839.2
60.557	1007.2
61.847	1174.4
63.1384	1274.8
64.4281	1299.2
65.7175	1285.6
67.0067	1291.2
68.2957	1366
69.586	1528
70.8746	1850.8
72.163	2079.6
73.4511	1760.8
74.7391	1411.6
76.0268	1245.6
77.3144	1148.4
78.6017	1097.6
79.8903	1089.2
81.1772	1042
82.4639	1027.6
83.7504	1032.4
85.0367	1010.8
86.3227	1013.6
87.6086	1016
88.8942	1002.4
90.1796	1002.4
91.4648	1021.6
92.7498	1004.8
94.0346	990.8
95.3192	977.6
96.6036	993.2
97.8878	1010
99.1717	992.4
100.455	1001.6
101.739	997.6
103.022	996.4
104.305	1020.4
105.588	1014.8
106.871	998
108.154	982.8
109.436	974
110.718	991.6
112	1000.4
113.281	1053.6
114.563	1118
115.844	1127.6
117.125	1054.8
118.406	1008
119.685	1007.6
120.965	998
122.246	990.4
123.526	968
124.805	945.6
126.085	950
127.364	937.2
128.642	953.6
129.921	934
131.199	926
132.478	930.8
133.756	921.6
135.033	907.6
136.311	931.6
137.588	914.8
138.866	930.8
140.143	909.6
141.419	903.2
142.696	905.2
143.972	904.8
145.249	912.4
146.523	923.6
147.799	909.2
149.075	908
150.349	912
151.625	919.6
152.9	904.8
154.175	922.8
155.448	918.4
156.723	922.8
157.997	914
159.27	920.4
160.544	950.4
161.816	951.6
163.089	948.8
164.363	972.8
165.634	963.6
166.907	976
168.18	986.4
169.451	1008.4
170.723	1024.8
171.994	1016
173.266	1039.6
174.536	1053.2
175.807	1058.4
177.079	1054
178.348	1046.4
179.619	1060.4
180.888	1072
182.158	1066.8
183.427	1056
184.697	1040.4
185.966	1036.8
187.235	1037.6
188.503	1018
189.772	1022.8
191.04	1026
192.308	1004.4
193.576	1014.4
194.844	1018
196.111	1031.2
197.377	1044
198.645	1011.2
199.911	1031.2
201.178	1019.2
202.444	1038
203.709	1032.8
204.976	1035.6
206.241	1043.6
207.507	1027.2
208.772	1056
210.036	1031.2
211.302	1058.8
212.566	1051.6
213.83	1080
215.095	1070
216.358	1073.6
217.621	1059.2
218.886	1061.2
220.149	1087.2
221.411	1078.8
222.675	1107.2
223.937	1089.2
225.199	1106
226.461	1086.8
227.724	1125.6
228.985	1096
230.246	1102.8
231.507	1134.4
232.768	1131.2
234.03	1171.6
235.29	1207.2
236.55	1242.4
237.81	1302.8
239.071	1378.4
240.331	1469.6
241.59	1574
242.849	1683.2
244.108	1814.4
245.367	1892
246.625	1899.2
247.885	1836
249.143	1790.8
250.401	1682.4
251.659	1598
252.916	1528
254.173	1495.6
255.43	1426.8
256.687	1415.6
257.944	1399.2
259.2	1400
260.457	1395.2
261.714	1404
262.97	1380
264.226	1420.4
265.481	1438
266.736	1435.6
267.991	1439.2
269.246	1422.8
270.501	1396.4
271.755	1349.2
273.009	1292.4
274.263	1259.2
275.517	1221.6
276.771	1204
278.023	1209.2
279.276	1206.8
280.529	1201.2
281.782	1175.6
283.034	1177.2
284.287	1201.6
285.539	1174.8
286.791	1215.6
288.043	1214.8
289.294	1242
290.546	1227.6
291.795	1263.2
293.046	1266
294.297	1280.4
295.548	1282.4
296.798	1323.6
298.048	1356.4
299.297	1398
300.546	1482.4
301.796	1535.6
303.045	1630.4
304.295	1727.2
305.542	1851.2
306.791	1944
308.039	2018
309.288	2030
310.534	1914.4
311.782	1844
313.03	1746.4
314.278	1601.2
315.524	1550.4
316.771	1473.6
318.018	1394.4
319.263	1368.4
320.51	1363.2
321.756	1322
323.002	1312.4
324.247	1300.8
325.492	1318.4
326.736	1324
327.982	1307.6
329.227	1304.4
330.47	1299.6
331.715	1239.6
332.96	1231.2
334.203	1211.6
335.447	1187.2
336.689	1183.6
337.933	1166
339.176	1162.8
340.418	1161.2
341.661	1127.2
342.903	1136
344.146	1119.2
345.387	1110.4
346.629	1107.2
347.87	1097.2
349.112	1088
350.352	1073.6
351.594	1071.6
352.834	1050.4
354.075	1072
355.314	1070.4
356.555	1054.4
357.794	1094
359.034	1082.8
360.273	1116.8
361.513	1152.8
362.751	1185.2
363.989	1213.2
365.229	1244.8
366.466	1281.2
367.705	1296
368.943	1307.2
370.18	1294
371.418	1260.8
372.655	1196.4
373.891	1157.6
375.129	1116.8
376.365	1062.8
377.601	1048
378.838	1009.6
380.074	993.2
381.309	952
382.546	964
383.781	964.4
385.016	935.6
386.25	944.8
387.486	926
388.72	936.8
389.954	934
391.188	917.2
392.423	926.4
393.656	950.8
394.889	915.2
396.122	940
397.356	907.2
398.589	912.8
399.821	920
401.053	919.6
402.285	919.6
403.517	915.2
404.75	908.8
405.982	905.2
407.213	897.2
408.444	925.2
409.675	904.4
410.905	912.4
412.136	923.6
413.366	912.8
414.597	918
415.827	924.8
417.057	920.4
418.286	919.6
419.515	915.2
420.744	910
421.973	915.2
423.202	908.4
424.43	912.4
425.658	930.8
426.886	918.4
428.114	897.6
429.342	918.8
430.569	910.8
431.797	900.8
433.024	911.2
434.25	899.6
435.477	912.8
436.704	923.6
437.93	916
439.156	908.4
440.382	921.2
441.608	916.4
442.832	923.6
444.057	920
445.282	936.4
446.507	932
447.732	935.6
448.956	914