File: muestras/papalo/leaf_100x_08.txt
#Acq. time (s)=	10
#Accumulations=	1
#Range (cm-¹)=	200...3000
#Windows=	3
#Autofocus=	Off
#AutoExposure=	Off
#Spike filter=	Off
#Delay time (s)=	0
#Binning=	1
#Readout mode=	Signal
#DeNoise=	Off
#ICS correction=	Off
#Dark correction=	Off
#Inst. Process=	Off
#Instrument=	LabRAM HR Evol
#Detector=	Syncerity OE
#Objective=	x100_VIS
#Grating=	600 (500nm)
#ND Filter=	0.1%
#Laser=	633nm_Edge
#Hole=	100.021
#Range=	Visible
#Project=	Omar
#Sample=	03-07-23
#Site=	papal
#Title=	leaf_100x
#Remark=
#Date=	03.07.2023 17:17
#Acquired=	03.07.2023 17:17:13
201.713	162
204.247	164
206.778	178
209.311	168
211.84	176
214.371	158
216.899	190
219.428	194
221.955	178
224.482	178
227.007	184
229.531	196
232.055	188
234.579	208
237.1	216
239.621	190
242.141	190
244.661	210
247.179	206
249.698	214
252.215	234
254.731	230
257.246	226
259.761	234
262.273	232
264.786	238
267.298	222
269.809	226
272.319	224
274.828	246
277.336	262
279.844	242
282.351	250
284.855	260
287.361	246
289.866	254
292.368	270
294.871	266
297.372	262
299.873	270
302.372	276
304.872	282
307.37	306
309.866	276
312.364	288
314.859	302
317.353	318
319.848	296
322.341	294
324.833	308
327.324	324
329.814	330
332.304	334
334.792	316
337.28	328
339.767	358
342.254	352
344.739	348
347.224	334
349.708	348
352.191	362
354.673	378
357.155	366
359.634	386
362.114	384
364.593	372
367.07	420
369.548	380
372.024	404
374.499	406
376.974	396
379.447	428
381.92	436
384.392	418
386.864	398
389.333	450
391.802	424
394.272	464
396.739	444
399.206	438
401.673	480
404.138	454
406.602	498
409.066	468
411.528	494
413.99	460
416.451	488
418.911	488
421.371	506
423.83	514
426.288	518
428.745	558
431.201	520
433.657	540
436.111	538
438.565	538
441.017	544
443.469	590
445.921	558
448.37	566
450.821	594
453.27	600
455.717	584
458.165	582
460.61	638
463.056	622
465.5	626
467.945	618
470.387	612
472.829	634
475.271	630
477.711	622
480.15	648
482.589	662
485.027	652
487.465	652
489.901	706
492.337	700
494.771	744
497.205	734
499.638	716
502.07	714
504.502	754
506.933	762
509.363	746
511.792	722
514.219	750
516.647	762
519.073	780
521.5	782
523.924	778
526.348	776
528.772	824
531.194	846
533.616	816
536.036	848
538.457	820
540.875	808
543.294	844
545.712	870
548.128	850
550.545	832
552.959	882
555.373	864
557.788	886
560.2	926
562.612	900
565.023	936
567.433	918
569.843	950
572.251	998
574.659	978
577.066	958
579.472	992
581.878	1054
584.283	1008
586.687	1080
589.09	1022
591.493	1054
593.893	1038
596.294	1040
598.694	1076
601.093	1100
603.491	1118
605.889	1094
608.285	1118
610.682	1150
613.076	1182
615.471	1202
617.864	1190
620.256	1220
622.648	1216
625.039	1220
627.429	1264
629.819	1296
632.208	1278
634.595	1300
636.982	1310
639.369	1342
641.755	1338
644.139	1408
646.523	1424
648.906	1404
651.288	1430
653.67	1422
656.051	1476
658.429	1466
660.808	1510
663.187	1542
665.565	1520
667.942	1536
670.317	1572
672.692	1570
675.067	1582
677.44	1634
679.813	1674
682.184	1554
684.556	1656
686.926	1638
689.296	1630
691.664	1720
694.033	1670
696.4	1762
698.766	1794
701.133	1866
703.497	1818
705.861	1850
708.224	1872
710.586	1884
712.949	1946
715.31	1920
717.67	1920
720.029	1974
722.388	2002
724.746	2080
727.103	2072
729.458	2076
731.814	2112
734.168	2104
736.523	2162
738.876	2186
741.227	2208
743.579	2262
745.931	2270
748.28	2276
750.629	2302
752.977	2430
755.325	2374
757.672	2440
760.018	2476
762.363	2488
764.708	2532
767.052	2560
769.394	2536
771.737	2584
774.078	2534
776.419	2588
778.758	2692
781.097	2752
783.435	2738
785.773	2770
788.11	2802
790.446	2816
792.781	2872
795.115	2874
797.449	3024
799.782	2974
802.115	2978
804.446	3096
806.777	3110
809.106	3124
811.435	3198
813.764	3188
816.091	3266
818.418	3302
820.743	3430
823.069	3388
825.393	3484
827.717	3530
830.039	3592
832.362	3570
834.683	3670
837.003	3660
839.324	3762
841.643	3768
843.961	3834
846.278	3872
848.594	3906
850.91	3924
853.227	4028
855.541	4062
857.855	4132
860.168	4132
862.48	4208
864.79	4262
867.101	4386
869.411	4366
871.721	4400
874.029	4500
876.336	4530
878.643	4524
880.95	4634
883.254	4604
885.559	4672
887.862	4770
890.166	4852
892.467	4856
894.77	4902
897.07	4980
899.371	5004
901.669	4962
903.968	5070
906.266	5118
908.563	5262
910.859	5274
913.154	5338
915.449	5366
917.742	5438
920.036	5478
922.329	5524
924.621	5568
926.911	5674
929.201	5758
931.49	5736
933.779	5948
936.068	5958
938.355	6022
940.64	6112
942.926	6164
945.212	6158
947.495	6266
949.779	6372
952.062	6474
954.344	6434
956.625	6572
958.905	6620
961.184	6718
963.464	6766
965.742	6814
968.02	7012
970.296	6860
972.572	7018
974.847	7130
977.121	7184
979.396	7218
981.669	7448
983.941	7378
986.212	7454
988.483	7534
990.753	7640
993.022	7670
995.29	7672
997.558	7792
999.825	7834
1002.09	8032
1004.36	8040
1006.62	8166
1008.89	8128
1011.15	8410
1013.41	8286
1015.67	8546
1017.93	8550
1020.19	8602
1022.45	8740
1024.71	8864
1026.97	8982
1029.23	9054
1031.49	9048
1033.74	9146
1036	9400
1038.25	9336
1040.5	9480
1042.76	9640
1045.01	9694
1047.26	9790
1049.51	9844
1051.76	9884
1054.01	10214
1056.26	10138
1058.51	10294
1060.75	10348
1063	10426
1065.25	10692
1067.49	10660
1069.73	10830
1071.98	10636
1074.22	10798
1076.46	10842
1078.7	11042
1080.94	11080
1083.18	11156
1085.42	11160
1087.66	11348
1089.9	11374
1092.14	11370
1094.37	11414
1096.61	11550
1098.84	11612
1101.08	11716
1103.31	11880
1105.54	11854
1107.77	11814
1110	12044
1112.23	12044
1114.46	12108
1116.69	12300
1118.92	12194
1121.15	12340
1123.37	12544
1125.6	12348
1127.83	12580
1130.05	12486
1132.27	12686
1134.5	12854
1136.72	12796
1138.94	12858
1141.16	12826
1143.38	13090
1145.6	13190
1147.82	13282
1150.04	13224
1152.26	13276
1154.47	13334
1156.69	13310
1158.9	13568
1161.12	13484
1163.33	13584
1165.54	13626
1167.76	13612
1169.97	13622
1172.18	13692
1174.39	13796
1176.6	13926
1178.81	13576
1181.02	13684
1183.22	13782
1185.43	13832
1187.63	13684
1189.84	13676
1192.04	13752
1194.25	13658
1196.45	13716
1198.65	13602
1200.85	13606
1203.05	13528
1205.25	13712
1207.45	13616
1209.65	13512
1211.85	13534
1214.05	13460
1216.24	13394
1218.44	13294
1220.64	13328
1222.83	13144
1225.02	13196
1227.22	13106
1229.41	13092
1231.6	12880
1233.79	13044
1235.98	12782
1238.17	13008
1240.36	12856
1242.55	12770
1244.73	12660
1246.92	12700
1249.11	12632
1251.29	12556
1253.48	12568
1255.66	12412
1257.84	12412
1260.03	12374
1262.21	12204
1264.39	12168
1266.57	12232
1268.75	12100
1270.93	11940
1273.11	11816
1275.28	11844
1277.46	11940
1279.64	11768
1281.81	11690
1283.98	11566.8
1286.16	11434.7
1288.33	11376.5
1290.5	11283.5
1292.68	11115
1294.85	11142.1
1297.02	11064.3
1299.19	10955.3
1301.36	10778.9
1303.53	10736.8
1305.69	10579.6
1307.86	10389.6
1310.03	10245.5
1312.19	10261.4
1314.36	10166.3
1316.52	10080.7
1318.68	9989.25
1320.85	9824.27
1323.01	9712.71
1325.17	9651.69
1327.33	9609.13
1329.49	9407.97
1331.65	9349.84
1333.81	9214
1335.97	9163.71
1338.12	9065.01
1340.28	8924.47
1342.44	8785.92
1344.59	8724.57
1346.75	8618.19
1348.9	8546.57
1351.05	8510.73
1353.2	8398.6
1355.36	8352.63
1357.51	8288.8
1359.66	8107.75
1361.81	8059.04
1363.96	7943.78
1366.1	7868.2
1368.25	7825.66
1370.4	7788.65
1372.54	7704.29
1374.69	7623.28
1376.83	7528.98
1378.98	7420.75
1381.12	7367.5
1383.26	7240.17
1385.41	7216.92
1387.55	7124.38
1389.69	7025.58
1391.83	7075.77
1393.02	7068
1395.17	6914
1397.32	6874
1399.47	6784
1401.62	6798
1403.77	6694
1405.91	6778
1408.06	6594
1410.2	6626
1412.35	6468
1414.49	6530
1416.63	6494
1418.78	6370
1420.92	6414
1423.06	6208
1425.2	6290
1427.34	6268
1429.48	6168
1431.61	6082
1433.75	6034
1435.89	5962
1438.02	6082
1440.16	5978
1442.3	5956
1444.43	5792
1446.56	5908
1448.7	5844
1450.83	5800
1452.96	5682
1455.09	5720
1457.22	5738
1459.35	5542
1461.48	5588
1463.61	5568
1465.73	5612
1467.86	5638
1469.98	5420
1472.11	5552
1474.24	5408
1476.36	5374
1478.48	5376
1480.6	5354
1482.73	5286
1484.85	5294
1486.97	5222
1489.09	5276
1491.21	5298
1493.33	5228
1495.44	5232
1497.56	5040
1499.68	5094
1501.79	5080
1503.91	5062
1506.02	4938
1508.14	5034
1510.25	4906
1512.36	4912
1514.48	4856
1516.59	4848
1518.7	4844
1520.81	4806
1522.92	4782
1525.02	4690
1527.13	4740
1529.24	4664
1531.35	4612
1533.45	4612
1535.56	4574
1537.66	4574
1539.77	4572
1541.87	4544
1543.97	4524
1546.08	4514
1548.18	4452
1550.28	4412
1552.38	4398
1554.48	4366
1556.57	4394
1558.67	4348
1560.77	4212
1562.87	4320
1564.96	4284
1567.06	4278
1569.15	4320
1571.25	4284
1573.34	4190
1575.43	4262
1577.53	4146
1579.62	4206
1581.71	4190
1583.8	4080
1585.89	4138
1587.98	4134
1590.06	4044
1592.15	4118
1594.24	4058
1596.33	3920
1598.41	4118
1600.5	4028
1602.58	4028
1604.66	3940
1606.75	4052
1608.83	4032
1610.91	3972
1612.99	4000
1615.07	3954
1617.15	4038
1619.23	3992
1621.31	3930
1623.39	3898
1625.46	3846
1627.54	3898
1629.62	3840
1631.69	3902
1633.77	3828
1635.84	3902
1637.91	3874
1639.99	3824
1642.06	3880
1644.13	3808
1646.2	3770
1648.27	3744
1650.34	3768
1652.41	3764
1654.47	3762
1656.54	3730
1658.61	3798
1660.67	3716
1662.74	3666
1664.81	3668
1666.87	3692
1668.93	3636
1671	3670
1673.06	3634
1675.12	3644
1677.18	3698
1679.24	3538
1681.3	3670
1683.36	3660
1685.42	3544
1687.47	3552
1689.53	3542
1691.59	3574
1693.64	3500
1695.7	3524
1697.75	3520
1699.81	3546
1701.86	3438
1703.91	3462
1705.97	3450
1708.02	3414
1710.07	3464
1712.12	3424
1714.17	3414
1716.22	3422
1718.26	3476
1720.31	3446
1722.36	3446
1724.4	3426
1726.45	3396
1728.49	3392
1730.54	3410
1732.58	3432
1734.63	3408
1736.67	3334
1738.71	3412
1740.75	3370
1742.79	3360
1744.83	3324
1746.87	3342
1748.91	3326
1750.95	3328
1752.98	3292
1755.02	3332
1757.06	3428
1759.09	3282
1761.13	3408
1763.16	3342
1765.19	3356
1767.23	3344
1769.26	3366
1771.29	3314
1773.32	3338
1775.35	3270
1777.38	3278
1779.41	3370
1781.44	3298
1783.47	3230
1785.49	3310
1787.52	3284
1789.55	3306
1791.57	3296
1793.6	3266
1795.62	3326
1797.64	3242
1799.67	3324
1801.69	3296
1803.71	3280
1805.73	3310
1807.75	3200
1809.77	3210
1811.79	3284
1813.81	3246
1815.83	3256
1817.84	3280
1819.86	3244
1821.88	3262
1823.89	3334
1825.91	3278
1827.92	3254
1829.93	3222
1831.95	3164
1833.96	3248
1835.97	3240
1837.98	3194
1839.99	3246
1842	3196
1844.01	3228
1846.02	3222
1848.03	3226
1850.03	3146
1852.04	3172
1854.05	3170
1856.05	3198
1858.06	3142
1860.06	3152
1862.06	3134
1864.07	3176
1866.07	3158
1868.07	3134
1870.07	3160
1872.07	3126
1874.07	3170
1876.07	3192
1878.07	3134
1880.07	3136
1882.07	3116
1884.06	3096
1886.06	3154
1888.05	3142
1890.05	3036
1892.04	3120
1894.04	3146
1896.03	3158
1898.02	3082
1900.01	3146
1902	3108
1903.99	3108
1905.98	3096
1907.97	3202
1909.96	3082
1911.95	3140
1913.94	3142
1915.93	3170
1917.91	3120
1919.9	3104
1921.88	3088
1923.87	3028
1925.85	3078
1927.83	3144
1929.82	3114
1931.8	3088
1933.78	3080
1935.76	3106
1937.74	3092
1939.72	3062
1941.7	3038
1943.68	3134
1945.65	3040
1947.63	3034
1949.61	3058
1951.58	3072
1953.56	3008
1955.53	3058
1957.51	3010
1959.48	2990
1961.45	3028
1963.43	3056
1965.4	3000
1967.37	3084
1969.34	3058
1971.31	2994
1973.28	2950
1975.25	2998
1977.22	3062
1979.18	2988
1981.15	3006
1983.12	2960
1985.08	3006
1987.05	3008
1989.01	3004
1990.97	2992
1992.94	2998
1994.9	2998
1996.86	3002
1998.82	2944
2000.78	2952
2002.74	3002
2004.7	2960
2006.66	2968
2008.62	2938
2010.58	2952
2012.54	3010
2014.49	2974
2016.45	2968
2018.4	2960
2020.36	2968
2022.31	2872
2024.27	2902
2026.22	2964
2028.17	2958
2030.12	2904
2032.07	2886
2034.03	2918
2035.98	2906
2037.93	2882
2039.87	2958
2041.82	2960
2043.77	2894
2045.72	2950
2047.66	2928
2049.61	2932
2051.55	2970
2053.5	2918
2055.44	2888
2057.39	2910
2059.33	2912
2061.27	2898
2063.21	2980
2065.15	2868
2067.09	2848
2069.03	2836
2070.97	2938
2072.91	2846
2074.85	2842
2076.79	2884
2078.73	2822
2080.66	2868
2082.6	2834
2084.53	2918
2086.47	2840
2088.4	2812
2090.33	2924
2092.27	2824
2094.2	2862
2096.13	2904
2098.06	2884
2099.99	2818
2101.92	2850
2103.85	2860
2105.78	2872
2107.71	2848
2109.64	2828
2111.56	2850
2113.49	2906
2115.41	2854
2117.34	2868
2119.26	2834
2121.19	2838
2123.11	2882
2125.03	2904
2126.96	2818
2128.88	2818
2130.8	2792
2132.72	2760
2134.64	2798
2136.56	2886
2138.48	2780
2140.4	2776
2142.31	2768
2144.23	2768
2146.15	2752
2148.06	2788
2149.98	2790
2151.89	2766
2153.81	2764
2155.72	2742
2157.63	2798
2159.55	2710
2161.46	2762
2163.37	2774
2165.28	2744
2167.19	2716
2169.1	2750
2171.01	2700
2172.91	2720
2174.82	2760
2176.73	2728
2178.64	2728
2180.54	2766
2182.45	2690
2184.35	2672
2186.26	2706
2188.16	2736
2190.06	2648
2191.96	2628
2193.87	2680
2195.77	2642
2197.67	2624
2199.57	2608
2201.47	2618
2203.37	2686
2205.27	2692
2207.16	2684
2209.06	2630
2210.96	2578
2212.85	2610
2214.75	2626
2216.64	2656
2218.54	2604
2220.43	2610
2222.33	2602
2224.22	2628.02
2226.11	2606.26
2228	2590.38
2229.89	2666.67
2231.78	2584.51
2233.67	2591.41
2235.56	2578.07
2237.45	2565.29
2239.34	2583.73
2241.23	2529.5
2243.11	2536.69
2245	2524.82
2246.89	2567.08
2248.77	2551.91
2250.66	2532.53
2252.54	2551.43
2254.42	2549.47
2256.31	2555.24
2258.19	2525.1
2260.07	2505.71
2261.95	2539.54
2263.83	2465.54
2265.71	2508.73
2267.59	2509.67
2269.47	2479.91
2271.35	2464.05
2273.23	2473.99
2275.1	2472.68
2276.98	2490.32
2278.86	2433.43
2280.73	2426.81
2282.61	2425.12
2284.48	2421.14
2286.36	2428.79
2288.23	2440.93
2290.1	2408.9
2291.98	2389.01
2293.85	2400.93
2295.72	2386.28
2297.59	2401.59
2299.46	2362.36
2301.33	2351.21
2303.2	2343.98
2305.06	2357.27
2306.93	2336.51
2308.8	2330.02
2310.67	2318.09
2312.53	2319.02
2314.4	2309.78
2316.26	2264.1
2317.62	2310
2319.5	2292
2321.37	2256
2323.24	2286
2325.12	2320
2326.99	2318
2328.86	2304
2330.73	2278
2332.6	2252
2334.47	2208
2336.34	2208
2338.2	2268
2340.07	2254
2341.94	2226
2343.81	2184
2345.67	2188
2347.54	2172
2349.4	2176
2351.27	2232
2353.13	2182
2354.99	2202
2356.86	2126
2358.72	2166
2360.58	2142
2362.44	2128
2364.3	2182
2366.16	2172
2368.02	2136
2369.88	2110
2371.74	2192
2373.6	2104
2375.45	2120
2377.31	2114
2379.17	2152
2381.02	2136
2382.88	2076
2384.73	2146
2386.58	2066
2388.44	2092
2390.29	2008
2392.14	2100
2393.99	2072
2395.85	2066
2397.7	2036
2399.55	2120
2401.4	1966
2403.25	1956
2405.09	1998
2406.94	2006
2408.79	2020
2410.63	2026
2412.48	1998
2414.33	1978
2416.17	1908
2418.02	1966
2419.86	1976
2421.7	1926
2423.55	1896
2425.39	1954
2427.23	1898
2429.07	1872
2430.91	1900
2432.75	1858
2434.59	1866
2436.43	1850
2438.27	1836
2440.11	1826
2441.95	1840
2443.78	1842
2445.62	1840
2447.46	1820
2449.29	1804
2451.13	1764
2452.96	1804
2454.79	1750
2456.63	1754
2458.46	1770
2460.29	1776
2462.12	1724
2463.95	1756
2465.78	1724
2467.61	1684
2469.44	1784
2471.27	1740
2473.1	1710
2474.93	1716
2476.76	1708
2478.58	1692
2480.41	1702
2482.23	1688
2484.06	1624
2485.88	1662
2487.71	1620
2489.53	1634
2491.35	1638
2493.18	1638
2495	1624
2496.82	1580
2498.64	1556
2500.46	1640
2502.28	1604
2504.1	1610
2505.92	1584
2507.74	1546
2509.55	1554
2511.37	1576
2513.19	1538
2515	1534
2516.82	1528
2518.63	1526
2520.45	1502
2522.26	1526
2524.07	1472
2525.89	1468
2527.7	1490
2529.51	1474
2531.32	1492
2533.13	1470
2534.94	1480
2536.75	1444
2538.56	1478
2540.37	1402
2542.18	1430
2543.98	1426
2545.79	1448
2547.6	1404
2549.4	1376
2551.21	1388
2553.01	1356
2554.82	1370
2556.62	1378
2558.42	1332
2560.23	1374
2562.03	1352
2563.83	1346
2565.63	1340
2567.43	1298
2569.23	1324
2571.03	1316
2572.83	1268
2574.63	1320
2576.43	1264
2578.22	1308
2580.02	1272
2581.82	1264
2583.61	1260
2585.41	1266
2587.2	1280
2589	1238
2590.79	1262
2592.58	1244
2594.38	1212
2596.17	1190
2597.96	1220
2599.75	1244
2601.54	1204
2603.33	1188
2605.12	1162
2606.91	1196
2608.7	1170
2610.49	1186
2612.27	1224
2614.06	1148
2615.85	1164
2617.63	1124
2619.42	1168
2621.2	1106
2622.99	1152
2624.77	1110
2626.55	1112
2628.34	1122
2630.12	1110
2631.9	1102
2633.68	1102
2635.46	1084
2637.24	1114
2639.02	1128
2640.8	1058
2642.58	1058
2644.36	1054
2646.14	1076
2647.91	1034
2649.69	1058
2651.46	1010
2653.24	1018
2655.01	1008
2656.79	1018
2658.56	984
2660.34	1016
2662.11	998
2663.88	998
2665.65	1024
2667.42	996
2669.2	996
2670.96	974
2672.73	1018
2674.5	1016
2676.27	940
2678.04	976
2679.81	966
2681.58	950
2683.34	952
2685.11	914
2686.87	932
2688.64	954
2690.4	964
2692.17	934
2693.93	898
2695.69	870
2697.46	916
2699.22	894
2700.98	882
2702.74	866
2704.5	866
2706.26	882
2708.02	880
2709.78	872
2711.54	842
2713.3	816
2715.05	818
2716.81	854
2718.57	826
2720.32	878
2722.08	800
2723.83	816
2725.59	808
2727.34	832
2729.09	800
2730.85	792
2732.6	824
2734.35	792
2736.1	780
2737.85	766
2739.6	788
2741.35	786
2743.1	778
2744.85	754
2746.6	782
2748.35	746
2750.09	754
2751.84	762
2753.59	730
2755.33	728
2757.08	724
2758.82	738
2760.57	726
2762.31	738
2764.05	700
2765.79	680
2767.54	710
2769.28	692
2771.02	662
2772.76	706
2774.5	690
2776.24	664
2777.98	678
2779.72	672
2781.46	656
2783.19	674
2784.93	658
2786.67	642
2788.4	622
2790.14	644
2791.87	628
2793.61	654
2795.34	626
2797.07	634
2798.81	606
2800.54	644
2802.27	646
2804	620
2805.74	646
2807.47	598
2809.2	600
2810.93	596
2812.65	594
2814.38	582
2816.11	560
2817.84	588
2819.56	588
2821.29	602
2823.02	566
2824.74	584
2826.47	568
2828.19	568
2829.92	556
2831.64	544
2833.36	552
2835.09	530
2836.81	522
2838.53	510
2840.25	540
2841.97	544
2843.69	518
2845.41	520
2847.13	544
2848.85	518
2850.57	532
2852.28	500
2854	528
2855.72	500
2857.43	478
2859.15	510
2860.86	456
2862.58	468
2864.29	480
2866.01	492
2867.72	470
2869.43	474
2871.14	466
2872.86	462
2874.57	458
2876.28	450
2877.99	478
2879.7	466
2881.41	456
2883.11	462
2884.82	436
2886.53	444
2888.24	424
2889.94	456
2891.65	444
2893.36	434
2895.06	446
2896.77	414
2898.47	430
2900.17	410
2901.88	432
2903.58	436
2905.28	436
2906.98	436
2908.69	388
2910.39	432
2912.09	412
2913.79	398
2915.49	400
2917.19	420
2918.88	398
2920.58	390
2922.28	392
2923.98	388
2925.67	390
2927.37	382
2929.06	370
2930.76	376
2932.45	380
2934.15	350
2935.84	396
2937.53	364
2939.23	382
2940.92	374
2942.61	366
2944.3	372
2945.99	382
2947.68	354
2949.37	350
2951.06	350
2952.75	342
2954.44	370
2956.12	354
2957.81	358
2959.5	354
2961.18	340
2962.87	364
2964.56	326
2966.24	348
2967.92	364
2969.61	330
2971.29	316
2972.97	324
2974.66	344
2976.34	310
2978.02	332
2979.7	350
2981.38	324
2983.06	316
2984.74	318
2986.42	332
2988.1	318
2989.78	314
2991.45	320
2993.13	310
2994.81	306
2996.48	306
2998.16	322
2999.83	310