File: muestras/papalo/leaf_05.txt
#Acq. time (s)=	10
#Accumulations=	1
#Range (cm-¹)=	200...3000
#Windows=	3
#Autofocus=	Off
#AutoExposure=	Off
#Spike filter=	Off
#Delay time (s)=	0
#Binning=	1
#Readout mode=	Signal
#DeNoise=	Off
#ICS correction=	Off
#Dark correction=	Off
#Inst. Process=	Off
#Instrument=	LabRAM HR Evol
#Detector=	Syncerity OE
#Objective=	x100_VIS
#Grating=	600 (500nm)
#ND Filter=	0.1%
#Laser=	633nm_Edge
#Hole=	5.0225
#Range=	Visible
#Project=	Omar
#Sample=	03-07-23
#Site=	papal
#Title=	leaf
#Remark=
#Date=	03.07.2023 16:53
#Acquired=	03.07.2023 16:53:34
201.713	24
204.247	30
206.778	18
209.311	24
211.84	26
214.371	22
216.899	30
219.428	30
221.955	28
224.482	36
227.007	30
229.531	24
232.055	26
234.579	22
237.1	30
239.621	30
242.141	34
244.661	24
247.179	22
249.698	30
252.215	26
254.731	24
257.246	24
259.761	26
262.273	26
264.786	18
267.298	28
269.809	28
272.319	28
274.828	24
277.336	26
279.844	30
282.351	30
284.855	30
287.361	36
289.866	32
292.368	30
294.871	24
297.372	30
299.873	28
302.372	28
304.872	28
307.37	38
309.866	36
312.364	30
314.859	26
317.353	32
319.848	30
322.341	30
324.833	30
327.324	32
329.814	28
332.304	30
334.792	28
337.28	24
339.767	26
342.254	36
344.739	30
347.224	24
349.708	26
352.191	34
354.673	30
357.155	36
359.634	30
362.114	28
364.593	28
367.07	44
369.548	30
372.024	28
374.499	24
376.974	34
379.447	32
381.92	34
384.392	26
386.864	28
389.333	34
391.802	32
394.272	30
396.739	28
399.206	32
401.673	28
404.138	28
406.602	30
409.066	34
411.528	28
413.99	36
416.451	30
418.911	30
421.371	32
423.83	28
426.288	26
428.745	26
431.201	30
433.657	32
436.111	20
438.565	24
441.017	26
443.469	26
445.921	34
448.37	30
450.821	36
453.27	36
455.717	34
458.165	30
460.61	28
463.056	32
465.5	24
467.945	26
470.387	38
472.829	24
475.271	30
477.711	30
480.15	36
482.589	24
485.027	26
487.465	30
489.901	32
492.337	28
494.771	34
497.205	42
499.638	30
502.07	32
504.502	30
506.933	32
509.363	30
511.792	30
514.219	26
516.647	34
519.073	28
521.5	34
523.924	30
526.348	34
528.772	26
531.194	34
533.616	22
536.036	26
538.457	32
540.875	34
543.294	32
545.712	30
548.128	28
550.545	32
552.959	26
555.373	36
557.788	38
560.2	30
562.612	34
565.023	28
567.433	36
569.843	30
572.251	28
574.659	32
577.066	28
579.472	28
581.878	30
584.283	30
586.687	30
589.09	20
591.493	24
593.893	28
596.294	36
598.694	36
601.093	26
603.491	28
605.889	30
608.285	32
610.682	36
613.076	40
615.471	38
617.864	30
620.256	30
622.648	30
625.039	36
627.429	38
629.819	32
632.208	30
634.595	28
636.982	28
639.369	30
641.755	28
644.139	30
646.523	32
648.906	26
651.288	32
653.67	24
656.051	28
658.429	32
660.808	24
663.187	24
665.565	32
667.942	36
670.317	32
672.692	32
675.067	26
677.44	36
679.813	28
682.184	34
684.556	34
686.926	34
689.296	38
691.664	36
694.033	36
696.4	36
698.766	32
701.133	40
703.497	32
705.861	38
708.224	32
710.586	34
712.949	34
715.31	28
717.67	32
720.029	28
722.388	36
724.746	30
727.103	32
729.458	38
731.814	32
734.168	34
736.523	30
738.876	34
741.227	38
743.579	44
745.931	40
748.28	32
750.629	30
752.977	42
755.325	34
757.672	32
760.018	30
762.363	34
764.708	36
767.052	38
769.394	32
771.737	36
774.078	36
776.419	36
778.758	32
781.097	32
783.435	32
785.773	38
788.11	38
790.446	30
792.781	36
795.115	40
797.449	36
799.782	34
802.115	40
804.446	30
806.777	38
809.106	32
811.435	34
813.764	40
816.091	42
818.418	38
820.743	34
823.069	36
825.393	42
827.717	34
830.039	40
832.362	40
834.683	34
837.003	36
839.324	34
841.643	38
843.961	32
846.278	32
848.594	36
850.91	36
853.227	38
855.541	34
857.855	28
860.168	38
862.48	38
864.79	42
867.101	40
869.411	40
871.721	38
874.029	38
876.336	42
878.643	30
880.95	46
883.254	38
885.559	44
887.862	40
890.166	42
892.467	46
894.77	40
897.07	38
899.371	36
901.669	36
903.968	36
906.266	38
908.563	40
910.859	32
913.154	34
915.449	36
917.742	46
920.036	36
922.329	38
924.621	36
926.911	36
929.201	48
931.49	42
933.779	40
936.068	40
938.355	50
940.64	46
942.926	44
945.212	46
947.495	42
949.779	38
952.062	46
954.344	44
956.625	38
958.905	40
961.184	44
963.464	46
965.742	40
968.02	50
970.296	48
972.572	40
974.847	48
977.121	48
979.396	48
981.669	42
983.941	40
986.212	44
988.483	50
990.753	48
993.022	48
995.29	44
997.558	44
999.825	46
1002.09	46
1004.36	48
1006.62	50
1008.89	52
1011.15	48
1013.41	54
1015.67	46
1017.93	38
1020.19	38
1022.45	42
1024.71	50
1026.97	44
1029.23	34
1031.49	40
1033.74	50
1036	42
1038.25	52
1040.5	50
1042.76	34
1045.01	42
1047.26	50
1049.51	36
1051.76	48
1054.01	48
1056.26	42
1058.51	46
1060.75	42
1063	58
1065.25	56
1067.49	52
1069.73	54
1071.98	48
1074.22	48
1076.46	48
1078.7	44
1080.94	44
1083.18	52
1085.42	48
1087.66	44
1089.9	48
1092.14	42
1094.37	46
1096.61	52
1098.84	54
1101.08	50
1103.31	48
1105.54	42
1107.77	46
1110	58
1112.23	54
1114.46	48
1116.69	46
1118.92	44
1121.15	52
1123.37	50
1125.6	58
1127.83	46
1130.05	56
1132.27	50
1134.5	56
1136.72	46
1138.94	54
1141.16	48
1143.38	46
1145.6	54
1147.82	36
1150.04	52
1152.26	62
1154.47	54
1156.69	52
1158.9	52
1161.12	56
1163.33	60
1165.54	58
1167.76	52
1169.97	56
1172.18	56
1174.39	48
1176.6	46
1178.81	52
1181.02	56
1183.22	52
1185.43	50
1187.63	60
1189.84	46
1192.04	54
1194.25	64
1196.45	52
1198.65	48
1200.85	42
1203.05	44
1205.25	54
1207.45	50
1209.65	54
1211.85	58
1214.05	52
1216.24	54
1218.44	44
1220.64	46
1222.83	42
1225.02	52
1227.22	54
1229.41	52
1231.6	42
1233.79	62
1235.98	54
1238.17	48
1240.36	54
1242.55	46
1244.73	54
1246.92	44
1249.11	50
1251.29	56
1253.48	50
1255.66	52
1257.84	54
1260.03	56
1262.21	60
1264.39	58
1266.57	56
1268.75	52
1270.93	58
1273.11	50
1275.28	48
1277.46	42
1279.64	54
1281.81	50
1283.98	52.0061
1286.16	51.9603
1288.33	49.9941
1290.5	46.4215
1292.68	55.9492
1294.85	43.5173
1297.02	47.1761
1299.19	55.8034
1301.36	51.5797
1303.53	49.8
1305.69	47.6078
1307.86	52.0708
1310.03	46.7961
1312.19	46.8323
1314.36	51.0379
1316.52	52
1318.68	50.4807
1320.85	49.5968
1323.01	47.2884
1325.17	50.0269
1327.33	50.5567
1329.49	47.2309
1331.65	45.6022
1333.81	48.3529
1335.97	44.066
1338.12	49.2953
1340.28	52.3868
1342.44	46.3701
1344.59	43.6512
1346.75	46.1846
1348.9	49.3548
1351.05	44.7745
1353.2	45.4315
1355.36	45.2157
1357.51	44.8422
1359.66	44.1009
1361.81	48.5399
1363.96	42.8165
1366.1	43.5212
1368.25	44.1569
1370.4	49.8103
1372.54	44.8028
1374.69	53.0952
1376.83	51.4801
1378.98	41.1625
1381.12	42.7895
1383.26	42.7699
1385.41	46.1471
1387.55	41.0674
1389.69	44
1391.83	40.7869
1393.02	42
1395.17	48
1397.32	38
1399.47	52
1401.62	40
1403.77	44
1405.91	52
1408.06	42
1410.2	32
1412.35	40
1414.49	42
1416.63	44
1418.78	36
1420.92	50
1423.06	42
1425.2	52
1427.34	40
1429.48	40
1431.61	38
1433.75	46
1435.89	44
1438.02	34
1440.16	34
1442.3	36
1444.43	44
1446.56	40
1448.7	38
1450.83	44
1452.96	40
1455.09	42
1457.22	42
1459.35	42
1461.48	44
1463.61	46
1465.73	36
1467.86	50
1469.98	42
1472.11	44
1474.24	50
1476.36	36
1478.48	38
1480.6	46
1482.73	38
1484.85	40
1486.97	46
1489.09	44
1491.21	42
1493.33	48
1495.44	38
1497.56	48
1499.68	42
1501.79	38
1503.91	42
1506.02	42
1508.14	44
1510.25	42
1512.36	48
1514.48	40
1516.59	44
1518.7	38
1520.81	40
1522.92	42
1525.02	40
1527.13	40
1529.24	40
1531.35	44
1533.45	40
1535.56	50
1537.66	42
1539.77	38
1541.87	42
1543.97	32
1546.08	42
1548.18	40
1550.28	40
1552.38	38
1554.48	38
1556.57	44
1558.67	36
1560.77	44
1562.87	40
1564.96	46
1567.06	38
1569.15	36
1571.25	34
1573.34	42
1575.43	38
1577.53	48
1579.62	38
1581.71	44
1583.8	38
1585.89	36
1587.98	36
1590.06	28
1592.15	44
1594.24	32
1596.33	46
1598.41	42
1600.5	38
1602.58	48
1604.66	44
1606.75	38
1608.83	48
1610.91	38
1612.99	48
1615.07	36
1617.15	38
1619.23	34
1621.31	42
1623.39	44
1625.46	46
1627.54	32
1629.62	46
1631.69	36
1633.77	44
1635.84	32
1637.91	42
1639.99	34
1642.06	46
1644.13	40
1646.2	44
1648.27	36
1650.34	40
1652.41	44
1654.47	38
1656.54	40
1658.61	44
1660.67	38
1662.74	34
1664.81	44
1666.87	40
1668.93	36
1671	40
1673.06	34
1675.12	40
1677.18	36
1679.24	44
1681.3	40
1683.36	36
1685.42	36
1687.47	28
1689.53	36
1691.59	34
1693.64	42
1695.7	38
1697.75	34
1699.81	48
1701.86	40
1703.91	38
1705.97	34
1708.02	40
1710.07	42
1712.12	38
1714.17	34
1716.22	38
1718.26	42
1720.31	36
1722.36	40
1724.4	32
1726.45	28
1728.49	40
1730.54	38
1732.58	36
1734.63	38
1736.67	32
1738.71	34
1740.75	34
1742.79	42
1744.83	38
1746.87	40
1748.91	40
1750.95	38
1752.98	40
1755.02	42
1757.06	40
1759.09	36
1761.13	46
1763.16	44
1765.19	42
1767.23	38
1769.26	34
1771.29	36
1773.32	44
1775.35	40
1777.38	38
1779.41	30
1781.44	34
1783.47	44
1785.49	34
1787.52	40
1789.55	48
1791.57	36
1793.6	34
1795.62	34
1797.64	36
1799.67	40
1801.69	34
1803.71	44
1805.73	36
1807.75	40
1809.77	36
1811.79	40
1813.81	42
1815.83	38
1817.84	36
1819.86	36
1821.88	38
1823.89	32
1825.91	40
1827.92	32
1829.93	34
1831.95	40
1833.96	36
1835.97	36
1837.98	34
1839.99	36
1842	34
1844.01	30
1846.02	32
1848.03	28
1850.03	38
1852.04	32
1854.05	42
1856.05	46
1858.06	38
1860.06	28
1862.06	40
1864.07	32
1866.07	32
1868.07	34
1870.07	32
1872.07	42
1874.07	42
1876.07	40
1878.07	32
1880.07	32
1882.07	40
1884.06	36
1886.06	36
1888.05	34
1890.05	42
1892.04	40
1894.04	36
1896.03	36
1898.02	40
1900.01	38
1902	42
1903.99	40
1905.98	44
1907.97	30
1909.96	38
1911.95	42
1913.94	34
1915.93	40
1917.91	36
1919.9	48
1921.88	40
1923.87	40
1925.85	40
1927.83	38
1929.82	30
1931.8	46
1933.78	34
1935.76	46
1937.74	40
1939.72	32
1941.7	32
1943.68	42
1945.65	46
1947.63	34
1949.61	42
1951.58	44
1953.56	36
1955.53	44
1957.51	38
1959.48	36
1961.45	36
1963.43	38
1965.4	36
1967.37	38
1969.34	34
1971.31	32
1973.28	32
1975.25	38
1977.22	32
1979.18	36
1981.15	36
1983.12	34
1985.08	36
1987.05	42
1989.01	36
1990.97	32
1992.94	34
1994.9	38
1996.86	36
1998.82	38
2000.78	38
2002.74	36
2004.7	34
2006.66	34
2008.62	34
2010.58	38
2012.54	36
2014.49	38
2016.45	42
2018.4	40
2020.36	40
2022.31	34
2024.27	36
2026.22	40
2028.17	37
2030.12	38
2032.07	42
2034.03	40
2035.98	44
2037.93	44
2039.87	40
2041.82	38
2043.77	36
2045.72	38
2047.66	50
2049.61	36
2051.55	34
2053.5	30
2055.44	38
2057.39	40
2059.33	34
2061.27	44
2063.21	32
2065.15	40
2067.09	38
2069.03	34
2070.97	36
2072.91	34
2074.85	36
2076.79	36
2078.73	36
2080.66	36
2082.6	42
2084.53	34
2086.47	38
2088.4	36
2090.33	40
2092.27	34
2094.2	40
2096.13	40
2098.06	38
2099.99	32
2101.92	44
2103.85	40
2105.78	36
2107.71	38
2109.64	36
2111.56	26
2113.49	28
2115.41	40
2117.34	40
2119.26	36
2121.19	46
2123.11	38
2125.03	38
2126.96	44
2128.88	24
2130.8	40
2132.72	32
2134.64	42
2136.56	34
2138.48	32
2140.4	38
2142.31	38
2144.23	30
2146.15	34
2148.06	38
2149.98	36
2151.89	34
2153.81	38
2155.72	46
2157.63	44
2159.55	38
2161.46	36
2163.37	36
2165.28	40
2167.19	26
2169.1	40
2171.01	42
2172.91	42
2174.82	36
2176.73	42
2178.64	42
2180.54	34
2182.45	40
2184.35	36
2186.26	30
2188.16	34
2190.06	34
2191.96	36
2193.87	28
2195.77	30
2197.67	36
2199.57	28
2201.47	38
2203.37	40
2205.27	44
2207.16	40
2209.06	36
2210.96	34
2212.85	36
2214.75	28
2216.64	30
2218.54	30
2220.43	38
2222.33	38
2224.22	43.7062
2226.11	26.073
2228	30.0146
2229.89	33.7202
2231.78	28.7575
2233.67	39.7695
2235.56	39.46
2237.45	32.6035
2239.34	30.6901
2241.23	29.9852
2243.11	31.6743
2245	39.7334
2246.89	30.815
2248.77	34.6192
2250.66	33.8224
2252.54	33.9374
2254.42	35.1941
2256.31	38.0451
2258.19	38.7094
2260.07	38.089
2261.95	35.66
2263.83	34.14
2265.71	36.18
2267.59	36.978
2269.47	32.6123
2271.35	38.1362
2273.23	38.14
2275.1	34.3682
2276.98	36.5043
2278.86	35.62
2280.73	29.8385
2282.61	40.4667
2284.48	33.0783
2286.36	35.7051
2288.23	35.6312
2290.1	32.7166
2291.98	31.459
2293.85	34.9864
2295.72	37.4228
2297.59	36.77
2299.46	34
2301.33	34.8361
2303.2	33.8633
2305.06	29.8873
2306.93	32.21
2308.8	31.5091
2310.67	33.0466
2312.53	38.4299
2314.4	38.2028
2316.26	34.7089
2317.62	36
2319.5	32
2321.37	36
2323.24	32
2325.12	34
2326.99	32
2328.86	34
2330.73	36
2332.6	38
2334.47	32
2336.34	38
2338.2	38
2340.07	36
2341.94	38
2343.81	34
2345.67	30
2347.54	34
2349.4	30
2351.27	32
2353.13	32
2354.99	30
2356.86	36
2358.72	34
2360.58	38
2362.44	34
2364.3	26
2366.16	32
2368.02	40
2369.88	30
2371.74	40
2373.6	32
2375.45	40
2377.31	36
2379.17	34
2381.02	34
2382.88	36
2384.73	36
2386.58	28
2388.44	34
2390.29	34
2392.14	36
2393.99	40
2395.85	32
2397.7	38
2399.55	28
2401.4	38
2403.25	32
2405.09	38
2406.94	38
2408.79	34
2410.63	40
2412.48	36
2414.33	34
2416.17	30
2418.02	32
2419.86	42
2421.7	38
2423.55	32
2425.39	34
2427.23	32
2429.07	36
2430.91	34
2432.75	38
2434.59	28
2436.43	34
2438.27	28
2440.11	34
2441.95	38
2443.78	28
2445.62	30
2447.46	34
2449.29	34
2451.13	30
2452.96	28
2454.79	30
2456.63	34
2458.46	42
2460.29	34
2462.12	34
2463.95	40
2465.78	36
2467.61	28
2469.44	28
2471.27	38
2473.1	22
2474.93	36
2476.76	38
2478.58	32
2480.41	36
2482.23	36
2484.06	28
2485.88	38
2487.71	34
2489.53	28
2491.35	36
2493.18	32
2495	34
2496.82	26
2498.64	28
2500.46	32
2502.28	34
2504.1	30
2505.92	38
2507.74	36
2509.55	34
2511.37	42
2513.19	38
2515	34
2516.82	36
2518.63	32
2520.45	32
2522.26	34
2524.07	30
2525.89	34
2527.7	30
2529.51	26
2531.32	32
2533.13	34
2534.94	38
2536.75	32
2538.56	32
2540.37	30
2542.18	36
2543.98	36
2545.79	30
2547.6	36
2549.4	38
2551.21	32
2553.01	40
2554.82	32
2556.62	30
2558.42	26
2560.23	30
2562.03	36
2563.83	30
2565.63	30
2567.43	38
2569.23	30
2571.03	32
2572.83	32
2574.63	36
2576.43	38
2578.22	30
2580.02	34
2581.82	30
2583.61	36
2585.41	34
2587.2	38
2589	28
2590.79	30
2592.58	32
2594.38	30
2596.17	28
2597.96	36
2599.75	38
2601.54	40
2603.33	28
2605.12	48
2606.91	40
2608.7	36
2610.49	40
2612.27	28
2614.06	38
2615.85	38
2617.63	36
2619.42	40
2621.2	34
2622.99	36
2624.77	32
2626.55	32
2628.34	34
2630.12	36
2631.9	34
2633.68	32
2635.46	38
2637.24	34
2639.02	30
2640.8	28
2642.58	30
2644.36	36
2646.14	40
2647.91	32
2649.69	28
2651.46	36
2653.24	26
2655.01	32
2656.79	38
2658.56	38
2660.34	38
2662.11	34
2663.88	30
2665.65	34
2667.42	38
2669.2	36
2670.96	34
2672.73	28
2674.5	32
2676.27	30
2678.04	34
2679.81	34
2681.58	30
2683.34	28
2685.11	26
2686.87	40
2688.64	32
2690.4	38
2692.17	36
2693.93	32
2695.69	34
2697.46	30
2699.22	34
2700.98	34
2702.74	36
2704.5	30
2706.26	34
2708.02	32
2709.78	26
2711.54	32
2713.3	28
2715.05	38
2716.81	38
2718.57	32
2720.32	38
2722.08	28
2723.83	36
2725.59	38
2727.34	30
2729.09	24
2730.85	34
2732.6	32
2734.35	38
2736.1	30
2737.85	26
2739.6	36
2741.35	30
2743.1	28
2744.85	36
2746.6	34
2748.35	36
2750.09	36
2751.84	32
2753.59	34
2755.33	30
2757.08	34
2758.82	32
2760.57	32
2762.31	32
2764.05	30
2765.79	22
2767.54	28
2769.28	32
2771.02	30
2772.76	24
2774.5	30
2776.24	34
2777.98	30
2779.72	26
2781.46	32
2783.19	30
2784.93	32
2786.67	30
2788.4	38
2790.14	32
2791.87	32
2793.61	32
2795.34	28
2797.07	32
2798.81	30
2800.54	34
2802.27	22
2804	30
2805.74	32
2807.47	26
2809.2	34
2810.93	32
2812.65	26
2814.38	28
2816.11	30
2817.84	26
2819.56	34
2821.29	24
2823.02	32
2824.74	22
2826.47	28
2828.19	30
2829.92	36
2831.64	34
2833.36	30
2835.09	34
2836.81	36
2838.53	34
2840.25	36
2841.97	30
2843.69	32
2845.41	34
2847.13	26
2848.85	30
2850.57	26
2852.28	30
2854	34
2855.72	30
2857.43	32
2859.15	24
2860.86	32
2862.58	22
2864.29	30
2866.01	36
2867.72	28
2869.43	32
2871.14	30
2872.86	32
2874.57	26
2876.28	22
2877.99	32
2879.7	34
2881.41	24
2883.11	30
2884.82	34
2886.53	34
2888.24	36
2889.94	30
2891.65	30
2893.36	32
2895.06	30
2896.77	36
2898.47	26
2900.17	32
2901.88	38
2903.58	26
2905.28	26
2906.98	34
2908.69	34
2910.39	36
2912.09	28
2913.79	22
2915.49	26
2917.19	34
2918.88	24
2920.58	32
2922.28	28
2923.98	28
2925.67	26
2927.37	30
2929.06	30
2930.76	24
2932.45	28
2934.15	26
2935.84	26
2937.53	40
2939.23	20
2940.92	24
2942.61	34
2944.3	36
2945.99	22
2947.68	34
2949.37	38
2951.06	38
2952.75	26
2954.44	28
2956.12	26
2957.81	30
2959.5	32
2961.18	32
2962.87	30
2964.56	34
2966.24	28
2967.92	32
2969.61	26
2971.29	26
2972.97	26
2974.66	32
2976.34	30
2978.02	32
2979.7	24
2981.38	26
2983.06	36
2984.74	36
2986.42	34
2988.1	30
2989.78	32
2991.45	28
2993.13	22
2994.81	32
2996.48	30
2998.16	32
2999.83	26