File: muestras/papalo/leaf_04.txt
#Acq. time (s)=	10
#Accumulations=	1
#Range (cm-¹)=	200...3000
#Windows=	3
#Autofocus=	Off
#AutoExposure=	Off
#Spike filter=	Off
#Delay time (s)=	0
#Binning=	1
#Readout mode=	Signal
#DeNoise=	Off
#ICS correction=	Off
#Dark correction=	Off
#Inst. Process=	Off
#Instrument=	LabRAM HR Evol
#Detector=	Syncerity OE
#Objective=	x100_VIS
#Grating=	600 (500nm)
#ND Filter=	1%
#Laser=	633nm_Edge
#Hole=	5.0225
#Range=	Visible
#Project=	Omar
#Sample=	03-07-23
#Site=	papal
#Title=	leaf
#Remark=
#Date=	03.07.2023 16:52
#Acquired=	03.07.2023 16:52:10
201.713	26
204.247	36
206.778	26
209.311	32
211.84	32
214.371	26
216.899	24
219.428	28
221.955	32
224.482	30
227.007	22
229.531	24
232.055	34
234.579	32
237.1	32
239.621	34
242.141	24
244.661	32
247.179	34
249.698	36
252.215	30
254.731	24
257.246	32
259.761	32
262.273	26
264.786	34
267.298	26
269.809	30
272.319	32
274.828	32
277.336	32
279.844	24
282.351	20
284.855	32
287.361	36
289.866	30
292.368	26
294.871	34
297.372	34
299.873	32
302.372	32
304.872	40
307.37	36
309.866	32
312.364	36
314.859	36
317.353	22
319.848	46
322.341	34
324.833	30
327.324	38
329.814	36
332.304	34
334.792	30
337.28	36
339.767	26
342.254	38
344.739	42
347.224	32
349.708	36
352.191	38
354.673	34
357.155	38
359.634	32
362.114	34
364.593	36
367.07	38
369.548	42
372.024	34
374.499	34
376.974	30
379.447	38
381.92	36
384.392	34
386.864	24
389.333	34
391.802	44
394.272	40
396.739	40
399.206	36
401.673	32
404.138	34
406.602	36
409.066	34
411.528	36
413.99	38
416.451	40
418.911	46
421.371	38
423.83	38
426.288	36
428.745	32
431.201	42
433.657	44
436.111	40
438.565	36
441.017	34
443.469	36
445.921	48
448.37	38
450.821	34
453.27	38
455.717	38
458.165	42
460.61	38
463.056	42
465.5	38
467.945	36
470.387	46
472.829	38
475.271	46
477.711	42
480.15	46
482.589	52
485.027	40
487.465	40
489.901	44
492.337	34
494.771	42
497.205	36
499.638	36
502.07	46
504.502	46
506.933	42
509.363	48
511.792	44
514.219	46
516.647	40
519.073	44
521.5	40
523.924	38
526.348	38
528.772	42
531.194	44
533.616	48
536.036	46
538.457	46
540.875	40
543.294	34
545.712	46
548.128	38
550.545	42
552.959	42
555.373	44
557.788	40
560.2	44
562.612	38
565.023	44
567.433	46
569.843	50
572.251	42
574.659	48
577.066	42
579.472	46
581.878	40
584.283	46
586.687	48
589.09	46
591.493	52
593.893	48
596.294	40
598.694	48
601.093	50
603.491	48
605.889	48
608.285	52
610.682	42
613.076	54
615.471	58
617.864	40
620.256	44
622.648	52
625.039	56
627.429	52
629.819	56
632.208	50
634.595	56
636.982	60
639.369	64
641.755	56
644.139	56
646.523	50
648.906	54
651.288	50
653.67	58
656.051	48
658.429	60
660.808	64
663.187	50
665.565	54
667.942	56
670.317	56
672.692	50
675.067	64
677.44	50
679.813	64
682.184	54
684.556	58
686.926	60
689.296	64
691.664	58
694.033	68
696.4	58
698.766	50
701.133	58
703.497	72
705.861	62
708.224	52
710.586	62
712.949	56
715.31	70
717.67	48
720.029	68
722.388	62
724.746	56
727.103	68
729.458	64
731.814	64
734.168	70
736.523	70
738.876	66
741.227	68
743.579	70
745.931	80
748.28	68
750.629	66
752.977	70
755.325	66
757.672	64
760.018	66
762.363	76
764.708	74
767.052	72
769.394	74
771.737	70
774.078	72
776.419	78
778.758	78
781.097	70
783.435	74
785.773	64
788.11	76
790.446	66
792.781	86
795.115	72
797.449	80
799.782	80
802.115	74
804.446	80
806.777	78
809.106	84
811.435	84
813.764	88
816.091	80
818.418	94
820.743	82
823.069	92
825.393	72
827.717	86
830.039	90
832.362	84
834.683	98
837.003	90
839.324	84
841.643	98
843.961	96
846.278	96
848.594	94
850.91	84
853.227	98
855.541	94
857.855	94
860.168	102
862.48	98
864.79	106
867.101	88
869.411	104
871.721	94
874.029	100
876.336	102
878.643	102
880.95	102
883.254	106
885.559	118
887.862	104
890.166	106
892.467	106
894.77	116
897.07	106
899.371	112
901.669	114
903.968	110
906.266	116
908.563	112
910.859	108
913.154	114
915.449	112
917.742	122
920.036	110
922.329	124
924.621	126
926.911	124
929.201	130
931.49	118
933.779	120
936.068	122
938.355	120
940.64	130
942.926	124
945.212	112
947.495	130
949.779	122
952.062	144
954.344	114
956.625	138
958.905	150
961.184	124
963.464	152
965.742	128
968.02	124
970.296	138
972.572	130
974.847	128
977.121	142
979.396	142
981.669	140
983.941	150
986.212	140
988.483	142
990.753	152
993.022	154
995.29	148
997.558	158
999.825	142
1002.09	152
1004.36	158
1006.62	158
1008.89	164
1011.15	160
1013.41	174
1015.67	166
1017.93	160
1020.19	172
1022.45	162
1024.71	166
1026.97	174
1029.23	184
1031.49	164
1033.74	180
1036	194
1038.25	190
1040.5	188
1042.76	178
1045.01	188
1047.26	180
1049.51	168
1051.76	186
1054.01	186
1056.26	186
1058.51	188
1060.75	192
1063	186
1065.25	192
1067.49	182
1069.73	180
1071.98	200
1074.22	208
1076.46	192
1078.7	196
1080.94	208
1083.18	202
1085.42	200
1087.66	198
1089.9	198
1092.14	220
1094.37	220
1096.61	204
1098.84	208
1101.08	216
1103.31	204
1105.54	226
1107.77	232
1110	214
1112.23	224
1114.46	220
1116.69	204
1118.92	228
1121.15	228
1123.37	220
1125.6	224
1127.83	230
1130.05	232
1132.27	234
1134.5	222
1136.72	228
1138.94	228
1141.16	214
1143.38	238
1145.6	238
1147.82	214
1150.04	236
1152.26	240
1154.47	226
1156.69	234
1158.9	246
1161.12	232
1163.33	238
1165.54	238
1167.76	272
1169.97	240
1172.18	238
1174.39	256
1176.6	250
1178.81	246
1181.02	248
1183.22	258
1185.43	224
1187.63	248
1189.84	266
1192.04	236
1194.25	268
1196.45	240
1198.65	236
1200.85	248
1203.05	244
1205.25	252
1207.45	262
1209.65	256
1211.85	260
1214.05	240
1216.24	238
1218.44	240
1220.64	218
1222.83	230
1225.02	240
1227.22	232
1229.41	240
1231.6	240
1233.79	258
1235.98	220
1238.17	232
1240.36	244
1242.55	244
1244.73	252
1246.92	236
1249.11	242
1251.29	236
1253.48	232
1255.66	222
1257.84	222
1260.03	234
1262.21	236
1264.39	222
1266.57	254
1268.75	254
1270.93	228
1273.11	236
1275.28	248
1277.46	252
1279.64	222
1281.81	226
1283.98	223.972
1286.16	223.87
1288.33	237.016
1290.5	229.049
1292.68	221.333
1294.85	222.495
1297.02	225.265
1299.19	222.764
1301.36	218.665
1303.53	217.518
1305.69	218.925
1307.86	217.388
1310.03	208.657
1312.19	192.935
1314.36	216.689
1316.52	216.559
1318.68	200.761
1320.85	202.865
1323.01	209.834
1325.17	193.79
1327.33	197.862
1329.49	202.693
1331.65	199.587
1333.81	197.027
1335.97	199.14
1338.12	188.95
1340.28	198.793
1342.44	186.945
1344.59	201.615
1346.75	184.449
1348.9	196.643
1351.05	191.411
1353.2	193.064
1355.36	191.705
1357.51	175.824
1359.66	179.033
1361.81	198.679
1363.96	185.931
1366.1	194.83
1368.25	195.912
1370.4	182.931
1372.54	181.63
1374.69	172.098
1376.83	169.968
1378.98	173.816
1381.12	176.79
1383.26	178.887
1385.41	180.824
1387.55	177.245
1389.69	164.465
1391.83	162.644
1393.02	162
1395.17	182
1397.32	174
1399.47	150
1401.62	178
1403.77	164
1405.91	162
1408.06	146
1410.2	158
1412.35	166
1414.49	174
1416.63	168
1418.78	136
1420.92	144
1423.06	138
1425.2	158
1427.34	152
1429.48	156
1431.61	158
1433.75	160
1435.89	152
1438.02	144
1440.16	150
1442.3	142
1444.43	152
1446.56	154
1448.7	142
1450.83	148
1452.96	164
1455.09	162
1457.22	140
1459.35	150
1461.48	144
1463.61	146
1465.73	152
1467.86	144
1469.98	148
1472.11	154
1474.24	150
1476.36	154
1478.48	140
1480.6	140
1482.73	142
1484.85	138
1486.97	140
1489.09	142
1491.21	142
1493.33	144
1495.44	142
1497.56	148
1499.68	142
1501.79	152
1503.91	144
1506.02	124
1508.14	138
1510.25	128
1512.36	144
1514.48	130
1516.59	130
1518.7	134
1520.81	134
1522.92	140
1525.02	140
1527.13	132
1529.24	128
1531.35	116
1533.45	134
1535.56	128
1537.66	132
1539.77	120
1541.87	134
1543.97	122
1546.08	128
1548.18	132
1550.28	122
1552.38	130
1554.48	126
1556.57	126
1558.67	126
1560.77	124
1562.87	130
1564.96	118
1567.06	130
1569.15	130
1571.25	114
1573.34	120
1575.43	116
1577.53	120
1579.62	126
1581.71	130
1583.8	128
1585.89	118
1587.98	116
1590.06	136
1592.15	128
1594.24	130
1596.33	136
1598.41	132
1600.5	124
1602.58	128
1604.66	120
1606.75	118
1608.83	114
1610.91	114
1612.99	116
1615.07	120
1617.15	132
1619.23	130
1621.31	108
1623.39	114
1625.46	122
1627.54	112
1629.62	116
1631.69	118
1633.77	112
1635.84	114
1637.91	122
1639.99	114
1642.06	110
1644.13	124
1646.2	124
1648.27	118
1650.34	126
1652.41	120
1654.47	124
1656.54	112
1658.61	112
1660.67	118
1662.74	116
1664.81	114
1666.87	106
1668.93	124
1671	112
1673.06	112
1675.12	106
1677.18	116
1679.24	112
1681.3	114
1683.36	130
1685.42	110
1687.47	114
1689.53	104
1691.59	118
1693.64	106
1695.7	112
1697.75	138
1699.81	110
1701.86	108
1703.91	108
1705.97	114
1708.02	108
1710.07	112
1712.12	108
1714.17	106
1716.22	106
1718.26	108
1720.31	106
1722.36	120
1724.4	120
1726.45	122
1728.49	114
1730.54	110
1732.58	118
1734.63	110
1736.67	112
1738.71	112
1740.75	120
1742.79	110
1744.83	98
1746.87	100
1748.91	116
1750.95	114
1752.98	102
1755.02	108
1757.06	116
1759.09	108
1761.13	112
1763.16	112
1765.19	112
1767.23	104
1769.26	108
1771.29	104
1773.32	106
1775.35	108
1777.38	100
1779.41	104
1781.44	110
1783.47	114
1785.49	112
1787.52	118
1789.55	104
1791.57	112
1793.6	108
1795.62	110
1797.64	96
1799.67	114
1801.69	108
1803.71	116
1805.73	110
1807.75	104
1809.77	106
1811.79	120
1813.81	106
1815.83	104
1817.84	102
1819.86	104
1821.88	108
1823.89	94
1825.91	112
1827.92	104
1829.93	102
1831.95	98
1833.96	102
1835.97	114
1837.98	116
1839.99	102
1842	112
1844.01	98
1846.02	96
1848.03	102
1850.03	112
1852.04	116
1854.05	108
1856.05	94
1858.06	96
1860.06	102
1862.06	116
1864.07	104
1866.07	102
1868.07	96
1870.07	120
1872.07	98
1874.07	108
1876.07	114
1878.07	108
1880.07	108
1882.07	98
1884.06	112
1886.06	108
1888.05	118
1890.05	114
1892.04	98
1894.04	98
1896.03	106
1898.02	96
1900.01	110
1902	106
1903.99	98
1905.98	116
1907.97	108
1909.96	104
1911.95	114
1913.94	100
1915.93	96
1917.91	114
1919.9	100
1921.88	112
1923.87	110
1925.85	104
1927.83	100
1929.82	102
1931.8	96
1933.78	108
1935.76	126
1937.74	98
1939.72	104
1941.7	104
1943.68	102
1945.65	110
1947.63	92
1949.61	106
1951.58	98
1953.56	108
1955.53	98
1957.51	104
1959.48	100
1961.45	108
1963.43	108
1965.4	106
1967.37	96
1969.34	102
1971.31	122
1973.28	110
1975.25	122
1977.22	104
1979.18	96
1981.15	98
1983.12	114
1985.08	84
1987.05	114
1989.01	98
1990.97	100
1992.94	96
1994.9	114
1996.86	90
1998.82	106
2000.78	114
2002.74	96
2004.7	106
2006.66	104
2008.62	102
2010.58	98
2012.54	94
2014.49	118
2016.45	112
2018.4	110
2020.36	98
2022.31	104
2024.27	108
2026.22	104
2028.17	99
2030.12	98
2032.07	94
2034.03	96
2035.98	120
2037.93	110
2039.87	110
2041.82	98
2043.77	94
2045.72	106
2047.66	88
2049.61	114
2051.55	104
2053.5	94
2055.44	112
2057.39	104
2059.33	112
2061.27	106
2063.21	96
2065.15	116
2067.09	110
2069.03	112
2070.97	90
2072.91	108
2074.85	90
2076.79	102
2078.73	100
2080.66	102
2082.6	102
2084.53	98
2086.47	92
2088.4	90
2090.33	114
2092.27	110
2094.2	100
2096.13	96
2098.06	100
2099.99	102
2101.92	104
2103.85	108
2105.78	106
2107.71	108
2109.64	120
2111.56	98
2113.49	96
2115.41	106
2117.34	110
2119.26	112
2121.19	104
2123.11	100
2125.03	94
2126.96	94
2128.88	88
2130.8	106
2132.72	96
2134.64	98
2136.56	100
2138.48	104
2140.4	102
2142.31	76
2144.23	96
2146.15	98
2148.06	100
2149.98	108
2151.89	100
2153.81	98
2155.72	100
2157.63	94
2159.55	102
2161.46	88
2163.37	96
2165.28	104
2167.19	98
2169.1	108
2171.01	98
2172.91	106
2174.82	104
2176.73	92
2178.64	94
2180.54	90
2182.45	98
2184.35	96
2186.26	98
2188.16	100
2190.06	102
2191.96	98
2193.87	88
2195.77	96
2197.67	92
2199.57	84
2201.47	88
2203.37	98
2205.27	104
2207.16	92
2209.06	88
2210.96	88
2212.85	106
2214.75	98
2216.64	96
2218.54	92
2220.43	92
2222.33	100
2224.22	95.9384
2226.11	94.1951
2228	86.5464
2229.89	89.8466
2231.78	88.5576
2233.67	91.5427
2235.56	86.9623
2237.45	99.841
2239.34	103.9
2241.23	95.3623
2243.11	101.812
2245	95.5109
2246.89	94.81
2248.77	88.7947
2250.66	100.282
2252.54	100.586
2254.42	91.2571
2256.31	86.0903
2258.19	95.9188
2260.07	90.0213
2261.95	98.9557
2263.83	90.87
2265.71	91.7692
2267.59	87.828
2269.47	96.8612
2271.35	95.4347
2273.23	98.2734
2275.1	94.5763
2276.98	89.8905
2278.86	90.5699
2280.73	87.3755
2282.61	93.5778
2284.48	90.9515
2286.36	92.6952
2288.23	92.6388
2290.1	90.5568
2291.98	92.3335
2293.85	85.5404
2295.72	93.4956
2297.59	86.82
2299.46	89.447
2301.33	89.5607
2303.2	92.895
2305.06	93.6127
2306.93	90.444
2308.8	83.0798
2310.67	93.04
2312.53	90.9849
2314.4	88.3264
2316.26	83.1504
2317.62	88
2319.5	82
2321.37	88
2323.24	96
2325.12	96
2326.99	94
2328.86	92
2330.73	86
2332.6	90
2334.47	82
2336.34	84
2338.2	88
2340.07	94
2341.94	76
2343.81	92
2345.67	94
2347.54	92
2349.4	82
2351.27	92
2353.13	92
2354.99	94
2356.86	90
2358.72	78
2360.58	92
2362.44	78
2364.3	92
2366.16	88
2368.02	86
2369.88	92
2371.74	82
2373.6	82
2375.45	94
2377.31	96
2379.17	98
2381.02	90
2382.88	84
2384.73	76
2386.58	80
2388.44	80
2390.29	76
2392.14	88
2393.99	76
2395.85	92
2397.7	88
2399.55	74
2401.4	86
2403.25	78
2405.09	84
2406.94	72
2408.79	82
2410.63	92
2412.48	86
2414.33	70
2416.17	74
2418.02	78
2419.86	76
2421.7	88
2423.55	76
2425.39	82
2427.23	82
2429.07	86
2430.91	76
2432.75	72
2434.59	86
2436.43	86
2438.27	78
2440.11	88
2441.95	74
2443.78	80
2445.62	74
2447.46	72
2449.29	70
2451.13	72
2452.96	82
2454.79	74
2456.63	72
2458.46	80
2460.29	70
2462.12	82
2463.95	78
2465.78	56
2467.61	66
2469.44	88
2471.27	74
2473.1	78
2474.93	78
2476.76	72
2478.58	66
2480.41	82
2482.23	78
2484.06	70
2485.88	82
2487.71	72
2489.53	74
2491.35	70
2493.18	74
2495	62
2496.82	74
2498.64	80
2500.46	76
2502.28	68
2504.1	62
2505.92	70
2507.74	70
2509.55	76
2511.37	62
2513.19	76
2515	74
2516.82	70
2518.63	66
2520.45	70
2522.26	58
2524.07	74
2525.89	74
2527.7	66
2529.51	76
2531.32	84
2533.13	64
2534.94	74
2536.75	68
2538.56	78
2540.37	64
2542.18	64
2543.98	74
2545.79	58
2547.6	68
2549.4	68
2551.21	70
2553.01	74
2554.82	66
2556.62	76
2558.42	64
2560.23	74
2562.03	58
2563.83	70
2565.63	64
2567.43	58
2569.23	70
2571.03	66
2572.83	66
2574.63	64
2576.43	76
2578.22	64
2580.02	60
2581.82	62
2583.61	68
2585.41	60
2587.2	60
2589	64
2590.79	62
2592.58	60
2594.38	64
2596.17	64
2597.96	78
2599.75	68
2601.54	72
2603.33	68
2605.12	66
2606.91	58
2608.7	68
2610.49	60
2612.27	62
2614.06	60
2615.85	58
2617.63	72
2619.42	54
2621.2	52
2622.99	56
2624.77	62
2626.55	58
2628.34	58
2630.12	64
2631.9	60
2633.68	62
2635.46	60
2637.24	54
2639.02	64
2640.8	60
2642.58	64
2644.36	52
2646.14	58
2647.91	56
2649.69	60
2651.46	58
2653.24	60
2655.01	58
2656.79	58
2658.56	64
2660.34	60
2662.11	56
2663.88	58
2665.65	56
2667.42	52
2669.2	52
2670.96	50
2672.73	60
2674.5	48
2676.27	54
2678.04	60
2679.81	60
2681.58	58
2683.34	54
2685.11	56
2686.87	50
2688.64	58
2690.4	52
2692.17	54
2693.93	56
2695.69	54
2697.46	56
2699.22	56
2700.98	58
2702.74	52
2704.5	48
2706.26	54
2708.02	50
2709.78	60
2711.54	58
2713.3	54
2715.05	58
2716.81	50
2718.57	54
2720.32	50
2722.08	56
2723.83	48
2725.59	60
2727.34	54
2729.09	46
2730.85	44
2732.6	52
2734.35	48
2736.1	52
2737.85	48
2739.6	46
2741.35	50
2743.1	58
2744.85	54
2746.6	52
2748.35	46
2750.09	60
2751.84	52
2753.59	60
2755.33	54
2757.08	56
2758.82	46
2760.57	56
2762.31	46
2764.05	54
2765.79	50
2767.54	38
2769.28	48
2771.02	46
2772.76	56
2774.5	48
2776.24	50
2777.98	52
2779.72	50
2781.46	46
2783.19	56
2784.93	46
2786.67	46
2788.4	46
2790.14	54
2791.87	50
2793.61	50
2795.34	48
2797.07	48
2798.81	42
2800.54	46
2802.27	52
2804	46
2805.74	48
2807.47	50
2809.2	46
2810.93	48
2812.65	38
2814.38	52
2816.11	48
2817.84	44
2819.56	54
2821.29	48
2823.02	50
2824.74	48
2826.47	44
2828.19	48
2829.92	48
2831.64	48
2833.36	44
2835.09	46
2836.81	40
2838.53	34
2840.25	44
2841.97	42
2843.69	52
2845.41	44
2847.13	48
2848.85	50
2850.57	50
2852.28	56
2854	48
2855.72	46
2857.43	40
2859.15	42
2860.86	46
2862.58	38
2864.29	40
2866.01	46
2867.72	54
2869.43	42
2871.14	38
2872.86	44
2874.57	38
2876.28	40
2877.99	40
2879.7	40
2881.41	40
2883.11	42
2884.82	48
2886.53	38
2888.24	42
2889.94	36
2891.65	44
2893.36	44
2895.06	44
2896.77	46
2898.47	42
2900.17	44
2901.88	34
2903.58	40
2905.28	48
2906.98	36
2908.69	36
2910.39	38
2912.09	38
2913.79	42
2915.49	48
2917.19	44
2918.88	36
2920.58	34
2922.28	40
2923.98	38
2925.67	40
2927.37	38
2929.06	42
2930.76	46
2932.45	44
2934.15	32
2935.84	46
2937.53	36
2939.23	36
2940.92	36
2942.61	40
2944.3	34
2945.99	44
2947.68	46
2949.37	42
2951.06	40
2952.75	52
2954.44	38
2956.12	34
2957.81	36
2959.5	38
2961.18	38
2962.87	38
2964.56	44
2966.24	34
2967.92	40
2969.61	46
2971.29	44
2972.97	38
2974.66	48
2976.34	44
2978.02	38
2979.7	36
2981.38	38
2983.06	38
2984.74	32
2986.42	42
2988.1	34
2989.78	42
2991.45	42
2993.13	38
2994.81	42
2996.48	44
2998.16	44
2999.83	30