File: muestras/papalo/leaf_02.txt
#Acq. time (s)=	10
#Accumulations=	1
#Range (cm-¹)=	200...3000
#Windows=	3
#Autofocus=	Off
#AutoExposure=	Off
#Spike filter=	Off
#Delay time (s)=	0
#Binning=	1
#Readout mode=	Signal
#DeNoise=	Off
#ICS correction=	Off
#Dark correction=	Off
#Inst. Process=	Off
#Instrument=	LabRAM HR Evol
#Detector=	Syncerity OE
#Objective=	x100_VIS
#Grating=	600 (500nm)
#ND Filter=	0.1%
#Laser=	633nm_Edge
#Hole=	20.0287
#Range=	Visible
#Project=	Omar
#Sample=	03-07-23
#Site=	papal
#Title=	leaf
#Remark=
#Date=	03.07.2023 16:49
#Acquired=	03.07.2023 16:49:34
201.713	56
204.247	62
206.778	62
209.311	74
211.84	70
214.371	66
216.899	74
219.428	72
221.955	74
224.482	70
227.007	66
229.531	70
232.055	68
234.579	74
237.1	82
239.621	70
242.141	76
244.661	88
247.179	76
249.698	86
252.215	66
254.731	90
257.246	82
259.761	78
262.273	84
264.786	76
267.298	82
269.809	90
272.319	88
274.828	86
277.336	96
279.844	84
282.351	88
284.855	84
287.361	86
289.866	98
292.368	88
294.871	94
297.372	100
299.873	104
302.372	98
304.872	106
307.37	98
309.866	108
312.364	108
314.859	88
317.353	102
319.848	98
322.341	110
324.833	106
327.324	114
329.814	106
332.304	108
334.792	106
337.28	120
339.767	116
342.254	120
344.739	116
347.224	116
349.708	124
352.191	120
354.673	120
357.155	112
359.634	110
362.114	128
364.593	122
367.07	124
369.548	134
372.024	120
374.499	128
376.974	140
379.447	140
381.92	128
384.392	134
386.864	138
389.333	138
391.802	130
394.272	148
396.739	148
399.206	148
401.673	138
404.138	156
406.602	154
409.066	158
411.528	156
413.99	148
416.451	158
418.911	154
421.371	158
423.83	160
426.288	150
428.745	160
431.201	156
433.657	160
436.111	172
438.565	164
441.017	166
443.469	162
445.921	168
448.37	168
450.821	188
453.27	162
455.717	182
458.165	182
460.61	194
463.056	188
465.5	196
467.945	196
470.387	202
472.829	188
475.271	190
477.711	204
480.15	200
482.589	224
485.027	212
487.465	206
489.901	188
492.337	204
494.771	206
497.205	194
499.638	218
502.07	218
504.502	202
506.933	234
509.363	216
511.792	210
514.219	212
516.647	220
519.073	228
521.5	236
523.924	232
526.348	228
528.772	246
531.194	234
533.616	220
536.036	220
538.457	234
540.875	208
543.294	230
545.712	236
548.128	234
550.545	234
552.959	238
555.373	246
557.788	254
560.2	268
562.612	252
565.023	250
567.433	280
569.843	258
572.251	258
574.659	282
577.066	284
579.472	262
581.878	292
584.283	282
586.687	288
589.09	296
591.493	300
593.893	296
596.294	310
598.694	310
601.093	298
603.491	298
605.889	304
608.285	320
610.682	332
613.076	314
615.471	324
617.864	338
620.256	306
622.648	342
625.039	338
627.429	330
629.819	340
632.208	344
634.595	364
636.982	372
639.369	368
641.755	380
644.139	374
646.523	352
648.906	406
651.288	390
653.67	394
656.051	356
658.429	394
660.808	398
663.187	404
665.565	398
667.942	410
670.317	410
672.692	426
675.067	428
677.44	426
679.813	434
682.184	418
684.556	450
686.926	432
689.296	468
691.664	448
694.033	488
696.4	450
698.766	478
701.133	486
703.497	472
705.861	470
708.224	510
710.586	486
712.949	504
715.31	506
717.67	482
720.029	552
722.388	512
724.746	546
727.103	538
729.458	546
731.814	550
734.168	576
736.523	560
738.876	546
741.227	576
743.579	594
745.931	584
748.28	590
750.629	578
752.977	592
755.325	596
757.672	624
760.018	592
762.363	622
764.708	648
767.052	678
769.394	628
771.737	662
774.078	672
776.419	712
778.758	682
781.097	730
783.435	710
785.773	728
788.11	712
790.446	706
792.781	702
795.115	752
797.449	792
799.782	768
802.115	766
804.446	798
806.777	816
809.106	788
811.435	824
813.764	844
816.091	830
818.418	860
820.743	872
823.069	872
825.393	856
827.717	888
830.039	872
832.362	922
834.683	950
837.003	876
839.324	904
841.643	974
843.961	986
846.278	1012
848.594	992
850.91	1000
853.227	998
855.541	1082
857.855	1016
860.168	1060
862.48	1042
864.79	1058
867.101	1088
869.411	1120
871.721	1084
874.029	1126
876.336	1150
878.643	1132
880.95	1200
883.254	1160
885.559	1140
887.862	1218
890.166	1204
892.467	1184
894.77	1238
897.07	1246
899.371	1260
901.669	1288
903.968	1252
906.266	1274
908.563	1320
910.859	1266
913.154	1336
915.449	1346
917.742	1344
920.036	1384
922.329	1370
924.621	1394
926.911	1410
929.201	1386
931.49	1454
933.779	1472
936.068	1490
938.355	1504
940.64	1496
942.926	1518
945.212	1568
947.495	1594
949.779	1572
952.062	1578
954.344	1574
956.625	1584
958.905	1594
961.184	1650
963.464	1656
965.742	1702
968.02	1704
970.296	1726
972.572	1738
974.847	1756
977.121	1750
979.396	1762
981.669	1792
983.941	1826
986.212	1874
988.483	1848
990.753	1876
993.022	1888
995.29	1882
997.558	1910
999.825	1892
1002.09	1950
1004.36	1984
1006.62	1990
1008.89	2052
1011.15	1992
1013.41	2026
1015.67	2046
1017.93	2056
1020.19	2102
1022.45	2144
1024.71	2168
1026.97	2236
1029.23	2202
1031.49	2210
1033.74	2286
1036	2234
1038.25	2310
1040.5	2368
1042.76	2384
1045.01	2428
1047.26	2392
1049.51	2430
1051.76	2422
1054.01	2450
1056.26	2428
1058.51	2468
1060.75	2582
1063	2550
1065.25	2502
1067.49	2584
1069.73	2560
1071.98	2644
1074.22	2658
1076.46	2648
1078.7	2612
1080.94	2650
1083.18	2650
1085.42	2658
1087.66	2766
1089.9	2732
1092.14	2746
1094.37	2706
1096.61	2772
1098.84	2784
1101.08	2768
1103.31	2848
1105.54	2786
1107.77	2884
1110	2860
1112.23	2890
1114.46	2872
1116.69	2888
1118.92	2896
1121.15	3002
1123.37	2980
1125.6	2944
1127.83	2938
1130.05	2942
1132.27	3032
1134.5	3002
1136.72	3046
1138.94	3090
1141.16	3092
1143.38	3124
1145.6	3082
1147.82	3176
1150.04	3188
1152.26	3184
1154.47	3140
1156.69	3162
1158.9	3132
1161.12	3136
1163.33	3212
1165.54	3184
1167.76	3168
1169.97	3252
1172.18	3254
1174.39	3170
1176.6	3184
1178.81	3234
1181.02	3254
1183.22	3260
1185.43	3100
1187.63	3234
1189.84	3144
1192.04	3214
1194.25	3172
1196.45	3188
1198.65	3142
1200.85	3154
1203.05	3208
1205.25	3162
1207.45	3054
1209.65	3116
1211.85	3116
1214.05	3162
1216.24	3072
1218.44	3060
1220.64	3044
1222.83	3108
1225.02	3058
1227.22	3030
1229.41	3038
1231.6	2952
1233.79	2946
1235.98	2948
1238.17	2996
1240.36	2916
1242.55	2884
1244.73	2950
1246.92	2936
1249.11	2894
1251.29	2852
1253.48	2890
1255.66	2836
1257.84	2858
1260.03	2818
1262.21	2820
1264.39	2852
1266.57	2764
1268.75	2820
1270.93	2754
1273.11	2728
1275.28	2662
1277.46	2702
1279.64	2684
1281.81	2678
1283.98	2624.65
1286.16	2686.76
1288.33	2634.53
1290.5	2615.63
1292.68	2640.68
1294.85	2595.67
1297.02	2519.83
1299.19	2516.81
1301.36	2528.17
1303.53	2468.03
1305.69	2480.32
1307.86	2486.63
1310.03	2411.05
1312.19	2409.99
1314.36	2423.15
1316.52	2360.89
1318.68	2353.75
1320.85	2365.5
1323.01	2374.94
1325.17	2309.67
1327.33	2319.11
1329.49	2245.46
1331.65	2272.35
1333.81	2253.93
1335.97	2230.33
1338.12	2218.1
1340.28	2197.23
1342.44	2191.59
1344.59	2194.19
1346.75	2147.81
1348.9	2130.85
1351.05	2162.99
1353.2	2127.08
1355.36	2116.85
1357.51	2123.02
1359.66	2020.54
1361.81	2080.47
1363.96	2019.03
1366.1	2019.02
1368.25	2021.88
1370.4	1976.25
1372.54	2002.1
1374.69	1935.32
1376.83	1913.54
1378.98	1924.28
1381.12	1906.51
1383.26	1955.92
1385.41	1923.68
1387.55	1867.26
1389.69	1908.9
1391.83	1944.51
1393.02	1896
1395.17	1840
1397.32	1880
1399.47	1810
1401.62	1848
1403.77	1800
1405.91	1768
1408.06	1784
1410.2	1796
1412.35	1720
1414.49	1724
1416.63	1722
1418.78	1694
1420.92	1704
1423.06	1678
1425.2	1690
1427.34	1638
1429.48	1630
1431.61	1654
1433.75	1618
1435.89	1642
1438.02	1606
1440.16	1618
1442.3	1614
1444.43	1598
1446.56	1570
1448.7	1582
1450.83	1564
1452.96	1544
1455.09	1544
1457.22	1534
1459.35	1526
1461.48	1494
1463.61	1526
1465.73	1536
1467.86	1490
1469.98	1482
1472.11	1500
1474.24	1456
1476.36	1466
1478.48	1478
1480.6	1460
1482.73	1418
1484.85	1412
1486.97	1444
1489.09	1448
1491.21	1404
1493.33	1388
1495.44	1404
1497.56	1392
1499.68	1432
1501.79	1432
1503.91	1352
1506.02	1378
1508.14	1336
1510.25	1308
1512.36	1328
1514.48	1330
1516.59	1380
1518.7	1348
1520.81	1356
1522.92	1334
1525.02	1322
1527.13	1278
1529.24	1310
1531.35	1256
1533.45	1276
1535.56	1276
1537.66	1296
1539.77	1264
1541.87	1288
1543.97	1208
1546.08	1252
1548.18	1210
1550.28	1250
1552.38	1198
1554.48	1228
1556.57	1236
1558.67	1184
1560.77	1264
1562.87	1176
1564.96	1196
1567.06	1194
1569.15	1140
1571.25	1162
1573.34	1202
1575.43	1162
1577.53	1146
1579.62	1116
1581.71	1146
1583.8	1148
1585.89	1144
1587.98	1154
1590.06	1212
1592.15	1114
1594.24	1100
1596.33	1168
1598.41	1138
1600.5	1146
1602.58	1144
1604.66	1150
1606.75	1164
1608.83	1110
1610.91	1094
1612.99	1148
1615.07	1094
1617.15	1078
1619.23	1108
1621.31	1116
1623.39	1094
1625.46	1092
1627.54	1078
1629.62	1060
1631.69	1086
1633.77	1070
1635.84	1138
1637.91	1052
1639.99	1088
1642.06	1036
1644.13	1086
1646.2	1064
1648.27	1024
1650.34	1042
1652.41	1092
1654.47	1054
1656.54	1064
1658.61	1040
1660.67	1016
1662.74	1058
1664.81	1024
1666.87	1010
1668.93	1050
1671	1022
1673.06	1024
1675.12	1016
1677.18	984
1679.24	1010
1681.3	950
1683.36	988
1685.42	964
1687.47	1022
1689.53	982
1691.59	1044
1693.64	1032
1695.7	992
1697.75	988
1699.81	990
1701.86	984
1703.91	940
1705.97	1000
1708.02	1000
1710.07	986
1712.12	996
1714.17	950
1716.22	972
1718.26	950
1720.31	928
1722.36	986
1724.4	1018
1726.45	976
1728.49	970
1730.54	924
1732.58	990
1734.63	960
1736.67	946
1738.71	968
1740.75	948
1742.79	932
1744.83	940
1746.87	960
1748.91	962
1750.95	952
1752.98	956
1755.02	936
1757.06	980
1759.09	938
1761.13	962
1763.16	952
1765.19	938
1767.23	976
1769.26	920
1771.29	914
1773.32	942
1775.35	942
1777.38	964
1779.41	922
1781.44	982
1783.47	952
1785.49	906
1787.52	936
1789.55	932
1791.57	984
1793.6	962
1795.62	930
1797.64	956
1799.67	964
1801.69	902
1803.71	932
1805.73	960
1807.75	910
1809.77	916
1811.79	920
1813.81	906
1815.83	916
1817.84	924
1819.86	930
1821.88	946
1823.89	950
1825.91	902
1827.92	894
1829.93	944
1831.95	880
1833.96	876
1835.97	920
1837.98	900
1839.99	936
1842	888
1844.01	934
1846.02	922
1848.03	874
1850.03	882
1852.04	890
1854.05	900
1856.05	908
1858.06	920
1860.06	872
1862.06	916
1864.07	894
1866.07	920
1868.07	898
1870.07	860
1872.07	878
1874.07	908
1876.07	882
1878.07	850
1880.07	908
1882.07	854
1884.06	886
1886.06	894
1888.05	890
1890.05	882
1892.04	894
1894.04	918
1896.03	856
1898.02	874
1900.01	888
1902	894
1903.99	882
1905.98	894
1907.97	868
1909.96	888
1911.95	878
1913.94	912
1915.93	900
1917.91	894
1919.9	856
1921.88	868
1923.87	878
1925.85	868
1927.83	854
1929.82	868
1931.8	880
1933.78	878
1935.76	890
1937.74	862
1939.72	838
1941.7	868
1943.68	854
1945.65	860
1947.63	880
1949.61	870
1951.58	846
1953.56	858
1955.53	838
1957.51	842
1959.48	822
1961.45	864
1963.43	872
1965.4	842
1967.37	890
1969.34	856
1971.31	854
1973.28	848
1975.25	852
1977.22	874
1979.18	832
1981.15	854
1983.12	814
1985.08	844
1987.05	812
1989.01	854
1990.97	886
1992.94	844
1994.9	834
1996.86	860
1998.82	852
2000.78	842
2002.74	830
2004.7	876
2006.66	850
2008.62	858
2010.58	858
2012.54	858
2014.49	854
2016.45	866
2018.4	828
2020.36	838
2022.31	826
2024.27	870
2026.22	822
2028.17	835
2030.12	804
2032.07	834
2034.03	834
2035.98	816
2037.93	888
2039.87	782
2041.82	818
2043.77	816
2045.72	830
2047.66	812
2049.61	810
2051.55	838
2053.5	824
2055.44	838
2057.39	834
2059.33	822
2061.27	850
2063.21	842
2065.15	820
2067.09	826
2069.03	828
2070.97	846
2072.91	820
2074.85	822
2076.79	822
2078.73	792
2080.66	798
2082.6	848
2084.53	792
2086.47	850
2088.4	810
2090.33	790
2092.27	796
2094.2	788
2096.13	802
2098.06	804
2099.99	830
2101.92	834
2103.85	812
2105.78	806
2107.71	786
2109.64	828
2111.56	830
2113.49	794
2115.41	812
2117.34	808
2119.26	808
2121.19	776
2123.11	792
2125.03	810
2126.96	776
2128.88	792
2130.8	800
2132.72	806
2134.64	786
2136.56	790
2138.48	816
2140.4	786
2142.31	820
2144.23	816
2146.15	810
2148.06	802
2149.98	808
2151.89	816
2153.81	770
2155.72	802
2157.63	776
2159.55	778
2161.46	792
2163.37	776
2165.28	784
2167.19	762
2169.1	768
2171.01	776
2172.91	774
2174.82	786
2176.73	792
2178.64	754
2180.54	764
2182.45	756
2184.35	780
2186.26	768
2188.16	728
2190.06	778
2191.96	772
2193.87	758
2195.77	770
2197.67	750
2199.57	724
2201.47	724
2203.37	756
2205.27	768
2207.16	772
2209.06	786
2210.96	752
2212.85	744
2214.75	742
2216.64	752
2218.54	758
2220.43	736
2222.33	750
2224.22	747.583
2226.11	746.037
2228	770.757
2229.89	729.814
2231.78	712.305
2233.67	739.368
2235.56	729.587
2237.45	745.936
2239.34	731.81
2241.23	736.49
2243.11	706.179
2245	738.029
2246.89	735.82
2248.77	727.624
2250.66	730.034
2252.54	748.96
2254.42	719.893
2256.31	728.19
2258.19	730.531
2260.07	731.886
2261.95	714.891
2263.83	726.29
2265.71	741.42
2267.59	704.728
2269.47	729.714
2271.35	732.824
2273.23	709.28
2275.1	744.905
2276.98	711.068
2278.86	722.181
2280.73	719.655
2282.61	712.74
2284.48	723.186
2286.36	707.935
2288.23	717.617
2290.1	688.237
2291.98	702.667
2293.85	699.731
2295.72	698.445
2297.59	683.62
2299.46	687.868
2301.33	685.829
2303.2	708.473
2305.06	690.554
2306.93	676.272
2308.8	705.933
2310.67	686.789
2312.53	697.694
2314.4	695.874
2316.26	659.776
2317.62	682
2319.5	660
2321.37	690
2323.24	702
2325.12	676
2326.99	664
2328.86	696
2330.73	634
2332.6	684
2334.47	676
2336.34	642
2338.2	644
2340.07	632
2341.94	654
2343.81	674
2345.67	650
2347.54	660
2349.4	644
2351.27	630
2353.13	664
2354.99	626
2356.86	640
2358.72	614
2360.58	650
2362.44	640
2364.3	634
2366.16	626
2368.02	652
2369.88	650
2371.74	628
2373.6	640
2375.45	634
2377.31	632
2379.17	602
2381.02	622
2382.88	628
2384.73	596
2386.58	622
2388.44	614
2390.29	620
2392.14	634
2393.99	600
2395.85	604
2397.7	614
2399.55	612
2401.4	600
2403.25	616
2405.09	592
2406.94	602
2408.79	582
2410.63	590
2412.48	596
2414.33	590
2416.17	612
2418.02	608
2419.86	558
2421.7	602
2423.55	598
2425.39	572
2427.23	566
2429.07	612
2430.91	576
2432.75	580
2434.59	586
2436.43	558
2438.27	550
2440.11	560
2441.95	572
2443.78	560
2445.62	554
2447.46	530
2449.29	522
2451.13	552
2452.96	562
2454.79	554
2456.63	536
2458.46	504
2460.29	558
2462.12	518
2463.95	528
2465.78	506
2467.61	520
2469.44	530
2471.27	518
2473.1	494
2474.93	526
2476.76	520
2478.58	512
2480.41	494
2482.23	538
2484.06	516
2485.88	522
2487.71	502
2489.53	498
2491.35	492
2493.18	506
2495	494
2496.82	492
2498.64	496
2500.46	496
2502.28	482
2504.1	478
2505.92	460
2507.74	474
2509.55	474
2511.37	488
2513.19	492
2515	486
2516.82	440
2518.63	460
2520.45	460
2522.26	502
2524.07	438
2525.89	448
2527.7	450
2529.51	460
2531.32	432
2533.13	434
2534.94	438
2536.75	450
2538.56	434
2540.37	466
2542.18	454
2543.98	426
2545.79	440
2547.6	446
2549.4	428
2551.21	452
2553.01	400
2554.82	402
2556.62	434
2558.42	404
2560.23	418
2562.03	406
2563.83	400
2565.63	428
2567.43	404
2569.23	436
2571.03	414
2572.83	376
2574.63	402
2576.43	404
2578.22	396
2580.02	426
2581.82	410
2583.61	394
2585.41	400
2587.2	384
2589	402
2590.79	420
2592.58	394
2594.38	398
2596.17	400
2597.96	372
2599.75	376
2601.54	390
2603.33	398
2605.12	380
2606.91	362
2608.7	370
2610.49	372
2612.27	390
2614.06	368
2615.85	378
2617.63	368
2619.42	358
2621.2	378
2622.99	358
2624.77	348
2626.55	346
2628.34	364
2630.12	386
2631.9	364
2633.68	370
2635.46	342
2637.24	332
2639.02	348
2640.8	350
2642.58	326
2644.36	350
2646.14	346
2647.91	336
2649.69	344
2651.46	342
2653.24	344
2655.01	326
2656.79	326
2658.56	340
2660.34	332
2662.11	324
2663.88	330
2665.65	306
2667.42	334
2669.2	312
2670.96	318
2672.73	322
2674.5	320
2676.27	330
2678.04	298
2679.81	314
2681.58	314
2683.34	320
2685.11	306
2686.87	312
2688.64	306
2690.4	292
2692.17	306
2693.93	296
2695.69	304
2697.46	276
2699.22	294
2700.98	302
2702.74	288
2704.5	308
2706.26	276
2708.02	302
2709.78	280
2711.54	294
2713.3	284
2715.05	298
2716.81	278
2718.57	292
2720.32	278
2722.08	264
2723.83	262
2725.59	258
2727.34	268
2729.09	270
2730.85	268
2732.6	290
2734.35	270
2736.1	270
2737.85	270
2739.6	256
2741.35	266
2743.1	250
2744.85	270
2746.6	258
2748.35	236
2750.09	248
2751.84	236
2753.59	244
2755.33	252
2757.08	262
2758.82	232
2760.57	240
2762.31	220
2764.05	248
2765.79	238
2767.54	264
2769.28	226
2771.02	224
2772.76	220
2774.5	234
2776.24	232
2777.98	236
2779.72	224
2781.46	232
2783.19	244
2784.93	218
2786.67	212
2788.4	232
2790.14	210
2791.87	222
2793.61	242
2795.34	222
2797.07	208
2798.81	226
2800.54	206
2802.27	194
2804	208
2805.74	200
2807.47	214
2809.2	220
2810.93	196
2812.65	196
2814.38	206
2816.11	210
2817.84	202
2819.56	202
2821.29	198
2823.02	222
2824.74	208
2826.47	206
2828.19	196
2829.92	208
2831.64	210
2833.36	194
2835.09	200
2836.81	192
2838.53	190
2840.25	184
2841.97	198
2843.69	184
2845.41	176
2847.13	190
2848.85	198
2850.57	194
2852.28	184
2854	184
2855.72	178
2857.43	176
2859.15	196
2860.86	170
2862.58	174
2864.29	190
2866.01	178
2867.72	172
2869.43	164
2871.14	164
2872.86	168
2874.57	158
2876.28	178
2877.99	156
2879.7	156
2881.41	176
2883.11	172
2884.82	160
2886.53	166
2888.24	146
2889.94	164
2891.65	170
2893.36	156
2895.06	154
2896.77	158
2898.47	158
2900.17	158
2901.88	164
2903.58	164
2905.28	160
2906.98	148
2908.69	154
2910.39	162
2912.09	136
2913.79	158
2915.49	152
2917.19	140
2918.88	140
2920.58	150
2922.28	140
2923.98	138
2925.67	130
2927.37	144
2929.06	136
2930.76	138
2932.45	118
2934.15	140
2935.84	146
2937.53	142
2939.23	146
2940.92	152
2942.61	144
2944.3	132
2945.99	148
2947.68	154
2949.37	134
2951.06	136
2952.75	120
2954.44	144
2956.12	132
2957.81	132
2959.5	128
2961.18	134
2962.87	130
2964.56	130
2966.24	140
2967.92	136
2969.61	128
2971.29	134
2972.97	126
2974.66	134
2976.34	116
2978.02	130
2979.7	120
2981.38	126
2983.06	134
2984.74	134
2986.42	118
2988.1	136
2989.78	128
2991.45	110
2993.13	118
2994.81	110
2996.48	118
2998.16	116
2999.83	118