File: muestras/papalo/leaf_100x_14.txt
#Acq. time (s)=	10
#Accumulations=	1
#Range (cm-¹)=	200...3000
#Windows=	3
#Autofocus=	Off
#AutoExposure=	Off
#Spike filter=	Off
#Delay time (s)=	0
#Binning=	1
#Readout mode=	Signal
#DeNoise=	Off
#ICS correction=	Off
#Dark correction=	Off
#Inst. Process=	Off
#Instrument=	LabRAM HR Evol
#Detector=	Syncerity OE
#Objective=	x100_VIS
#Grating=	600 (500nm)
#ND Filter=	0.1%
#Laser=	633nm_Edge
#Hole=	100.021
#Range=	Visible
#Project=	Omar
#Sample=	03-07-23
#Site=	papal
#Title=	leaf_100x
#Remark=
#Date=	03.07.2023 17:23
#Acquired=	03.07.2023 17:23:43
201.713	114
204.247	112
206.778	126
209.311	106
211.84	110
214.371	118
216.899	124
219.428	114
221.955	130
224.482	132
227.007	140
229.531	130
232.055	132
234.579	150
237.1	138
239.621	128
242.141	140
244.661	140
247.179	152
249.698	152
252.215	150
254.731	144
257.246	146
259.761	156
262.273	130
264.786	150
267.298	160
269.809	164
272.319	162
274.828	162
277.336	172
279.844	156
282.351	164
284.855	164
287.361	182
289.866	186
292.368	164
294.871	178
297.372	188
299.873	186
302.372	182
304.872	200
307.37	196
309.866	188
312.364	202
314.859	208
317.353	192
319.848	216
322.341	234
324.833	208
327.324	210
329.814	214
332.304	226
334.792	214
337.28	230
339.767	220
342.254	230
344.739	236
347.224	228
349.708	240
352.191	238
354.673	254
357.155	260
359.634	266
362.114	240
364.593	260
367.07	246
369.548	258
372.024	266
374.499	270
376.974	278
379.447	280
381.92	258
384.392	266
386.864	284
389.333	264
391.802	290
394.272	288
396.739	302
399.206	292
401.673	276
404.138	342
406.602	286
409.066	310
411.528	312
413.99	302
416.451	330
418.911	314
421.371	338
423.83	332
426.288	358
428.745	340
431.201	378
433.657	362
436.111	340
438.565	362
441.017	378
443.469	378
445.921	362
448.37	360
450.821	382
453.27	380
455.717	368
458.165	396
460.61	394
463.056	402
465.5	372
467.945	404
470.387	424
472.829	414
475.271	444
477.711	404
480.15	432
482.589	436
485.027	426
487.465	456
489.901	426
492.337	454
494.771	456
497.205	466
499.638	434
502.07	494
504.502	486
506.933	482
509.363	484
511.792	514
514.219	496
516.647	490
519.073	464
521.5	500
523.924	484
526.348	530
528.772	514
531.194	506
533.616	526
536.036	546
538.457	542
540.875	564
543.294	524
545.712	526
548.128	516
550.545	578
552.959	554
555.373	570
557.788	562
560.2	582
562.612	582
565.023	592
567.433	616
569.843	588
572.251	630
574.659	666
577.066	618
579.472	650
581.878	652
584.283	622
586.687	692
589.09	664
591.493	682
593.893	672
596.294	688
598.694	700
601.093	704
603.491	702
605.889	726
608.285	720
610.682	722
613.076	730
615.471	774
617.864	778
620.256	782
622.648	794
625.039	792
627.429	836
629.819	808
632.208	824
634.595	818
636.982	824
639.369	854
641.755	870
644.139	882
646.523	908
648.906	874
651.288	898
653.67	880
656.051	936
658.429	908
660.808	944
663.187	916
665.565	944
667.942	952
670.317	990
672.692	1006
675.067	1002
677.44	1006
679.813	1022
682.184	1014
684.556	1020
686.926	1050
689.296	1076
691.664	1062
694.033	1072
696.4	1110
698.766	1078
701.133	1116
703.497	1134
705.861	1174
708.224	1154
710.586	1176
712.949	1178
715.31	1178
717.67	1200
720.029	1254
722.388	1264
724.746	1294
727.103	1286
729.458	1306
731.814	1300
734.168	1338
736.523	1342
738.876	1330
741.227	1396
743.579	1396
745.931	1406
748.28	1414
750.629	1432
752.977	1460
755.325	1450
757.672	1462
760.018	1478
762.363	1528
764.708	1534
767.052	1526
769.394	1584
771.737	1620
774.078	1616
776.419	1612
778.758	1642
781.097	1622
783.435	1696
785.773	1738
788.11	1668
790.446	1768
792.781	1776
795.115	1798
797.449	1768
799.782	1828
802.115	1830
804.446	1944
806.777	1928
809.106	1924
811.435	1978
813.764	2026
816.091	1972
818.418	1974
820.743	2052
823.069	2076
825.393	2076
827.717	2118
830.039	2104
832.362	2188
834.683	2202
837.003	2296
839.324	2268
841.643	2296
843.961	2344
846.278	2326
848.594	2374
850.91	2436
853.227	2370
855.541	2434
857.855	2488
860.168	2552
862.48	2500
864.79	2554
867.101	2642
869.411	2694
871.721	2650
874.029	2698
876.336	2770
878.643	2758
880.95	2790
883.254	2786
885.559	2794
887.862	2880
890.166	2888
892.467	2938
894.77	2950
897.07	2966
899.371	2952
901.669	3036
903.968	3044
906.266	3022
908.563	3100
910.859	3110
913.154	3240
915.449	3194
917.742	3250
920.036	3294
922.329	3326
924.621	3314
926.911	3372
929.201	3384
931.49	3478
933.779	3492
936.068	3492
938.355	3606
940.64	3618
942.926	3714
945.212	3664
947.495	3818
949.779	3742
952.062	3788
954.344	3880
956.625	4016
958.905	3984
961.184	4056
963.464	4022
965.742	4104
968.02	4116
970.296	4192
972.572	4188
974.847	4334
977.121	4306
979.396	4362
981.669	4384
983.941	4402
986.212	4474
988.483	4490
990.753	4606
993.022	4586
995.29	4640
997.558	4686
999.825	4664
1002.09	4670
1004.36	4740
1006.62	4880
1008.89	4836
1011.15	5026
1013.41	4996
1015.67	5092
1017.93	5166
1020.19	5066
1022.45	5252
1024.71	5234
1026.97	5298
1029.23	5374
1031.49	5442
1033.74	5426
1036	5490
1038.25	5636
1040.5	5610
1042.76	5712
1045.01	5676
1047.26	5916
1049.51	5914
1051.76	5936
1054.01	6048
1056.26	6040
1058.51	6148
1060.75	6192
1063	6246
1065.25	6290
1067.49	6360
1069.73	6344
1071.98	6382
1074.22	6472
1076.46	6518
1078.7	6566
1080.94	6548
1083.18	6654
1085.42	6736
1087.66	6800
1089.9	6744
1092.14	6800
1094.37	6786
1096.61	6850
1098.84	6950
1101.08	6960
1103.31	6944
1105.54	7044
1107.77	7124
1110	7072
1112.23	7170
1114.46	7268
1116.69	7360
1118.92	7412
1121.15	7274
1123.37	7424
1125.6	7430
1127.83	7394
1130.05	7552
1132.27	7710
1134.5	7700
1136.72	7782
1138.94	7756
1141.16	7738
1143.38	7762
1145.6	7900
1147.82	7926
1150.04	7992
1152.26	8026
1154.47	8030
1156.69	8070
1158.9	8134
1161.12	8206
1163.33	8140
1165.54	8130
1167.76	8254
1169.97	8264
1172.18	8260
1174.39	8306
1176.6	8210
1178.81	8396
1181.02	8346
1183.22	8338
1185.43	8488
1187.63	8378
1189.84	8378
1192.04	8406
1194.25	8386
1196.45	8368
1198.65	8278
1200.85	8274
1203.05	8304
1205.25	8168
1207.45	8282
1209.65	8364
1211.85	8220
1214.05	8172
1216.24	8254
1218.44	8126
1220.64	8096
1222.83	8186
1225.02	8096
1227.22	8074
1229.41	8050
1231.6	8028
1233.79	7938
1235.98	7994
1238.17	8026
1240.36	7928
1242.55	7914
1244.73	7892
1246.92	7912
1249.11	7878
1251.29	7856
1253.48	7734
1255.66	7678
1257.84	7824
1260.03	7734
1262.21	7644
1264.39	7654
1266.57	7626
1268.75	7542
1270.93	7602
1273.11	7472
1275.28	7390
1277.46	7362
1279.64	7394
1281.81	7354
1283.98	7253.6
1286.16	7244.45
1288.33	7112.35
1290.5	7175.23
1292.68	7032.62
1294.85	6854.27
1297.02	6952.22
1299.19	6894.22
1301.36	6830.5
1303.53	6820.45
1305.69	6660.55
1307.86	6510.51
1310.03	6549.15
1312.19	6460.92
1314.36	6352.6
1316.52	6378.19
1318.68	6284.98
1320.85	6170.12
1323.01	6125.43
1325.17	6084.69
1327.33	5961.07
1329.49	5876.59
1331.65	5944.89
1333.81	5850.1
1335.97	5806.53
1338.12	5713.05
1340.28	5627.26
1342.44	5625.18
1344.59	5518.83
1346.75	5379.96
1348.9	5327.11
1351.05	5388.19
1353.2	5283.4
1355.36	5269.01
1357.51	5201.37
1359.66	5172.71
1361.81	5095.83
1363.96	4972.42
1366.1	4962.39
1368.25	4942.01
1370.4	4854.93
1372.54	4880.83
1374.69	4713.24
1376.83	4723.47
1378.98	4692.57
1381.12	4608.61
1383.26	4549
1385.41	4516.67
1387.55	4435.05
1389.69	4471.15
1391.83	4396.6
1393.02	4328
1395.17	4366
1397.32	4250
1399.47	4234
1401.62	4206
1403.77	4164
1405.91	4142
1408.06	4130
1410.2	4082
1412.35	4042
1414.49	4054
1416.63	3982
1418.78	4020
1420.92	3940
1423.06	3960
1425.2	3986
1427.34	3986
1429.48	3832
1431.61	3826
1433.75	3850
1435.89	3830
1438.02	3740
1440.16	3734
1442.3	3738
1444.43	3694
1446.56	3680
1448.7	3674
1450.83	3652
1452.96	3664
1455.09	3628
1457.22	3598
1459.35	3620
1461.48	3572
1463.61	3590
1465.73	3450
1467.86	3546
1469.98	3516
1472.11	3494
1474.24	3428
1476.36	3450
1478.48	3438
1480.6	3362
1482.73	3360
1484.85	3370
1486.97	3306
1489.09	3304
1491.21	3278
1493.33	3320
1495.44	3256
1497.56	3200
1499.68	3202
1501.79	3196
1503.91	3238
1506.02	3198
1508.14	3208
1510.25	3210
1512.36	3126
1514.48	3136
1516.59	3088
1518.7	3100
1520.81	3074
1522.92	3022
1525.02	2960
1527.13	3022
1529.24	3002
1531.35	2968
1533.45	2978
1535.56	2970
1537.66	2968
1539.77	2926
1541.87	2912
1543.97	2886
1546.08	2846
1548.18	2824
1550.28	2832
1552.38	2762
1554.48	2830
1556.57	2814
1558.67	2752
1560.77	2722
1562.87	2752
1564.96	2776
1567.06	2720
1569.15	2772
1571.25	2732
1573.34	2746
1575.43	2656
1577.53	2696
1579.62	2668
1581.71	2658
1583.8	2664
1585.89	2644
1587.98	2658
1590.06	2574
1592.15	2654
1594.24	2586
1596.33	2544
1598.41	2538
1600.5	2590
1602.58	2546
1604.66	2598
1606.75	2542
1608.83	2598
1610.91	2522
1612.99	2570
1615.07	2538
1617.15	2572
1619.23	2502
1621.31	2504
1623.39	2506
1625.46	2520
1627.54	2560
1629.62	2540
1631.69	2462
1633.77	2450
1635.84	2438
1637.91	2442
1639.99	2450
1642.06	2444
1644.13	2466
1646.2	2424
1648.27	2472
1650.34	2404
1652.41	2432
1654.47	2412
1656.54	2370
1658.61	2350
1660.67	2378
1662.74	2336
1664.81	2378
1666.87	2416
1668.93	2410
1671	2288
1673.06	2372
1675.12	2362
1677.18	2348
1679.24	2262
1681.3	2308
1683.36	2264
1685.42	2344
1687.47	2318
1689.53	2272
1691.59	2276
1693.64	2230
1695.7	2288
1697.75	2246
1699.81	2282
1701.86	2270
1703.91	2250
1705.97	2234
1708.02	2212
1710.07	2200
1712.12	2266
1714.17	2212
1716.22	2202
1718.26	2166
1720.31	2270
1722.36	2204
1724.4	2194
1726.45	2206
1728.49	2144
1730.54	2148
1732.58	2212
1734.63	2194
1736.67	2174
1738.71	2172
1740.75	2168
1742.79	2146
1744.83	2160
1746.87	2156
1748.91	2202
1750.95	2074
1752.98	2162
1755.02	2138
1757.06	2146
1759.09	2226
1761.13	2154
1763.16	2114
1765.19	2146
1767.23	2144
1769.26	2224
1771.29	2148
1773.32	2128
1775.35	2168
1777.38	2148
1779.41	2170
1781.44	2184
1783.47	2126
1785.49	2144
1787.52	2122
1789.55	2164
1791.57	2140
1793.6	2106
1795.62	2136
1797.64	2114
1799.67	2192
1801.69	2060
1803.71	2152
1805.73	2100
1807.75	2066
1809.77	2088
1811.79	2072
1813.81	2128
1815.83	2096
1817.84	2056
1819.86	2076
1821.88	2122
1823.89	2100
1825.91	2116
1827.92	2078
1829.93	1996
1831.95	2040
1833.96	2074
1835.97	2026
1837.98	2104
1839.99	2124
1842	2080
1844.01	2024
1846.02	2022
1848.03	2062
1850.03	2060
1852.04	2086
1854.05	2016
1856.05	2042
1858.06	2036
1860.06	2002
1862.06	1980
1864.07	2098
1866.07	2034
1868.07	2098
1870.07	2108
1872.07	2072
1874.07	2046
1876.07	2064
1878.07	2058
1880.07	2014
1882.07	2084
1884.06	2108
1886.06	1982
1888.05	2034
1890.05	2028
1892.04	1972
1894.04	2046
1896.03	2012
1898.02	2046
1900.01	2002
1902	2036
1903.99	2084
1905.98	2040
1907.97	2038
1909.96	2016
1911.95	2016
1913.94	1954
1915.93	2016
1917.91	2052
1919.9	1990
1921.88	2028
1923.87	2022
1925.85	1992
1927.83	2052
1929.82	1982
1931.8	2008
1933.78	1994
1935.76	1996
1937.74	1998
1939.72	2016
1941.7	1984
1943.68	2028
1945.65	1958
1947.63	1996
1949.61	2008
1951.58	1986
1953.56	1984
1955.53	1984
1957.51	1962
1959.48	2022
1961.45	1978
1963.43	1998
1965.4	1922
1967.37	2008
1969.34	1938
1971.31	1978
1973.28	1972
1975.25	1938
1977.22	1998
1979.18	1974
1981.15	1950
1983.12	1934
1985.08	1928
1987.05	1934
1989.01	1952
1990.97	1980
1992.94	1912
1994.9	1942
1996.86	1872
1998.82	1964
2000.78	1892
2002.74	1938
2004.7	1928
2006.66	1852
2008.62	1996
2010.58	1894
2012.54	1944
2014.49	1902
2016.45	1912
2018.4	1882
2020.36	1932
2022.31	1892
2024.27	1934
2026.22	1892
2028.17	1916
2030.12	1992
2032.07	1878
2034.03	1860
2035.98	1928
2037.93	1882
2039.87	1924
2041.82	1874
2043.77	1898
2045.72	1860
2047.66	1912
2049.61	1872
2051.55	1842
2053.5	1892
2055.44	1916
2057.39	1868
2059.33	1876
2061.27	1872
2063.21	1936
2065.15	1916
2067.09	1906
2069.03	1842
2070.97	1856
2072.91	1890
2074.85	1888
2076.79	1856
2078.73	1894
2080.66	1924
2082.6	1856
2084.53	1888
2086.47	1892
2088.4	1852
2090.33	1858
2092.27	1846
2094.2	1842
2096.13	1836
2098.06	1832
2099.99	1822
2101.92	1932
2103.85	1810
2105.78	1898
2107.71	1912
2109.64	1908
2111.56	1832
2113.49	1874
2115.41	1856
2117.34	1852
2119.26	1832
2121.19	1820
2123.11	1828
2125.03	1854
2126.96	1850
2128.88	1848
2130.8	1862
2132.72	1818
2134.64	1842
2136.56	1848
2138.48	1828
2140.4	1806
2142.31	1844
2144.23	1820
2146.15	1836
2148.06	1800
2149.98	1808
2151.89	1850
2153.81	1788
2155.72	1794
2157.63	1826
2159.55	1786
2161.46	1828
2163.37	1844
2165.28	1830
2167.19	1788
2169.1	1806
2171.01	1842
2172.91	1716
2174.82	1774
2176.73	1792
2178.64	1802
2180.54	1794
2182.45	1756
2184.35	1804
2186.26	1782
2188.16	1802
2190.06	1742
2191.96	1754
2193.87	1738
2195.77	1766
2197.67	1712
2199.57	1722
2201.47	1760
2203.37	1786
2205.27	1754
2207.16	1740
2209.06	1698
2210.96	1744
2212.85	1696
2214.75	1720
2216.64	1752
2218.54	1712
2220.43	1708
2222.33	1688
2224.22	1679.02
2226.11	1680.73
2228	1665.39
2229.89	1726.33
2231.78	1663.15
2233.67	1700.35
2235.56	1689.6
2237.45	1720.45
2239.34	1685.31
2241.23	1641.03
2243.11	1699.68
2245	1716.32
2246.89	1655.17
2248.77	1671.65
2250.66	1680.31
2252.54	1673.01
2254.42	1644.99
2256.31	1633.73
2258.19	1639.35
2260.07	1626.27
2261.95	1672.23
2263.83	1637.86
2265.71	1639.99
2267.59	1609.03
2269.47	1603.7
2271.35	1617.91
2273.23	1594.03
2275.1	1606.79
2276.98	1563.85
2278.86	1572.52
2280.73	1569.36
2282.61	1590.34
2284.48	1554
2286.36	1540.49
2288.23	1560.81
2290.1	1555.68
2291.98	1567.02
2293.85	1527.49
2295.72	1523.09
2297.59	1562.6
2299.46	1507.16
2301.33	1505.01
2303.2	1531.58
2305.06	1501.21
2306.93	1489.63
2308.8	1487.27
2310.67	1496.05
2312.53	1480.48
2314.4	1474.07
2316.26	1508.36
2317.62	1480
2319.5	1448
2321.37	1464
2323.24	1426
2325.12	1410
2326.99	1458
2328.86	1412
2330.73	1460
2332.6	1432
2334.47	1364
2336.34	1434
2338.2	1418
2340.07	1400
2341.94	1414
2343.81	1480
2345.67	1412
2347.54	1432
2349.4	1400
2351.27	1406
2353.13	1354
2354.99	1362
2356.86	1366
2358.72	1418
2360.58	1384
2362.44	1366
2364.3	1424
2366.16	1348
2368.02	1354
2369.88	1364
2371.74	1360
2373.6	1344
2375.45	1336
2377.31	1382
2379.17	1348
2381.02	1352
2382.88	1350
2384.73	1308
2386.58	1312
2388.44	1290
2390.29	1258
2392.14	1288
2393.99	1320
2395.85	1300
2397.7	1266
2399.55	1264
2401.4	1286
2403.25	1258
2405.09	1276
2406.94	1320
2408.79	1282
2410.63	1254
2412.48	1282
2414.33	1258
2416.17	1216
2418.02	1252
2419.86	1268
2421.7	1248
2423.55	1228
2425.39	1222
2427.23	1198
2429.07	1216
2430.91	1226
2432.75	1204
2434.59	1232
2436.43	1160
2438.27	1202
2440.11	1192
2441.95	1200
2443.78	1190
2445.62	1150
2447.46	1184
2449.29	1152
2451.13	1116
2452.96	1160
2454.79	1166
2456.63	1148
2458.46	1148
2460.29	1128
2462.12	1134
2463.95	1114
2465.78	1118
2467.61	1092
2469.44	1120
2471.27	1104
2473.1	1110
2474.93	1094
2476.76	1060
2478.58	1088
2480.41	1058
2482.23	1066
2484.06	1056
2485.88	1048
2487.71	1062
2489.53	1038
2491.35	1026
2493.18	1070
2495	1054
2496.82	1058
2498.64	1016
2500.46	986
2502.28	1018
2504.1	994
2505.92	1020
2507.74	988
2509.55	992
2511.37	988
2513.19	986
2515	970
2516.82	944
2518.63	976
2520.45	960
2522.26	958
2524.07	948
2525.89	938
2527.7	940
2529.51	940
2531.32	942
2533.13	896
2534.94	918
2536.75	912
2538.56	896
2540.37	912
2542.18	876
2543.98	912
2545.79	926
2547.6	922
2549.4	888
2551.21	896
2553.01	866
2554.82	864
2556.62	872
2558.42	898
2560.23	842
2562.03	858
2563.83	864
2565.63	836
2567.43	822
2569.23	844
2571.03	836
2572.83	840
2574.63	830
2576.43	820
2578.22	834
2580.02	804
2581.82	818
2583.61	802
2585.41	798
2587.2	796
2589	816
2590.79	820
2592.58	786
2594.38	786
2596.17	760
2597.96	794
2599.75	764
2601.54	792
2603.33	792
2605.12	758
2606.91	740
2608.7	746
2610.49	770
2612.27	768
2614.06	732
2615.85	708
2617.63	748
2619.42	724
2621.2	720
2622.99	720
2624.77	740
2626.55	712
2628.34	710
2630.12	696
2631.9	712
2633.68	698
2635.46	718
2637.24	704
2639.02	672
2640.8	668
2642.58	670
2644.36	666
2646.14	668
2647.91	674
2649.69	668
2651.46	644
2653.24	666
2655.01	652
2656.79	656
2658.56	630
2660.34	660
2662.11	628
2663.88	638
2665.65	632
2667.42	616
2669.2	620
2670.96	654
2672.73	616
2674.5	640
2676.27	622
2678.04	624
2679.81	620
2681.58	624
2683.34	594
2685.11	600
2686.87	594
2688.64	600
2690.4	594
2692.17	604
2693.93	614
2695.69	592
2697.46	566
2699.22	578
2700.98	598
2702.74	578
2704.5	582
2706.26	574
2708.02	538
2709.78	576
2711.54	546
2713.3	516
2715.05	542
2716.81	562
2718.57	528
2720.32	528
2722.08	550
2723.83	522
2725.59	528
2727.34	512
2729.09	550
2730.85	512
2732.6	518
2734.35	508
2736.1	476
2737.85	510
2739.6	500
2741.35	504
2743.1	496
2744.85	490
2746.6	490
2748.35	490
2750.09	472
2751.84	488
2753.59	494
2755.33	490
2757.08	472
2758.82	460
2760.57	450
2762.31	480
2764.05	458
2765.79	470
2767.54	466
2769.28	464
2771.02	468
2772.76	428
2774.5	470
2776.24	444
2777.98	430
2779.72	402
2781.46	412
2783.19	436
2784.93	426
2786.67	418
2788.4	424
2790.14	434
2791.87	424
2793.61	418
2795.34	388
2797.07	430
2798.81	400
2800.54	398
2802.27	402
2804	382
2805.74	394
2807.47	394
2809.2	388
2810.93	356
2812.65	386
2814.38	378
2816.11	382
2817.84	382
2819.56	362
2821.29	384
2823.02	362
2824.74	390
2826.47	394
2828.19	354
2829.92	348
2831.64	384
2833.36	340
2835.09	368
2836.81	336
2838.53	352
2840.25	332
2841.97	346
2843.69	324
2845.41	350
2847.13	318
2848.85	346
2850.57	332
2852.28	322
2854	328
2855.72	316
2857.43	312
2859.15	352
2860.86	322
2862.58	320
2864.29	318
2866.01	304
2867.72	320
2869.43	312
2871.14	286
2872.86	308
2874.57	316
2876.28	298
2877.99	292
2879.7	300
2881.41	294
2883.11	292
2884.82	292
2886.53	290
2888.24	286
2889.94	294
2891.65	286
2893.36	282
2895.06	272
2896.77	276
2898.47	268
2900.17	280
2901.88	272
2903.58	264
2905.28	274
2906.98	260
2908.69	254
2910.39	268
2912.09	256
2913.79	276
2915.49	274
2917.19	268
2918.88	278
2920.58	260
2922.28	248
2923.98	284
2925.67	260
2927.37	234
2929.06	246
2930.76	250
2932.45	256
2934.15	248
2935.84	228
2937.53	252
2939.23	250
2940.92	234
2942.61	256
2944.3	266
2945.99	226
2947.68	240
2949.37	216
2951.06	244
2952.75	244
2954.44	234
2956.12	246
2957.81	222
2959.5	232
2961.18	220
2962.87	210
2964.56	212
2966.24	226
2967.92	214
2969.61	222
2971.29	220
2972.97	202
2974.66	216
2976.34	230
2978.02	202
2979.7	208
2981.38	216
2983.06	206
2984.74	198
2986.42	204
2988.1	196
2989.78	202
2991.45	220
2993.13	210
2994.81	190
2996.48	212
2998.16	218
2999.83	204