File: muestras/papalo/leaf_100x_06.txt
#Acq. time (s)=	10
#Accumulations=	1
#Range (cm-¹)=	200...3000
#Windows=	3
#Autofocus=	Off
#AutoExposure=	Off
#Spike filter=	Off
#Delay time (s)=	0
#Binning=	1
#Readout mode=	Signal
#DeNoise=	Off
#ICS correction=	Off
#Dark correction=	Off
#Inst. Process=	Off
#Instrument=	LabRAM HR Evol
#Detector=	Syncerity OE
#Objective=	x100_VIS
#Grating=	600 (500nm)
#ND Filter=	0.1%
#Laser=	633nm_Edge
#Hole=	100.021
#Range=	Visible
#Project=	Omar
#Sample=	03-07-23
#Site=	papal
#Title=	leaf_100x
#Remark=
#Date=	03.07.2023 17:15
#Acquired=	03.07.2023 17:15:20
201.713	260
204.247	248
206.778	266
209.311	258
211.84	304
214.371	280
216.899	274
219.428	294
221.955	288
224.482	314
227.007	284
229.531	306
232.055	298
234.579	312
237.1	298
239.621	310
242.141	330
244.661	332
247.179	308
249.698	360
252.215	340
254.731	352
257.246	360
259.761	368
262.273	362
264.786	376
267.298	370
269.809	386
272.319	366
274.828	378
277.336	380
279.844	416
282.351	410
284.855	404
287.361	404
289.866	420
292.368	428
294.871	432
297.372	424
299.873	436
302.372	444
304.872	476
307.37	470
309.866	478
312.364	480
314.859	480
317.353	474
319.848	502
322.341	514
324.833	504
327.324	496
329.814	504
332.304	524
334.792	570
337.28	544
339.767	566
342.254	558
344.739	592
347.224	578
349.708	570
352.191	588
354.673	594
357.155	598
359.634	618
362.114	604
364.593	594
367.07	650
369.548	656
372.024	622
374.499	652
376.974	656
379.447	694
381.92	686
384.392	714
386.864	656
389.333	718
391.802	702
394.272	754
396.739	722
399.206	760
401.673	760
404.138	754
406.602	800
409.066	810
411.528	828
413.99	822
416.451	824
418.911	872
421.371	828
423.83	822
426.288	856
428.745	866
431.201	894
433.657	882
436.111	908
438.565	922
441.017	922
443.469	932
445.921	956
448.37	966
450.821	968
453.27	982
455.717	962
458.165	1000
460.61	1022
463.056	1018
465.5	1044
467.945	1060
470.387	1046
472.829	1064
475.271	1088
477.711	1090
480.15	1112
482.589	1128
485.027	1100
487.465	1120
489.901	1142
492.337	1204
494.771	1182
497.205	1182
499.638	1190
502.07	1198
504.502	1200
506.933	1242
509.363	1228
511.792	1256
514.219	1288
516.647	1294
519.073	1326
521.5	1266
523.924	1292
526.348	1300
528.772	1344
531.194	1374
533.616	1354
536.036	1392
538.457	1384
540.875	1366
543.294	1386
545.712	1436
548.128	1466
550.545	1494
552.959	1480
555.373	1478
557.788	1506
560.2	1530
562.612	1510
565.023	1554
567.433	1566
569.843	1578
572.251	1620
574.659	1648
577.066	1626
579.472	1672
581.878	1624
584.283	1772
586.687	1760
589.09	1702
591.493	1788
593.893	1790
596.294	1822
598.694	1852
601.093	1834
603.491	1880
605.889	1874
608.285	1892
610.682	1960
613.076	1976
615.471	1994
617.864	2022
620.256	2086
622.648	2070
625.039	2134
627.429	2140
629.819	2154
632.208	2218
634.595	2170
636.982	2272
639.369	2248
641.755	2262
644.139	2360
646.523	2280
648.906	2412
651.288	2388
653.67	2480
656.051	2490
658.429	2558
660.808	2506
663.187	2516
665.565	2574
667.942	2556
670.317	2638
672.692	2668
675.067	2714
677.44	2736
679.813	2794
682.184	2748
684.556	2802
686.926	2902
689.296	2904
691.664	2940
694.033	2944
696.4	2984
698.766	3056
701.133	3094
703.497	3042
705.861	3156
708.224	3250
710.586	3206
712.949	3250
715.31	3226
717.67	3368
720.029	3458
722.388	3412
724.746	3452
727.103	3504
729.458	3600
731.814	3604
734.168	3668
736.523	3628
738.876	3732
741.227	3764
743.579	3874
745.931	3844
748.28	3924
750.629	3950
752.977	4002
755.325	4110
757.672	4090
760.018	4192
762.363	4174
764.708	4256
767.052	4298
769.394	4420
771.737	4504
774.078	4488
776.419	4496
778.758	4598
781.097	4658
783.435	4612
785.773	4790
788.11	4818
790.446	4894
792.781	4930
795.115	4972
797.449	5090
799.782	5078
802.115	5286
804.446	5228
806.777	5368
809.106	5450
811.435	5498
813.764	5638
816.091	5658
818.418	5834
820.743	5734
823.069	5922
825.393	5952
827.717	6034
830.039	6106
832.362	6186
834.683	6238
837.003	6386
839.324	6434
841.643	6482
843.961	6658
846.278	6696
848.594	6832
850.91	6898
853.227	6914
855.541	7036
857.855	7128
860.168	7214
862.48	7224
864.79	7332
867.101	7458
869.411	7504
871.721	7668
874.029	7734
876.336	7758
878.643	7822
880.95	7930
883.254	8102
885.559	8158
887.862	8256
890.166	8298
892.467	8244
894.77	8408
897.07	8530
899.371	8556
901.669	8688
903.968	8842
906.266	8840
908.563	9080
910.859	9120
913.154	9138
915.449	9364
917.742	9446
920.036	9424
922.329	9694
924.621	9596
926.911	9750
929.201	10034
931.49	10224
933.779	10250
936.068	10252
938.355	10376
940.64	10454
942.926	10634
945.212	10700
947.495	10842
949.779	10934
952.062	11182
954.344	11352
956.625	11294
958.905	11592
961.184	11744
963.464	11766
965.742	12026
968.02	12114
970.296	12118
972.572	12366
974.847	12380
977.121	12548
979.396	12698
981.669	12870
983.941	12994
986.212	13100
988.483	13042
990.753	13392
993.022	13322
995.29	13512
997.558	13508
999.825	13888
1002.09	14010
1004.36	14078
1006.62	14144
1008.89	14390
1011.15	14446
1013.41	14524
1015.67	14828
1017.93	14782
1020.19	15148
1022.45	15364
1024.71	15366
1026.97	15654
1029.23	15770
1031.49	15968
1033.74	16224
1036	16314
1038.25	16530
1040.5	16686
1042.76	16850
1045.01	16974
1047.26	17086
1049.51	17282
1051.76	17298
1054.01	17648
1056.26	17828
1058.51	17918
1060.75	17998
1063	18344
1065.25	18442
1067.49	18734
1069.73	18826
1071.98	18906
1074.22	18974
1076.46	19128
1078.7	19292
1080.94	19480
1083.18	19684
1085.42	19530
1087.66	19712
1089.9	19880
1092.14	19982
1094.37	20066
1096.61	20266
1098.84	20222
1101.08	20488
1103.31	20622
1105.54	20600
1107.77	20818
1110	21100
1112.23	21016
1114.46	21290
1116.69	21294
1118.92	21268
1121.15	21572
1123.37	21762
1125.6	21690
1127.83	21854
1130.05	22032
1132.27	22308
1134.5	22486
1136.72	22436
1138.94	22712
1141.16	22758
1143.38	22888
1145.6	23030
1147.82	23060
1150.04	23138
1152.26	23348
1154.47	23524
1156.69	23522
1158.9	23490
1161.12	23700
1163.33	23614
1165.54	23714
1167.76	23956
1169.97	23774
1172.18	24046
1174.39	23808
1176.6	24038
1178.81	24012
1181.02	23814
1183.22	23914
1185.43	24038
1187.63	24058
1189.84	23880
1192.04	23592
1194.25	23902
1196.45	23698
1198.65	23674
1200.85	23718
1203.05	23640
1205.25	23662
1207.45	23456
1209.65	23292
1211.85	23200
1214.05	23212
1216.24	23022
1218.44	23036
1220.64	22932
1222.83	22848
1225.02	22786
1227.22	22582
1229.41	22448
1231.6	22404
1233.79	22238
1235.98	22342
1238.17	22180
1240.36	21934
1242.55	21962
1244.73	21874
1246.92	21816
1249.11	21628
1251.29	21652
1253.48	21546
1255.66	21362
1257.84	21368
1260.03	21172
1262.21	20954
1264.39	21062
1266.57	20732
1268.75	20688
1270.93	20560
1273.11	20456
1275.28	20360
1277.46	20118
1279.64	20012
1281.81	19968
1283.98	19685.8
1286.16	19495.7
1288.33	19291
1290.5	19117.8
1292.68	18827.5
1294.85	18477.1
1297.02	18428.9
1299.19	18225.8
1301.36	17896.6
1303.53	17705.2
1305.69	17763.6
1307.86	17354.6
1310.03	16981.8
1312.19	16801.5
1314.36	16729.4
1316.52	16452.2
1318.68	16219.4
1320.85	16011.3
1323.01	15778.4
1325.17	15614.5
1327.33	15439.5
1329.49	15150.8
1331.65	15018.1
1333.81	14795.8
1335.97	14686.5
1338.12	14474.1
1340.28	14282
1342.44	14072.2
1344.59	13911.9
1346.75	13785.3
1348.9	13557.1
1351.05	13345.6
1353.2	13241.8
1355.36	12960.5
1357.51	12920.5
1359.66	12766.8
1361.81	12764.6
1363.96	12449.3
1366.1	12260.9
1368.25	12076.6
1370.4	11889.4
1372.54	11793.5
1374.69	11601.9
1376.83	11322.3
1378.98	11283.4
1381.12	11108.6
1383.26	11050.2
1385.41	10851.8
1387.55	10889.7
1389.69	10653.5
1391.83	10546.1
1393.02	10324
1395.17	10472
1397.32	10340
1399.47	10256
1401.62	10150
1403.77	10008
1405.91	9910
1408.06	9740
1410.2	9738
1412.35	9690
1414.49	9748
1416.63	9524
1418.78	9522
1420.92	9462
1423.06	9358
1425.2	9344
1427.34	9166
1429.48	9154
1431.61	9076
1433.75	8970
1435.89	8880
1438.02	8844
1440.16	8934
1442.3	8706
1444.43	8548
1446.56	8648
1448.7	8676
1450.83	8588
1452.96	8468
1455.09	8432
1457.22	8312
1459.35	8366
1461.48	8268
1463.61	8334
1465.73	8298
1467.86	8254
1469.98	8172
1472.11	8058
1474.24	7964
1476.36	8006
1478.48	7902
1480.6	7882
1482.73	7856
1484.85	7716
1486.97	7716
1489.09	7666
1491.21	7712
1493.33	7610
1495.44	7524
1497.56	7648
1499.68	7478
1501.79	7448
1503.91	7272
1506.02	7332
1508.14	7394
1510.25	7342
1512.36	7230
1514.48	7178
1516.59	7220
1518.7	7030
1520.81	6988
1522.92	6958
1525.02	6950
1527.13	7012
1529.24	6914
1531.35	6804
1533.45	6858
1535.56	6690
1537.66	6708
1539.77	6686
1541.87	6634
1543.97	6588
1546.08	6504
1548.18	6590
1550.28	6502
1552.38	6428
1554.48	6364
1556.57	6322
1558.67	6416
1560.77	6364
1562.87	6358
1564.96	6222
1567.06	6198
1569.15	6194
1571.25	6162
1573.34	6134
1575.43	6124
1577.53	6026
1579.62	6072
1581.71	6002
1583.8	5976
1585.89	6020
1587.98	6018
1590.06	5936
1592.15	5918
1594.24	5934
1596.33	5906
1598.41	5942
1600.5	5784
1602.58	5886
1604.66	5820
1606.75	5790
1608.83	5780
1610.91	5900
1612.99	5816
1615.07	5698
1617.15	5722
1619.23	5696
1621.31	5708
1623.39	5642
1625.46	5678
1627.54	5792
1629.62	5584
1631.69	5680
1633.77	5500
1635.84	5590
1637.91	5578
1639.99	5544
1642.06	5434
1644.13	5554
1646.2	5446
1648.27	5440
1650.34	5426
1652.41	5552
1654.47	5458
1656.54	5418
1658.61	5358
1660.67	5444
1662.74	5342
1664.81	5314
1666.87	5306
1668.93	5314
1671	5270
1673.06	5252
1675.12	5402
1677.18	5216
1679.24	5200
1681.3	5222
1683.36	5072
1685.42	5158
1687.47	5068
1689.53	5102
1691.59	5116
1693.64	5100
1695.7	5044
1697.75	5040
1699.81	5086
1701.86	4998
1703.91	4994
1705.97	5028
1708.02	4994
1710.07	5018
1712.12	4908
1714.17	4916
1716.22	5030
1718.26	5010
1720.31	4940
1722.36	4904
1724.4	4908
1726.45	4932
1728.49	4886
1730.54	4838
1732.58	4958
1734.63	4872
1736.67	4842
1738.71	4786
1740.75	4828
1742.79	4816
1744.83	4894
1746.87	4850
1748.91	4840
1750.95	4794
1752.98	4814
1755.02	4796
1757.06	4776
1759.09	4822
1761.13	4834
1763.16	4798
1765.19	4818
1767.23	4794
1769.26	4814
1771.29	4786
1773.32	4784
1775.35	4754
1777.38	4732
1779.41	4776
1781.44	4742
1783.47	4664
1785.49	4724
1787.52	4782
1789.55	4818
1791.57	4678
1793.6	4726
1795.62	4672
1797.64	4782
1799.67	4744
1801.69	4746
1803.71	4750
1805.73	4662
1807.75	4746
1809.77	4654
1811.79	4708
1813.81	4730
1815.83	4758
1817.84	4602
1819.86	4682
1821.88	4688
1823.89	4558
1825.91	4686
1827.92	4650
1829.93	4546
1831.95	4610
1833.96	4602
1835.97	4656
1837.98	4636
1839.99	4612
1842	4532
1844.01	4600
1846.02	4526
1848.03	4498
1850.03	4492
1852.04	4538
1854.05	4558
1856.05	4494
1858.06	4566
1860.06	4512
1862.06	4544
1864.07	4536
1866.07	4478
1868.07	4500
1870.07	4424
1872.07	4528
1874.07	4474
1876.07	4530
1878.07	4526
1880.07	4466
1882.07	4502
1884.06	4466
1886.06	4516
1888.05	4518
1890.05	4486
1892.04	4486
1894.04	4444
1896.03	4460
1898.02	4538
1900.01	4542
1902	4616
1903.99	4486
1905.98	4532
1907.97	4494
1909.96	4446
1911.95	4530
1913.94	4470
1915.93	4508
1917.91	4476
1919.9	4358
1921.88	4526
1923.87	4434
1925.85	4416
1927.83	4426
1929.82	4440
1931.8	4364
1933.78	4404
1935.76	4406
1937.74	4360
1939.72	4454
1941.7	4456
1943.68	4388
1945.65	4340
1947.63	4400
1949.61	4412
1951.58	4388
1953.56	4434
1955.53	4324
1957.51	4374
1959.48	4384
1961.45	4322
1963.43	4402
1965.4	4358
1967.37	4270
1969.34	4286
1971.31	4318
1973.28	4342
1975.25	4356
1977.22	4374
1979.18	4310
1981.15	4292
1983.12	4354
1985.08	4302
1987.05	4284
1989.01	4240
1990.97	4318
1992.94	4248
1994.9	4232
1996.86	4274
1998.82	4306
2000.78	4312
2002.74	4256
2004.7	4266
2006.66	4228
2008.62	4168
2010.58	4236
2012.54	4152
2014.49	4236
2016.45	4252
2018.4	4210
2020.36	4280
2022.31	4220
2024.27	4192
2026.22	4232
2028.17	4191
2030.12	4188
2032.07	4166
2034.03	4234
2035.98	4138
2037.93	4176
2039.87	4170
2041.82	4190
2043.77	4154
2045.72	4124
2047.66	4128
2049.61	4130
2051.55	4130
2053.5	4214
2055.44	4106
2057.39	4144
2059.33	4180
2061.27	4144
2063.21	4106
2065.15	4116
2067.09	4182
2069.03	4114
2070.97	4134
2072.91	4116
2074.85	4112
2076.79	4166
2078.73	4046
2080.66	4174
2082.6	4110
2084.53	4136
2086.47	4044
2088.4	4180
2090.33	4188
2092.27	4010
2094.2	4050
2096.13	4018
2098.06	4028
2099.99	4074
2101.92	4138
2103.85	4072
2105.78	4060
2107.71	4022
2109.64	4068
2111.56	4032
2113.49	3984
2115.41	4058
2117.34	4046
2119.26	4046
2121.19	4012
2123.11	4072
2125.03	4078
2126.96	4100
2128.88	4054
2130.8	4078
2132.72	4064
2134.64	3926
2136.56	4014
2138.48	3926
2140.4	4016
2142.31	4030
2144.23	3952
2146.15	3964
2148.06	3982
2149.98	3968
2151.89	3976
2153.81	3998
2155.72	3914
2157.63	3938
2159.55	3916
2161.46	3924
2163.37	3984
2165.28	3920
2167.19	3930
2169.1	3868
2171.01	3902
2172.91	3894
2174.82	3974
2176.73	3872
2178.64	3898
2180.54	3828
2182.45	3880
2184.35	3804
2186.26	3952
2188.16	3828
2190.06	3898
2191.96	3838
2193.87	3826
2195.77	3878
2197.67	3830
2199.57	3758
2201.47	3756
2203.37	3758
2205.27	3820
2207.16	3780
2209.06	3770
2210.96	3834
2212.85	3816
2214.75	3788
2216.64	3752
2218.54	3726
2220.43	3772
2222.33	3756
2224.22	3697.88
2226.11	3731.95
2228	3695.57
2229.89	3745.11
2231.78	3756.08
2233.67	3628.59
2235.56	3653.83
2237.45	3699.13
2239.34	3701.84
2241.23	3651.12
2243.11	3636.24
2245	3643.12
2246.89	3543.53
2248.77	3613.56
2250.66	3571.2
2252.54	3557.57
2254.42	3618.57
2256.31	3549.15
2258.19	3539.22
2260.07	3530.62
2261.95	3459.95
2263.83	3513.78
2265.71	3532.04
2267.59	3460.87
2269.47	3430.19
2271.35	3440.26
2273.23	3485.7
2275.1	3341.14
2276.98	3337.36
2278.86	3395.81
2280.73	3394.26
2282.61	3323.92
2284.48	3290.69
2286.36	3353.72
2288.23	3288.24
2290.1	3251.71
2291.98	3267.33
2293.85	3199.78
2295.72	3232.32
2297.59	3208.81
2299.46	3218.5
2301.33	3160.03
2303.2	3215.34
2305.06	3132.29
2306.93	3113.03
2308.8	3136
2310.67	3123.2
2312.53	3103.36
2314.4	3079.18
2316.26	3082.43
2317.62	3090
2319.5	3122
2321.37	3088
2323.24	3028
2325.12	3006
2326.99	3052
2328.86	3010
2330.73	3060
2332.6	2948
2334.47	3028
2336.34	3050
2338.2	2934
2340.07	2982
2341.94	2970
2343.81	2930
2345.67	2984
2347.54	2940
2349.4	2970
2351.27	2906
2353.13	2934
2354.99	2982
2356.86	2932
2358.72	2978
2360.58	2908
2362.44	2934
2364.3	2878
2366.16	2906
2368.02	2856
2369.88	2888
2371.74	2910
2373.6	2852
2375.45	2876
2377.31	2844
2379.17	2764
2381.02	2828
2382.88	2798
2384.73	2772
2386.58	2736
2388.44	2760
2390.29	2700
2392.14	2768
2393.99	2688
2395.85	2686
2397.7	2728
2399.55	2640
2401.4	2660
2403.25	2680
2405.09	2690
2406.94	2692
2408.79	2666
2410.63	2634
2412.48	2618
2414.33	2690
2416.17	2644
2418.02	2616
2419.86	2578
2421.7	2588
2423.55	2564
2425.39	2590
2427.23	2504
2429.07	2450
2430.91	2520
2432.75	2574
2434.59	2468
2436.43	2488
2438.27	2520
2440.11	2452
2441.95	2428
2443.78	2490
2445.62	2442
2447.46	2392
2449.29	2360
2451.13	2426
2452.96	2386
2454.79	2416
2456.63	2396
2458.46	2376
2460.29	2394
2462.12	2366
2463.95	2376
2465.78	2342
2467.61	2240
2469.44	2300
2471.27	2286
2473.1	2272
2474.93	2196
2476.76	2198
2478.58	2234
2480.41	2234
2482.23	2128
2484.06	2238
2485.88	2200
2487.71	2182
2489.53	2198
2491.35	2184
2493.18	2238
2495	2154
2496.82	2102
2498.64	2088
2500.46	2054
2502.28	2096
2504.1	2066
2505.92	2042
2507.74	2062
2509.55	2034
2511.37	2060
2513.19	2018
2515	2002
2516.82	2046
2518.63	1976
2520.45	2062
2522.26	1980
2524.07	1962
2525.89	1954
2527.7	1938
2529.51	1914
2531.32	1934
2533.13	1948
2534.94	1934
2536.75	1892
2538.56	1886
2540.37	1914
2542.18	1920
2543.98	1900
2545.79	1830
2547.6	1894
2549.4	1836
2551.21	1878
2553.01	1862
2554.82	1800
2556.62	1806
2558.42	1794
2560.23	1784
2562.03	1768
2563.83	1752
2565.63	1788
2567.43	1770
2569.23	1754
2571.03	1752
2572.83	1738
2574.63	1700
2576.43	1718
2578.22	1676
2580.02	1774
2581.82	1700
2583.61	1676
2585.41	1668
2587.2	1688
2589	1640
2590.79	1630
2592.58	1606
2594.38	1634
2596.17	1600
2597.96	1610
2599.75	1608
2601.54	1558
2603.33	1598
2605.12	1554
2606.91	1588
2608.7	1522
2610.49	1570
2612.27	1530
2614.06	1548
2615.85	1504
2617.63	1522
2619.42	1506
2621.2	1506
2622.99	1514
2624.77	1466
2626.55	1496
2628.34	1412
2630.12	1472
2631.9	1462
2633.68	1492
2635.46	1438
2637.24	1430
2639.02	1400
2640.8	1402
2642.58	1408
2644.36	1368
2646.14	1384
2647.91	1412
2649.69	1390
2651.46	1346
2653.24	1344
2655.01	1314
2656.79	1328
2658.56	1342
2660.34	1336
2662.11	1298
2663.88	1302
2665.65	1330
2667.42	1320
2669.2	1318
2670.96	1300
2672.73	1306
2674.5	1304
2676.27	1220
2678.04	1298
2679.81	1176
2681.58	1268
2683.34	1238
2685.11	1242
2686.87	1240
2688.64	1250
2690.4	1198
2692.17	1248
2693.93	1188
2695.69	1186
2697.46	1194
2699.22	1224
2700.98	1172
2702.74	1162
2704.5	1122
2706.26	1174
2708.02	1168
2709.78	1114
2711.54	1130
2713.3	1104
2715.05	1112
2716.81	1100
2718.57	1118
2720.32	1102
2722.08	1096
2723.83	1126
2725.59	1058
2727.34	1046
2729.09	1058
2730.85	1074
2732.6	1038
2734.35	1060
2736.1	1028
2737.85	1004
2739.6	1016
2741.35	1026
2743.1	1026
2744.85	1000
2746.6	1022
2748.35	972
2750.09	996
2751.84	978
2753.59	984
2755.33	958
2757.08	952
2758.82	902
2760.57	946
2762.31	966
2764.05	918
2765.79	948
2767.54	916
2769.28	926
2771.02	912
2772.76	906
2774.5	938
2776.24	874
2777.98	888
2779.72	894
2781.46	888
2783.19	880
2784.93	896
2786.67	860
2788.4	862
2790.14	844
2791.87	844
2793.61	868
2795.34	798
2797.07	818
2798.81	824
2800.54	840
2802.27	788
2804	792
2805.74	796
2807.47	810
2809.2	776
2810.93	770
2812.65	776
2814.38	774
2816.11	774
2817.84	762
2819.56	712
2821.29	730
2823.02	770
2824.74	752
2826.47	730
2828.19	722
2829.92	720
2831.64	710
2833.36	724
2835.09	710
2836.81	704
2838.53	694
2840.25	694
2841.97	698
2843.69	692
2845.41	690
2847.13	646
2848.85	630
2850.57	648
2852.28	662
2854	650
2855.72	662
2857.43	638
2859.15	654
2860.86	634
2862.58	640
2864.29	636
2866.01	622
2867.72	620
2869.43	602
2871.14	644
2872.86	622
2874.57	608
2876.28	632
2877.99	614
2879.7	604
2881.41	582
2883.11	588
2884.82	578
2886.53	570
2888.24	588
2889.94	530
2891.65	602
2893.36	546
2895.06	528
2896.77	550
2898.47	572
2900.17	560
2901.88	522
2903.58	526
2905.28	534
2906.98	578
2908.69	512
2910.39	538
2912.09	526
2913.79	554
2915.49	524
2917.19	510
2918.88	524
2920.58	522
2922.28	506
2923.98	512
2925.67	484
2927.37	514
2929.06	512
2930.76	466
2932.45	502
2934.15	498
2935.84	474
2937.53	500
2939.23	486
2940.92	480
2942.61	472
2944.3	464
2945.99	460
2947.68	460
2949.37	466
2951.06	450
2952.75	464
2954.44	460
2956.12	492
2957.81	472
2959.5	452
2961.18	450
2962.87	446
2964.56	440
2966.24	434
2967.92	444
2969.61	434
2971.29	434
2972.97	434
2974.66	422
2976.34	438
2978.02	410
2979.7	420
2981.38	432
2983.06	390
2984.74	430
2986.42	432
2988.1	402
2989.78	416
2991.45	374
2993.13	402
2994.81	402
2996.48	398
2998.16	368
2999.83	364