File: muestras/papalo/leaf_08.txt
#Acq. time (s)=	10
#Accumulations=	1
#Range (cm-¹)=	200...3000
#Windows=	3
#Autofocus=	Off
#AutoExposure=	Off
#Spike filter=	Off
#Delay time (s)=	0
#Binning=	1
#Readout mode=	Signal
#DeNoise=	Off
#ICS correction=	Off
#Dark correction=	Off
#Inst. Process=	Off
#Instrument=	LabRAM HR Evol
#Detector=	Syncerity OE
#Objective=	x100_VIS
#Grating=	600 (500nm)
#ND Filter=	0.01%
#Laser=	633nm_Edge
#Hole=	34.9738
#Range=	Visible
#Project=	Omar
#Sample=	03-07-23
#Site=	papal
#Title=	leaf
#Remark=
#Date=	03.07.2023 16:59
#Acquired=	03.07.2023 16:59:10
201.713	40
204.247	42
206.778	38
209.311	36
211.84	38
214.371	38
216.899	40
219.428	50
221.955	42
224.482	34
227.007	36
229.531	30
232.055	42
234.579	44
237.1	40
239.621	42
242.141	30
244.661	42
247.179	44
249.698	34
252.215	34
254.731	46
257.246	38
259.761	32
262.273	42
264.786	44
267.298	40
269.809	44
272.319	48
274.828	40
277.336	50
279.844	38
282.351	46
284.855	44
287.361	38
289.866	46
292.368	44
294.871	46
297.372	46
299.873	40
302.372	46
304.872	44
307.37	54
309.866	46
312.364	42
314.859	50
317.353	40
319.848	46
322.341	46
324.833	36
327.324	52
329.814	48
332.304	46
334.792	52
337.28	44
339.767	44
342.254	50
344.739	54
347.224	54
349.708	50
352.191	60
354.673	40
357.155	54
359.634	60
362.114	50
364.593	48
367.07	46
369.548	50
372.024	52
374.499	52
376.974	56
379.447	54
381.92	48
384.392	54
386.864	50
389.333	60
391.802	56
394.272	70
396.739	58
399.206	58
401.673	58
404.138	58
406.602	56
409.066	62
411.528	56
413.99	56
416.451	60
418.911	56
421.371	64
423.83	58
426.288	52
428.745	64
431.201	64
433.657	68
436.111	76
438.565	70
441.017	62
443.469	62
445.921	62
448.37	74
450.821	74
453.27	66
455.717	72
458.165	62
460.61	62
463.056	68
465.5	66
467.945	70
470.387	66
472.829	74
475.271	72
477.711	68
480.15	72
482.589	70
485.027	70
487.465	72
489.901	68
492.337	70
494.771	80
497.205	78
499.638	76
502.07	84
504.502	84
506.933	78
509.363	76
511.792	94
514.219	82
516.647	76
519.073	86
521.5	80
523.924	82
526.348	92
528.772	82
531.194	74
533.616	78
536.036	80
538.457	82
540.875	88
543.294	88
545.712	84
548.128	94
550.545	88
552.959	82
555.373	98
557.788	90
560.2	86
562.612	84
565.023	92
567.433	92
569.843	84
572.251	92
574.659	90
577.066	92
579.472	106
581.878	88
584.283	92
586.687	88
589.09	92
591.493	96
593.893	96
596.294	106
598.694	102
601.093	100
603.491	110
605.889	102
608.285	106
610.682	122
613.076	122
615.471	122
617.864	114
620.256	106
622.648	116
625.039	116
627.429	118
629.819	116
632.208	106
634.595	132
636.982	120
639.369	118
641.755	124
644.139	130
646.523	118
648.906	136
651.288	138
653.67	124
656.051	130
658.429	122
660.808	122
663.187	128
665.565	124
667.942	144
670.317	136
672.692	140
675.067	136
677.44	132
679.813	134
682.184	144
684.556	150
686.926	156
689.296	160
691.664	144
694.033	162
696.4	148
698.766	154
701.133	152
703.497	174
705.861	158
708.224	172
710.586	146
712.949	176
715.31	166
717.67	164
720.029	160
722.388	182
724.746	170
727.103	168
729.458	180
731.814	190
734.168	180
736.523	192
738.876	192
741.227	192
743.579	182
745.931	172
748.28	184
750.629	194
752.977	204
755.325	202
757.672	188
760.018	188
762.363	214
764.708	208
767.052	194
769.394	222
771.737	194
774.078	210
776.419	232
778.758	220
781.097	228
783.435	218
785.773	230
788.11	232
790.446	244
792.781	230
795.115	228
797.449	244
799.782	242
802.115	240
804.446	244
806.777	248
809.106	250
811.435	252
813.764	238
816.091	252
818.418	242
820.743	278
823.069	242
825.393	266
827.717	278
830.039	252
832.362	274
834.683	302
837.003	274
839.324	296
841.643	278
843.961	302
846.278	294
848.594	276
850.91	308
853.227	304
855.541	308
857.855	316
860.168	320
862.48	326
864.79	340
867.101	320
869.411	336
871.721	364
874.029	344
876.336	340
878.643	336
880.95	346
883.254	354
885.559	340
887.862	364
890.166	368
892.467	378
894.77	386
897.07	390
899.371	400
901.669	380
903.968	380
906.266	390
908.563	370
910.859	416
913.154	414
915.449	404
917.742	432
920.036	426
922.329	444
924.621	434
926.911	446
929.201	420
931.49	440
933.779	436
936.068	482
938.355	450
940.64	486
942.926	454
945.212	480
947.495	486
949.779	480
952.062	508
954.344	494
956.625	482
958.905	492
961.184	518
963.464	542
965.742	518
968.02	530
970.296	544
972.572	544
974.847	522
977.121	524
979.396	550
981.669	572
983.941	602
986.212	558
988.483	584
990.753	566
993.022	572
995.29	586
997.558	588
999.825	588
1002.09	590
1004.36	602
1006.62	630
1008.89	612
1011.15	622
1013.41	648
1015.67	628
1017.93	674
1020.19	656
1022.45	638
1024.71	666
1026.97	688
1029.23	730
1031.49	704
1033.74	680
1036	702
1038.25	692
1040.5	724
1042.76	762
1045.01	718
1047.26	762
1049.51	772
1051.76	746
1054.01	742
1056.26	766
1058.51	778
1060.75	784
1063	780
1065.25	782
1067.49	770
1069.73	834
1071.98	816
1074.22	812
1076.46	828
1078.7	804
1080.94	832
1083.18	808
1085.42	878
1087.66	840
1089.9	866
1092.14	852
1094.37	854
1096.61	878
1098.84	862
1101.08	820
1103.31	890
1105.54	902
1107.77	910
1110	902
1112.23	924
1114.46	910
1116.69	964
1118.92	916
1121.15	876
1123.37	914
1125.6	954
1127.83	946
1130.05	918
1132.27	924
1134.5	986
1136.72	928
1138.94	944
1141.16	970
1143.38	954
1145.6	984
1147.82	954
1150.04	972
1152.26	968
1154.47	970
1156.69	982
1158.9	976
1161.12	990
1163.33	1016
1165.54	1016
1167.76	1030
1169.97	950
1172.18	1006
1174.39	990
1176.6	1006
1178.81	1032
1181.02	1010
1183.22	1004
1185.43	1032
1187.63	1000
1189.84	980
1192.04	986
1194.25	1024
1196.45	960
1198.65	996
1200.85	1012
1203.05	978
1205.25	1018
1207.45	976
1209.65	986
1211.85	928
1214.05	974
1216.24	942
1218.44	962
1220.64	970
1222.83	974
1225.02	956
1227.22	982
1229.41	932
1231.6	918
1233.79	922
1235.98	944
1238.17	932
1240.36	910
1242.55	904
1244.73	908
1246.92	894
1249.11	914
1251.29	902
1253.48	916
1255.66	904
1257.84	886
1260.03	924
1262.21	886
1264.39	868
1266.57	874
1268.75	850
1270.93	856
1273.11	880
1275.28	824
1277.46	834
1279.64	834
1281.81	848
1283.98	821.771
1286.16	820.16
1288.33	814.849
1290.5	810.436
1292.68	790.263
1294.85	774.299
1297.02	760.047
1299.19	764.015
1301.36	772.956
1303.53	747.779
1305.69	745.895
1307.86	723.225
1310.03	734.845
1312.19	724.801
1314.36	734.727
1316.52	721.26
1318.68	722.479
1320.85	720.887
1323.01	696.433
1325.17	690.054
1327.33	677.966
1329.49	678.821
1331.65	657.973
1333.81	643.87
1335.97	638.127
1338.12	641.108
1340.28	632.005
1342.44	633.941
1344.59	636.644
1346.75	640.21
1348.9	622.643
1351.05	610.913
1353.2	598.883
1355.36	604.206
1357.51	591.418
1359.66	592.857
1361.81	592.142
1363.96	548.312
1366.1	557.532
1368.25	589.763
1370.4	560.668
1372.54	565.927
1374.69	573.687
1376.83	570.816
1378.98	550.276
1381.12	533.832
1383.26	511.827
1385.41	528.412
1387.55	515.242
1389.69	529.947
1391.83	506.006
1393.02	510
1395.17	540
1397.32	514
1399.47	494
1401.62	490
1403.77	498
1405.91	466
1408.06	484
1410.2	478
1412.35	460
1414.49	456
1416.63	482
1418.78	472
1420.92	442
1423.06	460
1425.2	462
1427.34	450
1429.48	448
1431.61	436
1433.75	442
1435.89	438
1438.02	428
1440.16	466
1442.3	432
1444.43	442
1446.56	422
1448.7	444
1450.83	428
1452.96	404
1455.09	418
1457.22	420
1459.35	436
1461.48	424
1463.61	422
1465.73	394
1467.86	436
1469.98	392
1472.11	414
1474.24	400
1476.36	398
1478.48	392
1480.6	408
1482.73	388
1484.85	394
1486.97	400
1489.09	384
1491.21	390
1493.33	392
1495.44	392
1497.56	372
1499.68	370
1501.79	396
1503.91	352
1506.02	350
1508.14	368
1510.25	340
1512.36	366
1514.48	372
1516.59	348
1518.7	366
1520.81	372
1522.92	340
1525.02	358
1527.13	348
1529.24	354
1531.35	338
1533.45	336
1535.56	332
1537.66	336
1539.77	350
1541.87	326
1543.97	334
1546.08	324
1548.18	304
1550.28	340
1552.38	332
1554.48	330
1556.57	312
1558.67	334
1560.77	316
1562.87	320
1564.96	324
1567.06	316
1569.15	320
1571.25	294
1573.34	310
1575.43	304
1577.53	304
1579.62	312
1581.71	298
1583.8	302
1585.89	312
1587.98	282
1590.06	316
1592.15	322
1594.24	302
1596.33	308
1598.41	282
1600.5	304
1602.58	292
1604.66	300
1606.75	288
1608.83	284
1610.91	284
1612.99	286
1615.07	304
1617.15	298
1619.23	284
1621.31	302
1623.39	292
1625.46	278
1627.54	270
1629.62	286
1631.69	326
1633.77	276
1635.84	292
1637.91	300
1639.99	274
1642.06	280
1644.13	272
1646.2	284
1648.27	278
1650.34	272
1652.41	284
1654.47	276
1656.54	298
1658.61	272
1660.67	292
1662.74	274
1664.81	280
1666.87	270
1668.93	276
1671	254
1673.06	280
1675.12	252
1677.18	272
1679.24	286
1681.3	256
1683.36	262
1685.42	274
1687.47	264
1689.53	292
1691.59	256
1693.64	264
1695.7	284
1697.75	268
1699.81	244
1701.86	264
1703.91	290
1705.97	244
1708.02	270
1710.07	258
1712.12	272
1714.17	272
1716.22	236
1718.26	262
1720.31	258
1722.36	256
1724.4	230
1726.45	234
1728.49	266
1730.54	270
1732.58	250
1734.63	264
1736.67	250
1738.71	248
1740.75	234
1742.79	252
1744.83	244
1746.87	256
1748.91	254
1750.95	252
1752.98	256
1755.02	252
1757.06	246
1759.09	260
1761.13	264
1763.16	248
1765.19	254
1767.23	234
1769.26	264
1771.29	248
1773.32	242
1775.35	254
1777.38	258
1779.41	242
1781.44	252
1783.47	240
1785.49	256
1787.52	242
1789.55	232
1791.57	256
1793.6	246
1795.62	238
1797.64	244
1799.67	230
1801.69	230
1803.71	262
1805.73	254
1807.75	240
1809.77	260
1811.79	242
1813.81	234
1815.83	252
1817.84	248
1819.86	262
1821.88	252
1823.89	246
1825.91	252
1827.92	246
1829.93	238
1831.95	246
1833.96	262
1835.97	232
1837.98	266
1839.99	232
1842	222
1844.01	248
1846.02	242
1848.03	230
1850.03	256
1852.04	234
1854.05	236
1856.05	244
1858.06	232
1860.06	234
1862.06	230
1864.07	244
1866.07	260
1868.07	246
1870.07	246
1872.07	240
1874.07	244
1876.07	240
1878.07	228
1880.07	230
1882.07	236
1884.06	254
1886.06	242
1888.05	240
1890.05	234
1892.04	240
1894.04	246
1896.03	236
1898.02	234
1900.01	238
1902	226
1903.99	242
1905.98	240
1907.97	242
1909.96	236
1911.95	240
1913.94	226
1915.93	224
1917.91	220
1919.9	238
1921.88	262
1923.87	252
1925.85	234
1927.83	238
1929.82	236
1931.8	230
1933.78	238
1935.76	238
1937.74	238
1939.72	230
1941.7	244
1943.68	232
1945.65	234
1947.63	232
1949.61	238
1951.58	240
1953.56	242
1955.53	252
1957.51	234
1959.48	232
1961.45	212
1963.43	230
1965.4	248
1967.37	228
1969.34	238
1971.31	250
1973.28	236
1975.25	216
1977.22	222
1979.18	222
1981.15	238
1983.12	218
1985.08	240
1987.05	240
1989.01	238
1990.97	222
1992.94	242
1994.9	236
1996.86	234
1998.82	212
2000.78	216
2002.74	230
2004.7	210
2006.66	242
2008.62	222
2010.58	224
2012.54	240
2014.49	224
2016.45	228
2018.4	238
2020.36	222
2022.31	246
2024.27	246
2026.22	240
2028.17	227
2030.12	224
2032.07	242
2034.03	222
2035.98	230
2037.93	242
2039.87	210
2041.82	228
2043.77	236
2045.72	226
2047.66	214
2049.61	232
2051.55	236
2053.5	224
2055.44	232
2057.39	222
2059.33	216
2061.27	234
2063.21	232
2065.15	236
2067.09	218
2069.03	204
2070.97	240
2072.91	240
2074.85	224
2076.79	244
2078.73	232
2080.66	224
2082.6	226
2084.53	244
2086.47	226
2088.4	226
2090.33	224
2092.27	214
2094.2	222
2096.13	226
2098.06	208
2099.99	232
2101.92	222
2103.85	230
2105.78	238
2107.71	214
2109.64	202
2111.56	204
2113.49	206
2115.41	218
2117.34	214
2119.26	232
2121.19	218
2123.11	228
2125.03	228
2126.96	224
2128.88	246
2130.8	224
2132.72	226
2134.64	242
2136.56	238
2138.48	218
2140.4	246
2142.31	228
2144.23	230
2146.15	234
2148.06	228
2149.98	228
2151.89	196
2153.81	216
2155.72	216
2157.63	228
2159.55	232
2161.46	214
2163.37	230
2165.28	218
2167.19	212
2169.1	226
2171.01	204
2172.91	224
2174.82	208
2176.73	238
2178.64	212
2180.54	234
2182.45	218
2184.35	206
2186.26	226
2188.16	232
2190.06	216
2191.96	196
2193.87	224
2195.77	212
2197.67	218
2199.57	228
2201.47	220
2203.37	228
2205.27	220
2207.16	224
2209.06	202
2210.96	230
2212.85	206
2214.75	206
2216.64	208
2218.54	212
2220.43	222
2222.33	216
2224.22	200.077
2226.11	204.146
2228	202.026
2229.89	215.403
2231.78	210.175
2233.67	202.622
2235.56	231.676
2237.45	222.922
2239.34	214.73
2241.23	222.05
2243.11	209.057
2245	209.622
2246.89	212.795
2248.77	199.482
2250.66	209.751
2252.54	211.951
2254.42	212.902
2256.31	206.71
2258.19	216.984
2260.07	202.53
2261.95	213.373
2263.83	207.91
2265.71	208.479
2267.59	203.512
2269.47	207.376
2271.35	211.355
2273.23	218.283
2275.1	206.413
2276.98	207.619
2278.86	208.899
2280.73	196.504
2282.61	205.372
2284.48	195.587
2286.36	214
2288.23	211.05
2290.1	208.054
2291.98	196.491
2293.85	208.082
2295.72	193.241
2297.59	201.716
2299.46	197.944
2301.33	205.012
2303.2	190.98
2305.06	193.912
2306.93	202.506
2308.8	192.35
2310.67	211.61
2312.53	199.86
2314.4	194.524
2316.26	192.006
2317.62	184
2319.5	198
2321.37	190
2323.24	192
2325.12	190
2326.99	198
2328.86	202
2330.73	188
2332.6	192
2334.47	200
2336.34	196
2338.2	202
2340.07	174
2341.94	190
2343.81	196
2345.67	196
2347.54	190
2349.4	190
2351.27	198
2353.13	190
2354.99	180
2356.86	178
2358.72	194
2360.58	194
2362.44	192
2364.3	180
2366.16	196
2368.02	190
2369.88	200
2371.74	180
2373.6	192
2375.45	194
2377.31	174
2379.17	182
2381.02	176
2382.88	192
2384.73	176
2386.58	172
2388.44	178
2390.29	188
2392.14	194
2393.99	182
2395.85	160
2397.7	188
2399.55	194
2401.4	154
2403.25	160
2405.09	178
2406.94	190
2408.79	170
2410.63	170
2412.48	176
2414.33	184
2416.17	168
2418.02	168
2419.86	172
2421.7	158
2423.55	170
2425.39	166
2427.23	168
2429.07	152
2430.91	184
2432.75	182
2434.59	182
2436.43	160
2438.27	158
2440.11	168
2441.95	180
2443.78	152
2445.62	154
2447.46	166
2449.29	156
2451.13	154
2452.96	152
2454.79	164
2456.63	154
2458.46	158
2460.29	156
2462.12	166
2463.95	158
2465.78	154
2467.61	160
2469.44	154
2471.27	154
2473.1	158
2474.93	140
2476.76	170
2478.58	162
2480.41	152
2482.23	142
2484.06	144
2485.88	154
2487.71	156
2489.53	148
2491.35	146
2493.18	146
2495	154
2496.82	156
2498.64	148
2500.46	162
2502.28	148
2504.1	152
2505.92	148
2507.74	146
2509.55	144
2511.37	146
2513.19	128
2515	148
2516.82	136
2518.63	132
2520.45	136
2522.26	138
2524.07	146
2525.89	142
2527.7	144
2529.51	132
2531.32	138
2533.13	132
2534.94	140
2536.75	136
2538.56	130
2540.37	134
2542.18	140
2543.98	136
2545.79	140
2547.6	118
2549.4	128
2551.21	126
2553.01	124
2554.82	114
2556.62	134
2558.42	138
2560.23	124
2562.03	134
2563.83	126
2565.63	118
2567.43	132
2569.23	142
2571.03	122
2572.83	132
2574.63	116
2576.43	130
2578.22	130
2580.02	122
2581.82	120
2583.61	118
2585.41	124
2587.2	136
2589	128
2590.79	112
2592.58	128
2594.38	120
2596.17	118
2597.96	132
2599.75	112
2601.54	126
2603.33	118
2605.12	110
2606.91	120
2608.7	126
2610.49	120
2612.27	110
2614.06	118
2615.85	108
2617.63	118
2619.42	120
2621.2	116
2622.99	120
2624.77	110
2626.55	110
2628.34	118
2630.12	108
2631.9	116
2633.68	116
2635.46	112
2637.24	108
2639.02	120
2640.8	100
2642.58	98
2644.36	116
2646.14	108
2647.91	100
2649.69	114
2651.46	96
2653.24	108
2655.01	108
2656.79	112
2658.56	92
2660.34	110
2662.11	104
2663.88	102
2665.65	98
2667.42	104
2669.2	96
2670.96	96
2672.73	106
2674.5	102
2676.27	100
2678.04	92
2679.81	90
2681.58	104
2683.34	98
2685.11	94
2686.87	96
2688.64	96
2690.4	106
2692.17	98
2693.93	98
2695.69	108
2697.46	102
2699.22	96
2700.98	98
2702.74	100
2704.5	104
2706.26	84
2708.02	96
2709.78	90
2711.54	84
2713.3	92
2715.05	98
2716.81	102
2718.57	106
2720.32	92
2722.08	92
2723.83	104
2725.59	92
2727.34	84
2729.09	92
2730.85	80
2732.6	100
2734.35	86
2736.1	92
2737.85	102
2739.6	94
2741.35	88
2743.1	92
2744.85	98
2746.6	80
2748.35	70
2750.09	92
2751.84	88
2753.59	90
2755.33	80
2757.08	96
2758.82	86
2760.57	92
2762.31	84
2764.05	90
2765.79	84
2767.54	84
2769.28	90
2771.02	80
2772.76	88
2774.5	80
2776.24	84
2777.98	86
2779.72	78
2781.46	92
2783.19	86
2784.93	72
2786.67	82
2788.4	82
2790.14	72
2791.87	76
2793.61	72
2795.34	74
2797.07	78
2798.81	72
2800.54	74
2802.27	76
2804	74
2805.74	82
2807.47	74
2809.2	82
2810.93	72
2812.65	74
2814.38	86
2816.11	80
2817.84	68
2819.56	74
2821.29	66
2823.02	72
2824.74	70
2826.47	80
2828.19	70
2829.92	72
2831.64	68
2833.36	68
2835.09	62
2836.81	70
2838.53	68
2840.25	66
2841.97	66
2843.69	64
2845.41	70
2847.13	62
2848.85	64
2850.57	68
2852.28	68
2854	72
2855.72	74
2857.43	66
2859.15	72
2860.86	60
2862.58	64
2864.29	64
2866.01	60
2867.72	58
2869.43	58
2871.14	62
2872.86	60
2874.57	66
2876.28	70
2877.99	60
2879.7	66
2881.41	60
2883.11	66
2884.82	58
2886.53	62
2888.24	60
2889.94	68
2891.65	68
2893.36	66
2895.06	64
2896.77	56
2898.47	60
2900.17	60
2901.88	70
2903.58	62
2905.28	54
2906.98	64
2908.69	66
2910.39	52
2912.09	66
2913.79	56
2915.49	62
2917.19	66
2918.88	56
2920.58	56
2922.28	60
2923.98	66
2925.67	48
2927.37	52
2929.06	58
2930.76	56
2932.45	62
2934.15	60
2935.84	62
2937.53	56
2939.23	60
2940.92	58
2942.61	58
2944.3	52
2945.99	58
2947.68	54
2949.37	50
2951.06	52
2952.75	58
2954.44	56
2956.12	52
2957.81	54
2959.5	60
2961.18	62
2962.87	52
2964.56	58
2966.24	58
2967.92	56
2969.61	52
2971.29	48
2972.97	50
2974.66	50
2976.34	56
2978.02	44
2979.7	46
2981.38	48
2983.06	42
2984.74	52
2986.42	50
2988.1	54
2989.78	56
2991.45	52
2993.13	56
2994.81	46
2996.48	62
2998.16	60
2999.83	44