File: muestras/papalo/leaf_100x_15.txt
#Acq. time (s)=	10
#Accumulations=	1
#Range (cm-¹)=	200...3000
#Windows=	3
#Autofocus=	Off
#AutoExposure=	Off
#Spike filter=	Off
#Delay time (s)=	0
#Binning=	1
#Readout mode=	Signal
#DeNoise=	Off
#ICS correction=	Off
#Dark correction=	Off
#Inst. Process=	Off
#Instrument=	LabRAM HR Evol
#Detector=	Syncerity OE
#Objective=	x100_VIS
#Grating=	600 (500nm)
#ND Filter=	0.1%
#Laser=	633nm_Edge
#Hole=	100.021
#Range=	Visible
#Project=	Omar
#Sample=	03-07-23
#Site=	papal
#Title=	leaf_100x
#Remark=
#Date=	03.07.2023 17:24
#Acquired=	03.07.2023 17:24:38
201.713	92
204.247	102
206.778	92
209.311	110
211.84	104
214.371	106
216.899	98
219.428	104
221.955	108
224.482	86
227.007	112
229.531	116
232.055	106
234.579	106
237.1	126
239.621	120
242.141	128
244.661	116
247.179	106
249.698	120
252.215	132
254.731	130
257.246	124
259.761	128
262.273	126
264.786	124
267.298	132
269.809	142
272.319	142
274.828	142
277.336	140
279.844	136
282.351	148
284.855	140
287.361	150
289.866	144
292.368	150
294.871	152
297.372	164
299.873	158
302.372	162
304.872	144
307.37	162
309.866	164
312.364	174
314.859	150
317.353	164
319.848	164
322.341	170
324.833	180
327.324	180
329.814	176
332.304	178
334.792	174
337.28	164
339.767	170
342.254	188
344.739	186
347.224	174
349.708	188
352.191	196
354.673	204
357.155	194
359.634	196
362.114	200
364.593	210
367.07	202
369.548	196
372.024	200
374.499	218
376.974	222
379.447	220
381.92	220
384.392	248
386.864	208
389.333	226
391.802	226
394.272	228
396.739	244
399.206	242
401.673	246
404.138	238
406.602	242
409.066	256
411.528	256
413.99	262
416.451	246
418.911	248
421.371	262
423.83	262
426.288	290
428.745	268
431.201	282
433.657	288
436.111	290
438.565	288
441.017	294
443.469	280
445.921	294
448.37	290
450.821	306
453.27	280
455.717	306
458.165	312
460.61	308
463.056	306
465.5	314
467.945	316
470.387	318
472.829	314
475.271	334
477.711	342
480.15	322
482.589	330
485.027	346
487.465	336
489.901	348
492.337	340
494.771	346
497.205	374
499.638	366
502.07	342
504.502	398
506.933	366
509.363	378
511.792	376
514.219	396
516.647	380
519.073	412
521.5	396
523.924	408
526.348	406
528.772	406
531.194	430
533.616	410
536.036	426
538.457	428
540.875	432
543.294	434
545.712	414
548.128	452
550.545	440
552.959	456
555.373	440
557.788	460
560.2	476
562.612	474
565.023	486
567.433	498
569.843	466
572.251	482
574.659	476
577.066	492
579.472	514
581.878	518
584.283	510
586.687	522
589.09	518
591.493	524
593.893	510
596.294	548
598.694	570
601.093	552
603.491	554
605.889	576
608.285	552
610.682	540
613.076	558
615.471	600
617.864	598
620.256	600
622.648	618
625.039	606
627.429	610
629.819	624
632.208	662
634.595	660
636.982	674
639.369	694
641.755	668
644.139	668
646.523	684
648.906	668
651.288	704
653.67	734
656.051	690
658.429	746
660.808	758
663.187	744
665.565	758
667.942	746
670.317	780
672.692	760
675.067	778
677.44	788
679.813	786
682.184	836
684.556	796
686.926	844
689.296	808
691.664	796
694.033	882
696.4	878
698.766	850
701.133	888
703.497	878
705.861	916
708.224	894
710.586	908
712.949	928
715.31	928
717.67	966
720.029	938
722.388	976
724.746	966
727.103	1014
729.458	1022
731.814	1024
734.168	1014
736.523	1052
738.876	1064
741.227	1064
743.579	1064
745.931	1088
748.28	1076
750.629	1148
752.977	1146
755.325	1150
757.672	1154
760.018	1176
762.363	1160
764.708	1192
767.052	1228
769.394	1234
771.737	1212
774.078	1264
776.419	1248
778.758	1222
781.097	1274
783.435	1330
785.773	1300
788.11	1366
790.446	1358
792.781	1342
795.115	1400
797.449	1410
799.782	1440
802.115	1446
804.446	1502
806.777	1446
809.106	1448
811.435	1556
813.764	1564
816.091	1522
818.418	1530
820.743	1548
823.069	1632
825.393	1610
827.717	1604
830.039	1694
832.362	1700
834.683	1726
837.003	1712
839.324	1726
841.643	1788
843.961	1842
846.278	1810
848.594	1874
850.91	1906
853.227	1898
855.541	1912
857.855	1920
860.168	1986
862.48	1950
864.79	2014
867.101	2016
869.411	2010
871.721	2118
874.029	2110
876.336	2080
878.643	2138
880.95	2142
883.254	2158
885.559	2178
887.862	2218
890.166	2204
892.467	2302
894.77	2206
897.07	2268
899.371	2244
901.669	2332
903.968	2376
906.266	2366
908.563	2398
910.859	2418
913.154	2446
915.449	2470
917.742	2488
920.036	2548
922.329	2540
924.621	2598
926.911	2646
929.201	2590
931.49	2724
933.779	2772
936.068	2754
938.355	2682
940.64	2818
942.926	2886
945.212	2868
947.495	2920
949.779	2932
952.062	2952
954.344	2930
956.625	3046
958.905	3076
961.184	3084
963.464	3114
965.742	3160
968.02	3200
970.296	3186
972.572	3268
974.847	3262
977.121	3274
979.396	3354
981.669	3338
983.941	3380
986.212	3450
988.483	3484
990.753	3534
993.022	3568
995.29	3506
997.558	3598
999.825	3644
1002.09	3598
1004.36	3654
1006.62	3744
1008.89	3752
1011.15	3768
1013.41	3856
1015.67	3852
1017.93	3962
1020.19	3858
1022.45	3924
1024.71	3976
1026.97	4048
1029.23	4122
1031.49	4158
1033.74	4170
1036	4262
1038.25	4318
1040.5	4374
1042.76	4392
1045.01	4314
1047.26	4436
1049.51	4572
1051.76	4532
1054.01	4618
1056.26	4684
1058.51	4696
1060.75	4784
1063	4762
1065.25	4802
1067.49	4772
1069.73	4890
1071.98	4910
1074.22	4906
1076.46	4910
1078.7	5014
1080.94	5038
1083.18	5074
1085.42	5148
1087.66	5194
1089.9	5172
1092.14	5136
1094.37	5194
1096.61	5264
1098.84	5244
1101.08	5434
1103.31	5412
1105.54	5366
1107.77	5406
1110	5354
1112.23	5500
1114.46	5574
1116.69	5564
1118.92	5598
1121.15	5754
1123.37	5600
1125.6	5684
1127.83	5742
1130.05	5798
1132.27	5818
1134.5	5918
1136.72	5872
1138.94	5892
1141.16	6056
1143.38	6050
1145.6	6044
1147.82	6016
1150.04	6088
1152.26	6152
1154.47	6214
1156.69	6234
1158.9	6344
1161.12	6180
1163.33	6298
1165.54	6344
1167.76	6284
1169.97	6392
1172.18	6288
1174.39	6376
1176.6	6370
1178.81	6370
1181.02	6414
1183.22	6454
1185.43	6464
1187.63	6506
1189.84	6530
1192.04	6418
1194.25	6328
1196.45	6430
1198.65	6322
1200.85	6434
1203.05	6432
1205.25	6386
1207.45	6406
1209.65	6278
1211.85	6428
1214.05	6280
1216.24	6296
1218.44	6318
1220.64	6294
1222.83	6334
1225.02	6334
1227.22	6262
1229.41	6262
1231.6	6218
1233.79	6108
1235.98	6116
1238.17	6184
1240.36	6258
1242.55	6148
1244.73	6168
1246.92	6152
1249.11	6028
1251.29	6008
1253.48	6082
1255.66	6030
1257.84	6032
1260.03	6084
1262.21	5950
1264.39	5996
1266.57	5886
1268.75	5954
1270.93	5940
1273.11	5962
1275.28	5834
1277.46	5766
1279.64	5806
1281.81	5758
1283.98	5737.76
1286.16	5614.79
1288.33	5602.69
1290.5	5576.97
1292.68	5546.56
1294.85	5519.33
1297.02	5467.07
1299.19	5443.04
1301.36	5421.69
1303.53	5337.82
1305.69	5262.02
1307.86	5299.69
1310.03	5183.86
1312.19	5123.12
1314.36	5137.24
1316.52	5023.76
1318.68	5022.98
1320.85	4990.04
1323.01	4873.2
1325.17	4849.43
1327.33	4827.88
1329.49	4753.56
1331.65	4779.53
1333.81	4658.14
1335.97	4658.99
1338.12	4550.77
1340.28	4568.59
1342.44	4535.41
1344.59	4476.86
1346.75	4468.91
1348.9	4435.8
1351.05	4388.98
1353.2	4360.09
1355.36	4292.38
1357.51	4219.07
1359.66	4248.05
1361.81	4223.7
1363.96	4152.66
1366.1	4064.37
1368.25	4084.54
1370.4	4017.2
1372.54	3933.02
1374.69	3969.16
1376.83	3919.33
1378.98	3932.55
1381.12	3863.24
1383.26	3797.99
1385.41	3801.58
1387.55	3757.28
1389.69	3757.3
1391.83	3695.05
1393.02	3704
1395.17	3646
1397.32	3568
1399.47	3688
1401.62	3572
1403.77	3546
1405.91	3494
1408.06	3508
1410.2	3512
1412.35	3446
1414.49	3456
1416.63	3432
1418.78	3310
1420.92	3350
1423.06	3390
1425.2	3324
1427.34	3350
1429.48	3244
1431.61	3270
1433.75	3338
1435.89	3154
1438.02	3172
1440.16	3184
1442.3	3164
1444.43	3150
1446.56	3162
1448.7	3220
1450.83	3056
1452.96	3002
1455.09	3034
1457.22	2990
1459.35	3032
1461.48	2998
1463.61	3018
1465.73	3048
1467.86	2892
1469.98	2988
1472.11	3004
1474.24	2924
1476.36	2892
1478.48	2906
1480.6	2902
1482.73	2892
1484.85	2870
1486.97	2812
1489.09	2864
1491.21	2800
1493.33	2854
1495.44	2734
1497.56	2690
1499.68	2786
1501.79	2792
1503.91	2704
1506.02	2728
1508.14	2718
1510.25	2654
1512.36	2670
1514.48	2676
1516.59	2598
1518.7	2634
1520.81	2586
1522.92	2628
1525.02	2552
1527.13	2594
1529.24	2566
1531.35	2594
1533.45	2554
1535.56	2538
1537.66	2440
1539.77	2508
1541.87	2500
1543.97	2500
1546.08	2488
1548.18	2468
1550.28	2498
1552.38	2422
1554.48	2366
1556.57	2362
1558.67	2340
1560.77	2406
1562.87	2386
1564.96	2390
1567.06	2348
1569.15	2350
1571.25	2286
1573.34	2364
1575.43	2356
1577.53	2322
1579.62	2276
1581.71	2308
1583.8	2286
1585.89	2256
1587.98	2266
1590.06	2266
1592.15	2232
1594.24	2218
1596.33	2300
1598.41	2256
1600.5	2322
1602.58	2242
1604.66	2208
1606.75	2158
1608.83	2230
1610.91	2134
1612.99	2180
1615.07	2132
1617.15	2208
1619.23	2130
1621.31	2134
1623.39	2206
1625.46	2112
1627.54	2142
1629.62	2146
1631.69	2090
1633.77	2166
1635.84	2098
1637.91	2154
1639.99	2122
1642.06	2114
1644.13	2166
1646.2	2098
1648.27	2142
1650.34	2128
1652.41	2072
1654.47	2084
1656.54	2046
1658.61	2060
1660.67	2036
1662.74	2070
1664.81	2062
1666.87	2034
1668.93	2026
1671	2044
1673.06	2014
1675.12	2086
1677.18	2032
1679.24	2004
1681.3	1978
1683.36	2004
1685.42	1992
1687.47	1946
1689.53	1964
1691.59	1972
1693.64	1966
1695.7	1936
1697.75	1902
1699.81	1968
1701.86	1966
1703.91	1910
1705.97	1886
1708.02	1936
1710.07	1970
1712.12	1950
1714.17	1938
1716.22	1886
1718.26	1924
1720.31	1930
1722.36	1876
1724.4	1928
1726.45	1864
1728.49	1932
1730.54	1890
1732.58	1896
1734.63	1946
1736.67	1878
1738.71	1890
1740.75	1884
1742.79	1890
1744.83	1946
1746.87	1898
1748.91	1880
1750.95	1840
1752.98	1838
1755.02	1830
1757.06	1870
1759.09	1878
1761.13	1902
1763.16	1856
1765.19	1886
1767.23	1864
1769.26	1858
1771.29	1838
1773.32	1808
1775.35	1864
1777.38	1924
1779.41	1826
1781.44	1868
1783.47	1844
1785.49	1854
1787.52	1890
1789.55	1876
1791.57	1870
1793.6	1854
1795.62	1868
1797.64	1858
1799.67	1834
1801.69	1792
1803.71	1882
1805.73	1850
1807.75	1814
1809.77	1820
1811.79	1794
1813.81	1802
1815.83	1878
1817.84	1864
1819.86	1836
1821.88	1804
1823.89	1842
1825.91	1812
1827.92	1830
1829.93	1818
1831.95	1828
1833.96	1778
1835.97	1862
1837.98	1808
1839.99	1820
1842	1782
1844.01	1792
1846.02	1788
1848.03	1784
1850.03	1764
1852.04	1746
1854.05	1774
1856.05	1780
1858.06	1752
1860.06	1804
1862.06	1768
1864.07	1786
1866.07	1820
1868.07	1806
1870.07	1794
1872.07	1706
1874.07	1776
1876.07	1754
1878.07	1718
1880.07	1824
1882.07	1748
1884.06	1776
1886.06	1760
1888.05	1728
1890.05	1754
1892.04	1786
1894.04	1720
1896.03	1782
1898.02	1728
1900.01	1758
1902	1768
1903.99	1730
1905.98	1758
1907.97	1726
1909.96	1742
1911.95	1768
1913.94	1756
1915.93	1778
1917.91	1758
1919.9	1758
1921.88	1766
1923.87	1740
1925.85	1804
1927.83	1790
1929.82	1746
1931.8	1716
1933.78	1736
1935.76	1708
1937.74	1782
1939.72	1774
1941.7	1738
1943.68	1750
1945.65	1726
1947.63	1724
1949.61	1680
1951.58	1750
1953.56	1736
1955.53	1738
1957.51	1748
1959.48	1734
1961.45	1692
1963.43	1756
1965.4	1742
1967.37	1708
1969.34	1748
1971.31	1728
1973.28	1736
1975.25	1730
1977.22	1652
1979.18	1662
1981.15	1698
1983.12	1748
1985.08	1710
1987.05	1674
1989.01	1690
1990.97	1672
1992.94	1694
1994.9	1694
1996.86	1688
1998.82	1634
2000.78	1706
2002.74	1708
2004.7	1678
2006.66	1688
2008.62	1684
2010.58	1710
2012.54	1724
2014.49	1678
2016.45	1678
2018.4	1662
2020.36	1690
2022.31	1634
2024.27	1682
2026.22	1666
2028.17	1652
2030.12	1696
2032.07	1680
2034.03	1626
2035.98	1660
2037.93	1626
2039.87	1654
2041.82	1616
2043.77	1666
2045.72	1626
2047.66	1602
2049.61	1630
2051.55	1670
2053.5	1706
2055.44	1618
2057.39	1620
2059.33	1646
2061.27	1650
2063.21	1626
2065.15	1644
2067.09	1688
2069.03	1662
2070.97	1664
2072.91	1626
2074.85	1660
2076.79	1620
2078.73	1630
2080.66	1618
2082.6	1610
2084.53	1576
2086.47	1518
2088.4	1640
2090.33	1666
2092.27	1620
2094.2	1568
2096.13	1628
2098.06	1570
2099.99	1562
2101.92	1592
2103.85	1618
2105.78	1602
2107.71	1628
2109.64	1586
2111.56	1604
2113.49	1504
2115.41	1604
2117.34	1572
2119.26	1588
2121.19	1616
2123.11	1586
2125.03	1596
2126.96	1642
2128.88	1604
2130.8	1624
2132.72	1546
2134.64	1578
2136.56	1606
2138.48	1546
2140.4	1576
2142.31	1564
2144.23	1508
2146.15	1578
2148.06	1632
2149.98	1572
2151.89	1556
2153.81	1548
2155.72	1568
2157.63	1530
2159.55	1556
2161.46	1566
2163.37	1566
2165.28	1584
2167.19	1566
2169.1	1550
2171.01	1550
2172.91	1512
2174.82	1582
2176.73	1560
2178.64	1512
2180.54	1546
2182.45	1554
2184.35	1508
2186.26	1524
2188.16	1524
2190.06	1502
2191.96	1508
2193.87	1500
2195.77	1540
2197.67	1502
2199.57	1500
2201.47	1532
2203.37	1458
2205.27	1540
2207.16	1458
2209.06	1538
2210.96	1528
2212.85	1462
2214.75	1462
2216.64	1476
2218.54	1484
2220.43	1458
2222.33	1514
2224.22	1472.97
2226.11	1457.89
2228	1478.46
2229.89	1474.88
2231.78	1477.69
2233.67	1475.87
2235.56	1426.34
2237.45	1477.3
2239.34	1477.57
2241.23	1466.59
2243.11	1499.18
2245	1461.44
2246.89	1494.31
2248.77	1440.95
2250.66	1457.4
2252.54	1462.79
2254.42	1442.07
2256.31	1415.89
2258.19	1454.23
2260.07	1432.52
2261.95	1404.69
2263.83	1414.35
2265.71	1413.96
2267.59	1414.25
2269.47	1414.78
2271.35	1424.46
2273.23	1395.7
2275.1	1387.37
2276.98	1418.34
2278.86	1387.97
2280.73	1399.26
2282.61	1352.93
2284.48	1357.96
2286.36	1368.76
2288.23	1372.55
2290.1	1377.89
2291.98	1352.03
2293.85	1374.03
2295.72	1341
2297.59	1351.77
2299.46	1350.57
2301.33	1337.9
2303.2	1347.38
2305.06	1345.26
2306.93	1316.56
2308.8	1325.81
2310.67	1313.68
2312.53	1314.97
2314.4	1297.37
2316.26	1324.88
2317.62	1330
2319.5	1302
2321.37	1292
2323.24	1300
2325.12	1302
2326.99	1294
2328.86	1276
2330.73	1350
2332.6	1308
2334.47	1328
2336.34	1274
2338.2	1242
2340.07	1294
2341.94	1282
2343.81	1278
2345.67	1290
2347.54	1238
2349.4	1248
2351.27	1206
2353.13	1212
2354.99	1230
2356.86	1250
2358.72	1240
2360.58	1252
2362.44	1244
2364.3	1260
2366.16	1196
2368.02	1238
2369.88	1212
2371.74	1222
2373.6	1262
2375.45	1222
2377.31	1208
2379.17	1196
2381.02	1196
2382.88	1196
2384.73	1214
2386.58	1196
2388.44	1136
2390.29	1160
2392.14	1186
2393.99	1184
2395.85	1164
2397.7	1154
2399.55	1172
2401.4	1142
2403.25	1140
2405.09	1162
2406.94	1176
2408.79	1148
2410.63	1130
2412.48	1114
2414.33	1120
2416.17	1082
2418.02	1134
2419.86	1100
2421.7	1098
2423.55	1048
2425.39	1114
2427.23	1114
2429.07	1102
2430.91	1072
2432.75	1098
2434.59	1082
2436.43	1072
2438.27	1060
2440.11	1054
2441.95	1064
2443.78	1032
2445.62	1034
2447.46	1026
2449.29	1006
2451.13	1008
2452.96	1036
2454.79	1048
2456.63	990
2458.46	1002
2460.29	1034
2462.12	1026
2463.95	994
2465.78	978
2467.61	966
2469.44	978
2471.27	974
2473.1	974
2474.93	956
2476.76	958
2478.58	952
2480.41	958
2482.23	948
2484.06	922
2485.88	960
2487.71	930
2489.53	938
2491.35	918
2493.18	920
2495	946
2496.82	906
2498.64	900
2500.46	884
2502.28	926
2504.1	890
2505.92	878
2507.74	876
2509.55	860
2511.37	836
2513.19	874
2515	900
2516.82	892
2518.63	868
2520.45	858
2522.26	842
2524.07	822
2525.89	846
2527.7	858
2529.51	844
2531.32	840
2533.13	854
2534.94	836
2536.75	834
2538.56	818
2540.37	822
2542.18	772
2543.98	814
2545.79	774
2547.6	798
2549.4	782
2551.21	794
2553.01	766
2554.82	788
2556.62	784
2558.42	778
2560.23	774
2562.03	782
2563.83	776
2565.63	758
2567.43	744
2569.23	746
2571.03	766
2572.83	762
2574.63	716
2576.43	734
2578.22	706
2580.02	714
2581.82	734
2583.61	750
2585.41	704
2587.2	712
2589	696
2590.79	730
2592.58	712
2594.38	682
2596.17	742
2597.96	696
2599.75	706
2601.54	682
2603.33	690
2605.12	698
2606.91	646
2608.7	694
2610.49	638
2612.27	694
2614.06	660
2615.85	640
2617.63	652
2619.42	658
2621.2	636
2622.99	648
2624.77	634
2626.55	636
2628.34	642
2630.12	628
2631.9	620
2633.68	612
2635.46	612
2637.24	606
2639.02	604
2640.8	612
2642.58	612
2644.36	606
2646.14	604
2647.91	604
2649.69	576
2651.46	582
2653.24	586
2655.01	590
2656.79	580
2658.56	594
2660.34	584
2662.11	570
2663.88	572
2665.65	568
2667.42	592
2669.2	544
2670.96	570
2672.73	570
2674.5	562
2676.27	554
2678.04	572
2679.81	530
2681.58	530
2683.34	542
2685.11	554
2686.87	524
2688.64	534
2690.4	530
2692.17	536
2693.93	556
2695.69	528
2697.46	514
2699.22	490
2700.98	508
2702.74	530
2704.5	494
2706.26	512
2708.02	502
2709.78	512
2711.54	510
2713.3	492
2715.05	502
2716.81	494
2718.57	492
2720.32	492
2722.08	488
2723.83	460
2725.59	442
2727.34	500
2729.09	454
2730.85	486
2732.6	448
2734.35	458
2736.1	454
2737.85	452
2739.6	436
2741.35	450
2743.1	438
2744.85	442
2746.6	460
2748.35	424
2750.09	436
2751.84	436
2753.59	408
2755.33	424
2757.08	436
2758.82	424
2760.57	424
2762.31	406
2764.05	408
2765.79	416
2767.54	422
2769.28	414
2771.02	400
2772.76	402
2774.5	388
2776.24	378
2777.98	394
2779.72	406
2781.46	396
2783.19	378
2784.93	368
2786.67	392
2788.4	390
2790.14	364
2791.87	376
2793.61	380
2795.34	366
2797.07	368
2798.81	352
2800.54	366
2802.27	350
2804	368
2805.74	370
2807.47	362
2809.2	358
2810.93	366
2812.65	328
2814.38	328
2816.11	354
2817.84	354
2819.56	346
2821.29	336
2823.02	338
2824.74	332
2826.47	340
2828.19	322
2829.92	292
2831.64	334
2833.36	306
2835.09	318
2836.81	300
2838.53	304
2840.25	312
2841.97	312
2843.69	296
2845.41	284
2847.13	292
2848.85	298
2850.57	310
2852.28	304
2854	278
2855.72	278
2857.43	284
2859.15	280
2860.86	288
2862.58	278
2864.29	310
2866.01	292
2867.72	290
2869.43	282
2871.14	274
2872.86	276
2874.57	292
2876.28	280
2877.99	288
2879.7	262
2881.41	264
2883.11	264
2884.82	264
2886.53	240
2888.24	262
2889.94	276
2891.65	248
2893.36	250
2895.06	242
2896.77	252
2898.47	238
2900.17	248
2901.88	260
2903.58	234
2905.28	220
2906.98	210
2908.69	254
2910.39	260
2912.09	256
2913.79	254
2915.49	230
2917.19	218
2918.88	232
2920.58	230
2922.28	228
2923.98	230
2925.67	236
2927.37	222
2929.06	220
2930.76	214
2932.45	238
2934.15	222
2935.84	220
2937.53	224
2939.23	218
2940.92	236
2942.61	222
2944.3	212
2945.99	206
2947.68	210
2949.37	214
2951.06	210
2952.75	222
2954.44	200
2956.12	212
2957.81	204
2959.5	196
2961.18	212
2962.87	204
2964.56	212
2966.24	202
2967.92	204
2969.61	188
2971.29	200
2972.97	196
2974.66	208
2976.34	194
2978.02	196
2979.7	194
2981.38	192
2983.06	200
2984.74	192
2986.42	182
2988.1	192
2989.78	196
2991.45	178
2993.13	196
2994.81	178
2996.48	194
2998.16	178
2999.83	174