File: muestras/papalo/leaf_14.txt
#Acq. time (s)=	10
#Accumulations=	1
#Range (cm-¹)=	200...3000
#Windows=	3
#Autofocus=	Off
#AutoExposure=	Off
#Spike filter=	Off
#Delay time (s)=	0
#Binning=	1
#Readout mode=	Signal
#DeNoise=	Off
#ICS correction=	Off
#Dark correction=	Off
#Inst. Process=	Off
#Instrument=	LabRAM HR Evol
#Detector=	Syncerity OE
#Objective=	x100_VIS
#Grating=	600 (500nm)
#ND Filter=	0.01%
#Laser=	633nm_Edge
#Hole=	100.021
#Range=	Visible
#Project=	Omar
#Sample=	03-07-23
#Site=	papal
#Title=	leaf
#Remark=
#Date=	03.07.2023 17:05
#Acquired=	03.07.2023 17:05:24
201.713	112
204.247	108
206.778	100
209.311	110
211.84	112
214.371	102
216.899	122
219.428	110
221.955	110
224.482	126
227.007	116
229.531	124
232.055	122
234.579	116
237.1	132
239.621	126
242.141	122
244.661	130
247.179	120
249.698	122
252.215	138
254.731	132
257.246	128
259.761	140
262.273	144
264.786	140
267.298	134
269.809	132
272.319	130
274.828	142
277.336	142
279.844	138
282.351	152
284.855	154
287.361	152
289.866	154
292.368	164
294.871	156
297.372	162
299.873	152
302.372	158
304.872	180
307.37	174
309.866	162
312.364	164
314.859	184
317.353	190
319.848	166
322.341	172
324.833	180
327.324	184
329.814	184
332.304	182
334.792	182
337.28	180
339.767	180
342.254	184
344.739	198
347.224	202
349.708	210
352.191	206
354.673	206
357.155	222
359.634	210
362.114	216
364.593	218
367.07	222
369.548	212
372.024	220
374.499	246
376.974	226
379.447	244
381.92	246
384.392	244
386.864	254
389.333	238
391.802	244
394.272	260
396.739	244
399.206	268
401.673	248
404.138	252
406.602	270
409.066	276
411.528	288
413.99	292
416.451	292
418.911	298
421.371	288
423.83	298
426.288	290
428.745	298
431.201	316
433.657	304
436.111	316
438.565	312
441.017	318
443.469	324
445.921	318
448.37	312
450.821	324
453.27	312
455.717	326
458.165	366
460.61	350
463.056	350
465.5	346
467.945	350
470.387	340
472.829	382
475.271	362
477.711	358
480.15	378
482.589	376
485.027	358
487.465	374
489.901	388
492.337	368
494.771	422
497.205	392
499.638	390
502.07	382
504.502	418
506.933	414
509.363	420
511.792	442
514.219	414
516.647	452
519.073	448
521.5	424
523.924	410
526.348	412
528.772	444
531.194	458
533.616	450
536.036	450
538.457	448
540.875	480
543.294	478
545.712	476
548.128	466
550.545	494
552.959	522
555.373	494
557.788	494
560.2	526
562.612	518
565.023	518
567.433	528
569.843	502
572.251	524
574.659	548
577.066	570
579.472	536
581.878	554
584.283	558
586.687	566
589.09	586
591.493	594
593.893	616
596.294	574
598.694	598
601.093	592
603.491	614
605.889	632
608.285	646
610.682	656
613.076	650
615.471	648
617.864	656
620.256	690
622.648	688
625.039	662
627.429	708
629.819	714
632.208	708
634.595	710
636.982	758
639.369	758
641.755	712
644.139	774
646.523	764
648.906	796
651.288	794
653.67	800
656.051	786
658.429	834
660.808	794
663.187	816
665.565	832
667.942	896
670.317	898
672.692	866
675.067	920
677.44	910
679.813	886
682.184	904
684.556	902
686.926	938
689.296	948
691.664	978
694.033	974
696.4	950
698.766	1006
701.133	978
703.497	1018
705.861	1040
708.224	1018
710.586	1046
712.949	1062
715.31	1048
717.67	1078
720.029	1086
722.388	1120
724.746	1134
727.103	1178
729.458	1126
731.814	1188
734.168	1160
736.523	1206
738.876	1228
741.227	1202
743.579	1258
745.931	1262
748.28	1248
750.629	1306
752.977	1326
755.325	1336
757.672	1322
760.018	1342
762.363	1358
764.708	1416
767.052	1438
769.394	1440
771.737	1400
774.078	1410
776.419	1432
778.758	1520
781.097	1500
783.435	1530
785.773	1500
788.11	1520
790.446	1540
792.781	1596
795.115	1648
797.449	1692
799.782	1638
802.115	1694
804.446	1726
806.777	1696
809.106	1730
811.435	1748
813.764	1806
816.091	1782
818.418	1880
820.743	1856
823.069	1870
825.393	1858
827.717	1956
830.039	1960
832.362	1944
834.683	1980
837.003	2044
839.324	2018
841.643	2046
843.961	2104
846.278	2166
848.594	2170
850.91	2190
853.227	2240
855.541	2262
857.855	2298
860.168	2350
862.48	2290
864.79	2310
867.101	2360
869.411	2412
871.721	2314
874.029	2410
876.336	2466
878.643	2506
880.95	2582
883.254	2580
885.559	2540
887.862	2618
890.166	2618
892.467	2658
894.77	2680
897.07	2774
899.371	2742
901.669	2740
903.968	2756
906.266	2810
908.563	2838
910.859	2870
913.154	2964
915.449	2964
917.742	2990
920.036	3034
922.329	3080
924.621	3094
926.911	3098
929.201	3168
931.49	3170
933.779	3228
936.068	3252
938.355	3330
940.64	3434
942.926	3406
945.212	3512
947.495	3426
949.779	3554
952.062	3468
954.344	3644
956.625	3668
958.905	3618
961.184	3630
963.464	3762
965.742	3760
968.02	3822
970.296	3878
972.572	3994
974.847	3894
977.121	4016
979.396	4036
981.669	4030
983.941	4084
986.212	4164
988.483	4088
990.753	4300
993.022	4248
995.29	4282
997.558	4310
999.825	4330
1002.09	4380
1004.36	4416
1006.62	4438
1008.89	4556
1011.15	4606
1013.41	4680
1015.67	4696
1017.93	4784
1020.19	4712
1022.45	4798
1024.71	4840
1026.97	4936
1029.23	4950
1031.49	4960
1033.74	5048
1036	5116
1038.25	5246
1040.5	5342
1042.76	5326
1045.01	5300
1047.26	5422
1049.51	5474
1051.76	5460
1054.01	5624
1056.26	5616
1058.51	5640
1060.75	5704
1063	5758
1065.25	5762
1067.49	5936
1069.73	5856
1071.98	6060
1074.22	5952
1076.46	6018
1078.7	6030
1080.94	6124
1083.18	6142
1085.42	6174
1087.66	6334
1089.9	6436
1092.14	6400
1094.37	6290
1096.61	6326
1098.84	6456
1101.08	6430
1103.31	6470
1105.54	6546
1107.77	6528
1110	6640
1112.23	6710
1114.46	6682
1116.69	6738
1118.92	6758
1121.15	6848
1123.37	6896
1125.6	6892
1127.83	6884
1130.05	7024
1132.27	7002
1134.5	7194
1136.72	7064
1138.94	7182
1141.16	7190
1143.38	7318
1145.6	7276
1147.82	7340
1150.04	7370
1152.26	7398
1154.47	7452
1156.69	7390
1158.9	7484
1161.12	7430
1163.33	7506
1165.54	7626
1167.76	7552
1169.97	7566
1172.18	7584
1174.39	7568
1176.6	7668
1178.81	7598
1181.02	7608
1183.22	7670
1185.43	7618
1187.63	7650
1189.84	7506
1192.04	7474
1194.25	7544
1196.45	7546
1198.65	7604
1200.85	7530
1203.05	7562
1205.25	7542
1207.45	7504
1209.65	7500
1211.85	7454
1214.05	7366
1216.24	7436
1218.44	7394
1220.64	7292
1222.83	7426
1225.02	7310
1227.22	7328
1229.41	7268
1231.6	7254
1233.79	7224
1235.98	7198
1238.17	7138
1240.36	7066
1242.55	7196
1244.73	7142
1246.92	7038
1249.11	7146
1251.29	6990
1253.48	6946
1255.66	6996
1257.84	6914
1260.03	6964
1262.21	6856
1264.39	6796
1266.57	6780
1268.75	6754
1270.93	6746
1273.11	6762
1275.28	6638
1277.46	6622
1279.64	6534
1281.81	6448
1283.98	6453.16
1286.16	6438.21
1288.33	6470.83
1290.5	6412.26
1292.68	6308.58
1294.85	6340.71
1297.02	6220.37
1299.19	6153.68
1301.36	6141.22
1303.53	6129.86
1305.69	5978.07
1307.86	5940.42
1310.03	5823.33
1312.19	5830.09
1314.36	5726.92
1316.52	5727.87
1318.68	5677.21
1320.85	5634.03
1323.01	5627.13
1325.17	5549.8
1327.33	5459.52
1329.49	5438.21
1331.65	5423.81
1333.81	5321.34
1335.97	5313.73
1338.12	5216.15
1340.28	5177.44
1342.44	5123.56
1344.59	5073.57
1346.75	5085.98
1348.9	5006.1
1351.05	4967.81
1353.2	4908.19
1355.36	4919.14
1357.51	4880.69
1359.66	4820.1
1361.81	4804.15
1363.96	4751.9
1366.1	4728.29
1368.25	4637.45
1370.4	4577.98
1372.54	4601.32
1374.69	4523.72
1376.83	4542.68
1378.98	4436.37
1381.12	4461.1
1383.26	4360.17
1385.41	4313.34
1387.55	4305.87
1389.69	4275.99
1391.83	4262.13
1393.02	4236
1395.17	4138
1397.32	4064
1399.47	4126
1401.62	4114
1403.77	4000
1405.91	3946
1408.06	3994
1410.2	3964
1412.35	3966
1414.49	3932
1416.63	3856
1418.78	3836
1420.92	3874
1423.06	3792
1425.2	3808
1427.34	3750
1429.48	3766
1431.61	3654
1433.75	3700
1435.89	3630
1438.02	3570
1440.16	3650
1442.3	3550
1444.43	3600
1446.56	3596
1448.7	3504
1450.83	3534
1452.96	3486
1455.09	3410
1457.22	3426
1459.35	3454
1461.48	3390
1463.61	3418
1465.73	3354
1467.86	3410
1469.98	3322
1472.11	3262
1474.24	3298
1476.36	3298
1478.48	3270
1480.6	3328
1482.73	3228
1484.85	3268
1486.97	3216
1489.09	3178
1491.21	3246
1493.33	3192
1495.44	3096
1497.56	3108
1499.68	3104
1501.79	3134
1503.91	3096
1506.02	3060
1508.14	3040
1510.25	3092
1512.36	3018
1514.48	2968
1516.59	2934
1518.7	2918
1520.81	2952
1522.92	2898
1525.02	2858
1527.13	2936
1529.24	2834
1531.35	2882
1533.45	2864
1535.56	2856
1537.66	2854
1539.77	2774
1541.87	2750
1543.97	2748
1546.08	2746
1548.18	2796
1550.28	2634
1552.38	2672
1554.48	2664
1556.57	2714
1558.67	2648
1560.77	2696
1562.87	2694
1564.96	2646
1567.06	2630
1569.15	2624
1571.25	2604
1573.34	2592
1575.43	2568
1577.53	2616
1579.62	2552
1581.71	2524
1583.8	2558
1585.89	2444
1587.98	2542
1590.06	2502
1592.15	2570
1594.24	2496
1596.33	2516
1598.41	2488
1600.5	2470
1602.58	2460
1604.66	2478
1606.75	2452
1608.83	2496
1610.91	2424
1612.99	2444
1615.07	2452
1617.15	2430
1619.23	2424
1621.31	2446
1623.39	2448
1625.46	2396
1627.54	2390
1629.62	2440
1631.69	2398
1633.77	2406
1635.84	2416
1637.91	2334
1639.99	2424
1642.06	2384
1644.13	2296
1646.2	2308
1648.27	2318
1650.34	2366
1652.41	2334
1654.47	2334
1656.54	2268
1658.61	2358
1660.67	2286
1662.74	2268
1664.81	2262
1666.87	2292
1668.93	2304
1671	2222
1673.06	2230
1675.12	2252
1677.18	2196
1679.24	2192
1681.3	2210
1683.36	2180
1685.42	2160
1687.47	2180
1689.53	2184
1691.59	2132
1693.64	2188
1695.7	2124
1697.75	2170
1699.81	2192
1701.86	2154
1703.91	2114
1705.97	2108
1708.02	2128
1710.07	2100
1712.12	2104
1714.17	2072
1716.22	2158
1718.26	2108
1720.31	2080
1722.36	2172
1724.4	2090
1726.45	2074
1728.49	2142
1730.54	2134
1732.58	2072
1734.63	2104
1736.67	2126
1738.71	2082
1740.75	2092
1742.79	2092
1744.83	2106
1746.87	2108
1748.91	2084
1750.95	2118
1752.98	2044
1755.02	2128
1757.06	2108
1759.09	2100
1761.13	2138
1763.16	2058
1765.19	2098
1767.23	2082
1769.26	2098
1771.29	2084
1773.32	2088
1775.35	2016
1777.38	2042
1779.41	2070
1781.44	2118
1783.47	2110
1785.49	2066
1787.52	2062
1789.55	2130
1791.57	2108
1793.6	2076
1795.62	2040
1797.64	2038
1799.67	2040
1801.69	2052
1803.71	2068
1805.73	2042
1807.75	2054
1809.77	2036
1811.79	2048
1813.81	1998
1815.83	2068
1817.84	2012
1819.86	2104
1821.88	2092
1823.89	2002
1825.91	2024
1827.92	2028
1829.93	1994
1831.95	2080
1833.96	1992
1835.97	2060
1837.98	2036
1839.99	2054
1842	2010
1844.01	1986
1846.02	2044
1848.03	1986
1850.03	2014
1852.04	1970
1854.05	2020
1856.05	1988
1858.06	1994
1860.06	2078
1862.06	1980
1864.07	1960
1866.07	2002
1868.07	2002
1870.07	1940
1872.07	1964
1874.07	2042
1876.07	2000
1878.07	1944
1880.07	1978
1882.07	2032
1884.06	1984
1886.06	2028
1888.05	1988
1890.05	1968
1892.04	1968
1894.04	1980
1896.03	1970
1898.02	2030
1900.01	1950
1902	1990
1903.99	1964
1905.98	1972
1907.97	1924
1909.96	1980
1911.95	1942
1913.94	1970
1915.93	1936
1917.91	2012
1919.9	1922
1921.88	2006
1923.87	1922
1925.85	1964
1927.83	1966
1929.82	1994
1931.8	2046
1933.78	1986
1935.76	1922
1937.74	2010
1939.72	2016
1941.7	2006
1943.68	1936
1945.65	1958
1947.63	1948
1949.61	1978
1951.58	1952
1953.56	1930
1955.53	1980
1957.51	1928
1959.48	2004
1961.45	1976
1963.43	2002
1965.4	1996
1967.37	1952
1969.34	1976
1971.31	1896
1973.28	1924
1975.25	1916
1977.22	1924
1979.18	1930
1981.15	1914
1983.12	1910
1985.08	1924
1987.05	1962
1989.01	1948
1990.97	1874
1992.94	1884
1994.9	1910
1996.86	1890
1998.82	1910
2000.78	1908
2002.74	1912
2004.7	1930
2006.66	1906
2008.62	1952
2010.58	1896
2012.54	1898
2014.49	1918
2016.45	1858
2018.4	1920
2020.36	1952
2022.31	1836
2024.27	1982
2026.22	1918
2028.17	1929
2030.12	1896
2032.07	1896
2034.03	1892
2035.98	1934
2037.93	1838
2039.87	1950
2041.82	1910
2043.77	1894
2045.72	1918
2047.66	1916
2049.61	1870
2051.55	1920
2053.5	1898
2055.44	1902
2057.39	1882
2059.33	1890
2061.27	1866
2063.21	1888
2065.15	1842
2067.09	1902
2069.03	1910
2070.97	1866
2072.91	1862
2074.85	1926
2076.79	1878
2078.73	1940
2080.66	1852
2082.6	1878
2084.53	1874
2086.47	1878
2088.4	1868
2090.33	1908
2092.27	1868
2094.2	1842
2096.13	1878
2098.06	1906
2099.99	1886
2101.92	1832
2103.85	1854
2105.78	1868
2107.71	1902
2109.64	1870
2111.56	1804
2113.49	1828
2115.41	1894
2117.34	1868
2119.26	1904
2121.19	1858
2123.11	1886
2125.03	1848
2126.96	1842
2128.88	1882
2130.8	1860
2132.72	1860
2134.64	1868
2136.56	1838
2138.48	1824
2140.4	1844
2142.31	1928
2144.23	1812
2146.15	1836
2148.06	1846
2149.98	1790
2151.89	1816
2153.81	1838
2155.72	1848
2157.63	1828
2159.55	1806
2161.46	1804
2163.37	1834
2165.28	1760
2167.19	1820
2169.1	1802
2171.01	1860
2172.91	1776
2174.82	1768
2176.73	1848
2178.64	1760
2180.54	1812
2182.45	1840
2184.35	1784
2186.26	1792
2188.16	1844
2190.06	1806
2191.96	1780
2193.87	1784
2195.77	1774
2197.67	1826
2199.57	1792
2201.47	1762
2203.37	1800
2205.27	1750
2207.16	1754
2209.06	1744
2210.96	1820
2212.85	1744
2214.75	1764
2216.64	1752
2218.54	1766
2220.43	1756
2222.33	1778
2224.22	1730.29
2226.11	1782.36
2228	1746.61
2229.89	1770.46
2231.78	1768.21
2233.67	1792.41
2235.56	1793.82
2237.45	1726.42
2239.34	1704.89
2241.23	1769.95
2243.11	1729.66
2245	1735.81
2246.89	1771.1
2248.77	1733.17
2250.66	1731.26
2252.54	1758.25
2254.42	1723.75
2256.31	1750.67
2258.19	1724.89
2260.07	1710.74
2261.95	1729.71
2263.83	1706.83
2265.71	1694.61
2267.59	1726.68
2269.47	1737.16
2271.35	1692.32
2273.23	1698.32
2275.1	1698.28
2276.98	1672.55
2278.86	1636.6
2280.73	1680.74
2282.61	1694.56
2284.48	1687.06
2286.36	1693.16
2288.23	1650.64
2290.1	1674.48
2291.98	1666.15
2293.85	1663.81
2295.72	1672.91
2297.59	1642.84
2299.46	1657.77
2301.33	1622.42
2303.2	1646.08
2305.06	1626.11
2306.93	1625.97
2308.8	1643.07
2310.67	1637.01
2312.53	1622.53
2314.4	1596
2316.26	1652.33
2317.62	1588
2319.5	1618
2321.37	1634
2323.24	1578
2325.12	1600
2326.99	1544
2328.86	1588
2330.73	1626
2332.6	1568
2334.47	1598
2336.34	1594
2338.2	1576
2340.07	1576
2341.94	1538
2343.81	1610
2345.67	1516
2347.54	1556
2349.4	1504
2351.27	1538
2353.13	1548
2354.99	1564
2356.86	1554
2358.72	1586
2360.58	1582
2362.44	1522
2364.3	1542
2366.16	1510
2368.02	1484
2369.88	1466
2371.74	1494
2373.6	1494
2375.45	1522
2377.31	1496
2379.17	1520
2381.02	1454
2382.88	1492
2384.73	1514
2386.58	1470
2388.44	1458
2390.29	1424
2392.14	1496
2393.99	1398
2395.85	1460
2397.7	1436
2399.55	1444
2401.4	1486
2403.25	1460
2405.09	1412
2406.94	1464
2408.79	1440
2410.63	1428
2412.48	1432
2414.33	1432
2416.17	1432
2418.02	1394
2419.86	1426
2421.7	1404
2423.55	1352
2425.39	1420
2427.23	1388
2429.07	1358
2430.91	1386
2432.75	1340
2434.59	1316
2436.43	1314
2438.27	1332
2440.11	1286
2441.95	1328
2443.78	1298
2445.62	1308
2447.46	1308
2449.29	1324
2451.13	1282
2452.96	1298
2454.79	1278
2456.63	1296
2458.46	1282
2460.29	1304
2462.12	1280
2463.95	1278
2465.78	1256
2467.61	1258
2469.44	1274
2471.27	1230
2473.1	1212
2474.93	1194
2476.76	1236
2478.58	1214
2480.41	1256
2482.23	1208
2484.06	1232
2485.88	1198
2487.71	1206
2489.53	1200
2491.35	1166
2493.18	1186
2495	1156
2496.82	1202
2498.64	1128
2500.46	1162
2502.28	1170
2504.1	1128
2505.92	1154
2507.74	1114
2509.55	1122
2511.37	1094
2513.19	1148
2515	1096
2516.82	1148
2518.63	1114
2520.45	1118
2522.26	1112
2524.07	1098
2525.89	1066
2527.7	1058
2529.51	1088
2531.32	1068
2533.13	1066
2534.94	1030
2536.75	1054
2538.56	1080
2540.37	1076
2542.18	1030
2543.98	1032
2545.79	1046
2547.6	1030
2549.4	978
2551.21	998
2553.01	1022
2554.82	986
2556.62	1026
2558.42	1018
2560.23	1004
2562.03	1022
2563.83	1020
2565.63	1014
2567.43	968
2569.23	920
2571.03	916
2572.83	994
2574.63	954
2576.43	982
2578.22	930
2580.02	976
2581.82	930
2583.61	940
2585.41	918
2587.2	938
2589	926
2590.79	914
2592.58	942
2594.38	916
2596.17	908
2597.96	900
2599.75	916
2601.54	868
2603.33	900
2605.12	876
2606.91	898
2608.7	842
2610.49	886
2612.27	864
2614.06	830
2615.85	826
2617.63	812
2619.42	824
2621.2	850
2622.99	850
2624.77	834
2626.55	836
2628.34	850
2630.12	824
2631.9	828
2633.68	824
2635.46	812
2637.24	834
2639.02	790
2640.8	804
2642.58	804
2644.36	800
2646.14	772
2647.91	746
2649.69	800
2651.46	790
2653.24	784
2655.01	746
2656.79	740
2658.56	750
2660.34	770
2662.11	752
2663.88	730
2665.65	736
2667.42	756
2669.2	750
2670.96	730
2672.73	726
2674.5	740
2676.27	720
2678.04	742
2679.81	724
2681.58	760
2683.34	708
2685.11	712
2686.87	702
2688.64	730
2690.4	700
2692.17	728
2693.93	694
2695.69	710
2697.46	698
2699.22	704
2700.98	702
2702.74	692
2704.5	658
2706.26	656
2708.02	660
2709.78	684
2711.54	632
2713.3	648
2715.05	682
2716.81	640
2718.57	648
2720.32	634
2722.08	610
2723.83	614
2725.59	616
2727.34	604
2729.09	596
2730.85	632
2732.6	610
2734.35	636
2736.1	610
2737.85	624
2739.6	592
2741.35	606
2743.1	564
2744.85	582
2746.6	578
2748.35	578
2750.09	552
2751.84	574
2753.59	540
2755.33	544
2757.08	548
2758.82	548
2760.57	578
2762.31	560
2764.05	532
2765.79	538
2767.54	556
2769.28	556
2771.02	534
2772.76	536
2774.5	538
2776.24	522
2777.98	534
2779.72	498
2781.46	520
2783.19	492
2784.93	504
2786.67	494
2788.4	498
2790.14	488
2791.87	500
2793.61	480
2795.34	524
2797.07	498
2798.81	462
2800.54	462
2802.27	486
2804	494
2805.74	496
2807.47	488
2809.2	448
2810.93	474
2812.65	468
2814.38	458
2816.11	430
2817.84	474
2819.56	456
2821.29	444
2823.02	438
2824.74	422
2826.47	430
2828.19	422
2829.92	406
2831.64	434
2833.36	414
2835.09	414
2836.81	438
2838.53	426
2840.25	450
2841.97	426
2843.69	402
2845.41	422
2847.13	396
2848.85	428
2850.57	388
2852.28	394
2854	392
2855.72	398
2857.43	380
2859.15	372
2860.86	402
2862.58	374
2864.29	386
2866.01	356
2867.72	374
2869.43	370
2871.14	380
2872.86	382
2874.57	370
2876.28	374
2877.99	346
2879.7	336
2881.41	366
2883.11	374
2884.82	354
2886.53	342
2888.24	354
2889.94	342
2891.65	342
2893.36	310
2895.06	356
2896.77	344
2898.47	326
2900.17	324
2901.88	368
2903.58	350
2905.28	330
2906.98	312
2908.69	316
2910.39	324
2912.09	338
2913.79	314
2915.49	310
2917.19	326
2918.88	308
2920.58	326
2922.28	310
2923.98	300
2925.67	322
2927.37	314
2929.06	314
2930.76	306
2932.45	328
2934.15	310
2935.84	294
2937.53	312
2939.23	310
2940.92	312
2942.61	300
2944.3	294
2945.99	290
2947.68	290
2949.37	290
2951.06	274
2952.75	272
2954.44	296
2956.12	296
2957.81	278
2959.5	290
2961.18	286
2962.87	288
2964.56	270
2966.24	266
2967.92	284
2969.61	276
2971.29	286
2972.97	288
2974.66	266
2976.34	276
2978.02	264
2979.7	266
2981.38	264
2983.06	254
2984.74	264
2986.42	274
2988.1	258
2989.78	244
2991.45	268
2993.13	238
2994.81	258
2996.48	244
2998.16	248
2999.83	250