File: muestras/papalo/leaf_100x_05.txt
#Acq. time (s)=	10
#Accumulations=	1
#Range (cm-¹)=	200...3000
#Windows=	3
#Autofocus=	Off
#AutoExposure=	Off
#Spike filter=	Off
#Delay time (s)=	0
#Binning=	1
#Readout mode=	Signal
#DeNoise=	Off
#ICS correction=	Off
#Dark correction=	Off
#Inst. Process=	Off
#Instrument=	LabRAM HR Evol
#Detector=	Syncerity OE
#Objective=	x100_VIS
#Grating=	600 (500nm)
#ND Filter=	0.01%
#Laser=	633nm_Edge
#Hole=	100.021
#Range=	Visible
#Project=	Omar
#Sample=	03-07-23
#Site=	papal
#Title=	leaf_100x
#Remark=
#Date=	03.07.2023 17:14
#Acquired=	03.07.2023 17:14:10
201.713	64
204.247	68
206.778	66
209.311	60
211.84	64
214.371	66
216.899	66
219.428	70
221.955	72
224.482	60
227.007	68
229.531	76
232.055	70
234.579	68
237.1	70
239.621	70
242.141	76
244.661	74
247.179	84
249.698	78
252.215	76
254.731	76
257.246	76
259.761	74
262.273	76
264.786	78
267.298	84
269.809	88
272.319	78
274.828	90
277.336	76
279.844	82
282.351	84
284.855	80
287.361	78
289.866	100
292.368	86
294.871	84
297.372	90
299.873	86
302.372	82
304.872	92
307.37	96
309.866	104
312.364	98
314.859	78
317.353	96
319.848	86
322.341	100
324.833	102
327.324	96
329.814	90
332.304	114
334.792	114
337.28	100
339.767	114
342.254	116
344.739	112
347.224	116
349.708	122
352.191	116
354.673	120
357.155	116
359.634	112
362.114	112
364.593	130
367.07	124
369.548	110
372.024	128
374.499	122
376.974	122
379.447	136
381.92	118
384.392	116
386.864	140
389.333	138
391.802	132
394.272	138
396.739	130
399.206	142
401.673	136
404.138	140
406.602	146
409.066	148
411.528	152
413.99	156
416.451	130
418.911	142
421.371	154
423.83	146
426.288	164
428.745	168
431.201	156
433.657	176
436.111	166
438.565	166
441.017	162
443.469	170
445.921	172
448.37	164
450.821	182
453.27	170
455.717	184
458.165	188
460.61	196
463.056	194
465.5	176
467.945	192
470.387	186
472.829	194
475.271	200
477.711	182
480.15	190
482.589	196
485.027	182
487.465	208
489.901	198
492.337	204
494.771	200
497.205	218
499.638	208
502.07	200
504.502	208
506.933	210
509.363	212
511.792	206
514.219	218
516.647	212
519.073	212
521.5	222
523.924	218
526.348	244
528.772	228
531.194	218
533.616	228
536.036	236
538.457	234
540.875	240
543.294	242
545.712	250
548.128	258
550.545	264
552.959	260
555.373	256
557.788	272
560.2	242
562.612	246
565.023	268
567.433	276
569.843	264
572.251	272
574.659	264
577.066	270
579.472	284
581.878	286
584.283	302
586.687	296
589.09	286
591.493	278
593.893	304
596.294	306
598.694	300
601.093	300
603.491	316
605.889	314
608.285	308
610.682	330
613.076	314
615.471	342
617.864	326
620.256	326
622.648	332
625.039	360
627.429	344
629.819	352
632.208	358
634.595	366
636.982	386
639.369	392
641.755	376
644.139	382
646.523	404
648.906	388
651.288	370
653.67	402
656.051	400
658.429	420
660.808	406
663.187	400
665.565	428
667.942	416
670.317	426
672.692	468
675.067	430
677.44	460
679.813	480
682.184	452
684.556	480
686.926	460
689.296	468
691.664	486
694.033	520
696.4	476
698.766	510
701.133	502
703.497	512
705.861	520
708.224	514
710.586	498
712.949	538
715.31	548
717.67	540
720.029	542
722.388	574
724.746	564
727.103	556
729.458	584
731.814	576
734.168	568
736.523	582
738.876	600
741.227	614
743.579	608
745.931	598
748.28	626
750.629	658
752.977	690
755.325	642
757.672	684
760.018	702
762.363	664
764.708	704
767.052	716
769.394	706
771.737	712
774.078	724
776.419	724
778.758	762
781.097	756
783.435	778
785.773	788
788.11	760
790.446	818
792.781	1876
795.115	802
797.449	834
799.782	834
802.115	846
804.446	860
806.777	878
809.106	872
811.435	874
813.764	902
816.091	908
818.418	910
820.743	960
823.069	940
825.393	974
827.717	1006
830.039	1002
832.362	986
834.683	1026
837.003	1028
839.324	1104
841.643	1086
843.961	1078
846.278	1086
848.594	1112
850.91	1126
853.227	1138
855.541	1146
857.855	1156
860.168	1168
862.48	1200
864.79	1246
867.101	1210
869.411	1204
871.721	1250
874.029	1274
876.336	1268
878.643	1296
880.95	1304
883.254	1318
885.559	1318
887.862	1368
890.166	1316
892.467	1410
894.77	1368
897.07	1372
899.371	1402
901.669	1398
903.968	1416
906.266	1426
908.563	1480
910.859	1502
913.154	1528
915.449	1486
917.742	1536
920.036	1532
922.329	1548
924.621	1568
926.911	1616
929.201	1646
931.49	1676
933.779	1606
936.068	1686
938.355	1644
940.64	1746
942.926	1756
945.212	1746
947.495	1816
949.779	1794
952.062	1874
954.344	1830
956.625	1798
958.905	1892
961.184	1902
963.464	1860
965.742	1948
968.02	1896
970.296	2008
972.572	2016
974.847	2018
977.121	2028
979.396	2074
981.669	2056
983.941	2088
986.212	2108
988.483	2120
990.753	2202
993.022	2194
995.29	2250
997.558	2212
999.825	2250
1002.09	2258
1004.36	2222
1006.62	2262
1008.89	2332
1011.15	2402
1013.41	2386
1015.67	2362
1017.93	2454
1020.19	2474
1022.45	2458
1024.71	2518
1026.97	2520
1029.23	2540
1031.49	2606
1033.74	2614
1036	2684
1038.25	2640
1040.5	2720
1042.76	2766
1045.01	2664
1047.26	2782
1049.51	2756
1051.76	2792
1054.01	2846
1056.26	2858
1058.51	2912
1060.75	2908
1063	2914
1065.25	2992
1067.49	3010
1069.73	2934
1071.98	3044
1074.22	3070
1076.46	3090
1078.7	3118
1080.94	3114
1083.18	3166
1085.42	3180
1087.66	3188
1089.9	3264
1092.14	3214
1094.37	3282
1096.61	3246
1098.84	3314
1101.08	3282
1103.31	3352
1105.54	3356
1107.77	3394
1110	3334
1112.23	3336
1114.46	3370
1116.69	3470
1118.92	3428
1121.15	3462
1123.37	3542
1125.6	3532
1127.83	3512
1130.05	3544
1132.27	3576
1134.5	3582
1136.72	3590
1138.94	3670
1141.16	3716
1143.38	3658
1145.6	3694
1147.82	3694
1150.04	3778
1152.26	3768
1154.47	3796
1156.69	3760
1158.9	3778
1161.12	3814
1163.33	3814
1165.54	3850
1167.76	3816
1169.97	3822
1172.18	3782
1174.39	3792
1176.6	3844
1178.81	3796
1181.02	3886
1183.22	3858
1185.43	3820
1187.63	3838
1189.84	3816
1192.04	3816
1194.25	3754
1196.45	3754
1198.65	3818
1200.85	3704
1203.05	3808
1205.25	3724
1207.45	3754
1209.65	3682
1211.85	3666
1214.05	3602
1216.24	3640
1218.44	3662
1220.64	3584
1222.83	3626
1225.02	3568
1227.22	3554
1229.41	3600
1231.6	3508
1233.79	3484
1235.98	3470
1238.17	3460
1240.36	3444
1242.55	3448
1244.73	3434
1246.92	3432
1249.11	3308
1251.29	3364
1253.48	3382
1255.66	3436
1257.84	3326
1260.03	3318
1262.21	3346
1264.39	3218
1266.57	3276
1268.75	3152
1270.93	3184
1273.11	3142
1275.28	3162
1277.46	3198
1279.64	3114
1281.81	3074
1283.98	3046.46
1286.16	3039.02
1288.33	3009.36
1290.5	2969.68
1292.68	2919.74
1294.85	2935.15
1297.02	2906.16
1299.19	2875.9
1301.36	2781.4
1303.53	2788.38
1305.69	2748.38
1307.86	2745.69
1310.03	2725.88
1312.19	2642.06
1314.36	2587.28
1316.52	2587.43
1318.68	2521.97
1320.85	2579.41
1323.01	2527.19
1325.17	2475
1327.33	2471.4
1329.49	2397.35
1331.65	2355.42
1333.81	2324.65
1335.97	2335.06
1338.12	2312.16
1340.28	2281.26
1342.44	2237.98
1344.59	2240.45
1346.75	2196.81
1348.9	2157.14
1351.05	2143.05
1353.2	2149.29
1355.36	2089.96
1357.51	2111.25
1359.66	2080.61
1361.81	2014.55
1363.96	1991.92
1366.1	1997.82
1368.25	1957.93
1370.4	1965.96
1372.54	1920.84
1374.69	1872.01
1376.83	1857.44
1378.98	1869.56
1381.12	1835.26
1383.26	1765.52
1385.41	1773.27
1387.55	1757.31
1389.69	1746.08
1391.83	1732.41
1393.02	1676
1395.17	1744
1397.32	1726
1399.47	1662
1401.62	1706
1403.77	1668
1405.91	1630
1408.06	1590
1410.2	1626
1412.35	1612
1414.49	1546
1416.63	1606
1418.78	1572
1420.92	1548
1423.06	1564
1425.2	1518
1427.34	1512
1429.48	1538
1431.61	1488
1433.75	1502
1435.89	1504
1438.02	1454
1440.16	1436
1442.3	1448
1444.43	1484
1446.56	1444
1448.7	1408
1450.83	1406
1452.96	1408
1455.09	1362
1457.22	1338
1459.35	1368
1461.48	1338
1463.61	1316
1465.73	1336
1467.86	1324
1469.98	1316
1472.11	1334
1474.24	1294
1476.36	1306
1478.48	1312
1480.6	1284
1482.73	1332
1484.85	1322
1486.97	1282
1489.09	1260
1491.21	1190
1493.33	1224
1495.44	1234
1497.56	1230
1499.68	1266
1501.79	1218
1503.91	1196
1506.02	1234
1508.14	1196
1510.25	1188
1512.36	1184
1514.48	1150
1516.59	1152
1518.7	1162
1520.81	1142
1522.92	1128
1525.02	1120
1527.13	1134
1529.24	1140
1531.35	1072
1533.45	1094
1535.56	1092
1537.66	1078
1539.77	1098
1541.87	1068
1543.97	1046
1546.08	1082
1548.18	1038
1550.28	1046
1552.38	1052
1554.48	1032
1556.57	1036
1558.67	1050
1560.77	1046
1562.87	1040
1564.96	1038
1567.06	1026
1569.15	992
1571.25	992
1573.34	1012
1575.43	1006
1577.53	994
1579.62	1012
1581.71	980
1583.8	994
1585.89	952
1587.98	904
1590.06	968
1592.15	980
1594.24	942
1596.33	966
1598.41	956
1600.5	930
1602.58	938
1604.66	940
1606.75	958
1608.83	898
1610.91	938
1612.99	920
1615.07	912
1617.15	922
1619.23	934
1621.31	950
1623.39	968
1625.46	878
1627.54	916
1629.62	910
1631.69	878
1633.77	924
1635.84	892
1637.91	920
1639.99	924
1642.06	890
1644.13	874
1646.2	898
1648.27	858
1650.34	900
1652.41	904
1654.47	904
1656.54	900
1658.61	860
1660.67	914
1662.74	890
1664.81	882
1666.87	868
1668.93	878
1671	832
1673.06	872
1675.12	882
1677.18	850
1679.24	842
1681.3	824
1683.36	850
1685.42	834
1687.47	822
1689.53	884
1691.59	808
1693.64	824
1695.7	810
1697.75	820
1699.81	846
1701.86	822
1703.91	806
1705.97	798
1708.02	808
1710.07	810
1712.12	818
1714.17	804
1716.22	822
1718.26	808
1720.31	776
1722.36	824
1724.4	812
1726.45	798
1728.49	826
1730.54	798
1732.58	808
1734.63	794
1736.67	818
1738.71	798
1740.75	786
1742.79	784
1744.83	776
1746.87	810
1748.91	772
1750.95	756
1752.98	760
1755.02	812
1757.06	764
1759.09	812
1761.13	776
1763.16	812
1765.19	784
1767.23	762
1769.26	782
1771.29	784
1773.32	766
1775.35	756
1777.38	802
1779.41	750
1781.44	764
1783.47	790
1785.49	768
1787.52	780
1789.55	784
1791.57	778
1793.6	780
1795.62	784
1797.64	782
1799.67	798
1801.69	794
1803.71	768
1805.73	764
1807.75	746
1809.77	762
1811.79	768
1813.81	764
1815.83	776
1817.84	754
1819.86	734
1821.88	756
1823.89	762
1825.91	754
1827.92	750
1829.93	754
1831.95	770
1833.96	762
1835.97	746
1837.98	744
1839.99	762
1842	756
1844.01	768
1846.02	778
1848.03	752
1850.03	754
1852.04	754
1854.05	726
1856.05	724
1858.06	706
1860.06	758
1862.06	742
1864.07	708
1866.07	688
1868.07	720
1870.07	758
1872.07	740
1874.07	744
1876.07	710
1878.07	724
1880.07	748
1882.07	724
1884.06	734
1886.06	762
1888.05	752
1890.05	740
1892.04	742
1894.04	718
1896.03	736
1898.02	726
1900.01	714
1902	752
1903.99	716
1905.98	708
1907.97	732
1909.96	714
1911.95	738
1913.94	756
1915.93	736
1917.91	734
1919.9	690
1921.88	724
1923.87	718
1925.85	732
1927.83	712
1929.82	740
1931.8	728
1933.78	720
1935.76	716
1937.74	686
1939.72	704
1941.7	728
1943.68	712
1945.65	684
1947.63	736
1949.61	730
1951.58	730
1953.56	736
1955.53	712
1957.51	710
1959.48	732
1961.45	694
1963.43	706
1965.4	706
1967.37	694
1969.34	714
1971.31	704
1973.28	692
1975.25	712
1977.22	722
1979.18	696
1981.15	720
1983.12	688
1985.08	702
1987.05	686
1989.01	678
1990.97	702
1992.94	672
1994.9	726
1996.86	676
1998.82	704
2000.78	692
2002.74	688
2004.7	714
2006.66	686
2008.62	676
2010.58	700
2012.54	704
2014.49	700
2016.45	684
2018.4	684
2020.36	704
2022.31	682
2024.27	682
2026.22	672
2028.17	682
2030.12	728
2032.07	680
2034.03	682
2035.98	708
2037.93	692
2039.87	674
2041.82	696
2043.77	688
2045.72	664
2047.66	672
2049.61	674
2051.55	702
2053.5	688
2055.44	672
2057.39	684
2059.33	674
2061.27	688
2063.21	666
2065.15	678
2067.09	692
2069.03	682
2070.97	646
2072.91	680
2074.85	696
2076.79	684
2078.73	676
2080.66	666
2082.6	694
2084.53	662
2086.47	672
2088.4	672
2090.33	674
2092.27	672
2094.2	674
2096.13	650
2098.06	666
2099.99	664
2101.92	648
2103.85	694
2105.78	666
2107.71	646
2109.64	672
2111.56	644
2113.49	702
2115.41	686
2117.34	688
2119.26	644
2121.19	692
2123.11	654
2125.03	640
2126.96	638
2128.88	650
2130.8	666
2132.72	678
2134.64	668
2136.56	688
2138.48	634
2140.4	666
2142.31	656
2144.23	628
2146.15	674
2148.06	660
2149.98	652
2151.89	660
2153.81	652
2155.72	650
2157.63	680
2159.55	678
2161.46	648
2163.37	696
2165.28	652
2167.19	640
2169.1	650
2171.01	646
2172.91	658
2174.82	614
2176.73	654
2178.64	638
2180.54	610
2182.45	632
2184.35	624
2186.26	636
2188.16	608
2190.06	628
2191.96	656
2193.87	630
2195.77	658
2197.67	622
2199.57	624
2201.47	604
2203.37	630
2205.27	608
2207.16	640
2209.06	646
2210.96	616
2212.85	602
2214.75	638
2216.64	612
2218.54	612
2220.43	588
2222.33	606
2224.22	616.678
2226.11	630.098
2228	591.938
2229.89	605.256
2231.78	629.11
2233.67	581.306
2235.56	581.296
2237.45	608.299
2239.34	619.091
2241.23	605.047
2243.11	602.798
2245	603.733
2246.89	587.21
2248.77	583.962
2250.66	608.092
2252.54	573.556
2254.42	590.517
2256.31	564.702
2258.19	576.275
2260.07	588.611
2261.95	597.253
2263.83	576
2265.71	576.572
2267.59	594.284
2269.47	571.064
2271.35	582.329
2273.23	566.537
2275.1	578.465
2276.98	565.991
2278.86	566.12
2280.73	579.474
2282.61	569.331
2284.48	544.821
2286.36	551.98
2288.23	555.292
2290.1	532.463
2291.98	537.856
2293.85	535.357
2295.72	548.169
2297.59	553.576
2299.46	547.741
2301.33	554.335
2303.2	529.522
2305.06	547.662
2306.93	521.226
2308.8	543.97
2310.67	540.693
2312.53	528.42
2314.4	511.912
2316.26	507.022
2317.62	526
2319.5	536
2321.37	514
2323.24	526
2325.12	520
2326.99	504
2328.86	518
2330.73	492
2332.6	534
2334.47	512
2336.34	516
2338.2	518
2340.07	516
2341.94	492
2343.81	506
2345.67	498
2347.54	462
2349.4	488
2351.27	482
2353.13	498
2354.99	470
2356.86	496
2358.72	498
2360.58	470
2362.44	472
2364.3	504
2366.16	508
2368.02	498
2369.88	504
2371.74	468
2373.6	512
2375.45	508
2377.31	498
2379.17	468
2381.02	474
2382.88	470
2384.73	498
2386.58	482
2388.44	472
2390.29	448
2392.14	472
2393.99	464
2395.85	460
2397.7	464
2399.55	462
2401.4	428
2403.25	480
2405.09	474
2406.94	452
2408.79	456
2410.63	452
2412.48	462
2414.33	464
2416.17	444
2418.02	456
2419.86	458
2421.7	432
2423.55	444
2425.39	444
2427.23	454
2429.07	440
2430.91	420
2432.75	440
2434.59	446
2436.43	442
2438.27	434
2440.11	442
2441.95	414
2443.78	440
2445.62	414
2447.46	410
2449.29	444
2451.13	412
2452.96	394
2454.79	416
2456.63	400
2458.46	408
2460.29	420
2462.12	408
2463.95	414
2465.78	408
2467.61	390
2469.44	418
2471.27	390
2473.1	400
2474.93	396
2476.76	390
2478.58	380
2480.41	410
2482.23	392
2484.06	406
2485.88	384
2487.71	370
2489.53	398
2491.35	384
2493.18	358
2495	368
2496.82	374
2498.64	376
2500.46	382
2502.28	382
2504.1	368
2505.92	356
2507.74	368
2509.55	378
2511.37	336
2513.19	364
2515	358
2516.82	380
2518.63	366
2520.45	326
2522.26	342
2524.07	344
2525.89	330
2527.7	350
2529.51	338
2531.32	358
2533.13	364
2534.94	334
2536.75	320
2538.56	334
2540.37	334
2542.18	320
2543.98	328
2545.79	330
2547.6	322
2549.4	334
2551.21	338
2553.01	336
2554.82	330
2556.62	338
2558.42	306
2560.23	336
2562.03	322
2563.83	314
2565.63	312
2567.43	296
2569.23	322
2571.03	296
2572.83	302
2574.63	322
2576.43	286
2578.22	306
2580.02	308
2581.82	306
2583.61	296
2585.41	298
2587.2	312
2589	300
2590.79	312
2592.58	278
2594.38	282
2596.17	282
2597.96	290
2599.75	288
2601.54	276
2603.33	280
2605.12	280
2606.91	266
2608.7	292
2610.49	260
2612.27	268
2614.06	284
2615.85	272
2617.63	272
2619.42	280
2621.2	264
2622.99	260
2624.77	248
2626.55	264
2628.34	258
2630.12	254
2631.9	256
2633.68	262
2635.46	246
2637.24	258
2639.02	272
2640.8	256
2642.58	256
2644.36	258
2646.14	244
2647.91	248
2649.69	254
2651.46	260
2653.24	234
2655.01	224
2656.79	238
2658.56	222
2660.34	238
2662.11	248
2663.88	230
2665.65	236
2667.42	228
2669.2	232
2670.96	214
2672.73	228
2674.5	234
2676.27	236
2678.04	242
2679.81	220
2681.58	250
2683.34	226
2685.11	212
2686.87	228
2688.64	216
2690.4	214
2692.17	228
2693.93	232
2695.69	228
2697.46	210
2699.22	210
2700.98	218
2702.74	220
2704.5	220
2706.26	222
2708.02	212
2709.78	228
2711.54	206
2713.3	194
2715.05	214
2716.81	206
2718.57	220
2720.32	206
2722.08	212
2723.83	206
2725.59	204
2727.34	204
2729.09	198
2730.85	186
2732.6	174
2734.35	190
2736.1	214
2737.85	206
2739.6	188
2741.35	190
2743.1	174
2744.85	194
2746.6	198
2748.35	196
2750.09	188
2751.84	190
2753.59	194
2755.33	188
2757.08	184
2758.82	174
2760.57	176
2762.31	184
2764.05	176
2765.79	180
2767.54	180
2769.28	170
2771.02	190
2772.76	176
2774.5	166
2776.24	166
2777.98	170
2779.72	166
2781.46	178
2783.19	172
2784.93	162
2786.67	170
2788.4	158
2790.14	160
2791.87	156
2793.61	166
2795.34	142
2797.07	154
2798.81	156
2800.54	146
2802.27	158
2804	156
2805.74	156
2807.47	150
2809.2	152
2810.93	152
2812.65	144
2814.38	146
2816.11	154
2817.84	142
2819.56	152
2821.29	164
2823.02	150
2824.74	156
2826.47	144
2828.19	148
2829.92	146
2831.64	136
2833.36	144
2835.09	134
2836.81	144
2838.53	148
2840.25	132
2841.97	128
2843.69	144
2845.41	132
2847.13	146
2848.85	134
2850.57	130
2852.28	140
2854	126
2855.72	118
2857.43	132
2859.15	128
2860.86	132
2862.58	124
2864.29	124
2866.01	134
2867.72	126
2869.43	124
2871.14	124
2872.86	110
2874.57	130
2876.28	104
2877.99	122
2879.7	106
2881.41	124
2883.11	108
2884.82	116
2886.53	108
2888.24	120
2889.94	102
2891.65	122
2893.36	118
2895.06	120
2896.77	116
2898.47	108
2900.17	120
2901.88	118
2903.58	118
2905.28	122
2906.98	114
2908.69	114
2910.39	110
2912.09	102
2913.79	108
2915.49	102
2917.19	116
2918.88	106
2920.58	118
2922.28	106
2923.98	106
2925.67	102
2927.37	112
2929.06	114
2930.76	108
2932.45	110
2934.15	110
2935.84	96
2937.53	104
2939.23	96
2940.92	100
2942.61	98
2944.3	102
2945.99	90
2947.68	102
2949.37	116
2951.06	100
2952.75	100
2954.44	100
2956.12	94
2957.81	100
2959.5	106
2961.18	100
2962.87	102
2964.56	96
2966.24	88
2967.92	94
2969.61	102
2971.29	96
2972.97	90
2974.66	98
2976.34	94
2978.02	96
2979.7	92
2981.38	94
2983.06	92
2984.74	92
2986.42	84
2988.1	92
2989.78	88
2991.45	84
2993.13	88
2994.81	88
2996.48	90
2998.16	98
2999.83	92