File: muestras/papalo/leaf_07.txt
#Acq. time (s)=	10
#Accumulations=	1
#Range (cm-¹)=	200...3000
#Windows=	3
#Autofocus=	Off
#AutoExposure=	Off
#Spike filter=	Off
#Delay time (s)=	0
#Binning=	1
#Readout mode=	Signal
#DeNoise=	Off
#ICS correction=	Off
#Dark correction=	Off
#Inst. Process=	Off
#Instrument=	LabRAM HR Evol
#Detector=	Syncerity OE
#Objective=	x100_VIS
#Grating=	600 (500nm)
#ND Filter=	0.01%
#Laser=	633nm_Edge
#Hole=	49.98
#Range=	Visible
#Project=	Omar
#Sample=	03-07-23
#Site=	papal
#Title=	leaf
#Remark=
#Date=	03.07.2023 16:56
#Acquired=	03.07.2023 16:56:48
201.713	46
204.247	38
206.778	40
209.311	44
211.84	38
214.371	42
216.899	46
219.428	44
221.955	42
224.482	42
227.007	40
229.531	42
232.055	48
234.579	38
237.1	38
239.621	44
242.141	40
244.661	44
247.179	40
249.698	40
252.215	50
254.731	40
257.246	42
259.761	40
262.273	54
264.786	40
267.298	58
269.809	40
272.319	34
274.828	44
277.336	46
279.844	56
282.351	44
284.855	50
287.361	46
289.866	48
292.368	42
294.871	52
297.372	54
299.873	54
302.372	48
304.872	50
307.37	54
309.866	58
312.364	48
314.859	62
317.353	54
319.848	46
322.341	58
324.833	48
327.324	50
329.814	50
332.304	46
334.792	56
337.28	58
339.767	58
342.254	56
344.739	60
347.224	48
349.708	64
352.191	60
354.673	52
357.155	58
359.634	46
362.114	60
364.593	64
367.07	54
369.548	54
372.024	54
374.499	56
376.974	58
379.447	60
381.92	60
384.392	60
386.864	52
389.333	54
391.802	70
394.272	62
396.739	74
399.206	60
401.673	72
404.138	62
406.602	66
409.066	56
411.528	72
413.99	66
416.451	62
418.911	56
421.371	62
423.83	64
426.288	66
428.745	76
431.201	78
433.657	76
436.111	72
438.565	72
441.017	74
443.469	62
445.921	72
448.37	82
450.821	64
453.27	80
455.717	76
458.165	76
460.61	80
463.056	76
465.5	74
467.945	78
470.387	92
472.829	76
475.271	82
477.711	64
480.15	78
482.589	88
485.027	80
487.465	86
489.901	78
492.337	82
494.771	88
497.205	94
499.638	86
502.07	80
504.502	80
506.933	82
509.363	88
511.792	80
514.219	80
516.647	88
519.073	88
521.5	100
523.924	90
526.348	76
528.772	92
531.194	86
533.616	80
536.036	108
538.457	92
540.875	90
543.294	84
545.712	90
548.128	90
550.545	102
552.959	84
555.373	104
557.788	92
560.2	106
562.612	100
565.023	104
567.433	94
569.843	92
572.251	98
574.659	112
577.066	94
579.472	106
581.878	100
584.283	92
586.687	106
589.09	122
591.493	106
593.893	98
596.294	130
598.694	108
601.093	100
603.491	106
605.889	112
608.285	118
610.682	108
613.076	116
615.471	106
617.864	112
620.256	116
622.648	124
625.039	120
627.429	132
629.819	124
632.208	120
634.595	130
636.982	126
639.369	118
641.755	142
644.139	126
646.523	136
648.906	138
651.288	142
653.67	138
656.051	124
658.429	140
660.808	136
663.187	138
665.565	150
667.942	144
670.317	140
672.692	152
675.067	154
677.44	140
679.813	154
682.184	138
684.556	158
686.926	162
689.296	150
691.664	160
694.033	160
696.4	156
698.766	172
701.133	156
703.497	168
705.861	160
708.224	174
710.586	180
712.949	182
715.31	174
717.67	170
720.029	194
722.388	204
724.746	190
727.103	174
729.458	172
731.814	198
734.168	196
736.523	186
738.876	202
741.227	194
743.579	172
745.931	194
748.28	204
750.629	212
752.977	222
755.325	214
757.672	224
760.018	232
762.363	218
764.708	216
767.052	220
769.394	222
771.737	218
774.078	238
776.419	228
778.758	212
781.097	224
783.435	228
785.773	238
788.11	264
790.446	238
792.781	256
795.115	248
797.449	244
799.782	262
802.115	272
804.446	264
806.777	270
809.106	270
811.435	274
813.764	278
816.091	284
818.418	298
820.743	296
823.069	288
825.393	312
827.717	286
830.039	316
832.362	308
834.683	308
837.003	326
839.324	326
841.643	334
843.961	314
846.278	336
848.594	360
850.91	346
853.227	338
855.541	356
857.855	356
860.168	370
862.48	358
864.79	342
867.101	380
869.411	356
871.721	372
874.029	392
876.336	370
878.643	388
880.95	384
883.254	386
885.559	388
887.862	402
890.166	398
892.467	406
894.77	372
897.07	422
899.371	414
901.669	412
903.968	414
906.266	420
908.563	426
910.859	444
913.154	472
915.449	448
917.742	454
920.036	466
922.329	464
924.621	480
926.911	510
929.201	448
931.49	456
933.779	482
936.068	480
938.355	498
940.64	498
942.926	524
945.212	508
947.495	512
949.779	550
952.062	514
954.344	552
956.625	544
958.905	554
961.184	558
963.464	556
965.742	568
968.02	564
970.296	560
972.572	564
974.847	564
977.121	578
979.396	600
981.669	592
983.941	604
986.212	626
988.483	618
990.753	648
993.022	642
995.29	636
997.558	652
999.825	636
1002.09	674
1004.36	636
1006.62	682
1008.89	692
1011.15	658
1013.41	690
1015.67	700
1017.93	712
1020.19	666
1022.45	724
1024.71	704
1026.97	734
1029.23	778
1031.49	724
1033.74	732
1036	776
1038.25	780
1040.5	776
1042.76	826
1045.01	804
1047.26	794
1049.51	816
1051.76	784
1054.01	822
1056.26	822
1058.51	838
1060.75	804
1063	880
1065.25	914
1067.49	870
1069.73	862
1071.98	820
1074.22	898
1076.46	876
1078.7	916
1080.94	910
1083.18	892
1085.42	906
1087.66	960
1089.9	902
1092.14	926
1094.37	910
1096.61	898
1098.84	982
1101.08	934
1103.31	976
1105.54	944
1107.77	992
1110	978
1112.23	980
1114.46	996
1116.69	1016
1118.92	1002
1121.15	994
1123.37	982
1125.6	980
1127.83	1030
1130.05	1068
1132.27	1024
1134.5	1030
1136.72	1034
1138.94	1050
1141.16	1090
1143.38	1060
1145.6	1030
1147.82	1094
1150.04	1056
1152.26	1082
1154.47	1050
1156.69	1078
1158.9	1094
1161.12	1092
1163.33	1084
1165.54	1082
1167.76	1134
1169.97	1122
1172.18	1100
1174.39	1102
1176.6	1104
1178.81	1078
1181.02	1074
1183.22	1086
1185.43	1084
1187.63	1140
1189.84	1034
1192.04	1088
1194.25	1090
1196.45	1068
1198.65	1126
1200.85	1076
1203.05	1086
1205.25	1088
1207.45	1102
1209.65	1068
1211.85	1094
1214.05	1062
1216.24	1048
1218.44	1058
1220.64	1040
1222.83	1092
1225.02	1038
1227.22	1008
1229.41	1094
1231.6	1044
1233.79	1038
1235.98	1024
1238.17	1054
1240.36	996
1242.55	1062
1244.73	1022
1246.92	1004
1249.11	1014
1251.29	1018
1253.48	1020
1255.66	1030
1257.84	1000
1260.03	964
1262.21	972
1264.39	946
1266.57	964
1268.75	958
1270.93	988
1273.11	968
1275.28	968
1277.46	936
1279.64	980
1281.81	940
1283.98	897.935
1286.16	898.331
1288.33	915.421
1290.5	882.275
1292.68	915.1
1294.85	891.81
1297.02	885.263
1299.19	880.53
1301.36	875.247
1303.53	825.665
1305.69	864.897
1307.86	883.322
1310.03	843.079
1312.19	825.479
1314.36	844.974
1316.52	828.278
1318.68	791.312
1320.85	792.439
1323.01	814.668
1325.17	782.516
1327.33	795.489
1329.49	805.307
1331.65	757.791
1333.81	761.657
1335.97	745.608
1338.12	739.335
1340.28	727.442
1342.44	753.534
1344.59	732.998
1346.75	737.826
1348.9	703.049
1351.05	716.348
1353.2	733.174
1355.36	727.402
1357.51	708
1359.66	707.824
1361.81	677.404
1363.96	671.552
1366.1	661.511
1368.25	674.109
1370.4	677.749
1372.54	663.237
1374.69	652.07
1376.83	668.023
1378.98	643.775
1381.12	625.997
1383.26	667.567
1385.41	639.441
1387.55	619.271
1389.69	596.462
1391.83	627.218
1393.02	614
1395.17	614
1397.32	612
1399.47	600
1401.62	612
1403.77	586
1405.91	542
1408.06	610
1410.2	578
1412.35	580
1414.49	582
1416.63	560
1418.78	584
1420.92	550
1423.06	560
1425.2	574
1427.34	570
1429.48	556
1431.61	536
1433.75	526
1435.89	574
1438.02	528
1440.16	542
1442.3	530
1444.43	520
1446.56	526
1448.7	518
1450.83	534
1452.96	542
1455.09	512
1457.22	510
1459.35	506
1461.48	504
1463.61	512
1465.73	514
1467.86	522
1469.98	488
1472.11	506
1474.24	492
1476.36	482
1478.48	490
1480.6	488
1482.73	494
1484.85	474
1486.97	478
1489.09	462
1491.21	464
1493.33	462
1495.44	478
1497.56	470
1499.68	462
1501.79	450
1503.91	466
1506.02	452
1508.14	456
1510.25	466
1512.36	458
1514.48	466
1516.59	440
1518.7	450
1520.81	456
1522.92	452
1525.02	440
1527.13	458
1529.24	430
1531.35	430
1533.45	426
1535.56	438
1537.66	438
1539.77	420
1541.87	438
1543.97	412
1546.08	416
1548.18	430
1550.28	412
1552.38	416
1554.48	386
1556.57	422
1558.67	424
1560.77	392
1562.87	394
1564.96	410
1567.06	398
1569.15	396
1571.25	396
1573.34	400
1575.43	402
1577.53	394
1579.62	412
1581.71	386
1583.8	382
1585.89	374
1587.98	384
1590.06	378
1592.15	394
1594.24	394
1596.33	404
1598.41	352
1600.5	352
1602.58	378
1604.66	374
1606.75	384
1608.83	394
1610.91	372
1612.99	404
1615.07	350
1617.15	364
1619.23	370
1621.31	360
1623.39	356
1625.46	372
1627.54	366
1629.62	382
1631.69	388
1633.77	378
1635.84	392
1637.91	352
1639.99	352
1642.06	356
1644.13	362
1646.2	372
1648.27	376
1650.34	378
1652.41	352
1654.47	364
1656.54	376
1658.61	360
1660.67	366
1662.74	344
1664.81	362
1666.87	338
1668.93	358
1671	338
1673.06	352
1675.12	356
1677.18	356
1679.24	346
1681.3	346
1683.36	328
1685.42	346
1687.47	332
1689.53	334
1691.59	360
1693.64	336
1695.7	344
1697.75	348
1699.81	348
1701.86	338
1703.91	334
1705.97	336
1708.02	332
1710.07	348
1712.12	334
1714.17	322
1716.22	318
1718.26	314
1720.31	332
1722.36	322
1724.4	332
1726.45	340
1728.49	342
1730.54	364
1732.58	316
1734.63	334
1736.67	322
1738.71	354
1740.75	324
1742.79	336
1744.83	316
1746.87	320
1748.91	338
1750.95	330
1752.98	308
1755.02	316
1757.06	326
1759.09	354
1761.13	324
1763.16	340
1765.19	314
1767.23	340
1769.26	338
1771.29	306
1773.32	324
1775.35	348
1777.38	328
1779.41	324
1781.44	324
1783.47	318
1785.49	328
1787.52	310
1789.55	312
1791.57	340
1793.6	334
1795.62	328
1797.64	320
1799.67	344
1801.69	336
1803.71	350
1805.73	316
1807.75	342
1809.77	336
1811.79	340
1813.81	332
1815.83	308
1817.84	318
1819.86	320
1821.88	362
1823.89	310
1825.91	336
1827.92	326
1829.93	340
1831.95	310
1833.96	342
1835.97	326
1837.98	308
1839.99	326
1842	316
1844.01	314
1846.02	312
1848.03	332
1850.03	310
1852.04	304
1854.05	312
1856.05	308
1858.06	326
1860.06	312
1862.06	314
1864.07	314
1866.07	318
1868.07	352
1870.07	284
1872.07	336
1874.07	322
1876.07	322
1878.07	306
1880.07	312
1882.07	310
1884.06	320
1886.06	312
1888.05	308
1890.05	322
1892.04	314
1894.04	290
1896.03	292
1898.02	324
1900.01	310
1902	322
1903.99	320
1905.98	314
1907.97	338
1909.96	332
1911.95	306
1913.94	328
1915.93	292
1917.91	326
1919.9	320
1921.88	302
1923.87	316
1925.85	330
1927.83	308
1929.82	328
1931.8	318
1933.78	338
1935.76	300
1937.74	298
1939.72	292
1941.7	314
1943.68	328
1945.65	310
1947.63	322
1949.61	322
1951.58	308
1953.56	322
1955.53	302
1957.51	302
1959.48	310
1961.45	318
1963.43	302
1965.4	322
1967.37	308
1969.34	302
1971.31	322
1973.28	326
1975.25	308
1977.22	298
1979.18	292
1981.15	324
1983.12	324
1985.08	324
1987.05	338
1989.01	322
1990.97	290
1992.94	330
1994.9	314
1996.86	330
1998.82	316
2000.78	304
2002.74	308
2004.7	314
2006.66	332
2008.62	326
2010.58	304
2012.54	292
2014.49	322
2016.45	298
2018.4	308
2020.36	302
2022.31	300
2024.27	314
2026.22	290
2028.17	307
2030.12	316
2032.07	312
2034.03	290
2035.98	314
2037.93	300
2039.87	312
2041.82	322
2043.77	296
2045.72	332
2047.66	310
2049.61	308
2051.55	306
2053.5	310
2055.44	304
2057.39	310
2059.33	308
2061.27	310
2063.21	314
2065.15	302
2067.09	306
2069.03	314
2070.97	320
2072.91	306
2074.85	306
2076.79	302
2078.73	306
2080.66	300
2082.6	302
2084.53	336
2086.47	312
2088.4	302
2090.33	328
2092.27	304
2094.2	308
2096.13	332
2098.06	304
2099.99	290
2101.92	304
2103.85	308
2105.78	270
2107.71	290
2109.64	286
2111.56	286
2113.49	294
2115.41	280
2117.34	286
2119.26	278
2121.19	288
2123.11	312
2125.03	290
2126.96	280
2128.88	324
2130.8	308
2132.72	296
2134.64	298
2136.56	308
2138.48	298
2140.4	298
2142.31	300
2144.23	300
2146.15	278
2148.06	296
2149.98	302
2151.89	296
2153.81	290
2155.72	302
2157.63	300
2159.55	276
2161.46	306
2163.37	294
2165.28	294
2167.19	296
2169.1	302
2171.01	286
2172.91	292
2174.82	292
2176.73	300
2178.64	292
2180.54	286
2182.45	296
2184.35	306
2186.26	294
2188.16	280
2190.06	304
2191.96	284
2193.87	276
2195.77	310
2197.67	280
2199.57	272
2201.47	268
2203.37	278
2205.27	278
2207.16	276
2209.06	282
2210.96	272
2212.85	272
2214.75	284
2216.64	302
2218.54	270
2220.43	300
2222.33	290
2224.22	287.796
2226.11	289.044
2228	279.868
2229.89	297.54
2231.78	285.182
2233.67	273.995
2235.56	287.044
2237.45	287.38
2239.34	295.88
2241.23	278.954
2243.11	298.497
2245	277.698
2246.89	291.005
2248.77	276.682
2250.66	274.745
2252.54	270.803
2254.42	281.174
2256.31	265.68
2258.19	300.716
2260.07	274.78
2261.95	298.404
2263.83	276.9
2265.71	280.098
2267.59	290.546
2269.47	276.664
2271.35	281.05
2273.23	276.087
2275.1	294.544
2276.98	291.537
2278.86	282.041
2280.73	276.928
2282.61	274.788
2284.48	265.963
2286.36	285.685
2288.23	273.973
2290.1	270.56
2291.98	277.656
2293.85	261.48
2295.72	270.646
2297.59	276.744
2299.46	265.996
2301.33	276.546
2303.2	273.673
2305.06	274.338
2306.93	276.296
2308.8	257.202
2310.67	254.55
2312.53	253.25
2314.4	264.217
2316.26	257.638
2317.62	254
2319.5	264
2321.37	262
2323.24	252
2325.12	254
2326.99	260
2328.86	282
2330.73	266
2332.6	276
2334.47	270
2336.34	274
2338.2	262
2340.07	258
2341.94	260
2343.81	246
2345.67	232
2347.54	256
2349.4	252
2351.27	250
2353.13	254
2354.99	258
2356.86	242
2358.72	234
2360.58	260
2362.44	250
2364.3	244
2366.16	256
2368.02	274
2369.88	248
2371.74	236
2373.6	242
2375.45	252
2377.31	246
2379.17	238
2381.02	254
2382.88	248
2384.73	228
2386.58	254
2388.44	236
2390.29	246
2392.14	244
2393.99	230
2395.85	248
2397.7	254
2399.55	250
2401.4	238
2403.25	224
2405.09	244
2406.94	240
2408.79	234
2410.63	234
2412.48	262
2414.33	236
2416.17	228
2418.02	238
2419.86	242
2421.7	236
2423.55	228
2425.39	240
2427.23	220
2429.07	228
2430.91	222
2432.75	226
2434.59	228
2436.43	218
2438.27	232
2440.11	228
2441.95	230
2443.78	230
2445.62	214
2447.46	252
2449.29	230
2451.13	214
2452.96	208
2454.79	212
2456.63	206
2458.46	216
2460.29	224
2462.12	224
2463.95	220
2465.78	192
2467.61	198
2469.44	216
2471.27	214
2473.1	206
2474.93	212
2476.76	218
2478.58	208
2480.41	210
2482.23	204
2484.06	206
2485.88	210
2487.71	194
2489.53	194
2491.35	200
2493.18	212
2495	184
2496.82	182
2498.64	204
2500.46	198
2502.28	170
2504.1	176
2505.92	182
2507.74	212
2509.55	196
2511.37	192
2513.19	194
2515	184
2516.82	188
2518.63	186
2520.45	202
2522.26	180
2524.07	186
2525.89	202
2527.7	204
2529.51	188
2531.32	186
2533.13	196
2534.94	166
2536.75	172
2538.56	190
2540.37	194
2542.18	184
2543.98	168
2545.79	178
2547.6	186
2549.4	180
2551.21	174
2553.01	178
2554.82	168
2556.62	184
2558.42	172
2560.23	174
2562.03	162
2563.83	164
2565.63	168
2567.43	182
2569.23	172
2571.03	172
2572.83	180
2574.63	174
2576.43	172
2578.22	168
2580.02	176
2581.82	168
2583.61	178
2585.41	184
2587.2	166
2589	162
2590.79	164
2592.58	182
2594.38	166
2596.17	160
2597.96	162
2599.75	158
2601.54	144
2603.33	148
2605.12	156
2606.91	156
2608.7	146
2610.49	158
2612.27	160
2614.06	150
2615.85	154
2617.63	150
2619.42	142
2621.2	150
2622.99	154
2624.77	146
2626.55	168
2628.34	158
2630.12	154
2631.9	154
2633.68	152
2635.46	134
2637.24	152
2639.02	152
2640.8	136
2642.58	148
2644.36	142
2646.14	142
2647.91	126
2649.69	150
2651.46	134
2653.24	134
2655.01	142
2656.79	140
2658.56	138
2660.34	138
2662.11	134
2663.88	152
2665.65	134
2667.42	142
2669.2	150
2670.96	152
2672.73	140
2674.5	124
2676.27	142
2678.04	122
2679.81	140
2681.58	132
2683.34	136
2685.11	140
2686.87	120
2688.64	126
2690.4	120
2692.17	136
2693.93	128
2695.69	132
2697.46	112
2699.22	128
2700.98	122
2702.74	112
2704.5	120
2706.26	130
2708.02	120
2709.78	126
2711.54	134
2713.3	128
2715.05	134
2716.81	124
2718.57	124
2720.32	118
2722.08	118
2723.83	122
2725.59	120
2727.34	114
2729.09	132
2730.85	112
2732.6	122
2734.35	110
2736.1	114
2737.85	118
2739.6	122
2741.35	120
2743.1	114
2744.85	104
2746.6	118
2748.35	112
2750.09	108
2751.84	112
2753.59	104
2755.33	116
2757.08	104
2758.82	108
2760.57	96
2762.31	104
2764.05	120
2765.79	100
2767.54	108
2769.28	104
2771.02	118
2772.76	108
2774.5	122
2776.24	118
2777.98	94
2779.72	104
2781.46	92
2783.19	112
2784.93	100
2786.67	106
2788.4	104
2790.14	94
2791.87	106
2793.61	100
2795.34	108
2797.07	96
2798.81	98
2800.54	100
2802.27	98
2804	86
2805.74	102
2807.47	104
2809.2	94
2810.93	110
2812.65	106
2814.38	102
2816.11	94
2817.84	92
2819.56	88
2821.29	90
2823.02	96
2824.74	90
2826.47	88
2828.19	92
2829.92	82
2831.64	88
2833.36	86
2835.09	80
2836.81	88
2838.53	82
2840.25	90
2841.97	96
2843.69	76
2845.41	86
2847.13	88
2848.85	70
2850.57	86
2852.28	80
2854	82
2855.72	80
2857.43	88
2859.15	88
2860.86	84
2862.58	84
2864.29	86
2866.01	86
2867.72	88
2869.43	82
2871.14	82
2872.86	80
2874.57	74
2876.28	80
2877.99	82
2879.7	78
2881.41	94
2883.11	82
2884.82	76
2886.53	78
2888.24	68
2889.94	80
2891.65	84
2893.36	82
2895.06	74
2896.77	68
2898.47	68
2900.17	84
2901.88	76
2903.58	76
2905.28	76
2906.98	82
2908.69	68
2910.39	68
2912.09	80
2913.79	80
2915.49	80
2917.19	72
2918.88	72
2920.58	62
2922.28	76
2923.98	66
2925.67	64
2927.37	78
2929.06	76
2930.76	78
2932.45	72
2934.15	72
2935.84	64
2937.53	62
2939.23	70
2940.92	64
2942.61	70
2944.3	66
2945.99	72
2947.68	60
2949.37	70
2951.06	72
2952.75	62
2954.44	68
2956.12	78
2957.81	66
2959.5	64
2961.18	62
2962.87	78
2964.56	74
2966.24	68
2967.92	72
2969.61	68
2971.29	72
2972.97	70
2974.66	64
2976.34	68
2978.02	72
2979.7	50
2981.38	68
2983.06	68
2984.74	66
2986.42	66
2988.1	60
2989.78	70
2991.45	72
2993.13	58
2994.81	64
2996.48	64
2998.16	56
2999.83	64