File: muestras/papalo/leaf_15.txt
#Acq. time (s)=	10
#Accumulations=	1
#Range (cm-¹)=	200...3000
#Windows=	3
#Autofocus=	Off
#AutoExposure=	Off
#Spike filter=	Off
#Delay time (s)=	0
#Binning=	1
#Readout mode=	Signal
#DeNoise=	Off
#ICS correction=	Off
#Dark correction=	Off
#Inst. Process=	Off
#Instrument=	LabRAM HR Evol
#Detector=	Syncerity OE
#Objective=	x100_VIS
#Grating=	600 (500nm)
#ND Filter=	0.01%
#Laser=	633nm_Edge
#Hole=	100.021
#Range=	Visible
#Project=	Omar
#Sample=	03-07-23
#Site=	papal
#Title=	leaf
#Remark=
#Date=	03.07.2023 17:06
#Acquired=	03.07.2023 17:06:18
201.713	100
204.247	106
206.778	108
209.311	100
211.84	104
214.371	112
216.899	92
219.428	102
221.955	116
224.482	116
227.007	106
229.531	112
232.055	118
234.579	114
237.1	114
239.621	116
242.141	122
244.661	128
247.179	120
249.698	134
252.215	134
254.731	116
257.246	128
259.761	140
262.273	138
264.786	136
267.298	136
269.809	132
272.319	138
274.828	134
277.336	134
279.844	130
282.351	152
284.855	148
287.361	154
289.866	150
292.368	144
294.871	158
297.372	154
299.873	168
302.372	164
304.872	152
307.37	164
309.866	168
312.364	162
314.859	160
317.353	176
319.848	180
322.341	170
324.833	176
327.324	180
329.814	180
332.304	178
334.792	190
337.28	184
339.767	206
342.254	204
344.739	206
347.224	202
349.708	186
352.191	196
354.673	198
357.155	236
359.634	220
362.114	204
364.593	222
367.07	228
369.548	218
372.024	232
374.499	222
376.974	218
379.447	240
381.92	226
384.392	234
386.864	244
389.333	246
391.802	254
394.272	248
396.739	254
399.206	286
401.673	266
404.138	252
406.602	274
409.066	234
411.528	266
413.99	270
416.451	282
418.911	276
421.371	272
423.83	288
426.288	272
428.745	292
431.201	304
433.657	306
436.111	304
438.565	302
441.017	298
443.469	312
445.921	312
448.37	306
450.821	296
453.27	308
455.717	336
458.165	312
460.61	316
463.056	348
465.5	330
467.945	336
470.387	350
472.829	348
475.271	332
477.711	356
480.15	356
482.589	366
485.027	394
487.465	354
489.901	388
492.337	392
494.771	362
497.205	392
499.638	386
502.07	396
504.502	400
506.933	388
509.363	406
511.792	410
514.219	408
516.647	442
519.073	430
521.5	422
523.924	428
526.348	436
528.772	430
531.194	434
533.616	412
536.036	472
538.457	440
540.875	458
543.294	430
545.712	454
548.128	458
550.545	446
552.959	478
555.373	496
557.788	458
560.2	492
562.612	498
565.023	524
567.433	480
569.843	486
572.251	520
574.659	558
577.066	510
579.472	532
581.878	560
584.283	540
586.687	566
589.09	572
591.493	560
593.893	610
596.294	588
598.694	564
601.093	588
603.491	606
605.889	620
608.285	592
610.682	612
613.076	642
615.471	662
617.864	668
620.256	628
622.648	658
625.039	662
627.429	688
629.819	690
632.208	686
634.595	716
636.982	730
639.369	724
641.755	736
644.139	756
646.523	764
648.906	702
651.288	752
653.67	776
656.051	782
658.429	780
660.808	800
663.187	784
665.565	788
667.942	816
670.317	820
672.692	814
675.067	866
677.44	854
679.813	836
682.184	886
684.556	888
686.926	874
689.296	870
691.664	920
694.033	922
696.4	948
698.766	936
701.133	982
703.497	1000
705.861	988
708.224	1054
710.586	984
712.949	1038
715.31	1068
717.67	1048
720.029	1074
722.388	1066
724.746	1102
727.103	1104
729.458	1080
731.814	1164
734.168	1200
736.523	1178
738.876	1210
741.227	1216
743.579	1232
745.931	1212
748.28	1220
750.629	1228
752.977	1238
755.325	1250
757.672	1262
760.018	1318
762.363	1296
764.708	1266
767.052	1324
769.394	1376
771.737	1386
774.078	1396
776.419	1362
778.758	1454
781.097	1466
783.435	1490
785.773	1486
788.11	1474
790.446	1498
792.781	1556
795.115	1528
797.449	1544
799.782	1580
802.115	1602
804.446	1636
806.777	1700
809.106	1650
811.435	1654
813.764	1724
816.091	1718
818.418	1704
820.743	1774
823.069	1800
825.393	1826
827.717	1842
830.039	1926
832.362	1930
834.683	1854
837.003	1918
839.324	1938
841.643	2046
843.961	2042
846.278	2010
848.594	2080
850.91	2064
853.227	2154
855.541	2174
857.855	2136
860.168	2222
862.48	2258
864.79	2274
867.101	2292
869.411	2284
871.721	2342
874.029	2364
876.336	2378
878.643	2396
880.95	2452
883.254	2458
885.559	2490
887.862	2558
890.166	2544
892.467	2644
894.77	2596
897.07	2624
899.371	2636
901.669	2670
903.968	2768
906.266	2780
908.563	2722
910.859	2790
913.154	2874
915.449	2850
917.742	2884
920.036	2920
922.329	2878
924.621	2976
926.911	2964
929.201	2984
931.49	3084
933.779	3104
936.068	3206
938.355	3172
940.64	3182
942.926	3206
945.212	3252
947.495	3280
949.779	3432
952.062	3396
954.344	3404
956.625	3510
958.905	3496
961.184	3592
963.464	3558
965.742	3618
968.02	3646
970.296	3730
972.572	3716
974.847	3770
977.121	3856
979.396	3812
981.669	3882
983.941	3878
986.212	3932
988.483	4000
990.753	4060
993.022	4050
995.29	4184
997.558	4178
999.825	4208
1002.09	4222
1004.36	4326
1006.62	4358
1008.89	4414
1011.15	4356
1013.41	4460
1015.67	4486
1017.93	4568
1020.19	4560
1022.45	4652
1024.71	4768
1026.97	4728
1029.23	4808
1031.49	4942
1033.74	4856
1036	4934
1038.25	4968
1040.5	5008
1042.76	5036
1045.01	5162
1047.26	5158
1049.51	5308
1051.76	5298
1054.01	5456
1056.26	5418
1058.51	5496
1060.75	5464
1063	5588
1065.25	5672
1067.49	5672
1069.73	5672
1071.98	5822
1074.22	5782
1076.46	5850
1078.7	5960
1080.94	5986
1083.18	5934
1085.42	6018
1087.66	6020
1089.9	5996
1092.14	6074
1094.37	6228
1096.61	6226
1098.84	6212
1101.08	6204
1103.31	6210
1105.54	6254
1107.77	6256
1110	6306
1112.23	6474
1114.46	6432
1116.69	6502
1118.92	6522
1121.15	6568
1123.37	6588
1125.6	6620
1127.83	6634
1130.05	6778
1132.27	6832
1134.5	6754
1136.72	6914
1138.94	6968
1141.16	6950
1143.38	6926
1145.6	6930
1147.82	7040
1150.04	7032
1152.26	7202
1154.47	7258
1156.69	7032
1158.9	7176
1161.12	7276
1163.33	7250
1165.54	7258
1167.76	7242
1169.97	7316
1172.18	7326
1174.39	7350
1176.6	7410
1178.81	7326
1181.02	7364
1183.22	7262
1185.43	7318
1187.63	7300
1189.84	7332
1192.04	7374
1194.25	7278
1196.45	7294
1198.65	7234
1200.85	7404
1203.05	7242
1205.25	7336
1207.45	7206
1209.65	7254
1211.85	7276
1214.05	7160
1216.24	7234
1218.44	7120
1220.64	6984
1222.83	7070
1225.02	7084
1227.22	7032
1229.41	6986
1231.6	6976
1233.79	6962
1235.98	6972
1238.17	6968
1240.36	6894
1242.55	6902
1244.73	6850
1246.92	6776
1249.11	6764
1251.29	6726
1253.48	6758
1255.66	6628
1257.84	6762
1260.03	6582
1262.21	6622
1264.39	6606
1266.57	6608
1268.75	6568
1270.93	6440
1273.11	6442
1275.28	6416
1277.46	6408
1279.64	6276
1281.81	6306
1283.98	6259.24
1286.16	6242.85
1288.33	6163.54
1290.5	6149.03
1292.68	6071.62
1294.85	6012.86
1297.02	5961.86
1299.19	5916.72
1301.36	5958.56
1303.53	5854.39
1305.69	5806.35
1307.86	5721.76
1310.03	5606.86
1312.19	5680.23
1314.36	5576.13
1316.52	5457.22
1318.68	5444.59
1320.85	5417.42
1323.01	5353.92
1325.17	5286.38
1327.33	5364.81
1329.49	5206.31
1331.65	5162.55
1333.81	5113.56
1335.97	5119.55
1338.12	5029.8
1340.28	4994.11
1342.44	4957.96
1344.59	4920.88
1346.75	4901.63
1348.9	4836.35
1351.05	4788.22
1353.2	4705.55
1355.36	4783.17
1357.51	4637.42
1359.66	4621.43
1361.81	4580.71
1363.96	4562.9
1366.1	4474.12
1368.25	4499.89
1370.4	4447.09
1372.54	4408.79
1374.69	4373.63
1376.83	4332.41
1378.98	4266.32
1381.12	4235.2
1383.26	4237.92
1385.41	4181.19
1387.55	4127.43
1389.69	4091.65
1391.83	4117.5
1393.02	4102
1395.17	3988
1397.32	3982
1399.47	3998
1401.62	3838
1403.77	3932
1405.91	3838
1408.06	3806
1410.2	3796
1412.35	3770
1414.49	3674
1416.63	3806
1418.78	3758
1420.92	3780
1423.06	3672
1425.2	3662
1427.34	3658
1429.48	3578
1431.61	3602
1433.75	3478
1435.89	3516
1438.02	3528
1440.16	3486
1442.3	3502
1444.43	3394
1446.56	3426
1448.7	3466
1450.83	3434
1452.96	3414
1455.09	3332
1457.22	3356
1459.35	3294
1461.48	3292
1463.61	3324
1465.73	3236
1467.86	3206
1469.98	3244
1472.11	3142
1474.24	3226
1476.36	3188
1478.48	3140
1480.6	3136
1482.73	3086
1484.85	3124
1486.97	3088
1489.09	3116
1491.21	3130
1493.33	2994
1495.44	3002
1497.56	3066
1499.68	2950
1501.79	3022
1503.91	2920
1506.02	2954
1508.14	2932
1510.25	2854
1512.36	2888
1514.48	2798
1516.59	2856
1518.7	2910
1520.81	2856
1522.92	2812
1525.02	2806
1527.13	2772
1529.24	2812
1531.35	2726
1533.45	2710
1535.56	2838
1537.66	2722
1539.77	2688
1541.87	2648
1543.97	2610
1546.08	2680
1548.18	2642
1550.28	2564
1552.38	2644
1554.48	2530
1556.57	2610
1558.67	2614
1560.77	2580
1562.87	2566
1564.96	2538
1567.06	2512
1569.15	2510
1571.25	2504
1573.34	2476
1575.43	2526
1577.53	2452
1579.62	2518
1581.71	2414
1583.8	2484
1585.89	2408
1587.98	2430
1590.06	2444
1592.15	2376
1594.24	2444
1596.33	2434
1598.41	2418
1600.5	2376
1602.58	2370
1604.66	2446
1606.75	2354
1608.83	2386
1610.91	2376
1612.99	2346
1615.07	2382
1617.15	2354
1619.23	2346
1621.31	2290
1623.39	2304
1625.46	2324
1627.54	2268
1629.62	2354
1631.69	2320
1633.77	2288
1635.84	2302
1637.91	2278
1639.99	2290
1642.06	2266
1644.13	2278
1646.2	2234
1648.27	2248
1650.34	2224
1652.41	2270
1654.47	2190
1656.54	2226
1658.61	2276
1660.67	2204
1662.74	2184
1664.81	2218
1666.87	2206
1668.93	2146
1671	2162
1673.06	2246
1675.12	2190
1677.18	2122
1679.24	2134
1681.3	2160
1683.36	2086
1685.42	2138
1687.47	2146
1689.53	2120
1691.59	2138
1693.64	2110
1695.7	2096
1697.75	2110
1699.81	2046
1701.86	2086
1703.91	2088
1705.97	2058
1708.02	2054
1710.07	2072
1712.12	2104
1714.17	2060
1716.22	2020
1718.26	2032
1720.31	2082
1722.36	2080
1724.4	2076
1726.45	1972
1728.49	1994
1730.54	2034
1732.58	2098
1734.63	1976
1736.67	2070
1738.71	2022
1740.75	1998
1742.79	1976
1744.83	2016
1746.87	2066
1748.91	1996
1750.95	1980
1752.98	2012
1755.02	2094
1757.06	1960
1759.09	2080
1761.13	1918
1763.16	2052
1765.19	2038
1767.23	2040
1769.26	1960
1771.29	2018
1773.32	1990
1775.35	2040
1777.38	1970
1779.41	1968
1781.44	2004
1783.47	1988
1785.49	1942
1787.52	1998
1789.55	1988
1791.57	2018
1793.6	1994
1795.62	1946
1797.64	1984
1799.67	2006
1801.69	2016
1803.71	2024
1805.73	1986
1807.75	2012
1809.77	2004
1811.79	1926
1813.81	1938
1815.83	1972
1817.84	1926
1819.86	1976
1821.88	1918
1823.89	1966
1825.91	1924
1827.92	1948
1829.93	1970
1831.95	1926
1833.96	1954
1835.97	1912
1837.98	1982
1839.99	1924
1842	1954
1844.01	1910
1846.02	1996
1848.03	1910
1850.03	1922
1852.04	1970
1854.05	1886
1856.05	1978
1858.06	1942
1860.06	1948
1862.06	1904
1864.07	1926
1866.07	1910
1868.07	1926
1870.07	1886
1872.07	1940
1874.07	1938
1876.07	1914
1878.07	1924
1880.07	1926
1882.07	1886
1884.06	1936
1886.06	1914
1888.05	1908
1890.05	1934
1892.04	1896
1894.04	1926
1896.03	1900
1898.02	1938
1900.01	1954
1902	1912
1903.99	1986
1905.98	1918
1907.97	1932
1909.96	1934
1911.95	1908
1913.94	1866
1915.93	1904
1917.91	1894
1919.9	1926
1921.88	1914
1923.87	1898
1925.85	1866
1927.83	1942
1929.82	1906
1931.8	1822
1933.78	1924
1935.76	1862
1937.74	1876
1939.72	1904
1941.7	1848
1943.68	1902
1945.65	1906
1947.63	1856
1949.61	1908
1951.58	1902
1953.56	1878
1955.53	1906
1957.51	1886
1959.48	1928
1961.45	1906
1963.43	1920
1965.4	1872
1967.37	1868
1969.34	1854
1971.31	1878
1973.28	1888
1975.25	1890
1977.22	1824
1979.18	1864
1981.15	1882
1983.12	1910
1985.08	1820
1987.05	1890
1989.01	1870
1990.97	1820
1992.94	1884
1994.9	1908
1996.86	1872
1998.82	1874
2000.78	1882
2002.74	1846
2004.7	1850
2006.66	1850
2008.62	1818
2010.58	1804
2012.54	1862
2014.49	1888
2016.45	1852
2018.4	1880
2020.36	1834
2022.31	1840
2024.27	1848
2026.22	1890
2028.17	1864
2030.12	1838
2032.07	1878
2034.03	1804
2035.98	1840
2037.93	1848
2039.87	1832
2041.82	1786
2043.77	1852
2045.72	1788
2047.66	1808
2049.61	1820
2051.55	1868
2053.5	1782
2055.44	1826
2057.39	1842
2059.33	1820
2061.27	1858
2063.21	1804
2065.15	1870
2067.09	1834
2069.03	1796
2070.97	1788
2072.91	1834
2074.85	1788
2076.79	1790
2078.73	1844
2080.66	1784
2082.6	1794
2084.53	1832
2086.47	1818
2088.4	1774
2090.33	1808
2092.27	1812
2094.2	1780
2096.13	1814
2098.06	1794
2099.99	1750
2101.92	1822
2103.85	1800
2105.78	1788
2107.71	1822
2109.64	1810
2111.56	1804
2113.49	1794
2115.41	1812
2117.34	1810
2119.26	1800
2121.19	1780
2123.11	1840
2125.03	1788
2126.96	1766
2128.88	1822
2130.8	1844
2132.72	1764
2134.64	1818
2136.56	1770
2138.48	1774
2140.4	1796
2142.31	1760
2144.23	1788
2146.15	1782
2148.06	1784
2149.98	1786
2151.89	1800
2153.81	1792
2155.72	1756
2157.63	1800
2159.55	1770
2161.46	1768
2163.37	1750
2165.28	1804
2167.19	1744
2169.1	1736
2171.01	1780
2172.91	1750
2174.82	1700
2176.73	1760
2178.64	1738
2180.54	1752
2182.45	1742
2184.35	1738
2186.26	1698
2188.16	1712
2190.06	1730
2191.96	1744
2193.87	1720
2195.77	1728
2197.67	1676
2199.57	1754
2201.47	1784
2203.37	1722
2205.27	1698
2207.16	1708
2209.06	1728
2210.96	1708
2212.85	1682
2214.75	1708
2216.64	1690
2218.54	1712
2220.43	1730
2222.33	1678
2224.22	1633.76
2226.11	1658.4
2228	1689.58
2229.89	1720.86
2231.78	1635.71
2233.67	1718.78
2235.56	1695.72
2237.45	1687.13
2239.34	1681.09
2241.23	1709.23
2243.11	1711.47
2245	1714.94
2246.89	1705.38
2248.77	1652.62
2250.66	1685.35
2252.54	1664.87
2254.42	1681.65
2256.31	1656.53
2258.19	1643.39
2260.07	1650.3
2261.95	1667.27
2263.83	1665.51
2265.71	1646.72
2267.59	1628.18
2269.47	1637.39
2271.35	1651.81
2273.23	1651.66
2275.1	1635.64
2276.98	1599.99
2278.86	1638.91
2280.73	1618.59
2282.61	1646.37
2284.48	1585.71
2286.36	1655.4
2288.23	1613.04
2290.1	1624.02
2291.98	1603.23
2293.85	1615.46
2295.72	1605.77
2297.59	1623.68
2299.46	1609.97
2301.33	1610.31
2303.2	1615.37
2305.06	1560.73
2306.93	1568.63
2308.8	1547.9
2310.67	1569.08
2312.53	1594.44
2314.4	1562.3
2316.26	1562.3
2317.62	1536
2319.5	1568
2321.37	1562
2323.24	1568
2325.12	1546
2326.99	1564
2328.86	1508
2330.73	1536
2332.6	1544
2334.47	1528
2336.34	1486
2338.2	1546
2340.07	1552
2341.94	1538
2343.81	1540
2345.67	1524
2347.54	1494
2349.4	1488
2351.27	1488
2353.13	1500
2354.99	1502
2356.86	1534
2358.72	1486
2360.58	1526
2362.44	1444
2364.3	1488
2366.16	1486
2368.02	1468
2369.88	1480
2371.74	1512
2373.6	1438
2375.45	1456
2377.31	1472
2379.17	1472
2381.02	1454
2382.88	1460
2384.73	1452
2386.58	1428
2388.44	1438
2390.29	1404
2392.14	1428
2393.99	1426
2395.85	1410
2397.7	1402
2399.55	1408
2401.4	1368
2403.25	1430
2405.09	1420
2406.94	1360
2408.79	1368
2410.63	1398
2412.48	1374
2414.33	1374
2416.17	1332
2418.02	1342
2419.86	1342
2421.7	1308
2423.55	1342
2425.39	1318
2427.23	1278
2429.07	1332
2430.91	1356
2432.75	1316
2434.59	1344
2436.43	1308
2438.27	1324
2440.11	1288
2441.95	1258
2443.78	1282
2445.62	1300
2447.46	1302
2449.29	1274
2451.13	1208
2452.96	1228
2454.79	1254
2456.63	1258
2458.46	1202
2460.29	1212
2462.12	1216
2463.95	1264
2465.78	1216
2467.61	1204
2469.44	1194
2471.27	1222
2473.1	1218
2474.93	1192
2476.76	1192
2478.58	1200
2480.41	1180
2482.23	1152
2484.06	1128
2485.88	1226
2487.71	1188
2489.53	1168
2491.35	1164
2493.18	1188
2495	1142
2496.82	1126
2498.64	1100
2500.46	1134
2502.28	1086
2504.1	1114
2505.92	1092
2507.74	1116
2509.55	1076
2511.37	1078
2513.19	1082
2515	1094
2516.82	1078
2518.63	1032
2520.45	1016
2522.26	1092
2524.07	1062
2525.89	1036
2527.7	1078
2529.51	1044
2531.32	1022
2533.13	1014
2534.94	1036
2536.75	1052
2538.56	982
2540.37	1008
2542.18	1004
2543.98	990
2545.79	1022
2547.6	1014
2549.4	980
2551.21	996
2553.01	994
2554.82	988
2556.62	950
2558.42	942
2560.23	966
2562.03	940
2563.83	964
2565.63	978
2567.43	948
2569.23	932
2571.03	926
2572.83	974
2574.63	948
2576.43	948
2578.22	894
2580.02	884
2581.82	898
2583.61	888
2585.41	922
2587.2	910
2589	900
2590.79	870
2592.58	930
2594.38	860
2596.17	890
2597.96	872
2599.75	864
2601.54	856
2603.33	838
2605.12	854
2606.91	858
2608.7	882
2610.49	874
2612.27	822
2614.06	874
2615.85	808
2617.63	818
2619.42	830
2621.2	804
2622.99	814
2624.77	846
2626.55	784
2628.34	806
2630.12	802
2631.9	780
2633.68	788
2635.46	780
2637.24	746
2639.02	766
2640.8	776
2642.58	790
2644.36	790
2646.14	778
2647.91	758
2649.69	766
2651.46	756
2653.24	760
2655.01	756
2656.79	732
2658.56	752
2660.34	732
2662.11	740
2663.88	752
2665.65	720
2667.42	722
2669.2	728
2670.96	702
2672.73	708
2674.5	732
2676.27	694
2678.04	684
2679.81	694
2681.58	706
2683.34	676
2685.11	678
2686.87	704
2688.64	708
2690.4	698
2692.17	666
2693.93	690
2695.69	640
2697.46	644
2699.22	640
2700.98	650
2702.74	674
2704.5	646
2706.26	628
2708.02	640
2709.78	622
2711.54	594
2713.3	604
2715.05	618
2716.81	624
2718.57	600
2720.32	608
2722.08	614
2723.83	598
2725.59	616
2727.34	610
2729.09	588
2730.85	610
2732.6	580
2734.35	594
2736.1	568
2737.85	584
2739.6	546
2741.35	540
2743.1	582
2744.85	546
2746.6	566
2748.35	544
2750.09	546
2751.84	538
2753.59	538
2755.33	540
2757.08	558
2758.82	526
2760.57	540
2762.31	522
2764.05	550
2765.79	514
2767.54	536
2769.28	506
2771.02	530
2772.76	512
2774.5	502
2776.24	488
2777.98	490
2779.72	500
2781.46	484
2783.19	514
2784.93	478
2786.67	480
2788.4	486
2790.14	482
2791.87	486
2793.61	480
2795.34	508
2797.07	494
2798.81	466
2800.54	468
2802.27	486
2804	436
2805.74	482
2807.47	450
2809.2	472
2810.93	446
2812.65	424
2814.38	464
2816.11	450
2817.84	422
2819.56	424
2821.29	448
2823.02	466
2824.74	424
2826.47	422
2828.19	434
2829.92	424
2831.64	404
2833.36	426
2835.09	426
2836.81	412
2838.53	408
2840.25	402
2841.97	392
2843.69	398
2845.41	384
2847.13	404
2848.85	378
2850.57	392
2852.28	398
2854	366
2855.72	380
2857.43	392
2859.15	366
2860.86	376
2862.58	356
2864.29	376
2866.01	364
2867.72	368
2869.43	386
2871.14	366
2872.86	374
2874.57	348
2876.28	366
2877.99	332
2879.7	326
2881.41	356
2883.11	344
2884.82	340
2886.53	378
2888.24	362
2889.94	322
2891.65	330
2893.36	320
2895.06	326
2896.77	314
2898.47	316
2900.17	348
2901.88	328
2903.58	294
2905.28	310
2906.98	344
2908.69	318
2910.39	330
2912.09	306
2913.79	310
2915.49	306
2917.19	286
2918.88	302
2920.58	306
2922.28	308
2923.98	284
2925.67	288
2927.37	300
2929.06	290
2930.76	308
2932.45	286
2934.15	296
2935.84	298
2937.53	280
2939.23	288
2940.92	268
2942.61	306
2944.3	296
2945.99	282
2947.68	302
2949.37	284
2951.06	268
2952.75	292
2954.44	270
2956.12	282
2957.81	276
2959.5	286
2961.18	284
2962.87	248
2964.56	280
2966.24	276
2967.92	276
2969.61	272
2971.29	264
2972.97	266
2974.66	246
2976.34	260
2978.02	272
2979.7	246
2981.38	256
2983.06	262
2984.74	256
2986.42	234
2988.1	258
2989.78	256
2991.45	246
2993.13	250
2994.81	230
2996.48	228
2998.16	260
2999.83	236