File: muestras/papalo/leaf_100x_07.txt
#Acq. time (s)=	10
#Accumulations=	1
#Range (cm-¹)=	200...3000
#Windows=	3
#Autofocus=	Off
#AutoExposure=	Off
#Spike filter=	Off
#Delay time (s)=	0
#Binning=	1
#Readout mode=	Signal
#DeNoise=	Off
#ICS correction=	Off
#Dark correction=	Off
#Inst. Process=	Off
#Instrument=	LabRAM HR Evol
#Detector=	Syncerity OE
#Objective=	x100_VIS
#Grating=	600 (500nm)
#ND Filter=	0.1%
#Laser=	633nm_Edge
#Hole=	100.021
#Range=	Visible
#Project=	Omar
#Sample=	03-07-23
#Site=	papal
#Title=	leaf_100x
#Remark=
#Date=	03.07.2023 17:16
#Acquired=	03.07.2023 17:16:17
201.713	170
204.247	188
206.778	190
209.311	188
211.84	196
214.371	200
216.899	188
219.428	216
221.955	204
224.482	212
227.007	200
229.531	216
232.055	204
234.579	216
237.1	210
239.621	244
242.141	226
244.661	228
247.179	224
249.698	242
252.215	224
254.731	228
257.246	258
259.761	276
262.273	264
264.786	258
267.298	252
269.809	250
272.319	274
274.828	262
277.336	282
279.844	278
282.351	294
284.855	282
287.361	292
289.866	312
292.368	302
294.871	312
297.372	308
299.873	294
302.372	304
304.872	290
307.37	320
309.866	300
312.364	326
314.859	344
317.353	332
319.848	334
322.341	344
324.833	336
327.324	358
329.814	346
332.304	382
334.792	374
337.28	382
339.767	368
342.254	386
344.739	394
347.224	394
349.708	386
352.191	396
354.673	412
357.155	426
359.634	408
362.114	428
364.593	448
367.07	456
369.548	426
372.024	452
374.499	460
376.974	468
379.447	448
381.92	468
384.392	460
386.864	476
389.333	504
391.802	492
394.272	498
396.739	490
399.206	498
401.673	538
404.138	510
406.602	544
409.066	540
411.528	542
413.99	558
416.451	560
418.911	584
421.371	592
423.83	588
426.288	588
428.745	572
431.201	628
433.657	618
436.111	618
438.565	650
441.017	640
443.469	630
445.921	652
448.37	646
450.821	670
453.27	682
455.717	678
458.165	674
460.61	662
463.056	718
465.5	712
467.945	712
470.387	724
472.829	732
475.271	744
477.711	728
480.15	742
482.589	748
485.027	752
487.465	766
489.901	796
492.337	786
494.771	786
497.205	796
499.638	806
502.07	808
504.502	812
506.933	870
509.363	824
511.792	834
514.219	844
516.647	862
519.073	856
521.5	892
523.924	908
526.348	920
528.772	958
531.194	884
533.616	942
536.036	942
538.457	960
540.875	934
543.294	986
545.712	980
548.128	968
550.545	998
552.959	998
555.373	1018
557.788	1016
560.2	1018
562.612	988
565.023	1020
567.433	1078
569.843	1048
572.251	1062
574.659	1122
577.066	1142
579.472	1136
581.878	1130
584.283	1154
586.687	1176
589.09	1202
591.493	1204
593.893	1168
596.294	1226
598.694	1258
601.093	1244
603.491	1274
605.889	1300
608.285	1312
610.682	1306
613.076	1348
615.471	1376
617.864	1386
620.256	1380
622.648	1392
625.039	1420
627.429	1468
629.819	1484
632.208	1440
634.595	1456
636.982	1508
639.369	1522
641.755	1558
644.139	1554
646.523	1608
648.906	1604
651.288	1648
653.67	1622
656.051	1668
658.429	1672
660.808	1728
663.187	1674
665.565	1700
667.942	1754
670.317	1776
672.692	1784
675.067	1842
677.44	1878
679.813	1792
682.184	1908
684.556	1894
686.926	1896
689.296	1924
691.664	1998
694.033	2020
696.4	1976
698.766	1984
701.133	2062
703.497	2088
705.861	2090
708.224	2102
710.586	2142
712.949	2276
715.31	2232
717.67	2242
720.029	2304
722.388	2338
724.746	2352
727.103	2396
729.458	2404
731.814	2432
734.168	2424
736.523	2514
738.876	2550
741.227	2582
743.579	2514
745.931	2614
748.28	2654
750.629	2678
752.977	2724
755.325	2728
757.672	2746
760.018	2816
762.363	2830
764.708	2808
767.052	2902
769.394	2910
771.737	2960
774.078	3050
776.419	3028
778.758	3080
781.097	3140
783.435	3144
785.773	3138
788.11	3216
790.446	3300
792.781	3314
795.115	3342
797.449	3340
799.782	3402
802.115	3418
804.446	3520
806.777	3572
809.106	3606
811.435	3598
813.764	3752
816.091	3776
818.418	3798
820.743	3880
823.069	3936
825.393	3944
827.717	4046
830.039	4054
832.362	4154
834.683	4246
837.003	4206
839.324	4278
841.643	4296
843.961	4372
846.278	4424
848.594	4510
850.91	4544
853.227	4712
855.541	4692
857.855	4798
860.168	4844
862.48	4888
864.79	4908
867.101	4982
869.411	5110
871.721	5044
874.029	5178
876.336	5156
878.643	5332
880.95	5262
883.254	5352
885.559	5414
887.862	5494
890.166	5562
892.467	5588
894.77	5596
897.07	5702
899.371	5722
901.669	5866
903.968	5874
906.266	5960
908.563	5974
910.859	6058
913.154	6164
915.449	6190
917.742	6230
920.036	6372
922.329	6402
924.621	6482
926.911	6546
929.201	6588
931.49	6692
933.779	6734
936.068	6928
938.355	6940
940.64	7000
942.926	7104
945.212	7232
947.495	7310
949.779	7420
952.062	7416
954.344	7506
956.625	7544
958.905	7706
961.184	7826
963.464	7876
965.742	7876
968.02	8090
970.296	8110
972.572	8118
974.847	8192
977.121	8332
979.396	8382
981.669	8550
983.941	8622
986.212	8626
988.483	8748
990.753	8844
993.022	8832
995.29	8948
997.558	9024
999.825	9274
1002.09	9262
1004.36	9358
1006.62	9360
1008.89	9476
1011.15	9620
1013.41	9792
1015.67	9704
1017.93	9892
1020.19	9942
1022.45	10198
1024.71	10282
1026.97	10478
1029.23	10466
1031.49	10578
1033.74	10832
1036	10858
1038.25	10980
1040.5	11148
1042.76	11208
1045.01	11302
1047.26	11338
1049.51	11430
1051.76	11682
1054.01	11732
1056.26	11818
1058.51	12012
1060.75	11954
1063	12268
1065.25	12288
1067.49	12452
1069.73	12388
1071.98	12552
1074.22	12592
1076.46	12682
1078.7	12838
1080.94	12776
1083.18	12854
1085.42	13046
1087.66	13194
1089.9	13156
1092.14	13170
1094.37	13288
1096.61	13426
1098.84	13460
1101.08	13620
1103.31	13714
1105.54	13688
1107.77	13934
1110	13930
1112.23	13940
1114.46	14282
1116.69	14206
1118.92	14254
1121.15	14410
1123.37	14384
1125.6	14534
1127.83	14660
1130.05	14624
1132.27	14748
1134.5	14810
1136.72	15054
1138.94	15112
1141.16	15158
1143.38	15288
1145.6	15290
1147.82	15474
1150.04	15474
1152.26	15434
1154.47	15680
1156.69	15778
1158.9	15776
1161.12	15814
1163.33	15728
1165.54	15782
1167.76	15818
1169.97	15822
1172.18	15964
1174.39	15838
1176.6	15866
1178.81	15956
1181.02	15888
1183.22	15974
1185.43	15952
1187.63	15916
1189.84	15908
1192.04	15966
1194.25	15826
1196.45	15842
1198.65	15822
1200.85	15704
1203.05	15864
1205.25	15560
1207.45	15740
1209.65	15630
1211.85	15434
1214.05	15608
1216.24	15370
1218.44	15516
1220.64	15278
1222.83	15208
1225.02	15258
1227.22	15172
1229.41	15062
1231.6	15034
1233.79	15002
1235.98	14844
1238.17	14812
1240.36	14798
1242.55	14730
1244.73	14628
1246.92	14632
1249.11	14610
1251.29	14580
1253.48	14462
1255.66	14388
1257.84	14218
1260.03	14094
1262.21	14048
1264.39	13936
1266.57	13846
1268.75	13790
1270.93	13842
1273.11	13722
1275.28	13518
1277.46	13670
1279.64	13446
1281.81	13404
1283.98	13152.3
1286.16	13040.8
1288.33	13032
1290.5	12955.5
1292.68	12922.8
1294.85	12690.3
1297.02	12620.8
1299.19	12514.7
1301.36	12237.5
1303.53	12202.4
1305.69	11996
1307.86	11877.5
1310.03	11874.9
1312.19	11625.2
1314.36	11564.6
1316.52	11348.1
1318.68	11286.7
1320.85	11181.1
1323.01	11144
1325.17	11019.4
1327.33	10886.8
1329.49	10721
1331.65	10551.3
1333.81	10470.3
1335.97	10528.5
1338.12	10347
1340.28	10199.9
1342.44	10003.6
1344.59	9955.71
1346.75	9858.44
1348.9	9781.79
1351.05	9680
1353.2	9477.84
1355.36	9454.53
1357.51	9299.39
1359.66	9231.61
1361.81	9231.62
1363.96	9063.14
1366.1	9029.99
1368.25	8916.29
1370.4	8813.72
1372.54	8752.37
1374.69	8576.58
1376.83	8522.96
1378.98	8402.96
1381.12	8276.01
1383.26	8296.8
1385.41	8123.09
1387.55	8010.81
1389.69	7940.15
1391.83	7835.89
1393.02	7754
1395.17	7894
1397.32	7810
1399.47	7750
1401.62	7620
1403.77	7540
1405.91	7580
1408.06	7502
1410.2	7468
1412.35	7358
1414.49	7248
1416.63	7246
1418.78	7162
1420.92	7108
1423.06	7072
1425.2	7046
1427.34	6976
1429.48	6934
1431.61	6858
1433.75	6842
1435.89	6800
1438.02	6800
1440.16	6762
1442.3	6732
1444.43	6582
1446.56	6598
1448.7	6576
1450.83	6498
1452.96	6410
1455.09	6518
1457.22	6392
1459.35	6342
1461.48	6248
1463.61	6334
1465.73	6154
1467.86	6248
1469.98	6186
1472.11	6156
1474.24	6118
1476.36	5978
1478.48	5922
1480.6	6018
1482.73	5934
1484.85	5984
1486.97	5880
1489.09	5844
1491.21	5814
1493.33	5842
1495.44	5706
1497.56	5698
1499.68	5686
1501.79	5646
1503.91	5740
1506.02	5612
1508.14	5514
1510.25	5596
1512.36	5460
1514.48	5438
1516.59	5316
1518.7	5398
1520.81	5294
1522.92	5292
1525.02	5328
1527.13	5194
1529.24	5148
1531.35	5262
1533.45	5128
1535.56	5048
1537.66	5062
1539.77	4992
1541.87	5072
1543.97	5026
1546.08	5010
1548.18	4926
1550.28	4894
1552.38	4980
1554.48	4908
1556.57	4828
1558.67	4734
1560.77	4762
1562.87	4770
1564.96	4716
1567.06	4784
1569.15	4772
1571.25	4662
1573.34	4674
1575.43	4694
1577.53	4604
1579.62	4644
1581.71	4632
1583.8	4640
1585.89	4612
1587.98	4620
1590.06	4560
1592.15	4524
1594.24	4550
1596.33	4502
1598.41	4548
1600.5	4478
1602.58	4478
1604.66	4446
1606.75	4490
1608.83	4378
1610.91	4358
1612.99	4470
1615.07	4390
1617.15	4360
1619.23	4394
1621.31	4276
1623.39	4288
1625.46	4328
1627.54	4294
1629.62	4306
1631.69	4286
1633.77	4334
1635.84	4242
1637.91	4288
1639.99	4242
1642.06	4256
1644.13	4184
1646.2	4184
1648.27	4220
1650.34	4184
1652.41	4126
1654.47	4156
1656.54	4086
1658.61	4110
1660.67	4184
1662.74	4122
1664.81	4076
1666.87	4094
1668.93	4134
1671	4092
1673.06	4004
1675.12	4022
1677.18	4044
1679.24	3968
1681.3	3982
1683.36	3944
1685.42	4030
1687.47	3964
1689.53	3864
1691.59	3966
1693.64	3866
1695.7	3864
1697.75	3874
1699.81	3768
1701.86	3880
1703.91	3836
1705.97	3872
1708.02	3896
1710.07	3796
1712.12	3798
1714.17	3816
1716.22	3742
1718.26	3800
1720.31	3780
1722.36	3694
1724.4	3820
1726.45	3738
1728.49	3748
1730.54	3748
1732.58	3726
1734.63	3708
1736.67	3746
1738.71	3774
1740.75	3704
1742.79	3602
1744.83	3724
1746.87	3744
1748.91	3648
1750.95	3762
1752.98	3672
1755.02	3682
1757.06	3654
1759.09	3692
1761.13	3694
1763.16	3638
1765.19	3698
1767.23	3706
1769.26	3704
1771.29	3694
1773.32	3742
1775.35	3790
1777.38	3720
1779.41	3710
1781.44	3668
1783.47	3640
1785.49	3670
1787.52	3688
1789.55	3690
1791.57	3660
1793.6	3676
1795.62	3668
1797.64	3642
1799.67	3692
1801.69	3626
1803.71	3628
1805.73	3610
1807.75	3688
1809.77	3596
1811.79	3616
1813.81	3560
1815.83	3588
1817.84	3676
1819.86	3580
1821.88	3538
1823.89	3556
1825.91	3568
1827.92	3564
1829.93	3588
1831.95	3570
1833.96	3584
1835.97	3578
1837.98	3526
1839.99	3532
1842	3530
1844.01	3570
1846.02	3428
1848.03	3518
1850.03	3472
1852.04	3512
1854.05	3462
1856.05	3520
1858.06	3526
1860.06	3468
1862.06	3452
1864.07	3522
1866.07	3478
1868.07	3476
1870.07	3480
1872.07	3496
1874.07	3548
1876.07	3470
1878.07	3452
1880.07	3404
1882.07	3454
1884.06	3424
1886.06	3492
1888.05	3508
1890.05	3428
1892.04	3482
1894.04	3466
1896.03	3464
1898.02	3432
1900.01	3476
1902	3412
1903.99	3444
1905.98	3414
1907.97	3444
1909.96	3422
1911.95	3396
1913.94	3422
1915.93	3378
1917.91	3514
1919.9	3370
1921.88	3410
1923.87	3432
1925.85	3436
1927.83	3366
1929.82	3470
1931.8	3448
1933.78	3322
1935.76	3366
1937.74	3368
1939.72	3422
1941.7	3432
1943.68	3496
1945.65	3322
1947.63	3422
1949.61	3378
1951.58	3482
1953.56	3298
1955.53	3422
1957.51	3406
1959.48	3382
1961.45	3342
1963.43	3332
1965.4	3266
1967.37	3280
1969.34	3306
1971.31	3314
1973.28	3332
1975.25	3304
1977.22	3340
1979.18	3288
1981.15	3254
1983.12	3348
1985.08	3276
1987.05	3254
1989.01	3268
1990.97	3322
1992.94	3308
1994.9	3278
1996.86	3340
1998.82	3308
2000.78	3352
2002.74	3326
2004.7	3316
2006.66	3276
2008.62	3330
2010.58	3286
2012.54	3282
2014.49	3326
2016.45	3184
2018.4	3190
2020.36	3252
2022.31	3242
2024.27	3264
2026.22	3210
2028.17	3264
2030.12	3218
2032.07	3180
2034.03	3206
2035.98	3234
2037.93	3218
2039.87	3246
2041.82	3212
2043.77	3222
2045.72	3218
2047.66	3162
2049.61	3246
2051.55	3246
2053.5	3156
2055.44	3108
2057.39	3206
2059.33	3166
2061.27	3166
2063.21	3150
2065.15	3238
2067.09	3224
2069.03	3206
2070.97	3206
2072.91	3200
2074.85	3164
2076.79	3174
2078.73	3144
2080.66	3206
2082.6	3188
2084.53	3210
2086.47	3156
2088.4	3124
2090.33	3160
2092.27	3092
2094.2	3164
2096.13	3130
2098.06	3192
2099.99	3132
2101.92	3100
2103.85	3142
2105.78	3174
2107.71	3104
2109.64	3190
2111.56	3076
2113.49	3064
2115.41	3102
2117.34	3116
2119.26	3154
2121.19	3108
2123.11	3060
2125.03	3044
2126.96	3072
2128.88	3108
2130.8	3072
2132.72	3166
2134.64	3120
2136.56	3076
2138.48	3092
2140.4	3158
2142.31	3094
2144.23	3076
2146.15	3006
2148.06	3040
2149.98	3056
2151.89	3048
2153.81	3080
2155.72	3070
2157.63	3014
2159.55	2978
2161.46	3038
2163.37	3066
2165.28	2986
2167.19	3036
2169.1	2976
2171.01	3024
2172.91	2980
2174.82	2964
2176.73	2968
2178.64	2968
2180.54	2984
2182.45	2966
2184.35	2942
2186.26	2966
2188.16	2958
2190.06	3020
2191.96	2862
2193.87	2984
2195.77	2982
2197.67	2918
2199.57	2834
2201.47	2846
2203.37	2960
2205.27	2900
2207.16	2942
2209.06	2840
2210.96	2876
2212.85	2812
2214.75	2842
2216.64	2916
2218.54	2850
2220.43	2936
2222.33	2922
2224.22	2846.03
2226.11	2809.68
2228	2788.47
2229.89	2861.82
2231.78	2825.12
2233.67	2859.21
2235.56	2809.72
2237.45	2783.05
2239.34	2774.54
2241.23	2835.03
2243.11	2845.85
2245	2840.96
2246.89	2780.02
2248.77	2801.12
2250.66	2787.11
2252.54	2800.5
2254.42	2827.32
2256.31	2755.16
2258.19	2771.21
2260.07	2775.94
2261.95	2765.93
2263.83	2790.42
2265.71	2786.94
2267.59	2759.31
2269.47	2772.14
2271.35	2695.83
2273.23	2711.49
2275.1	2728.54
2276.98	2682.45
2278.86	2673.31
2280.73	2672.89
2282.61	2656.18
2284.48	2665.38
2286.36	2647.78
2288.23	2677.21
2290.1	2628.3
2291.98	2657.96
2293.85	2598.54
2295.72	2594.09
2297.59	2567.42
2299.46	2599.7
2301.33	2558.81
2303.2	2581.9
2305.06	2550.54
2306.93	2572.99
2308.8	2571.67
2310.67	2572.5
2312.53	2563.13
2314.4	2529.85
2316.26	2514.62
2317.62	2480
2319.5	2482
2321.37	2504
2323.24	2482
2325.12	2480
2326.99	2456
2328.86	2458
2330.73	2468
2332.6	2418
2334.47	2514
2336.34	2392
2338.2	2450
2340.07	2472
2341.94	2426
2343.81	2476
2345.67	2440
2347.54	2404
2349.4	2362
2351.27	2468
2353.13	2428
2354.99	2382
2356.86	2390
2358.72	2374
2360.58	2374
2362.44	2348
2364.3	2344
2366.16	2362
2368.02	2344
2369.88	2356
2371.74	2304
2373.6	2364
2375.45	2332
2377.31	2356
2379.17	2278
2381.02	2266
2382.88	2300
2384.73	2320
2386.58	2296
2388.44	2266
2390.29	2300
2392.14	2250
2393.99	2252
2395.85	2182
2397.7	2234
2399.55	2212
2401.4	2214
2403.25	2176
2405.09	2196
2406.94	2166
2408.79	2174
2410.63	2160
2412.48	2194
2414.33	2166
2416.17	2090
2418.02	2200
2419.86	2110
2421.7	2104
2423.55	2094
2425.39	2066
2427.23	2088
2429.07	2002
2430.91	2100
2432.75	2052
2434.59	2070
2436.43	2080
2438.27	2094
2440.11	2060
2441.95	1984
2443.78	1974
2445.62	1996
2447.46	1974
2449.29	1944
2451.13	2042
2452.96	2018
2454.79	2016
2456.63	1932
2458.46	1962
2460.29	1928
2462.12	1918
2463.95	1946
2465.78	1922
2467.61	1886
2469.44	1860
2471.27	1864
2473.1	1814
2474.93	1876
2476.76	1816
2478.58	1808
2480.41	1804
2482.23	1852
2484.06	1854
2485.88	1838
2487.71	1770
2489.53	1776
2491.35	1786
2493.18	1762
2495	1744
2496.82	1754
2498.64	1762
2500.46	1726
2502.28	1742
2504.1	1704
2505.92	1708
2507.74	1620
2509.55	1718
2511.37	1730
2513.19	1652
2515	1646
2516.82	1664
2518.63	1606
2520.45	1686
2522.26	1638
2524.07	1608
2525.89	1638
2527.7	1608
2529.51	1606
2531.32	1588
2533.13	1588
2534.94	1572
2536.75	1578
2538.56	1574
2540.37	1530
2542.18	1554
2543.98	1546
2545.79	1566
2547.6	1538
2549.4	1532
2551.21	1488
2553.01	1488
2554.82	1474
2556.62	1502
2558.42	1436
2560.23	1502
2562.03	1478
2563.83	1448
2565.63	1470
2567.43	1410
2569.23	1420
2571.03	1408
2572.83	1418
2574.63	1428
2576.43	1412
2578.22	1396
2580.02	1364
2581.82	1348
2583.61	1358
2585.41	1396
2587.2	1358
2589	1364
2590.79	1368
2592.58	1344
2594.38	1348
2596.17	1294
2597.96	1342
2599.75	1298
2601.54	1296
2603.33	1318
2605.12	1318
2606.91	1238
2608.7	1270
2610.49	1274
2612.27	1276
2614.06	1258
2615.85	1238
2617.63	1236
2619.42	1254
2621.2	1260
2622.99	1258
2624.77	1232
2626.55	1210
2628.34	1216
2630.12	1238
2631.9	1176
2633.68	1222
2635.46	1160
2637.24	1204
2639.02	1152
2640.8	1180
2642.58	1130
2644.36	1162
2646.14	1106
2647.91	1152
2649.69	1190
2651.46	1108
2653.24	1094
2655.01	1116
2656.79	1122
2658.56	1120
2660.34	1068
2662.11	1098
2663.88	1098
2665.65	1062
2667.42	1024
2669.2	1054
2670.96	1104
2672.73	1054
2674.5	1076
2676.27	1070
2678.04	1028
2679.81	1022
2681.58	1028
2683.34	992
2685.11	996
2686.87	1028
2688.64	996
2690.4	978
2692.17	984
2693.93	966
2695.69	982
2697.46	960
2699.22	970
2700.98	970
2702.74	990
2704.5	988
2706.26	974
2708.02	944
2709.78	908
2711.54	930
2713.3	916
2715.05	934
2716.81	946
2718.57	922
2720.32	910
2722.08	914
2723.83	886
2725.59	900
2727.34	934
2729.09	884
2730.85	852
2732.6	834
2734.35	878
2736.1	880
2737.85	828
2739.6	880
2741.35	842
2743.1	838
2744.85	810
2746.6	816
2748.35	800
2750.09	786
2751.84	828
2753.59	804
2755.33	796
2757.08	774
2758.82	792
2760.57	800
2762.31	756
2764.05	778
2765.79	770
2767.54	782
2769.28	774
2771.02	752
2772.76	750
2774.5	730
2776.24	722
2777.98	784
2779.72	724
2781.46	714
2783.19	680
2784.93	726
2786.67	718
2788.4	706
2790.14	690
2791.87	668
2793.61	708
2795.34	674
2797.07	712
2798.81	660
2800.54	688
2802.27	692
2804	676
2805.74	678
2807.47	640
2809.2	652
2810.93	676
2812.65	624
2814.38	644
2816.11	626
2817.84	620
2819.56	640
2821.29	608
2823.02	622
2824.74	614
2826.47	586
2828.19	602
2829.92	616
2831.64	602
2833.36	600
2835.09	620
2836.81	592
2838.53	568
2840.25	578
2841.97	562
2843.69	608
2845.41	556
2847.13	554
2848.85	542
2850.57	572
2852.28	548
2854	552
2855.72	526
2857.43	526
2859.15	536
2860.86	514
2862.58	510
2864.29	508
2866.01	542
2867.72	534
2869.43	490
2871.14	492
2872.86	500
2874.57	514
2876.28	482
2877.99	496
2879.7	480
2881.41	482
2883.11	492
2884.82	488
2886.53	498
2888.24	494
2889.94	480
2891.65	482
2893.36	464
2895.06	480
2896.77	476
2898.47	442
2900.17	474
2901.88	466
2903.58	420
2905.28	458
2906.98	462
2908.69	430
2910.39	436
2912.09	446
2913.79	428
2915.49	440
2917.19	442
2918.88	456
2920.58	436
2922.28	420
2923.98	440
2925.67	408
2927.37	414
2929.06	430
2930.76	438
2932.45	432
2934.15	420
2935.84	390
2937.53	384
2939.23	414
2940.92	378
2942.61	398
2944.3	402
2945.99	386
2947.68	400
2949.37	392
2951.06	394
2952.75	404
2954.44	384
2956.12	376
2957.81	376
2959.5	380
2961.18	388
2962.87	382
2964.56	384
2966.24	384
2967.92	372
2969.61	360
2971.29	346
2972.97	372
2974.66	348
2976.34	340
2978.02	342
2979.7	362
2981.38	360
2983.06	362
2984.74	330
2986.42	362
2988.1	336
2989.78	342
2991.45	348
2993.13	328
2994.81	322
2996.48	316
2998.16	312
2999.83	318