File: muestras/papalo/leaf_100x_02.txt
#Acq. time (s)=	10
#Accumulations=	1
#Range (cm-¹)=	200...3000
#Windows=	3
#Autofocus=	Off
#AutoExposure=	Off
#Spike filter=	Off
#Delay time (s)=	0
#Binning=	1
#Readout mode=	Signal
#DeNoise=	Off
#ICS correction=	Off
#Dark correction=	Off
#Inst. Process=	Off
#Instrument=	LabRAM HR Evol
#Detector=	Syncerity OE
#Objective=	x100_VIS
#Grating=	600 (500nm)
#ND Filter=	0.01%
#Laser=	633nm_Edge
#Hole=	100.021
#Range=	Visible
#Project=	Omar
#Sample=	03-07-23
#Site=	papal
#Title=	leaf_100x
#Remark=
#Date=	03.07.2023 17:11
#Acquired=	03.07.2023 17:11:03
201.713	98
204.247	94
206.778	100
209.311	92
211.84	98
214.371	102
216.899	100
219.428	104
221.955	114
224.482	116
227.007	114
229.531	110
232.055	108
234.579	112
237.1	112
239.621	108
242.141	126
244.661	118
247.179	126
249.698	126
252.215	122
254.731	126
257.246	132
259.761	134
262.273	122
264.786	128
267.298	134
269.809	134
272.319	130
274.828	142
277.336	132
279.844	146
282.351	148
284.855	148
287.361	136
289.866	140
292.368	146
294.871	152
297.372	146
299.873	162
302.372	138
304.872	162
307.37	158
309.866	154
312.364	170
314.859	142
317.353	160
319.848	176
322.341	168
324.833	188
327.324	180
329.814	184
332.304	188
334.792	208
337.28	176
339.767	208
342.254	212
344.739	196
347.224	200
349.708	200
352.191	216
354.673	198
357.155	210
359.634	222
362.114	214
364.593	226
367.07	222
369.548	224
372.024	214
374.499	228
376.974	218
379.447	236
381.92	216
384.392	230
386.864	228
389.333	248
391.802	228
394.272	218
396.739	240
399.206	248
401.673	246
404.138	242
406.602	274
409.066	252
411.528	270
413.99	262
416.451	270
418.911	272
421.371	264
423.83	286
426.288	272
428.745	284
431.201	282
433.657	324
436.111	308
438.565	282
441.017	290
443.469	298
445.921	300
448.37	328
450.821	306
453.27	334
455.717	326
458.165	340
460.61	322
463.056	354
465.5	334
467.945	338
470.387	336
472.829	352
475.271	364
477.711	364
480.15	384
482.589	366
485.027	368
487.465	366
489.901	378
492.337	366
494.771	384
497.205	406
499.638	396
502.07	396
504.502	404
506.933	398
509.363	398
511.792	420
514.219	416
516.647	400
519.073	440
521.5	420
523.924	438
526.348	458
528.772	438
531.194	424
533.616	446
536.036	442
538.457	462
540.875	456
543.294	478
545.712	498
548.128	478
550.545	464
552.959	482
555.373	476
557.788	494
560.2	492
562.612	490
565.023	528
567.433	512
569.843	542
572.251	542
574.659	538
577.066	544
579.472	520
581.878	554
584.283	572
586.687	568
589.09	546
591.493	584
593.893	566
596.294	594
598.694	606
601.093	600
603.491	592
605.889	650
608.285	630
610.682	630
613.076	648
615.471	644
617.864	674
620.256	674
622.648	648
625.039	700
627.429	726
629.819	728
632.208	720
634.595	694
636.982	738
639.369	792
641.755	762
644.139	782
646.523	774
648.906	762
651.288	798
653.67	794
656.051	816
658.429	786
660.808	850
663.187	840
665.565	864
667.942	822
670.317	892
672.692	892
675.067	912
677.44	910
679.813	890
682.184	884
684.556	944
686.926	952
689.296	936
691.664	972
694.033	980
696.4	986
698.766	986
701.133	1044
703.497	1036
705.861	1038
708.224	1066
710.586	1078
712.949	1078
715.31	1080
717.67	1120
720.029	1130
722.388	1162
724.746	1196
727.103	1158
729.458	1202
731.814	1200
734.168	1216
736.523	1266
738.876	1250
741.227	1294
743.579	1298
745.931	1350
748.28	1374
750.629	1374
752.977	1384
755.325	1412
757.672	1362
760.018	1392
762.363	1396
764.708	1512
767.052	1474
769.394	1482
771.737	1534
774.078	1566
776.419	1538
778.758	1560
781.097	1586
783.435	1586
785.773	1610
788.11	1624
790.446	1670
792.781	1696
795.115	1750
797.449	1726
799.782	1804
802.115	1832
804.446	1784
806.777	1804
809.106	1898
811.435	1888
813.764	1950
816.091	1910
818.418	1914
820.743	2022
823.069	2038
825.393	2094
827.717	2118
830.039	2126
832.362	2162
834.683	2216
837.003	2204
839.324	2278
841.643	2314
843.961	2306
846.278	2342
848.594	2374
850.91	2458
853.227	2446
855.541	2464
857.855	2440
860.168	2554
862.48	2582
864.79	2602
867.101	2694
869.411	2688
871.721	2674
874.029	2710
876.336	2714
878.643	2726
880.95	2812
883.254	2904
885.559	2916
887.862	2916
890.166	2954
892.467	2974
894.77	2944
897.07	3094
899.371	3050
901.669	3036
903.968	3094
906.266	3198
908.563	3200
910.859	3242
913.154	3250
915.449	3344
917.742	3314
920.036	3394
922.329	3434
924.621	3478
926.911	3564
929.201	3556
931.49	3614
933.779	3662
936.068	3680
938.355	3698
940.64	3852
942.926	3874
945.212	3858
947.495	3924
949.779	3968
952.062	4030
954.344	4030
956.625	4124
958.905	4116
961.184	4220
963.464	4212
965.742	4258
968.02	4330
970.296	4378
972.572	4496
974.847	4344
977.121	4572
979.396	4504
981.669	4646
983.941	4730
986.212	4670
988.483	4730
990.753	4756
993.022	4890
995.29	4972
997.558	4958
999.825	4926
1002.09	5000
1004.36	5082
1006.62	5224
1008.89	5186
1011.15	5210
1013.41	5372
1015.67	5428
1017.93	5396
1020.19	5456
1022.45	5548
1024.71	5586
1026.97	5692
1029.23	5696
1031.49	5830
1033.74	5866
1036	5868
1038.25	5948
1040.5	6000
1042.76	6200
1045.01	6170
1047.26	6222
1049.51	6326
1051.76	6362
1054.01	6470
1056.26	6472
1058.51	6480
1060.75	6600
1063	6554
1065.25	6726
1067.49	6734
1069.73	6760
1071.98	6896
1074.22	6918
1076.46	6860
1078.7	7096
1080.94	7066
1083.18	7128
1085.42	7150
1087.66	7070
1089.9	7174
1092.14	7234
1094.37	7146
1096.61	7302
1098.84	7430
1101.08	7398
1103.31	7446
1105.54	7418
1107.77	7556
1110	7510
1112.23	7602
1114.46	7588
1116.69	7686
1118.92	7754
1121.15	7736
1123.37	7744
1125.6	7908
1127.83	7896
1130.05	7966
1132.27	8026
1134.5	8116
1136.72	8008
1138.94	8104
1141.16	8122
1143.38	8144
1145.6	8218
1147.82	8362
1150.04	8258
1152.26	8314
1154.47	8334
1156.69	8270
1158.9	8390
1161.12	8338
1163.33	8520
1165.54	8372
1167.76	8436
1169.97	8372
1172.18	8404
1174.39	8336
1176.6	8410
1178.81	8270
1181.02	8466
1183.22	8412
1185.43	8332
1187.63	8178
1189.84	8318
1192.04	8336
1194.25	8194
1196.45	8192
1198.65	8148
1200.85	8084
1203.05	8046
1205.25	8014
1207.45	8018
1209.65	7932
1211.85	7888
1214.05	7828
1216.24	7798
1218.44	7714
1220.64	7708
1222.83	7690
1225.02	7596
1227.22	7504
1229.41	7566
1231.6	7490
1233.79	7386
1235.98	7408
1238.17	7306
1240.36	7262
1242.55	7278
1244.73	7262
1246.92	7176
1249.11	7118
1251.29	6992
1253.48	6964
1255.66	6874
1257.84	6866
1260.03	6848
1262.21	6796
1264.39	6796
1266.57	6678
1268.75	6594
1270.93	6504
1273.11	6570
1275.28	6404
1277.46	6370
1279.64	6340
1281.81	6366
1283.98	6181.51
1286.16	6146.62
1288.33	6232.49
1290.5	6027.74
1292.68	5968.62
1294.85	5860.95
1297.02	5791.43
1299.19	5825.19
1301.36	5750.84
1303.53	5705.64
1305.69	5643.32
1307.86	5542.56
1310.03	5433.36
1312.19	5456.2
1314.36	5372.89
1316.52	5294.25
1318.68	5248.63
1320.85	5175.99
1323.01	5125.9
1325.17	5136.76
1327.33	4998.61
1329.49	4969.53
1331.65	4919.58
1333.81	4877.02
1335.97	4763.99
1338.12	4755.7
1340.28	4754.15
1342.44	4653.7
1344.59	4615.92
1346.75	4583.15
1348.9	4458.45
1351.05	4489.13
1353.2	4370.98
1355.36	4340.66
1357.51	4364.78
1359.66	4305.57
1361.81	4198.92
1363.96	4118.33
1366.1	4182.43
1368.25	4115.57
1370.4	4035.57
1372.54	4015.37
1374.69	4001.48
1376.83	3959.53
1378.98	3874.38
1381.12	3789.1
1383.26	3810.78
1385.41	3775.91
1387.55	3766.16
1389.69	3744.96
1391.83	3693.1
1393.02	3642
1395.17	3648
1397.32	3682
1399.47	3552
1401.62	3512
1403.77	3516
1405.91	3468
1408.06	3442
1410.2	3464
1412.35	3362
1414.49	3340
1416.63	3354
1418.78	3298
1420.92	3300
1423.06	3258
1425.2	3190
1427.34	3228
1429.48	3184
1431.61	3178
1433.75	3080
1435.89	3124
1438.02	3076
1440.16	2994
1442.3	2948
1444.43	2940
1446.56	2966
1448.7	2940
1450.83	2934
1452.96	2878
1455.09	2880
1457.22	2880
1459.35	2866
1461.48	2804
1463.61	2840
1465.73	2814
1467.86	2806
1469.98	2764
1472.11	2758
1474.24	2672
1476.36	2722
1478.48	2664
1480.6	2686
1482.73	2638
1484.85	2590
1486.97	2630
1489.09	2586
1491.21	2584
1493.33	2534
1495.44	2494
1497.56	2566
1499.68	2476
1501.79	2516
1503.91	2490
1506.02	2486
1508.14	2400
1510.25	2448
1512.36	2424
1514.48	2410
1516.59	2340
1518.7	2342
1520.81	2332
1522.92	2346
1525.02	2304
1527.13	2330
1529.24	2248
1531.35	2310
1533.45	2248
1535.56	2276
1537.66	2192
1539.77	2208
1541.87	2208
1543.97	2238
1546.08	2180
1548.18	2146
1550.28	2150
1552.38	2164
1554.48	2120
1556.57	2074
1558.67	2158
1560.77	2098
1562.87	2050
1564.96	2102
1567.06	2058
1569.15	2076
1571.25	2062
1573.34	2010
1575.43	2016
1577.53	2000
1579.62	1974
1581.71	2060
1583.8	1968
1585.89	1980
1587.98	2046
1590.06	1990
1592.15	1954
1594.24	1934
1596.33	2012
1598.41	1870
1600.5	1942
1602.58	1930
1604.66	1914
1606.75	1928
1608.83	1976
1610.91	1938
1612.99	1922
1615.07	1914
1617.15	1870
1619.23	1868
1621.31	1888
1623.39	1864
1625.46	1876
1627.54	1822
1629.62	1876
1631.69	1856
1633.77	1830
1635.84	1826
1637.91	1824
1639.99	1796
1642.06	1766
1644.13	1844
1646.2	1790
1648.27	1796
1650.34	1824
1652.41	1806
1654.47	1776
1656.54	1774
1658.61	1854
1660.67	1756
1662.74	1776
1664.81	1734
1666.87	1752
1668.93	1730
1671	1704
1673.06	1768
1675.12	1730
1677.18	1770
1679.24	1726
1681.3	1710
1683.36	1686
1685.42	1686
1687.47	1730
1689.53	1650
1691.59	1702
1693.64	1730
1695.7	1668
1697.75	1700
1699.81	1708
1701.86	1652
1703.91	1622
1705.97	1584
1708.02	1676
1710.07	1686
1712.12	1652
1714.17	1632
1716.22	1622
1718.26	1596
1720.31	1608
1722.36	1614
1724.4	1632
1726.45	1610
1728.49	1604
1730.54	1596
1732.58	1550
1734.63	1562
1736.67	1536
1738.71	1566
1740.75	1608
1742.79	1570
1744.83	1540
1746.87	1548
1748.91	1634
1750.95	1546
1752.98	1576
1755.02	1572
1757.06	1600
1759.09	1590
1761.13	1536
1763.16	1608
1765.19	1560
1767.23	1532
1769.26	1568
1771.29	1566
1773.32	1522
1775.35	1578
1777.38	1576
1779.41	1592
1781.44	1534
1783.47	1526
1785.49	1580
1787.52	1576
1789.55	1552
1791.57	1552
1793.6	1540
1795.62	1520
1797.64	1538
1799.67	1556
1801.69	1562
1803.71	1552
1805.73	1560
1807.75	1548
1809.77	1568
1811.79	1496
1813.81	1528
1815.83	1550
1817.84	1538
1819.86	1546
1821.88	1534
1823.89	1528
1825.91	1490
1827.92	1512
1829.93	1486
1831.95	1506
1833.96	1490
1835.97	1472
1837.98	1492
1839.99	1482
1842	1472
1844.01	1450
1846.02	1454
1848.03	1522
1850.03	1486
1852.04	1490
1854.05	1510
1856.05	1512
1858.06	1468
1860.06	1454
1862.06	1476
1864.07	1508
1866.07	1424
1868.07	1496
1870.07	1428
1872.07	1454
1874.07	1438
1876.07	1468
1878.07	1482
1880.07	1446
1882.07	1476
1884.06	1512
1886.06	1494
1888.05	1486
1890.05	1446
1892.04	1424
1894.04	1476
1896.03	1430
1898.02	1450
1900.01	1480
1902	1456
1903.99	1502
1905.98	1432
1907.97	1446
1909.96	1482
1911.95	1450
1913.94	1484
1915.93	1426
1917.91	1474
1919.9	1426
1921.88	1462
1923.87	1444
1925.85	1406
1927.83	1376
1929.82	1462
1931.8	1426
1933.78	1420
1935.76	1416
1937.74	1432
1939.72	1406
1941.7	1404
1943.68	1394
1945.65	1398
1947.63	1430
1949.61	1404
1951.58	1422
1953.56	1412
1955.53	1388
1957.51	1384
1959.48	1376
1961.45	1390
1963.43	1484
1965.4	1408
1967.37	1342
1969.34	1418
1971.31	1434
1973.28	1412
1975.25	1374
1977.22	1322
1979.18	1386
1981.15	1400
1983.12	1358
1985.08	1394
1987.05	1346
1989.01	1382
1990.97	1414
1992.94	1372
1994.9	1318
1996.86	1348
1998.82	1322
2000.78	1338
2002.74	1348
2004.7	1316
2006.66	1322
2008.62	1328
2010.58	1372
2012.54	1326
2014.49	1332
2016.45	1346
2018.4	1356
2020.36	1358
2022.31	1366
2024.27	1372
2026.22	1374
2028.17	1349
2030.12	1312
2032.07	1348
2034.03	1364
2035.98	1334
2037.93	1360
2039.87	1312
2041.82	1330
2043.77	1306
2045.72	1300
2047.66	1302
2049.61	1328
2051.55	1336
2053.5	1356
2055.44	1286
2057.39	1320
2059.33	1304
2061.27	1282
2063.21	1322
2065.15	1354
2067.09	1290
2069.03	1314
2070.97	1240
2072.91	1314
2074.85	1296
2076.79	1302
2078.73	1276
2080.66	1292
2082.6	1320
2084.53	1326
2086.47	1304
2088.4	1270
2090.33	1318
2092.27	1304
2094.2	1278
2096.13	1266
2098.06	1246
2099.99	1270
2101.92	1298
2103.85	1316
2105.78	1290
2107.71	1286
2109.64	1256
2111.56	1280
2113.49	1250
2115.41	1282
2117.34	1272
2119.26	1290
2121.19	1302
2123.11	1250
2125.03	1264
2126.96	1294
2128.88	1278
2130.8	1270
2132.72	1246
2134.64	1244
2136.56	1314
2138.48	1240
2140.4	1292
2142.31	1298
2144.23	1230
2146.15	1254
2148.06	1248
2149.98	1280
2151.89	1262
2153.81	1266
2155.72	1230
2157.63	1270
2159.55	1276
2161.46	1262
2163.37	1232
2165.28	1242
2167.19	1178
2169.1	1232
2171.01	1218
2172.91	1262
2174.82	1218
2176.73	1238
2178.64	1174
2180.54	1178
2182.45	1222
2184.35	1206
2186.26	1176
2188.16	1218
2190.06	1198
2191.96	1214
2193.87	1154
2195.77	1248
2197.67	1222
2199.57	1198
2201.47	1146
2203.37	1178
2205.27	1188
2207.16	1174
2209.06	1212
2210.96	1174
2212.85	1222
2214.75	1204
2216.64	1144
2218.54	1186
2220.43	1166
2222.33	1154
2224.22	1206.36
2226.11	1177.85
2228	1194.78
2229.89	1196.66
2231.78	1155.42
2233.67	1144.31
2235.56	1154.57
2237.45	1169.17
2239.34	1202.84
2241.23	1130.03
2243.11	1116.8
2245	1116.32
2246.89	1143.57
2248.77	1118.56
2250.66	1145.56
2252.54	1143.51
2254.42	1121.79
2256.31	1110.07
2258.19	1119.1
2260.07	1119.41
2261.95	1114.08
2263.83	1135.03
2265.71	1131.35
2267.59	1102.09
2269.47	1112.59
2271.35	1096.15
2273.23	1099.94
2275.1	1058.92
2276.98	1088.36
2278.86	1080.84
2280.73	1069.38
2282.61	1085.54
2284.48	1085.27
2286.36	1064.36
2288.23	1062.71
2290.1	1053.73
2291.98	1062.12
2293.85	1056.11
2295.72	1059.09
2297.59	1062.14
2299.46	1044.5
2301.33	1062.51
2303.2	1029.08
2305.06	1017.52
2306.93	1020.15
2308.8	1032.62
2310.67	1034.52
2312.53	998.26
2314.4	997.759
2316.26	992.744
2317.62	994
2319.5	1014
2321.37	1006
2323.24	1010
2325.12	1050
2326.99	1014
2328.86	940
2330.73	1006
2332.6	992
2334.47	966
2336.34	950
2338.2	960
2340.07	994
2341.94	968
2343.81	960
2345.67	980
2347.54	974
2349.4	970
2351.27	952
2353.13	962
2354.99	974
2356.86	928
2358.72	948
2360.58	968
2362.44	956
2364.3	940
2366.16	936
2368.02	962
2369.88	912
2371.74	948
2373.6	958
2375.45	928
2377.31	918
2379.17	906
2381.02	934
2382.88	906
2384.73	890
2386.58	884
2388.44	890
2390.29	906
2392.14	890
2393.99	884
2395.85	886
2397.7	876
2399.55	908
2401.4	864
2403.25	876
2405.09	850
2406.94	844
2408.79	866
2410.63	898
2412.48	870
2414.33	848
2416.17	840
2418.02	866
2419.86	828
2421.7	828
2423.55	840
2425.39	818
2427.23	844
2429.07	818
2430.91	818
2432.75	836
2434.59	828
2436.43	820
2438.27	786
2440.11	798
2441.95	750
2443.78	784
2445.62	762
2447.46	794
2449.29	792
2451.13	790
2452.96	794
2454.79	812
2456.63	758
2458.46	754
2460.29	782
2462.12	730
2463.95	772
2465.78	790
2467.61	748
2469.44	750
2471.27	796
2473.1	760
2474.93	738
2476.76	712
2478.58	746
2480.41	716
2482.23	706
2484.06	748
2485.88	720
2487.71	726
2489.53	696
2491.35	696
2493.18	696
2495	700
2496.82	720
2498.64	704
2500.46	688
2502.28	684
2504.1	666
2505.92	670
2507.74	670
2509.55	660
2511.37	678
2513.19	644
2515	646
2516.82	672
2518.63	664
2520.45	650
2522.26	658
2524.07	658
2525.89	626
2527.7	618
2529.51	614
2531.32	646
2533.13	602
2534.94	648
2536.75	636
2538.56	606
2540.37	636
2542.18	636
2543.98	634
2545.79	600
2547.6	626
2549.4	584
2551.21	590
2553.01	588
2554.82	578
2556.62	602
2558.42	608
2560.23	594
2562.03	564
2563.83	588
2565.63	566
2567.43	560
2569.23	568
2571.03	570
2572.83	550
2574.63	566
2576.43	602
2578.22	530
2580.02	548
2581.82	562
2583.61	548
2585.41	572
2587.2	574
2589	528
2590.79	560
2592.58	568
2594.38	548
2596.17	516
2597.96	516
2599.75	544
2601.54	528
2603.33	530
2605.12	550
2606.91	506
2608.7	508
2610.49	508
2612.27	518
2614.06	484
2615.85	508
2617.63	498
2619.42	490
2621.2	502
2622.99	504
2624.77	496
2626.55	494
2628.34	492
2630.12	470
2631.9	478
2633.68	474
2635.46	502
2637.24	476
2639.02	452
2640.8	446
2642.58	494
2644.36	460
2646.14	450
2647.91	470
2649.69	434
2651.46	458
2653.24	440
2655.01	432
2656.79	454
2658.56	428
2660.34	426
2662.11	438
2663.88	430
2665.65	426
2667.42	444
2669.2	438
2670.96	398
2672.73	444
2674.5	424
2676.27	434
2678.04	436
2679.81	416
2681.58	420
2683.34	416
2685.11	394
2686.87	416
2688.64	430
2690.4	392
2692.17	418
2693.93	380
2695.69	382
2697.46	420
2699.22	416
2700.98	392
2702.74	394
2704.5	390
2706.26	402
2708.02	382
2709.78	382
2711.54	376
2713.3	380
2715.05	362
2716.81	374
2718.57	388
2720.32	378
2722.08	370
2723.83	366
2725.59	344
2727.34	370
2729.09	360
2730.85	368
2732.6	340
2734.35	356
2736.1	356
2737.85	336
2739.6	332
2741.35	338
2743.1	332
2744.85	342
2746.6	320
2748.35	336
2750.09	350
2751.84	304
2753.59	302
2755.33	330
2757.08	334
2758.82	318
2760.57	332
2762.31	320
2764.05	314
2765.79	318
2767.54	290
2769.28	306
2771.02	300
2772.76	316
2774.5	322
2776.24	324
2777.98	292
2779.72	298
2781.46	274
2783.19	294
2784.93	284
2786.67	294
2788.4	302
2790.14	290
2791.87	294
2793.61	266
2795.34	292
2797.07	284
2798.81	296
2800.54	266
2802.27	272
2804	260
2805.74	280
2807.47	284
2809.2	252
2810.93	262
2812.65	264
2814.38	268
2816.11	264
2817.84	246
2819.56	254
2821.29	264
2823.02	258
2824.74	252
2826.47	254
2828.19	238
2829.92	274
2831.64	242
2833.36	236
2835.09	250
2836.81	234
2838.53	240
2840.25	234
2841.97	236
2843.69	222
2845.41	230
2847.13	254
2848.85	244
2850.57	226
2852.28	240
2854	220
2855.72	240
2857.43	230
2859.15	218
2860.86	228
2862.58	210
2864.29	238
2866.01	218
2867.72	218
2869.43	210
2871.14	204
2872.86	208
2874.57	202
2876.28	210
2877.99	206
2879.7	206
2881.41	208
2883.11	208
2884.82	228
2886.53	208
2888.24	220
2889.94	196
2891.65	190
2893.36	198
2895.06	202
2896.77	202
2898.47	192
2900.17	186
2901.88	182
2903.58	214
2905.28	194
2906.98	206
2908.69	192
2910.39	198
2912.09	172
2913.79	178
2915.49	184
2917.19	180
2918.88	190
2920.58	178
2922.28	178
2923.98	164
2925.67	202
2927.37	174
2929.06	164
2930.76	188
2932.45	174
2934.15	182
2935.84	168
2937.53	176
2939.23	178
2940.92	160
2942.61	172
2944.3	174
2945.99	158
2947.68	166
2949.37	164
2951.06	176
2952.75	156
2954.44	158
2956.12	182
2957.81	168
2959.5	154
2961.18	158
2962.87	156
2964.56	150
2966.24	154
2967.92	144
2969.61	150
2971.29	158
2972.97	150
2974.66	158
2976.34	166
2978.02	156
2979.7	152
2981.38	158
2983.06	154
2984.74	158
2986.42	160
2988.1	148
2989.78	140
2991.45	148
2993.13	150
2994.81	130
2996.48	156
2998.16	146
2999.83	150