File: muestras/papalo/leaf_100x_01.txt
#Acq. time (s)=	10
#Accumulations=	1
#Range (cm-¹)=	200...3000
#Windows=	3
#Autofocus=	Off
#AutoExposure=	Off
#Spike filter=	Off
#Delay time (s)=	0
#Binning=	1
#Readout mode=	Signal
#DeNoise=	Off
#ICS correction=	Off
#Dark correction=	Off
#Inst. Process=	Off
#Instrument=	LabRAM HR Evol
#Detector=	Syncerity OE
#Objective=	x100_VIS
#Grating=	600 (500nm)
#ND Filter=	0.01%
#Laser=	633nm_Edge
#Hole=	100.021
#Range=	Visible
#Project=	Omar
#Sample=	03-07-23
#Site=	papal
#Title=	leaf_100x
#Remark=
#Date=	03.07.2023 17:10
#Acquired=	03.07.2023 17:10:07
201.713	160
204.247	174
206.778	158
209.311	182
211.84	178
214.371	204
216.899	196
219.428	168
221.955	190
224.482	194
227.007	206
229.531	186
232.055	206
234.579	198
237.1	202
239.621	188
242.141	208
244.661	206
247.179	208
249.698	220
252.215	224
254.731	214
257.246	198
259.761	230
262.273	212
264.786	232
267.298	216
269.809	230
272.319	222
274.828	242
277.336	238
279.844	232
282.351	230
284.855	250
287.361	236
289.866	256
292.368	256
294.871	254
297.372	272
299.873	266
302.372	266
304.872	268
307.37	252
309.866	270
312.364	260
314.859	278
317.353	286
319.848	282
322.341	274
324.833	292
327.324	292
329.814	310
332.304	298
334.792	304
337.28	308
339.767	310
342.254	322
344.739	312
347.224	332
349.708	322
352.191	316
354.673	326
357.155	336
359.634	320
362.114	360
364.593	338
367.07	344
369.548	344
372.024	334
374.499	340
376.974	354
379.447	354
381.92	362
384.392	376
386.864	382
389.333	384
391.802	388
394.272	374
396.739	384
399.206	404
401.673	406
404.138	406
406.602	386
409.066	428
411.528	424
413.99	444
416.451	414
418.911	426
421.371	446
423.83	468
426.288	428
428.745	464
431.201	462
433.657	474
436.111	464
438.565	460
441.017	466
443.469	496
445.921	498
448.37	498
450.821	498
453.27	514
455.717	488
458.165	494
460.61	486
463.056	484
465.5	508
467.945	528
470.387	544
472.829	560
475.271	550
477.711	550
480.15	602
482.589	562
485.027	566
487.465	544
489.901	564
492.337	566
494.771	606
497.205	578
499.638	636
502.07	600
504.502	626
506.933	648
509.363	642
511.792	640
514.219	666
516.647	632
519.073	672
521.5	646
523.924	646
526.348	678
528.772	692
531.194	714
533.616	710
536.036	660
538.457	696
540.875	752
543.294	712
545.712	720
548.128	720
550.545	712
552.959	770
555.373	750
557.788	740
560.2	778
562.612	758
565.023	786
567.433	762
569.843	828
572.251	822
574.659	818
577.066	818
579.472	850
581.878	872
584.283	850
586.687	878
589.09	874
591.493	890
593.893	884
596.294	892
598.694	896
601.093	926
603.491	924
605.889	958
608.285	958
610.682	946
613.076	1016
615.471	1018
617.864	998
620.256	998
622.648	1034
625.039	1078
627.429	1054
629.819	1094
632.208	1102
634.595	1112
636.982	1138
639.369	1114
641.755	1160
644.139	1188
646.523	1198
648.906	1218
651.288	1212
653.67	1268
656.051	1218
658.429	1244
660.808	1312
663.187	1290
665.565	1312
667.942	1342
670.317	1338
672.692	1378
675.067	1346
677.44	1378
679.813	1392
682.184	1446
684.556	1506
686.926	1512
689.296	1506
691.664	1502
694.033	1542
696.4	1548
698.766	1580
701.133	1556
703.497	1622
705.861	1604
708.224	1684
710.586	1662
712.949	1736
715.31	1702
717.67	1724
720.029	1770
722.388	1822
724.746	1786
727.103	1790
729.458	1888
731.814	1944
734.168	1970
736.523	1924
738.876	1974
741.227	1942
743.579	2054
745.931	2014
748.28	2064
750.629	2090
752.977	2132
755.325	2182
757.672	2178
760.018	2150
762.363	2228
764.708	2240
767.052	2244
769.394	2316
771.737	2376
774.078	2366
776.419	2426
778.758	2426
781.097	2500
783.435	2448
785.773	2560
788.11	2568
790.446	2584
792.781	2606
795.115	2670
797.449	2748
799.782	2840
802.115	2794
804.446	2834
806.777	2890
809.106	2982
811.435	2980
813.764	3018
816.091	3024
818.418	3026
820.743	3188
823.069	3206
825.393	3094
827.717	3240
830.039	3336
832.362	3330
834.683	3402
837.003	3428
839.324	3582
841.643	3550
843.961	3636
846.278	3670
848.594	3738
850.91	3722
853.227	3820
855.541	3908
857.855	3892
860.168	3908
862.48	4012
864.79	4066
867.101	4044
869.411	4162
871.721	4184
874.029	4272
876.336	4338
878.643	4284
880.95	4306
883.254	4426
885.559	4424
887.862	4490
890.166	4486
892.467	4560
894.77	4602
897.07	4622
899.371	4698
901.669	4880
903.968	4842
906.266	4868
908.563	4932
910.859	4946
913.154	5028
915.449	5066
917.742	5076
920.036	5194
922.329	5262
924.621	5360
926.911	5366
929.201	5496
931.49	5450
933.779	5620
936.068	5594
938.355	5744
940.64	5820
942.926	5862
945.212	5952
947.495	5970
949.779	6112
952.062	6158
954.344	6174
956.625	6274
958.905	6294
961.184	6448
963.464	6454
965.742	6562
968.02	6498
970.296	6762
972.572	6776
974.847	6834
977.121	6894
979.396	7026
981.669	6902
983.941	6952
986.212	7150
988.483	7260
990.753	7196
993.022	7324
995.29	7382
997.558	7550
999.825	7484
1002.09	7516
1004.36	7670
1006.62	7640
1008.89	7766
1011.15	7790
1013.41	7932
1015.67	7922
1017.93	8086
1020.19	8198
1022.45	8260
1024.71	8318
1026.97	8456
1029.23	8520
1031.49	8556
1033.74	8732
1036	8774
1038.25	8790
1040.5	8888
1042.76	9072
1045.01	9134
1047.26	9230
1049.51	9344
1051.76	9468
1054.01	9464
1056.26	9670
1058.51	9646
1060.75	9724
1063	9908
1065.25	9828
1067.49	10012
1069.73	9998
1071.98	9976
1074.22	10062
1076.46	10172
1078.7	10206
1080.94	10442
1083.18	10386
1085.42	10310
1087.66	10522
1089.9	10466
1092.14	10510
1094.37	10544
1096.61	10556
1098.84	10722
1101.08	10876
1103.31	10792
1105.54	10926
1107.77	10934
1110	10928
1112.23	10934
1114.46	10976
1116.69	11052
1118.92	10924
1121.15	11138
1123.37	11226
1125.6	11174
1127.83	11186
1130.05	11418
1132.27	11316
1134.5	11350
1136.72	11426
1138.94	11534
1141.16	11638
1143.38	11596
1145.6	11532
1147.82	11624
1150.04	11594
1152.26	11604
1154.47	11732
1156.69	11748
1158.9	11700
1161.12	11770
1163.33	11654
1165.54	11816
1167.76	11734
1169.97	11548
1172.18	11754
1174.39	11760
1176.6	11654
1178.81	11508
1181.02	11624
1183.22	11472
1185.43	11532
1187.63	11216
1189.84	11444
1192.04	11286
1194.25	11302
1196.45	11120
1198.65	11058
1200.85	11158
1203.05	11058
1205.25	10888
1207.45	10922
1209.65	10776
1211.85	10680
1214.05	10652
1216.24	10556
1218.44	10506
1220.64	10430
1222.83	10280
1225.02	10270
1227.22	10214
1229.41	10160
1231.6	10020
1233.79	10040
1235.98	9882
1238.17	9810
1240.36	9846
1242.55	9780
1244.73	9658
1246.92	9646
1249.11	9516
1251.29	9436
1253.48	9370
1255.66	9220
1257.84	9244
1260.03	9240
1262.21	9068
1264.39	9090
1266.57	8868
1268.75	8954
1270.93	8742
1273.11	8750
1275.28	8654
1277.46	8496
1279.64	8460
1281.81	8268
1283.98	8307.27
1286.16	8277.05
1288.33	8149.66
1290.5	8060.15
1292.68	7845.61
1294.85	7762.89
1297.02	7600.51
1299.19	7556.75
1301.36	7399.38
1303.53	7339.12
1305.69	7135.63
1307.86	7014.59
1310.03	6933.81
1312.19	6832.35
1314.36	6782.26
1316.52	6628.53
1318.68	6526.61
1320.85	6416.76
1323.01	6180.98
1325.17	6216.77
1327.33	6075.77
1329.49	6037.89
1331.65	5926.61
1333.81	5838.54
1335.97	5701.52
1338.12	5529.48
1340.28	5503.93
1342.44	5453.74
1344.59	5422.26
1346.75	5236.49
1348.9	5146.77
1351.05	5062.96
1353.2	5023.76
1355.36	4935.45
1357.51	4866.43
1359.66	4702.15
1361.81	4771.46
1363.96	4586.55
1366.1	4568.48
1368.25	4528.82
1370.4	4416.66
1372.54	4235.91
1374.69	4265.07
1376.83	4229.09
1378.98	4204.18
1381.12	4077.86
1383.26	4027.96
1385.41	4003.37
1387.55	3879.18
1389.69	3816.4
1391.83	3757.88
1393.02	3656
1395.17	3614
1397.32	3618
1399.47	3620
1401.62	3618
1403.77	3534
1405.91	3528
1408.06	3430
1410.2	3444
1412.35	3432
1414.49	3346
1416.63	3352
1418.78	3350
1420.92	3332
1423.06	3256
1425.2	3278
1427.34	3178
1429.48	3154
1431.61	3138
1433.75	3082
1435.89	3154
1438.02	3104
1440.16	3054
1442.3	3132
1444.43	3100
1446.56	3018
1448.7	2958
1450.83	2992
1452.96	2998
1455.09	2862
1457.22	2916
1459.35	2928
1461.48	2814
1463.61	2900
1465.73	2878
1467.86	2846
1469.98	2806
1472.11	2776
1474.24	2802
1476.36	2786
1478.48	2742
1480.6	2730
1482.73	2730
1484.85	2694
1486.97	2730
1489.09	2670
1491.21	2664
1493.33	2588
1495.44	2620
1497.56	2614
1499.68	2568
1501.79	2548
1503.91	2542
1506.02	2550
1508.14	2442
1510.25	2506
1512.36	2466
1514.48	2468
1516.59	2542
1518.7	2484
1520.81	2370
1522.92	2402
1525.02	2378
1527.13	2432
1529.24	2404
1531.35	2330
1533.45	2418
1535.56	2260
1537.66	2384
1539.77	2338
1541.87	2266
1543.97	2300
1546.08	2252
1548.18	2260
1550.28	2248
1552.38	2198
1554.48	2160
1556.57	2198
1558.67	2180
1560.77	2168
1562.87	2166
1564.96	2102
1567.06	2156
1569.15	2156
1571.25	2094
1573.34	2156
1575.43	2136
1577.53	2072
1579.62	2068
1581.71	2078
1583.8	2086
1585.89	2050
1587.98	2092
1590.06	2052
1592.15	2046
1594.24	2060
1596.33	2050
1598.41	2034
1600.5	2044
1602.58	2032
1604.66	2088
1606.75	1958
1608.83	1986
1610.91	2018
1612.99	2016
1615.07	1978
1617.15	1932
1619.23	2008
1621.31	1970
1623.39	1978
1625.46	1976
1627.54	1916
1629.62	2000
1631.69	1964
1633.77	2004
1635.84	1902
1637.91	1920
1639.99	1838
1642.06	1910
1644.13	1906
1646.2	1884
1648.27	1944
1650.34	1880
1652.41	1908
1654.47	1880
1656.54	1866
1658.61	1854
1660.67	1838
1662.74	1850
1664.81	1852
1666.87	1822
1668.93	1826
1671	1838
1673.06	1846
1675.12	1816
1677.18	1782
1679.24	1806
1681.3	1794
1683.36	1748
1685.42	1764
1687.47	1790
1689.53	1762
1691.59	1750
1693.64	1724
1695.7	1788
1697.75	1742
1699.81	1740
1701.86	1736
1703.91	1776
1705.97	1750
1708.02	1694
1710.07	1724
1712.12	1722
1714.17	1744
1716.22	1724
1718.26	1652
1720.31	1770
1722.36	1714
1724.4	1740
1726.45	1662
1728.49	1692
1730.54	1730
1732.58	1678
1734.63	1670
1736.67	1700
1738.71	1646
1740.75	1708
1742.79	1646
1744.83	1696
1746.87	1648
1748.91	1672
1750.95	1666
1752.98	1640
1755.02	1684
1757.06	1664
1759.09	1662
1761.13	1638
1763.16	1652
1765.19	1666
1767.23	1686
1769.26	1644
1771.29	1610
1773.32	1604
1775.35	1676
1777.38	1610
1779.41	1638
1781.44	1652
1783.47	1626
1785.49	1600
1787.52	1650
1789.55	1598
1791.57	1626
1793.6	1674
1795.62	1602
1797.64	1678
1799.67	1612
1801.69	1634
1803.71	1628
1805.73	1622
1807.75	1660
1809.77	1638
1811.79	1604
1813.81	1602
1815.83	1622
1817.84	1608
1819.86	1656
1821.88	1576
1823.89	1596
1825.91	1582
1827.92	1568
1829.93	1586
1831.95	1554
1833.96	1556
1835.97	1594
1837.98	1554
1839.99	1550
1842	1538
1844.01	1554
1846.02	1558
1848.03	1592
1850.03	1542
1852.04	1602
1854.05	1550
1856.05	1558
1858.06	1564
1860.06	1554
1862.06	1548
1864.07	1584
1866.07	1522
1868.07	1516
1870.07	1568
1872.07	1562
1874.07	1520
1876.07	1542
1878.07	1514
1880.07	1536
1882.07	1576
1884.06	1548
1886.06	1572
1888.05	1518
1890.05	1516
1892.04	1530
1894.04	1540
1896.03	1560
1898.02	1552
1900.01	1506
1902	1512
1903.99	1554
1905.98	1506
1907.97	1542
1909.96	1486
1911.95	1544
1913.94	1492
1915.93	1508
1917.91	1528
1919.9	1488
1921.88	1534
1923.87	1534
1925.85	1524
1927.83	1494
1929.82	1516
1931.8	1512
1933.78	1518
1935.76	1502
1937.74	1492
1939.72	1454
1941.7	1452
1943.68	1496
1945.65	1444
1947.63	1468
1949.61	1518
1951.58	1504
1953.56	1494
1955.53	1452
1957.51	1480
1959.48	1480
1961.45	1478
1963.43	1472
1965.4	1496
1967.37	1476
1969.34	1458
1971.31	1460
1973.28	1426
1975.25	1484
1977.22	1474
1979.18	1430
1981.15	1434
1983.12	1426
1985.08	1452
1987.05	1442
1989.01	1430
1990.97	1486
1992.94	1496
1994.9	1490
1996.86	1456
1998.82	1444
2000.78	1400
2002.74	1430
2004.7	1490
2006.66	1418
2008.62	1432
2010.58	1460
2012.54	1432
2014.49	1486
2016.45	1378
2018.4	1452
2020.36	1406
2022.31	1426
2024.27	1470
2026.22	1436
2028.17	1444
2030.12	1416
2032.07	1448
2034.03	1434
2035.98	1410
2037.93	1420
2039.87	1400
2041.82	1436
2043.77	1422
2045.72	1406
2047.66	1370
2049.61	1412
2051.55	1392
2053.5	1436
2055.44	1398
2057.39	1404
2059.33	1388
2061.27	1396
2063.21	1392
2065.15	1402
2067.09	1412
2069.03	1410
2070.97	1380
2072.91	1334
2074.85	1430
2076.79	1370
2078.73	1398
2080.66	1384
2082.6	1374
2084.53	1388
2086.47	1384
2088.4	1382
2090.33	1360
2092.27	1344
2094.2	1392
2096.13	1358
2098.06	1390
2099.99	1402
2101.92	1386
2103.85	1380
2105.78	1346
2107.71	1378
2109.64	1350
2111.56	1336
2113.49	1326
2115.41	1406
2117.34	1336
2119.26	1334
2121.19	1352
2123.11	1334
2125.03	1336
2126.96	1380
2128.88	1394
2130.8	1340
2132.72	1332
2134.64	1348
2136.56	1340
2138.48	1324
2140.4	2150
2142.31	1292
2144.23	1374
2146.15	1284
2148.06	1286
2149.98	1334
2151.89	1366
2153.81	1298
2155.72	1354
2157.63	1342
2159.55	1324
2161.46	1314
2163.37	1326
2165.28	1338
2167.19	1320
2169.1	1318
2171.01	1286
2172.91	1260
2174.82	1330
2176.73	1276
2178.64	1312
2180.54	1272
2182.45	1286
2184.35	1274
2186.26	1282
2188.16	1326
2190.06	1304
2191.96	1254
2193.87	1270
2195.77	1266
2197.67	1254
2199.57	1252
2201.47	1292
2203.37	1278
2205.27	1254
2207.16	1250
2209.06	1252
2210.96	1282
2212.85	1254
2214.75	1272
2216.64	1216
2218.54	1242
2220.43	1246
2222.33	1246
2224.22	1235.65
2226.11	1226.44
2228	1250.23
2229.89	1217.34
2231.78	1235.03
2233.67	1186.55
2235.56	1175.03
2237.45	1161.58
2239.34	1144.11
2241.23	1148.53
2243.11	1110.68
2245	1155.7
2246.89	1144.71
2248.77	1105.53
2250.66	1095.9
2252.54	1069.95
2254.42	1066.77
2256.31	1077.04
2258.19	1091.37
2260.07	1057.83
2261.95	1047.21
2263.83	1027.45
2265.71	1004.65
2267.59	998.828
2269.47	1007.05
2271.35	992.926
2273.23	964.987
2275.1	976.462
2276.98	959.859
2278.86	926.87
2280.73	966.416
2282.61	939.036
2284.48	925.949
2286.36	907.046
2288.23	895.405
2290.1	886.43
2291.98	906.143
2293.85	877.695
2295.72	867.11
2297.59	867.538
2299.46	831.031
2301.33	851.828
2303.2	820.953
2305.06	811.176
2306.93	798.95
2308.8	817.049
2310.67	799.214
2312.53	789.71
2314.4	758.753
2316.26	748.527
2317.62	760
2319.5	744
2321.37	766
2323.24	754
2325.12	712
2326.99	736
2328.86	750
2330.73	726
2332.6	744
2334.47	738
2336.34	762
2338.2	702
2340.07	726
2341.94	684
2343.81	742
2345.67	732
2347.54	710
2349.4	692
2351.27	740
2353.13	710
2354.99	698
2356.86	730
2358.72	706
2360.58	732
2362.44	710
2364.3	706
2366.16	718
2368.02	702
2369.88	738
2371.74	678
2373.6	704
2375.45	720
2377.31	708
2379.17	714
2381.02	676
2382.88	692
2384.73	688
2386.58	686
2388.44	690
2390.29	670
2392.14	668
2393.99	646
2395.85	682
2397.7	690
2399.55	672
2401.4	672
2403.25	660
2405.09	654
2406.94	648
2408.79	652
2410.63	674
2412.48	670
2414.33	654
2416.17	634
2418.02	640
2419.86	664
2421.7	684
2423.55	620
2425.39	620
2427.23	628
2429.07	638
2430.91	652
2432.75	614
2434.59	632
2436.43	616
2438.27	598
2440.11	602
2441.95	620
2443.78	612
2445.62	596
2447.46	582
2449.29	604
2451.13	604
2452.96	582
2454.79	608
2456.63	600
2458.46	588
2460.29	600
2462.12	572
2463.95	602
2465.78	552
2467.61	610
2469.44	546
2471.27	566
2473.1	610
2474.93	586
2476.76	548
2478.58	584
2480.41	578
2482.23	574
2484.06	538
2485.88	558
2487.71	524
2489.53	534
2491.35	562
2493.18	564
2495	514
2496.82	542
2498.64	552
2500.46	534
2502.28	546
2504.1	524
2505.92	544
2507.74	528
2509.55	526
2511.37	500
2513.19	526
2515	502
2516.82	528
2518.63	526
2520.45	510
2522.26	500
2524.07	490
2525.89	490
2527.7	504
2529.51	464
2531.32	488
2533.13	512
2534.94	478
2536.75	466
2538.56	468
2540.37	492
2542.18	448
2543.98	470
2545.79	484
2547.6	472
2549.4	480
2551.21	470
2553.01	468
2554.82	438
2556.62	454
2558.42	464
2560.23	452
2562.03	442
2563.83	464
2565.63	460
2567.43	454
2569.23	436
2571.03	440
2572.83	424
2574.63	426
2576.43	434
2578.22	444
2580.02	418
2581.82	432
2583.61	434
2585.41	402
2587.2	416
2589	424
2590.79	420
2592.58	446
2594.38	416
2596.17	430
2597.96	414
2599.75	420
2601.54	408
2603.33	402
2605.12	418
2606.91	416
2608.7	388
2610.49	398
2612.27	380
2614.06	382
2615.85	386
2617.63	392
2619.42	394
2621.2	376
2622.99	390
2624.77	382
2626.55	394
2628.34	370
2630.12	378
2631.9	390
2633.68	376
2635.46	348
2637.24	376
2639.02	384
2640.8	358
2642.58	374
2644.36	370
2646.14	366
2647.91	336
2649.69	360
2651.46	366
2653.24	354
2655.01	390
2656.79	340
2658.56	328
2660.34	344
2662.11	330
2663.88	322
2665.65	354
2667.42	340
2669.2	360
2670.96	326
2672.73	340
2674.5	346
2676.27	338
2678.04	350
2679.81	362
2681.58	306
2683.34	306
2685.11	316
2686.87	346
2688.64	334
2690.4	326
2692.17	312
2693.93	320
2695.69	312
2697.46	308
2699.22	316
2700.98	316
2702.74	318
2704.5	304
2706.26	298
2708.02	288
2709.78	282
2711.54	302
2713.3	298
2715.05	288
2716.81	296
2718.57	302
2720.32	308
2722.08	268
2723.83	280
2725.59	290
2727.34	298
2729.09	284
2730.85	292
2732.6	274
2734.35	294
2736.1	280
2737.85	280
2739.6	272
2741.35	276
2743.1	274
2744.85	308
2746.6	264
2748.35	258
2750.09	268
2751.84	266
2753.59	258
2755.33	278
2757.08	272
2758.82	260
2760.57	280
2762.31	256
2764.05	260
2765.79	254
2767.54	240
2769.28	240
2771.02	248
2772.76	236
2774.5	250
2776.24	234
2777.98	238
2779.72	240
2781.46	232
2783.19	228
2784.93	242
2786.67	234
2788.4	236
2790.14	240
2791.87	246
2793.61	230
2795.34	224
2797.07	214
2798.81	256
2800.54	232
2802.27	200
2804	220
2805.74	220
2807.47	220
2809.2	220
2810.93	218
2812.65	216
2814.38	220
2816.11	214
2817.84	210
2819.56	212
2821.29	214
2823.02	216
2824.74	190
2826.47	192
2828.19	198
2829.92	188
2831.64	198
2833.36	196
2835.09	210
2836.81	194
2838.53	190
2840.25	212
2841.97	184
2843.69	190
2845.41	202
2847.13	206
2848.85	182
2850.57	192
2852.28	184
2854	190
2855.72	176
2857.43	176
2859.15	174
2860.86	186
2862.58	164
2864.29	156
2866.01	160
2867.72	192
2869.43	168
2871.14	186
2872.86	190
2874.57	170
2876.28	168
2877.99	168
2879.7	176
2881.41	176
2883.11	180
2884.82	168
2886.53	178
2888.24	170
2889.94	172
2891.65	164
2893.36	162
2895.06	156
2896.77	160
2898.47	170
2900.17	168
2901.88	164
2903.58	160
2905.28	162
2906.98	158
2908.69	172
2910.39	170
2912.09	144
2913.79	150
2915.49	164
2917.19	154
2918.88	146
2920.58	154
2922.28	160
2923.98	156
2925.67	158
2927.37	160
2929.06	162
2930.76	144
2932.45	148
2934.15	130
2935.84	154
2937.53	152
2939.23	150
2940.92	146
2942.61	146
2944.3	138
2945.99	140
2947.68	154
2949.37	148
2951.06	150
2952.75	130
2954.44	148
2956.12	132
2957.81	150
2959.5	128
2961.18	144
2962.87	134
2964.56	156
2966.24	154
2967.92	130
2969.61	128
2971.29	126
2972.97	138
2974.66	134
2976.34	124
2978.02	146
2979.7	114
2981.38	130
2983.06	136
2984.74	126
2986.42	136
2988.1	118
2989.78	110
2991.45	144
2993.13	128
2994.81	126
2996.48	126
2998.16	126
2999.83	110