File: muestras/papalo/leaf_16.txt
#Acq. time (s)=	10
#Accumulations=	1
#Range (cm-¹)=	200...3000
#Windows=	3
#Autofocus=	Off
#AutoExposure=	Off
#Spike filter=	Off
#Delay time (s)=	0
#Binning=	1
#Readout mode=	Signal
#DeNoise=	Off
#ICS correction=	Off
#Dark correction=	Off
#Inst. Process=	Off
#Instrument=	LabRAM HR Evol
#Detector=	Syncerity OE
#Objective=	x100_VIS
#Grating=	600 (500nm)
#ND Filter=	0.01%
#Laser=	633nm_Edge
#Hole=	100.021
#Range=	Visible
#Project=	Omar
#Sample=	03-07-23
#Site=	papal
#Title=	leaf
#Remark=
#Date=	03.07.2023 17:07
#Acquired=	03.07.2023 17:07:19
201.713	104
204.247	102
206.778	106
209.311	94
211.84	114
214.371	96
216.899	122
219.428	124
221.955	104
224.482	114
227.007	118
229.531	112
232.055	126
234.579	134
237.1	116
239.621	120
242.141	128
244.661	128
247.179	136
249.698	122
252.215	128
254.731	142
257.246	134
259.761	128
262.273	138
264.786	128
267.298	146
269.809	142
272.319	146
274.828	158
277.336	146
279.844	136
282.351	136
284.855	154
287.361	164
289.866	156
292.368	140
294.871	166
297.372	168
299.873	176
302.372	164
304.872	178
307.37	162
309.866	180
312.364	178
314.859	188
317.353	190
319.848	180
322.341	186
324.833	200
327.324	198
329.814	186
332.304	204
334.792	216
337.28	188
339.767	200
342.254	194
344.739	188
347.224	208
349.708	218
352.191	212
354.673	216
357.155	224
359.634	208
362.114	214
364.593	220
367.07	232
369.548	232
372.024	222
374.499	254
376.974	224
379.447	240
381.92	234
384.392	248
386.864	246
389.333	246
391.802	242
394.272	258
396.739	272
399.206	236
401.673	282
404.138	276
406.602	270
409.066	268
411.528	276
413.99	284
416.451	294
418.911	302
421.371	282
423.83	308
426.288	288
428.745	300
431.201	312
433.657	300
436.111	338
438.565	318
441.017	330
443.469	334
445.921	318
448.37	326
450.821	334
453.27	332
455.717	340
458.165	362
460.61	334
463.056	348
465.5	348
467.945	388
470.387	370
472.829	378
475.271	372
477.711	362
480.15	354
482.589	392
485.027	390
487.465	406
489.901	406
492.337	404
494.771	410
497.205	410
499.638	422
502.07	412
504.502	428
506.933	452
509.363	430
511.792	440
514.219	438
516.647	436
519.073	438
521.5	442
523.924	452
526.348	462
528.772	470
531.194	470
533.616	462
536.036	474
538.457	490
540.875	494
543.294	480
545.712	460
548.128	482
550.545	534
552.959	528
555.373	474
557.788	476
560.2	504
562.612	520
565.023	510
567.433	536
569.843	546
572.251	560
574.659	532
577.066	550
579.472	564
581.878	596
584.283	586
586.687	598
589.09	586
591.493	600
593.893	600
596.294	600
598.694	640
601.093	620
603.491	622
605.889	634
608.285	646
610.682	638
613.076	698
615.471	664
617.864	672
620.256	710
622.648	684
625.039	722
627.429	698
629.819	700
632.208	714
634.595	722
636.982	732
639.369	744
641.755	754
644.139	756
646.523	790
648.906	792
651.288	770
653.67	790
656.051	816
658.429	816
660.808	862
663.187	816
665.565	880
667.942	842
670.317	872
672.692	860
675.067	908
677.44	872
679.813	890
682.184	890
684.556	922
686.926	936
689.296	984
691.664	986
694.033	948
696.4	1022
698.766	980
701.133	1042
703.497	1028
705.861	1072
708.224	1042
710.586	1058
712.949	1118
715.31	1088
717.67	1108
720.029	1090
722.388	1142
724.746	1134
727.103	1172
729.458	1166
731.814	1210
734.168	1256
736.523	1210
738.876	1234
741.227	1254
743.579	1272
745.931	1296
748.28	1318
750.629	1314
752.977	1366
755.325	1366
757.672	1376
760.018	1370
762.363	1376
764.708	1416
767.052	1444
769.394	1436
771.737	1410
774.078	1470
776.419	1492
778.758	1520
781.097	1514
783.435	1604
785.773	1548
788.11	1618
790.446	1610
792.781	1644
795.115	1648
797.449	1636
799.782	1636
802.115	1706
804.446	1724
806.777	1788
809.106	1760
811.435	1790
813.764	1820
816.091	1850
818.418	1874
820.743	1886
823.069	1918
825.393	1968
827.717	1974
830.039	2026
832.362	2050
834.683	2052
837.003	2020
839.324	2118
841.643	2144
843.961	2186
846.278	2176
848.594	2220
850.91	2286
853.227	2260
855.541	2264
857.855	2350
860.168	2284
862.48	2346
864.79	2404
867.101	2482
869.411	2472
871.721	2508
874.029	2524
876.336	2476
878.643	2554
880.95	2598
883.254	2662
885.559	2628
887.862	2716
890.166	2708
892.467	2696
894.77	2778
897.07	2796
899.371	2812
901.669	2828
903.968	2792
906.266	2888
908.563	2900
910.859	2926
913.154	2986
915.449	3004
917.742	3130
920.036	3094
922.329	3110
924.621	3180
926.911	3196
929.201	3244
931.49	3330
933.779	3366
936.068	3314
938.355	3350
940.64	3450
942.926	3398
945.212	3532
947.495	3558
949.779	3564
952.062	3592
954.344	3682
956.625	3696
958.905	3782
961.184	3756
963.464	3760
965.742	3868
968.02	3936
970.296	3946
972.572	4014
974.847	3996
977.121	4090
979.396	4062
981.669	4196
983.941	4186
986.212	4224
988.483	4258
990.753	4296
993.022	4324
995.29	4398
997.558	4432
999.825	4502
1002.09	4420
1004.36	4528
1006.62	4554
1008.89	4648
1011.15	4720
1013.41	4764
1015.67	4812
1017.93	4792
1020.19	4912
1022.45	4924
1024.71	5014
1026.97	5022
1029.23	5052
1031.49	5146
1033.74	5244
1036	5278
1038.25	5258
1040.5	5406
1042.76	5368
1045.01	5370
1047.26	5450
1049.51	5594
1051.76	5668
1054.01	5744
1056.26	5756
1058.51	5804
1060.75	5818
1063	6002
1065.25	5906
1067.49	5998
1069.73	6138
1071.98	6080
1074.22	6024
1076.46	6206
1078.7	6208
1080.94	6252
1083.18	6250
1085.42	6294
1087.66	6406
1089.9	6360
1092.14	6480
1094.37	6402
1096.61	6530
1098.84	6494
1101.08	6700
1103.31	6596
1105.54	6674
1107.77	6718
1110	6882
1112.23	6810
1114.46	6770
1116.69	6898
1118.92	6954
1121.15	7002
1123.37	6958
1125.6	7118
1127.83	7140
1130.05	7232
1132.27	7216
1134.5	7230
1136.72	7302
1138.94	7364
1141.16	7420
1143.38	7392
1145.6	7474
1147.82	7444
1150.04	7462
1152.26	7480
1154.47	7560
1156.69	7616
1158.9	7744
1161.12	7602
1163.33	7762
1165.54	7786
1167.76	7726
1169.97	7652
1172.18	7724
1174.39	7840
1176.6	7862
1178.81	7766
1181.02	7740
1183.22	7842
1185.43	7754
1187.63	7800
1189.84	7646
1192.04	7800
1194.25	7824
1196.45	7746
1198.65	7752
1200.85	7690
1203.05	7648
1205.25	7768
1207.45	7698
1209.65	7580
1211.85	7638
1214.05	7682
1216.24	7660
1218.44	7506
1220.64	7492
1222.83	7584
1225.02	7500
1227.22	7474
1229.41	7462
1231.6	7462
1233.79	7350
1235.98	7386
1238.17	7386
1240.36	7346
1242.55	7296
1244.73	7224
1246.92	7242
1249.11	7098
1251.29	7168
1253.48	7176
1255.66	7056
1257.84	7132
1260.03	7104
1262.21	7064
1264.39	6932
1266.57	6904
1268.75	6868
1270.93	6828
1273.11	6856
1275.28	6792
1277.46	6746
1279.64	6678
1281.81	6652
1283.98	6596.44
1286.16	6627.87
1288.33	6591.36
1290.5	6559.06
1292.68	6360.77
1294.85	6324.58
1297.02	6230.65
1299.19	6305.31
1301.36	6185.16
1303.53	6145.55
1305.69	6060.2
1307.86	6022.26
1310.03	5947.09
1312.19	5954.81
1314.36	5957.95
1316.52	5821.37
1318.68	5764.87
1320.85	5735.86
1323.01	5668.13
1325.17	5644.96
1327.33	5555.2
1329.49	5547.13
1331.65	5442.78
1333.81	5401.32
1335.97	5314.22
1338.12	5367.26
1340.28	5285.34
1342.44	5195.78
1344.59	5133.99
1346.75	5094.13
1348.9	5055.07
1351.05	5018.13
1353.2	4989.96
1355.36	4844.11
1357.51	4927.5
1359.66	4830.14
1361.81	4816.25
1363.96	4734.21
1366.1	4752.25
1368.25	4649.55
1370.4	4630.54
1372.54	4598.98
1374.69	4582.48
1376.83	4482.33
1378.98	4469.17
1381.12	4450.97
1383.26	4466.43
1385.41	4406.11
1387.55	4313.51
1389.69	4311.69
1391.83	4241.2
1393.02	4164
1395.17	4144
1397.32	4196
1399.47	4148
1401.62	4176
1403.77	4080
1405.91	4010
1408.06	3976
1410.2	3984
1412.35	3934
1414.49	3818
1416.63	3854
1418.78	3968
1420.92	3876
1423.06	3792
1425.2	3814
1427.34	3772
1429.48	3726
1431.61	3786
1433.75	3602
1435.89	3616
1438.02	3536
1440.16	3616
1442.3	3578
1444.43	3560
1446.56	3490
1448.7	3548
1450.83	3558
1452.96	3472
1455.09	3474
1457.22	3476
1459.35	3442
1461.48	3430
1463.61	3408
1465.73	3430
1467.86	3400
1469.98	3302
1472.11	3354
1474.24	3274
1476.36	3314
1478.48	3294
1480.6	3236
1482.73	3194
1484.85	3190
1486.97	3160
1489.09	3154
1491.21	3114
1493.33	3132
1495.44	3114
1497.56	3108
1499.68	3066
1501.79	3036
1503.91	3066
1506.02	2946
1508.14	3024
1510.25	3044
1512.36	3016
1514.48	2938
1516.59	2974
1518.7	2906
1520.81	2942
1522.92	2886
1525.02	2910
1527.13	2826
1529.24	2834
1531.35	2876
1533.45	2858
1535.56	2750
1537.66	2774
1539.77	2770
1541.87	2762
1543.97	2752
1546.08	2742
1548.18	2784
1550.28	2728
1552.38	2748
1554.48	2652
1556.57	2648
1558.67	2658
1560.77	2644
1562.87	2550
1564.96	2664
1567.06	2582
1569.15	2550
1571.25	2546
1573.34	2550
1575.43	2532
1577.53	2542
1579.62	2510
1581.71	2496
1583.8	2498
1585.89	2498
1587.98	2462
1590.06	2464
1592.15	2484
1594.24	2476
1596.33	2510
1598.41	2524
1600.5	2394
1602.58	2432
1604.66	2466
1606.75	2444
1608.83	2416
1610.91	2422
1612.99	2408
1615.07	2362
1617.15	2424
1619.23	2420
1621.31	2404
1623.39	2314
1625.46	2346
1627.54	2362
1629.62	2384
1631.69	2292
1633.77	2360
1635.84	2358
1637.91	2326
1639.99	2338
1642.06	2344
1644.13	2316
1646.2	2332
1648.27	2322
1650.34	2302
1652.41	2230
1654.47	2308
1656.54	2272
1658.61	2308
1660.67	2278
1662.74	2248
1664.81	2220
1666.87	2254
1668.93	2228
1671	2198
1673.06	2146
1675.12	2194
1677.18	2198
1679.24	2188
1681.3	2144
1683.36	2200
1685.42	2192
1687.47	2222
1689.53	2196
1691.59	2162
1693.64	2118
1695.7	2164
1697.75	2120
1699.81	2124
1701.86	2106
1703.91	2140
1705.97	2106
1708.02	2068
1710.07	2116
1712.12	2090
1714.17	2092
1716.22	2036
1718.26	2040
1720.31	2132
1722.36	2060
1724.4	2102
1726.45	2026
1728.49	2098
1730.54	2082
1732.58	2060
1734.63	2074
1736.67	2010
1738.71	2104
1740.75	2060
1742.79	2052
1744.83	2038
1746.87	2044
1748.91	2052
1750.95	2044
1752.98	2108
1755.02	2054
1757.06	2022
1759.09	2064
1761.13	2032
1763.16	2050
1765.19	2000
1767.23	2056
1769.26	2010
1771.29	2054
1773.32	2054
1775.35	2022
1777.38	1994
1779.41	2008
1781.44	2026
1783.47	2054
1785.49	2068
1787.52	2064
1789.55	2030
1791.57	2024
1793.6	1984
1795.62	2060
1797.64	2036
1799.67	2042
1801.69	2068
1803.71	1994
1805.73	2032
1807.75	2068
1809.77	2050
1811.79	1960
1813.81	1996
1815.83	2070
1817.84	1980
1819.86	2054
1821.88	2042
1823.89	1946
1825.91	1974
1827.92	2048
1829.93	1992
1831.95	1990
1833.96	1960
1835.97	1994
1837.98	1990
1839.99	1990
1842	1948
1844.01	1976
1846.02	1978
1848.03	1996
1850.03	1984
1852.04	1960
1854.05	1986
1856.05	1984
1858.06	1992
1860.06	1954
1862.06	1926
1864.07	1892
1866.07	1952
1868.07	1934
1870.07	1950
1872.07	1938
1874.07	1994
1876.07	1934
1878.07	1990
1880.07	1942
1882.07	1962
1884.06	1956
1886.06	1946
1888.05	1986
1890.05	1978
1892.04	1966
1894.04	1940
1896.03	1966
1898.02	1950
1900.01	1960
1902	1962
1903.99	1990
1905.98	1962
1907.97	1914
1909.96	1982
1911.95	1922
1913.94	1948
1915.93	1958
1917.91	1936
1919.9	1958
1921.88	1962
1923.87	1926
1925.85	1944
1927.83	1908
1929.82	1964
1931.8	1970
1933.78	1972
1935.76	1964
1937.74	1926
1939.72	1984
1941.7	1962
1943.68	1984
1945.65	1936
1947.63	1910
1949.61	1960
1951.58	1950
1953.56	1894
1955.53	1920
1957.51	1932
1959.48	1940
1961.45	1882
1963.43	1912
1965.4	1928
1967.37	1914
1969.34	1894
1971.31	1956
1973.28	1964
1975.25	1892
1977.22	1834
1979.18	1936
1981.15	1936
1983.12	1892
1985.08	1900
1987.05	1938
1989.01	1928
1990.97	1910
1992.94	1886
1994.9	1914
1996.86	1908
1998.82	1860
2000.78	1902
2002.74	1884
2004.7	1888
2006.66	1866
2008.62	1872
2010.58	1890
2012.54	1874
2014.49	1886
2016.45	1876
2018.4	1886
2020.36	1846
2022.31	1944
2024.27	1840
2026.22	1890
2028.17	1889
2030.12	1900
2032.07	1886
2034.03	1912
2035.98	1894
2037.93	1878
2039.87	1898
2041.82	1856
2043.77	1880
2045.72	1900
2047.66	1918
2049.61	1846
2051.55	1884
2053.5	1868
2055.44	1854
2057.39	1884
2059.33	1896
2061.27	1824
2063.21	1882
2065.15	1860
2067.09	1840
2069.03	1816
2070.97	1822
2072.91	1858
2074.85	1868
2076.79	1878
2078.73	1870
2080.66	1866
2082.6	1844
2084.53	1830
2086.47	1886
2088.4	1868
2090.33	1860
2092.27	1850
2094.2	1868
2096.13	1814
2098.06	1846
2099.99	1872
2101.92	1814
2103.85	1834
2105.78	1856
2107.71	1860
2109.64	1780
2111.56	1900
2113.49	1860
2115.41	1830
2117.34	1820
2119.26	1876
2121.19	1838
2123.11	1864
2125.03	1832
2126.96	1854
2128.88	1816
2130.8	1802
2132.72	1792
2134.64	1846
2136.56	1854
2138.48	1808
2140.4	1860
2142.31	1834
2144.23	1846
2146.15	1806
2148.06	1764
2149.98	1870
2151.89	1842
2153.81	1866
2155.72	1780
2157.63	1796
2159.55	1840
2161.46	1842
2163.37	1792
2165.28	1856
2167.19	1832
2169.1	1802
2171.01	1802
2172.91	1818
2174.82	1818
2176.73	1838
2178.64	1776
2180.54	1810
2182.45	1798
2184.35	1782
2186.26	1816
2188.16	1808
2190.06	1736
2191.96	1772
2193.87	1776
2195.77	1816
2197.67	1752
2199.57	1760
2201.47	1784
2203.37	1820
2205.27	1782
2207.16	1750
2209.06	1766
2210.96	1770
2212.85	1746
2214.75	1760
2216.64	1754
2218.54	1716
2220.43	1726
2222.33	1728
2224.22	1756.65
2226.11	1730.13
2228	1742.54
2229.89	1725.14
2231.78	1716.04
2233.67	1776.33
2235.56	1713.09
2237.45	1715.02
2239.34	1719.97
2241.23	1724.01
2243.11	1706.14
2245	1712.11
2246.89	1731.42
2248.77	1717.26
2250.66	1681.58
2252.54	1737.91
2254.42	1714.81
2256.31	1704.68
2258.19	1705.6
2260.07	1694.4
2261.95	1691.14
2263.83	1686.59
2265.71	1668.87
2267.59	1660.98
2269.47	1699.74
2271.35	1693.95
2273.23	1673.41
2275.1	1677.38
2276.98	1646.59
2278.86	1636.83
2280.73	1665.04
2282.61	1627.56
2284.48	1662.14
2286.36	1645
2288.23	1651.76
2290.1	1668.02
2291.98	1655.51
2293.85	1605.64
2295.72	1626.98
2297.59	1615.6
2299.46	1590.92
2301.33	1619.05
2303.2	1646.85
2305.06	1635.85
2306.93	1607.25
2308.8	1636.59
2310.67	1603.76
2312.53	1595.88
2314.4	1573.25
2316.26	1593.44
2317.62	1616
2319.5	1564
2321.37	1570
2323.24	1578
2325.12	1568
2326.99	1514
2328.86	1636
2330.73	1506
2332.6	1592
2334.47	1524
2336.34	1570
2338.2	1536
2340.07	1522
2341.94	1554
2343.81	1530
2345.67	1496
2347.54	1516
2349.4	1552
2351.27	1528
2353.13	1570
2354.99	1532
2356.86	1542
2358.72	1432
2360.58	1518
2362.44	1498
2364.3	1500
2366.16	1502
2368.02	1466
2369.88	1472
2371.74	1532
2373.6	1514
2375.45	1468
2377.31	1464
2379.17	1490
2381.02	1428
2382.88	1404
2384.73	1458
2386.58	1464
2388.44	1462
2390.29	1430
2392.14	1450
2393.99	1452
2395.85	1366
2397.7	1432
2399.55	1432
2401.4	1430
2403.25	1456
2405.09	1438
2406.94	1402
2408.79	1404
2410.63	1368
2412.48	1332
2414.33	1354
2416.17	1332
2418.02	1322
2419.86	1410
2421.7	1356
2423.55	1384
2425.39	1336
2427.23	1358
2429.07	1358
2430.91	1328
2432.75	1310
2434.59	1314
2436.43	1310
2438.27	1304
2440.11	1288
2441.95	1322
2443.78	1284
2445.62	1276
2447.46	1312
2449.29	1278
2451.13	1296
2452.96	1304
2454.79	1312
2456.63	1284
2458.46	1258
2460.29	1264
2462.12	1266
2463.95	1222
2465.78	1234
2467.61	1208
2469.44	1220
2471.27	1202
2473.1	1224
2474.93	1228
2476.76	1204
2478.58	1222
2480.41	1152
2482.23	1196
2484.06	1180
2485.88	1218
2487.71	1170
2489.53	1174
2491.35	1166
2493.18	1156
2495	1174
2496.82	1164
2498.64	1152
2500.46	1120
2502.28	1106
2504.1	1082
2505.92	1102
2507.74	1120
2509.55	1108
2511.37	1138
2513.19	1092
2515	1090
2516.82	1104
2518.63	1090
2520.45	1106
2522.26	1060
2524.07	1064
2525.89	1046
2527.7	1088
2529.51	1054
2531.32	1030
2533.13	1036
2534.94	992
2536.75	1026
2538.56	1072
2540.37	1010
2542.18	1028
2543.98	1036
2545.79	994
2547.6	1016
2549.4	1034
2551.21	1010
2553.01	984
2554.82	962
2556.62	972
2558.42	992
2560.23	992
2562.03	960
2563.83	940
2565.63	960
2567.43	974
2569.23	952
2571.03	946
2572.83	930
2574.63	938
2576.43	942
2578.22	924
2580.02	914
2581.82	922
2583.61	912
2585.41	916
2587.2	952
2589	938
2590.79	858
2592.58	878
2594.38	902
2596.17	888
2597.96	868
2599.75	898
2601.54	852
2603.33	890
2605.12	878
2606.91	890
2608.7	868
2610.49	880
2612.27	830
2614.06	840
2615.85	828
2617.63	814
2619.42	888
2621.2	820
2622.99	818
2624.77	830
2626.55	782
2628.34	828
2630.12	810
2631.9	802
2633.68	810
2635.46	794
2637.24	792
2639.02	772
2640.8	784
2642.58	802
2644.36	750
2646.14	776
2647.91	776
2649.69	802
2651.46	782
2653.24	784
2655.01	778
2656.79	778
2658.56	738
2660.34	750
2662.11	710
2663.88	732
2665.65	730
2667.42	736
2669.2	718
2670.96	730
2672.73	752
2674.5	722
2676.27	694
2678.04	706
2679.81	720
2681.58	716
2683.34	664
2685.11	702
2686.87	706
2688.64	682
2690.4	694
2692.17	712
2693.93	698
2695.69	678
2697.46	684
2699.22	638
2700.98	668
2702.74	660
2704.5	658
2706.26	638
2708.02	628
2709.78	624
2711.54	606
2713.3	634
2715.05	652
2716.81	628
2718.57	600
2720.32	614
2722.08	610
2723.83	616
2725.59	648
2727.34	592
2729.09	584
2730.85	584
2732.6	588
2734.35	588
2736.1	582
2737.85	584
2739.6	578
2741.35	606
2743.1	572
2744.85	584
2746.6	554
2748.35	542
2750.09	582
2751.84	542
2753.59	576
2755.33	544
2757.08	528
2758.82	560
2760.57	556
2762.31	564
2764.05	548
2765.79	566
2767.54	532
2769.28	506
2771.02	528
2772.76	524
2774.5	520
2776.24	522
2777.98	536
2779.72	522
2781.46	520
2783.19	486
2784.93	490
2786.67	526
2788.4	492
2790.14	482
2791.87	474
2793.61	470
2795.34	464
2797.07	464
2798.81	464
2800.54	456
2802.27	478
2804	456
2805.74	456
2807.47	484
2809.2	480
2810.93	474
2812.65	446
2814.38	422
2816.11	442
2817.84	448
2819.56	450
2821.29	426
2823.02	442
2824.74	424
2826.47	434
2828.19	412
2829.92	434
2831.64	440
2833.36	396
2835.09	414
2836.81	416
2838.53	404
2840.25	398
2841.97	412
2843.69	388
2845.41	394
2847.13	396
2848.85	384
2850.57	382
2852.28	402
2854	380
2855.72	374
2857.43	390
2859.15	372
2860.86	364
2862.58	388
2864.29	406
2866.01	374
2867.72	378
2869.43	376
2871.14	372
2872.86	368
2874.57	380
2876.28	364
2877.99	370
2879.7	378
2881.41	336
2883.11	358
2884.82	354
2886.53	336
2888.24	342
2889.94	328
2891.65	332
2893.36	352
2895.06	336
2896.77	338
2898.47	320
2900.17	344
2901.88	340
2903.58	318
2905.28	310
2906.98	344
2908.69	328
2910.39	316
2912.09	284
2913.79	322
2915.49	320
2917.19	324
2918.88	316
2920.58	304
2922.28	306
2923.98	316
2925.67	290
2927.37	314
2929.06	306
2930.76	316
2932.45	282
2934.15	310
2935.84	308
2937.53	322
2939.23	298
2940.92	274
2942.61	306
2944.3	294
2945.99	288
2947.68	272
2949.37	292
2951.06	304
2952.75	282
2954.44	272
2956.12	278
2957.81	270
2959.5	266
2961.18	284
2962.87	280
2964.56	268
2966.24	256
2967.92	250
2969.61	268
2971.29	276
2972.97	274
2974.66	276
2976.34	244
2978.02	256
2979.7	242
2981.38	286
2983.06	248
2984.74	250
2986.42	240
2988.1	258
2989.78	254
2991.45	244
2993.13	250
2994.81	248
2996.48	252
2998.16	246
2999.83	250