File: muestras/papalo/leaf_10.txt
#Acq. time (s)=	10
#Accumulations=	1
#Range (cm-¹)=	200...3000
#Windows=	3
#Autofocus=	Off
#AutoExposure=	Off
#Spike filter=	Off
#Delay time (s)=	0
#Binning=	1
#Readout mode=	Signal
#DeNoise=	Off
#ICS correction=	Off
#Dark correction=	Off
#Inst. Process=	Off
#Instrument=	LabRAM HR Evol
#Detector=	Syncerity OE
#Objective=	x100_VIS
#Grating=	600 (500nm)
#ND Filter=	0.01%
#Laser=	633nm_Edge
#Hole=	49.98
#Range=	Visible
#Project=	Omar
#Sample=	03-07-23
#Site=	papal
#Title=	leaf
#Remark=
#Date=	03.07.2023 17:01
#Acquired=	03.07.2023 17:01:17
201.713	52
204.247	52
206.778	46
209.311	52
211.84	60
214.371	52
216.899	46
219.428	64
221.955	66
224.482	58
227.007	66
229.531	58
232.055	56
234.579	54
237.1	58
239.621	64
242.141	56
244.661	58
247.179	54
249.698	74
252.215	66
254.731	62
257.246	62
259.761	64
262.273	66
264.786	64
267.298	60
269.809	74
272.319	60
274.828	74
277.336	52
279.844	62
282.351	74
284.855	70
287.361	76
289.866	60
292.368	68
294.871	74
297.372	64
299.873	70
302.372	66
304.872	80
307.37	84
309.866	84
312.364	80
314.859	72
317.353	74
319.848	80
322.341	78
324.833	96
327.324	80
329.814	84
332.304	92
334.792	80
337.28	80
339.767	86
342.254	90
344.739	84
347.224	86
349.708	92
352.191	82
354.673	96
357.155	78
359.634	92
362.114	88
364.593	100
367.07	94
369.548	86
372.024	110
374.499	98
376.974	94
379.447	102
381.92	96
384.392	96
386.864	92
389.333	104
391.802	96
394.272	96
396.739	102
399.206	108
401.673	110
404.138	114
406.602	110
409.066	122
411.528	114
413.99	106
416.451	120
418.911	122
421.371	124
423.83	126
426.288	122
428.745	112
431.201	132
433.657	134
436.111	126
438.565	126
441.017	124
443.469	128
445.921	130
448.37	134
450.821	126
453.27	126
455.717	114
458.165	126
460.61	132
463.056	128
465.5	136
467.945	138
470.387	144
472.829	136
475.271	144
477.711	132
480.15	140
482.589	146
485.027	158
487.465	150
489.901	154
492.337	142
494.771	164
497.205	152
499.638	160
502.07	162
504.502	168
506.933	170
509.363	168
511.792	168
514.219	158
516.647	172
519.073	156
521.5	170
523.924	174
526.348	174
528.772	166
531.194	190
533.616	166
536.036	182
538.457	178
540.875	176
543.294	192
545.712	194
548.128	184
550.545	166
552.959	180
555.373	188
557.788	206
560.2	198
562.612	184
565.023	194
567.433	198
569.843	206
572.251	190
574.659	198
577.066	192
579.472	202
581.878	194
584.283	204
586.687	210
589.09	220
591.493	202
593.893	232
596.294	202
598.694	224
601.093	218
603.491	226
605.889	226
608.285	238
610.682	236
613.076	226
615.471	224
617.864	256
620.256	262
622.648	246
625.039	254
627.429	246
629.819	246
632.208	232
634.595	256
636.982	264
639.369	290
641.755	276
644.139	268
646.523	300
648.906	294
651.288	282
653.67	278
656.051	298
658.429	302
660.808	286
663.187	294
665.565	282
667.942	286
670.317	298
672.692	326
675.067	330
677.44	322
679.813	322
682.184	330
684.556	330
686.926	328
689.296	338
691.664	320
694.033	338
696.4	360
698.766	354
701.133	368
703.497	352
705.861	364
708.224	372
710.586	402
712.949	380
715.31	364
717.67	364
720.029	408
722.388	398
724.746	384
727.103	426
729.458	382
731.814	414
734.168	458
736.523	418
738.876	442
741.227	440
743.579	408
745.931	430
748.28	444
750.629	452
752.977	468
755.325	442
757.672	472
760.018	480
762.363	496
764.708	510
767.052	496
769.394	494
771.737	508
774.078	514
776.419	558
778.758	522
781.097	526
783.435	518
785.773	526
788.11	540
790.446	558
792.781	552
795.115	572
797.449	596
799.782	594
802.115	590
804.446	558
806.777	606
809.106	620
811.435	626
813.764	618
816.091	622
818.418	654
820.743	666
823.069	662
825.393	658
827.717	690
830.039	664
832.362	720
834.683	722
837.003	710
839.324	720
841.643	752
843.961	742
846.278	764
848.594	778
850.91	764
853.227	760
855.541	770
857.855	772
860.168	818
862.48	850
864.79	874
867.101	854
869.411	822
871.721	840
874.029	866
876.336	852
878.643	882
880.95	896
883.254	874
885.559	904
887.862	870
890.166	966
892.467	922
894.77	976
897.07	982
899.371	930
901.669	1004
903.968	978
906.266	994
908.563	996
910.859	1014
913.154	1022
915.449	1032
917.742	1058
920.036	1080
922.329	1018
924.621	1052
926.911	1116
929.201	1078
931.49	1114
933.779	1134
936.068	1146
938.355	1176
940.64	1176
942.926	1204
945.212	1236
947.495	1204
949.779	1228
952.062	1260
954.344	1290
956.625	1258
958.905	1266
961.184	1288
963.464	1310
965.742	1296
968.02	1310
970.296	1350
972.572	1334
974.847	1360
977.121	1388
979.396	1366
981.669	1396
983.941	1412
986.212	1420
988.483	1462
990.753	1460
993.022	1498
995.29	1482
997.558	1500
999.825	1508
1002.09	1586
1004.36	1526
1006.62	1600
1008.89	1564
1011.15	1632
1013.41	1612
1015.67	1600
1017.93	1606
1020.19	1654
1022.45	1726
1024.71	1628
1026.97	1692
1029.23	1750
1031.49	1766
1033.74	1764
1036	1792
1038.25	1768
1040.5	1856
1042.76	1818
1045.01	1888
1047.26	1890
1049.51	1894
1051.76	1962
1054.01	1926
1056.26	1952
1058.51	1962
1060.75	1990
1063	2004
1065.25	1996
1067.49	2020
1069.73	1990
1071.98	2056
1074.22	2122
1076.46	2100
1078.7	2102
1080.94	2034
1083.18	2118
1085.42	2140
1087.66	2146
1089.9	2156
1092.14	2136
1094.37	2206
1096.61	2246
1098.84	2196
1101.08	2214
1103.31	2292
1105.54	2278
1107.77	2270
1110	2292
1112.23	2252
1114.46	2292
1116.69	2316
1118.92	2368
1121.15	2340
1123.37	2378
1125.6	2390
1127.83	2432
1130.05	2452
1132.27	2424
1134.5	2390
1136.72	2472
1138.94	2470
1141.16	2496
1143.38	2484
1145.6	2478
1147.82	2508
1150.04	2518
1152.26	2500
1154.47	2520
1156.69	2546
1158.9	2570
1161.12	2530
1163.33	2552
1165.54	2580
1167.76	2568
1169.97	2592
1172.18	2600
1174.39	2562
1176.6	2574
1178.81	2612
1181.02	2594
1183.22	2570
1185.43	2568
1187.63	2620
1189.84	2586
1192.04	2538
1194.25	2526
1196.45	2574
1198.65	2544
1200.85	2522
1203.05	2632
1205.25	2532
1207.45	2544
1209.65	2538
1211.85	2534
1214.05	2450
1216.24	2512
1218.44	2500
1220.64	2488
1222.83	2502
1225.02	2392
1227.22	2438
1229.41	2486
1231.6	2458
1233.79	2424
1235.98	2412
1238.17	2396
1240.36	2380
1242.55	2434
1244.73	2362
1246.92	2350
1249.11	2342
1251.29	2238
1253.48	2346
1255.66	2344
1257.84	2306
1260.03	2282
1262.21	2280
1264.39	2228
1266.57	2238
1268.75	2180
1270.93	2266
1273.11	2190
1275.28	2214
1277.46	2160
1279.64	2098
1281.81	2148
1283.98	2091.89
1286.16	2068.58
1288.33	2125.63
1290.5	2139.4
1292.68	2040.54
1294.85	2044.22
1297.02	2057.15
1299.19	1986.38
1301.36	2012.53
1303.53	1963.49
1305.69	1972.06
1307.86	1915.43
1310.03	1890.17
1312.19	1888.28
1314.36	1899.32
1316.52	1860.68
1318.68	1796.03
1320.85	1828.72
1323.01	1815.96
1325.17	1811.2
1327.33	1773.99
1329.49	1767.96
1331.65	1747.36
1333.81	1730.02
1335.97	1734.41
1338.12	1700.53
1340.28	1688.08
1342.44	1644.78
1344.59	1648.75
1346.75	1606.05
1348.9	1614.35
1351.05	1602.43
1353.2	1565.13
1355.36	1576.83
1357.51	1541.39
1359.66	1541.55
1361.81	1544.59
1363.96	1491.66
1366.1	1445.25
1368.25	1485.3
1370.4	1481.1
1372.54	1448.01
1374.69	1451.86
1376.83	1417.33
1378.98	1399.52
1381.12	1406.31
1383.26	1420.62
1385.41	1351.14
1387.55	1383.56
1389.69	1318.67
1391.83	1343.92
1393.02	1316
1395.17	1324
1397.32	1328
1399.47	1336
1401.62	1254
1403.77	1256
1405.91	1262
1408.06	1240
1410.2	1276
1412.35	1246
1414.49	1286
1416.63	1258
1418.78	1246
1420.92	1184
1423.06	1204
1425.2	1162
1427.34	1226
1429.48	1160
1431.61	1196
1433.75	1124
1435.89	1156
1438.02	1118
1440.16	1130
1442.3	1118
1444.43	1122
1446.56	1142
1448.7	1130
1450.83	1108
1452.96	1086
1455.09	1064
1457.22	1072
1459.35	1100
1461.48	1074
1463.61	1096
1465.73	1076
1467.86	1054
1469.98	1010
1472.11	1068
1474.24	1046
1476.36	1022
1478.48	1046
1480.6	1002
1482.73	1018
1484.85	980
1486.97	1034
1489.09	992
1491.21	1008
1493.33	970
1495.44	976
1497.56	996
1499.68	978
1501.79	950
1503.91	980
1506.02	944
1508.14	910
1510.25	942
1512.36	952
1514.48	942
1516.59	902
1518.7	952
1520.81	924
1522.92	936
1525.02	922
1527.13	890
1529.24	912
1531.35	868
1533.45	878
1535.56	884
1537.66	896
1539.77	886
1541.87	882
1543.97	862
1546.08	818
1548.18	860
1550.28	828
1552.38	828
1554.48	816
1556.57	824
1558.67	818
1560.77	838
1562.87	856
1564.96	816
1567.06	826
1569.15	830
1571.25	806
1573.34	834
1575.43	786
1577.53	818
1579.62	816
1581.71	772
1583.8	812
1585.89	818
1587.98	776
1590.06	786
1592.15	808
1594.24	770
1596.33	760
1598.41	760
1600.5	762
1602.58	770
1604.66	770
1606.75	764
1608.83	798
1610.91	780
1612.99	768
1615.07	774
1617.15	780
1619.23	758
1621.31	722
1623.39	748
1625.46	758
1627.54	726
1629.62	736
1631.69	712
1633.77	728
1635.84	692
1637.91	700
1639.99	728
1642.06	736
1644.13	718
1646.2	736
1648.27	688
1650.34	716
1652.41	668
1654.47	708
1656.54	708
1658.61	716
1660.67	684
1662.74	690
1664.81	710
1666.87	694
1668.93	706
1671	718
1673.06	674
1675.12	690
1677.18	708
1679.24	696
1681.3	656
1683.36	666
1685.42	680
1687.47	680
1689.53	668
1691.59	668
1693.64	658
1695.7	678
1697.75	684
1699.81	670
1701.86	674
1703.91	664
1705.97	670
1708.02	688
1710.07	666
1712.12	648
1714.17	662
1716.22	652
1718.26	674
1720.31	668
1722.36	624
1724.4	640
1726.45	634
1728.49	656
1730.54	650
1732.58	642
1734.63	646
1736.67	628
1738.71	640
1740.75	646
1742.79	632
1744.83	664
1746.87	642
1748.91	624
1750.95	652
1752.98	636
1755.02	630
1757.06	620
1759.09	644
1761.13	640
1763.16	614
1765.19	648
1767.23	646
1769.26	616
1771.29	642
1773.32	632
1775.35	646
1777.38	622
1779.41	660
1781.44	616
1783.47	614
1785.49	666
1787.52	616
1789.55	624
1791.57	620
1793.6	614
1795.62	608
1797.64	604
1799.67	638
1801.69	644
1803.71	616
1805.73	616
1807.75	628
1809.77	636
1811.79	630
1813.81	658
1815.83	626
1817.84	622
1819.86	612
1821.88	598
1823.89	622
1825.91	636
1827.92	616
1829.93	602
1831.95	616
1833.96	596
1835.97	600
1837.98	622
1839.99	638
1842	606
1844.01	608
1846.02	624
1848.03	624
1850.03	618
1852.04	600
1854.05	592
1856.05	630
1858.06	620
1860.06	630
1862.06	618
1864.07	590
1866.07	588
1868.07	594
1870.07	612
1872.07	594
1874.07	628
1876.07	592
1878.07	604
1880.07	620
1882.07	606
1884.06	604
1886.06	614
1888.05	652
1890.05	610
1892.04	592
1894.04	588
1896.03	598
1898.02	582
1900.01	618
1902	600
1903.99	612
1905.98	630
1907.97	590
1909.96	572
1911.95	614
1913.94	578
1915.93	618
1917.91	626
1919.9	616
1921.88	628
1923.87	618
1925.85	610
1927.83	612
1929.82	604
1931.8	584
1933.78	616
1935.76	584
1937.74	616
1939.72	630
1941.7	608
1943.68	590
1945.65	582
1947.63	612
1949.61	600
1951.58	586
1953.56	590
1955.53	586
1957.51	610
1959.48	596
1961.45	578
1963.43	604
1965.4	576
1967.37	614
1969.34	622
1971.31	584
1973.28	594
1975.25	592
1977.22	550
1979.18	606
1981.15	578
1983.12	590
1985.08	580
1987.05	580
1989.01	570
1990.97	564
1992.94	590
1994.9	600
1996.86	578
1998.82	586
2000.78	554
2002.74	578
2004.7	604
2006.66	590
2008.62	590
2010.58	544
2012.54	566
2014.49	572
2016.45	558
2018.4	594
2020.36	576
2022.31	598
2024.27	582
2026.22	584
2028.17	590
2030.12	588
2032.07	562
2034.03	576
2035.98	564
2037.93	598
2039.87	594
2041.82	600
2043.77	584
2045.72	586
2047.66	560
2049.61	548
2051.55	578
2053.5	562
2055.44	554
2057.39	576
2059.33	590
2061.27	560
2063.21	564
2065.15	566
2067.09	588
2069.03	558
2070.97	580
2072.91	592
2074.85	558
2076.79	604
2078.73	588
2080.66	554
2082.6	586
2084.53	540
2086.47	562
2088.4	558
2090.33	570
2092.27	566
2094.2	586
2096.13	580
2098.06	548
2099.99	568
2101.92	574
2103.85	582
2105.78	586
2107.71	564
2109.64	554
2111.56	572
2113.49	580
2115.41	542
2117.34	568
2119.26	562
2121.19	568
2123.11	588
2125.03	558
2126.96	552
2128.88	566
2130.8	564
2132.72	560
2134.64	554
2136.56	546
2138.48	564
2140.4	552
2142.31	554
2144.23	566
2146.15	558
2148.06	556
2149.98	562
2151.89	582
2153.81	570
2155.72	552
2157.63	544
2159.55	554
2161.46	524
2163.37	534
2165.28	576
2167.19	538
2169.1	566
2171.01	548
2172.91	546
2174.82	530
2176.73	558
2178.64	544
2180.54	534
2182.45	550
2184.35	568
2186.26	562
2188.16	546
2190.06	530
2191.96	528
2193.87	562
2195.77	526
2197.67	540
2199.57	528
2201.47	534
2203.37	524
2205.27	524
2207.16	538
2209.06	532
2210.96	542
2212.85	524
2214.75	534
2216.64	532
2218.54	528
2220.43	542
2222.33	530
2224.22	527.956
2226.11	536.883
2228	514.055
2229.89	527.58
2231.78	495.975
2233.67	519.54
2235.56	555.4
2237.45	537.103
2239.34	508.19
2241.23	524.07
2243.11	524.322
2245	536.445
2246.89	514.98
2248.77	520.857
2250.66	524.349
2252.54	532.239
2254.42	529.887
2256.31	530.23
2258.19	504.75
2260.07	507.741
2261.95	530.994
2263.83	510.23
2265.71	506.886
2267.59	509.818
2269.47	507.276
2271.35	514.069
2273.23	513.287
2275.1	520.208
2276.98	522.869
2278.86	507.119
2280.73	515.5
2282.61	504.514
2284.48	503.378
2286.36	503.51
2288.23	518.71
2290.1	505.676
2291.98	491.459
2293.85	510.484
2295.72	518.754
2297.59	500.692
2299.46	504.153
2301.33	492.707
2303.2	495.975
2305.06	500.167
2306.93	495.852
2308.8	484.017
2310.67	483.006
2312.53	500.31
2314.4	505.812
2316.26	484.367
2317.62	478
2319.5	468
2321.37	474
2323.24	480
2325.12	464
2326.99	486
2328.86	482
2330.73	476
2332.6	492
2334.47	468
2336.34	470
2338.2	470
2340.07	472
2341.94	462
2343.81	476
2345.67	482
2347.54	458
2349.4	468
2351.27	468
2353.13	466
2354.99	468
2356.86	484
2358.72	468
2360.58	484
2362.44	456
2364.3	484
2366.16	468
2368.02	460
2369.88	458
2371.74	476
2373.6	426
2375.45	436
2377.31	430
2379.17	460
2381.02	460
2382.88	448
2384.73	458
2386.58	436
2388.44	450
2390.29	426
2392.14	440
2393.99	430
2395.85	436
2397.7	428
2399.55	444
2401.4	426
2403.25	464
2405.09	436
2406.94	438
2408.79	418
2410.63	412
2412.48	444
2414.33	412
2416.17	416
2418.02	418
2419.86	426
2421.7	420
2423.55	442
2425.39	430
2427.23	414
2429.07	434
2430.91	420
2432.75	416
2434.59	418
2436.43	424
2438.27	418
2440.11	422
2441.95	400
2443.78	410
2445.62	386
2447.46	390
2449.29	400
2451.13	406
2452.96	388
2454.79	422
2456.63	386
2458.46	386
2460.29	414
2462.12	402
2463.95	386
2465.78	370
2467.61	372
2469.44	400
2471.27	374
2473.1	372
2474.93	372
2476.76	390
2478.58	372
2480.41	408
2482.23	378
2484.06	358
2485.88	354
2487.71	378
2489.53	364
2491.35	356
2493.18	352
2495	348
2496.82	360
2498.64	362
2500.46	350
2502.28	360
2504.1	350
2505.92	348
2507.74	314
2509.55	336
2511.37	326
2513.19	364
2515	352
2516.82	334
2518.63	326
2520.45	326
2522.26	338
2524.07	326
2525.89	336
2527.7	314
2529.51	324
2531.32	344
2533.13	300
2534.94	338
2536.75	330
2538.56	320
2540.37	336
2542.18	318
2543.98	308
2545.79	314
2547.6	312
2549.4	336
2551.21	302
2553.01	294
2554.82	322
2556.62	298
2558.42	318
2560.23	314
2562.03	334
2563.83	324
2565.63	288
2567.43	304
2569.23	328
2571.03	316
2572.83	310
2574.63	300
2576.43	316
2578.22	294
2580.02	298
2581.82	302
2583.61	280
2585.41	288
2587.2	286
2589	278
2590.79	286
2592.58	280
2594.38	266
2596.17	270
2597.96	264
2599.75	266
2601.54	274
2603.33	298
2605.12	288
2606.91	278
2608.7	292
2610.49	276
2612.27	258
2614.06	270
2615.85	266
2617.63	270
2619.42	276
2621.2	264
2622.99	268
2624.77	272
2626.55	266
2628.34	260
2630.12	262
2631.9	256
2633.68	246
2635.46	248
2637.24	238
2639.02	246
2640.8	250
2642.58	236
2644.36	258
2646.14	248
2647.91	240
2649.69	246
2651.46	236
2653.24	230
2655.01	242
2656.79	222
2658.56	230
2660.34	244
2662.11	256
2663.88	242
2665.65	244
2667.42	240
2669.2	220
2670.96	236
2672.73	230
2674.5	246
2676.27	232
2678.04	208
2679.81	230
2681.58	220
2683.34	232
2685.11	222
2686.87	222
2688.64	210
2690.4	210
2692.17	230
2693.93	222
2695.69	218
2697.46	212
2699.22	220
2700.98	206
2702.74	214
2704.5	228
2706.26	212
2708.02	200
2709.78	216
2711.54	218
2713.3	208
2715.05	202
2716.81	212
2718.57	208
2720.32	216
2722.08	210
2723.83	204
2725.59	198
2727.34	198
2729.09	190
2730.85	182
2732.6	198
2734.35	194
2736.1	202
2737.85	184
2739.6	170
2741.35	206
2743.1	190
2744.85	198
2746.6	180
2748.35	176
2750.09	186
2751.84	178
2753.59	182
2755.33	196
2757.08	170
2758.82	182
2760.57	170
2762.31	184
2764.05	170
2765.79	176
2767.54	164
2769.28	170
2771.02	178
2772.76	178
2774.5	184
2776.24	166
2777.98	174
2779.72	170
2781.46	168
2783.19	168
2784.93	166
2786.67	166
2788.4	160
2790.14	172
2791.87	152
2793.61	154
2795.34	168
2797.07	144
2798.81	162
2800.54	152
2802.27	166
2804	154
2805.74	160
2807.47	154
2809.2	162
2810.93	158
2812.65	140
2814.38	158
2816.11	148
2817.84	150
2819.56	144
2821.29	152
2823.02	148
2824.74	140
2826.47	148
2828.19	154
2829.92	144
2831.64	144
2833.36	144
2835.09	134
2836.81	138
2838.53	140
2840.25	142
2841.97	150
2843.69	140
2845.41	136
2847.13	130
2848.85	116
2850.57	132
2852.28	136
2854	134
2855.72	116
2857.43	136
2859.15	144
2860.86	122
2862.58	140
2864.29	140
2866.01	132
2867.72	120
2869.43	128
2871.14	122
2872.86	112
2874.57	120
2876.28	126
2877.99	134
2879.7	112
2881.41	112
2883.11	126
2884.82	120
2886.53	106
2888.24	104
2889.94	108
2891.65	120
2893.36	106
2895.06	118
2896.77	112
2898.47	106
2900.17	120
2901.88	110
2903.58	112
2905.28	102
2906.98	118
2908.69	100
2910.39	102
2912.09	104
2913.79	124
2915.49	100
2917.19	122
2918.88	116
2920.58	88
2922.28	112
2923.98	108
2925.67	98
2927.37	114
2929.06	112
2930.76	108
2932.45	102
2934.15	124
2935.84	108
2937.53	100
2939.23	108
2940.92	100
2942.61	110
2944.3	104
2945.99	98
2947.68	90
2949.37	106
2951.06	96
2952.75	102
2954.44	108
2956.12	104
2957.81	102
2959.5	94
2961.18	100
2962.87	94
2964.56	88
2966.24	106
2967.92	100
2969.61	88
2971.29	102
2972.97	104
2974.66	106
2976.34	100
2978.02	98
2979.7	86
2981.38	96
2983.06	108
2984.74	86
2986.42	112
2988.1	94
2989.78	96
2991.45	88
2993.13	94
2994.81	86
2996.48	90
2998.16	90
2999.83	88