File: muestras/papalo/leaf_100x_16.txt
#Acq. time (s)=	10
#Accumulations=	1
#Range (cm-¹)=	200...3000
#Windows=	3
#Autofocus=	Off
#AutoExposure=	Off
#Spike filter=	Off
#Delay time (s)=	0
#Binning=	1
#Readout mode=	Signal
#DeNoise=	Off
#ICS correction=	Off
#Dark correction=	Off
#Inst. Process=	Off
#Instrument=	LabRAM HR Evol
#Detector=	Syncerity OE
#Objective=	x100_VIS
#Grating=	600 (500nm)
#ND Filter=	0.1%
#Laser=	633nm_Edge
#Hole=	100.021
#Range=	Visible
#Project=	Omar
#Sample=	03-07-23
#Site=	papal
#Title=	leaf_100x
#Remark=
#Date=	03.07.2023 17:25
#Acquired=	03.07.2023 17:25:35
201.713	84
204.247	88
206.778	98
209.311	102
211.84	80
214.371	92
216.899	98
219.428	92
221.955	92
224.482	110
227.007	100
229.531	102
232.055	96
234.579	104
237.1	110
239.621	102
242.141	114
244.661	118
247.179	120
249.698	116
252.215	110
254.731	118
257.246	116
259.761	112
262.273	114
264.786	110
267.298	124
269.809	128
272.319	130
274.828	118
277.336	112
279.844	124
282.351	132
284.855	128
287.361	144
289.866	126
292.368	140
294.871	142
297.372	134
299.873	140
302.372	130
304.872	142
307.37	138
309.866	134
312.364	156
314.859	146
317.353	148
319.848	146
322.341	160
324.833	170
327.324	164
329.814	160
332.304	172
334.792	150
337.28	162
339.767	172
342.254	196
344.739	172
347.224	180
349.708	170
352.191	180
354.673	160
357.155	188
359.634	184
362.114	190
364.593	184
367.07	192
369.548	188
372.024	208
374.499	188
376.974	208
379.447	212
381.92	208
384.392	196
386.864	212
389.333	214
391.802	200
394.272	210
396.739	208
399.206	200
401.673	210
404.138	224
406.602	230
409.066	242
411.528	234
413.99	246
416.451	246
418.911	246
421.371	244
423.83	250
426.288	248
428.745	246
431.201	256
433.657	272
436.111	236
438.565	260
441.017	260
443.469	276
445.921	276
448.37	250
450.821	278
453.27	286
455.717	274
458.165	286
460.61	276
463.056	282
465.5	294
467.945	278
470.387	300
472.829	292
475.271	288
477.711	318
480.15	306
482.589	292
485.027	290
487.465	316
489.901	316
492.337	322
494.771	314
497.205	318
499.638	316
502.07	334
504.502	344
506.933	354
509.363	326
511.792	334
514.219	328
516.647	372
519.073	360
521.5	356
523.924	340
526.348	366
528.772	388
531.194	384
533.616	354
536.036	384
538.457	406
540.875	388
543.294	386
545.712	390
548.128	418
550.545	396
552.959	408
555.373	428
557.788	438
560.2	402
562.612	392
565.023	446
567.433	438
569.843	420
572.251	424
574.659	460
577.066	476
579.472	454
581.878	420
584.283	448
586.687	462
589.09	468
591.493	478
593.893	500
596.294	498
598.694	504
601.093	516
603.491	532
605.889	526
608.285	504
610.682	512
613.076	506
615.471	526
617.864	524
620.256	536
622.648	584
625.039	572
627.429	584
629.819	570
632.208	598
634.595	616
636.982	600
639.369	596
641.755	608
644.139	610
646.523	654
648.906	606
651.288	654
653.67	638
656.051	634
658.429	670
660.808	674
663.187	650
665.565	722
667.942	694
670.317	700
672.692	702
675.067	676
677.44	688
679.813	722
682.184	732
684.556	718
686.926	744
689.296	742
691.664	764
694.033	764
696.4	794
698.766	774
701.133	792
703.497	794
705.861	868
708.224	838
710.586	812
712.949	824
715.31	868
717.67	864
720.029	904
722.388	920
724.746	912
727.103	894
729.458	900
731.814	934
734.168	936
736.523	962
738.876	942
741.227	970
743.579	994
745.931	964
748.28	968
750.629	1026
752.977	972
755.325	1054
757.672	1038
760.018	1050
762.363	1046
764.708	1110
767.052	1112
769.394	1092
771.737	1096
774.078	1124
776.419	1140
778.758	1170
781.097	1200
783.435	1192
785.773	1184
788.11	1178
790.446	1226
792.781	1224
795.115	1216
797.449	1250
799.782	1302
802.115	1280
804.446	1312
806.777	1298
809.106	1332
811.435	1362
813.764	1374
816.091	1376
818.418	1382
820.743	1442
823.069	1392
825.393	1444
827.717	1498
830.039	1514
832.362	1588
834.683	1564
837.003	1564
839.324	1584
841.643	1578
843.961	1640
846.278	1628
848.594	1656
850.91	1650
853.227	1692
855.541	1762
857.855	1762
860.168	1734
862.48	1794
864.79	1772
867.101	1846
869.411	1812
871.721	1896
874.029	1862
876.336	1838
878.643	1886
880.95	1946
883.254	2022
885.559	1968
887.862	1984
890.166	2028
892.467	2016
894.77	2076
897.07	2024
899.371	2038
901.669	2058
903.968	2128
906.266	2148
908.563	2172
910.859	2222
913.154	2182
915.449	2208
917.742	2234
920.036	2294
922.329	2356
924.621	2388
926.911	2318
929.201	2370
931.49	2394
933.779	2426
936.068	2466
938.355	2506
940.64	2524
942.926	2556
945.212	2556
947.495	2638
949.779	2618
952.062	2622
954.344	2690
956.625	2688
958.905	2770
961.184	2698
963.464	2762
965.742	2786
968.02	2876
970.296	2924
972.572	2916
974.847	2982
977.121	2966
979.396	2950
981.669	3048
983.941	3020
986.212	3062
988.483	3092
990.753	3068
993.022	3120
995.29	3204
997.558	3234
999.825	3198
1002.09	3236
1004.36	3292
1006.62	3454
1008.89	3376
1011.15	3408
1013.41	3458
1015.67	3540
1017.93	3592
1020.19	3538
1022.45	3646
1024.71	3530
1026.97	3626
1029.23	3716
1031.49	3668
1033.74	3726
1036	3804
1038.25	3908
1040.5	3928
1042.76	3914
1045.01	3930
1047.26	4032
1049.51	4020
1051.76	4050
1054.01	4182
1056.26	4176
1058.51	4200
1060.75	4282
1063	4292
1065.25	4374
1067.49	4378
1069.73	4340
1071.98	4368
1074.22	4418
1076.46	4456
1078.7	4426
1080.94	4492
1083.18	4434
1085.42	4542
1087.66	4568
1089.9	4672
1092.14	4626
1094.37	4680
1096.61	4706
1098.84	4764
1101.08	4860
1103.31	4802
1105.54	4910
1107.77	4852
1110	4884
1112.23	4982
1114.46	4998
1116.69	4950
1118.92	5056
1121.15	5044
1123.37	5092
1125.6	5082
1127.83	5208
1130.05	5172
1132.27	5230
1134.5	5308
1136.72	5300
1138.94	5264
1141.16	5368
1143.38	5426
1145.6	5486
1147.82	5496
1150.04	5414
1152.26	5444
1154.47	5570
1156.69	5620
1158.9	5566
1161.12	5644
1163.33	5572
1165.54	5762
1167.76	5678
1169.97	5704
1172.18	5706
1174.39	5762
1176.6	5746
1178.81	5738
1181.02	5812
1183.22	5722
1185.43	5710
1187.63	5816
1189.84	5806
1192.04	5726
1194.25	5804
1196.45	5750
1198.65	5732
1200.85	5772
1203.05	5780
1205.25	5676
1207.45	5704
1209.65	5722
1211.85	5654
1214.05	5812
1216.24	5620
1218.44	5658
1220.64	5608
1222.83	5612
1225.02	5624
1227.22	5626
1229.41	5642
1231.6	5644
1233.79	5662
1235.98	5544
1238.17	5658
1240.36	5546
1242.55	5532
1244.73	5538
1246.92	5486
1249.11	5400
1251.29	5492
1253.48	5590
1255.66	5492
1257.84	5450
1260.03	5426
1262.21	5392
1264.39	5400
1266.57	5310
1268.75	5396
1270.93	5328
1273.11	5138
1275.28	5344
1277.46	5274
1279.64	5192
1281.81	5168
1283.98	5130.42
1286.16	5148.46
1288.33	5121.08
1290.5	5098.78
1292.68	4929.17
1294.85	4981.55
1297.02	4990.9
1299.19	4952.6
1301.36	4923.94
1303.53	4763.24
1305.69	4737.82
1307.86	4752.23
1310.03	4692.6
1312.19	4578.62
1314.36	4604.49
1316.52	4585.44
1318.68	4628.76
1320.85	4486.32
1323.01	4423.17
1325.17	4465.67
1327.33	4427.7
1329.49	4337.96
1331.65	4324.71
1333.81	4297.18
1335.97	4230.69
1338.12	4219.29
1340.28	4136.65
1342.44	4128.13
1344.59	4114.44
1346.75	4047.08
1348.9	3967.81
1351.05	4037.77
1353.2	3971.82
1355.36	3941.24
1357.51	3871.6
1359.66	3845.12
1361.81	3834.29
1363.96	3804.32
1366.1	3792.27
1368.25	3683.31
1370.4	3671.64
1372.54	3658.83
1374.69	3678.61
1376.83	3591.56
1378.98	3516.81
1381.12	3569.87
1383.26	3478.35
1385.41	3447.78
1387.55	3466.54
1389.69	3430.71
1391.83	3385.74
1393.02	3340
1395.17	3420
1397.32	3314
1399.47	3306
1401.62	3278
1403.77	3276
1405.91	3172
1408.06	3212
1410.2	3208
1412.35	3140
1414.49	3168
1416.63	3128
1418.78	3134
1420.92	3096
1423.06	3048
1425.2	3040
1427.34	3076
1429.48	3036
1431.61	2986
1433.75	2934
1435.89	2948
1438.02	2930
1440.16	2922
1442.3	2924
1444.43	2930
1446.56	2848
1448.7	2844
1450.83	2816
1452.96	2882
1455.09	2726
1457.22	2852
1459.35	2756
1461.48	2828
1463.61	2796
1465.73	2782
1467.86	2758
1469.98	2748
1472.11	2710
1474.24	2668
1476.36	2694
1478.48	2620
1480.6	2648
1482.73	2618
1484.85	2686
1486.97	2642
1489.09	2550
1491.21	2540
1493.33	2594
1495.44	2558
1497.56	2540
1499.68	2506
1501.79	2512
1503.91	2570
1506.02	2544
1508.14	2442
1510.25	2482
1512.36	2454
1514.48	2426
1516.59	2434
1518.7	2472
1520.81	2424
1522.92	2402
1525.02	2402
1527.13	2358
1529.24	2398
1531.35	2348
1533.45	2334
1535.56	2356
1537.66	2280
1539.77	2252
1541.87	2214
1543.97	2192
1546.08	2194
1548.18	2196
1550.28	2212
1552.38	2234
1554.48	2200
1556.57	2158
1558.67	2162
1560.77	2190
1562.87	2108
1564.96	2160
1567.06	2206
1569.15	2166
1571.25	2134
1573.34	2112
1575.43	2112
1577.53	2158
1579.62	2112
1581.71	2094
1583.8	2046
1585.89	2066
1587.98	2128
1590.06	2080
1592.15	2020
1594.24	2066
1596.33	2048
1598.41	2096
1600.5	2048
1602.58	2084
1604.66	2058
1606.75	1990
1608.83	1990
1610.91	2046
1612.99	2056
1615.07	2038
1617.15	2048
1619.23	1980
1621.31	2020
1623.39	1982
1625.46	1960
1627.54	1998
1629.62	2048
1631.69	2034
1633.77	1970
1635.84	1988
1637.91	1942
1639.99	1948
1642.06	1940
1644.13	2010
1646.2	1982
1648.27	1900
1650.34	1860
1652.41	1936
1654.47	1966
1656.54	1876
1658.61	1856
1660.67	1876
1662.74	1846
1664.81	1900
1666.87	1880
1668.93	1890
1671	1886
1673.06	1828
1675.12	1848
1677.18	1826
1679.24	1824
1681.3	1860
1683.36	1804
1685.42	1844
1687.47	1808
1689.53	1838
1691.59	1790
1693.64	1848
1695.7	1790
1697.75	1782
1699.81	1856
1701.86	1814
1703.91	1768
1705.97	1824
1708.02	1778
1710.07	1770
1712.12	1764
1714.17	1796
1716.22	1778
1718.26	1758
1720.31	1736
1722.36	1724
1724.4	1744
1726.45	1750
1728.49	1760
1730.54	1764
1732.58	1710
1734.63	1762
1736.67	1700
1738.71	1720
1740.75	1772
1742.79	1764
1744.83	1730
1746.87	1706
1748.91	1734
1750.95	1764
1752.98	1714
1755.02	1756
1757.06	1724
1759.09	1704
1761.13	1758
1763.16	1674
1765.19	1762
1767.23	1702
1769.26	1678
1771.29	1738
1773.32	1730
1775.35	1742
1777.38	1716
1779.41	1688
1781.44	1700
1783.47	1678
1785.49	1660
1787.52	1716
1789.55	1700
1791.57	1666
1793.6	1704
1795.62	1728
1797.64	1766
1799.67	1720
1801.69	1718
1803.71	1650
1805.73	1708
1807.75	1654
1809.77	1710
1811.79	1628
1813.81	1694
1815.83	1636
1817.84	1604
1819.86	1654
1821.88	1686
1823.89	1688
1825.91	1684
1827.92	1668
1829.93	1672
1831.95	1624
1833.96	1634
1835.97	1628
1837.98	1686
1839.99	1662
1842	1670
1844.01	1650
1846.02	1646
1848.03	1640
1850.03	1640
1852.04	1670
1854.05	1658
1856.05	1670
1858.06	1668
1860.06	1618
1862.06	1652
1864.07	1668
1866.07	1634
1868.07	1622
1870.07	1630
1872.07	1624
1874.07	1666
1876.07	1644
1878.07	1654
1880.07	1652
1882.07	1656
1884.06	1660
1886.06	1608
1888.05	1624
1890.05	1628
1892.04	1646
1894.04	1626
1896.03	1658
1898.02	1660
1900.01	1586
1902	1596
1903.99	1620
1905.98	1648
1907.97	1594
1909.96	1620
1911.95	1680
1913.94	1648
1915.93	1640
1917.91	1612
1919.9	1628
1921.88	1678
1923.87	1606
1925.85	1640
1927.83	1624
1929.82	1626
1931.8	1584
1933.78	1602
1935.76	1574
1937.74	1664
1939.72	1628
1941.7	1576
1943.68	1558
1945.65	1592
1947.63	1632
1949.61	1572
1951.58	1602
1953.56	1580
1955.53	1574
1957.51	1616
1959.48	1574
1961.45	1604
1963.43	1584
1965.4	1608
1967.37	1594
1969.34	1568
1971.31	1554
1973.28	1554
1975.25	1560
1977.22	1558
1979.18	1604
1981.15	1584
1983.12	1604
1985.08	1562
1987.05	1590
1989.01	1586
1990.97	1582
1992.94	1606
1994.9	1598
1996.86	1566
1998.82	1554
2000.78	1576
2002.74	1546
2004.7	1556
2006.66	1576
2008.62	1562
2010.58	1522
2012.54	1498
2014.49	1578
2016.45	1524
2018.4	1538
2020.36	1618
2022.31	1580
2024.27	1518
2026.22	1524
2028.17	1538
2030.12	1556
2032.07	1560
2034.03	1526
2035.98	1604
2037.93	1454
2039.87	1510
2041.82	1544
2043.77	1494
2045.72	1544
2047.66	1534
2049.61	1524
2051.55	1494
2053.5	1520
2055.44	1550
2057.39	1520
2059.33	1528
2061.27	1504
2063.21	1528
2065.15	1482
2067.09	1536
2069.03	1490
2070.97	1458
2072.91	1526
2074.85	1448
2076.79	1464
2078.73	1534
2080.66	1512
2082.6	1516
2084.53	1516
2086.47	1490
2088.4	1508
2090.33	1528
2092.27	1484
2094.2	1490
2096.13	1530
2098.06	1460
2099.99	1526
2101.92	1500
2103.85	1506
2105.78	1454
2107.71	1488
2109.64	1458
2111.56	1452
2113.49	1490
2115.41	1446
2117.34	1464
2119.26	1488
2121.19	1508
2123.11	1500
2125.03	1456
2126.96	1462
2128.88	1464
2130.8	1448
2132.72	1476
2134.64	1498
2136.56	1454
2138.48	1490
2140.4	1488
2142.31	1458
2144.23	1452
2146.15	1460
2148.06	1448
2149.98	1460
2151.89	1468
2153.81	1408
2155.72	1454
2157.63	1434
2159.55	1462
2161.46	1462
2163.37	1406
2165.28	1462
2167.19	1478
2169.1	1388
2171.01	1406
2172.91	1454
2174.82	1408
2176.73	1434
2178.64	1390
2180.54	1402
2182.45	1438
2184.35	1432
2186.26	1432
2188.16	1384
2190.06	1404
2191.96	1408
2193.87	1422
2195.77	1354
2197.67	1406
2199.57	1438
2201.47	1402
2203.37	1416
2205.27	1352
2207.16	1378
2209.06	1386
2210.96	1348
2212.85	1392
2214.75	1408
2216.64	1350
2218.54	1426
2220.43	1412
2222.33	1360
2224.22	1390.29
2226.11	1405.04
2228	1388.99
2229.89	1338.46
2231.78	1357.6
2233.67	1350.78
2235.56	1358.89
2237.45	1342.13
2239.34	1407.28
2241.23	1336.87
2243.11	1340.71
2245	1311.04
2246.89	1348.1
2248.77	1339.01
2250.66	1306.65
2252.54	1317.67
2254.42	1336.89
2256.31	1313.83
2258.19	1323.61
2260.07	1323.81
2261.95	1300.92
2263.83	1329.26
2265.71	1294.23
2267.59	1308.1
2269.47	1295.23
2271.35	1309.18
2273.23	1310.77
2275.1	1307.84
2276.98	1292.53
2278.86	1290.25
2280.73	1279.89
2282.61	1278
2284.48	1255.5
2286.36	1267.64
2288.23	1299.98
2290.1	1249.09
2291.98	1224.38
2293.85	1242.68
2295.72	1245.14
2297.59	1233.63
2299.46	1255.66
2301.33	1246.87
2303.2	1282.87
2305.06	1245.85
2306.93	1225.1
2308.8	1216.06
2310.67	1234.49
2312.53	1217.48
2314.4	1244.4
2316.26	1203.13
2317.62	1166
2319.5	1208
2321.37	1198
2323.24	1240
2325.12	1178
2326.99	1182
2328.86	1164
2330.73	1194
2332.6	1182
2334.47	1176
2336.34	1182
2338.2	1222
2340.07	1172
2341.94	1176
2343.81	1192
2345.67	1180
2347.54	1196
2349.4	1170
2351.27	1174
2353.13	1196
2354.99	1164
2356.86	1168
2358.72	1148
2360.58	1176
2362.44	1132
2364.3	1124
2366.16	1102
2368.02	1116
2369.88	1148
2371.74	1110
2373.6	1144
2375.45	1118
2377.31	1094
2379.17	1134
2381.02	1120
2382.88	1086
2384.73	1112
2386.58	1122
2388.44	1068
2390.29	1094
2392.14	1070
2393.99	1058
2395.85	1066
2397.7	1094
2399.55	1078
2401.4	1084
2403.25	1082
2405.09	1030
2406.94	1064
2408.79	1074
2410.63	1056
2412.48	1046
2414.33	1046
2416.17	1062
2418.02	1042
2419.86	1028
2421.7	1014
2423.55	1012
2425.39	1004
2427.23	1006
2429.07	1028
2430.91	976
2432.75	1002
2434.59	968
2436.43	998
2438.27	982
2440.11	980
2441.95	982
2443.78	1008
2445.62	946
2447.46	946
2449.29	968
2451.13	926
2452.96	956
2454.79	942
2456.63	960
2458.46	926
2460.29	950
2462.12	906
2463.95	890
2465.78	958
2467.61	910
2469.44	928
2471.27	940
2473.1	910
2474.93	914
2476.76	910
2478.58	858
2480.41	902
2482.23	884
2484.06	890
2485.88	904
2487.71	858
2489.53	858
2491.35	856
2493.18	854
2495	872
2496.82	858
2498.64	882
2500.46	856
2502.28	846
2504.1	824
2505.92	808
2507.74	820
2509.55	824
2511.37	848
2513.19	802
2515	796
2516.82	790
2518.63	826
2520.45	756
2522.26	780
2524.07	808
2525.89	716
2527.7	762
2529.51	786
2531.32	778
2533.13	770
2534.94	770
2536.75	742
2538.56	774
2540.37	784
2542.18	744
2543.98	736
2545.79	744
2547.6	732
2549.4	740
2551.21	758
2553.01	714
2554.82	752
2556.62	716
2558.42	706
2560.23	712
2562.03	718
2563.83	750
2565.63	714
2567.43	696
2569.23	690
2571.03	700
2572.83	712
2574.63	698
2576.43	682
2578.22	694
2580.02	662
2581.82	704
2583.61	680
2585.41	658
2587.2	684
2589	664
2590.79	666
2592.58	656
2594.38	650
2596.17	670
2597.96	654
2599.75	616
2601.54	636
2603.33	622
2605.12	614
2606.91	624
2608.7	614
2610.49	652
2612.27	628
2614.06	624
2615.85	624
2617.63	608
2619.42	622
2621.2	590
2622.99	594
2624.77	596
2626.55	568
2628.34	630
2630.12	616
2631.9	608
2633.68	578
2635.46	604
2637.24	590
2639.02	588
2640.8	594
2642.58	566
2644.36	558
2646.14	588
2647.91	580
2649.69	580
2651.46	554
2653.24	568
2655.01	546
2656.79	528
2658.56	540
2660.34	534
2662.11	538
2663.88	566
2665.65	554
2667.42	534
2669.2	544
2670.96	534
2672.73	526
2674.5	502
2676.27	506
2678.04	516
2679.81	498
2681.58	506
2683.34	494
2685.11	526
2686.87	500
2688.64	498
2690.4	484
2692.17	478
2693.93	458
2695.69	496
2697.46	504
2699.22	478
2700.98	450
2702.74	496
2704.5	490
2706.26	482
2708.02	476
2709.78	470
2711.54	484
2713.3	450
2715.05	434
2716.81	474
2718.57	434
2720.32	440
2722.08	458
2723.83	448
2725.59	452
2727.34	408
2729.09	446
2730.85	444
2732.6	416
2734.35	420
2736.1	438
2737.85	402
2739.6	412
2741.35	414
2743.1	424
2744.85	408
2746.6	426
2748.35	422
2750.09	406
2751.84	396
2753.59	410
2755.33	404
2757.08	382
2758.82	388
2760.57	400
2762.31	372
2764.05	372
2765.79	386
2767.54	386
2769.28	344
2771.02	374
2772.76	364
2774.5	370
2776.24	370
2777.98	362
2779.72	386
2781.46	384
2783.19	380
2784.93	362
2786.67	366
2788.4	334
2790.14	334
2791.87	368
2793.61	366
2795.34	354
2797.07	362
2798.81	352
2800.54	328
2802.27	328
2804	326
2805.74	340
2807.47	308
2809.2	328
2810.93	338
2812.65	316
2814.38	318
2816.11	320
2817.84	318
2819.56	310
2821.29	308
2823.02	322
2824.74	310
2826.47	294
2828.19	280
2829.92	310
2831.64	304
2833.36	298
2835.09	282
2836.81	294
2838.53	288
2840.25	284
2841.97	288
2843.69	282
2845.41	274
2847.13	276
2848.85	276
2850.57	282
2852.28	232
2854	268
2855.72	280
2857.43	262
2859.15	272
2860.86	274
2862.58	270
2864.29	254
2866.01	264
2867.72	256
2869.43	246
2871.14	238
2872.86	254
2874.57	262
2876.28	256
2877.99	246
2879.7	262
2881.41	240
2883.11	254
2884.82	248
2886.53	250
2888.24	256
2889.94	226
2891.65	246
2893.36	240
2895.06	226
2896.77	244
2898.47	242
2900.17	238
2901.88	236
2903.58	230
2905.28	240
2906.98	228
2908.69	248
2910.39	224
2912.09	218
2913.79	224
2915.49	238
2917.19	218
2918.88	210
2920.58	222
2922.28	236
2923.98	212
2925.67	200
2927.37	206
2929.06	228
2930.76	228
2932.45	202
2934.15	212
2935.84	224
2937.53	204
2939.23	208
2940.92	202
2942.61	206
2944.3	198
2945.99	194
2947.68	204
2949.37	196
2951.06	188
2952.75	212
2954.44	196
2956.12	204
2957.81	204
2959.5	190
2961.18	196
2962.87	192
2964.56	194
2966.24	198
2967.92	170
2969.61	196
2971.29	198
2972.97	196
2974.66	174
2976.34	180
2978.02	178
2979.7	178
2981.38	186
2983.06	184
2984.74	184
2986.42	172
2988.1	186
2989.78	184
2991.45	180
2993.13	162
2994.81	172
2996.48	168
2998.16	176
2999.83	172