File: muestras/papalo/leaf_01.txt
#Acq. time (s)=	10
#Accumulations=	1
#Range (cm-¹)=	200...3000
#Windows=	3
#Autofocus=	Off
#AutoExposure=	Off
#Spike filter=	Off
#Delay time (s)=	0
#Binning=	1
#Readout mode=	Signal
#DeNoise=	Off
#ICS correction=	Off
#Dark correction=	Off
#Inst. Process=	Off
#Instrument=	LabRAM HR Evol
#Detector=	Syncerity OE
#Objective=	x100_VIS
#Grating=	600 (500nm)
#ND Filter=	1%
#Laser=	633nm_Edge
#Hole=	30.0125
#Range=	Visible
#Project=	Omar
#Sample=	03-07-23
#Site=	papal
#Title=	leaf
#Remark=
#Date=	03.07.2023 16:48
#Acquired=	03.07.2023 16:48:25
201.713	1160
204.247	1108
206.778	1184
209.311	1170
211.84	1202
214.371	1220
216.899	1268
219.428	1258
221.955	1282
224.482	1280
227.007	1354
229.531	1340
232.055	1368
234.579	1388
237.1	1394
239.621	1436
242.141	1436
244.661	1456
247.179	1454
249.698	1458
252.215	1502
254.731	1554
257.246	1600
259.761	1560
262.273	1612
264.786	1640
267.298	1640
269.809	1662
272.319	1680
274.828	1712
277.336	1690
279.844	1726
282.351	1804
284.855	1806
287.361	1854
289.866	1860
292.368	1870
294.871	1910
297.372	1948
299.873	1988
302.372	2028
304.872	2080
307.37	2124
309.866	2132
312.364	2142
314.859	2240
317.353	2276
319.848	2212
322.341	2222
324.833	2248
327.324	2350
329.814	2314
332.304	2384
334.792	2438
337.28	2464
339.767	2462
342.254	2500
344.739	2506
347.224	2602
349.708	2612
352.191	2652
354.673	2748
357.155	2706
359.634	2742
362.114	2776
364.593	2860
367.07	2804
369.548	2884
372.024	2902
374.499	2920
376.974	3020
379.447	3068
381.92	3074
384.392	3126
386.864	3152
389.333	3190
391.802	3212
394.272	3248
396.739	3320
399.206	3420
401.673	3352
404.138	3364
406.602	3522
409.066	3582
411.528	3592
413.99	3644
416.451	3700
418.911	3782
421.371	3788
423.83	3786
426.288	3958
428.745	4032
431.201	4010
433.657	4040
436.111	4138
438.565	4078
441.017	4178
443.469	4282
445.921	4272
448.37	4314
450.821	4396
453.27	4370
455.717	4408
458.165	4444
460.61	4542
463.056	4548
465.5	4634
467.945	4666
470.387	4686
472.829	4796
475.271	4862
477.711	4872
480.15	4950
482.589	4984
485.027	5044
487.465	5072
489.901	5146
492.337	5210
494.771	5304
497.205	5290
499.638	5358
502.07	5510
504.502	5514
506.933	5616
509.363	5624
511.792	5660
514.219	5694
516.647	5818
519.073	5810
521.5	5924
523.924	5816
526.348	5980
528.772	5974
531.194	6002
533.616	6092
536.036	6184
538.457	6140
540.875	6380
543.294	6398
545.712	6442
548.128	6436
550.545	6720
552.959	6574
555.373	6736
557.788	6742
560.2	6782
562.612	6914
565.023	7008
567.433	7072
569.843	7048
572.251	7292
574.659	7304
577.066	7398
579.472	7404
581.878	7656
584.283	7654
586.687	7732
589.09	7814
591.493	7962
593.893	7988
596.294	7984
598.694	8088
601.093	8180
603.491	8340
605.889	8452
608.285	8536
610.682	8658
613.076	8822
615.471	8856
617.864	8952
620.256	9044
622.648	9304
625.039	9302
627.429	9384
629.819	9538
632.208	9566
634.595	9826
636.982	9954
639.369	10016
641.755	10200
644.139	10238
646.523	10424
648.906	10504
651.288	10602
653.67	10784
656.051	10926
658.429	10962
660.808	11152
663.187	11272
665.565	11400
667.942	11576
670.317	11670
672.692	11784
675.067	11752
677.44	12100
679.813	12078
682.184	12310
684.556	12336
686.926	12554
689.296	12724
691.664	12930
694.033	12800
696.4	13082
698.766	13354
701.133	13454
703.497	13528
705.861	13762
708.224	14146
710.586	14204
712.949	14318
715.31	14486
717.67	14718
720.029	14850
722.388	15098
724.746	15190
727.103	15508
729.458	15488
731.814	15656
734.168	15938
736.523	16166
738.876	16328
741.227	16560
743.579	16744
745.931	16922
748.28	17274
750.629	17356
752.977	17576
755.325	17644
757.672	18010
760.018	18240
762.363	18336
764.708	18508
767.052	18780
769.394	18950
771.737	19208
774.078	19190
776.419	19568
778.758	20048
781.097	20154
783.435	20340
785.773	20572
788.11	20884
790.446	21048
792.781	21320
795.115	21600
797.449	21976
799.782	22328
802.115	22552
804.446	22694
806.777	23032
809.106	23160
811.435	23586
813.764	23994
816.091	24178
818.418	24758
820.743	24856
823.069	25356
825.393	25754
827.717	25856
830.039	26452
832.362	26738
834.683	26782
837.003	27142
839.324	27724
841.643	28038
843.961	28358
846.278	28686
848.594	29132
850.91	29270
853.227	29784
855.541	30258
857.855	30610
860.168	31014
862.48	31152
864.79	31404
867.101	31842
869.411	32422
871.721	32472
874.029	33128
876.336	33310
878.643	33664
880.95	34182
883.254	34416
885.559	34796
887.862	35050
890.166	35228
892.467	35982
894.77	36094
897.07	36772
899.371	36894
901.669	37196
903.968	37794
906.266	38060
908.563	38490
910.859	38824
913.154	39196
915.449	39802
917.742	40090
920.036	40250
922.329	41008
924.621	41194
926.911	41996
929.201	42390
931.49	42814
933.779	43070
936.068	43980
938.355	44108
940.64	44800
942.926	45292
945.212	46012
947.495	46220
949.779	46932
952.062	47570
954.344	47744
956.625	48142
958.905	49032
961.184	49496
963.464	50012
965.742	50746
968.02	50948
970.296	51634
972.572	52034
974.847	52696
977.121	53112
979.396	53690
981.669	54362
983.941	54552
986.212	55128
988.483	55640
990.753	56268
993.022	56372
995.29	57108
997.558	57554
999.825	58056
1002.09	58646
1004.36	59256
1006.62	59618
1008.89	60976
1011.15	61214
1013.41	62216
1015.67	62438
1017.93	63158
1020.19	63670
1022.45	64282
1024.71	64535
1026.97	64535
1029.23	64535
1031.49	64535
1033.74	64535
1036	64535
1038.25	64535
1040.5	64535
1042.76	64535
1045.01	64535
1047.26	64535
1049.51	64535
1051.76	64535
1054.01	64535
1056.26	64535
1058.51	64535
1060.75	64535
1063	64535
1065.25	64535
1067.49	64535
1069.73	64535
1071.98	64535
1074.22	64535
1076.46	64535
1078.7	64535
1080.94	64535
1083.18	64535
1085.42	64535
1087.66	64535
1089.9	64535
1092.14	64535
1094.37	64535
1096.61	64535
1098.84	64535
1101.08	64535
1103.31	64535
1105.54	64535
1107.77	64535
1110	64535
1112.23	64535
1114.46	64535
1116.69	64535
1118.92	64535
1121.15	64535
1123.37	64535
1125.6	64535
1127.83	64535
1130.05	64535
1132.27	64535
1134.5	64535
1136.72	64535
1138.94	64535
1141.16	64535
1143.38	64535
1145.6	64535
1147.82	64535
1150.04	64535
1152.26	64535
1154.47	64535
1156.69	64535
1158.9	64535
1161.12	64535
1163.33	64535
1165.54	64535
1167.76	64535
1169.97	64535
1172.18	64535
1174.39	64535
1176.6	64535
1178.81	64535
1181.02	64535
1183.22	64535
1185.43	64535
1187.63	64535
1189.84	64535
1192.04	64535
1194.25	64535
1196.45	64535
1198.65	64535
1200.85	64535
1203.05	64535
1205.25	64535
1207.45	64535
1209.65	64535
1211.85	64535
1214.05	64535
1216.24	64535
1218.44	64535
1220.64	64535
1222.83	64535
1225.02	64535
1227.22	64535
1229.41	64535
1231.6	64535
1233.79	64535
1235.98	64535
1238.17	64535
1240.36	64535
1242.55	64535
1244.73	64535
1246.92	64535
1249.11	64535
1251.29	64535
1253.48	64535
1255.66	64535
1257.84	64535
1260.03	64535
1262.21	64535
1264.39	64535
1266.57	64535
1268.75	64535
1270.93	64535
1273.11	64535
1275.28	64535
1277.46	64535
1279.64	64535
1281.81	64535
1283.98	64535
1286.16	64535
1288.33	64535
1290.5	64535
1292.68	64532.1
1294.85	64505.3
1297.02	64451
1299.19	64341.4
1301.36	64227.4
1303.53	64159.8
1305.69	64050.3
1307.86	63863.9
1310.03	63648.9
1312.19	63562.5
1314.36	63301.7
1316.52	63098.6
1318.68	62948.2
1320.85	62642.9
1323.01	62405.4
1325.17	62170.5
1327.33	61743.9
1329.49	61523.5
1331.65	61174.3
1333.81	60796.9
1335.97	60357.7
1338.12	60114.7
1340.28	59727.5
1342.44	59380
1344.59	58905.4
1346.75	58496.2
1348.9	58016.2
1351.05	57559.7
1353.2	57030.5
1355.36	56769.1
1357.51	56169.2
1359.66	55670.9
1361.81	55073.3
1363.96	54680.9
1366.1	53941.7
1368.25	53144.3
1370.4	52812.5
1372.54	52184.9
1374.69	51657.3
1376.83	50728.8
1378.98	50228.3
1381.12	49245.2
1383.26	49182.3
1385.41	48584.7
1387.55	48056.3
1389.69	47240.8
1391.83	46810.5
1393.02	46432
1395.17	46112
1397.32	45862
1399.47	45686
1401.62	44918
1403.77	45036
1405.91	44632
1408.06	44516
1410.2	44078
1412.35	43728
1414.49	43480
1416.63	42972
1418.78	42866
1420.92	42634
1423.06	42372
1425.2	42212
1427.34	41674
1429.48	41422
1431.61	41362
1433.75	41174
1435.89	40954
1438.02	40616
1440.16	40458
1442.3	40334
1444.43	40062
1446.56	39708
1448.7	39450
1450.83	39402
1452.96	39264
1455.09	39016
1457.22	38946
1459.35	38586
1461.48	38256
1463.61	38050
1465.73	37758
1467.86	38066
1469.98	37650
1472.11	37762
1474.24	37312
1476.36	37156
1478.48	36934
1480.6	36892
1482.73	36720
1484.85	36608
1486.97	36268
1489.09	36222
1491.21	36392
1493.33	35852
1495.44	35518
1497.56	35392
1499.68	35222
1501.79	34916
1503.91	34812
1506.02	34402
1508.14	34472
1510.25	34642
1512.36	34086
1514.48	33842
1516.59	33698
1518.7	33436
1520.81	33294
1522.92	33166
1525.02	32890
1527.13	32982
1529.24	32612
1531.35	32368
1533.45	32334
1535.56	31994
1537.66	31884
1539.77	31654
1541.87	31606
1543.97	31302
1546.08	31266
1548.18	31056
1550.28	30920
1552.38	30968
1554.48	30772
1556.57	30682
1558.67	30436
1560.77	30306
1562.87	30300
1564.96	30130
1567.06	30036
1569.15	29872
1571.25	29662
1573.34	29636
1575.43	29386
1577.53	29472
1579.62	29280
1581.71	29270
1583.8	29392
1585.89	29096
1587.98	29064
1590.06	28916
1592.15	28774
1594.24	28744
1596.33	28808
1598.41	28764
1600.5	28562
1602.58	28546
1604.66	28414
1606.75	28454
1608.83	28150
1610.91	28104
1612.99	28062
1615.07	28170
1617.15	27918
1619.23	27898
1621.31	27840
1623.39	27974
1625.46	27538
1627.54	27678
1629.62	27846
1631.69	27508
1633.77	27644
1635.84	27330
1637.91	27326
1639.99	27226
1642.06	27304
1644.13	26978
1646.2	26984
1648.27	27074
1650.34	26964
1652.41	26850
1654.47	26702
1656.54	26644
1658.61	26732
1660.67	26614
1662.74	26434
1664.81	26464
1666.87	26396
1668.93	26188
1671	25966
1673.06	25868
1675.12	26132
1677.18	25776
1679.24	25814
1681.3	25814
1683.36	25404
1685.42	25608
1687.47	25518
1689.53	25564
1691.59	25572
1693.64	25382
1695.7	25240
1697.75	25038
1699.81	25172
1701.86	25126
1703.91	24976
1705.97	24844
1708.02	24810
1710.07	25036
1712.12	25088
1714.17	25018
1716.22	24678
1718.26	24764
1720.31	24608
1722.36	24762
1724.4	24642
1726.45	24484
1728.49	24436
1730.54	24520
1732.58	24432
1734.63	24296
1736.67	24436
1738.71	24626
1740.75	24412
1742.79	24262
1744.83	24184
1746.87	24400
1748.91	24112
1750.95	24152
1752.98	24268
1755.02	24238
1757.06	24134
1759.09	24270
1761.13	24072
1763.16	24062
1765.19	24462
1767.23	24122
1769.26	23872
1771.29	24382
1773.32	24066
1775.35	24282
1777.38	24012
1779.41	24036
1781.44	24030
1783.47	24282
1785.49	24054
1787.52	23806
1789.55	24190
1791.57	24088
1793.6	24014
1795.62	23978
1797.64	24132
1799.67	24118
1801.69	23502
1803.71	23886
1805.73	23982
1807.75	23714
1809.77	23768
1811.79	23934
1813.81	23800
1815.83	23652
1817.84	23626
1819.86	23572
1821.88	23688
1823.89	23632
1825.91	23548
1827.92	23510
1829.93	23444
1831.95	23350
1833.96	23540
1835.97	23258
1837.98	23358
1839.99	23404
1842	23260
1844.01	23202
1846.02	23234
1848.03	23188
1850.03	23186
1852.04	23246
1854.05	23120
1856.05	23064
1858.06	22946
1860.06	23166
1862.06	23074
1864.07	23076
1866.07	23026
1868.07	23084
1870.07	23100
1872.07	23064
1874.07	23068
1876.07	22962
1878.07	22928
1880.07	22914
1882.07	22892
1884.06	23266
1886.06	22912
1888.05	22848
1890.05	22984
1892.04	22964
1894.04	23114
1896.03	22810
1898.02	22886
1900.01	22928
1902	22858
1903.99	22784
1905.98	22806
1907.97	23120
1909.96	22886
1911.95	23086
1913.94	22852
1915.93	22952
1917.91	22936
1919.9	22848
1921.88	22866
1923.87	22742
1925.85	22646
1927.83	22568
1929.82	22752
1931.8	22792
1933.78	22928
1935.76	22682
1937.74	22784
1939.72	22678
1941.7	22656
1943.68	22550
1945.65	22580
1947.63	22780
1949.61	22490
1951.58	22554
1953.56	22582
1955.53	22514
1957.51	22506
1959.48	22452
1961.45	22612
1963.43	22428
1965.4	22462
1967.37	22602
1969.34	22418
1971.31	22650
1973.28	22340
1975.25	22310
1977.22	22242
1979.18	21992
1981.15	22328
1983.12	22226
1985.08	22202
1987.05	22110
1989.01	22182
1990.97	22232
1992.94	22108
1994.9	22202
1996.86	22080
1998.82	22016
2000.78	21960
2002.74	21878
2004.7	22104
2006.66	22042
2008.62	22178
2010.58	22150
2012.54	22112
2014.49	22154
2016.45	21960
2018.4	21982
2020.36	22016
2022.31	21998
2024.27	21900
2026.22	21762
2028.17	21859
2030.12	21744
2032.07	21770
2034.03	21820
2035.98	21848
2037.93	21768
2039.87	21872
2041.82	21868
2043.77	21730
2045.72	21782
2047.66	21720
2049.61	21756
2051.55	21866
2053.5	21594
2055.44	21832
2057.39	21638
2059.33	21740
2061.27	21604
2063.21	21578
2065.15	21624
2067.09	21616
2069.03	21690
2070.97	21340
2072.91	21584
2074.85	21620
2076.79	21546
2078.73	21616
2080.66	21458
2082.6	21424
2084.53	21400
2086.47	21368
2088.4	21440
2090.33	21344
2092.27	21464
2094.2	21438
2096.13	21334
2098.06	21334
2099.99	21430
2101.92	21488
2103.85	21344
2105.78	21384
2107.71	21320
2109.64	21246
2111.56	21236
2113.49	21324
2115.41	21282
2117.34	21364
2119.26	21142
2121.19	21238
2123.11	21262
2125.03	21216
2126.96	21066
2128.88	21122
2130.8	21292
2132.72	21178
2134.64	21050
2136.56	21062
2138.48	21066
2140.4	21162
2142.31	21146
2144.23	20848
2146.15	21028
2148.06	21120
2149.98	21074
2151.89	20736
2153.81	20942
2155.72	20732
2157.63	20980
2159.55	20778
2161.46	20970
2163.37	20760
2165.28	20654
2167.19	20672
2169.1	20750
2171.01	20586
2172.91	20694
2174.82	20590
2176.73	20608
2178.64	20560
2180.54	20446
2182.45	20480
2184.35	20516
2186.26	20362
2188.16	20342
2190.06	20548
2191.96	20472
2193.87	20122
2195.77	20130
2197.67	20158
2199.57	20166
2201.47	20056
2203.37	20040
2205.27	20060
2207.16	20088
2209.06	19934
2210.96	19948
2212.85	20040
2214.75	20020
2216.64	20084
2218.54	20050
2220.43	20036
2222.33	20012
2224.22	20004.9
2226.11	19992.1
2228	19932.9
2229.89	20055.3
2231.78	19991
2233.67	20004.9
2235.56	19985.4
2237.45	19979.2
2239.34	19962.5
2241.23	19939.8
2243.11	20071.3
2245	19978.9
2246.89	20011.6
2248.77	20127.4
2250.66	20022.3
2252.54	20022.9
2254.42	20160.2
2256.31	20047.2
2258.19	20011.3
2260.07	20071.1
2261.95	20026.6
2263.83	19989.6
2265.71	20037.9
2267.59	20048.8
2269.47	19954.5
2271.35	20076
2273.23	19954.4
2275.1	19939.9
2276.98	19945.3
2278.86	20043.7
2280.73	19948.1
2282.61	20000.9
2284.48	19877.4
2286.36	19936.8
2288.23	19900.8
2290.1	19959.4
2291.98	19795.4
2293.85	19757.1
2295.72	19788.3
2297.59	19964
2299.46	19728.3
2301.33	19829.4
2303.2	19803.8
2305.06	19609.2
2306.93	19669.7
2308.8	19660.4
2310.67	19601.3
2312.53	19617.3
2314.4	19588.8
2316.26	19475.7
2317.62	19662
2319.5	19568
2321.37	19496
2323.24	19570
2325.12	19280
2326.99	19252
2328.86	19280
2330.73	19124
2332.6	19434
2334.47	19172
2336.34	19268
2338.2	19140
2340.07	19018
2341.94	18968
2343.81	19002
2345.67	19050
2347.54	18848
2349.4	18882
2351.27	18702
2353.13	18724
2354.99	18624
2356.86	18782
2358.72	18606
2360.58	18586
2362.44	18490
2364.3	18338
2366.16	18436
2368.02	18424
2369.88	18368
2371.74	18142
2373.6	18126
2375.45	18236
2377.31	17886
2379.17	18056
2381.02	18006
2382.88	18038
2384.73	17800
2386.58	17744
2388.44	17838
2390.29	17762
2392.14	17634
2393.99	17656
2395.85	17548
2397.7	17364
2399.55	17360
2401.4	17410
2403.25	17086
2405.09	17268
2406.94	17298
2408.79	17142
2410.63	16930
2412.48	16866
2414.33	16758
2416.17	16824
2418.02	16826
2419.86	16624
2421.7	16532
2423.55	16500
2425.39	16438
2427.23	16474
2429.07	16232
2430.91	16396
2432.75	16288
2434.59	16214
2436.43	16224
2438.27	16068
2440.11	16042
2441.95	16042
2443.78	15964
2445.62	15874
2447.46	15838
2449.29	15652
2451.13	15834
2452.96	15588
2454.79	15548
2456.63	15456
2458.46	15406
2460.29	15342
2462.12	15296
2463.95	15324
2465.78	15074
2467.61	15080
2469.44	15028
2471.27	14972
2473.1	14806
2474.93	14702
2476.76	14830
2478.58	14802
2480.41	14712
2482.23	14368
2484.06	14452
2485.88	14294
2487.71	14410
2489.53	14392
2491.35	14126
2493.18	14292
2495	14116
2496.82	14004
2498.64	13898
2500.46	14060
2502.28	13848
2504.1	13754
2505.92	13784
2507.74	13716
2509.55	13684
2511.37	13562
2513.19	13596
2515	13468
2516.82	13394
2518.63	13298
2520.45	13238
2522.26	13164
2524.07	13204
2525.89	13036
2527.7	12960
2529.51	12838
2531.32	12820
2533.13	12832
2534.94	12662
2536.75	12546
2538.56	12598
2540.37	12690
2542.18	12630
2543.98	12526
2545.79	12420
2547.6	12312
2549.4	12284
2551.21	12250
2553.01	12174
2554.82	12204
2556.62	12134
2558.42	12018
2560.23	12026
2562.03	12056
2563.83	11812
2565.63	11786
2567.43	11702
2569.23	11728
2571.03	11566
2572.83	11478
2574.63	11534
2576.43	11430
2578.22	11440
2580.02	11356
2581.82	11298
2583.61	11166
2585.41	11286
2587.2	11110
2589	11086
2590.79	10996
2592.58	10994
2594.38	10984
2596.17	10818
2597.96	10668
2599.75	10612
2601.54	10674
2603.33	10614
2605.12	10582
2606.91	10464
2608.7	10554
2610.49	10430
2612.27	10276
2614.06	10534
2615.85	10224
2617.63	10178
2619.42	10248
2621.2	10208
2622.99	10126
2624.77	10124
2626.55	10022
2628.34	9964
2630.12	9928
2631.9	9824
2633.68	9820
2635.46	9674
2637.24	9694
2639.02	9718
2640.8	9616
2642.58	9572
2644.36	9478
2646.14	9426
2647.91	9372
2649.69	9350
2651.46	9268
2653.24	9386
2655.01	9196
2656.79	9142
2658.56	9110
2660.34	9102
2662.11	9076
2663.88	9100
2665.65	9044
2667.42	9000
2669.2	8914
2670.96	8992
2672.73	8908
2674.5	8836
2676.27	8806
2678.04	8796
2679.81	8634
2681.58	8704
2683.34	8578
2685.11	8498
2686.87	8336
2688.64	8488
2690.4	8428
2692.17	8426
2693.93	8382
2695.69	8286
2697.46	8258
2699.22	8134
2700.98	8140
2702.74	8036
2704.5	8074
2706.26	7974
2708.02	7854
2709.78	7866
2711.54	7868
2713.3	7856
2715.05	7736
2716.81	7676
2718.57	7628
2720.32	7642
2722.08	7548
2723.83	7504
2725.59	7496
2727.34	7562
2729.09	7300
2730.85	7320
2732.6	7302
2734.35	7298
2736.1	7260
2737.85	7226
2739.6	7112
2741.35	7066
2743.1	7052
2744.85	7022
2746.6	6890
2748.35	6962
2750.09	6892
2751.84	6842
2753.59	6782
2755.33	6686
2757.08	6726
2758.82	6646
2760.57	6686
2762.31	6674
2764.05	6538
2765.79	6498
2767.54	6432
2769.28	6416
2771.02	6388
2772.76	6378
2774.5	6260
2776.24	6400
2777.98	6334
2779.72	6238
2781.46	6264
2783.19	6228
2784.93	6154
2786.67	6086
2788.4	6056
2790.14	6088
2791.87	6080
2793.61	5968
2795.34	5944
2797.07	5822
2798.81	5938
2800.54	5756
2802.27	5790
2804	5732
2805.74	5816
2807.47	5728
2809.2	5606
2810.93	5594
2812.65	5622
2814.38	5512
2816.11	5496
2817.84	5504
2819.56	5446
2821.29	5424
2823.02	5362
2824.74	5270
2826.47	5242
2828.19	5250
2829.92	5250
2831.64	5200
2833.36	5124
2835.09	5084
2836.81	5094
2838.53	4990
2840.25	4984
2841.97	4966
2843.69	4930
2845.41	4902
2847.13	4922
2848.85	4858
2850.57	4816
2852.28	4778
2854	4882
2855.72	4726
2857.43	4630
2859.15	4662
2860.86	4716
2862.58	4640
2864.29	4604
2866.01	4542
2867.72	4534
2869.43	4590
2871.14	4380
2872.86	4430
2874.57	4408
2876.28	4366
2877.99	4372
2879.7	4338
2881.41	4300
2883.11	4256
2884.82	4284
2886.53	4214
2888.24	4182
2889.94	4072
2891.65	4180
2893.36	4146
2895.06	4158
2896.77	4064
2898.47	4022
2900.17	4050
2901.88	4040
2903.58	3992
2905.28	3970
2906.98	3990
2908.69	3980
2910.39	3916
2912.09	3988
2913.79	3810
2915.49	3854
2917.19	3860
2918.88	3856
2920.58	3786
2922.28	3788
2923.98	3768
2925.67	3808
2927.37	3752
2929.06	3756
2930.76	3696
2932.45	3742
2934.15	3668
2935.84	3678
2937.53	3580
2939.23	3614
2940.92	3546
2942.61	3600
2944.3	3532
2945.99	3496
2947.68	3588
2949.37	3500
2951.06	3476
2952.75	3424
2954.44	3442
2956.12	3402
2957.81	3412
2959.5	3398
2961.18	3366
2962.87	3430
2964.56	3342
2966.24	3316
2967.92	3348
2969.61	3356
2971.29	3238
2972.97	3232
2974.66	3220
2976.34	3238
2978.02	3182
2979.7	3236
2981.38	3128
2983.06	3126
2984.74	3212
2986.42	3162
2988.1	3104
2989.78	3104
2991.45	3060
2993.13	3000
2994.81	3028
2996.48	2998
2998.16	2986
2999.83	2998