File: muestras/papalo/leaf_100x_11.txt
#Acq. time (s)=	10
#Accumulations=	1
#Range (cm-¹)=	200...3000
#Windows=	3
#Autofocus=	Off
#AutoExposure=	Off
#Spike filter=	Off
#Delay time (s)=	0
#Binning=	1
#Readout mode=	Signal
#DeNoise=	Off
#ICS correction=	Off
#Dark correction=	Off
#Inst. Process=	Off
#Instrument=	LabRAM HR Evol
#Detector=	Syncerity OE
#Objective=	x100_VIS
#Grating=	600 (500nm)
#ND Filter=	0.1%
#Laser=	633nm_Edge
#Hole=	100.021
#Range=	Visible
#Project=	Omar
#Sample=	03-07-23
#Site=	papal
#Title=	leaf_100x
#Remark=
#Date=	03.07.2023 17:20
#Acquired=	03.07.2023 17:20:22
201.713	118
204.247	136
206.778	146
209.311	134
211.84	136
214.371	146
216.899	154
219.428	148
221.955	130
224.482	150
227.007	156
229.531	156
232.055	158
234.579	154
237.1	166
239.621	162
242.141	164
244.661	174
247.179	158
249.698	176
252.215	182
254.731	170
257.246	158
259.761	182
262.273	186
264.786	180
267.298	188
269.809	196
272.319	210
274.828	188
277.336	206
279.844	196
282.351	208
284.855	188
287.361	196
289.866	192
292.368	220
294.871	206
297.372	214
299.873	212
302.372	226
304.872	236
307.37	236
309.866	234
312.364	220
314.859	230
317.353	232
319.848	240
322.341	252
324.833	246
327.324	248
329.814	254
332.304	230
334.792	270
337.28	262
339.767	262
342.254	260
344.739	276
347.224	288
349.708	276
352.191	282
354.673	292
357.155	288
359.634	294
362.114	300
364.593	286
367.07	298
369.548	314
372.024	320
374.499	318
376.974	312
379.447	326
381.92	340
384.392	344
386.864	350
389.333	358
391.802	346
394.272	324
396.739	362
399.206	356
401.673	348
404.138	356
406.602	378
409.066	384
411.528	386
413.99	390
416.451	388
418.911	384
421.371	398
423.83	392
426.288	404
428.745	432
431.201	436
433.657	416
436.111	436
438.565	438
441.017	440
443.469	414
445.921	452
448.37	470
450.821	428
453.27	448
455.717	458
458.165	472
460.61	482
463.056	466
465.5	454
467.945	486
470.387	486
472.829	480
475.271	496
477.711	520
480.15	502
482.589	472
485.027	518
487.465	534
489.901	570
492.337	534
494.771	554
497.205	580
499.638	488
502.07	538
504.502	580
506.933	588
509.363	600
511.792	574
514.219	574
516.647	592
519.073	596
521.5	588
523.924	604
526.348	602
528.772	604
531.194	626
533.616	604
536.036	606
538.457	616
540.875	680
543.294	666
545.712	662
548.128	692
550.545	700
552.959	672
555.373	680
557.788	710
560.2	656
562.612	724
565.023	724
567.433	718
569.843	740
572.251	752
574.659	778
577.066	792
579.472	730
581.878	764
584.283	762
586.687	788
589.09	798
591.493	798
593.893	818
596.294	804
598.694	852
601.093	822
603.491	844
605.889	862
608.285	860
610.682	904
613.076	868
615.471	926
617.864	946
620.256	954
622.648	938
625.039	972
627.429	984
629.819	994
632.208	1004
634.595	1028
636.982	1008
639.369	998
641.755	1082
644.139	1028
646.523	1060
648.906	1086
651.288	1096
653.67	1108
656.051	1146
658.429	1138
660.808	1114
663.187	1142
665.565	1212
667.942	1154
670.317	1208
672.692	1162
675.067	1170
677.44	1190
679.813	1238
682.184	1246
684.556	1294
686.926	1284
689.296	1328
691.664	1290
694.033	1314
696.4	1328
698.766	1358
701.133	1418
703.497	1404
705.861	1410
708.224	1382
710.586	1448
712.949	1458
715.31	1504
717.67	1476
720.029	1516
722.388	1514
724.746	1588
727.103	1570
729.458	1540
731.814	1608
734.168	1632
736.523	1620
738.876	1636
741.227	1704
743.579	1656
745.931	1678
748.28	1696
750.629	1744
752.977	1788
755.325	1814
757.672	1820
760.018	1866
762.363	1888
764.708	1876
767.052	1910
769.394	1894
771.737	1942
774.078	1964
776.419	1954
778.758	2038
781.097	2024
783.435	2122
785.773	2082
788.11	2092
790.446	2136
792.781	2184
795.115	2206
797.449	2210
799.782	2264
802.115	2312
804.446	2304
806.777	2320
809.106	2296
811.435	2430
813.764	2384
816.091	2446
818.418	2450
820.743	2576
823.069	2496
825.393	2612
827.717	2604
830.039	2674
832.362	2700
834.683	2694
837.003	2754
839.324	2794
841.643	2814
843.961	2854
846.278	2892
848.594	2926
850.91	3004
853.227	2996
855.541	3030
857.855	3032
860.168	3142
862.48	3156
864.79	3194
867.101	3260
869.411	3248
871.721	3254
874.029	3410
876.336	3312
878.643	3392
880.95	3436
883.254	3534
885.559	3476
887.862	3556
890.166	3612
892.467	3578
894.77	3590
897.07	3626
899.371	3714
901.669	3714
903.968	3784
906.266	3706
908.563	3808
910.859	3902
913.154	3924
915.449	4008
917.742	3978
920.036	4046
922.329	4046
924.621	4154
926.911	4256
929.201	4162
931.49	4342
933.779	4346
936.068	4372
938.355	4448
940.64	4432
942.926	4472
945.212	4574
947.495	4622
949.779	4694
952.062	4634
954.344	4762
956.625	4848
958.905	4842
961.184	4924
963.464	4956
965.742	5052
968.02	5070
970.296	5122
972.572	5168
974.847	5200
977.121	5248
979.396	5336
981.669	5486
983.941	5434
986.212	5430
988.483	5530
990.753	5606
993.022	5688
995.29	5706
997.558	5658
999.825	5844
1002.09	5794
1004.36	5922
1006.62	5938
1008.89	6032
1011.15	6094
1013.41	6216
1015.67	6228
1017.93	6200
1020.19	6328
1022.45	6338
1024.71	6452
1026.97	6502
1029.23	6536
1031.49	6672
1033.74	6698
1036	6782
1038.25	6832
1040.5	7010
1042.76	7000
1045.01	7104
1047.26	7172
1049.51	7318
1051.76	7166
1054.01	7362
1056.26	7438
1058.51	7496
1060.75	7548
1063	7722
1065.25	7654
1067.49	7776
1069.73	7752
1071.98	7882
1074.22	7950
1076.46	7948
1078.7	8050
1080.94	7972
1083.18	8118
1085.42	8178
1087.66	8226
1089.9	8286
1092.14	8362
1094.37	8342
1096.61	8446
1098.84	8450
1101.08	8438
1103.31	8474
1105.54	8636
1107.77	8600
1110	8742
1112.23	8706
1114.46	8820
1116.69	8958
1118.92	8924
1121.15	9094
1123.37	9090
1125.6	9218
1127.83	9148
1130.05	9200
1132.27	9274
1134.5	9410
1136.72	9350
1138.94	9474
1141.16	9574
1143.38	9646
1145.6	9662
1147.82	9624
1150.04	9688
1152.26	9758
1154.47	9830
1156.69	9944
1158.9	9976
1161.12	9902
1163.33	10020
1165.54	10032
1167.76	9998
1169.97	9950
1172.18	10132
1174.39	10092
1176.6	10196
1178.81	10110
1181.02	10066
1183.22	10158
1185.43	10144
1187.63	10092
1189.84	10124
1192.04	10170
1194.25	10118
1196.45	10202
1198.65	10124
1200.85	10090
1203.05	10074
1205.25	10132
1207.45	10072
1209.65	10088
1211.85	10010
1214.05	10090
1216.24	9912
1218.44	9850
1220.64	9928
1222.83	9906
1225.02	9848
1227.22	9854
1229.41	9768
1231.6	9700
1233.79	9896
1235.98	9632
1238.17	9730
1240.36	9684
1242.55	9618
1244.73	9552
1246.92	9540
1249.11	9406
1251.29	9462
1253.48	9574
1255.66	9516
1257.84	9376
1260.03	9304
1262.21	9296
1264.39	9188
1266.57	9180
1268.75	9094
1270.93	9044
1273.11	9162
1275.28	9068
1277.46	8926
1279.64	8908
1281.81	8830
1283.98	8921.83
1286.16	8763.38
1288.33	8624.58
1290.5	8691.07
1292.68	8561.65
1294.85	8457.33
1297.02	8396.66
1299.19	8362.15
1301.36	8220.41
1303.53	8160.97
1305.69	8066.23
1307.86	7961.31
1310.03	7941.34
1312.19	7803.09
1314.36	7823.86
1316.52	7786.73
1318.68	7644.2
1320.85	7632.2
1323.01	7579.38
1325.17	7519.09
1327.33	7376.86
1329.49	7331.27
1331.65	7278.74
1333.81	7148.38
1335.97	7095.34
1338.12	7037.34
1340.28	7015.64
1342.44	6968.15
1344.59	6842.57
1346.75	6804.56
1348.9	6746.4
1351.05	6660.71
1353.2	6523.73
1355.36	6620.44
1357.51	6509.64
1359.66	6420.94
1361.81	6347.5
1363.96	6235.02
1366.1	6184.07
1368.25	6184
1370.4	6149.28
1372.54	6059.74
1374.69	6113.95
1376.83	6011.85
1378.98	5874.54
1381.12	5930.23
1383.26	5840.73
1385.41	5685.88
1387.55	5675.97
1389.69	5728.94
1391.83	5714.63
1393.02	5586
1395.17	5486
1397.32	5462
1399.47	5486
1401.62	5346
1403.77	5290
1405.91	5284
1408.06	5210
1410.2	5296
1412.35	5178
1414.49	5122
1416.63	5146
1418.78	5210
1420.92	4996
1423.06	5030
1425.2	5060
1427.34	4966
1429.48	5034
1431.61	4876
1433.75	4906
1435.89	4762
1438.02	4822
1440.16	4714
1442.3	4718
1444.43	4806
1446.56	4654
1448.7	4690
1450.83	4712
1452.96	4682
1455.09	4612
1457.22	4552
1459.35	4598
1461.48	4562
1463.61	4380
1465.73	4458
1467.86	4394
1469.98	4564
1472.11	4422
1474.24	4464
1476.36	4416
1478.48	4356
1480.6	4344
1482.73	4314
1484.85	4316
1486.97	4186
1489.09	4290
1491.21	4252
1493.33	4216
1495.44	4132
1497.56	4198
1499.68	4096
1501.79	4072
1503.91	4072
1506.02	4058
1508.14	4038
1510.25	4052
1512.36	3904
1514.48	3962
1516.59	3906
1518.7	3892
1520.81	3868
1522.92	3878
1525.02	3832
1527.13	3810
1529.24	3754
1531.35	3766
1533.45	3710
1535.56	3740
1537.66	3688
1539.77	3666
1541.87	3678
1543.97	3648
1546.08	3616
1548.18	3600
1550.28	3660
1552.38	3558
1554.48	3614
1556.57	3596
1558.67	3554
1560.77	3526
1562.87	3478
1564.96	3524
1567.06	3464
1569.15	3440
1571.25	3446
1573.34	3496
1575.43	3492
1577.53	3432
1579.62	3420
1581.71	3408
1583.8	3328
1585.89	3346
1587.98	3408
1590.06	3400
1592.15	3308
1594.24	3344
1596.33	3316
1598.41	3296
1600.5	3322
1602.58	3296
1604.66	3234
1606.75	3278
1608.83	3240
1610.91	3212
1612.99	3206
1615.07	3248
1617.15	3240
1619.23	3266
1621.31	3288
1623.39	3178
1625.46	3206
1627.54	3180
1629.62	3156
1631.69	3182
1633.77	3188
1635.84	3088
1637.91	3136
1639.99	3100
1642.06	3126
1644.13	3126
1646.2	3184
1648.27	3078
1650.34	3102
1652.41	3138
1654.47	3074
1656.54	3026
1658.61	3026
1660.67	2994
1662.74	2970
1664.81	2994
1666.87	2998
1668.93	3012
1671	2992
1673.06	2980
1675.12	3070
1677.18	2960
1679.24	2982
1681.3	2956
1683.36	2958
1685.42	2916
1687.47	2930
1689.53	2970
1691.59	2900
1693.64	2882
1695.7	2962
1697.75	2848
1699.81	2840
1701.86	2852
1703.91	2904
1705.97	2790
1708.02	2886
1710.07	2856
1712.12	2908
1714.17	2844
1716.22	2808
1718.26	2892
1720.31	2786
1722.36	2830
1724.4	2860
1726.45	2826
1728.49	2796
1730.54	2840
1732.58	2772
1734.63	2872
1736.67	2814
1738.71	2796
1740.75	2812
1742.79	2720
1744.83	2770
1746.87	2768
1748.91	2798
1750.95	2750
1752.98	2792
1755.02	2724
1757.06	2764
1759.09	2778
1761.13	2710
1763.16	2728
1765.19	2756
1767.23	2756
1769.26	2800
1771.29	2774
1773.32	2776
1775.35	2766
1777.38	2812
1779.41	2736
1781.44	2714
1783.47	2724
1785.49	2746
1787.52	2776
1789.55	2756
1791.57	2732
1793.6	2704
1795.62	2732
1797.64	2694
1799.67	2802
1801.69	2670
1803.71	2728
1805.73	2654
1807.75	2672
1809.77	2718
1811.79	2674
1813.81	2676
1815.83	2728
1817.84	2732
1819.86	2762
1821.88	2628
1823.89	2702
1825.91	2726
1827.92	2718
1829.93	2674
1831.95	2682
1833.96	2658
1835.97	2638
1837.98	2608
1839.99	2592
1842	2704
1844.01	2646
1846.02	2674
1848.03	2654
1850.03	2552
1852.04	2684
1854.05	2610
1856.05	2628
1858.06	2616
1860.06	2544
1862.06	2582
1864.07	2638
1866.07	2600
1868.07	2612
1870.07	2596
1872.07	2610
1874.07	2640
1876.07	2632
1878.07	2626
1880.07	2610
1882.07	2580
1884.06	2610
1886.06	2590
1888.05	2636
1890.05	2566
1892.04	2580
1894.04	2582
1896.03	2618
1898.02	2542
1900.01	2616
1902	2550
1903.99	2572
1905.98	2544
1907.97	2566
1909.96	2566
1911.95	2604
1913.94	2596
1915.93	2538
1917.91	2594
1919.9	2556
1921.88	2534
1923.87	2576
1925.85	2566
1927.83	2572
1929.82	2590
1931.8	2564
1933.78	2532
1935.76	2512
1937.74	2584
1939.72	2584
1941.7	2580
1943.68	2552
1945.65	2498
1947.63	2494
1949.61	2504
1951.58	2612
1953.56	2594
1955.53	2518
1957.51	2522
1959.48	2548
1961.45	2486
1963.43	2552
1965.4	2516
1967.37	2540
1969.34	2512
1971.31	2536
1973.28	2494
1975.25	2504
1977.22	2504
1979.18	2518
1981.15	2474
1983.12	2524
1985.08	2470
1987.05	2498
1989.01	2432
1990.97	2478
1992.94	2490
1994.9	2466
1996.86	2444
1998.82	2506
2000.78	2474
2002.74	2400
2004.7	2434
2006.66	2460
2008.62	2434
2010.58	2436
2012.54	2452
2014.49	2494
2016.45	2464
2018.4	2486
2020.36	2414
2022.31	2488
2024.27	2442
2026.22	2442
2028.17	2416
2030.12	2462
2032.07	2414
2034.03	2386
2035.98	2400
2037.93	2432
2039.87	2462
2041.82	2464
2043.77	2362
2045.72	2456
2047.66	2402
2049.61	2436
2051.55	2432
2053.5	2432
2055.44	2400
2057.39	2390
2059.33	2418
2061.27	2330
2063.21	2390
2065.15	2402
2067.09	2402
2069.03	2392
2070.97	2360
2072.91	2346
2074.85	2350
2076.79	2406
2078.73	2364
2080.66	2376
2082.6	2334
2084.53	2368
2086.47	2346
2088.4	2370
2090.33	2348
2092.27	2330
2094.2	2374
2096.13	2382
2098.06	2390
2099.99	2372
2101.92	2364
2103.85	2418
2105.78	2344
2107.71	2352
2109.64	2356
2111.56	2330
2113.49	2360
2115.41	2252
2117.34	2350
2119.26	2326
2121.19	2328
2123.11	2388
2125.03	2330
2126.96	2316
2128.88	2366
2130.8	2308
2132.72	2292
2134.64	2302
2136.56	2280
2138.48	2262
2140.4	2358
2142.31	2284
2144.23	2294
2146.15	2276
2148.06	2288
2149.98	2318
2151.89	2288
2153.81	2244
2155.72	2324
2157.63	2254
2159.55	2334
2161.46	2284
2163.37	2260
2165.28	2312
2167.19	2264
2169.1	2226
2171.01	2282
2172.91	2260
2174.82	2210
2176.73	2254
2178.64	2218
2180.54	2234
2182.45	2258
2184.35	2224
2186.26	2254
2188.16	2294
2190.06	2196
2191.96	2222
2193.87	2202
2195.77	2184
2197.67	2162
2199.57	2174
2201.47	2208
2203.37	2192
2205.27	2122
2207.16	2200
2209.06	2222
2210.96	2202
2212.85	2128
2214.75	2178
2216.64	2128
2218.54	2134
2220.43	2126
2222.33	2184
2224.22	2148.89
2226.11	2127.67
2228	2162.41
2229.89	2172.67
2231.78	2135.25
2233.67	2096.84
2235.56	2145.53
2237.45	2116.56
2239.34	2178.23
2241.23	2138.71
2243.11	2099.51
2245	2067.52
2246.89	2114.05
2248.77	2053.42
2250.66	2126.14
2252.54	2071.14
2254.42	2088.18
2256.31	2125.49
2258.19	2087.18
2260.07	2099.18
2261.95	2081.36
2263.83	2095.92
2265.71	2037.65
2267.59	2044.29
2269.47	2025.76
2271.35	2016.9
2273.23	2013.47
2275.1	2028.94
2276.98	2017.86
2278.86	2018.99
2280.73	1999.3
2282.61	2004.16
2284.48	2008.86
2286.36	1981.07
2288.23	1942.36
2290.1	1976.41
2291.98	1949.92
2293.85	1977.43
2295.72	1963.22
2297.59	1958.15
2299.46	1963.2
2301.33	1923.45
2303.2	1951.35
2305.06	1922.26
2306.93	1929.49
2308.8	1886.3
2310.67	1901.69
2312.53	1882.99
2314.4	1901.09
2316.26	1893.27
2317.62	1866
2319.5	1860
2321.37	1878
2323.24	1852
2325.12	1876
2326.99	1906
2328.86	1848
2330.73	1808
2332.6	1896
2334.47	1842
2336.34	1844
2338.2	1886
2340.07	1840
2341.94	1834
2343.81	1832
2345.67	1840
2347.54	1760
2349.4	1804
2351.27	1760
2353.13	1862
2354.99	1764
2356.86	1800
2358.72	1800
2360.58	1752
2362.44	1776
2364.3	1786
2366.16	1810
2368.02	1752
2369.88	1778
2371.74	1712
2373.6	1748
2375.45	1738
2377.31	1794
2379.17	1792
2381.02	1750
2382.88	1706
2384.73	1750
2386.58	1704
2388.44	1698
2390.29	1696
2392.14	1688
2393.99	1684
2395.85	1612
2397.7	1682
2399.55	1650
2401.4	1674
2403.25	1652
2405.09	1670
2406.94	1644
2408.79	1644
2410.63	1602
2412.48	1612
2414.33	1620
2416.17	1634
2418.02	1634
2419.86	1604
2421.7	1590
2423.55	1514
2425.39	1562
2427.23	1576
2429.07	1588
2430.91	1558
2432.75	1484
2434.59	1538
2436.43	1526
2438.27	1530
2440.11	1556
2441.95	1538
2443.78	1470
2445.62	1476
2447.46	1458
2449.29	1468
2451.13	1476
2452.96	1478
2454.79	1490
2456.63	1442
2458.46	1406
2460.29	1440
2462.12	1410
2463.95	1424
2465.78	1426
2467.61	1380
2469.44	1368
2471.27	1400
2473.1	1382
2474.93	1382
2476.76	1392
2478.58	1392
2480.41	1408
2482.23	1372
2484.06	1392
2485.88	1376
2487.71	1336
2489.53	1346
2491.35	1348
2493.18	1356
2495	1330
2496.82	1340
2498.64	1312
2500.46	1364
2502.28	1264
2504.1	1284
2505.92	1284
2507.74	1324
2509.55	1296
2511.37	1254
2513.19	1250
2515	1288
2516.82	1226
2518.63	1192
2520.45	1226
2522.26	1200
2524.07	1216
2525.89	1206
2527.7	1164
2529.51	1168
2531.32	1178
2533.13	1192
2534.94	1196
2536.75	1178
2538.56	1180
2540.37	1178
2542.18	1166
2543.98	1180
2545.79	1112
2547.6	1130
2549.4	1172
2551.21	1182
2553.01	1102
2554.82	1098
2556.62	1100
2558.42	1114
2560.23	1106
2562.03	1084
2563.83	1094
2565.63	1082
2567.43	1082
2569.23	1072
2571.03	1090
2572.83	1086
2574.63	1088
2576.43	1048
2578.22	1058
2580.02	1070
2581.82	1030
2583.61	1044
2585.41	1030
2587.2	1036
2589	1028
2590.79	1012
2592.58	996
2594.38	958
2596.17	994
2597.96	970
2599.75	958
2601.54	960
2603.33	970
2605.12	958
2606.91	964
2608.7	994
2610.49	960
2612.27	940
2614.06	952
2615.85	916
2617.63	944
2619.42	916
2621.2	928
2622.99	954
2624.77	934
2626.55	936
2628.34	906
2630.12	898
2631.9	876
2633.68	920
2635.46	886
2637.24	868
2639.02	860
2640.8	890
2642.58	864
2644.36	862
2646.14	880
2647.91	890
2649.69	858
2651.46	844
2653.24	812
2655.01	834
2656.79	834
2658.56	806
2660.34	844
2662.11	800
2663.88	802
2665.65	816
2667.42	820
2669.2	778
2670.96	810
2672.73	842
2674.5	818
2676.27	798
2678.04	778
2679.81	786
2681.58	776
2683.34	738
2685.11	744
2686.87	768
2688.64	766
2690.4	754
2692.17	736
2693.93	732
2695.69	768
2697.46	728
2699.22	730
2700.98	740
2702.74	724
2704.5	750
2706.26	702
2708.02	722
2709.78	702
2711.54	716
2713.3	698
2715.05	668
2716.81	724
2718.57	670
2720.32	720
2722.08	674
2723.83	678
2725.59	638
2727.34	656
2729.09	678
2730.85	644
2732.6	646
2734.35	628
2736.1	662
2737.85	614
2739.6	628
2741.35	618
2743.1	616
2744.85	620
2746.6	600
2748.35	604
2750.09	596
2751.84	604
2753.59	618
2755.33	582
2757.08	576
2758.82	620
2760.57	596
2762.31	568
2764.05	584
2765.79	572
2767.54	582
2769.28	562
2771.02	548
2772.76	568
2774.5	558
2776.24	564
2777.98	574
2779.72	558
2781.46	534
2783.19	576
2784.93	520
2786.67	526
2788.4	534
2790.14	526
2791.87	506
2793.61	534
2795.34	544
2797.07	520
2798.81	564
2800.54	526
2802.27	492
2804	504
2805.74	510
2807.47	496
2809.2	498
2810.93	502
2812.65	478
2814.38	490
2816.11	488
2817.84	494
2819.56	500
2821.29	490
2823.02	466
2824.74	460
2826.47	468
2828.19	456
2829.92	474
2831.64	458
2833.36	444
2835.09	436
2836.81	452
2838.53	446
2840.25	428
2841.97	426
2843.69	436
2845.41	456
2847.13	434
2848.85	414
2850.57	438
2852.28	430
2854	414
2855.72	424
2857.43	452
2859.15	406
2860.86	398
2862.58	416
2864.29	406
2866.01	408
2867.72	376
2869.43	392
2871.14	386
2872.86	398
2874.57	384
2876.28	392
2877.99	368
2879.7	372
2881.41	382
2883.11	378
2884.82	372
2886.53	358
2888.24	352
2889.94	352
2891.65	372
2893.36	354
2895.06	348
2896.77	334
2898.47	358
2900.17	338
2901.88	358
2903.58	348
2905.28	346
2906.98	336
2908.69	326
2910.39	330
2912.09	350
2913.79	330
2915.49	334
2917.19	342
2918.88	344
2920.58	332
2922.28	330
2923.98	316
2925.67	324
2927.37	306
2929.06	314
2930.76	334
2932.45	314
2934.15	338
2935.84	314
2937.53	292
2939.23	306
2940.92	318
2942.61	312
2944.3	318
2945.99	294
2947.68	300
2949.37	286
2951.06	296
2952.75	304
2954.44	282
2956.12	314
2957.81	288
2959.5	268
2961.18	284
2962.87	284
2964.56	280
2966.24	306
2967.92	278
2969.61	272
2971.29	280
2972.97	260
2974.66	286
2976.34	284
2978.02	284
2979.7	260
2981.38	280
2983.06	266
2984.74	284
2986.42	252
2988.1	272
2989.78	250
2991.45	270
2993.13	274
2994.81	262
2996.48	254
2998.16	254
2999.83	240