File: muestras/papalo/leaf_09.txt
#Acq. time (s)=	10
#Accumulations=	1
#Range (cm-¹)=	200...3000
#Windows=	3
#Autofocus=	Off
#AutoExposure=	Off
#Spike filter=	Off
#Delay time (s)=	0
#Binning=	1
#Readout mode=	Signal
#DeNoise=	Off
#ICS correction=	Off
#Dark correction=	Off
#Inst. Process=	Off
#Instrument=	LabRAM HR Evol
#Detector=	Syncerity OE
#Objective=	x100_VIS
#Grating=	600 (500nm)
#ND Filter=	0.01%
#Laser=	633nm_Edge
#Hole=	34.9738
#Range=	Visible
#Project=	Omar
#Sample=	03-07-23
#Site=	papal
#Title=	leaf
#Remark=
#Date=	03.07.2023 17:00
#Acquired=	03.07.2023 17:00:15
201.713	54
204.247	46
206.778	40
209.311	36
211.84	42
214.371	44
216.899	40
219.428	34
221.955	38
224.482	34
227.007	38
229.531	44
232.055	38
234.579	38
237.1	42
239.621	38
242.141	34
244.661	38
247.179	44
249.698	38
252.215	44
254.731	44
257.246	36
259.761	42
262.273	40
264.786	50
267.298	44
269.809	38
272.319	46
274.828	48
277.336	46
279.844	50
282.351	42
284.855	48
287.361	50
289.866	50
292.368	34
294.871	48
297.372	46
299.873	42
302.372	42
304.872	48
307.37	42
309.866	36
312.364	56
314.859	40
317.353	54
319.848	46
322.341	48
324.833	46
327.324	36
329.814	56
332.304	44
334.792	54
337.28	52
339.767	54
342.254	44
344.739	60
347.224	54
349.708	50
352.191	44
354.673	60
357.155	50
359.634	50
362.114	44
364.593	60
367.07	54
369.548	40
372.024	60
374.499	48
376.974	60
379.447	56
381.92	58
384.392	64
386.864	54
389.333	58
391.802	56
394.272	62
396.739	76
399.206	50
401.673	54
404.138	60
406.602	70
409.066	66
411.528	62
413.99	56
416.451	70
418.911	64
421.371	70
423.83	70
426.288	62
428.745	66
431.201	62
433.657	74
436.111	72
438.565	70
441.017	74
443.469	66
445.921	66
448.37	66
450.821	74
453.27	74
455.717	62
458.165	68
460.61	80
463.056	76
465.5	66
467.945	72
470.387	70
472.829	76
475.271	70
477.711	80
480.15	78
482.589	74
485.027	84
487.465	62
489.901	72
492.337	80
494.771	76
497.205	72
499.638	88
502.07	74
504.502	72
506.933	76
509.363	86
511.792	90
514.219	82
516.647	92
519.073	98
521.5	80
523.924	84
526.348	88
528.772	76
531.194	84
533.616	90
536.036	84
538.457	100
540.875	98
543.294	98
545.712	102
548.128	96
550.545	98
552.959	92
555.373	88
557.788	92
560.2	90
562.612	90
565.023	88
567.433	98
569.843	98
572.251	108
574.659	96
577.066	98
579.472	100
581.878	92
584.283	98
586.687	108
589.09	108
591.493	110
593.893	106
596.294	106
598.694	104
601.093	96
603.491	106
605.889	106
608.285	118
610.682	128
613.076	116
615.471	106
617.864	112
620.256	108
622.648	128
625.039	118
627.429	114
629.819	114
632.208	118
634.595	114
636.982	126
639.369	130
641.755	132
644.139	154
646.523	136
648.906	126
651.288	136
653.67	140
656.051	134
658.429	144
660.808	122
663.187	126
665.565	136
667.942	148
670.317	154
672.692	148
675.067	148
677.44	152
679.813	164
682.184	158
684.556	148
686.926	148
689.296	158
691.664	154
694.033	152
696.4	166
698.766	162
701.133	172
703.497	170
705.861	162
708.224	172
710.586	148
712.949	170
715.31	172
717.67	182
720.029	170
722.388	174
724.746	182
727.103	176
729.458	176
731.814	174
734.168	174
736.523	202
738.876	194
741.227	192
743.579	206
745.931	204
748.28	182
750.629	214
752.977	204
755.325	218
757.672	228
760.018	210
762.363	228
764.708	224
767.052	228
769.394	218
771.737	212
774.078	208
776.419	228
778.758	218
781.097	224
783.435	236
785.773	238
788.11	246
790.446	262
792.781	264
795.115	240
797.449	264
799.782	262
802.115	274
804.446	286
806.777	274
809.106	264
811.435	262
813.764	276
816.091	274
818.418	278
820.743	290
823.069	286
825.393	268
827.717	304
830.039	300
832.362	292
834.683	300
837.003	310
839.324	302
841.643	310
843.961	336
846.278	334
848.594	326
850.91	332
853.227	334
855.541	352
857.855	354
860.168	342
862.48	368
864.79	376
867.101	368
869.411	362
871.721	374
874.029	374
876.336	388
878.643	386
880.95	384
883.254	384
885.559	366
887.862	376
890.166	400
892.467	416
894.77	396
897.07	404
899.371	414
901.669	400
903.968	420
906.266	410
908.563	430
910.859	438
913.154	414
915.449	444
917.742	450
920.036	456
922.329	448
924.621	488
926.911	458
929.201	458
931.49	486
933.779	504
936.068	462
938.355	496
940.64	498
942.926	502
945.212	506
947.495	506
949.779	504
952.062	524
954.344	508
956.625	544
958.905	548
961.184	542
963.464	538
965.742	562
968.02	546
970.296	602
972.572	566
974.847	556
977.121	586
979.396	562
981.669	612
983.941	624
986.212	580
988.483	612
990.753	618
993.022	618
995.29	602
997.558	658
999.825	638
1002.09	658
1004.36	676
1006.62	674
1008.89	674
1011.15	696
1013.41	660
1015.67	684
1017.93	696
1020.19	686
1022.45	698
1024.71	740
1026.97	732
1029.23	738
1031.49	736
1033.74	744
1036	742
1038.25	770
1040.5	780
1042.76	752
1045.01	764
1047.26	794
1049.51	792
1051.76	802
1054.01	812
1056.26	840
1058.51	840
1060.75	828
1063	846
1065.25	844
1067.49	850
1069.73	852
1071.98	862
1074.22	868
1076.46	854
1078.7	884
1080.94	882
1083.18	934
1085.42	908
1087.66	930
1089.9	920
1092.14	906
1094.37	902
1096.61	906
1098.84	980
1101.08	944
1103.31	946
1105.54	954
1107.77	934
1110	956
1112.23	998
1114.46	888
1116.69	958
1118.92	988
1121.15	998
1123.37	1010
1125.6	940
1127.83	962
1130.05	1014
1132.27	1064
1134.5	1018
1136.72	1002
1138.94	1018
1141.16	1014
1143.38	1042
1145.6	1016
1147.82	1066
1150.04	998
1152.26	1052
1154.47	1054
1156.69	1050
1158.9	1052
1161.12	1076
1163.33	1082
1165.54	1130
1167.76	1094
1169.97	1114
1172.18	1072
1174.39	1090
1176.6	1084
1178.81	1102
1181.02	1072
1183.22	1046
1185.43	1080
1187.63	1036
1189.84	1088
1192.04	1052
1194.25	1058
1196.45	1066
1198.65	1056
1200.85	1054
1203.05	1046
1205.25	1068
1207.45	1088
1209.65	1048
1211.85	1068
1214.05	1024
1216.24	1028
1218.44	1022
1220.64	1006
1222.83	994
1225.02	1020
1227.22	1038
1229.41	974
1231.6	994
1233.79	1018
1235.98	978
1238.17	968
1240.36	998
1242.55	970
1244.73	996
1246.92	980
1249.11	960
1251.29	982
1253.48	948
1255.66	972
1257.84	944
1260.03	962
1262.21	930
1264.39	900
1266.57	928
1268.75	960
1270.93	936
1273.11	968
1275.28	922
1277.46	928
1279.64	910
1281.81	872
1283.98	889.71
1286.16	855.434
1288.33	893.937
1290.5	895.177
1292.68	863
1294.85	834.105
1297.02	841.984
1299.19	845.737
1301.36	834.913
1303.53	831.982
1305.69	827.417
1307.86	790.258
1310.03	801.318
1312.19	780.851
1314.36	769.849
1316.52	793.02
1318.68	771.734
1320.85	737.34
1323.01	742.246
1325.17	755.31
1327.33	735.215
1329.49	720.949
1331.65	728.279
1333.81	720.671
1335.97	691.295
1338.12	714.772
1340.28	691.107
1342.44	682.779
1344.59	686.031
1346.75	680.875
1348.9	662.183
1351.05	671.538
1353.2	637.014
1355.36	652.373
1357.51	668.954
1359.66	628.95
1361.81	651.807
1363.96	610.66
1366.1	613.926
1368.25	589.428
1370.4	608.909
1372.54	602.13
1374.69	589.763
1376.83	589.51
1378.98	571.912
1381.12	603.993
1383.26	557.22
1385.41	555.512
1387.55	563.026
1389.69	547.46
1391.83	549.839
1393.02	554
1395.17	580
1397.32	552
1399.47	518
1401.62	532
1403.77	502
1405.91	520
1408.06	534
1410.2	528
1412.35	512
1414.49	516
1416.63	512
1418.78	508
1420.92	486
1423.06	514
1425.2	512
1427.34	502
1429.48	488
1431.61	472
1433.75	482
1435.89	458
1438.02	494
1440.16	472
1442.3	488
1444.43	472
1446.56	446
1448.7	454
1450.83	442
1452.96	456
1455.09	472
1457.22	470
1459.35	448
1461.48	454
1463.61	430
1465.73	434
1467.86	434
1469.98	412
1472.11	400
1474.24	432
1476.36	434
1478.48	420
1480.6	402
1482.73	428
1484.85	418
1486.97	440
1489.09	414
1491.21	416
1493.33	418
1495.44	406
1497.56	394
1499.68	412
1501.79	410
1503.91	384
1506.02	408
1508.14	400
1510.25	412
1512.36	400
1514.48	414
1516.59	388
1518.7	380
1520.81	378
1522.92	388
1525.02	364
1527.13	346
1529.24	388
1531.35	370
1533.45	388
1535.56	354
1537.66	372
1539.77	384
1541.87	364
1543.97	370
1546.08	364
1548.18	374
1550.28	344
1552.38	356
1554.48	368
1556.57	336
1558.67	334
1560.77	342
1562.87	332
1564.96	334
1567.06	356
1569.15	332
1571.25	350
1573.34	338
1575.43	332
1577.53	352
1579.62	336
1581.71	348
1583.8	342
1585.89	336
1587.98	320
1590.06	326
1592.15	334
1594.24	332
1596.33	300
1598.41	314
1600.5	320
1602.58	320
1604.66	306
1606.75	322
1608.83	292
1610.91	296
1612.99	314
1615.07	322
1617.15	316
1619.23	326
1621.31	314
1623.39	320
1625.46	312
1627.54	338
1629.62	310
1631.69	316
1633.77	300
1635.84	294
1637.91	304
1639.99	298
1642.06	310
1644.13	296
1646.2	296
1648.27	304
1650.34	298
1652.41	318
1654.47	292
1656.54	288
1658.61	320
1660.67	296
1662.74	298
1664.81	302
1666.87	284
1668.93	296
1671	296
1673.06	286
1675.12	278
1677.18	290
1679.24	300
1681.3	272
1683.36	306
1685.42	306
1687.47	298
1689.53	304
1691.59	286
1693.64	280
1695.7	286
1697.75	300
1699.81	288
1701.86	290
1703.91	286
1705.97	266
1708.02	290
1710.07	290
1712.12	296
1714.17	300
1716.22	294
1718.26	294
1720.31	266
1722.36	276
1724.4	284
1726.45	260
1728.49	292
1730.54	270
1732.58	276
1734.63	266
1736.67	278
1738.71	266
1740.75	286
1742.79	294
1744.83	254
1746.87	288
1748.91	280
1750.95	264
1752.98	294
1755.02	274
1757.06	276
1759.09	284
1761.13	284
1763.16	278
1765.19	264
1767.23	282
1769.26	264
1771.29	290
1773.32	264
1775.35	270
1777.38	292
1779.41	258
1781.44	268
1783.47	254
1785.49	274
1787.52	264
1789.55	258
1791.57	262
1793.6	278
1795.62	278
1797.64	278
1799.67	274
1801.69	284
1803.71	280
1805.73	262
1807.75	278
1809.77	250
1811.79	250
1813.81	274
1815.83	262
1817.84	282
1819.86	276
1821.88	268
1823.89	256
1825.91	258
1827.92	264
1829.93	282
1831.95	276
1833.96	278
1835.97	280
1837.98	260
1839.99	264
1842	278
1844.01	258
1846.02	260
1848.03	280
1850.03	260
1852.04	252
1854.05	250
1856.05	256
1858.06	270
1860.06	252
1862.06	280
1864.07	250
1866.07	280
1868.07	260
1870.07	250
1872.07	264
1874.07	278
1876.07	272
1878.07	252
1880.07	250
1882.07	246
1884.06	260
1886.06	260
1888.05	248
1890.05	252
1892.04	266
1894.04	242
1896.03	274
1898.02	248
1900.01	252
1902	260
1903.99	250
1905.98	250
1907.97	264
1909.96	256
1911.95	250
1913.94	236
1915.93	256
1917.91	282
1919.9	254
1921.88	254
1923.87	238
1925.85	278
1927.83	260
1929.82	250
1931.8	262
1933.78	252
1935.76	262
1937.74	250
1939.72	246
1941.7	252
1943.68	252
1945.65	258
1947.63	256
1949.61	248
1951.58	258
1953.56	240
1955.53	258
1957.51	252
1959.48	258
1961.45	244
1963.43	230
1965.4	256
1967.37	274
1969.34	258
1971.31	238
1973.28	244
1975.25	264
1977.22	248
1979.18	266
1981.15	264
1983.12	226
1985.08	232
1987.05	254
1989.01	256
1990.97	268
1992.94	252
1994.9	222
1996.86	246
1998.82	256
2000.78	240
2002.74	258
2004.7	256
2006.66	242
2008.62	248
2010.58	270
2012.54	254
2014.49	246
2016.45	260
2018.4	248
2020.36	260
2022.31	244
2024.27	246
2026.22	252
2028.17	249
2030.12	250
2032.07	236
2034.03	262
2035.98	262
2037.93	246
2039.87	256
2041.82	226
2043.77	240
2045.72	240
2047.66	254
2049.61	244
2051.55	246
2053.5	262
2055.44	244
2057.39	270
2059.33	232
2061.27	242
2063.21	232
2065.15	224
2067.09	248
2069.03	246
2070.97	244
2072.91	248
2074.85	238
2076.79	254
2078.73	258
2080.66	256
2082.6	246
2084.53	252
2086.47	236
2088.4	218
2090.33	234
2092.27	242
2094.2	228
2096.13	244
2098.06	252
2099.99	242
2101.92	238
2103.85	240
2105.78	232
2107.71	248
2109.64	248
2111.56	252
2113.49	234
2115.41	240
2117.34	238
2119.26	232
2121.19	232
2123.11	242
2125.03	234
2126.96	254
2128.88	226
2130.8	236
2132.72	236
2134.64	242
2136.56	240
2138.48	234
2140.4	246
2142.31	216
2144.23	230
2146.15	216
2148.06	254
2149.98	248
2151.89	234
2153.81	244
2155.72	230
2157.63	260
2159.55	234
2161.46	234
2163.37	252
2165.28	224
2167.19	236
2169.1	228
2171.01	242
2172.91	252
2174.82	230
2176.73	240
2178.64	240
2180.54	240
2182.45	224
2184.35	218
2186.26	210
2188.16	232
2190.06	240
2191.96	224
2193.87	240
2195.77	248
2197.67	230
2199.57	216
2201.47	250
2203.37	220
2205.27	230
2207.16	228
2209.06	224
2210.96	232
2212.85	228
2214.75	232
2216.64	232
2218.54	232
2220.43	220
2222.33	228
2224.22	216.147
2226.11	211.032
2228	234.103
2229.89	204.97
2231.78	239.18
2233.67	223.079
2235.56	208.661
2237.45	229.204
2239.34	224.62
2241.23	221.719
2243.11	227.487
2245	214.11
2246.89	225.93
2248.77	219.276
2250.66	219.036
2252.54	221.163
2254.42	222.746
2256.31	225.949
2258.19	226.347
2260.07	233.414
2261.95	238.417
2263.83	225.56
2265.71	227.63
2267.59	222.334
2269.47	223.617
2271.35	216.256
2273.23	205.1
2275.1	214.035
2276.98	225.241
2278.86	216.641
2280.73	223.716
2282.61	221.064
2284.48	218.925
2286.36	217.295
2288.23	217.206
2290.1	221.54
2291.98	208.119
2293.85	221.826
2295.72	216.449
2297.59	204.046
2299.46	218.154
2301.33	221.141
2303.2	224.813
2305.06	226.093
2306.93	211.494
2308.8	208.363
2310.67	220.917
2312.53	222.15
2314.4	218.688
2316.26	201.817
2317.62	210
2319.5	208
2321.37	216
2323.24	208
2325.12	212
2326.99	208
2328.86	214
2330.73	214
2332.6	222
2334.47	208
2336.34	224
2338.2	196
2340.07	200
2341.94	210
2343.81	186
2345.67	200
2347.54	206
2349.4	212
2351.27	212
2353.13	200
2354.99	224
2356.86	216
2358.72	192
2360.58	196
2362.44	188
2364.3	192
2366.16	194
2368.02	192
2369.88	194
2371.74	188
2373.6	190
2375.45	180
2377.31	188
2379.17	222
2381.02	202
2382.88	208
2384.73	192
2386.58	180
2388.44	208
2390.29	206
2392.14	192
2393.99	198
2395.85	188
2397.7	190
2399.55	172
2401.4	176
2403.25	188
2405.09	188
2406.94	178
2408.79	178
2410.63	202
2412.48	202
2414.33	172
2416.17	182
2418.02	198
2419.86	186
2421.7	188
2423.55	188
2425.39	184
2427.23	196
2429.07	196
2430.91	204
2432.75	194
2434.59	182
2436.43	182
2438.27	204
2440.11	194
2441.95	176
2443.78	168
2445.62	180
2447.46	188
2449.29	176
2451.13	172
2452.96	172
2454.79	186
2456.63	186
2458.46	166
2460.29	168
2462.12	176
2463.95	182
2465.78	164
2467.61	160
2469.44	168
2471.27	174
2473.1	162
2474.93	154
2476.76	170
2478.58	180
2480.41	162
2482.23	168
2484.06	158
2485.88	168
2487.71	156
2489.53	156
2491.35	154
2493.18	142
2495	156
2496.82	158
2498.64	178
2500.46	156
2502.28	150
2504.1	164
2505.92	148
2507.74	148
2509.55	164
2511.37	152
2513.19	150
2515	160
2516.82	144
2518.63	156
2520.45	148
2522.26	162
2524.07	146
2525.89	154
2527.7	152
2529.51	152
2531.32	158
2533.13	152
2534.94	158
2536.75	152
2538.56	134
2540.37	134
2542.18	138
2543.98	134
2545.79	138
2547.6	134
2549.4	130
2551.21	138
2553.01	134
2554.82	144
2556.62	150
2558.42	134
2560.23	144
2562.03	150
2563.83	148
2565.63	144
2567.43	154
2569.23	126
2571.03	132
2572.83	134
2574.63	134
2576.43	132
2578.22	130
2580.02	132
2581.82	140
2583.61	146
2585.41	134
2587.2	140
2589	120
2590.79	124
2592.58	130
2594.38	142
2596.17	122
2597.96	122
2599.75	126
2601.54	138
2603.33	120
2605.12	122
2606.91	126
2608.7	126
2610.49	120
2612.27	116
2614.06	118
2615.85	136
2617.63	128
2619.42	124
2621.2	142
2622.99	122
2624.77	122
2626.55	118
2628.34	124
2630.12	120
2631.9	116
2633.68	136
2635.46	110
2637.24	122
2639.02	128
2640.8	114
2642.58	104
2644.36	112
2646.14	114
2647.91	112
2649.69	104
2651.46	112
2653.24	102
2655.01	112
2656.79	112
2658.56	118
2660.34	132
2662.11	118
2663.88	114
2665.65	102
2667.42	108
2669.2	122
2670.96	112
2672.73	108
2674.5	114
2676.27	106
2678.04	102
2679.81	110
2681.58	118
2683.34	98
2685.11	102
2686.87	120
2688.64	114
2690.4	110
2692.17	118
2693.93	104
2695.69	96
2697.46	94
2699.22	98
2700.98	116
2702.74	92
2704.5	108
2706.26	104
2708.02	106
2709.78	92
2711.54	96
2713.3	102
2715.05	100
2716.81	94
2718.57	84
2720.32	90
2722.08	98
2723.83	104
2725.59	82
2727.34	86
2729.09	104
2730.85	98
2732.6	94
2734.35	90
2736.1	90
2737.85	84
2739.6	92
2741.35	88
2743.1	92
2744.85	96
2746.6	78
2748.35	90
2750.09	90
2751.84	82
2753.59	88
2755.33	98
2757.08	92
2758.82	86
2760.57	78
2762.31	80
2764.05	92
2765.79	78
2767.54	94
2769.28	90
2771.02	88
2772.76	74
2774.5	78
2776.24	92
2777.98	86
2779.72	86
2781.46	86
2783.19	86
2784.93	82
2786.67	76
2788.4	86
2790.14	78
2791.87	86
2793.61	80
2795.34	70
2797.07	84
2798.81	84
2800.54	90
2802.27	78
2804	70
2805.74	78
2807.47	78
2809.2	76
2810.93	74
2812.65	80
2814.38	88
2816.11	68
2817.84	78
2819.56	76
2821.29	66
2823.02	82
2824.74	84
2826.47	70
2828.19	72
2829.92	76
2831.64	74
2833.36	74
2835.09	82
2836.81	64
2838.53	82
2840.25	74
2841.97	66
2843.69	70
2845.41	66
2847.13	70
2848.85	66
2850.57	76
2852.28	72
2854	70
2855.72	64
2857.43	68
2859.15	68
2860.86	72
2862.58	68
2864.29	64
2866.01	64
2867.72	84
2869.43	68
2871.14	60
2872.86	68
2874.57	72
2876.28	56
2877.99	62
2879.7	72
2881.41	72
2883.11	70
2884.82	62
2886.53	64
2888.24	64
2889.94	70
2891.65	64
2893.36	66
2895.06	66
2896.77	62
2898.47	54
2900.17	58
2901.88	66
2903.58	62
2905.28	60
2906.98	64
2908.69	66
2910.39	56
2912.09	64
2913.79	48
2915.49	68
2917.19	62
2918.88	68
2920.58	66
2922.28	62
2923.98	64
2925.67	50
2927.37	62
2929.06	68
2930.76	62
2932.45	62
2934.15	58
2935.84	64
2937.53	60
2939.23	68
2940.92	58
2942.61	64
2944.3	62
2945.99	54
2947.68	64
2949.37	46
2951.06	54
2952.75	56
2954.44	66
2956.12	52
2957.81	64
2959.5	64
2961.18	58
2962.87	56
2964.56	60
2966.24	62
2967.92	60
2969.61	64
2971.29	60
2972.97	50
2974.66	64
2976.34	50
2978.02	60
2979.7	50
2981.38	64
2983.06	58
2984.74	54
2986.42	54
2988.1	60
2989.78	44
2991.45	52
2993.13	50
2994.81	50
2996.48	50
2998.16	48
2999.83	60