File: muestras/papalo/leaf_03.txt
#Acq. time (s)=	10
#Accumulations=	1
#Range (cm-¹)=	200...3000
#Windows=	3
#Autofocus=	Off
#AutoExposure=	Off
#Spike filter=	Off
#Delay time (s)=	0
#Binning=	1
#Readout mode=	Signal
#DeNoise=	Off
#ICS correction=	Off
#Dark correction=	Off
#Inst. Process=	Off
#Instrument=	LabRAM HR Evol
#Detector=	Syncerity OE
#Objective=	x100_VIS
#Grating=	600 (500nm)
#ND Filter=	1%
#Laser=	633nm_Edge
#Hole=	9.98375
#Range=	Visible
#Project=	Omar
#Sample=	03-07-23
#Site=	papal
#Title=	leaf
#Remark=
#Date=	03.07.2023 16:50
#Acquired=	03.07.2023 16:50:55
201.713	42
204.247	54
206.778	68
209.311	50
211.84	54
214.371	56
216.899	60
219.428	62
221.955	50
224.482	56
227.007	60
229.531	52
232.055	54
234.579	54
237.1	54
239.621	58
242.141	44
244.661	66
247.179	50
249.698	58
252.215	54
254.731	54
257.246	62
259.761	66
262.273	56
264.786	62
267.298	50
269.809	62
272.319	58
274.828	62
277.336	74
279.844	70
282.351	62
284.855	60
287.361	62
289.866	74
292.368	76
294.871	70
297.372	68
299.873	68
302.372	72
304.872	78
307.37	76
309.866	80
312.364	78
314.859	72
317.353	68
319.848	72
322.341	72
324.833	82
327.324	74
329.814	82
332.304	78
334.792	84
337.28	72
339.767	76
342.254	86
344.739	84
347.224	72
349.708	80
352.191	82
354.673	82
357.155	84
359.634	80
362.114	94
364.593	78
367.07	84
369.548	88
372.024	92
374.499	86
376.974	100
379.447	88
381.92	98
384.392	102
386.864	94
389.333	98
391.802	94
394.272	104
396.739	102
399.206	96
401.673	100
404.138	98
406.602	100
409.066	106
411.528	118
413.99	104
416.451	112
418.911	112
421.371	108
423.83	110
426.288	114
428.745	110
431.201	100
433.657	120
436.111	120
438.565	112
441.017	118
443.469	112
445.921	124
448.37	124
450.821	132
453.27	122
455.717	120
458.165	122
460.61	120
463.056	126
465.5	124
467.945	132
470.387	128
472.829	124
475.271	136
477.711	134
480.15	132
482.589	130
485.027	146
487.465	134
489.901	130
492.337	132
494.771	144
497.205	150
499.638	146
502.07	132
504.502	150
506.933	134
509.363	140
511.792	138
514.219	142
516.647	166
519.073	152
521.5	150
523.924	154
526.348	162
528.772	150
531.194	158
533.616	166
536.036	162
538.457	160
540.875	158
543.294	174
545.712	158
548.128	166
550.545	174
552.959	160
555.373	152
557.788	174
560.2	184
562.612	166
565.023	188
567.433	178
569.843	168
572.251	182
574.659	182
577.066	188
579.472	168
581.878	180
584.283	178
586.687	202
589.09	178
591.493	172
593.893	186
596.294	198
598.694	186
601.093	198
603.491	198
605.889	214
608.285	228
610.682	218
613.076	206
615.471	206
617.864	220
620.256	226
622.648	210
625.039	236
627.429	232
629.819	234
632.208	244
634.595	224
636.982	234
639.369	248
641.755	240
644.139	252
646.523	236
648.906	244
651.288	238
653.67	260
656.051	254
658.429	260
660.808	272
663.187	258
665.565	250
667.942	266
670.317	270
672.692	282
675.067	298
677.44	274
679.813	294
682.184	290
684.556	290
686.926	284
689.296	288
691.664	314
694.033	298
696.4	308
698.766	316
701.133	324
703.497	318
705.861	330
708.224	334
710.586	320
712.949	320
715.31	338
717.67	332
720.029	338
722.388	352
724.746	338
727.103	350
729.458	366
731.814	348
734.168	370
736.523	386
738.876	372
741.227	382
743.579	394
745.931	394
748.28	380
750.629	378
752.977	404
755.325	414
757.672	400
760.018	404
762.363	398
764.708	428
767.052	410
769.394	404
771.737	408
774.078	440
776.419	430
778.758	454
781.097	426
783.435	458
785.773	458
788.11	480
790.446	476
792.781	482
795.115	494
797.449	492
799.782	514
802.115	498
804.446	498
806.777	516
809.106	508
811.435	522
813.764	522
816.091	564
818.418	542
820.743	506
823.069	558
825.393	554
827.717	576
830.039	596
832.362	582
834.683	602
837.003	600
839.324	630
841.643	606
843.961	606
846.278	626
848.594	634
850.91	668
853.227	634
855.541	664
857.855	624
860.168	686
862.48	676
864.79	720
867.101	678
869.411	692
871.721	722
874.029	676
876.336	702
878.643	744
880.95	744
883.254	706
885.559	748
887.862	782
890.166	746
892.467	788
894.77	776
897.07	786
899.371	778
901.669	816
903.968	818
906.266	812
908.563	846
910.859	830
913.154	822
915.449	850
917.742	828
920.036	860
922.329	880
924.621	918
926.911	898
929.201	884
931.49	904
933.779	984
936.068	986
938.355	942
940.64	938
942.926	966
945.212	990
947.495	980
949.779	1010
952.062	1038
954.344	992
956.625	1044
958.905	1038
961.184	1036
963.464	1092
965.742	1088
968.02	1078
970.296	1118
972.572	1102
974.847	1100
977.121	1150
979.396	1176
981.669	1162
983.941	1154
986.212	1206
988.483	1204
990.753	1142
993.022	1238
995.29	1230
997.558	1238
999.825	1228
1002.09	1230
1004.36	1234
1006.62	1294
1008.89	1322
1011.15	1250
1013.41	1276
1015.67	1348
1017.93	1360
1020.19	1338
1022.45	1378
1024.71	1352
1026.97	1378
1029.23	1390
1031.49	1412
1033.74	1454
1036	1470
1038.25	1502
1040.5	1426
1042.76	1474
1045.01	1554
1047.26	1572
1049.51	1502
1051.76	1570
1054.01	1542
1056.26	1576
1058.51	1614
1060.75	1600
1063	1652
1065.25	1634
1067.49	1612
1069.73	1644
1071.98	1682
1074.22	1664
1076.46	1714
1078.7	1680
1080.94	1678
1083.18	1702
1085.42	1712
1087.66	1720
1089.9	1794
1092.14	1770
1094.37	1776
1096.61	1772
1098.84	1792
1101.08	1816
1103.31	1794
1105.54	1834
1107.77	1888
1110	1812
1112.23	1848
1114.46	1874
1116.69	1862
1118.92	1900
1121.15	1838
1123.37	1886
1125.6	1962
1127.83	1968
1130.05	1954
1132.27	1964
1134.5	1978
1136.72	2014
1138.94	1988
1141.16	1998
1143.38	1990
1145.6	2026
1147.82	2022
1150.04	1982
1152.26	2064
1154.47	2120
1156.69	2056
1158.9	2080
1161.12	2046
1163.33	2046
1165.54	2076
1167.76	2130
1169.97	2104
1172.18	2132
1174.39	2126
1176.6	2098
1178.81	2114
1181.02	2048
1183.22	2212
1185.43	2144
1187.63	2104
1189.84	2120
1192.04	2092
1194.25	2064
1196.45	2134
1198.65	2144
1200.85	2072
1203.05	2104
1205.25	2070
1207.45	2102
1209.65	2046
1211.85	2056
1214.05	2074
1216.24	2030
1218.44	2108
1220.64	2006
1222.83	2036
1225.02	2060
1227.22	2032
1229.41	2054
1231.6	1950
1233.79	1984
1235.98	1962
1238.17	2002
1240.36	2012
1242.55	1942
1244.73	1958
1246.92	1970
1249.11	1942
1251.29	1896
1253.48	1962
1255.66	1884
1257.84	1904
1260.03	1920
1262.21	1892
1264.39	1896
1266.57	1900
1268.75	1872
1270.93	1870
1273.11	1862
1275.28	1876
1277.46	1844
1279.64	1850
1281.81	1820
1283.98	1817.33
1286.16	1823.57
1288.33	1799.64
1290.5	1852.9
1292.68	1754.89
1294.85	1754.33
1297.02	1731.01
1299.19	1708.06
1301.36	1712.86
1303.53	1644.23
1305.69	1708.44
1307.86	1642.56
1310.03	1639.1
1312.19	1631.68
1314.36	1643.55
1316.52	1631.47
1318.68	1612.02
1320.85	1587.3
1323.01	1538.07
1325.17	1552.56
1327.33	1568.67
1329.49	1561.13
1331.65	1514.77
1333.81	1507.67
1335.97	1480.01
1338.12	1499.58
1340.28	1480.1
1342.44	1445.69
1344.59	1417.81
1346.75	1425.39
1348.9	1447.17
1351.05	1401.06
1353.2	1395.63
1355.36	1382.47
1357.51	1360.03
1359.66	1337.48
1361.81	1345.81
1363.96	1376.35
1366.1	1342.22
1368.25	1311.47
1370.4	1306.35
1372.54	1245.69
1374.69	1311.12
1376.83	1275.1
1378.98	1227.67
1381.12	1267.7
1383.26	1214.14
1385.41	1190.47
1387.55	1261.02
1389.69	1203.98
1391.83	1204.35
1393.02	1226
1395.17	1204
1397.32	1204
1399.47	1178
1401.62	1190
1403.77	1178
1405.91	1182
1408.06	1154
1410.2	1152
1412.35	1128
1414.49	1130
1416.63	1098
1418.78	1124
1420.92	1098
1423.06	1124
1425.2	1120
1427.34	1078
1429.48	1062
1431.61	1036
1433.75	1064
1435.89	1078
1438.02	1044
1440.16	1062
1442.3	1064
1444.43	1022
1446.56	1026
1448.7	1042
1450.83	1032
1452.96	1050
1455.09	1030
1457.22	998
1459.35	1018
1461.48	1040
1463.61	1014
1465.73	996
1467.86	982
1469.98	1022
1472.11	988
1474.24	992
1476.36	994
1478.48	1010
1480.6	964
1482.73	950
1484.85	950
1486.97	950
1489.09	962
1491.21	932
1493.33	958
1495.44	900
1497.56	930
1499.68	926
1501.79	944
1503.91	900
1506.02	958
1508.14	916
1510.25	918
1512.36	918
1514.48	942
1516.59	906
1518.7	872
1520.81	900
1522.92	832
1525.02	876
1527.13	836
1529.24	890
1531.35	842
1533.45	840
1535.56	850
1537.66	876
1539.77	830
1541.87	826
1543.97	820
1546.08	842
1548.18	824
1550.28	828
1552.38	850
1554.48	848
1556.57	784
1558.67	816
1560.77	812
1562.87	792
1564.96	788
1567.06	778
1569.15	804
1571.25	790
1573.34	798
1575.43	778
1577.53	800
1579.62	766
1581.71	788
1583.8	780
1585.89	774
1587.98	778
1590.06	754
1592.15	760
1594.24	764
1596.33	808
1598.41	756
1600.5	750
1602.58	764
1604.66	786
1606.75	754
1608.83	760
1610.91	738
1612.99	760
1615.07	738
1617.15	794
1619.23	728
1621.31	774
1623.39	770
1625.46	794
1627.54	730
1629.62	748
1631.69	752
1633.77	730
1635.84	760
1637.91	722
1639.99	732
1642.06	766
1644.13	718
1646.2	704
1648.27	740
1650.34	708
1652.41	734
1654.47	714
1656.54	696
1658.61	718
1660.67	696
1662.74	714
1664.81	706
1666.87	728
1668.93	714
1671	714
1673.06	700
1675.12	698
1677.18	678
1679.24	688
1681.3	712
1683.36	692
1685.42	664
1687.47	696
1689.53	680
1691.59	680
1693.64	706
1695.7	660
1697.75	700
1699.81	700
1701.86	704
1703.91	704
1705.97	686
1708.02	692
1710.07	674
1712.12	692
1714.17	652
1716.22	682
1718.26	660
1720.31	684
1722.36	654
1724.4	650
1726.45	642
1728.49	646
1730.54	664
1732.58	654
1734.63	698
1736.67	666
1738.71	692
1740.75	638
1742.79	676
1744.83	678
1746.87	634
1748.91	652
1750.95	680
1752.98	648
1755.02	672
1757.06	630
1759.09	690
1761.13	674
1763.16	660
1765.19	668
1767.23	670
1769.26	664
1771.29	622
1773.32	672
1775.35	668
1777.38	636
1779.41	654
1781.44	650
1783.47	662
1785.49	662
1787.52	660
1789.55	654
1791.57	666
1793.6	660
1795.62	630
1797.64	670
1799.67	654
1801.69	666
1803.71	664
1805.73	626
1807.75	640
1809.77	692
1811.79	630
1813.81	646
1815.83	644
1817.84	636
1819.86	656
1821.88	660
1823.89	652
1825.91	676
1827.92	640
1829.93	624
1831.95	654
1833.96	660
1835.97	662
1837.98	662
1839.99	648
1842	628
1844.01	624
1846.02	654
1848.03	662
1850.03	628
1852.04	658
1854.05	650
1856.05	636
1858.06	610
1860.06	648
1862.06	620
1864.07	656
1866.07	610
1868.07	634
1870.07	648
1872.07	620
1874.07	636
1876.07	636
1878.07	598
1880.07	666
1882.07	638
1884.06	632
1886.06	612
1888.05	618
1890.05	602
1892.04	642
1894.04	626
1896.03	622
1898.02	624
1900.01	646
1902	634
1903.99	608
1905.98	644
1907.97	624
1909.96	634
1911.95	604
1913.94	634
1915.93	632
1917.91	634
1919.9	632
1921.88	650
1923.87	650
1925.85	620
1927.83	628
1929.82	636
1931.8	652
1933.78	624
1935.76	630
1937.74	632
1939.72	632
1941.7	648
1943.68	622
1945.65	612
1947.63	618
1949.61	606
1951.58	644
1953.56	626
1955.53	596
1957.51	624
1959.48	610
1961.45	636
1963.43	610
1965.4	638
1967.37	652
1969.34	614
1971.31	608
1973.28	618
1975.25	598
1977.22	640
1979.18	648
1981.15	630
1983.12	620
1985.08	628
1987.05	596
1989.01	602
1990.97	622
1992.94	600
1994.9	612
1996.86	602
1998.82	618
2000.78	582
2002.74	590
2004.7	574
2006.66	580
2008.62	592
2010.58	604
2012.54	602
2014.49	630
2016.45	598
2018.4	594
2020.36	612
2022.31	600
2024.27	616
2026.22	610
2028.17	618
2030.12	602
2032.07	592
2034.03	608
2035.98	624
2037.93	600
2039.87	592
2041.82	596
2043.77	602
2045.72	588
2047.66	596
2049.61	592
2051.55	578
2053.5	594
2055.44	594
2057.39	604
2059.33	622
2061.27	602
2063.21	594
2065.15	578
2067.09	600
2069.03	598
2070.97	582
2072.91	610
2074.85	568
2076.79	602
2078.73	582
2080.66	598
2082.6	598
2084.53	606
2086.47	598
2088.4	570
2090.33	594
2092.27	584
2094.2	604
2096.13	588
2098.06	598
2099.99	584
2101.92	604
2103.85	594
2105.78	580
2107.71	584
2109.64	590
2111.56	594
2113.49	598
2115.41	578
2117.34	592
2119.26	594
2121.19	610
2123.11	556
2125.03	582
2126.96	588
2128.88	572
2130.8	592
2132.72	584
2134.64	572
2136.56	574
2138.48	566
2140.4	598
2142.31	584
2144.23	588
2146.15	570
2148.06	604
2149.98	578
2151.89	556
2153.81	588
2155.72	594
2157.63	596
2159.55	566
2161.46	588
2163.37	580
2165.28	582
2167.19	568
2169.1	554
2171.01	580
2172.91	554
2174.82	552
2176.73	558
2178.64	594
2180.54	590
2182.45	568
2184.35	558
2186.26	556
2188.16	566
2190.06	578
2191.96	518
2193.87	548
2195.77	570
2197.67	570
2199.57	560
2201.47	582
2203.37	548
2205.27	544
2207.16	546
2209.06	550
2210.96	554
2212.85	560
2214.75	544
2216.64	550
2218.54	546
2220.43	550
2222.33	562
2224.22	563.343
2226.11	540.101
2228	547.146
2229.89	551.603
2231.78	548.085
2233.67	555.174
2235.56	544.768
2237.45	560.722
2239.34	532.389
2241.23	537.882
2243.11	542.606
2245	541.845
2246.89	541.62
2248.77	529.722
2250.66	524.872
2252.54	519.803
2254.42	537.426
2256.31	536.708
2258.19	526.435
2260.07	523.989
2261.95	528.427
2263.83	536.85
2265.71	499.111
2267.59	523.33
2269.47	541.817
2271.35	541.106
2273.23	526.92
2275.1	518.608
2276.98	534.722
2278.86	520.929
2280.73	526.113
2282.61	511.007
2284.48	515.784
2286.36	518.3
2288.23	533.493
2290.1	505.766
2291.98	529.698
2293.85	522.03
2295.72	498.1
2297.59	515.958
2299.46	496.407
2301.33	509.169
2303.2	501.202
2305.06	502
2306.93	495.088
2308.8	489.479
2310.67	501.292
2312.53	488.81
2314.4	484.194
2316.26	492.471
2317.62	494
2319.5	468
2321.37	492
2323.24	508
2325.12	508
2326.99	478
2328.86	480
2330.73	494
2332.6	500
2334.47	466
2336.34	504
2338.2	508
2340.07	482
2341.94	426
2343.81	480
2345.67	468
2347.54	500
2349.4	478
2351.27	474
2353.13	468
2354.99	500
2356.86	480
2358.72	490
2360.58	460
2362.44	460
2364.3	492
2366.16	448
2368.02	458
2369.88	458
2371.74	472
2373.6	452
2375.45	484
2377.31	468
2379.17	452
2381.02	468
2382.88	470
2384.73	476
2386.58	446
2388.44	476
2390.29	430
2392.14	446
2393.99	442
2395.85	408
2397.7	450
2399.55	454
2401.4	438
2403.25	444
2405.09	422
2406.94	454
2408.79	414
2410.63	424
2412.48	446
2414.33	414
2416.17	464
2418.02	456
2419.86	440
2421.7	418
2423.55	418
2425.39	428
2427.23	404
2429.07	402
2430.91	410
2432.75	424
2434.59	418
2436.43	424
2438.27	408
2440.11	414
2441.95	418
2443.78	406
2445.62	404
2447.46	440
2449.29	392
2451.13	386
2452.96	386
2454.79	410
2456.63	402
2458.46	386
2460.29	386
2462.12	378
2463.95	392
2465.78	376
2467.61	388
2469.44	392
2471.27	390
2473.1	390
2474.93	386
2476.76	382
2478.58	360
2480.41	372
2482.23	362
2484.06	376
2485.88	370
2487.71	366
2489.53	364
2491.35	378
2493.18	374
2495	360
2496.82	342
2498.64	366
2500.46	352
2502.28	348
2504.1	362
2505.92	352
2507.74	360
2509.55	358
2511.37	334
2513.19	346
2515	344
2516.82	366
2518.63	356
2520.45	342
2522.26	348
2524.07	354
2525.89	332
2527.7	338
2529.51	334
2531.32	336
2533.13	350
2534.94	328
2536.75	322
2538.56	348
2540.37	322
2542.18	316
2543.98	302
2545.79	306
2547.6	322
2549.4	324
2551.21	330
2553.01	308
2554.82	328
2556.62	326
2558.42	298
2560.23	304
2562.03	310
2563.83	310
2565.63	284
2567.43	310
2569.23	322
2571.03	300
2572.83	286
2574.63	320
2576.43	302
2578.22	298
2580.02	304
2581.82	300
2583.61	290
2585.41	292
2587.2	310
2589	288
2590.79	284
2592.58	302
2594.38	282
2596.17	284
2597.96	302
2599.75	274
2601.54	278
2603.33	282
2605.12	288
2606.91	294
2608.7	256
2610.49	280
2612.27	258
2614.06	270
2615.85	280
2617.63	292
2619.42	290
2621.2	262
2622.99	246
2624.77	268
2626.55	266
2628.34	264
2630.12	278
2631.9	266
2633.68	246
2635.46	254
2637.24	274
2639.02	246
2640.8	248
2642.58	270
2644.36	256
2646.14	254
2647.91	268
2649.69	250
2651.46	252
2653.24	244
2655.01	236
2656.79	236
2658.56	244
2660.34	234
2662.11	264
2663.88	240
2665.65	242
2667.42	236
2669.2	238
2670.96	244
2672.73	248
2674.5	248
2676.27	244
2678.04	232
2679.81	240
2681.58	260
2683.34	222
2685.11	242
2686.87	212
2688.64	228
2690.4	214
2692.17	234
2693.93	240
2695.69	214
2697.46	224
2699.22	226
2700.98	218
2702.74	206
2704.5	224
2706.26	210
2708.02	238
2709.78	232
2711.54	228
2713.3	210
2715.05	208
2716.81	204
2718.57	220
2720.32	212
2722.08	194
2723.83	206
2725.59	194
2727.34	218
2729.09	202
2730.85	192
2732.6	204
2734.35	206
2736.1	204
2737.85	214
2739.6	180
2741.35	188
2743.1	192
2744.85	204
2746.6	196
2748.35	206
2750.09	184
2751.84	206
2753.59	176
2755.33	192
2757.08	198
2758.82	188
2760.57	190
2762.31	196
2764.05	182
2765.79	194
2767.54	176
2769.28	192
2771.02	194
2772.76	178
2774.5	172
2776.24	182
2777.98	176
2779.72	166
2781.46	184
2783.19	166
2784.93	174
2786.67	188
2788.4	182
2790.14	176
2791.87	186
2793.61	180
2795.34	182
2797.07	160
2798.81	174
2800.54	170
2802.27	160
2804	166
2805.74	162
2807.47	152
2809.2	148
2810.93	154
2812.65	164
2814.38	178
2816.11	168
2817.84	160
2819.56	152
2821.29	164
2823.02	152
2824.74	168
2826.47	132
2828.19	152
2829.92	146
2831.64	164
2833.36	130
2835.09	142
2836.81	132
2838.53	148
2840.25	138
2841.97	156
2843.69	132
2845.41	138
2847.13	146
2848.85	144
2850.57	146
2852.28	124
2854	152
2855.72	136
2857.43	146
2859.15	134
2860.86	126
2862.58	128
2864.29	136
2866.01	134
2867.72	140
2869.43	136
2871.14	142
2872.86	124
2874.57	128
2876.28	132
2877.99	138
2879.7	136
2881.41	118
2883.11	134
2884.82	120
2886.53	140
2888.24	124
2889.94	110
2891.65	124
2893.36	132
2895.06	126
2896.77	126
2898.47	120
2900.17	112
2901.88	136
2903.58	114
2905.28	116
2906.98	118
2908.69	122
2910.39	120
2912.09	118
2913.79	114
2915.49	124
2917.19	116
2918.88	106
2920.58	106
2922.28	116
2923.98	104
2925.67	122
2927.37	122
2929.06	122
2930.76	110
2932.45	114
2934.15	122
2935.84	106
2937.53	104
2939.23	114
2940.92	116
2942.61	100
2944.3	90
2945.99	102
2947.68	118
2949.37	118
2951.06	122
2952.75	122
2954.44	94
2956.12	102
2957.81	88
2959.5	104
2961.18	112
2962.87	114
2964.56	100
2966.24	106
2967.92	108
2969.61	110
2971.29	104
2972.97	110
2974.66	104
2976.34	112
2978.02	100
2979.7	98
2981.38	102
2983.06	104
2984.74	96
2986.42	108
2988.1	98
2989.78	102
2991.45	98
2993.13	98
2994.81	106
2996.48	96
2998.16	90
2999.83	108