File: muestras/papalo/leaf_12.txt
#Acq. time (s)=	10
#Accumulations=	1
#Range (cm-¹)=	200...3000
#Windows=	3
#Autofocus=	Off
#AutoExposure=	Off
#Spike filter=	Off
#Delay time (s)=	0
#Binning=	1
#Readout mode=	Signal
#DeNoise=	Off
#ICS correction=	Off
#Dark correction=	Off
#Inst. Process=	Off
#Instrument=	LabRAM HR Evol
#Detector=	Syncerity OE
#Objective=	x100_VIS
#Grating=	600 (500nm)
#ND Filter=	0.01%
#Laser=	633nm_Edge
#Hole=	100.021
#Range=	Visible
#Project=	Omar
#Sample=	03-07-23
#Site=	papal
#Title=	leaf
#Remark=
#Date=	03.07.2023 17:03
#Acquired=	03.07.2023 17:03:37
201.713	124
204.247	122
206.778	142
209.311	130
211.84	122
214.371	124
216.899	116
219.428	132
221.955	130
224.482	132
227.007	120
229.531	136
232.055	146
234.579	134
237.1	138
239.621	148
242.141	142
244.661	148
247.179	148
249.698	146
252.215	148
254.731	146
257.246	166
259.761	144
262.273	162
264.786	160
267.298	160
269.809	174
272.319	156
274.828	174
277.336	158
279.844	182
282.351	182
284.855	164
287.361	176
289.866	188
292.368	190
294.871	190
297.372	200
299.873	188
302.372	194
304.872	186
307.37	212
309.866	200
312.364	216
314.859	212
317.353	200
319.848	222
322.341	218
324.833	244
327.324	214
329.814	234
332.304	224
334.792	234
337.28	248
339.767	216
342.254	254
344.739	244
347.224	232
349.708	258
352.191	256
354.673	244
357.155	250
359.634	252
362.114	246
364.593	266
367.07	266
369.548	268
372.024	254
374.499	274
376.974	278
379.447	286
381.92	304
384.392	286
386.864	266
389.333	286
391.802	294
394.272	304
396.739	316
399.206	316
401.673	298
404.138	298
406.602	318
409.066	320
411.528	338
413.99	346
416.451	328
418.911	348
421.371	360
423.83	360
426.288	344
428.745	364
431.201	386
433.657	378
436.111	364
438.565	348
441.017	382
443.469	384
445.921	376
448.37	378
450.821	410
453.27	380
455.717	402
458.165	408
460.61	416
463.056	410
465.5	418
467.945	396
470.387	440
472.829	400
475.271	464
477.711	448
480.15	464
482.589	446
485.027	454
487.465	462
489.901	468
492.337	492
494.771	490
497.205	478
499.638	484
502.07	494
504.502	506
506.933	496
509.363	508
511.792	516
514.219	512
516.647	526
519.073	544
521.5	568
523.924	544
526.348	534
528.772	546
531.194	532
533.616	526
536.036	564
538.457	582
540.875	566
543.294	560
545.712	560
548.128	584
550.545	586
552.959	596
555.373	614
557.788	618
560.2	626
562.612	626
565.023	612
567.433	626
569.843	622
572.251	674
574.659	684
577.066	666
579.472	688
581.878	650
584.283	676
586.687	690
589.09	720
591.493	710
593.893	734
596.294	734
598.694	740
601.093	738
603.491	756
605.889	776
608.285	764
610.682	796
613.076	818
615.471	782
617.864	792
620.256	810
622.648	836
625.039	820
627.429	848
629.819	846
632.208	886
634.595	868
636.982	868
639.369	910
641.755	946
644.139	938
646.523	916
648.906	956
651.288	962
653.67	954
656.051	990
658.429	996
660.808	990
663.187	1012
665.565	998
667.942	1040
670.317	1062
672.692	1060
675.067	1036
677.44	1102
679.813	1098
682.184	1112
684.556	1126
686.926	1122
689.296	1172
691.664	1176
694.033	1136
696.4	1200
698.766	1158
701.133	1210
703.497	1236
705.861	1230
708.224	1210
710.586	1300
712.949	1298
715.31	1280
717.67	1288
720.029	1324
722.388	1342
724.746	1354
727.103	1422
729.458	1436
731.814	1410
734.168	1462
736.523	1428
738.876	1472
741.227	1496
743.579	1510
745.931	1496
748.28	1590
750.629	1606
752.977	1564
755.325	1568
757.672	1592
760.018	1648
762.363	1668
764.708	1666
767.052	1714
769.394	1704
771.737	1764
774.078	1776
776.419	1794
778.758	1748
781.097	1824
783.435	1884
785.773	1852
788.11	1874
790.446	1912
792.781	1946
795.115	1954
797.449	2040
799.782	2004
802.115	2036
804.446	2068
806.777	2078
809.106	2100
811.435	2170
813.764	2156
816.091	2202
818.418	2282
820.743	2292
823.069	2314
825.393	2264
827.717	2420
830.039	2346
832.362	2424
834.683	2400
837.003	2480
839.324	2490
841.643	2572
843.961	2588
846.278	2606
848.594	2696
850.91	2676
853.227	2732
855.541	2778
857.855	2718
860.168	2766
862.48	2792
864.79	2878
867.101	2932
869.411	2958
871.721	2970
874.029	3046
876.336	3048
878.643	3050
880.95	3098
883.254	3128
885.559	3170
887.862	3206
890.166	3252
892.467	3252
894.77	3326
897.07	3276
899.371	3390
901.669	3414
903.968	3372
906.266	3550
908.563	3428
910.859	3530
913.154	3600
915.449	3622
917.742	3634
920.036	3656
922.329	3748
924.621	3850
926.911	3802
929.201	3808
931.49	3928
933.779	4032
936.068	4020
938.355	3996
940.64	4150
942.926	4110
945.212	4306
947.495	4238
949.779	4296
952.062	4274
954.344	4364
956.625	4432
958.905	4488
961.184	4504
963.464	4590
965.742	4752
968.02	4578
970.296	4868
972.572	4670
974.847	4810
977.121	4910
979.396	4926
981.669	4910
983.941	5012
986.212	5064
988.483	5110
990.753	5174
993.022	5262
995.29	5292
997.558	5332
999.825	5292
1002.09	5526
1004.36	5514
1006.62	5474
1008.89	5600
1011.15	5572
1013.41	5722
1015.67	5766
1017.93	5812
1020.19	5806
1022.45	5922
1024.71	6084
1026.97	6026
1029.23	6092
1031.49	6216
1033.74	6358
1036	6314
1038.25	6276
1040.5	6458
1042.76	6466
1045.01	6586
1047.26	6656
1049.51	6680
1051.76	6764
1054.01	6864
1056.26	6966
1058.51	6994
1060.75	7122
1063	7206
1065.25	7220
1067.49	7214
1069.73	7354
1071.98	7286
1074.22	7456
1076.46	7358
1078.7	7498
1080.94	7540
1083.18	7526
1085.42	7580
1087.66	7664
1089.9	7652
1092.14	7740
1094.37	7836
1096.61	7858
1098.84	7906
1101.08	7908
1103.31	8034
1105.54	8054
1107.77	8016
1110	8072
1112.23	8192
1114.46	8200
1116.69	8250
1118.92	8282
1121.15	8408
1123.37	8472
1125.6	8480
1127.83	8518
1130.05	8508
1132.27	8712
1134.5	8636
1136.72	8700
1138.94	8766
1141.16	8808
1143.38	8862
1145.6	8934
1147.82	8916
1150.04	8960
1152.26	9090
1154.47	9130
1156.69	9160
1158.9	9138
1161.12	9198
1163.33	9264
1165.54	9270
1167.76	9330
1169.97	9282
1172.18	9426
1174.39	9338
1176.6	9336
1178.81	9188
1181.02	9414
1183.22	9358
1185.43	9338
1187.63	9476
1189.84	9324
1192.04	9312
1194.25	9314
1196.45	9380
1198.65	9376
1200.85	9208
1203.05	9306
1205.25	9304
1207.45	9176
1209.65	9110
1211.85	9192
1214.05	9044
1216.24	9128
1218.44	9130
1220.64	9170
1222.83	8992
1225.02	8986
1227.22	9056
1229.41	9022
1231.6	8916
1233.79	8822
1235.98	8826
1238.17	8788
1240.36	8692
1242.55	8752
1244.73	8700
1246.92	8674
1249.11	8670
1251.29	8494
1253.48	8506
1255.66	8498
1257.84	8526
1260.03	8408
1262.21	8378
1264.39	8434
1266.57	8296
1268.75	8246
1270.93	8254
1273.11	8152
1275.28	8158
1277.46	8190
1279.64	8064
1281.81	7992
1283.98	7947.15
1286.16	7916.8
1288.33	7883.34
1290.5	7712.42
1292.68	7733.34
1294.85	7593.9
1297.02	7501.46
1299.19	7442.83
1301.36	7373.46
1303.53	7344.43
1305.69	7366.37
1307.86	7135.64
1310.03	7045.42
1312.19	7011.53
1314.36	6954.85
1316.52	6964.48
1318.68	6832.26
1320.85	6834.03
1323.01	6745.33
1325.17	6609.01
1327.33	6620.87
1329.49	6516.39
1331.65	6480.32
1333.81	6341.1
1335.97	6283.34
1338.12	6281.43
1340.28	6191.23
1342.44	6132.13
1344.59	6046.09
1346.75	5952.62
1348.9	5918.2
1351.05	5903.64
1353.2	5833.14
1355.36	5738.09
1357.51	5697.96
1359.66	5681.84
1361.81	5545.57
1363.96	5551.16
1366.1	5466.44
1368.25	5414.52
1370.4	5418.63
1372.54	5305.13
1374.69	5260.74
1376.83	5235.26
1378.98	5169.27
1381.12	5131.67
1383.26	5036.95
1385.41	5100.06
1387.55	4985.32
1389.69	4964.49
1391.83	4921.88
1393.02	4964
1395.17	4820
1397.32	4884
1399.47	4720
1401.62	4730
1403.77	4716
1405.91	4660
1408.06	4602
1410.2	4626
1412.35	4564
1414.49	4472
1416.63	4480
1418.78	4452
1420.92	4454
1423.06	4420
1425.2	4338
1427.34	4280
1429.48	4316
1431.61	4222
1433.75	4272
1435.89	4334
1438.02	4160
1440.16	4178
1442.3	4102
1444.43	4104
1446.56	4012
1448.7	4098
1450.83	4074
1452.96	4070
1455.09	4010
1457.22	3940
1459.35	3988
1461.48	3940
1463.61	3928
1465.73	3912
1467.86	3874
1469.98	3790
1472.11	3828
1474.24	3798
1476.36	3778
1478.48	3758
1480.6	3722
1482.73	3736
1484.85	3672
1486.97	3688
1489.09	3640
1491.21	3646
1493.33	3594
1495.44	3608
1497.56	3526
1499.68	3544
1501.79	3544
1503.91	3580
1506.02	3560
1508.14	3372
1510.25	3508
1512.36	3452
1514.48	3422
1516.59	3376
1518.7	3382
1520.81	3316
1522.92	3304
1525.02	3310
1527.13	3302
1529.24	3278
1531.35	3252
1533.45	3260
1535.56	3240
1537.66	3178
1539.77	3176
1541.87	3188
1543.97	3174
1546.08	3126
1548.18	3172
1550.28	3106
1552.38	3094
1554.48	3054
1556.57	3040
1558.67	3106
1560.77	3018
1562.87	3038
1564.96	3022
1567.06	3018
1569.15	2950
1571.25	2924
1573.34	2978
1575.43	2918
1577.53	2938
1579.62	2916
1581.71	2842
1583.8	2858
1585.89	2878
1587.98	2924
1590.06	2844
1592.15	2864
1594.24	2838
1596.33	2818
1598.41	2792
1600.5	2790
1602.58	2850
1604.66	2888
1606.75	2774
1608.83	2786
1610.91	2824
1612.99	2774
1615.07	2808
1617.15	2830
1619.23	2786
1621.31	2778
1623.39	2744
1625.46	2752
1627.54	2754
1629.62	2692
1631.69	2668
1633.77	2700
1635.84	2654
1637.91	2698
1639.99	2634
1642.06	2684
1644.13	2710
1646.2	2668
1648.27	2654
1650.34	2646
1652.41	2636
1654.47	2640
1656.54	2618
1658.61	2632
1660.67	2570
1662.74	2656
1664.81	2560
1666.87	2570
1668.93	2578
1671	2540
1673.06	2592
1675.12	2538
1677.18	2560
1679.24	2502
1681.3	2506
1683.36	2514
1685.42	2502
1687.47	2438
1689.53	2502
1691.59	2420
1693.64	2450
1695.7	2470
1697.75	2416
1699.81	2502
1701.86	2442
1703.91	2422
1705.97	2420
1708.02	2486
1710.07	2406
1712.12	2462
1714.17	2412
1716.22	2374
1718.26	2426
1720.31	2406
1722.36	2426
1724.4	2370
1726.45	2322
1728.49	2402
1730.54	2408
1732.58	2428
1734.63	2412
1736.67	2356
1738.71	2352
1740.75	2350
1742.79	2326
1744.83	2328
1746.87	2376
1748.91	2348
1750.95	2340
1752.98	2388
1755.02	2346
1757.06	2330
1759.09	2262
1761.13	2370
1763.16	2354
1765.19	2346
1767.23	2300
1769.26	2310
1771.29	2386
1773.32	2346
1775.35	2394
1777.38	2360
1779.41	2362
1781.44	2324
1783.47	2316
1785.49	2306
1787.52	2344
1789.55	2300
1791.57	2358
1793.6	2384
1795.62	2360
1797.64	2282
1799.67	2326
1801.69	2282
1803.71	2302
1805.73	2294
1807.75	2326
1809.77	2284
1811.79	2358
1813.81	2286
1815.83	2340
1817.84	2324
1819.86	2300
1821.88	2272
1823.89	2248
1825.91	2272
1827.92	2278
1829.93	2322
1831.95	2284
1833.96	2292
1835.97	2312
1837.98	2326
1839.99	2256
1842	2264
1844.01	2240
1846.02	2360
1848.03	2266
1850.03	2276
1852.04	2254
1854.05	2234
1856.05	2228
1858.06	2204
1860.06	2210
1862.06	2276
1864.07	2256
1866.07	2308
1868.07	2242
1870.07	2268
1872.07	2258
1874.07	2226
1876.07	2292
1878.07	2218
1880.07	2210
1882.07	2252
1884.06	2214
1886.06	2226
1888.05	2266
1890.05	2258
1892.04	2228
1894.04	2218
1896.03	2260
1898.02	2238
1900.01	2292
1902	2232
1903.99	2270
1905.98	2262
1907.97	2232
1909.96	2230
1911.95	2300
1913.94	2248
1915.93	2306
1917.91	2222
1919.9	2216
1921.88	2214
1923.87	2250
1925.85	2232
1927.83	2240
1929.82	2238
1931.8	2234
1933.78	2200
1935.76	2210
1937.74	2238
1939.72	2284
1941.7	2236
1943.68	2238
1945.65	2216
1947.63	2244
1949.61	2188
1951.58	2146
1953.56	2192
1955.53	2174
1957.51	2204
1959.48	2180
1961.45	2194
1963.43	2176
1965.4	2232
1967.37	2260
1969.34	2180
1971.31	2170
1973.28	2162
1975.25	2174
1977.22	2186
1979.18	2212
1981.15	2166
1983.12	2170
1985.08	2130
1987.05	2222
1989.01	2158
1990.97	2158
1992.94	2134
1994.9	2172
1996.86	2140
1998.82	2200
2000.78	2116
2002.74	2198
2004.7	2176
2006.66	2180
2008.62	2212
2010.58	2218
2012.54	2154
2014.49	2254
2016.45	2266
2018.4	2108
2020.36	2150
2022.31	2078
2024.27	2172
2026.22	2168
2028.17	2165
2030.12	2104
2032.07	2158
2034.03	2098
2035.98	2150
2037.93	2128
2039.87	2060
2041.82	2148
2043.77	2136
2045.72	2120
2047.66	2138
2049.61	2138
2051.55	2154
2053.5	2138
2055.44	2170
2057.39	2114
2059.33	2164
2061.27	2110
2063.21	2164
2065.15	2162
2067.09	2076
2069.03	2094
2070.97	2126
2072.91	2130
2074.85	2132
2076.79	2082
2078.73	2164
2080.66	2124
2082.6	2146
2084.53	2136
2086.47	2116
2088.4	2090
2090.33	2132
2092.27	2146
2094.2	2136
2096.13	2116
2098.06	2112
2099.99	2114
2101.92	2132
2103.85	2118
2105.78	2102
2107.71	2084
2109.64	2170
2111.56	2062
2113.49	2086
2115.41	2080
2117.34	2100
2119.26	2094
2121.19	2114
2123.11	2104
2125.03	2134
2126.96	2102
2128.88	2088
2130.8	2092
2132.72	2146
2134.64	2106
2136.56	2100
2138.48	2122
2140.4	2090
2142.31	2064
2144.23	2084
2146.15	2060
2148.06	2044
2149.98	2090
2151.89	2090
2153.81	2076
2155.72	2080
2157.63	2120
2159.55	2130
2161.46	2050
2163.37	2058
2165.28	2142
2167.19	2012
2169.1	2010
2171.01	2072
2172.91	2054
2174.82	2136
2176.73	2082
2178.64	2056
2180.54	2056
2182.45	2096
2184.35	2056
2186.26	2038
2188.16	2046
2190.06	2028
2191.96	1992
2193.87	2028
2195.77	2068
2197.67	2012
2199.57	2006
2201.47	2002
2203.37	2012
2205.27	2030
2207.16	1972
2209.06	2012
2210.96	2008
2212.85	1998
2214.75	1962
2216.64	2008
2218.54	1984
2220.43	1906
2222.33	2008
2224.22	2012.05
2226.11	2032.36
2228	1933.7
2229.89	2041.22
2231.78	1989.63
2233.67	1983.42
2235.56	1927.22
2237.45	2005.34
2239.34	1948.13
2241.23	1995.75
2243.11	1935.53
2245	1991.7
2246.89	1949.35
2248.77	1946.25
2250.66	1985.82
2252.54	1939.82
2254.42	1900.42
2256.31	1939.4
2258.19	1895.35
2260.07	1940.08
2261.95	1921.08
2263.83	1919.49
2265.71	1935.44
2267.59	1885.49
2269.47	1884.76
2271.35	1911.6
2273.23	1938.2
2275.1	1882.38
2276.98	1889.89
2278.86	1899.31
2280.73	1895.28
2282.61	1851.66
2284.48	1875.5
2286.36	1874.18
2288.23	1833.59
2290.1	1877.81
2291.98	1863.52
2293.85	1837.91
2295.72	1845.12
2297.59	1799.19
2299.46	1816.16
2301.33	1836.4
2303.2	1836.19
2305.06	1832.2
2306.93	1802.49
2308.8	1835.76
2310.67	1814.98
2312.53	1815.92
2314.4	1773.81
2316.26	1764.99
2317.62	1782
2319.5	1790
2321.37	1752
2323.24	1780
2325.12	1750
2326.99	1780
2328.86	1786
2330.73	1762
2332.6	1756
2334.47	1734
2336.34	1748
2338.2	1794
2340.07	1802
2341.94	1734
2343.81	1728
2345.67	1738
2347.54	1756
2349.4	1732
2351.27	1712
2353.13	1712
2354.99	1680
2356.86	1744
2358.72	1724
2360.58	1682
2362.44	1750
2364.3	1720
2366.16	1672
2368.02	1660
2369.88	1676
2371.74	1662
2373.6	1664
2375.45	1636
2377.31	1688
2379.17	1674
2381.02	1678
2382.88	1672
2384.73	1686
2386.58	1610
2388.44	1606
2390.29	1598
2392.14	1628
2393.99	1648
2395.85	1584
2397.7	1574
2399.55	1582
2401.4	1566
2403.25	1650
2405.09	1536
2406.94	1598
2408.79	1546
2410.63	1500
2412.48	1574
2414.33	1532
2416.17	1524
2418.02	1524
2419.86	1558
2421.7	1544
2423.55	1516
2425.39	1482
2427.23	1516
2429.07	1462
2430.91	1504
2432.75	1462
2434.59	1468
2436.43	1468
2438.27	1464
2440.11	1446
2441.95	1464
2443.78	1442
2445.62	1472
2447.46	1470
2449.29	1452
2451.13	1440
2452.96	1378
2454.79	1410
2456.63	1428
2458.46	1408
2460.29	1408
2462.12	1360
2463.95	1432
2465.78	1388
2467.61	1402
2469.44	1404
2471.27	1392
2473.1	1358
2474.93	1350
2476.76	1364
2478.58	1352
2480.41	1350
2482.23	1304
2484.06	1352
2485.88	1328
2487.71	1282
2489.53	1336
2491.35	1244
2493.18	1270
2495	1312
2496.82	1290
2498.64	1328
2500.46	1264
2502.28	1288
2504.1	1258
2505.92	1218
2507.74	1238
2509.55	1230
2511.37	1240
2513.19	1260
2515	1212
2516.82	1190
2518.63	1224
2520.45	1206
2522.26	1184
2524.07	1212
2525.89	1190
2527.7	1206
2529.51	1172
2531.32	1148
2533.13	1196
2534.94	1178
2536.75	1166
2538.56	1142
2540.37	1116
2542.18	1158
2543.98	1160
2545.79	1128
2547.6	1144
2549.4	1126
2551.21	1120
2553.01	1096
2554.82	1126
2556.62	1088
2558.42	1104
2560.23	1106
2562.03	1086
2563.83	1050
2565.63	1074
2567.43	1076
2569.23	1062
2571.03	1060
2572.83	1046
2574.63	1088
2576.43	1066
2578.22	1030
2580.02	1052
2581.82	1050
2583.61	1048
2585.41	1076
2587.2	1046
2589	998
2590.79	1022
2592.58	966
2594.38	1006
2596.17	1020
2597.96	994
2599.75	982
2601.54	954
2603.33	944
2605.12	986
2606.91	938
2608.7	928
2610.49	954
2612.27	948
2614.06	960
2615.85	920
2617.63	944
2619.42	938
2621.2	930
2622.99	926
2624.77	896
2626.55	916
2628.34	906
2630.12	914
2631.9	928
2633.68	940
2635.46	894
2637.24	878
2639.02	848
2640.8	876
2642.58	878
2644.36	896
2646.14	870
2647.91	882
2649.69	874
2651.46	868
2653.24	838
2655.01	872
2656.79	856
2658.56	808
2660.34	808
2662.11	818
2663.88	836
2665.65	860
2667.42	822
2669.2	864
2670.96	826
2672.73	812
2674.5	782
2676.27	820
2678.04	820
2679.81	820
2681.58	792
2683.34	800
2685.11	794
2686.87	772
2688.64	788
2690.4	752
2692.17	772
2693.93	750
2695.69	766
2697.46	764
2699.22	724
2700.98	728
2702.74	726
2704.5	744
2706.26	742
2708.02	690
2709.78	690
2711.54	730
2713.3	728
2715.05	706
2716.81	704
2718.57	682
2720.32	664
2722.08	694
2723.83	666
2725.59	706
2727.34	664
2729.09	668
2730.85	652
2732.6	682
2734.35	664
2736.1	664
2737.85	664
2739.6	688
2741.35	648
2743.1	646
2744.85	632
2746.6	632
2748.35	632
2750.09	648
2751.84	638
2753.59	642
2755.33	628
2757.08	626
2758.82	614
2760.57	606
2762.31	598
2764.05	582
2765.79	598
2767.54	610
2769.28	614
2771.02	560
2772.76	564
2774.5	590
2776.24	588
2777.98	582
2779.72	582
2781.46	582
2783.19	566
2784.93	546
2786.67	554
2788.4	556
2790.14	558
2791.87	534
2793.61	554
2795.34	520
2797.07	522
2798.81	532
2800.54	522
2802.27	538
2804	516
2805.74	538
2807.47	536
2809.2	508
2810.93	486
2812.65	510
2814.38	522
2816.11	502
2817.84	522
2819.56	486
2821.29	500
2823.02	476
2824.74	480
2826.47	474
2828.19	514
2829.92	454
2831.64	480
2833.36	474
2835.09	472
2836.81	454
2838.53	460
2840.25	452
2841.97	484
2843.69	456
2845.41	434
2847.13	438
2848.85	444
2850.57	426
2852.28	444
2854	442
2855.72	420
2857.43	414
2859.15	420
2860.86	430
2862.58	438
2864.29	418
2866.01	396
2867.72	420
2869.43	394
2871.14	412
2872.86	410
2874.57	422
2876.28	402
2877.99	410
2879.7	392
2881.41	382
2883.11	374
2884.82	388
2886.53	400
2888.24	392
2889.94	386
2891.65	372
2893.36	378
2895.06	368
2896.77	378
2898.47	362
2900.17	366
2901.88	366
2903.58	362
2905.28	340
2906.98	362
2908.69	366
2910.39	330
2912.09	352
2913.79	356
2915.49	332
2917.19	360
2918.88	340
2920.58	320
2922.28	340
2923.98	346
2925.67	334
2927.37	328
2929.06	334
2930.76	340
2932.45	336
2934.15	348
2935.84	334
2937.53	348
2939.23	328
2940.92	332
2942.61	332
2944.3	336
2945.99	316
2947.68	314
2949.37	330
2951.06	338
2952.75	334
2954.44	304
2956.12	302
2957.81	306
2959.5	310
2961.18	296
2962.87	308
2964.56	308
2966.24	308
2967.92	306
2969.61	286
2971.29	290
2972.97	292
2974.66	284
2976.34	296
2978.02	282
2979.7	298
2981.38	298
2983.06	258
2984.74	284
2986.42	290
2988.1	282
2989.78	292
2991.45	286
2993.13	284
2994.81	266
2996.48	268
2998.16	282
2999.83	256