File: muestras/papalo/leaf_100x_03.txt
#Acq. time (s)=	10
#Accumulations=	1
#Range (cm-¹)=	200...3000
#Windows=	3
#Autofocus=	Off
#AutoExposure=	Off
#Spike filter=	Off
#Delay time (s)=	0
#Binning=	1
#Readout mode=	Signal
#DeNoise=	Off
#ICS correction=	Off
#Dark correction=	Off
#Inst. Process=	Off
#Instrument=	LabRAM HR Evol
#Detector=	Syncerity OE
#Objective=	x100_VIS
#Grating=	600 (500nm)
#ND Filter=	0.01%
#Laser=	633nm_Edge
#Hole=	100.021
#Range=	Visible
#Project=	Omar
#Sample=	03-07-23
#Site=	papal
#Title=	leaf_100x
#Remark=
#Date=	03.07.2023 17:11
#Acquired=	03.07.2023 17:11:57
201.713	74
204.247	76
206.778	72
209.311	66
211.84	64
214.371	82
216.899	92
219.428	80
221.955	74
224.482	78
227.007	90
229.531	94
232.055	88
234.579	92
237.1	84
239.621	96
242.141	90
244.661	88
247.179	86
249.698	90
252.215	96
254.731	92
257.246	94
259.761	116
262.273	94
264.786	100
267.298	106
269.809	92
272.319	98
274.828	114
277.336	106
279.844	104
282.351	98
284.855	104
287.361	110
289.866	110
292.368	108
294.871	122
297.372	110
299.873	132
302.372	112
304.872	120
307.37	122
309.866	124
312.364	126
314.859	120
317.353	120
319.848	136
322.341	126
324.833	138
327.324	126
329.814	124
332.304	144
334.792	142
337.28	146
339.767	160
342.254	158
344.739	150
347.224	148
349.708	148
352.191	130
354.673	154
357.155	140
359.634	144
362.114	144
364.593	144
367.07	166
369.548	170
372.024	162
374.499	176
376.974	158
379.447	156
381.92	174
384.392	168
386.864	180
389.333	188
391.802	176
394.272	180
396.739	180
399.206	198
401.673	196
404.138	182
406.602	184
409.066	190
411.528	196
413.99	210
416.451	200
418.911	178
421.371	192
423.83	186
426.288	214
428.745	206
431.201	226
433.657	214
436.111	226
438.565	226
441.017	236
443.469	220
445.921	220
448.37	236
450.821	240
453.27	222
455.717	244
458.165	256
460.61	238
463.056	234
465.5	260
467.945	244
470.387	262
472.829	248
475.271	266
477.711	260
480.15	250
482.589	262
485.027	274
487.465	276
489.901	258
492.337	278
494.771	274
497.205	268
499.638	280
502.07	280
504.502	306
506.933	272
509.363	290
511.792	280
514.219	288
516.647	278
519.073	314
521.5	278
523.924	298
526.348	290
528.772	308
531.194	316
533.616	318
536.036	318
538.457	314
540.875	322
543.294	324
545.712	342
548.128	342
550.545	342
552.959	338
555.373	332
557.788	350
560.2	346
562.612	364
565.023	360
567.433	368
569.843	368
572.251	394
574.659	376
577.066	386
579.472	390
581.878	394
584.283	384
586.687	398
589.09	402
591.493	404
593.893	410
596.294	428
598.694	424
601.093	430
603.491	448
605.889	430
608.285	426
610.682	436
613.076	470
615.471	464
617.864	448
620.256	496
622.648	478
625.039	474
627.429	494
629.819	498
632.208	488
634.595	480
636.982	538
639.369	526
641.755	526
644.139	516
646.523	550
648.906	562
651.288	524
653.67	582
656.051	560
658.429	552
660.808	592
663.187	602
665.565	594
667.942	572
670.317	616
672.692	594
675.067	658
677.44	624
679.813	642
682.184	648
684.556	662
686.926	704
689.296	620
691.664	700
694.033	664
696.4	662
698.766	696
701.133	714
703.497	742
705.861	736
708.224	754
710.586	742
712.949	732
715.31	780
717.67	794
720.029	810
722.388	796
724.746	836
727.103	832
729.458	872
731.814	820
734.168	862
736.523	814
738.876	864
741.227	882
743.579	894
745.931	886
748.28	916
750.629	906
752.977	946
755.325	938
757.672	944
760.018	996
762.363	1002
764.708	1000
767.052	994
769.394	1044
771.737	1042
774.078	1060
776.419	1078
778.758	1112
781.097	1110
783.435	1120
785.773	1144
788.11	1176
790.446	1204
792.781	1172
795.115	1244
797.449	1232
799.782	1218
802.115	1266
804.446	1260
806.777	1302
809.106	1286
811.435	1312
813.764	1358
816.091	1366
818.418	1398
820.743	1418
823.069	1406
825.393	1430
827.717	1466
830.039	1486
832.362	1546
834.683	1516
837.003	1554
839.324	1556
841.643	1572
843.961	1606
846.278	1594
848.594	1678
850.91	1684
853.227	1680
855.541	1756
857.855	1760
860.168	1752
862.48	1832
864.79	1776
867.101	1844
869.411	1826
871.721	1848
874.029	1896
876.336	1910
878.643	1956
880.95	1966
883.254	1990
885.559	1934
887.862	2050
890.166	2052
892.467	2128
894.77	2106
897.07	2134
899.371	2122
901.669	2158
903.968	2150
906.266	2198
908.563	2212
910.859	2284
913.154	2230
915.449	2284
917.742	2340
920.036	2334
922.329	2348
924.621	2348
926.911	2442
929.201	2448
931.49	2484
933.779	2506
936.068	2530
938.355	2574
940.64	2590
942.926	2596
945.212	2644
947.495	2682
949.779	2780
952.062	2782
954.344	2810
956.625	2898
958.905	2914
961.184	2918
963.464	2898
965.742	2954
968.02	2942
970.296	3012
972.572	3068
974.847	3060
977.121	3088
979.396	3192
981.669	3254
983.941	3208
986.212	3208
988.483	3298
990.753	3352
993.022	3314
995.29	3440
997.558	3488
999.825	3466
1002.09	3458
1004.36	3618
1006.62	3530
1008.89	3580
1011.15	3658
1013.41	3694
1015.67	3650
1017.93	3648
1020.19	3814
1022.45	3892
1024.71	3978
1026.97	3898
1029.23	3978
1031.49	4040
1033.74	4160
1036	4018
1038.25	4124
1040.5	4170
1042.76	4172
1045.01	4220
1047.26	4292
1049.51	4368
1051.76	4338
1054.01	4402
1056.26	4546
1058.51	4552
1060.75	4584
1063	4532
1065.25	4690
1067.49	4674
1069.73	4712
1071.98	4704
1074.22	4734
1076.46	4816
1078.7	4860
1080.94	4816
1083.18	4930
1085.42	4988
1087.66	4864
1089.9	4964
1092.14	5024
1094.37	5084
1096.61	5152
1098.84	5178
1101.08	5162
1103.31	5108
1105.54	5130
1107.77	5142
1110	5238
1112.23	5254
1114.46	5358
1116.69	5320
1118.92	5366
1121.15	5350
1123.37	5432
1125.6	5400
1127.83	5474
1130.05	5414
1132.27	5548
1134.5	5474
1136.72	5578
1138.94	5584
1141.16	5582
1143.38	5616
1145.6	5698
1147.82	5720
1150.04	5684
1152.26	5674
1154.47	5726
1156.69	5822
1158.9	5660
1161.12	5892
1163.33	5774
1165.54	5812
1167.76	5718
1169.97	5788
1172.18	5836
1174.39	5720
1176.6	5792
1178.81	5856
1181.02	5788
1183.22	5602
1185.43	5770
1187.63	5810
1189.84	5804
1192.04	5720
1194.25	5726
1196.45	5662
1198.65	5614
1200.85	5680
1203.05	5506
1205.25	5594
1207.45	5486
1209.65	5446
1211.85	5526
1214.05	5436
1216.24	5436
1218.44	5360
1220.64	5288
1222.83	5358
1225.02	5340
1227.22	5330
1229.41	5238
1231.6	5264
1233.79	5264
1235.98	5202
1238.17	5098
1240.36	5108
1242.55	5004
1244.73	4954
1246.92	5002
1249.11	4944
1251.29	4912
1253.48	4878
1255.66	4846
1257.84	4796
1260.03	4814
1262.21	4814
1264.39	4712
1266.57	4746
1268.75	4698
1270.93	4648
1273.11	4556
1275.28	4618
1277.46	4450
1279.64	4460
1281.81	4418
1283.98	4359.96
1286.16	4363.5
1288.33	4313.51
1290.5	4283.55
1292.68	4252.1
1294.85	4185.46
1297.02	4130.8
1299.19	4091.61
1301.36	3951.16
1303.53	3948.72
1305.69	3889.73
1307.86	3837.46
1310.03	3768.22
1312.19	3764.16
1314.36	3698.07
1316.52	3594.15
1318.68	3614.09
1320.85	3552.39
1323.01	3527.74
1325.17	3516.28
1327.33	3448.49
1329.49	3413.32
1331.65	3389.12
1333.81	3296.84
1335.97	3240.45
1338.12	3193.54
1340.28	3202.46
1342.44	3163.28
1344.59	3065.97
1346.75	3066.95
1348.9	3009.77
1351.05	2985.17
1353.2	2994.62
1355.36	2905.64
1357.51	2886.64
1359.66	2867.69
1361.81	2832.09
1363.96	2748.63
1366.1	2770.97
1368.25	2779.86
1370.4	2648.57
1372.54	2633.28
1374.69	2589.87
1376.83	2587.48
1378.98	2557.11
1381.12	2552.44
1383.26	2550.08
1385.41	2508.47
1387.55	2422.8
1389.69	2472.19
1391.83	2344.15
1393.02	2384
1395.17	2362
1397.32	2368
1399.47	2324
1401.62	2274
1403.77	2242
1405.91	2228
1408.06	2238
1410.2	2248
1412.35	2190
1414.49	2196
1416.63	2146
1418.78	2150
1420.92	2066
1423.06	2136
1425.2	2114
1427.34	2072
1429.48	2032
1431.61	2066
1433.75	2024
1435.89	2004
1438.02	1978
1440.16	1964
1442.3	1952
1444.43	2030
1446.56	1984
1448.7	1904
1450.83	1932
1452.96	1900
1455.09	1912
1457.22	1884
1459.35	1896
1461.48	1920
1463.61	1856
1465.73	1882
1467.86	1844
1469.98	1844
1472.11	1864
1474.24	1816
1476.36	1816
1478.48	1750
1480.6	1774
1482.73	1722
1484.85	1746
1486.97	1700
1489.09	1688
1491.21	1718
1493.33	1690
1495.44	1670
1497.56	1674
1499.68	1672
1501.79	1676
1503.91	1628
1506.02	1654
1508.14	1660
1510.25	1570
1512.36	1592
1514.48	1570
1516.59	1604
1518.7	1552
1520.81	1524
1522.92	1516
1525.02	1520
1527.13	1520
1529.24	1502
1531.35	1496
1533.45	1494
1535.56	1500
1537.66	1450
1539.77	1500
1541.87	1486
1543.97	1436
1546.08	1480
1548.18	1446
1550.28	1454
1552.38	1462
1554.48	1366
1556.57	1432
1558.67	1384
1560.77	1376
1562.87	1422
1564.96	1426
1567.06	1390
1569.15	1360
1571.25	1370
1573.34	1376
1575.43	1400
1577.53	1354
1579.62	1346
1581.71	1340
1583.8	1374
1585.89	1326
1587.98	1344
1590.06	1340
1592.15	1352
1594.24	1348
1596.33	1330
1598.41	1302
1600.5	1278
1602.58	1334
1604.66	1292
1606.75	1288
1608.83	1274
1610.91	1288
1612.99	1304
1615.07	1296
1617.15	1274
1619.23	1256
1621.31	1306
1623.39	1300
1625.46	1266
1627.54	1234
1629.62	1228
1631.69	1244
1633.77	1262
1635.84	1240
1637.91	1234
1639.99	1226
1642.06	1198
1644.13	1240
1646.2	1220
1648.27	1252
1650.34	1236
1652.41	1232
1654.47	1168
1656.54	1222
1658.61	1206
1660.67	1224
1662.74	1198
1664.81	1168
1666.87	1190
1668.93	1166
1671	1206
1673.06	1166
1675.12	1228
1677.18	1192
1679.24	1148
1681.3	1148
1683.36	1144
1685.42	1164
1687.47	1162
1689.53	1154
1691.59	1184
1693.64	1126
1695.7	1148
1697.75	1114
1699.81	1174
1701.86	1150
1703.91	1090
1705.97	1126
1708.02	1152
1710.07	1172
1712.12	1128
1714.17	1160
1716.22	1116
1718.26	1130
1720.31	1072
1722.36	1076
1724.4	1092
1726.45	1074
1728.49	1126
1730.54	1146
1732.58	1056
1734.63	1134
1736.67	1088
1738.71	1106
1740.75	1108
1742.79	1096
1744.83	1106
1746.87	1104
1748.91	1068
1750.95	1094
1752.98	1036
1755.02	1108
1757.06	1064
1759.09	1092
1761.13	1092
1763.16	1108
1765.19	1068
1767.23	1076
1769.26	1062
1771.29	1076
1773.32	1042
1775.35	1122
1777.38	1088
1779.41	1054
1781.44	1040
1783.47	1070
1785.49	1076
1787.52	1056
1789.55	1060
1791.57	1090
1793.6	1086
1795.62	1066
1797.64	1058
1799.67	1052
1801.69	1078
1803.71	1056
1805.73	1062
1807.75	1066
1809.77	1062
1811.79	1028
1813.81	1060
1815.83	1042
1817.84	972
1819.86	1042
1821.88	1044
1823.89	1020
1825.91	1038
1827.92	1008
1829.93	1024
1831.95	1044
1833.96	1032
1835.97	994
1837.98	1048
1839.99	1004
1842	1078
1844.01	1000
1846.02	1018
1848.03	1016
1850.03	1008
1852.04	1028
1854.05	1038
1856.05	1034
1858.06	1042
1860.06	1004
1862.06	1022
1864.07	1034
1866.07	1014
1868.07	1010
1870.07	1026
1872.07	996
1874.07	984
1876.07	1022
1878.07	1006
1880.07	1036
1882.07	1042
1884.06	1024
1886.06	992
1888.05	992
1890.05	1012
1892.04	1050
1894.04	1034
1896.03	1022
1898.02	1000
1900.01	1034
1902	1026
1903.99	1024
1905.98	1006
1907.97	998
1909.96	988
1911.95	1012
1913.94	952
1915.93	990
1917.91	1024
1919.9	1004
1921.88	1016
1923.87	974
1925.85	1044
1927.83	988
1929.82	1022
1931.8	964
1933.78	986
1935.76	1002
1937.74	1012
1939.72	996
1941.7	990
1943.68	974
1945.65	980
1947.63	990
1949.61	968
1951.58	944
1953.56	982
1955.53	978
1957.51	978
1959.48	966
1961.45	986
1963.43	958
1965.4	966
1967.37	984
1969.34	974
1971.31	998
1973.28	982
1975.25	954
1977.22	930
1979.18	952
1981.15	910
1983.12	962
1985.08	944
1987.05	934
1989.01	940
1990.97	932
1992.94	958
1994.9	920
1996.86	950
1998.82	950
2000.78	946
2002.74	938
2004.7	934
2006.66	956
2008.62	916
2010.58	934
2012.54	930
2014.49	946
2016.45	942
2018.4	932
2020.36	924
2022.31	904
2024.27	926
2026.22	942
2028.17	955
2030.12	958
2032.07	948
2034.03	940
2035.98	940
2037.93	938
2039.87	964
2041.82	938
2043.77	902
2045.72	892
2047.66	934
2049.61	956
2051.55	924
2053.5	904
2055.44	932
2057.39	928
2059.33	882
2061.27	910
2063.21	908
2065.15	922
2067.09	882
2069.03	914
2070.97	898
2072.91	904
2074.85	896
2076.79	890
2078.73	902
2080.66	918
2082.6	876
2084.53	922
2086.47	884
2088.4	924
2090.33	886
2092.27	900
2094.2	926
2096.13	882
2098.06	922
2099.99	896
2101.92	912
2103.85	906
2105.78	876
2107.71	880
2109.64	888
2111.56	852
2113.49	942
2115.41	856
2117.34	906
2119.26	898
2121.19	946
2123.11	866
2125.03	880
2126.96	844
2128.88	886
2130.8	906
2132.72	878
2134.64	862
2136.56	866
2138.48	888
2140.4	900
2142.31	918
2144.23	884
2146.15	842
2148.06	872
2149.98	890
2151.89	846
2153.81	850
2155.72	868
2157.63	882
2159.55	840
2161.46	834
2163.37	866
2165.28	862
2167.19	850
2169.1	848
2171.01	872
2172.91	840
2174.82	840
2176.73	836
2178.64	862
2180.54	858
2182.45	858
2184.35	834
2186.26	838
2188.16	820
2190.06	828
2191.96	848
2193.87	818
2195.77	822
2197.67	824
2199.57	822
2201.47	834
2203.37	826
2205.27	806
2207.16	838
2209.06	838
2210.96	796
2212.85	832
2214.75	812
2216.64	860
2218.54	854
2220.43	804
2222.33	824
2224.22	812.42
2226.11	787.881
2228	788.783
2229.89	829.817
2231.78	813.045
2233.67	789.224
2235.56	802.978
2237.45	808.703
2239.34	801.271
2241.23	788.486
2243.11	821.223
2245	800.68
2246.89	843.5
2248.77	799.75
2250.66	799.137
2252.54	800.93
2254.42	821.058
2256.31	810.237
2258.19	803.565
2260.07	811.252
2261.95	817.609
2263.83	812.76
2265.71	811.793
2267.59	790.216
2269.47	820.415
2271.35	802.276
2273.23	800.68
2275.1	802.051
2276.98	814.505
2278.86	770.624
2280.73	796.194
2282.61	792.582
2284.48	795.525
2286.36	784.755
2288.23	778.865
2290.1	787.205
2291.98	793.727
2293.85	778.343
2295.72	812.086
2297.59	780.782
2299.46	753.57
2301.33	802.455
2303.2	799.425
2305.06	755.24
2306.93	771.332
2308.8	785.268
2310.67	803.196
2312.53	793.5
2314.4	781.718
2316.26	779.974
2317.62	768
2319.5	794
2321.37	758
2323.24	748
2325.12	738
2326.99	768
2328.86	734
2330.73	778
2332.6	748
2334.47	758
2336.34	762
2338.2	760
2340.07	752
2341.94	762
2343.81	742
2345.67	732
2347.54	750
2349.4	750
2351.27	722
2353.13	686
2354.99	758
2356.86	736
2358.72	746
2360.58	742
2362.44	734
2364.3	706
2366.16	732
2368.02	730
2369.88	728
2371.74	730
2373.6	658
2375.45	716
2377.31	716
2379.17	720
2381.02	676
2382.88	728
2384.73	696
2386.58	722
2388.44	680
2390.29	680
2392.14	696
2393.99	726
2395.85	690
2397.7	688
2399.55	672
2401.4	668
2403.25	626
2405.09	694
2406.94	664
2408.79	656
2410.63	674
2412.48	696
2414.33	652
2416.17	652
2418.02	674
2419.86	634
2421.7	666
2423.55	658
2425.39	864
2427.23	2266
2429.07	636
2430.91	656
2432.75	622
2434.59	604
2436.43	612
2438.27	642
2440.11	638
2441.95	624
2443.78	620
2445.62	628
2447.46	588
2449.29	610
2451.13	582
2452.96	622
2454.79	580
2456.63	604
2458.46	580
2460.29	598
2462.12	582
2463.95	600
2465.78	612
2467.61	590
2469.44	572
2471.27	568
2473.1	568
2474.93	574
2476.76	586
2478.58	526
2480.41	570
2482.23	580
2484.06	536
2485.88	560
2487.71	556
2489.53	574
2491.35	566
2493.18	540
2495	572
2496.82	538
2498.64	576
2500.46	552
2502.28	528
2504.1	550
2505.92	532
2507.74	530
2509.55	514
2511.37	536
2513.19	520
2515	548
2516.82	530
2518.63	496
2520.45	504
2522.26	520
2524.07	496
2525.89	488
2527.7	502
2529.51	494
2531.32	510
2533.13	486
2534.94	488
2536.75	494
2538.56	480
2540.37	480
2542.18	470
2543.98	478
2545.79	478
2547.6	464
2549.4	462
2551.21	490
2553.01	506
2554.82	478
2556.62	464
2558.42	452
2560.23	476
2562.03	462
2563.83	456
2565.63	456
2567.43	454
2569.23	442
2571.03	462
2572.83	422
2574.63	448
2576.43	440
2578.22	446
2580.02	414
2581.82	418
2583.61	440
2585.41	412
2587.2	416
2589	440
2590.79	420
2592.58	422
2594.38	424
2596.17	410
2597.96	414
2599.75	404
2601.54	420
2603.33	396
2605.12	406
2606.91	396
2608.7	408
2610.49	396
2612.27	388
2614.06	402
2615.85	390
2617.63	382
2619.42	410
2621.2	374
2622.99	404
2624.77	408
2626.55	374
2628.34	392
2630.12	392
2631.9	376
2633.68	390
2635.46	376
2637.24	370
2639.02	374
2640.8	364
2642.58	354
2644.36	384
2646.14	342
2647.91	356
2649.69	346
2651.46	362
2653.24	368
2655.01	372
2656.79	360
2658.56	344
2660.34	368
2662.11	334
2663.88	356
2665.65	320
2667.42	334
2669.2	338
2670.96	348
2672.73	334
2674.5	344
2676.27	348
2678.04	366
2679.81	336
2681.58	328
2683.34	328
2685.11	322
2686.87	340
2688.64	310
2690.4	336
2692.17	320
2693.93	312
2695.69	326
2697.46	304
2699.22	318
2700.98	332
2702.74	318
2704.5	316
2706.26	294
2708.02	284
2709.78	268
2711.54	284
2713.3	310
2715.05	312
2716.81	288
2718.57	282
2720.32	306
2722.08	308
2723.83	274
2725.59	260
2727.34	282
2729.09	298
2730.85	288
2732.6	296
2734.35	278
2736.1	278
2737.85	276
2739.6	262
2741.35	266
2743.1	278
2744.85	282
2746.6	268
2748.35	270
2750.09	256
2751.84	260
2753.59	256
2755.33	258
2757.08	254
2758.82	256
2760.57	250
2762.31	254
2764.05	226
2765.79	252
2767.54	232
2769.28	256
2771.02	248
2772.76	242
2774.5	236
2776.24	250
2777.98	240
2779.72	222
2781.46	242
2783.19	256
2784.93	254
2786.67	228
2788.4	236
2790.14	234
2791.87	224
2793.61	222
2795.34	230
2797.07	232
2798.81	234
2800.54	214
2802.27	230
2804	230
2805.74	230
2807.47	214
2809.2	206
2810.93	210
2812.65	202
2814.38	220
2816.11	218
2817.84	226
2819.56	222
2821.29	240
2823.02	218
2824.74	214
2826.47	210
2828.19	216
2829.92	212
2831.64	202
2833.36	198
2835.09	184
2836.81	208
2838.53	212
2840.25	200
2841.97	188
2843.69	194
2845.41	190
2847.13	188
2848.85	192
2850.57	206
2852.28	180
2854	182
2855.72	208
2857.43	182
2859.15	174
2860.86	174
2862.58	188
2864.29	184
2866.01	178
2867.72	182
2869.43	176
2871.14	156
2872.86	170
2874.57	170
2876.28	180
2877.99	176
2879.7	174
2881.41	178
2883.11	180
2884.82	154
2886.53	166
2888.24	154
2889.94	190
2891.65	162
2893.36	152
2895.06	164
2896.77	164
2898.47	154
2900.17	146
2901.88	156
2903.58	158
2905.28	154
2906.98	162
2908.69	146
2910.39	136
2912.09	160
2913.79	152
2915.49	146
2917.19	164
2918.88	156
2920.58	148
2922.28	144
2923.98	152
2925.67	146
2927.37	140
2929.06	146
2930.76	146
2932.45	146
2934.15	148
2935.84	156
2937.53	134
2939.23	164
2940.92	140
2942.61	134
2944.3	140
2945.99	134
2947.68	132
2949.37	134
2951.06	128
2952.75	136
2954.44	132
2956.12	132
2957.81	134
2959.5	140
2961.18	130
2962.87	122
2964.56	124
2966.24	122
2967.92	130
2969.61	118
2971.29	136
2972.97	130
2974.66	126
2976.34	142
2978.02	134
2979.7	136
2981.38	130
2983.06	124
2984.74	126
2986.42	126
2988.1	124
2989.78	126
2991.45	130
2993.13	132
2994.81	130
2996.48	114
2998.16	122
2999.83	116