File: muestras/papalo/leaf_06.txt
#Acq. time (s)=	10
#Accumulations=	1
#Range (cm-¹)=	200...3000
#Windows=	3
#Autofocus=	Off
#AutoExposure=	Off
#Spike filter=	Off
#Delay time (s)=	0
#Binning=	1
#Readout mode=	Signal
#DeNoise=	Off
#ICS correction=	Off
#Dark correction=	Off
#Inst. Process=	Off
#Instrument=	LabRAM HR Evol
#Detector=	Syncerity OE
#Objective=	x100_VIS
#Grating=	600 (500nm)
#ND Filter=	0.1%
#Laser=	633nm_Edge
#Hole=	9.98375
#Range=	Visible
#Project=	Omar
#Sample=	03-07-23
#Site=	papal
#Title=	leaf
#Remark=
#Date=	03.07.2023 16:55
#Acquired=	03.07.2023 16:55:20
201.713	28
204.247	36
206.778	28
209.311	24
211.84	28
214.371	30
216.899	32
219.428	28
221.955	36
224.482	32
227.007	38
229.531	34
232.055	28
234.579	28
237.1	32
239.621	26
242.141	28
244.661	42
247.179	26
249.698	28
252.215	28
254.731	30
257.246	26
259.761	26
262.273	30
264.786	32
267.298	32
269.809	34
272.319	22
274.828	28
277.336	34
279.844	28
282.351	28
284.855	26
287.361	32
289.866	30
292.368	32
294.871	36
297.372	32
299.873	32
302.372	32
304.872	38
307.37	34
309.866	34
312.364	32
314.859	34
317.353	38
319.848	40
322.341	1598
324.833	38
327.324	30
329.814	34
332.304	32
334.792	32
337.28	34
339.767	28
342.254	32
344.739	30
347.224	38
349.708	30
352.191	32
354.673	38
357.155	32
359.634	30
362.114	30
364.593	34
367.07	36
369.548	38
372.024	36
374.499	34
376.974	40
379.447	32
381.92	38
384.392	36
386.864	34
389.333	38
391.802	30
394.272	34
396.739	38
399.206	30
401.673	32
404.138	36
406.602	30
409.066	36
411.528	38
413.99	40
416.451	32
418.911	36
421.371	40
423.83	38
426.288	42
428.745	34
431.201	34
433.657	38
436.111	40
438.565	34
441.017	28
443.469	32
445.921	38
448.37	38
450.821	36
453.27	34
455.717	36
458.165	36
460.61	30
463.056	36
465.5	50
467.945	36
470.387	34
472.829	36
475.271	36
477.711	28
480.15	32
482.589	40
485.027	38
487.465	44
489.901	42
492.337	36
494.771	48
497.205	34
499.638	42
502.07	36
504.502	34
506.933	38
509.363	40
511.792	38
514.219	34
516.647	40
519.073	42
521.5	38
523.924	42
526.348	38
528.772	42
531.194	44
533.616	34
536.036	38
538.457	40
540.875	40
543.294	34
545.712	28
548.128	42
550.545	42
552.959	46
555.373	52
557.788	42
560.2	46
562.612	34
565.023	40
567.433	46
569.843	38
572.251	52
574.659	44
577.066	44
579.472	48
581.878	42
584.283	42
586.687	42
589.09	44
591.493	44
593.893	50
596.294	42
598.694	42
601.093	44
603.491	46
605.889	42
608.285	42
610.682	46
613.076	40
615.471	50
617.864	42
620.256	44
622.648	50
625.039	40
627.429	48
629.819	54
632.208	48
634.595	56
636.982	42
639.369	42
641.755	54
644.139	54
646.523	44
648.906	50
651.288	46
653.67	46
656.051	48
658.429	40
660.808	46
663.187	58
665.565	54
667.942	52
670.317	46
672.692	48
675.067	46
677.44	44
679.813	60
682.184	58
684.556	68
686.926	40
689.296	54
691.664	48
694.033	54
696.4	56
698.766	66
701.133	46
703.497	56
705.861	56
708.224	58
710.586	56
712.949	52
715.31	62
717.67	58
720.029	66
722.388	52
724.746	52
727.103	64
729.458	64
731.814	62
734.168	54
736.523	52
738.876	66
741.227	54
743.579	64
745.931	60
748.28	64
750.629	66
752.977	64
755.325	64
757.672	66
760.018	58
762.363	62
764.708	66
767.052	64
769.394	76
771.737	64
774.078	72
776.419	50
778.758	68
781.097	68
783.435	62
785.773	70
788.11	80
790.446	66
792.781	74
795.115	78
797.449	72
799.782	64
802.115	70
804.446	70
806.777	76
809.106	70
811.435	80
813.764	70
816.091	74
818.418	74
820.743	72
823.069	76
825.393	76
827.717	74
830.039	76
832.362	78
834.683	84
837.003	86
839.324	84
841.643	92
843.961	100
846.278	88
848.594	92
850.91	98
853.227	86
855.541	94
857.855	82
860.168	92
862.48	74
864.79	90
867.101	88
869.411	94
871.721	88
874.029	80
876.336	112
878.643	98
880.95	100
883.254	104
885.559	110
887.862	112
890.166	100
892.467	100
894.77	96
897.07	94
899.371	106
901.669	92
903.968	94
906.266	104
908.563	102
910.859	98
913.154	112
915.449	104
917.742	106
920.036	112
922.329	114
924.621	116
926.911	112
929.201	112
931.49	118
933.779	110
936.068	108
938.355	118
940.64	118
942.926	114
945.212	128
947.495	116
949.779	126
952.062	124
954.344	124
956.625	124
958.905	126
961.184	132
963.464	120
965.742	140
968.02	142
970.296	130
972.572	134
974.847	138
977.121	126
979.396	124
981.669	136
983.941	136
986.212	128
988.483	140
990.753	148
993.022	134
995.29	146
997.558	134
999.825	130
1002.09	138
1004.36	148
1006.62	138
1008.89	156
1011.15	152
1013.41	136
1015.67	150
1017.93	142
1020.19	166
1022.45	146
1024.71	156
1026.97	162
1029.23	156
1031.49	156
1033.74	158
1036	164
1038.25	164
1040.5	174
1042.76	158
1045.01	172
1047.26	164
1049.51	168
1051.76	164
1054.01	168
1056.26	182
1058.51	180
1060.75	198
1063	188
1065.25	178
1067.49	176
1069.73	190
1071.98	174
1074.22	192
1076.46	172
1078.7	188
1080.94	190
1083.18	190
1085.42	198
1087.66	192
1089.9	192
1092.14	176
1094.37	192
1096.61	170
1098.84	190
1101.08	186
1103.31	204
1105.54	196
1107.77	188
1110	186
1112.23	188
1114.46	216
1116.69	202
1118.92	208
1121.15	200
1123.37	202
1125.6	202
1127.83	204
1130.05	218
1132.27	220
1134.5	200
1136.72	218
1138.94	206
1141.16	206
1143.38	210
1145.6	204
1147.82	230
1150.04	218
1152.26	232
1154.47	230
1156.69	238
1158.9	222
1161.12	216
1163.33	238
1165.54	238
1167.76	230
1169.97	242
1172.18	230
1174.39	224
1176.6	216
1178.81	218
1181.02	236
1183.22	222
1185.43	232
1187.63	220
1189.84	234
1192.04	234
1194.25	240
1196.45	224
1198.65	208
1200.85	222
1203.05	210
1205.25	206
1207.45	228
1209.65	218
1211.85	228
1214.05	216
1216.24	200
1218.44	216
1220.64	204
1222.83	212
1225.02	206
1227.22	194
1229.41	222
1231.6	200
1233.79	196
1235.98	230
1238.17	204
1240.36	218
1242.55	212
1244.73	204
1246.92	192
1249.11	208
1251.29	200
1253.48	228
1255.66	204
1257.84	198
1260.03	202
1262.21	192
1264.39	200
1266.57	206
1268.75	190
1270.93	198
1273.11	204
1275.28	204
1277.46	186
1279.64	208
1281.81	204
1283.98	207.86
1286.16	195.59
1288.33	202.608
1290.5	186.755
1292.68	178.279
1294.85	178.491
1297.02	177.382
1299.19	173.08
1301.36	183.445
1303.53	180.115
1305.69	172.803
1307.86	163.118
1310.03	176.696
1312.19	160.913
1314.36	172.971
1316.52	170.551
1318.68	170.64
1320.85	167.265
1323.01	166.399
1325.17	159.696
1327.33	165.716
1329.49	163.538
1331.65	160.255
1333.81	158.353
1335.97	170.014
1338.12	157.162
1340.28	158.093
1342.44	157.409
1344.59	159.846
1346.75	148.922
1348.9	151.9
1351.05	147.769
1353.2	147.407
1355.36	152.25
1357.51	145.756
1359.66	149.95
1361.81	140.661
1363.96	136.973
1366.1	126.064
1368.25	149.805
1370.4	130.467
1372.54	141.528
1374.69	135.548
1376.83	140.52
1378.98	129.324
1381.12	131.692
1383.26	147.098
1385.41	122.4
1387.55	119.378
1389.69	127.299
1391.83	128.206
1393.02	124
1395.17	142
1397.32	124
1399.47	128
1401.62	122
1403.77	122
1405.91	120
1408.06	122
1410.2	130
1412.35	122
1414.49	112
1416.63	122
1418.78	122
1420.92	124
1423.06	120
1425.2	116
1427.34	116
1429.48	118
1431.61	126
1433.75	114
1435.89	116
1438.02	112
1440.16	120
1442.3	116
1444.43	124
1446.56	110
1448.7	114
1450.83	106
1452.96	120
1455.09	112
1457.22	110
1459.35	106
1461.48	120
1463.61	96
1465.73	108
1467.86	100
1469.98	120
1472.11	106
1474.24	104
1476.36	106
1478.48	114
1480.6	108
1482.73	100
1484.85	108
1486.97	122
1489.09	102
1491.21	100
1493.33	112
1495.44	106
1497.56	106
1499.68	122
1501.79	98
1503.91	102
1506.02	106
1508.14	100
1510.25	106
1512.36	94
1514.48	102
1516.59	92
1518.7	108
1520.81	92
1522.92	98
1525.02	100
1527.13	110
1529.24	100
1531.35	96
1533.45	94
1535.56	98
1537.66	92
1539.77	114
1541.87	102
1543.97	114
1546.08	94
1548.18	88
1550.28	96
1552.38	104
1554.48	96
1556.57	74
1558.67	100
1560.77	88
1562.87	102
1564.96	102
1567.06	94
1569.15	86
1571.25	86
1573.34	86
1575.43	84
1577.53	84
1579.62	94
1581.71	96
1583.8	100
1585.89	92
1587.98	106
1590.06	74
1592.15	94
1594.24	88
1596.33	92
1598.41	96
1600.5	90
1602.58	88
1604.66	96
1606.75	84
1608.83	82
1610.91	92
1612.99	78
1615.07	88
1617.15	88
1619.23	88
1621.31	90
1623.39	94
1625.46	96
1627.54	78
1629.62	90
1631.69	90
1633.77	94
1635.84	84
1637.91	88
1639.99	86
1642.06	100
1644.13	78
1646.2	80
1648.27	84
1650.34	86
1652.41	94
1654.47	90
1656.54	80
1658.61	92
1660.67	88
1662.74	94
1664.81	74
1666.87	86
1668.93	88
1671	90
1673.06	78
1675.12	68
1677.18	82
1679.24	90
1681.3	88
1683.36	78
1685.42	76
1687.47	92
1689.53	86
1691.59	88
1693.64	82
1695.7	92
1697.75	74
1699.81	92
1701.86	76
1703.91	80
1705.97	80
1708.02	86
1710.07	88
1712.12	94
1714.17	80
1716.22	72
1718.26	82
1720.31	92
1722.36	84
1724.4	88
1726.45	84
1728.49	80
1730.54	78
1732.58	82
1734.63	80
1736.67	78
1738.71	72
1740.75	84
1742.79	70
1744.83	80
1746.87	92
1748.91	80
1750.95	68
1752.98	72
1755.02	78
1757.06	88
1759.09	82
1761.13	82
1763.16	78
1765.19	86
1767.23	90
1769.26	80
1771.29	80
1773.32	80
1775.35	82
1777.38	94
1779.41	74
1781.44	74
1783.47	74
1785.49	76
1787.52	86
1789.55	66
1791.57	70
1793.6	82
1795.62	70
1797.64	80
1799.67	84
1801.69	80
1803.71	76
1805.73	90
1807.75	78
1809.77	78
1811.79	74
1813.81	80
1815.83	84
1817.84	82
1819.86	86
1821.88	82
1823.89	74
1825.91	78
1827.92	74
1829.93	86
1831.95	78
1833.96	82
1835.97	92
1837.98	78
1839.99	82
1842	72
1844.01	80
1846.02	82
1848.03	66
1850.03	76
1852.04	82
1854.05	74
1856.05	76
1858.06	84
1860.06	76
1862.06	78
1864.07	78
1866.07	84
1868.07	84
1870.07	76
1872.07	80
1874.07	76
1876.07	82
1878.07	88
1880.07	68
1882.07	74
1884.06	88
1886.06	78
1888.05	72
1890.05	76
1892.04	80
1894.04	84
1896.03	78
1898.02	80
1900.01	74
1902	82
1903.99	80
1905.98	74
1907.97	84
1909.96	80
1911.95	72
1913.94	74
1915.93	88
1917.91	82
1919.9	78
1921.88	88
1923.87	90
1925.85	70
1927.83	82
1929.82	82
1931.8	78
1933.78	80
1935.76	74
1937.74	74
1939.72	82
1941.7	76
1943.68	82
1945.65	78
1947.63	84
1949.61	90
1951.58	76
1953.56	78
1955.53	78
1957.51	76
1959.48	78
1961.45	88
1963.43	74
1965.4	76
1967.37	74
1969.34	84
1971.31	72
1973.28	68
1975.25	74
1977.22	74
1979.18	74
1981.15	88
1983.12	70
1985.08	82
1987.05	76
1989.01	84
1990.97	80
1992.94	78
1994.9	86
1996.86	72
1998.82	66
2000.78	90
2002.74	74
2004.7	76
2006.66	78
2008.62	82
2010.58	68
2012.54	76
2014.49	72
2016.45	72
2018.4	82
2020.36	78
2022.31	72
2024.27	76
2026.22	78
2028.17	84
2030.12	88
2032.07	72
2034.03	74
2035.98	80
2037.93	74
2039.87	74
2041.82	86
2043.77	74
2045.72	74
2047.66	72
2049.61	64
2051.55	74
2053.5	76
2055.44	78
2057.39	86
2059.33	70
2061.27	78
2063.21	86
2065.15	72
2067.09	78
2069.03	80
2070.97	72
2072.91	84
2074.85	74
2076.79	76
2078.73	68
2080.66	72
2082.6	74
2084.53	68
2086.47	84
2088.4	66
2090.33	78
2092.27	76
2094.2	72
2096.13	82
2098.06	68
2099.99	76
2101.92	66
2103.85	76
2105.78	72
2107.71	62
2109.64	80
2111.56	78
2113.49	78
2115.41	80
2117.34	72
2119.26	76
2121.19	78
2123.11	70
2125.03	62
2126.96	66
2128.88	76
2130.8	88
2132.72	76
2134.64	76
2136.56	82
2138.48	76
2140.4	72
2142.31	74
2144.23	80
2146.15	72
2148.06	80
2149.98	66
2151.89	64
2153.81	68
2155.72	68
2157.63	78
2159.55	72
2161.46	78
2163.37	70
2165.28	72
2167.19	76
2169.1	56
2171.01	68
2172.91	66
2174.82	82
2176.73	74
2178.64	84
2180.54	62
2182.45	82
2184.35	78
2186.26	78
2188.16	72
2190.06	76
2191.96	68
2193.87	72
2195.77	70
2197.67	76
2199.57	72
2201.47	70
2203.37	82
2205.27	76
2207.16	74
2209.06	78
2210.96	76
2212.85	70
2214.75	80
2216.64	66
2218.54	68
2220.43	66
2222.33	76
2224.22	67.9163
2226.11	74.2561
2228	67.6846
2229.89	71.7
2231.78	74.4751
2233.67	71.0827
2235.56	71.1977
2237.45	70.7765
2239.34	72.2798
2241.23	66.7062
2243.11	71.3109
2245	67.0878
2246.89	70.54
2248.77	65.9128
2250.66	71.3324
2252.54	72.74
2254.42	67.34
2256.31	60.2997
2258.19	70.5
2260.07	71.9787
2261.95	65.9385
2263.83	69.13
2265.71	59.8438
2267.59	65.872
2269.47	69.4677
2271.35	62.8622
2273.23	68.3034
2275.1	61.671
2276.98	69.8232
2278.86	69.7099
2280.73	67.0815
2282.61	68.19
2284.48	61.1456
2286.36	64.8602
2288.23	66.61
2290.1	68.8268
2291.98	63.459
2293.85	66.4228
2295.72	61.5139
2297.59	67.4581
2299.46	56.366
2301.33	61.98
2303.2	65.215
2305.06	69.5636
2306.93	66.062
2308.8	75.9089
2310.67	70.5634
2312.53	68
2314.4	65.5707
2316.26	69.6426
2317.62	72
2319.5	68
2321.37	76
2323.24	60
2325.12	66
2326.99	64
2328.86	64
2330.73	64
2332.6	66
2334.47	60
2336.34	70
2338.2	60
2340.07	62
2341.94	62
2343.81	58
2345.67	74
2347.54	58
2349.4	76
2351.27	58
2353.13	58
2354.99	66
2356.86	66
2358.72	74
2360.58	76
2362.44	58
2364.3	64
2366.16	66
2368.02	62
2369.88	54
2371.74	50
2373.6	58
2375.45	62
2377.31	64
2379.17	56
2381.02	58
2382.88	58
2384.73	54
2386.58	60
2388.44	68
2390.29	66
2392.14	60
2393.99	64
2395.85	60
2397.7	62
2399.55	64
2401.4	48
2403.25	58
2405.09	64
2406.94	60
2408.79	60
2410.63	70
2412.48	54
2414.33	58
2416.17	64
2418.02	60
2419.86	58
2421.7	66
2423.55	56
2425.39	60
2427.23	66
2429.07	60
2430.91	70
2432.75	54
2434.59	52
2436.43	44
2438.27	60
2440.11	60
2441.95	60
2443.78	54
2445.62	58
2447.46	56
2449.29	60
2451.13	62
2452.96	62
2454.79	60
2456.63	64
2458.46	54
2460.29	56
2462.12	68
2463.95	62
2465.78	64
2467.61	58
2469.44	58
2471.27	52
2473.1	54
2474.93	64
2476.76	58
2478.58	54
2480.41	48
2482.23	60
2484.06	56
2485.88	58
2487.71	60
2489.53	56
2491.35	46
2493.18	46
2495	72
2496.82	56
2498.64	52
2500.46	52
2502.28	68
2504.1	52
2505.92	48
2507.74	52
2509.55	56
2511.37	52
2513.19	50
2515	62
2516.82	56
2518.63	54
2520.45	54
2522.26	66
2524.07	58
2525.89	52
2527.7	52
2529.51	58
2531.32	52
2533.13	52
2534.94	50
2536.75	54
2538.56	50
2540.37	46
2542.18	52
2543.98	54
2545.79	50
2547.6	50
2549.4	70
2551.21	50
2553.01	50
2554.82	50
2556.62	56
2558.42	52
2560.23	52
2562.03	54
2563.83	46
2565.63	54
2567.43	48
2569.23	46
2571.03	52
2572.83	46
2574.63	48
2576.43	52
2578.22	48
2580.02	52
2581.82	52
2583.61	50
2585.41	46
2587.2	50
2589	60
2590.79	50
2592.58	54
2594.38	50
2596.17	48
2597.96	48
2599.75	50
2601.54	46
2603.33	60
2605.12	54
2606.91	52
2608.7	48
2610.49	48
2612.27	48
2614.06	50
2615.85	50
2617.63	46
2619.42	40
2621.2	50
2622.99	58
2624.77	48
2626.55	44
2628.34	46
2630.12	46
2631.9	50
2633.68	44
2635.46	52
2637.24	48
2639.02	50
2640.8	48
2642.58	54
2644.36	48
2646.14	52
2647.91	50
2649.69	42
2651.46	40
2653.24	50
2655.01	52
2656.79	42
2658.56	46
2660.34	48
2662.11	36
2663.88	48
2665.65	44
2667.42	34
2669.2	44
2670.96	44
2672.73	44
2674.5	46
2676.27	48
2678.04	50
2679.81	40
2681.58	48
2683.34	48
2685.11	54
2686.87	44
2688.64	48
2690.4	54
2692.17	48
2693.93	38
2695.69	44
2697.46	52
2699.22	58
2700.98	46
2702.74	38
2704.5	42
2706.26	44
2708.02	50
2709.78	40
2711.54	46
2713.3	42
2715.05	48
2716.81	38
2718.57	48
2720.32	44
2722.08	44
2723.83	38
2725.59	40
2727.34	42
2729.09	48
2730.85	40
2732.6	36
2734.35	44
2736.1	48
2737.85	36
2739.6	40
2741.35	52
2743.1	50
2744.85	44
2746.6	36
2748.35	42
2750.09	44
2751.84	46
2753.59	36
2755.33	40
2757.08	48
2758.82	50
2760.57	34
2762.31	36
2764.05	38
2765.79	40
2767.54	44
2769.28	42
2771.02	44
2772.76	42
2774.5	38
2776.24	42
2777.98	38
2779.72	44
2781.46	38
2783.19	38
2784.93	34
2786.67	38
2788.4	30
2790.14	40
2791.87	42
2793.61	44
2795.34	46
2797.07	42
2798.81	46
2800.54	44
2802.27	38
2804	44
2805.74	36
2807.47	40
2809.2	42
2810.93	38
2812.65	44
2814.38	40
2816.11	44
2817.84	36
2819.56	36
2821.29	40
2823.02	42
2824.74	34
2826.47	38
2828.19	40
2829.92	40
2831.64	44
2833.36	42
2835.09	40
2836.81	32
2838.53	34
2840.25	42
2841.97	42
2843.69	38
2845.41	38
2847.13	38
2848.85	36
2850.57	40
2852.28	40
2854	40
2855.72	38
2857.43	30
2859.15	38
2860.86	34
2862.58	40
2864.29	46
2866.01	28
2867.72	34
2869.43	36
2871.14	40
2872.86	32
2874.57	42
2876.28	34
2877.99	32
2879.7	38
2881.41	38
2883.11	34
2884.82	30
2886.53	42
2888.24	40
2889.94	34
2891.65	30
2893.36	38
2895.06	40
2896.77	32
2898.47	30
2900.17	42
2901.88	40
2903.58	36
2905.28	32
2906.98	38
2908.69	32
2910.39	38
2912.09	32
2913.79	42
2915.49	50
2917.19	32
2918.88	36
2920.58	34
2922.28	32
2923.98	46
2925.67	34
2927.37	42
2929.06	42
2930.76	36
2932.45	40
2934.15	34
2935.84	36
2937.53	40
2939.23	38
2940.92	34
2942.61	30
2944.3	28
2945.99	34
2947.68	34
2949.37	32
2951.06	36
2952.75	32
2954.44	34
2956.12	32
2957.81	32
2959.5	28
2961.18	42
2962.87	36
2964.56	34
2966.24	36
2967.92	42
2969.61	30
2971.29	34
2972.97	36
2974.66	36
2976.34	34
2978.02	40
2979.7	36
2981.38	40
2983.06	34
2984.74	28
2986.42	32
2988.1	32
2989.78	34
2991.45	28
2993.13	32
2994.81	38
2996.48	32
2998.16	36
2999.83	34