File: muestras/papalo/leaf_11.txt
#Acq. time (s)=	10
#Accumulations=	1
#Range (cm-¹)=	200...3000
#Windows=	3
#Autofocus=	Off
#AutoExposure=	Off
#Spike filter=	Off
#Delay time (s)=	0
#Binning=	1
#Readout mode=	Signal
#DeNoise=	Off
#ICS correction=	Off
#Dark correction=	Off
#Inst. Process=	Off
#Instrument=	LabRAM HR Evol
#Detector=	Syncerity OE
#Objective=	x100_VIS
#Grating=	600 (500nm)
#ND Filter=	0.01%
#Laser=	633nm_Edge
#Hole=	74.97
#Range=	Visible
#Project=	Omar
#Sample=	03-07-23
#Site=	papal
#Title=	leaf
#Remark=
#Date=	03.07.2023 17:02
#Acquired=	03.07.2023 17:02:32
201.713	94
204.247	94
206.778	92
209.311	104
211.84	100
214.371	106
216.899	102
219.428	90
221.955	106
224.482	114
227.007	90
229.531	106
232.055	104
234.579	120
237.1	100
239.621	112
242.141	112
244.661	124
247.179	114
249.698	122
252.215	116
254.731	108
257.246	108
259.761	120
262.273	126
264.786	132
267.298	134
269.809	136
272.319	114
274.828	134
277.336	130
279.844	142
282.351	138
284.855	146
287.361	138
289.866	142
292.368	142
294.871	136
297.372	144
299.873	158
302.372	148
304.872	160
307.37	158
309.866	166
312.364	162
314.859	148
317.353	158
319.848	164
322.341	182
324.833	158
327.324	152
329.814	162
332.304	172
334.792	170
337.28	162
339.767	174
342.254	178
344.739	170
347.224	188
349.708	188
352.191	206
354.673	202
357.155	194
359.634	194
362.114	192
364.593	218
367.07	204
369.548	196
372.024	202
374.499	214
376.974	222
379.447	218
381.92	216
384.392	208
386.864	206
389.333	210
391.802	226
394.272	240
396.739	222
399.206	220
401.673	236
404.138	248
406.602	246
409.066	256
411.528	242
413.99	248
416.451	254
418.911	242
421.371	268
423.83	266
426.288	278
428.745	258
431.201	268
433.657	278
436.111	294
438.565	266
441.017	284
443.469	286
445.921	276
448.37	302
450.821	290
453.27	300
455.717	314
458.165	298
460.61	302
463.056	298
465.5	312
467.945	292
470.387	324
472.829	346
475.271	308
477.711	330
480.15	340
482.589	338
485.027	330
487.465	330
489.901	358
492.337	352
494.771	368
497.205	344
499.638	370
502.07	360
504.502	344
506.933	354
509.363	386
511.792	386
514.219	358
516.647	366
519.073	366
521.5	380
523.924	384
526.348	390
528.772	408
531.194	404
533.616	396
536.036	406
538.457	426
540.875	424
543.294	422
545.712	446
548.128	450
550.545	434
552.959	458
555.373	468
557.788	438
560.2	468
562.612	464
565.023	456
567.433	494
569.843	450
572.251	512
574.659	484
577.066	470
579.472	496
581.878	478
584.283	496
586.687	502
589.09	548
591.493	538
593.893	512
596.294	540
598.694	546
601.093	556
603.491	550
605.889	560
608.285	566
610.682	566
613.076	566
615.471	554
617.864	590
620.256	590
622.648	576
625.039	640
627.429	616
629.819	636
632.208	640
634.595	666
636.982	624
639.369	646
641.755	668
644.139	690
646.523	706
648.906	720
651.288	698
653.67	678
656.051	710
658.429	704
660.808	734
663.187	712
665.565	756
667.942	784
670.317	774
672.692	778
675.067	770
677.44	798
679.813	810
682.184	776
684.556	824
686.926	834
689.296	830
691.664	802
694.033	842
696.4	864
698.766	836
701.133	866
703.497	858
705.861	894
708.224	944
710.586	964
712.949	944
715.31	916
717.67	962
720.029	1006
722.388	988
724.746	1020
727.103	1000
729.458	1040
731.814	1040
734.168	1064
736.523	1042
738.876	1096
741.227	1074
743.579	1098
745.931	1116
748.28	1116
750.629	1176
752.977	1132
755.325	1166
757.672	1132
760.018	1210
762.363	1238
764.708	1256
767.052	1232
769.394	1222
771.737	1272
774.078	1304
776.419	1296
778.758	1284
781.097	1344
783.435	1334
785.773	1358
788.11	1336
790.446	1360
792.781	1378
795.115	1440
797.449	1442
799.782	1450
802.115	1498
804.446	1518
806.777	1516
809.106	1498
811.435	1522
813.764	1552
816.091	1608
818.418	1624
820.743	1654
823.069	1724
825.393	1726
827.717	1746
830.039	1672
832.362	1804
834.683	1814
837.003	1808
839.324	1776
841.643	1880
843.961	1850
846.278	1948
848.594	1948
850.91	1932
853.227	2008
855.541	1994
857.855	2010
860.168	2046
862.48	2064
864.79	2030
867.101	2204
869.411	2122
871.721	2200
874.029	2198
876.336	2232
878.643	2208
880.95	2288
883.254	2354
885.559	2250
887.862	2332
890.166	2398
892.467	2416
894.77	2400
897.07	2394
899.371	2500
901.669	2464
903.968	2508
906.266	2508
908.563	2548
910.859	2546
913.154	2602
915.449	2606
917.742	2658
920.036	2620
922.329	2732
924.621	2784
926.911	2816
929.201	2804
931.49	2822
933.779	2856
936.068	2852
938.355	2950
940.64	2938
942.926	2950
945.212	3056
947.495	3060
949.779	3096
952.062	3128
954.344	3190
956.625	3192
958.905	3244
961.184	3314
963.464	3368
965.742	3338
968.02	3386
970.296	3434
972.572	3440
974.847	3464
977.121	3528
979.396	3602
981.669	3626
983.941	3654
986.212	3652
988.483	3742
990.753	3700
993.022	3762
995.29	3752
997.558	3828
999.825	3870
1002.09	3846
1004.36	3896
1006.62	4006
1008.89	3986
1011.15	4094
1013.41	4116
1015.67	4200
1017.93	4148
1020.19	4260
1022.45	4264
1024.71	4402
1026.97	4336
1029.23	4456
1031.49	4484
1033.74	4516
1036	4646
1038.25	4624
1040.5	4702
1042.76	4700
1045.01	4744
1047.26	4832
1049.51	4870
1051.76	4954
1054.01	4860
1056.26	5094
1058.51	5048
1060.75	5116
1063	5180
1065.25	5238
1067.49	5214
1069.73	5222
1071.98	5344
1074.22	5448
1076.46	5424
1078.7	5478
1080.94	5466
1083.18	5510
1085.42	5616
1087.66	5512
1089.9	5534
1092.14	5562
1094.37	5580
1096.61	5672
1098.84	5740
1101.08	5672
1103.31	5754
1105.54	5876
1107.77	5784
1110	5904
1112.23	5936
1114.46	5864
1116.69	5974
1118.92	5938
1121.15	6002
1123.37	6002
1125.6	6078
1127.83	6134
1130.05	6278
1132.27	6126
1134.5	6180
1136.72	6290
1138.94	6360
1141.16	6456
1143.38	6432
1145.6	6474
1147.82	6514
1150.04	6518
1152.26	6482
1154.47	6510
1156.69	6782
1158.9	6576
1161.12	6642
1163.33	6654
1165.54	6744
1167.76	6766
1169.97	6780
1172.18	6636
1174.39	6698
1176.6	6752
1178.81	6712
1181.02	6730
1183.22	6838
1185.43	6826
1187.63	6674
1189.84	6732
1192.04	6750
1194.25	6612
1196.45	6658
1198.65	6652
1200.85	6660
1203.05	6634
1205.25	6576
1207.45	6562
1209.65	6684
1211.85	6564
1214.05	6584
1216.24	6476
1218.44	6534
1220.64	6438
1222.83	6434
1225.02	6444
1227.22	6340
1229.41	6406
1231.6	6338
1233.79	6328
1235.98	6282
1238.17	6312
1240.36	6166
1242.55	6242
1244.73	6214
1246.92	6148
1249.11	6104
1251.29	6058
1253.48	6102
1255.66	6122
1257.84	5896
1260.03	6064
1262.21	6028
1264.39	5872
1266.57	5966
1268.75	5858
1270.93	5798
1273.11	5798
1275.28	5780
1277.46	5716
1279.64	5698
1281.81	5666
1283.98	5595.66
1286.16	5564.92
1288.33	5566.37
1290.5	5504.25
1292.68	5338.2
1294.85	5274.46
1297.02	5320.53
1299.19	5297.35
1301.36	5180.74
1303.53	5187.17
1305.69	5170.59
1307.86	5022.02
1310.03	5002.26
1312.19	4978.85
1314.36	4946.6
1316.52	4923.01
1318.68	4847.18
1320.85	4789.37
1323.01	4807.24
1325.17	4648.02
1327.33	4560.12
1329.49	4529.43
1331.65	4483.96
1333.81	4504.13
1335.97	4435.61
1338.12	4358.27
1340.28	4312.95
1342.44	4279.99
1344.59	4268.5
1346.75	4175.83
1348.9	4154.32
1351.05	4093.24
1353.2	4093.8
1355.36	4091.38
1357.51	3966.64
1359.66	3976.38
1361.81	3932.76
1363.96	3878.76
1366.1	3857.89
1368.25	3806.6
1370.4	3724.76
1372.54	3653.66
1374.69	3689.58
1376.83	3639.3
1378.98	3642.79
1381.12	3567.24
1383.26	3532.92
1385.41	3492.83
1387.55	3518.66
1389.69	3415.15
1391.83	3420.15
1393.02	3384
1395.17	3362
1397.32	3328
1399.47	3282
1401.62	3276
1403.77	3226
1405.91	3258
1408.06	3216
1410.2	3196
1412.35	3116
1414.49	3162
1416.63	3144
1418.78	3052
1420.92	3042
1423.06	3054
1425.2	3002
1427.34	2984
1429.48	2928
1431.61	2938
1433.75	3002
1435.89	2910
1438.02	2936
1440.16	2886
1442.3	2872
1444.43	2850
1446.56	2798
1448.7	2898
1450.83	2764
1452.96	2766
1455.09	2756
1457.22	2726
1459.35	2714
1461.48	2790
1463.61	2696
1465.73	2690
1467.86	2662
1469.98	2652
1472.11	2590
1474.24	2582
1476.36	2630
1478.48	2622
1480.6	2566
1482.73	2608
1484.85	2624
1486.97	2542
1489.09	2476
1491.21	2488
1493.33	2518
1495.44	2526
1497.56	2484
1499.68	2512
1501.79	2380
1503.91	2456
1506.02	2474
1508.14	2388
1510.25	2368
1512.36	2384
1514.48	2336
1516.59	2340
1518.7	2372
1520.81	2356
1522.92	2286
1525.02	2318
1527.13	2266
1529.24	2234
1531.35	2194
1533.45	2250
1535.56	2174
1537.66	2240
1539.77	2176
1541.87	2114
1543.97	2240
1546.08	2148
1548.18	2194
1550.28	2038
1552.38	2090
1554.48	2140
1556.57	2116
1558.67	2052
1560.77	2108
1562.87	1996
1564.96	2070
1567.06	2062
1569.15	2040
1571.25	2004
1573.34	1984
1575.43	1990
1577.53	2020
1579.62	1940
1581.71	2012
1583.8	1974
1585.89	1956
1587.98	1984
1590.06	1960
1592.15	1962
1594.24	1886
1596.33	1958
1598.41	1924
1600.5	1914
1602.58	1938
1604.66	1904
1606.75	1982
1608.83	1948
1610.91	1910
1612.99	1890
1615.07	1934
1617.15	1924
1619.23	1858
1621.31	1870
1623.39	1852
1625.46	1870
1627.54	1892
1629.62	1852
1631.69	1820
1633.77	1918
1635.84	1788
1637.91	1862
1639.99	1844
1642.06	1806
1644.13	1816
1646.2	1834
1648.27	1832
1650.34	1826
1652.41	1764
1654.47	1728
1656.54	1714
1658.61	1750
1660.67	1750
1662.74	1774
1664.81	1738
1666.87	1734
1668.93	1720
1671	1748
1673.06	1722
1675.12	1666
1677.18	1716
1679.24	1690
1681.3	1720
1683.36	1686
1685.42	1724
1687.47	1690
1689.53	1738
1691.59	1722
1693.64	1696
1695.7	1690
1697.75	1624
1699.81	1656
1701.86	1688
1703.91	1636
1705.97	1662
1708.02	1654
1710.07	1636
1712.12	1634
1714.17	1654
1716.22	1648
1718.26	1680
1720.31	1654
1722.36	1634
1724.4	1658
1726.45	1608
1728.49	1600
1730.54	1634
1732.58	1608
1734.63	1558
1736.67	1604
1738.71	1622
1740.75	1576
1742.79	1600
1744.83	1662
1746.87	1626
1748.91	1588
1750.95	1636
1752.98	1616
1755.02	1592
1757.06	1620
1759.09	1624
1761.13	1584
1763.16	1588
1765.19	1572
1767.23	1628
1769.26	1588
1771.29	1598
1773.32	1592
1775.35	1594
1777.38	1564
1779.41	1640
1781.44	1592
1783.47	1608
1785.49	1590
1787.52	1576
1789.55	1600
1791.57	1564
1793.6	1574
1795.62	1578
1797.64	1564
1799.67	1572
1801.69	1528
1803.71	1566
1805.73	1548
1807.75	1562
1809.77	1612
1811.79	1576
1813.81	1588
1815.83	1526
1817.84	1560
1819.86	1534
1821.88	1596
1823.89	1512
1825.91	1546
1827.92	1606
1829.93	1504
1831.95	1586
1833.96	1526
1835.97	1610
1837.98	1538
1839.99	1542
1842	1514
1844.01	1546
1846.02	1498
1848.03	1538
1850.03	1510
1852.04	1484
1854.05	1570
1856.05	1526
1858.06	1526
1860.06	1512
1862.06	1548
1864.07	1502
1866.07	1548
1868.07	1506
1870.07	1418
1872.07	1486
1874.07	1544
1876.07	1498
1878.07	1546
1880.07	1490
1882.07	1506
1884.06	1484
1886.06	1488
1888.05	1496
1890.05	1514
1892.04	1538
1894.04	1532
1896.03	1546
1898.02	1532
1900.01	1468
1902	1502
1903.99	1508
1905.98	1554
1907.97	1506
1909.96	1508
1911.95	1538
1913.94	1492
1915.93	1510
1917.91	1534
1919.9	1456
1921.88	1502
1923.87	1536
1925.85	1524
1927.83	1476
1929.82	1544
1931.8	1498
1933.78	1464
1935.76	1498
1937.74	1530
1939.72	1514
1941.7	1514
1943.68	1490
1945.65	1504
1947.63	1520
1949.61	1540
1951.58	1488
1953.56	1506
1955.53	1494
1957.51	1484
1959.48	1480
1961.45	1454
1963.43	1504
1965.4	1448
1967.37	1498
1969.34	1496
1971.31	1430
1973.28	1518
1975.25	1444
1977.22	1458
1979.18	1438
1981.15	1456
1983.12	1444
1985.08	1456
1987.05	1464
1989.01	1468
1990.97	1426
1992.94	1452
1994.9	1426
1996.86	1446
1998.82	1472
2000.78	1436
2002.74	1440
2004.7	1458
2006.66	1410
2008.62	1478
2010.58	1458
2012.54	1422
2014.49	1456
2016.45	1518
2018.4	1448
2020.36	1438
2022.31	1464
2024.27	1460
2026.22	1454
2028.17	1410
2030.12	1460
2032.07	1448
2034.03	1456
2035.98	1436
2037.93	1426
2039.87	1442
2041.82	1424
2043.77	1420
2045.72	1436
2047.66	1450
2049.61	1492
2051.55	1406
2053.5	1442
2055.44	1440
2057.39	1420
2059.33	1416
2061.27	1450
2063.21	1456
2065.15	1454
2067.09	1458
2069.03	1444
2070.97	1366
2072.91	1438
2074.85	1426
2076.79	1460
2078.73	1358
2080.66	1434
2082.6	1390
2084.53	1390
2086.47	1436
2088.4	1446
2090.33	1480
2092.27	1400
2094.2	1408
2096.13	1428
2098.06	1406
2099.99	1438
2101.92	1410
2103.85	1412
2105.78	1376
2107.71	1412
2109.64	1430
2111.56	1388
2113.49	1408
2115.41	1424
2117.34	1434
2119.26	1448
2121.19	1458
2123.11	1408
2125.03	1450
2126.96	1382
2128.88	1398
2130.8	1382
2132.72	1450
2134.64	1408
2136.56	1452
2138.48	1392
2140.4	1400
2142.31	1406
2144.23	1408
2146.15	1390
2148.06	1408
2149.98	1406
2151.89	1448
2153.81	1430
2155.72	1378
2157.63	1376
2159.55	1376
2161.46	1436
2163.37	1374
2165.28	1404
2167.19	1388
2169.1	1388
2171.01	1362
2172.91	1356
2174.82	1408
2176.73	1364
2178.64	1364
2180.54	1368
2182.45	1392
2184.35	1352
2186.26	1334
2188.16	1356
2190.06	1352
2191.96	1370
2193.87	1382
2195.77	1340
2197.67	1356
2199.57	1352
2201.47	1364
2203.37	1326
2205.27	1276
2207.16	1356
2209.06	1330
2210.96	1358
2212.85	1324
2214.75	1316
2216.64	1344
2218.54	1392
2220.43	1338
2222.33	1300
2224.22	1334.77
2226.11	1318.46
2228	1294.58
2229.89	1340.76
2231.78	1329.97
2233.67	1325.34
2235.56	1308.49
2237.45	1312.95
2239.34	1320.9
2241.23	1314.93
2243.11	1290.3
2245	1301.43
2246.89	1308.98
2248.77	1331.82
2250.66	1356.43
2252.54	1317.05
2254.42	1274.43
2256.31	1259.33
2258.19	1282.98
2260.07	1311.09
2261.95	1273.77
2263.83	1282.64
2265.71	1261.56
2267.59	1303.42
2269.47	1283.59
2271.35	1293.82
2273.23	1254.29
2275.1	1252.06
2276.98	1271.31
2278.86	1249.91
2280.73	1257.71
2282.61	1247.6
2284.48	1258.73
2286.36	1254.52
2288.23	1233.68
2290.1	1244.31
2291.98	1244.64
2293.85	1238.49
2295.72	1246.44
2297.59	1223.26
2299.46	1206.91
2301.33	1232.26
2303.2	1212.49
2305.06	1232.99
2306.93	1222.87
2308.8	1220.14
2310.67	1251.07
2312.53	1194
2314.4	1204.9
2316.26	1186.31
2317.62	1206
2319.5	1216
2321.37	1194
2323.24	1176
2325.12	1174
2326.99	1184
2328.86	1178
2330.73	1172
2332.6	1194
2334.47	1162
2336.34	1188
2338.2	1196
2340.07	1134
2341.94	1190
2343.81	1174
2345.67	1174
2347.54	1134
2349.4	1134
2351.27	1120
2353.13	1134
2354.99	1142
2356.86	1158
2358.72	1114
2360.58	1130
2362.44	1160
2364.3	1134
2366.16	1112
2368.02	1078
2369.88	1134
2371.74	1152
2373.6	1080
2375.45	1114
2377.31	1120
2379.17	1120
2381.02	1120
2382.88	1098
2384.73	1098
2386.58	1102
2388.44	1100
2390.29	1044
2392.14	1158
2393.99	1064
2395.85	1058
2397.7	1050
2399.55	1056
2401.4	1078
2403.25	1032
2405.09	1028
2406.94	1060
2408.79	1020
2410.63	1020
2412.48	1056
2414.33	1038
2416.17	990
2418.02	1024
2419.86	1040
2421.7	1028
2423.55	1008
2425.39	1016
2427.23	1000
2429.07	1006
2430.91	1034
2432.75	978
2434.59	998
2436.43	970
2438.27	970
2440.11	956
2441.95	974
2443.78	970
2445.62	950
2447.46	956
2449.29	894
2451.13	950
2452.96	952
2454.79	946
2456.63	912
2458.46	962
2460.29	936
2462.12	956
2463.95	926
2465.78	868
2467.61	914
2469.44	906
2471.27	934
2473.1	900
2474.93	930
2476.76	918
2478.58	892
2480.41	898
2482.23	876
2484.06	886
2485.88	894
2487.71	876
2489.53	868
2491.35	874
2493.18	918
2495	854
2496.82	874
2498.64	858
2500.46	842
2502.28	830
2504.1	864
2505.92	870
2507.74	850
2509.55	822
2511.37	852
2513.19	862
2515	806
2516.82	812
2518.63	814
2520.45	780
2522.26	780
2524.07	816
2525.89	790
2527.7	778
2529.51	798
2531.32	792
2533.13	790
2534.94	778
2536.75	766
2538.56	800
2540.37	758
2542.18	802
2543.98	752
2545.79	796
2547.6	740
2549.4	724
2551.21	724
2553.01	742
2554.82	742
2556.62	760
2558.42	742
2560.23	726
2562.03	722
2563.83	718
2565.63	742
2567.43	746
2569.23	700
2571.03	696
2572.83	676
2574.63	718
2576.43	708
2578.22	708
2580.02	670
2581.82	674
2583.61	704
2585.41	680
2587.2	684
2589	662
2590.79	664
2592.58	686
2594.38	690
2596.17	672
2597.96	638
2599.75	670
2601.54	668
2603.33	678
2605.12	628
2606.91	652
2608.7	636
2610.49	636
2612.27	654
2614.06	638
2615.85	626
2617.63	634
2619.42	660
2621.2	602
2622.99	644
2624.77	616
2626.55	596
2628.34	648
2630.12	614
2631.9	608
2633.68	594
2635.46	602
2637.24	580
2639.02	592
2640.8	584
2642.58	604
2644.36	564
2646.14	562
2647.91	578
2649.69	562
2651.46	570
2653.24	576
2655.01	556
2656.79	552
2658.56	570
2660.34	556
2662.11	550
2663.88	566
2665.65	540
2667.42	538
2669.2	566
2670.96	540
2672.73	540
2674.5	552
2676.27	546
2678.04	542
2679.81	522
2681.58	534
2683.34	536
2685.11	540
2686.87	510
2688.64	532
2690.4	492
2692.17	536
2693.93	508
2695.69	508
2697.46	508
2699.22	472
2700.98	496
2702.74	516
2704.5	474
2706.26	498
2708.02	518
2709.78	486
2711.54	486
2713.3	474
2715.05	472
2716.81	496
2718.57	480
2720.32	444
2722.08	458
2723.83	454
2725.59	452
2727.34	462
2729.09	444
2730.85	460
2732.6	462
2734.35	466
2736.1	446
2737.85	442
2739.6	418
2741.35	438
2743.1	442
2744.85	416
2746.6	430
2748.35	440
2750.09	432
2751.84	432
2753.59	414
2755.33	398
2757.08	412
2758.82	428
2760.57	422
2762.31	414
2764.05	396
2765.79	374
2767.54	400
2769.28	376
2771.02	400
2772.76	374
2774.5	376
2776.24	412
2777.98	374
2779.72	370
2781.46	376
2783.19	372
2784.93	358
2786.67	406
2788.4	372
2790.14	360
2791.87	366
2793.61	358
2795.34	362
2797.07	372
2798.81	364
2800.54	360
2802.27	356
2804	340
2805.74	338
2807.47	348
2809.2	350
2810.93	344
2812.65	328
2814.38	352
2816.11	322
2817.84	346
2819.56	350
2821.29	344
2823.02	334
2824.74	318
2826.47	318
2828.19	310
2829.92	324
2831.64	312
2833.36	310
2835.09	324
2836.81	312
2838.53	316
2840.25	304
2841.97	296
2843.69	298
2845.41	322
2847.13	298
2848.85	300
2850.57	290
2852.28	298
2854	294
2855.72	312
2857.43	280
2859.15	304
2860.86	280
2862.58	278
2864.29	272
2866.01	280
2867.72	268
2869.43	286
2871.14	284
2872.86	264
2874.57	248
2876.28	268
2877.99	256
2879.7	270
2881.41	258
2883.11	260
2884.82	266
2886.53	264
2888.24	266
2889.94	256
2891.65	258
2893.36	246
2895.06	262
2896.77	244
2898.47	238
2900.17	252
2901.88	252
2903.58	240
2905.28	252
2906.98	256
2908.69	256
2910.39	222
2912.09	234
2913.79	232
2915.49	248
2917.19	230
2918.88	240
2920.58	236
2922.28	238
2923.98	232
2925.67	246
2927.37	230
2929.06	230
2930.76	214
2932.45	232
2934.15	202
2935.84	242
2937.53	236
2939.23	238
2940.92	228
2942.61	218
2944.3	232
2945.99	204
2947.68	216
2949.37	216
2951.06	216
2952.75	220
2954.44	198
2956.12	222
2957.81	200
2959.5	212
2961.18	208
2962.87	220
2964.56	192
2966.24	198
2967.92	222
2969.61	192
2971.29	198
2972.97	210
2974.66	196
2976.34	206
2978.02	198
2979.7	190
2981.38	190
2983.06	192
2984.74	184
2986.42	200
2988.1	208
2989.78	184
2991.45	194
2993.13	200
2994.81	174
2996.48	188
2998.16	164
2999.83	194