File: muestras/papalo/leaf_100x_12.txt
#Acq. time (s)=	10
#Accumulations=	1
#Range (cm-¹)=	200...3000
#Windows=	3
#Autofocus=	Off
#AutoExposure=	Off
#Spike filter=	Off
#Delay time (s)=	0
#Binning=	1
#Readout mode=	Signal
#DeNoise=	Off
#ICS correction=	Off
#Dark correction=	Off
#Inst. Process=	Off
#Instrument=	LabRAM HR Evol
#Detector=	Syncerity OE
#Objective=	x100_VIS
#Grating=	600 (500nm)
#ND Filter=	0.1%
#Laser=	633nm_Edge
#Hole=	100.021
#Range=	Visible
#Project=	Omar
#Sample=	03-07-23
#Site=	papal
#Title=	leaf_100x
#Remark=
#Date=	03.07.2023 17:21
#Acquired=	03.07.2023 17:21:16
201.713	118
204.247	112
206.778	124
209.311	112
211.84	124
214.371	124
216.899	118
219.428	132
221.955	130
224.482	130
227.007	134
229.531	130
232.055	120
234.579	136
237.1	162
239.621	152
242.141	140
244.661	136
247.179	154
249.698	140
252.215	144
254.731	160
257.246	160
259.761	164
262.273	166
264.786	158
267.298	150
269.809	168
272.319	164
274.828	168
277.336	174
279.844	170
282.351	178
284.855	172
287.361	180
289.866	170
292.368	190
294.871	192
297.372	198
299.873	206
302.372	214
304.872	196
307.37	198
309.866	210
312.364	214
314.859	202
317.353	206
319.848	212
322.341	218
324.833	224
327.324	216
329.814	240
332.304	246
334.792	216
337.28	240
339.767	222
342.254	244
344.739	232
347.224	254
349.708	242
352.191	248
354.673	252
357.155	260
359.634	272
362.114	264
364.593	256
367.07	266
369.548	260
372.024	278
374.499	286
376.974	274
379.447	286
381.92	290
384.392	288
386.864	276
389.333	304
391.802	298
394.272	284
396.739	300
399.206	298
401.673	282
404.138	336
406.602	308
409.066	306
411.528	318
413.99	328
416.451	328
418.911	344
421.371	350
423.83	344
426.288	348
428.745	352
431.201	366
433.657	350
436.111	372
438.565	380
441.017	370
443.469	390
445.921	382
448.37	394
450.821	392
453.27	418
455.717	372
458.165	398
460.61	380
463.056	406
465.5	428
467.945	422
470.387	442
472.829	424
475.271	432
477.711	412
480.15	444
482.589	454
485.027	430
487.465	438
489.901	446
492.337	476
494.771	466
497.205	486
499.638	508
502.07	488
504.502	488
506.933	496
509.363	478
511.792	528
514.219	514
516.647	502
519.073	488
521.5	506
523.924	534
526.348	544
528.772	536
531.194	524
533.616	544
536.036	534
538.457	530
540.875	538
543.294	582
545.712	560
548.128	540
550.545	570
552.959	598
555.373	594
557.788	584
560.2	586
562.612	606
565.023	616
567.433	582
569.843	620
572.251	646
574.659	646
577.066	620
579.472	630
581.878	678
584.283	644
586.687	654
589.09	644
591.493	674
593.893	656
596.294	710
598.694	694
601.093	712
603.491	688
605.889	752
608.285	750
610.682	766
613.076	740
615.471	758
617.864	778
620.256	788
622.648	776
625.039	818
627.429	834
629.819	828
632.208	848
634.595	844
636.982	834
639.369	898
641.755	880
644.139	884
646.523	946
648.906	880
651.288	946
653.67	946
656.051	940
658.429	942
660.808	976
663.187	958
665.565	1024
667.942	1020
670.317	1024
672.692	996
675.067	1028
677.44	1046
679.813	1052
682.184	1074
684.556	1078
686.926	1074
689.296	1060
691.664	1102
694.033	1102
696.4	1124
698.766	1144
701.133	1138
703.497	1202
705.861	1170
708.224	1234
710.586	1214
712.949	1246
715.31	1212
717.67	1298
720.029	1278
722.388	1314
724.746	1308
727.103	1344
729.458	1322
731.814	1340
734.168	1374
736.523	1414
738.876	1416
741.227	1426
743.579	1420
745.931	1432
748.28	1474
750.629	1520
752.977	1486
755.325	1504
757.672	1574
760.018	1536
762.363	1584
764.708	1578
767.052	1636
769.394	1632
771.737	1618
774.078	1700
776.419	1684
778.758	1744
781.097	1712
783.435	1730
785.773	1744
788.11	1814
790.446	1814
792.781	1816
795.115	1824
797.449	1860
799.782	1892
802.115	1936
804.446	1944
806.777	1958
809.106	1980
811.435	2040
813.764	2002
816.091	2012
818.418	2112
820.743	2134
823.069	2138
825.393	2214
827.717	2180
830.039	2260
832.362	2326
834.683	2278
837.003	2288
839.324	2322
841.643	2392
843.961	2454
846.278	2476
848.594	2460
850.91	2558
853.227	2500
855.541	2538
857.855	2512
860.168	2672
862.48	2742
864.79	2714
867.101	2642
869.411	2736
871.721	2718
874.029	2750
876.336	2808
878.643	2774
880.95	2890
883.254	2866
885.559	2950
887.862	2914
890.166	2966
892.467	3010
894.77	3028
897.07	3094
899.371	3168
901.669	3140
903.968	3170
906.266	3182
908.563	3208
910.859	3252
913.154	3306
915.449	3312
917.742	3350
920.036	3488
922.329	3540
924.621	3412
926.911	3512
929.201	3482
931.49	3596
933.779	3580
936.068	3678
938.355	3766
940.64	3736
942.926	3766
945.212	3842
947.495	3864
949.779	3986
952.062	3928
954.344	4084
956.625	4040
958.905	4072
961.184	4164
963.464	4238
965.742	4240
968.02	4204
970.296	4332
972.572	4282
974.847	4490
977.121	4440
979.396	4524
981.669	4530
983.941	4516
986.212	4652
988.483	4562
990.753	4674
993.022	4716
995.29	4804
997.558	4838
999.825	4896
1002.09	4942
1004.36	4998
1006.62	5000
1008.89	5020
1011.15	5120
1013.41	5256
1015.67	5182
1017.93	5220
1020.19	5328
1022.45	5372
1024.71	5456
1026.97	5452
1029.23	5458
1031.49	5594
1033.74	5604
1036	5768
1038.25	5794
1040.5	5848
1042.76	5838
1045.01	6004
1047.26	5968
1049.51	6022
1051.76	6102
1054.01	6184
1056.26	6156
1058.51	6248
1060.75	6332
1063	6500
1065.25	6460
1067.49	6554
1069.73	6534
1071.98	6576
1074.22	6554
1076.46	6680
1078.7	6806
1080.94	6730
1083.18	6834
1085.42	6910
1087.66	6848
1089.9	6906
1092.14	7002
1094.37	7086
1096.61	7074
1098.84	7096
1101.08	7232
1103.31	7048
1105.54	7182
1107.77	7320
1110	7368
1112.23	7250
1114.46	7450
1116.69	7472
1118.92	7516
1121.15	7464
1123.37	7618
1125.6	7646
1127.83	7676
1130.05	7754
1132.27	7758
1134.5	7844
1136.72	7934
1138.94	7956
1141.16	7968
1143.38	8058
1145.6	8278
1147.82	8210
1150.04	8160
1152.26	8128
1154.47	8128
1156.69	8284
1158.9	8450
1161.12	8352
1163.33	8376
1165.54	8474
1167.76	8408
1169.97	8468
1172.18	8478
1174.39	8524
1176.6	8624
1178.81	8618
1181.02	8652
1183.22	8508
1185.43	8506
1187.63	8510
1189.84	8516
1192.04	8614
1194.25	8468
1196.45	8474
1198.65	8560
1200.85	8482
1203.05	8400
1205.25	8406
1207.45	8456
1209.65	8382
1211.85	8484
1214.05	8410
1216.24	8322
1218.44	8320
1220.64	8316
1222.83	8250
1225.02	8220
1227.22	8302
1229.41	8336
1231.6	8222
1233.79	8216
1235.98	8198
1238.17	8072
1240.36	8144
1242.55	7988
1244.73	8054
1246.92	8022
1249.11	8074
1251.29	8026
1253.48	7990
1255.66	7892
1257.84	7918
1260.03	7878
1262.21	7834
1264.39	7824
1266.57	7796
1268.75	7694
1270.93	7676
1273.11	7716
1275.28	7640
1277.46	7602
1279.64	7646
1281.81	7598
1283.98	7463.89
1286.16	7508.28
1288.33	7401.04
1290.5	7339
1292.68	7320.32
1294.85	7166.93
1297.02	7132.38
1299.19	7019.69
1301.36	7026.26
1303.53	6973.22
1305.69	7004.58
1307.86	6889.05
1310.03	6867.3
1312.19	6728.23
1314.36	6647.75
1316.52	6588.14
1318.68	6499.4
1320.85	6535.28
1323.01	6470.52
1325.17	6408.03
1327.33	6305.2
1329.49	6280.98
1331.65	6138.04
1333.81	6193.51
1335.97	6110.64
1338.12	6014.06
1340.28	5972.88
1342.44	5936.23
1344.59	5880.91
1346.75	5850.11
1348.9	5751.83
1351.05	5680.2
1353.2	5706.97
1355.36	5671.62
1357.51	5588.8
1359.66	5586.48
1361.81	5458.91
1363.96	5373.45
1366.1	5401.62
1368.25	5338.52
1370.4	5310.15
1372.54	5209.95
1374.69	5181.02
1376.83	5120.28
1378.98	5113.12
1381.12	5145.7
1383.26	5065.88
1385.41	5044.14
1387.55	4959.06
1389.69	4859.48
1391.83	4883.76
1393.02	4822
1395.17	4820
1397.32	4796
1399.47	4820
1401.62	4726
1403.77	4698
1405.91	4616
1408.06	4638
1410.2	4610
1412.35	4534
1414.49	4494
1416.63	4560
1418.78	4446
1420.92	4402
1423.06	4364
1425.2	4362
1427.34	4398
1429.48	4290
1431.61	4228
1433.75	4252
1435.89	4232
1438.02	4196
1440.16	4236
1442.3	4182
1444.43	4134
1446.56	4150
1448.7	4054
1450.83	4060
1452.96	4012
1455.09	4012
1457.22	3872
1459.35	4002
1461.48	3940
1463.61	3902
1465.73	3902
1467.86	3874
1469.98	3830
1472.11	3868
1474.24	3886
1476.36	3900
1478.48	3844
1480.6	3748
1482.73	3790
1484.85	3724
1486.97	3730
1489.09	3656
1491.21	3728
1493.33	3662
1495.44	3650
1497.56	3622
1499.68	3566
1501.79	3564
1503.91	3562
1506.02	3518
1508.14	3510
1510.25	3512
1512.36	3478
1514.48	3456
1516.59	3408
1518.7	3392
1520.81	3392
1522.92	3404
1525.02	3344
1527.13	3374
1529.24	3374
1531.35	3372
1533.45	3306
1535.56	3274
1537.66	3282
1539.77	3184
1541.87	3182
1543.97	3178
1546.08	3242
1548.18	3180
1550.28	3132
1552.38	3078
1554.48	3112
1556.57	3042
1558.67	3122
1560.77	3120
1562.87	3126
1564.96	3082
1567.06	3070
1569.15	3094
1571.25	3014
1573.34	3024
1575.43	3016
1577.53	3024
1579.62	3024
1581.71	3022
1583.8	2924
1585.89	2928
1587.98	2982
1590.06	2912
1592.15	2942
1594.24	2906
1596.33	2916
1598.41	2828
1600.5	2932
1602.58	2864
1604.66	2856
1606.75	2834
1608.83	2870
1610.91	2872
1612.99	2782
1615.07	2828
1617.15	2820
1619.23	2854
1621.31	2836
1623.39	2868
1625.46	2826
1627.54	2832
1629.62	2756
1631.69	2804
1633.77	2744
1635.84	2784
1637.91	2796
1639.99	2768
1642.06	2706
1644.13	2756
1646.2	2756
1648.27	2678
1650.34	2716
1652.41	2702
1654.47	2660
1656.54	2724
1658.61	2718
1660.67	2650
1662.74	2718
1664.81	2688
1666.87	2582
1668.93	2616
1671	2662
1673.06	2564
1675.12	2640
1677.18	2612
1679.24	2566
1681.3	2586
1683.36	2536
1685.42	2564
1687.47	2618
1689.53	2530
1691.59	2556
1693.64	2582
1695.7	2498
1697.75	2548
1699.81	2504
1701.86	2524
1703.91	2558
1705.97	2514
1708.02	2510
1710.07	2486
1712.12	2458
1714.17	2516
1716.22	2458
1718.26	2530
1720.31	2498
1722.36	2488
1724.4	2460
1726.45	2464
1728.49	2478
1730.54	2506
1732.58	2474
1734.63	2456
1736.67	2422
1738.71	2444
1740.75	2482
1742.79	2494
1744.83	2414
1746.87	2414
1748.91	2458
1750.95	2416
1752.98	2364
1755.02	2398
1757.06	2396
1759.09	2434
1761.13	2454
1763.16	2460
1765.19	2384
1767.23	2420
1769.26	2430
1771.29	2430
1773.32	2400
1775.35	2440
1777.38	2398
1779.41	2380
1781.44	2388
1783.47	2408
1785.49	2376
1787.52	2390
1789.55	2374
1791.57	2378
1793.6	2344
1795.62	2392
1797.64	2422
1799.67	2430
1801.69	2322
1803.71	2428
1805.73	2414
1807.75	2400
1809.77	2376
1811.79	2366
1813.81	2380
1815.83	2372
1817.84	2358
1819.86	2314
1821.88	2332
1823.89	2358
1825.91	2334
1827.92	2318
1829.93	2366
1831.95	2354
1833.96	2382
1835.97	2310
1837.98	2338
1839.99	2398
1842	2306
1844.01	2274
1846.02	2314
1848.03	2340
1850.03	2366
1852.04	2338
1854.05	2306
1856.05	2284
1858.06	2292
1860.06	2276
1862.06	2258
1864.07	2334
1866.07	2300
1868.07	2260
1870.07	2290
1872.07	2304
1874.07	2288
1876.07	2306
1878.07	2340
1880.07	2340
1882.07	2236
1884.06	2264
1886.06	2238
1888.05	2290
1890.05	2262
1892.04	2296
1894.04	2310
1896.03	2214
1898.02	2298
1900.01	2300
1902	2236
1903.99	2318
1905.98	2292
1907.97	2262
1909.96	2320
1911.95	2308
1913.94	2240
1915.93	2278
1917.91	2284
1919.9	2324
1921.88	2252
1923.87	2326
1925.85	2254
1927.83	2226
1929.82	2206
1931.8	2194
1933.78	2282
1935.76	2278
1937.74	2332
1939.72	2270
1941.7	2272
1943.68	2244
1945.65	2202
1947.63	2264
1949.61	2242
1951.58	2218
1953.56	2234
1955.53	2256
1957.51	2152
1959.48	2212
1961.45	2182
1963.43	2200
1965.4	2254
1967.37	2268
1969.34	2172
1971.31	2220
1973.28	2190
1975.25	2230
1977.22	2146
1979.18	2184
1981.15	2224
1983.12	2218
1985.08	2230
1987.05	2176
1989.01	2174
1990.97	2168
1992.94	2242
1994.9	2218
1996.86	2120
1998.82	2132
2000.78	2178
2002.74	2156
2004.7	2178
2006.66	2160
2008.62	2136
2010.58	2136
2012.54	2186
2014.49	2182
2016.45	2120
2018.4	2138
2020.36	2164
2022.31	2164
2024.27	2138
2026.22	2158
2028.17	2150
2030.12	2182
2032.07	2100
2034.03	2136
2035.98	2146
2037.93	2158
2039.87	2138
2041.82	2126
2043.77	2102
2045.72	2140
2047.66	2108
2049.61	2134
2051.55	2104
2053.5	2186
2055.44	2072
2057.39	2122
2059.33	2052
2061.27	2124
2063.21	2084
2065.15	2126
2067.09	2110
2069.03	2152
2070.97	2138
2072.91	2116
2074.85	2106
2076.79	2054
2078.73	2044
2080.66	2102
2082.6	2044
2084.53	2118
2086.47	2032
2088.4	2022
2090.33	2108
2092.27	2068
2094.2	2074
2096.13	2034
2098.06	2138
2099.99	2104
2101.92	2052
2103.85	2034
2105.78	2054
2107.71	2084
2109.64	2078
2111.56	2044
2113.49	2094
2115.41	2032
2117.34	2088
2119.26	2068
2121.19	2056
2123.11	2050
2125.03	2030
2126.96	2104
2128.88	2006
2130.8	2040
2132.72	2016
2134.64	2076
2136.56	2072
2138.48	1966
2140.4	2052
2142.31	2020
2144.23	2048
2146.15	2022
2148.06	2084
2149.98	2016
2151.89	2062
2153.81	2028
2155.72	2016
2157.63	2022
2159.55	2076
2161.46	1996
2163.37	2000
2165.28	2020
2167.19	2016
2169.1	1962
2171.01	1930
2172.91	1982
2174.82	2040
2176.73	1932
2178.64	1938
2180.54	1950
2182.45	1990
2184.35	1980
2186.26	1958
2188.16	2000
2190.06	1948
2191.96	1964
2193.87	1926
2195.77	1938
2197.67	1910
2199.57	1940
2201.47	1904
2203.37	1900
2205.27	2010
2207.16	1936
2209.06	1904
2210.96	1904
2212.85	1890
2214.75	1892
2216.64	1926
2218.54	1914
2220.43	1906
2222.33	1944
2224.22	1872.76
2226.11	1918.05
2228	1916.37
2229.89	1908.78
2231.78	1866.59
2233.67	1880.27
2235.56	1879.7
2237.45	1850.82
2239.34	1925.04
2241.23	1900.77
2243.11	1856.85
2245	1852.65
2246.89	1893.76
2248.77	1841.31
2250.66	1831.41
2252.54	1829.74
2254.42	1860.07
2256.31	1789.19
2258.19	1844.32
2260.07	1798.68
2261.95	1849.37
2263.83	1820.35
2265.71	1804.42
2267.59	1816.02
2269.47	1808.77
2271.35	1756.68
2273.23	1795.36
2275.1	1785.33
2276.98	1768.04
2278.86	1792.76
2280.73	1771.47
2282.61	1757.49
2284.48	1745.12
2286.36	1729.59
2288.23	1748.47
2290.1	1763.34
2291.98	1736.99
2293.85	1753.84
2295.72	1759.8
2297.59	1746.2
2299.46	1723.76
2301.33	1739.29
2303.2	1713.62
2305.06	1708.5
2306.93	1718.82
2308.8	1710.16
2310.67	1677.84
2312.53	1694.79
2314.4	1654.78
2316.26	1680.46
2317.62	1654
2319.5	1642
2321.37	1672
2323.24	1674
2325.12	1658
2326.99	1622
2328.86	1674
2330.73	1590
2332.6	1624
2334.47	1678
2336.34	1626
2338.2	1634
2340.07	1602
2341.94	1672
2343.81	1634
2345.67	1620
2347.54	1606
2349.4	1594
2351.27	1568
2353.13	1628
2354.99	1578
2356.86	1532
2358.72	1604
2360.58	1560
2362.44	1540
2364.3	1590
2366.16	1564
2368.02	1564
2369.88	1600
2371.74	1490
2373.6	1528
2375.45	1556
2377.31	1502
2379.17	1538
2381.02	1482
2382.88	1494
2384.73	1522
2386.58	1500
2388.44	1522
2390.29	1516
2392.14	1502
2393.99	1464
2395.85	1504
2397.7	1506
2399.55	1430
2401.4	1422
2403.25	1460
2405.09	1480
2406.94	1428
2408.79	1390
2410.63	1418
2412.48	1458
2414.33	1402
2416.17	1368
2418.02	1396
2419.86	1434
2421.7	1428
2423.55	1366
2425.39	1388
2427.23	1400
2429.07	1374
2430.91	1360
2432.75	1356
2434.59	1382
2436.43	1374
2438.27	1312
2440.11	1370
2441.95	1330
2443.78	1316
2445.62	1340
2447.46	1316
2449.29	1270
2451.13	1326
2452.96	1360
2454.79	1322
2456.63	1306
2458.46	1298
2460.29	1264
2462.12	1244
2463.95	1328
2465.78	1320
2467.61	1242
2469.44	1266
2471.27	1244
2473.1	1256
2474.93	1264
2476.76	1214
2478.58	1234
2480.41	1204
2482.23	1226
2484.06	1196
2485.88	1192
2487.71	1220
2489.53	1190
2491.35	1200
2493.18	1158
2495	1168
2496.82	1176
2498.64	1188
2500.46	1156
2502.28	1136
2504.1	1172
2505.92	1138
2507.74	1138
2509.55	1158
2511.37	1128
2513.19	1120
2515	1122
2516.82	1134
2518.63	1068
2520.45	1136
2522.26	1094
2524.07	1082
2525.89	1068
2527.7	1100
2529.51	1088
2531.32	1064
2533.13	1046
2534.94	1054
2536.75	1054
2538.56	1070
2540.37	1032
2542.18	1056
2543.98	1006
2545.79	1016
2547.6	1048
2549.4	986
2551.21	992
2553.01	1002
2554.82	970
2556.62	1008
2558.42	978
2560.23	964
2562.03	980
2563.83	970
2565.63	982
2567.43	996
2569.23	982
2571.03	876
2572.83	930
2574.63	920
2576.43	948
2578.22	972
2580.02	934
2581.82	938
2583.61	938
2585.41	902
2587.2	892
2589	912
2590.79	930
2592.58	900
2594.38	874
2596.17	880
2597.96	874
2599.75	868
2601.54	860
2603.33	886
2605.12	838
2606.91	854
2608.7	864
2610.49	818
2612.27	834
2614.06	824
2615.85	828
2617.63	826
2619.42	798
2621.2	814
2622.99	812
2624.77	778
2626.55	814
2628.34	780
2630.12	802
2631.9	826
2633.68	800
2635.46	778
2637.24	776
2639.02	798
2640.8	748
2642.58	766
2644.36	766
2646.14	780
2647.91	738
2649.69	728
2651.46	754
2653.24	738
2655.01	732
2656.79	794
2658.56	716
2660.34	750
2662.11	756
2663.88	734
2665.65	732
2667.42	746
2669.2	712
2670.96	692
2672.73	716
2674.5	734
2676.27	694
2678.04	698
2679.81	702
2681.58	706
2683.34	710
2685.11	666
2686.87	672
2688.64	674
2690.4	666
2692.17	674
2693.93	676
2695.69	674
2697.46	656
2699.22	644
2700.98	662
2702.74	654
2704.5	642
2706.26	646
2708.02	652
2709.78	626
2711.54	596
2713.3	636
2715.05	626
2716.81	646
2718.57	608
2720.32	580
2722.08	584
2723.83	596
2725.59	606
2727.34	580
2729.09	574
2730.85	574
2732.6	572
2734.35	590
2736.1	586
2737.85	570
2739.6	568
2741.35	548
2743.1	582
2744.85	580
2746.6	528
2748.35	578
2750.09	542
2751.84	540
2753.59	530
2755.33	538
2757.08	554
2758.82	552
2760.57	530
2762.31	514
2764.05	520
2765.79	496
2767.54	500
2769.28	512
2771.02	504
2772.76	466
2774.5	502
2776.24	504
2777.98	478
2779.72	484
2781.46	500
2783.19	506
2784.93	468
2786.67	486
2788.4	476
2790.14	490
2791.87	440
2793.61	488
2795.34	478
2797.07	460
2798.81	456
2800.54	450
2802.27	438
2804	448
2805.74	472
2807.47	448
2809.2	472
2810.93	444
2812.65	470
2814.38	458
2816.11	436
2817.84	412
2819.56	430
2821.29	430
2823.02	400
2824.74	414
2826.47	422
2828.19	426
2829.92	366
2831.64	420
2833.36	402
2835.09	392
2836.81	422
2838.53	384
2840.25	378
2841.97	394
2843.69	372
2845.41	390
2847.13	382
2848.85	374
2850.57	372
2852.28	382
2854	370
2855.72	380
2857.43	364
2859.15	378
2860.86	364
2862.58	338
2864.29	370
2866.01	352
2867.72	330
2869.43	340
2871.14	362
2872.86	352
2874.57	334
2876.28	356
2877.99	352
2879.7	336
2881.41	350
2883.11	336
2884.82	316
2886.53	348
2888.24	338
2889.94	336
2891.65	338
2893.36	324
2895.06	302
2896.77	314
2898.47	328
2900.17	332
2901.88	308
2903.58	326
2905.28	314
2906.98	320
2908.69	330
2910.39	296
2912.09	316
2913.79	300
2915.49	286
2917.19	322
2918.88	294
2920.58	308
2922.28	296
2923.98	298
2925.67	290
2927.37	282
2929.06	284
2930.76	280
2932.45	278
2934.15	276
2935.84	268
2937.53	286
2939.23	274
2940.92	296
2942.61	266
2944.3	278
2945.99	276
2947.68	296
2949.37	264
2951.06	262
2952.75	278
2954.44	266
2956.12	262
2957.81	274
2959.5	244
2961.18	260
2962.87	250
2964.56	260
2966.24	254
2967.92	272
2969.61	260
2971.29	254
2972.97	248
2974.66	254
2976.34	226
2978.02	246
2979.7	248
2981.38	244
2983.06	242
2984.74	242
2986.42	250
2988.1	250
2989.78	228
2991.45	228
2993.13	232
2994.81	260
2996.48	228
2998.16	218
2999.83	242