File: muestras/papalo/leaf_13.txt
#Acq. time (s)=	10
#Accumulations=	1
#Range (cm-¹)=	200...3000
#Windows=	3
#Autofocus=	Off
#AutoExposure=	Off
#Spike filter=	Off
#Delay time (s)=	0
#Binning=	1
#Readout mode=	Signal
#DeNoise=	Off
#ICS correction=	Off
#Dark correction=	Off
#Inst. Process=	Off
#Instrument=	LabRAM HR Evol
#Detector=	Syncerity OE
#Objective=	x100_VIS
#Grating=	600 (500nm)
#ND Filter=	0.01%
#Laser=	633nm_Edge
#Hole=	100.021
#Range=	Visible
#Project=	Omar
#Sample=	03-07-23
#Site=	papal
#Title=	leaf
#Remark=
#Date=	03.07.2023 17:04
#Acquired=	03.07.2023 17:04:30
201.713	94
204.247	112
206.778	106
209.311	118
211.84	128
214.371	110
216.899	112
219.428	124
221.955	118
224.482	122
227.007	128
229.531	134
232.055	122
234.579	118
237.1	124
239.621	140
242.141	136
244.661	126
247.179	126
249.698	138
252.215	134
254.731	136
257.246	134
259.761	140
262.273	146
264.786	122
267.298	134
269.809	148
272.319	150
274.828	152
277.336	154
279.844	142
282.351	164
284.855	164
287.361	162
289.866	152
292.368	166
294.871	170
297.372	176
299.873	176
302.372	184
304.872	168
307.37	184
309.866	190
312.364	182
314.859	186
317.353	190
319.848	184
322.341	196
324.833	182
327.324	202
329.814	188
332.304	184
334.792	204
337.28	196
339.767	202
342.254	218
344.739	224
347.224	210
349.708	218
352.191	218
354.673	214
357.155	250
359.634	230
362.114	252
364.593	242
367.07	232
369.548	246
372.024	228
374.499	238
376.974	244
379.447	256
381.92	242
384.392	252
386.864	262
389.333	252
391.802	256
394.272	276
396.739	270
399.206	282
401.673	272
404.138	294
406.602	296
409.066	260
411.528	288
413.99	270
416.451	278
418.911	312
421.371	296
423.83	300
426.288	324
428.745	340
431.201	328
433.657	332
436.111	342
438.565	328
441.017	344
443.469	340
445.921	350
448.37	348
450.821	354
453.27	358
455.717	358
458.165	348
460.61	372
463.056	358
465.5	372
467.945	372
470.387	380
472.829	372
475.271	392
477.711	392
480.15	402
482.589	398
485.027	404
487.465	392
489.901	414
492.337	404
494.771	430
497.205	426
499.638	422
502.07	434
504.502	436
506.933	418
509.363	448
511.792	452
514.219	472
516.647	452
519.073	444
521.5	448
523.924	464
526.348	446
528.772	482
531.194	488
533.616	476
536.036	456
538.457	464
540.875	472
543.294	500
545.712	518
548.128	502
550.545	532
552.959	530
555.373	558
557.788	536
560.2	560
562.612	534
565.023	538
567.433	560
569.843	546
572.251	568
574.659	570
577.066	562
579.472	588
581.878	594
584.283	608
586.687	614
589.09	606
591.493	596
593.893	626
596.294	640
598.694	632
601.093	648
603.491	674
605.889	676
608.285	654
610.682	670
613.076	664
615.471	682
617.864	690
620.256	720
622.648	712
625.039	718
627.429	752
629.819	756
632.208	768
634.595	780
636.982	802
639.369	780
641.755	798
644.139	824
646.523	784
648.906	838
651.288	868
653.67	820
656.051	816
658.429	856
660.808	838
663.187	872
665.565	882
667.942	882
670.317	878
672.692	934
675.067	948
677.44	938
679.813	1002
682.184	948
684.556	944
686.926	964
689.296	1000
691.664	1012
694.033	1018
696.4	1012
698.766	1068
701.133	1040
703.497	1056
705.861	1026
708.224	1094
710.586	1118
712.949	1134
715.31	1144
717.67	1144
720.029	1180
722.388	1178
724.746	1194
727.103	1206
729.458	1212
731.814	1216
734.168	1238
736.523	1278
738.876	1272
741.227	1294
743.579	1318
745.931	1310
748.28	1286
750.629	1362
752.977	1342
755.325	1390
757.672	1428
760.018	1418
762.363	1470
764.708	1422
767.052	1452
769.394	1454
771.737	1506
774.078	1492
776.419	1512
778.758	1528
781.097	1594
783.435	1610
785.773	1604
788.11	1606
790.446	1672
792.781	1672
795.115	1716
797.449	1718
799.782	1736
802.115	1780
804.446	1818
806.777	1832
809.106	1842
811.435	1896
813.764	1854
816.091	1916
818.418	2024
820.743	1964
823.069	2012
825.393	2020
827.717	2084
830.039	2106
832.362	2044
834.683	2084
837.003	2112
839.324	2186
841.643	2190
843.961	2238
846.278	2306
848.594	2294
850.91	2272
853.227	2364
855.541	2346
857.855	2404
860.168	2390
862.48	2402
864.79	2462
867.101	2536
869.411	2574
871.721	2604
874.029	2598
876.336	2572
878.643	2560
880.95	2682
883.254	2692
885.559	2704
887.862	2694
890.166	2750
892.467	2798
894.77	2814
897.07	2842
899.371	2956
901.669	2942
903.968	2908
906.266	3000
908.563	3018
910.859	3012
913.154	3074
915.449	3180
917.742	3128
920.036	3194
922.329	3230
924.621	3230
926.911	3338
929.201	3348
931.49	3290
933.779	3394
936.068	3464
938.355	3498
940.64	3500
942.926	3470
945.212	3598
947.495	3722
949.779	3604
952.062	3804
954.344	3720
956.625	3832
958.905	3830
961.184	3906
963.464	3944
965.742	3934
968.02	4000
970.296	4028
972.572	4116
974.847	4130
977.121	4226
979.396	4246
981.669	4226
983.941	4336
986.212	4384
988.483	4402
990.753	4390
993.022	4434
995.29	4512
997.558	4466
999.825	4596
1002.09	4700
1004.36	4714
1006.62	4728
1008.89	4792
1011.15	4824
1013.41	4850
1015.67	4970
1017.93	5020
1020.19	5086
1022.45	5074
1024.71	5132
1026.97	5126
1029.23	5280
1031.49	5308
1033.74	5358
1036	5384
1038.25	5526
1040.5	5588
1042.76	5586
1045.01	5658
1047.26	5710
1049.51	5686
1051.76	5814
1054.01	5918
1056.26	6018
1058.51	5984
1060.75	6142
1063	6076
1065.25	6218
1067.49	6316
1069.73	6264
1071.98	6316
1074.22	6356
1076.46	6316
1078.7	6390
1080.94	6438
1083.18	6498
1085.42	6560
1087.66	6580
1089.9	6604
1092.14	6690
1094.37	6702
1096.61	6840
1098.84	6802
1101.08	6766
1103.31	6924
1105.54	6918
1107.77	7048
1110	7054
1112.23	6958
1114.46	7172
1116.69	7080
1118.92	7108
1121.15	7212
1123.37	7118
1125.6	7422
1127.83	7332
1130.05	7380
1132.27	7456
1134.5	7512
1136.72	7504
1138.94	7574
1141.16	7624
1143.38	7688
1145.6	7678
1147.82	7730
1150.04	7636
1152.26	7748
1154.47	7882
1156.69	7814
1158.9	7860
1161.12	8008
1163.33	7870
1165.54	7938
1167.76	8124
1169.97	8146
1172.18	8116
1174.39	8050
1176.6	8102
1178.81	8038
1181.02	8034
1183.22	8130
1185.43	8128
1187.63	8004
1189.84	8068
1192.04	8080
1194.25	8100
1196.45	8078
1198.65	7966
1200.85	8014
1203.05	7982
1205.25	7838
1207.45	7870
1209.65	7972
1211.85	7906
1214.05	7926
1216.24	7840
1218.44	7736
1220.64	7854
1222.83	7788
1225.02	7622
1227.22	7776
1229.41	7586
1231.6	7608
1233.79	7608
1235.98	7602
1238.17	7502
1240.36	7562
1242.55	7548
1244.73	7408
1246.92	7450
1249.11	7366
1251.29	7396
1253.48	7336
1255.66	7274
1257.84	7434
1260.03	7322
1262.21	7166
1264.39	7236
1266.57	7140
1268.75	7026
1270.93	7118
1273.11	7072
1275.28	7094
1277.46	6882
1279.64	6972
1281.81	6952
1283.98	6801.06
1286.16	6798.27
1288.33	6728.78
1290.5	6724.58
1292.68	6630.21
1294.85	6615.13
1297.02	6556.24
1299.19	6516.56
1301.36	6498.42
1303.53	6363.65
1305.69	6268.81
1307.86	6306
1310.03	6200.55
1312.19	6216.54
1314.36	6170.1
1316.52	6048.24
1318.68	5944.76
1320.85	5974.67
1323.01	5902.57
1325.17	5828.69
1327.33	5782.58
1329.49	5731.56
1331.65	5706.53
1333.81	5670.93
1335.97	5552.65
1338.12	5516.36
1340.28	5485.41
1342.44	5482.55
1344.59	5352.99
1346.75	5308.23
1348.9	5315.54
1351.05	5216.77
1353.2	5174.59
1355.36	5163.99
1357.51	5108.63
1359.66	5044.01
1361.81	5005.93
1363.96	4970.91
1366.1	4913.78
1368.25	4966.56
1370.4	4865.19
1372.54	4822.95
1374.69	4805.57
1376.83	4813.95
1378.98	4752.79
1381.12	4588.16
1383.26	4676.12
1385.41	4591.11
1387.55	4551.38
1389.69	4502.8
1391.83	4453.49
1393.02	4422
1395.17	4362
1397.32	4360
1399.47	4372
1401.62	4266
1403.77	4292
1405.91	4254
1408.06	4156
1410.2	4140
1412.35	4122
1414.49	4106
1416.63	4038
1418.78	4054
1420.92	3926
1423.06	3974
1425.2	4022
1427.34	3912
1429.48	3874
1431.61	3848
1433.75	3870
1435.89	3752
1438.02	3780
1440.16	3886
1442.3	3802
1444.43	3728
1446.56	3728
1448.7	3716
1450.83	3748
1452.96	3674
1455.09	3654
1457.22	3682
1459.35	3582
1461.48	3570
1463.61	3590
1465.73	3510
1467.86	3526
1469.98	3516
1472.11	3534
1474.24	3468
1476.36	3468
1478.48	3432
1480.6	3388
1482.73	3442
1484.85	3412
1486.97	3404
1489.09	3384
1491.21	3332
1493.33	3316
1495.44	3310
1497.56	3228
1499.68	3300
1501.79	3236
1503.91	3216
1506.02	3246
1508.14	3160
1510.25	3152
1512.36	3092
1514.48	3146
1516.59	3168
1518.7	3118
1520.81	3086
1522.92	3048
1525.02	3036
1527.13	3026
1529.24	2976
1531.35	3026
1533.45	2964
1535.56	2940
1537.66	2858
1539.77	2950
1541.87	2914
1543.97	2842
1546.08	2932
1548.18	2800
1550.28	2878
1552.38	2812
1554.48	2864
1556.57	2836
1558.67	2782
1560.77	2818
1562.87	2714
1564.96	2792
1567.06	2770
1569.15	2734
1571.25	2768
1573.34	2794
1575.43	2670
1577.53	2654
1579.62	2650
1581.71	2652
1583.8	2680
1585.89	2740
1587.98	2608
1590.06	2630
1592.15	2642
1594.24	2618
1596.33	2564
1598.41	2522
1600.5	2640
1602.58	2612
1604.66	2648
1606.75	2562
1608.83	2602
1610.91	2580
1612.99	2620
1615.07	2544
1617.15	2528
1619.23	2562
1621.31	2548
1623.39	2530
1625.46	2480
1627.54	2492
1629.62	2494
1631.69	2460
1633.77	2434
1635.84	2554
1637.91	2448
1639.99	2428
1642.06	2436
1644.13	2500
1646.2	2430
1648.27	2432
1650.34	2396
1652.41	2448
1654.47	2486
1656.54	2408
1658.61	2384
1660.67	2398
1662.74	2386
1664.81	2320
1666.87	2378
1668.93	2394
1671	2358
1673.06	2404
1675.12	2322
1677.18	2356
1679.24	2306
1681.3	2346
1683.36	2262
1685.42	2372
1687.47	2292
1689.53	2308
1691.59	2254
1693.64	2352
1695.7	2332
1697.75	2262
1699.81	2282
1701.86	2290
1703.91	2282
1705.97	2256
1708.02	2228
1710.07	2246
1712.12	2270
1714.17	2196
1716.22	2196
1718.26	2232
1720.31	2226
1722.36	2232
1724.4	2224
1726.45	2252
1728.49	2192
1730.54	2248
1732.58	2180
1734.63	2208
1736.67	2222
1738.71	2222
1740.75	2234
1742.79	2192
1744.83	2170
1746.87	2172
1748.91	2176
1750.95	2216
1752.98	2150
1755.02	2166
1757.06	2182
1759.09	2220
1761.13	2174
1763.16	2206
1765.19	2128
1767.23	2210
1769.26	2190
1771.29	2174
1773.32	2190
1775.35	2174
1777.38	2104
1779.41	2138
1781.44	2166
1783.47	2204
1785.49	2188
1787.52	2190
1789.55	2176
1791.57	2158
1793.6	2146
1795.62	2134
1797.64	2170
1799.67	2132
1801.69	2186
1803.71	2130
1805.73	2212
1807.75	2128
1809.77	2122
1811.79	2148
1813.81	2132
1815.83	2164
1817.84	2138
1819.86	2150
1821.88	2112
1823.89	2102
1825.91	2118
1827.92	2132
1829.93	2112
1831.95	2134
1833.96	2130
1835.97	2094
1837.98	2088
1839.99	2094
1842	2088
1844.01	2102
1846.02	2106
1848.03	2084
1850.03	2136
1852.04	2084
1854.05	2070
1856.05	2068
1858.06	2058
1860.06	2078
1862.06	2072
1864.07	2106
1866.07	2070
1868.07	2114
1870.07	2042
1872.07	2114
1874.07	2030
1876.07	2076
1878.07	2086
1880.07	2092
1882.07	2052
1884.06	2104
1886.06	2046
1888.05	2090
1890.05	2038
1892.04	2106
1894.04	2126
1896.03	2112
1898.02	2082
1900.01	2088
1902	2126
1903.99	2030
1905.98	2078
1907.97	2088
1909.96	2034
1911.95	2094
1913.94	2044
1915.93	2024
1917.91	2048
1919.9	2058
1921.88	2036
1923.87	2080
1925.85	2054
1927.83	2040
1929.82	2060
1931.8	2074
1933.78	2036
1935.76	2064
1937.74	2096
1939.72	2026
1941.7	2058
1943.68	2114
1945.65	2062
1947.63	2058
1949.61	2014
1951.58	2100
1953.56	2060
1955.53	2034
1957.51	2066
1959.48	2090
1961.45	2048
1963.43	2014
1965.4	2000
1967.37	2074
1969.34	2006
1971.31	2060
1973.28	2028
1975.25	2008
1977.22	2026
1979.18	2018
1981.15	2056
1983.12	2018
1985.08	2006
1987.05	2110
1989.01	1970
1990.97	2032
1992.94	1926
1994.9	2072
1996.86	2062
1998.82	1982
2000.78	2044
2002.74	2044
2004.7	2034
2006.66	1988
2008.62	2028
2010.58	2012
2012.54	2002
2014.49	1992
2016.45	2070
2018.4	2016
2020.36	2008
2022.31	2000
2024.27	1950
2026.22	2002
2028.17	1996
2030.12	2018
2032.07	1998
2034.03	2046
2035.98	1966
2037.93	1994
2039.87	2010
2041.82	1988
2043.77	1988
2045.72	2004
2047.66	1968
2049.61	1986
2051.55	1992
2053.5	2024
2055.44	1956
2057.39	1992
2059.33	2004
2061.27	1986
2063.21	2008
2065.15	1980
2067.09	1960
2069.03	1946
2070.97	1926
2072.91	1956
2074.85	1994
2076.79	2024
2078.73	1994
2080.66	2002
2082.6	1962
2084.53	1928
2086.47	2002
2088.4	1908
2090.33	1964
2092.27	2000
2094.2	1958
2096.13	1958
2098.06	1968
2099.99	1952
2101.92	1946
2103.85	1958
2105.78	1946
2107.71	1970
2109.64	1934
2111.56	2004
2113.49	1940
2115.41	1938
2117.34	1980
2119.26	1928
2121.19	1930
2123.11	1944
2125.03	1926
2126.96	1966
2128.88	1968
2130.8	1928
2132.72	1950
2134.64	1972
2136.56	1892
2138.48	1946
2140.4	1960
2142.31	1908
2144.23	1940
2146.15	1892
2148.06	1944
2149.98	1922
2151.89	1904
2153.81	1912
2155.72	1898
2157.63	1888
2159.55	1948
2161.46	1870
2163.37	1900
2165.28	1896
2167.19	1882
2169.1	1876
2171.01	1940
2172.91	1914
2174.82	1912
2176.73	1810
2178.64	1882
2180.54	1886
2182.45	1896
2184.35	1898
2186.26	1908
2188.16	1894
2190.06	1894
2191.96	1884
2193.87	1894
2195.77	1914
2197.67	1846
2199.57	1838
2201.47	1862
2203.37	1824
2205.27	1864
2207.16	1802
2209.06	1868
2210.96	1862
2212.85	1846
2214.75	1848
2216.64	1850
2218.54	1806
2220.43	1836
2222.33	1860
2224.22	1872.53
2226.11	1818.87
2228	1855.15
2229.89	1818.13
2231.78	1809.65
2233.67	1823.86
2235.56	1846.99
2237.45	1781.96
2239.34	1868.76
2241.23	1817.78
2243.11	1822.01
2245	1808.76
2246.89	1789.25
2248.77	1817.13
2250.66	1810.78
2252.54	1819.42
2254.42	1801.62
2256.31	1795.67
2258.19	1806.49
2260.07	1791.86
2261.95	1809.31
2263.83	1797.23
2265.71	1791.29
2267.59	1764.9
2269.47	1790.23
2271.35	1811.95
2273.23	1763.58
2275.1	1780.02
2276.98	1782.76
2278.86	1780
2280.73	1745.73
2282.61	1745.34
2284.48	1747.11
2286.36	1749.51
2288.23	1741.19
2290.1	1730.38
2291.98	1756.62
2293.85	1708.2
2295.72	1733.64
2297.59	1729.26
2299.46	1727.35
2301.33	1735.19
2303.2	1720.06
2305.06	1675
2306.93	1712.22
2308.8	1685.68
2310.67	1671.71
2312.53	1720.34
2314.4	1704.21
2316.26	1660.9
2317.62	1706
2319.5	1708
2321.37	1728
2323.24	1678
2325.12	1648
2326.99	1678
2328.86	1656
2330.73	1680
2332.6	1660
2334.47	1648
2336.34	1628
2338.2	1668
2340.07	1656
2341.94	1708
2343.81	1608
2345.67	1658
2347.54	1660
2349.4	1636
2351.27	1586
2353.13	1640
2354.99	1638
2356.86	1594
2358.72	1598
2360.58	1604
2362.44	1550
2364.3	1596
2366.16	1596
2368.02	1578
2369.88	1572
2371.74	1562
2373.6	1602
2375.45	1582
2377.31	1580
2379.17	1528
2381.02	1592
2382.88	1592
2384.73	1552
2386.58	1582
2388.44	1558
2390.29	1508
2392.14	1486
2393.99	1538
2395.85	1508
2397.7	1556
2399.55	1530
2401.4	1498
2403.25	1462
2405.09	1480
2406.94	1464
2408.79	1482
2410.63	1488
2412.48	1478
2414.33	1500
2416.17	1484
2418.02	1454
2419.86	1466
2421.7	1432
2423.55	1446
2425.39	1444
2427.23	1404
2429.07	1438
2430.91	1388
2432.75	1398
2434.59	1394
2436.43	1424
2438.27	1384
2440.11	1392
2441.95	1410
2443.78	1372
2445.62	1388
2447.46	1404
2449.29	1366
2451.13	1386
2452.96	1356
2454.79	1360
2456.63	1354
2458.46	1354
2460.29	1336
2462.12	1292
2463.95	1340
2465.78	1340
2467.61	1330
2469.44	1292
2471.27	1284
2473.1	1310
2474.93	1314
2476.76	1280
2478.58	1266
2480.41	1260
2482.23	1254
2484.06	1284
2485.88	1252
2487.71	1236
2489.53	1266
2491.35	1286
2493.18	1234
2495	1226
2496.82	1248
2498.64	1192
2500.46	1192
2502.28	1196
2504.1	1176
2505.92	1196
2507.74	1194
2509.55	1250
2511.37	1188
2513.19	1182
2515	1138
2516.82	1156
2518.63	1120
2520.45	1142
2522.26	1170
2524.07	1140
2525.89	1136
2527.7	1106
2529.51	1124
2531.32	1140
2533.13	1106
2534.94	1112
2536.75	1126
2538.56	1106
2540.37	1114
2542.18	1118
2543.98	1084
2545.79	1056
2547.6	1068
2549.4	1074
2551.21	1070
2553.01	1034
2554.82	1052
2556.62	1054
2558.42	1016
2560.23	1042
2562.03	1084
2563.83	1016
2565.63	998
2567.43	1000
2569.23	1002
2571.03	1048
2572.83	966
2574.63	994
2576.43	990
2578.22	1004
2580.02	982
2581.82	968
2583.61	956
2585.41	964
2587.2	970
2589	950
2590.79	958
2592.58	956
2594.38	914
2596.17	932
2597.96	944
2599.75	910
2601.54	936
2603.33	926
2605.12	926
2606.91	898
2608.7	914
2610.49	872
2612.27	892
2614.06	900
2615.85	916
2617.63	914
2619.42	890
2621.2	890
2622.99	896
2624.77	854
2626.55	862
2628.34	860
2630.12	866
2631.9	842
2633.68	872
2635.46	818
2637.24	856
2639.02	830
2640.8	848
2642.58	814
2644.36	802
2646.14	846
2647.91	824
2649.69	806
2651.46	836
2653.24	824
2655.01	810
2656.79	778
2658.56	794
2660.34	784
2662.11	772
2663.88	818
2665.65	772
2667.42	766
2669.2	792
2670.96	778
2672.73	786
2674.5	762
2676.27	724
2678.04	760
2679.81	790
2681.58	760
2683.34	758
2685.11	756
2686.87	744
2688.64	730
2690.4	734
2692.17	752
2693.93	720
2695.69	720
2697.46	742
2699.22	694
2700.98	718
2702.74	670
2704.5	724
2706.26	708
2708.02	684
2709.78	666
2711.54	674
2713.3	698
2715.05	684
2716.81	646
2718.57	686
2720.32	650
2722.08	630
2723.83	656
2725.59	638
2727.34	642
2729.09	662
2730.85	638
2732.6	646
2734.35	638
2736.1	590
2737.85	610
2739.6	574
2741.35	594
2743.1	614
2744.85	596
2746.6	602
2748.35	594
2750.09	594
2751.84	574
2753.59	580
2755.33	612
2757.08	590
2758.82	590
2760.57	598
2762.31	584
2764.05	602
2765.79	546
2767.54	556
2769.28	570
2771.02	546
2772.76	566
2774.5	542
2776.24	538
2777.98	542
2779.72	526
2781.46	530
2783.19	530
2784.93	526
2786.67	550
2788.4	514
2790.14	526
2791.87	554
2793.61	526
2795.34	504
2797.07	480
2798.81	512
2800.54	490
2802.27	536
2804	496
2805.74	506
2807.47	504
2809.2	510
2810.93	470
2812.65	486
2814.38	470
2816.11	470
2817.84	468
2819.56	468
2821.29	460
2823.02	446
2824.74	466
2826.47	466
2828.19	466
2829.92	448
2831.64	458
2833.36	478
2835.09	444
2836.81	434
2838.53	432
2840.25	444
2841.97	450
2843.69	406
2845.41	422
2847.13	428
2848.85	406
2850.57	404
2852.28	428
2854	436
2855.72	416
2857.43	396
2859.15	392
2860.86	410
2862.58	398
2864.29	396
2866.01	410
2867.72	412
2869.43	372
2871.14	382
2872.86	382
2874.57	376
2876.28	382
2877.99	378
2879.7	368
2881.41	380
2883.11	376
2884.82	362
2886.53	358
2888.24	354
2889.94	364
2891.65	346
2893.36	364
2895.06	360
2896.77	366
2898.47	368
2900.17	334
2901.88	358
2903.58	346
2905.28	368
2906.98	354
2908.69	354
2910.39	350
2912.09	340
2913.79	326
2915.49	354
2917.19	332
2918.88	314
2920.58	332
2922.28	318
2923.98	342
2925.67	318
2927.37	330
2929.06	308
2930.76	320
2932.45	308
2934.15	294
2935.84	302
2937.53	324
2939.23	314
2940.92	312
2942.61	282
2944.3	320
2945.99	324
2947.68	308
2949.37	298
2951.06	314
2952.75	284
2954.44	306
2956.12	292
2957.81	298
2959.5	310
2961.18	280
2962.87	286
2964.56	274
2966.24	318
2967.92	296
2969.61	282
2971.29	288
2972.97	296
2974.66	286
2976.34	284
2978.02	274
2979.7	252
2981.38	272
2983.06	262
2984.74	278
2986.42	292
2988.1	264
2989.78	254
2991.45	272
2993.13	250
2994.81	260
2996.48	260
2998.16	278
2999.83	278