File: muestras/papalo/leaf_100x_04.txt
#Acq. time (s)=	10
#Accumulations=	1
#Range (cm-¹)=	200...3000
#Windows=	3
#Autofocus=	Off
#AutoExposure=	Off
#Spike filter=	Off
#Delay time (s)=	0
#Binning=	1
#Readout mode=	Signal
#DeNoise=	Off
#ICS correction=	Off
#Dark correction=	Off
#Inst. Process=	Off
#Instrument=	LabRAM HR Evol
#Detector=	Syncerity OE
#Objective=	x100_VIS
#Grating=	600 (500nm)
#ND Filter=	0.01%
#Laser=	633nm_Edge
#Hole=	100.021
#Range=	Visible
#Project=	Omar
#Sample=	03-07-23
#Site=	papal
#Title=	leaf_100x
#Remark=
#Date=	03.07.2023 17:13
#Acquired=	03.07.2023 17:13:15
201.713	74
204.247	74
206.778	82
209.311	80
211.84	74
214.371	90
216.899	86
219.428	88
221.955	82
224.482	92
227.007	94
229.531	88
232.055	92
234.579	100
237.1	94
239.621	94
242.141	100
244.661	98
247.179	98
249.698	88
252.215	90
254.731	80
257.246	102
259.761	98
262.273	94
264.786	92
267.298	100
269.809	114
272.319	96
274.828	108
277.336	104
279.844	116
282.351	106
284.855	108
287.361	108
289.866	106
292.368	112
294.871	126
297.372	120
299.873	124
302.372	120
304.872	114
307.37	132
309.866	122
312.364	132
314.859	130
317.353	124
319.848	132
322.341	136
324.833	132
327.324	148
329.814	144
332.304	138
334.792	152
337.28	154
339.767	134
342.254	140
344.739	134
347.224	164
349.708	150
352.191	148
354.673	148
357.155	150
359.634	156
362.114	162
364.593	164
367.07	156
369.548	158
372.024	178
374.499	180
376.974	166
379.447	182
381.92	172
384.392	170
386.864	178
389.333	188
391.802	188
394.272	190
396.739	172
399.206	198
401.673	194
404.138	188
406.602	202
409.066	202
411.528	202
413.99	202
416.451	210
418.911	192
421.371	218
423.83	196
426.288	198
428.745	214
431.201	224
433.657	224
436.111	216
438.565	224
441.017	232
443.469	224
445.921	222
448.37	256
450.821	220
453.27	262
455.717	236
458.165	254
460.61	244
463.056	252
465.5	258
467.945	240
470.387	270
472.829	254
475.271	268
477.711	280
480.15	274
482.589	266
485.027	266
487.465	286
489.901	278
492.337	282
494.771	290
497.205	278
499.638	306
502.07	308
504.502	280
506.933	308
509.363	304
511.792	304
514.219	320
516.647	312
519.073	314
521.5	334
523.924	310
526.348	312
528.772	314
531.194	324
533.616	340
536.036	350
538.457	336
540.875	330
543.294	352
545.712	352
548.128	344
550.545	340
552.959	340
555.373	358
557.788	362
560.2	392
562.612	374
565.023	398
567.433	380
569.843	344
572.251	398
574.659	390
577.066	404
579.472	402
581.878	416
584.283	434
586.687	420
589.09	418
591.493	432
593.893	438
596.294	428
598.694	450
601.093	432
603.491	458
605.889	446
608.285	448
610.682	460
613.076	446
615.471	438
617.864	498
620.256	486
622.648	476
625.039	474
627.429	526
629.819	498
632.208	498
634.595	550
636.982	518
639.369	530
641.755	550
644.139	550
646.523	562
648.906	546
651.288	588
653.67	592
656.051	598
658.429	610
660.808	592
663.187	620
665.565	610
667.942	626
670.317	598
672.692	646
675.067	656
677.44	644
679.813	674
682.184	668
684.556	660
686.926	710
689.296	704
691.664	688
694.033	712
696.4	730
698.766	724
701.133	728
703.497	722
705.861	732
708.224	768
710.586	786
712.949	774
715.31	794
717.67	832
720.029	780
722.388	844
724.746	864
727.103	888
729.458	864
731.814	878
734.168	856
736.523	880
738.876	882
741.227	882
743.579	902
745.931	964
748.28	978
750.629	974
752.977	976
755.325	968
757.672	956
760.018	1004
762.363	1044
764.708	1060
767.052	1066
769.394	1008
771.737	1072
774.078	1058
776.419	1066
778.758	1132
781.097	1138
783.435	1162
785.773	1160
788.11	1176
790.446	1156
792.781	1200
795.115	1210
797.449	1200
799.782	1240
802.115	1246
804.446	1252
806.777	1334
809.106	1334
811.435	1312
813.764	1342
816.091	1310
818.418	1358
820.743	1394
823.069	1408
825.393	1404
827.717	1462
830.039	1488
832.362	1542
834.683	1588
837.003	1552
839.324	1552
841.643	1580
843.961	1632
846.278	1678
848.594	1652
850.91	1650
853.227	1700
855.541	1736
857.855	1728
860.168	1758
862.48	1788
864.79	1804
867.101	1812
869.411	1820
871.721	1880
874.029	1882
876.336	1984
878.643	1906
880.95	1954
883.254	1994
885.559	2018
887.862	2082
890.166	2052
892.467	2058
894.77	2112
897.07	2108
899.371	2152
901.669	2148
903.968	2130
906.266	2170
908.563	2188
910.859	2222
913.154	2294
915.449	2328
917.742	2324
920.036	2332
922.329	2324
924.621	2350
926.911	2454
929.201	2428
931.49	2420
933.779	2476
936.068	2508
938.355	2508
940.64	2570
942.926	2602
945.212	2692
947.495	2644
949.779	2742
952.062	2782
954.344	2806
956.625	2748
958.905	2776
961.184	2860
963.464	2898
965.742	2906
968.02	2976
970.296	3020
972.572	3068
974.847	3052
977.121	3062
979.396	3054
981.669	3228
983.941	3202
986.212	3214
988.483	3248
990.753	3280
993.022	3364
995.29	3300
997.558	3380
999.825	3410
1002.09	3398
1004.36	3472
1006.62	3466
1008.89	3510
1011.15	3602
1013.41	3656
1015.67	3694
1017.93	3732
1020.19	3698
1022.45	3766
1024.71	3840
1026.97	3898
1029.23	3860
1031.49	3876
1033.74	3994
1036	4102
1038.25	4116
1040.5	4180
1042.76	4164
1045.01	4228
1047.26	4160
1049.51	4246
1051.76	4356
1054.01	4362
1056.26	4402
1058.51	4448
1060.75	4536
1063	4470
1065.25	4608
1067.49	4580
1069.73	4608
1071.98	4634
1074.22	4682
1076.46	4676
1078.7	4818
1080.94	4804
1083.18	4786
1085.42	4882
1087.66	4884
1089.9	4880
1092.14	4960
1094.37	4952
1096.61	5020
1098.84	5010
1101.08	5024
1103.31	5048
1105.54	5108
1107.77	5128
1110	5166
1112.23	5182
1114.46	5242
1116.69	5222
1118.92	5272
1121.15	5260
1123.37	5338
1125.6	5372
1127.83	5364
1130.05	5404
1132.27	5462
1134.5	5474
1136.72	5392
1138.94	5590
1141.16	5620
1143.38	5548
1145.6	5578
1147.82	5598
1150.04	5680
1152.26	5654
1154.47	5690
1156.69	5744
1158.9	5740
1161.12	5744
1163.33	5748
1165.54	5776
1167.76	5762
1169.97	5746
1172.18	5782
1174.39	5744
1176.6	5778
1178.81	5782
1181.02	5770
1183.22	5814
1185.43	5766
1187.63	5786
1189.84	5782
1192.04	5736
1194.25	5626
1196.45	5648
1198.65	5704
1200.85	5706
1203.05	5642
1205.25	5714
1207.45	5444
1209.65	5578
1211.85	5586
1214.05	5438
1216.24	5550
1218.44	5496
1220.64	5436
1222.83	5382
1225.02	5400
1227.22	5296
1229.41	5242
1231.6	5266
1233.79	5174
1235.98	5268
1238.17	5198
1240.36	5184
1242.55	5036
1244.73	5092
1246.92	5076
1249.11	5022
1251.29	5054
1253.48	5022
1255.66	4952
1257.84	4996
1260.03	4834
1262.21	4860
1264.39	4784
1266.57	4854
1268.75	4688
1270.93	4792
1273.11	4634
1275.28	4638
1277.46	4694
1279.64	4524
1281.81	4614
1283.98	4480.42
1286.16	4427.27
1288.33	4373.86
1290.5	4329.56
1292.68	4190.62
1294.85	4196.11
1297.02	4186.3
1299.19	4122.52
1301.36	4088.12
1303.53	4058.02
1305.69	3969.57
1307.86	3920.44
1310.03	3935.76
1312.19	3872.54
1314.36	3748.64
1316.52	3744.19
1318.68	3637.25
1320.85	3615.17
1323.01	3561.09
1325.17	3506.07
1327.33	3481.76
1329.49	3453.34
1331.65	3406.81
1333.81	3376.97
1335.97	3295.08
1338.12	3241.29
1340.28	3198.9
1342.44	3152.18
1344.59	3128.98
1346.75	3118.95
1348.9	3092.44
1351.05	3043.55
1353.2	2953
1355.36	2969.34
1357.51	2867.8
1359.66	2854.77
1361.81	2841.34
1363.96	2812.13
1366.1	2759.34
1368.25	2761.1
1370.4	2650.73
1372.54	2669.94
1374.69	2602.56
1376.83	2610.02
1378.98	2483.5
1381.12	2503.96
1383.26	2508.52
1385.41	2436.29
1387.55	2400
1389.69	2410.5
1391.83	2340.81
1393.02	2382
1395.17	2352
1397.32	2270
1399.47	2302
1401.62	2290
1403.77	2280
1405.91	2240
1408.06	2208
1410.2	2240
1412.35	2204
1414.49	2184
1416.63	2150
1418.78	2114
1420.92	2120
1423.06	2072
1425.2	2072
1427.34	2046
1429.48	2048
1431.61	2012
1433.75	2010
1435.89	1974
1438.02	1936
1440.16	2010
1442.3	1968
1444.43	1942
1446.56	1976
1448.7	1832
1450.83	1984
1452.96	1918
1455.09	1892
1457.22	1908
1459.35	1828
1461.48	1828
1463.61	1854
1465.73	1832
1467.86	1778
1469.98	1760
1472.11	1750
1474.24	1830
1476.36	1768
1478.48	1762
1480.6	1712
1482.73	1700
1484.85	1704
1486.97	1720
1489.09	1750
1491.21	1658
1493.33	1678
1495.44	1696
1497.56	1642
1499.68	1644
1501.79	1606
1503.91	1632
1506.02	1638
1508.14	1618
1510.25	1626
1512.36	1598
1514.48	1598
1516.59	1584
1518.7	1554
1520.81	1554
1522.92	1530
1525.02	1470
1527.13	1536
1529.24	1500
1531.35	1502
1533.45	1480
1535.56	1488
1537.66	1460
1539.77	1414
1541.87	1424
1543.97	1460
1546.08	1406
1548.18	1408
1550.28	1464
1552.38	1408
1554.48	1444
1556.57	1378
1558.67	1394
1560.77	1374
1562.87	1400
1564.96	1392
1567.06	1364
1569.15	1362
1571.25	1336
1573.34	1340
1575.43	1342
1577.53	1330
1579.62	1306
1581.71	1322
1583.8	1292
1585.89	1328
1587.98	1340
1590.06	1326
1592.15	1330
1594.24	1314
1596.33	1296
1598.41	1248
1600.5	1266
1602.58	1294
1604.66	1276
1606.75	1280
1608.83	1254
1610.91	1232
1612.99	1268
1615.07	1256
1617.15	1222
1619.23	1248
1621.31	1278
1623.39	1234
1625.46	1216
1627.54	1224
1629.62	1240
1631.69	1212
1633.77	1222
1635.84	1200
1637.91	1234
1639.99	1256
1642.06	1216
1644.13	1222
1646.2	1176
1648.27	1180
1650.34	1202
1652.41	1196
1654.47	1148
1656.54	1190
1658.61	1152
1660.67	1142
1662.74	1182
1664.81	1174
1666.87	1218
1668.93	1142
1671	1152
1673.06	1128
1675.12	1104
1677.18	1132
1679.24	1158
1681.3	1120
1683.36	1124
1685.42	1124
1687.47	1146
1689.53	1106
1691.59	1104
1693.64	1106
1695.7	1094
1697.75	1120
1699.81	1068
1701.86	1070
1703.91	1050
1705.97	1086
1708.02	1074
1710.07	1092
1712.12	1100
1714.17	1080
1716.22	1032
1718.26	1106
1720.31	1090
1722.36	1096
1724.4	1090
1726.45	1062
1728.49	1080
1730.54	1060
1732.58	1034
1734.63	1034
1736.67	1078
1738.71	1032
1740.75	1088
1742.79	1050
1744.83	1034
1746.87	1056
1748.91	1070
1750.95	1028
1752.98	1058
1755.02	1050
1757.06	1048
1759.09	1042
1761.13	1026
1763.16	1040
1765.19	1022
1767.23	1048
1769.26	1020
1771.29	1036
1773.32	1042
1775.35	1038
1777.38	1052
1779.41	1064
1781.44	1050
1783.47	1070
1785.49	984
1787.52	1028
1789.55	1016
1791.57	1004
1793.6	996
1795.62	1000
1797.64	1014
1799.67	1012
1801.69	1008
1803.71	1054
1805.73	974
1807.75	1024
1809.77	1006
1811.79	1064
1813.81	1002
1815.83	1034
1817.84	1018
1819.86	976
1821.88	1032
1823.89	992
1825.91	1004
1827.92	1020
1829.93	966
1831.95	984
1833.96	996
1835.97	974
1837.98	988
1839.99	988
1842	986
1844.01	978
1846.02	984
1848.03	1008
1850.03	1000
1852.04	966
1854.05	980
1856.05	978
1858.06	984
1860.06	990
1862.06	1006
1864.07	1000
1866.07	976
1868.07	984
1870.07	1002
1872.07	1008
1874.07	982
1876.07	968
1878.07	942
1880.07	1002
1882.07	946
1884.06	986
1886.06	950
1888.05	936
1890.05	976
1892.04	930
1894.04	966
1896.03	950
1898.02	974
1900.01	958
1902	984
1903.99	958
1905.98	920
1907.97	948
1909.96	966
1911.95	946
1913.94	942
1915.93	930
1917.91	946
1919.9	916
1921.88	954
1923.87	960
1925.85	926
1927.83	958
1929.82	1004
1931.8	948
1933.78	972
1935.76	944
1937.74	978
1939.72	966
1941.7	922
1943.68	1014
1945.65	940
1947.63	944
1949.61	940
1951.58	966
1953.56	918
1955.53	950
1957.51	900
1959.48	934
1961.45	950
1963.43	926
1965.4	922
1967.37	940
1969.34	938
1971.31	948
1973.28	904
1975.25	936
1977.22	932
1979.18	912
1981.15	928
1983.12	912
1985.08	962
1987.05	920
1989.01	918
1990.97	926
1992.94	904
1994.9	922
1996.86	930
1998.82	942
2000.78	916
2002.74	922
2004.7	908
2006.66	934
2008.62	916
2010.58	886
2012.54	928
2014.49	884
2016.45	918
2018.4	904
2020.36	900
2022.31	916
2024.27	864
2026.22	896
2028.17	920
2030.12	882
2032.07	906
2034.03	894
2035.98	910
2037.93	926
2039.87	902
2041.82	912
2043.77	906
2045.72	916
2047.66	894
2049.61	916
2051.55	916
2053.5	874
2055.44	902
2057.39	848
2059.33	894
2061.27	896
2063.21	898
2065.15	886
2067.09	882
2069.03	886
2070.97	850
2072.91	892
2074.85	872
2076.79	910
2078.73	844
2080.66	874
2082.6	870
2084.53	884
2086.47	894
2088.4	892
2090.33	874
2092.27	858
2094.2	870
2096.13	876
2098.06	898
2099.99	872
2101.92	870
2103.85	880
2105.78	874
2107.71	878
2109.64	876
2111.56	848
2113.49	866
2115.41	862
2117.34	872
2119.26	884
2121.19	886
2123.11	882
2125.03	892
2126.96	890
2128.88	844
2130.8	878
2132.72	862
2134.64	846
2136.56	856
2138.48	878
2140.4	878
2142.31	846
2144.23	862
2146.15	890
2148.06	846
2149.98	860
2151.89	824
2153.81	844
2155.72	864
2157.63	862
2159.55	838
2161.46	876
2163.37	862
2165.28	868
2167.19	832
2169.1	834
2171.01	842
2172.91	822
2174.82	842
2176.73	862
2178.64	826
2180.54	840
2182.45	840
2184.35	826
2186.26	832
2188.16	840
2190.06	818
2191.96	800
2193.87	818
2195.77	822
2197.67	854
2199.57	780
2201.47	824
2203.37	808
2205.27	818
2207.16	792
2209.06	822
2210.96	812
2212.85	832
2214.75	834
2216.64	810
2218.54	794
2220.43	810
2222.33	802
2224.22	814.484
2226.11	835.718
2228	784.774
2229.89	772.983
2231.78	790.73
2233.67	785.04
2235.56	786.966
2237.45	802.522
2239.34	795.851
2241.23	781.596
2243.11	799.556
2245	754.298
2246.89	768.59
2248.77	771.465
2250.66	763.357
2252.54	757.214
2254.42	782.374
2256.31	774.047
2258.19	780.597
2260.07	744.009
2261.95	742.067
2263.83	721.471
2265.71	744.825
2267.59	769.954
2269.47	738.632
2271.35	742.852
2273.23	735.737
2275.1	732.746
2276.98	732.113
2278.86	736.747
2280.73	720.315
2282.61	741.202
2284.48	722.071
2286.36	709.1
2288.23	717.365
2290.1	708.65
2291.98	715.808
2293.85	701.136
2295.72	723.296
2297.59	705.23
2299.46	698.731
2301.33	687.572
2303.2	682.732
2305.06	697.946
2306.93	672.51
2308.8	662.567
2310.67	685.878
2312.53	660.764
2314.4	680.036
2316.26	678.003
2317.62	678
2319.5	670
2321.37	648
2323.24	664
2325.12	666
2326.99	684
2328.86	654
2330.73	662
2332.6	668
2334.47	636
2336.34	708
2338.2	654
2340.07	652
2341.94	660
2343.81	648
2345.67	618
2347.54	634
2349.4	642
2351.27	632
2353.13	658
2354.99	646
2356.86	620
2358.72	640
2360.58	638
2362.44	626
2364.3	634
2366.16	622
2368.02	624
2369.88	610
2371.74	594
2373.6	618
2375.45	590
2377.31	598
2379.17	602
2381.02	580
2382.88	616
2384.73	618
2386.58	614
2388.44	594
2390.29	610
2392.14	602
2393.99	614
2395.85	624
2397.7	560
2399.55	584
2401.4	610
2403.25	582
2405.09	580
2406.94	562
2408.79	558
2410.63	584
2412.48	586
2414.33	580
2416.17	552
2418.02	542
2419.86	576
2421.7	570
2423.55	578
2425.39	596
2427.23	588
2429.07	560
2430.91	546
2432.75	550
2434.59	562
2436.43	580
2438.27	536
2440.11	566
2441.95	536
2443.78	536
2445.62	520
2447.46	528
2449.29	544
2451.13	512
2452.96	526
2454.79	522
2456.63	530
2458.46	522
2460.29	510
2462.12	516
2463.95	498
2465.78	522
2467.61	500
2469.44	522
2471.27	476
2473.1	488
2474.93	482
2476.76	488
2478.58	496
2480.41	504
2482.23	492
2484.06	482
2485.88	496
2487.71	496
2489.53	476
2491.35	496
2493.18	482
2495	480
2496.82	484
2498.64	460
2500.46	482
2502.28	484
2504.1	470
2505.92	434
2507.74	456
2509.55	444
2511.37	446
2513.19	432
2515	450
2516.82	444
2518.63	440
2520.45	450
2522.26	446
2524.07	444
2525.89	472
2527.7	440
2529.51	430
2531.32	422
2533.13	450
2534.94	416
2536.75	414
2538.56	432
2540.37	426
2542.18	418
2543.98	422
2545.79	438
2547.6	426
2549.4	410
2551.21	402
2553.01	384
2554.82	382
2556.62	418
2558.42	396
2560.23	400
2562.03	408
2563.83	398
2565.63	380
2567.43	402
2569.23	386
2571.03	382
2572.83	390
2574.63	386
2576.43	370
2578.22	390
2580.02	382
2581.82	366
2583.61	376
2585.41	360
2587.2	352
2589	382
2590.79	352
2592.58	378
2594.38	360
2596.17	386
2597.96	354
2599.75	358
2601.54	354
2603.33	362
2605.12	378
2606.91	372
2608.7	360
2610.49	348
2612.27	350
2614.06	322
2615.85	348
2617.63	354
2619.42	346
2621.2	338
2622.99	340
2624.77	356
2626.55	326
2628.34	322
2630.12	332
2631.9	332
2633.68	326
2635.46	332
2637.24	328
2639.02	296
2640.8	332
2642.58	334
2644.36	318
2646.14	308
2647.91	314
2649.69	312
2651.46	318
2653.24	310
2655.01	316
2656.79	310
2658.56	308
2660.34	290
2662.11	326
2663.88	298
2665.65	282
2667.42	312
2669.2	312
2670.96	276
2672.73	310
2674.5	306
2676.27	294
2678.04	272
2679.81	288
2681.58	286
2683.34	308
2685.11	292
2686.87	288
2688.64	302
2690.4	290
2692.17	284
2693.93	286
2695.69	282
2697.46	280
2699.22	270
2700.98	274
2702.74	264
2704.5	258
2706.26	276
2708.02	264
2709.78	266
2711.54	264
2713.3	262
2715.05	252
2716.81	262
2718.57	260
2720.32	246
2722.08	248
2723.83	248
2725.59	264
2727.34	238
2729.09	270
2730.85	238
2732.6	250
2734.35	222
2736.1	246
2737.85	242
2739.6	234
2741.35	224
2743.1	250
2744.85	238
2746.6	206
2748.35	230
2750.09	242
2751.84	242
2753.59	226
2755.33	224
2757.08	234
2758.82	232
2760.57	226
2762.31	238
2764.05	230
2765.79	218
2767.54	220
2769.28	214
2771.02	220
2772.76	212
2774.5	194
2776.24	228
2777.98	214
2779.72	218
2781.46	200
2783.19	200
2784.93	194
2786.67	202
2788.4	210
2790.14	202
2791.87	206
2793.61	202
2795.34	204
2797.07	198
2798.81	204
2800.54	182
2802.27	182
2804	188
2805.74	218
2807.47	206
2809.2	196
2810.93	180
2812.65	188
2814.38	192
2816.11	190
2817.84	172
2819.56	188
2821.29	180
2823.02	182
2824.74	166
2826.47	172
2828.19	178
2829.92	180
2831.64	186
2833.36	176
2835.09	182
2836.81	158
2838.53	170
2840.25	168
2841.97	174
2843.69	180
2845.41	152
2847.13	178
2848.85	170
2850.57	170
2852.28	168
2854	184
2855.72	156
2857.43	150
2859.15	154
2860.86	152
2862.58	160
2864.29	168
2866.01	152
2867.72	156
2869.43	146
2871.14	144
2872.86	126
2874.57	154
2876.28	158
2877.99	142
2879.7	138
2881.41	144
2883.11	138
2884.82	148
2886.53	128
2888.24	142
2889.94	142
2891.65	162
2893.36	144
2895.06	142
2896.77	136
2898.47	122
2900.17	144
2901.88	146
2903.58	144
2905.28	134
2906.98	142
2908.69	130
2910.39	132
2912.09	138
2913.79	132
2915.49	128
2917.19	132
2918.88	128
2920.58	126
2922.28	134
2923.98	130
2925.67	132
2927.37	120
2929.06	136
2930.76	124
2932.45	128
2934.15	132
2935.84	120
2937.53	126
2939.23	132
2940.92	116
2942.61	122
2944.3	120
2945.99	108
2947.68	120
2949.37	130
2951.06	110
2952.75	118
2954.44	118
2956.12	120
2957.81	114
2959.5	104
2961.18	118
2962.87	114
2964.56	96
2966.24	124
2967.92	108
2969.61	122
2971.29	116
2972.97	116
2974.66	112
2976.34	122
2978.02	118
2979.7	102
2981.38	100
2983.06	98
2984.74	112
2986.42	108
2988.1	110
2989.78	108
2991.45	108
2993.13	94
2994.81	98
2996.48	88
2998.16	108
2999.83	100