File: muestras/papalo/leaf_100x_10.txt
#Acq. time (s)=	10
#Accumulations=	1
#Range (cm-¹)=	200...3000
#Windows=	3
#Autofocus=	Off
#AutoExposure=	Off
#Spike filter=	Off
#Delay time (s)=	0
#Binning=	1
#Readout mode=	Signal
#DeNoise=	Off
#ICS correction=	Off
#Dark correction=	Off
#Inst. Process=	Off
#Instrument=	LabRAM HR Evol
#Detector=	Syncerity OE
#Objective=	x100_VIS
#Grating=	600 (500nm)
#ND Filter=	0.1%
#Laser=	633nm_Edge
#Hole=	100.021
#Range=	Visible
#Project=	Omar
#Sample=	03-07-23
#Site=	papal
#Title=	leaf_100x
#Remark=
#Date=	03.07.2023 17:19
#Acquired=	03.07.2023 17:19:25
201.713	146
204.247	156
206.778	150
209.311	156
211.84	146
214.371	152
216.899	154
219.428	154
221.955	162
224.482	178
227.007	162
229.531	184
232.055	178
234.579	168
237.1	178
239.621	200
242.141	180
244.661	180
247.179	196
249.698	182
252.215	202
254.731	180
257.246	198
259.761	202
262.273	204
264.786	194
267.298	204
269.809	216
272.319	208
274.828	206
277.336	206
279.844	208
282.351	228
284.855	206
287.361	234
289.866	234
292.368	218
294.871	214
297.372	252
299.873	240
302.372	248
304.872	254
307.37	262
309.866	242
312.364	266
314.859	250
317.353	274
319.848	262
322.341	264
324.833	276
327.324	278
329.814	288
332.304	298
334.792	256
337.28	280
339.767	278
342.254	306
344.739	298
347.224	326
349.708	292
352.191	316
354.673	320
357.155	330
359.634	344
362.114	346
364.593	312
367.07	348
369.548	348
372.024	350
374.499	360
376.974	358
379.447	358
381.92	394
384.392	344
386.864	362
389.333	342
391.802	410
394.272	388
396.739	376
399.206	400
401.673	408
404.138	382
406.602	412
409.066	422
411.528	416
413.99	430
416.451	440
418.911	416
421.371	414
423.83	450
426.288	466
428.745	490
431.201	430
433.657	480
436.111	476
438.565	488
441.017	500
443.469	516
445.921	502
448.37	516
450.821	506
453.27	538
455.717	492
458.165	502
460.61	516
463.056	488
465.5	548
467.945	536
470.387	550
472.829	568
475.271	566
477.711	604
480.15	600
482.589	554
485.027	596
487.465	566
489.901	600
492.337	600
494.771	608
497.205	624
499.638	604
502.07	606
504.502	640
506.933	646
509.363	638
511.792	658
514.219	656
516.647	654
519.073	676
521.5	672
523.924	658
526.348	674
528.772	688
531.194	684
533.616	716
536.036	712
538.457	716
540.875	708
543.294	742
545.712	702
548.128	752
550.545	800
552.959	768
555.373	782
557.788	762
560.2	786
562.612	806
565.023	858
567.433	822
569.843	852
572.251	798
574.659	836
577.066	840
579.472	890
581.878	886
584.283	854
586.687	864
589.09	874
591.493	924
593.893	910
596.294	932
598.694	948
601.093	946
603.491	940
605.889	952
608.285	1000
610.682	986
613.076	1042
615.471	1006
617.864	1060
620.256	1034
622.648	1064
625.039	1052
627.429	1076
629.819	1090
632.208	1094
634.595	1180
636.982	1146
639.369	1176
641.755	1108
644.139	1178
646.523	1156
648.906	1230
651.288	1194
653.67	1234
656.051	1230
658.429	1230
660.808	1256
663.187	1288
665.565	1268
667.942	1298
670.317	1332
672.692	1376
675.067	1348
677.44	1416
679.813	1380
682.184	1370
684.556	1442
686.926	1412
689.296	1402
691.664	1456
694.033	1490
696.4	1442
698.766	1478
701.133	1532
703.497	1504
705.861	1564
708.224	1556
710.586	1610
712.949	1582
715.31	1640
717.67	1590
720.029	1650
722.388	1666
724.746	1754
727.103	1750
729.458	1748
731.814	1776
734.168	1862
736.523	1876
738.876	1878
741.227	1884
743.579	1906
745.931	1942
748.28	1954
750.629	1958
752.977	1990
755.325	1978
757.672	2090
760.018	2042
762.363	2126
764.708	2118
767.052	2136
769.394	2154
771.737	2188
774.078	2222
776.419	2238
778.758	2308
781.097	2240
783.435	2346
785.773	2330
788.11	2332
790.446	2364
792.781	2438
795.115	2432
797.449	2486
799.782	2558
802.115	2536
804.446	2606
806.777	2566
809.106	2702
811.435	2696
813.764	2754
816.091	2754
818.418	2774
820.743	2808
823.069	2882
825.393	2934
827.717	2980
830.039	2908
832.362	3004
834.683	3030
837.003	3106
839.324	3194
841.643	3142
843.961	3222
846.278	3262
848.594	3300
850.91	3362
853.227	3402
855.541	3318
857.855	3474
860.168	3508
862.48	3578
864.79	3564
867.101	3660
869.411	3692
871.721	3788
874.029	3634
876.336	3774
878.643	3868
880.95	3832
883.254	3806
885.559	3884
887.862	4012
890.166	4048
892.467	4020
894.77	4098
897.07	4094
899.371	4154
901.669	4230
903.968	4200
906.266	4270
908.563	4282
910.859	4362
913.154	4490
915.449	4596
917.742	4474
920.036	4634
922.329	4618
924.621	4622
926.911	4772
929.201	4754
931.49	4922
933.779	4858
936.068	5000
938.355	5018
940.64	5056
942.926	5112
945.212	5130
947.495	5278
949.779	5248
952.062	5394
954.344	5352
956.625	5482
958.905	5508
961.184	5548
963.464	5594
965.742	5746
968.02	5768
970.296	5726
972.572	5816
974.847	5884
977.121	6004
979.396	6084
981.669	6050
983.941	6130
986.212	6090
988.483	6192
990.753	6306
993.022	6288
995.29	6472
997.558	6460
999.825	6530
1002.09	6676
1004.36	6668
1006.62	6736
1008.89	6724
1011.15	6902
1013.41	6926
1015.67	7024
1017.93	7080
1020.19	7174
1022.45	7242
1024.71	7274
1026.97	7354
1029.23	7442
1031.49	7474
1033.74	7626
1036	7698
1038.25	7842
1040.5	7732
1042.76	7956
1045.01	8052
1047.26	8024
1049.51	8182
1051.76	8234
1054.01	8370
1056.26	8394
1058.51	8422
1060.75	8548
1063	8598
1065.25	8654
1067.49	8752
1069.73	8906
1071.98	8976
1074.22	9018
1076.46	9106
1078.7	9096
1080.94	9052
1083.18	9248
1085.42	9270
1087.66	9294
1089.9	9374
1092.14	9420
1094.37	9494
1096.61	9514
1098.84	9648
1101.08	9572
1103.31	9664
1105.54	9810
1107.77	9780
1110	9940
1112.23	10092
1114.46	9978
1116.69	10040
1118.92	10200
1121.15	10182
1123.37	10352
1125.6	10268
1127.83	10352
1130.05	10398
1132.27	10502
1134.5	10454
1136.72	10656
1138.94	10704
1141.16	10842
1143.38	10816
1145.6	10976
1147.82	10982
1150.04	10966
1152.26	10948
1154.47	11124
1156.69	11210
1158.9	11204
1161.12	11310
1163.33	11230
1165.54	11396
1167.76	11302
1169.97	11372
1172.18	11508
1174.39	11418
1176.6	11324
1178.81	11442
1181.02	11412
1183.22	11394
1185.43	11402
1187.63	11384
1189.84	11368
1192.04	11520
1194.25	11414
1196.45	11400
1198.65	11436
1200.85	11434
1203.05	11234
1205.25	11282
1207.45	11316
1209.65	11164
1211.85	11274
1214.05	11168
1216.24	11274
1218.44	11240
1220.64	11188
1222.83	11096
1225.02	11068
1227.22	11104
1229.41	10916
1231.6	10988
1233.79	10940
1235.98	10930
1238.17	10984
1240.36	10954
1242.55	10816
1244.73	10740
1246.92	10592
1249.11	10680
1251.29	10628
1253.48	10618
1255.66	10530
1257.84	10572
1260.03	10520
1262.21	10548
1264.39	10426
1266.57	10314
1268.75	10236
1270.93	10342
1273.11	10238
1275.28	10152
1277.46	10104
1279.64	9972
1281.81	9978
1283.98	9915.85
1286.16	9817.92
1288.33	9618.42
1290.5	9733.32
1292.68	9539.74
1294.85	9501.19
1297.02	9464.04
1299.19	9299.34
1301.36	9180.71
1303.53	9149.43
1305.69	9022.5
1307.86	8911.82
1310.03	8858.78
1312.19	8733.91
1314.36	8743.27
1316.52	8639.67
1318.68	8486.18
1320.85	8461.09
1323.01	8364.42
1325.17	8224.46
1327.33	8210.64
1329.49	8199.57
1331.65	8021.11
1333.81	7996.91
1335.97	7930.39
1338.12	7804.08
1340.28	7755.8
1342.44	7672.17
1344.59	7554.41
1346.75	7530.62
1348.9	7444.38
1351.05	7382.61
1353.2	7300.4
1355.36	7378.07
1357.51	7106.77
1359.66	7094.2
1361.81	7100.39
1363.96	6888.56
1366.1	6964.49
1368.25	6802.32
1370.4	6721.2
1372.54	6693.54
1374.69	6653.3
1376.83	6513.25
1378.98	6442.74
1381.12	6407.6
1383.26	6409.56
1385.41	6322.56
1387.55	6268.84
1389.69	6135.61
1391.83	6107.05
1393.02	6104
1395.17	6070
1397.32	6094
1399.47	5994
1401.62	5834
1403.77	5878
1405.91	5812
1408.06	5828
1410.2	5810
1412.35	5720
1414.49	5692
1416.63	5680
1418.78	5608
1420.92	5482
1423.06	5484
1425.2	5512
1427.34	5478
1429.48	5452
1431.61	5396
1433.75	5276
1435.89	5274
1438.02	5216
1440.16	5210
1442.3	5254
1444.43	5068
1446.56	5088
1448.7	5126
1450.83	5064
1452.96	5000
1455.09	5008
1457.22	4946
1459.35	4892
1461.48	4928
1463.61	4944
1465.73	4846
1467.86	4796
1469.98	4878
1472.11	4838
1474.24	4770
1476.36	4810
1478.48	4800
1480.6	4724
1482.73	4674
1484.85	4670
1486.97	4584
1489.09	4568
1491.21	4602
1493.33	4540
1495.44	4522
1497.56	4510
1499.68	4424
1501.79	4512
1503.91	4460
1506.02	4428
1508.14	4324
1510.25	4368
1512.36	4300
1514.48	4372
1516.59	4300
1518.7	4240
1520.81	4258
1522.92	4216
1525.02	4202
1527.13	4172
1529.24	4142
1531.35	4146
1533.45	4030
1535.56	4036
1537.66	4096
1539.77	4086
1541.87	3922
1543.97	3936
1546.08	3930
1548.18	3896
1550.28	3976
1552.38	3828
1554.48	3894
1556.57	3848
1558.67	3828
1560.77	3774
1562.87	3826
1564.96	3804
1567.06	3804
1569.15	3834
1571.25	3770
1573.34	3682
1575.43	3788
1577.53	3712
1579.62	3698
1581.71	3652
1583.8	3676
1585.89	3608
1587.98	3620
1590.06	3622
1592.15	3516
1594.24	3644
1596.33	3612
1598.41	3616
1600.5	3548
1602.58	3608
1604.66	3592
1606.75	3600
1608.83	3616
1610.91	3608
1612.99	3560
1615.07	3524
1617.15	3512
1619.23	3534
1621.31	3464
1623.39	3428
1625.46	3434
1627.54	3546
1629.62	3438
1631.69	3470
1633.77	3456
1635.84	3514
1637.91	3386
1639.99	3412
1642.06	3366
1644.13	3402
1646.2	3354
1648.27	3390
1650.34	3354
1652.41	3346
1654.47	3352
1656.54	3278
1658.61	3258
1660.67	3258
1662.74	3264
1664.81	3290
1666.87	3280
1668.93	3224
1671	3276
1673.06	3248
1675.12	3140
1677.18	3214
1679.24	3182
1681.3	3226
1683.36	3236
1685.42	3196
1687.47	3114
1689.53	3124
1691.59	3128
1693.64	3146
1695.7	3134
1697.75	3090
1699.81	3066
1701.86	3058
1703.91	3070
1705.97	3140
1708.02	3178
1710.07	3130
1712.12	3114
1714.17	3136
1716.22	3062
1718.26	2970
1720.31	3114
1722.36	3126
1724.4	3044
1726.45	3032
1728.49	3018
1730.54	3030
1732.58	3030
1734.63	3006
1736.67	2982
1738.71	2968
1740.75	2994
1742.79	2964
1744.83	2992
1746.87	3062
1748.91	2956
1750.95	2998
1752.98	3020
1755.02	2992
1757.06	2974
1759.09	2976
1761.13	2982
1763.16	3008
1765.19	2988
1767.23	2922
1769.26	2948
1771.29	2962
1773.32	2960
1775.35	3014
1777.38	2948
1779.41	3032
1781.44	2954
1783.47	2888
1785.49	2968
1787.52	2920
1789.55	2904
1791.57	2944
1793.6	2934
1795.62	2918
1797.64	2948
1799.67	2966
1801.69	2836
1803.71	2974
1805.73	2930
1807.75	2954
1809.77	2874
1811.79	2876
1813.81	2934
1815.83	2852
1817.84	2872
1819.86	2854
1821.88	2902
1823.89	2830
1825.91	2858
1827.92	2916
1829.93	2798
1831.95	2854
1833.96	2912
1835.97	2878
1837.98	2882
1839.99	2894
1842	2852
1844.01	2820
1846.02	2896
1848.03	2856
1850.03	2806
1852.04	2854
1854.05	2778
1856.05	2778
1858.06	2856
1860.06	2786
1862.06	2814
1864.07	2868
1866.07	2812
1868.07	2796
1870.07	2756
1872.07	2762
1874.07	2840
1876.07	2840
1878.07	2784
1880.07	2786
1882.07	2738
1884.06	2792
1886.06	2774
1888.05	2770
1890.05	2770
1892.04	2792
1894.04	2832
1896.03	2782
1898.02	2770
1900.01	2780
1902	2792
1903.99	2802
1905.98	2838
1907.97	2790
1909.96	2786
1911.95	2812
1913.94	2764
1915.93	2806
1917.91	2808
1919.9	2748
1921.88	2792
1923.87	2802
1925.85	2730
1927.83	2820
1929.82	2736
1931.8	2764
1933.78	2802
1935.76	2718
1937.74	2750
1939.72	2754
1941.7	2700
1943.68	2760
1945.65	2706
1947.63	2772
1949.61	2826
1951.58	2724
1953.56	2734
1955.53	2710
1957.51	2744
1959.48	2700
1961.45	2674
1963.43	2678
1965.4	2748
1967.37	2678
1969.34	2710
1971.31	2686
1973.28	2694
1975.25	2680
1977.22	2630
1979.18	2646
1981.15	2660
1983.12	2696
1985.08	2714
1987.05	2672
1989.01	2596
1990.97	2654
1992.94	2614
1994.9	2664
1996.86	2668
1998.82	2652
2000.78	2664
2002.74	2640
2004.7	2612
2006.66	2608
2008.62	2644
2010.58	2696
2012.54	2584
2014.49	2660
2016.45	2634
2018.4	2690
2020.36	2632
2022.31	2594
2024.27	2570
2026.22	2694
2028.17	2612
2030.12	2632
2032.07	2662
2034.03	2602
2035.98	2590
2037.93	2530
2039.87	2626
2041.82	2594
2043.77	2560
2045.72	2572
2047.66	2614
2049.61	2606
2051.55	2636
2053.5	2566
2055.44	2586
2057.39	2616
2059.33	2552
2061.27	2568
2063.21	2572
2065.15	2586
2067.09	2562
2069.03	2552
2070.97	2596
2072.91	2566
2074.85	2574
2076.79	2606
2078.73	2580
2080.66	2560
2082.6	2578
2084.53	2652
2086.47	2556
2088.4	2562
2090.33	2566
2092.27	2564
2094.2	2460
2096.13	2530
2098.06	2600
2099.99	2622
2101.92	2554
2103.85	2514
2105.78	2498
2107.71	2540
2109.64	2538
2111.56	2552
2113.49	2526
2115.41	2542
2117.34	2588
2119.26	2532
2121.19	2514
2123.11	2500
2125.03	2558
2126.96	2510
2128.88	2534
2130.8	2504
2132.72	2546
2134.64	2452
2136.56	2468
2138.48	2496
2140.4	2492
2142.31	2464
2144.23	2536
2146.15	2466
2148.06	2448
2149.98	2520
2151.89	2464
2153.81	2524
2155.72	2460
2157.63	2458
2159.55	2484
2161.46	2416
2163.37	2396
2165.28	2478
2167.19	2436
2169.1	2446
2171.01	2448
2172.91	2384
2174.82	2414
2176.73	2422
2178.64	2392
2180.54	2422
2182.45	2432
2184.35	2400
2186.26	2430
2188.16	2474
2190.06	2414
2191.96	2376
2193.87	2356
2195.77	2358
2197.67	2370
2199.57	2346
2201.47	2336
2203.37	2348
2205.27	2344
2207.16	2344
2209.06	2312
2210.96	2324
2212.85	2348
2214.75	2342
2216.64	2366
2218.54	2380
2220.43	2274
2222.33	2402
2224.22	2360.64
2226.11	2343.8
2228	2291.28
2229.89	2368.54
2231.78	2313.19
2233.67	2335.11
2235.56	2300.65
2237.45	2301.07
2239.34	2256.96
2241.23	2316.2
2243.11	2326.1
2245	2280.73
2246.89	2246.72
2248.77	2280.74
2250.66	2284.15
2252.54	2265.89
2254.42	2258.03
2256.31	2248.17
2258.19	2222.84
2260.07	2255.73
2261.95	2239.63
2263.83	2245.44
2265.71	2274.81
2267.59	2227.19
2269.47	2203.77
2271.35	2202.02
2273.23	2199.06
2275.1	2216.85
2276.98	2184.5
2278.86	2151.35
2280.73	2174.35
2282.61	2183.91
2284.48	2178.65
2286.36	2161.54
2288.23	2152.19
2290.1	2125.13
2291.98	2130.78
2293.85	2171.74
2295.72	2081.63
2297.59	2104.29
2299.46	2109.75
2301.33	2136.65
2303.2	2105.55
2305.06	2099.52
2306.93	2063.02
2308.8	2067.39
2310.67	2079.17
2312.53	2089.72
2314.4	2082.88
2316.26	2050.9
2317.62	2054
2319.5	2050
2321.37	2012
2323.24	2026
2325.12	1972
2326.99	2046
2328.86	2018
2330.73	1992
2332.6	2032
2334.47	1990
2336.34	2006
2338.2	2036
2340.07	1940
2341.94	2014
2343.81	2012
2345.67	1990
2347.54	2026
2349.4	1962
2351.27	1942
2353.13	1886
2354.99	1938
2356.86	1942
2358.72	1944
2360.58	1958
2362.44	1932
2364.3	1936
2366.16	1900
2368.02	1948
2369.88	1942
2371.74	1936
2373.6	1950
2375.45	1898
2377.31	1914
2379.17	1910
2381.02	1888
2382.88	1816
2384.73	1904
2386.58	1866
2388.44	1878
2390.29	1862
2392.14	1834
2393.99	1822
2395.85	1762
2397.7	1830
2399.55	1790
2401.4	1852
2403.25	1790
2405.09	1778
2406.94	1812
2408.79	1790
2410.63	1748
2412.48	1730
2414.33	1770
2416.17	1756
2418.02	1738
2419.86	1730
2421.7	1750
2423.55	1744
2425.39	1714
2427.23	1682
2429.07	1690
2430.91	1748
2432.75	1720
2434.59	1746
2436.43	1608
2438.27	1692
2440.11	1664
2441.95	1612
2443.78	1640
2445.62	1624
2447.46	1680
2449.29	1618
2451.13	1648
2452.96	1580
2454.79	1604
2456.63	1590
2458.46	1584
2460.29	1584
2462.12	1578
2463.95	1578
2465.78	1546
2467.61	1550
2469.44	1520
2471.27	1476
2473.1	1472
2474.93	1534
2476.76	1556
2478.58	1470
2480.41	1514
2482.23	1460
2484.06	1470
2485.88	1496
2487.71	1474
2489.53	1450
2491.35	1432
2493.18	1416
2495	1418
2496.82	1416
2498.64	1430
2500.46	1414
2502.28	1418
2504.1	1414
2505.92	1408
2507.74	1382
2509.55	1404
2511.37	1378
2513.19	1356
2515	1408
2516.82	1370
2518.63	1406
2520.45	1358
2522.26	1338
2524.07	1354
2525.89	1330
2527.7	1340
2529.51	1300
2531.32	1266
2533.13	1300
2534.94	1296
2536.75	1290
2538.56	1232
2540.37	1252
2542.18	1236
2543.98	1322
2545.79	1274
2547.6	1248
2549.4	1248
2551.21	1264
2553.01	1216
2554.82	1204
2556.62	1254
2558.42	1208
2560.23	1200
2562.03	1232
2563.83	1188
2565.63	1158
2567.43	1160
2569.23	1208
2571.03	1166
2572.83	1154
2574.63	1180
2576.43	1152
2578.22	1140
2580.02	1138
2581.82	1082
2583.61	1144
2585.41	1108
2587.2	1128
2589	1092
2590.79	1142
2592.58	1086
2594.38	1114
2596.17	1094
2597.96	1062
2599.75	1098
2601.54	1074
2603.33	1050
2605.12	1070
2606.91	1076
2608.7	1048
2610.49	1020
2612.27	1060
2614.06	1044
2615.85	1036
2617.63	1050
2619.42	1034
2621.2	986
2622.99	1024
2624.77	988
2626.55	974
2628.34	970
2630.12	964
2631.9	980
2633.68	996
2635.46	988
2637.24	1018
2639.02	930
2640.8	992
2642.58	954
2644.36	950
2646.14	974
2647.91	952
2649.69	934
2651.46	924
2653.24	924
2655.01	930
2656.79	924
2658.56	948
2660.34	870
2662.11	912
2663.88	880
2665.65	892
2667.42	892
2669.2	880
2670.96	884
2672.73	858
2674.5	858
2676.27	864
2678.04	840
2679.81	884
2681.58	828
2683.34	838
2685.11	872
2686.87	828
2688.64	824
2690.4	782
2692.17	810
2693.93	834
2695.69	812
2697.46	812
2699.22	754
2700.98	758
2702.74	782
2704.5	774
2706.26	786
2708.02	774
2709.78	724
2711.54	754
2713.3	788
2715.05	752
2716.81	810
2718.57	764
2720.32	734
2722.08	722
2723.83	738
2725.59	756
2727.34	742
2729.09	738
2730.85	690
2732.6	732
2734.35	708
2736.1	722
2737.85	722
2739.6	684
2741.35	664
2743.1	684
2744.85	680
2746.6	678
2748.35	662
2750.09	662
2751.84	656
2753.59	648
2755.33	660
2757.08	638
2758.82	646
2760.57	630
2762.31	638
2764.05	644
2765.79	632
2767.54	608
2769.28	658
2771.02	618
2772.76	598
2774.5	602
2776.24	622
2777.98	598
2779.72	620
2781.46	598
2783.19	586
2784.93	592
2786.67	604
2788.4	586
2790.14	590
2791.87	578
2793.61	548
2795.34	530
2797.07	566
2798.81	568
2800.54	568
2802.27	540
2804	568
2805.74	530
2807.47	538
2809.2	518
2810.93	560
2812.65	534
2814.38	526
2816.11	502
2817.84	508
2819.56	512
2821.29	520
2823.02	508
2824.74	508
2826.47	504
2828.19	496
2829.92	490
2831.64	480
2833.36	490
2835.09	488
2836.81	474
2838.53	462
2840.25	490
2841.97	478
2843.69	482
2845.41	468
2847.13	460
2848.85	438
2850.57	464
2852.28	458
2854	462
2855.72	448
2857.43	440
2859.15	430
2860.86	466
2862.58	458
2864.29	434
2866.01	442
2867.72	456
2869.43	408
2871.14	412
2872.86	410
2874.57	404
2876.28	416
2877.99	420
2879.7	402
2881.41	426
2883.11	398
2884.82	406
2886.53	400
2888.24	384
2889.94	374
2891.65	406
2893.36	384
2895.06	376
2896.77	388
2898.47	388
2900.17	384
2901.88	372
2903.58	374
2905.28	380
2906.98	384
2908.69	376
2910.39	372
2912.09	358
2913.79	404
2915.49	370
2917.19	342
2918.88	354
2920.58	362
2922.28	388
2923.98	368
2925.67	340
2927.37	360
2929.06	366
2930.76	312
2932.45	348
2934.15	346
2935.84	340
2937.53	356
2939.23	338
2940.92	354
2942.61	316
2944.3	336
2945.99	336
2947.68	340
2949.37	312
2951.06	308
2952.75	326
2954.44	324
2956.12	328
2957.81	328
2959.5	322
2961.18	312
2962.87	314
2964.56	298
2966.24	318
2967.92	316
2969.61	334
2971.29	316
2972.97	308
2974.66	314
2976.34	306
2978.02	296
2979.7	282
2981.38	314
2983.06	304
2984.74	290
2986.42	306
2988.1	284
2989.78	274
2991.45	266
2993.13	272
2994.81	278
2996.48	298
2998.16	274
2999.83	284