File: muestras/papalo/leaf_100x_09.txt
#Acq. time (s)=	10
#Accumulations=	1
#Range (cm-¹)=	200...3000
#Windows=	3
#Autofocus=	Off
#AutoExposure=	Off
#Spike filter=	Off
#Delay time (s)=	0
#Binning=	1
#Readout mode=	Signal
#DeNoise=	Off
#ICS correction=	Off
#Dark correction=	Off
#Inst. Process=	Off
#Instrument=	LabRAM HR Evol
#Detector=	Syncerity OE
#Objective=	x100_VIS
#Grating=	600 (500nm)
#ND Filter=	0.1%
#Laser=	633nm_Edge
#Hole=	100.021
#Range=	Visible
#Project=	Omar
#Sample=	03-07-23
#Site=	papal
#Title=	leaf_100x
#Remark=
#Date=	03.07.2023 17:18
#Acquired=	03.07.2023 17:18:28
201.713	172
204.247	176
206.778	194
209.311	186
211.84	188
214.371	184
216.899	194
219.428	184
221.955	188
224.482	206
227.007	194
229.531	198
232.055	204
234.579	220
237.1	214
239.621	210
242.141	218
244.661	220
247.179	230
249.698	208
252.215	240
254.731	230
257.246	236
259.761	224
262.273	228
264.786	254
267.298	256
269.809	248
272.319	240
274.828	246
277.336	262
279.844	266
282.351	258
284.855	260
287.361	288
289.866	272
292.368	268
294.871	282
297.372	268
299.873	304
302.372	296
304.872	314
307.37	306
309.866	324
312.364	298
314.859	312
317.353	318
319.848	324
322.341	340
324.833	322
327.324	336
329.814	380
332.304	336
334.792	376
337.28	362
339.767	332
342.254	388
344.739	370
347.224	374
349.708	378
352.191	408
354.673	400
357.155	418
359.634	392
362.114	412
364.593	418
367.07	376
369.548	418
372.024	430
374.499	430
376.974	408
379.447	436
381.92	486
384.392	480
386.864	448
389.333	452
391.802	470
394.272	474
396.739	464
399.206	468
401.673	488
404.138	474
406.602	496
409.066	500
411.528	516
413.99	524
416.451	542
418.911	542
421.371	572
423.83	560
426.288	570
428.745	544
431.201	590
433.657	558
436.111	598
438.565	596
441.017	558
443.469	594
445.921	616
448.37	626
450.821	604
453.27	630
455.717	634
458.165	656
460.61	656
463.056	642
465.5	682
467.945	666
470.387	640
472.829	648
475.271	682
477.711	702
480.15	700
482.589	726
485.027	738
487.465	748
489.901	726
492.337	732
494.771	778
497.205	752
499.638	760
502.07	760
504.502	780
506.933	792
509.363	816
511.792	816
514.219	828
516.647	806
519.073	806
521.5	856
523.924	848
526.348	842
528.772	882
531.194	870
533.616	870
536.036	896
538.457	920
540.875	904
543.294	910
545.712	922
548.128	910
550.545	960
552.959	950
555.373	942
557.788	958
560.2	940
562.612	992
565.023	1006
567.433	1012
569.843	1022
572.251	1044
574.659	1012
577.066	1096
579.472	1076
581.878	1088
584.283	1080
586.687	1038
589.09	1088
591.493	1110
593.893	1136
596.294	1164
598.694	1154
601.093	1170
603.491	1196
605.889	1194
608.285	1212
610.682	1232
613.076	1270
615.471	1210
617.864	1262
620.256	1324
622.648	1304
625.039	1310
627.429	1356
629.819	1378
632.208	1350
634.595	1406
636.982	1408
639.369	1412
641.755	1438
644.139	1430
646.523	1480
648.906	1488
651.288	1498
653.67	1526
656.051	1562
658.429	1628
660.808	1604
663.187	1600
665.565	1646
667.942	1636
670.317	1674
672.692	1628
675.067	1686
677.44	1702
679.813	1774
682.184	1750
684.556	1782
686.926	1780
689.296	1780
691.664	1754
694.033	1880
696.4	1870
698.766	1900
701.133	1862
703.497	1954
705.861	1974
708.224	2002
710.586	2004
712.949	2030
715.31	2088
717.67	2098
720.029	2140
722.388	2156
724.746	2148
727.103	2248
729.458	2168
731.814	2268
734.168	2252
736.523	2314
738.876	2310
741.227	2410
743.579	2408
745.931	2392
748.28	2440
750.629	2488
752.977	2504
755.325	2558
757.672	2590
760.018	2586
762.363	2644
764.708	2634
767.052	2688
769.394	2674
771.737	2712
774.078	2764
776.419	2852
778.758	2842
781.097	2912
783.435	2934
785.773	2980
788.11	2976
790.446	3022
792.781	3076
795.115	3026
797.449	3172
799.782	3140
802.115	3152
804.446	3256
806.777	3268
809.106	3350
811.435	3342
813.764	3410
816.091	3478
818.418	3442
820.743	3660
823.069	3572
825.393	3714
827.717	3704
830.039	3798
832.362	3778
834.683	3836
837.003	3874
839.324	3896
841.643	4008
843.961	4024
846.278	4088
848.594	4146
850.91	4180
853.227	4280
855.541	4354
857.855	4342
860.168	4316
862.48	4454
864.79	4530
867.101	4598
869.411	4620
871.721	4664
874.029	4732
876.336	4778
878.643	4818
880.95	4866
883.254	4886
885.559	4976
887.862	5002
890.166	5116
892.467	5154
894.77	5184
897.07	5104
899.371	5236
901.669	5230
903.968	5364
906.266	5468
908.563	5494
910.859	5524
913.154	5614
915.449	5610
917.742	5736
920.036	5772
922.329	5864
924.621	5926
926.911	5958
929.201	6034
931.49	6140
933.779	6180
936.068	6224
938.355	6300
940.64	6404
942.926	6432
945.212	6512
947.495	6686
949.779	6628
952.062	6732
954.344	6760
956.625	6904
958.905	6952
961.184	7030
963.464	7080
965.742	7084
968.02	7262
970.296	7428
972.572	7278
974.847	7468
977.121	7648
979.396	7664
981.669	7796
983.941	7756
986.212	7864
988.483	7936
990.753	7890
993.022	8080
995.29	8108
997.558	8262
999.825	8390
1002.09	8374
1004.36	8378
1006.62	8486
1008.89	8630
1011.15	8688
1013.41	8918
1015.67	8884
1017.93	8932
1020.19	9078
1022.45	9302
1024.71	9190
1026.97	9334
1029.23	9388
1031.49	9596
1033.74	9716
1036	9912
1038.25	9982
1040.5	9904
1042.76	10106
1045.01	10152
1047.26	10278
1049.51	10322
1051.76	10444
1054.01	10740
1056.26	10676
1058.51	10734
1060.75	10756
1063	10888
1065.25	11016
1067.49	11124
1069.73	11180
1071.98	11264
1074.22	11430
1076.46	11560
1078.7	11530
1080.94	11572
1083.18	11680
1085.42	11802
1087.66	11854
1089.9	11908
1092.14	11968
1094.37	12068
1096.61	12170
1098.84	12290
1101.08	12268
1103.31	12236
1105.54	12390
1107.77	12518
1110	12542
1112.23	12728
1114.46	12552
1116.69	12734
1118.92	12824
1121.15	12952
1123.37	13020
1125.6	13124
1127.83	13086
1130.05	13260
1132.27	13296
1134.5	13484
1136.72	13740
1138.94	13398
1141.16	13670
1143.38	13844
1145.6	13770
1147.82	13936
1150.04	14020
1152.26	14028
1154.47	14100
1156.69	14050
1158.9	14184
1161.12	14104
1163.33	14444
1165.54	14366
1167.76	14508
1169.97	14454
1172.18	14548
1174.39	14530
1176.6	14550
1178.81	14538
1181.02	14474
1183.22	14468
1185.43	14532
1187.63	14474
1189.84	14594
1192.04	14394
1194.25	14418
1196.45	14416
1198.65	14378
1200.85	14368
1203.05	14250
1205.25	14460
1207.45	14252
1209.65	14320
1211.85	14228
1214.05	14274
1216.24	14238
1218.44	14278
1220.64	14020
1222.83	14088
1225.02	13988
1227.22	14004
1229.41	13880
1231.6	13940
1233.79	13828
1235.98	13700
1238.17	13698
1240.36	13484
1242.55	13690
1244.73	13566
1246.92	13474
1249.11	13366
1251.29	13256
1253.48	13206
1255.66	13336
1257.84	13140
1260.03	13044
1262.21	12990
1264.39	13120
1266.57	13000
1268.75	12826
1270.93	12712
1273.11	12700
1275.28	12638
1277.46	12696
1279.64	12556
1281.81	12514
1283.98	12470.6
1286.16	12335.6
1288.33	12107.1
1290.5	12036.5
1292.68	11909.4
1294.85	11791.4
1297.02	11623.5
1299.19	11526.2
1301.36	11365.1
1303.53	11308
1305.69	11196.1
1307.86	11083.1
1310.03	10945
1312.19	10833.5
1314.36	10701.2
1316.52	10541.7
1318.68	10451.5
1320.85	10316.6
1323.01	10168.8
1325.17	10050.6
1327.33	10058.6
1329.49	9873.69
1331.65	9736.27
1333.81	9554.52
1335.97	9608.24
1338.12	9404.65
1340.28	9264.92
1342.44	9175.09
1344.59	9143.01
1346.75	8960.33
1348.9	8958.61
1351.05	8815.57
1353.2	8621.54
1355.36	8540.37
1357.51	8539.02
1359.66	8514.89
1361.81	8319.57
1363.96	8226.1
1366.1	8269.07
1368.25	8062.53
1370.4	7940.57
1372.54	7936.13
1374.69	7761.28
1376.83	7717.21
1378.98	7602.05
1381.12	7570.78
1383.26	7499.67
1385.41	7357.21
1387.55	7276.55
1389.69	7213.15
1391.83	7209.51
1393.02	7112
1395.17	6948
1397.32	6960
1399.47	7002
1401.62	6956
1403.77	6922
1405.91	6764
1408.06	6756
1410.2	6708
1412.35	6726
1414.49	6606
1416.63	6606
1418.78	6408
1420.92	6484
1423.06	6354
1425.2	6404
1427.34	6224
1429.48	6266
1431.61	6190
1433.75	6200
1435.89	6134
1438.02	6154
1440.16	6138
1442.3	5998
1444.43	6158
1446.56	6008
1448.7	5986
1450.83	5874
1452.96	5848
1455.09	5846
1457.22	5722
1459.35	5712
1461.48	5672
1463.61	5680
1465.73	5574
1467.86	5602
1469.98	5600
1472.11	5514
1474.24	5506
1476.36	5468
1478.48	5558
1480.6	5430
1482.73	5446
1484.85	5374
1486.97	5366
1489.09	5346
1491.21	5310
1493.33	5304
1495.44	5268
1497.56	5258
1499.68	5236
1501.79	5150
1503.91	5202
1506.02	5134
1508.14	5006
1510.25	5012
1512.36	5042
1514.48	4994
1516.59	4836
1518.7	4926
1520.81	4856
1522.92	4810
1525.02	4866
1527.13	4870
1529.24	4824
1531.35	4778
1533.45	4752
1535.56	4628
1537.66	4668
1539.77	4616
1541.87	4618
1543.97	4546
1546.08	4604
1548.18	4532
1550.28	4520
1552.38	4444
1554.48	4448
1556.57	4412
1558.67	4332
1560.77	4388
1562.87	4346
1564.96	4372
1567.06	4318
1569.15	4326
1571.25	4298
1573.34	4376
1575.43	4352
1577.53	4276
1579.62	4246
1581.71	4268
1583.8	4280
1585.89	4190
1587.98	4188
1590.06	4146
1592.15	4132
1594.24	4148
1596.33	4072
1598.41	4094
1600.5	4056
1602.58	4112
1604.66	4068
1606.75	4072
1608.83	4022
1610.91	4026
1612.99	4038
1615.07	4042
1617.15	4016
1619.23	3968
1621.31	3974
1623.39	3964
1625.46	3950
1627.54	3970
1629.62	3914
1631.69	3936
1633.77	3996
1635.84	3876
1637.91	3930
1639.99	3822
1642.06	3872
1644.13	3824
1646.2	3852
1648.27	3860
1650.34	3804
1652.41	3760
1654.47	3754
1656.54	3778
1658.61	3778
1660.67	3742
1662.74	3722
1664.81	3768
1666.87	3808
1668.93	3626
1671	3672
1673.06	3660
1675.12	3612
1677.18	3620
1679.24	3730
1681.3	3724
1683.36	3538
1685.42	3650
1687.47	3582
1689.53	3630
1691.59	3558
1693.64	3538
1695.7	3564
1697.75	3548
1699.81	3530
1701.86	3526
1703.91	3522
1705.97	3518
1708.02	3520
1710.07	3462
1712.12	3428
1714.17	3488
1716.22	3514
1718.26	3518
1720.31	3522
1722.36	3454
1724.4	3438
1726.45	3406
1728.49	3334
1730.54	3420
1732.58	3450
1734.63	3436
1736.67	3380
1738.71	3432
1740.75	3414
1742.79	3376
1744.83	3318
1746.87	3388
1748.91	3452
1750.95	3390
1752.98	3428
1755.02	3394
1757.06	3308
1759.09	3324
1761.13	3422
1763.16	3378
1765.19	3424
1767.23	3356
1769.26	3388
1771.29	3314
1773.32	3386
1775.35	3408
1777.38	3344
1779.41	3350
1781.44	3384
1783.47	3330
1785.49	3356
1787.52	3356
1789.55	3318
1791.57	3348
1793.6	3304
1795.62	3310
1797.64	3290
1799.67	3362
1801.69	3364
1803.71	3374
1805.73	3278
1807.75	3268
1809.77	3342
1811.79	3286
1813.81	3276
1815.83	3362
1817.84	3290
1819.86	3284
1821.88	3282
1823.89	3286
1825.91	3220
1827.92	3370
1829.93	3304
1831.95	3270
1833.96	3328
1835.97	3252
1837.98	3224
1839.99	3240
1842	3184
1844.01	3260
1846.02	3264
1848.03	3214
1850.03	3236
1852.04	3234
1854.05	3238
1856.05	3240
1858.06	3230
1860.06	3212
1862.06	3130
1864.07	3150
1866.07	3136
1868.07	3254
1870.07	3202
1872.07	3154
1874.07	3220
1876.07	3188
1878.07	3154
1880.07	3226
1882.07	3198
1884.06	3154
1886.06	3190
1888.05	3186
1890.05	3092
1892.04	3144
1894.04	3120
1896.03	3110
1898.02	3146
1900.01	3116
1902	3190
1903.99	3182
1905.98	3218
1907.97	3224
1909.96	3164
1911.95	3162
1913.94	3104
1915.93	3164
1917.91	3128
1919.9	3100
1921.88	3198
1923.87	3160
1925.85	3138
1927.83	3098
1929.82	3104
1931.8	3184
1933.78	3152
1935.76	3116
1937.74	3126
1939.72	3132
1941.7	3092
1943.68	3144
1945.65	3150
1947.63	3140
1949.61	3160
1951.58	3108
1953.56	3060
1955.53	3066
1957.51	3078
1959.48	3134
1961.45	3098
1963.43	3070
1965.4	3062
1967.37	3074
1969.34	3090
1971.31	2988
1973.28	3056
1975.25	3082
1977.22	3086
1979.18	3014
1981.15	2970
1983.12	3014
1985.08	2986
1987.05	2992
1989.01	3078
1990.97	2994
1992.94	3062
1994.9	3092
1996.86	3020
1998.82	3018
2000.78	2986
2002.74	2986
2004.7	2968
2006.66	3012
2008.62	3026
2010.58	3006
2012.54	3086
2014.49	2974
2016.45	3018
2018.4	2972
2020.36	3014
2022.31	2978
2024.27	2932
2026.22	3008
2028.17	3013
2030.12	2980
2032.07	2962
2034.03	2966
2035.98	2976
2037.93	2934
2039.87	2962
2041.82	2942
2043.77	2970
2045.72	2984
2047.66	2932
2049.61	2938
2051.55	2896
2053.5	2876
2055.44	2956
2057.39	2946
2059.33	2872
2061.27	2832
2063.21	3006
2065.15	2956
2067.09	2940
2069.03	2888
2070.97	2956
2072.91	2936
2074.85	2922
2076.79	2802
2078.73	2912
2080.66	2920
2082.6	2862
2084.53	2858
2086.47	2878
2088.4	2954
2090.33	2862
2092.27	2906
2094.2	2874
2096.13	2840
2098.06	2920
2099.99	2892
2101.92	2812
2103.85	2854
2105.78	2920
2107.71	2886
2109.64	2896
2111.56	2894
2113.49	2834
2115.41	2908
2117.34	2912
2119.26	2928
2121.19	2872
2123.11	2896
2125.03	2868
2126.96	2892
2128.88	2858
2130.8	2876
2132.72	2868
2134.64	2868
2136.56	2910
2138.48	2820
2140.4	2852
2142.31	2800
2144.23	2824
2146.15	2756
2148.06	2864
2149.98	2786
2151.89	2818
2153.81	2866
2155.72	2824
2157.63	2798
2159.55	2822
2161.46	2828
2163.37	2850
2165.28	2736
2167.19	2844
2169.1	2700
2171.01	2782
2172.91	2728
2174.82	2762
2176.73	2784
2178.64	2744
2180.54	2760
2182.45	2782
2184.35	2686
2186.26	2758
2188.16	2724
2190.06	2698
2191.96	2618
2193.87	2740
2195.77	2746
2197.67	2702
2199.57	2704
2201.47	2678
2203.37	2606
2205.27	2704
2207.16	2630
2209.06	2650
2210.96	2612
2212.85	2676
2214.75	2634
2216.64	2588
2218.54	2684
2220.43	2676
2222.33	2694
2224.22	2629.89
2226.11	2715.13
2228	2597.37
2229.89	2656.13
2231.78	2583.6
2233.67	2619.55
2235.56	2592.88
2237.45	2671.26
2239.34	2652.81
2241.23	2574.45
2243.11	2616.27
2245	2556.39
2246.89	2573.44
2248.77	2593.51
2250.66	2554.97
2252.54	2552.45
2254.42	2560.29
2256.31	2557.79
2258.19	2562.48
2260.07	2503.69
2261.95	2507.56
2263.83	2538.16
2265.71	2488.88
2267.59	2460.62
2269.47	2478.36
2271.35	2479.57
2273.23	2486.42
2275.1	2462.71
2276.98	2462.94
2278.86	2449.03
2280.73	2463.3
2282.61	2388.87
2284.48	2443.08
2286.36	2425.65
2288.23	2382.8
2290.1	2416.49
2291.98	2393.17
2293.85	2389.18
2295.72	2344.25
2297.59	2334.08
2299.46	2374.36
2301.33	2377.31
2303.2	2306.97
2305.06	2359.67
2306.93	2303.51
2308.8	2335.76
2310.67	2278.68
2312.53	2305.96
2314.4	2262.94
2316.26	2278.36
2317.62	2290
2319.5	2254
2321.37	2280
2323.24	2216
2325.12	2244
2326.99	2258
2328.86	2186
2330.73	2198
2332.6	2270
2334.47	2218
2336.34	2224
2338.2	2224
2340.07	2186
2341.94	2256
2343.81	2232
2345.67	2122
2347.54	2202
2349.4	2158
2351.27	2200
2353.13	2178
2354.99	2094
2356.86	2108
2358.72	2158
2360.58	2106
2362.44	2162
2364.3	2082
2366.16	2138
2368.02	2134
2369.88	2126
2371.74	2098
2373.6	2090
2375.45	2102
2377.31	2068
2379.17	2070
2381.02	2052
2382.88	2070
2384.73	2016
2386.58	2058
2388.44	2084
2390.29	2004
2392.14	2002
2393.99	2020
2395.85	1956
2397.7	1996
2399.55	2012
2401.4	2036
2403.25	1988
2405.09	1896
2406.94	1956
2408.79	1958
2410.63	1918
2412.48	1946
2414.33	1884
2416.17	1910
2418.02	1896
2419.86	1868
2421.7	1910
2423.55	1890
2425.39	1854
2427.23	1898
2429.07	1858
2430.91	1862
2432.75	1854
2434.59	1882
2436.43	1832
2438.27	1810
2440.11	1848
2441.95	1858
2443.78	1826
2445.62	1816
2447.46	1768
2449.29	1758
2451.13	1776
2452.96	1790
2454.79	1778
2456.63	1776
2458.46	1756
2460.29	1742
2462.12	1682
2463.95	1712
2465.78	1738
2467.61	1720
2469.44	1680
2471.27	1670
2473.1	1698
2474.93	1716
2476.76	1624
2478.58	1652
2480.41	1640
2482.23	1654
2484.06	1666
2485.88	1608
2487.71	1608
2489.53	1652
2491.35	1602
2493.18	1594
2495	1600
2496.82	1578
2498.64	1618
2500.46	1570
2502.28	1552
2504.1	1546
2505.92	1590
2507.74	1526
2509.55	1526
2511.37	1510
2513.19	1498
2515	1496
2516.82	1464
2518.63	1532
2520.45	1456
2522.26	1442
2524.07	1460
2525.89	1488
2527.7	1424
2529.51	1438
2531.32	1464
2533.13	1408
2534.94	1392
2536.75	1466
2538.56	1380
2540.37	1354
2542.18	1396
2543.98	1380
2545.79	1396
2547.6	1378
2549.4	1400
2551.21	1344
2553.01	1358
2554.82	1362
2556.62	1362
2558.42	1308
2560.23	1364
2562.03	1322
2563.83	1330
2565.63	1316
2567.43	1308
2569.23	1326
2571.03	1296
2572.83	1278
2574.63	1310
2576.43	1264
2578.22	1298
2580.02	1268
2581.82	1278
2583.61	1250
2585.41	1236
2587.2	1198
2589	1240
2590.79	1196
2592.58	1220
2594.38	1180
2596.17	1188
2597.96	1216
2599.75	1172
2601.54	1218
2603.33	1172
2605.12	1146
2606.91	1214
2608.7	1132
2610.49	1162
2612.27	1152
2614.06	1156
2615.85	1112
2617.63	1154
2619.42	1144
2621.2	1132
2622.99	1132
2624.77	1120
2626.55	1076
2628.34	1030
2630.12	1092
2631.9	1080
2633.68	1060
2635.46	1056
2637.24	1106
2639.02	1078
2640.8	1046
2642.58	1062
2644.36	1034
2646.14	998
2647.91	1052
2649.69	1026
2651.46	1034
2653.24	988
2655.01	978
2656.79	1036
2658.56	990
2660.34	1018
2662.11	978
2663.88	972
2665.65	988
2667.42	940
2669.2	944
2670.96	950
2672.73	960
2674.5	948
2676.27	932
2678.04	922
2679.81	978
2681.58	884
2683.34	914
2685.11	924
2686.87	910
2688.64	884
2690.4	906
2692.17	874
2693.93	896
2695.69	898
2697.46	876
2699.22	878
2700.98	916
2702.74	892
2704.5	880
2706.26	828
2708.02	882
2709.78	872
2711.54	832
2713.3	816
2715.05	822
2716.81	826
2718.57	796
2720.32	806
2722.08	804
2723.83	762
2725.59	838
2727.34	796
2729.09	820
2730.85	764
2732.6	778
2734.35	790
2736.1	756
2737.85	748
2739.6	722
2741.35	760
2743.1	748
2744.85	784
2746.6	730
2748.35	706
2750.09	728
2751.84	732
2753.59	704
2755.33	706
2757.08	710
2758.82	724
2760.57	674
2762.31	728
2764.05	706
2765.79	700
2767.54	702
2769.28	704
2771.02	690
2772.76	658
2774.5	672
2776.24	630
2777.98	658
2779.72	662
2781.46	630
2783.19	644
2784.93	658
2786.67	654
2788.4	648
2790.14	670
2791.87	650
2793.61	632
2795.34	632
2797.07	634
2798.81	606
2800.54	598
2802.27	596
2804	588
2805.74	632
2807.47	616
2809.2	602
2810.93	576
2812.65	596
2814.38	584
2816.11	578
2817.84	568
2819.56	556
2821.29	566
2823.02	564
2824.74	554
2826.47	528
2828.19	498
2829.92	568
2831.64	542
2833.36	556
2835.09	540
2836.81	542
2838.53	542
2840.25	522
2841.97	540
2843.69	536
2845.41	480
2847.13	520
2848.85	502
2850.57	488
2852.28	506
2854	502
2855.72	510
2857.43	480
2859.15	492
2860.86	486
2862.58	446
2864.29	480
2866.01	466
2867.72	476
2869.43	436
2871.14	464
2872.86	462
2874.57	464
2876.28	448
2877.99	468
2879.7	438
2881.41	424
2883.11	438
2884.82	428
2886.53	430
2888.24	448
2889.94	432
2891.65	404
2893.36	418
2895.06	408
2896.77	430
2898.47	404
2900.17	426
2901.88	406
2903.58	412
2905.28	412
2906.98	402
2908.69	412
2910.39	394
2912.09	414
2913.79	388
2915.49	392
2917.19	392
2918.88	390
2920.58	400
2922.28	364
2923.98	396
2925.67	382
2927.37	372
2929.06	390
2930.76	336
2932.45	360
2934.15	342
2935.84	356
2937.53	362
2939.23	364
2940.92	366
2942.61	372
2944.3	346
2945.99	372
2947.68	370
2949.37	348
2951.06	340
2952.75	342
2954.44	356
2956.12	338
2957.81	350
2959.5	340
2961.18	348
2962.87	336
2964.56	350
2966.24	316
2967.92	336
2969.61	328
2971.29	306
2972.97	320
2974.66	320
2976.34	318
2978.02	332
2979.7	330
2981.38	304
2983.06	318
2984.74	316
2986.42	304
2988.1	304
2989.78	306
2991.45	306
2993.13	314
2994.81	292
2996.48	316
2998.16	330
2999.83	310