File: muestras/papalo/leaf_100x_13.txt
#Acq. time (s)=	10
#Accumulations=	1
#Range (cm-¹)=	200...3000
#Windows=	3
#Autofocus=	Off
#AutoExposure=	Off
#Spike filter=	Off
#Delay time (s)=	0
#Binning=	1
#Readout mode=	Signal
#DeNoise=	Off
#ICS correction=	Off
#Dark correction=	Off
#Inst. Process=	Off
#Instrument=	LabRAM HR Evol
#Detector=	Syncerity OE
#Objective=	x100_VIS
#Grating=	600 (500nm)
#ND Filter=	0.1%
#Laser=	633nm_Edge
#Hole=	100.021
#Range=	Visible
#Project=	Omar
#Sample=	03-07-23
#Site=	papal
#Title=	leaf_100x
#Remark=
#Date=	03.07.2023 17:22
#Acquired=	03.07.2023 17:22:22
201.713	106
204.247	120
206.778	126
209.311	122
211.84	122
214.371	120
216.899	126
219.428	134
221.955	128
224.482	144
227.007	128
229.531	146
232.055	148
234.579	138
237.1	152
239.621	148
242.141	132
244.661	150
247.179	136
249.698	146
252.215	142
254.731	158
257.246	156
259.761	164
262.273	144
264.786	162
267.298	142
269.809	154
272.319	166
274.828	154
277.336	172
279.844	154
282.351	168
284.855	166
287.361	194
289.866	178
292.368	186
294.871	182
297.372	178
299.873	188
302.372	188
304.872	196
307.37	192
309.866	190
312.364	202
314.859	200
317.353	216
319.848	196
322.341	208
324.833	220
327.324	204
329.814	226
332.304	224
334.792	220
337.28	224
339.767	260
342.254	228
344.739	246
347.224	234
349.708	246
352.191	246
354.673	252
357.155	234
359.634	246
362.114	244
364.593	248
367.07	284
369.548	276
372.024	268
374.499	256
376.974	268
379.447	262
381.92	272
384.392	270
386.864	256
389.333	272
391.802	280
394.272	306
396.739	286
399.206	292
401.673	300
404.138	298
406.602	290
409.066	318
411.528	300
413.99	332
416.451	330
418.911	340
421.371	332
423.83	354
426.288	346
428.745	350
431.201	362
433.657	358
436.111	352
438.565	368
441.017	362
443.469	372
445.921	356
448.37	388
450.821	384
453.27	372
455.717	382
458.165	380
460.61	378
463.056	366
465.5	410
467.945	396
470.387	416
472.829	428
475.271	426
477.711	402
480.15	418
482.589	440
485.027	434
487.465	464
489.901	446
492.337	470
494.771	442
497.205	470
499.638	468
502.07	464
504.502	452
506.933	464
509.363	482
511.792	466
514.219	478
516.647	474
519.073	522
521.5	494
523.924	508
526.348	510
528.772	488
531.194	532
533.616	496
536.036	532
538.457	530
540.875	508
543.294	544
545.712	536
548.128	546
550.545	562
552.959	556
555.373	550
557.788	580
560.2	558
562.612	614
565.023	600
567.433	588
569.843	596
572.251	620
574.659	622
577.066	636
579.472	648
581.878	646
584.283	660
586.687	672
589.09	626
591.493	686
593.893	670
596.294	672
598.694	714
601.093	684
603.491	700
605.889	740
608.285	754
610.682	732
613.076	746
615.471	728
617.864	764
620.256	780
622.648	782
625.039	782
627.429	820
629.819	844
632.208	822
634.595	810
636.982	838
639.369	810
641.755	836
644.139	862
646.523	854
648.906	880
651.288	894
653.67	904
656.051	894
658.429	886
660.808	896
663.187	952
665.565	930
667.942	998
670.317	950
672.692	1002
675.067	1022
677.44	1012
679.813	1060
682.184	1028
684.556	1032
686.926	1040
689.296	994
691.664	1074
694.033	1060
696.4	1084
698.766	1070
701.133	1096
703.497	1100
705.861	1140
708.224	1132
710.586	1214
712.949	1158
715.31	1206
717.67	1218
720.029	1206
722.388	1278
724.746	1274
727.103	1324
729.458	1286
731.814	1320
734.168	1344
736.523	1384
738.876	1368
741.227	1376
743.579	1410
745.931	1420
748.28	1392
750.629	1402
752.977	1476
755.325	1430
757.672	1484
760.018	1536
762.363	1478
764.708	1498
767.052	1586
769.394	1546
771.737	1544
774.078	1584
776.419	1606
778.758	1684
781.097	1684
783.435	1634
785.773	1662
788.11	1736
790.446	1740
792.781	1736
795.115	1778
797.449	1798
799.782	1884
802.115	1882
804.446	1866
806.777	1892
809.106	1968
811.435	1944
813.764	2012
816.091	2056
818.418	2056
820.743	2096
823.069	2112
825.393	2084
827.717	2082
830.039	2168
832.362	2194
834.683	2252
837.003	2234
839.324	2278
841.643	2316
843.961	2312
846.278	2386
848.594	2332
850.91	2414
853.227	2482
855.541	2472
857.855	2506
860.168	2496
862.48	2504
864.79	2630
867.101	2630
869.411	2692
871.721	2650
874.029	2696
876.336	2678
878.643	2758
880.95	2758
883.254	2808
885.559	2822
887.862	2874
890.166	2918
892.467	2932
894.77	2856
897.07	3030
899.371	2980
901.669	3006
903.968	3030
906.266	3020
908.563	3124
910.859	3168
913.154	3250
915.449	3190
917.742	3272
920.036	3282
922.329	3296
924.621	3286
926.911	3402
929.201	3420
931.49	3466
933.779	3454
936.068	3428
938.355	3576
940.64	3642
942.926	3648
945.212	3652
947.495	3742
949.779	3764
952.062	3914
954.344	3844
956.625	3936
958.905	4002
961.184	3974
963.464	4048
965.742	4124
968.02	4166
970.296	4166
972.572	4140
974.847	4210
977.121	4316
979.396	4362
981.669	4390
983.941	4336
986.212	4518
988.483	4522
990.753	4526
993.022	4610
995.29	4638
997.558	4602
999.825	4648
1002.09	4718
1004.36	4850
1006.62	4822
1008.89	4886
1011.15	4930
1013.41	5010
1015.67	5010
1017.93	5070
1020.19	5108
1022.45	5170
1024.71	5244
1026.97	5312
1029.23	5322
1031.49	5356
1033.74	5450
1036	5458
1038.25	5530
1040.5	5630
1042.76	5688
1045.01	5706
1047.26	5884
1049.51	5954
1051.76	5936
1054.01	6070
1056.26	5980
1058.51	6152
1060.75	6178
1063	6122
1065.25	6194
1067.49	6252
1069.73	6284
1071.98	6364
1074.22	6362
1076.46	6464
1078.7	6472
1080.94	6520
1083.18	6510
1085.42	6660
1087.66	6654
1089.9	6660
1092.14	6780
1094.37	6856
1096.61	6828
1098.84	6870
1101.08	6796
1103.31	6900
1105.54	6968
1107.77	7046
1110	7032
1112.23	7066
1114.46	7092
1116.69	7210
1118.92	7288
1121.15	7360
1123.37	7392
1125.6	7296
1127.83	7454
1130.05	7500
1132.27	7612
1134.5	7544
1136.72	7672
1138.94	7634
1141.16	7758
1143.38	7828
1145.6	7746
1147.82	7968
1150.04	7884
1152.26	7976
1154.47	7998
1156.69	8104
1158.9	8058
1161.12	8126
1163.33	8192
1165.54	8150
1167.76	8126
1169.97	8108
1172.18	8156
1174.39	8250
1176.6	8288
1178.81	8238
1181.02	8312
1183.22	8236
1185.43	8110
1187.63	8214
1189.84	8280
1192.04	8352
1194.25	8276
1196.45	8124
1198.65	8310
1200.85	8200
1203.05	8294
1205.25	8232
1207.45	8216
1209.65	8218
1211.85	8154
1214.05	8144
1216.24	8112
1218.44	8068
1220.64	7994
1222.83	7984
1225.02	7952
1227.22	7968
1229.41	8096
1231.6	7916
1233.79	7932
1235.98	7914
1238.17	7896
1240.36	7912
1242.55	7922
1244.73	7784
1246.92	7886
1249.11	7758
1251.29	7904
1253.48	7774
1255.66	7662
1257.84	7700
1260.03	7620
1262.21	7614
1264.39	7598
1266.57	7478
1268.75	7594
1270.93	7488
1273.11	7514
1275.28	7574
1277.46	7334
1279.64	7286
1281.81	7256
1283.98	7260.3
1286.16	7136.49
1288.33	7099.23
1290.5	7134.64
1292.68	7047.42
1294.85	6886.78
1297.02	6831.06
1299.19	6817.78
1301.36	6761.4
1303.53	6660.96
1305.69	6728.87
1307.86	6599.65
1310.03	6485.63
1312.19	6498.75
1314.36	6446.82
1316.52	6382.28
1318.68	6301.41
1320.85	6236.51
1323.01	6191.96
1325.17	6182.87
1327.33	6097.87
1329.49	6027.06
1331.65	5958.99
1333.81	5905.93
1335.97	5787.95
1338.12	5787.34
1340.28	5768.31
1342.44	5647.39
1344.59	5570.57
1346.75	5485.55
1348.9	5444.13
1351.05	5472.14
1353.2	5403.52
1355.36	5308.31
1357.51	5345.78
1359.66	5325.6
1361.81	5107.04
1363.96	5061.09
1366.1	5101.53
1368.25	5064.44
1370.4	4943.74
1372.54	4904.94
1374.69	4915.01
1376.83	4826.41
1378.98	4831.01
1381.12	4691.88
1383.26	4744.57
1385.41	4730.99
1387.55	4660.9
1389.69	4547.89
1391.83	4603.46
1393.02	4496
1395.17	4492
1397.32	4436
1399.47	4484
1401.62	4298
1403.77	4338
1405.91	4342
1408.06	4262
1410.2	4292
1412.35	4338
1414.49	4256
1416.63	4168
1418.78	4164
1420.92	4084
1423.06	4094
1425.2	4080
1427.34	4092
1429.48	3988
1431.61	4030
1433.75	3924
1435.89	3968
1438.02	3912
1440.16	3988
1442.3	3902
1444.43	3832
1446.56	3702
1448.7	3798
1450.83	3806
1452.96	3736
1455.09	3736
1457.22	3688
1459.35	3654
1461.48	3674
1463.61	3616
1465.73	3690
1467.86	3600
1469.98	3560
1472.11	3620
1474.24	3488
1476.36	3556
1478.48	3538
1480.6	3550
1482.73	3444
1484.85	3508
1486.97	3378
1489.09	3412
1491.21	3434
1493.33	3402
1495.44	3448
1497.56	3354
1499.68	3314
1501.79	3368
1503.91	3290
1506.02	3334
1508.14	3280
1510.25	3278
1512.36	3312
1514.48	3172
1516.59	3222
1518.7	3242
1520.81	3138
1522.92	3124
1525.02	3098
1527.13	3096
1529.24	3114
1531.35	3088
1533.45	3050
1535.56	3036
1537.66	3096
1539.77	3048
1541.87	2992
1543.97	3044
1546.08	2932
1548.18	2948
1550.28	2926
1552.38	2982
1554.48	2910
1556.57	2906
1558.67	2810
1560.77	2804
1562.87	2816
1564.96	2850
1567.06	2772
1569.15	2886
1571.25	2866
1573.34	2832
1575.43	2764
1577.53	2746
1579.62	2782
1581.71	2802
1583.8	2772
1585.89	2780
1587.98	2746
1590.06	2720
1592.15	2750
1594.24	2708
1596.33	2678
1598.41	2700
1600.5	2694
1602.58	2696
1604.66	2630
1606.75	2644
1608.83	2698
1610.91	2602
1612.99	2640
1615.07	2702
1617.15	2636
1619.23	2630
1621.31	2626
1623.39	2566
1625.46	2606
1627.54	2638
1629.62	2566
1631.69	2624
1633.77	2606
1635.84	2606
1637.91	2592
1639.99	2616
1642.06	2474
1644.13	2522
1646.2	2550
1648.27	2536
1650.34	2550
1652.41	2570
1654.47	2512
1656.54	2482
1658.61	2472
1660.67	2476
1662.74	2456
1664.81	2484
1666.87	2464
1668.93	2468
1671	2452
1673.06	2404
1675.12	2406
1677.18	2436
1679.24	2460
1681.3	2350
1683.36	2364
1685.42	2354
1687.47	2386
1689.53	2386
1691.59	2406
1693.64	2352
1695.7	2348
1697.75	2396
1699.81	2352
1701.86	2314
1703.91	2346
1705.97	2304
1708.02	2364
1710.07	2320
1712.12	2310
1714.17	2344
1716.22	2200
1718.26	2320
1720.31	2304
1722.36	2300
1724.4	2258
1726.45	2360
1728.49	2286
1730.54	2296
1732.58	2268
1734.63	2270
1736.67	2228
1738.71	2294
1740.75	2214
1742.79	2206
1744.83	2240
1746.87	2224
1748.91	2268
1750.95	2260
1752.98	2236
1755.02	2226
1757.06	2272
1759.09	2228
1761.13	2198
1763.16	2184
1765.19	2258
1767.23	2236
1769.26	2194
1771.29	2182
1773.32	2220
1775.35	2240
1777.38	2212
1779.41	2156
1781.44	2236
1783.47	2252
1785.49	2212
1787.52	2270
1789.55	2226
1791.57	2214
1793.6	2208
1795.62	2222
1797.64	2216
1799.67	2172
1801.69	2138
1803.71	2264
1805.73	2148
1807.75	2172
1809.77	2166
1811.79	2196
1813.81	2216
1815.83	2190
1817.84	2172
1819.86	2198
1821.88	2156
1823.89	2176
1825.91	2156
1827.92	2190
1829.93	2180
1831.95	2140
1833.96	2158
1835.97	2140
1837.98	2130
1839.99	2156
1842	2184
1844.01	2172
1846.02	2120
1848.03	2140
1850.03	2144
1852.04	2146
1854.05	2130
1856.05	2190
1858.06	2100
1860.06	2092
1862.06	2144
1864.07	2120
1866.07	2108
1868.07	2176
1870.07	2078
1872.07	2112
1874.07	2116
1876.07	2082
1878.07	2094
1880.07	2160
1882.07	2174
1884.06	2120
1886.06	2150
1888.05	2100
1890.05	2128
1892.04	2120
1894.04	2138
1896.03	2086
1898.02	2118
1900.01	2116
1902	2096
1903.99	2110
1905.98	2106
1907.97	2072
1909.96	2116
1911.95	2098
1913.94	2070
1915.93	2108
1917.91	2096
1919.9	2064
1921.88	2084
1923.87	2104
1925.85	2082
1927.83	2100
1929.82	2094
1931.8	2092
1933.78	2094
1935.76	2100
1937.74	2100
1939.72	2096
1941.7	2084
1943.68	2112
1945.65	2076
1947.63	2026
1949.61	2064
1951.58	2036
1953.56	2050
1955.53	2046
1957.51	2066
1959.48	2052
1961.45	2026
1963.43	2032
1965.4	2038
1967.37	2004
1969.34	2006
1971.31	2028
1973.28	2050
1975.25	2032
1977.22	2082
1979.18	1980
1981.15	2034
1983.12	2066
1985.08	2046
1987.05	1986
1989.01	2014
1990.97	2004
1992.94	2026
1994.9	2010
1996.86	2032
1998.82	1986
2000.78	2038
2002.74	1994
2004.7	2046
2006.66	2022
2008.62	2046
2010.58	2026
2012.54	1978
2014.49	1982
2016.45	1978
2018.4	2012
2020.36	2010
2022.31	2008
2024.27	1950
2026.22	2006
2028.17	1991
2030.12	1990
2032.07	1990
2034.03	1966
2035.98	1956
2037.93	1986
2039.87	1970
2041.82	1946
2043.77	2000
2045.72	1964
2047.66	1954
2049.61	1970
2051.55	1912
2053.5	1986
2055.44	1948
2057.39	1926
2059.33	1996
2061.27	1958
2063.21	1920
2065.15	1914
2067.09	1978
2069.03	1958
2070.97	1918
2072.91	1946
2074.85	1918
2076.79	1970
2078.73	1968
2080.66	1884
2082.6	1922
2084.53	1956
2086.47	1966
2088.4	1926
2090.33	1940
2092.27	1944
2094.2	1922
2096.13	1932
2098.06	1876
2099.99	1914
2101.92	1900
2103.85	1886
2105.78	1918
2107.71	1970
2109.64	1898
2111.56	1938
2113.49	1920
2115.41	1932
2117.34	1916
2119.26	1894
2121.19	1936
2123.11	1888
2125.03	1890
2126.96	1898
2128.88	1862
2130.8	1894
2132.72	1922
2134.64	1928
2136.56	1854
2138.48	1892
2140.4	1866
2142.31	1922
2144.23	1892
2146.15	1926
2148.06	1900
2149.98	1912
2151.89	1878
2153.81	1856
2155.72	1864
2157.63	1880
2159.55	1856
2161.46	1840
2163.37	1822
2165.28	1860
2167.19	1896
2169.1	1888
2171.01	1864
2172.91	1856
2174.82	1848
2176.73	1832
2178.64	1830
2180.54	1862
2182.45	1898
2184.35	1864
2186.26	1846
2188.16	1810
2190.06	1802
2191.96	1826
2193.87	1794
2195.77	1766
2197.67	1760
2199.57	1778
2201.47	1794
2203.37	1772
2205.27	1766
2207.16	1764
2209.06	1808
2210.96	1784
2212.85	1844
2214.75	1796
2216.64	1760
2218.54	1740
2220.43	1724
2222.33	1800
2224.22	1707.46
2226.11	1732.1
2228	1745.37
2229.89	1726.67
2231.78	1789.56
2233.67	1757.25
2235.56	1749.13
2237.45	1765.82
2239.34	1714.95
2241.23	1736.96
2243.11	1713.53
2245	1734.94
2246.89	1720.75
2248.77	1708.08
2250.66	1715.13
2252.54	1663.68
2254.42	1684.35
2256.31	1723.54
2258.19	1713.37
2260.07	1699.73
2261.95	1700.78
2263.83	1667.36
2265.71	1685.21
2267.59	1681.67
2269.47	1666.22
2271.35	1637.09
2273.23	1660.53
2275.1	1661.54
2276.98	1632.09
2278.86	1626.95
2280.73	1662.04
2282.61	1614.94
2284.48	1608.86
2286.36	1609.47
2288.23	1601.72
2290.1	1602.4
2291.98	1604.61
2293.85	1601.19
2295.72	1592.76
2297.59	1594.18
2299.46	1608.01
2301.33	1596.59
2303.2	1556.99
2305.06	1569.69
2306.93	1547.38
2308.8	1557.51
2310.67	1574.76
2312.53	1534.3
2314.4	1529.92
2316.26	1503.98
2317.62	1514
2319.5	1536
2321.37	1506
2323.24	1526
2325.12	1524
2326.99	1506
2328.86	1556
2330.73	1520
2332.6	1540
2334.47	1540
2336.34	1508
2338.2	1470
2340.07	1440
2341.94	1480
2343.81	1484
2345.67	1478
2347.54	1486
2349.4	1462
2351.27	1462
2353.13	1476
2354.99	1502
2356.86	1442
2358.72	1448
2360.58	1476
2362.44	1458
2364.3	1438
2366.16	1476
2368.02	1454
2369.88	1426
2371.74	1442
2373.6	1436
2375.45	1350
2377.31	1422
2379.17	1416
2381.02	1428
2382.88	1418
2384.73	1380
2386.58	1346
2388.44	1386
2390.29	1348
2392.14	1362
2393.99	1356
2395.85	1324
2397.7	1374
2399.55	1380
2401.4	1330
2403.25	1328
2405.09	1314
2406.94	1344
2408.79	1350
2410.63	1328
2412.48	1342
2414.33	1316
2416.17	1340
2418.02	1322
2419.86	1292
2421.7	1288
2423.55	1246
2425.39	1284
2427.23	1256
2429.07	1276
2430.91	1208
2432.75	1250
2434.59	1300
2436.43	1278
2438.27	1256
2440.11	1268
2441.95	1246
2443.78	1202
2445.62	1218
2447.46	1218
2449.29	1218
2451.13	1200
2452.96	1170
2454.79	1186
2456.63	1162
2458.46	1174
2460.29	1158
2462.12	1172
2463.95	1158
2465.78	1140
2467.61	1178
2469.44	1154
2471.27	1146
2473.1	1118
2474.93	1098
2476.76	1130
2478.58	1146
2480.41	1146
2482.23	1096
2484.06	1108
2485.88	1080
2487.71	1098
2489.53	1124
2491.35	1058
2493.18	1086
2495	1070
2496.82	1056
2498.64	1058
2500.46	1084
2502.28	1058
2504.1	1028
2505.92	1006
2507.74	986
2509.55	1040
2511.37	1040
2513.19	1010
2515	1032
2516.82	1010
2518.63	1018
2520.45	976
2522.26	1024
2524.07	1018
2525.89	1026
2527.7	1006
2529.51	976
2531.32	972
2533.13	964
2534.94	986
2536.75	950
2538.56	936
2540.37	938
2542.18	924
2543.98	898
2545.79	932
2547.6	914
2549.4	922
2551.21	940
2553.01	908
2554.82	900
2556.62	902
2558.42	920
2560.23	878
2562.03	896
2563.83	882
2565.63	886
2567.43	872
2569.23	894
2571.03	866
2572.83	906
2574.63	876
2576.43	896
2578.22	848
2580.02	808
2581.82	822
2583.61	826
2585.41	814
2587.2	856
2589	828
2590.79	814
2592.58	816
2594.38	796
2596.17	814
2597.96	794
2599.75	794
2601.54	800
2603.33	778
2605.12	816
2606.91	788
2608.7	806
2610.49	760
2612.27	778
2614.06	734
2615.85	786
2617.63	758
2619.42	726
2621.2	776
2622.99	750
2624.77	768
2626.55	780
2628.34	714
2630.12	714
2631.9	756
2633.68	748
2635.46	724
2637.24	710
2639.02	720
2640.8	720
2642.58	690
2644.36	706
2646.14	708
2647.91	700
2649.69	732
2651.46	692
2653.24	712
2655.01	686
2656.79	644
2658.56	672
2660.34	700
2662.11	628
2663.88	684
2665.65	676
2667.42	660
2669.2	690
2670.96	672
2672.73	686
2674.5	628
2676.27	656
2678.04	650
2679.81	624
2681.58	618
2683.34	618
2685.11	638
2686.87	600
2688.64	620
2690.4	586
2692.17	634
2693.93	650
2695.69	622
2697.46	592
2699.22	598
2700.98	604
2702.74	618
2704.5	586
2706.26	600
2708.02	580
2709.78	572
2711.54	576
2713.3	558
2715.05	586
2716.81	556
2718.57	548
2720.32	570
2722.08	550
2723.83	554
2725.59	564
2727.34	530
2729.09	542
2730.85	546
2732.6	546
2734.35	518
2736.1	542
2737.85	534
2739.6	538
2741.35	530
2743.1	524
2744.85	538
2746.6	512
2748.35	494
2750.09	490
2751.84	534
2753.59	504
2755.33	474
2757.08	492
2758.82	472
2760.57	474
2762.31	492
2764.05	464
2765.79	480
2767.54	472
2769.28	496
2771.02	468
2772.76	468
2774.5	464
2776.24	482
2777.98	466
2779.72	448
2781.46	454
2783.19	440
2784.93	456
2786.67	434
2788.4	434
2790.14	448
2791.87	450
2793.61	438
2795.34	410
2797.07	446
2798.81	434
2800.54	390
2802.27	406
2804	422
2805.74	426
2807.47	404
2809.2	410
2810.93	412
2812.65	400
2814.38	422
2816.11	414
2817.84	404
2819.56	400
2821.29	390
2823.02	392
2824.74	358
2826.47	350
2828.19	378
2829.92	380
2831.64	406
2833.36	350
2835.09	368
2836.81	354
2838.53	352
2840.25	376
2841.97	358
2843.69	368
2845.41	372
2847.13	374
2848.85	330
2850.57	338
2852.28	372
2854	326
2855.72	346
2857.43	344
2859.15	326
2860.86	334
2862.58	320
2864.29	340
2866.01	332
2867.72	300
2869.43	332
2871.14	322
2872.86	338
2874.57	310
2876.28	298
2877.99	310
2879.7	322
2881.41	326
2883.11	332
2884.82	316
2886.53	308
2888.24	290
2889.94	304
2891.65	308
2893.36	312
2895.06	280
2896.77	306
2898.47	316
2900.17	298
2901.88	270
2903.58	262
2905.28	274
2906.98	276
2908.69	264
2910.39	276
2912.09	260
2913.79	256
2915.49	288
2917.19	280
2918.88	284
2920.58	264
2922.28	280
2923.98	266
2925.67	280
2927.37	268
2929.06	238
2930.76	260
2932.45	266
2934.15	238
2935.84	274
2937.53	268
2939.23	268
2940.92	266
2942.61	246
2944.3	256
2945.99	248
2947.68	254
2949.37	238
2951.06	258
2952.75	240
2954.44	248
2956.12	258
2957.81	248
2959.5	248
2961.18	224
2962.87	220
2964.56	248
2966.24	236
2967.92	232
2969.61	224
2971.29	264
2972.97	214
2974.66	212
2976.34	226
2978.02	224
2979.7	224
2981.38	234
2983.06	218
2984.74	216
2986.42	220
2988.1	210
2989.78	252
2991.45	186
2993.13	218
2994.81	208
2996.48	212
2998.16	196
2999.83	224