File: 3/Organic_01.txt
#Acq. time (s)=	15
#Accumulations=	1
#Range (cm-¹)=	100...2000
#Windows=	2
#Autofocus=	Off
#AutoExposure=	Off
#Spike filter=	Off
#Delay time (s)=	0
#Binning=	1
#Readout mode=	Signal
#DeNoise=	Off
#ICS correction=	Off
#Dark correction=	Off
#Inst. Process=	Off
#Instrument=	LabRAM HR Evol
#Detector=	Syncerity OE
#Objective=	x100_VIS
#Grating=	600 (500nm)
#ND Filter=	10%
#Laser=	633nm_Edge
#Hole=	100.021
#Range=	Visible
#Project=	Omar
#Sample=	20-06-23
#Site=	3
#Title=	Organic
#Remark=
#Date=	20.06.2023 12:12
#Acquired=	20.06.2023 12:12:37
101.054	7806
103.621	7734
106.187	7796
108.752	7760
111.317	7794
113.881	7728
116.443	7766
119.005	7798
121.566	7848
124.126	7842
126.685	7896
129.243	7814
131.801	7872
134.356	8216
136.911	8332
139.466	8670
142.021	8780
144.574	8250
147.125	8196
149.676	8044
152.227	7998
154.776	7790
157.325	8000
159.873	7968
162.419	7950
164.966	7886
167.51	7896
170.055	7862
172.598	7876
175.141	7926
177.682	7816
180.222	7888
182.763	7886
185.302	7920
187.839	7956
190.376	7908
192.914	8064
195.449	7884
197.983	8042
200.517	8026
203.05	8046
205.582	8076
208.113	8106
210.643	7918
213.173	8086
215.701	8074
218.229	8010
220.756	8158
223.282	8132
225.808	8116
228.331	8178
230.855	8178
233.378	8148
235.898	8128
238.419	8168
240.94	8152
243.458	8144
245.977	8208
248.495	8206
251.011	8268
253.527	8248
256.041	8134
258.555	8116
261.068	8166
263.58	8038
266.092	8154
268.603	8000
271.112	8074
273.62	8098
276.129	8146
278.636	7994
281.142	8122
283.647	8076
286.152	8002
288.655	8182
291.158	8086
293.66	8102
296.161	8274
298.661	8230
301.161	8164
303.66	8218
306.158	8238
308.655	8186
311.15	8270
313.645	8238
316.14	8258
318.634	8070
321.125	8206
323.618	8162
326.109	8168
328.598	8268
331.088	8098
333.576	8128
336.064	8166
338.55	8200
341.037	8260
343.521	8160
346.005	8214
348.489	8132
350.971	8100
353.453	8150
355.933	8150
358.414	8234
360.893	8030
363.371	8096
365.848	8196
368.325	8092
370.801	8166
373.275	8106
375.75	8038
378.223	8066
380.695	7894
383.167	7996
385.638	8074
388.108	7980
390.577	7998
393.044	7938
395.512	7958
397.979	7960
400.444	8006
402.909	7968
405.374	8036
407.836	7960
410.299	8026
412.76	7912
415.221	7894
417.681	8016
420.141	8224
422.598	8144
425.057	8124
427.513	8102
429.968	8108
432.422	8100
434.878	8134
437.33	8104
439.783	8028
442.234	8106
444.685	8118
447.134	8066
449.583	8116
452.032	7948
454.479	8006
456.926	7942
459.372	7956
461.817	7870
464.261	7920
466.705	7922
469.147	7880
471.588	7778
474.029	7834
476.47	7984
478.909	7896
481.347	7844
483.785	7812
486.221	7884
488.657	7976
491.092	7926
493.527	7972
495.96	7836
498.393	7882
500.824	7754
503.255	7976
505.686	7816
508.115	7818
510.543	7850
512.972	7756
515.399	7690
517.825	7818
520.25	7808
522.674	7776
525.097	7654
527.52	7444
529.942	7542
532.364	7576
534.784	7584
537.204	7490
539.623	7610
542.041	7542
544.457	7490
546.874	7438
549.289	7518
551.705	7412
554.118	7436
556.531	7344
558.943	7426
561.355	7410
563.766	7462
566.175	7478
568.585	7324
570.992	7370
573.399	7426
575.807	7222
578.212	7298
580.617	7274
583.022	7240
585.425	7346
587.827	7238
590.229	7346
592.63	7188
595.03	7378
597.43	7240
599.829	7360
602.226	7276
604.623	7106
607.02	7280
609.414	7200
611.808	7220
614.202	7292
616.596	7292
618.988	7228
621.378	7292
623.769	7280
626.159	7136
628.548	7250
630.936	7280
633.324	7398
635.71	7196
638.096	7294
640.481	7290
642.866	7392
645.248	7252
647.63	7266
650.013	7342
652.394	7158
654.773	7288
657.154	7224
659.532	7146
661.91	7146
664.286	7244
666.663	7080
669.038	7132
671.412	7046
673.786	7110
676.159	7038
678.532	6898
680.903	6940
683.274	7030
685.644	7020
688.014	6976
690.381	6882
692.749	6946
695.116	6868
697.481	6940
699.846	6858
702.211	6954
704.574	6920
706.938	6958
709.299	6894
711.661	6946
714.021	6804
716.381	6922
718.739	6902
721.097	6884
723.455	6930
725.811	6902
728.167	6806
730.521	6824
732.875	6854
735.23	6774
737.582	6810
739.934	6672
742.285	6754
744.635	6736
746.985	6670
749.332	6710
751.68	6708
754.028	6650
756.374	6600
758.72	6782
761.065	6570
763.408	6622
765.752	6620
768.095	6756
770.436	6602
772.777	6634
775.116	6528
777.456	6442
779.794	6450
782.133	6444
784.469	6518
786.805	6460
789.141	6522
791.476	6470
793.809	6402
796.142	6464
798.476	6444
800.807	6502
803.138	6358
805.468	6328
807.797	6442
810.125	6438
812.453	6402
814.78	6426
817.106	6444
819.432	6382
821.757	6356
824.08	6368
826.403	6312
828.726	6402
831.048	6338
833.368	6406
835.688	6450
838.007	6404
840.326	6358
842.644	6402
844.96	6386
847.276	6434
849.592	6402
851.906	6330
854.221	6360
856.534	6332
858.846	6412
861.157	6360
863.469	6364
865.779	6442
868.088	6310
870.396	6420
872.704	6224
875.011	6372
877.318	6358
879.623	6284
881.928	6284
884.232	6252
886.536	6180
888.837	6182
891.139	6164
893.44	6092
895.741	6200
898.039	6140
900.339	6170
902.637	6066
904.933	6134
907.231	6010
909.526	6054
911.821	6094
914.115	6018
916.408	6048
918.701	6076
920.993	6136
923.283	6046
925.573	5998
927.864	5986
930.153	6056
932.441	6072
934.728	5902
937.014	6064
939.3	6014
941.585	6080
943.87	6056
946.154	6064
948.437	6026
950.719	6112
952.999	5988
955.28	6022
957.56	5954
959.84	6076
962.117	6026
964.395	5980
966.671	6040
968.948	6026
971.223	6078
973.498	5980
975.771	6046
978.045	5864
980.317	5906
982.588	5886
984.86	6030
987.13	5936
989.399	5922
991.667	6040
993.937	5930
996.204	5934
998.47	5928
1000.74	5908
1003	5940
1005.26	5960
1007.53	5922
1009.79	5866
1012.05	5906
1014.31	5832
1016.57	5888
1018.83	5842
1021.09	5994
1023.35	5910
1025.61	5920
1027.87	6018
1030.12	5868
1032.38	5952
1034.63	5916
1036.88	5924
1039.14	5894
1041.39	6030
1043.64	6028
1045.89	5976
1048.14	6016
1050.39	5970
1052.64	6006
1054.89	5934
1057.14	5976
1059.38	5956
1061.63	5914
1063.87	5922
1066.12	5910
1068.36	5914
1070.6	6004
1072.85	5904
1075.09	5954
1077.33	5966
1079.57	5840
1081.81	5840
1084.05	5902
1086.28	5886
1088.52	5848
1090.76	5778
1092.99	5840
1095.23	5874
1097.46	5788
1099.69	5820
1101.93	5764
1104.16	5706
1106.39	5680
1108.62	5682
1110.85	5762
1113.08	5728
1115.31	5730
1117.53	5820
1119.76	5662
1121.99	5802
1124.21	5786
1126.44	5758
1128.66	5736
1130.88	5654
1133.11	5702
1135.33	5732
1137.55	5734
1139.77	5710
1141.99	5798
1144.21	5700
1146.43	5888
1148.64	5754
1150.86	5854
1153.08	5800
1155.29	5784
1157.51	5798
1159.72	5832
1161.93	5738
1164.14	5796
1166.36	5840
1168.57	5756
1170.78	5794
1172.99	5808
1175.2	5798
1177.4	5724
1179.61	5774
1181.82	5754
1184.02	5706
1186.23	5692
1188.43	5676
1190.64	5690
1192.84	5692
1195.04	5722
1197.24	5736
1199.45	5648.16
1201.64	5609.01
1203.84	5579.37
1206.04	5618.55
1208.24	5631.56
1210.44	5564.16
1212.64	5571.42
1214.83	5637.37
1217.03	5589.47
1219.22	5601.46
1221.41	5595.47
1223.61	5621.43
1225.8	5556.62
1227.99	5580.54
1230.18	5557.07
1232.37	5582.79
1234.56	5527.87
1236.75	5590.98
1238.94	5600.63
1241.13	5600.86
1243.31	5563.58
1245.5	5531.01
1247.68	5563.9
1249.87	5592.81
1252.05	5604.35
1254.24	5600.64
1256.42	5616.46
1258.6	5623.43
1260.78	5566.91
1262.96	5588.22
1265.14	5606.49
1267.32	5600.49
1269.5	5634.63
1271.67	5600.2
1273.85	5643.07
1276.03	5607.22
1278.2	5675.23
1280.38	5657.05
1282.55	5682.95
1284.72	5644.44
1286.9	5651.68
1289.07	5619.36
1291.24	5649.86
1293.41	5640.18
1295.58	5681.84
1297.75	5633.91
1299.92	5659.5
1302.09	5611.88
1304.25	5671.29
1306.42	5595.39
1308.46	5644
1310.63	5576
1312.81	5638
1314.98	5514
1317.16	5606
1319.33	5572
1321.5	5586
1323.67	5612
1325.85	5576
1328.02	5570
1330.19	5556
1332.35	5520
1334.52	5554
1336.69	5678
1338.86	5468
1341.02	5550
1343.19	5458
1345.35	5498
1347.52	5448
1349.68	5456
1351.84	5518
1354	5490
1356.17	5472
1358.33	5454
1360.49	5534
1362.65	5530
1364.8	5446
1366.96	5474
1369.12	5352
1371.28	5512
1373.43	5430
1375.59	5448
1377.74	5468
1379.89	5440
1382.05	5372
1384.2	5474
1386.35	5412
1388.5	5294
1390.65	5360
1392.8	5438
1394.95	5390
1397.1	5344
1399.25	5366
1401.4	5366
1403.54	5420
1405.69	5300
1407.83	5382
1409.98	5340
1412.12	5328
1414.26	5332
1416.4	5300
1418.55	5214
1420.69	5352
1422.83	5304
1424.97	5384
1427.1	5278
1429.24	5284
1431.38	5332
1433.52	5288
1435.65	5258
1437.79	5228
1439.92	5196
1442.06	5324
1444.19	5230
1446.32	5210
1448.46	5216
1450.59	5226
1452.72	5240
1454.85	5176
1456.98	5264
1459.11	5374
1461.23	5118
1463.36	5180
1465.49	5078
1467.61	5192
1469.74	5236
1471.86	5142
1473.99	5208
1476.11	5158
1478.23	5126
1480.36	5130
1482.48	5130
1484.6	5008
1486.72	5128
1488.84	5116
1490.96	5162
1493.07	5124
1495.19	5104
1497.31	5096
1499.42	5112
1501.54	5086
1503.65	5160
1505.77	5132
1507.88	5080
1509.99	4998
1512.1	5034
1514.22	5016
1516.33	5012
1518.44	4896
1520.55	4946
1522.65	5002
1524.76	4934
1526.87	4898
1528.98	4908
1531.08	4922
1533.19	4870
1535.29	4946
1537.4	4922
1539.5	4762
1541.6	4810
1543.7	4826
1545.8	4800
1547.91	4770
1550.01	4842
1552.11	4710
1554.2	4714
1556.3	4718
1558.4	4748
1560.5	4756
1562.59	4712
1564.69	4678
1566.78	4754
1568.88	4652
1570.97	4694
1573.06	4680
1575.15	4698
1577.25	4704
1579.34	4624
1581.43	4650
1583.52	4614
1585.6	4680
1587.69	4638
1589.78	4778
1591.87	4606
1593.95	4608
1596.04	4672
1598.12	4684
1600.21	4644
1602.29	4624
1604.37	4672
1606.46	4702
1608.54	4590
1610.62	4612
1612.7	4578
1614.78	4564
1616.86	4560
1618.94	4486
1621.01	4464
1623.09	4528
1625.17	4496
1627.24	4512
1629.32	4468
1631.39	4462
1633.47	4484
1635.54	4462
1637.61	4450
1639.68	4510
1641.76	4426
1643.83	4454
1645.9	4462
1647.96	4436
1650.03	4472
1652.1	4458
1654.17	4402
1656.24	4330
1658.3	4396
1660.37	4346
1662.43	4380
1664.5	4348
1666.56	4374
1668.62	4282
1670.68	4280
1672.75	4270
1674.81	4280
1676.87	4240
1678.93	4278
1680.99	4240
1683.04	4242
1685.1	4244
1687.16	4182
1689.21	4252
1691.27	4176
1693.33	4130
1695.38	4110
1697.43	4164
1699.49	4042
1701.54	4074
1703.59	4228
1705.64	4084
1707.69	4040
1709.74	4034
1711.79	4056
1713.84	4056
1715.89	4102
1717.94	4024
1719.98	3994
1722.03	3980
1724.07	3968
1726.12	3826
1728.16	4004
1730.21	3996
1732.25	4000
1734.29	3882
1736.33	3924
1738.37	3918
1740.41	3960
1742.45	3888
1744.49	3910
1746.53	3904
1748.57	3856
1750.61	3834
1752.64	3818
1754.68	3820
1756.71	3848
1758.75	3842
1760.78	3856
1762.82	3840
1764.85	3850
1766.88	3800
1768.91	3794
1770.94	3798
1772.97	3664
1775	3830
1777.03	3750
1779.06	3664
1781.09	3732
1783.12	3802
1785.14	3734
1787.17	3666
1789.19	3708
1791.22	3574
1793.24	3696
1795.27	3704
1797.29	3680
1799.31	3668
1801.33	3638
1803.35	3656
1805.37	3638
1807.39	3616
1809.41	3560
1811.43	3586
1813.45	3626
1815.46	3590
1817.48	3432
1819.5	3544
1821.51	3474
1823.53	3514
1825.54	3520
1827.55	3520
1829.57	3470
1831.58	3504
1833.59	3424
1835.6	3434
1837.61	3374
1839.62	3412
1841.63	3428
1843.64	3438
1845.65	3408
1847.65	3350
1849.66	3360
1851.66	3440
1853.67	3316
1855.67	3268
1857.68	3250
1859.68	3290
1861.68	3232
1863.69	3218
1865.69	3228
1867.69	3314
1869.69	3214
1871.69	3230
1873.69	3208
1875.69	3272
1877.68	3216
1879.68	3154
1881.68	3120
1883.67	3128
1885.67	3160
1887.66	3230
1889.66	3160
1891.65	3190
1893.64	3180
1895.64	3124
1897.63	3162
1899.62	3144
1901.61	3140
1903.6	3170
1905.59	3088
1907.58	3098
1909.56	3120
1911.55	3092
1913.54	3096
1915.53	3080
1917.51	3032
1919.5	3078
1921.48	3080
1923.46	3026
1925.45	3002
1927.43	3092
1929.41	3004
1931.39	2982
1933.37	3010
1935.35	2998
1937.33	3004
1939.31	2948
1941.29	2892
1943.27	2952
1945.24	2920
1947.22	2918
1949.2	2944
1951.17	2834
1953.14	2863
1955.12	2832
1957.09	2820
1959.06	2868
1961.04	2804
1963.01	2846
1964.98	2798
1966.95	2816
1968.92	2772
1970.89	2858
1972.86	2862
1974.82	2800
1976.79	2760
1978.76	2774
1980.72	2792
1982.69	2748
1984.65	2722
1986.62	2712
1988.58	2716
1990.54	2692
1992.51	2696
1994.47	2670
1996.43	2680
1998.39	2698
1999.37	2676