File: 3/Organic_06.txt
#Acq. time (s)=	15
#Accumulations=	1
#Range (cm-¹)=	100...2000
#Windows=	2
#Autofocus=	Off
#AutoExposure=	Off
#Spike filter=	Off
#Delay time (s)=	0
#Binning=	1
#Readout mode=	Signal
#DeNoise=	Off
#ICS correction=	Off
#Dark correction=	Off
#Inst. Process=	Off
#Instrument=	LabRAM HR Evol
#Detector=	Syncerity OE
#Objective=	x100_VIS
#Grating=	600 (500nm)
#ND Filter=	25%
#Laser=	633nm_Edge
#Hole=	49.98
#Range=	Visible
#Project=	Omar
#Sample=	20-06-23
#Site=	3
#Title=	Organic
#Remark=
#Date=	20.06.2023 12:19
#Acquired=	20.06.2023 12:19:22
101.054	7940
103.621	7926
106.187	8024
108.752	7892
111.317	8112
113.881	8050
116.443	8118
119.005	8130
121.566	8296
124.126	8352
126.685	8440
129.243	8402
131.801	8626
134.356	8420
136.911	8612
139.466	8598
142.021	8668
144.574	8728
147.125	8736
149.676	8904
152.227	8842
154.776	8808
157.325	8972
159.873	8834
162.419	8926
164.966	8984
167.51	9230
170.055	9032
172.598	9212
175.141	9174
177.682	9256
180.222	9250
182.763	9328
185.302	9444
187.839	9536
190.376	9676
192.914	9618
195.449	9786
197.983	9932
200.517	9872
203.05	9936
205.582	9918
208.113	10116
210.643	10204
213.173	10238
215.701	10298
218.229	10410
220.756	10376
223.282	10556
225.808	10674
228.331	10718
230.855	10732
233.378	10844
235.898	10872
238.419	11084
240.94	10894
243.458	11242
245.977	11160
248.495	11340
251.011	11288
253.527	11454
256.041	11470
258.555	11588
261.068	11586
263.58	11710
266.092	11672
268.603	11834
271.112	11680
273.62	11662
276.129	11908
278.636	11968
281.142	12012
283.647	12214
286.152	12120
288.655	12222
291.158	12426
293.66	12594
296.161	12498
298.661	12814
301.161	12842
303.66	12880
306.158	13060
308.655	13020
311.15	13220
313.645	13272
316.14	13308
318.634	13380
321.125	13434
323.618	13504
326.109	13602
328.598	13780
331.088	13616
333.576	13830
336.064	13960
338.55	13892
341.037	14144
343.521	14168
346.005	14420
348.489	14490
350.971	14394
353.453	14460
355.933	14518
358.414	14670
360.893	14692
363.371	14854
365.848	14828
368.325	15050
370.801	14972
373.275	15168
375.75	15174
378.223	15008
380.695	15142
383.167	15338
385.638	15366
388.108	15140
390.577	15432
393.044	15538
395.512	15700
397.979	15806
400.444	15836
402.909	16078
405.374	16042
407.836	16296
410.299	16508
412.76	16466
415.221	16686
417.681	16806
420.141	16950
422.598	17078
425.057	17140
427.513	17222
429.968	17482
432.422	17498
434.878	17400
437.33	17648
439.783	17660
442.234	17854
444.685	17628
447.134	17968
449.583	18040
452.032	17820
454.479	17944
456.926	17988
459.372	18194
461.817	18306
464.261	18148
466.705	18404
469.147	18490
471.588	18654
474.029	18670
476.47	18760
478.909	18894
481.347	19134
483.785	19038
486.221	19438
488.657	19444
491.092	19550
493.527	19734
495.96	19672
498.393	19674
500.824	19822
503.255	20122
505.686	19912
508.115	19800
510.543	20164
512.972	20174
515.399	20226
517.825	20336
520.25	20286
522.674	20498
525.097	20446
527.52	20408
529.942	20468
532.364	20494
534.784	20422
537.204	20652
539.623	20684
542.041	20808
544.457	20934
546.874	20966
549.289	20994
551.705	20992
554.118	21176
556.531	21100
558.943	21212
561.355	21308
563.766	21396
566.175	21484
568.585	21846
570.992	21660
573.399	21568
575.807	21864
578.212	21850
580.617	22082
583.022	22072
585.425	22230
587.827	22366
590.229	22338
592.63	22452
595.03	22646
597.43	22468
599.829	22614
602.226	22930
604.623	22856
607.02	23092
609.414	23212
611.808	23324
614.202	23214
616.596	23712
618.988	23568
621.378	23642
623.769	23658
626.159	23892
628.548	24034
630.936	24202
633.324	24288
635.71	24280
638.096	24646
640.481	24608
642.866	24676
645.248	24706
647.63	24728
650.013	24990
652.394	25022
654.773	25082
657.154	25086
659.532	25150
661.91	25180
664.286	25196
666.663	25102
669.038	25218
671.412	25224
673.786	25374
676.159	25226
678.532	25508
680.903	25562
683.274	25648
685.644	25404
688.014	25648
690.381	25540
692.749	25740
695.116	25662
697.481	25698
699.846	25800
702.211	25974
704.574	25962
706.938	26156
709.299	26108
711.661	26194
714.021	26392
716.381	26342
718.739	26410
721.097	26470
723.455	26612
725.811	26724
728.167	26664
730.521	26830
732.875	26790
735.23	26568
737.582	26842
739.934	26872
742.285	26894
744.635	27036
746.985	26988
749.332	26962
751.68	26880
754.028	27172
756.374	27168
758.72	27060
761.065	26918
763.408	27130
765.752	27090
768.095	27134
770.436	26974
772.777	27240
775.116	27228
777.456	27110
779.794	27060
782.133	27220
784.469	27158
786.805	27364
789.141	27476
791.476	27356
793.809	27386
796.142	27532
798.476	27478
800.807	27708
803.138	27690
805.468	27638
807.797	27822
810.125	27848
812.453	27872
814.78	28068
817.106	28202
819.432	28042
821.757	27962
824.08	28306
826.403	28060
828.726	28402
831.048	28428
833.368	28614
835.688	28444
838.007	28388
840.326	28660
842.644	28520
844.96	28492
847.276	28758
849.592	28788
851.906	28682
854.221	28692
856.534	28784
858.846	28794
861.157	29002
863.469	29006
865.779	28882
868.088	28870
870.396	28756
872.704	28806
875.011	28764
877.318	28732
879.623	28638
881.928	28318
884.232	28440
886.536	28576
888.837	28252
891.139	28414
893.44	28346
895.741	28092
898.039	28240
900.339	28230
902.637	28246
904.933	28074
907.231	27998
909.526	28012
911.821	27946
914.115	28072
916.408	27818
918.701	27944
920.993	27978
923.283	27788
925.573	28012
927.864	27968
930.153	28120
932.441	27948
934.728	27880
937.014	27810
939.3	27774
941.585	27904
943.87	27918
946.154	28142
948.437	27876
950.719	27740
952.999	27796
955.28	27978
957.56	27978
959.84	27850
962.117	27910
964.395	27894
966.671	27738
968.948	28094
971.223	27732
973.498	27840
975.771	27770
978.045	27408
980.317	27588
982.588	27574
984.86	27480
987.13	27368
989.399	27550
991.667	27440
993.937	27392
996.204	27178
998.47	27182
1000.74	27102
1003	26966
1005.26	27016
1007.53	27160
1009.79	27060
1012.05	27132
1014.31	27038
1016.57	26926
1018.83	26928
1021.09	27032
1023.35	27078
1025.61	27018
1027.87	26808
1030.12	26738
1032.38	26998
1034.63	27072
1036.88	26898
1039.14	26920
1041.39	26676
1043.64	26794
1045.89	26992
1048.14	26946
1050.39	27038
1052.64	26754
1054.89	26770
1057.14	26796
1059.38	26674
1061.63	26562
1063.87	26564
1066.12	26464
1068.36	26302
1070.6	26304
1072.85	26226
1075.09	26208
1077.33	26106
1079.57	25964
1081.81	25626
1084.05	25776
1086.28	25624
1088.52	25646
1090.76	25244
1092.99	25074
1095.23	25282
1097.46	25180
1099.69	24862
1101.93	24974
1104.16	24906
1106.39	24816
1108.62	24802
1110.85	24468
1113.08	24688
1115.31	24402
1117.53	24508
1119.76	24308
1121.99	24348
1124.21	24334
1126.44	24224
1128.66	24206
1130.88	24266
1133.11	24132
1135.33	24036
1137.55	23962
1139.77	23940
1141.99	24088
1144.21	24016
1146.43	24088
1148.64	23896
1150.86	23700
1153.08	23850
1155.29	23852
1157.51	23842
1159.72	23736
1161.93	23748
1164.14	23508
1166.36	23428
1168.57	23632
1170.78	23238
1172.99	23146
1175.2	23330
1177.4	23304
1179.61	23310
1181.82	23044
1184.02	23048
1186.23	22904
1188.43	22876
1190.64	22850
1192.84	22494
1195.04	22486
1197.24	22408
1199.45	22463.2
1201.64	22156.5
1203.84	21883.2
1206.04	21973.4
1208.24	21668.8
1210.44	21619.8
1212.64	21347.7
1214.83	21238
1217.03	21036.2
1219.22	20952
1221.41	20899
1223.61	20700
1225.8	20570.1
1227.99	20452.9
1230.18	20395.5
1232.37	20269.4
1234.56	20179.4
1236.75	19955
1238.94	19963.6
1241.13	19633.7
1243.31	19551.6
1245.5	19495.2
1247.68	19338.6
1249.87	19238.9
1252.05	19088.8
1254.24	19174.8
1256.42	18980.8
1258.6	18911.6
1260.78	18753.5
1262.96	18672.6
1265.14	18534.4
1267.32	18500.1
1269.5	18245.2
1271.67	18272
1273.85	18171.7
1276.03	17994.8
1278.2	17897
1280.38	17845.2
1282.55	17798.4
1284.72	17707.2
1286.9	17645.7
1289.07	17428.1
1291.24	17483.7
1293.41	17272.1
1295.58	17177.4
1297.75	17122.6
1299.92	16948.5
1302.09	16810.7
1304.25	16713
1306.42	16566.1
1308.46	16530
1310.63	16376
1312.81	16310
1314.98	16274
1317.16	16370
1319.33	16262
1321.5	16154
1323.67	15992
1325.85	15860
1328.02	15978
1330.19	15852
1332.35	15684
1334.52	15764
1336.69	15660
1338.86	15432
1341.02	15750
1343.19	15534
1345.35	15586
1347.52	15480
1349.68	15388
1351.84	15354
1354	15176
1356.17	15198
1358.33	15184
1360.49	15134
1362.65	15064
1364.8	15042
1366.96	14866
1369.12	14910
1371.28	14786
1373.43	14724
1375.59	14580
1377.74	14666
1379.89	14530
1382.05	14494
1384.2	14554
1386.35	14268
1388.5	14492
1390.65	14342
1392.8	14426
1394.95	14308
1397.1	14166
1399.25	14314
1401.4	14086
1403.54	14174
1405.69	13894
1407.83	14008
1409.98	13758
1412.12	13780
1414.26	13804
1416.4	13702
1418.55	13616
1420.69	13648
1422.83	13580
1424.97	13606
1427.1	13404
1429.24	13450
1431.38	13298
1433.52	13372
1435.65	13326
1437.79	13244
1439.92	13208
1442.06	13176
1444.19	13052
1446.32	13078
1448.46	13078
1450.59	12992
1452.72	12896
1454.85	12842
1456.98	12796
1459.11	12924
1461.23	12642
1463.36	12644
1465.49	12746
1467.61	12700
1469.74	12744
1471.86	12550
1473.99	12466
1476.11	12434
1478.23	12306
1480.36	12470
1482.48	12458
1484.6	12340
1486.72	12260
1488.84	12226
1490.96	12202
1493.07	12208
1495.19	12030
1497.31	12212
1499.42	12082
1501.54	12054
1503.65	11906
1505.77	11796
1507.88	11732
1509.99	11674
1512.1	11692
1514.22	11772
1516.33	11392
1518.44	11580
1520.55	11538
1522.65	11400
1524.76	11458
1526.87	11338
1528.98	11232
1531.08	11200
1533.19	11184
1535.29	10962
1537.4	11042
1539.5	11082
1541.6	10868
1543.7	10846
1545.8	10836
1547.91	10776
1550.01	10746
1552.11	10720
1554.2	10820
1556.3	10760
1558.4	10628
1560.5	10656
1562.59	10500
1564.69	10596
1566.78	10418
1568.88	10516
1570.97	10468
1573.06	10440
1575.15	10314
1577.25	10328
1579.34	10308
1581.43	10186
1583.52	10314
1585.6	10292
1587.69	10152
1589.78	10220
1591.87	10134
1593.95	10132
1596.04	10102
1598.12	10026
1600.21	9976
1602.29	9966
1604.37	9978
1606.46	9796
1608.54	9946
1610.62	9850
1612.7	9956
1614.78	9752
1616.86	9836
1618.94	9780
1621.01	9824
1623.09	9784
1625.17	9672
1627.24	9572
1629.32	9476
1631.39	9614
1633.47	9534
1635.54	9496
1637.61	9398
1639.68	9394
1641.76	9414
1643.83	9402
1645.9	9294
1647.96	9318
1650.03	9300
1652.1	9282
1654.17	9168
1656.24	9092
1658.3	9128
1660.37	9240
1662.43	9182
1664.5	8992
1666.56	8980
1668.62	9040
1670.68	9076
1672.75	8966
1674.81	8910
1676.87	8796
1678.93	8840
1680.99	8966
1683.04	8764
1685.1	8840
1687.16	8736
1689.21	8588
1691.27	8586
1693.33	8574
1695.38	8460
1697.43	8512
1699.49	8542
1701.54	8454
1703.59	8428
1705.64	8456
1707.69	8392
1709.74	8252
1711.79	8288
1713.84	8364
1715.89	8342
1717.94	8226
1719.98	8246
1722.03	8328
1724.07	8274
1726.12	8242
1728.16	8114
1730.21	8144
1732.25	8022
1734.29	8060
1736.33	7954
1738.37	8076
1740.41	7920
1742.45	7974
1744.49	7922
1746.53	7950
1748.57	7916
1750.61	7840
1752.64	7746
1754.68	7808
1756.71	7760
1758.75	7776
1760.78	7780
1762.82	7790
1764.85	7772
1766.88	7746
1768.91	7682
1770.94	7776
1772.97	7614
1775	7672
1777.03	7554
1779.06	7598
1781.09	7624
1783.12	7546
1785.14	7530
1787.17	7494
1789.19	7444
1791.22	7510
1793.24	7398
1795.27	7406
1797.29	7372
1799.31	7356
1801.33	7412
1803.35	7360
1805.37	7258
1807.39	7334
1809.41	7236
1811.43	7088
1813.45	7174
1815.46	7276
1817.48	7206
1819.5	7100
1821.51	7080
1823.53	7012
1825.54	7080
1827.55	7012
1829.57	6912
1831.58	7000
1833.59	6972
1835.6	6880
1837.61	6888
1839.62	6824
1841.63	6866
1843.64	6748
1845.65	6672
1847.65	6716
1849.66	6708
1851.66	6682
1853.67	6670
1855.67	6568
1857.68	6644
1859.68	6620
1861.68	6642
1863.69	6516
1865.69	6698
1867.69	6534
1869.69	6558
1871.69	6478
1873.69	6474
1875.69	6484
1877.68	6438
1879.68	6512
1881.68	6322
1883.67	6452
1885.67	6306
1887.66	6340
1889.66	6322
1891.65	6368
1893.64	6326
1895.64	6266
1897.63	6346
1899.62	6410
1901.61	6292
1903.6	6164
1905.59	6214
1907.58	6168
1909.56	6146
1911.55	6158
1913.54	6264
1915.53	6158
1917.51	6152
1919.5	6168
1921.48	6164
1923.46	6156
1925.45	6100
1927.43	5946
1929.41	6128
1931.39	6036
1933.37	6032
1935.35	6074
1937.33	6054
1939.31	5968
1941.29	5978
1943.27	6048
1945.24	5892
1947.22	5932
1949.2	5970
1951.17	5892
1953.14	5882
1955.12	5908
1957.09	5862
1959.06	5846
1961.04	5828
1963.01	5700
1964.98	5762
1966.95	5694
1968.92	5726
1970.89	5784
1972.86	5822
1974.82	5794
1976.79	5730
1978.76	5644
1980.72	5602
1982.69	5584
1984.65	5682
1986.62	5638
1988.58	5578
1990.54	5656
1992.51	5472
1994.47	5490
1996.43	5514
1998.39	5520
1999.37	5564