File: 3/Organic_05.txt
#Acq. time (s)=	15
#Accumulations=	1
#Range (cm-¹)=	100...2000
#Windows=	2
#Autofocus=	Off
#AutoExposure=	Off
#Spike filter=	Off
#Delay time (s)=	0
#Binning=	1
#Readout mode=	Signal
#DeNoise=	Off
#ICS correction=	Off
#Dark correction=	Off
#Inst. Process=	Off
#Instrument=	LabRAM HR Evol
#Detector=	Syncerity OE
#Objective=	x100_VIS
#Grating=	600 (500nm)
#ND Filter=	10%
#Laser=	633nm_Edge
#Hole=	49.98
#Range=	Visible
#Project=	Omar
#Sample=	20-06-23
#Site=	3
#Title=	Organic
#Remark=
#Date=	20.06.2023 12:17
#Acquired=	20.06.2023 12:17:20
101.054	4678
103.621	4778
106.187	4770
108.752	4752
111.317	4832
113.881	4872
116.443	4884
119.005	4906
121.566	4950
124.126	4998
126.685	5032
129.243	5000
131.801	5116
134.356	5144
136.911	5128
139.466	5098
142.021	5146
144.574	5320
147.125	5238
149.676	5166
152.227	5288
154.776	5270
157.325	5378
159.873	5338
162.419	5448
164.966	5374
167.51	5528
170.055	5450
172.598	5524
175.141	5492
177.682	5602
180.222	5648
182.763	5554
185.302	5650
187.839	5782
190.376	5786
192.914	5852
195.449	5856
197.983	5938
200.517	5948
203.05	5902
205.582	6028
208.113	6134
210.643	6104
213.173	6242
215.701	6200
218.229	6274
220.756	6242
223.282	6314
225.808	6426
228.331	6398
230.855	6448
233.378	6542
235.898	6574
238.419	6510
240.94	6654
243.458	6754
245.977	6692
248.495	6792
251.011	6796
253.527	6766
256.041	6818
258.555	6904
261.068	6896
263.58	6934
266.092	6960
268.603	7052
271.112	7074
273.62	7052
276.129	7078
278.636	7190
281.142	7254
283.647	7228
286.152	7330
288.655	7444
291.158	7506
293.66	7458
296.161	7550
298.661	7602
301.161	7716
303.66	7758
306.158	7830
308.655	7910
311.15	7898
313.645	7990
316.14	7984
318.634	8176
321.125	8090
323.618	8038
326.109	8128
328.598	8146
331.088	8292
333.576	8366
336.064	8354
338.55	8382
341.037	8518
343.521	8518
346.005	8596
348.489	8656
350.971	8802
353.453	8776
355.933	8744
358.414	8844
360.893	8916
363.371	8940
365.848	9042
368.325	9012
370.801	9092
373.275	9012
375.75	9128
378.223	9250
380.695	9170
383.167	9310
385.638	9314
388.108	9236
390.577	9412
393.044	9368
395.512	9612
397.979	9532
400.444	9652
402.909	9656
405.374	9710
407.836	9906
410.299	9850
412.76	10032
415.221	10104
417.681	10238
420.141	10260
422.598	10328
425.057	10410
427.513	10522
429.968	10544
432.422	10562
434.878	10666
437.33	10778
439.783	10760
442.234	10872
444.685	10864
447.134	10946
449.583	11072
452.032	10948
454.479	10988
456.926	11110
459.372	11042
461.817	11160
464.261	11274
466.705	11288
469.147	11358
471.588	11424
474.029	11472
476.47	11436
478.909	11690
481.347	11782
483.785	11678
486.221	11780
488.657	11738
491.092	11860
493.527	12070
495.96	11904
498.393	12096
500.824	11994
503.255	12142
505.686	12276
508.115	12366
510.543	12478
512.972	12458
515.399	12442
517.825	12428
520.25	12550
522.674	12516
525.097	12590
527.52	12636
529.942	12670
532.364	12582
534.784	12556
537.204	12716
539.623	12848
542.041	12758
544.457	12912
546.874	12960
549.289	12984
551.705	12892
554.118	13122
556.531	13200
558.943	13154
561.355	13304
563.766	13338
566.175	13338
568.585	13460
570.992	13472
573.399	13702
575.807	13668
578.212	13746
580.617	13664
583.022	13788
585.425	13792
587.827	13974
590.229	13888
592.63	13958
595.03	14066
597.43	14122
599.829	14072
602.226	14102
604.623	14386
607.02	14366
609.414	14430
611.808	14348
614.202	14546
616.596	14798
618.988	14708
621.378	14766
623.769	14820
626.159	15010
628.548	15136
630.936	14938
633.324	15216
635.71	15272
638.096	15290
640.481	15350
642.866	15566
645.248	15350
647.63	15552
650.013	15600
652.394	15580
654.773	15436
657.154	15664
659.532	15488
661.91	15680
664.286	15768
666.663	15636
669.038	15744
671.412	15826
673.786	15844
676.159	15686
678.532	15700
680.903	15870
683.274	15900
685.644	15920
688.014	16042
690.381	15842
692.749	16102
695.116	16058
697.481	16252
699.846	16192
702.211	16280
704.574	16280
706.938	16304
709.299	16276
711.661	16390
714.021	16522
716.381	16478
718.739	16478
721.097	16530
723.455	16480
725.811	16608
728.167	16700
730.521	16504
732.875	16676
735.23	16804
737.582	16724
739.934	16732
742.285	16804
744.635	16800
746.985	16874
749.332	16596
751.68	16758
754.028	16798
756.374	16750
758.72	16858
761.065	16784
763.408	16820
765.752	16816
768.095	16888
770.436	16798
772.777	16810
775.116	17038
777.456	17014
779.794	16886
782.133	16970
784.469	17054
786.805	16936
789.141	17010
791.476	17160
793.809	17102
796.142	17260
798.476	17016
800.807	17286
803.138	17042
805.468	17336
807.797	17180
810.125	17248
812.453	17362
814.78	17494
817.106	17464
819.432	17654
821.757	17590
824.08	17530
826.403	17418
828.726	17722
831.048	17692
833.368	17716
835.688	17884
838.007	17840
840.326	17622
842.644	17932
844.96	17884
847.276	17852
849.592	17940
851.906	17890
854.221	17974
856.534	17768
858.846	17822
861.157	17680
863.469	17852
865.779	17928
868.088	18010
870.396	17930
872.704	17886
875.011	17902
877.318	17880
879.623	17940
881.928	17888
884.232	17832
886.536	18026
888.837	17920
891.139	17840
893.44	17822
895.741	17710
898.039	17734
900.339	17718
902.637	17780
904.933	17558
907.231	17822
909.526	17620
911.821	17704
914.115	17674
916.408	17744
918.701	17746
920.993	17546
923.283	17664
925.573	17728
927.864	17550
930.153	17564
932.441	17744
934.728	17632
937.014	17680
939.3	17784
941.585	17808
943.87	17808
946.154	17876
948.437	17768
950.719	17608
952.999	17816
955.28	17886
957.56	17870
959.84	17742
962.117	17964
964.395	17878
966.671	17634
968.948	17766
971.223	17686
973.498	17538
975.771	17662
978.045	17548
980.317	17756
982.588	17536
984.86	17432
987.13	17454
989.399	17542
991.667	17528
993.937	17670
996.204	17488
998.47	17492
1000.74	17388
1003	17510
1005.26	17390
1007.53	17330
1009.79	17334
1012.05	17326
1014.31	17302
1016.57	17196
1018.83	17054
1021.09	17230
1023.35	17374
1025.61	17328
1027.87	17108
1030.12	17148
1032.38	17190
1034.63	17148
1036.88	17208
1039.14	17010
1041.39	17086
1043.64	17088
1045.89	17216
1048.14	17206
1050.39	17168
1052.64	17130
1054.89	16996
1057.14	17014
1059.38	16826
1061.63	16790
1063.87	16810
1066.12	16786
1068.36	16774
1070.6	16626
1072.85	16710
1075.09	16524
1077.33	16488
1079.57	16466
1081.81	16562
1084.05	16194
1086.28	16268
1088.52	16204
1090.76	16264
1092.99	16124
1095.23	16232
1097.46	15936
1099.69	15782
1101.93	15846
1104.16	15828
1106.39	15870
1108.62	15812
1110.85	15630
1113.08	15632
1115.31	15524
1117.53	15504
1119.76	15452
1121.99	15496
1124.21	15530
1126.44	15434
1128.66	15384
1130.88	15132
1133.11	15252
1135.33	15304
1137.55	15282
1139.77	15408
1141.99	15372
1144.21	15066
1146.43	15124
1148.64	15256
1150.86	15066
1153.08	15318
1155.29	15092
1157.51	15080
1159.72	15164
1161.93	15036
1164.14	15034
1166.36	14938
1168.57	15012
1170.78	14858
1172.99	14778
1175.2	14798
1177.4	14776
1179.61	14702
1181.82	14582
1184.02	14606
1186.23	14562
1188.43	14412
1190.64	14418
1192.84	14288
1195.04	14280
1197.24	14228
1199.45	14082.9
1201.64	14027.1
1203.84	13962.1
1206.04	13868
1208.24	13835.5
1210.44	13639.3
1212.64	13627.8
1214.83	13460
1217.03	13462
1219.22	13492.7
1221.41	13273.4
1223.61	13258.3
1225.8	13110.3
1227.99	13062.2
1230.18	12965.4
1232.37	13058.8
1234.56	12862.8
1236.75	12911.6
1238.94	12770.3
1241.13	12749.9
1243.31	12730.3
1245.5	12638.8
1247.68	12590
1249.87	12442.5
1252.05	12447.1
1254.24	12516.4
1256.42	12405.1
1258.6	12349.9
1260.78	12294.4
1262.96	12224.7
1265.14	12148.1
1267.32	12129.7
1269.5	12118
1271.67	12042.7
1273.85	11948.8
1276.03	11867.2
1278.2	11849.4
1280.38	11831.6
1282.55	11740.9
1284.72	11742.3
1286.9	11615.5
1289.07	11614.3
1291.24	11587.6
1293.41	11479.8
1295.58	11382.2
1297.75	11373.3
1299.92	11298.9
1302.09	11325.3
1304.25	11373.8
1306.42	11134.9
1308.46	11268
1310.63	11172
1312.81	11066
1314.98	10964
1317.16	11008
1319.33	10862
1321.5	10936
1323.67	10944
1325.85	10926
1328.02	10778
1330.19	10644
1332.35	10670
1334.52	10784
1336.69	10662
1338.86	10716
1341.02	10520
1343.19	10678
1345.35	10518
1347.52	10406
1349.68	10560
1351.84	10412
1354	10306
1356.17	10376
1358.33	10290
1360.49	10312
1362.65	10316
1364.8	10090
1366.96	10116
1369.12	10216
1371.28	9978
1373.43	10164
1375.59	9844
1377.74	9954
1379.89	9974
1382.05	9880
1384.2	9868
1386.35	9804
1388.5	9800
1390.65	9632
1392.8	9752
1394.95	9588
1397.1	9654
1399.25	9650
1401.4	9552
1403.54	9600
1405.69	9516
1407.83	9470
1409.98	9478
1412.12	9282
1414.26	9420
1416.4	9428
1418.55	9416
1420.69	9300
1422.83	9174
1424.97	9092
1427.1	9182
1429.24	9154
1431.38	9132
1433.52	9004
1435.65	9006
1437.79	9006
1439.92	8992
1442.06	8998
1444.19	8912
1446.32	8768
1448.46	8808
1450.59	8754
1452.72	8816
1454.85	8812
1456.98	8622
1459.11	8532
1461.23	8588
1463.36	8560
1465.49	8538
1467.61	8556
1469.74	8546
1471.86	8446
1473.99	8490
1476.11	8394
1478.23	8516
1480.36	8530
1482.48	8340
1484.6	8178
1486.72	8222
1488.84	8194
1490.96	8218
1493.07	8122
1495.19	8180
1497.31	8218
1499.42	8134
1501.54	8018
1503.65	8026
1505.77	7978
1507.88	8068
1509.99	7982
1512.1	7894
1514.22	7930
1516.33	7798
1518.44	7792
1520.55	7916
1522.65	7816
1524.76	7702
1526.87	7634
1528.98	7596
1531.08	7562
1533.19	7500
1535.29	7392
1537.4	7536
1539.5	7462
1541.6	7486
1543.7	7370
1545.8	7356
1547.91	7338
1550.01	7362
1552.11	7236
1554.2	7192
1556.3	7322
1558.4	7228
1560.5	7110
1562.59	7094
1564.69	7092
1566.78	7106
1568.88	6996
1570.97	6994
1573.06	7106
1575.15	6980
1577.25	7004
1579.34	7020
1581.43	6920
1583.52	6982
1585.6	6842
1587.69	6798
1589.78	6930
1591.87	6890
1593.95	6818
1596.04	6764
1598.12	6720
1600.21	6722
1602.29	6644
1604.37	6698
1606.46	6644
1608.54	6666
1610.62	6620
1612.7	6628
1614.78	6568
1616.86	6504
1618.94	6496
1621.01	6496
1623.09	6470
1625.17	6398
1627.24	6518
1629.32	6402
1631.39	6436
1633.47	6346
1635.54	6440
1637.61	6346
1639.68	6306
1641.76	6278
1643.83	6224
1645.9	6234
1647.96	6252
1650.03	6160
1652.1	6140
1654.17	6112
1656.24	6000
1658.3	6116
1660.37	6060
1662.43	6094
1664.5	5972
1666.56	5968
1668.62	5976
1670.68	5902
1672.75	5932
1674.81	5898
1676.87	5862
1678.93	5926
1680.99	5868
1683.04	5734
1685.1	5698
1687.16	5790
1689.21	5834
1691.27	5680
1693.33	5678
1695.38	5708
1697.43	5556
1699.49	5596
1701.54	5592
1703.59	5570
1705.64	5594
1707.69	5574
1709.74	5486
1711.79	5436
1713.84	5502
1715.89	5410
1717.94	5438
1719.98	5410
1722.03	5480
1724.07	5336
1726.12	5302
1728.16	5420
1730.21	5296
1732.25	5302
1734.29	5310
1736.33	5236
1738.37	5228
1740.41	5170
1742.45	5254
1744.49	5154
1746.53	5286
1748.57	5152
1750.61	5148
1752.64	5138
1754.68	5130
1756.71	5106
1758.75	5128
1760.78	5070
1762.82	5130
1764.85	5058
1766.88	5114
1768.91	5140
1770.94	5072
1772.97	5014
1775	5014
1777.03	4978
1779.06	4982
1781.09	5024
1783.12	4978
1785.14	5034
1787.17	5036
1789.19	4912
1791.22	5012
1793.24	4876
1795.27	4866
1797.29	4784
1799.31	4860
1801.33	4768
1803.35	4742
1805.37	4846
1807.39	4644
1809.41	4816
1811.43	4752
1813.45	4758
1815.46	4666
1817.48	4620
1819.5	4662
1821.51	4676
1823.53	4558
1825.54	4654
1827.55	4596
1829.57	4528
1831.58	4462
1833.59	4472
1835.6	4508
1837.61	4518
1839.62	4490
1841.63	4544
1843.64	4452
1845.65	4418
1847.65	4382
1849.66	4330
1851.66	4414
1853.67	4430
1855.67	4286
1857.68	4344
1859.68	4346
1861.68	4330
1863.69	4314
1865.69	4286
1867.69	4278
1869.69	4236
1871.69	4266
1873.69	4150
1875.69	4260
1877.68	4126
1879.68	4156
1881.68	4248
1883.67	4258
1885.67	4102
1887.66	4092
1889.66	4158
1891.65	4096
1893.64	4156
1895.64	4136
1897.63	4122
1899.62	4090
1901.61	4134
1903.6	4038
1905.59	4074
1907.58	4078
1909.56	4138
1911.55	4072
1913.54	4162
1915.53	4104
1917.51	4052
1919.5	4072
1921.48	4048
1923.46	4016
1925.45	4048
1927.43	3990
1929.41	3988
1931.39	3948
1933.37	4022
1935.35	3964
1937.33	3976
1939.31	3984
1941.29	3902
1943.27	4006
1945.24	3864
1947.22	3968
1949.2	3854
1951.17	3874
1953.14	3877
1955.12	3916
1957.09	3828
1959.06	3854
1961.04	3908
1963.01	3848
1964.98	3794
1966.95	3772
1968.92	3674
1970.89	3722
1972.86	3752
1974.82	3790
1976.79	3846
1978.76	3676
1980.72	3694
1982.69	3792
1984.65	3766
1986.62	3738
1988.58	3672
1990.54	3648
1992.51	3622
1994.47	3762
1996.43	3628
1998.39	3678
1999.37	3688