File: 3/Organic_14.txt
#Acq. time (s)=	15
#Accumulations=	1
#Range (cm-¹)=	100...2000
#Windows=	2
#Autofocus=	Off
#AutoExposure=	Off
#Spike filter=	Off
#Delay time (s)=	0
#Binning=	1
#Readout mode=	Signal
#DeNoise=	Off
#ICS correction=	Off
#Dark correction=	Off
#Inst. Process=	Off
#Instrument=	LabRAM HR Evol
#Detector=	Syncerity OE
#Objective=	x100_VIS
#Grating=	600 (500nm)
#ND Filter=	50%
#Laser=	633nm_Edge
#Hole=	74.97
#Range=	Visible
#Project=	Omar
#Sample=	20-06-23
#Site=	3
#Title=	Organic
#Remark=
#Date=	20.06.2023 12:33
#Acquired=	20.06.2023 12:33:31
101.054	1944
103.621	1914
106.187	1968
108.752	1984
111.317	1992
113.881	1980
116.443	1996
119.005	1916
121.566	1958
124.126	1960
126.685	2002
129.243	1960
131.801	1936
134.356	1916
136.911	1944
139.466	1964
142.021	1974
144.574	1972
147.125	1870
149.676	1962
152.227	1928
154.776	1976
157.325	1938
159.873	1958
162.419	1920
164.966	1904
167.51	1912
170.055	1918
172.598	1892
175.141	1954
177.682	1914
180.222	1904
182.763	1910
185.302	1920
187.839	1916
190.376	1876
192.914	1890
195.449	1858
197.983	1920
200.517	1866
203.05	1854
205.582	1852
208.113	1886
210.643	1902
213.173	1900
215.701	1906
218.229	1928
220.756	1882
223.282	1854
225.808	1864
228.331	1872
230.855	1856
233.378	1886
235.898	1870
238.419	1800
240.94	1882
243.458	1856
245.977	1864
248.495	1846
251.011	1826
253.527	1826
256.041	1876
258.555	1854
261.068	1758
263.58	1828
266.092	1812
268.603	1742
271.112	1722
273.62	1802
276.129	1758
278.636	1768
281.142	1730
283.647	1794
286.152	1758
288.655	1714
291.158	1742
293.66	1664
296.161	1808
298.661	1714
301.161	1730
303.66	1784
306.158	1730
308.655	1730
311.15	1772
313.645	1756
316.14	1700
318.634	1754
321.125	1708
323.618	1654
326.109	1694
328.598	1674
331.088	1668
333.576	1680
336.064	1694
338.55	1654
341.037	1620
343.521	1686
346.005	1676
348.489	1666
350.971	1692
353.453	1680
355.933	1638
358.414	1648
360.893	1650
363.371	1654
365.848	1644
368.325	1640
370.801	1600
373.275	1692
375.75	1612
378.223	1630
380.695	1566
383.167	1588
385.638	1578
388.108	1620
390.577	1544
393.044	1566
395.512	1562
397.979	1622
400.444	1550
402.909	1604
405.374	1534
407.836	1644
410.299	1598
412.76	1576
415.221	1586
417.681	1618
420.141	1596
422.598	1640
425.057	1630
427.513	1580
429.968	1590
432.422	1630
434.878	1568
437.33	1614
439.783	1566
442.234	1578
444.685	1616
447.134	1588
449.583	1580
452.032	1604
454.479	1596
456.926	1566
459.372	1580
461.817	1580
464.261	1572
466.705	1550
469.147	1536
471.588	1538
474.029	1588
476.47	1516
478.909	1530
481.347	1596
483.785	1552
486.221	1536
488.657	1552
491.092	1558
493.527	1584
495.96	1552
498.393	1542
500.824	1510
503.255	1602
505.686	1610
508.115	1614
510.543	1628
512.972	1540
515.399	1494
517.825	1552
520.25	1504
522.674	1500
525.097	1516
527.52	1548
529.942	1534
532.364	1510
534.784	1488
537.204	1544
539.623	1500
542.041	1538
544.457	1500
546.874	1458
549.289	1556
551.705	1454
554.118	1516
556.531	1484
558.943	1476
561.355	1540
563.766	1510
566.175	1534
568.585	1530
570.992	1510
573.399	1496
575.807	1508
578.212	1506
580.617	1530
583.022	1502
585.425	1540
587.827	1504
590.229	1506
592.63	1518
595.03	1484
597.43	1508
599.829	1566
602.226	1540
604.623	1506
607.02	1534
609.414	1532
611.808	1526
614.202	1516
616.596	1536
618.988	1518
621.378	1590
623.769	1558
626.159	1550
628.548	1568
630.936	1598
633.324	1562
635.71	1516
638.096	1558
640.481	1602
642.866	1576
645.248	1586
647.63	1616
650.013	1580
652.394	1600
654.773	1628
657.154	1620
659.532	1572
661.91	1572
664.286	1598
666.663	1606
669.038	1628
671.412	1540
673.786	1634
676.159	1552
678.532	1568
680.903	1604
683.274	1598
685.644	1574
688.014	1558
690.381	1578
692.749	1566
695.116	1560
697.481	1570
699.846	1632
702.211	1594
704.574	1602
706.938	1590
709.299	1638
711.661	1620
714.021	1600
716.381	1612
718.739	1614
721.097	1580
723.455	1612
725.811	1638
728.167	1622
730.521	1650
732.875	1584
735.23	1550
737.582	1616
739.934	1652
742.285	1616
744.635	1640
746.985	1588
749.332	1624
751.68	1594
754.028	1564
756.374	1598
758.72	1574
761.065	1630
763.408	1600
765.752	1690
768.095	1638
770.436	1654
772.777	1598
775.116	1632
777.456	1568
779.794	1632
782.133	1604
784.469	1628
786.805	1588
789.141	1640
791.476	1618
793.809	1626
796.142	1612
798.476	1660
800.807	1662
803.138	1610
805.468	1624
807.797	1596
810.125	1588
812.453	1638
814.78	1636
817.106	1562
819.432	1604
821.757	1624
824.08	1658
826.403	1648
828.726	1636
831.048	1646
833.368	1656
835.688	1660
838.007	1668
840.326	1626
842.644	1650
844.96	1712
847.276	1648
849.592	1652
851.906	1648
854.221	1662
856.534	1682
858.846	1656
861.157	1668
863.469	1660
865.779	1602
868.088	1668
870.396	1662
872.704	1624
875.011	1654
877.318	1602
879.623	1588
881.928	1624
884.232	1668
886.536	1638
888.837	1586
891.139	1628
893.44	1586
895.741	1590
898.039	1596
900.339	1692
902.637	1608
904.933	1608
907.231	1630
909.526	1572
911.821	1606
914.115	1588
916.408	1632
918.701	1572
920.993	1592
923.283	1590
925.573	1590
927.864	1576
930.153	1612
932.441	1606
934.728	1626
937.014	1592
939.3	1564
941.585	1612
943.87	1630
946.154	1612
948.437	1658
950.719	1562
952.999	1634
955.28	1582
957.56	1608
959.84	1612
962.117	1570
964.395	1598
966.671	1588
968.948	1632
971.223	1606
973.498	1600
975.771	1556
978.045	1576
980.317	1544
982.588	1574
984.86	1636
987.13	1552
989.399	1626
991.667	1558
993.937	1572
996.204	1546
998.47	1584
1000.74	1526
1003	1614
1005.26	1564
1007.53	1562
1009.79	1528
1012.05	1584
1014.31	1558
1016.57	1516
1018.83	1556
1021.09	1566
1023.35	1554
1025.61	1586
1027.87	1572
1030.12	1532
1032.38	1556
1034.63	1556
1036.88	1620
1039.14	1572
1041.39	1542
1043.64	1562
1045.89	1538
1048.14	1518
1050.39	1524
1052.64	1540
1054.89	1552
1057.14	1554
1059.38	1506
1061.63	1568
1063.87	1552
1066.12	1488
1068.36	1558
1070.6	1496
1072.85	1488
1075.09	1542
1077.33	1484
1079.57	1488
1081.81	1488
1084.05	1466
1086.28	1436
1088.52	1456
1090.76	1544
1092.99	1516
1095.23	1536
1097.46	1512
1099.69	1408
1101.93	1470
1104.16	1458
1106.39	1460
1108.62	1458
1110.85	1400
1113.08	1402
1115.31	1408
1117.53	1390
1119.76	1400
1121.99	1416
1124.21	1394
1126.44	1428
1128.66	1434
1130.88	1390
1133.11	1472
1135.33	1478
1137.55	1390
1139.77	1418
1141.99	1410
1144.21	1416
1146.43	1442
1148.64	1416
1150.86	1380
1153.08	1344
1155.29	1382
1157.51	1416
1159.72	1406
1161.93	1380
1164.14	1424
1166.36	1364
1168.57	1430
1170.78	1398
1172.99	1380
1175.2	1350
1177.4	1376
1179.61	1392
1181.82	1360
1184.02	1398
1186.23	1426
1188.43	1386
1190.64	1358
1192.84	1384
1195.04	1380
1197.24	1388
1199.45	1397.69
1201.64	1387.06
1203.84	1293.38
1206.04	1361.49
1208.24	1335.44
1210.44	1303.37
1212.64	1291.88
1214.83	1284.36
1217.03	1313.29
1219.22	1311.58
1221.41	1281.06
1223.61	1286.94
1225.8	1263.51
1227.99	1291.66
1230.18	1288.22
1232.37	1293.4
1234.56	1277.59
1236.75	1289.4
1238.94	1251.58
1241.13	1265.29
1243.31	1261.28
1245.5	1258.76
1247.68	1264.76
1249.87	1253.04
1252.05	1254.66
1254.24	1275.94
1256.42	1240.26
1258.6	1254.18
1260.78	1250.74
1262.96	1245.72
1265.14	1264.8
1267.32	1255.42
1269.5	1254.38
1271.67	1278.93
1273.85	1254.29
1276.03	1264.53
1278.2	1243.76
1280.38	1235.41
1282.55	1282.6
1284.72	1239.29
1286.9	1220.89
1289.07	1237.8
1291.24	1223.1
1293.41	1264.93
1295.58	1275.53
1297.75	1228.25
1299.92	1196.17
1302.09	1221.63
1304.25	1254.55
1306.42	1233.33
1308.46	1256
1310.63	1214
1312.81	1186
1314.98	1206
1317.16	1222
1319.33	1210
1321.5	1152
1323.67	1194
1325.85	1172
1328.02	1192
1330.19	1214
1332.35	1148
1334.52	1188
1336.69	1178
1338.86	1218
1341.02	1204
1343.19	1152
1345.35	1198
1347.52	1194
1349.68	1166
1351.84	1172
1354	1190
1356.17	1192
1358.33	1224
1360.49	1158
1362.65	1196
1364.8	1154
1366.96	1168
1369.12	1192
1371.28	1192
1373.43	1168
1375.59	1168
1377.74	1154
1379.89	1128
1382.05	1186
1384.2	1176
1386.35	1174
1388.5	1164
1390.65	1178
1392.8	1136
1394.95	1152
1397.1	1170
1399.25	1118
1401.4	1162
1403.54	1112
1405.69	1158
1407.83	1134
1409.98	1142
1412.12	1146
1414.26	1136
1416.4	1114
1418.55	1116
1420.69	1130
1422.83	1128
1424.97	1136
1427.1	1146
1429.24	1124
1431.38	1128
1433.52	1106
1435.65	1132
1437.79	1134
1439.92	1132
1442.06	1130
1444.19	1152
1446.32	1138
1448.46	1160
1450.59	1108
1452.72	1118
1454.85	1150
1456.98	1116
1459.11	1090
1461.23	1146
1463.36	1108
1465.49	1108
1467.61	1146
1469.74	1124
1471.86	1116
1473.99	1112
1476.11	1098
1478.23	1116
1480.36	1126
1482.48	1094
1484.6	1082
1486.72	1082
1488.84	1104
1490.96	1100
1493.07	1076
1495.19	1070
1497.31	1078
1499.42	1082
1501.54	1088
1503.65	1098
1505.77	1090
1507.88	1086
1509.99	1114
1512.1	1062
1514.22	1134
1516.33	1088
1518.44	1090
1520.55	1068
1522.65	1092
1524.76	1030
1526.87	1080
1528.98	1080
1531.08	1046
1533.19	1052
1535.29	1032
1537.4	1022
1539.5	1098
1541.6	1036
1543.7	1038
1545.8	1022
1547.91	1030
1550.01	1070
1552.11	1018
1554.2	1044
1556.3	1038
1558.4	1034
1560.5	1066
1562.59	1040
1564.69	1026
1566.78	1060
1568.88	1036
1570.97	1074
1573.06	1030
1575.15	1018
1577.25	1066
1579.34	1062
1581.43	1020
1583.52	1008
1585.6	1044
1587.69	1030
1589.78	1064
1591.87	1016
1593.95	1000
1596.04	1048
1598.12	1024
1600.21	992
1602.29	1016
1604.37	978
1606.46	996
1608.54	990
1610.62	1028
1612.7	1010
1614.78	1004
1616.86	1012
1618.94	1032
1621.01	1020
1623.09	1024
1625.17	994
1627.24	974
1629.32	982
1631.39	1012
1633.47	998
1635.54	986
1637.61	986
1639.68	958
1641.76	1006
1643.83	988
1645.9	942
1647.96	996
1650.03	974
1652.1	964
1654.17	980
1656.24	962
1658.3	938
1660.37	944
1662.43	986
1664.5	966
1666.56	934
1668.62	980
1670.68	950
1672.75	964
1674.81	918
1676.87	896
1678.93	924
1680.99	926
1683.04	898
1685.1	904
1687.16	908
1689.21	892
1691.27	916
1693.33	940
1695.38	912
1697.43	876
1699.49	878
1701.54	928
1703.59	894
1705.64	904
1707.69	890
1709.74	920
1711.79	878
1713.84	900
1715.89	906
1717.94	860
1719.98	874
1722.03	882
1724.07	890
1726.12	864
1728.16	908
1730.21	840
1732.25	888
1734.29	882
1736.33	858
1738.37	856
1740.41	854
1742.45	838
1744.49	850
1746.53	864
1748.57	840
1750.61	838
1752.64	840
1754.68	816
1756.71	812
1758.75	866
1760.78	824
1762.82	812
1764.85	838
1766.88	844
1768.91	786
1770.94	790
1772.97	810
1775	808
1777.03	824
1779.06	802
1781.09	798
1783.12	814
1785.14	794
1787.17	828
1789.19	798
1791.22	798
1793.24	774
1795.27	796
1797.29	832
1799.31	750
1801.33	820
1803.35	772
1805.37	776
1807.39	762
1809.41	762
1811.43	764
1813.45	772
1815.46	748
1817.48	750
1819.5	740
1821.51	726
1823.53	708
1825.54	776
1827.55	766
1829.57	748
1831.58	738
1833.59	736
1835.6	714
1837.61	714
1839.62	728
1841.63	702
1843.64	726
1845.65	708
1847.65	710
1849.66	682
1851.66	658
1853.67	694
1855.67	684
1857.68	736
1859.68	672
1861.68	658
1863.69	676
1865.69	698
1867.69	690
1869.69	674
1871.69	674
1873.69	650
1875.69	668
1877.68	660
1879.68	674
1881.68	652
1883.67	650
1885.67	638
1887.66	650
1889.66	638
1891.65	650
1893.64	648
1895.64	660
1897.63	658
1899.62	632
1901.61	656
1903.6	624
1905.59	632
1907.58	644
1909.56	622
1911.55	632
1913.54	632
1915.53	626
1917.51	598
1919.5	612
1921.48	596
1923.46	644
1925.45	596
1927.43	600
1929.41	594
1931.39	592
1933.37	594
1935.35	572
1937.33	574
1939.31	596
1941.29	580
1943.27	550
1945.24	578
1947.22	554
1949.2	574
1951.17	574
1953.14	557
1955.12	558
1957.09	544
1959.06	550
1961.04	562
1963.01	578
1964.98	538
1966.95	530
1968.92	540
1970.89	552
1972.86	566
1974.82	522
1976.79	548
1978.76	520
1980.72	562
1982.69	530
1984.65	508
1986.62	534
1988.58	542
1990.54	536
1992.51	528
1994.47	516
1996.43	540
1998.39	506
1999.37	506