File: 3/Organic_09.txt
#Acq. time (s)=	15
#Accumulations=	1
#Range (cm-¹)=	100...2000
#Windows=	2
#Autofocus=	Off
#AutoExposure=	Off
#Spike filter=	Off
#Delay time (s)=	0
#Binning=	1
#Readout mode=	Signal
#DeNoise=	Off
#ICS correction=	Off
#Dark correction=	Off
#Inst. Process=	Off
#Instrument=	LabRAM HR Evol
#Detector=	Syncerity OE
#Objective=	x100_VIS
#Grating=	600 (500nm)
#ND Filter=	25%
#Laser=	633nm_Edge
#Hole=	49.98
#Range=	Visible
#Project=	Omar
#Sample=	20-06-23
#Site=	3
#Title=	Organic
#Remark=
#Date=	20.06.2023 12:25
#Acquired=	20.06.2023 12:25:47
101.054	1504
103.621	1564
106.187	1546
108.752	1540
111.317	1512
113.881	1534
116.443	1520
119.005	1562
121.566	1528
124.126	1546
126.685	1522
129.243	1510
131.801	1542
134.356	1526
136.911	1518
139.466	1544
142.021	1492
144.574	1544
147.125	1530
149.676	1512
152.227	1526
154.776	1532
157.325	1482
159.873	1494
162.419	1484
164.966	1464
167.51	1480
170.055	1506
172.598	1508
175.141	1524
177.682	1428
180.222	1472
182.763	1462
185.302	1428
187.839	1470
190.376	1484
192.914	1466
195.449	1496
197.983	1494
200.517	1426
203.05	1474
205.582	1480
208.113	1512
210.643	1500
213.173	1522
215.701	1462
218.229	1446
220.756	1504
223.282	1498
225.808	1446
228.331	1506
230.855	1534
233.378	1456
235.898	1492
238.419	1488
240.94	1422
243.458	1482
245.977	1486
248.495	1498
251.011	1562
253.527	1494
256.041	1502
258.555	1412
261.068	1414
263.58	1450
266.092	1428
268.603	1434
271.112	1436
273.62	1384
276.129	1432
278.636	1444
281.142	1414
283.647	1424
286.152	1406
288.655	1418
291.158	1398
293.66	1424
296.161	1382
298.661	1406
301.161	1428
303.66	1454
306.158	1404
308.655	1424
311.15	1396
313.645	1420
316.14	1450
318.634	1414
321.125	1436
323.618	1372
326.109	1414
328.598	1422
331.088	1394
333.576	1374
336.064	1394
338.55	1384
341.037	1406
343.521	1356
346.005	1402
348.489	1384
350.971	1404
353.453	1384
355.933	1390
358.414	1374
360.893	1360
363.371	1370
365.848	1390
368.325	1366
370.801	1396
373.275	1324
375.75	1360
378.223	1346
380.695	1342
383.167	1314
385.638	1324
388.108	1336
390.577	1340
393.044	1340
395.512	1356
397.979	1370
400.444	1254
402.909	1336
405.374	1332
407.836	1306
410.299	1322
412.76	1346
415.221	1272
417.681	1334
420.141	1374
422.598	1346
425.057	1318
427.513	1308
429.968	1332
432.422	1314
434.878	1298
437.33	1344
439.783	1302
442.234	1308
444.685	1266
447.134	1304
449.583	1288
452.032	1274
454.479	1288
456.926	1248
459.372	1278
461.817	1256
464.261	1218
466.705	1306
469.147	1286
471.588	1240
474.029	1282
476.47	1230
478.909	1246
481.347	1220
483.785	1258
486.221	1244
488.657	1226
491.092	1254
493.527	1220
495.96	1218
498.393	1230
500.824	1232
503.255	1246
505.686	1248
508.115	1258
510.543	1200
512.972	1198
515.399	1196
517.825	1198
520.25	1192
522.674	1200
525.097	1224
527.52	1182
529.942	1192
532.364	1120
534.784	1184
537.204	1142
539.623	1162
542.041	1190
544.457	1144
546.874	1144
549.289	1168
551.705	1198
554.118	1152
556.531	1084
558.943	1106
561.355	1138
563.766	1122
566.175	1138
568.585	1120
570.992	1176
573.399	1180
575.807	1094
578.212	1126
580.617	1106
583.022	1092
585.425	1132
587.827	1164
590.229	1088
592.63	1114
595.03	1102
597.43	1080
599.829	1080
602.226	1086
604.623	1070
607.02	1112
609.414	1092
611.808	1106
614.202	1088
616.596	1092
618.988	1060
621.378	1060
623.769	1070
626.159	1096
628.548	1100
630.936	1092
633.324	1110
635.71	1028
638.096	1058
640.481	1068
642.866	1040
645.248	1060
647.63	1048
650.013	1054
652.394	1044
654.773	1044
657.154	1046
659.532	1046
661.91	1038
664.286	1056
666.663	1064
669.038	1006
671.412	998
673.786	1008
676.159	996
678.532	1020
680.903	1016
683.274	1002
685.644	1070
688.014	1004
690.381	984
692.749	990
695.116	978
697.481	1004
699.846	1002
702.211	980
704.574	956
706.938	938
709.299	986
711.661	978
714.021	968
716.381	976
718.739	1024
721.097	980
723.455	996
725.811	940
728.167	1008
730.521	978
732.875	952
735.23	1000
737.582	924
739.934	996
742.285	968
744.635	934
746.985	912
749.332	964
751.68	946
754.028	946
756.374	934
758.72	926
761.065	936
763.408	886
765.752	902
768.095	926
770.436	888
772.777	938
775.116	938
777.456	916
779.794	904
782.133	908
784.469	896
786.805	914
789.141	882
791.476	876
793.809	948
796.142	860
798.476	872
800.807	892
803.138	868
805.468	884
807.797	898
810.125	860
812.453	900
814.78	858
817.106	872
819.432	874
821.757	898
824.08	878
826.403	902
828.726	876
831.048	862
833.368	868
835.688	888
838.007	896
840.326	870
842.644	900
844.96	890
847.276	890
849.592	854
851.906	858
854.221	902
856.534	898
858.846	854
861.157	902
863.469	876
865.779	900
868.088	916
870.396	880
872.704	880
875.011	884
877.318	882
879.623	872
881.928	890
884.232	856
886.536	894
888.837	898
891.139	872
893.44	858
895.741	864
898.039	832
900.339	884
902.637	896
904.933	882
907.231	844
909.526	854
911.821	870
914.115	858
916.408	856
918.701	862
920.993	840
923.283	852
925.573	856
927.864	834
930.153	832
932.441	880
934.728	852
937.014	916
939.3	868
941.585	868
943.87	864
946.154	852
948.437	862
950.719	836
952.999	844
955.28	868
957.56	876
959.84	880
962.117	876
964.395	856
966.671	848
968.948	878
971.223	796
973.498	856
975.771	880
978.045	866
980.317	888
982.588	884
984.86	908
987.13	924
989.399	838
991.667	862
993.937	860
996.204	856
998.47	888
1000.74	876
1003	880
1005.26	844
1007.53	828
1009.79	896
1012.05	880
1014.31	848
1016.57	894
1018.83	858
1021.09	902
1023.35	858
1025.61	874
1027.87	894
1030.12	864
1032.38	882
1034.63	866
1036.88	890
1039.14	880
1041.39	876
1043.64	884
1045.89	892
1048.14	894
1050.39	894
1052.64	874
1054.89	904
1057.14	906
1059.38	890
1061.63	882
1063.87	910
1066.12	870
1068.36	900
1070.6	886
1072.85	884
1075.09	904
1077.33	924
1079.57	904
1081.81	872
1084.05	918
1086.28	866
1088.52	894
1090.76	878
1092.99	876
1095.23	906
1097.46	932
1099.69	892
1101.93	884
1104.16	918
1106.39	878
1108.62	920
1110.85	896
1113.08	880
1115.31	922
1117.53	904
1119.76	882
1121.99	888
1124.21	898
1126.44	874
1128.66	856
1130.88	906
1133.11	900
1135.33	926
1137.55	902
1139.77	918
1141.99	922
1144.21	876
1146.43	944
1148.64	864
1150.86	894
1153.08	902
1155.29	926
1157.51	910
1159.72	912
1161.93	910
1164.14	908
1166.36	896
1168.57	930
1170.78	942
1172.99	908
1175.2	958
1177.4	910
1179.61	958
1181.82	906
1184.02	924
1186.23	920
1188.43	952
1190.64	924
1192.84	916
1195.04	906
1197.24	930
1199.45	958.83
1201.64	899.415
1203.84	900.337
1206.04	894.938
1208.24	879.204
1210.44	903.857
1212.64	901.143
1214.83	890.42
1217.03	869.445
1219.22	902.49
1221.41	855.669
1223.61	872.054
1225.8	858.919
1227.99	876.989
1230.18	872.118
1232.37	831.274
1234.56	829.05
1236.75	852.139
1238.94	839.463
1241.13	840.992
1243.31	855.764
1245.5	855.02
1247.68	810.768
1249.87	825.334
1252.05	837.057
1254.24	855.138
1256.42	816.218
1258.6	792.805
1260.78	817.18
1262.96	803.058
1265.14	817.004
1267.32	817.788
1269.5	792.179
1271.67	784.839
1273.85	792.954
1276.03	797.932
1278.2	776.582
1280.38	787.872
1282.55	796.32
1284.72	780.215
1286.9	759.526
1289.07	777.128
1291.24	790.453
1293.41	771.044
1295.58	757.939
1297.75	777.873
1299.92	731.26
1302.09	750.551
1304.25	760.193
1306.42	712.777
1308.46	716
1310.63	748
1312.81	728
1314.98	736
1317.16	724
1319.33	756
1321.5	718
1323.67	766
1325.85	734
1328.02	744
1330.19	712
1332.35	730
1334.52	748
1336.69	746
1338.86	734
1341.02	734
1343.19	748
1345.35	762
1347.52	718
1349.68	734
1351.84	728
1354	720
1356.17	694
1358.33	734
1360.49	728
1362.65	700
1364.8	730
1366.96	704
1369.12	740
1371.28	696
1373.43	766
1375.59	720
1377.74	720
1379.89	728
1382.05	734
1384.2	718
1386.35	716
1388.5	702
1390.65	732
1392.8	726
1394.95	714
1397.1	682
1399.25	698
1401.4	700
1403.54	722
1405.69	724
1407.83	734
1409.98	704
1412.12	704
1414.26	690
1416.4	708
1418.55	682
1420.69	722
1422.83	680
1424.97	708
1427.1	696
1429.24	710
1431.38	694
1433.52	712
1435.65	722
1437.79	684
1439.92	698
1442.06	674
1444.19	690
1446.32	686
1448.46	700
1450.59	692
1452.72	676
1454.85	732
1456.98	688
1459.11	682
1461.23	702
1463.36	710
1465.49	670
1467.61	656
1469.74	696
1471.86	684
1473.99	698
1476.11	682
1478.23	658
1480.36	682
1482.48	700
1484.6	676
1486.72	668
1488.84	700
1490.96	702
1493.07	690
1495.19	664
1497.31	686
1499.42	660
1501.54	662
1503.65	662
1505.77	626
1507.88	684
1509.99	666
1512.1	672
1514.22	704
1516.33	644
1518.44	646
1520.55	666
1522.65	662
1524.76	662
1526.87	668
1528.98	628
1531.08	652
1533.19	646
1535.29	622
1537.4	694
1539.5	630
1541.6	628
1543.7	630
1545.8	628
1547.91	648
1550.01	640
1552.11	622
1554.2	612
1556.3	612
1558.4	636
1560.5	634
1562.59	620
1564.69	622
1566.78	626
1568.88	600
1570.97	600
1573.06	614
1575.15	608
1577.25	632
1579.34	612
1581.43	596
1583.52	572
1585.6	626
1587.69	566
1589.78	632
1591.87	620
1593.95	634
1596.04	622
1598.12	574
1600.21	606
1602.29	598
1604.37	582
1606.46	596
1608.54	618
1610.62	638
1612.7	604
1614.78	620
1616.86	622
1618.94	586
1621.01	594
1623.09	564
1625.17	582
1627.24	578
1629.32	574
1631.39	580
1633.47	568
1635.54	584
1637.61	594
1639.68	584
1641.76	550
1643.83	594
1645.9	558
1647.96	602
1650.03	568
1652.1	576
1654.17	580
1656.24	564
1658.3	592
1660.37	580
1662.43	578
1664.5	574
1666.56	526
1668.62	566
1670.68	550
1672.75	544
1674.81	572
1676.87	554
1678.93	546
1680.99	536
1683.04	526
1685.1	554
1687.16	546
1689.21	508
1691.27	550
1693.33	534
1695.38	546
1697.43	534
1699.49	534
1701.54	534
1703.59	510
1705.64	526
1707.69	522
1709.74	520
1711.79	534
1713.84	506
1715.89	502
1717.94	508
1719.98	518
1722.03	520
1724.07	502
1726.12	520
1728.16	508
1730.21	504
1732.25	516
1734.29	522
1736.33	516
1738.37	490
1740.41	524
1742.45	512
1744.49	498
1746.53	496
1748.57	466
1750.61	456
1752.64	464
1754.68	488
1756.71	482
1758.75	500
1760.78	496
1762.82	462
1764.85	474
1766.88	486
1768.91	490
1770.94	486
1772.97	466
1775	468
1777.03	476
1779.06	472
1781.09	502
1783.12	460
1785.14	466
1787.17	470
1789.19	446
1791.22	484
1793.24	468
1795.27	462
1797.29	460
1799.31	454
1801.33	446
1803.35	432
1805.37	488
1807.39	452
1809.41	460
1811.43	466
1813.45	412
1815.46	468
1817.48	460
1819.5	476
1821.51	450
1823.53	444
1825.54	446
1827.55	448
1829.57	448
1831.58	420
1833.59	450
1835.6	436
1837.61	426
1839.62	454
1841.63	422
1843.64	426
1845.65	440
1847.65	418
1849.66	428
1851.66	428
1853.67	434
1855.67	428
1857.68	422
1859.68	412
1861.68	428
1863.69	424
1865.69	432
1867.69	406
1869.69	422
1871.69	420
1873.69	390
1875.69	398
1877.68	366
1879.68	442
1881.68	406
1883.67	382
1885.67	408
1887.66	408
1889.66	402
1891.65	402
1893.64	416
1895.64	390
1897.63	402
1899.62	400
1901.61	372
1903.6	390
1905.59	404
1907.58	396
1909.56	378
1911.55	384
1913.54	410
1915.53	372
1917.51	366
1919.5	392
1921.48	386
1923.46	388
1925.45	390
1927.43	388
1929.41	400
1931.39	370
1933.37	388
1935.35	354
1937.33	382
1939.31	410
1941.29	378
1943.27	366
1945.24	376
1947.22	380
1949.2	360
1951.17	386
1953.14	369
1955.12	376
1957.09	382
1959.06	374
1961.04	366
1963.01	380
1964.98	360
1966.95	370
1968.92	366
1970.89	354
1972.86	380
1974.82	350
1976.79	352
1978.76	380
1980.72	360
1982.69	358
1984.65	348
1986.62	340
1988.58	350
1990.54	336
1992.51	334
1994.47	340
1996.43	362
1998.39	350
1999.37	362