File: 3/Organic_13.txt
#Acq. time (s)=	15
#Accumulations=	1
#Range (cm-¹)=	100...2000
#Windows=	2
#Autofocus=	Off
#AutoExposure=	Off
#Spike filter=	Off
#Delay time (s)=	0
#Binning=	1
#Readout mode=	Signal
#DeNoise=	Off
#ICS correction=	Off
#Dark correction=	Off
#Inst. Process=	Off
#Instrument=	LabRAM HR Evol
#Detector=	Syncerity OE
#Objective=	x100_VIS
#Grating=	600 (500nm)
#ND Filter=	50%
#Laser=	633nm_Edge
#Hole=	74.97
#Range=	Visible
#Project=	Omar
#Sample=	20-06-23
#Site=	3
#Title=	Organic
#Remark=
#Date=	20.06.2023 12:32
#Acquired=	20.06.2023 12:32:43
101.054	2084
103.621	2070
106.187	2120
108.752	2096
111.317	2140
113.881	2094
116.443	2102
119.005	2164
121.566	2130
124.126	2146
126.685	2098
129.243	2084
131.801	2138
134.356	2126
136.911	2090
139.466	2116
142.021	2094
144.574	2130
147.125	2104
149.676	2094
152.227	2060
154.776	2042
157.325	2044
159.873	2070
162.419	2102
164.966	2078
167.51	2060
170.055	2020
172.598	2010
175.141	2004
177.682	2050
180.222	2084
182.763	2044
185.302	2060
187.839	2008
190.376	2038
192.914	1990
195.449	2012
197.983	2010
200.517	2042
203.05	1978
205.582	2070
208.113	2040
210.643	2018
213.173	2008
215.701	2090
218.229	2012
220.756	2020
223.282	2022
225.808	1964
228.331	1944
230.855	2002
233.378	1984
235.898	1980
238.419	1964
240.94	1942
243.458	2016
245.977	1980
248.495	1986
251.011	2036
253.527	1988
256.041	1958
258.555	1980
261.068	1898
263.58	1958
266.092	1916
268.603	1890
271.112	1918
273.62	1872
276.129	1882
278.636	1896
281.142	1846
283.647	1902
286.152	1894
288.655	1892
291.158	1872
293.66	1904
296.161	1880
298.661	1906
301.161	1898
303.66	1908
306.158	1880
308.655	1912
311.15	1890
313.645	1884
316.14	1892
318.634	1924
321.125	1878
323.618	1888
326.109	1852
328.598	1822
331.088	1832
333.576	1850
336.064	1838
338.55	1770
341.037	1862
343.521	1794
346.005	1766
348.489	1780
350.971	1836
353.453	1814
355.933	1784
358.414	1790
360.893	1808
363.371	1828
365.848	1828
368.325	1784
370.801	1736
373.275	1758
375.75	1728
378.223	1712
380.695	1710
383.167	1734
385.638	1714
388.108	1680
390.577	1678
393.044	1702
395.512	1754
397.979	1756
400.444	1738
402.909	1740
405.374	1744
407.836	1706
410.299	1722
412.76	1746
415.221	1750
417.681	1750
420.141	1726
422.598	1744
425.057	1762
427.513	1708
429.968	1774
432.422	1768
434.878	1752
437.33	1754
439.783	1738
442.234	1776
444.685	1790
447.134	1770
449.583	1738
452.032	1742
454.479	1726
456.926	1738
459.372	1748
461.817	1730
464.261	1704
466.705	1664
469.147	1658
471.588	1710
474.029	1710
476.47	1748
478.909	1714
481.347	1722
483.785	1686
486.221	1696
488.657	1706
491.092	1720
493.527	1676
495.96	1710
498.393	1694
500.824	1674
503.255	1714
505.686	1708
508.115	1676
510.543	1654
512.972	1660
515.399	1690
517.825	1652
520.25	1680
522.674	1676
525.097	1688
527.52	1664
529.942	1670
532.364	1666
534.784	1606
537.204	1676
539.623	1624
542.041	1662
544.457	1658
546.874	1658
549.289	1618
551.705	1660
554.118	1642
556.531	1632
558.943	1654
561.355	1642
563.766	1654
566.175	1616
568.585	1628
570.992	1664
573.399	1666
575.807	1642
578.212	1624
580.617	1610
583.022	1682
585.425	1640
587.827	1616
590.229	1648
592.63	1682
595.03	1694
597.43	1664
599.829	1654
602.226	1664
604.623	1652
607.02	1622
609.414	1650
611.808	1676
614.202	1692
616.596	1700
618.988	1692
621.378	1684
623.769	1664
626.159	1688
628.548	1680
630.936	1674
633.324	1690
635.71	1670
638.096	1718
640.481	1708
642.866	1710
645.248	1710
647.63	1740
650.013	1734
652.394	1698
654.773	1704
657.154	1722
659.532	1718
661.91	1694
664.286	1716
666.663	1764
669.038	1694
671.412	1696
673.786	1730
676.159	1760
678.532	1728
680.903	1688
683.274	1746
685.644	1718
688.014	1744
690.381	1758
692.749	1696
695.116	1692
697.481	1718
699.846	1796
702.211	1682
704.574	1730
706.938	1750
709.299	1718
711.661	1782
714.021	1762
716.381	1778
718.739	1748
721.097	1718
723.455	1706
725.811	1776
728.167	1752
730.521	1744
732.875	1804
735.23	1736
737.582	1708
739.934	1760
742.285	1746
744.635	1756
746.985	1742
749.332	1712
751.68	1812
754.028	1766
756.374	1738
758.72	1754
761.065	1738
763.408	1768
765.752	1756
768.095	1764
770.436	1726
772.777	1792
775.116	1734
777.456	1772
779.794	1750
782.133	1774
784.469	1742
786.805	1730
789.141	1770
791.476	1744
793.809	1744
796.142	1766
798.476	1782
800.807	1804
803.138	1796
805.468	1806
807.797	1774
810.125	1748
812.453	1784
814.78	1772
817.106	1790
819.432	1750
821.757	1780
824.08	1792
826.403	1738
828.726	1800
831.048	1858
833.368	1792
835.688	1790
838.007	1828
840.326	1794
842.644	1844
844.96	1800
847.276	1870
849.592	1790
851.906	1810
854.221	1840
856.534	1836
858.846	1832
861.157	1834
863.469	1850
865.779	1830
868.088	1816
870.396	1770
872.704	1806
875.011	1814
877.318	1786
879.623	1802
881.928	1828
884.232	1832
886.536	1792
888.837	1842
891.139	1786
893.44	1812
895.741	1778
898.039	1768
900.339	1860
902.637	1824
904.933	1774
907.231	1816
909.526	1830
911.821	1806
914.115	1848
916.408	1784
918.701	1756
920.993	1770
923.283	1772
925.573	1752
927.864	1826
930.153	1734
932.441	1748
934.728	1776
937.014	1758
939.3	1778
941.585	1826
943.87	1764
946.154	1798
948.437	1792
950.719	1770
952.999	1748
955.28	1762
957.56	1796
959.84	1780
962.117	1756
964.395	1818
966.671	1766
968.948	1714
971.223	1794
973.498	1740
975.771	1778
978.045	1772
980.317	1744
982.588	1744
984.86	1750
987.13	1698
989.399	1762
991.667	1726
993.937	1724
996.204	1730
998.47	1696
1000.74	1708
1003	1694
1005.26	1716
1007.53	1702
1009.79	1688
1012.05	1712
1014.31	1668
1016.57	1682
1018.83	1708
1021.09	1696
1023.35	1692
1025.61	1692
1027.87	1666
1030.12	1636
1032.38	1678
1034.63	1634
1036.88	1690
1039.14	1706
1041.39	1672
1043.64	1684
1045.89	1682
1048.14	1698
1050.39	1682
1052.64	1650
1054.89	1698
1057.14	1708
1059.38	1640
1061.63	1656
1063.87	1590
1066.12	1680
1068.36	1694
1070.6	1668
1072.85	1598
1075.09	1588
1077.33	1608
1079.57	1600
1081.81	1556
1084.05	1558
1086.28	1590
1088.52	1630
1090.76	1642
1092.99	1604
1095.23	1574
1097.46	1534
1099.69	1570
1101.93	1554
1104.16	1536
1106.39	1522
1108.62	1522
1110.85	1512
1113.08	1570
1115.31	1568
1117.53	1558
1119.76	1504
1121.99	1538
1124.21	1494
1126.44	1496
1128.66	1532
1130.88	1538
1133.11	1540
1135.33	1470
1137.55	1508
1139.77	1520
1141.99	1470
1144.21	1544
1146.43	1556
1148.64	1476
1150.86	1490
1153.08	1506
1155.29	1530
1157.51	1514
1159.72	1494
1161.93	1466
1164.14	1488
1166.36	1482
1168.57	1484
1170.78	1464
1172.99	1460
1175.2	1514
1177.4	1524
1179.61	1470
1181.82	1468
1184.02	1452
1186.23	1446
1188.43	1484
1190.64	1454
1192.84	1414
1195.04	1442
1197.24	1448
1199.45	1436.13
1201.64	1435.59
1203.84	1439.3
1206.04	1391.79
1208.24	1375.58
1210.44	1394.03
1212.64	1396.27
1214.83	1392.5
1217.03	1385.67
1219.22	1395.75
1221.41	1371.38
1223.61	1392.09
1225.8	1364.97
1227.99	1377.42
1230.18	1348.48
1232.37	1381.23
1234.56	1366.28
1236.75	1357.81
1238.94	1335.64
1241.13	1348.54
1243.31	1361.94
1245.5	1357.99
1247.68	1392.75
1249.87	1359.55
1252.05	1350.42
1254.24	1360.64
1256.42	1355.31
1258.6	1370.48
1260.78	1323.77
1262.96	1349.77
1265.14	1363.9
1267.32	1327.04
1269.5	1340.73
1271.67	1337.27
1273.85	1323.19
1276.03	1344.81
1278.2	1319.26
1280.38	1308.34
1282.55	1316.03
1284.72	1352.63
1286.9	1348.2
1289.07	1349.71
1291.24	1338.51
1293.41	1325.08
1295.58	1315.75
1297.75	1316.16
1299.92	1319.08
1302.09	1340
1304.25	1309.43
1306.42	1318.19
1308.46	1306
1310.63	1292
1312.81	1264
1314.98	1282
1317.16	1290
1319.33	1276
1321.5	1312
1323.67	1310
1325.85	1292
1328.02	1290
1330.19	1256
1332.35	1268
1334.52	1326
1336.69	1304
1338.86	1276
1341.02	1312
1343.19	1292
1345.35	1282
1347.52	1296
1349.68	1266
1351.84	1254
1354	1214
1356.17	1262
1358.33	1290
1360.49	1280
1362.65	1240
1364.8	1228
1366.96	1246
1369.12	1240
1371.28	1264
1373.43	1236
1375.59	1204
1377.74	1238
1379.89	1218
1382.05	1228
1384.2	1284
1386.35	1236
1388.5	1264
1390.65	1228
1392.8	1254
1394.95	1290
1397.1	1226
1399.25	1248
1401.4	1264
1403.54	1222
1405.69	1220
1407.83	1176
1409.98	1212
1412.12	1190
1414.26	1222
1416.4	1226
1418.55	1274
1420.69	1234
1422.83	1220
1424.97	1218
1427.1	1174
1429.24	1218
1431.38	1236
1433.52	1246
1435.65	1228
1437.79	1252
1439.92	1174
1442.06	1236
1444.19	1212
1446.32	1224
1448.46	1230
1450.59	1200
1452.72	1250
1454.85	1278
1456.98	1206
1459.11	1218
1461.23	1244
1463.36	1190
1465.49	1204
1467.61	1240
1469.74	1260
1471.86	1202
1473.99	1208
1476.11	1240
1478.23	1194
1480.36	1242
1482.48	1220
1484.6	1216
1486.72	1224
1488.84	1212
1490.96	1158
1493.07	1214
1495.19	1256
1497.31	1204
1499.42	1162
1501.54	1222
1503.65	1164
1505.77	1204
1507.88	1176
1509.99	1176
1512.1	1162
1514.22	1178
1516.33	1190
1518.44	1178
1520.55	1220
1522.65	1166
1524.76	1178
1526.87	1186
1528.98	1196
1531.08	1190
1533.19	1172
1535.29	1132
1537.4	1164
1539.5	1170
1541.6	1140
1543.7	1144
1545.8	1174
1547.91	1136
1550.01	1158
1552.11	1150
1554.2	1152
1556.3	1094
1558.4	1122
1560.5	1122
1562.59	1170
1564.69	1146
1566.78	1156
1568.88	1150
1570.97	1084
1573.06	1134
1575.15	1114
1577.25	1122
1579.34	1140
1581.43	1128
1583.52	1100
1585.6	1104
1587.69	1112
1589.78	1100
1591.87	1136
1593.95	1086
1596.04	1102
1598.12	1106
1600.21	1114
1602.29	1112
1604.37	1070
1606.46	1120
1608.54	1144
1610.62	1136
1612.7	1112
1614.78	1078
1616.86	1060
1618.94	1082
1621.01	1112
1623.09	1078
1625.17	1114
1627.24	1054
1629.32	1054
1631.39	1080
1633.47	1078
1635.54	1082
1637.61	1076
1639.68	1028
1641.76	1078
1643.83	1076
1645.9	1102
1647.96	1064
1650.03	1050
1652.1	1064
1654.17	1066
1656.24	1048
1658.3	1056
1660.37	1022
1662.43	1078
1664.5	1012
1666.56	1076
1668.62	1042
1670.68	1044
1672.75	998
1674.81	1008
1676.87	1010
1678.93	996
1680.99	1020
1683.04	1016
1685.1	1010
1687.16	1004
1689.21	1028
1691.27	1014
1693.33	996
1695.38	996
1697.43	978
1699.49	980
1701.54	988
1703.59	982
1705.64	972
1707.69	976
1709.74	1008
1711.79	942
1713.84	978
1715.89	942
1717.94	904
1719.98	964
1722.03	964
1724.07	938
1726.12	914
1728.16	954
1730.21	956
1732.25	952
1734.29	908
1736.33	910
1738.37	912
1740.41	902
1742.45	948
1744.49	928
1746.53	948
1748.57	916
1750.61	902
1752.64	910
1754.68	918
1756.71	884
1758.75	896
1760.78	908
1762.82	880
1764.85	892
1766.88	906
1768.91	872
1770.94	894
1772.97	882
1775	860
1777.03	880
1779.06	874
1781.09	870
1783.12	870
1785.14	870
1787.17	882
1789.19	858
1791.22	868
1793.24	880
1795.27	840
1797.29	860
1799.31	826
1801.33	814
1803.35	826
1805.37	808
1807.39	776
1809.41	814
1811.43	842
1813.45	802
1815.46	826
1817.48	812
1819.5	794
1821.51	816
1823.53	802
1825.54	798
1827.55	802
1829.57	786
1831.58	790
1833.59	768
1835.6	780
1837.61	784
1839.62	790
1841.63	776
1843.64	750
1845.65	768
1847.65	744
1849.66	750
1851.66	758
1853.67	708
1855.67	738
1857.68	740
1859.68	748
1861.68	766
1863.69	752
1865.69	722
1867.69	694
1869.69	694
1871.69	706
1873.69	698
1875.69	708
1877.68	706
1879.68	698
1881.68	716
1883.67	708
1885.67	714
1887.66	688
1889.66	664
1891.65	712
1893.64	688
1895.64	670
1897.63	660
1899.62	668
1901.61	656
1903.6	674
1905.59	662
1907.58	652
1909.56	650
1911.55	656
1913.54	660
1915.53	664
1917.51	626
1919.5	620
1921.48	646
1923.46	616
1925.45	632
1927.43	650
1929.41	632
1931.39	634
1933.37	620
1935.35	614
1937.33	628
1939.31	614
1941.29	620
1943.27	614
1945.24	638
1947.22	632
1949.2	626
1951.17	624
1953.14	614
1955.12	594
1957.09	582
1959.06	612
1961.04	594
1963.01	626
1964.98	588
1966.95	582
1968.92	574
1970.89	586
1972.86	590
1974.82	596
1976.79	570
1978.76	574
1980.72	552
1982.69	562
1984.65	562
1986.62	540
1988.58	564
1990.54	588
1992.51	552
1994.47	548
1996.43	546
1998.39	576
1999.37	540