File: muestras/nopal/inside_prf_17.txt
#Acq. time (s)=	10
#Accumulations=	1
#Range (cm-¹)=	200...3000
#Windows=	3
#Autofocus=	Off
#AutoExposure=	Off
#Spike filter=	Off
#Delay time (s)=	0
#Binning=	1
#Readout mode=	Signal
#DeNoise=	Off
#ICS correction=	Off
#Dark correction=	Off
#Inst. Process=	Off
#Instrument=	LabRAM HR Evol
#Detector=	Syncerity OE
#Objective=	x100_VIS
#Grating=	600 (500nm)
#ND Filter=	0.01%
#Laser=	633nm_Edge
#Hole=	30.0125
#Range=	Visible
#Project=	Omar
#Sample=	03-07-23
#Site=	nop
#Title=	inside_prf
#Remark=
#Date=	03.07.2023 14:46
#Acquired=	03.07.2023 14:46:10
201.713	28
204.247	34
206.778	34
209.311	38
211.84	32
214.371	36
216.899	26
219.428	40
221.955	26
224.482	32
227.007	30
229.531	30
232.055	32
234.579	36
237.1	32
239.621	38
242.141	38
244.661	40
247.179	30
249.698	34
252.215	36
254.731	38
257.246	40
259.761	34
262.273	36
264.786	38
267.298	30
269.809	48
272.319	32
274.828	36
277.336	26
279.844	36
282.351	28
284.855	26
287.361	44
289.866	30
292.368	30
294.871	36
297.372	36
299.873	34
302.372	38
304.872	28
307.37	40
309.866	34
312.364	34
314.859	42
317.353	34
319.848	30
322.341	38
324.833	36
327.324	42
329.814	34
332.304	38
334.792	36
337.28	38
339.767	36
342.254	40
344.739	32
347.224	38
349.708	36
352.191	46
354.673	36
357.155	40
359.634	40
362.114	42
364.593	40
367.07	42
369.548	42
372.024	38
374.499	36
376.974	38
379.447	44
381.92	38
384.392	44
386.864	38
389.333	46
391.802	48
394.272	52
396.739	40
399.206	44
401.673	42
404.138	36
406.602	46
409.066	50
411.528	40
413.99	40
416.451	44
418.911	38
421.371	38
423.83	52
426.288	54
428.745	50
431.201	46
433.657	50
436.111	54
438.565	46
441.017	40
443.469	44
445.921	46
448.37	50
450.821	48
453.27	52
455.717	42
458.165	56
460.61	44
463.056	52
465.5	50
467.945	50
470.387	52
472.829	50
475.271	50
477.711	50
480.15	56
482.589	54
485.027	50
487.465	60
489.901	54
492.337	62
494.771	60
497.205	48
499.638	54
502.07	62
504.502	56
506.933	62
509.363	46
511.792	60
514.219	60
516.647	58
519.073	54
521.5	58
523.924	62
526.348	50
528.772	60
531.194	54
533.616	62
536.036	58
538.457	56
540.875	58
543.294	60
545.712	62
548.128	64
550.545	58
552.959	68
555.373	58
557.788	58
560.2	68
562.612	58
565.023	64
567.433	64
569.843	72
572.251	72
574.659	60
577.066	66
579.472	60
581.878	62
584.283	76
586.687	72
589.09	68
591.493	66
593.893	66
596.294	76
598.694	70
601.093	64
603.491	66
605.889	74
608.285	74
610.682	80
613.076	78
615.471	76
617.864	72
620.256	78
622.648	94
625.039	76
627.429	84
629.819	82
632.208	80
634.595	78
636.982	80
639.369	82
641.755	74
644.139	86
646.523	86
648.906	94
651.288	88
653.67	92
656.051	84
658.429	96
660.808	78
663.187	86
665.565	88
667.942	98
670.317	92
672.692	92
675.067	98
677.44	110
679.813	100
682.184	100
684.556	104
686.926	102
689.296	110
691.664	118
694.033	90
696.4	108
698.766	108
701.133	100
703.497	110
705.861	120
708.224	118
710.586	108
712.949	118
715.31	106
717.67	122
720.029	104
722.388	112
724.746	118
727.103	110
729.458	118
731.814	116
734.168	124
736.523	120
738.876	120
741.227	126
743.579	134
745.931	128
748.28	132
750.629	130
752.977	132
755.325	126
757.672	132
760.018	136
762.363	134
764.708	148
767.052	142
769.394	142
771.737	152
774.078	150
776.419	154
778.758	148
781.097	146
783.435	156
785.773	150
788.11	148
790.446	172
792.781	162
795.115	160
797.449	178
799.782	178
802.115	166
804.446	184
806.777	184
809.106	172
811.435	166
813.764	186
816.091	178
818.418	196
820.743	190
823.069	178
825.393	176
827.717	200
830.039	204
832.362	202
834.683	202
837.003	206
839.324	208
841.643	208
843.961	216
846.278	224
848.594	232
850.91	228
853.227	222
855.541	218
857.855	224
860.168	226
862.48	232
864.79	252
867.101	246
869.411	246
871.721	248
874.029	242
876.336	238
878.643	252
880.95	276
883.254	268
885.559	252
887.862	268
890.166	266
892.467	280
894.77	264
897.07	260
899.371	268
901.669	284
903.968	254
906.266	278
908.563	276
910.859	284
913.154	308
915.449	310
917.742	292
920.036	300
922.329	302
924.621	302
926.911	318
929.201	312
931.49	312
933.779	316
936.068	336
938.355	318
940.64	340
942.926	358
945.212	358
947.495	354
949.779	342
952.062	356
954.344	352
956.625	394
958.905	368
961.184	372
963.464	388
965.742	396
968.02	378
970.296	384
972.572	396
974.847	400
977.121	388
979.396	412
981.669	406
983.941	426
986.212	434
988.483	424
990.753	458
993.022	426
995.29	458
997.558	448
999.825	438
1002.09	462
1004.36	468
1006.62	466
1008.89	482
1011.15	490
1013.41	492
1015.67	480
1017.93	474
1020.19	490
1022.45	492
1024.71	508
1026.97	516
1029.23	510
1031.49	516
1033.74	534
1036	560
1038.25	560
1040.5	578
1042.76	526
1045.01	574
1047.26	560
1049.51	576
1051.76	558
1054.01	628
1056.26	566
1058.51	604
1060.75	602
1063	602
1065.25	564
1067.49	628
1069.73	644
1071.98	654
1074.22	640
1076.46	640
1078.7	658
1080.94	664
1083.18	634
1085.42	688
1087.66	654
1089.9	640
1092.14	676
1094.37	684
1096.61	658
1098.84	708
1101.08	690
1103.31	666
1105.54	672
1107.77	662
1110	680
1112.23	688
1114.46	698
1116.69	702
1118.92	706
1121.15	694
1123.37	736
1125.6	716
1127.83	738
1130.05	700
1132.27	730
1134.5	742
1136.72	714
1138.94	776
1141.16	778
1143.38	770
1145.6	722
1147.82	794
1150.04	798
1152.26	788
1154.47	788
1156.69	798
1158.9	772
1161.12	826
1163.33	786
1165.54	742
1167.76	786
1169.97	766
1172.18	790
1174.39	784
1176.6	788
1178.81	830
1181.02	788
1183.22	774
1185.43	832
1187.63	758
1189.84	804
1192.04	798
1194.25	796
1196.45	798
1198.65	780
1200.85	794
1203.05	746
1205.25	762
1207.45	786
1209.65	772
1211.85	776
1214.05	766
1216.24	742
1218.44	770
1220.64	738
1222.83	736
1225.02	760
1227.22	720
1229.41	752
1231.6	740
1233.79	716
1235.98	716
1238.17	740
1240.36	730
1242.55	704
1244.73	696
1246.92	694
1249.11	710
1251.29	660
1253.48	684
1255.66	686
1257.84	712
1260.03	676
1262.21	696
1264.39	682
1266.57	700
1268.75	680
1270.93	652
1273.11	658
1275.28	654
1277.46	638
1279.64	634
1281.81	624
1283.98	639.556
1286.16	594.849
1288.33	596.816
1290.5	619.235
1292.68	604.905
1294.85	617.149
1297.02	596.571
1299.19	572.224
1301.36	591.276
1303.53	576.778
1305.69	555.491
1307.86	553.18
1310.03	565.684
1312.19	545.829
1314.36	533.589
1316.52	514.699
1318.68	516.625
1320.85	516.671
1323.01	494.954
1325.17	498.794
1327.33	497.218
1329.49	486.838
1331.65	479.461
1333.81	481.731
1335.97	473.106
1338.12	468.446
1340.28	448.661
1342.44	461.844
1344.59	452.143
1346.75	449.548
1348.9	442.682
1351.05	445.442
1353.2	425.07
1355.36	432.161
1357.51	434.714
1359.66	412.043
1361.81	401.468
1363.96	406.088
1366.1	411.894
1368.25	402.869
1370.4	407.989
1372.54	378.016
1374.69	386.161
1376.83	390.407
1378.98	394.334
1381.12	376.707
1383.26	372.451
1385.41	371.288
1387.55	338.331
1389.69	355.464
1391.83	364.524
1393.02	362
1395.17	358
1397.32	358
1399.47	358
1401.62	342
1403.77	338
1405.91	324
1408.06	344
1410.2	328
1412.35	328
1414.49	332
1416.63	308
1418.78	346
1420.92	324
1423.06	304
1425.2	324
1427.34	294
1429.48	308
1431.61	312
1433.75	316
1435.89	338
1438.02	316
1440.16	284
1442.3	314
1444.43	288
1446.56	290
1448.7	286
1450.83	300
1452.96	290
1455.09	282
1457.22	300
1459.35	296
1461.48	274
1463.61	276
1465.73	270
1467.86	268
1469.98	278
1472.11	270
1474.24	248
1476.36	290
1478.48	274
1480.6	260
1482.73	254
1484.85	274
1486.97	252
1489.09	270
1491.21	262
1493.33	258
1495.44	250
1497.56	276
1499.68	256
1501.79	242
1503.91	274
1506.02	242
1508.14	244
1510.25	214
1512.36	234
1514.48	240
1516.59	250
1518.7	242
1520.81	242
1522.92	238
1525.02	246
1527.13	236
1529.24	236
1531.35	224
1533.45	236
1535.56	230
1537.66	234
1539.77	242
1541.87	246
1543.97	234
1546.08	242
1548.18	214
1550.28	226
1552.38	230
1554.48	212
1556.57	224
1558.67	232
1560.77	226
1562.87	224
1564.96	222
1567.06	218
1569.15	220
1571.25	220
1573.34	226
1575.43	216
1577.53	212
1579.62	214
1581.71	202
1583.8	214
1585.89	198
1587.98	198
1590.06	214
1592.15	196
1594.24	200
1596.33	232
1598.41	220
1600.5	202
1602.58	202
1604.66	222
1606.75	210
1608.83	206
1610.91	214
1612.99	210
1615.07	200
1617.15	212
1619.23	224
1621.31	216
1623.39	202
1625.46	216
1627.54	206
1629.62	198
1631.69	218
1633.77	220
1635.84	186
1637.91	206
1639.99	202
1642.06	214
1644.13	196
1646.2	194
1648.27	202
1650.34	186
1652.41	214
1654.47	202
1656.54	186
1658.61	184
1660.67	194
1662.74	178
1664.81	190
1666.87	196
1668.93	198
1671	204
1673.06	202
1675.12	182
1677.18	188
1679.24	200
1681.3	218
1683.36	206
1685.42	172
1687.47	212
1689.53	192
1691.59	188
1693.64	192
1695.7	188
1697.75	190
1699.81	182
1701.86	188
1703.91	186
1705.97	170
1708.02	196
1710.07	180
1712.12	194
1714.17	182
1716.22	180
1718.26	192
1720.31	192
1722.36	196
1724.4	180
1726.45	178
1728.49	178
1730.54	194
1732.58	180
1734.63	194
1736.67	180
1738.71	192
1740.75	198
1742.79	190
1744.83	182
1746.87	174
1748.91	174
1750.95	186
1752.98	176
1755.02	166
1757.06	192
1759.09	188
1761.13	178
1763.16	184
1765.19	192
1767.23	164
1769.26	180
1771.29	176
1773.32	190
1775.35	186
1777.38	188
1779.41	186
1781.44	188
1783.47	166
1785.49	174
1787.52	186
1789.55	182
1791.57	162
1793.6	186
1795.62	166
1797.64	190
1799.67	182
1801.69	164
1803.71	168
1805.73	188
1807.75	192
1809.77	184
1811.79	160
1813.81	170
1815.83	194
1817.84	180
1819.86	168
1821.88	164
1823.89	186
1825.91	178
1827.92	184
1829.93	180
1831.95	176
1833.96	168
1835.97	178
1837.98	198
1839.99	176
1842	174
1844.01	182
1846.02	174
1848.03	182
1850.03	176
1852.04	178
1854.05	178
1856.05	184
1858.06	164
1860.06	178
1862.06	198
1864.07	162
1866.07	180
1868.07	186
1870.07	166
1872.07	168
1874.07	180
1876.07	192
1878.07	168
1880.07	176
1882.07	182
1884.06	168
1886.06	196
1888.05	164
1890.05	154
1892.04	184
1894.04	180
1896.03	176
1898.02	182
1900.01	182
1902	170
1903.99	172
1905.98	178
1907.97	176
1909.96	182
1911.95	170
1913.94	166
1915.93	168
1917.91	180
1919.9	182
1921.88	188
1923.87	182
1925.85	182
1927.83	156
1929.82	164
1931.8	178
1933.78	176
1935.76	176
1937.74	162
1939.72	192
1941.7	166
1943.68	170
1945.65	180
1947.63	178
1949.61	170
1951.58	174
1953.56	192
1955.53	164
1957.51	178
1959.48	198
1961.45	168
1963.43	172
1965.4	176
1967.37	182
1969.34	184
1971.31	170
1973.28	172
1975.25	172
1977.22	170
1979.18	168
1981.15	170
1983.12	166
1985.08	162
1987.05	164
1989.01	154
1990.97	180
1992.94	178
1994.9	166
1996.86	170
1998.82	176
2000.78	178
2002.74	160
2004.7	172
2006.66	166
2008.62	174
2010.58	170
2012.54	176
2014.49	172
2016.45	172
2018.4	168
2020.36	184
2022.31	166
2024.27	174
2026.22	166
2028.17	168
2030.12	182
2032.07	166
2034.03	180
2035.98	156
2037.93	166
2039.87	174
2041.82	170
2043.77	164
2045.72	166
2047.66	162
2049.61	146
2051.55	182
2053.5	168
2055.44	154
2057.39	172
2059.33	166
2061.27	170
2063.21	184
2065.15	174
2067.09	152
2069.03	166
2070.97	162
2072.91	164
2074.85	172
2076.79	182
2078.73	158
2080.66	162
2082.6	160
2084.53	154
2086.47	168
2088.4	178
2090.33	178
2092.27	166
2094.2	180
2096.13	172
2098.06	160
2099.99	152
2101.92	166
2103.85	164
2105.78	160
2107.71	158
2109.64	154
2111.56	160
2113.49	180
2115.41	162
2117.34	158
2119.26	174
2121.19	166
2123.11	162
2125.03	172
2126.96	168
2128.88	164
2130.8	170
2132.72	160
2134.64	164
2136.56	170
2138.48	166
2140.4	168
2142.31	170
2144.23	150
2146.15	168
2148.06	172
2149.98	166
2151.89	164
2153.81	176
2155.72	168
2157.63	176
2159.55	158
2161.46	154
2163.37	168
2165.28	164
2167.19	158
2169.1	174
2171.01	150
2172.91	150
2174.82	154
2176.73	174
2178.64	170
2180.54	168
2182.45	170
2184.35	156
2186.26	158
2188.16	164
2190.06	150
2191.96	158
2193.87	162
2195.77	162
2197.67	152
2199.57	170
2201.47	154
2203.37	168
2205.27	158
2207.16	150
2209.06	178
2210.96	150
2212.85	170
2214.75	162
2216.64	168
2218.54	154
2220.43	158
2222.33	152
2224.22	145.886
2226.11	147.184
2228	159.921
2229.89	158.187
2231.78	161.52
2233.67	157.237
2235.56	162.866
2237.45	152.878
2239.34	154.14
2241.23	156.46
2243.11	152.606
2245	141.032
2246.89	139.89
2248.77	147.505
2250.66	153.02
2252.54	143.508
2254.42	143.32
2256.31	145.861
2258.19	142.25
2260.07	146.979
2261.95	151.208
2263.83	149.01
2265.71	143.81
2267.59	149.622
2269.47	152.515
2271.35	145.015
2273.23	154.643
2275.1	147.416
2276.98	148.359
2278.86	138.309
2280.73	140.467
2282.61	136.95
2284.48	133.301
2286.36	141.875
2288.23	141.575
2290.1	139.71
2291.98	136.48
2293.85	134.4
2295.72	140.609
2297.59	130.602
2299.46	136.34
2301.33	140.839
2303.2	136.098
2305.06	135.025
2306.93	129.15
2308.8	133.93
2310.67	138.847
2312.53	130.65
2314.4	127.718
2316.26	140.94
2317.62	126
2319.5	118
2321.37	136
2323.24	114
2325.12	126
2326.99	144
2328.86	130
2330.73	122
2332.6	124
2334.47	142
2336.34	120
2338.2	122
2340.07	128
2341.94	132
2343.81	128
2345.67	134
2347.54	126
2349.4	130
2351.27	130
2353.13	138
2354.99	128
2356.86	128
2358.72	130
2360.58	124
2362.44	118
2364.3	126
2366.16	128
2368.02	126
2369.88	120
2371.74	128
2373.6	132
2375.45	124
2377.31	118
2379.17	120
2381.02	124
2382.88	120
2384.73	122
2386.58	134
2388.44	126
2390.29	120
2392.14	122
2393.99	120
2395.85	112
2397.7	116
2399.55	126
2401.4	120
2403.25	124
2405.09	106
2406.94	126
2408.79	134
2410.63	110
2412.48	120
2414.33	126
2416.17	124
2418.02	118
2419.86	120
2421.7	110
2423.55	116
2425.39	116
2427.23	130
2429.07	112
2430.91	136
2432.75	112
2434.59	106
2436.43	102
2438.27	112
2440.11	118
2441.95	118
2443.78	108
2445.62	110
2447.46	110
2449.29	100
2451.13	124
2452.96	116
2454.79	108
2456.63	112
2458.46	114
2460.29	110
2462.12	112
2463.95	118
2465.78	116
2467.61	112
2469.44	102
2471.27	114
2473.1	102
2474.93	112
2476.76	110
2478.58	124
2480.41	114
2482.23	106
2484.06	108
2485.88	106
2487.71	110
2489.53	108
2491.35	108
2493.18	104
2495	96
2496.82	106
2498.64	104
2500.46	106
2502.28	110
2504.1	100
2505.92	90
2507.74	104
2509.55	98
2511.37	114
2513.19	96
2515	94
2516.82	104
2518.63	102
2520.45	108
2522.26	100
2524.07	110
2525.89	104
2527.7	102
2529.51	102
2531.32	104
2533.13	102
2534.94	104
2536.75	100
2538.56	104
2540.37	96
2542.18	110
2543.98	90
2545.79	98
2547.6	106
2549.4	100
2551.21	100
2553.01	84
2554.82	98
2556.62	98
2558.42	104
2560.23	92
2562.03	102
2563.83	86
2565.63	92
2567.43	96
2569.23	92
2571.03	92
2572.83	90
2574.63	106
2576.43	102
2578.22	96
2580.02	94
2581.82	104
2583.61	90
2585.41	106
2587.2	88
2589	86
2590.79	96
2592.58	98
2594.38	92
2596.17	98
2597.96	102
2599.75	92
2601.54	90
2603.33	96
2605.12	90
2606.91	94
2608.7	94
2610.49	98
2612.27	76
2614.06	92
2615.85	80
2617.63	90
2619.42	90
2621.2	96
2622.99	88
2624.77	80
2626.55	104
2628.34	88
2630.12	86
2631.9	80
2633.68	86
2635.46	86
2637.24	88
2639.02	92
2640.8	82
2642.58	84
2644.36	84
2646.14	78
2647.91	78
2649.69	78
2651.46	88
2653.24	74
2655.01	84
2656.79	76
2658.56	78
2660.34	82
2662.11	78
2663.88	80
2665.65	68
2667.42	90
2669.2	76
2670.96	82
2672.73	80
2674.5	90
2676.27	78
2678.04	84
2679.81	80
2681.58	78
2683.34	84
2685.11	84
2686.87	76
2688.64	90
2690.4	76
2692.17	76
2693.93	66
2695.69	82
2697.46	82
2699.22	74
2700.98	78
2702.74	86
2704.5	84
2706.26	84
2708.02	64
2709.78	64
2711.54	80
2713.3	70
2715.05	74
2716.81	70
2718.57	62
2720.32	70
2722.08	70
2723.83	60
2725.59	74
2727.34	70
2729.09	74
2730.85	72
2732.6	66
2734.35	74
2736.1	70
2737.85	70
2739.6	66
2741.35	60
2743.1	68
2744.85	70
2746.6	66
2748.35	66
2750.09	68
2751.84	68
2753.59	66
2755.33	66
2757.08	60
2758.82	70
2760.57	70
2762.31	80
2764.05	64
2765.79	74
2767.54	72
2769.28	64
2771.02	74
2772.76	70
2774.5	68
2776.24	52
2777.98	66
2779.72	62
2781.46	54
2783.19	62
2784.93	54
2786.67	66
2788.4	78
2790.14	62
2791.87	68
2793.61	66
2795.34	58
2797.07	70
2798.81	62
2800.54	62
2802.27	66
2804	60
2805.74	62
2807.47	64
2809.2	70
2810.93	64
2812.65	54
2814.38	66
2816.11	60
2817.84	60
2819.56	70
2821.29	66
2823.02	58
2824.74	54
2826.47	60
2828.19	62
2829.92	72
2831.64	56
2833.36	54
2835.09	58
2836.81	62
2838.53	62
2840.25	56
2841.97	60
2843.69	56
2845.41	48
2847.13	56
2848.85	58
2850.57	56
2852.28	62
2854	54
2855.72	58
2857.43	50
2859.15	50
2860.86	60
2862.58	50
2864.29	54
2866.01	70
2867.72	66
2869.43	58
2871.14	54
2872.86	60
2874.57	50
2876.28	60
2877.99	48
2879.7	56
2881.41	56
2883.11	50
2884.82	50
2886.53	48
2888.24	52
2889.94	54
2891.65	40
2893.36	54
2895.06	54
2896.77	62
2898.47	48
2900.17	54
2901.88	46
2903.58	56
2905.28	48
2906.98	48
2908.69	58
2910.39	64
2912.09	52
2913.79	56
2915.49	48
2917.19	50
2918.88	56
2920.58	52
2922.28	50
2923.98	50
2925.67	52
2927.37	54
2929.06	48
2930.76	40
2932.45	42
2934.15	48
2935.84	52
2937.53	42
2939.23	50
2940.92	58
2942.61	40
2944.3	48
2945.99	50
2947.68	44
2949.37	50
2951.06	48
2952.75	50
2954.44	46
2956.12	46
2957.81	48
2959.5	42
2961.18	46
2962.87	52
2964.56	48
2966.24	48
2967.92	54
2969.61	38
2971.29	54
2972.97	48
2974.66	46
2976.34	44
2978.02	44
2979.7	46
2981.38	36
2983.06	48
2984.74	52
2986.42	38
2988.1	48
2989.78	46
2991.45	42
2993.13	46
2994.81	46
2996.48	46
2998.16	52
2999.83	50