File: muestras/nopal/inside_prf_13.txt
#Acq. time (s)=	10
#Accumulations=	1
#Range (cm-¹)=	200...3000
#Windows=	3
#Autofocus=	Off
#AutoExposure=	Off
#Spike filter=	Off
#Delay time (s)=	0
#Binning=	1
#Readout mode=	Signal
#DeNoise=	Off
#ICS correction=	Off
#Dark correction=	Off
#Inst. Process=	Off
#Instrument=	LabRAM HR Evol
#Detector=	Syncerity OE
#Objective=	x100_VIS
#Grating=	600 (500nm)
#ND Filter=	0.01%
#Laser=	633nm_Edge
#Hole=	30.0125
#Range=	Visible
#Project=	Omar
#Sample=	03-07-23
#Site=	nop
#Title=	inside_prf
#Remark=
#Date=	03.07.2023 14:42
#Acquired=	03.07.2023 14:42:01
201.713	32
204.247	36
206.778	28
209.311	24
211.84	34
214.371	30
216.899	34
219.428	38
221.955	24
224.482	36
227.007	32
229.531	38
232.055	32
234.579	28
237.1	30
239.621	34
242.141	38
244.661	30
247.179	28
249.698	40
252.215	28
254.731	24
257.246	26
259.761	40
262.273	38
264.786	30
267.298	28
269.809	36
272.319	32
274.828	36
277.336	34
279.844	40
282.351	36
284.855	38
287.361	34
289.866	36
292.368	34
294.871	38
297.372	38
299.873	30
302.372	30
304.872	32
307.37	28
309.866	32
312.364	44
314.859	32
317.353	28
319.848	28
322.341	30
324.833	36
327.324	32
329.814	42
332.304	42
334.792	30
337.28	38
339.767	36
342.254	38
344.739	34
347.224	32
349.708	38
352.191	30
354.673	38
357.155	34
359.634	44
362.114	34
364.593	38
367.07	34
369.548	36
372.024	34
374.499	38
376.974	42
379.447	32
381.92	38
384.392	38
386.864	34
389.333	40
391.802	44
394.272	32
396.739	28
399.206	40
401.673	44
404.138	44
406.602	32
409.066	40
411.528	34
413.99	36
416.451	36
418.911	42
421.371	34
423.83	34
426.288	42
428.745	38
431.201	40
433.657	40
436.111	40
438.565	36
441.017	46
443.469	40
445.921	38
448.37	44
450.821	36
453.27	52
455.717	38
458.165	40
460.61	36
463.056	36
465.5	42
467.945	42
470.387	40
472.829	40
475.271	46
477.711	44
480.15	40
482.589	38
485.027	46
487.465	38
489.901	44
492.337	44
494.771	40
497.205	42
499.638	44
502.07	40
504.502	40
506.933	46
509.363	46
511.792	44
514.219	50
516.647	46
519.073	46
521.5	38
523.924	48
526.348	40
528.772	50
531.194	46
533.616	48
536.036	42
538.457	46
540.875	40
543.294	50
545.712	48
548.128	44
550.545	46
552.959	54
555.373	46
557.788	50
560.2	46
562.612	48
565.023	40
567.433	50
569.843	48
572.251	40
574.659	38
577.066	50
579.472	46
581.878	48
584.283	40
586.687	50
589.09	52
591.493	50
593.893	46
596.294	54
598.694	52
601.093	54
603.491	52
605.889	50
608.285	52
610.682	56
613.076	56
615.471	54
617.864	52
620.256	58
622.648	46
625.039	58
627.429	58
629.819	54
632.208	54
634.595	52
636.982	44
639.369	64
641.755	60
644.139	68
646.523	62
648.906	56
651.288	58
653.67	60
656.051	62
658.429	56
660.808	58
663.187	62
665.565	56
667.942	66
670.317	56
672.692	68
675.067	72
677.44	66
679.813	60
682.184	64
684.556	66
686.926	72
689.296	60
691.664	70
694.033	64
696.4	66
698.766	66
701.133	68
703.497	80
705.861	64
708.224	72
710.586	62
712.949	72
715.31	76
717.67	68
720.029	72
722.388	76
724.746	68
727.103	76
729.458	86
731.814	74
734.168	64
736.523	70
738.876	68
741.227	86
743.579	62
745.931	84
748.28	68
750.629	78
752.977	82
755.325	84
757.672	78
760.018	82
762.363	98
764.708	94
767.052	94
769.394	98
771.737	92
774.078	106
776.419	92
778.758	92
781.097	92
783.435	102
785.773	102
788.11	90
790.446	94
792.781	96
795.115	100
797.449	104
799.782	102
802.115	110
804.446	102
806.777	110
809.106	106
811.435	112
813.764	110
816.091	108
818.418	120
820.743	114
823.069	114
825.393	118
827.717	112
830.039	124
832.362	114
834.683	120
837.003	130
839.324	120
841.643	132
843.961	122
846.278	120
848.594	124
850.91	122
853.227	124
855.541	138
857.855	134
860.168	114
862.48	140
864.79	146
867.101	130
869.411	142
871.721	138
874.029	150
876.336	136
878.643	146
880.95	152
883.254	134
885.559	150
887.862	156
890.166	150
892.467	158
894.77	148
897.07	156
899.371	154
901.669	176
903.968	174
906.266	150
908.563	146
910.859	164
913.154	162
915.449	174
917.742	186
920.036	176
922.329	178
924.621	174
926.911	186
929.201	178
931.49	180
933.779	182
936.068	174
938.355	190
940.64	192
942.926	192
945.212	206
947.495	196
949.779	196
952.062	210
954.344	194
956.625	206
958.905	208
961.184	210
963.464	222
965.742	214
968.02	208
970.296	204
972.572	212
974.847	222
977.121	214
979.396	224
981.669	242
983.941	240
986.212	224
988.483	240
990.753	216
993.022	236
995.29	254
997.558	226
999.825	232
1002.09	240
1004.36	262
1006.62	254
1008.89	240
1011.15	252
1013.41	262
1015.67	258
1017.93	268
1020.19	296
1022.45	272
1024.71	272
1026.97	286
1029.23	282
1031.49	280
1033.74	292
1036	288
1038.25	272
1040.5	294
1042.76	296
1045.01	284
1047.26	280
1049.51	304
1051.76	288
1054.01	300
1056.26	310
1058.51	316
1060.75	304
1063	316
1065.25	334
1067.49	326
1069.73	348
1071.98	318
1074.22	322
1076.46	350
1078.7	332
1080.94	358
1083.18	354
1085.42	322
1087.66	344
1089.9	346
1092.14	362
1094.37	358
1096.61	354
1098.84	360
1101.08	372
1103.31	354
1105.54	372
1107.77	366
1110	356
1112.23	364
1114.46	360
1116.69	374
1118.92	362
1121.15	378
1123.37	362
1125.6	360
1127.83	368
1130.05	366
1132.27	404
1134.5	394
1136.72	390
1138.94	388
1141.16	378
1143.38	390
1145.6	368
1147.82	432
1150.04	440
1152.26	378
1154.47	380
1156.69	412
1158.9	422
1161.12	396
1163.33	400
1165.54	430
1167.76	400
1169.97	414
1172.18	412
1174.39	406
1176.6	406
1178.81	414
1181.02	410
1183.22	404
1185.43	378
1187.63	402
1189.84	408
1192.04	394
1194.25	402
1196.45	410
1198.65	412
1200.85	406
1203.05	392
1205.25	376
1207.45	394
1209.65	374
1211.85	354
1214.05	386
1216.24	402
1218.44	374
1220.64	386
1222.83	384
1225.02	386
1227.22	388
1229.41	364
1231.6	370
1233.79	378
1235.98	358
1238.17	352
1240.36	380
1242.55	380
1244.73	340
1246.92	344
1249.11	366
1251.29	346
1253.48	348
1255.66	338
1257.84	354
1260.03	338
1262.21	334
1264.39	348
1266.57	354
1268.75	324
1270.93	340
1273.11	322
1275.28	336
1277.46	312
1279.64	326
1281.81	294
1283.98	320.219
1286.16	317.017
1288.33	322.131
1290.5	314.019
1292.68	304.721
1294.85	312.742
1297.02	303.94
1299.19	308.679
1301.36	288.75
1303.53	313.699
1305.69	316.796
1307.86	302.031
1310.03	288.285
1312.19	296.212
1314.36	275.156
1316.52	289.21
1318.68	300.322
1320.85	297.729
1323.01	289.738
1325.17	275.415
1327.33	266.605
1329.49	265.196
1331.65	275.682
1333.81	276.891
1335.97	280.89
1338.12	275.786
1340.28	277.141
1342.44	274.523
1344.59	271.032
1346.75	273.633
1348.9	260.337
1351.05	284.292
1353.2	261.035
1355.36	255.633
1357.51	264.522
1359.66	260.979
1361.81	244.75
1363.96	255.228
1366.1	247.064
1368.25	243.126
1370.4	252.896
1372.54	252.277
1374.69	241.262
1376.83	251.721
1378.98	253.716
1381.12	242.844
1383.26	238.824
1385.41	252.171
1387.55	247.412
1389.69	246.971
1391.83	229.15
1393.02	250
1395.17	234
1397.32	258
1399.47	242
1401.62	222
1403.77	226
1405.91	240
1408.06	214
1410.2	224
1412.35	210
1414.49	216
1416.63	238
1418.78	228
1420.92	208
1423.06	214
1425.2	216
1427.34	190
1429.48	198
1431.61	216
1433.75	222
1435.89	204
1438.02	198
1440.16	198
1442.3	216
1444.43	196
1446.56	192
1448.7	190
1450.83	196
1452.96	192
1455.09	212
1457.22	182
1459.35	188
1461.48	194
1463.61	196
1465.73	200
1467.86	182
1469.98	206
1472.11	194
1474.24	168
1476.36	178
1478.48	178
1480.6	192
1482.73	184
1484.85	192
1486.97	188
1489.09	174
1491.21	178
1493.33	178
1495.44	184
1497.56	164
1499.68	182
1501.79	176
1503.91	184
1506.02	180
1508.14	190
1510.25	176
1512.36	188
1514.48	174
1516.59	174
1518.7	174
1520.81	168
1522.92	160
1525.02	166
1527.13	166
1529.24	168
1531.35	158
1533.45	166
1535.56	150
1537.66	164
1539.77	166
1541.87	166
1543.97	162
1546.08	152
1548.18	154
1550.28	164
1552.38	170
1554.48	164
1556.57	168
1558.67	164
1560.77	142
1562.87	164
1564.96	158
1567.06	160
1569.15	148
1571.25	142
1573.34	146
1575.43	152
1577.53	160
1579.62	150
1581.71	148
1583.8	162
1585.89	146
1587.98	150
1590.06	140
1592.15	148
1594.24	146
1596.33	150
1598.41	144
1600.5	152
1602.58	134
1604.66	152
1606.75	144
1608.83	146
1610.91	144
1612.99	126
1615.07	146
1617.15	152
1619.23	144
1621.31	142
1623.39	158
1625.46	146
1627.54	140
1629.62	144
1631.69	148
1633.77	146
1635.84	150
1637.91	142
1639.99	140
1642.06	138
1644.13	146
1646.2	140
1648.27	134
1650.34	126
1652.41	144
1654.47	146
1656.54	146
1658.61	138
1660.67	148
1662.74	148
1664.81	150
1666.87	144
1668.93	122
1671	136
1673.06	138
1675.12	132
1677.18	134
1679.24	134
1681.3	130
1683.36	142
1685.42	138
1687.47	132
1689.53	130
1691.59	120
1693.64	140
1695.7	146
1697.75	136
1699.81	126
1701.86	132
1703.91	138
1705.97	120
1708.02	136
1710.07	142
1712.12	144
1714.17	136
1716.22	120
1718.26	140
1720.31	118
1722.36	140
1724.4	126
1726.45	136
1728.49	138
1730.54	120
1732.58	126
1734.63	124
1736.67	130
1738.71	122
1740.75	128
1742.79	138
1744.83	130
1746.87	124
1748.91	130
1750.95	130
1752.98	128
1755.02	134
1757.06	110
1759.09	124
1761.13	134
1763.16	136
1765.19	122
1767.23	130
1769.26	130
1771.29	138
1773.32	118
1775.35	144
1777.38	126
1779.41	136
1781.44	126
1783.47	126
1785.49	130
1787.52	130
1789.55	128
1791.57	120
1793.6	132
1795.62	136
1797.64	126
1799.67	120
1801.69	122
1803.71	132
1805.73	140
1807.75	126
1809.77	138
1811.79	124
1813.81	120
1815.83	136
1817.84	120
1819.86	126
1821.88	134
1823.89	136
1825.91	128
1827.92	126
1829.93	124
1831.95	128
1833.96	124
1835.97	134
1837.98	112
1839.99	128
1842	124
1844.01	126
1846.02	134
1848.03	124
1850.03	134
1852.04	132
1854.05	126
1856.05	126
1858.06	122
1860.06	134
1862.06	136
1864.07	122
1866.07	124
1868.07	122
1870.07	120
1872.07	126
1874.07	122
1876.07	120
1878.07	128
1880.07	118
1882.07	126
1884.06	124
1886.06	134
1888.05	120
1890.05	110
1892.04	138
1894.04	110
1896.03	118
1898.02	110
1900.01	116
1902	128
1903.99	120
1905.98	120
1907.97	122
1909.96	114
1911.95	114
1913.94	116
1915.93	108
1917.91	134
1919.9	116
1921.88	120
1923.87	128
1925.85	116
1927.83	128
1929.82	116
1931.8	138
1933.78	126
1935.76	126
1937.74	120
1939.72	128
1941.7	122
1943.68	120
1945.65	128
1947.63	132
1949.61	126
1951.58	126
1953.56	122
1955.53	122
1957.51	134
1959.48	118
1961.45	118
1963.43	124
1965.4	116
1967.37	136
1969.34	114
1971.31	122
1973.28	110
1975.25	116
1977.22	118
1979.18	128
1981.15	112
1983.12	140
1985.08	114
1987.05	124
1989.01	120
1990.97	120
1992.94	128
1994.9	126
1996.86	124
1998.82	122
2000.78	124
2002.74	114
2004.7	120
2006.66	128
2008.62	126
2010.58	114
2012.54	116
2014.49	120
2016.45	112
2018.4	104
2020.36	110
2022.31	120
2024.27	106
2026.22	124
2028.17	119
2030.12	104
2032.07	112
2034.03	122
2035.98	128
2037.93	116
2039.87	118
2041.82	130
2043.77	118
2045.72	130
2047.66	132
2049.61	116
2051.55	122
2053.5	116
2055.44	118
2057.39	110
2059.33	126
2061.27	118
2063.21	130
2065.15	130
2067.09	122
2069.03	112
2070.97	128
2072.91	130
2074.85	122
2076.79	120
2078.73	124
2080.66	120
2082.6	122
2084.53	114
2086.47	122
2088.4	94
2090.33	112
2092.27	116
2094.2	128
2096.13	118
2098.06	122
2099.99	126
2101.92	116
2103.85	126
2105.78	116
2107.71	136
2109.64	110
2111.56	132
2113.49	122
2115.41	114
2117.34	118
2119.26	112
2121.19	122
2123.11	116
2125.03	118
2126.96	118
2128.88	128
2130.8	128
2132.72	106
2134.64	126
2136.56	122
2138.48	128
2140.4	120
2142.31	124
2144.23	120
2146.15	122
2148.06	100
2149.98	114
2151.89	118
2153.81	118
2155.72	116
2157.63	118
2159.55	110
2161.46	110
2163.37	108
2165.28	110
2167.19	120
2169.1	114
2171.01	108
2172.91	130
2174.82	116
2176.73	108
2178.64	122
2180.54	114
2182.45	110
2184.35	120
2186.26	136
2188.16	122
2190.06	118
2191.96	108
2193.87	112
2195.77	114
2197.67	122
2199.57	114
2201.47	122
2203.37	120
2205.27	106
2207.16	124
2209.06	118
2210.96	110
2212.85	130
2214.75	112
2216.64	112
2218.54	122
2220.43	108
2222.33	110
2224.22	119.982
2226.11	110.286
2228	114.444
2229.89	120.137
2231.78	112.572
2233.67	114.528
2235.56	123.346
2237.45	118.631
2239.34	116.42
2241.23	134.316
2243.11	113.114
2245	121.789
2246.89	115.495
2248.77	113.712
2250.66	126.105
2252.54	119.213
2254.42	114.093
2256.31	113.185
2258.19	125.887
2260.07	113.259
2261.95	120.741
2263.83	125.2
2265.71	120.781
2267.59	120.43
2269.47	112.006
2271.35	122.268
2273.23	113.78
2275.1	117.77
2276.98	119.355
2278.86	123.84
2280.73	122.15
2282.61	120.218
2284.48	111.903
2286.36	128.85
2288.23	118.481
2290.1	122.713
2291.98	110.268
2293.85	118.962
2295.72	126.668
2297.59	128.948
2299.46	123.323
2301.33	131.799
2303.2	124.742
2305.06	117.52
2306.93	127.666
2308.8	113.67
2310.67	124.377
2312.53	131.915
2314.4	112.303
2316.26	111.271
2317.62	110
2319.5	112
2321.37	130
2323.24	130
2325.12	130
2326.99	140
2328.86	120
2330.73	116
2332.6	128
2334.47	138
2336.34	122
2338.2	126
2340.07	122
2341.94	122
2343.81	126
2345.67	122
2347.54	138
2349.4	112
2351.27	128
2353.13	120
2354.99	124
2356.86	128
2358.72	118
2360.58	114
2362.44	122
2364.3	110
2366.16	128
2368.02	110
2369.88	124
2371.74	120
2373.6	118
2375.45	124
2377.31	118
2379.17	118
2381.02	130
2382.88	112
2384.73	130
2386.58	118
2388.44	120
2390.29	118
2392.14	114
2393.99	116
2395.85	116
2397.7	106
2399.55	112
2401.4	126
2403.25	112
2405.09	122
2406.94	116
2408.79	118
2410.63	114
2412.48	108
2414.33	126
2416.17	110
2418.02	98
2419.86	112
2421.7	106
2423.55	112
2425.39	110
2427.23	108
2429.07	104
2430.91	104
2432.75	118
2434.59	118
2436.43	96
2438.27	118
2440.11	112
2441.95	104
2443.78	112
2445.62	112
2447.46	112
2449.29	112
2451.13	106
2452.96	102
2454.79	110
2456.63	102
2458.46	102
2460.29	104
2462.12	108
2463.95	108
2465.78	120
2467.61	102
2469.44	114
2471.27	104
2473.1	104
2474.93	100
2476.76	110
2478.58	102
2480.41	80
2482.23	106
2484.06	98
2485.88	102
2487.71	104
2489.53	108
2491.35	90
2493.18	112
2495	104
2496.82	106
2498.64	102
2500.46	86
2502.28	110
2504.1	98
2505.92	110
2507.74	96
2509.55	106
2511.37	108
2513.19	102
2515	90
2516.82	102
2518.63	94
2520.45	114
2522.26	98
2524.07	96
2525.89	100
2527.7	96
2529.51	106
2531.32	106
2533.13	94
2534.94	86
2536.75	100
2538.56	92
2540.37	96
2542.18	92
2543.98	98
2545.79	102
2547.6	98
2549.4	90
2551.21	96
2553.01	114
2554.82	80
2556.62	92
2558.42	96
2560.23	88
2562.03	92
2563.83	82
2565.63	92
2567.43	86
2569.23	94
2571.03	86
2572.83	98
2574.63	84
2576.43	94
2578.22	98
2580.02	88
2581.82	86
2583.61	84
2585.41	78
2587.2	90
2589	92
2590.79	88
2592.58	86
2594.38	86
2596.17	82
2597.96	84
2599.75	96
2601.54	72
2603.33	70
2605.12	98
2606.91	96
2608.7	88
2610.49	76
2612.27	98
2614.06	94
2615.85	80
2617.63	92
2619.42	96
2621.2	80
2622.99	94
2624.77	88
2626.55	96
2628.34	84
2630.12	78
2631.9	78
2633.68	86
2635.46	78
2637.24	92
2639.02	80
2640.8	78
2642.58	76
2644.36	84
2646.14	78
2647.91	88
2649.69	80
2651.46	82
2653.24	74
2655.01	82
2656.79	84
2658.56	84
2660.34	70
2662.11	76
2663.88	84
2665.65	82
2667.42	70
2669.2	78
2670.96	70
2672.73	74
2674.5	84
2676.27	76
2678.04	78
2679.81	70
2681.58	74
2683.34	70
2685.11	82
2686.87	72
2688.64	68
2690.4	80
2692.17	74
2693.93	68
2695.69	74
2697.46	72
2699.22	70
2700.98	74
2702.74	76
2704.5	70
2706.26	76
2708.02	74
2709.78	72
2711.54	72
2713.3	70
2715.05	70
2716.81	78
2718.57	64
2720.32	70
2722.08	76
2723.83	70
2725.59	66
2727.34	68
2729.09	66
2730.85	72
2732.6	58
2734.35	68
2736.1	78
2737.85	56
2739.6	72
2741.35	66
2743.1	70
2744.85	72
2746.6	70
2748.35	72
2750.09	68
2751.84	72
2753.59	58
2755.33	56
2757.08	66
2758.82	70
2760.57	58
2762.31	58
2764.05	72
2765.79	74
2767.54	64
2769.28	56
2771.02	64
2772.76	64
2774.5	72
2776.24	64
2777.98	68
2779.72	62
2781.46	66
2783.19	60
2784.93	74
2786.67	54
2788.4	64
2790.14	58
2791.87	56
2793.61	64
2795.34	74
2797.07	68
2798.81	58
2800.54	60
2802.27	50
2804	68
2805.74	66
2807.47	64
2809.2	68
2810.93	48
2812.65	60
2814.38	56
2816.11	68
2817.84	54
2819.56	64
2821.29	72
2823.02	58
2824.74	60
2826.47	58
2828.19	52
2829.92	60
2831.64	58
2833.36	60
2835.09	68
2836.81	56
2838.53	54
2840.25	62
2841.97	52
2843.69	56
2845.41	56
2847.13	60
2848.85	52
2850.57	54
2852.28	58
2854	68
2855.72	58
2857.43	50
2859.15	54
2860.86	56
2862.58	56
2864.29	56
2866.01	48
2867.72	46
2869.43	52
2871.14	62
2872.86	52
2874.57	52
2876.28	56
2877.99	56
2879.7	52
2881.41	54
2883.11	46
2884.82	56
2886.53	46
2888.24	50
2889.94	44
2891.65	56
2893.36	40
2895.06	58
2896.77	54
2898.47	58
2900.17	60
2901.88	46
2903.58	50
2905.28	48
2906.98	56
2908.69	56
2910.39	56
2912.09	50
2913.79	44
2915.49	48
2917.19	40
2918.88	52
2920.58	44
2922.28	54
2923.98	42
2925.67	46
2927.37	48
2929.06	52
2930.76	50
2932.45	46
2934.15	50
2935.84	46
2937.53	46
2939.23	56
2940.92	48
2942.61	46
2944.3	48
2945.99	46
2947.68	52
2949.37	48
2951.06	52
2952.75	52
2954.44	48
2956.12	48
2957.81	50
2959.5	44
2961.18	52
2962.87	36
2964.56	44
2966.24	50
2967.92	44
2969.61	46
2971.29	46
2972.97	42
2974.66	44
2976.34	48
2978.02	38
2979.7	48
2981.38	48
2983.06	42
2984.74	48
2986.42	48
2988.1	52
2989.78	38
2991.45	42
2993.13	52
2994.81	44
2996.48	44
2998.16	44
2999.83	48