File: muestras/nopal/inside_prf_15.txt
#Acq. time (s)=	10
#Accumulations=	1
#Range (cm-¹)=	200...3000
#Windows=	3
#Autofocus=	Off
#AutoExposure=	Off
#Spike filter=	Off
#Delay time (s)=	0
#Binning=	1
#Readout mode=	Signal
#DeNoise=	Off
#ICS correction=	Off
#Dark correction=	Off
#Inst. Process=	Off
#Instrument=	LabRAM HR Evol
#Detector=	Syncerity OE
#Objective=	x100_VIS
#Grating=	600 (500nm)
#ND Filter=	0.01%
#Laser=	633nm_Edge
#Hole=	30.0125
#Range=	Visible
#Project=	Omar
#Sample=	03-07-23
#Site=	nop
#Title=	inside_prf
#Remark=
#Date=	03.07.2023 14:44
#Acquired=	03.07.2023 14:44:14
201.713	28
204.247	36
206.778	30
209.311	32
211.84	36
214.371	32
216.899	30
219.428	32
221.955	30
224.482	26
227.007	30
229.531	32
232.055	30
234.579	32
237.1	36
239.621	32
242.141	34
244.661	32
247.179	22
249.698	34
252.215	38
254.731	32
257.246	36
259.761	44
262.273	34
264.786	36
267.298	28
269.809	38
272.319	36
274.828	32
277.336	34
279.844	38
282.351	38
284.855	30
287.361	32
289.866	32
292.368	32
294.871	30
297.372	32
299.873	32
302.372	32
304.872	28
307.37	36
309.866	34
312.364	34
314.859	30
317.353	40
319.848	34
322.341	36
324.833	42
327.324	30
329.814	32
332.304	38
334.792	40
337.28	38
339.767	32
342.254	36
344.739	30
347.224	36
349.708	40
352.191	36
354.673	46
357.155	28
359.634	38
362.114	44
364.593	42
367.07	42
369.548	36
372.024	32
374.499	40
376.974	36
379.447	36
381.92	38
384.392	44
386.864	34
389.333	44
391.802	34
394.272	38
396.739	44
399.206	36
401.673	40
404.138	40
406.602	36
409.066	38
411.528	42
413.99	40
416.451	46
418.911	50
421.371	36
423.83	38
426.288	40
428.745	38
431.201	40
433.657	38
436.111	40
438.565	44
441.017	44
443.469	50
445.921	44
448.37	42
450.821	44
453.27	54
455.717	48
458.165	50
460.61	44
463.056	40
465.5	52
467.945	38
470.387	54
472.829	48
475.271	40
477.711	46
480.15	42
482.589	40
485.027	42
487.465	48
489.901	44
492.337	44
494.771	38
497.205	52
499.638	48
502.07	48
504.502	46
506.933	56
509.363	52
511.792	44
514.219	48
516.647	36
519.073	46
521.5	56
523.924	46
526.348	50
528.772	52
531.194	54
533.616	44
536.036	46
538.457	52
540.875	52
543.294	56
545.712	54
548.128	54
550.545	54
552.959	48
555.373	62
557.788	54
560.2	56
562.612	70
565.023	48
567.433	56
569.843	50
572.251	56
574.659	50
577.066	50
579.472	66
581.878	64
584.283	64
586.687	58
589.09	50
591.493	54
593.893	52
596.294	62
598.694	64
601.093	66
603.491	54
605.889	56
608.285	58
610.682	52
613.076	62
615.471	54
617.864	56
620.256	62
622.648	66
625.039	64
627.429	74
629.819	62
632.208	58
634.595	66
636.982	66
639.369	60
641.755	66
644.139	64
646.523	60
648.906	72
651.288	62
653.67	72
656.051	70
658.429	66
660.808	62
663.187	74
665.565	66
667.942	68
670.317	74
672.692	66
675.067	76
677.44	74
679.813	72
682.184	78
684.556	72
686.926	78
689.296	80
691.664	84
694.033	78
696.4	74
698.766	74
701.133	72
703.497	88
705.861	86
708.224	82
710.586	78
712.949	86
715.31	90
717.67	86
720.029	84
722.388	88
724.746	86
727.103	92
729.458	96
731.814	94
734.168	104
736.523	86
738.876	92
741.227	98
743.579	96
745.931	92
748.28	92
750.629	100
752.977	114
755.325	102
757.672	100
760.018	112
762.363	114
764.708	108
767.052	106
769.394	110
771.737	126
774.078	116
776.419	100
778.758	100
781.097	126
783.435	120
785.773	120
788.11	128
790.446	118
792.781	122
795.115	134
797.449	126
799.782	116
802.115	132
804.446	120
806.777	134
809.106	122
811.435	146
813.764	130
816.091	136
818.418	140
820.743	126
823.069	142
825.393	140
827.717	128
830.039	148
832.362	158
834.683	144
837.003	158
839.324	160
841.643	162
843.961	144
846.278	152
848.594	174
850.91	146
853.227	156
855.541	156
857.855	166
860.168	176
862.48	158
864.79	178
867.101	176
869.411	184
871.721	184
874.029	166
876.336	182
878.643	164
880.95	190
883.254	174
885.559	176
887.862	194
890.166	196
892.467	222
894.77	204
897.07	194
899.371	194
901.669	214
903.968	212
906.266	200
908.563	218
910.859	236
913.154	202
915.449	208
917.742	210
920.036	234
922.329	194
924.621	224
926.911	226
929.201	228
931.49	248
933.779	220
936.068	240
938.355	244
940.64	232
942.926	238
945.212	264
947.495	230
949.779	260
952.062	264
954.344	264
956.625	254
958.905	258
961.184	262
963.464	276
965.742	290
968.02	276
970.296	296
972.572	294
974.847	292
977.121	300
979.396	274
981.669	302
983.941	302
986.212	308
988.483	304
990.753	294
993.022	318
995.29	328
997.558	320
999.825	338
1002.09	308
1004.36	336
1006.62	322
1008.89	356
1011.15	366
1013.41	326
1015.67	368
1017.93	356
1020.19	338
1022.45	350
1024.71	368
1026.97	362
1029.23	368
1031.49	336
1033.74	378
1036	412
1038.25	390
1040.5	382
1042.76	368
1045.01	392
1047.26	400
1049.51	408
1051.76	404
1054.01	410
1056.26	410
1058.51	402
1060.75	414
1063	418
1065.25	444
1067.49	444
1069.73	420
1071.98	460
1074.22	408
1076.46	458
1078.7	466
1080.94	444
1083.18	466
1085.42	458
1087.66	454
1089.9	488
1092.14	464
1094.37	484
1096.61	496
1098.84	482
1101.08	472
1103.31	508
1105.54	484
1107.77	510
1110	506
1112.23	518
1114.46	520
1116.69	522
1118.92	492
1121.15	520
1123.37	506
1125.6	492
1127.83	512
1130.05	530
1132.27	520
1134.5	524
1136.72	524
1138.94	496
1141.16	502
1143.38	508
1145.6	546
1147.82	528
1150.04	546
1152.26	522
1154.47	564
1156.69	550
1158.9	554
1161.12	552
1163.33	560
1165.54	546
1167.76	550
1169.97	574
1172.18	554
1174.39	564
1176.6	554
1178.81	574
1181.02	562
1183.22	528
1185.43	572
1187.63	546
1189.84	544
1192.04	560
1194.25	564
1196.45	544
1198.65	528
1200.85	564
1203.05	540
1205.25	534
1207.45	536
1209.65	528
1211.85	564
1214.05	564
1216.24	558
1218.44	534
1220.64	536
1222.83	502
1225.02	552
1227.22	506
1229.41	536
1231.6	504
1233.79	514
1235.98	508
1238.17	526
1240.36	502
1242.55	530
1244.73	498
1246.92	500
1249.11	470
1251.29	508
1253.48	476
1255.66	500
1257.84	476
1260.03	496
1262.21	474
1264.39	484
1266.57	468
1268.75	476
1270.93	456
1273.11	486
1275.28	444
1277.46	472
1279.64	450
1281.81	432
1283.98	460.146
1286.16	454.223
1288.33	421.32
1290.5	440.544
1292.68	441.786
1294.85	417.005
1297.02	429.069
1299.19	451.253
1301.36	422.484
1303.53	405.014
1305.69	429.103
1307.86	422.963
1310.03	420.988
1312.19	408.366
1314.36	408.412
1316.52	399.607
1318.68	384.222
1320.85	392.175
1323.01	380.872
1325.17	394.374
1327.33	362.254
1329.49	388.821
1331.65	374.552
1333.81	355.335
1335.97	355.327
1338.12	372.168
1340.28	364.234
1342.44	349.371
1344.59	360.415
1346.75	352.369
1348.9	330.337
1351.05	343.619
1353.2	347.456
1355.36	343.75
1357.51	319.635
1359.66	335.151
1361.81	324.866
1363.96	348.491
1366.1	338.394
1368.25	337.343
1370.4	319.532
1372.54	336.993
1374.69	319.177
1376.83	316.608
1378.98	308.57
1381.12	293.129
1383.26	304.099
1385.41	306.153
1387.55	299.881
1389.69	291.924
1391.83	299.463
1393.02	316
1395.17	288
1397.32	308
1399.47	290
1401.62	290
1403.77	276
1405.91	276
1408.06	278
1410.2	284
1412.35	292
1414.49	294
1416.63	268
1418.78	260
1420.92	286
1423.06	252
1425.2	266
1427.34	278
1429.48	268
1431.61	256
1433.75	254
1435.89	278
1438.02	256
1440.16	252
1442.3	252
1444.43	252
1446.56	266
1448.7	252
1450.83	232
1452.96	230
1455.09	242
1457.22	250
1459.35	212
1461.48	234
1463.61	226
1465.73	240
1467.86	236
1469.98	238
1472.11	226
1474.24	236
1476.36	230
1478.48	228
1480.6	226
1482.73	218
1484.85	238
1486.97	220
1489.09	220
1491.21	232
1493.33	248
1495.44	216
1497.56	214
1499.68	224
1501.79	212
1503.91	204
1506.02	208
1508.14	198
1510.25	208
1512.36	206
1514.48	218
1516.59	216
1518.7	214
1520.81	196
1522.92	198
1525.02	192
1527.13	210
1529.24	196
1531.35	202
1533.45	188
1535.56	190
1537.66	194
1539.77	186
1541.87	192
1543.97	180
1546.08	212
1548.18	194
1550.28	176
1552.38	184
1554.48	184
1556.57	194
1558.67	194
1560.77	190
1562.87	188
1564.96	180
1567.06	176
1569.15	182
1571.25	186
1573.34	188
1575.43	184
1577.53	172
1579.62	164
1581.71	170
1583.8	184
1585.89	172
1587.98	188
1590.06	178
1592.15	180
1594.24	186
1596.33	166
1598.41	168
1600.5	174
1602.58	172
1604.66	190
1606.75	160
1608.83	178
1610.91	182
1612.99	172
1615.07	174
1617.15	168
1619.23	178
1621.31	174
1623.39	174
1625.46	174
1627.54	172
1629.62	180
1631.69	160
1633.77	182
1635.84	164
1637.91	154
1639.99	172
1642.06	182
1644.13	164
1646.2	168
1648.27	154
1650.34	152
1652.41	166
1654.47	146
1656.54	160
1658.61	162
1660.67	162
1662.74	162
1664.81	158
1666.87	164
1668.93	158
1671	170
1673.06	166
1675.12	158
1677.18	160
1679.24	164
1681.3	148
1683.36	162
1685.42	162
1687.47	156
1689.53	146
1691.59	148
1693.64	154
1695.7	148
1697.75	164
1699.81	142
1701.86	156
1703.91	154
1705.97	158
1708.02	162
1710.07	160
1712.12	160
1714.17	156
1716.22	146
1718.26	140
1720.31	136
1722.36	158
1724.4	152
1726.45	164
1728.49	152
1730.54	166
1732.58	152
1734.63	150
1736.67	150
1738.71	158
1740.75	156
1742.79	148
1744.83	154
1746.87	154
1748.91	148
1750.95	144
1752.98	152
1755.02	150
1757.06	148
1759.09	150
1761.13	152
1763.16	154
1765.19	156
1767.23	154
1769.26	148
1771.29	138
1773.32	158
1775.35	138
1777.38	150
1779.41	132
1781.44	152
1783.47	154
1785.49	160
1787.52	144
1789.55	156
1791.57	132
1793.6	154
1795.62	144
1797.64	142
1799.67	150
1801.69	142
1803.71	146
1805.73	148
1807.75	150
1809.77	150
1811.79	150
1813.81	146
1815.83	150
1817.84	150
1819.86	148
1821.88	140
1823.89	134
1825.91	132
1827.92	142
1829.93	140
1831.95	144
1833.96	144
1835.97	138
1837.98	162
1839.99	130
1842	156
1844.01	160
1846.02	150
1848.03	148
1850.03	150
1852.04	148
1854.05	166
1856.05	148
1858.06	138
1860.06	132
1862.06	154
1864.07	138
1866.07	144
1868.07	146
1870.07	144
1872.07	136
1874.07	140
1876.07	140
1878.07	138
1880.07	142
1882.07	144
1884.06	148
1886.06	144
1888.05	150
1890.05	130
1892.04	136
1894.04	136
1896.03	160
1898.02	152
1900.01	132
1902	130
1903.99	128
1905.98	152
1907.97	146
1909.96	150
1911.95	142
1913.94	154
1915.93	148
1917.91	154
1919.9	164
1921.88	140
1923.87	142
1925.85	148
1927.83	144
1929.82	144
1931.8	142
1933.78	138
1935.76	150
1937.74	152
1939.72	146
1941.7	134
1943.68	148
1945.65	154
1947.63	150
1949.61	146
1951.58	132
1953.56	130
1955.53	132
1957.51	132
1959.48	128
1961.45	138
1963.43	150
1965.4	140
1967.37	136
1969.34	140
1971.31	148
1973.28	142
1975.25	126
1977.22	136
1979.18	138
1981.15	144
1983.12	146
1985.08	138
1987.05	140
1989.01	132
1990.97	138
1992.94	146
1994.9	146
1996.86	132
1998.82	138
2000.78	152
2002.74	152
2004.7	136
2006.66	138
2008.62	140
2010.58	142
2012.54	144
2014.49	132
2016.45	136
2018.4	138
2020.36	146
2022.31	154
2024.27	146
2026.22	138
2028.17	137
2030.12	148
2032.07	136
2034.03	138
2035.98	130
2037.93	138
2039.87	140
2041.82	146
2043.77	138
2045.72	144
2047.66	146
2049.61	138
2051.55	118
2053.5	138
2055.44	134
2057.39	148
2059.33	136
2061.27	136
2063.21	146
2065.15	128
2067.09	128
2069.03	132
2070.97	142
2072.91	152
2074.85	156
2076.79	136
2078.73	148
2080.66	126
2082.6	144
2084.53	128
2086.47	136
2088.4	120
2090.33	152
2092.27	126
2094.2	134
2096.13	130
2098.06	138
2099.99	134
2101.92	138
2103.85	138
2105.78	146
2107.71	128
2109.64	142
2111.56	140
2113.49	132
2115.41	146
2117.34	132
2119.26	132
2121.19	144
2123.11	130
2125.03	138
2126.96	130
2128.88	140
2130.8	134
2132.72	144
2134.64	126
2136.56	142
2138.48	136
2140.4	130
2142.31	146
2144.23	126
2146.15	140
2148.06	142
2149.98	132
2151.89	130
2153.81	128
2155.72	132
2157.63	144
2159.55	134
2161.46	126
2163.37	124
2165.28	142
2167.19	140
2169.1	152
2171.01	132
2172.91	136
2174.82	136
2176.73	130
2178.64	134
2180.54	134
2182.45	128
2184.35	130
2186.26	126
2188.16	130
2190.06	136
2191.96	132
2193.87	138
2195.77	136
2197.67	134
2199.57	130
2201.47	132
2203.37	112
2205.27	134
2207.16	124
2209.06	120
2210.96	114
2212.85	122
2214.75	132
2216.64	144
2218.54	134
2220.43	128
2222.33	128
2224.22	126.062
2226.11	138.515
2228	126.656
2229.89	142.276
2231.78	129.432
2233.67	115.675
2235.56	121.346
2237.45	119.388
2239.34	129.34
2241.23	141.235
2243.11	138.539
2245	127.327
2246.89	131.055
2248.77	134.681
2250.66	129.408
2252.54	121.103
2254.42	135.078
2256.31	123.98
2258.19	139.435
2260.07	126.32
2261.95	125.936
2263.83	122.27
2265.71	132.262
2267.59	128.606
2269.47	131.926
2271.35	132.304
2273.23	135.977
2275.1	128.895
2276.98	126.068
2278.86	130.29
2280.73	125.809
2282.61	126.874
2284.48	129.224
2286.36	130.18
2288.23	137.404
2290.1	122.954
2291.98	129.131
2293.85	135.142
2295.72	125.101
2297.59	122
2299.46	140.161
2301.33	127.36
2303.2	134.523
2305.06	124.544
2306.93	124.95
2308.8	136.671
2310.67	130.737
2312.53	132.59
2314.4	134.297
2316.26	132.753
2317.62	132
2319.5	138
2321.37	134
2323.24	118
2325.12	116
2326.99	130
2328.86	136
2330.73	120
2332.6	132
2334.47	128
2336.34	120
2338.2	138
2340.07	136
2341.94	122
2343.81	112
2345.67	120
2347.54	122
2349.4	122
2351.27	130
2353.13	130
2354.99	136
2356.86	134
2358.72	130
2360.58	120
2362.44	140
2364.3	116
2366.16	128
2368.02	148
2369.88	132
2371.74	138
2373.6	126
2375.45	136
2377.31	136
2379.17	118
2381.02	120
2382.88	120
2384.73	122
2386.58	120
2388.44	112
2390.29	128
2392.14	112
2393.99	118
2395.85	104
2397.7	106
2399.55	108
2401.4	118
2403.25	116
2405.09	122
2406.94	122
2408.79	110
2410.63	120
2412.48	112
2414.33	118
2416.17	110
2418.02	112
2419.86	124
2421.7	124
2423.55	118
2425.39	114
2427.23	120
2429.07	112
2430.91	114
2432.75	98
2434.59	100
2436.43	114
2438.27	130
2440.11	112
2441.95	124
2443.78	110
2445.62	102
2447.46	124
2449.29	110
2451.13	98
2452.96	112
2454.79	112
2456.63	118
2458.46	114
2460.29	106
2462.12	130
2463.95	106
2465.78	108
2467.61	112
2469.44	106
2471.27	102
2473.1	112
2474.93	102
2476.76	108
2478.58	96
2480.41	102
2482.23	108
2484.06	98
2485.88	114
2487.71	126
2489.53	98
2491.35	100
2493.18	108
2495	102
2496.82	106
2498.64	108
2500.46	112
2502.28	116
2504.1	106
2505.92	102
2507.74	104
2509.55	100
2511.37	100
2513.19	98
2515	102
2516.82	98
2518.63	98
2520.45	100
2522.26	100
2524.07	92
2525.89	92
2527.7	90
2529.51	88
2531.32	104
2533.13	96
2534.94	80
2536.75	100
2538.56	80
2540.37	108
2542.18	90
2543.98	108
2545.79	110
2547.6	96
2549.4	94
2551.21	98
2553.01	106
2554.82	94
2556.62	100
2558.42	102
2560.23	92
2562.03	90
2563.83	86
2565.63	98
2567.43	102
2569.23	106
2571.03	82
2572.83	98
2574.63	84
2576.43	110
2578.22	90
2580.02	96
2581.82	90
2583.61	86
2585.41	86
2587.2	90
2589	82
2590.79	82
2592.58	82
2594.38	90
2596.17	88
2597.96	74
2599.75	90
2601.54	90
2603.33	84
2605.12	96
2606.91	90
2608.7	78
2610.49	84
2612.27	80
2614.06	84
2615.85	84
2617.63	104
2619.42	82
2621.2	80
2622.99	102
2624.77	72
2626.55	82
2628.34	84
2630.12	90
2631.9	80
2633.68	76
2635.46	72
2637.24	86
2639.02	88
2640.8	82
2642.58	80
2644.36	82
2646.14	84
2647.91	74
2649.69	74
2651.46	82
2653.24	86
2655.01	88
2656.79	78
2658.56	76
2660.34	88
2662.11	88
2663.88	88
2665.65	82
2667.42	70
2669.2	78
2670.96	82
2672.73	68
2674.5	74
2676.27	74
2678.04	82
2679.81	68
2681.58	72
2683.34	74
2685.11	80
2686.87	82
2688.64	80
2690.4	66
2692.17	60
2693.93	78
2695.69	58
2697.46	74
2699.22	80
2700.98	70
2702.74	64
2704.5	74
2706.26	68
2708.02	76
2709.78	74
2711.54	74
2713.3	76
2715.05	66
2716.81	74
2718.57	64
2720.32	66
2722.08	74
2723.83	68
2725.59	70
2727.34	70
2729.09	70
2730.85	66
2732.6	72
2734.35	76
2736.1	74
2737.85	66
2739.6	66
2741.35	62
2743.1	70
2744.85	64
2746.6	70
2748.35	62
2750.09	68
2751.84	70
2753.59	60
2755.33	72
2757.08	64
2758.82	76
2760.57	64
2762.31	58
2764.05	64
2765.79	68
2767.54	62
2769.28	72
2771.02	60
2772.76	64
2774.5	64
2776.24	60
2777.98	58
2779.72	72
2781.46	64
2783.19	70
2784.93	60
2786.67	56
2788.4	68
2790.14	62
2791.87	68
2793.61	46
2795.34	62
2797.07	60
2798.81	58
2800.54	60
2802.27	58
2804	52
2805.74	64
2807.47	60
2809.2	64
2810.93	56
2812.65	74
2814.38	60
2816.11	58
2817.84	56
2819.56	70
2821.29	74
2823.02	60
2824.74	64
2826.47	54
2828.19	62
2829.92	56
2831.64	60
2833.36	60
2835.09	60
2836.81	52
2838.53	52
2840.25	60
2841.97	60
2843.69	62
2845.41	56
2847.13	60
2848.85	56
2850.57	52
2852.28	48
2854	54
2855.72	56
2857.43	46
2859.15	52
2860.86	60
2862.58	50
2864.29	48
2866.01	56
2867.72	60
2869.43	60
2871.14	58
2872.86	50
2874.57	52
2876.28	58
2877.99	56
2879.7	52
2881.41	60
2883.11	48
2884.82	56
2886.53	56
2888.24	50
2889.94	50
2891.65	60
2893.36	56
2895.06	46
2896.77	54
2898.47	54
2900.17	56
2901.88	50
2903.58	46
2905.28	58
2906.98	56
2908.69	52
2910.39	50
2912.09	52
2913.79	52
2915.49	60
2917.19	54
2918.88	52
2920.58	50
2922.28	40
2923.98	40
2925.67	56
2927.37	48
2929.06	46
2930.76	52
2932.45	44
2934.15	44
2935.84	46
2937.53	48
2939.23	50
2940.92	52
2942.61	52
2944.3	46
2945.99	48
2947.68	46
2949.37	40
2951.06	44
2952.75	38
2954.44	44
2956.12	54
2957.81	48
2959.5	58
2961.18	44
2962.87	48
2964.56	50
2966.24	44
2967.92	44
2969.61	44
2971.29	50
2972.97	46
2974.66	52
2976.34	42
2978.02	40
2979.7	50
2981.38	42
2983.06	50
2984.74	42
2986.42	52
2988.1	38
2989.78	46
2991.45	42
2993.13	46
2994.81	44
2996.48	48
2998.16	40
2999.83	34