File: muestras/nopal/inside_prf_18.txt
#Acq. time (s)=	10
#Accumulations=	1
#Range (cm-¹)=	200...3000
#Windows=	3
#Autofocus=	Off
#AutoExposure=	Off
#Spike filter=	Off
#Delay time (s)=	0
#Binning=	1
#Readout mode=	Signal
#DeNoise=	Off
#ICS correction=	Off
#Dark correction=	Off
#Inst. Process=	Off
#Instrument=	LabRAM HR Evol
#Detector=	Syncerity OE
#Objective=	x100_VIS
#Grating=	600 (500nm)
#ND Filter=	0.01%
#Laser=	633nm_Edge
#Hole=	30.0125
#Range=	Visible
#Project=	Omar
#Sample=	03-07-23
#Site=	nop
#Title=	inside_prf
#Remark=
#Date=	03.07.2023 14:47
#Acquired=	03.07.2023 14:47:03
201.713	30
204.247	28
206.778	28
209.311	28
211.84	26
214.371	30
216.899	28
219.428	32
221.955	30
224.482	26
227.007	30
229.531	32
232.055	26
234.579	30
237.1	26
239.621	28
242.141	32
244.661	32
247.179	32
249.698	30
252.215	30
254.731	30
257.246	32
259.761	28
262.273	36
264.786	30
267.298	38
269.809	30
272.319	34
274.828	22
277.336	30
279.844	32
282.351	36
284.855	28
287.361	34
289.866	34
292.368	32
294.871	24
297.372	28
299.873	28
302.372	32
304.872	26
307.37	22
309.866	26
312.364	30
314.859	28
317.353	40
319.848	32
322.341	28
324.833	34
327.324	34
329.814	30
332.304	36
334.792	40
337.28	30
339.767	30
342.254	40
344.739	34
347.224	30
349.708	42
352.191	40
354.673	30
357.155	32
359.634	34
362.114	36
364.593	34
367.07	40
369.548	38
372.024	46
374.499	28
376.974	36
379.447	38
381.92	28
384.392	34
386.864	42
389.333	30
391.802	42
394.272	34
396.739	40
399.206	38
401.673	34
404.138	42
406.602	40
409.066	30
411.528	32
413.99	32
416.451	38
418.911	42
421.371	32
423.83	38
426.288	36
428.745	36
431.201	36
433.657	36
436.111	32
438.565	40
441.017	38
443.469	46
445.921	42
448.37	38
450.821	36
453.27	34
455.717	40
458.165	34
460.61	42
463.056	36
465.5	42
467.945	40
470.387	44
472.829	34
475.271	40
477.711	36
480.15	38
482.589	28
485.027	38
487.465	34
489.901	38
492.337	42
494.771	36
497.205	34
499.638	34
502.07	44
504.502	44
506.933	42
509.363	40
511.792	44
514.219	42
516.647	40
519.073	44
521.5	36
523.924	42
526.348	46
528.772	42
531.194	42
533.616	40
536.036	48
538.457	54
540.875	32
543.294	36
545.712	44
548.128	36
550.545	46
552.959	42
555.373	52
557.788	50
560.2	38
562.612	44
565.023	52
567.433	46
569.843	46
572.251	46
574.659	42
577.066	50
579.472	48
581.878	48
584.283	48
586.687	50
589.09	56
591.493	48
593.893	40
596.294	40
598.694	50
601.093	62
603.491	48
605.889	52
608.285	46
610.682	52
613.076	48
615.471	50
617.864	46
620.256	50
622.648	50
625.039	58
627.429	52
629.819	48
632.208	50
634.595	54
636.982	52
639.369	60
641.755	48
644.139	52
646.523	58
648.906	52
651.288	56
653.67	58
656.051	58
658.429	62
660.808	62
663.187	50
665.565	56
667.942	60
670.317	60
672.692	56
675.067	44
677.44	64
679.813	60
682.184	62
684.556	66
686.926	62
689.296	60
691.664	62
694.033	64
696.4	64
698.766	56
701.133	64
703.497	64
705.861	64
708.224	64
710.586	72
712.949	82
715.31	66
717.67	72
720.029	74
722.388	62
724.746	74
727.103	74
729.458	64
731.814	70
734.168	66
736.523	76
738.876	84
741.227	74
743.579	74
745.931	78
748.28	62
750.629	66
752.977	76
755.325	80
757.672	76
760.018	70
762.363	80
764.708	66
767.052	86
769.394	82
771.737	76
774.078	84
776.419	84
778.758	96
781.097	90
783.435	82
785.773	100
788.11	90
790.446	96
792.781	82
795.115	94
797.449	78
799.782	88
802.115	92
804.446	82
806.777	102
809.106	108
811.435	94
813.764	92
816.091	98
818.418	108
820.743	96
823.069	100
825.393	104
827.717	106
830.039	94
832.362	104
834.683	106
837.003	98
839.324	108
841.643	108
843.961	116
846.278	106
848.594	128
850.91	120
853.227	116
855.541	122
857.855	112
860.168	122
862.48	114
864.79	122
867.101	128
869.411	118
871.721	132
874.029	130
876.336	130
878.643	134
880.95	126
883.254	138
885.559	134
887.862	130
890.166	126
892.467	140
894.77	136
897.07	142
899.371	144
901.669	140
903.968	142
906.266	138
908.563	156
910.859	146
913.154	152
915.449	154
917.742	162
920.036	150
922.329	146
924.621	158
926.911	172
929.201	168
931.49	158
933.779	164
936.068	158
938.355	166
940.64	164
942.926	174
945.212	174
947.495	168
949.779	164
952.062	158
954.344	180
956.625	182
958.905	168
961.184	186
963.464	172
965.742	188
968.02	172
970.296	188
972.572	182
974.847	204
977.121	196
979.396	202
981.669	180
983.941	216
986.212	216
988.483	194
990.753	210
993.022	196
995.29	218
997.558	216
999.825	224
1002.09	208
1004.36	212
1006.62	238
1008.89	222
1011.15	240
1013.41	230
1015.67	230
1017.93	238
1020.19	240
1022.45	234
1024.71	240
1026.97	246
1029.23	240
1031.49	244
1033.74	242
1036	242
1038.25	246
1040.5	232
1042.76	256
1045.01	280
1047.26	260
1049.51	276
1051.76	264
1054.01	266
1056.26	270
1058.51	300
1060.75	284
1063	280
1065.25	248
1067.49	274
1069.73	254
1071.98	288
1074.22	304
1076.46	292
1078.7	292
1080.94	316
1083.18	286
1085.42	316
1087.66	280
1089.9	308
1092.14	326
1094.37	314
1096.61	294
1098.84	306
1101.08	330
1103.31	300
1105.54	294
1107.77	308
1110	316
1112.23	316
1114.46	316
1116.69	304
1118.92	326
1121.15	328
1123.37	328
1125.6	340
1127.83	340
1130.05	306
1132.27	336
1134.5	346
1136.72	312
1138.94	320
1141.16	344
1143.38	354
1145.6	336
1147.82	352
1150.04	346
1152.26	352
1154.47	336
1156.69	350
1158.9	340
1161.12	346
1163.33	352
1165.54	350
1167.76	338
1169.97	370
1172.18	346
1174.39	350
1176.6	372
1178.81	354
1181.02	356
1183.22	374
1185.43	360
1187.63	358
1189.84	336
1192.04	382
1194.25	344
1196.45	350
1198.65	372
1200.85	354
1203.05	352
1205.25	382
1207.45	316
1209.65	348
1211.85	348
1214.05	340
1216.24	334
1218.44	340
1220.64	348
1222.83	352
1225.02	310
1227.22	342
1229.41	326
1231.6	342
1233.79	332
1235.98	340
1238.17	318
1240.36	314
1242.55	318
1244.73	308
1246.92	334
1249.11	344
1251.29	310
1253.48	312
1255.66	332
1257.84	308
1260.03	312
1262.21	300
1264.39	302
1266.57	306
1268.75	292
1270.93	282
1273.11	294
1275.28	292
1277.46	294
1279.64	294
1281.81	280
1283.98	289.738
1286.16	279.412
1288.33	295.977
1290.5	271.387
1292.68	281.105
1294.85	243.114
1297.02	263.93
1299.19	264.384
1301.36	256.765
1303.53	265.484
1305.69	276.419
1307.86	263.05
1310.03	234.362
1312.19	250.776
1314.36	266.857
1316.52	234.609
1318.68	251.043
1320.85	225.036
1323.01	239.704
1325.17	261.326
1327.33	231.357
1329.49	226.517
1331.65	243.657
1333.81	227.758
1335.97	223.792
1338.12	226.153
1340.28	218.011
1342.44	212.603
1344.59	212.81
1346.75	216.495
1348.9	215.19
1351.05	206.196
1353.2	199.103
1355.36	208.504
1357.51	212.34
1359.66	203.306
1361.81	210.43
1363.96	198.398
1366.1	202.011
1368.25	184.977
1370.4	206.638
1372.54	196.192
1374.69	179.202
1376.83	200.656
1378.98	191.153
1381.12	182.566
1383.26	191.325
1385.41	182.859
1387.55	175.459
1389.69	173.09
1391.83	176.963
1393.02	170
1395.17	178
1397.32	172
1399.47	178
1401.62	178
1403.77	156
1405.91	174
1408.06	176
1410.2	166
1412.35	160
1414.49	160
1416.63	170
1418.78	160
1420.92	156
1423.06	156
1425.2	160
1427.34	164
1429.48	170
1431.61	156
1433.75	164
1435.89	152
1438.02	150
1440.16	158
1442.3	150
1444.43	148
1446.56	154
1448.7	142
1450.83	130
1452.96	160
1455.09	150
1457.22	152
1459.35	132
1461.48	150
1463.61	144
1465.73	162
1467.86	140
1469.98	146
1472.11	148
1474.24	120
1476.36	128
1478.48	124
1480.6	136
1482.73	134
1484.85	132
1486.97	146
1489.09	128
1491.21	144
1493.33	140
1495.44	144
1497.56	142
1499.68	124
1501.79	144
1503.91	138
1506.02	136
1508.14	130
1510.25	132
1512.36	136
1514.48	134
1516.59	128
1518.7	132
1520.81	126
1522.92	130
1525.02	118
1527.13	120
1529.24	124
1531.35	116
1533.45	112
1535.56	120
1537.66	122
1539.77	134
1541.87	118
1543.97	114
1546.08	124
1548.18	132
1550.28	128
1552.38	122
1554.48	118
1556.57	136
1558.67	110
1560.77	128
1562.87	128
1564.96	116
1567.06	122
1569.15	126
1571.25	124
1573.34	114
1575.43	130
1577.53	100
1579.62	110
1581.71	110
1583.8	116
1585.89	106
1587.98	106
1590.06	114
1592.15	116
1594.24	118
1596.33	110
1598.41	114
1600.5	102
1602.58	120
1604.66	116
1606.75	108
1608.83	104
1610.91	110
1612.99	112
1615.07	104
1617.15	100
1619.23	112
1621.31	112
1623.39	112
1625.46	98
1627.54	102
1629.62	112
1631.69	102
1633.77	108
1635.84	100
1637.91	112
1639.99	118
1642.06	108
1644.13	108
1646.2	106
1648.27	106
1650.34	96
1652.41	104
1654.47	108
1656.54	104
1658.61	102
1660.67	102
1662.74	106
1664.81	110
1666.87	112
1668.93	102
1671	102
1673.06	94
1675.12	114
1677.18	96
1679.24	96
1681.3	102
1683.36	98
1685.42	102
1687.47	102
1689.53	106
1691.59	108
1693.64	100
1695.7	100
1697.75	108
1699.81	110
1701.86	96
1703.91	94
1705.97	106
1708.02	106
1710.07	104
1712.12	106
1714.17	108
1716.22	100
1718.26	98
1720.31	112
1722.36	98
1724.4	110
1726.45	100
1728.49	92
1730.54	108
1732.58	98
1734.63	104
1736.67	82
1738.71	104
1740.75	96
1742.79	114
1744.83	96
1746.87	104
1748.91	112
1750.95	98
1752.98	106
1755.02	114
1757.06	94
1759.09	102
1761.13	90
1763.16	106
1765.19	102
1767.23	82
1769.26	96
1771.29	92
1773.32	86
1775.35	102
1777.38	114
1779.41	102
1781.44	100
1783.47	98
1785.49	100
1787.52	108
1789.55	94
1791.57	96
1793.6	102
1795.62	100
1797.64	96
1799.67	100
1801.69	98
1803.71	96
1805.73	88
1807.75	100
1809.77	94
1811.79	88
1813.81	82
1815.83	116
1817.84	114
1819.86	90
1821.88	112
1823.89	92
1825.91	98
1827.92	100
1829.93	96
1831.95	98
1833.96	94
1835.97	90
1837.98	106
1839.99	96
1842	112
1844.01	94
1846.02	88
1848.03	94
1850.03	94
1852.04	94
1854.05	106
1856.05	94
1858.06	94
1860.06	104
1862.06	106
1864.07	90
1866.07	102
1868.07	100
1870.07	98
1872.07	108
1874.07	92
1876.07	100
1878.07	98
1880.07	98
1882.07	98
1884.06	102
1886.06	92
1888.05	96
1890.05	102
1892.04	96
1894.04	100
1896.03	100
1898.02	104
1900.01	86
1902	94
1903.99	88
1905.98	98
1907.97	98
1909.96	84
1911.95	104
1913.94	102
1915.93	84
1917.91	110
1919.9	100
1921.88	108
1923.87	92
1925.85	106
1927.83	102
1929.82	98
1931.8	98
1933.78	88
1935.76	98
1937.74	82
1939.72	104
1941.7	88
1943.68	94
1945.65	94
1947.63	100
1949.61	86
1951.58	100
1953.56	104
1955.53	88
1957.51	94
1959.48	98
1961.45	90
1963.43	92
1965.4	92
1967.37	106
1969.34	86
1971.31	86
1973.28	100
1975.25	90
1977.22	88
1979.18	88
1981.15	104
1983.12	88
1985.08	94
1987.05	106
1989.01	90
1990.97	102
1992.94	98
1994.9	92
1996.86	98
1998.82	100
2000.78	88
2002.74	90
2004.7	88
2006.66	88
2008.62	92
2010.58	88
2012.54	78
2014.49	98
2016.45	92
2018.4	104
2020.36	98
2022.31	84
2024.27	98
2026.22	82
2028.17	93
2030.12	96
2032.07	96
2034.03	104
2035.98	88
2037.93	94
2039.87	102
2041.82	84
2043.77	104
2045.72	96
2047.66	106
2049.61	96
2051.55	84
2053.5	92
2055.44	92
2057.39	82
2059.33	84
2061.27	94
2063.21	84
2065.15	92
2067.09	90
2069.03	90
2070.97	90
2072.91	92
2074.85	100
2076.79	90
2078.73	98
2080.66	90
2082.6	90
2084.53	102
2086.47	90
2088.4	84
2090.33	88
2092.27	98
2094.2	82
2096.13	88
2098.06	92
2099.99	90
2101.92	92
2103.85	98
2105.78	78
2107.71	90
2109.64	82
2111.56	102
2113.49	96
2115.41	98
2117.34	86
2119.26	100
2121.19	96
2123.11	82
2125.03	94
2126.96	96
2128.88	90
2130.8	86
2132.72	86
2134.64	90
2136.56	94
2138.48	98
2140.4	90
2142.31	94
2144.23	86
2146.15	84
2148.06	92
2149.98	92
2151.89	82
2153.81	82
2155.72	98
2157.63	94
2159.55	86
2161.46	94
2163.37	88
2165.28	92
2167.19	92
2169.1	88
2171.01	84
2172.91	88
2174.82	88
2176.73	96
2178.64	94
2180.54	90
2182.45	90
2184.35	90
2186.26	88
2188.16	92
2190.06	88
2191.96	78
2193.87	96
2195.77	90
2197.67	94
2199.57	92
2201.47	90
2203.37	92
2205.27	92
2207.16	92
2209.06	86
2210.96	84
2212.85	70
2214.75	86
2216.64	86
2218.54	98
2220.43	96
2222.33	82
2224.22	86.1091
2226.11	85.3939
2228	74.8545
2229.89	90.2663
2231.78	98.4701
2233.67	95.0778
2235.56	87.4562
2237.45	86.919
2239.34	85.6798
2241.23	87.61
2243.11	88.1291
2245	89.6853
2246.89	92.47
2248.77	92.3575
2250.66	87.41
2252.54	85.6053
2254.42	91.0382
2256.31	82.5854
2258.19	86.3874
2260.07	81.2881
2261.95	91.9385
2263.83	84.9101
2265.71	84.2138
2267.59	86.3101
2269.47	87.382
2271.35	84.91
2273.23	92.5534
2275.1	86.9718
2276.98	87.4
2278.86	90.6689
2280.73	84.31
2282.61	87.81
2284.48	82.8815
2286.36	84.5051
2288.23	85.645
2290.1	87.3098
2291.98	85.5135
2293.85	82.86
2295.72	86.4133
2297.59	88.3999
2299.46	88.4265
2301.33	82.6376
2303.2	87.0617
2305.06	85.5246
2306.93	84.482
2308.8	81.3391
2310.67	81.1462
2312.53	86.4851
2314.4	90.8793
2316.26	85.3511
2317.62	80
2319.5	82
2321.37	84
2323.24	86
2325.12	94
2326.99	76
2328.86	90
2330.73	74
2332.6	94
2334.47	80
2336.34	76
2338.2	86
2340.07	76
2341.94	98
2343.81	84
2345.67	80
2347.54	82
2349.4	94
2351.27	86
2353.13	70
2354.99	88
2356.86	84
2358.72	78
2360.58	80
2362.44	80
2364.3	96
2366.16	82
2368.02	78
2369.88	74
2371.74	74
2373.6	84
2375.45	78
2377.31	82
2379.17	80
2381.02	84
2382.88	86
2384.73	82
2386.58	92
2388.44	72
2390.29	84
2392.14	72
2393.99	74
2395.85	92
2397.7	74
2399.55	74
2401.4	88
2403.25	84
2405.09	74
2406.94	88
2408.79	74
2410.63	68
2412.48	74
2414.33	86
2416.17	82
2418.02	72
2419.86	80
2421.7	82
2423.55	78
2425.39	78
2427.23	74
2429.07	80
2430.91	60
2432.75	86
2434.59	78
2436.43	78
2438.27	76
2440.11	74
2441.95	72
2443.78	66
2445.62	76
2447.46	78
2449.29	76
2451.13	84
2452.96	80
2454.79	72
2456.63	82
2458.46	80
2460.29	84
2462.12	72
2463.95	74
2465.78	72
2467.61	66
2469.44	70
2471.27	78
2473.1	78
2474.93	72
2476.76	74
2478.58	74
2480.41	66
2482.23	72
2484.06	72
2485.88	68
2487.71	64
2489.53	68
2491.35	78
2493.18	78
2495	66
2496.82	72
2498.64	66
2500.46	78
2502.28	70
2504.1	74
2505.92	64
2507.74	58
2509.55	70
2511.37	68
2513.19	76
2515	80
2516.82	62
2518.63	66
2520.45	76
2522.26	72
2524.07	68
2525.89	60
2527.7	62
2529.51	62
2531.32	70
2533.13	80
2534.94	68
2536.75	70
2538.56	62
2540.37	68
2542.18	64
2543.98	66
2545.79	58
2547.6	64
2549.4	60
2551.21	64
2553.01	68
2554.82	72
2556.62	76
2558.42	62
2560.23	68
2562.03	60
2563.83	62
2565.63	64
2567.43	70
2569.23	72
2571.03	54
2572.83	76
2574.63	64
2576.43	54
2578.22	54
2580.02	74
2581.82	62
2583.61	64
2585.41	58
2587.2	58
2589	60
2590.79	66
2592.58	60
2594.38	66
2596.17	66
2597.96	66
2599.75	70
2601.54	72
2603.33	66
2605.12	58
2606.91	50
2608.7	68
2610.49	64
2612.27	64
2614.06	64
2615.85	64
2617.63	60
2619.42	64
2621.2	50
2622.99	52
2624.77	58
2626.55	58
2628.34	54
2630.12	58
2631.9	58
2633.68	48
2635.46	66
2637.24	52
2639.02	66
2640.8	54
2642.58	46
2644.36	60
2646.14	58
2647.91	58
2649.69	66
2651.46	52
2653.24	58
2655.01	60
2656.79	58
2658.56	52
2660.34	56
2662.11	62
2663.88	64
2665.65	60
2667.42	58
2669.2	62
2670.96	48
2672.73	54
2674.5	64
2676.27	54
2678.04	54
2679.81	60
2681.58	56
2683.34	64
2685.11	56
2686.87	54
2688.64	68
2690.4	62
2692.17	52
2693.93	54
2695.69	48
2697.46	54
2699.22	52
2700.98	58
2702.74	50
2704.5	46
2706.26	50
2708.02	66
2709.78	48
2711.54	56
2713.3	50
2715.05	52
2716.81	50
2718.57	58
2720.32	60
2722.08	54
2723.83	52
2725.59	52
2727.34	46
2729.09	46
2730.85	52
2732.6	54
2734.35	56
2736.1	56
2737.85	46
2739.6	38
2741.35	44
2743.1	48
2744.85	50
2746.6	46
2748.35	48
2750.09	38
2751.84	54
2753.59	50
2755.33	56
2757.08	48
2758.82	50
2760.57	52
2762.31	46
2764.05	50
2765.79	54
2767.54	58
2769.28	58
2771.02	56
2772.76	48
2774.5	44
2776.24	54
2777.98	56
2779.72	54
2781.46	36
2783.19	60
2784.93	52
2786.67	46
2788.4	42
2790.14	48
2791.87	42
2793.61	46
2795.34	44
2797.07	52
2798.81	48
2800.54	44
2802.27	52
2804	48
2805.74	60
2807.47	42
2809.2	42
2810.93	48
2812.65	38
2814.38	38
2816.11	40
2817.84	48
2819.56	50
2821.29	52
2823.02	48
2824.74	50
2826.47	52
2828.19	48
2829.92	50
2831.64	44
2833.36	38
2835.09	40
2836.81	48
2838.53	40
2840.25	38
2841.97	48
2843.69	36
2845.41	44
2847.13	50
2848.85	38
2850.57	40
2852.28	52
2854	42
2855.72	46
2857.43	48
2859.15	40
2860.86	42
2862.58	38
2864.29	48
2866.01	36
2867.72	42
2869.43	46
2871.14	48
2872.86	42
2874.57	56
2876.28	38
2877.99	44
2879.7	46
2881.41	44
2883.11	42
2884.82	44
2886.53	38
2888.24	34
2889.94	40
2891.65	48
2893.36	40
2895.06	38
2896.77	48
2898.47	48
2900.17	34
2901.88	54
2903.58	54
2905.28	44
2906.98	36
2908.69	44
2910.39	44
2912.09	46
2913.79	34
2915.49	40
2917.19	32
2918.88	34
2920.58	42
2922.28	40
2923.98	42
2925.67	36
2927.37	36
2929.06	46
2930.76	42
2932.45	38
2934.15	40
2935.84	34
2937.53	42
2939.23	46
2940.92	40
2942.61	46
2944.3	42
2945.99	42
2947.68	38
2949.37	42
2951.06	36
2952.75	46
2954.44	40
2956.12	40
2957.81	36
2959.5	48
2961.18	32
2962.87	44
2964.56	44
2966.24	34
2967.92	40
2969.61	40
2971.29	30
2972.97	40
2974.66	38
2976.34	40
2978.02	40
2979.7	28
2981.38	40
2983.06	44
2984.74	36
2986.42	38
2988.1	34
2989.78	40
2991.45	42
2993.13	42
2994.81	38
2996.48	38
2998.16	42
2999.83	36