File: muestras/nopal/inside_prf_21.txt
#Acq. time (s)=	10
#Accumulations=	1
#Range (cm-¹)=	200...3000
#Windows=	3
#Autofocus=	Off
#AutoExposure=	Off
#Spike filter=	Off
#Delay time (s)=	0
#Binning=	1
#Readout mode=	Signal
#DeNoise=	Off
#ICS correction=	Off
#Dark correction=	Off
#Inst. Process=	Off
#Instrument=	LabRAM HR Evol
#Detector=	Syncerity OE
#Objective=	x100_VIS
#Grating=	600 (500nm)
#ND Filter=	0.01%
#Laser=	633nm_Edge
#Hole=	30.0125
#Range=	Visible
#Project=	Omar
#Sample=	03-07-23
#Site=	nop
#Title=	inside_prf
#Remark=
#Date=	03.07.2023 14:50
#Acquired=	03.07.2023 14:50:16
201.713	36
204.247	38
206.778	36
209.311	30
211.84	38
214.371	32
216.899	28
219.428	36
221.955	34
224.482	32
227.007	40
229.531	42
232.055	42
234.579	34
237.1	28
239.621	36
242.141	36
244.661	34
247.179	30
249.698	38
252.215	40
254.731	38
257.246	40
259.761	36
262.273	34
264.786	38
267.298	44
269.809	36
272.319	36
274.828	32
277.336	38
279.844	42
282.351	34
284.855	32
287.361	38
289.866	30
292.368	38
294.871	34
297.372	36
299.873	36
302.372	36
304.872	38
307.37	44
309.866	36
312.364	46
314.859	44
317.353	40
319.848	34
322.341	46
324.833	36
327.324	38
329.814	44
332.304	50
334.792	42
337.28	42
339.767	40
342.254	48
344.739	38
347.224	48
349.708	42
352.191	48
354.673	40
357.155	48
359.634	44
362.114	46
364.593	42
367.07	50
369.548	38
372.024	46
374.499	34
376.974	50
379.447	48
381.92	46
384.392	46
386.864	50
389.333	46
391.802	42
394.272	50
396.739	54
399.206	56
401.673	50
404.138	54
406.602	46
409.066	48
411.528	58
413.99	56
416.451	54
418.911	48
421.371	50
423.83	48
426.288	54
428.745	52
431.201	54
433.657	60
436.111	66
438.565	54
441.017	50
443.469	46
445.921	56
448.37	54
450.821	68
453.27	60
455.717	56
458.165	62
460.61	50
463.056	66
465.5	58
467.945	72
470.387	58
472.829	50
475.271	58
477.711	66
480.15	60
482.589	54
485.027	56
487.465	66
489.901	64
492.337	60
494.771	62
497.205	78
499.638	68
502.07	64
504.502	62
506.933	68
509.363	70
511.792	68
514.219	56
516.647	64
519.073	64
521.5	72
523.924	64
526.348	68
528.772	70
531.194	80
533.616	78
536.036	68
538.457	74
540.875	72
543.294	68
545.712	70
548.128	60
550.545	68
552.959	72
555.373	76
557.788	72
560.2	76
562.612	84
565.023	78
567.433	80
569.843	82
572.251	80
574.659	88
577.066	80
579.472	70
581.878	80
584.283	72
586.687	68
589.09	82
591.493	80
593.893	80
596.294	86
598.694	76
601.093	94
603.491	82
605.889	82
608.285	96
610.682	90
613.076	86
615.471	94
617.864	90
620.256	92
622.648	92
625.039	92
627.429	90
629.819	96
632.208	92
634.595	104
636.982	102
639.369	104
641.755	92
644.139	100
646.523	102
648.906	104
651.288	102
653.67	106
656.051	102
658.429	100
660.808	96
663.187	110
665.565	104
667.942	108
670.317	108
672.692	106
675.067	106
677.44	102
679.813	110
682.184	116
684.556	124
686.926	128
689.296	116
691.664	112
694.033	130
696.4	128
698.766	132
701.133	132
703.497	138
705.861	120
708.224	134
710.586	138
712.949	140
715.31	154
717.67	128
720.029	128
722.388	138
724.746	144
727.103	140
729.458	140
731.814	156
734.168	150
736.523	150
738.876	152
741.227	144
743.579	146
745.931	150
748.28	158
750.629	164
752.977	170
755.325	160
757.672	172
760.018	168
762.363	172
764.708	164
767.052	176
769.394	182
771.737	160
774.078	180
776.419	188
778.758	176
781.097	166
783.435	180
785.773	190
788.11	196
790.446	194
792.781	198
795.115	198
797.449	186
799.782	220
802.115	208
804.446	194
806.777	206
809.106	214
811.435	204
813.764	202
816.091	216
818.418	212
820.743	238
823.069	236
825.393	244
827.717	222
830.039	224
832.362	224
834.683	250
837.003	224
839.324	254
841.643	248
843.961	258
846.278	264
848.594	246
850.91	240
853.227	282
855.541	260
857.855	276
860.168	266
862.48	264
864.79	274
867.101	290
869.411	268
871.721	294
874.029	306
876.336	294
878.643	268
880.95	296
883.254	316
885.559	306
887.862	328
890.166	300
892.467	308
894.77	322
897.07	316
899.371	332
901.669	320
903.968	340
906.266	326
908.563	308
910.859	332
913.154	362
915.449	338
917.742	330
920.036	352
922.329	384
924.621	362
926.911	350
929.201	366
931.49	384
933.779	366
936.068	364
938.355	384
940.64	370
942.926	416
945.212	394
947.495	406
949.779	418
952.062	420
954.344	414
956.625	402
958.905	432
961.184	424
963.464	458
965.742	462
968.02	452
970.296	442
972.572	490
974.847	434
977.121	492
979.396	460
981.669	510
983.941	476
986.212	478
988.483	504
990.753	504
993.022	504
995.29	510
997.558	522
999.825	496
1002.09	536
1004.36	508
1006.62	548
1008.89	558
1011.15	552
1013.41	538
1015.67	568
1017.93	552
1020.19	554
1022.45	566
1024.71	602
1026.97	580
1029.23	584
1031.49	578
1033.74	610
1036	616
1038.25	606
1040.5	580
1042.76	636
1045.01	618
1047.26	624
1049.51	636
1051.76	648
1054.01	672
1056.26	682
1058.51	696
1060.75	686
1063	676
1065.25	680
1067.49	714
1069.73	708
1071.98	702
1074.22	704
1076.46	728
1078.7	702
1080.94	674
1083.18	736
1085.42	736
1087.66	738
1089.9	748
1092.14	728
1094.37	762
1096.61	736
1098.84	778
1101.08	776
1103.31	794
1105.54	754
1107.77	792
1110	794
1112.23	794
1114.46	794
1116.69	814
1118.92	838
1121.15	842
1123.37	826
1125.6	828
1127.83	828
1130.05	870
1132.27	868
1134.5	840
1136.72	874
1138.94	824
1141.16	840
1143.38	878
1145.6	846
1147.82	894
1150.04	888
1152.26	852
1154.47	902
1156.69	916
1158.9	922
1161.12	912
1163.33	924
1165.54	908
1167.76	900
1169.97	934
1172.18	944
1174.39	932
1176.6	910
1178.81	912
1181.02	946
1183.22	944
1185.43	934
1187.63	952
1189.84	920
1192.04	918
1194.25	934
1196.45	950
1198.65	940
1200.85	930
1203.05	920
1205.25	978
1207.45	944
1209.65	916
1211.85	942
1214.05	918
1216.24	922
1218.44	882
1220.64	942
1222.83	914
1225.02	912
1227.22	914
1229.41	912
1231.6	880
1233.79	918
1235.98	902
1238.17	894
1240.36	874
1242.55	912
1244.73	858
1246.92	880
1249.11	890
1251.29	874
1253.48	882
1255.66	856
1257.84	862
1260.03	860
1262.21	882
1264.39	866
1266.57	860
1268.75	840
1270.93	880
1273.11	854
1275.28	882
1277.46	818
1279.64	860
1281.81	840
1283.98	809.42
1286.16	838.265
1288.33	814.127
1290.5	805.201
1292.68	787.832
1294.85	781.514
1297.02	769.86
1299.19	751.172
1301.36	776.166
1303.53	737.388
1305.69	753.06
1307.86	732.592
1310.03	726.656
1312.19	706.127
1314.36	722.798
1316.52	724.486
1318.68	693.533
1320.85	707.911
1323.01	684.627
1325.17	675.594
1327.33	669.019
1329.49	664.988
1331.65	647.867
1333.81	642.036
1335.97	643.331
1338.12	630.047
1340.28	604.406
1342.44	635.239
1344.59	604.703
1346.75	593.193
1348.9	593.435
1351.05	599.652
1353.2	579.039
1355.36	578.995
1357.51	594.488
1359.66	554.409
1361.81	580.646
1363.96	551.464
1366.1	535.042
1368.25	518.314
1370.4	539.546
1372.54	506.608
1374.69	521.703
1376.83	507.027
1378.98	492.651
1381.12	498.259
1383.26	492.54
1385.41	496.771
1387.55	508.513
1389.69	482.338
1391.83	465.696
1393.02	476
1395.17	458
1397.32	462
1399.47	470
1401.62	444
1403.77	446
1405.91	430
1408.06	446
1410.2	466
1412.35	440
1414.49	456
1416.63	420
1418.78	430
1420.92	420
1423.06	432
1425.2	434
1427.34	400
1429.48	420
1431.61	432
1433.75	416
1435.89	418
1438.02	390
1440.16	426
1442.3	414
1444.43	394
1446.56	422
1448.7	410
1450.83	392
1452.96	408
1455.09	388
1457.22	394
1459.35	386
1461.48	426
1463.61	386
1465.73	382
1467.86	370
1469.98	364
1472.11	378
1474.24	374
1476.36	374
1478.48	386
1480.6	356
1482.73	382
1484.85	360
1486.97	336
1489.09	350
1491.21	366
1493.33	346
1495.44	356
1497.56	346
1499.68	354
1501.79	386
1503.91	374
1506.02	330
1508.14	360
1510.25	336
1512.36	340
1514.48	344
1516.59	344
1518.7	342
1520.81	330
1522.92	346
1525.02	336
1527.13	336
1529.24	346
1531.35	338
1533.45	332
1535.56	330
1537.66	316
1539.77	328
1541.87	320
1543.97	320
1546.08	316
1548.18	318
1550.28	312
1552.38	308
1554.48	296
1556.57	294
1558.67	328
1560.77	308
1562.87	294
1564.96	314
1567.06	302
1569.15	292
1571.25	302
1573.34	304
1575.43	318
1577.53	292
1579.62	294
1581.71	310
1583.8	304
1585.89	288
1587.98	304
1590.06	296
1592.15	308
1594.24	274
1596.33	310
1598.41	308
1600.5	292
1602.58	288
1604.66	272
1606.75	292
1608.83	282
1610.91	290
1612.99	304
1615.07	288
1617.15	278
1619.23	308
1621.31	292
1623.39	296
1625.46	276
1627.54	298
1629.62	296
1631.69	298
1633.77	300
1635.84	274
1637.91	276
1639.99	282
1642.06	298
1644.13	274
1646.2	282
1648.27	294
1650.34	276
1652.41	280
1654.47	278
1656.54	262
1658.61	278
1660.67	272
1662.74	286
1664.81	272
1666.87	270
1668.93	268
1671	272
1673.06	264
1675.12	266
1677.18	284
1679.24	260
1681.3	272
1683.36	278
1685.42	260
1687.47	260
1689.53	284
1691.59	274
1693.64	268
1695.7	272
1697.75	266
1699.81	256
1701.86	240
1703.91	244
1705.97	272
1708.02	264
1710.07	240
1712.12	250
1714.17	262
1716.22	264
1718.26	258
1720.31	270
1722.36	228
1724.4	250
1726.45	254
1728.49	272
1730.54	250
1732.58	250
1734.63	258
1736.67	242
1738.71	262
1740.75	252
1742.79	266
1744.83	266
1746.87	246
1748.91	262
1750.95	242
1752.98	252
1755.02	262
1757.06	252
1759.09	260
1761.13	260
1763.16	242
1765.19	256
1767.23	260
1769.26	232
1771.29	262
1773.32	258
1775.35	244
1777.38	250
1779.41	258
1781.44	268
1783.47	262
1785.49	248
1787.52	242
1789.55	258
1791.57	250
1793.6	256
1795.62	264
1797.64	260
1799.67	254
1801.69	262
1803.71	268
1805.73	242
1807.75	270
1809.77	254
1811.79	240
1813.81	252
1815.83	236
1817.84	246
1819.86	238
1821.88	256
1823.89	248
1825.91	252
1827.92	226
1829.93	236
1831.95	240
1833.96	246
1835.97	254
1837.98	254
1839.99	266
1842	266
1844.01	242
1846.02	240
1848.03	252
1850.03	242
1852.04	248
1854.05	260
1856.05	238
1858.06	248
1860.06	254
1862.06	248
1864.07	262
1866.07	244
1868.07	250
1870.07	268
1872.07	274
1874.07	256
1876.07	252
1878.07	248
1880.07	236
1882.07	266
1884.06	244
1886.06	268
1888.05	240
1890.05	236
1892.04	248
1894.04	266
1896.03	244
1898.02	268
1900.01	266
1902	250
1903.99	250
1905.98	244
1907.97	248
1909.96	238
1911.95	264
1913.94	232
1915.93	236
1917.91	234
1919.9	246
1921.88	248
1923.87	250
1925.85	242
1927.83	226
1929.82	242
1931.8	248
1933.78	262
1935.76	270
1937.74	260
1939.72	238
1941.7	238
1943.68	268
1945.65	232
1947.63	222
1949.61	218
1951.58	260
1953.56	252
1955.53	228
1957.51	242
1959.48	240
1961.45	250
1963.43	230
1965.4	240
1967.37	242
1969.34	246
1971.31	252
1973.28	240
1975.25	252
1977.22	228
1979.18	262
1981.15	246
1983.12	242
1985.08	240
1987.05	236
1989.01	248
1990.97	246
1992.94	234
1994.9	246
1996.86	230
1998.82	254
2000.78	244
2002.74	238
2004.7	254
2006.66	234
2008.62	242
2010.58	240
2012.54	248
2014.49	260
2016.45	228
2018.4	230
2020.36	246
2022.31	246
2024.27	238
2026.22	262
2028.17	245
2030.12	256
2032.07	240
2034.03	246
2035.98	238
2037.93	224
2039.87	258
2041.82	260
2043.77	242
2045.72	248
2047.66	228
2049.61	254
2051.55	258
2053.5	240
2055.44	248
2057.39	238
2059.33	230
2061.27	242
2063.21	242
2065.15	244
2067.09	226
2069.03	248
2070.97	218
2072.91	230
2074.85	260
2076.79	234
2078.73	236
2080.66	254
2082.6	234
2084.53	230
2086.47	246
2088.4	238
2090.33	240
2092.27	236
2094.2	248
2096.13	232
2098.06	244
2099.99	228
2101.92	232
2103.85	230
2105.78	224
2107.71	236
2109.64	230
2111.56	226
2113.49	234
2115.41	236
2117.34	238
2119.26	246
2121.19	234
2123.11	240
2125.03	244
2126.96	256
2128.88	232
2130.8	242
2132.72	252
2134.64	212
2136.56	224
2138.48	228
2140.4	234
2142.31	244
2144.23	242
2146.15	252
2148.06	232
2149.98	234
2151.89	226
2153.81	236
2155.72	238
2157.63	228
2159.55	238
2161.46	232
2163.37	230
2165.28	234
2167.19	216
2169.1	238
2171.01	232
2172.91	236
2174.82	232
2176.73	218
2178.64	230
2180.54	244
2182.45	240
2184.35	238
2186.26	224
2188.16	230
2190.06	206
2191.96	228
2193.87	234
2195.77	224
2197.67	232
2199.57	220
2201.47	228
2203.37	232
2205.27	232
2207.16	238
2209.06	232
2210.96	228
2212.85	244
2214.75	224
2216.64	232
2218.54	216
2220.43	238
2222.33	222
2224.22	219.113
2226.11	226.183
2228	228.194
2229.89	229.787
2231.78	229.918
2233.67	233.724
2235.56	224.837
2237.45	223.021
2239.34	214.5
2241.23	207.154
2243.11	231.81
2245	207.76
2246.89	214.34
2248.77	215.769
2250.66	212.195
2252.54	203.855
2254.42	195.658
2256.31	208.83
2258.19	207.725
2260.07	209.072
2261.95	208.773
2263.83	201.07
2265.71	204.755
2267.59	200.412
2269.47	194.423
2271.35	204.206
2273.23	203.87
2275.1	181.466
2276.98	190.431
2278.86	191.711
2280.73	196.966
2282.61	191.958
2284.48	185.967
2286.36	197.625
2288.23	189.25
2290.1	189.563
2291.98	182.135
2293.85	189.472
2295.72	174.205
2297.59	176.056
2299.46	177.496
2301.33	179.064
2303.2	176.56
2305.06	172.142
2306.93	178.854
2308.8	177.151
2310.67	168.019
2312.53	176.49
2314.4	159.617
2316.26	173.019
2317.62	168
2319.5	166
2321.37	170
2323.24	174
2325.12	176
2326.99	152
2328.86	158
2330.73	168
2332.6	152
2334.47	156
2336.34	162
2338.2	160
2340.07	170
2341.94	156
2343.81	160
2345.67	170
2347.54	170
2349.4	164
2351.27	154
2353.13	168
2354.99	162
2356.86	182
2358.72	158
2360.58	164
2362.44	158
2364.3	172
2366.16	160
2368.02	138
2369.88	160
2371.74	154
2373.6	160
2375.45	162
2377.31	144
2379.17	152
2381.02	146
2382.88	162
2384.73	158
2386.58	150
2388.44	164
2390.29	130
2392.14	162
2393.99	158
2395.85	142
2397.7	164
2399.55	160
2401.4	152
2403.25	148
2405.09	152
2406.94	164
2408.79	152
2410.63	166
2412.48	160
2414.33	144
2416.17	162
2418.02	150
2419.86	146
2421.7	140
2423.55	148
2425.39	144
2427.23	156
2429.07	150
2430.91	146
2432.75	150
2434.59	146
2436.43	142
2438.27	136
2440.11	144
2441.95	136
2443.78	148
2445.62	152
2447.46	140
2449.29	146
2451.13	146
2452.96	142
2454.79	142
2456.63	150
2458.46	140
2460.29	142
2462.12	148
2463.95	146
2465.78	150
2467.61	152
2469.44	138
2471.27	150
2473.1	140
2474.93	136
2476.76	130
2478.58	124
2480.41	114
2482.23	134
2484.06	142
2485.88	142
2487.71	144
2489.53	128
2491.35	128
2493.18	136
2495	146
2496.82	124
2498.64	130
2500.46	130
2502.28	136
2504.1	112
2505.92	138
2507.74	128
2509.55	130
2511.37	148
2513.19	130
2515	138
2516.82	124
2518.63	128
2520.45	136
2522.26	140
2524.07	144
2525.89	114
2527.7	140
2529.51	124
2531.32	120
2533.13	126
2534.94	120
2536.75	124
2538.56	130
2540.37	136
2542.18	136
2543.98	124
2545.79	130
2547.6	120
2549.4	136
2551.21	114
2553.01	126
2554.82	112
2556.62	114
2558.42	120
2560.23	112
2562.03	124
2563.83	124
2565.63	114
2567.43	122
2569.23	104
2571.03	106
2572.83	124
2574.63	114
2576.43	114
2578.22	102
2580.02	120
2581.82	116
2583.61	114
2585.41	126
2587.2	116
2589	112
2590.79	126
2592.58	110
2594.38	114
2596.17	124
2597.96	112
2599.75	104
2601.54	126
2603.33	110
2605.12	124
2606.91	110
2608.7	122
2610.49	106
2612.27	102
2614.06	104
2615.85	108
2617.63	120
2619.42	112
2621.2	108
2622.99	102
2624.77	108
2626.55	106
2628.34	110
2630.12	90
2631.9	108
2633.68	98
2635.46	104
2637.24	104
2639.02	104
2640.8	100
2642.58	104
2644.36	104
2646.14	92
2647.91	94
2649.69	114
2651.46	104
2653.24	108
2655.01	108
2656.79	96
2658.56	106
2660.34	96
2662.11	86
2663.88	110
2665.65	96
2667.42	86
2669.2	110
2670.96	102
2672.73	96
2674.5	94
2676.27	94
2678.04	94
2679.81	106
2681.58	90
2683.34	104
2685.11	92
2686.87	102
2688.64	92
2690.4	100
2692.17	96
2693.93	102
2695.69	90
2697.46	92
2699.22	86
2700.98	86
2702.74	96
2704.5	86
2706.26	98
2708.02	96
2709.78	102
2711.54	88
2713.3	104
2715.05	100
2716.81	92
2718.57	96
2720.32	94
2722.08	96
2723.83	100
2725.59	90
2727.34	88
2729.09	84
2730.85	88
2732.6	84
2734.35	86
2736.1	84
2737.85	72
2739.6	84
2741.35	94
2743.1	86
2744.85	90
2746.6	96
2748.35	90
2750.09	94
2751.84	88
2753.59	78
2755.33	86
2757.08	94
2758.82	84
2760.57	88
2762.31	88
2764.05	82
2765.79	80
2767.54	84
2769.28	78
2771.02	78
2772.76	82
2774.5	80
2776.24	86
2777.98	82
2779.72	88
2781.46	72
2783.19	72
2784.93	68
2786.67	86
2788.4	78
2790.14	84
2791.87	66
2793.61	82
2795.34	66
2797.07	76
2798.81	78
2800.54	70
2802.27	80
2804	72
2805.74	70
2807.47	74
2809.2	80
2810.93	68
2812.65	68
2814.38	80
2816.11	68
2817.84	76
2819.56	74
2821.29	70
2823.02	70
2824.74	70
2826.47	76
2828.19	76
2829.92	74
2831.64	76
2833.36	70
2835.09	64
2836.81	76
2838.53	70
2840.25	74
2841.97	70
2843.69	76
2845.41	80
2847.13	62
2848.85	72
2850.57	70
2852.28	74
2854	66
2855.72	60
2857.43	64
2859.15	66
2860.86	64
2862.58	68
2864.29	72
2866.01	66
2867.72	54
2869.43	66
2871.14	62
2872.86	66
2874.57	60
2876.28	58
2877.99	72
2879.7	64
2881.41	62
2883.11	60
2884.82	68
2886.53	64
2888.24	56
2889.94	58
2891.65	60
2893.36	58
2895.06	54
2896.77	56
2898.47	64
2900.17	56
2901.88	78
2903.58	52
2905.28	64
2906.98	58
2908.69	68
2910.39	52
2912.09	58
2913.79	66
2915.49	62
2917.19	54
2918.88	60
2920.58	56
2922.28	56
2923.98	50
2925.67	54
2927.37	58
2929.06	52
2930.76	56
2932.45	50
2934.15	60
2935.84	62
2937.53	56
2939.23	56
2940.92	56
2942.61	62
2944.3	54
2945.99	56
2947.68	54
2949.37	64
2951.06	58
2952.75	60
2954.44	52
2956.12	50
2957.81	58
2959.5	50
2961.18	48
2962.87	60
2964.56	58
2966.24	54
2967.92	52
2969.61	52
2971.29	52
2972.97	56
2974.66	52
2976.34	56
2978.02	56
2979.7	50
2981.38	56
2983.06	52
2984.74	54
2986.42	62
2988.1	54
2989.78	54
2991.45	48
2993.13	64
2994.81	52
2996.48	50
2998.16	48
2999.83	60