File: muestras/nopal/inside_prf_16.txt
#Acq. time (s)=	10
#Accumulations=	1
#Range (cm-¹)=	200...3000
#Windows=	3
#Autofocus=	Off
#AutoExposure=	Off
#Spike filter=	Off
#Delay time (s)=	0
#Binning=	1
#Readout mode=	Signal
#DeNoise=	Off
#ICS correction=	Off
#Dark correction=	Off
#Inst. Process=	Off
#Instrument=	LabRAM HR Evol
#Detector=	Syncerity OE
#Objective=	x100_VIS
#Grating=	600 (500nm)
#ND Filter=	0.01%
#Laser=	633nm_Edge
#Hole=	30.0125
#Range=	Visible
#Project=	Omar
#Sample=	03-07-23
#Site=	nop
#Title=	inside_prf
#Remark=
#Date=	03.07.2023 14:45
#Acquired=	03.07.2023 14:45:14
201.713	24
204.247	40
206.778	38
209.311	30
211.84	32
214.371	30
216.899	32
219.428	44
221.955	32
224.482	26
227.007	32
229.531	36
232.055	34
234.579	38
237.1	26
239.621	34
242.141	40
244.661	38
247.179	32
249.698	28
252.215	28
254.731	30
257.246	34
259.761	34
262.273	32
264.786	28
267.298	36
269.809	34
272.319	40
274.828	30
277.336	34
279.844	36
282.351	38
284.855	36
287.361	42
289.866	42
292.368	32
294.871	34
297.372	38
299.873	40
302.372	38
304.872	38
307.37	40
309.866	36
312.364	38
314.859	34
317.353	48
319.848	42
322.341	34
324.833	42
327.324	36
329.814	40
332.304	42
334.792	34
337.28	40
339.767	48
342.254	46
344.739	34
347.224	42
349.708	50
352.191	42
354.673	50
357.155	38
359.634	44
362.114	38
364.593	42
367.07	40
369.548	32
372.024	48
374.499	44
376.974	44
379.447	48
381.92	42
384.392	48
386.864	38
389.333	42
391.802	50
394.272	44
396.739	48
399.206	44
401.673	42
404.138	52
406.602	50
409.066	40
411.528	52
413.99	52
416.451	54
418.911	44
421.371	52
423.83	50
426.288	46
428.745	46
431.201	48
433.657	44
436.111	42
438.565	44
441.017	54
443.469	52
445.921	46
448.37	50
450.821	50
453.27	50
455.717	50
458.165	50
460.61	48
463.056	56
465.5	54
467.945	52
470.387	54
472.829	48
475.271	54
477.711	58
480.15	52
482.589	50
485.027	46
487.465	44
489.901	52
492.337	60
494.771	60
497.205	58
499.638	54
502.07	44
504.502	54
506.933	50
509.363	60
511.792	60
514.219	58
516.647	52
519.073	58
521.5	58
523.924	44
526.348	56
528.772	56
531.194	50
533.616	66
536.036	62
538.457	60
540.875	48
543.294	64
545.712	58
548.128	60
550.545	64
552.959	64
555.373	64
557.788	70
560.2	64
562.612	54
565.023	66
567.433	56
569.843	60
572.251	68
574.659	66
577.066	62
579.472	72
581.878	60
584.283	62
586.687	62
589.09	78
591.493	66
593.893	64
596.294	64
598.694	74
601.093	62
603.491	64
605.889	64
608.285	70
610.682	70
613.076	74
615.471	74
617.864	78
620.256	78
622.648	84
625.039	68
627.429	80
629.819	88
632.208	72
634.595	80
636.982	86
639.369	88
641.755	82
644.139	88
646.523	88
648.906	84
651.288	90
653.67	88
656.051	90
658.429	92
660.808	92
663.187	98
665.565	86
667.942	92
670.317	92
672.692	90
675.067	108
677.44	84
679.813	96
682.184	92
684.556	96
686.926	90
689.296	104
691.664	96
694.033	102
696.4	102
698.766	102
701.133	106
703.497	104
705.861	108
708.224	116
710.586	110
712.949	116
715.31	114
717.67	104
720.029	108
722.388	118
724.746	104
727.103	106
729.458	116
731.814	118
734.168	122
736.523	124
738.876	116
741.227	112
743.579	136
745.931	132
748.28	136
750.629	112
752.977	132
755.325	132
757.672	134
760.018	144
762.363	128
764.708	148
767.052	142
769.394	140
771.737	150
774.078	150
776.419	140
778.758	162
781.097	146
783.435	138
785.773	164
788.11	148
790.446	152
792.781	164
795.115	160
797.449	168
799.782	162
802.115	176
804.446	180
806.777	192
809.106	182
811.435	180
813.764	172
816.091	186
818.418	186
820.743	200
823.069	180
825.393	180
827.717	186
830.039	192
832.362	192
834.683	210
837.003	204
839.324	212
841.643	200
843.961	214
846.278	206
848.594	212
850.91	216
853.227	212
855.541	224
857.855	226
860.168	218
862.48	212
864.79	230
867.101	262
869.411	234
871.721	248
874.029	240
876.336	256
878.643	258
880.95	278
883.254	242
885.559	256
887.862	272
890.166	280
892.467	266
894.77	268
897.07	262
899.371	274
901.669	292
903.968	274
906.266	282
908.563	282
910.859	272
913.154	286
915.449	286
917.742	284
920.036	284
922.329	296
924.621	320
926.911	316
929.201	314
931.49	322
933.779	316
936.068	336
938.355	338
940.64	326
942.926	306
945.212	354
947.495	358
949.779	354
952.062	360
954.344	396
956.625	370
958.905	352
961.184	354
963.464	360
965.742	372
968.02	412
970.296	406
972.572	394
974.847	386
977.121	398
979.396	412
981.669	402
983.941	410
986.212	398
988.483	440
990.753	424
993.022	442
995.29	402
997.558	440
999.825	428
1002.09	442
1004.36	436
1006.62	450
1008.89	438
1011.15	462
1013.41	460
1015.67	482
1017.93	534
1020.19	490
1022.45	504
1024.71	508
1026.97	510
1029.23	534
1031.49	502
1033.74	516
1036	554
1038.25	554
1040.5	550
1042.76	546
1045.01	544
1047.26	566
1049.51	560
1051.76	584
1054.01	592
1056.26	592
1058.51	578
1060.75	584
1063	566
1065.25	604
1067.49	598
1069.73	656
1071.98	600
1074.22	612
1076.46	634
1078.7	628
1080.94	638
1083.18	656
1085.42	636
1087.66	660
1089.9	678
1092.14	686
1094.37	668
1096.61	650
1098.84	658
1101.08	672
1103.31	680
1105.54	694
1107.77	672
1110	684
1112.23	690
1114.46	708
1116.69	682
1118.92	706
1121.15	706
1123.37	696
1125.6	716
1127.83	718
1130.05	752
1132.27	720
1134.5	746
1136.72	704
1138.94	748
1141.16	758
1143.38	780
1145.6	756
1147.82	742
1150.04	746
1152.26	782
1154.47	778
1156.69	776
1158.9	804
1161.12	746
1163.33	782
1165.54	758
1167.76	770
1169.97	774
1172.18	782
1174.39	780
1176.6	762
1178.81	776
1181.02	806
1183.22	804
1185.43	766
1187.63	796
1189.84	776
1192.04	776
1194.25	772
1196.45	768
1198.65	778
1200.85	776
1203.05	744
1205.25	734
1207.45	760
1209.65	738
1211.85	720
1214.05	726
1216.24	756
1218.44	730
1220.64	740
1222.83	738
1225.02	706
1227.22	722
1229.41	730
1231.6	756
1233.79	706
1235.98	746
1238.17	704
1240.36	692
1242.55	720
1244.73	700
1246.92	710
1249.11	682
1251.29	682
1253.48	688
1255.66	692
1257.84	672
1260.03	690
1262.21	666
1264.39	678
1266.57	664
1268.75	666
1270.93	642
1273.11	646
1275.28	650
1277.46	662
1279.64	608
1281.81	636
1283.98	590.483
1286.16	619.591
1288.33	612.502
1290.5	650.029
1292.68	599.881
1294.85	593.206
1297.02	594.094
1299.19	603.449
1301.36	590.475
1303.53	601.831
1305.69	571.816
1307.86	585.348
1310.03	569.11
1312.19	560.8
1314.36	574.029
1316.52	547.113
1318.68	528.692
1320.85	567.614
1323.01	534.324
1325.17	541.746
1327.33	549.376
1329.49	539.445
1331.65	535.115
1333.81	527.854
1335.97	528.27
1338.12	525.066
1340.28	515.536
1342.44	512.882
1344.59	509.561
1346.75	516.918
1348.9	506.533
1351.05	485.863
1353.2	486.736
1355.36	470.348
1357.51	480.479
1359.66	475.895
1361.81	480.195
1363.96	460.164
1366.1	468.542
1368.25	465.113
1370.4	458.89
1372.54	461.246
1374.69	466.038
1376.83	463.203
1378.98	470.344
1381.12	450.44
1383.26	447.467
1385.41	433.918
1387.55	429.32
1389.69	439.301
1391.83	412.4
1393.02	436
1395.17	418
1397.32	414
1399.47	444
1401.62	422
1403.77	400
1405.91	396
1408.06	404
1410.2	402
1412.35	410
1414.49	412
1416.63	406
1418.78	404
1420.92	380
1423.06	392
1425.2	366
1427.34	380
1429.48	384
1431.61	370
1433.75	356
1435.89	336
1438.02	396
1440.16	362
1442.3	348
1444.43	362
1446.56	368
1448.7	342
1450.83	364
1452.96	338
1455.09	320
1457.22	332
1459.35	328
1461.48	354
1463.61	346
1465.73	350
1467.86	370
1469.98	338
1472.11	326
1474.24	346
1476.36	332
1478.48	320
1480.6	324
1482.73	336
1484.85	308
1486.97	340
1489.09	320
1491.21	318
1493.33	308
1495.44	306
1497.56	320
1499.68	318
1501.79	288
1503.91	314
1506.02	304
1508.14	302
1510.25	294
1512.36	302
1514.48	302
1516.59	278
1518.7	290
1520.81	280
1522.92	288
1525.02	288
1527.13	290
1529.24	288
1531.35	274
1533.45	306
1535.56	288
1537.66	274
1539.77	268
1541.87	286
1543.97	268
1546.08	276
1548.18	274
1550.28	280
1552.38	268
1554.48	274
1556.57	264
1558.67	254
1560.77	258
1562.87	256
1564.96	248
1567.06	286
1569.15	262
1571.25	258
1573.34	250
1575.43	264
1577.53	248
1579.62	252
1581.71	258
1583.8	278
1585.89	270
1587.98	250
1590.06	256
1592.15	258
1594.24	246
1596.33	246
1598.41	234
1600.5	254
1602.58	280
1604.66	240
1606.75	244
1608.83	250
1610.91	230
1612.99	248
1615.07	240
1617.15	262
1619.23	232
1621.31	248
1623.39	246
1625.46	266
1627.54	232
1629.62	246
1631.69	242
1633.77	252
1635.84	238
1637.91	238
1639.99	250
1642.06	228
1644.13	248
1646.2	236
1648.27	240
1650.34	234
1652.41	236
1654.47	236
1656.54	230
1658.61	224
1660.67	230
1662.74	246
1664.81	224
1666.87	224
1668.93	230
1671	224
1673.06	232
1675.12	216
1677.18	244
1679.24	244
1681.3	220
1683.36	236
1685.42	226
1687.47	250
1689.53	232
1691.59	216
1693.64	216
1695.7	208
1697.75	230
1699.81	248
1701.86	220
1703.91	204
1705.97	220
1708.02	246
1710.07	216
1712.12	214
1714.17	214
1716.22	230
1718.26	228
1720.31	234
1722.36	226
1724.4	210
1726.45	218
1728.49	218
1730.54	214
1732.58	216
1734.63	200
1736.67	204
1738.71	222
1740.75	214
1742.79	238
1744.83	206
1746.87	210
1748.91	212
1750.95	226
1752.98	232
1755.02	224
1757.06	222
1759.09	228
1761.13	216
1763.16	216
1765.19	224
1767.23	228
1769.26	198
1771.29	216
1773.32	216
1775.35	210
1777.38	224
1779.41	216
1781.44	212
1783.47	208
1785.49	198
1787.52	206
1789.55	202
1791.57	212
1793.6	212
1795.62	230
1797.64	210
1799.67	236
1801.69	220
1803.71	200
1805.73	210
1807.75	220
1809.77	220
1811.79	214
1813.81	212
1815.83	214
1817.84	208
1819.86	206
1821.88	214
1823.89	200
1825.91	204
1827.92	212
1829.93	204
1831.95	214
1833.96	210
1835.97	214
1837.98	224
1839.99	206
1842	208
1844.01	210
1846.02	208
1848.03	204
1850.03	206
1852.04	218
1854.05	222
1856.05	206
1858.06	200
1860.06	206
1862.06	214
1864.07	204
1866.07	214
1868.07	210
1870.07	190
1872.07	202
1874.07	212
1876.07	200
1878.07	208
1880.07	206
1882.07	224
1884.06	204
1886.06	216
1888.05	216
1890.05	194
1892.04	212
1894.04	198
1896.03	204
1898.02	212
1900.01	214
1902	204
1903.99	210
1905.98	208
1907.97	204
1909.96	200
1911.95	208
1913.94	214
1915.93	206
1917.91	222
1919.9	204
1921.88	226
1923.87	192
1925.85	224
1927.83	202
1929.82	208
1931.8	204
1933.78	216
1935.76	212
1937.74	206
1939.72	208
1941.7	208
1943.68	202
1945.65	194
1947.63	196
1949.61	218
1951.58	204
1953.56	210
1955.53	200
1957.51	212
1959.48	200
1961.45	206
1963.43	194
1965.4	202
1967.37	204
1969.34	186
1971.31	190
1973.28	202
1975.25	204
1977.22	208
1979.18	190
1981.15	194
1983.12	184
1985.08	202
1987.05	202
1989.01	196
1990.97	212
1992.94	204
1994.9	208
1996.86	190
1998.82	198
2000.78	198
2002.74	202
2004.7	202
2006.66	200
2008.62	186
2010.58	204
2012.54	202
2014.49	206
2016.45	198
2018.4	204
2020.36	194
2022.31	202
2024.27	196
2026.22	196
2028.17	199
2030.12	198
2032.07	208
2034.03	216
2035.98	216
2037.93	194
2039.87	196
2041.82	204
2043.77	200
2045.72	200
2047.66	200
2049.61	178
2051.55	204
2053.5	190
2055.44	196
2057.39	216
2059.33	182
2061.27	204
2063.21	202
2065.15	194
2067.09	198
2069.03	200
2070.97	188
2072.91	204
2074.85	204
2076.79	188
2078.73	186
2080.66	204
2082.6	196
2084.53	208
2086.47	190
2088.4	178
2090.33	194
2092.27	196
2094.2	194
2096.13	194
2098.06	194
2099.99	202
2101.92	194
2103.85	202
2105.78	198
2107.71	186
2109.64	186
2111.56	200
2113.49	198
2115.41	202
2117.34	192
2119.26	180
2121.19	194
2123.11	192
2125.03	200
2126.96	206
2128.88	194
2130.8	196
2132.72	210
2134.64	190
2136.56	184
2138.48	180
2140.4	196
2142.31	198
2144.23	168
2146.15	208
2148.06	184
2149.98	182
2151.89	190
2153.81	190
2155.72	186
2157.63	198
2159.55	200
2161.46	198
2163.37	188
2165.28	192
2167.19	202
2169.1	190
2171.01	198
2172.91	198
2174.82	202
2176.73	178
2178.64	190
2180.54	198
2182.45	186
2184.35	188
2186.26	200
2188.16	208
2190.06	190
2191.96	188
2193.87	192
2195.77	190
2197.67	190
2199.57	178
2201.47	182
2203.37	182
2205.27	182
2207.16	202
2209.06	172
2210.96	190
2212.85	212
2214.75	194
2216.64	194
2218.54	184
2220.43	192
2222.33	200
2224.22	197.845
2226.11	185.148
2228	189.074
2229.89	198.247
2231.78	183.21
2233.67	188.232
2235.56	186.571
2237.45	195.257
2239.34	180.45
2241.23	173.011
2243.11	189.695
2245	181.612
2246.89	194.955
2248.77	184.069
2250.66	192.274
2252.54	183.588
2254.42	187.331
2256.31	184.395
2258.19	192.903
2260.07	199.47
2261.95	187.657
2263.83	201.54
2265.71	200.543
2267.59	204.624
2269.47	193.053
2271.35	192.762
2273.23	189.747
2275.1	195.824
2276.98	188.795
2278.86	196.969
2280.73	191.065
2282.61	195.123
2284.48	185.361
2286.36	197.065
2288.23	193.546
2290.1	200.433
2291.98	181.957
2293.85	192.245
2295.72	192.127
2297.59	193.646
2299.46	198.091
2301.33	190.392
2303.2	189.19
2305.06	199.181
2306.93	200.616
2308.8	192.07
2310.67	194.798
2312.53	193.585
2314.4	188.383
2316.26	197.894
2317.62	184
2319.5	200
2321.37	200
2323.24	208
2325.12	166
2326.99	176
2328.86	188
2330.73	202
2332.6	180
2334.47	188
2336.34	192
2338.2	182
2340.07	186
2341.94	182
2343.81	184
2345.67	176
2347.54	184
2349.4	206
2351.27	190
2353.13	196
2354.99	190
2356.86	186
2358.72	190
2360.58	182
2362.44	188
2364.3	172
2366.16	188
2368.02	184
2369.88	194
2371.74	176
2373.6	184
2375.45	176
2377.31	178
2379.17	172
2381.02	188
2382.88	180
2384.73	192
2386.58	194
2388.44	176
2390.29	172
2392.14	188
2393.99	196
2395.85	176
2397.7	174
2399.55	184
2401.4	180
2403.25	188
2405.09	172
2406.94	172
2408.79	170
2410.63	176
2412.48	168
2414.33	174
2416.17	178
2418.02	172
2419.86	194
2421.7	174
2423.55	186
2425.39	170
2427.23	168
2429.07	182
2430.91	160
2432.75	168
2434.59	174
2436.43	168
2438.27	182
2440.11	170
2441.95	162
2443.78	170
2445.62	162
2447.46	168
2449.29	168
2451.13	164
2452.96	162
2454.79	170
2456.63	158
2458.46	170
2460.29	160
2462.12	160
2463.95	166
2465.78	162
2467.61	176
2469.44	162
2471.27	160
2473.1	150
2474.93	154
2476.76	152
2478.58	152
2480.41	158
2482.23	154
2484.06	166
2485.88	158
2487.71	146
2489.53	144
2491.35	176
2493.18	160
2495	140
2496.82	152
2498.64	166
2500.46	158
2502.28	160
2504.1	158
2505.92	136
2507.74	154
2509.55	154
2511.37	146
2513.19	162
2515	160
2516.82	148
2518.63	152
2520.45	150
2522.26	142
2524.07	138
2525.89	140
2527.7	150
2529.51	146
2531.32	126
2533.13	154
2534.94	156
2536.75	140
2538.56	144
2540.37	132
2542.18	140
2543.98	142
2545.79	130
2547.6	146
2549.4	152
2551.21	128
2553.01	130
2554.82	136
2556.62	150
2558.42	140
2560.23	136
2562.03	142
2563.83	142
2565.63	134
2567.43	134
2569.23	128
2571.03	144
2572.83	132
2574.63	130
2576.43	122
2578.22	126
2580.02	124
2581.82	140
2583.61	150
2585.41	126
2587.2	140
2589	150
2590.79	126
2592.58	142
2594.38	136
2596.17	126
2597.96	130
2599.75	128
2601.54	128
2603.33	114
2605.12	126
2606.91	126
2608.7	126
2610.49	118
2612.27	116
2614.06	112
2615.85	126
2617.63	122
2619.42	124
2621.2	130
2622.99	130
2624.77	120
2626.55	122
2628.34	114
2630.12	138
2631.9	112
2633.68	118
2635.46	128
2637.24	122
2639.02	118
2640.8	126
2642.58	114
2644.36	112
2646.14	108
2647.91	112
2649.69	116
2651.46	130
2653.24	106
2655.01	116
2656.79	114
2658.56	120
2660.34	122
2662.11	110
2663.88	110
2665.65	112
2667.42	104
2669.2	124
2670.96	108
2672.73	108
2674.5	122
2676.27	112
2678.04	98
2679.81	120
2681.58	98
2683.34	100
2685.11	114
2686.87	116
2688.64	108
2690.4	94
2692.17	114
2693.93	132
2695.69	102
2697.46	110
2699.22	110
2700.98	106
2702.74	110
2704.5	94
2706.26	106
2708.02	102
2709.78	88
2711.54	106
2713.3	96
2715.05	112
2716.81	102
2718.57	102
2720.32	100
2722.08	104
2723.83	90
2725.59	94
2727.34	110
2729.09	94
2730.85	102
2732.6	96
2734.35	94
2736.1	98
2737.85	100
2739.6	98
2741.35	102
2743.1	94
2744.85	94
2746.6	96
2748.35	96
2750.09	94
2751.84	94
2753.59	96
2755.33	86
2757.08	88
2758.82	78
2760.57	98
2762.31	74
2764.05	90
2765.79	92
2767.54	86
2769.28	80
2771.02	80
2772.76	88
2774.5	92
2776.24	82
2777.98	88
2779.72	84
2781.46	90
2783.19	90
2784.93	82
2786.67	90
2788.4	90
2790.14	78
2791.87	92
2793.61	80
2795.34	88
2797.07	78
2798.81	72
2800.54	84
2802.27	78
2804	86
2805.74	82
2807.47	74
2809.2	86
2810.93	86
2812.65	86
2814.38	82
2816.11	84
2817.84	80
2819.56	76
2821.29	86
2823.02	80
2824.74	80
2826.47	76
2828.19	88
2829.92	66
2831.64	78
2833.36	84
2835.09	76
2836.81	72
2838.53	84
2840.25	72
2841.97	76
2843.69	70
2845.41	66
2847.13	74
2848.85	74
2850.57	62
2852.28	74
2854	74
2855.72	58
2857.43	72
2859.15	74
2860.86	68
2862.58	66
2864.29	78
2866.01	82
2867.72	70
2869.43	72
2871.14	80
2872.86	80
2874.57	62
2876.28	70
2877.99	74
2879.7	68
2881.41	72
2883.11	82
2884.82	70
2886.53	76
2888.24	66
2889.94	80
2891.65	74
2893.36	68
2895.06	66
2896.77	76
2898.47	72
2900.17	66
2901.88	68
2903.58	64
2905.28	72
2906.98	78
2908.69	70
2910.39	66
2912.09	60
2913.79	64
2915.49	74
2917.19	64
2918.88	68
2920.58	62
2922.28	76
2923.98	64
2925.67	72
2927.37	70
2929.06	72
2930.76	70
2932.45	64
2934.15	60
2935.84	62
2937.53	64
2939.23	58
2940.92	66
2942.61	62
2944.3	62
2945.99	56
2947.68	56
2949.37	54
2951.06	62
2952.75	66
2954.44	60
2956.12	56
2957.81	72
2959.5	46
2961.18	64
2962.87	60
2964.56	58
2966.24	56
2967.92	56
2969.61	60
2971.29	70
2972.97	58
2974.66	56
2976.34	64
2978.02	54
2979.7	66
2981.38	58
2983.06	64
2984.74	56
2986.42	48
2988.1	54
2989.78	70
2991.45	58
2993.13	62
2994.81	48
2996.48	56
2998.16	56
2999.83	56