File: muestras/nopal/inside_prf_02.txt
#Acq. time (s)=	10
#Accumulations=	2
#Range (cm-¹)=	200...2000
#Windows=	2
#Autofocus=	Off
#AutoExposure=	Off
#Spike filter=	Multiple accum.
#Delay time (s)=	0
#Binning=	1
#Readout mode=	Signal
#DeNoise=	Off
#ICS correction=	Off
#Dark correction=	Off
#Inst. Process=	Off
#Instrument=	LabRAM HR Evol
#Detector=	Syncerity OE
#Objective=	x100_VIS
#Grating=	600 (500nm)
#ND Filter=	10%
#Laser=	633nm_Edge
#Hole=	24.99
#Range=	Visible
#Project=	Omar
#Sample=	03-07-23
#Site=	nop
#Title=	inside_prf
#Remark=
#Date=	03.07.2023 14:12
#Acquired=	03.07.2023 14:12:29
200.319	418
202.854	438
205.387	448
207.918	436
210.45	438
212.98	406
215.51	450
218.038	452
220.565	474
223.093	462
225.618	444
228.143	476
230.668	458
233.191	438
235.713	470
238.235	424
240.757	474
243.276	458
245.795	478
248.313	476
250.831	478
253.347	496
255.863	476
258.378	498
260.892	458
263.405	480
265.916	496
268.427	492
270.938	480
273.448	508
275.957	494
278.464	480
280.972	492
283.478	508
285.983	502
288.488	540
290.992	510
293.494	508
295.997	506
298.497	540
300.998	534
303.497	504
305.995	536
308.494	550
310.99	542
313.486	558
315.982	544
318.476	532
320.969	574
323.461	562
325.953	562
328.445	562
330.935	576
333.424	574
335.912	560
338.4	578
340.887	560
343.373	594
345.858	582
348.341	580
350.824	598
353.307	590
355.789	584
358.27	596
360.749	618
363.229	610
365.707	610
368.184	612
370.661	624
373.137	596
375.612	616
378.086	598
380.559	646
383.032	596
385.503	598
387.973	622
390.444	624
392.913	632
395.38	614
397.849	618
400.315	652
402.78	616
405.245	668
407.709	640
410.173	676
412.636	650
415.097	658
417.558	686
420.018	702
422.477	698
424.935	702
427.393	688
429.848	696
432.304	736
434.759	696
437.214	708
439.667	722
442.119	714
444.571	714
447.022	760
449.471	732
451.921	710
454.37	754
456.816	712
459.264	768
461.709	722
464.155	766
466.598	766
469.041	760
471.485	760
473.926	764
476.366	752
478.806	776
481.247	784
483.685	762
486.122	786
488.559	836
490.995	778
493.43	772
495.864	832
498.297	792
500.73	806
503.162	806
505.593	854
508.024	840
510.453	854
512.882	830
515.31	838
517.736	852
520.163	852
522.588	854
525.012	834
527.436	838
529.86	848
532.281	864
534.703	846
537.123	850
539.543	838
541.961	860
544.379	876
546.797	884
549.213	918
551.628	876
554.044	902
556.457	896
558.87	904
561.282	886
563.695	880
566.106	888
568.515	920
570.924	928
573.333	908
575.74	924
578.147	964
580.553	956
582.958	952
585.361	936
587.765	946
590.168	958
592.57	984
594.97	1004
597.371	1010
599.771	982
602.169	1036
604.567	1028
606.965	1078
609.36	1024
611.756	1034
614.15	1028
616.545	1052
618.937	1064
621.329	1098
623.721	1056
626.112	1086
628.501	1140
630.891	1116
633.279	1134
635.666	1108
638.053	1138
640.439	1112
642.824	1120
645.208	1146
647.591	1190
649.974	1166
652.356	1146
654.737	1214
657.117	1180
659.497	1194
661.876	1204
664.253	1238
666.63	1214
669.007	1276
671.383	1250
673.757	1228
676.131	1196
678.504	1244
680.877	1284
683.248	1252
685.619	1296
687.988	1270
690.358	1308
692.726	1310
695.095	1322
697.461	1322
699.827	1374
702.192	1350
704.557	1362
706.921	1440
709.284	1368
711.645	1406
714.007	1380
716.367	1384
718.727	1446
721.086	1468
723.444	1440
725.802	1484
728.158	1494
730.514	1510
732.87	1502
735.223	1552
737.577	1510
739.93	1538
742.282	1570
744.633	1562
746.983	1614
749.332	1628
751.682	1640
754.029	1630
756.377	1640
758.723	1662
761.069	1658
763.414	1664
765.757	1690
768.102	1770
770.444	1734
772.785	1678
775.127	1734
777.467	1778
779.807	1778
782.145	1792
784.483	1808
786.82	1808
789.157	1882
791.492	1832
793.827	1872
796.161	1864
798.495	1930
800.828	1938
803.158	1884
805.49	1998
807.82	1966
810.15	2046
812.478	2066
814.806	2050
817.132	2066
819.459	2122
821.784	2122
824.11	2138
826.433	2172
828.757	2170
831.079	2158
833.402	2186
835.722	2224
838.042	2252
840.361	2256
842.681	2314
844.999	2398
847.315	2340
849.632	2480
851.947	2466
854.262	2488
856.576	2498
858.889	2492
861.202	2512
863.514	2502
865.825	2526
868.136	2568
870.444	2622
872.753	2594
875.062	2658
877.369	2664
879.675	2682
881.981	2734
884.286	2696
886.59	2706
888.894	2734
891.196	2798
893.499	2864
895.799	2840
898.099	2846
900.4	2840
902.698	2936
904.996	2886
907.293	2962
909.591	2960
911.886	2922
914.181	3072
916.475	3074
918.769	3092
921.062	3146
923.354	3134
925.645	3106
927.936	3194
930.226	3140
932.515	3254
934.802	3344
937.09	3326
939.377	3288
941.664	3356
943.948	3408
946.233	3416
948.517	3446
950.8	3426
953.083	3574
955.363	3596
957.645	3510
959.924	3572
962.203	3688
964.483	3666
966.76	3806
969.037	3728
971.314	3804
973.589	3814
975.864	3818
978.138	3938
980.411	3934
982.684	3914
984.955	4038
987.226	4092
989.497	4156
991.767	4112
994.036	4012
996.304	4142
998.572	4148
1000.84	4222
1003.1	4254
1005.37	4234
1007.63	4340
1009.9	4354
1012.16	4368
1014.42	4426
1016.68	4484
1018.94	4558
1021.2	4584
1023.46	4494
1025.72	4680
1027.98	4722
1030.24	4672
1032.49	4716
1034.75	4806
1037	4814
1039.26	4962
1041.51	4930
1043.76	4820
1046.01	4964
1048.27	5080
1050.52	5126
1052.77	5094
1055.01	5266
1057.26	5250
1059.51	5255
1061.76	5402
1064	5394
1066.25	5328
1068.49	5460
1070.74	5518
1072.98	5484
1075.22	5492
1077.46	5564
1079.71	5548
1081.94	5600
1084.18	5544
1086.42	5626
1088.66	5616
1090.9	5744
1093.13	5670
1095.37	5786
1097.6	5832
1099.84	5782
1102.07	5798
1104.31	5896
1106.54	5838
1108.77	5874
1111	5924
1113.23	6062
1115.46	6064
1117.69	6058
1119.92	6016
1122.14	6128
1124.37	6080
1126.59	6160
1128.82	6266
1131.04	6314
1133.27	6274
1135.49	6334
1137.71	6304
1139.93	6384
1142.15	6520
1144.37	6480
1146.59	6498
1148.81	6538
1151.03	6554
1153.24	6660
1155.46	6686
1157.68	6682
1159.89	6736
1162.11	6646
1164.32	6604
1166.53	6668
1168.74	6786
1170.95	6718
1173.16	6630
1175.37	6742
1177.58	6732
1179.79	6888
1182	6824
1184.21	6950
1186.41	6742
1188.62	6816
1190.82	6704
1193.03	6850
1195.23	6728
1197.43	6750
1199.63	6806
1201.84	6750
1204.04	6706
1206.23	6684
1208.43	6734
1210.63	6716
1212.83	6736
1215.03	6766
1217.22	6694
1219.42	6640
1221.61	6634
1223.81	6652
1226	6648
1228.19	6586
1230.39	6608
1232.58	6586
1234.77	6656
1236.96	6600
1239.15	6486
1241.33	6590
1243.52	6522
1245.71	6492
1247.9	6540
1250.08	6478
1252.27	6562
1254.45	6566
1256.63	6412
1258.81	6496
1261	6414
1263.18	6462
1265.36	6414
1267.54	6286
1269.72	6342
1271.9	6444
1274.07	6346
1276.25	6252
1278.43	6312
1280.6	6318
1282.78	6298.82
1284.95	6320.96
1287.13	6283.94
1289.3	6224.89
1291.47	6233.84
1293.64	6088.55
1295.81	6162.86
1297.98	6079.42
1300.15	6011.33
1302.32	5950.78
1304.49	5922.12
1306.66	5821.79
1308.82	5847.96
1310.99	5862.07
1313.16	5751.45
1315.32	5757.69
1317.48	5695.31
1319.65	5597.02
1321.81	5616.48
1323.97	5572.03
1326.13	5512.46
1328.29	5539.23
1330.45	5358.66
1332.61	5431.86
1334.77	5331.04
1336.93	5366.18
1339.08	5295.06
1341.24	5254.32
1343.39	5233.03
1345.55	5222.91
1347.7	5193.3
1349.86	5128.66
1352.01	5053.07
1354.16	5097.18
1356.31	5008.92
1358.46	5005.78
1360.61	4946.54
1362.76	4947.94
1364.91	4828.96
1367.06	4821.44
1369.21	4844.55
1371.35	4789.31
1373.5	4797.92
1375.64	4693.54
1377.79	4715.15
1379.93	4636.56
1382.07	4580.37
1384.22	4646.29
1386.36	4586.36
1388.5	4541.61
1390.64	4550.98
1391.76	4554
1393.91	4444
1396.06	4416
1398.21	4458
1400.36	4502
1402.51	4476
1404.65	4384
1406.8	4346
1408.95	4330
1411.09	4296
1413.23	4310
1415.38	4272
1417.52	4228
1419.66	4286
1421.8	4306
1423.94	4204
1426.08	4168
1428.22	4158
1430.36	4236
1432.5	4162
1434.64	4072
1436.77	4100
1438.91	4134
1441.04	4138
1443.18	4010
1445.31	4082
1447.45	3996
1449.58	4000
1451.71	3968
1453.84	4030
1455.97	4064
1458.1	3982
1460.23	3922
1462.36	3966
1464.48	3952
1466.61	3842
1468.74	3776
1470.86	3876
1472.99	3892
1475.11	3918
1477.24	3886
1479.36	3822
1481.48	3842
1483.6	3814
1485.73	3816
1487.85	3764
1489.96	3806
1492.08	3768
1494.2	3736
1496.32	3730
1498.44	3770
1500.55	3748
1502.67	3698
1504.78	3732
1506.9	3742
1509.01	3720
1511.13	3586
1513.24	3690
1515.35	3630
1517.46	3624
1519.57	3670
1521.68	3542
1523.79	3572
1525.9	3582
1528.01	3582
1530.11	3520
1532.22	3460
1534.32	3520
1536.43	3478
1538.53	3424
1540.64	3430
1542.74	3434
1544.84	3468
1546.94	3454
1549.04	3484
1551.15	3434
1553.25	3394
1555.34	3430
1557.44	3430
1559.54	3386
1561.64	3434
1563.73	3332
1565.83	3362
1567.92	3360
1570.02	3312
1572.11	3334
1574.21	3276
1576.3	3290
1578.39	3268
1580.48	3304
1582.57	3272
1584.66	3304
1586.75	3288
1588.84	3228
1590.93	3170
1593.02	3238
1595.1	3292
1597.19	3284
1599.27	3230
1601.36	3188
1603.44	3264
1605.53	3200
1607.61	3198
1609.69	3222
1611.77	3232
1613.85	3168
1615.93	3228
1618.01	3260
1620.09	3184
1622.17	3196
1624.24	3126
1626.32	3182
1628.4	3164
1630.47	3256
1632.55	3120
1634.62	3110
1636.7	3110
1638.77	3088
1640.84	3140
1642.91	3072
1644.98	3172
1647.05	3144
1649.12	3160
1651.19	3068
1653.26	3022
1655.33	3106
1657.4	3120
1659.46	3068
1661.53	3036
1663.59	3080
1665.66	3000
1667.72	3068
1669.78	3050
1671.85	2980
1673.91	3018
1675.97	3022
1678.03	3020
1680.09	2974
1682.15	3020
1684.21	2982
1686.27	2980
1688.32	2908
1690.38	2926
1692.44	2962
1694.49	2966
1696.55	2914
1698.6	2958
1700.66	2926
1702.71	2946
1704.76	2926
1706.81	2992
1708.86	2854
1710.91	2870
1712.96	2936
1715.01	2944
1717.06	2802
1719.11	2872
1721.16	2928
1723.2	2850
1725.25	2856
1727.29	2934
1729.34	2808
1731.38	2888
1733.43	2914
1735.47	2768
1737.51	2864
1739.55	2836
1741.59	2830
1743.63	2878
1745.67	2794
1747.71	2850
1749.75	2866
1751.79	2816
1753.83	2830
1755.86	2886
1757.9	2820
1759.93	2820
1761.97	2830
1764	2836
1766.03	2770
1768.07	2894
1770.1	2832
1772.13	2848
1774.16	2796
1776.19	2850
1778.22	2824
1780.25	2852
1782.28	2794
1784.3	2774
1786.33	2860
1788.36	2798
1790.38	2762
1792.41	2818
1794.43	2816
1796.46	2774
1798.48	2822
1800.5	2838
1802.52	2764
1804.55	2752
1806.57	2840
1808.59	2830
1810.61	2838
1812.62	2708
1814.64	2814
1816.66	2754
1818.68	2814
1820.69	2758
1822.71	2796
1824.72	2706
1826.74	2686
1828.75	2756
1830.77	2740
1832.78	2778
1834.79	2732
1836.8	2752
1838.81	2732
1840.82	2802
1842.83	2708
1844.84	2702
1846.85	2744
1848.85	2688
1850.86	2700
1852.87	2676
1854.87	2730
1856.88	2746
1858.88	2692
1860.89	2702
1862.89	2674
1864.89	2764
1866.89	2696
1868.9	2658
1870.9	2684
1872.9	2674
1874.9	2700
1876.9	2646
1878.89	2680
1880.89	2678
1882.89	2718
1884.88	2672
1886.88	2680
1888.88	2664
1890.87	2690
1892.87	2654
1894.86	2636
1896.85	2586
1898.84	2638
1900.83	2664
1902.82	2694
1904.81	2648
1906.8	2650
1908.79	2670
1910.78	2638
1912.77	2696
1914.76	2670
1916.74	2642
1918.73	2628
1920.72	2680
1922.7	2650
1924.68	2670
1926.67	2692
1928.65	2660
1930.63	2686
1932.61	2586
1934.6	2674
1936.58	2680
1938.56	2640
1940.54	2580
1942.51	2652
1944.49	2648
1946.47	2634
1948.45	2602
1950.42	2628
1952.4	2588
1954.37	2640
1956.35	2618
1958.32	2694
1960.29	2560
1962.27	2598
1964.24	2616
1966.21	2610
1968.18	2590
1970.15	2608
1972.12	2602
1974.09	2572
1976.06	2596
1978.03	2562
1979.99	2588
1981.96	2642
1983.93	2618
1985.89	2632
1987.86	2574
1989.82	2636
1991.78	2562
1993.75	2586
1995.71	2576
1997.67	2550
1999.63	2568