File: muestras/nopal/inside_prf_08.txt
#Acq. time (s)=	20
#Accumulations=	1
#Range (cm-¹)=	200...3000
#Windows=	3
#Autofocus=	Off
#AutoExposure=	Off
#Spike filter=	Off
#Delay time (s)=	0
#Binning=	1
#Readout mode=	Signal
#DeNoise=	Off
#ICS correction=	Off
#Dark correction=	Off
#Inst. Process=	Off
#Instrument=	LabRAM HR Evol
#Detector=	Syncerity OE
#Objective=	x100_VIS
#Grating=	600 (500nm)
#ND Filter=	0.1%
#Laser=	633nm_Edge
#Hole=	49.98
#Range=	Visible
#Project=	Omar
#Sample=	03-07-23
#Site=	nop
#Title=	inside_prf
#Remark=
#Date=	03.07.2023 14:29
#Acquired=	03.07.2023 14:29:25
201.713	244
204.247	234
206.778	254
209.311	236
211.84	244
214.371	244
216.899	254
219.428	262
221.955	258
224.482	262
227.007	276
229.531	272
232.055	278
234.579	266
237.1	300
239.621	268
242.141	288
244.661	278
247.179	312
249.698	306
252.215	302
254.731	318
257.246	336
259.761	318
262.273	326
264.786	330
267.298	306
269.809	330
272.319	330
274.828	340
277.336	334
279.844	366
282.351	354
284.855	344
287.361	374
289.866	384
292.368	378
294.871	366
297.372	388
299.873	388
302.372	400
304.872	376
307.37	394
309.866	402
312.364	414
314.859	432
317.353	450
319.848	428
322.341	458
324.833	446
327.324	474
329.814	448
332.304	474
334.792	464
337.28	468
339.767	468
342.254	492
344.739	496
347.224	496
349.708	522
352.191	524
354.673	554
357.155	540
359.634	534
362.114	592
364.593	548
367.07	542
369.548	552
372.024	550
374.499	554
376.974	560
379.447	618
381.92	580
384.392	592
386.864	604
389.333	576
391.802	612
394.272	628
396.739	628
399.206	650
401.673	644
404.138	660
406.602	654
409.066	692
411.528	698
413.99	662
416.451	690
418.911	718
421.371	744
423.83	718
426.288	766
428.745	736
431.201	746
433.657	766
436.111	764
438.565	774
441.017	800
443.469	826
445.921	816
448.37	812
450.821	834
453.27	846
455.717	828
458.165	850
460.61	838
463.056	868
465.5	884
467.945	880
470.387	888
472.829	924
475.271	912
477.711	928
480.15	928
482.589	982
485.027	938
487.465	966
489.901	948
492.337	982
494.771	994
497.205	1020
499.638	1010
502.07	994
504.502	1058
506.933	1048
509.363	1068
511.792	1078
514.219	1062
516.647	1116
519.073	1122
521.5	1068
523.924	1082
526.348	1126
528.772	1156
531.194	1140
533.616	1156
536.036	1162
538.457	1146
540.875	1204
543.294	1198
545.712	1242
548.128	1214
550.545	1256
552.959	1202
555.373	1272
557.788	1258
560.2	1262
562.612	1278
565.023	1292
567.433	1312
569.843	1352
572.251	1342
574.659	1394
577.066	1414
579.472	1340
581.878	1418
584.283	1418
586.687	1422
589.09	1442
591.493	1460
593.893	1472
596.294	1504
598.694	1558
601.093	1536
603.491	1572
605.889	1602
608.285	1582
610.682	1590
613.076	1670
615.471	1688
617.864	1654
620.256	1644
622.648	1678
625.039	1784
627.429	1776
629.819	1778
632.208	1754
634.595	1888
636.982	1858
639.369	1842
641.755	1930
644.139	1932
646.523	1944
648.906	2008
651.288	2006
653.67	1970
656.051	2026
658.429	2108
660.808	2124
663.187	2092
665.565	2094
667.942	2166
670.317	2186
672.692	2178
675.067	2286
677.44	2288
679.813	2278
682.184	2298
684.556	2314
686.926	2326
689.296	2422
691.664	2432
694.033	2388
696.4	2506
698.766	2560
701.133	2596
703.497	2630
705.861	2598
708.224	2584
710.586	2652
712.949	2728
715.31	2802
717.67	2800
720.029	2836
722.388	2894
724.746	2964
727.103	3018
729.458	2980
731.814	3002
734.168	3114
736.523	3186
738.876	3172
741.227	3206
743.579	3190
745.931	3314
748.28	3274
750.629	3474
752.977	3474
755.325	3500
757.672	3436
760.018	3626
762.363	3574
764.708	3562
767.052	3676
769.394	3712
771.737	3798
774.078	3830
776.419	3932
778.758	3900
781.097	3946
783.435	4020
785.773	4092
788.11	4106
790.446	4230
792.781	4190
795.115	4226
797.449	4414
799.782	4390
802.115	4432
804.446	4500
806.777	4588
809.106	4654
811.435	4694
813.764	4728
816.091	4858
818.418	4876
820.743	4918
823.069	5032
825.393	5150
827.717	5256
830.039	5310
832.362	5372
834.683	5436
837.003	5528
839.324	5532
841.643	5558
843.961	5690
846.278	5660
848.594	5874
850.91	5844
853.227	5982
855.541	6024
857.855	6198
860.168	6198
862.48	6344
864.79	6396
867.101	6404
869.411	6622
871.721	6572
874.029	6658
876.336	6754
878.643	6848
880.95	6914
883.254	6968
885.559	7056
887.862	7134
890.166	7192
892.467	7322
894.77	7274
897.07	7438
899.371	7568
901.669	7614
903.968	7706
906.266	7712
908.563	7880
910.859	7930
913.154	8070
915.449	8192
917.742	8212
920.036	8390
922.329	8446
924.621	8536
926.911	8526
929.201	8674
931.49	8708
933.779	8910
936.068	8922
938.355	9028
940.64	9260
942.926	9316
945.212	9484
947.495	9590
949.779	9634
952.062	9804
954.344	9920
956.625	10070
958.905	10028
961.184	10170
963.464	10324
965.742	10438
968.02	10592
970.296	10712
972.572	10762
974.847	10900
977.121	11074
979.396	11222
981.669	11214
983.941	11456
986.212	11620
988.483	11520
990.753	11798
993.022	11946
995.29	12018
997.558	12104
999.825	12242
1002.09	12294
1004.36	12376
1006.62	12638
1008.89	12682
1011.15	12842
1013.41	13118
1015.67	12988
1017.93	13298
1020.19	13608
1022.45	13560
1024.71	13924
1026.97	13888
1029.23	13984
1031.49	14096
1033.74	14294
1036	14568
1038.25	14454
1040.5	14810
1042.76	14984
1045.01	15070
1047.26	15312
1049.51	15526
1051.76	15444
1054.01	15836
1056.26	15848
1058.51	16122
1060.75	16208
1063	16526
1065.25	16524
1067.49	16630
1069.73	16670
1071.98	16998
1074.22	17052
1076.46	17042
1078.7	17476
1080.94	17300
1083.18	17436
1085.42	17730
1087.66	17660
1089.9	18012
1092.14	18000
1094.37	18078
1096.61	18344
1098.84	18166
1101.08	18428
1103.31	18522
1105.54	18666
1107.77	18784
1110	18892
1112.23	19018
1114.46	19088
1116.69	19066
1118.92	19346
1121.15	19524
1123.37	19504
1125.6	19708
1127.83	19796
1130.05	19882
1132.27	20094
1134.5	20342
1136.72	20456
1138.94	20500
1141.16	20496
1143.38	20678
1145.6	20908
1147.82	20800
1150.04	21086
1152.26	21254
1154.47	21230
1156.69	21344
1158.9	21498
1161.12	21518
1163.33	21708
1165.54	21488
1167.76	21624
1169.97	21846
1172.18	21594
1174.39	21856
1176.6	21622
1178.81	21888
1181.02	21796
1183.22	21716
1185.43	21768
1187.63	21748
1189.84	21754
1192.04	21618
1194.25	21696
1196.45	21608
1198.65	21638
1200.85	21644
1203.05	21626
1205.25	21426
1207.45	21398
1209.65	21460
1211.85	21440
1214.05	21176
1216.24	21202
1218.44	21238
1220.64	20996
1222.83	21026
1225.02	20958
1227.22	20812
1229.41	20446
1231.6	20744
1233.79	20612
1235.98	20368
1238.17	20364
1240.36	20390
1242.55	20250
1244.73	20218
1246.92	20214
1249.11	19848
1251.29	19796
1253.48	19890
1255.66	19630
1257.84	19758
1260.03	19450
1262.21	19258
1264.39	19316
1266.57	19260
1268.75	19090
1270.93	19076
1273.11	18854
1275.28	18772
1277.46	18744
1279.64	18456
1281.81	18340
1283.98	18252.2
1286.16	18195.9
1288.33	18110.6
1290.5	17846.8
1292.68	17619.1
1294.85	17503.5
1297.02	17420
1299.19	17189.8
1301.36	17103.8
1303.53	16788.6
1305.69	16821.3
1307.86	16567.6
1310.03	16339.8
1312.19	16315.6
1314.36	16028.2
1316.52	15940.9
1318.68	15770
1320.85	15573.5
1323.01	15586
1325.17	15369.1
1327.33	15271.6
1329.49	14962
1331.65	14886.3
1333.81	14677.5
1335.97	14595
1338.12	14453.4
1340.28	14335.5
1342.44	14112.6
1344.59	13935.3
1346.75	13822.8
1348.9	13763.5
1351.05	13542.4
1353.2	13324.3
1355.36	13289.5
1357.51	13237.3
1359.66	12949
1361.81	12893.7
1363.96	12723.2
1366.1	12509.3
1368.25	12458.1
1370.4	12419.8
1372.54	12343.5
1374.69	12181.6
1376.83	12015.1
1378.98	11807.6
1381.12	11826.2
1383.26	11732.9
1385.41	11614.4
1387.55	11364.2
1389.69	11270.4
1391.83	11251.2
1393.02	11142
1395.17	11138
1397.32	11000
1399.47	11080
1401.62	10840
1403.77	10818
1405.91	10674
1408.06	10652
1410.2	10536
1412.35	10430
1414.49	10412
1416.63	10352
1418.78	10150
1420.92	10114
1423.06	10018
1425.2	10032
1427.34	9918
1429.48	9924
1431.61	9812
1433.75	9788
1435.89	9528
1438.02	9470
1440.16	9502
1442.3	9400
1444.43	9338
1446.56	9320
1448.7	9250
1450.83	9296
1452.96	9174
1455.09	9052
1457.22	9146
1459.35	9078
1461.48	9010
1463.61	8896
1465.73	8892
1467.86	8712
1469.98	8822
1472.11	8670
1474.24	8666
1476.36	8694
1478.48	8574
1480.6	8482
1482.73	8582
1484.85	8500
1486.97	8362
1489.09	8356
1491.21	8372
1493.33	8290
1495.44	8218
1497.56	8180
1499.68	8098
1501.79	8022
1503.91	8082
1506.02	7978
1508.14	7846
1510.25	7994
1512.36	7830
1514.48	7734
1516.59	7766
1518.7	7658
1520.81	7534
1522.92	7596
1525.02	7514
1527.13	7502
1529.24	7452
1531.35	7428
1533.45	7282
1535.56	7348
1537.66	7234
1539.77	7234
1541.87	7250
1543.97	7156
1546.08	7136
1548.18	7172
1550.28	6984
1552.38	7110
1554.48	7050
1556.57	6920
1558.67	6804
1560.77	6816
1562.87	6884
1564.96	6840
1567.06	6864
1569.15	6788
1571.25	6750
1573.34	6706
1575.43	6690
1577.53	6620
1579.62	6742
1581.71	6676
1583.8	6494
1585.89	6666
1587.98	6580
1590.06	6564
1592.15	6548
1594.24	6514
1596.33	6480
1598.41	6492
1600.5	6460
1602.58	6422
1604.66	6396
1606.75	6406
1608.83	6356
1610.91	6254
1612.99	6346
1615.07	6362
1617.15	6390
1619.23	6332
1621.31	6334
1623.39	6368
1625.46	6182
1627.54	6258
1629.62	6202
1631.69	6120
1633.77	6174
1635.84	6170
1637.91	6162
1639.99	6188
1642.06	6090
1644.13	5990
1646.2	6088
1648.27	6038
1650.34	6036
1652.41	5974
1654.47	5932
1656.54	6006
1658.61	6000
1660.67	5968
1662.74	5846
1664.81	5862
1666.87	5764
1668.93	5820
1671	5784
1673.06	5692
1675.12	5776
1677.18	5718
1679.24	5704
1681.3	5690
1683.36	5656
1685.42	5690
1687.47	5756
1689.53	5560
1691.59	5578
1693.64	5712
1695.7	5634
1697.75	5478
1699.81	5620
1701.86	5612
1703.91	5450
1705.97	5590
1708.02	5504
1710.07	5524
1712.12	5552
1714.17	5600
1716.22	5374
1718.26	5526
1720.31	5454
1722.36	5372
1724.4	5464
1726.45	5434
1728.49	5382
1730.54	5396
1732.58	5362
1734.63	5388
1736.67	5392
1738.71	5374
1740.75	5362
1742.79	5352
1744.83	5324
1746.87	5344
1748.91	5382
1750.95	5358
1752.98	5352
1755.02	5288
1757.06	5250
1759.09	5232
1761.13	5222
1763.16	5356
1765.19	5178
1767.23	5188
1769.26	5262
1771.29	5208
1773.32	5272
1775.35	5218
1777.38	5166
1779.41	5250
1781.44	5280
1783.47	5194
1785.49	5180
1787.52	5168
1789.55	5244
1791.57	5194
1793.6	5246
1795.62	5176
1797.64	5198
1799.67	5164
1801.69	5162
1803.71	5122
1805.73	5188
1807.75	5182
1809.77	5126
1811.79	5172
1813.81	5232
1815.83	5102
1817.84	5150
1819.86	5240
1821.88	5096
1823.89	5052
1825.91	5054
1827.92	5018
1829.93	5040
1831.95	5086
1833.96	5098
1835.97	5068
1837.98	5032
1839.99	5086
1842	5082
1844.01	5040
1846.02	4992
1848.03	4922
1850.03	5034
1852.04	4924
1854.05	5010
1856.05	4966
1858.06	5060
1860.06	4950
1862.06	4996
1864.07	4896
1866.07	4922
1868.07	4890
1870.07	4942
1872.07	4920
1874.07	4956
1876.07	4898
1878.07	5018
1880.07	4882
1882.07	4872
1884.06	4964
1886.06	4938
1888.05	4920
1890.05	4906
1892.04	4920
1894.04	4910
1896.03	4888
1898.02	4950
1900.01	4954
1902	4944
1903.99	4892
1905.98	4810
1907.97	4810
1909.96	4856
1911.95	4920
1913.94	4928
1915.93	4872
1917.91	4938
1919.9	4850
1921.88	4862
1923.87	4834
1925.85	4798
1927.83	4884
1929.82	4748
1931.8	4862
1933.78	4874
1935.76	4780
1937.74	4792
1939.72	4886
1941.7	4730
1943.68	4742
1945.65	4836
1947.63	4812
1949.61	4792
1951.58	4856
1953.56	4718
1955.53	4746
1957.51	4838
1959.48	4682
1961.45	4710
1963.43	4764
1965.4	4750
1967.37	4748
1969.34	4724
1971.31	4718
1973.28	4708
1975.25	4708
1977.22	4652
1979.18	4710
1981.15	4732
1983.12	4706
1985.08	4638
1987.05	4696
1989.01	4648
1990.97	4720
1992.94	4734
1994.9	4682
1996.86	4686
1998.82	4654
2000.78	4688
2002.74	4682
2004.7	4648
2006.66	4666
2008.62	4646
2010.58	4658
2012.54	4644
2014.49	4638
2016.45	4602
2018.4	4614
2020.36	4708
2022.31	4608
2024.27	4618
2026.22	4590
2028.17	4694
2030.12	4684
2032.07	4626
2034.03	4640
2035.98	4564
2037.93	4676
2039.87	4600
2041.82	4546
2043.77	4590
2045.72	4608
2047.66	4658
2049.61	4556
2051.55	4634
2053.5	4528
2055.44	4610
2057.39	4552
2059.33	4516
2061.27	4530
2063.21	4534
2065.15	4542
2067.09	4594
2069.03	4490
2070.97	4592
2072.91	4578
2074.85	4536
2076.79	4546
2078.73	4566
2080.66	4620
2082.6	4548
2084.53	4608
2086.47	4570
2088.4	4568
2090.33	4534
2092.27	4570
2094.2	4560
2096.13	4460
2098.06	4534
2099.99	4516
2101.92	4500
2103.85	4568
2105.78	4512
2107.71	4552
2109.64	4528
2111.56	4478
2113.49	4506
2115.41	4576
2117.34	4494
2119.26	4478
2121.19	4452
2123.11	4526
2125.03	4414
2126.96	4474
2128.88	4450
2130.8	4470
2132.72	4526
2134.64	4476
2136.56	4530
2138.48	4466
2140.4	4524
2142.31	4436
2144.23	4418
2146.15	4530
2148.06	4532
2149.98	4446
2151.89	4436
2153.81	4402
2155.72	4446
2157.63	4484
2159.55	4330
2161.46	4438
2163.37	4306
2165.28	4394
2167.19	4456
2169.1	4420
2171.01	4462
2172.91	4434
2174.82	4362
2176.73	4400
2178.64	4408
2180.54	4298
2182.45	4310
2184.35	4318
2186.26	4376
2188.16	4328
2190.06	4386
2191.96	4308
2193.87	4248
2195.77	4356
2197.67	4348
2199.57	4242
2201.47	4208
2203.37	4340
2205.27	4200
2207.16	4236
2209.06	4254
2210.96	4248
2212.85	4148
2214.75	4230
2216.64	4294
2218.54	4196
2220.43	4284
2222.33	4156
2224.22	4202.35
2226.11	4268.99
2228	4217.75
2229.89	4173.64
2231.78	4248.11
2233.67	4223.28
2235.56	4281.48
2237.45	4207.96
2239.34	4228.53
2241.23	4242.4
2243.11	4193.19
2245	4206
2246.89	4121.64
2248.77	4257.31
2250.66	4201.02
2252.54	4200.08
2254.42	4163.11
2256.31	4130.71
2258.19	4138.89
2260.07	4170.61
2261.95	4180.36
2263.83	4108.91
2265.71	4174.73
2267.59	4103.14
2269.47	4086.68
2271.35	4123.39
2273.23	4198.67
2275.1	4090.04
2276.98	4078.36
2278.86	4080.6
2280.73	4058.5
2282.61	4092.71
2284.48	4120.85
2286.36	4822.17
2288.23	4979.66
2290.1	6767.02
2291.98	4344.82
2293.85	4024.05
2295.72	4031.65
2297.59	4040.91
2299.46	4002.05
2301.33	3997.02
2303.2	4003.67
2305.06	3962.12
2306.93	3974.44
2308.8	3961.99
2310.67	3954.88
2312.53	3913.65
2314.4	3917.95
2316.26	3967.87
2317.62	3936
2319.5	3844
2321.37	3974
2323.24	3894
2325.12	3906
2326.99	3944
2328.86	3858
2330.73	3952
2332.6	3892
2334.47	3904
2336.34	3850
2338.2	3838
2340.07	3810
2341.94	3898
2343.81	3858
2345.67	3822
2347.54	3852
2349.4	3754
2351.27	3814
2353.13	3726
2354.99	3734
2356.86	3698
2358.72	3796
2360.58	3756
2362.44	3848
2364.3	3758
2366.16	3784
2368.02	3682
2369.88	3714
2371.74	3744
2373.6	3676
2375.45	3774
2377.31	3720
2379.17	3770
2381.02	3642
2382.88	3674
2384.73	3658
2386.58	3746
2388.44	3644
2390.29	3646
2392.14	3618
2393.99	3610
2395.85	3604
2397.7	3608
2399.55	3522
2401.4	3546
2403.25	3594
2405.09	3558
2406.94	3494
2408.79	3540
2410.63	3490
2412.48	3480
2414.33	3512
2416.17	3474
2418.02	3486
2419.86	3528
2421.7	3468
2423.55	3350
2425.39	3476
2427.23	3316
2429.07	3402
2430.91	3402
2432.75	3320
2434.59	3492
2436.43	3408
2438.27	3332
2440.11	3358
2441.95	3384
2443.78	3306
2445.62	3366
2447.46	3308
2449.29	3256
2451.13	3296
2452.96	3280
2454.79	3300
2456.63	3230
2458.46	3204
2460.29	3230
2462.12	3266
2463.95	3222
2465.78	3156
2467.61	3220
2469.44	3156
2471.27	3182
2473.1	3168
2474.93	3172
2476.76	3218
2478.58	3070
2480.41	3118
2482.23	3098
2484.06	3034
2485.88	3072
2487.71	3092
2489.53	3048
2491.35	2990
2493.18	2978
2495	2974
2496.82	2972
2498.64	2948
2500.46	2996
2502.28	2922
2504.1	2976
2505.92	2912
2507.74	2958
2509.55	2920
2511.37	2896
2513.19	2918
2515	2788
2516.82	2940
2518.63	2800
2520.45	2884
2522.26	2850
2524.07	2786
2525.89	2762
2527.7	2778
2529.51	2788
2531.32	2734
2533.13	2706
2534.94	2768
2536.75	2764
2538.56	2710
2540.37	2694
2542.18	2662
2543.98	2646
2545.79	2802
2547.6	2676
2549.4	2658
2551.21	2700
2553.01	2614
2554.82	2652
2556.62	2562
2558.42	2576
2560.23	2636
2562.03	2660
2563.83	2646
2565.63	2558
2567.43	2516
2569.23	2582
2571.03	2590
2572.83	2528
2574.63	2554
2576.43	2492
2578.22	2518
2580.02	2472
2581.82	2548
2583.61	2468
2585.41	2468
2587.2	2452
2589	2488
2590.79	2426
2592.58	2388
2594.38	2416
2596.17	2404
2597.96	2396
2599.75	2390
2601.54	2376
2603.33	2374
2605.12	2326
2606.91	2292
2608.7	2336
2610.49	2308
2612.27	2246
2614.06	2336
2615.85	2282
2617.63	2236
2619.42	2328
2621.2	2250
2622.99	2204
2624.77	2260
2626.55	2274
2628.34	2224
2630.12	2256
2631.9	2196
2633.68	2154
2635.46	2204
2637.24	2174
2639.02	2122
2640.8	2126
2642.58	2128
2644.36	2128
2646.14	2164
2647.91	2052
2649.69	2112
2651.46	2120
2653.24	2064
2655.01	2060
2656.79	2062
2658.56	2090
2660.34	2090
2662.11	2004
2663.88	2026
2665.65	2050
2667.42	2000
2669.2	2018
2670.96	1992
2672.73	2070
2674.5	2004
2676.27	1972
2678.04	1966
2679.81	1946
2681.58	1924
2683.34	1922
2685.11	1962
2686.87	1914
2688.64	1906
2690.4	1908
2692.17	1906
2693.93	1862
2695.69	1894
2697.46	1864
2699.22	1820
2700.98	1864
2702.74	1802
2704.5	1816
2706.26	1786
2708.02	1756
2709.78	1848
2711.54	1836
2713.3	1770
2715.05	1782
2716.81	1778
2718.57	1754
2720.32	1698
2722.08	1726
2723.83	1752
2725.59	1740
2727.34	1734
2729.09	1706
2730.85	1670
2732.6	1682
2734.35	1698
2736.1	1664
2737.85	1662
2739.6	1662
2741.35	1630
2743.1	1654
2744.85	1616
2746.6	1634
2748.35	1602
2750.09	1560
2751.84	1578
2753.59	1594
2755.33	1582
2757.08	1580
2758.82	1566
2760.57	1572
2762.31	1570
2764.05	1568
2765.79	1526
2767.54	1548
2769.28	1522
2771.02	1506
2772.76	1490
2774.5	1548
2776.24	1460
2777.98	1452
2779.72	1466
2781.46	1470
2783.19	1446
2784.93	1482
2786.67	1420
2788.4	1390
2790.14	1406
2791.87	1426
2793.61	1418
2795.34	1388
2797.07	1362
2798.81	1394
2800.54	1402
2802.27	1364
2804	1366
2805.74	1338
2807.47	1324
2809.2	1356
2810.93	1342
2812.65	1310
2814.38	1342
2816.11	1300
2817.84	1286
2819.56	1292
2821.29	1246
2823.02	1228
2824.74	1310
2826.47	1284
2828.19	1278
2829.92	1222
2831.64	1256
2833.36	1246
2835.09	1238
2836.81	1246
2838.53	1184
2840.25	1194
2841.97	1198
2843.69	1188
2845.41	1270
2847.13	1172
2848.85	1188
2850.57	1152
2852.28	1168
2854	1144
2855.72	1118
2857.43	1142
2859.15	1136
2860.86	1102
2862.58	1164
2864.29	1120
2866.01	1084
2867.72	1110
2869.43	1074
2871.14	1102
2872.86	1074
2874.57	1070
2876.28	1090
2877.99	1112
2879.7	1066
2881.41	1050
2883.11	1004
2884.82	1044
2886.53	1066
2888.24	1014
2889.94	1070
2891.65	1026
2893.36	1004
2895.06	1024
2896.77	1010
2898.47	992
2900.17	1014
2901.88	1006
2903.58	994
2905.28	1000
2906.98	968
2908.69	976
2910.39	970
2912.09	950
2913.79	948
2915.49	966
2917.19	950
2918.88	966
2920.58	972
2922.28	922
2923.98	904
2925.67	926
2927.37	910
2929.06	994
2930.76	926
2932.45	924
2934.15	918
2935.84	878
2937.53	894
2939.23	900
2940.92	918
2942.61	906
2944.3	918
2945.99	882
2947.68	878
2949.37	908
2951.06	872
2952.75	890
2954.44	836
2956.12	860
2957.81	886
2959.5	840
2961.18	836
2962.87	824
2964.56	866
2966.24	858
2967.92	806
2969.61	836
2971.29	850
2972.97	844
2974.66	826
2976.34	836
2978.02	802
2979.7	830
2981.38	820
2983.06	782
2984.74	788
2986.42	790
2988.1	800
2989.78	784
2991.45	774
2993.13	788
2994.81	778
2996.48	760
2998.16	776
2999.83	772