File: muestras/nopal/inside_prf_09.txt
#Acq. time (s)=	20
#Accumulations=	1
#Range (cm-¹)=	200...3000
#Windows=	3
#Autofocus=	Off
#AutoExposure=	Off
#Spike filter=	Off
#Delay time (s)=	0
#Binning=	1
#Readout mode=	Signal
#DeNoise=	Off
#ICS correction=	Off
#Dark correction=	Off
#Inst. Process=	Off
#Instrument=	LabRAM HR Evol
#Detector=	Syncerity OE
#Objective=	x100_VIS
#Grating=	600 (500nm)
#ND Filter=	1%
#Laser=	633nm_Edge
#Hole=	49.98
#Range=	Visible
#Project=	Omar
#Sample=	03-07-23
#Site=	nop
#Title=	inside_prf
#Remark=
#Date=	03.07.2023 14:31
#Acquired=	03.07.2023 14:31:12
201.713	2396
204.247	2344
206.778	2418
209.311	2440
211.84	2478
214.371	2496
216.899	2562
219.428	2568
221.955	2484
224.482	2620
227.007	2598
229.531	2680
232.055	2668
234.579	2708
237.1	2684
239.621	2762
242.141	2806
244.661	2792
247.179	2918
249.698	2852
252.215	2916
254.731	2934
257.246	2974
259.761	2970
262.273	2994
264.786	3040
267.298	3072
269.809	3012
272.319	3028
274.828	3110
277.336	3124
279.844	3172
282.351	3208
284.855	3214
287.361	3242
289.866	3296
292.368	3304
294.871	3340
297.372	3382
299.873	3354
302.372	3482
304.872	3466
307.37	3540
309.866	3552
312.364	3732
314.859	3656
317.353	3670
319.848	3772
322.341	3780
324.833	3840
327.324	3862
329.814	3840
332.304	3968
334.792	3906
337.28	3994
339.767	4052
342.254	4060
344.739	4072
347.224	4212
349.708	4264
352.191	4292
354.673	4196
357.155	4332
359.634	4400
362.114	4482
364.593	4468
367.07	4484
369.548	4586
372.024	4672
374.499	4552
376.974	4604
379.447	4726
381.92	4662
384.392	4612
386.864	4768
389.333	4792
391.802	4762
394.272	4950
396.739	4976
399.206	4992
401.673	5036
404.138	5098
406.602	5182
409.066	5274
411.528	5328
413.99	5328
416.451	5358
418.911	5446
421.371	5546
423.83	5600
426.288	5680
428.745	5716
431.201	5840
433.657	5936
436.111	5956
438.565	5946
441.017	5992
443.469	6094
445.921	5990
448.37	6076
450.821	6276
453.27	6164
455.717	6212
458.165	6364
460.61	6318
463.056	6360
465.5	6376
467.945	6366
470.387	6540
472.829	6476
475.271	6624
477.711	6682
480.15	6624
482.589	6788
485.027	6856
487.465	6970
489.901	6938
492.337	7070
494.771	7052
497.205	7160
499.638	7252
502.07	7258
504.502	7328
506.933	7348
509.363	7484
511.792	7474
514.219	7546
516.647	7586
519.073	7526
521.5	7754
523.924	7716
526.348	7758
528.772	7806
531.194	7842
533.616	8030
536.036	7992
538.457	8012
540.875	8040
543.294	8080
545.712	8178
548.128	8166
550.545	8182
552.959	8294
555.373	8458
557.788	8486
560.2	8642
562.612	8530
565.023	8716
567.433	8780
569.843	8900
572.251	8822
574.659	8960
577.066	8980
579.472	9166
581.878	9258
584.283	9378
586.687	9254
589.09	9504
591.493	9674
593.893	9706
596.294	9802
598.694	9858
601.093	9886
603.491	10010
605.889	10106
608.285	10190
610.682	10252
613.076	10514
615.471	10598
617.864	10656
620.256	10858
622.648	10816
625.039	11046
627.429	11182
629.819	11296
632.208	11304
634.595	11644
636.982	11704
639.369	11864
641.755	11852
644.139	12104
646.523	12182
648.906	12308
651.288	12290
653.67	12404
656.051	12550
658.429	12802
660.808	12784
663.187	12814
665.565	13000
667.942	13210
670.317	13252
672.692	13496
675.067	13458
677.44	13782
679.813	13916
682.184	13904
684.556	14138
686.926	14240
689.296	14366
691.664	14708
694.033	14862
696.4	14922
698.766	15030
701.133	15148
703.497	15442
705.861	15520
708.224	15734
710.586	15856
712.949	16140
715.31	16392
717.67	16548
720.029	16642
722.388	16898
724.746	17190
727.103	17434
729.458	17644
731.814	17740
734.168	17760
736.523	18066
738.876	18370
741.227	18670
743.579	18808
745.931	18958
748.28	19218
750.629	19518
752.977	19652
755.325	19970
757.672	20226
760.018	20460
762.363	20392
764.708	20798
767.052	20982
769.394	21240
771.737	21308
774.078	21524
776.419	21810
778.758	22224
781.097	22566
783.435	22698
785.773	22928
788.11	23244
790.446	23506
792.781	23740
795.115	24106
797.449	24482
799.782	24692
802.115	24890
804.446	25086
806.777	25738
809.106	25918
811.435	26230
813.764	26706
816.091	26856
818.418	27370
820.743	27566
823.069	28128
825.393	28324
827.717	28846
830.039	29264
832.362	29526
834.683	30092
837.003	30320
839.324	30662
841.643	31046
843.961	31898
846.278	31904
848.594	32426
850.91	32962
853.227	33182
855.541	33668
857.855	33942
860.168	34008
862.48	34720
864.79	35288
867.101	35494
869.411	36118
871.721	36326
874.029	36752
876.336	37066
878.643	37410
880.95	37612
883.254	38372
885.559	38696
887.862	39074
890.166	39254
892.467	39434
894.77	40288
897.07	40758
899.371	41090
901.669	41320
903.968	41832
906.266	42276
908.563	42240
910.859	42980
913.154	43698
915.449	44028
917.742	44300
920.036	44998
922.329	45542
924.621	46090
926.911	46122
929.201	47028
931.49	47268
933.779	47920
936.068	48374
938.355	49218
940.64	49482
942.926	50034
945.212	50598
947.495	51068
949.779	52030
952.062	52484
954.344	52904
956.625	53576
958.905	54436
961.184	54930
963.464	55508
965.742	55752
968.02	56868
970.296	57092
972.572	57654
974.847	58214
977.121	58500
979.396	59212
981.669	59930
983.941	60578
986.212	61246
988.483	61456
990.753	62072
993.022	62770
995.29	63006
997.558	63614
999.825	64260
1002.09	64535
1004.36	64535
1006.62	64535
1008.89	64535
1011.15	64535
1013.41	64535
1015.67	64535
1017.93	64535
1020.19	64535
1022.45	64535
1024.71	64535
1026.97	64535
1029.23	64535
1031.49	64535
1033.74	64535
1036	64535
1038.25	64535
1040.5	64535
1042.76	64535
1045.01	64535
1047.26	64535
1049.51	64535
1051.76	64535
1054.01	64535
1056.26	64535
1058.51	64535
1060.75	64535
1063	64535
1065.25	64535
1067.49	64535
1069.73	64535
1071.98	64535
1074.22	64535
1076.46	64535
1078.7	64535
1080.94	64535
1083.18	64535
1085.42	64535
1087.66	64535
1089.9	64535
1092.14	64535
1094.37	64535
1096.61	64535
1098.84	64535
1101.08	64535
1103.31	64535
1105.54	64535
1107.77	64535
1110	64535
1112.23	64535
1114.46	64535
1116.69	64535
1118.92	64535
1121.15	64535
1123.37	64535
1125.6	64535
1127.83	64535
1130.05	64535
1132.27	64535
1134.5	64535
1136.72	64535
1138.94	64535
1141.16	64535
1143.38	64535
1145.6	64535
1147.82	64535
1150.04	64535
1152.26	64535
1154.47	64535
1156.69	64535
1158.9	64535
1161.12	64535
1163.33	64535
1165.54	64535
1167.76	64535
1169.97	64535
1172.18	64535
1174.39	64535
1176.6	64535
1178.81	64535
1181.02	64535
1183.22	64535
1185.43	64535
1187.63	64535
1189.84	64535
1192.04	64535
1194.25	64535
1196.45	64535
1198.65	64535
1200.85	64535
1203.05	64535
1205.25	64535
1207.45	64535
1209.65	64535
1211.85	64535
1214.05	64535
1216.24	64535
1218.44	64535
1220.64	64535
1222.83	64535
1225.02	64535
1227.22	64535
1229.41	64535
1231.6	64535
1233.79	64535
1235.98	64535
1238.17	64535
1240.36	64535
1242.55	64535
1244.73	64535
1246.92	64535
1249.11	64535
1251.29	64535
1253.48	64535
1255.66	64535
1257.84	64535
1260.03	64535
1262.21	64535
1264.39	64535
1266.57	64535
1268.75	64535
1270.93	64535
1273.11	64535
1275.28	64535
1277.46	64535
1279.64	64535
1281.81	64535
1283.98	64480.1
1286.16	64250.1
1288.33	64011.9
1290.5	63750.1
1292.68	63486.2
1294.85	63190.6
1297.02	62869.1
1299.19	62569.2
1301.36	62260.5
1303.53	61944.4
1305.69	61583.8
1307.86	61136.7
1310.03	60801.6
1312.19	60335.3
1314.36	59961.8
1316.52	59478.9
1318.68	59185.7
1320.85	58630.4
1323.01	58190.3
1325.17	57722.8
1327.33	57181.4
1329.49	56664.5
1331.65	56121.8
1333.81	55770.1
1335.97	55090.8
1338.12	54563
1340.28	53976.2
1342.44	53374.7
1344.59	52819
1346.75	52243.2
1348.9	51487.1
1351.05	51086.3
1353.2	50420.4
1355.36	49753.8
1357.51	49011.6
1359.66	48527.6
1361.81	47709.1
1363.96	46805.5
1366.1	46105.5
1368.25	45379.6
1370.4	44429
1372.54	43768.2
1374.69	43009.6
1376.83	42437.7
1378.98	41772.2
1381.12	40850.7
1383.26	40268.5
1385.41	39508.9
1387.55	38857.5
1389.69	38278.7
1391.83	37513.4
1393.02	37180
1395.17	36996
1397.32	36702
1399.47	36540
1401.62	35986
1403.77	36006
1405.91	35454
1408.06	35586
1410.2	35508
1412.35	34916
1414.49	34636
1416.63	34278
1418.78	34314
1420.92	33992
1423.06	33982
1425.2	33618
1427.34	33400
1429.48	33324
1431.61	33362
1433.75	32862
1435.89	32600
1438.02	32550
1440.16	32398
1442.3	32244
1444.43	31800
1446.56	31960
1448.7	31882
1450.83	31748
1452.96	31480
1455.09	31424
1457.22	31266
1459.35	30964
1461.48	30742
1463.61	30748
1465.73	30392
1467.86	30584
1469.98	30252
1472.11	30176
1474.24	30162
1476.36	29862
1478.48	29718
1480.6	29834
1482.73	29448
1484.85	29382
1486.97	29256
1489.09	29318
1491.21	29160
1493.33	28970
1495.44	28818
1497.56	28602
1499.68	28406
1501.79	28236
1503.91	28318
1506.02	28136
1508.14	27852
1510.25	27850
1512.36	27652
1514.48	27530
1516.59	27350
1518.7	27570
1520.81	26896
1522.92	27056
1525.02	26846
1527.13	26648
1529.24	26722
1531.35	26462
1533.45	26334
1535.56	26136
1537.66	26168
1539.77	25908
1541.87	25912
1543.97	25748
1546.08	25486
1548.18	25438
1550.28	25306
1552.38	25122
1554.48	24816
1556.57	24948
1558.67	24846
1560.77	24702
1562.87	24758
1564.96	24610
1567.06	24538
1569.15	24362
1571.25	24286
1573.34	24282
1575.43	24224
1577.53	24096
1579.62	23972
1581.71	24016
1583.8	23692
1585.89	23810
1587.98	23862
1590.06	23620
1592.15	23638
1594.24	23690
1596.33	23568
1598.41	23730
1600.5	23398
1602.58	23388
1604.66	23450
1606.75	23164
1608.83	23252
1610.91	23258
1612.99	23174
1615.07	23130
1617.15	22934
1619.23	22932
1621.31	22774
1623.39	23182
1625.46	22790
1627.54	22630
1629.62	22750
1631.69	22680
1633.77	22528
1635.84	22524
1637.91	22426
1639.99	22280
1642.06	22228
1644.13	22354
1646.2	22226
1648.27	22018
1650.34	21914
1652.41	22006
1654.47	21880
1656.54	22004
1658.61	21778
1660.67	21728
1662.74	21622
1664.81	21514
1666.87	21558
1668.93	21374
1671	21432
1673.06	21088
1675.12	21166
1677.18	21158
1679.24	21182
1681.3	20948
1683.36	20966
1685.42	20764
1687.47	20764
1689.53	20712
1691.59	20762
1693.64	20542
1695.7	20566
1697.75	20440
1699.81	20400
1701.86	20504
1703.91	20292
1705.97	20320
1708.02	20156
1710.07	20162
1712.12	20080
1714.17	19982
1716.22	20100
1718.26	20124
1720.31	19924
1722.36	19764
1724.4	19864
1726.45	19894
1728.49	19692
1730.54	19804
1732.58	19646
1734.63	19496
1736.67	19630
1738.71	19550
1740.75	19284
1742.79	19432
1744.83	19464
1746.87	19378
1748.91	19494
1750.95	19324
1752.98	19222
1755.02	19392
1757.06	19214
1759.09	19478
1761.13	19316
1763.16	19294
1765.19	19164
1767.23	19124
1769.26	19032
1771.29	19228
1773.32	19224
1775.35	19026
1777.38	18928
1779.41	19054
1781.44	19232
1783.47	19096
1785.49	19060
1787.52	18908
1789.55	18898
1791.57	18862
1793.6	18862
1795.62	18796
1797.64	18846
1799.67	18786
1801.69	18794
1803.71	18852
1805.73	18640
1807.75	18702
1809.77	18694
1811.79	18636
1813.81	18724
1815.83	18532
1817.84	18494
1819.86	18290
1821.88	18420
1823.89	18482
1825.91	18382
1827.92	18300
1829.93	18296
1831.95	18302
1833.96	18234
1835.97	18272
1837.98	18210
1839.99	18184
1842	18046
1844.01	18024
1846.02	18016
1848.03	18002
1850.03	17910
1852.04	18050
1854.05	17834
1856.05	17844
1858.06	17798
1860.06	17632
1862.06	17888
1864.07	17746
1866.07	17902
1868.07	17790
1870.07	17656
1872.07	17590
1874.07	17616
1876.07	17566
1878.07	17662
1880.07	17514
1882.07	17574
1884.06	17506
1886.06	17570
1888.05	17342
1890.05	17370
1892.04	17592
1894.04	17394
1896.03	17550
1898.02	17504
1900.01	17394
1902	17500
1903.99	17516
1905.98	17422
1907.97	17540
1909.96	17356
1911.95	17416
1913.94	17460
1915.93	17284
1917.91	17388
1919.9	17458
1921.88	17178
1923.87	17126
1925.85	17184
1927.83	17210
1929.82	17320
1931.8	17202
1933.78	17050
1935.76	17180
1937.74	17142
1939.72	17256
1941.7	17180
1943.68	17172
1945.65	17118
1947.63	16936
1949.61	16994
1951.58	16968
1953.56	16944
1955.53	16974
1957.51	16730
1959.48	16894
1961.45	16906
1963.43	16782
1965.4	16974
1967.37	16994
1969.34	16726
1971.31	16722
1973.28	16796
1975.25	16720
1977.22	16556
1979.18	16580
1981.15	16538
1983.12	16712
1985.08	16494
1987.05	16500
1989.01	16664
1990.97	16540
1992.94	16584
1994.9	16516
1996.86	16370
1998.82	16554
2000.78	16520
2002.74	16462
2004.7	16436
2006.66	16400
2008.62	16434
2010.58	16344
2012.54	16434
2014.49	16390
2016.45	16444
2018.4	16458
2020.36	16360
2022.31	16396
2024.27	16360
2026.22	16430
2028.17	16325
2030.12	16206
2032.07	16290
2034.03	16256
2035.98	16216
2037.93	16258
2039.87	16102
2041.82	16202
2043.77	16126
2045.72	16130
2047.66	16138
2049.61	16250
2051.55	16120
2053.5	16148
2055.44	15952
2057.39	16078
2059.33	16074
2061.27	16060
2063.21	16092
2065.15	15962
2067.09	15918
2069.03	15814
2070.97	16058
2072.91	15850
2074.85	15956
2076.79	16072
2078.73	15974
2080.66	15886
2082.6	15960
2084.53	15858
2086.47	15814
2088.4	15868
2090.33	15736
2092.27	15830
2094.2	15828
2096.13	15750
2098.06	15840
2099.99	15662
2101.92	15838
2103.85	15746
2105.78	15856
2107.71	15792
2109.64	15786
2111.56	15656
2113.49	15620
2115.41	15642
2117.34	15660
2119.26	15538
2121.19	15762
2123.11	15618
2125.03	15524
2126.96	15592
2128.88	15548
2130.8	15490
2132.72	15718
2134.64	15496
2136.56	15404
2138.48	15492
2140.4	15494
2142.31	15458
2144.23	15354
2146.15	15482
2148.06	15396
2149.98	15498
2151.89	15310
2153.81	15356
2155.72	15218
2157.63	15462
2159.55	15242
2161.46	15244
2163.37	15268
2165.28	15130
2167.19	15200
2169.1	15162
2171.01	15252
2172.91	14930
2174.82	15086
2176.73	15134
2178.64	15002
2180.54	15028
2182.45	14854
2184.35	14882
2186.26	14880
2188.16	14848
2190.06	14920
2191.96	14876
2193.87	14724
2195.77	14710
2197.67	14718
2199.57	14786
2201.47	14650
2203.37	14600
2205.27	14786
2207.16	14636
2209.06	14686
2210.96	14756
2212.85	14608
2214.75	14634
2216.64	14640
2218.54	14678
2220.43	14696
2222.33	14688
2224.22	14545.4
2226.11	14439.9
2228	14498.7
2229.89	14376.8
2231.78	14290
2233.67	14313.5
2235.56	14258.8
2237.45	14079.5
2239.34	14061.9
2241.23	14112
2243.11	13945
2245	13933.3
2246.89	13784.6
2248.77	13847.2
2250.66	13619.5
2252.54	13555
2254.42	13628.9
2256.31	13498.5
2258.19	13467.3
2260.07	13430.4
2261.95	13274.4
2263.83	13222.1
2265.71	13242
2267.59	13076.4
2269.47	12961.6
2271.35	13012.9
2273.23	12884.2
2275.1	12743.1
2276.98	12823.3
2278.86	12708.5
2280.73	12563.3
2282.61	12484.6
2284.48	12509.9
2286.36	12393.7
2288.23	12293.5
2290.1	12286.5
2291.98	12226.5
2293.85	12066.7
2295.72	12046
2297.59	11926.3
2299.46	11949.8
2301.33	11845.8
2303.2	11709.7
2305.06	11654.6
2306.93	11627.2
2308.8	11581.8
2310.67	11425.5
2312.53	11345.9
2314.4	11306.4
2316.26	11229.7
2317.62	11274
2319.5	11190
2321.37	11114
2323.24	11086
2325.12	11048
2326.99	11118
2328.86	11056
2330.73	11088
2332.6	11186
2334.47	11122
2336.34	11032
2338.2	11020
2340.07	11078
2341.94	10892
2343.81	11032
2345.67	10930
2347.54	10904
2349.4	10830
2351.27	10962
2353.13	10860
2354.99	10898
2356.86	10766
2358.72	10914
2360.58	10824
2362.44	10832
2364.3	10792
2366.16	10722
2368.02	10742
2369.88	10606
2371.74	10608
2373.6	10568
2375.45	10602
2377.31	10548
2379.17	10614
2381.02	10586
2382.88	10584
2384.73	10410
2386.58	10408
2388.44	10482
2390.29	10426
2392.14	10372
2393.99	10512
2395.85	10330
2397.7	10322
2399.55	10218
2401.4	10354
2403.25	10318
2405.09	10244
2406.94	10098
2408.79	10164
2410.63	10110
2412.48	10268
2414.33	9940
2416.17	10130
2418.02	10010
2419.86	10074
2421.7	9820
2423.55	9796
2425.39	9856
2427.23	9896
2429.07	9860
2430.91	9872
2432.75	9794
2434.59	9844
2436.43	9746
2438.27	9620
2440.11	9738
2441.95	9734
2443.78	9604
2445.62	9622
2447.46	9612
2449.29	9638
2451.13	9564
2452.96	9510
2454.79	9426
2456.63	9392
2458.46	9442
2460.29	9444
2462.12	9220
2463.95	9166
2465.78	9292
2467.61	9196
2469.44	9210
2471.27	9198
2473.1	9188
2474.93	9138
2476.76	9032
2478.58	9086
2480.41	9046
2482.23	9016
2484.06	8972
2485.88	8936
2487.71	8890
2489.53	8950
2491.35	8878
2493.18	8768
2495	8820
2496.82	8690
2498.64	8734
2500.46	8752
2502.28	8782
2504.1	8678
2505.92	8580
2507.74	8642
2509.55	8468
2511.37	8564
2513.19	8504
2515	8514
2516.82	8510
2518.63	8424
2520.45	8430
2522.26	8400
2524.07	8336
2525.89	8260
2527.7	8328
2529.51	8300
2531.32	8234
2533.13	8066
2534.94	8174
2536.75	8166
2538.56	8048
2540.37	8174
2542.18	8066
2543.98	8042
2545.79	7880
2547.6	8030
2549.4	7954
2551.21	7874
2553.01	7852
2554.82	7766
2556.62	7860
2558.42	7808
2560.23	7944
2562.03	7766
2563.83	7780
2565.63	7708
2567.43	7712
2569.23	7648
2571.03	7726
2572.83	7632
2574.63	7604
2576.43	7556
2578.22	7390
2580.02	7438
2581.82	7440
2583.61	7360
2585.41	7390
2587.2	7232
2589	7298
2590.79	7330
2592.58	7368
2594.38	7178
2596.17	7230
2597.96	7188
2599.75	7172
2601.54	7080
2603.33	7164
2605.12	7048
2606.91	7056
2608.7	7012
2610.49	6990
2612.27	6922
2614.06	6990
2615.85	6984
2617.63	6806
2619.42	6876
2621.2	6876
2622.99	6878
2624.77	6856
2626.55	6790
2628.34	6816
2630.12	6766
2631.9	6718
2633.68	6756
2635.46	6676
2637.24	6696
2639.02	6630
2640.8	6594
2642.58	6554
2644.36	6482
2646.14	6420
2647.91	6418
2649.69	6502
2651.46	6346
2653.24	6448
2655.01	6406
2656.79	6488
2658.56	6374
2660.34	6156
2662.11	6216
2663.88	6364
2665.65	6254
2667.42	6186
2669.2	6278
2670.96	6202
2672.73	6088
2674.5	6100
2676.27	6174
2678.04	6146
2679.81	6168
2681.58	6006
2683.34	6114
2685.11	6026
2686.87	5926
2688.64	5954
2690.4	5934
2692.17	5952
2693.93	5848
2695.69	5906
2697.46	5750
2699.22	5794
2700.98	5784
2702.74	5736
2704.5	5704
2706.26	5686
2708.02	5656
2709.78	5640
2711.54	5598
2713.3	5620
2715.05	5512
2716.81	5572
2718.57	5640
2720.32	5524
2722.08	5530
2723.83	5458
2725.59	5456
2727.34	5366
2729.09	5402
2730.85	5368
2732.6	5342
2734.35	5304
2736.1	5280
2737.85	5294
2739.6	5298
2741.35	5220
2743.1	5216
2744.85	5214
2746.6	5144
2748.35	5096
2750.09	5144
2751.84	5100
2753.59	5056
2755.33	5074
2757.08	5018
2758.82	5004
2760.57	5010
2762.31	4964
2764.05	4998
2765.79	4916
2767.54	4930
2769.28	4890
2771.02	4846
2772.76	4826
2774.5	4812
2776.24	4866
2777.98	4804
2779.72	4772
2781.46	4730
2783.19	4666
2784.93	4724
2786.67	4722
2788.4	4704
2790.14	4646
2791.87	4636
2793.61	4618
2795.34	4572
2797.07	4574
2798.81	4590
2800.54	4462
2802.27	4440
2804	4526
2805.74	4456
2807.47	4490
2809.2	4452
2810.93	4422
2812.65	4432
2814.38	4322
2816.11	4352
2817.84	4360
2819.56	4270
2821.29	4354
2823.02	4330
2824.74	4304
2826.47	4238
2828.19	4178
2829.92	4144
2831.64	4138
2833.36	4188
2835.09	4166
2836.81	4094
2838.53	4148
2840.25	4118
2841.97	4058
2843.69	4082
2845.41	4030
2847.13	3986
2848.85	3988
2850.57	3916
2852.28	3972
2854	3888
2855.72	3868
2857.43	3844
2859.15	3902
2860.86	3842
2862.58	3804
2864.29	3832
2866.01	3914
2867.72	3858
2869.43	3782
2871.14	3680
2872.86	3804
2874.57	3664
2876.28	3658
2877.99	3626
2879.7	3658
2881.41	3638
2883.11	3682
2884.82	3616
2886.53	3618
2888.24	3618
2889.94	3552
2891.65	3582
2893.36	3562
2895.06	3586
2896.77	3552
2898.47	3598
2900.17	3426
2901.88	3540
2903.58	3426
2905.28	3442
2906.98	3418
2908.69	3434
2910.39	3508
2912.09	3446
2913.79	3358
2915.49	3430
2917.19	3350
2918.88	3372
2920.58	3336
2922.28	3374
2923.98	3324
2925.67	3348
2927.37	3292
2929.06	3224
2930.76	3282
2932.45	3236
2934.15	3230
2935.84	3258
2937.53	3184
2939.23	3244
2940.92	3146
2942.61	3256
2944.3	3234
2945.99	3160
2947.68	3184
2949.37	3176
2951.06	3132
2952.75	3144
2954.44	3130
2956.12	3114
2957.81	3056
2959.5	3110
2961.18	3024
2962.87	3080
2964.56	3006
2966.24	3082
2967.92	3076
2969.61	3056
2971.29	2970
2972.97	2974
2974.66	3008
2976.34	2948
2978.02	2946
2979.7	2972
2981.38	2954
2983.06	2900
2984.74	2954
2986.42	2824
2988.1	2866
2989.78	2858
2991.45	2854
2993.13	2840
2994.81	2862
2996.48	2778
2998.16	2792
2999.83	2842