File: muestras/nopal/inside_prf_04.txt
#Acq. time (s)=	15
#Accumulations=	2
#Range (cm-¹)=	200...3000
#Windows=	3
#Autofocus=	Off
#AutoExposure=	Off
#Spike filter=	Multiple accum.
#Delay time (s)=	0
#Binning=	1
#Readout mode=	Signal
#DeNoise=	Off
#ICS correction=	Off
#Dark correction=	Off
#Inst. Process=	Off
#Instrument=	LabRAM HR Evol
#Detector=	Syncerity OE
#Objective=	x100_VIS
#Grating=	600 (500nm)
#ND Filter=	10%
#Laser=	633nm_Edge
#Hole=	49.98
#Range=	Visible
#Project=	Omar
#Sample=	03-07-23
#Site=	nop
#Title=	inside_prf
#Remark=
#Date=	03.07.2023 14:16
#Acquired=	03.07.2023 14:16:20
201.713	2472
204.247	2502
206.778	2548
209.311	2566
211.84	2592
214.371	2664
216.899	2702
219.428	2670
221.955	2760
224.482	2696
227.007	2650
229.531	2650
232.055	2702
234.579	2806
237.1	2846
239.621	2860
242.141	2906
244.661	2890
247.179	2930
249.698	2936
252.215	2988
254.731	2986
257.246	3038
259.761	2966
262.273	3060
264.786	3050
267.298	3020
269.809	3040
272.319	3122
274.828	3038
277.336	3016
279.844	3090
282.351	3092
284.855	3202
287.361	3168
289.866	3254
292.368	3248
294.871	3326
297.372	3326
299.873	3336
302.372	3366
304.872	3410
307.37	3514
309.866	3504
312.364	3480
314.859	3446
317.353	3532
319.848	3580
322.341	3656
324.833	3580
327.324	3672
329.814	3654
332.304	3664
334.792	3748
337.28	3708
339.767	3790
342.254	3814
344.739	3894
347.224	3914
349.708	3906
352.191	3876
354.673	3960
357.155	3992
359.634	4008
362.114	3976
364.593	4084
367.07	4104
369.548	4036
372.024	4128
374.499	4198
376.974	4222
379.447	4190
381.92	4242
384.392	4350
386.864	4300
389.333	4360
391.802	4380
394.272	4366
396.739	4432
399.206	4414
401.673	4560
404.138	4558
406.602	4594
409.066	4656
411.528	4708
413.99	4742
416.451	4782
418.911	4818
421.371	4928
423.83	4914
426.288	4898
428.745	4990
431.201	4964
433.657	4982
436.111	5120
438.565	5168
441.017	5098
443.469	5242
445.921	5182
448.37	5260
450.821	5320
453.27	5350
455.717	5248
458.165	5270
460.61	5354
463.056	5464
465.5	5432
467.945	5518
470.387	5556
472.829	5572
475.271	5596
477.711	5624
480.15	5694
482.589	5706
485.027	5758
487.465	5816
489.901	5896
492.337	5830
494.771	5908
497.205	5924
499.638	6066
502.07	6058
504.502	6066
506.933	6108
509.363	6224
511.792	6162
514.219	6156
516.647	6318
519.073	6310
521.5	6314
523.924	6270
526.348	6394
528.772	6402
531.194	6392
533.616	6444
536.036	6508
538.457	6510
540.875	6538
543.294	6554
545.712	6596
548.128	6714
550.545	6708
552.959	6716
555.373	6772
557.788	6856
560.2	6822
562.612	6940
565.023	6924
567.433	6988
569.843	7118
572.251	7084
574.659	7122
577.066	7172
579.472	7300
581.878	7306
584.283	7432
586.687	7314
589.09	7452
591.493	7462
593.893	7516
596.294	7632
598.694	7622
601.093	7772
603.491	7830
605.889	7834
608.285	7944
610.682	8046
613.076	8100
615.471	8158
617.864	8244
620.256	8282
622.648	8366
625.039	8444
627.429	8464
629.819	8508
632.208	8572
634.595	8668
636.982	8832
639.369	8958
641.755	8932
644.139	9090
646.523	9200
648.906	9226
651.288	9328
653.67	9454
656.051	9442
658.429	9470
660.808	9592
663.187	9528
665.565	9580
667.942	9770
670.317	9866
672.692	9878
675.067	9914
677.44	10122
679.813	10000
682.184	10202
684.556	10288
686.926	10456
689.296	10550
691.664	10564
694.033	10722
696.4	10712
698.766	10732
701.133	10824
703.497	11060
705.861	11188
708.224	11298
710.586	11342
712.949	11450
715.31	11496
717.67	11704
720.029	11648
722.388	11944
724.746	12152
727.103	12010
729.458	12210
731.814	12428
734.168	12376
736.523	12536
738.876	12780
741.227	12784
743.579	12916
745.931	13078
748.28	13240
750.629	13202
752.977	13272
755.325	13640
757.672	13490
760.018	13740
762.363	13910
764.708	14078
767.052	14154
769.394	14158
771.737	14266
774.078	14516
776.419	14622
778.758	14622
781.097	15000
783.435	15106
785.773	15270
788.11	15348
790.446	15486
792.781	15642
795.115	15804
797.449	16042
799.782	16190
802.115	16450
804.446	16640
806.777	16762
809.106	17016
811.435	17002
813.764	17248
816.091	17384
818.418	17670
820.743	17950
823.069	17982
825.393	18346
827.717	18460
830.039	18710
832.362	18714
834.683	19102
837.003	19216
839.324	19580
841.643	19822
843.961	19934
846.278	20190
848.594	20360
850.91	20484
853.227	20870
855.541	21096
857.855	21164
860.168	21554
862.48	21792
864.79	21988
867.101	22144
869.411	22470
871.721	22592
874.029	22712
876.336	22930
878.643	23356
880.95	23362
883.254	23530
885.559	23678
887.862	23808
890.166	24138
892.467	24254
894.77	24604
897.07	24758
899.371	25080
901.669	25234
903.968	25534
906.266	25624
908.563	26100
910.859	26270
913.154	26490
915.449	26752
917.742	26886
920.036	26980
922.329	27506
924.621	27778
926.911	27894
929.201	28454
931.49	28440
933.779	28818
936.068	29000
938.355	29492
940.64	29778
942.926	29988
945.212	30322
947.495	30602
949.779	31076
952.062	31248
954.344	31482
956.625	31858
958.905	32194
961.184	32630
963.464	32850
965.742	33016
968.02	33484
970.296	33926
972.572	33882
974.847	34276
977.121	34518
979.396	34794
981.669	35270
983.941	35508
986.212	35812
988.483	36076
990.753	36224
993.022	36740
995.29	36804
997.558	37334
999.825	37458
1002.09	37654
1004.36	38150
1006.62	38300
1008.89	38786
1011.15	39116
1013.41	39756
1015.67	40234
1017.93	40312
1020.19	40508
1022.45	41122
1024.71	41242
1026.97	41948
1029.23	42348
1031.49	42470
1033.74	42924
1036	43254
1038.25	43794
1040.5	43930
1042.76	44506
1045.01	44972
1047.26	44960
1049.51	45908
1051.76	45902
1054.01	46386
1056.26	46964
1058.51	47396
1060.75	47662
1063	47998
1065.25	48358
1067.49	48788
1069.73	49098
1071.98	49362
1074.22	49592
1076.46	49920
1078.7	50094
1080.94	50300
1083.18	51044
1085.42	50850
1087.66	50994
1089.9	51360
1092.14	51580
1094.37	51784
1096.61	52348
1098.84	52240
1101.08	52688
1103.31	52812
1105.54	52756
1107.77	53286
1110	53834
1112.23	53720
1114.46	54212
1116.69	54224
1118.92	54572
1121.15	55268
1123.37	55414
1125.6	55688
1127.83	55804
1130.05	56150
1132.27	56648
1134.5	56978
1136.72	56932
1138.94	57390
1141.16	57556
1143.38	57828
1145.6	57968
1147.82	58298
1150.04	58722
1152.26	58890
1154.47	59008
1156.69	59290
1158.9	59584
1161.12	59438
1163.33	59986
1165.54	59920
1167.76	60030
1169.97	60428
1172.18	60130
1174.39	60382
1176.6	60710
1178.81	60358
1181.02	60286
1183.22	60170
1185.43	60292
1187.63	60304
1189.84	60406
1192.04	60138
1194.25	59942
1196.45	60180
1198.65	59720
1200.85	59742
1203.05	59420
1205.25	59400
1207.45	59156
1209.65	59280
1211.85	58814
1214.05	58920
1216.24	58656
1218.44	58480
1220.64	58162
1222.83	58156
1225.02	58064
1227.22	57932
1229.41	57926
1231.6	57526
1233.79	57486
1235.98	57280
1238.17	57042
1240.36	57182
1242.55	57334
1244.73	56774
1246.92	56490
1249.11	56258
1251.29	56236
1253.48	56304
1255.66	56204
1257.84	55560
1260.03	55612
1262.21	55662
1264.39	55558
1266.57	55436
1268.75	54964
1270.93	55254
1273.11	54818
1275.28	54414
1277.46	54676
1279.64	54278
1281.81	53822
1283.98	53599.7
1286.16	53650.2
1288.33	53377.6
1290.5	53087.5
1292.68	52661.4
1294.85	52860.7
1297.02	52442.5
1299.19	52160.3
1301.36	52141.3
1303.53	51724
1305.69	51566.8
1307.86	51385.7
1310.03	50946.9
1312.19	50901.1
1314.36	50412.6
1316.52	50458.7
1318.68	50213.4
1320.85	50099
1323.01	49739.5
1325.17	49396.8
1327.33	49218
1329.49	48960.8
1331.65	48493.2
1333.81	48453
1335.97	48191.3
1338.12	47899.3
1340.28	47753.2
1342.44	47754.7
1344.59	47200.5
1346.75	47013.8
1348.9	46952.5
1351.05	46637.8
1353.2	46339
1355.36	46354.4
1357.51	46058.8
1359.66	45924.6
1361.81	45735.9
1363.96	45333.4
1366.1	45407.1
1368.25	45188.4
1370.4	45088
1372.54	44711.2
1374.69	44640.4
1376.83	44460.1
1378.98	44219.9
1381.12	44074.2
1383.26	43912.9
1385.41	43783.7
1387.55	43638.6
1389.69	43350.4
1391.83	43065.6
1393.02	43240
1395.17	43040
1397.32	42830
1399.47	42718
1401.62	42380
1403.77	42224
1405.91	41990
1408.06	41538
1410.2	41770
1412.35	41382
1414.49	41260
1416.63	41064
1418.78	40874
1420.92	40662
1423.06	40484
1425.2	40294
1427.34	40068
1429.48	40034
1431.61	40162
1433.75	39796
1435.89	39584
1438.02	39390
1440.16	39228
1442.3	39312
1444.43	38996
1446.56	38670
1448.7	38624
1450.83	38584
1452.96	38454
1455.09	38356
1457.22	38188
1459.35	37896
1461.48	37748
1463.61	37726
1465.73	37608
1467.86	37450
1469.98	37604
1472.11	37300
1474.24	37086
1476.36	37146
1478.48	37034
1480.6	36650
1482.73	36864
1484.85	36782
1486.97	36466
1489.09	36384
1491.21	36336
1493.33	35988
1495.44	35934
1497.56	35750
1499.68	35704
1501.79	35756
1503.91	35274
1506.02	35332
1508.14	35174
1510.25	35098
1512.36	34768
1514.48	34752
1516.59	34674
1518.7	34396
1520.81	34250
1522.92	34228
1525.02	33800
1527.13	33998
1529.24	33916
1531.35	33670
1533.45	33474
1535.56	33054
1537.66	33430
1539.77	33144
1541.87	32748
1543.97	32920
1546.08	32670
1548.18	32676
1550.28	32390
1552.38	32460
1554.48	32202
1556.57	32134
1558.67	31944
1560.77	31908
1562.87	31784
1564.96	31846
1567.06	31592
1569.15	31680
1571.25	31318
1573.34	31282
1575.43	31450
1577.53	31122
1579.62	31050
1581.71	31016
1583.8	30878
1585.89	30974
1587.98	30862
1590.06	30634
1592.15	30678
1594.24	30592
1596.33	30540
1598.41	30584
1600.5	30496
1602.58	30444
1604.66	30338
1606.75	30230
1608.83	30412
1610.91	30136
1612.99	30114
1615.07	30118
1617.15	29968
1619.23	29830
1621.31	29870
1623.39	30026
1625.46	29918
1627.54	29614
1629.62	29888
1631.69	29594
1633.77	29482
1635.84	29426
1637.91	29362
1639.99	29486
1642.06	29200
1644.13	29164
1646.2	29072
1648.27	29136
1650.34	29068
1652.41	29078
1654.47	28934
1656.54	28696
1658.61	28982
1660.67	28710
1662.74	28520
1664.81	28540
1666.87	28400
1668.93	28232
1671	28244
1673.06	28236
1675.12	28114
1677.18	27984
1679.24	28020
1681.3	27978
1683.36	27660
1685.42	27870
1687.47	27598
1689.53	27542
1691.59	27434
1693.64	27174
1695.7	27136
1697.75	27324
1699.81	27230
1701.86	27074
1703.91	27034
1705.97	26968
1708.02	27002
1710.07	26764
1712.12	26988
1714.17	26980
1716.22	26782
1718.26	26586
1720.31	26614
1722.36	26564
1724.4	26504
1726.45	26520
1728.49	26278
1730.54	26318
1732.58	26290
1734.63	26258
1736.67	26328
1738.71	26216
1740.75	26296
1742.79	26184
1744.83	26334
1746.87	26174
1748.91	25916
1750.95	25982
1752.98	26012
1755.02	25992
1757.06	26122
1759.09	26048
1761.13	25906
1763.16	25864
1765.19	25906
1767.23	26034
1769.26	25906
1771.29	26002
1773.32	25930
1775.35	25758
1777.38	25790
1779.41	25846
1781.44	25786
1783.47	25748
1785.49	25600
1787.52	25788
1789.55	25488
1791.57	25832
1793.6	25422
1795.62	25406
1797.64	25472
1799.67	25636
1801.69	25602
1803.71	25446
1805.73	25438
1807.75	25272
1809.77	25380
1811.79	25262
1813.81	25190
1815.83	25178
1817.84	25260
1819.86	25132
1821.88	25364
1823.89	24928
1825.91	25210
1827.92	25042
1829.93	25012
1831.95	24746
1833.96	24876
1835.97	24772
1837.98	24722
1839.99	24682
1842	24690
1844.01	24578
1846.02	24632
1848.03	24410
1850.03	24358
1852.04	24322
1854.05	24504
1856.05	24290
1858.06	24286
1860.06	24452
1862.06	24250
1864.07	24410
1866.07	24482
1868.07	24266
1870.07	24216
1872.07	24186
1874.07	24220
1876.07	24046
1878.07	24258
1880.07	24188
1882.07	23968
1884.06	24130
1886.06	23974
1888.05	23998
1890.05	23934
1892.04	24082
1894.04	23890
1896.03	24116
1898.02	23932
1900.01	23964
1902	23912
1903.99	23990
1905.98	24000
1907.97	23846
1909.96	23780
1911.95	24026
1913.94	23844
1915.93	23976
1917.91	23764
1919.9	24050
1921.88	23632
1923.87	23808
1925.85	23524
1927.83	23836
1929.82	23836
1931.8	23824
1933.78	23724
1935.76	23790
1937.74	23782
1939.72	23650
1941.7	23458
1943.68	23692
1945.65	23434
1947.63	23520
1949.61	23462
1951.58	23488
1953.56	23484
1955.53	23404
1957.51	23270
1959.48	23414
1961.45	23406
1963.43	23268
1965.4	23166
1967.37	23222
1969.34	23232
1971.31	23222
1973.28	23216
1975.25	22984
1977.22	22982
1979.18	23018
1981.15	23140
1983.12	22814
1985.08	22836
1987.05	23000
1989.01	23176
1990.97	22862
1992.94	22778
1994.9	22906
1996.86	22848
1998.82	22912
2000.78	22602
2002.74	22904
2004.7	22782
2006.66	22494
2008.62	22836
2010.58	22822
2012.54	22952
2014.49	22700
2016.45	22654
2018.4	22752
2020.36	22608
2022.31	22754
2024.27	22656
2026.22	22692
2028.17	22682
2030.12	22762
2032.07	22592
2034.03	22608
2035.98	22510
2037.93	22556
2039.87	22626
2041.82	22460
2043.77	22402
2045.72	22432
2047.66	22422
2049.61	22400
2051.55	22594
2053.5	22542
2055.44	22328
2057.39	22406
2059.33	22476
2061.27	22270
2063.21	22444
2065.15	22234
2067.09	22366
2069.03	22244
2070.97	22220
2072.91	22194
2074.85	22234
2076.79	22252
2078.73	22132
2080.66	22132
2082.6	22010
2084.53	22064
2086.47	22158
2088.4	21966
2090.33	22150
2092.27	22162
2094.2	22190
2096.13	21870
2098.06	22072
2099.99	22012
2101.92	21958
2103.85	21954
2105.78	21890
2107.71	22062
2109.64	21898
2111.56	21822
2113.49	21842
2115.41	22086
2117.34	22076
2119.26	21918
2121.19	21914
2123.11	21842
2125.03	21948
2126.96	21854
2128.88	21948
2130.8	21760
2132.72	21718
2134.64	21784
2136.56	21644
2138.48	21782
2140.4	21694
2142.31	21566
2144.23	21684
2146.15	21532
2148.06	21640
2149.98	21610
2151.89	21448
2153.81	21498
2155.72	21454
2157.63	21338
2159.55	21450
2161.46	21352
2163.37	21436
2165.28	21416
2167.19	21202
2169.1	21300
2171.01	21188
2172.91	21130
2174.82	21160
2176.73	21106
2178.64	21048
2180.54	21070
2182.45	21040
2184.35	20968
2186.26	20938
2188.16	20980
2190.06	20890
2191.96	20878
2193.87	20854
2195.77	20528
2197.67	20754
2199.57	20592
2201.47	20574
2203.37	20748
2205.27	20666
2207.16	20572
2209.06	20648
2210.96	20556
2212.85	20682
2214.75	20628
2216.64	20600
2218.54	20694
2220.43	20690
2222.33	20480
2224.22	20527.9
2226.11	20516.4
2228	20509.4
2229.89	20626.4
2231.78	20577.1
2233.67	20677
2235.56	20588.4
2237.45	20588.1
2239.34	20709.6
2241.23	20639.5
2243.11	20666
2245	20613.1
2246.89	20564.4
2248.77	20605.4
2250.66	20624.4
2252.54	20604.3
2254.42	20596.4
2256.31	20577.2
2258.19	20552
2260.07	20491
2261.95	20680.5
2263.83	20632.3
2265.71	20551
2267.59	20664.9
2269.47	20562.5
2271.35	20565.7
2273.23	20628.6
2275.1	20460.4
2276.98	20431.8
2278.86	20554.8
2280.73	20480
2282.61	20432.2
2284.48	20368.9
2286.36	20460.5
2288.23	20441.2
2290.1	20426.6
2291.98	20519.3
2293.85	20457.3
2295.72	20290
2297.59	20365.5
2299.46	20444.5
2301.33	20379.8
2303.2	20341.2
2305.06	20273.4
2306.93	20232.9
2308.8	20220
2310.67	20192.4
2312.53	20263.3
2314.4	20133.8
2316.26	20192.3
2317.62	20072
2319.5	20150
2321.37	20186
2323.24	20102
2325.12	19934
2326.99	19898
2328.86	20112
2330.73	19974
2332.6	19946
2334.47	19726
2336.34	19868
2338.2	19786
2340.07	19956
2341.94	19856
2343.81	19892
2345.67	19676
2347.54	19818
2349.4	19730
2351.27	19780
2353.13	19662
2354.99	19524
2356.86	19640
2358.72	19544
2360.58	19576
2362.44	19570
2364.3	19390
2366.16	19346
2368.02	19340
2369.88	19310
2371.74	19198
2373.6	19248
2375.45	19092
2377.31	19222
2379.17	19232
2381.02	19136
2382.88	19044
2384.73	19088
2386.58	18928
2388.44	18932
2390.29	18992
2392.14	18834
2393.99	18848
2395.85	18872
2397.7	18664
2399.55	18652
2401.4	18722
2403.25	18544
2405.09	18546
2406.94	18428
2408.79	18472
2410.63	18308
2412.48	18362
2414.33	18304
2416.17	18168
2418.02	18072
2419.86	18256
2421.7	17920
2423.55	18020
2425.39	18014
2427.23	17848
2429.07	17912
2430.91	17848
2432.75	17796
2434.59	17756
2436.43	17766
2438.27	17676
2440.11	17666
2441.95	17524
2443.78	17634
2445.62	17488
2447.46	17476
2449.29	17354
2451.13	17294
2452.96	17352
2454.79	17220
2456.63	17148
2458.46	17144
2460.29	17040
2462.12	17114
2463.95	16970
2465.78	16932
2467.61	16890
2469.44	16882
2471.27	16922
2473.1	16834
2474.93	16764
2476.76	16684
2478.58	16642
2480.41	16480
2482.23	16416
2484.06	16496
2485.88	16546
2487.71	16374
2489.53	16318
2491.35	16214
2493.18	16216
2495	16106
2496.82	16166
2498.64	16066
2500.46	16080
2502.28	15996
2504.1	15872
2505.92	15748
2507.74	15820
2509.55	15742
2511.37	15632
2513.19	15628
2515	15648
2516.82	15594
2518.63	15552
2520.45	15452
2522.26	15330
2524.07	15382
2525.89	15284
2527.7	15252
2529.51	15142
2531.32	15198
2533.13	15106
2534.94	15000
2536.75	14890
2538.56	14978
2540.37	14798
2542.18	14860
2543.98	14868
2545.79	14700
2547.6	14738
2549.4	14776
2551.21	14630
2553.01	14650
2554.82	14472
2556.62	14510
2558.42	14418
2560.23	14416
2562.03	14332
2563.83	14320
2565.63	14194
2567.43	14270
2569.23	14118
2571.03	14202
2572.83	14080
2574.63	14028
2576.43	13956
2578.22	13922
2580.02	13804
2581.82	13774
2583.61	13750
2585.41	13800
2587.2	13700
2589	13608
2590.79	13552
2592.58	13654
2594.38	13498
2596.17	13376
2597.96	13430
2599.75	13400
2601.54	13220
2603.33	13318
2605.12	13246
2606.91	13096
2608.7	13066
2610.49	13024
2612.27	13060
2614.06	12916
2615.85	12954
2617.63	12894
2619.42	12860
2621.2	12794
2622.99	12752
2624.77	12756
2626.55	12688
2628.34	12562
2630.12	12446
2631.9	12614
2633.68	12348
2635.46	12380
2637.24	12498
2639.02	12284
2640.8	12308
2642.58	12156
2644.36	12248
2646.14	12162
2647.91	12072
2649.69	12118
2651.46	11982
2653.24	12008
2655.01	11942
2656.79	11910
2658.56	11724
2660.34	11762
2662.11	11696
2663.88	11884
2665.65	11790
2667.42	11634
2669.2	11584
2670.96	11474
2672.73	11614
2674.5	11612
2676.27	11492
2678.04	11518
2679.81	11418
2681.58	11476
2683.34	11222
2685.11	11172
2686.87	11244
2688.64	11234
2690.4	11232
2692.17	11254
2693.93	11136
2695.69	11050
2697.46	10936
2699.22	10904
2700.98	10852
2702.74	10850
2704.5	10784
2706.26	10774
2708.02	10770
2709.78	10692
2711.54	10658
2713.3	10624
2715.05	10426
2716.81	10556
2718.57	10574
2720.32	10380
2722.08	10392
2723.83	10374
2725.59	10400
2727.34	10170
2729.09	10082
2730.85	10230
2732.6	10124
2734.35	10082
2736.1	10156
2737.85	9978
2739.6	9928
2741.35	9888
2743.1	9866
2744.85	9856
2746.6	9870
2748.35	9748
2750.09	9686
2751.84	9674
2753.59	9712
2755.33	9570
2757.08	9544
2758.82	9550
2760.57	9594
2762.31	9416
2764.05	9500
2765.79	9424
2767.54	9348
2769.28	9260
2771.02	9260
2772.76	9172
2774.5	9194
2776.24	9150
2777.98	9144
2779.72	8982
2781.46	8990
2783.19	8992
2784.93	8954
2786.67	9034
2788.4	8954
2790.14	8864
2791.87	8864
2793.61	8776
2795.34	8722
2797.07	8626
2798.81	8638
2800.54	8632
2802.27	8698
2804	8660
2805.74	8636
2807.47	8518
2809.2	8504
2810.93	8368
2812.65	8378
2814.38	8370
2816.11	8420
2817.84	8244
2819.56	8286
2821.29	8304
2823.02	8182
2824.74	8190
2826.47	8172
2828.19	8114
2829.92	8142
2831.64	7928
2833.36	7998
2835.09	7946
2836.81	8000
2838.53	7962
2840.25	7808
2841.97	7816
2843.69	7774
2845.41	7696
2847.13	7682
2848.85	7642
2850.57	7638
2852.28	7624
2854	7632
2855.72	7604
2857.43	7386
2859.15	7344
2860.86	7460
2862.58	7428
2864.29	7368
2866.01	7282
2867.72	7288
2869.43	7260
2871.14	7262
2872.86	7218
2874.57	7120
2876.28	7108
2877.99	7188
2879.7	7078
2881.41	7152
2883.11	7034
2884.82	7030
2886.53	6970
2888.24	6954
2889.94	6978
2891.65	6854
2893.36	6922
2895.06	6870
2896.77	6904
2898.47	6804
2900.17	6792
2901.88	6756
2903.58	6850
2905.28	6758
2906.98	6738
2908.69	6662
2910.39	6596
2912.09	6706
2913.79	6578
2915.49	6668
2917.19	6540
2918.88	6590
2920.58	6426
2922.28	6556
2923.98	6502
2925.67	6516
2927.37	6536
2929.06	6542
2930.76	6372
2932.45	6334
2934.15	6388
2935.84	6436
2937.53	6334
2939.23	6294
2940.92	6258
2942.61	6252
2944.3	6198
2945.99	6220
2947.68	6256
2949.37	6210
2951.06	6242
2952.75	6132
2954.44	6110
2956.12	6146
2957.81	6082
2959.5	6078
2961.18	5960
2962.87	6018
2964.56	5966
2966.24	5880
2967.92	5994
2969.61	5828
2971.29	5922
2972.97	5884
2974.66	5890
2976.34	5854
2978.02	5744
2979.7	5826
2981.38	5786
2983.06	5710
2984.74	5632
2986.42	5674
2988.1	5638
2989.78	5656
2991.45	5664
2993.13	5614
2994.81	5554
2996.48	5624
2998.16	5580
2999.83	5522