File: muestras/nopal/inside_prf_07.txt
#Acq. time (s)=	15
#Accumulations=	1
#Range (cm-¹)=	200...3000
#Windows=	3
#Autofocus=	Off
#AutoExposure=	Off
#Spike filter=	Off
#Delay time (s)=	0
#Binning=	1
#Readout mode=	Signal
#DeNoise=	Off
#ICS correction=	Off
#Dark correction=	Off
#Inst. Process=	Off
#Instrument=	LabRAM HR Evol
#Detector=	Syncerity OE
#Objective=	x100_VIS
#Grating=	600 (500nm)
#ND Filter=	0.1%
#Laser=	633nm_Edge
#Hole=	100.021
#Range=	Visible
#Project=	Omar
#Sample=	03-07-23
#Site=	nop
#Title=	inside_prf
#Remark=
#Date=	03.07.2023 14:27
#Acquired=	03.07.2023 14:27:17
201.713	456
204.247	450
206.778	474
209.311	454
211.84	472
214.371	490
216.899	480
219.428	474
221.955	498
224.482	502
227.007	508
229.531	540
232.055	506
234.579	522
237.1	512
239.621	580
242.141	572
244.661	570
247.179	560
249.698	616
252.215	568
254.731	578
257.246	580
259.761	648
262.273	582
264.786	668
267.298	604
269.809	654
272.319	668
274.828	682
277.336	666
279.844	674
282.351	692
284.855	730
287.361	720
289.866	712
292.368	716
294.871	780
297.372	776
299.873	834
302.372	800
304.872	806
307.37	802
309.866	820
312.364	838
314.859	862
317.353	878
319.848	850
322.341	864
324.833	882
327.324	904
329.814	882
332.304	946
334.792	940
337.28	968
339.767	956
342.254	1012
344.739	1016
347.224	978
349.708	1018
352.191	1062
354.673	1056
357.155	1042
359.634	1070
362.114	1120
364.593	1068
367.07	1108
369.548	1128
372.024	1146
374.499	1178
376.974	1154
379.447	1192
381.92	1200
384.392	1212
386.864	1224
389.333	1224
391.802	1370
394.272	1250
396.739	1302
399.206	1306
401.673	1374
404.138	1324
406.602	1352
409.066	1402
411.528	1472
413.99	1430
416.451	1504
418.911	1444
421.371	1508
423.83	1564
426.288	1558
428.745	1550
431.201	1584
433.657	1636
436.111	1646
438.565	1662
441.017	1688
443.469	1690
445.921	1746
448.37	1698
450.821	1744
453.27	1734
455.717	1760
458.165	1814
460.61	1804
463.056	1848
465.5	1846
467.945	1840
470.387	1836
472.829	1930
475.271	1890
477.711	1908
480.15	1970
482.589	2006
485.027	2052
487.465	2084
489.901	2028
492.337	2106
494.771	2128
497.205	2154
499.638	2116
502.07	2202
504.502	2192
506.933	2256
509.363	2260
511.792	2248
514.219	2320
516.647	2362
519.073	2348
521.5	2386
523.924	2410
526.348	2450
528.772	2434
531.194	2498
533.616	2492
536.036	2484
538.457	2560
540.875	2564
543.294	2554
545.712	2636
548.128	2620
550.545	2678
552.959	2676
555.373	2704
557.788	2746
560.2	2844
562.612	2778
565.023	2826
567.433	2936
569.843	2938
572.251	3022
574.659	3036
577.066	3072
579.472	3038
581.878	3026
584.283	3076
586.687	3218
589.09	3192
591.493	3212
593.893	3264
596.294	3338
598.694	3396
601.093	3464
603.491	3470
605.889	3502
608.285	3566
610.682	3630
613.076	3640
615.471	3728
617.864	3702
620.256	3742
622.648	3866
625.039	3894
627.429	3964
629.819	4046
632.208	4026
634.595	4158
636.982	4174
639.369	4204
641.755	4274
644.139	4348
646.523	4424
648.906	4470
651.288	4584
653.67	4592
656.051	4688
658.429	4684
660.808	4790
663.187	4796
665.565	4840
667.942	4948
670.317	4994
672.692	5026
675.067	5070
677.44	5194
679.813	5126
682.184	5296
684.556	5342
686.926	5400
689.296	5398
691.664	5496
694.033	5594
696.4	5632
698.766	5784
701.133	5892
703.497	5866
705.861	5998
708.224	6070
710.586	6176
712.949	6256
715.31	6290
717.67	6496
720.029	6570
722.388	6628
724.746	6712
727.103	6798
729.458	6868
731.814	6938
734.168	7040
736.523	7190
738.876	7322
741.227	7270
743.579	7578
745.931	7564
748.28	7666
750.629	7750
752.977	7856
755.325	8024
757.672	7978
760.018	8198
762.363	8138
764.708	8330
767.052	8522
769.394	8532
771.737	8600
774.078	8740
776.419	8886
778.758	8996
781.097	9092
783.435	9192
785.773	9208
788.11	9394
790.446	9596
792.781	9790
795.115	9806
797.449	10008
799.782	10102
802.115	10354
804.446	10410
806.777	10628
809.106	10728
811.435	10832
813.764	10964
816.091	11096
818.418	11190
820.743	11374
823.069	11604
825.393	11738
827.717	11918
830.039	12076
832.362	12250
834.683	12382
837.003	12698
839.324	12894
841.643	12992
843.961	13168
846.278	13242
848.594	13454
850.91	13648
853.227	13792
855.541	13966
857.855	14212
860.168	14218
862.48	14586
864.79	14610
867.101	14852
869.411	15026
871.721	15246
874.029	15370
876.336	15592
878.643	15718
880.95	15922
883.254	16036
885.559	16218
887.862	16446
890.166	16748
892.467	16722
894.77	16930
897.07	17022
899.371	17408
901.669	17716
903.968	17914
906.266	17924
908.563	18150
910.859	18282
913.154	18512
915.449	18636
917.742	18990
920.036	19148
922.329	19296
924.621	19550
926.911	19798
929.201	20016
931.49	20342
933.779	20510
936.068	20772
938.355	20944
940.64	21400
942.926	21430
945.212	21742
947.495	22400
949.779	22284
952.062	22630
954.344	22890
956.625	23072
958.905	23426
961.184	23568
963.464	24316
965.742	24150
968.02	24460
970.296	24956
972.572	25162
974.847	25262
977.121	25692
979.396	26060
981.669	25914
983.941	26370
986.212	26650
988.483	26982
990.753	27286
993.022	27594
995.29	27812
997.558	27970
999.825	28350
1002.09	28892
1004.36	28798
1006.62	29390
1008.89	29502
1011.15	29918
1013.41	30130
1015.67	30428
1017.93	30882
1020.19	31360
1022.45	31342
1024.71	31924
1026.97	32194
1029.23	32540
1031.49	33124
1033.74	33414
1036	33696
1038.25	34194
1040.5	34750
1042.76	34940
1045.01	35242
1047.26	35526
1049.51	36106
1051.76	36294
1054.01	36924
1056.26	37346
1058.51	37590
1060.75	37836
1063	38130
1065.25	38756
1067.49	39252
1069.73	39168
1071.98	39770
1074.22	39902
1076.46	40344
1078.7	40226
1080.94	40858
1083.18	41148
1085.42	41568
1087.66	41378
1089.9	41812
1092.14	42162
1094.37	42340
1096.61	42604
1098.84	43136
1101.08	43174
1103.31	43628
1105.54	44070
1107.77	44394
1110	44674
1112.23	44700
1114.46	45164
1116.69	45512
1118.92	45606
1121.15	46092
1123.37	46276
1125.6	46646
1127.83	46924
1130.05	47436
1132.27	47536
1134.5	48024
1136.72	48394
1138.94	48494
1141.16	48746
1143.38	49224
1145.6	49536
1147.82	49468
1150.04	50132
1152.26	50598
1154.47	50532
1156.69	51248
1158.9	51004
1161.12	51236
1163.33	51580
1165.54	51482
1167.76	51812
1169.97	51978
1172.18	52230
1174.39	51954
1176.6	52386
1178.81	52404
1181.02	52602
1183.22	52188
1185.43	52574
1187.63	52706
1189.84	52484
1192.04	52506
1194.25	52356
1196.45	52542
1198.65	52424
1200.85	52330
1203.05	51934
1205.25	52210
1207.45	52132
1209.65	52092
1211.85	51946
1214.05	51628
1216.24	51376
1218.44	51392
1220.64	51080
1222.83	51240
1225.02	50734
1227.22	50842
1229.41	50752
1231.6	50370
1233.79	50164
1235.98	50190
1238.17	50086
1240.36	49536
1242.55	49658
1244.73	49704
1246.92	49210
1249.11	48784
1251.29	48744
1253.48	48858
1255.66	50488
1257.84	49922
1260.03	48336
1262.21	47778
1264.39	47426
1266.57	47124
1268.75	46986
1270.93	47082
1273.11	46560
1275.28	46452
1277.46	46010
1279.64	45562
1281.81	45668
1283.98	45133.8
1286.16	45039.7
1288.33	44161.6
1290.5	43775.7
1292.68	42976
1294.85	42586.8
1297.02	42308.2
1299.19	41494.5
1301.36	41180.2
1303.53	40665.2
1305.69	40150.4
1307.86	39477.4
1310.03	38915.1
1312.19	38476.6
1314.36	38114.8
1316.52	37502.2
1318.68	37008.2
1320.85	36738.3
1323.01	36122.8
1325.17	35657.2
1327.33	35223.4
1329.49	34634.2
1331.65	34193.2
1333.81	33724.9
1335.97	33391
1338.12	32705.4
1340.28	32420.3
1342.44	31928.5
1344.59	31506.5
1346.75	31232.1
1348.9	30707
1351.05	30345.5
1353.2	29991.2
1355.36	29356.8
1357.51	29144.6
1359.66	28716.5
1361.81	28247
1363.96	27901.3
1366.1	27567.7
1368.25	27262
1370.4	26994.8
1372.54	26668.9
1374.69	26061.2
1376.83	25744
1378.98	25629
1381.12	25015.3
1383.26	24710.4
1385.41	24551.2
1387.55	24201.6
1389.69	23838.4
1391.83	23452.7
1393.02	23224
1395.17	23052
1397.32	22924
1399.47	22830
1401.62	22416
1403.77	22242
1405.91	22204
1408.06	22006
1410.2	21862
1412.35	21696
1414.49	21440
1416.63	21380
1418.78	21170
1420.92	20812
1423.06	20890
1425.2	20876
1427.34	20484
1429.48	20264
1431.61	20384
1433.75	20064
1435.89	20006
1438.02	19828
1440.16	19802
1442.3	19686
1444.43	19358
1446.56	19400
1448.7	19092
1450.83	19106
1452.96	19056
1455.09	18960
1457.22	18764
1459.35	18582
1461.48	18398
1463.61	18418
1465.73	18406
1467.86	18194
1469.98	18086
1472.11	18068
1474.24	17960
1476.36	17808
1478.48	17708
1480.6	17560
1482.73	17536
1484.85	17344
1486.97	17232
1489.09	17416
1491.21	17032
1493.33	17016
1495.44	16908
1497.56	16808
1499.68	16722
1501.79	16652
1503.91	16462
1506.02	16452
1508.14	16214
1510.25	16236
1512.36	16206
1514.48	15856
1516.59	15752
1518.7	15886
1520.81	15640
1522.92	15718
1525.02	15536
1527.13	15302
1529.24	15324
1531.35	15352
1533.45	15120
1535.56	15082
1537.66	15030
1539.77	14930
1541.87	14886
1543.97	14702
1546.08	14538
1548.18	14416
1550.28	14384
1552.38	14474
1554.48	14418
1556.57	14268
1558.67	14134
1560.77	14128
1562.87	13920
1564.96	14032
1567.06	13936
1569.15	13816
1571.25	13894
1573.34	13742
1575.43	13676
1577.53	13662
1579.62	13644
1581.71	13458
1583.8	13506
1585.89	13526
1587.98	13504
1590.06	13298
1592.15	13454
1594.24	13268
1596.33	13364
1598.41	13198
1600.5	13392
1602.58	13250
1604.66	13088
1606.75	12898
1608.83	12954
1610.91	13006
1612.99	13020
1615.07	13074
1617.15	12970
1619.23	13118
1621.31	12754
1623.39	12862
1625.46	12848
1627.54	12834
1629.62	12862
1631.69	12752
1633.77	12568
1635.84	12644
1637.91	12608
1639.99	12536
1642.06	12520
1644.13	12336
1646.2	12362
1648.27	12520
1650.34	12290
1652.41	12346
1654.47	12366
1656.54	12314
1658.61	12302
1660.67	12120
1662.74	12102
1664.81	12152
1666.87	12096
1668.93	12064
1671	11898
1673.06	11872
1675.12	11820
1677.18	11862
1679.24	11760
1681.3	11808
1683.36	11752
1685.42	11652
1687.47	11752
1689.53	11678
1691.59	11512
1693.64	11508
1695.7	11636
1697.75	11544
1699.81	11592
1701.86	11414
1703.91	11468
1705.97	11444
1708.02	11470
1710.07	11496
1712.12	11390
1714.17	11348
1716.22	11342
1718.26	11188
1720.31	11240
1722.36	11262
1724.4	11188
1726.45	11228
1728.49	11072
1730.54	11252
1732.58	11150
1734.63	11150
1736.67	11164
1738.71	11114
1740.75	10886
1742.79	11114
1744.83	11040
1746.87	11060
1748.91	11048
1750.95	11166
1752.98	11058
1755.02	10910
1757.06	11034
1759.09	10886
1761.13	11036
1763.16	11026
1765.19	11012
1767.23	10916
1769.26	10942
1771.29	10958
1773.32	10862
1775.35	11012
1777.38	10846
1779.41	11012
1781.44	11002
1783.47	10870
1785.49	11008
1787.52	10992
1789.55	10916
1791.57	10974
1793.6	10910
1795.62	10900
1797.64	10860
1799.67	10868
1801.69	10762
1803.71	10792
1805.73	10784
1807.75	10746
1809.77	10844
1811.79	10778
1813.81	10768
1815.83	10742
1817.84	10774
1819.86	10578
1821.88	10840
1823.89	10756
1825.91	10606
1827.92	10740
1829.93	10692
1831.95	10756
1833.96	10692
1835.97	10540
1837.98	10462
1839.99	10670
1842	10506
1844.01	10598
1846.02	10546
1848.03	10564
1850.03	10598
1852.04	10502
1854.05	10616
1856.05	10438
1858.06	10424
1860.06	10402
1862.06	10502
1864.07	10570
1866.07	10504
1868.07	10434
1870.07	10444
1872.07	10474
1874.07	10310
1876.07	10438
1878.07	10460
1880.07	10424
1882.07	10514
1884.06	10322
1886.06	10464
1888.05	10326
1890.05	10398
1892.04	10456
1894.04	10436
1896.03	10410
1898.02	10390
1900.01	10354
1902	10262
1903.99	10542
1905.98	10446
1907.97	10472
1909.96	10400
1911.95	10236
1913.94	10350
1915.93	10422
1917.91	10454
1919.9	10412
1921.88	10380
1923.87	10414
1925.85	10338
1927.83	10392
1929.82	10354
1931.8	10306
1933.78	10222
1935.76	10370
1937.74	10270
1939.72	10410
1941.7	10304
1943.68	10202
1945.65	10296
1947.63	10166
1949.61	10226
1951.58	10344
1953.56	10284
1955.53	10124
1957.51	10162
1959.48	10208
1961.45	10026
1963.43	10182
1965.4	10152
1967.37	10086
1969.34	10148
1971.31	10174
1973.28	10220
1975.25	10114
1977.22	9966
1979.18	10146
1981.15	10080
1983.12	10028
1985.08	10012
1987.05	10154
1989.01	10052
1990.97	10140
1992.94	10048
1994.9	10028
1996.86	9970
1998.82	9922
2000.78	10022
2002.74	10076
2004.7	9964
2006.66	9992
2008.62	9956
2010.58	10016
2012.54	9904
2014.49	9908
2016.45	9942
2018.4	10022
2020.36	9990
2022.31	9900
2024.27	9886
2026.22	9884
2028.17	9899
2030.12	9952
2032.07	9830
2034.03	10036
2035.98	9928
2037.93	9906
2039.87	9832
2041.82	9798
2043.77	9884
2045.72	9966
2047.66	9834
2049.61	9796
2051.55	9840
2053.5	9810
2055.44	9832
2057.39	9864
2059.33	9924
2061.27	9942
2063.21	9866
2065.15	9816
2067.09	9806
2069.03	9864
2070.97	9792
2072.91	9828
2074.85	9714
2076.79	9766
2078.73	9700
2080.66	9784
2082.6	9726
2084.53	9812
2086.47	9768
2088.4	9792
2090.33	9794
2092.27	9836
2094.2	9758
2096.13	9680
2098.06	9808
2099.99	9748
2101.92	9696
2103.85	9624
2105.78	9750
2107.71	9744
2109.64	9616
2111.56	9692
2113.49	9654
2115.41	9670
2117.34	9720
2119.26	9702
2121.19	9636
2123.11	9654
2125.03	9658
2126.96	9582
2128.88	9528
2130.8	9548
2132.72	9666
2134.64	9622
2136.56	9540
2138.48	9602
2140.4	9594
2142.31	9618
2144.23	9514
2146.15	9634
2148.06	9510
2149.98	9538
2151.89	9542
2153.81	9478
2155.72	9404
2157.63	9458
2159.55	9508
2161.46	9458
2163.37	9482
2165.28	9490
2167.19	9506
2169.1	9334
2171.01	9490
2172.91	9414
2174.82	9408
2176.73	9320
2178.64	9396
2180.54	9438
2182.45	9376
2184.35	9314
2186.26	9320
2188.16	9216
2190.06	9198
2191.96	9300
2193.87	9252
2195.77	9104
2197.67	9256
2199.57	9250
2201.47	9162
2203.37	9048
2205.27	9268
2207.16	9172
2209.06	9106
2210.96	9186
2212.85	9162
2214.75	9042
2216.64	9224
2218.54	9132
2220.43	9066
2222.33	9190
2224.22	9189.08
2226.11	9130.15
2228	8979.97
2229.89	8962.93
2231.78	9031.11
2233.67	9035.38
2235.56	8904.88
2237.45	8953.02
2239.34	8929.71
2241.23	8839.1
2243.11	8899.57
2245	8846.3
2246.89	8791.86
2248.77	8813.22
2250.66	8811.65
2252.54	8800.02
2254.42	8780.01
2256.31	8763.3
2258.19	8707.62
2260.07	8659.88
2261.95	8591.9
2263.83	8617.48
2265.71	8647.05
2267.59	8616.39
2269.47	8583.46
2271.35	8592.83
2273.23	8550.39
2275.1	8501.6
2276.98	8464.52
2278.86	8460.42
2280.73	8397.06
2282.61	8378.49
2284.48	8350.65
2286.36	8291.81
2288.23	8333.64
2290.1	8263.44
2291.98	8247.7
2293.85	8168.83
2295.72	8071.73
2297.59	8140.82
2299.46	8123.13
2301.33	8045.69
2303.2	7986.72
2305.06	8000.41
2306.93	7993.08
2308.8	7999.9
2310.67	7939.29
2312.53	7919.95
2314.4	7902.47
2316.26	7865.5
2317.62	7852
2319.5	7810
2321.37	7872
2323.24	7856
2325.12	7842
2326.99	7808
2328.86	7786
2330.73	7708
2332.6	7662
2334.47	7618
2336.34	7766
2338.2	7602
2340.07	7658
2341.94	7540
2343.81	7594
2345.67	7644
2347.54	7614
2349.4	7606
2351.27	7604
2353.13	7464
2354.99	7542
2356.86	7674
2358.72	7560
2360.58	7540
2362.44	7562
2364.3	7498
2366.16	7576
2368.02	7432
2369.88	7448
2371.74	7418
2373.6	7352
2375.45	7460
2377.31	7354
2379.17	7370
2381.02	7394
2382.88	7334
2384.73	7172
2386.58	7264
2388.44	7354
2390.29	7314
2392.14	7122
2393.99	7228
2395.85	7128
2397.7	7166
2399.55	7092
2401.4	6990
2403.25	7138
2405.09	7044
2406.94	7074
2408.79	6912
2410.63	6950
2412.48	6964
2414.33	6920
2416.17	6916
2418.02	6954
2419.86	6922
2421.7	6834
2423.55	6848
2425.39	6746
2427.23	6766
2429.07	6828
2430.91	6700
2432.75	6658
2434.59	6638
2436.43	6576
2438.27	6644
2440.11	6586
2441.95	6608
2443.78	6578
2445.62	6516
2447.46	6478
2449.29	6532
2451.13	6502
2452.96	6466
2454.79	6374
2456.63	6384
2458.46	6450
2460.29	6308
2462.12	6398
2463.95	6252
2465.78	6328
2467.61	6312
2469.44	6294
2471.27	6160
2473.1	6306
2474.93	6274
2476.76	6088
2478.58	6144
2480.41	6204
2482.23	5996
2484.06	5978
2485.88	5964
2487.71	5916
2489.53	5942
2491.35	5884
2493.18	6014
2495	5834
2496.82	5800
2498.64	5832
2500.46	5802
2502.28	5832
2504.1	5720
2505.92	5810
2507.74	5642
2509.55	5712
2511.37	5690
2513.19	5618
2515	5546
2516.82	5526
2518.63	5570
2520.45	5540
2522.26	5552
2524.07	5504
2525.89	5522
2527.7	5432
2529.51	5414
2531.32	5410
2533.13	5280
2534.94	5338
2536.75	5250
2538.56	5310
2540.37	5240
2542.18	5222
2543.98	5298
2545.79	5266
2547.6	5274
2549.4	5082
2551.21	5258
2553.01	5032
2554.82	5132
2556.62	5082
2558.42	5064
2560.23	5044
2562.03	4988
2563.83	5068
2565.63	4994
2567.43	4930
2569.23	4928
2571.03	4968
2572.83	4910
2574.63	4916
2576.43	4818
2578.22	4902
2580.02	4740
2581.82	4754
2583.61	4716
2585.41	4822
2587.2	4674
2589	4666
2590.79	4670
2592.58	4658
2594.38	4586
2596.17	4572
2597.96	4522
2599.75	4552
2601.54	4626
2603.33	4456
2605.12	4480
2606.91	4446
2608.7	4468
2610.49	4432
2612.27	4392
2614.06	4362
2615.85	4408
2617.63	4338
2619.42	4266
2621.2	4362
2622.99	4334
2624.77	4272
2626.55	4340
2628.34	4214
2630.12	4138
2631.9	4222
2633.68	4152
2635.46	4142
2637.24	4106
2639.02	4124
2640.8	4092
2642.58	4112
2644.36	4030
2646.14	4036
2647.91	4020
2649.69	3968
2651.46	3974
2653.24	3902
2655.01	4052
2656.79	3912
2658.56	3926
2660.34	3894
2662.11	3836
2663.88	3814
2665.65	3848
2667.42	3894
2669.2	3744
2670.96	3694
2672.73	3742
2674.5	3744
2676.27	3770
2678.04	3796
2679.81	3704
2681.58	3732
2683.34	3714
2685.11	3646
2686.87	3656
2688.64	3582
2690.4	3586
2692.17	3596
2693.93	3608
2695.69	3640
2697.46	3546
2699.22	3472
2700.98	3528
2702.74	3466
2704.5	3438
2706.26	3416
2708.02	3322
2709.78	3450
2711.54	3300
2713.3	3386
2715.05	3350
2716.81	3330
2718.57	3348
2720.32	3282
2722.08	3258
2723.83	3218
2725.59	3258
2727.34	3202
2729.09	3236
2730.85	3102
2732.6	3190
2734.35	3046
2736.1	3136
2737.85	3148
2739.6	3070
2741.35	3056
2743.1	3050
2744.85	3032
2746.6	2960
2748.35	3042
2750.09	2932
2751.84	2960
2753.59	2938
2755.33	2954
2757.08	2914
2758.82	2858
2760.57	2912
2762.31	2870
2764.05	2814
2765.79	2796
2767.54	2860
2769.28	2796
2771.02	2718
2772.76	2768
2774.5	2758
2776.24	2740
2777.98	2732
2779.72	2692
2781.46	2626
2783.19	2746
2784.93	2624
2786.67	2630
2788.4	2572
2790.14	2586
2791.87	2604
2793.61	2572
2795.34	2578
2797.07	2558
2798.81	2530
2800.54	2536
2802.27	2526
2804	2460
2805.74	2480
2807.47	2424
2809.2	2432
2810.93	2426
2812.65	2422
2814.38	2420
2816.11	2412
2817.84	2322
2819.56	2324
2821.29	2338
2823.02	2322
2824.74	2368
2826.47	2280
2828.19	2320
2829.92	2294
2831.64	2250
2833.36	2164
2835.09	2280
2836.81	2216
2838.53	2234
2840.25	2180
2841.97	2206
2843.69	2156
2845.41	2208
2847.13	2112
2848.85	2130
2850.57	2104
2852.28	2100
2854	2044
2855.72	2054
2857.43	2044
2859.15	2116
2860.86	2052
2862.58	2004
2864.29	2006
2866.01	1980
2867.72	1970
2869.43	1974
2871.14	1914
2872.86	1960
2874.57	1912
2876.28	1902
2877.99	1912
2879.7	1916
2881.41	1898
2883.11	1888
2884.82	1862
2886.53	1848
2888.24	1878
2889.94	1862
2891.65	1760
2893.36	1778
2895.06	1816
2896.77	1816
2898.47	1720
2900.17	1772
2901.88	1762
2903.58	1730
2905.28	1732
2906.98	1738
2908.69	1708
2910.39	1712
2912.09	1720
2913.79	1742
2915.49	1720
2917.19	1666
2918.88	1684
2920.58	1674
2922.28	1670
2923.98	1678
2925.67	1610
2927.37	1666
2929.06	1638
2930.76	1630
2932.45	1638
2934.15	1614
2935.84	1592
2937.53	1578
2939.23	1636
2940.92	1540
2942.61	1554
2944.3	1540
2945.99	1526
2947.68	1556
2949.37	1516
2951.06	1556
2952.75	1522
2954.44	1540
2956.12	1480
2957.81	1524
2959.5	1484
2961.18	1496
2962.87	1452
2964.56	1498
2966.24	1472
2967.92	1446
2969.61	1452
2971.29	1428
2972.97	1442
2974.66	1402
2976.34	1454
2978.02	1432
2979.7	1422
2981.38	1430
2983.06	1370
2984.74	1382
2986.42	1338
2988.1	1366
2989.78	1404
2991.45	1312
2993.13	1342
2994.81	1350
2996.48	1348
2998.16	1334
2999.83	1328