File: muestras/nopal/inside_prf_05.txt
#Acq. time (s)=	15
#Accumulations=	2
#Range (cm-¹)=	200...3000
#Windows=	3
#Autofocus=	Off
#AutoExposure=	Off
#Spike filter=	Multiple accum.
#Delay time (s)=	0
#Binning=	1
#Readout mode=	Signal
#DeNoise=	Off
#ICS correction=	Off
#Dark correction=	Off
#Inst. Process=	Off
#Instrument=	LabRAM HR Evol
#Detector=	Syncerity OE
#Objective=	x100_VIS
#Grating=	600 (500nm)
#ND Filter=	25%
#Laser=	633nm_Edge
#Hole=	9.98375
#Range=	Visible
#Project=	Omar
#Sample=	03-07-23
#Site=	nop
#Title=	inside_prf
#Remark=
#Date=	03.07.2023 14:21
#Acquired=	03.07.2023 14:21:56
201.713	166
204.247	174
206.778	172
209.311	170
211.84	166
214.371	158
216.899	170
219.428	178
221.955	172
224.482	168
227.007	164
229.531	160
232.055	170
234.579	178
237.1	170
239.621	182
242.141	182
244.661	178
247.179	176
249.698	186
252.215	176
254.731	186
257.246	190
259.761	186
262.273	176
264.786	186
267.298	174
269.809	176
272.319	178
274.828	178
277.336	184
279.844	188
282.351	180
284.855	204
287.361	202
289.866	188
292.368	180
294.871	190
297.372	182
299.873	178
302.372	192
304.872	196
307.37	194
309.866	196
312.364	202
314.859	184
317.353	188
319.848	190
322.341	198
324.833	198
327.324	180
329.814	206
332.304	190
334.792	204
337.28	202
339.767	196
342.254	210
344.739	206
347.224	192
349.708	208
352.191	230
354.673	218
357.155	214
359.634	220
362.114	230
364.593	204
367.07	216
369.548	204
372.024	228
374.499	206
376.974	210
379.447	228
381.92	214
384.392	222
386.864	216
389.333	216
391.802	222
394.272	234
396.739	220
399.206	232
401.673	210
404.138	236
406.602	210
409.066	236
411.528	224
413.99	226
416.451	264
418.911	242
421.371	250
423.83	232
426.288	232
428.745	238
431.201	232
433.657	252
436.111	256
438.565	262
441.017	258
443.469	238
445.921	230
448.37	250
450.821	254
453.27	260
455.717	232
458.165	238
460.61	252
463.056	264
465.5	234
467.945	254
470.387	252
472.829	260
475.271	234
477.711	262
480.15	264
482.589	244
485.027	264
487.465	266
489.901	252
492.337	286
494.771	280
497.205	256
499.638	270
502.07	248
504.502	258
506.933	280
509.363	276
511.792	288
514.219	288
516.647	280
519.073	298
521.5	278
523.924	284
526.348	274
528.772	262
531.194	272
533.616	284
536.036	266
538.457	292
540.875	270
543.294	278
545.712	288
548.128	272
550.545	280
552.959	282
555.373	282
557.788	298
560.2	288
562.612	274
565.023	288
567.433	306
569.843	284
572.251	284
574.659	292
577.066	308
579.472	300
581.878	318
584.283	298
586.687	304
589.09	282
591.493	302
593.893	322
596.294	328
598.694	308
601.093	298
603.491	306
605.889	306
608.285	314
610.682	296
613.076	318
615.471	332
617.864	344
620.256	314
622.648	306
625.039	316
627.429	328
629.819	298
632.208	336
634.595	318
636.982	318
639.369	342
641.755	348
644.139	338
646.523	344
648.906	366
651.288	330
653.67	358
656.051	346
658.429	344
660.808	372
663.187	346
665.565	344
667.942	346
670.317	370
672.692	362
675.067	346
677.44	358
679.813	362
682.184	368
684.556	374
686.926	372
689.296	352
691.664	386
694.033	374
696.4	370
698.766	382
701.133	392
703.497	384
705.861	394
708.224	396
710.586	430
712.949	382
715.31	398
717.67	410
720.029	402
722.388	410
724.746	416
727.103	416
729.458	400
731.814	434
734.168	418
736.523	432
738.876	432
741.227	424
743.579	436
745.931	440
748.28	432
750.629	434
752.977	460
755.325	466
757.672	444
760.018	446
762.363	442
764.708	454
767.052	468
769.394	466
771.737	470
774.078	478
776.419	464
778.758	470
781.097	504
783.435	468
785.773	504
788.11	498
790.446	496
792.781	512
795.115	506
797.449	510
799.782	472
802.115	496
804.446	486
806.777	540
809.106	502
811.435	532
813.764	548
816.091	544
818.418	550
820.743	562
823.069	540
825.393	572
827.717	540
830.039	564
832.362	558
834.683	562
837.003	584
839.324	606
841.643	588
843.961	588
846.278	600
848.594	642
850.91	606
853.227	608
855.541	632
857.855	636
860.168	610
862.48	630
864.79	660
867.101	616
869.411	684
871.721	668
874.029	654
876.336	684
878.643	636
880.95	666
883.254	680
885.559	676
887.862	662
890.166	712
892.467	676
894.77	676
897.07	698
899.371	714
901.669	702
903.968	716
906.266	692
908.563	738
910.859	724
913.154	730
915.449	706
917.742	750
920.036	768
922.329	772
924.621	760
926.911	734
929.201	772
931.49	792
933.779	816
936.068	784
938.355	822
940.64	790
942.926	814
945.212	820
947.495	818
949.779	838
952.062	858
954.344	876
956.625	846
958.905	888
961.184	856
963.464	894
965.742	868
968.02	896
970.296	910
972.572	908
974.847	902
977.121	926
979.396	906
981.669	904
983.941	944
986.212	960
988.483	924
990.753	934
993.022	964
995.29	950
997.558	978
999.825	1008
1002.09	1046
1004.36	1018
1006.62	1028
1008.89	976
1011.15	1024
1013.41	1046
1015.67	1034
1017.93	1066
1020.19	1056
1022.45	1022
1024.71	1054
1026.97	1078
1029.23	1056
1031.49	1064
1033.74	1092
1036	1106
1038.25	1082
1040.5	1116
1042.76	1148
1045.01	1166
1047.26	1146
1049.51	1116
1051.76	1180
1054.01	1164
1056.26	1180
1058.51	1178
1060.75	1166
1063	1196
1065.25	1176
1067.49	1200
1069.73	1190
1071.98	1208
1074.22	1178
1076.46	1260
1078.7	1186
1080.94	1258
1083.18	1190
1085.42	1250
1087.66	1208
1089.9	1290
1092.14	1244
1094.37	1298
1096.61	1226
1098.84	1262
1101.08	1288
1103.31	1286
1105.54	1304
1107.77	1308
1110	1276
1112.23	1330
1114.46	1340
1116.69	1294
1118.92	1338
1121.15	1356
1123.37	1330
1125.6	1326
1127.83	1354
1130.05	1356
1132.27	1356
1134.5	1372
1136.72	1352
1138.94	1386
1141.16	1420
1143.38	1414
1145.6	1378
1147.82	1436
1150.04	1408
1152.26	1430
1154.47	1432
1156.69	1444
1158.9	1432
1161.12	1426
1163.33	1460
1165.54	1424
1167.76	1448
1169.97	1440
1172.18	1404
1174.39	1454
1176.6	1422
1178.81	1462
1181.02	1422
1183.22	1468
1185.43	1444
1187.63	1434
1189.84	1440
1192.04	1458
1194.25	1448
1196.45	1426
1198.65	1474
1200.85	1434
1203.05	1434
1205.25	1398
1207.45	1438
1209.65	1428
1211.85	1422
1214.05	1402
1216.24	1418
1218.44	1394
1220.64	1410
1222.83	1388
1225.02	1388
1227.22	1426
1229.41	1406
1231.6	1426
1233.79	1406
1235.98	1382
1238.17	1402
1240.36	1392
1242.55	1380
1244.73	1332
1246.92	1362
1249.11	1406
1251.29	1390
1253.48	1382
1255.66	1380
1257.84	1364
1260.03	1334
1262.21	1382
1264.39	1348
1266.57	1370
1268.75	1348
1270.93	1338
1273.11	1358
1275.28	1332
1277.46	1372
1279.64	1360
1281.81	1346
1283.98	1376.04
1286.16	1343.62
1288.33	1300.61
1290.5	1304.75
1292.68	1293.34
1294.85	1255.34
1297.02	1292.09
1299.19	1262.67
1301.36	1243.2
1303.53	1220.17
1305.69	1231.8
1307.86	1187.5
1310.03	1170.4
1312.19	1190.51
1314.36	1181.86
1316.52	1155.8
1318.68	1138.73
1320.85	1149.83
1323.01	1124.57
1325.17	1109.97
1327.33	1097.64
1329.49	1110.52
1331.65	1066.34
1333.81	1088.54
1335.97	1043.55
1338.12	1023.07
1340.28	1025.74
1342.44	1018.71
1344.59	1009.3
1346.75	1022.58
1348.9	994.943
1351.05	999.162
1353.2	976.843
1355.36	944.501
1357.51	953.965
1359.66	969.945
1361.81	956.898
1363.96	941.708
1366.1	889.159
1368.25	907.149
1370.4	912.916
1372.54	915.311
1374.69	887.294
1376.83	864.903
1378.98	880.739
1381.12	879.395
1383.26	858.833
1385.41	818.359
1387.55	841.858
1389.69	794.539
1391.83	838.831
1393.02	814
1395.17	820
1397.32	820
1399.47	794
1401.62	788
1403.77	742
1405.91	762
1408.06	822
1410.2	774
1412.35	766
1414.49	812
1416.63	796
1418.78	798
1420.92	772
1423.06	764
1425.2	788
1427.34	782
1429.48	764
1431.61	784
1433.75	772
1435.89	722
1438.02	758
1440.16	748
1442.3	796
1444.43	742
1446.56	726
1448.7	698
1450.83	748
1452.96	732
1455.09	762
1457.22	740
1459.35	712
1461.48	732
1463.61	732
1465.73	720
1467.86	740
1469.98	728
1472.11	730
1474.24	714
1476.36	726
1478.48	722
1480.6	706
1482.73	700
1484.85	668
1486.97	708
1489.09	698
1491.21	708
1493.33	680
1495.44	710
1497.56	692
1499.68	704
1501.79	688
1503.91	710
1506.02	690
1508.14	674
1510.25	698
1512.36	700
1514.48	684
1516.59	690
1518.7	676
1520.81	696
1522.92	648
1525.02	664
1527.13	642
1529.24	648
1531.35	634
1533.45	638
1535.56	682
1537.66	646
1539.77	640
1541.87	676
1543.97	630
1546.08	638
1548.18	616
1550.28	658
1552.38	632
1554.48	666
1556.57	610
1558.67	656
1560.77	654
1562.87	608
1564.96	626
1567.06	594
1569.15	634
1571.25	656
1573.34	624
1575.43	650
1577.53	634
1579.62	612
1581.71	626
1583.8	654
1585.89	606
1587.98	620
1590.06	596
1592.15	606
1594.24	570
1596.33	594
1598.41	614
1600.5	626
1602.58	618
1604.66	610
1606.75	602
1608.83	584
1610.91	588
1612.99	600
1615.07	572
1617.15	592
1619.23	612
1621.31	606
1623.39	612
1625.46	590
1627.54	600
1629.62	594
1631.69	578
1633.77	610
1635.84	590
1637.91	586
1639.99	592
1642.06	574
1644.13	588
1646.2	592
1648.27	596
1650.34	608
1652.41	600
1654.47	544
1656.54	564
1658.61	602
1660.67	574
1662.74	614
1664.81	580
1666.87	584
1668.93	580
1671	594
1673.06	566
1675.12	580
1677.18	566
1679.24	558
1681.3	546
1683.36	610
1685.42	552
1687.47	548
1689.53	560
1691.59	548
1693.64	576
1695.7	570
1697.75	530
1699.81	538
1701.86	560
1703.91	570
1705.97	548
1708.02	558
1710.07	552
1712.12	562
1714.17	552
1716.22	574
1718.26	568
1720.31	550
1722.36	526
1724.4	562
1726.45	532
1728.49	570
1730.54	536
1732.58	550
1734.63	548
1736.67	546
1738.71	562
1740.75	572
1742.79	556
1744.83	554
1746.87	536
1748.91	538
1750.95	524
1752.98	546
1755.02	546
1757.06	522
1759.09	546
1761.13	536
1763.16	584
1765.19	546
1767.23	534
1769.26	552
1771.29	510
1773.32	534
1775.35	546
1777.38	562
1779.41	546
1781.44	548
1783.47	530
1785.49	548
1787.52	540
1789.55	542
1791.57	546
1793.6	520
1795.62	540
1797.64	550
1799.67	552
1801.69	538
1803.71	558
1805.73	534
1807.75	548
1809.77	540
1811.79	530
1813.81	526
1815.83	550
1817.84	530
1819.86	532
1821.88	534
1823.89	544
1825.91	534
1827.92	538
1829.93	552
1831.95	520
1833.96	536
1835.97	528
1837.98	534
1839.99	506
1842	518
1844.01	500
1846.02	558
1848.03	500
1850.03	520
1852.04	534
1854.05	522
1856.05	524
1858.06	532
1860.06	532
1862.06	540
1864.07	506
1866.07	514
1868.07	528
1870.07	526
1872.07	518
1874.07	542
1876.07	508
1878.07	514
1880.07	512
1882.07	484
1884.06	514
1886.06	526
1888.05	534
1890.05	534
1892.04	526
1894.04	510
1896.03	510
1898.02	510
1900.01	516
1902	530
1903.99	528
1905.98	500
1907.97	526
1909.96	536
1911.95	516
1913.94	526
1915.93	502
1917.91	546
1919.9	528
1921.88	502
1923.87	530
1925.85	506
1927.83	514
1929.82	508
1931.8	526
1933.78	522
1935.76	504
1937.74	520
1939.72	506
1941.7	510
1943.68	520
1945.65	538
1947.63	516
1949.61	526
1951.58	526
1953.56	536
1955.53	492
1957.51	506
1959.48	492
1961.45	506
1963.43	500
1965.4	506
1967.37	486
1969.34	506
1971.31	508
1973.28	516
1975.25	510
1977.22	492
1979.18	480
1981.15	486
1983.12	508
1985.08	504
1987.05	522
1989.01	510
1990.97	486
1992.94	514
1994.9	482
1996.86	504
1998.82	506
2000.78	478
2002.74	506
2004.7	498
2006.66	510
2008.62	494
2010.58	538
2012.54	534
2014.49	494
2016.45	516
2018.4	532
2020.36	472
2022.31	502
2024.27	520
2026.22	514
2028.17	486
2030.12	504
2032.07	498
2034.03	514
2035.98	512
2037.93	524
2039.87	522
2041.82	502
2043.77	500
2045.72	504
2047.66	528
2049.61	522
2051.55	528
2053.5	488
2055.44	476
2057.39	496
2059.33	504
2061.27	508
2063.21	498
2065.15	500
2067.09	494
2069.03	504
2070.97	508
2072.91	494
2074.85	496
2076.79	512
2078.73	488
2080.66	506
2082.6	500
2084.53	478
2086.47	462
2088.4	520
2090.33	484
2092.27	524
2094.2	490
2096.13	490
2098.06	494
2099.99	486
2101.92	480
2103.85	498
2105.78	494
2107.71	516
2109.64	472
2111.56	516
2113.49	514
2115.41	480
2117.34	510
2119.26	474
2121.19	498
2123.11	526
2125.03	492
2126.96	496
2128.88	496
2130.8	454
2132.72	512
2134.64	482
2136.56	480
2138.48	470
2140.4	452
2142.31	492
2144.23	494
2146.15	484
2148.06	492
2149.98	472
2151.89	488
2153.81	492
2155.72	490
2157.63	494
2159.55	480
2161.46	466
2163.37	474
2165.28	492
2167.19	510
2169.1	486
2171.01	486
2172.91	480
2174.82	478
2176.73	494
2178.64	474
2180.54	482
2182.45	484
2184.35	492
2186.26	472
2188.16	482
2190.06	488
2191.96	476
2193.87	442
2195.77	498
2197.67	492
2199.57	484
2201.47	452
2203.37	482
2205.27	464
2207.16	466
2209.06	466
2210.96	446
2212.85	474
2214.75	474
2216.64	488
2218.54	452
2220.43	472
2222.33	484
2224.22	456.45
2226.11	474.99
2228	472.154
2229.89	469.807
2231.78	463.228
2233.67	466.075
2235.56	494.397
2237.45	486.346
2239.34	447.39
2241.23	489.19
2243.11	483.703
2245	495.069
2246.89	474.425
2248.77	467.595
2250.66	476.162
2252.54	468.921
2254.42	463.944
2256.31	492.192
2258.19	490.016
2260.07	464.47
2261.95	486.164
2263.83	482.35
2265.71	461.466
2267.59	476.322
2269.47	469.969
2271.35	464.87
2273.23	453.503
2275.1	474.111
2276.98	467.958
2278.86	498.268
2280.73	466.576
2282.61	474.496
2284.48	485.361
2286.36	477.77
2288.23	489.616
2290.1	463.95
2291.98	473.934
2293.85	481.285
2295.72	464.182
2297.59	479.408
2299.46	475.077
2301.33	475.159
2303.2	473.513
2305.06	476.074
2306.93	477.766
2308.8	461.612
2310.67	488.481
2312.53	465.585
2314.4	457.524
2316.26	476.187
2317.62	480
2319.5	484
2321.37	462
2323.24	466
2325.12	448
2326.99	472
2328.86	462
2330.73	480
2332.6	464
2334.47	486
2336.34	462
2338.2	476
2340.07	462
2341.94	478
2343.81	466
2345.67	462
2347.54	470
2349.4	478
2351.27	464
2353.13	468
2354.99	450
2356.86	470
2358.72	472
2360.58	450
2362.44	446
2364.3	452
2366.16	456
2368.02	464
2369.88	464
2371.74	458
2373.6	464
2375.45	470
2377.31	460
2379.17	426
2381.02	420
2382.88	460
2384.73	468
2386.58	458
2388.44	446
2390.29	440
2392.14	464
2393.99	438
2395.85	440
2397.7	434
2399.55	444
2401.4	430
2403.25	456
2405.09	424
2406.94	432
2408.79	456
2410.63	420
2412.48	460
2414.33	424
2416.17	462
2418.02	426
2419.86	460
2421.7	446
2423.55	426
2425.39	446
2427.23	416
2429.07	442
2430.91	428
2432.75	422
2434.59	434
2436.43	456
2438.27	428
2440.11	434
2441.95	422
2443.78	442
2445.62	444
2447.46	438
2449.29	454
2451.13	410
2452.96	408
2454.79	392
2456.63	408
2458.46	406
2460.29	426
2462.12	434
2463.95	426
2465.78	406
2467.61	408
2469.44	412
2471.27	404
2473.1	412
2474.93	410
2476.76	418
2478.58	392
2480.41	396
2482.23	404
2484.06	392
2485.88	412
2487.71	420
2489.53	400
2491.35	388
2493.18	426
2495	406
2496.82	374
2498.64	382
2500.46	390
2502.28	408
2504.1	410
2505.92	378
2507.74	392
2509.55	400
2511.37	402
2513.19	376
2515	376
2516.82	384
2518.63	384
2520.45	358
2522.26	358
2524.07	376
2525.89	372
2527.7	372
2529.51	374
2531.32	352
2533.13	382
2534.94	380
2536.75	380
2538.56	366
2540.37	358
2542.18	388
2543.98	358
2545.79	376
2547.6	366
2549.4	360
2551.21	374
2553.01	370
2554.82	374
2556.62	360
2558.42	364
2560.23	358
2562.03	352
2563.83	348
2565.63	360
2567.43	368
2569.23	338
2571.03	350
2572.83	356
2574.63	358
2576.43	334
2578.22	358
2580.02	332
2581.82	350
2583.61	348
2585.41	318
2587.2	352
2589	350
2590.79	328
2592.58	356
2594.38	310
2596.17	348
2597.96	342
2599.75	322
2601.54	344
2603.33	336
2605.12	316
2606.91	340
2608.7	352
2610.49	332
2612.27	322
2614.06	330
2615.85	310
2617.63	324
2619.42	338
2621.2	316
2622.99	340
2624.77	312
2626.55	326
2628.34	316
2630.12	300
2631.9	312
2633.68	318
2635.46	320
2637.24	320
2639.02	312
2640.8	318
2642.58	312
2644.36	314
2646.14	306
2647.91	308
2649.69	292
2651.46	312
2653.24	328
2655.01	306
2656.79	290
2658.56	292
2660.34	296
2662.11	300
2663.88	314
2665.65	310
2667.42	306
2669.2	298
2670.96	302
2672.73	312
2674.5	312
2676.27	304
2678.04	300
2679.81	288
2681.58	308
2683.34	300
2685.11	286
2686.87	272
2688.64	298
2690.4	278
2692.17	282
2693.93	296
2695.69	288
2697.46	302
2699.22	300
2700.98	292
2702.74	268
2704.5	278
2706.26	282
2708.02	268
2709.78	296
2711.54	274
2713.3	268
2715.05	280
2716.81	276
2718.57	250
2720.32	292
2722.08	272
2723.83	282
2725.59	296
2727.34	258
2729.09	280
2730.85	258
2732.6	274
2734.35	280
2736.1	272
2737.85	258
2739.6	250
2741.35	256
2743.1	268
2744.85	264
2746.6	278
2748.35	264
2750.09	244
2751.84	246
2753.59	258
2755.33	266
2757.08	262
2758.82	238
2760.57	264
2762.31	238
2764.05	256
2765.79	260
2767.54	256
2769.28	250
2771.02	240
2772.76	242
2774.5	250
2776.24	256
2777.98	242
2779.72	236
2781.46	250
2783.19	240
2784.93	244
2786.67	240
2788.4	236
2790.14	248
2791.87	232
2793.61	228
2795.34	250
2797.07	230
2798.81	238
2800.54	238
2802.27	216
2804	242
2805.74	222
2807.47	218
2809.2	244
2810.93	230
2812.65	236
2814.38	216
2816.11	228
2817.84	232
2819.56	220
2821.29	242
2823.02	230
2824.74	230
2826.47	230
2828.19	214
2829.92	208
2831.64	226
2833.36	238
2835.09	218
2836.81	232
2838.53	220
2840.25	212
2841.97	222
2843.69	214
2845.41	198
2847.13	224
2848.85	214
2850.57	206
2852.28	214
2854	204
2855.72	204
2857.43	198
2859.15	216
2860.86	200
2862.58	204
2864.29	202
2866.01	208
2867.72	212
2869.43	212
2871.14	190
2872.86	200
2874.57	198
2876.28	202
2877.99	208
2879.7	200
2881.41	200
2883.11	198
2884.82	196
2886.53	184
2888.24	212
2889.94	202
2891.65	212
2893.36	200
2895.06	190
2896.77	210
2898.47	202
2900.17	192
2901.88	204
2903.58	186
2905.28	198
2906.98	194
2908.69	206
2910.39	190
2912.09	194
2913.79	186
2915.49	196
2917.19	190
2918.88	192
2920.58	178
2922.28	178
2923.98	184
2925.67	196
2927.37	182
2929.06	188
2930.76	186
2932.45	188
2934.15	188
2935.84	182
2937.53	188
2939.23	186
2940.92	176
2942.61	164
2944.3	194
2945.99	186
2947.68	190
2949.37	166
2951.06	182
2952.75	186
2954.44	188
2956.12	178
2957.81	184
2959.5	176
2961.18	174
2962.87	186
2964.56	174
2966.24	174
2967.92	180
2969.61	168
2971.29	178
2972.97	176
2974.66	186
2976.34	182
2978.02	170
2979.7	182
2981.38	174
2983.06	178
2984.74	186
2986.42	184
2988.1	180
2989.78	162
2991.45	164
2993.13	164
2994.81	156
2996.48	168
2998.16	168
2999.83	156