File: muestras/nopal/inside_prf_22.txt
#Acq. time (s)=	10
#Accumulations=	1
#Range (cm-¹)=	200...3000
#Windows=	3
#Autofocus=	Off
#AutoExposure=	Off
#Spike filter=	Off
#Delay time (s)=	0
#Binning=	1
#Readout mode=	Signal
#DeNoise=	Off
#ICS correction=	Off
#Dark correction=	Off
#Inst. Process=	Off
#Instrument=	LabRAM HR Evol
#Detector=	Syncerity OE
#Objective=	x100_VIS
#Grating=	600 (500nm)
#ND Filter=	0.01%
#Laser=	633nm_Edge
#Hole=	30.0125
#Range=	Visible
#Project=	Omar
#Sample=	03-07-23
#Site=	nop
#Title=	inside_prf
#Remark=
#Date=	03.07.2023 14:51
#Acquired=	03.07.2023 14:51:10
201.713	36
204.247	30
206.778	32
209.311	22
211.84	30
214.371	32
216.899	24
219.428	36
221.955	26
224.482	26
227.007	24
229.531	28
232.055	30
234.579	36
237.1	20
239.621	28
242.141	34
244.661	28
247.179	30
249.698	28
252.215	32
254.731	34
257.246	24
259.761	30
262.273	32
264.786	28
267.298	32
269.809	32
272.319	42
274.828	28
277.336	40
279.844	34
282.351	32
284.855	34
287.361	30
289.866	22
292.368	30
294.871	24
297.372	34
299.873	26
302.372	28
304.872	38
307.37	26
309.866	24
312.364	24
314.859	28
317.353	34
319.848	26
322.341	34
324.833	36
327.324	42
329.814	36
332.304	36
334.792	28
337.28	28
339.767	40
342.254	32
344.739	32
347.224	28
349.708	28
352.191	26
354.673	36
357.155	28
359.634	34
362.114	30
364.593	32
367.07	36
369.548	36
372.024	36
374.499	28
376.974	34
379.447	48
381.92	30
384.392	36
386.864	32
389.333	38
391.802	32
394.272	36
396.739	34
399.206	38
401.673	36
404.138	28
406.602	28
409.066	38
411.528	32
413.99	34
416.451	32
418.911	42
421.371	34
423.83	30
426.288	32
428.745	34
431.201	34
433.657	32
436.111	32
438.565	40
441.017	40
443.469	30
445.921	32
448.37	30
450.821	30
453.27	38
455.717	36
458.165	36
460.61	32
463.056	32
465.5	36
467.945	40
470.387	38
472.829	36
475.271	40
477.711	42
480.15	42
482.589	44
485.027	36
487.465	42
489.901	40
492.337	38
494.771	42
497.205	36
499.638	34
502.07	40
504.502	40
506.933	40
509.363	32
511.792	36
514.219	44
516.647	38
519.073	48
521.5	38
523.924	38
526.348	34
528.772	42
531.194	40
533.616	32
536.036	34
538.457	46
540.875	44
543.294	40
545.712	50
548.128	44
550.545	38
552.959	40
555.373	42
557.788	48
560.2	48
562.612	50
565.023	44
567.433	40
569.843	40
572.251	46
574.659	52
577.066	40
579.472	38
581.878	46
584.283	46
586.687	44
589.09	46
591.493	38
593.893	46
596.294	46
598.694	38
601.093	50
603.491	48
605.889	46
608.285	42
610.682	50
613.076	46
615.471	48
617.864	56
620.256	44
622.648	48
625.039	48
627.429	50
629.819	50
632.208	38
634.595	58
636.982	56
639.369	48
641.755	48
644.139	46
646.523	48
648.906	50
651.288	58
653.67	52
656.051	50
658.429	50
660.808	42
663.187	52
665.565	54
667.942	54
670.317	54
672.692	60
675.067	62
677.44	60
679.813	50
682.184	56
684.556	50
686.926	50
689.296	50
691.664	58
694.033	52
696.4	52
698.766	60
701.133	58
703.497	58
705.861	64
708.224	62
710.586	60
712.949	54
715.31	68
717.67	56
720.029	66
722.388	60
724.746	64
727.103	70
729.458	62
731.814	76
734.168	54
736.523	68
738.876	72
741.227	68
743.579	78
745.931	76
748.28	76
750.629	66
752.977	78
755.325	74
757.672	72
760.018	74
762.363	64
764.708	62
767.052	76
769.394	72
771.737	76
774.078	88
776.419	70
778.758	72
781.097	68
783.435	76
785.773	68
788.11	68
790.446	82
792.781	80
795.115	68
797.449	88
799.782	78
802.115	72
804.446	78
806.777	92
809.106	98
811.435	86
813.764	86
816.091	92
818.418	90
820.743	92
823.069	84
825.393	88
827.717	96
830.039	86
832.362	82
834.683	92
837.003	82
839.324	102
841.643	100
843.961	96
846.278	106
848.594	92
850.91	118
853.227	106
855.541	98
857.855	112
860.168	102
862.48	94
864.79	112
867.101	106
869.411	110
871.721	112
874.029	114
876.336	106
878.643	116
880.95	118
883.254	122
885.559	114
887.862	132
890.166	124
892.467	112
894.77	116
897.07	112
899.371	116
901.669	136
903.968	132
906.266	124
908.563	138
910.859	138
913.154	126
915.449	142
917.742	128
920.036	134
922.329	138
924.621	138
926.911	132
929.201	136
931.49	130
933.779	144
936.068	152
938.355	136
940.64	136
942.926	154
945.212	144
947.495	134
949.779	146
952.062	148
954.344	156
956.625	144
958.905	166
961.184	172
963.464	152
965.742	180
968.02	168
970.296	168
972.572	168
974.847	174
977.121	166
979.396	176
981.669	172
983.941	170
986.212	182
988.483	180
990.753	188
993.022	188
995.29	184
997.558	186
999.825	182
1002.09	182
1004.36	196
1006.62	196
1008.89	196
1011.15	198
1013.41	222
1015.67	206
1017.93	200
1020.19	202
1022.45	192
1024.71	222
1026.97	192
1029.23	204
1031.49	212
1033.74	202
1036	212
1038.25	222
1040.5	226
1042.76	220
1045.01	240
1047.26	228
1049.51	232
1051.76	218
1054.01	224
1056.26	234
1058.51	242
1060.75	256
1063	244
1065.25	258
1067.49	252
1069.73	250
1071.98	250
1074.22	276
1076.46	242
1078.7	264
1080.94	246
1083.18	274
1085.42	278
1087.66	268
1089.9	290
1092.14	268
1094.37	274
1096.61	260
1098.84	266
1101.08	274
1103.31	274
1105.54	288
1107.77	278
1110	270
1112.23	290
1114.46	274
1116.69	286
1118.92	278
1121.15	290
1123.37	296
1125.6	276
1127.83	296
1130.05	284
1132.27	298
1134.5	278
1136.72	292
1138.94	290
1141.16	304
1143.38	310
1145.6	296
1147.82	318
1150.04	322
1152.26	308
1154.47	304
1156.69	320
1158.9	300
1161.12	324
1163.33	338
1165.54	314
1167.76	318
1169.97	308
1172.18	302
1174.39	288
1176.6	326
1178.81	308
1181.02	310
1183.22	328
1185.43	312
1187.63	330
1189.84	328
1192.04	334
1194.25	314
1196.45	302
1198.65	324
1200.85	316
1203.05	322
1205.25	288
1207.45	316
1209.65	324
1211.85	310
1214.05	322
1216.24	298
1218.44	312
1220.64	300
1222.83	302
1225.02	296
1227.22	324
1229.41	296
1231.6	286
1233.79	308
1235.98	290
1238.17	292
1240.36	296
1242.55	294
1244.73	298
1246.92	292
1249.11	316
1251.29	292
1253.48	294
1255.66	282
1257.84	294
1260.03	280
1262.21	294
1264.39	270
1266.57	292
1268.75	278
1270.93	286
1273.11	270
1275.28	280
1277.46	280
1279.64	258
1281.81	288
1283.98	285.626
1286.16	266.877
1288.33	266.949
1290.5	263.922
1292.68	251.447
1294.85	254.117
1297.02	246.569
1299.19	229.745
1301.36	266.896
1303.53	233.938
1305.69	240.035
1307.86	240.494
1310.03	231.885
1312.19	228.281
1314.36	224.555
1316.52	239.499
1318.68	224.653
1320.85	229.688
1323.01	209.109
1325.17	225.262
1327.33	220.427
1329.49	203.162
1331.65	206.303
1333.81	197.239
1335.97	185.835
1338.12	192.52
1340.28	186.017
1342.44	199.038
1344.59	186.403
1346.75	188.442
1348.9	188.678
1351.05	180.195
1353.2	180.27
1355.36	171.074
1357.51	165.458
1359.66	170.656
1361.81	174.682
1363.96	165.839
1366.1	162.479
1368.25	164.732
1370.4	166.015
1372.54	161.203
1374.69	157.359
1376.83	154.415
1378.98	154.56
1381.12	143.442
1383.26	152.765
1385.41	143.383
1387.55	146.714
1389.69	143.975
1391.83	138.743
1393.02	136
1395.17	134
1397.32	146
1399.47	128
1401.62	130
1403.77	142
1405.91	142
1408.06	136
1410.2	132
1412.35	130
1414.49	126
1416.63	138
1418.78	124
1420.92	132
1423.06	138
1425.2	128
1427.34	134
1429.48	136
1431.61	132
1433.75	114
1435.89	128
1438.02	132
1440.16	126
1442.3	116
1444.43	126
1446.56	120
1448.7	118
1450.83	128
1452.96	116
1455.09	114
1457.22	122
1459.35	114
1461.48	106
1463.61	138
1465.73	120
1467.86	114
1469.98	124
1472.11	130
1474.24	108
1476.36	118
1478.48	108
1480.6	118
1482.73	108
1484.85	114
1486.97	122
1489.09	122
1491.21	100
1493.33	104
1495.44	116
1497.56	110
1499.68	110
1501.79	116
1503.91	104
1506.02	104
1508.14	96
1510.25	96
1512.36	104
1514.48	104
1516.59	102
1518.7	98
1520.81	110
1522.92	104
1525.02	102
1527.13	98
1529.24	110
1531.35	112
1533.45	110
1535.56	98
1537.66	96
1539.77	100
1541.87	100
1543.97	94
1546.08	108
1548.18	86
1550.28	106
1552.38	92
1554.48	84
1556.57	96
1558.67	102
1560.77	96
1562.87	92
1564.96	100
1567.06	90
1569.15	100
1571.25	90
1573.34	102
1575.43	90
1577.53	92
1579.62	112
1581.71	94
1583.8	92
1585.89	98
1587.98	96
1590.06	98
1592.15	82
1594.24	96
1596.33	92
1598.41	86
1600.5	100
1602.58	96
1604.66	100
1606.75	86
1608.83	100
1610.91	94
1612.99	88
1615.07	94
1617.15	96
1619.23	86
1621.31	100
1623.39	92
1625.46	92
1627.54	96
1629.62	90
1631.69	92
1633.77	98
1635.84	78
1637.91	104
1639.99	78
1642.06	88
1644.13	92
1646.2	90
1648.27	92
1650.34	92
1652.41	98
1654.47	88
1656.54	82
1658.61	92
1660.67	88
1662.74	90
1664.81	100
1666.87	92
1668.93	86
1671	88
1673.06	98
1675.12	82
1677.18	94
1679.24	80
1681.3	90
1683.36	84
1685.42	88
1687.47	86
1689.53	90
1691.59	90
1693.64	74
1695.7	98
1697.75	88
1699.81	84
1701.86	82
1703.91	84
1705.97	82
1708.02	90
1710.07	80
1712.12	78
1714.17	82
1716.22	80
1718.26	72
1720.31	84
1722.36	68
1724.4	84
1726.45	68
1728.49	78
1730.54	76
1732.58	66
1734.63	86
1736.67	84
1738.71	82
1740.75	84
1742.79	88
1744.83	76
1746.87	76
1748.91	72
1750.95	82
1752.98	82
1755.02	86
1757.06	88
1759.09	84
1761.13	88
1763.16	74
1765.19	76
1767.23	86
1769.26	80
1771.29	90
1773.32	90
1775.35	80
1777.38	90
1779.41	90
1781.44	80
1783.47	84
1785.49	76
1787.52	78
1789.55	78
1791.57	76
1793.6	82
1795.62	74
1797.64	80
1799.67	82
1801.69	90
1803.71	70
1805.73	78
1807.75	82
1809.77	90
1811.79	88
1813.81	86
1815.83	86
1817.84	84
1819.86	68
1821.88	88
1823.89	76
1825.91	80
1827.92	88
1829.93	82
1831.95	76
1833.96	92
1835.97	88
1837.98	72
1839.99	88
1842	90
1844.01	88
1846.02	88
1848.03	86
1850.03	94
1852.04	80
1854.05	84
1856.05	80
1858.06	78
1860.06	76
1862.06	76
1864.07	82
1866.07	84
1868.07	84
1870.07	78
1872.07	78
1874.07	84
1876.07	72
1878.07	78
1880.07	90
1882.07	80
1884.06	82
1886.06	74
1888.05	88
1890.05	78
1892.04	88
1894.04	86
1896.03	86
1898.02	80
1900.01	76
1902	90
1903.99	78
1905.98	82
1907.97	84
1909.96	86
1911.95	74
1913.94	82
1915.93	74
1917.91	70
1919.9	82
1921.88	72
1923.87	74
1925.85	80
1927.83	78
1929.82	78
1931.8	76
1933.78	80
1935.76	92
1937.74	76
1939.72	82
1941.7	68
1943.68	86
1945.65	88
1947.63	78
1949.61	78
1951.58	74
1953.56	78
1955.53	70
1957.51	76
1959.48	80
1961.45	74
1963.43	74
1965.4	76
1967.37	80
1969.34	76
1971.31	82
1973.28	74
1975.25	70
1977.22	78
1979.18	86
1981.15	86
1983.12	74
1985.08	82
1987.05	82
1989.01	82
1990.97	90
1992.94	80
1994.9	76
1996.86	84
1998.82	90
2000.78	68
2002.74	86
2004.7	70
2006.66	80
2008.62	76
2010.58	78
2012.54	82
2014.49	80
2016.45	80
2018.4	68
2020.36	84
2022.31	78
2024.27	72
2026.22	70
2028.17	82
2030.12	74
2032.07	78
2034.03	80
2035.98	78
2037.93	82
2039.87	80
2041.82	62
2043.77	74
2045.72	84
2047.66	78
2049.61	76
2051.55	80
2053.5	78
2055.44	86
2057.39	72
2059.33	80
2061.27	88
2063.21	80
2065.15	84
2067.09	70
2069.03	78
2070.97	64
2072.91	76
2074.85	72
2076.79	84
2078.73	84
2080.66	72
2082.6	74
2084.53	66
2086.47	68
2088.4	76
2090.33	78
2092.27	70
2094.2	86
2096.13	72
2098.06	82
2099.99	72
2101.92	76
2103.85	72
2105.78	76
2107.71	80
2109.64	74
2111.56	78
2113.49	78
2115.41	82
2117.34	74
2119.26	74
2121.19	84
2123.11	70
2125.03	74
2126.96	78
2128.88	84
2130.8	76
2132.72	68
2134.64	70
2136.56	78
2138.48	88
2140.4	74
2142.31	68
2144.23	70
2146.15	68
2148.06	78
2149.98	70
2151.89	82
2153.81	80
2155.72	78
2157.63	74
2159.55	68
2161.46	86
2163.37	76
2165.28	74
2167.19	76
2169.1	78
2171.01	66
2172.91	92
2174.82	84
2176.73	70
2178.64	78
2180.54	68
2182.45	78
2184.35	70
2186.26	76
2188.16	82
2190.06	80
2191.96	66
2193.87	72
2195.77	76
2197.67	84
2199.57	80
2201.47	64
2203.37	76
2205.27	76
2207.16	72
2209.06	70
2210.96	76
2212.85	70
2214.75	76
2216.64	68
2218.54	74
2220.43	78
2222.33	72
2224.22	71.7916
2226.11	70.1921
2228	84.7754
2229.89	72.8067
2231.78	68.5047
2233.67	71.3067
2235.56	79.2923
2237.45	74.738
2239.34	67.8901
2241.23	71.9909
2243.11	71.4031
2245	67.0966
2246.89	67.6499
2248.77	69.3192
2250.66	61.2595
2252.54	74.3147
2254.42	67.6882
2256.31	66.204
2258.19	68.6126
2260.07	65.3594
2261.95	70.4786
2263.83	67.8199
2265.71	69.5792
2267.59	71.0679
2269.47	69.7223
2271.35	65.0869
2273.23	69.9167
2275.1	62.9445
2276.98	69.8095
2278.86	63.0602
2280.73	68.604
2282.61	63.7078
2284.48	63.7385
2286.36	60.1153
2288.23	63.6175
2290.1	64.6902
2291.98	64.8465
2293.85	66.554
2295.72	60.1589
2297.59	59.372
2299.46	57.4235
2301.33	64.3746
2303.2	64.8566
2305.06	55.3136
2306.93	67.346
2308.8	63.0694
2310.67	58.8538
2312.53	58.18
2314.4	53.3118
2316.26	65.0804
2317.62	60
2319.5	56
2321.37	68
2323.24	64
2325.12	68
2326.99	58
2328.86	56
2330.73	72
2332.6	54
2334.47	56
2336.34	58
2338.2	54
2340.07	54
2341.94	48
2343.81	64
2345.67	62
2347.54	66
2349.4	60
2351.27	64
2353.13	62
2354.99	56
2356.86	66
2358.72	60
2360.58	60
2362.44	52
2364.3	64
2366.16	68
2368.02	62
2369.88	66
2371.74	62
2373.6	64
2375.45	58
2377.31	54
2379.17	62
2381.02	60
2382.88	66
2384.73	56
2386.58	60
2388.44	56
2390.29	66
2392.14	60
2393.99	50
2395.85	62
2397.7	60
2399.55	66
2401.4	64
2403.25	68
2405.09	54
2406.94	62
2408.79	56
2410.63	62
2412.48	66
2414.33	50
2416.17	52
2418.02	56
2419.86	58
2421.7	54
2423.55	52
2425.39	58
2427.23	54
2429.07	50
2430.91	50
2432.75	58
2434.59	58
2436.43	64
2438.27	52
2440.11	60
2441.95	56
2443.78	56
2445.62	48
2447.46	64
2449.29	50
2451.13	56
2452.96	48
2454.79	62
2456.63	58
2458.46	60
2460.29	56
2462.12	56
2463.95	56
2465.78	48
2467.61	48
2469.44	48
2471.27	52
2473.1	52
2474.93	58
2476.76	56
2478.58	50
2480.41	56
2482.23	50
2484.06	50
2485.88	50
2487.71	54
2489.53	60
2491.35	56
2493.18	46
2495	58
2496.82	62
2498.64	60
2500.46	50
2502.28	48
2504.1	52
2505.92	54
2507.74	48
2509.55	52
2511.37	56
2513.19	54
2515	58
2516.82	58
2518.63	56
2520.45	70
2522.26	54
2524.07	52
2525.89	54
2527.7	52
2529.51	50
2531.32	50
2533.13	62
2534.94	50
2536.75	54
2538.56	52
2540.37	42
2542.18	44
2543.98	48
2545.79	54
2547.6	52
2549.4	46
2551.21	50
2553.01	46
2554.82	42
2556.62	60
2558.42	54
2560.23	54
2562.03	48
2563.83	54
2565.63	48
2567.43	48
2569.23	54
2571.03	52
2572.83	42
2574.63	54
2576.43	44
2578.22	52
2580.02	56
2581.82	42
2583.61	50
2585.41	50
2587.2	44
2589	50
2590.79	56
2592.58	38
2594.38	38
2596.17	54
2597.96	48
2599.75	54
2601.54	48
2603.33	48
2605.12	48
2606.91	46
2608.7	54
2610.49	46
2612.27	50
2614.06	46
2615.85	44
2617.63	52
2619.42	44
2621.2	46
2622.99	44
2624.77	46
2626.55	48
2628.34	48
2630.12	44
2631.9	46
2633.68	42
2635.46	34
2637.24	40
2639.02	48
2640.8	52
2642.58	48
2644.36	44
2646.14	52
2647.91	50
2649.69	48
2651.46	42
2653.24	46
2655.01	48
2656.79	52
2658.56	52
2660.34	48
2662.11	40
2663.88	44
2665.65	36
2667.42	50
2669.2	44
2670.96	44
2672.73	50
2674.5	48
2676.27	46
2678.04	44
2679.81	38
2681.58	42
2683.34	46
2685.11	48
2686.87	52
2688.64	46
2690.4	38
2692.17	46
2693.93	46
2695.69	46
2697.46	46
2699.22	42
2700.98	34
2702.74	42
2704.5	32
2706.26	46
2708.02	46
2709.78	42
2711.54	42
2713.3	44
2715.05	40
2716.81	48
2718.57	44
2720.32	42
2722.08	46
2723.83	44
2725.59	42
2727.34	46
2729.09	50
2730.85	38
2732.6	40
2734.35	46
2736.1	40
2737.85	38
2739.6	44
2741.35	38
2743.1	44
2744.85	42
2746.6	46
2748.35	40
2750.09	38
2751.84	36
2753.59	40
2755.33	38
2757.08	42
2758.82	38
2760.57	40
2762.31	44
2764.05	38
2765.79	40
2767.54	38
2769.28	48
2771.02	46
2772.76	54
2774.5	44
2776.24	40
2777.98	40
2779.72	36
2781.46	46
2783.19	34
2784.93	46
2786.67	32
2788.4	42
2790.14	34
2791.87	36
2793.61	36
2795.34	38
2797.07	42
2798.81	40
2800.54	42
2802.27	36
2804	40
2805.74	32
2807.47	40
2809.2	34
2810.93	40
2812.65	38
2814.38	42
2816.11	36
2817.84	34
2819.56	48
2821.29	44
2823.02	42
2824.74	32
2826.47	40
2828.19	44
2829.92	44
2831.64	36
2833.36	42
2835.09	34
2836.81	44
2838.53	40
2840.25	32
2841.97	46
2843.69	36
2845.41	38
2847.13	40
2848.85	42
2850.57	36
2852.28	30
2854	32
2855.72	36
2857.43	30
2859.15	30
2860.86	40
2862.58	42
2864.29	40
2866.01	36
2867.72	44
2869.43	32
2871.14	34
2872.86	34
2874.57	38
2876.28	36
2877.99	38
2879.7	38
2881.41	40
2883.11	44
2884.82	32
2886.53	34
2888.24	42
2889.94	38
2891.65	36
2893.36	32
2895.06	38
2896.77	36
2898.47	36
2900.17	42
2901.88	38
2903.58	36
2905.28	34
2906.98	32
2908.69	30
2910.39	36
2912.09	36
2913.79	40
2915.49	38
2917.19	28
2918.88	50
2920.58	34
2922.28	42
2923.98	40
2925.67	40
2927.37	36
2929.06	42
2930.76	32
2932.45	38
2934.15	30
2935.84	32
2937.53	38
2939.23	32
2940.92	26
2942.61	32
2944.3	36
2945.99	36
2947.68	34
2949.37	28
2951.06	34
2952.75	22
2954.44	46
2956.12	40
2957.81	28
2959.5	36
2961.18	32
2962.87	40
2964.56	34
2966.24	34
2967.92	36
2969.61	42
2971.29	40
2972.97	36
2974.66	38
2976.34	32
2978.02	28
2979.7	36
2981.38	30
2983.06	32
2984.74	30
2986.42	40
2988.1	38
2989.78	42
2991.45	36
2993.13	38
2994.81	36
2996.48	38
2998.16	34
2999.83	32