File: muestras/nopal/inside_prf_19.txt
#Acq. time (s)=	10
#Accumulations=	1
#Range (cm-¹)=	200...3000
#Windows=	3
#Autofocus=	Off
#AutoExposure=	Off
#Spike filter=	Off
#Delay time (s)=	0
#Binning=	1
#Readout mode=	Signal
#DeNoise=	Off
#ICS correction=	Off
#Dark correction=	Off
#Inst. Process=	Off
#Instrument=	LabRAM HR Evol
#Detector=	Syncerity OE
#Objective=	x100_VIS
#Grating=	600 (500nm)
#ND Filter=	0.01%
#Laser=	633nm_Edge
#Hole=	30.0125
#Range=	Visible
#Project=	Omar
#Sample=	03-07-23
#Site=	nop
#Title=	inside_prf
#Remark=
#Date=	03.07.2023 14:47
#Acquired=	03.07.2023 14:47:56
201.713	26
204.247	34
206.778	32
209.311	30
211.84	24
214.371	32
216.899	34
219.428	26
221.955	38
224.482	30
227.007	28
229.531	30
232.055	26
234.579	38
237.1	32
239.621	30
242.141	28
244.661	28
247.179	34
249.698	30
252.215	28
254.731	32
257.246	28
259.761	30
262.273	30
264.786	26
267.298	30
269.809	26
272.319	30
274.828	26
277.336	28
279.844	30
282.351	28
284.855	24
287.361	32
289.866	30
292.368	28
294.871	24
297.372	32
299.873	32
302.372	28
304.872	28
307.37	36
309.866	22
312.364	30
314.859	34
317.353	32
319.848	28
322.341	38
324.833	32
327.324	36
329.814	40
332.304	32
334.792	26
337.28	28
339.767	32
342.254	32
344.739	34
347.224	26
349.708	28
352.191	42
354.673	36
357.155	30
359.634	34
362.114	36
364.593	34
367.07	36
369.548	28
372.024	32
374.499	30
376.974	38
379.447	28
381.92	26
384.392	30
386.864	30
389.333	44
391.802	36
394.272	38
396.739	32
399.206	32
401.673	26
404.138	40
406.602	32
409.066	34
411.528	30
413.99	38
416.451	32
418.911	36
421.371	32
423.83	28
426.288	38
428.745	34
431.201	34
433.657	34
436.111	44
438.565	36
441.017	42
443.469	28
445.921	34
448.37	40
450.821	42
453.27	40
455.717	32
458.165	36
460.61	30
463.056	38
465.5	42
467.945	34
470.387	34
472.829	38
475.271	26
477.711	42
480.15	36
482.589	38
485.027	52
487.465	38
489.901	42
492.337	36
494.771	42
497.205	42
499.638	40
502.07	40
504.502	46
506.933	36
509.363	54
511.792	38
514.219	52
516.647	46
519.073	44
521.5	46
523.924	36
526.348	40
528.772	38
531.194	38
533.616	36
536.036	42
538.457	36
540.875	48
543.294	40
545.712	40
548.128	38
550.545	34
552.959	36
555.373	36
557.788	40
560.2	46
562.612	40
565.023	44
567.433	48
569.843	48
572.251	52
574.659	38
577.066	46
579.472	42
581.878	42
584.283	48
586.687	44
589.09	48
591.493	38
593.893	46
596.294	44
598.694	46
601.093	38
603.491	40
605.889	40
608.285	50
610.682	42
613.076	44
615.471	48
617.864	48
620.256	40
622.648	46
625.039	40
627.429	44
629.819	48
632.208	58
634.595	48
636.982	54
639.369	50
641.755	56
644.139	46
646.523	54
648.906	50
651.288	56
653.67	48
656.051	54
658.429	50
660.808	48
663.187	58
665.565	54
667.942	52
670.317	62
672.692	54
675.067	48
677.44	54
679.813	60
682.184	52
684.556	64
686.926	52
689.296	58
691.664	54
694.033	62
696.4	54
698.766	54
701.133	56
703.497	56
705.861	62
708.224	66
710.586	60
712.949	60
715.31	58
717.67	72
720.029	60
722.388	52
724.746	72
727.103	62
729.458	68
731.814	58
734.168	62
736.523	68
738.876	66
741.227	66
743.579	62
745.931	60
748.28	66
750.629	72
752.977	76
755.325	64
757.672	74
760.018	72
762.363	68
764.708	74
767.052	80
769.394	76
771.737	62
774.078	72
776.419	72
778.758	68
781.097	62
783.435	76
785.773	68
788.11	82
790.446	66
792.781	80
795.115	80
797.449	74
799.782	92
802.115	80
804.446	70
806.777	88
809.106	74
811.435	90
813.764	100
816.091	82
818.418	78
820.743	88
823.069	88
825.393	94
827.717	86
830.039	84
832.362	94
834.683	86
837.003	90
839.324	84
841.643	94
843.961	98
846.278	92
848.594	104
850.91	102
853.227	102
855.541	98
857.855	108
860.168	106
862.48	96
864.79	96
867.101	116
869.411	100
871.721	114
874.029	122
876.336	116
878.643	112
880.95	112
883.254	106
885.559	110
887.862	112
890.166	108
892.467	98
894.77	114
897.07	106
899.371	120
901.669	112
903.968	130
906.266	122
908.563	126
910.859	140
913.154	118
915.449	124
917.742	124
920.036	116
922.329	124
924.621	120
926.911	124
929.201	128
931.49	134
933.779	134
936.068	134
938.355	134
940.64	138
942.926	128
945.212	134
947.495	146
949.779	156
952.062	142
954.344	140
956.625	150
958.905	154
961.184	148
963.464	144
965.742	154
968.02	166
970.296	150
972.572	142
974.847	158
977.121	156
979.396	152
981.669	156
983.941	158
986.212	162
988.483	142
990.753	172
993.022	174
995.29	162
997.558	168
999.825	182
1002.09	190
1004.36	186
1006.62	170
1008.89	182
1011.15	166
1013.41	172
1015.67	170
1017.93	192
1020.19	188
1022.45	198
1024.71	178
1026.97	186
1029.23	196
1031.49	196
1033.74	204
1036	196
1038.25	196
1040.5	200
1042.76	216
1045.01	204
1047.26	220
1049.51	202
1051.76	208
1054.01	232
1056.26	216
1058.51	224
1060.75	230
1063	224
1065.25	230
1067.49	230
1069.73	240
1071.98	250
1074.22	218
1076.46	206
1078.7	228
1080.94	232
1083.18	226
1085.42	248
1087.66	252
1089.9	242
1092.14	234
1094.37	234
1096.61	256
1098.84	250
1101.08	256
1103.31	240
1105.54	242
1107.77	248
1110	260
1112.23	244
1114.46	258
1116.69	252
1118.92	252
1121.15	250
1123.37	250
1125.6	270
1127.83	272
1130.05	262
1132.27	262
1134.5	272
1136.72	274
1138.94	254
1141.16	292
1143.38	286
1145.6	272
1147.82	280
1150.04	302
1152.26	270
1154.47	302
1156.69	314
1158.9	280
1161.12	282
1163.33	282
1165.54	298
1167.76	274
1169.97	282
1172.18	282
1174.39	284
1176.6	296
1178.81	304
1181.02	298
1183.22	284
1185.43	280
1187.63	298
1189.84	274
1192.04	302
1194.25	292
1196.45	286
1198.65	282
1200.85	296
1203.05	286
1205.25	294
1207.45	300
1209.65	302
1211.85	268
1214.05	278
1216.24	286
1218.44	304
1220.64	278
1222.83	288
1225.02	296
1227.22	280
1229.41	284
1231.6	274
1233.79	294
1235.98	280
1238.17	280
1240.36	284
1242.55	284
1244.73	274
1246.92	284
1249.11	278
1251.29	292
1253.48	256
1255.66	244
1257.84	282
1260.03	268
1262.21	258
1264.39	288
1266.57	266
1268.75	262
1270.93	260
1273.11	284
1275.28	278
1277.46	258
1279.64	246
1281.81	260
1283.98	246.3
1286.16	263.092
1288.33	244.68
1290.5	251.583
1292.68	243.002
1294.85	245.424
1297.02	245.324
1299.19	248.333
1301.36	248.929
1303.53	249.214
1305.69	242.451
1307.86	252.93
1310.03	248.787
1312.19	258.364
1314.36	234.899
1316.52	243.477
1318.68	251.109
1320.85	234.02
1323.01	244.472
1325.17	243.561
1327.33	232.525
1329.49	236.393
1331.65	235.281
1333.81	224.164
1335.97	246.837
1338.12	231.844
1340.28	238.261
1342.44	237.948
1344.59	229.878
1346.75	221.403
1348.9	226.743
1351.05	236.464
1353.2	214.937
1355.36	233.323
1357.51	236.065
1359.66	233.79
1361.81	226.542
1363.96	211.276
1366.1	239.862
1368.25	217.24
1370.4	242.47
1372.54	208.187
1374.69	227.655
1376.83	212.298
1378.98	225.512
1381.12	220.395
1383.26	209.711
1385.41	209.912
1387.55	225.788
1389.69	206.368
1391.83	203.976
1393.02	204
1395.17	216
1397.32	210
1399.47	216
1401.62	208
1403.77	218
1405.91	206
1408.06	200
1410.2	212
1412.35	194
1414.49	198
1416.63	202
1418.78	216
1420.92	204
1423.06	190
1425.2	190
1427.34	190
1429.48	208
1431.61	188
1433.75	202
1435.89	194
1438.02	184
1440.16	184
1442.3	190
1444.43	184
1446.56	188
1448.7	188
1450.83	176
1452.96	176
1455.09	170
1457.22	174
1459.35	178
1461.48	176
1463.61	180
1465.73	166
1467.86	178
1469.98	176
1472.11	164
1474.24	178
1476.36	164
1478.48	170
1480.6	170
1482.73	168
1484.85	168
1486.97	170
1489.09	154
1491.21	160
1493.33	154
1495.44	150
1497.56	164
1499.68	166
1501.79	152
1503.91	142
1506.02	152
1508.14	172
1510.25	154
1512.36	154
1514.48	148
1516.59	164
1518.7	164
1520.81	158
1522.92	148
1525.02	150
1527.13	146
1529.24	148
1531.35	150
1533.45	148
1535.56	146
1537.66	148
1539.77	146
1541.87	152
1543.97	144
1546.08	142
1548.18	136
1550.28	148
1552.38	130
1554.48	158
1556.57	144
1558.67	140
1560.77	150
1562.87	134
1564.96	136
1567.06	138
1569.15	132
1571.25	128
1573.34	144
1575.43	130
1577.53	138
1579.62	132
1581.71	132
1583.8	134
1585.89	142
1587.98	138
1590.06	130
1592.15	134
1594.24	134
1596.33	136
1598.41	136
1600.5	146
1602.58	132
1604.66	128
1606.75	128
1608.83	130
1610.91	130
1612.99	136
1615.07	132
1617.15	128
1619.23	130
1621.31	156
1623.39	144
1625.46	132
1627.54	134
1629.62	128
1631.69	110
1633.77	138
1635.84	124
1637.91	120
1639.99	130
1642.06	138
1644.13	126
1646.2	136
1648.27	138
1650.34	128
1652.41	130
1654.47	122
1656.54	122
1658.61	126
1660.67	130
1662.74	122
1664.81	110
1666.87	126
1668.93	118
1671	132
1673.06	108
1675.12	116
1677.18	118
1679.24	120
1681.3	130
1683.36	130
1685.42	128
1687.47	122
1689.53	114
1691.59	124
1693.64	124
1695.7	112
1697.75	106
1699.81	126
1701.86	114
1703.91	116
1705.97	118
1708.02	124
1710.07	128
1712.12	110
1714.17	106
1716.22	112
1718.26	112
1720.31	118
1722.36	114
1724.4	122
1726.45	112
1728.49	122
1730.54	116
1732.58	128
1734.63	126
1736.67	134
1738.71	116
1740.75	128
1742.79	112
1744.83	116
1746.87	122
1748.91	110
1750.95	116
1752.98	122
1755.02	122
1757.06	118
1759.09	128
1761.13	110
1763.16	104
1765.19	122
1767.23	112
1769.26	124
1771.29	108
1773.32	124
1775.35	120
1777.38	108
1779.41	124
1781.44	110
1783.47	104
1785.49	120
1787.52	104
1789.55	118
1791.57	114
1793.6	118
1795.62	112
1797.64	118
1799.67	138
1801.69	118
1803.71	108
1805.73	102
1807.75	112
1809.77	114
1811.79	116
1813.81	110
1815.83	108
1817.84	118
1819.86	132
1821.88	120
1823.89	160
1825.91	364
1827.92	114
1829.93	120
1831.95	120
1833.96	116
1835.97	114
1837.98	122
1839.99	118
1842	108
1844.01	116
1846.02	122
1848.03	124
1850.03	122
1852.04	106
1854.05	118
1856.05	112
1858.06	116
1860.06	134
1862.06	102
1864.07	110
1866.07	114
1868.07	106
1870.07	120
1872.07	106
1874.07	120
1876.07	122
1878.07	120
1880.07	114
1882.07	114
1884.06	108
1886.06	102
1888.05	124
1890.05	122
1892.04	126
1894.04	106
1896.03	104
1898.02	102
1900.01	112
1902	108
1903.99	116
1905.98	98
1907.97	106
1909.96	98
1911.95	106
1913.94	102
1915.93	124
1917.91	106
1919.9	118
1921.88	104
1923.87	114
1925.85	118
1927.83	102
1929.82	104
1931.8	120
1933.78	114
1935.76	118
1937.74	106
1939.72	112
1941.7	114
1943.68	108
1945.65	122
1947.63	116
1949.61	118
1951.58	110
1953.56	116
1955.53	118
1957.51	112
1959.48	98
1961.45	106
1963.43	100
1965.4	110
1967.37	94
1969.34	120
1971.31	108
1973.28	114
1975.25	118
1977.22	114
1979.18	116
1981.15	94
1983.12	106
1985.08	114
1987.05	114
1989.01	112
1990.97	110
1992.94	132
1994.9	104
1996.86	94
1998.82	114
2000.78	112
2002.74	112
2004.7	110
2006.66	102
2008.62	104
2010.58	108
2012.54	108
2014.49	108
2016.45	108
2018.4	118
2020.36	106
2022.31	110
2024.27	102
2026.22	110
2028.17	111
2030.12	116
2032.07	106
2034.03	106
2035.98	116
2037.93	112
2039.87	100
2041.82	106
2043.77	114
2045.72	100
2047.66	100
2049.61	104
2051.55	116
2053.5	102
2055.44	108
2057.39	102
2059.33	100
2061.27	108
2063.21	110
2065.15	102
2067.09	104
2069.03	112
2070.97	116
2072.91	116
2074.85	110
2076.79	106
2078.73	122
2080.66	106
2082.6	108
2084.53	104
2086.47	110
2088.4	110
2090.33	100
2092.27	110
2094.2	114
2096.13	114
2098.06	114
2099.99	100
2101.92	98
2103.85	110
2105.78	106
2107.71	112
2109.64	104
2111.56	104
2113.49	110
2115.41	92
2117.34	96
2119.26	106
2121.19	104
2123.11	112
2125.03	116
2126.96	102
2128.88	106
2130.8	108
2132.72	110
2134.64	106
2136.56	94
2138.48	108
2140.4	100
2142.31	106
2144.23	118
2146.15	104
2148.06	116
2149.98	106
2151.89	110
2153.81	104
2155.72	112
2157.63	102
2159.55	106
2161.46	108
2163.37	110
2165.28	104
2167.19	106
2169.1	106
2171.01	106
2172.91	110
2174.82	104
2176.73	116
2178.64	108
2180.54	108
2182.45	94
2184.35	98
2186.26	96
2188.16	98
2190.06	102
2191.96	102
2193.87	100
2195.77	92
2197.67	100
2199.57	114
2201.47	96
2203.37	114
2205.27	104
2207.16	98
2209.06	98
2210.96	102
2212.85	106
2214.75	102
2216.64	106
2218.54	82
2220.43	96
2222.33	110
2224.22	100.322
2226.11	95.0649
2228	98.4582
2229.89	100.777
2231.78	106.472
2233.67	98.5316
2235.56	105.506
2237.45	98.8395
2239.34	101.46
2241.23	103.332
2243.11	103.891
2245	103.76
2246.89	106.59
2248.77	102.137
2250.66	98.0842
2252.54	115.404
2254.42	107.122
2256.31	97.3095
2258.19	105.025
2260.07	116.939
2261.95	108.854
2263.83	108.37
2265.71	104.862
2267.59	112.468
2269.47	111.522
2271.35	113.959
2273.23	108.117
2275.1	106.138
2276.98	110.523
2278.86	116.41
2280.73	107.68
2282.61	101.823
2284.48	105.294
2286.36	104.725
2288.23	122.028
2290.1	97.6363
2291.98	114.301
2293.85	112.15
2295.72	105.968
2297.59	108.402
2299.46	109.073
2301.33	112.678
2303.2	116.243
2305.06	119.456
2306.93	116.11
2308.8	108.491
2310.67	104.334
2312.53	116.525
2314.4	114.991
2316.26	108.332
2317.62	120
2319.5	120
2321.37	122
2323.24	104
2325.12	112
2326.99	116
2328.86	132
2330.73	110
2332.6	106
2334.47	110
2336.34	124
2338.2	104
2340.07	114
2341.94	110
2343.81	118
2345.67	104
2347.54	114
2349.4	100
2351.27	116
2353.13	110
2354.99	100
2356.86	100
2358.72	106
2360.58	116
2362.44	102
2364.3	100
2366.16	116
2368.02	104
2369.88	110
2371.74	122
2373.6	100
2375.45	110
2377.31	118
2379.17	120
2381.02	116
2382.88	104
2384.73	104
2386.58	112
2388.44	98
2390.29	114
2392.14	102
2393.99	116
2395.85	112
2397.7	104
2399.55	108
2401.4	96
2403.25	98
2405.09	100
2406.94	94
2408.79	106
2410.63	108
2412.48	104
2414.33	104
2416.17	112
2418.02	110
2419.86	98
2421.7	102
2423.55	106
2425.39	100
2427.23	94
2429.07	92
2430.91	100
2432.75	102
2434.59	108
2436.43	98
2438.27	106
2440.11	96
2441.95	98
2443.78	104
2445.62	106
2447.46	104
2449.29	102
2451.13	98
2452.96	96
2454.79	94
2456.63	82
2458.46	100
2460.29	94
2462.12	88
2463.95	94
2465.78	94
2467.61	100
2469.44	96
2471.27	96
2473.1	90
2474.93	102
2476.76	100
2478.58	96
2480.41	90
2482.23	100
2484.06	90
2485.88	98
2487.71	94
2489.53	90
2491.35	98
2493.18	100
2495	94
2496.82	86
2498.64	90
2500.46	90
2502.28	98
2504.1	96
2505.92	86
2507.74	94
2509.55	90
2511.37	90
2513.19	96
2515	88
2516.82	82
2518.63	88
2520.45	90
2522.26	86
2524.07	88
2525.89	78
2527.7	94
2529.51	92
2531.32	84
2533.13	88
2534.94	80
2536.75	86
2538.56	90
2540.37	84
2542.18	88
2543.98	96
2545.79	82
2547.6	96
2549.4	70
2551.21	84
2553.01	84
2554.82	92
2556.62	84
2558.42	92
2560.23	86
2562.03	86
2563.83	74
2565.63	78
2567.43	74
2569.23	80
2571.03	84
2572.83	80
2574.63	88
2576.43	82
2578.22	82
2580.02	78
2581.82	64
2583.61	68
2585.41	70
2587.2	74
2589	80
2590.79	72
2592.58	80
2594.38	80
2596.17	80
2597.96	76
2599.75	86
2601.54	64
2603.33	72
2605.12	86
2606.91	78
2608.7	72
2610.49	72
2612.27	72
2614.06	68
2615.85	78
2617.63	76
2619.42	68
2621.2	90
2622.99	86
2624.77	72
2626.55	80
2628.34	70
2630.12	78
2631.9	88
2633.68	70
2635.46	82
2637.24	78
2639.02	80
2640.8	72
2642.58	74
2644.36	72
2646.14	70
2647.91	64
2649.69	74
2651.46	70
2653.24	76
2655.01	78
2656.79	76
2658.56	68
2660.34	70
2662.11	80
2663.88	82
2665.65	78
2667.42	60
2669.2	70
2670.96	68
2672.73	72
2674.5	76
2676.27	68
2678.04	72
2679.81	68
2681.58	78
2683.34	70
2685.11	70
2686.87	68
2688.64	66
2690.4	74
2692.17	66
2693.93	68
2695.69	64
2697.46	80
2699.22	70
2700.98	68
2702.74	62
2704.5	58
2706.26	66
2708.02	62
2709.78	74
2711.54	68
2713.3	64
2715.05	74
2716.81	66
2718.57	72
2720.32	64
2722.08	64
2723.83	62
2725.59	62
2727.34	64
2729.09	68
2730.85	62
2732.6	64
2734.35	62
2736.1	72
2737.85	60
2739.6	62
2741.35	72
2743.1	58
2744.85	48
2746.6	66
2748.35	70
2750.09	66
2751.84	68
2753.59	62
2755.33	62
2757.08	58
2758.82	66
2760.57	54
2762.31	58
2764.05	54
2765.79	58
2767.54	58
2769.28	46
2771.02	46
2772.76	62
2774.5	52
2776.24	52
2777.98	62
2779.72	52
2781.46	54
2783.19	62
2784.93	52
2786.67	62
2788.4	56
2790.14	50
2791.87	50
2793.61	60
2795.34	54
2797.07	54
2798.81	56
2800.54	60
2802.27	54
2804	54
2805.74	46
2807.47	48
2809.2	52
2810.93	50
2812.65	56
2814.38	66
2816.11	50
2817.84	48
2819.56	56
2821.29	54
2823.02	50
2824.74	50
2826.47	60
2828.19	54
2829.92	56
2831.64	60
2833.36	48
2835.09	52
2836.81	64
2838.53	62
2840.25	60
2841.97	44
2843.69	54
2845.41	56
2847.13	56
2848.85	50
2850.57	60
2852.28	58
2854	44
2855.72	52
2857.43	50
2859.15	34
2860.86	48
2862.58	56
2864.29	52
2866.01	52
2867.72	52
2869.43	54
2871.14	50
2872.86	42
2874.57	46
2876.28	46
2877.99	44
2879.7	50
2881.41	54
2883.11	54
2884.82	48
2886.53	54
2888.24	56
2889.94	50
2891.65	48
2893.36	44
2895.06	46
2896.77	44
2898.47	46
2900.17	46
2901.88	54
2903.58	44
2905.28	42
2906.98	46
2908.69	52
2910.39	44
2912.09	42
2913.79	38
2915.49	38
2917.19	48
2918.88	40
2920.58	44
2922.28	38
2923.98	46
2925.67	48
2927.37	40
2929.06	42
2930.76	42
2932.45	44
2934.15	40
2935.84	46
2937.53	40
2939.23	50
2940.92	46
2942.61	48
2944.3	48
2945.99	46
2947.68	38
2949.37	42
2951.06	42
2952.75	36
2954.44	36
2956.12	54
2957.81	50
2959.5	44
2961.18	44
2962.87	52
2964.56	46
2966.24	44
2967.92	42
2969.61	44
2971.29	42
2972.97	44
2974.66	42
2976.34	40
2978.02	42
2979.7	48
2981.38	40
2983.06	46
2984.74	44
2986.42	46
2988.1	46
2989.78	36
2991.45	40
2993.13	48
2994.81	44
2996.48	42
2998.16	40
2999.83	36