File: muestras/nopal/inside_prf_20.txt
#Acq. time (s)=	10
#Accumulations=	1
#Range (cm-¹)=	200...3000
#Windows=	3
#Autofocus=	Off
#AutoExposure=	Off
#Spike filter=	Off
#Delay time (s)=	0
#Binning=	1
#Readout mode=	Signal
#DeNoise=	Off
#ICS correction=	Off
#Dark correction=	Off
#Inst. Process=	Off
#Instrument=	LabRAM HR Evol
#Detector=	Syncerity OE
#Objective=	x100_VIS
#Grating=	600 (500nm)
#ND Filter=	0.01%
#Laser=	633nm_Edge
#Hole=	30.0125
#Range=	Visible
#Project=	Omar
#Sample=	03-07-23
#Site=	nop
#Title=	inside_prf
#Remark=
#Date=	03.07.2023 14:49
#Acquired=	03.07.2023 14:49:21
201.713	42
204.247	38
206.778	36
209.311	32
211.84	34
214.371	34
216.899	34
219.428	36
221.955	30
224.482	38
227.007	28
229.531	32
232.055	38
234.579	36
237.1	36
239.621	36
242.141	40
244.661	42
247.179	48
249.698	36
252.215	38
254.731	30
257.246	40
259.761	42
262.273	40
264.786	38
267.298	34
269.809	46
272.319	34
274.828	52
277.336	40
279.844	44
282.351	42
284.855	44
287.361	42
289.866	44
292.368	38
294.871	48
297.372	44
299.873	36
302.372	44
304.872	48
307.37	44
309.866	44
312.364	46
314.859	36
317.353	46
319.848	40
322.341	50
324.833	48
327.324	44
329.814	36
332.304	50
334.792	38
337.28	54
339.767	54
342.254	54
344.739	52
347.224	54
349.708	52
352.191	42
354.673	54
357.155	44
359.634	60
362.114	52
364.593	54
367.07	54
369.548	58
372.024	54
374.499	60
376.974	50
379.447	44
381.92	50
384.392	56
386.864	56
389.333	56
391.802	60
394.272	58
396.739	56
399.206	60
401.673	66
404.138	52
406.602	54
409.066	60
411.528	60
413.99	62
416.451	60
418.911	60
421.371	62
423.83	68
426.288	62
428.745	72
431.201	64
433.657	62
436.111	68
438.565	64
441.017	60
443.469	64
445.921	72
448.37	62
450.821	62
453.27	72
455.717	66
458.165	68
460.61	74
463.056	78
465.5	64
467.945	66
470.387	76
472.829	60
475.271	70
477.711	72
480.15	82
482.589	70
485.027	82
487.465	78
489.901	78
492.337	78
494.771	88
497.205	84
499.638	82
502.07	80
504.502	80
506.933	80
509.363	84
511.792	86
514.219	86
516.647	72
519.073	76
521.5	72
523.924	90
526.348	84
528.772	94
531.194	92
533.616	88
536.036	80
538.457	88
540.875	74
543.294	84
545.712	92
548.128	96
550.545	88
552.959	94
555.373	94
557.788	96
560.2	86
562.612	82
565.023	104
567.433	108
569.843	98
572.251	92
574.659	104
577.066	96
579.472	90
581.878	98
584.283	92
586.687	118
589.09	98
591.493	100
593.893	96
596.294	114
598.694	102
601.093	120
603.491	118
605.889	122
608.285	110
610.682	100
613.076	120
615.471	122
617.864	110
620.256	124
622.648	118
625.039	112
627.429	112
629.819	130
632.208	132
634.595	128
636.982	136
639.369	116
641.755	124
644.139	122
646.523	122
648.906	122
651.288	132
653.67	134
656.051	144
658.429	134
660.808	144
663.187	142
665.565	138
667.942	128
670.317	152
672.692	136
675.067	138
677.44	154
679.813	138
682.184	148
684.556	150
686.926	162
689.296	162
691.664	154
694.033	150
696.4	154
698.766	162
701.133	154
703.497	168
705.861	154
708.224	146
710.586	158
712.949	178
715.31	172
717.67	178
720.029	174
722.388	176
724.746	170
727.103	182
729.458	188
731.814	172
734.168	184
736.523	178
738.876	196
741.227	172
743.579	188
745.931	194
748.28	200
750.629	196
752.977	212
755.325	206
757.672	212
760.018	218
762.363	202
764.708	226
767.052	210
769.394	238
771.737	242
774.078	252
776.419	236
778.758	224
781.097	234
783.435	232
785.773	224
788.11	244
790.446	250
792.781	254
795.115	246
797.449	244
799.782	266
802.115	260
804.446	270
806.777	284
809.106	274
811.435	286
813.764	272
816.091	284
818.418	298
820.743	286
823.069	278
825.393	302
827.717	300
830.039	282
832.362	306
834.683	298
837.003	302
839.324	324
841.643	302
843.961	332
846.278	334
848.594	338
850.91	338
853.227	364
855.541	340
857.855	354
860.168	342
862.48	372
864.79	358
867.101	346
869.411	382
871.721	362
874.029	364
876.336	390
878.643	394
880.95	376
883.254	394
885.559	398
887.862	414
890.166	396
892.467	398
894.77	406
897.07	408
899.371	450
901.669	446
903.968	456
906.266	426
908.563	466
910.859	424
913.154	438
915.449	450
917.742	448
920.036	466
922.329	470
924.621	462
926.911	480
929.201	496
931.49	480
933.779	492
936.068	492
938.355	520
940.64	502
942.926	508
945.212	516
947.495	524
949.779	556
952.062	550
954.344	552
956.625	556
958.905	566
961.184	558
963.464	560
965.742	610
968.02	544
970.296	580
972.572	600
974.847	620
977.121	592
979.396	598
981.669	576
983.941	654
986.212	652
988.483	654
990.753	686
993.022	644
995.29	666
997.558	676
999.825	664
1002.09	700
1004.36	692
1006.62	678
1008.89	724
1011.15	688
1013.41	730
1015.67	716
1017.93	734
1020.19	746
1022.45	734
1024.71	770
1026.97	760
1029.23	784
1031.49	800
1033.74	772
1036	778
1038.25	814
1040.5	830
1042.76	834
1045.01	816
1047.26	844
1049.51	848
1051.76	866
1054.01	850
1056.26	912
1058.51	884
1060.75	912
1063	894
1065.25	890
1067.49	910
1069.73	898
1071.98	928
1074.22	952
1076.46	936
1078.7	936
1080.94	924
1083.18	948
1085.42	952
1087.66	960
1089.9	990
1092.14	984
1094.37	994
1096.61	1034
1098.84	982
1101.08	1000
1103.31	1042
1105.54	988
1107.77	1040
1110	1044
1112.23	1060
1114.46	1064
1116.69	1040
1118.92	1066
1121.15	1070
1123.37	1104
1125.6	1110
1127.83	1122
1130.05	1076
1132.27	1130
1134.5	1114
1136.72	1144
1138.94	1170
1141.16	1102
1143.38	1120
1145.6	1178
1147.82	1160
1150.04	1160
1152.26	1156
1154.47	1190
1156.69	1188
1158.9	1206
1161.12	1204
1163.33	1202
1165.54	1218
1167.76	1238
1169.97	1194
1172.18	1216
1174.39	1242
1176.6	1252
1178.81	1246
1181.02	1266
1183.22	1240
1185.43	1212
1187.63	1264
1189.84	1260
1192.04	1250
1194.25	1240
1196.45	1240
1198.65	1290
1200.85	1268
1203.05	1222
1205.25	1238
1207.45	1260
1209.65	1274
1211.85	1280
1214.05	1240
1216.24	1264
1218.44	1242
1220.64	1248
1222.83	1250
1225.02	1234
1227.22	1216
1229.41	1254
1231.6	1232
1233.79	1236
1235.98	1216
1238.17	1218
1240.36	1206
1242.55	1216
1244.73	1250
1246.92	1186
1249.11	1228
1251.29	1186
1253.48	1212
1255.66	1188
1257.84	1212
1260.03	1220
1262.21	1150
1264.39	1200
1266.57	1204
1268.75	1152
1270.93	1162
1273.11	1178
1275.28	1116
1277.46	1162
1279.64	1142
1281.81	1104
1283.98	1130.12
1286.16	1150.84
1288.33	1128.01
1290.5	1115.38
1292.68	1097.26
1294.85	1111.31
1297.02	1108.23
1299.19	1068.25
1301.36	1062.91
1303.53	1094.5
1305.69	1051.54
1307.86	1071.37
1310.03	1066.51
1312.19	1050.21
1314.36	1041.74
1316.52	1018.02
1318.68	1037.85
1320.85	1033.42
1323.01	972.334
1325.17	983.366
1327.33	998.962
1329.49	1000.54
1331.65	1010.09
1333.81	961.133
1335.97	957.152
1338.12	957.734
1340.28	948.279
1342.44	945.985
1344.59	925.044
1346.75	929.118
1348.9	924.67
1351.05	932.152
1353.2	884.848
1355.36	901.507
1357.51	863.799
1359.66	910.268
1361.81	903.978
1363.96	870.552
1366.1	837.574
1368.25	848.338
1370.4	866.087
1372.54	814.778
1374.69	838.625
1376.83	850.242
1378.98	816.568
1381.12	845.431
1383.26	783.704
1385.41	817.394
1387.55	791.726
1389.69	795.494
1391.83	770.846
1393.02	812
1395.17	796
1397.32	772
1399.47	786
1401.62	760
1403.77	770
1405.91	726
1408.06	732
1410.2	720
1412.35	752
1414.49	702
1416.63	724
1418.78	736
1420.92	698
1423.06	698
1425.2	752
1427.34	712
1429.48	736
1431.61	690
1433.75	712
1435.89	690
1438.02	696
1440.16	708
1442.3	668
1444.43	666
1446.56	660
1448.7	664
1450.83	680
1452.96	658
1455.09	648
1457.22	620
1459.35	652
1461.48	638
1463.61	602
1465.73	636
1467.86	622
1469.98	626
1472.11	644
1474.24	600
1476.36	624
1478.48	640
1480.6	634
1482.73	622
1484.85	594
1486.97	624
1489.09	630
1491.21	602
1493.33	606
1495.44	588
1497.56	586
1499.68	582
1501.79	582
1503.91	610
1506.02	608
1508.14	578
1510.25	576
1512.36	560
1514.48	574
1516.59	604
1518.7	594
1520.81	556
1522.92	558
1525.02	590
1527.13	560
1529.24	560
1531.35	548
1533.45	528
1535.56	568
1537.66	540
1539.77	550
1541.87	568
1543.97	520
1546.08	534
1548.18	488
1550.28	524
1552.38	518
1554.48	530
1556.57	480
1558.67	506
1560.77	508
1562.87	486
1564.96	514
1567.06	530
1569.15	510
1571.25	494
1573.34	526
1575.43	490
1577.53	500
1579.62	486
1581.71	490
1583.8	544
1585.89	480
1587.98	484
1590.06	492
1592.15	484
1594.24	498
1596.33	490
1598.41	492
1600.5	490
1602.58	494
1604.66	484
1606.75	490
1608.83	510
1610.91	470
1612.99	490
1615.07	470
1617.15	500
1619.23	482
1621.31	458
1623.39	478
1625.46	474
1627.54	466
1629.62	474
1631.69	460
1633.77	472
1635.84	470
1637.91	456
1639.99	480
1642.06	474
1644.13	458
1646.2	466
1648.27	458
1650.34	480
1652.41	460
1654.47	474
1656.54	442
1658.61	454
1660.67	458
1662.74	442
1664.81	446
1666.87	458
1668.93	464
1671	454
1673.06	460
1675.12	454
1677.18	464
1679.24	448
1681.3	452
1683.36	400
1685.42	434
1687.47	434
1689.53	432
1691.59	444
1693.64	456
1695.7	404
1697.75	436
1699.81	450
1701.86	438
1703.91	452
1705.97	438
1708.02	418
1710.07	422
1712.12	430
1714.17	420
1716.22	434
1718.26	424
1720.31	424
1722.36	430
1724.4	408
1726.45	420
1728.49	442
1730.54	424
1732.58	414
1734.63	408
1736.67	434
1738.71	418
1740.75	396
1742.79	428
1744.83	424
1746.87	400
1748.91	434
1750.95	410
1752.98	434
1755.02	424
1757.06	444
1759.09	446
1761.13	404
1763.16	422
1765.19	396
1767.23	410
1769.26	432
1771.29	448
1773.32	432
1775.35	412
1777.38	428
1779.41	394
1781.44	384
1783.47	424
1785.49	444
1787.52	420
1789.55	420
1791.57	402
1793.6	428
1795.62	408
1797.64	426
1799.67	400
1801.69	410
1803.71	446
1805.73	416
1807.75	430
1809.77	432
1811.79	408
1813.81	440
1815.83	414
1817.84	406
1819.86	422
1821.88	428
1823.89	414
1825.91	420
1827.92	426
1829.93	402
1831.95	418
1833.96	418
1835.97	424
1837.98	416
1839.99	424
1842	416
1844.01	406
1846.02	418
1848.03	424
1850.03	412
1852.04	404
1854.05	410
1856.05	402
1858.06	420
1860.06	420
1862.06	414
1864.07	442
1866.07	382
1868.07	410
1870.07	386
1872.07	422
1874.07	408
1876.07	422
1878.07	398
1880.07	426
1882.07	380
1884.06	424
1886.06	414
1888.05	420
1890.05	410
1892.04	392
1894.04	416
1896.03	396
1898.02	428
1900.01	408
1902	426
1903.99	418
1905.98	418
1907.97	398
1909.96	400
1911.95	400
1913.94	416
1915.93	410
1917.91	406
1919.9	384
1921.88	408
1923.87	426
1925.85	404
1927.83	416
1929.82	392
1931.8	404
1933.78	436
1935.76	418
1937.74	400
1939.72	438
1941.7	402
1943.68	410
1945.65	396
1947.63	430
1949.61	410
1951.58	404
1953.56	396
1955.53	400
1957.51	410
1959.48	374
1961.45	400
1963.43	404
1965.4	378
1967.37	388
1969.34	376
1971.31	376
1973.28	402
1975.25	420
1977.22	386
1979.18	410
1981.15	420
1983.12	398
1985.08	420
1987.05	416
1989.01	420
1990.97	402
1992.94	402
1994.9	414
1996.86	392
1998.82	396
2000.78	402
2002.74	390
2004.7	388
2006.66	422
2008.62	402
2010.58	412
2012.54	410
2014.49	416
2016.45	404
2018.4	412
2020.36	392
2022.31	436
2024.27	410
2026.22	408
2028.17	392
2030.12	412
2032.07	404
2034.03	404
2035.98	434
2037.93	406
2039.87	410
2041.82	384
2043.77	422
2045.72	406
2047.66	400
2049.61	426
2051.55	406
2053.5	410
2055.44	402
2057.39	382
2059.33	374
2061.27	394
2063.21	420
2065.15	408
2067.09	392
2069.03	394
2070.97	412
2072.91	430
2074.85	398
2076.79	412
2078.73	400
2080.66	418
2082.6	392
2084.53	396
2086.47	394
2088.4	384
2090.33	402
2092.27	412
2094.2	416
2096.13	376
2098.06	402
2099.99	388
2101.92	382
2103.85	402
2105.78	376
2107.71	404
2109.64	396
2111.56	384
2113.49	416
2115.41	398
2117.34	378
2119.26	396
2121.19	382
2123.11	402
2125.03	376
2126.96	392
2128.88	390
2130.8	388
2132.72	402
2134.64	396
2136.56	384
2138.48	392
2140.4	410
2142.31	402
2144.23	390
2146.15	418
2148.06	406
2149.98	410
2151.89	396
2153.81	414
2155.72	418
2157.63	380
2159.55	398
2161.46	390
2163.37	388
2165.28	408
2167.19	380
2169.1	384
2171.01	390
2172.91	388
2174.82	416
2176.73	412
2178.64	396
2180.54	372
2182.45	408
2184.35	382
2186.26	386
2188.16	420
2190.06	366
2191.96	386
2193.87	402
2195.77	388
2197.67	386
2199.57	406
2201.47	398
2203.37	380
2205.27	422
2207.16	386
2209.06	402
2210.96	404
2212.85	380
2214.75	382
2216.64	396
2218.54	370
2220.43	392
2222.33	372
2224.22	380.038
2226.11	376.097
2228	406.276
2229.89	385.297
2231.78	376.26
2233.67	381.931
2235.56	374.532
2237.45	402.411
2239.34	378.02
2241.23	400.871
2243.11	382.28
2245	363.087
2246.89	377.215
2248.77	392.658
2250.66	380.906
2252.54	386.423
2254.42	384.932
2256.31	381.491
2258.19	385.5
2260.07	387.694
2261.95	388.556
2263.83	388.29
2265.71	375.918
2267.59	387.99
2269.47	393.076
2271.35	393.463
2273.23	373.173
2275.1	379.899
2276.98	385.006
2278.86	359.951
2280.73	386.269
2282.61	370.804
2284.48	385.862
2286.36	365.92
2288.23	381.164
2290.1	375.193
2291.98	366.12
2293.85	367.907
2295.72	382.663
2297.59	372.576
2299.46	367.4
2301.33	373.213
2303.2	383.877
2305.06	381.868
2306.93	388.358
2308.8	382.493
2310.67	362.156
2312.53	362.585
2314.4	373.859
2316.26	358.321
2317.62	384
2319.5	380
2321.37	366
2323.24	364
2325.12	360
2326.99	334
2328.86	342
2330.73	354
2332.6	326
2334.47	356
2336.34	364
2338.2	360
2340.07	348
2341.94	350
2343.81	358
2345.67	368
2347.54	366
2349.4	378
2351.27	384
2353.13	360
2354.99	360
2356.86	334
2358.72	362
2360.58	366
2362.44	368
2364.3	378
2366.16	364
2368.02	356
2369.88	330
2371.74	354
2373.6	358
2375.45	368
2377.31	348
2379.17	358
2381.02	352
2382.88	360
2384.73	346
2386.58	350
2388.44	356
2390.29	344
2392.14	334
2393.99	326
2395.85	344
2397.7	350
2399.55	320
2401.4	362
2403.25	322
2405.09	346
2406.94	344
2408.79	334
2410.63	350
2412.48	334
2414.33	338
2416.17	316
2418.02	380
2419.86	340
2421.7	342
2423.55	324
2425.39	320
2427.23	338
2429.07	310
2430.91	324
2432.75	340
2434.59	312
2436.43	352
2438.27	318
2440.11	316
2441.95	320
2443.78	320
2445.62	312
2447.46	314
2449.29	332
2451.13	292
2452.96	302
2454.79	318
2456.63	314
2458.46	330
2460.29	302
2462.12	326
2463.95	324
2465.78	302
2467.61	304
2469.44	332
2471.27	332
2473.1	290
2474.93	302
2476.76	312
2478.58	304
2480.41	298
2482.23	308
2484.06	300
2485.88	322
2487.71	306
2489.53	296
2491.35	308
2493.18	280
2495	312
2496.82	304
2498.64	296
2500.46	300
2502.28	286
2504.1	290
2505.92	298
2507.74	274
2509.55	286
2511.37	296
2513.19	290
2515	286
2516.82	290
2518.63	290
2520.45	270
2522.26	260
2524.07	268
2525.89	276
2527.7	276
2529.51	268
2531.32	280
2533.13	286
2534.94	272
2536.75	284
2538.56	264
2540.37	266
2542.18	264
2543.98	268
2545.79	260
2547.6	270
2549.4	264
2551.21	274
2553.01	278
2554.82	266
2556.62	254
2558.42	264
2560.23	266
2562.03	248
2563.83	248
2565.63	262
2567.43	270
2569.23	254
2571.03	250
2572.83	254
2574.63	248
2576.43	250
2578.22	268
2580.02	264
2581.82	230
2583.61	250
2585.41	248
2587.2	256
2589	246
2590.79	240
2592.58	250
2594.38	244
2596.17	248
2597.96	226
2599.75	240
2601.54	226
2603.33	222
2605.12	236
2606.91	258
2608.7	252
2610.49	250
2612.27	252
2614.06	234
2615.85	236
2617.63	242
2619.42	224
2621.2	232
2622.99	224
2624.77	234
2626.55	230
2628.34	236
2630.12	224
2631.9	248
2633.68	222
2635.46	228
2637.24	226
2639.02	224
2640.8	212
2642.58	234
2644.36	212
2646.14	226
2647.91	218
2649.69	220
2651.46	220
2653.24	220
2655.01	220
2656.79	190
2658.56	212
2660.34	210
2662.11	200
2663.88	214
2665.65	216
2667.42	222
2669.2	222
2670.96	206
2672.73	214
2674.5	208
2676.27	220
2678.04	206
2679.81	192
2681.58	214
2683.34	206
2685.11	196
2686.87	212
2688.64	190
2690.4	200
2692.17	206
2693.93	190
2695.69	218
2697.46	204
2699.22	184
2700.98	202
2702.74	202
2704.5	182
2706.26	208
2708.02	178
2709.78	186
2711.54	182
2713.3	196
2715.05	198
2716.81	192
2718.57	198
2720.32	178
2722.08	174
2723.83	182
2725.59	202
2727.34	182
2729.09	178
2730.85	182
2732.6	196
2734.35	188
2736.1	190
2737.85	184
2739.6	194
2741.35	192
2743.1	156
2744.85	182
2746.6	176
2748.35	184
2750.09	182
2751.84	174
2753.59	178
2755.33	168
2757.08	172
2758.82	162
2760.57	178
2762.31	162
2764.05	162
2765.79	174
2767.54	162
2769.28	166
2771.02	164
2772.76	164
2774.5	162
2776.24	156
2777.98	172
2779.72	158
2781.46	150
2783.19	148
2784.93	166
2786.67	162
2788.4	154
2790.14	138
2791.87	166
2793.61	166
2795.34	166
2797.07	146
2798.81	160
2800.54	150
2802.27	166
2804	164
2805.74	154
2807.47	140
2809.2	142
2810.93	152
2812.65	146
2814.38	152
2816.11	162
2817.84	148
2819.56	138
2821.29	164
2823.02	146
2824.74	140
2826.47	144
2828.19	138
2829.92	144
2831.64	132
2833.36	142
2835.09	136
2836.81	148
2838.53	132
2840.25	138
2841.97	152
2843.69	142
2845.41	136
2847.13	144
2848.85	126
2850.57	138
2852.28	122
2854	146
2855.72	140
2857.43	140
2859.15	136
2860.86	138
2862.58	116
2864.29	130
2866.01	138
2867.72	118
2869.43	124
2871.14	122
2872.86	140
2874.57	118
2876.28	136
2877.99	124
2879.7	140
2881.41	130
2883.11	128
2884.82	128
2886.53	126
2888.24	132
2889.94	130
2891.65	116
2893.36	130
2895.06	134
2896.77	116
2898.47	120
2900.17	134
2901.88	124
2903.58	102
2905.28	136
2906.98	120
2908.69	112
2910.39	116
2912.09	126
2913.79	128
2915.49	118
2917.19	124
2918.88	118
2920.58	112
2922.28	122
2923.98	116
2925.67	118
2927.37	104
2929.06	116
2930.76	104
2932.45	118
2934.15	106
2935.84	100
2937.53	110
2939.23	120
2940.92	108
2942.61	112
2944.3	114
2945.99	102
2947.68	100
2949.37	112
2951.06	96
2952.75	116
2954.44	106
2956.12	104
2957.81	116
2959.5	114
2961.18	104
2962.87	112
2964.56	104
2966.24	100
2967.92	120
2969.61	96
2971.29	106
2972.97	116
2974.66	102
2976.34	102
2978.02	94
2979.7	96
2981.38	96
2983.06	96
2984.74	88
2986.42	82
2988.1	100
2989.78	92
2991.45	102
2993.13	98
2994.81	104
2996.48	100
2998.16	96
2999.83	96