File: muestras/nopal/inside_prf_12.txt
#Acq. time (s)=	10
#Accumulations=	1
#Range (cm-¹)=	200...3000
#Windows=	3
#Autofocus=	Off
#AutoExposure=	Off
#Spike filter=	Off
#Delay time (s)=	0
#Binning=	1
#Readout mode=	Signal
#DeNoise=	Off
#ICS correction=	Off
#Dark correction=	Off
#Inst. Process=	Off
#Instrument=	LabRAM HR Evol
#Detector=	Syncerity OE
#Objective=	x100_VIS
#Grating=	600 (500nm)
#ND Filter=	0.01%
#Laser=	633nm_Edge
#Hole=	30.0125
#Range=	Visible
#Project=	Omar
#Sample=	03-07-23
#Site=	nop
#Title=	inside_prf
#Remark=
#Date=	03.07.2023 14:37
#Acquired=	03.07.2023 14:37:09
201.713	26
204.247	42
206.778	30
209.311	36
211.84	32
214.371	34
216.899	36
219.428	34
221.955	44
224.482	28
227.007	32
229.531	32
232.055	38
234.579	30
237.1	32
239.621	34
242.141	24
244.661	34
247.179	42
249.698	36
252.215	24
254.731	30
257.246	36
259.761	30
262.273	34
264.786	28
267.298	40
269.809	38
272.319	36
274.828	34
277.336	34
279.844	40
282.351	38
284.855	40
287.361	36
289.866	38
292.368	36
294.871	34
297.372	40
299.873	36
302.372	38
304.872	28
307.37	40
309.866	34
312.364	30
314.859	34
317.353	34
319.848	32
322.341	32
324.833	34
327.324	42
329.814	32
332.304	32
334.792	46
337.28	42
339.767	50
342.254	36
344.739	40
347.224	42
349.708	40
352.191	44
354.673	38
357.155	34
359.634	54
362.114	46
364.593	36
367.07	50
369.548	44
372.024	32
374.499	34
376.974	42
379.447	48
381.92	38
384.392	42
386.864	38
389.333	42
391.802	46
394.272	48
396.739	42
399.206	42
401.673	44
404.138	42
406.602	42
409.066	48
411.528	52
413.99	56
416.451	46
418.911	46
421.371	46
423.83	40
426.288	44
428.745	46
431.201	46
433.657	44
436.111	46
438.565	52
441.017	36
443.469	54
445.921	54
448.37	58
450.821	60
453.27	54
455.717	54
458.165	58
460.61	44
463.056	52
465.5	54
467.945	52
470.387	56
472.829	54
475.271	62
477.711	44
480.15	58
482.589	58
485.027	46
487.465	50
489.901	54
492.337	54
494.771	56
497.205	54
499.638	62
502.07	62
504.502	46
506.933	54
509.363	54
511.792	54
514.219	52
516.647	56
519.073	60
521.5	60
523.924	64
526.348	60
528.772	68
531.194	68
533.616	58
536.036	56
538.457	66
540.875	58
543.294	68
545.712	60
548.128	72
550.545	64
552.959	64
555.373	58
557.788	60
560.2	58
562.612	72
565.023	60
567.433	66
569.843	58
572.251	74
574.659	68
577.066	66
579.472	66
581.878	60
584.283	66
586.687	72
589.09	68
591.493	66
593.893	66
596.294	62
598.694	64
601.093	72
603.491	70
605.889	82
608.285	76
610.682	82
613.076	82
615.471	80
617.864	72
620.256	76
622.648	82
625.039	80
627.429	78
629.819	82
632.208	88
634.595	74
636.982	84
639.369	84
641.755	78
644.139	92
646.523	94
648.906	84
651.288	96
653.67	92
656.051	96
658.429	82
660.808	94
663.187	92
665.565	90
667.942	88
670.317	102
672.692	92
675.067	78
677.44	104
679.813	104
682.184	102
684.556	90
686.926	102
689.296	98
691.664	100
694.033	108
696.4	108
698.766	106
701.133	100
703.497	106
705.861	108
708.224	110
710.586	110
712.949	114
715.31	108
717.67	104
720.029	114
722.388	108
724.746	116
727.103	122
729.458	132
731.814	120
734.168	136
736.523	134
738.876	130
741.227	134
743.579	118
745.931	132
748.28	136
750.629	144
752.977	144
755.325	130
757.672	128
760.018	134
762.363	152
764.708	142
767.052	138
769.394	144
771.737	140
774.078	162
776.419	146
778.758	168
781.097	152
783.435	150
785.773	160
788.11	152
790.446	170
792.781	174
795.115	172
797.449	160
799.782	172
802.115	160
804.446	174
806.777	168
809.106	176
811.435	186
813.764	174
816.091	198
818.418	186
820.743	196
823.069	188
825.393	188
827.717	216
830.039	200
832.362	202
834.683	200
837.003	232
839.324	204
841.643	228
843.961	216
846.278	214
848.594	226
850.91	226
853.227	214
855.541	220
857.855	216
860.168	232
862.48	230
864.79	240
867.101	244
869.411	246
871.721	258
874.029	252
876.336	240
878.643	254
880.95	252
883.254	250
885.559	270
887.862	282
890.166	280
892.467	264
894.77	280
897.07	284
899.371	300
901.669	280
903.968	264
906.266	304
908.563	284
910.859	302
913.154	292
915.449	298
917.742	318
920.036	294
922.329	322
924.621	328
926.911	300
929.201	330
931.49	298
933.779	326
936.068	332
938.355	344
940.64	332
942.926	334
945.212	350
947.495	370
949.779	348
952.062	384
954.344	366
956.625	380
958.905	370
961.184	348
963.464	368
965.742	396
968.02	386
970.296	408
972.572	420
974.847	400
977.121	404
979.396	430
981.669	416
983.941	418
986.212	420
988.483	424
990.753	434
993.022	446
995.29	430
997.558	462
999.825	444
1002.09	418
1004.36	464
1006.62	470
1008.89	474
1011.15	486
1013.41	500
1015.67	470
1017.93	476
1020.19	498
1022.45	492
1024.71	508
1026.97	512
1029.23	526
1031.49	520
1033.74	534
1036	540
1038.25	520
1040.5	536
1042.76	546
1045.01	572
1047.26	558
1049.51	564
1051.76	576
1054.01	598
1056.26	596
1058.51	600
1060.75	604
1063	606
1065.25	604
1067.49	646
1069.73	608
1071.98	638
1074.22	636
1076.46	618
1078.7	638
1080.94	636
1083.18	634
1085.42	652
1087.66	668
1089.9	668
1092.14	678
1094.37	666
1096.61	668
1098.84	684
1101.08	682
1103.31	686
1105.54	648
1107.77	722
1110	674
1112.23	722
1114.46	686
1116.69	730
1118.92	714
1121.15	736
1123.37	746
1125.6	718
1127.83	700
1130.05	718
1132.27	712
1134.5	740
1136.72	732
1138.94	760
1141.16	766
1143.38	758
1145.6	758
1147.82	756
1150.04	760
1152.26	732
1154.47	784
1156.69	814
1158.9	752
1161.12	790
1163.33	776
1165.54	794
1167.76	778
1169.97	758
1172.18	800
1174.39	802
1176.6	784
1178.81	816
1181.02	816
1183.22	784
1185.43	790
1187.63	794
1189.84	748
1192.04	792
1194.25	748
1196.45	812
1198.65	768
1200.85	788
1203.05	754
1205.25	770
1207.45	734
1209.65	758
1211.85	740
1214.05	740
1216.24	760
1218.44	728
1220.64	720
1222.83	732
1225.02	690
1227.22	734
1229.41	706
1231.6	714
1233.79	694
1235.98	698
1238.17	706
1240.36	688
1242.55	694
1244.73	706
1246.92	688
1249.11	664
1251.29	682
1253.48	712
1255.66	676
1257.84	644
1260.03	678
1262.21	686
1264.39	648
1266.57	638
1268.75	644
1270.93	624
1273.11	664
1275.28	638
1277.46	634
1279.64	630
1281.81	592
1283.98	607.408
1286.16	604.493
1288.33	599.259
1290.5	606.348
1292.68	593.6
1294.85	555.298
1297.02	573.276
1299.19	537.295
1301.36	540.232
1303.53	540.448
1305.69	537.003
1307.86	534.799
1310.03	519.808
1312.19	526.22
1314.36	515.181
1316.52	524.506
1318.68	481.698
1320.85	485.164
1323.01	486.921
1325.17	457.46
1327.33	457.99
1329.49	445.812
1331.65	459.678
1333.81	456.985
1335.97	449.744
1338.12	424.455
1340.28	424.435
1342.44	420.296
1344.59	415.197
1346.75	394.209
1348.9	399.059
1351.05	391.511
1353.2	391.828
1355.36	379.202
1357.51	386.897
1359.66	378.151
1361.81	371.199
1363.96	361.918
1366.1	372.436
1368.25	349.369
1370.4	343.69
1372.54	329.054
1374.69	331.85
1376.83	330.836
1378.98	334.015
1381.12	323.694
1383.26	308.44
1385.41	324.565
1387.55	309.951
1389.69	310.603
1391.83	289.432
1393.02	288
1395.17	298
1397.32	298
1399.47	290
1401.62	292
1403.77	294
1405.91	284
1408.06	266
1410.2	286
1412.35	284
1414.49	264
1416.63	280
1418.78	284
1420.92	260
1423.06	258
1425.2	272
1427.34	268
1429.48	272
1431.61	248
1433.75	260
1435.89	262
1438.02	252
1440.16	270
1442.3	274
1444.43	248
1446.56	234
1448.7	242
1450.83	248
1452.96	246
1455.09	240
1457.22	234
1459.35	226
1461.48	258
1463.61	226
1465.73	240
1467.86	238
1469.98	226
1472.11	234
1474.24	244
1476.36	232
1478.48	228
1480.6	244
1482.73	220
1484.85	234
1486.97	242
1489.09	226
1491.21	226
1493.33	218
1495.44	240
1497.56	234
1499.68	204
1501.79	218
1503.91	226
1506.02	218
1508.14	216
1510.25	208
1512.36	192
1514.48	210
1516.59	228
1518.7	200
1520.81	206
1522.92	192
1525.02	204
1527.13	206
1529.24	212
1531.35	196
1533.45	214
1535.56	208
1537.66	196
1539.77	214
1541.87	210
1543.97	202
1546.08	200
1548.18	180
1550.28	200
1552.38	190
1554.48	182
1556.57	182
1558.67	188
1560.77	178
1562.87	182
1564.96	206
1567.06	196
1569.15	186
1571.25	174
1573.34	184
1575.43	170
1577.53	188
1579.62	188
1581.71	184
1583.8	182
1585.89	194
1587.98	184
1590.06	178
1592.15	180
1594.24	198
1596.33	196
1598.41	182
1600.5	184
1602.58	184
1604.66	174
1606.75	190
1608.83	178
1610.91	190
1612.99	176
1615.07	186
1617.15	188
1619.23	178
1621.31	190
1623.39	174
1625.46	162
1627.54	154
1629.62	182
1631.69	178
1633.77	186
1635.84	172
1637.91	166
1639.99	182
1642.06	172
1644.13	176
1646.2	154
1648.27	180
1650.34	176
1652.41	180
1654.47	164
1656.54	162
1658.61	160
1660.67	156
1662.74	154
1664.81	154
1666.87	170
1668.93	156
1671	152
1673.06	190
1675.12	166
1677.18	160
1679.24	170
1681.3	156
1683.36	150
1685.42	160
1687.47	162
1689.53	166
1691.59	158
1693.64	174
1695.7	150
1697.75	152
1699.81	156
1701.86	156
1703.91	164
1705.97	164
1708.02	160
1710.07	148
1712.12	144
1714.17	170
1716.22	166
1718.26	164
1720.31	148
1722.36	158
1724.4	164
1726.45	168
1728.49	146
1730.54	174
1732.58	156
1734.63	168
1736.67	162
1738.71	136
1740.75	160
1742.79	152
1744.83	184
1746.87	160
1748.91	168
1750.95	168
1752.98	160
1755.02	146
1757.06	150
1759.09	154
1761.13	154
1763.16	146
1765.19	160
1767.23	160
1769.26	138
1771.29	150
1773.32	152
1775.35	144
1777.38	146
1779.41	146
1781.44	152
1783.47	160
1785.49	152
1787.52	148
1789.55	152
1791.57	156
1793.6	156
1795.62	154
1797.64	160
1799.67	144
1801.69	160
1803.71	152
1805.73	154
1807.75	154
1809.77	150
1811.79	164
1813.81	138
1815.83	164
1817.84	144
1819.86	144
1821.88	140
1823.89	160
1825.91	148
1827.92	150
1829.93	148
1831.95	134
1833.96	154
1835.97	160
1837.98	142
1839.99	146
1842	162
1844.01	148
1846.02	166
1848.03	156
1850.03	152
1852.04	158
1854.05	138
1856.05	144
1858.06	146
1860.06	140
1862.06	158
1864.07	146
1866.07	138
1868.07	146
1870.07	148
1872.07	140
1874.07	152
1876.07	142
1878.07	152
1880.07	144
1882.07	150
1884.06	142
1886.06	132
1888.05	158
1890.05	140
1892.04	154
1894.04	150
1896.03	158
1898.02	158
1900.01	144
1902	142
1903.99	156
1905.98	148
1907.97	144
1909.96	144
1911.95	154
1913.94	150
1915.93	142
1917.91	156
1919.9	164
1921.88	162
1923.87	150
1925.85	146
1927.83	140
1929.82	144
1931.8	150
1933.78	148
1935.76	166
1937.74	142
1939.72	146
1941.7	150
1943.68	160
1945.65	140
1947.63	134
1949.61	150
1951.58	154
1953.56	152
1955.53	140
1957.51	148
1959.48	160
1961.45	134
1963.43	146
1965.4	136
1967.37	150
1969.34	162
1971.31	170
1973.28	160
1975.25	140
1977.22	148
1979.18	148
1981.15	152
1983.12	138
1985.08	146
1987.05	130
1989.01	152
1990.97	146
1992.94	138
1994.9	140
1996.86	140
1998.82	142
2000.78	150
2002.74	146
2004.7	142
2006.66	134
2008.62	136
2010.58	152
2012.54	132
2014.49	142
2016.45	134
2018.4	150
2020.36	134
2022.31	156
2024.27	138
2026.22	148
2028.17	146
2030.12	142
2032.07	138
2034.03	154
2035.98	150
2037.93	154
2039.87	144
2041.82	140
2043.77	134
2045.72	156
2047.66	148
2049.61	158
2051.55	150
2053.5	138
2055.44	136
2057.39	144
2059.33	128
2061.27	144
2063.21	140
2065.15	134
2067.09	138
2069.03	158
2070.97	156
2072.91	148
2074.85	136
2076.79	142
2078.73	134
2080.66	142
2082.6	138
2084.53	152
2086.47	144
2088.4	140
2090.33	146
2092.27	140
2094.2	132
2096.13	158
2098.06	134
2099.99	152
2101.92	146
2103.85	138
2105.78	126
2107.71	146
2109.64	140
2111.56	152
2113.49	142
2115.41	142
2117.34	154
2119.26	150
2121.19	148
2123.11	134
2125.03	146
2126.96	146
2128.88	142
2130.8	130
2132.72	136
2134.64	142
2136.56	148
2138.48	136
2140.4	154
2142.31	138
2144.23	152
2146.15	140
2148.06	142
2149.98	132
2151.89	144
2153.81	146
2155.72	154
2157.63	140
2159.55	134
2161.46	150
2163.37	130
2165.28	144
2167.19	142
2169.1	146
2171.01	130
2172.91	142
2174.82	158
2176.73	132
2178.64	144
2180.54	138
2182.45	140
2184.35	132
2186.26	136
2188.16	140
2190.06	152
2191.96	124
2193.87	144
2195.77	142
2197.67	138
2199.57	126
2201.47	130
2203.37	146
2205.27	130
2207.16	154
2209.06	120
2210.96	126
2212.85	142
2214.75	124
2216.64	142
2218.54	134
2220.43	140
2222.33	136
2224.22	147.143
2226.11	144.573
2228	139.485
2229.89	133.733
2231.78	134.41
2233.67	137.562
2235.56	129.672
2237.45	139.641
2239.34	130.39
2241.23	133.5
2243.11	121.893
2245	128.987
2246.89	127.02
2248.77	124.213
2250.66	125.654
2252.54	114.095
2254.42	120.975
2256.31	123.186
2258.19	119.653
2260.07	117.951
2261.95	109.034
2263.83	124.6
2265.71	121.671
2267.59	122.818
2269.47	110.712
2271.35	123.199
2273.23	113.973
2275.1	112.47
2276.98	110.654
2278.86	122.119
2280.73	107.832
2282.61	112.219
2284.48	116.627
2286.36	110.955
2288.23	110.214
2290.1	116.113
2291.98	109.463
2293.85	112.793
2295.72	105.237
2297.59	105.816
2299.46	98.4292
2301.33	103.081
2303.2	108.985
2305.06	98.2254
2306.93	96.224
2308.8	100.979
2310.67	102.21
2312.53	100.59
2314.4	95.5354
2316.26	99.0696
2317.62	100
2319.5	96
2321.37	100
2323.24	88
2325.12	96
2326.99	104
2328.86	102
2330.73	106
2332.6	88
2334.47	94
2336.34	98
2338.2	92
2340.07	92
2341.94	100
2343.81	92
2345.67	102
2347.54	92
2349.4	116
2351.27	102
2353.13	88
2354.99	98
2356.86	102
2358.72	88
2360.58	102
2362.44	104
2364.3	102
2366.16	98
2368.02	96
2369.88	110
2371.74	100
2373.6	88
2375.45	96
2377.31	86
2379.17	92
2381.02	88
2382.88	94
2384.73	94
2386.58	86
2388.44	98
2390.29	90
2392.14	92
2393.99	92
2395.85	84
2397.7	102
2399.55	92
2401.4	90
2403.25	96
2405.09	106
2406.94	114
2408.79	102
2410.63	98
2412.48	98
2414.33	80
2416.17	74
2418.02	96
2419.86	88
2421.7	96
2423.55	84
2425.39	104
2427.23	90
2429.07	90
2430.91	100
2432.75	100
2434.59	98
2436.43	88
2438.27	92
2440.11	94
2441.95	94
2443.78	90
2445.62	100
2447.46	92
2449.29	96
2451.13	100
2452.96	76
2454.79	88
2456.63	94
2458.46	82
2460.29	92
2462.12	100
2463.95	82
2465.78	86
2467.61	98
2469.44	88
2471.27	84
2473.1	84
2474.93	92
2476.76	78
2478.58	82
2480.41	80
2482.23	80
2484.06	78
2485.88	72
2487.71	76
2489.53	74
2491.35	88
2493.18	78
2495	82
2496.82	72
2498.64	88
2500.46	98
2502.28	78
2504.1	90
2505.92	84
2507.74	82
2509.55	72
2511.37	86
2513.19	80
2515	82
2516.82	74
2518.63	80
2520.45	76
2522.26	82
2524.07	68
2525.89	82
2527.7	76
2529.51	74
2531.32	70
2533.13	84
2534.94	78
2536.75	76
2538.56	92
2540.37	74
2542.18	74
2543.98	92
2545.79	76
2547.6	80
2549.4	74
2551.21	82
2553.01	78
2554.82	86
2556.62	82
2558.42	78
2560.23	80
2562.03	72
2563.83	74
2565.63	74
2567.43	76
2569.23	80
2571.03	80
2572.83	74
2574.63	72
2576.43	72
2578.22	82
2580.02	64
2581.82	68
2583.61	72
2585.41	66
2587.2	68
2589	74
2590.79	70
2592.58	74
2594.38	78
2596.17	62
2597.96	64
2599.75	70
2601.54	66
2603.33	76
2605.12	68
2606.91	74
2608.7	70
2610.49	66
2612.27	78
2614.06	76
2615.85	62
2617.63	60
2619.42	68
2621.2	56
2622.99	70
2624.77	58
2626.55	72
2628.34	74
2630.12	68
2631.9	70
2633.68	66
2635.46	74
2637.24	74
2639.02	74
2640.8	62
2642.58	76
2644.36	66
2646.14	66
2647.91	64
2649.69	68
2651.46	66
2653.24	66
2655.01	74
2656.79	52
2658.56	60
2660.34	62
2662.11	60
2663.88	66
2665.65	58
2667.42	64
2669.2	68
2670.96	74
2672.73	64
2674.5	68
2676.27	62
2678.04	66
2679.81	60
2681.58	58
2683.34	56
2685.11	62
2686.87	66
2688.64	68
2690.4	70
2692.17	62
2693.93	58
2695.69	64
2697.46	62
2699.22	64
2700.98	62
2702.74	66
2704.5	58
2706.26	62
2708.02	64
2709.78	64
2711.54	68
2713.3	70
2715.05	58
2716.81	58
2718.57	60
2720.32	60
2722.08	58
2723.83	52
2725.59	60
2727.34	76
2729.09	64
2730.85	58
2732.6	60
2734.35	62
2736.1	56
2737.85	60
2739.6	64
2741.35	54
2743.1	54
2744.85	66
2746.6	54
2748.35	56
2750.09	56
2751.84	56
2753.59	58
2755.33	70
2757.08	62
2758.82	50
2760.57	54
2762.31	56
2764.05	58
2765.79	64
2767.54	58
2769.28	48
2771.02	50
2772.76	56
2774.5	60
2776.24	56
2777.98	60
2779.72	60
2781.46	52
2783.19	48
2784.93	66
2786.67	52
2788.4	52
2790.14	52
2791.87	56
2793.61	58
2795.34	54
2797.07	54
2798.81	50
2800.54	56
2802.27	48
2804	52
2805.74	62
2807.47	54
2809.2	54
2810.93	42
2812.65	48
2814.38	54
2816.11	52
2817.84	56
2819.56	52
2821.29	60
2823.02	50
2824.74	54
2826.47	52
2828.19	48
2829.92	44
2831.64	36
2833.36	46
2835.09	38
2836.81	44
2838.53	46
2840.25	44
2841.97	44
2843.69	48
2845.41	48
2847.13	48
2848.85	52
2850.57	48
2852.28	44
2854	46
2855.72	50
2857.43	54
2859.15	48
2860.86	64
2862.58	50
2864.29	42
2866.01	54
2867.72	52
2869.43	48
2871.14	46
2872.86	48
2874.57	50
2876.28	44
2877.99	44
2879.7	46
2881.41	46
2883.11	46
2884.82	50
2886.53	40
2888.24	52
2889.94	44
2891.65	42
2893.36	44
2895.06	50
2896.77	44
2898.47	44
2900.17	38
2901.88	42
2903.58	50
2905.28	46
2906.98	52
2908.69	46
2910.39	52
2912.09	48
2913.79	50
2915.49	50
2917.19	60
2918.88	58
2920.58	50
2922.28	54
2923.98	48
2925.67	44
2927.37	40
2929.06	38
2930.76	42
2932.45	52
2934.15	42
2935.84	44
2937.53	50
2939.23	36
2940.92	40
2942.61	44
2944.3	44
2945.99	44
2947.68	38
2949.37	44
2951.06	44
2952.75	38
2954.44	46
2956.12	42
2957.81	42
2959.5	46
2961.18	42
2962.87	50
2964.56	34
2966.24	46
2967.92	48
2969.61	50
2971.29	42
2972.97	42
2974.66	44
2976.34	44
2978.02	38
2979.7	44
2981.38	42
2983.06	40
2984.74	42
2986.42	44
2988.1	40
2989.78	48
2991.45	30
2993.13	50
2994.81	40
2996.48	44
2998.16	40
2999.83	40