File: muestras/nopal/inside_prf_01.txt
#Acq. time (s)=	10
#Accumulations=	2
#Range (cm-¹)=	200...2000
#Windows=	2
#Autofocus=	Off
#AutoExposure=	Off
#Spike filter=	Multiple accum.
#Delay time (s)=	0
#Binning=	1
#Readout mode=	Signal
#DeNoise=	Off
#ICS correction=	Off
#Dark correction=	Off
#Inst. Process=	Off
#Instrument=	LabRAM HR Evol
#Detector=	Syncerity OE
#Objective=	x100_VIS
#Grating=	600 (500nm)
#ND Filter=	25%
#Laser=	633nm_Edge
#Hole=	100.021
#Range=	Visible
#Project=	Omar
#Sample=	03-07-23
#Site=	nop
#Title=	inside_prf
#Remark=
#Date=	03.07.2023 14:11
#Acquired=	03.07.2023 14:11:18
200.319	17062
202.854	17366
205.387	17566
207.918	17628
210.45	18014
212.98	18340
215.51	18364
218.038	18740
220.565	18806
223.093	19070
225.618	19038
228.143	19492
230.668	19966
233.191	19988
235.713	20410
238.235	20662
240.757	20992
243.276	21212
245.795	21512
248.313	21870
250.831	21922
253.347	22140
255.863	22406
258.378	22394
260.892	22528
263.405	22522
265.916	22812
268.427	23006
270.938	23182
273.448	23352
275.957	23692
278.464	23778
280.972	24072
283.478	24286
285.983	24508
288.488	24960
290.992	25218
293.494	25296
295.997	25634
298.497	26132
300.998	26402
303.497	26672
305.995	26708
308.494	27236
310.99	27360
313.486	27642
315.982	27838
318.476	27968
320.969	28310
323.461	28486
325.953	28830
328.445	28896
330.935	29174
333.424	29500
335.912	29772
338.4	30132
340.887	30522
343.373	30830
345.858	31088
348.341	31390
350.824	31666
353.307	32142
355.789	32342
358.27	32488
360.749	32860
363.229	33018
365.707	33256
368.184	33526
370.661	33780
373.137	34114
375.612	34300
378.086	34768
380.559	34930
383.032	34878
385.503	35250
387.973	35766
390.444	35836
392.913	36134
395.38	36396
397.849	36994
400.315	37216
402.78	37912
405.245	38236
407.709	38552
410.173	38926
412.636	39286
415.097	39828
417.558	40342
420.018	40894
422.477	41410
424.935	41828
427.393	42114
429.848	42746
432.304	42986
434.759	43464
437.214	43844
439.667	44126
442.119	44690
444.571	44420
447.022	44806
449.471	45364
451.921	45352
454.37	45938
456.816	46064
459.264	46356
461.709	46866
464.155	47340
466.598	47004
469.041	47936
471.485	48164
473.926	48572
476.366	49080
478.806	49566
481.247	50194
483.685	50174
486.122	50498
488.559	51230
490.995	51896
493.43	52126
495.864	52502
498.297	53042
500.73	53644
503.162	54130
505.593	54096
508.024	54794
510.453	55100
512.882	55350
515.31	55294
517.736	55632
520.163	56408
522.588	56528
525.012	56982
527.436	57502
529.86	57630
532.281	58114
534.703	58488
537.123	58808
539.543	59286
541.961	59610
544.379	59926
546.797	60334
549.213	61000
551.628	60938
554.044	61680
556.457	62112
558.87	62848
561.282	63314
563.695	63524
566.106	64338
568.515	64535
570.924	64535
573.333	64535
575.74	64535
578.147	64535
580.553	64535
582.958	64535
585.361	64535
587.765	64535
590.168	64535
592.57	64535
594.97	64535
597.371	64535
599.771	64535
602.169	64535
604.567	64535
606.965	64535
609.36	64535
611.756	64535
614.15	64535
616.545	64535
618.937	64535
621.329	64535
623.721	64535
626.112	64535
628.501	64535
630.891	64535
633.279	64535
635.666	64535
638.053	64535
640.439	64535
642.824	64535
645.208	64535
647.591	64535
649.974	64535
652.356	64535
654.737	64535
657.117	64535
659.497	64535
661.876	64535
664.253	64535
666.63	64535
669.007	64535
671.383	64535
673.757	64535
676.131	64535
678.504	64535
680.877	64535
683.248	64535
685.619	64535
687.988	64535
690.358	64535
692.726	64535
695.095	64535
697.461	64535
699.827	64535
702.192	64535
704.557	64535
706.921	64535
709.284	64535
711.645	64535
714.007	64535
716.367	64535
718.727	64535
721.086	64535
723.444	64535
725.802	64535
728.158	64535
730.514	64535
732.87	64535
735.223	64535
737.577	64535
739.93	64535
742.282	64535
744.633	64535
746.983	64535
749.332	64535
751.682	64535
754.029	64535
756.377	64535
758.723	64535
761.069	64535
763.414	64535
765.757	64535
768.102	64535
770.444	64535
772.785	64535
775.127	64535
777.467	64535
779.807	64535
782.145	64535
784.483	64535
786.82	64535
789.157	64535
791.492	64535
793.827	64535
796.161	64535
798.495	64535
800.828	64535
803.158	64535
805.49	64535
807.82	64535
810.15	64535
812.478	64535
814.806	64535
817.132	64535
819.459	64535
821.784	64535
824.11	64535
826.433	64535
828.757	64535
831.079	64535
833.402	64535
835.722	64535
838.042	64535
840.361	64535
842.681	64535
844.999	64535
847.315	64535
849.632	64535
851.947	64535
854.262	64535
856.576	64535
858.889	64535
861.202	64535
863.514	64535
865.825	64535
868.136	64535
870.444	64535
872.753	64535
875.062	64535
877.369	64535
879.675	64535
881.981	64535
884.286	64535
886.59	64535
888.894	64535
891.196	64535
893.499	64535
895.799	64535
898.099	64535
900.4	64535
902.698	64535
904.996	64535
907.293	64535
909.591	64535
911.886	64535
914.181	64535
916.475	64535
918.769	64535
921.062	64535
923.354	64535
925.645	64535
927.936	64535
930.226	64535
932.515	64535
934.802	64535
937.09	64535
939.377	64535
941.664	61266
943.948	57732
946.233	54244
948.517	50618
950.8	47068
953.083	42934
955.363	39094
957.645	34486
959.924	29314
962.203	23950
964.483	20302
966.76	18278
969.037	17472
971.314	16994
973.589	16636
975.864	16256
978.138	15986
980.411	15772
982.684	15604
984.955	15468
987.226	15340
989.497	15296
991.767	15192
994.036	15196
996.304	15134
998.572	15110
1000.84	15176
1003.1	15120
1005.37	15136
1007.63	15086
1009.9	15110
1012.16	15098
1014.42	15116
1016.68	15142
1018.94	15100
1021.2	15092
1023.46	15126
1025.72	15106
1027.98	15180
1030.24	15138
1032.49	15134
1034.75	15140
1037	15128
1039.26	15142
1041.51	15188
1043.76	15180
1046.01	15172
1048.27	15130
1050.52	15190
1052.77	15210
1055.01	15280
1057.26	15196
1059.51	15243
1061.76	15228
1064	15270
1066.25	15258
1068.49	15280
1070.74	15292
1072.98	15280
1075.22	15268
1077.46	15272
1079.71	15248
1081.94	15296
1084.18	15316
1086.42	15294
1088.66	15314
1090.9	15376
1093.13	15352
1095.37	15332
1097.6	15338
1099.84	15326
1102.07	15396
1104.31	15396
1106.54	15370
1108.77	15400
1111	15388
1113.23	15392
1115.46	15416
1117.69	15422
1119.92	15438
1122.14	15442
1124.37	15412
1126.59	15448
1128.82	15450
1131.04	15468
1133.27	15520
1135.49	15518
1137.71	15534
1139.93	15544
1142.15	15532
1144.37	15528
1146.59	15540
1148.81	15540
1151.03	15592
1153.24	15578
1155.46	15580
1157.68	15626
1159.89	15612
1162.11	15604
1164.32	15632
1166.53	15614
1168.74	15658
1170.95	15672
1173.16	15664
1175.37	15686
1177.58	15704
1179.79	15716
1182	15690
1184.21	15750
1186.41	15748
1188.62	15710
1190.82	15728
1193.03	15740
1195.23	15786
1197.43	15782
1199.63	15746
1201.84	15802
1204.04	15742
1206.23	15758
1208.43	15804
1210.63	15860
1212.83	15806
1215.03	15840
1217.22	15806
1219.42	15850
1221.61	15836
1223.81	15856
1226	15878
1228.19	15848
1230.39	15862
1232.58	15868
1234.77	15868
1236.96	15898
1239.15	15906
1241.33	15882
1243.52	15904
1245.71	15916
1247.9	15910
1250.08	15898
1252.27	15940
1254.45	15938
1256.63	15914
1258.81	15970
1261	15976
1263.18	15946
1265.36	15970
1267.54	15980
1269.72	15978
1271.9	15994
1274.07	16014
1276.25	16002
1278.43	16016
1280.6	16008
1282.78	16224.4
1284.95	17246.2
1287.13	18187.3
1289.3	19132.9
1291.47	20143.2
1293.64	20999.7
1295.81	21337.3
1297.98	21613.2
1300.15	21831.7
1302.32	22150
1304.49	22615.4
1306.66	23085
1308.82	23764
1310.99	24429.4
1313.16	25195.5
1315.32	25997.8
1317.48	26916.3
1319.65	27858.6
1321.81	28946.2
1323.97	29957
1326.13	31021.8
1328.29	32178.9
1330.45	33376.9
1332.61	34775.3
1334.77	36026.6
1336.93	37375.4
1339.08	38700.2
1341.24	40150.5
1343.39	41724.5
1345.55	43261.2
1347.7	44805.1
1349.86	46122.5
1352.01	47083.3
1354.16	48025.2
1356.31	48984.2
1358.46	49942.4
1360.61	50895.9
1362.76	51866.2
1364.91	52817.4
1367.06	53774.9
1369.21	54739.4
1371.35	55695.1
1373.5	56651.8
1375.64	57611.9
1377.79	58572
1379.93	59520.1
1382.07	60477.6
1384.22	61431.4
1386.36	62387.1
1388.5	63341.2
1390.64	64465.2
1391.76	64535
1393.91	64535
1396.06	64535
1398.21	64535
1400.36	64535
1402.51	64535
1404.65	64535
1406.8	64535
1408.95	64535
1411.09	64535
1413.23	64535
1415.38	64535
1417.52	64535
1419.66	64535
1421.8	64535
1423.94	64535
1426.08	64535
1428.22	64535
1430.36	64535
1432.5	64535
1434.64	64535
1436.77	64535
1438.91	64535
1441.04	64535
1443.18	64535
1445.31	64535
1447.45	64535
1449.58	64535
1451.71	64535
1453.84	64535
1455.97	64535
1458.1	64535
1460.23	64535
1462.36	64535
1464.48	64535
1466.61	64535
1468.74	64535
1470.86	64535
1472.99	64535
1475.11	64535
1477.24	64535
1479.36	64535
1481.48	64535
1483.6	64535
1485.73	64535
1487.85	64535
1489.96	64535
1492.08	64535
1494.2	64535
1496.32	64535
1498.44	64535
1500.55	64535
1502.67	64535
1504.78	64535
1506.9	64535
1509.01	64535
1511.13	64535
1513.24	64535
1515.35	64535
1517.46	64535
1519.57	64535
1521.68	64535
1523.79	64535
1525.9	64535
1528.01	64535
1530.11	64535
1532.22	64535
1534.32	64535
1536.43	64535
1538.53	64535
1540.64	64535
1542.74	64535
1544.84	64535
1546.94	64535
1549.04	64535
1551.15	64535
1553.25	64535
1555.34	64535
1557.44	64535
1559.54	64535
1561.64	64535
1563.73	64535
1565.83	64535
1567.92	64535
1570.02	64535
1572.11	64535
1574.21	64535
1576.3	64535
1578.39	64535
1580.48	64535
1582.57	64535
1584.66	64535
1586.75	64535
1588.84	64535
1590.93	64535
1593.02	64535
1595.1	64535
1597.19	64535
1599.27	64535
1601.36	64535
1603.44	64535
1605.53	64535
1607.61	64535
1609.69	64535
1611.77	64535
1613.85	64535
1615.93	64535
1618.01	64535
1620.09	64535
1622.17	64535
1624.24	64535
1626.32	64535
1628.4	64535
1630.47	64535
1632.55	64535
1634.62	64535
1636.7	64535
1638.77	64535
1640.84	64535
1642.91	64535
1644.98	64535
1647.05	64535
1649.12	64535
1651.19	64535
1653.26	64535
1655.33	64535
1657.4	64535
1659.46	64535
1661.53	64535
1663.59	64535
1665.66	64535
1667.72	64535
1669.78	64535
1671.85	64535
1673.91	64535
1675.97	64535
1678.03	64535
1680.09	64535
1682.15	64535
1684.21	64535
1686.27	64535
1688.32	64535
1690.38	64535
1692.44	64535
1694.49	64535
1696.55	64535
1698.6	64535
1700.66	64535
1702.71	64535
1704.76	64535
1706.81	64535
1708.86	64535
1710.91	64535
1712.96	64535
1715.01	64535
1717.06	64535
1719.11	64535
1721.16	64535
1723.2	64535
1725.25	64535
1727.29	64535
1729.34	64535
1731.38	64535
1733.43	64535
1735.47	64535
1737.51	64535
1739.55	64535
1741.59	64535
1743.63	64535
1745.67	64535
1747.71	64535
1749.75	64535
1751.79	64535
1753.83	64535
1755.86	64535
1757.9	64535
1759.93	64535
1761.97	64535
1764	64535
1766.03	64535
1768.07	64535
1770.1	64535
1772.13	64535
1774.16	64535
1776.19	64535
1778.22	64535
1780.25	64535
1782.28	64535
1784.3	64535
1786.33	64535
1788.36	64535
1790.38	64535
1792.41	64535
1794.43	64535
1796.46	64535
1798.48	64535
1800.5	64535
1802.52	64535
1804.55	64535
1806.57	64535
1808.59	64535
1810.61	64535
1812.62	64535
1814.64	64535
1816.66	64535
1818.68	64535
1820.69	64535
1822.71	64535
1824.72	64535
1826.74	64535
1828.75	64535
1830.77	64535
1832.78	64535
1834.79	64535
1836.8	64535
1838.81	64535
1840.82	64535
1842.83	64535
1844.84	64535
1846.85	64535
1848.85	64535
1850.86	64535
1852.87	64535
1854.87	64535
1856.88	64535
1858.88	64535
1860.89	64535
1862.89	64535
1864.89	64535
1866.89	64535
1868.9	64535
1870.9	64535
1872.9	64535
1874.9	64535
1876.9	64535
1878.89	64535
1880.89	64535
1882.89	64535
1884.88	64535
1886.88	64535
1888.88	64535
1890.87	64535
1892.87	64535
1894.86	64535
1896.85	64535
1898.84	64535
1900.83	64535
1902.82	64535
1904.81	64535
1906.8	64535
1908.79	64535
1910.78	64535
1912.77	64535
1914.76	64535
1916.74	64535
1918.73	64535
1920.72	64535
1922.7	64535
1924.68	64535
1926.67	64535
1928.65	64535
1930.63	64535
1932.61	64535
1934.6	64535
1936.58	64535
1938.56	64535
1940.54	64535
1942.51	64535
1944.49	64535
1946.47	64535
1948.45	64535
1950.42	64535
1952.4	64535
1954.37	64535
1956.35	64535
1958.32	64535
1960.29	64535
1962.27	64535
1964.24	64535
1966.21	64535
1968.18	64535
1970.15	64535
1972.12	64535
1974.09	64535
1976.06	64535
1978.03	64535
1979.99	64535
1981.96	64535
1983.93	64535
1985.89	64535
1987.86	64535
1989.82	64535
1991.78	64535
1993.75	64535
1995.71	64535
1997.67	64535
1999.63	64535