File: muestras/nopal/inside_prf_10.txt
#Acq. time (s)=	20
#Accumulations=	1
#Range (cm-¹)=	200...3000
#Windows=	3
#Autofocus=	Off
#AutoExposure=	Off
#Spike filter=	Off
#Delay time (s)=	0
#Binning=	1
#Readout mode=	Signal
#DeNoise=	Off
#ICS correction=	Off
#Dark correction=	Off
#Inst. Process=	Off
#Instrument=	LabRAM HR Evol
#Detector=	Syncerity OE
#Objective=	x100_VIS
#Grating=	600 (500nm)
#ND Filter=	0.01%
#Laser=	633nm_Edge
#Hole=	49.98
#Range=	Visible
#Project=	Omar
#Sample=	03-07-23
#Site=	nop
#Title=	inside_prf
#Remark=
#Date=	03.07.2023 14:32
#Acquired=	03.07.2023 14:32:58
201.713	60
204.247	64
206.778	60
209.311	68
211.84	74
214.371	62
216.899	64
219.428	58
221.955	66
224.482	64
227.007	72
229.531	74
232.055	72
234.579	54
237.1	68
239.621	78
242.141	68
244.661	72
247.179	74
249.698	80
252.215	68
254.731	76
257.246	74
259.761	62
262.273	70
264.786	78
267.298	76
269.809	70
272.319	80
274.828	84
277.336	70
279.844	70
282.351	74
284.855	76
287.361	70
289.866	78
292.368	70
294.871	64
297.372	78
299.873	78
302.372	74
304.872	66
307.37	82
309.866	82
312.364	80
314.859	86
317.353	76
319.848	76
322.341	74
324.833	74
327.324	92
329.814	80
332.304	80
334.792	74
337.28	80
339.767	92
342.254	88
344.739	80
347.224	76
349.708	98
352.191	74
354.673	82
357.155	74
359.634	84
362.114	82
364.593	76
367.07	94
369.548	94
372.024	82
374.499	88
376.974	100
379.447	80
381.92	84
384.392	72
386.864	80
389.333	100
391.802	88
394.272	94
396.739	88
399.206	88
401.673	82
404.138	100
406.602	84
409.066	100
411.528	98
413.99	94
416.451	104
418.911	92
421.371	82
423.83	106
426.288	100
428.745	98
431.201	94
433.657	104
436.111	106
438.565	94
441.017	100
443.469	106
445.921	104
448.37	110
450.821	106
453.27	102
455.717	102
458.165	88
460.61	108
463.056	94
465.5	108
467.945	96
470.387	100
472.829	110
475.271	110
477.711	104
480.15	112
482.589	112
485.027	102
487.465	96
489.901	102
492.337	114
494.771	104
497.205	116
499.638	112
502.07	110
504.502	106
506.933	112
509.363	110
511.792	110
514.219	102
516.647	110
519.073	122
521.5	114
523.924	110
526.348	106
528.772	122
531.194	120
533.616	112
536.036	124
538.457	138
540.875	118
543.294	116
545.712	124
548.128	112
550.545	110
552.959	122
555.373	104
557.788	114
560.2	128
562.612	124
565.023	116
567.433	116
569.843	122
572.251	130
574.659	128
577.066	124
579.472	116
581.878	124
584.283	126
586.687	140
589.09	126
591.493	126
593.893	132
596.294	132
598.694	140
601.093	142
603.491	138
605.889	134
608.285	134
610.682	146
613.076	142
615.471	148
617.864	150
620.256	154
622.648	146
625.039	160
627.429	158
629.819	136
632.208	140
634.595	142
636.982	148
639.369	146
641.755	142
644.139	164
646.523	152
648.906	154
651.288	152
653.67	164
656.051	156
658.429	164
660.808	186
663.187	168
665.565	162
667.942	156
670.317	160
672.692	164
675.067	168
677.44	148
679.813	162
682.184	174
684.556	180
686.926	170
689.296	178
691.664	164
694.033	190
696.4	186
698.766	180
701.133	180
703.497	206
705.861	180
708.224	196
710.586	178
712.949	182
715.31	200
717.67	206
720.029	184
722.388	200
724.746	200
727.103	194
729.458	206
731.814	214
734.168	222
736.523	200
738.876	212
741.227	192
743.579	196
745.931	208
748.28	212
750.629	218
752.977	222
755.325	234
757.672	236
760.018	230
762.363	220
764.708	260
767.052	238
769.394	226
771.737	224
774.078	244
776.419	262
778.758	242
781.097	278
783.435	256
785.773	232
788.11	248
790.446	276
792.781	264
795.115	250
797.449	256
799.782	280
802.115	266
804.446	266
806.777	266
809.106	280
811.435	266
813.764	296
816.091	294
818.418	288
820.743	304
823.069	282
825.393	302
827.717	296
830.039	304
832.362	306
834.683	304
837.003	328
839.324	310
841.643	302
843.961	322
846.278	316
848.594	320
850.91	344
853.227	328
855.541	366
857.855	336
860.168	346
862.48	358
864.79	368
867.101	378
869.411	366
871.721	382
874.029	368
876.336	372
878.643	382
880.95	364
883.254	374
885.559	362
887.862	356
890.166	372
892.467	378
894.77	418
897.07	418
899.371	388
901.669	382
903.968	416
906.266	418
908.563	424
910.859	404
913.154	442
915.449	414
917.742	420
920.036	442
922.329	452
924.621	456
926.911	436
929.201	476
931.49	456
933.779	480
936.068	482
938.355	488
940.64	478
942.926	466
945.212	520
947.495	508
949.779	508
952.062	498
954.344	488
956.625	492
958.905	514
961.184	520
963.464	514
965.742	526
968.02	508
970.296	560
972.572	554
974.847	534
977.121	534
979.396	522
981.669	564
983.941	570
986.212	576
988.483	572
990.753	572
993.022	586
995.29	566
997.558	590
999.825	584
1002.09	612
1004.36	616
1006.62	610
1008.89	604
1011.15	618
1013.41	634
1015.67	624
1017.93	628
1020.19	630
1022.45	654
1024.71	652
1026.97	650
1029.23	664
1031.49	670
1033.74	660
1036	668
1038.25	722
1040.5	720
1042.76	718
1045.01	730
1047.26	716
1049.51	740
1051.76	700
1054.01	750
1056.26	740
1058.51	722
1060.75	750
1063	742
1065.25	776
1067.49	798
1069.73	782
1071.98	764
1074.22	776
1076.46	788
1078.7	814
1080.94	812
1083.18	830
1085.42	802
1087.66	818
1089.9	812
1092.14	814
1094.37	814
1096.61	814
1098.84	868
1101.08	826
1103.31	816
1105.54	838
1107.77	850
1110	862
1112.23	838
1114.46	838
1116.69	854
1118.92	872
1121.15	874
1123.37	812
1125.6	862
1127.83	876
1130.05	888
1132.27	872
1134.5	890
1136.72	886
1138.94	906
1141.16	902
1143.38	902
1145.6	906
1147.82	840
1150.04	912
1152.26	884
1154.47	880
1156.69	890
1158.9	904
1161.12	916
1163.33	920
1165.54	952
1167.76	910
1169.97	900
1172.18	890
1174.39	938
1176.6	896
1178.81	944
1181.02	894
1183.22	862
1185.43	916
1187.63	902
1189.84	910
1192.04	910
1194.25	854
1196.45	882
1198.65	870
1200.85	890
1203.05	874
1205.25	852
1207.45	884
1209.65	874
1211.85	878
1214.05	862
1216.24	818
1218.44	866
1220.64	880
1222.83	812
1225.02	828
1227.22	830
1229.41	852
1231.6	844
1233.79	820
1235.98	802
1238.17	842
1240.36	850
1242.55	770
1244.73	824
1246.92	822
1249.11	814
1251.29	800
1253.48	810
1255.66	802
1257.84	802
1260.03	794
1262.21	750
1264.39	782
1266.57	798
1268.75	782
1270.93	754
1273.11	782
1275.28	754
1277.46	768
1279.64	746
1281.81	730
1283.98	725.478
1286.16	740.693
1288.33	733.08
1290.5	742.103
1292.68	725.723
1294.85	770.723
1297.02	754.494
1299.19	749.167
1301.36	735.027
1303.53	750.686
1305.69	732.094
1307.86	746.436
1310.03	730.32
1312.19	738.145
1314.36	750.252
1316.52	727.918
1318.68	740.797
1320.85	738.76
1323.01	734.88
1325.17	745.474
1327.33	711.225
1329.49	736.133
1331.65	729.13
1333.81	701.322
1335.97	718.909
1338.12	710.499
1340.28	718.277
1342.44	719.358
1344.59	711.362
1346.75	710.568
1348.9	729.945
1351.05	716.192
1353.2	703.291
1355.36	711.158
1357.51	722.378
1359.66	686.455
1361.81	699.781
1363.96	712.205
1366.1	726.958
1368.25	697.385
1370.4	696.243
1372.54	717.265
1374.69	715.679
1376.83	677.27
1378.98	711.106
1381.12	697.867
1383.26	704.317
1385.41	713.335
1387.55	665.183
1389.69	714.686
1391.83	674.236
1393.02	704
1395.17	706
1397.32	678
1399.47	698
1401.62	686
1403.77	654
1405.91	684
1408.06	680
1410.2	668
1412.35	668
1414.49	662
1416.63	654
1418.78	650
1420.92	620
1423.06	658
1425.2	662
1427.34	590
1429.48	618
1431.61	612
1433.75	608
1435.89	600
1438.02	626
1440.16	620
1442.3	604
1444.43	598
1446.56	612
1448.7	618
1450.83	584
1452.96	608
1455.09	586
1457.22	594
1459.35	584
1461.48	582
1463.61	560
1465.73	580
1467.86	540
1469.98	560
1472.11	564
1474.24	540
1476.36	542
1478.48	558
1480.6	534
1482.73	536
1484.85	558
1486.97	544
1489.09	580
1491.21	556
1493.33	564
1495.44	542
1497.56	524
1499.68	552
1501.79	524
1503.91	516
1506.02	516
1508.14	518
1510.25	504
1512.36	496
1514.48	500
1516.59	518
1518.7	494
1520.81	518
1522.92	516
1525.02	520
1527.13	484
1529.24	502
1531.35	508
1533.45	486
1535.56	502
1537.66	494
1539.77	496
1541.87	490
1543.97	460
1546.08	506
1548.18	472
1550.28	480
1552.38	466
1554.48	474
1556.57	490
1558.67	442
1560.77	456
1562.87	464
1564.96	422
1567.06	438
1569.15	444
1571.25	462
1573.34	458
1575.43	466
1577.53	450
1579.62	444
1581.71	432
1583.8	456
1585.89	444
1587.98	442
1590.06	446
1592.15	434
1594.24	432
1596.33	450
1598.41	420
1600.5	456
1602.58	428
1604.66	452
1606.75	442
1608.83	446
1610.91	430
1612.99	410
1615.07	412
1617.15	416
1619.23	430
1621.31	432
1623.39	412
1625.46	420
1627.54	424
1629.62	414
1631.69	410
1633.77	426
1635.84	404
1637.91	422
1639.99	410
1642.06	422
1644.13	398
1646.2	418
1648.27	400
1650.34	402
1652.41	426
1654.47	420
1656.54	418
1658.61	424
1660.67	408
1662.74	396
1664.81	404
1666.87	402
1668.93	416
1671	416
1673.06	384
1675.12	380
1677.18	398
1679.24	386
1681.3	380
1683.36	384
1685.42	382
1687.47	362
1689.53	390
1691.59	384
1693.64	394
1695.7	384
1697.75	376
1699.81	392
1701.86	360
1703.91	378
1705.97	380
1708.02	394
1710.07	386
1712.12	388
1714.17	380
1716.22	398
1718.26	364
1720.31	376
1722.36	362
1724.4	394
1726.45	380
1728.49	368
1730.54	364
1732.58	374
1734.63	380
1736.67	362
1738.71	386
1740.75	370
1742.79	376
1744.83	372
1746.87	382
1748.91	362
1750.95	368
1752.98	364
1755.02	364
1757.06	386
1759.09	368
1761.13	346
1763.16	378
1765.19	368
1767.23	362
1769.26	356
1771.29	350
1773.32	370
1775.35	346
1777.38	340
1779.41	346
1781.44	386
1783.47	348
1785.49	362
1787.52	350
1789.55	354
1791.57	356
1793.6	356
1795.62	354
1797.64	342
1799.67	366
1801.69	350
1803.71	348
1805.73	348
1807.75	352
1809.77	348
1811.79	352
1813.81	350
1815.83	386
1817.84	340
1819.86	348
1821.88	368
1823.89	364
1825.91	352
1827.92	352
1829.93	354
1831.95	342
1833.96	350
1835.97	340
1837.98	332
1839.99	340
1842	356
1844.01	304
1846.02	350
1848.03	330
1850.03	334
1852.04	332
1854.05	336
1856.05	342
1858.06	352
1860.06	330
1862.06	322
1864.07	340
1866.07	336
1868.07	328
1870.07	312
1872.07	336
1874.07	360
1876.07	342
1878.07	350
1880.07	330
1882.07	330
1884.06	356
1886.06	340
1888.05	322
1890.05	312
1892.04	304
1894.04	338
1896.03	330
1898.02	314
1900.01	332
1902	338
1903.99	338
1905.98	320
1907.97	336
1909.96	320
1911.95	330
1913.94	318
1915.93	330
1917.91	312
1919.9	334
1921.88	338
1923.87	324
1925.85	326
1927.83	334
1929.82	334
1931.8	326
1933.78	328
1935.76	328
1937.74	322
1939.72	326
1941.7	304
1943.68	348
1945.65	328
1947.63	308
1949.61	320
1951.58	310
1953.56	292
1955.53	322
1957.51	312
1959.48	334
1961.45	304
1963.43	312
1965.4	336
1967.37	324
1969.34	304
1971.31	302
1973.28	324
1975.25	324
1977.22	310
1979.18	318
1981.15	310
1983.12	300
1985.08	300
1987.05	320
1989.01	328
1990.97	316
1992.94	326
1994.9	306
1996.86	328
1998.82	326
2000.78	310
2002.74	296
2004.7	314
2006.66	326
2008.62	306
2010.58	310
2012.54	302
2014.49	300
2016.45	316
2018.4	306
2020.36	314
2022.31	292
2024.27	328
2026.22	300
2028.17	311
2030.12	330
2032.07	322
2034.03	294
2035.98	318
2037.93	324
2039.87	334
2041.82	292
2043.77	298
2045.72	296
2047.66	328
2049.61	318
2051.55	312
2053.5	320
2055.44	320
2057.39	324
2059.33	298
2061.27	298
2063.21	302
2065.15	288
2067.09	306
2069.03	288
2070.97	302
2072.91	288
2074.85	306
2076.79	292
2078.73	304
2080.66	314
2082.6	282
2084.53	330
2086.47	288
2088.4	304
2090.33	310
2092.27	308
2094.2	290
2096.13	302
2098.06	300
2099.99	300
2101.92	294
2103.85	298
2105.78	316
2107.71	278
2109.64	298
2111.56	306
2113.49	294
2115.41	332
2117.34	290
2119.26	306
2121.19	286
2123.11	310
2125.03	298
2126.96	306
2128.88	282
2130.8	282
2132.72	294
2134.64	280
2136.56	300
2138.48	294
2140.4	304
2142.31	286
2144.23	274
2146.15	292
2148.06	312
2149.98	292
2151.89	274
2153.81	288
2155.72	298
2157.63	296
2159.55	294
2161.46	300
2163.37	294
2165.28	274
2167.19	292
2169.1	306
2171.01	308
2172.91	306
2174.82	290
2176.73	266
2178.64	286
2180.54	276
2182.45	316
2184.35	284
2186.26	276
2188.16	278
2190.06	304
2191.96	294
2193.87	278
2195.77	284
2197.67	278
2199.57	286
2201.47	276
2203.37	272
2205.27	306
2207.16	280
2209.06	278
2210.96	268
2212.85	284
2214.75	270
2216.64	288
2218.54	276
2220.43	292
2222.33	266
2224.22	286.853
2226.11	292.27
2228	297.531
2229.89	287.216
2231.78	269.055
2233.67	278.121
2235.56	282.001
2237.45	288.115
2239.34	294.9
2241.23	300.268
2243.11	289.271
2245	283.094
2246.89	300.825
2248.77	299.826
2250.66	303.319
2252.54	294.253
2254.42	300.358
2256.31	313.625
2258.19	300.412
2260.07	291.031
2261.95	307.453
2263.83	298.71
2265.71	292.074
2267.59	309.54
2269.47	308.135
2271.35	317.089
2273.23	304.973
2275.1	315.609
2276.98	311.337
2278.86	329.059
2280.73	313.733
2282.61	317.733
2284.48	322.599
2286.36	314.49
2288.23	336.04
2290.1	323.917
2291.98	319.887
2293.85	320.85
2295.72	322.646
2297.59	323.62
2299.46	334.314
2301.33	328.45
2303.2	324.125
2305.06	336.657
2306.93	327.008
2308.8	327.747
2310.67	330.629
2312.53	335.991
2314.4	348.703
2316.26	338.359
2317.62	328
2319.5	330
2321.37	332
2323.24	342
2325.12	316
2326.99	348
2328.86	328
2330.73	318
2332.6	326
2334.47	328
2336.34	322
2338.2	326
2340.07	336
2341.94	332
2343.81	316
2345.67	330
2347.54	340
2349.4	336
2351.27	354
2353.13	304
2354.99	308
2356.86	324
2358.72	320
2360.58	322
2362.44	318
2364.3	326
2366.16	334
2368.02	340
2369.88	326
2371.74	322
2373.6	322
2375.45	312
2377.31	312
2379.17	326
2381.02	320
2382.88	324
2384.73	318
2386.58	320
2388.44	314
2390.29	318
2392.14	318
2393.99	326
2395.85	306
2397.7	314
2399.55	320
2401.4	314
2403.25	314
2405.09	298
2406.94	308
2408.79	306
2410.63	314
2412.48	314
2414.33	318
2416.17	308
2418.02	290
2419.86	316
2421.7	318
2423.55	306
2425.39	306
2427.23	288
2429.07	308
2430.91	306
2432.75	308
2434.59	298
2436.43	290
2438.27	284
2440.11	304
2441.95	298
2443.78	298
2445.62	300
2447.46	300
2449.29	304
2451.13	276
2452.96	292
2454.79	272
2456.63	298
2458.46	284
2460.29	286
2462.12	298
2463.95	280
2465.78	282
2467.61	302
2469.44	306
2471.27	296
2473.1	282
2474.93	270
2476.76	278
2478.58	268
2480.41	288
2482.23	282
2484.06	278
2485.88	276
2487.71	270
2489.53	272
2491.35	280
2493.18	260
2495	294
2496.82	272
2498.64	262
2500.46	274
2502.28	270
2504.1	266
2505.92	246
2507.74	264
2509.55	276
2511.37	254
2513.19	274
2515	262
2516.82	274
2518.63	276
2520.45	238
2522.26	264
2524.07	270
2525.89	272
2527.7	240
2529.51	248
2531.32	258
2533.13	250
2534.94	246
2536.75	256
2538.56	242
2540.37	234
2542.18	250
2543.98	240
2545.79	240
2547.6	238
2549.4	228
2551.21	246
2553.01	254
2554.82	234
2556.62	236
2558.42	240
2560.23	254
2562.03	216
2563.83	242
2565.63	218
2567.43	230
2569.23	240
2571.03	244
2572.83	232
2574.63	250
2576.43	232
2578.22	248
2580.02	238
2581.82	222
2583.61	232
2585.41	224
2587.2	244
2589	224
2590.79	228
2592.58	226
2594.38	232
2596.17	214
2597.96	222
2599.75	220
2601.54	220
2603.33	220
2605.12	222
2606.91	220
2608.7	204
2610.49	220
2612.27	224
2614.06	228
2615.85	230
2617.63	226
2619.42	216
2621.2	210
2622.99	208
2624.77	224
2626.55	214
2628.34	216
2630.12	214
2631.9	210
2633.68	216
2635.46	196
2637.24	192
2639.02	214
2640.8	208
2642.58	200
2644.36	204
2646.14	216
2647.91	220
2649.69	212
2651.46	210
2653.24	200
2655.01	208
2656.79	216
2658.56	204
2660.34	188
2662.11	206
2663.88	218
2665.65	200
2667.42	170
2669.2	178
2670.96	196
2672.73	196
2674.5	208
2676.27	194
2678.04	192
2679.81	200
2681.58	186
2683.34	194
2685.11	162
2686.87	196
2688.64	172
2690.4	192
2692.17	182
2693.93	188
2695.69	180
2697.46	184
2699.22	192
2700.98	186
2702.74	176
2704.5	156
2706.26	188
2708.02	174
2709.78	178
2711.54	196
2713.3	196
2715.05	162
2716.81	164
2718.57	152
2720.32	154
2722.08	178
2723.83	166
2725.59	172
2727.34	188
2729.09	164
2730.85	168
2732.6	186
2734.35	162
2736.1	170
2737.85	164
2739.6	172
2741.35	166
2743.1	158
2744.85	170
2746.6	162
2748.35	172
2750.09	154
2751.84	184
2753.59	164
2755.33	152
2757.08	154
2758.82	160
2760.57	158
2762.31	148
2764.05	164
2765.79	150
2767.54	144
2769.28	146
2771.02	160
2772.76	146
2774.5	162
2776.24	150
2777.98	158
2779.72	164
2781.46	166
2783.19	148
2784.93	146
2786.67	150
2788.4	158
2790.14	138
2791.87	148
2793.61	168
2795.34	146
2797.07	144
2798.81	134
2800.54	136
2802.27	148
2804	146
2805.74	142
2807.47	140
2809.2	160
2810.93	134
2812.65	138
2814.38	132
2816.11	140
2817.84	152
2819.56	148
2821.29	126
2823.02	134
2824.74	136
2826.47	128
2828.19	128
2829.92	146
2831.64	140
2833.36	144
2835.09	128
2836.81	140
2838.53	130
2840.25	134
2841.97	126
2843.69	126
2845.41	134
2847.13	118
2848.85	124
2850.57	128
2852.28	112
2854	128
2855.72	120
2857.43	138
2859.15	122
2860.86	116
2862.58	124
2864.29	128
2866.01	126
2867.72	116
2869.43	120
2871.14	114
2872.86	132
2874.57	134
2876.28	122
2877.99	128
2879.7	124
2881.41	116
2883.11	116
2884.82	118
2886.53	120
2888.24	106
2889.94	118
2891.65	120
2893.36	106
2895.06	118
2896.77	118
2898.47	106
2900.17	108
2901.88	124
2903.58	124
2905.28	108
2906.98	112
2908.69	120
2910.39	114
2912.09	112
2913.79	112
2915.49	104
2917.19	102
2918.88	106
2920.58	108
2922.28	110
2923.98	98
2925.67	118
2927.37	112
2929.06	118
2930.76	98
2932.45	100
2934.15	102
2935.84	108
2937.53	110
2939.23	102
2940.92	102
2942.61	102
2944.3	106
2945.99	110
2947.68	94
2949.37	104
2951.06	112
2952.75	94
2954.44	106
2956.12	102
2957.81	112
2959.5	114
2961.18	106
2962.87	108
2964.56	102
2966.24	94
2967.92	96
2969.61	92
2971.29	94
2972.97	94
2974.66	90
2976.34	96
2978.02	86
2979.7	98
2981.38	94
2983.06	100
2984.74	88
2986.42	96
2988.1	96
2989.78	100
2991.45	94
2993.13	88
2994.81	98
2996.48	92
2998.16	90
2999.83	96