File: muestras/nopal/inside_prf_03.txt
#Acq. time (s)=	15
#Accumulations=	2
#Range (cm-¹)=	200...3000
#Windows=	3
#Autofocus=	Off
#AutoExposure=	Off
#Spike filter=	Multiple accum.
#Delay time (s)=	0
#Binning=	1
#Readout mode=	Signal
#DeNoise=	Off
#ICS correction=	Off
#Dark correction=	Off
#Inst. Process=	Off
#Instrument=	LabRAM HR Evol
#Detector=	Syncerity OE
#Objective=	x100_VIS
#Grating=	600 (500nm)
#ND Filter=	10%
#Laser=	633nm_Edge
#Hole=	24.99
#Range=	Visible
#Project=	Omar
#Sample=	03-07-23
#Site=	nop
#Title=	inside_prf
#Remark=
#Date=	03.07.2023 14:13
#Acquired=	03.07.2023 14:13:55
201.713	512
204.247	484
206.778	530
209.311	510
211.84	478
214.371	488
216.899	456
219.428	492
221.955	496
224.482	528
227.007	516
229.531	510
232.055	496
234.579	506
237.1	524
239.621	536
242.141	546
244.661	544
247.179	534
249.698	548
252.215	550
254.731	532
257.246	550
259.761	540
262.273	532
264.786	588
267.298	526
269.809	556
272.319	556
274.828	544
277.336	566
279.844	562
282.351	552
284.855	564
287.361	576
289.866	614
292.368	582
294.871	582
297.372	574
299.873	628
302.372	602
304.872	612
307.37	618
309.866	632
312.364	598
314.859	600
317.353	612
319.848	622
322.341	630
324.833	622
327.324	632
329.814	646
332.304	658
334.792	632
337.28	648
339.767	648
342.254	662
344.739	650
347.224	672
349.708	654
352.191	664
354.673	646
357.155	682
359.634	682
362.114	664
364.593	654
367.07	678
369.548	706
372.024	698
374.499	722
376.974	676
379.447	722
381.92	684
384.392	722
386.864	712
389.333	688
391.802	700
394.272	688
396.739	742
399.206	724
401.673	736
404.138	692
406.602	740
409.066	728
411.528	764
413.99	778
416.451	736
418.911	758
421.371	758
423.83	788
426.288	804
428.745	808
431.201	798
433.657	788
436.111	820
438.565	826
441.017	822
443.469	860
445.921	862
448.37	828
450.821	810
453.27	832
455.717	828
458.165	878
460.61	826
463.056	892
465.5	860
467.945	822
470.387	880
472.829	854
475.271	850
477.711	832
480.15	862
482.589	880
485.027	864
487.465	900
489.901	926
492.337	916
494.771	920
497.205	908
499.638	936
502.07	922
504.502	926
506.933	954
509.363	964
511.792	912
514.219	948
516.647	924
519.073	906
521.5	992
523.924	950
526.348	936
528.772	962
531.194	992
533.616	1000
536.036	988
538.457	960
540.875	1000
543.294	996
545.712	1032
548.128	990
550.545	1036
552.959	1046
555.373	1042
557.788	1020
560.2	1086
562.612	1032
565.023	1036
567.433	1032
569.843	1028
572.251	1102
574.659	1086
577.066	1050
579.472	1092
581.878	1104
584.283	1118
586.687	1116
589.09	1074
591.493	1126
593.893	1104
596.294	1156
598.694	1158
601.093	1138
603.491	1140
605.889	1182
608.285	1166
610.682	1162
613.076	1196
615.471	1220
617.864	1246
620.256	1216
622.648	1232
625.039	1232
627.429	1206
629.819	1242
632.208	1222
634.595	1296
636.982	1290
639.369	1316
641.755	1322
644.139	1296
646.523	1330
648.906	1320
651.288	1344
653.67	1340
656.051	1398
658.429	1344
660.808	1390
663.187	1360
665.565	1406
667.942	1414
670.317	1370
672.692	1434
675.067	1410
677.44	1422
679.813	1454
682.184	1430
684.556	1472
686.926	1478
689.296	1542
691.664	1458
694.033	1458
696.4	1554
698.766	1530
701.133	1510
703.497	1540
705.861	1602
708.224	1610
710.586	1616
712.949	1604
715.31	1622
717.67	1646
720.029	1638
722.388	1654
724.746	1662
727.103	1702
729.458	1694
731.814	1722
734.168	1724
736.523	1754
738.876	1736
741.227	1780
743.579	1836
745.931	1782
748.28	1846
750.629	1854
752.977	1850
755.325	1870
757.672	1902
760.018	1898
762.363	1904
764.708	1894
767.052	2002
769.394	2000
771.737	2020
774.078	1972
776.419	1976
778.758	2074
781.097	2032
783.435	2068
785.773	2082
788.11	2088
790.446	2128
792.781	2176
795.115	2096
797.449	2138
799.782	2160
802.115	2204
804.446	2240
806.777	2246
809.106	2298
811.435	2282
813.764	2350
816.091	2402
818.418	2352
820.743	2392
823.069	2398
825.393	2474
827.717	2454
830.039	2492
832.362	2576
834.683	2566
837.003	2606
839.324	2666
841.643	2622
843.961	2618
846.278	2666
848.594	2728
850.91	2746
853.227	2798
855.541	2714
857.855	2818
860.168	2894
862.48	2864
864.79	2896
867.101	2938
869.411	2962
871.721	2964
874.029	2994
876.336	2986
878.643	3030
880.95	3004
883.254	3116
885.559	3122
887.862	3164
890.166	3172
892.467	3276
894.77	3194
897.07	3254
899.371	3298
901.669	3232
903.968	3316
906.266	3344
908.563	3418
910.859	3396
913.154	3506
915.449	3478
917.742	3462
920.036	3544
922.329	3574
924.621	3608
926.911	3626
929.201	3618
931.49	3716
933.779	3754
936.068	3782
938.355	3816
940.64	3862
942.926	3888
945.212	3970
947.495	4030
949.779	4004
952.062	4040
954.344	4128
956.625	4120
958.905	4216
961.184	4148
963.464	4192
965.742	4298
968.02	4334
970.296	4282
972.572	4374
974.847	4432
977.121	4408
979.396	4454
981.669	4538
983.941	4566
986.212	4618
988.483	4624
990.753	4696
993.022	4746
995.29	4844
997.558	4834
999.825	4816
1002.09	4878
1004.36	4918
1006.62	5002
1008.89	4980
1011.15	5080
1013.41	5020
1015.67	5076
1017.93	5164
1020.19	5186
1022.45	5320
1024.71	5354
1026.97	5374
1029.23	5390
1031.49	5422
1033.74	5508
1036	5570
1038.25	5534
1040.5	5668
1042.76	5742
1045.01	5838
1047.26	5776
1049.51	5994
1051.76	5928
1054.01	5940
1056.26	6082
1058.51	6164
1060.75	6186
1063	6132
1065.25	6224
1067.49	6298
1069.73	6330
1071.98	6272
1074.22	6482
1076.46	6528
1078.7	6468
1080.94	6504
1083.18	6524
1085.42	6528
1087.66	6626
1089.9	6612
1092.14	6658
1094.37	6654
1096.61	6698
1098.84	6780
1101.08	6850
1103.31	6814
1105.54	6756
1107.77	6928
1110	6906
1112.23	6944
1114.46	6974
1116.69	7064
1118.92	7198
1121.15	7106
1123.37	7198
1125.6	7226
1127.83	7240
1130.05	7328
1132.27	7342
1134.5	7272
1136.72	7442
1138.94	7444
1141.16	7436
1143.38	7496
1145.6	7512
1147.82	7558
1150.04	7706
1152.26	7756
1154.47	7632
1156.69	7780
1158.9	7784
1161.12	7782
1163.33	7826
1165.54	7868
1167.76	7840
1169.97	8018
1172.18	7812
1174.39	7902
1176.6	7936
1178.81	7954
1181.02	7880
1183.22	7918
1185.43	8038
1187.63	7968
1189.84	7898
1192.04	7936
1194.25	7814
1196.45	7862
1198.65	7900
1200.85	7800
1203.05	7924
1205.25	7812
1207.45	7728
1209.65	7838
1211.85	7820
1214.05	7850
1216.24	7668
1218.44	7786
1220.64	7816
1222.83	7776
1225.02	7776
1227.22	7816
1229.41	7758
1231.6	7742
1233.79	7632
1235.98	7608
1238.17	7770
1240.36	7734
1242.55	7716
1244.73	7648
1246.92	7670
1249.11	7604
1251.29	7570
1253.48	7534
1255.66	7566
1257.84	7532
1260.03	7492
1262.21	7444
1264.39	7504
1266.57	7454
1268.75	7460
1270.93	7450
1273.11	7398
1275.28	7322
1277.46	7414
1279.64	7354
1281.81	7358
1283.98	7265.39
1286.16	7295.1
1288.33	7267.17
1290.5	7268.02
1292.68	7233.68
1294.85	7063.49
1297.02	7032.2
1299.19	7064.76
1301.36	6972.12
1303.53	7055.68
1305.69	6947.72
1307.86	6788.25
1310.03	6831.02
1312.19	6812.75
1314.36	6819.72
1316.52	6734.48
1318.68	6605.52
1320.85	6654.56
1323.01	6642.08
1325.17	6555.85
1327.33	6436.26
1329.49	6414.46
1331.65	6370.27
1333.81	6335.89
1335.97	6331.02
1338.12	6246.67
1340.28	6295.73
1342.44	6152.6
1344.59	6151.84
1346.75	6157.56
1348.9	6130.45
1351.05	6030.58
1353.2	6022.97
1355.36	5992.08
1357.51	5884.6
1359.66	5913.48
1361.81	5815.02
1363.96	5781.02
1366.1	5766.68
1368.25	5811.36
1370.4	5650.53
1372.54	5654.02
1374.69	5692.41
1376.83	5621.61
1378.98	5595
1381.12	5510.49
1383.26	5602.47
1385.41	5468.65
1387.55	5539.99
1389.69	5496.72
1391.83	5451.24
1393.02	5412
1395.17	5320
1397.32	5374
1399.47	5296
1401.62	5234
1403.77	5084
1405.91	5172
1408.06	5138
1410.2	5188
1412.35	5218
1414.49	5034
1416.63	5172
1418.78	5022
1420.92	5138
1423.06	4988
1425.2	4992
1427.34	4956
1429.48	5020
1431.61	4904
1433.75	4866
1435.89	4864
1438.02	4954
1440.16	4894
1442.3	4930
1444.43	4892
1446.56	4832
1448.7	4868
1450.83	4806
1452.96	4752
1455.09	4920
1457.22	4790
1459.35	4762
1461.48	4740
1463.61	4808
1465.73	4672
1467.86	4712
1469.98	4778
1472.11	4612
1474.24	4686
1476.36	4692
1478.48	4560
1480.6	4556
1482.73	4688
1484.85	4608
1486.97	4544
1489.09	4528
1491.21	4556
1493.33	4570
1495.44	4496
1497.56	4506
1499.68	4582
1501.79	4534
1503.91	4402
1506.02	4416
1508.14	4462
1510.25	4424
1512.36	4346
1514.48	4374
1516.59	4400
1518.7	4326
1520.81	4356
1522.92	4306
1525.02	4330
1527.13	4240
1529.24	4258
1531.35	4190
1533.45	4230
1535.56	4244
1537.66	4206
1539.77	4242
1541.87	4140
1543.97	4152
1546.08	4194
1548.18	4106
1550.28	4074
1552.38	4112
1554.48	4074
1556.57	4072
1558.67	4030
1560.77	4064
1562.87	4040
1564.96	4106
1567.06	4046
1569.15	3980
1571.25	3930
1573.34	3990
1575.43	4034
1577.53	4028
1579.62	3918
1581.71	3900
1583.8	3844
1585.89	3926
1587.98	3918
1590.06	4008
1592.15	3966
1594.24	3836
1596.33	3938
1598.41	3902
1600.5	3880
1602.58	3890
1604.66	3910
1606.75	3846
1608.83	3882
1610.91	3866
1612.99	3838
1615.07	3790
1617.15	3822
1619.23	3904
1621.31	3842
1623.39	3824
1625.46	3866
1627.54	3880
1629.62	3778
1631.69	3786
1633.77	3816
1635.84	3774
1637.91	3776
1639.99	3770
1642.06	3726
1644.13	3772
1646.2	3752
1648.27	3774
1650.34	3688
1652.41	3760
1654.47	3664
1656.54	3694
1658.61	3714
1660.67	3634
1662.74	3638
1664.81	3686
1666.87	3564
1668.93	3704
1671	3648
1673.06	3572
1675.12	3640
1677.18	3628
1679.24	3616
1681.3	3556
1683.36	3568
1685.42	3504
1687.47	3564
1689.53	3524
1691.59	3566
1693.64	3534
1695.7	3502
1697.75	3536
1699.81	3514
1701.86	3518
1703.91	3476
1705.97	3542
1708.02	3518
1710.07	3506
1712.12	3536
1714.17	3484
1716.22	3468
1718.26	3546
1720.31	3466
1722.36	3484
1724.4	3506
1726.45	3520
1728.49	3426
1730.54	3484
1732.58	3400
1734.63	3482
1736.67	3418
1738.71	3446
1740.75	3484
1742.79	3370
1744.83	3448
1746.87	3394
1748.91	3418
1750.95	3378
1752.98	3396
1755.02	3458
1757.06	3476
1759.09	3476
1761.13	3472
1763.16	3374
1765.19	3460
1767.23	3368
1769.26	3426
1771.29	3422
1773.32	3422
1775.35	3386
1777.38	3410
1779.41	3382
1781.44	3426
1783.47	3396
1785.49	3432
1787.52	3356
1789.55	3386
1791.57	3386
1793.6	3446
1795.62	3400
1797.64	3384
1799.67	3386
1801.69	3418
1803.71	3400
1805.73	3436
1807.75	3460
1809.77	3368
1811.79	3358
1813.81	3418
1815.83	3336
1817.84	3304
1819.86	3368
1821.88	3332
1823.89	3360
1825.91	3320
1827.92	3356
1829.93	3276
1831.95	3364
1833.96	3324
1835.97	3364
1837.98	3344
1839.99	3308
1842	3324
1844.01	3248
1846.02	3318
1848.03	3304
1850.03	3220
1852.04	3268
1854.05	3250
1856.05	3234
1858.06	3224
1860.06	3232
1862.06	3204
1864.07	3256
1866.07	3308
1868.07	3250
1870.07	3228
1872.07	3218
1874.07	3202
1876.07	3164
1878.07	3256
1880.07	3166
1882.07	3228
1884.06	3194
1886.06	3240
1888.05	3202
1890.05	3288
1892.04	3150
1894.04	3256
1896.03	3300
1898.02	3246
1900.01	3242
1902	3244
1903.99	3280
1905.98	3250
1907.97	3176
1909.96	3284
1911.95	3232
1913.94	3246
1915.93	3224
1917.91	3198
1919.9	3162
1921.88	3170
1923.87	3260
1925.85	3172
1927.83	3228
1929.82	3256
1931.8	3176
1933.78	3266
1935.76	3286
1937.74	3196
1939.72	3174
1941.7	3162
1943.68	3190
1945.65	3180
1947.63	3180
1949.61	3222
1951.58	3152
1953.56	3292
1955.53	3212
1957.51	3084
1959.48	3156
1961.45	3218
1963.43	3204
1965.4	3160
1967.37	3134
1969.34	3170
1971.31	3208
1973.28	3214
1975.25	3168
1977.22	3162
1979.18	3152
1981.15	3060
1983.12	3130
1985.08	3160
1987.05	3176
1989.01	3130
1990.97	3136
1992.94	3196
1994.9	3152
1996.86	3100
1998.82	3094
2000.78	3116
2002.74	3176
2004.7	3098
2006.66	3118
2008.62	3022
2010.58	3156
2012.54	3098
2014.49	3080
2016.45	3120
2018.4	3094
2020.36	3100
2022.31	3130
2024.27	3134
2026.22	3126
2028.17	3060
2030.12	3104
2032.07	3088
2034.03	3182
2035.98	3130
2037.93	3028
2039.87	3054
2041.82	3126
2043.77	3078
2045.72	3026
2047.66	3100
2049.61	3088
2051.55	3022
2053.5	3070
2055.44	3150
2057.39	3080
2059.33	3062
2061.27	3134
2063.21	3026
2065.15	3076
2067.09	3024
2069.03	3044
2070.97	3012
2072.91	3068
2074.85	3080
2076.79	3120
2078.73	3008
2080.66	3010
2082.6	3064
2084.53	3026
2086.47	3078
2088.4	3034
2090.33	3054
2092.27	3082
2094.2	3026
2096.13	3022
2098.06	3020
2099.99	3012
2101.92	3078
2103.85	3022
2105.78	3040
2107.71	2962
2109.64	3050
2111.56	2988
2113.49	2938
2115.41	2988
2117.34	2962
2119.26	3022
2121.19	3004
2123.11	3040
2125.03	2978
2126.96	2992
2128.88	2980
2130.8	3068
2132.72	3012
2134.64	2938
2136.56	3022
2138.48	2966
2140.4	3054
2142.31	3010
2144.23	3012
2146.15	2966
2148.06	2990
2149.98	3002
2151.89	2998
2153.81	2992
2155.72	2964
2157.63	2974
2159.55	2986
2161.46	2970
2163.37	2936
2165.28	2948
2167.19	2968
2169.1	2858
2171.01	2956
2172.91	2866
2174.82	2930
2176.73	2888
2178.64	2944
2180.54	2926
2182.45	2872
2184.35	2898
2186.26	2892
2188.16	2908
2190.06	2908
2191.96	2880
2193.87	2886
2195.77	2896
2197.67	2888
2199.57	2806
2201.47	2854
2203.37	2926
2205.27	2846
2207.16	2862
2209.06	2852
2210.96	2874
2212.85	2856
2214.75	2878
2216.64	2864
2218.54	2846
2220.43	2874
2222.33	2852
2224.22	2882.25
2226.11	2835.55
2228	2880.74
2229.89	2874.84
2231.78	2810.42
2233.67	2820.56
2235.56	2849.11
2237.45	2839.57
2239.34	2827.95
2241.23	2840.53
2243.11	2778.02
2245	2824.07
2246.89	2845.9
2248.77	2806.84
2250.66	2779.12
2252.54	2802.21
2254.42	2794.06
2256.31	2793.74
2258.19	2800.76
2260.07	2777.75
2261.95	2724.08
2263.83	2804.05
2265.71	2758.85
2267.59	2727.91
2269.47	2704.49
2271.35	2796.9
2273.23	2714
2275.1	2736.29
2276.98	2725.42
2278.86	2699.61
2280.73	2696.48
2282.61	2714.24
2284.48	2709.61
2286.36	2731.96
2288.23	2669.48
2290.1	2676.26
2291.98	2712.84
2293.85	2693.55
2295.72	2631.13
2297.59	2651.98
2299.46	2670.57
2301.33	2656.27
2303.2	2650.66
2305.06	2661.63
2306.93	2639
2308.8	2676.7
2310.67	2608.54
2312.53	2641.45
2314.4	2608.22
2316.26	2606.18
2317.62	2570
2319.5	2514
2321.37	2546
2323.24	2596
2325.12	2584
2326.99	2582
2328.86	2618
2330.73	2564
2332.6	2556
2334.47	2500
2336.34	2648
2338.2	2556
2340.07	2566
2341.94	2540
2343.81	2560
2345.67	2538
2347.54	2554
2349.4	2530
2351.27	2546
2353.13	2556
2354.99	2520
2356.86	2502
2358.72	2512
2360.58	2492
2362.44	2500
2364.3	2530
2366.16	2470
2368.02	2474
2369.88	2512
2371.74	2510
2373.6	2492
2375.45	2470
2377.31	2412
2379.17	2432
2381.02	2454
2382.88	2452
2384.73	2442
2386.58	2432
2388.44	2490
2390.29	2438
2392.14	2408
2393.99	2416
2395.85	2440
2397.7	2408
2399.55	2416
2401.4	2436
2403.25	2446
2405.09	2396
2406.94	2366
2408.79	2354
2410.63	2380
2412.48	2328
2414.33	2358
2416.17	2322
2418.02	2356
2419.86	2368
2421.7	2322
2423.55	2298
2425.39	2346
2427.23	2276
2429.07	2318
2430.91	2310
2432.75	2250
2434.59	2284
2436.43	2338
2438.27	2300
2440.11	2214
2441.95	2244
2443.78	2208
2445.62	2222
2447.46	2228
2449.29	2254
2451.13	2250
2452.96	2238
2454.79	2184
2456.63	2228
2458.46	2158
2460.29	2210
2462.12	2200
2463.95	2148
2465.78	2146
2467.61	2202
2469.44	2108
2471.27	2146
2473.1	2086
2474.93	2150
2476.76	2148
2478.58	2098
2480.41	2114
2482.23	2102
2484.06	2050
2485.88	2080
2487.71	2068
2489.53	2058
2491.35	2070
2493.18	2076
2495	2020
2496.82	2024
2498.64	2026
2500.46	2040
2502.28	2004
2504.1	2026
2505.92	2070
2507.74	1990
2509.55	1998
2511.37	1974
2513.19	2004
2515	1952
2516.82	1924
2518.63	1944
2520.45	1976
2522.26	1970
2524.07	1962
2525.89	1906
2527.7	1936
2529.51	1966
2531.32	1878
2533.13	1922
2534.94	1892
2536.75	1870
2538.56	1890
2540.37	1856
2542.18	1898
2543.98	1886
2545.79	1834
2547.6	1836
2549.4	1876
2551.21	1832
2553.01	1862
2554.82	1816
2556.62	1820
2558.42	1768
2560.23	1788
2562.03	1778
2563.83	1772
2565.63	1756
2567.43	1786
2569.23	1784
2571.03	1804
2572.83	1766
2574.63	1756
2576.43	1754
2578.22	1744
2580.02	1744
2581.82	1782
2583.61	1754
2585.41	1738
2587.2	1756
2589	1680
2590.79	1732
2592.58	1716
2594.38	1690
2596.17	1716
2597.96	1690
2599.75	1700
2601.54	1670
2603.33	1672
2605.12	1638
2606.91	1636
2608.7	1644
2610.49	1602
2612.27	1652
2614.06	1680
2615.85	1618
2617.63	1588
2619.42	1650
2621.2	1600
2622.99	1622
2624.77	1588
2626.55	1532
2628.34	1538
2630.12	1556
2631.9	1566
2633.68	1528
2635.46	1600
2637.24	1516
2639.02	1506
2640.8	1520
2642.58	1510
2644.36	1512
2646.14	1516
2647.91	1458
2649.69	1546
2651.46	1488
2653.24	1484
2655.01	1450
2656.79	1492
2658.56	1468
2660.34	1454
2662.11	1480
2663.88	1478
2665.65	1482
2667.42	1468
2669.2	1464
2670.96	1450
2672.73	1412
2674.5	1424
2676.27	1390
2678.04	1462
2679.81	1386
2681.58	1394
2683.34	1394
2685.11	1424
2686.87	1420
2688.64	1394
2690.4	1348
2692.17	1368
2693.93	1392
2695.69	1346
2697.46	1348
2699.22	1342
2700.98	1304
2702.74	1344
2704.5	1296
2706.26	1288
2708.02	1326
2709.78	1350
2711.54	1312
2713.3	1322
2715.05	1294
2716.81	1306
2718.57	1266
2720.32	1272
2722.08	1258
2723.83	1276
2725.59	1298
2727.34	1224
2729.09	1286
2730.85	1262
2732.6	1250
2734.35	1234
2736.1	1218
2737.85	1230
2739.6	1210
2741.35	1210
2743.1	1186
2744.85	1180
2746.6	1146
2748.35	1166
2750.09	1194
2751.84	1176
2753.59	1110
2755.33	1176
2757.08	1170
2758.82	1156
2760.57	1136
2762.31	1174
2764.05	1170
2765.79	1152
2767.54	1088
2769.28	1156
2771.02	1116
2772.76	1142
2774.5	1150
2776.24	1148
2777.98	1128
2779.72	1134
2781.46	1084
2783.19	1082
2784.93	1086
2786.67	1066
2788.4	1054
2790.14	1102
2791.87	1080
2793.61	1064
2795.34	1064
2797.07	1040
2798.81	1036
2800.54	1056
2802.27	1012
2804	1054
2805.74	986
2807.47	1054
2809.2	1014
2810.93	1012
2812.65	1020
2814.38	992
2816.11	990
2817.84	1028
2819.56	1014
2821.29	976
2823.02	982
2824.74	990
2826.47	1014
2828.19	1000
2829.92	974
2831.64	966
2833.36	980
2835.09	958
2836.81	950
2838.53	970
2840.25	918
2841.97	906
2843.69	910
2845.41	926
2847.13	900
2848.85	932
2850.57	914
2852.28	902
2854	906
2855.72	908
2857.43	882
2859.15	896
2860.86	896
2862.58	878
2864.29	878
2866.01	860
2867.72	882
2869.43	878
2871.14	872
2872.86	848
2874.57	816
2876.28	818
2877.99	860
2879.7	840
2881.41	802
2883.11	842
2884.82	862
2886.53	824
2888.24	848
2889.94	836
2891.65	844
2893.36	814
2895.06	800
2896.77	828
2898.47	796
2900.17	800
2901.88	840
2903.58	818
2905.28	778
2906.98	806
2908.69	808
2910.39	802
2912.09	778
2913.79	790
2915.49	790
2917.19	786
2918.88	754
2920.58	782
2922.28	744
2923.98	778
2925.67	746
2927.37	770
2929.06	754
2930.76	770
2932.45	740
2934.15	756
2935.84	754
2937.53	758
2939.23	736
2940.92	750
2942.61	736
2944.3	772
2945.99	732
2947.68	726
2949.37	714
2951.06	726
2952.75	684
2954.44	724
2956.12	712
2957.81	684
2959.5	710
2961.18	702
2962.87	710
2964.56	732
2966.24	708
2967.92	676
2969.61	742
2971.29	682
2972.97	676
2974.66	692
2976.34	682
2978.02	674
2979.7	676
2981.38	654
2983.06	676
2984.74	672
2986.42	662
2988.1	634
2989.78	670
2991.45	656
2993.13	658
2994.81	642
2996.48	664
2998.16	652
2999.83	642