File: muestras/nopal/inside_prf_14.txt
#Acq. time (s)=	10
#Accumulations=	1
#Range (cm-¹)=	200...3000
#Windows=	3
#Autofocus=	Off
#AutoExposure=	Off
#Spike filter=	Off
#Delay time (s)=	0
#Binning=	1
#Readout mode=	Signal
#DeNoise=	Off
#ICS correction=	Off
#Dark correction=	Off
#Inst. Process=	Off
#Instrument=	LabRAM HR Evol
#Detector=	Syncerity OE
#Objective=	x100_VIS
#Grating=	600 (500nm)
#ND Filter=	0.01%
#Laser=	633nm_Edge
#Hole=	30.0125
#Range=	Visible
#Project=	Omar
#Sample=	03-07-23
#Site=	nop
#Title=	inside_prf
#Remark=
#Date=	03.07.2023 14:43
#Acquired=	03.07.2023 14:43:02
201.713	28
204.247	32
206.778	32
209.311	30
211.84	28
214.371	24
216.899	30
219.428	34
221.955	36
224.482	28
227.007	24
229.531	32
232.055	30
234.579	30
237.1	32
239.621	32
242.141	26
244.661	36
247.179	30
249.698	30
252.215	32
254.731	32
257.246	30
259.761	26
262.273	34
264.786	34
267.298	40
269.809	42
272.319	38
274.828	34
277.336	40
279.844	36
282.351	32
284.855	32
287.361	32
289.866	36
292.368	32
294.871	32
297.372	36
299.873	34
302.372	30
304.872	28
307.37	32
309.866	32
312.364	36
314.859	34
317.353	34
319.848	36
322.341	34
324.833	30
327.324	42
329.814	32
332.304	34
334.792	48
337.28	40
339.767	30
342.254	36
344.739	40
347.224	40
349.708	32
352.191	40
354.673	36
357.155	38
359.634	34
362.114	34
364.593	40
367.07	38
369.548	42
372.024	42
374.499	36
376.974	40
379.447	40
381.92	36
384.392	30
386.864	34
389.333	40
391.802	32
394.272	38
396.739	38
399.206	42
401.673	36
404.138	46
406.602	40
409.066	46
411.528	40
413.99	40
416.451	38
418.911	42
421.371	40
423.83	36
426.288	40
428.745	42
431.201	44
433.657	40
436.111	42
438.565	48
441.017	42
443.469	32
445.921	44
448.37	38
450.821	36
453.27	34
455.717	38
458.165	38
460.61	38
463.056	38
465.5	48
467.945	44
470.387	46
472.829	38
475.271	40
477.711	50
480.15	40
482.589	44
485.027	44
487.465	46
489.901	42
492.337	50
494.771	48
497.205	48
499.638	52
502.07	40
504.502	56
506.933	52
509.363	42
511.792	42
514.219	42
516.647	52
519.073	46
521.5	60
523.924	54
526.348	46
528.772	58
531.194	50
533.616	60
536.036	58
538.457	60
540.875	52
543.294	54
545.712	56
548.128	60
550.545	56
552.959	64
555.373	52
557.788	50
560.2	54
562.612	58
565.023	56
567.433	52
569.843	46
572.251	50
574.659	56
577.066	58
579.472	50
581.878	54
584.283	54
586.687	64
589.09	66
591.493	58
593.893	58
596.294	58
598.694	62
601.093	56
603.491	50
605.889	48
608.285	62
610.682	66
613.076	64
615.471	54
617.864	58
620.256	60
622.648	72
625.039	64
627.429	66
629.819	58
632.208	66
634.595	64
636.982	60
639.369	62
641.755	60
644.139	62
646.523	68
648.906	74
651.288	68
653.67	68
656.051	62
658.429	78
660.808	80
663.187	68
665.565	80
667.942	64
670.317	72
672.692	66
675.067	80
677.44	74
679.813	74
682.184	80
684.556	76
686.926	82
689.296	84
691.664	78
694.033	84
696.4	70
698.766	78
701.133	76
703.497	90
705.861	82
708.224	92
710.586	90
712.949	80
715.31	82
717.67	102
720.029	80
722.388	100
724.746	92
727.103	92
729.458	94
731.814	94
734.168	102
736.523	94
738.876	92
741.227	102
743.579	104
745.931	102
748.28	110
750.629	108
752.977	104
755.325	102
757.672	106
760.018	116
762.363	100
764.708	110
767.052	110
769.394	114
771.737	118
774.078	108
776.419	100
778.758	124
781.097	104
783.435	98
785.773	122
788.11	122
790.446	116
792.781	122
795.115	112
797.449	120
799.782	126
802.115	126
804.446	126
806.777	128
809.106	140
811.435	148
813.764	146
816.091	130
818.418	142
820.743	172
823.069	150
825.393	150
827.717	140
830.039	138
832.362	158
834.683	166
837.003	154
839.324	166
841.643	172
843.961	174
846.278	156
848.594	154
850.91	166
853.227	180
855.541	162
857.855	162
860.168	178
862.48	172
864.79	178
867.101	192
869.411	180
871.721	166
874.029	172
876.336	180
878.643	184
880.95	184
883.254	194
885.559	194
887.862	210
890.166	194
892.467	212
894.77	202
897.07	198
899.371	202
901.669	212
903.968	210
906.266	214
908.563	216
910.859	216
913.154	220
915.449	226
917.742	218
920.036	230
922.329	242
924.621	234
926.911	236
929.201	226
931.49	246
933.779	226
936.068	254
938.355	228
940.64	230
942.926	254
945.212	246
947.495	258
949.779	254
952.062	252
954.344	266
956.625	276
958.905	260
961.184	280
963.464	282
965.742	288
968.02	292
970.296	278
972.572	282
974.847	296
977.121	306
979.396	294
981.669	306
983.941	304
986.212	302
988.483	330
990.753	306
993.022	322
995.29	334
997.558	338
999.825	326
1002.09	336
1004.36	330
1006.62	346
1008.89	360
1011.15	360
1013.41	336
1015.67	358
1017.93	356
1020.19	338
1022.45	380
1024.71	360
1026.97	372
1029.23	378
1031.49	360
1033.74	382
1036	394
1038.25	386
1040.5	398
1042.76	416
1045.01	382
1047.26	394
1049.51	428
1051.76	418
1054.01	438
1056.26	432
1058.51	428
1060.75	416
1063	466
1065.25	428
1067.49	438
1069.73	460
1071.98	468
1074.22	484
1076.46	474
1078.7	488
1080.94	442
1083.18	490
1085.42	478
1087.66	476
1089.9	442
1092.14	474
1094.37	502
1096.61	490
1098.84	484
1101.08	520
1103.31	486
1105.54	494
1107.77	482
1110	508
1112.23	506
1114.46	524
1116.69	518
1118.92	496
1121.15	500
1123.37	530
1125.6	542
1127.83	534
1130.05	528
1132.27	546
1134.5	528
1136.72	548
1138.94	554
1141.16	546
1143.38	554
1145.6	528
1147.82	550
1150.04	568
1152.26	512
1154.47	566
1156.69	576
1158.9	588
1161.12	572
1163.33	558
1165.54	582
1167.76	572
1169.97	542
1172.18	564
1174.39	558
1176.6	598
1178.81	566
1181.02	576
1183.22	568
1185.43	584
1187.63	570
1189.84	558
1192.04	580
1194.25	584
1196.45	556
1198.65	560
1200.85	564
1203.05	552
1205.25	546
1207.45	534
1209.65	550
1211.85	576
1214.05	550
1216.24	562
1218.44	552
1220.64	566
1222.83	538
1225.02	538
1227.22	538
1229.41	514
1231.6	512
1233.79	498
1235.98	534
1238.17	506
1240.36	518
1242.55	510
1244.73	494
1246.92	502
1249.11	482
1251.29	500
1253.48	478
1255.66	524
1257.84	494
1260.03	470
1262.21	486
1264.39	494
1266.57	480
1268.75	452
1270.93	452
1273.11	490
1275.28	490
1277.46	470
1279.64	448
1281.81	444
1283.98	446.263
1286.16	449.474
1288.33	477.406
1290.5	478.824
1292.68	453.783
1294.85	444.798
1297.02	433.09
1299.19	424.006
1301.36	433.673
1303.53	426.716
1305.69	440.562
1307.86	417.335
1310.03	419.536
1312.19	435.635
1314.36	404.235
1316.52	398.545
1318.68	401.607
1320.85	409.027
1323.01	406.589
1325.17	404.412
1327.33	420.149
1329.49	392.44
1331.65	380.992
1333.81	385.878
1335.97	389.645
1338.12	385.025
1340.28	396.051
1342.44	378.085
1344.59	380.821
1346.75	373.749
1348.9	365.457
1351.05	370.21
1353.2	373.435
1355.36	372.557
1357.51	342.834
1359.66	370.29
1361.81	371.183
1363.96	362.279
1366.1	343.127
1368.25	346.53
1370.4	354.016
1372.54	347.194
1374.69	353.452
1376.83	350.362
1378.98	329.868
1381.12	354.895
1383.26	332.867
1385.41	325.194
1387.55	318.24
1389.69	329.035
1391.83	334.767
1393.02	338
1395.17	316
1397.32	316
1399.47	328
1401.62	320
1403.77	316
1405.91	298
1408.06	304
1410.2	316
1412.35	294
1414.49	302
1416.63	306
1418.78	280
1420.92	306
1423.06	292
1425.2	296
1427.34	302
1429.48	302
1431.61	272
1433.75	280
1435.89	268
1438.02	272
1440.16	292
1442.3	272
1444.43	276
1446.56	254
1448.7	264
1450.83	292
1452.96	258
1455.09	274
1457.22	248
1459.35	266
1461.48	272
1463.61	244
1465.73	260
1467.86	248
1469.98	256
1472.11	238
1474.24	244
1476.36	260
1478.48	246
1480.6	232
1482.73	248
1484.85	246
1486.97	242
1489.09	230
1491.21	248
1493.33	244
1495.44	242
1497.56	242
1499.68	248
1501.79	224
1503.91	244
1506.02	248
1508.14	248
1510.25	244
1512.36	238
1514.48	230
1516.59	226
1518.7	224
1520.81	210
1522.92	226
1525.02	218
1527.13	232
1529.24	234
1531.35	224
1533.45	240
1535.56	218
1537.66	214
1539.77	218
1541.87	226
1543.97	206
1546.08	214
1548.18	206
1550.28	208
1552.38	202
1554.48	214
1556.57	192
1558.67	212
1560.77	208
1562.87	210
1564.96	198
1567.06	198
1569.15	200
1571.25	180
1573.34	192
1575.43	198
1577.53	200
1579.62	196
1581.71	212
1583.8	214
1585.89	210
1587.98	186
1590.06	182
1592.15	206
1594.24	192
1596.33	180
1598.41	198
1600.5	186
1602.58	198
1604.66	194
1606.75	202
1608.83	208
1610.91	182
1612.99	194
1615.07	190
1617.15	188
1619.23	184
1621.31	186
1623.39	188
1625.46	174
1627.54	188
1629.62	190
1631.69	194
1633.77	176
1635.84	194
1637.91	192
1639.99	188
1642.06	182
1644.13	172
1646.2	184
1648.27	188
1650.34	180
1652.41	188
1654.47	178
1656.54	184
1658.61	180
1660.67	190
1662.74	198
1664.81	178
1666.87	188
1668.93	156
1671	156
1673.06	182
1675.12	190
1677.18	172
1679.24	166
1681.3	174
1683.36	174
1685.42	160
1687.47	182
1689.53	180
1691.59	194
1693.64	180
1695.7	172
1697.75	172
1699.81	170
1701.86	184
1703.91	168
1705.97	162
1708.02	178
1710.07	180
1712.12	158
1714.17	176
1716.22	160
1718.26	166
1720.31	176
1722.36	166
1724.4	176
1726.45	184
1728.49	174
1730.54	160
1732.58	158
1734.63	158
1736.67	146
1738.71	168
1740.75	158
1742.79	160
1744.83	174
1746.87	182
1748.91	168
1750.95	166
1752.98	160
1755.02	184
1757.06	174
1759.09	160
1761.13	180
1763.16	170
1765.19	174
1767.23	160
1769.26	168
1771.29	166
1773.32	178
1775.35	164
1777.38	168
1779.41	162
1781.44	168
1783.47	182
1785.49	160
1787.52	172
1789.55	174
1791.57	164
1793.6	158
1795.62	164
1797.64	170
1799.67	152
1801.69	162
1803.71	166
1805.73	172
1807.75	174
1809.77	158
1811.79	158
1813.81	170
1815.83	176
1817.84	154
1819.86	166
1821.88	158
1823.89	172
1825.91	162
1827.92	178
1829.93	166
1831.95	180
1833.96	172
1835.97	174
1837.98	164
1839.99	160
1842	154
1844.01	168
1846.02	156
1848.03	164
1850.03	174
1852.04	168
1854.05	154
1856.05	160
1858.06	140
1860.06	162
1862.06	146
1864.07	164
1866.07	176
1868.07	168
1870.07	174
1872.07	168
1874.07	162
1876.07	174
1878.07	174
1880.07	158
1882.07	162
1884.06	148
1886.06	172
1888.05	158
1890.05	160
1892.04	166
1894.04	178
1896.03	156
1898.02	160
1900.01	168
1902	144
1903.99	162
1905.98	164
1907.97	164
1909.96	154
1911.95	146
1913.94	182
1915.93	146
1917.91	162
1919.9	158
1921.88	166
1923.87	166
1925.85	170
1927.83	172
1929.82	172
1931.8	164
1933.78	162
1935.76	160
1937.74	156
1939.72	174
1941.7	160
1943.68	162
1945.65	170
1947.63	178
1949.61	158
1951.58	170
1953.56	162
1955.53	172
1957.51	168
1959.48	158
1961.45	168
1963.43	172
1965.4	164
1967.37	150
1969.34	158
1971.31	156
1973.28	180
1975.25	172
1977.22	146
1979.18	154
1981.15	160
1983.12	164
1985.08	168
1987.05	152
1989.01	158
1990.97	166
1992.94	168
1994.9	164
1996.86	168
1998.82	158
2000.78	164
2002.74	168
2004.7	164
2006.66	164
2008.62	160
2010.58	158
2012.54	164
2014.49	166
2016.45	182
2018.4	162
2020.36	146
2022.31	166
2024.27	160
2026.22	162
2028.17	170
2030.12	148
2032.07	170
2034.03	156
2035.98	168
2037.93	166
2039.87	154
2041.82	172
2043.77	158
2045.72	172
2047.66	166
2049.61	164
2051.55	158
2053.5	150
2055.44	166
2057.39	164
2059.33	156
2061.27	164
2063.21	162
2065.15	156
2067.09	170
2069.03	162
2070.97	178
2072.91	154
2074.85	164
2076.79	178
2078.73	164
2080.66	162
2082.6	170
2084.53	166
2086.47	170
2088.4	154
2090.33	158
2092.27	176
2094.2	172
2096.13	148
2098.06	162
2099.99	166
2101.92	162
2103.85	168
2105.78	154
2107.71	162
2109.64	172
2111.56	162
2113.49	154
2115.41	152
2117.34	162
2119.26	158
2121.19	170
2123.11	160
2125.03	160
2126.96	156
2128.88	164
2130.8	164
2132.72	162
2134.64	168
2136.56	178
2138.48	164
2140.4	162
2142.31	162
2144.23	180
2146.15	178
2148.06	150
2149.98	168
2151.89	162
2153.81	160
2155.72	166
2157.63	154
2159.55	156
2161.46	156
2163.37	166
2165.28	168
2167.19	168
2169.1	150
2171.01	170
2172.91	172
2174.82	154
2176.73	146
2178.64	162
2180.54	152
2182.45	148
2184.35	146
2186.26	148
2188.16	144
2190.06	176
2191.96	168
2193.87	176
2195.77	162
2197.67	162
2199.57	148
2201.47	148
2203.37	152
2205.27	168
2207.16	158
2209.06	176
2210.96	148
2212.85	150
2214.75	174
2216.64	156
2218.54	152
2220.43	168
2222.33	160
2224.22	148.261
2226.11	156.329
2228	154.348
2229.89	153.877
2231.78	159.5
2233.67	159.313
2235.56	156.814
2237.45	147.709
2239.34	151.989
2241.23	154.869
2243.11	162.28
2245	160.111
2246.89	166.37
2248.77	153.719
2250.66	155.515
2252.54	163.605
2254.42	155.791
2256.31	157.966
2258.19	150
2260.07	144.082
2261.95	163.749
2263.83	154.96
2265.71	152.108
2267.59	161.456
2269.47	155.7
2271.35	150.954
2273.23	163.133
2275.1	147.439
2276.98	151.213
2278.86	156.261
2280.73	160.742
2282.61	159.124
2284.48	153.033
2286.36	156.905
2288.23	160.326
2290.1	155.547
2291.98	154.246
2293.85	152.372
2295.72	161.445
2297.59	153.18
2299.46	160.261
2301.33	152.04
2303.2	157.265
2305.06	157.544
2306.93	156.678
2308.8	159.16
2310.67	165.888
2312.53	156.305
2314.4	163.247
2316.26	155.428
2317.62	164
2319.5	164
2321.37	162
2323.24	160
2325.12	158
2326.99	162
2328.86	152
2330.73	148
2332.6	162
2334.47	156
2336.34	156
2338.2	150
2340.07	144
2341.94	158
2343.81	162
2345.67	152
2347.54	160
2349.4	150
2351.27	166
2353.13	164
2354.99	146
2356.86	140
2358.72	142
2360.58	148
2362.44	156
2364.3	140
2366.16	156
2368.02	164
2369.88	150
2371.74	156
2373.6	156
2375.45	162
2377.31	150
2379.17	148
2381.02	164
2382.88	156
2384.73	156
2386.58	154
2388.44	136
2390.29	146
2392.14	128
2393.99	148
2395.85	148
2397.7	138
2399.55	138
2401.4	142
2403.25	138
2405.09	136
2406.94	152
2408.79	146
2410.63	138
2412.48	142
2414.33	136
2416.17	144
2418.02	140
2419.86	152
2421.7	146
2423.55	148
2425.39	136
2427.23	140
2429.07	138
2430.91	138
2432.75	142
2434.59	134
2436.43	148
2438.27	146
2440.11	144
2441.95	146
2443.78	124
2445.62	142
2447.46	152
2449.29	146
2451.13	136
2452.96	136
2454.79	130
2456.63	134
2458.46	134
2460.29	126
2462.12	138
2463.95	140
2465.78	128
2467.61	126
2469.44	132
2471.27	120
2473.1	136
2474.93	126
2476.76	128
2478.58	132
2480.41	132
2482.23	134
2484.06	120
2485.88	128
2487.71	134
2489.53	122
2491.35	136
2493.18	132
2495	130
2496.82	122
2498.64	126
2500.46	136
2502.28	122
2504.1	126
2505.92	126
2507.74	120
2509.55	116
2511.37	110
2513.19	146
2515	144
2516.82	120
2518.63	114
2520.45	122
2522.26	134
2524.07	122
2525.89	120
2527.7	126
2529.51	124
2531.32	126
2533.13	126
2534.94	134
2536.75	120
2538.56	112
2540.37	118
2542.18	116
2543.98	118
2545.79	124
2547.6	110
2549.4	130
2551.21	126
2553.01	108
2554.82	112
2556.62	116
2558.42	104
2560.23	114
2562.03	102
2563.83	120
2565.63	114
2567.43	126
2569.23	106
2571.03	114
2572.83	106
2574.63	112
2576.43	104
2578.22	120
2580.02	110
2581.82	112
2583.61	108
2585.41	114
2587.2	120
2589	108
2590.79	114
2592.58	108
2594.38	92
2596.17	100
2597.96	102
2599.75	106
2601.54	114
2603.33	120
2605.12	94
2606.91	112
2608.7	98
2610.49	94
2612.27	110
2614.06	104
2615.85	98
2617.63	112
2619.42	104
2621.2	106
2622.99	106
2624.77	96
2626.55	104
2628.34	94
2630.12	110
2631.9	98
2633.68	106
2635.46	102
2637.24	102
2639.02	102
2640.8	94
2642.58	102
2644.36	88
2646.14	104
2647.91	98
2649.69	92
2651.46	106
2653.24	102
2655.01	90
2656.79	104
2658.56	94
2660.34	86
2662.11	90
2663.88	96
2665.65	92
2667.42	90
2669.2	92
2670.96	92
2672.73	94
2674.5	100
2676.27	84
2678.04	98
2679.81	90
2681.58	90
2683.34	86
2685.11	88
2686.87	84
2688.64	92
2690.4	86
2692.17	82
2693.93	108
2695.69	86
2697.46	84
2699.22	96
2700.98	88
2702.74	96
2704.5	84
2706.26	86
2708.02	82
2709.78	88
2711.54	92
2713.3	94
2715.05	102
2716.81	84
2718.57	90
2720.32	86
2722.08	76
2723.83	80
2725.59	86
2727.34	74
2729.09	82
2730.85	84
2732.6	86
2734.35	88
2736.1	78
2737.85	74
2739.6	86
2741.35	70
2743.1	78
2744.85	84
2746.6	84
2748.35	100
2750.09	92
2751.84	78
2753.59	72
2755.33	70
2757.08	76
2758.82	78
2760.57	90
2762.31	90
2764.05	82
2765.79	66
2767.54	82
2769.28	70
2771.02	76
2772.76	74
2774.5	86
2776.24	76
2777.98	70
2779.72	80
2781.46	72
2783.19	86
2784.93	62
2786.67	76
2788.4	76
2790.14	80
2791.87	70
2793.61	78
2795.34	70
2797.07	74
2798.81	72
2800.54	74
2802.27	74
2804	84
2805.74	84
2807.47	70
2809.2	68
2810.93	68
2812.65	74
2814.38	78
2816.11	74
2817.84	68
2819.56	62
2821.29	70
2823.02	68
2824.74	62
2826.47	72
2828.19	74
2829.92	58
2831.64	68
2833.36	70
2835.09	72
2836.81	70
2838.53	68
2840.25	68
2841.97	58
2843.69	68
2845.41	68
2847.13	72
2848.85	68
2850.57	72
2852.28	72
2854	50
2855.72	76
2857.43	62
2859.15	60
2860.86	66
2862.58	66
2864.29	54
2866.01	60
2867.72	66
2869.43	66
2871.14	52
2872.86	68
2874.57	54
2876.28	66
2877.99	64
2879.7	62
2881.41	62
2883.11	64
2884.82	64
2886.53	60
2888.24	58
2889.94	54
2891.65	62
2893.36	68
2895.06	56
2896.77	52
2898.47	66
2900.17	66
2901.88	64
2903.58	66
2905.28	56
2906.98	58
2908.69	62
2910.39	54
2912.09	60
2913.79	60
2915.49	48
2917.19	50
2918.88	54
2920.58	54
2922.28	52
2923.98	62
2925.67	56
2927.37	56
2929.06	54
2930.76	56
2932.45	58
2934.15	54
2935.84	56
2937.53	48
2939.23	60
2940.92	48
2942.61	46
2944.3	60
2945.99	52
2947.68	60
2949.37	58
2951.06	56
2952.75	56
2954.44	60
2956.12	56
2957.81	56
2959.5	60
2961.18	52
2962.87	54
2964.56	56
2966.24	60
2967.92	52
2969.61	54
2971.29	60
2972.97	52
2974.66	58
2976.34	52
2978.02	50
2979.7	52
2981.38	46
2983.06	50
2984.74	56
2986.42	48
2988.1	60
2989.78	44
2991.45	46
2993.13	54
2994.81	54
2996.48	48
2998.16	56
2999.83	48