File: muestras/nopal/inside_prf_11.txt
#Acq. time (s)=	20
#Accumulations=	1
#Range (cm-¹)=	200...3000
#Windows=	3
#Autofocus=	Off
#AutoExposure=	Off
#Spike filter=	Off
#Delay time (s)=	0
#Binning=	1
#Readout mode=	Signal
#DeNoise=	Off
#ICS correction=	Off
#Dark correction=	Off
#Inst. Process=	Off
#Instrument=	LabRAM HR Evol
#Detector=	Syncerity OE
#Objective=	x100_VIS
#Grating=	600 (500nm)
#ND Filter=	0.01%
#Laser=	633nm_Edge
#Hole=	49.98
#Range=	Visible
#Project=	Omar
#Sample=	03-07-23
#Site=	nop
#Title=	inside_prf
#Remark=
#Date=	03.07.2023 14:35
#Acquired=	03.07.2023 14:35:02
201.713	62
204.247	56
206.778	64
209.311	60
211.84	58
214.371	66
216.899	70
219.428	70
221.955	72
224.482	70
227.007	72
229.531	68
232.055	66
234.579	76
237.1	92
239.621	80
242.141	78
244.661	70
247.179	74
249.698	64
252.215	86
254.731	82
257.246	62
259.761	70
262.273	72
264.786	74
267.298	82
269.809	82
272.319	80
274.828	86
277.336	84
279.844	78
282.351	80
284.855	84
287.361	76
289.866	78
292.368	82
294.871	90
297.372	86
299.873	84
302.372	92
304.872	94
307.37	88
309.866	84
312.364	88
314.859	100
317.353	90
319.848	90
322.341	96
324.833	106
327.324	92
329.814	110
332.304	98
334.792	92
337.28	98
339.767	106
342.254	100
344.739	102
347.224	106
349.708	106
352.191	98
354.673	92
357.155	114
359.634	110
362.114	124
364.593	108
367.07	104
369.548	114
372.024	108
374.499	114
376.974	102
379.447	106
381.92	120
384.392	122
386.864	128
389.333	136
391.802	110
394.272	128
396.739	110
399.206	116
401.673	132
404.138	120
406.602	112
409.066	136
411.528	144
413.99	140
416.451	140
418.911	132
421.371	132
423.83	134
426.288	150
428.745	142
431.201	132
433.657	134
436.111	152
438.565	128
441.017	132
443.469	148
445.921	154
448.37	158
450.821	150
453.27	138
455.717	154
458.165	146
460.61	162
463.056	156
465.5	174
467.945	154
470.387	166
472.829	158
475.271	160
477.711	162
480.15	170
482.589	188
485.027	174
487.465	184
489.901	180
492.337	178
494.771	178
497.205	192
499.638	186
502.07	188
504.502	166
506.933	184
509.363	182
511.792	200
514.219	190
516.647	192
519.073	190
521.5	208
523.924	196
526.348	192
528.772	184
531.194	206
533.616	182
536.036	186
538.457	198
540.875	200
543.294	208
545.712	222
548.128	208
550.545	212
552.959	216
555.373	214
557.788	226
560.2	216
562.612	214
565.023	232
567.433	240
569.843	218
572.251	230
574.659	240
577.066	238
579.472	250
581.878	228
584.283	250
586.687	252
589.09	258
591.493	244
593.893	262
596.294	262
598.694	250
601.093	250
603.491	272
605.889	270
608.285	274
610.682	284
613.076	276
615.471	276
617.864	302
620.256	266
622.648	290
625.039	316
627.429	316
629.819	300
632.208	296
634.595	306
636.982	290
639.369	354
641.755	328
644.139	332
646.523	318
648.906	326
651.288	338
653.67	340
656.051	366
658.429	348
660.808	352
663.187	376
665.565	358
667.942	378
670.317	366
672.692	374
675.067	360
677.44	388
679.813	376
682.184	380
684.556	384
686.926	404
689.296	408
691.664	396
694.033	416
696.4	424
698.766	392
701.133	426
703.497	440
705.861	440
708.224	448
710.586	446
712.949	454
715.31	466
717.67	486
720.029	466
722.388	490
724.746	524
727.103	512
729.458	510
731.814	484
734.168	500
736.523	528
738.876	514
741.227	554
743.579	554
745.931	546
748.28	566
750.629	540
752.977	546
755.325	580
757.672	586
760.018	588
762.363	598
764.708	596
767.052	628
769.394	638
771.737	614
774.078	658
776.419	630
778.758	664
781.097	644
783.435	680
785.773	704
788.11	684
790.446	664
792.781	734
795.115	768
797.449	690
799.782	724
802.115	730
804.446	768
806.777	780
809.106	818
811.435	780
813.764	792
816.091	816
818.418	824
820.743	872
823.069	850
825.393	880
827.717	874
830.039	902
832.362	904
834.683	912
837.003	892
839.324	932
841.643	934
843.961	954
846.278	968
848.594	986
850.91	1032
853.227	992
855.541	1016
857.855	1058
860.168	1042
862.48	1056
864.79	1044
867.101	1090
869.411	1092
871.721	1130
874.029	1114
876.336	1112
878.643	1170
880.95	1136
883.254	1118
885.559	1154
887.862	1206
890.166	1220
892.467	1222
894.77	1210
897.07	1248
899.371	1268
901.669	1296
903.968	1260
906.266	1292
908.563	1342
910.859	1328
913.154	1324
915.449	1374
917.742	1366
920.036	1384
922.329	1426
924.621	1398
926.911	1442
929.201	1476
931.49	1504
933.779	1512
936.068	1484
938.355	1560
940.64	1554
942.926	1540
945.212	1574
947.495	1614
949.779	1636
952.062	1664
954.344	1656
956.625	1694
958.905	1682
961.184	1682
963.464	1750
965.742	1780
968.02	1788
970.296	1816
972.572	1822
974.847	1848
977.121	1878
979.396	1882
981.669	1892
983.941	1944
986.212	1954
988.483	1944
990.753	1984
993.022	2052
995.29	2070
997.558	2060
999.825	2062
1002.09	2124
1004.36	2096
1006.62	2216
1008.89	2170
1011.15	2192
1013.41	2194
1015.67	2198
1017.93	2294
1020.19	2304
1022.45	2342
1024.71	2336
1026.97	2356
1029.23	2380
1031.49	2386
1033.74	2476
1036	2494
1038.25	2516
1040.5	2490
1042.76	2620
1045.01	2576
1047.26	2572
1049.51	2656
1051.76	2654
1054.01	2752
1056.26	2650
1058.51	2710
1060.75	2754
1063	2828
1065.25	2914
1067.49	2862
1069.73	2900
1071.98	2888
1074.22	3002
1076.46	2998
1078.7	2968
1080.94	3036
1083.18	2960
1085.42	2960
1087.66	3052
1089.9	3006
1092.14	3060
1094.37	3072
1096.61	3098
1098.84	3188
1101.08	3116
1103.31	3184
1105.54	3180
1107.77	3218
1110	3216
1112.23	3202
1114.46	3264
1116.69	3326
1118.92	3334
1121.15	3356
1123.37	3306
1125.6	3276
1127.83	3330
1130.05	3320
1132.27	3412
1134.5	3376
1136.72	3498
1138.94	3430
1141.16	3452
1143.38	3568
1145.6	3536
1147.82	3476
1150.04	3508
1152.26	3512
1154.47	3598
1156.69	3530
1158.9	3588
1161.12	3566
1163.33	3598
1165.54	3634
1167.76	3646
1169.97	3642
1172.18	3646
1174.39	3584
1176.6	3654
1178.81	3600
1181.02	3602
1183.22	3604
1185.43	3570
1187.63	3538
1189.84	3610
1192.04	3528
1194.25	3502
1196.45	3532
1198.65	3512
1200.85	3470
1203.05	3558
1205.25	3460
1207.45	3434
1209.65	3420
1211.85	3438
1214.05	3438
1216.24	3346
1218.44	3340
1220.64	3370
1222.83	3368
1225.02	3352
1227.22	3346
1229.41	3344
1231.6	3254
1233.79	3236
1235.98	3322
1238.17	3278
1240.36	3164
1242.55	3156
1244.73	3190
1246.92	3144
1249.11	3124
1251.29	3104
1253.48	3128
1255.66	3112
1257.84	3082
1260.03	2988
1262.21	3134
1264.39	3034
1266.57	2992
1268.75	2954
1270.93	2988
1273.11	2870
1275.28	2956
1277.46	2840
1279.64	2826
1281.81	2780
1283.98	2771.48
1286.16	2833.62
1288.33	2748.86
1290.5	2800.84
1292.68	2823.46
1294.85	2727.78
1297.02	2746.04
1299.19	2728.19
1301.36	2772.82
1303.53	2698.52
1305.69	2682.63
1307.86	2750.99
1310.03	2658.2
1312.19	2655.3
1314.36	2636.36
1316.52	2628.67
1318.68	2622.64
1320.85	2590.26
1323.01	2596.09
1325.17	2601.7
1327.33	2579.77
1329.49	2539.27
1331.65	2540.4
1333.81	2504.78
1335.97	2490.23
1338.12	2468.46
1340.28	2487.86
1342.44	2466.13
1344.59	2441.31
1346.75	2434.71
1348.9	2389.75
1351.05	2401.02
1353.2	2398.35
1355.36	2360.73
1357.51	2362.04
1359.66	2356.81
1361.81	2369.95
1363.96	2315.29
1366.1	2368.99
1368.25	2299.84
1370.4	2346.99
1372.54	2300.34
1374.69	2313.24
1376.83	2283.93
1378.98	2248.27
1381.12	2251.36
1383.26	2275.37
1385.41	2205.8
1387.55	2193.17
1389.69	2173.85
1391.83	2230.7
1393.02	2148
1395.17	2110
1397.32	2188
1399.47	2062
1401.62	2116
1403.77	2104
1405.91	2028
1408.06	2026
1410.2	2040
1412.35	2050
1414.49	2012
1416.63	2022
1418.78	1952
1420.92	1926
1423.06	1896
1425.2	1926
1427.34	1890
1429.48	1896
1431.61	1850
1433.75	1910
1435.89	1876
1438.02	1878
1440.16	1894
1442.3	1848
1444.43	1860
1446.56	1796
1448.7	1852
1450.83	1756
1452.96	1782
1455.09	1778
1457.22	1734
1459.35	1750
1461.48	1820
1463.61	1732
1465.73	1760
1467.86	1682
1469.98	1698
1472.11	1706
1474.24	1678
1476.36	1656
1478.48	1650
1480.6	1582
1482.73	1614
1484.85	1644
1486.97	1606
1489.09	1602
1491.21	1620
1493.33	1588
1495.44	1572
1497.56	1594
1499.68	1580
1501.79	1532
1503.91	1574
1506.02	1602
1508.14	1482
1510.25	1544
1512.36	1510
1514.48	1512
1516.59	1520
1518.7	1454
1520.81	1478
1522.92	1484
1525.02	1476
1527.13	1430
1529.24	1410
1531.35	1422
1533.45	1426
1535.56	1446
1537.66	1408
1539.77	1416
1541.87	1428
1543.97	1378
1546.08	1418
1548.18	1404
1550.28	1328
1552.38	1390
1554.48	1338
1556.57	1332
1558.67	1304
1560.77	1324
1562.87	1310
1564.96	1320
1567.06	1352
1569.15	1306
1571.25	1284
1573.34	1306
1575.43	1290
1577.53	1308
1579.62	1282
1581.71	1300
1583.8	1348
1585.89	1256
1587.98	1252
1590.06	1286
1592.15	1276
1594.24	1250
1596.33	1234
1598.41	1228
1600.5	1246
1602.58	1248
1604.66	1268
1606.75	1240
1608.83	1210
1610.91	1252
1612.99	1194
1615.07	1192
1617.15	1214
1619.23	1230
1621.31	1212
1623.39	1224
1625.46	1168
1627.54	1184
1629.62	1194
1631.69	1224
1633.77	1176
1635.84	1186
1637.91	1170
1639.99	1132
1642.06	1206
1644.13	1176
1646.2	1110
1648.27	1206
1650.34	1140
1652.41	1178
1654.47	1102
1656.54	1174
1658.61	1140
1660.67	1182
1662.74	1136
1664.81	1124
1666.87	1118
1668.93	1134
1671	1128
1673.06	1130
1675.12	1152
1677.18	1148
1679.24	1134
1681.3	1080
1683.36	1142
1685.42	1106
1687.47	1118
1689.53	1052
1691.59	1092
1693.64	1072
1695.7	1070
1697.75	1094
1699.81	1108
1701.86	1080
1703.91	1042
1705.97	1074
1708.02	1072
1710.07	1086
1712.12	1068
1714.17	1056
1716.22	1022
1718.26	1042
1720.31	1062
1722.36	1054
1724.4	1040
1726.45	1074
1728.49	1092
1730.54	1066
1732.58	1056
1734.63	1050
1736.67	1048
1738.71	1038
1740.75	1032
1742.79	1058
1744.83	1056
1746.87	1016
1748.91	1032
1750.95	1036
1752.98	1020
1755.02	1042
1757.06	1022
1759.09	1036
1761.13	1020
1763.16	990
1765.19	1032
1767.23	1052
1769.26	1002
1771.29	1006
1773.32	1020
1775.35	1058
1777.38	1006
1779.41	1054
1781.44	1006
1783.47	1034
1785.49	1004
1787.52	1020
1789.55	1032
1791.57	996
1793.6	1016
1795.62	998
1797.64	1024
1799.67	1016
1801.69	1000
1803.71	986
1805.73	1000
1807.75	1002
1809.77	1036
1811.79	990
1813.81	966
1815.83	996
1817.84	1004
1819.86	976
1821.88	980
1823.89	980
1825.91	998
1827.92	968
1829.93	992
1831.95	978
1833.96	990
1835.97	1002
1837.98	968
1839.99	1002
1842	956
1844.01	976
1846.02	952
1848.03	990
1850.03	974
1852.04	972
1854.05	946
1856.05	940
1858.06	972
1860.06	960
1862.06	946
1864.07	922
1866.07	954
1868.07	966
1870.07	970
1872.07	926
1874.07	948
1876.07	996
1878.07	958
1880.07	964
1882.07	964
1884.06	932
1886.06	908
1888.05	966
1890.05	934
1892.04	982
1894.04	934
1896.03	946
1898.02	940
1900.01	948
1902	958
1903.99	978
1905.98	994
1907.97	938
1909.96	948
1911.95	942
1913.94	944
1915.93	946
1917.91	938
1919.9	954
1921.88	914
1923.87	928
1925.85	938
1927.83	950
1929.82	982
1931.8	908
1933.78	918
1935.76	940
1937.74	962
1939.72	932
1941.7	968
1943.68	934
1945.65	914
1947.63	972
1949.61	948
1951.58	962
1953.56	944
1955.53	966
1957.51	922
1959.48	888
1961.45	926
1963.43	904
1965.4	934
1967.37	956
1969.34	926
1971.31	922
1973.28	906
1975.25	934
1977.22	930
1979.18	886
1981.15	914
1983.12	912
1985.08	940
1987.05	916
1989.01	918
1990.97	938
1992.94	852
1994.9	928
1996.86	916
1998.82	924
2000.78	906
2002.74	890
2004.7	892
2006.66	900
2008.62	920
2010.58	918
2012.54	912
2014.49	914
2016.45	938
2018.4	892
2020.36	900
2022.31	872
2024.27	880
2026.22	884
2028.17	876
2030.12	892
2032.07	870
2034.03	882
2035.98	940
2037.93	890
2039.87	884
2041.82	876
2043.77	864
2045.72	878
2047.66	936
2049.61	892
2051.55	892
2053.5	932
2055.44	882
2057.39	880
2059.33	882
2061.27	882
2063.21	916
2065.15	906
2067.09	894
2069.03	870
2070.97	870
2072.91	890
2074.85	886
2076.79	852
2078.73	888
2080.66	846
2082.6	874
2084.53	868
2086.47	878
2088.4	852
2090.33	848
2092.27	876
2094.2	840
2096.13	862
2098.06	910
2099.99	872
2101.92	844
2103.85	836
2105.78	896
2107.71	878
2109.64	852
2111.56	860
2113.49	852
2115.41	884
2117.34	862
2119.26	846
2121.19	876
2123.11	858
2125.03	854
2126.96	824
2128.88	830
2130.8	870
2132.72	858
2134.64	852
2136.56	828
2138.48	848
2140.4	856
2142.31	856
2144.23	836
2146.15	862
2148.06	844
2149.98	870
2151.89	828
2153.81	828
2155.72	800
2157.63	842
2159.55	840
2161.46	826
2163.37	832
2165.28	864
2167.19	844
2169.1	826
2171.01	860
2172.91	818
2174.82	862
2176.73	818
2178.64	836
2180.54	832
2182.45	816
2184.35	810
2186.26	836
2188.16	820
2190.06	818
2191.96	802
2193.87	798
2195.77	824
2197.67	806
2199.57	798
2201.47	828
2203.37	792
2205.27	776
2207.16	810
2209.06	792
2210.96	810
2212.85	786
2214.75	796
2216.64	796
2218.54	826
2220.43	804
2222.33	812
2224.22	809.006
2226.11	797.731
2228	810.477
2229.89	774.657
2231.78	847.802
2233.67	809.134
2235.56	811.068
2237.45	838.098
2239.34	809.679
2241.23	808.825
2243.11	831.924
2245	803.026
2246.89	820.975
2248.77	805.191
2250.66	836.602
2252.54	796.921
2254.42	842.598
2256.31	813.328
2258.19	814.637
2260.07	818.206
2261.95	824.92
2263.83	821.51
2265.71	827.867
2267.59	821.694
2269.47	819.411
2271.35	837.084
2273.23	821.753
2275.1	822.487
2276.98	844.234
2278.86	822.062
2280.73	830.799
2282.61	818.766
2284.48	828.901
2286.36	810.6
2288.23	830.209
2290.1	828.554
2291.98	828.51
2293.85	835.031
2295.72	821.06
2297.59	841.736
2299.46	834.75
2301.33	835.942
2303.2	816.043
2305.06	821.926
2306.93	840.76
2308.8	815.268
2310.67	850.007
2312.53	839.505
2314.4	817.288
2316.26	823.353
2317.62	814
2319.5	810
2321.37	826
2323.24	828
2325.12	836
2326.99	830
2328.86	800
2330.73	786
2332.6	826
2334.47	814
2336.34	836
2338.2	802
2340.07	806
2341.94	816
2343.81	832
2345.67	792
2347.54	824
2349.4	788
2351.27	780
2353.13	810
2354.99	786
2356.86	774
2358.72	808
2360.58	780
2362.44	796
2364.3	794
2366.16	786
2368.02	772
2369.88	764
2371.74	784
2373.6	774
2375.45	768
2377.31	784
2379.17	792
2381.02	762
2382.88	796
2384.73	794
2386.58	804
2388.44	770
2390.29	726
2392.14	756
2393.99	792
2395.85	756
2397.7	734
2399.55	754
2401.4	718
2403.25	740
2405.09	754
2406.94	742
2408.79	722
2410.63	738
2412.48	784
2414.33	734
2416.17	722
2418.02	710
2419.86	726
2421.7	688
2423.55	726
2425.39	720
2427.23	724
2429.07	696
2430.91	716
2432.75	682
2434.59	712
2436.43	688
2438.27	696
2440.11	684
2441.95	682
2443.78	738
2445.62	670
2447.46	672
2449.29	706
2451.13	664
2452.96	682
2454.79	678
2456.63	728
2458.46	692
2460.29	660
2462.12	680
2463.95	692
2465.78	692
2467.61	684
2469.44	630
2471.27	658
2473.1	638
2474.93	662
2476.76	644
2478.58	642
2480.41	654
2482.23	670
2484.06	622
2485.88	676
2487.71	622
2489.53	622
2491.35	638
2493.18	634
2495	644
2496.82	628
2498.64	600
2500.46	632
2502.28	614
2504.1	622
2505.92	588
2507.74	596
2509.55	600
2511.37	596
2513.19	620
2515	600
2516.82	580
2518.63	602
2520.45	580
2522.26	592
2524.07	600
2525.89	562
2527.7	592
2529.51	572
2531.32	578
2533.13	570
2534.94	592
2536.75	572
2538.56	578
2540.37	592
2542.18	560
2543.98	576
2545.79	550
2547.6	556
2549.4	544
2551.21	562
2553.01	548
2554.82	548
2556.62	566
2558.42	552
2560.23	536
2562.03	540
2563.83	522
2565.63	534
2567.43	526
2569.23	540
2571.03	524
2572.83	516
2574.63	518
2576.43	512
2578.22	518
2580.02	514
2581.82	542
2583.61	516
2585.41	524
2587.2	536
2589	522
2590.79	518
2592.58	482
2594.38	490
2596.17	500
2597.96	488
2599.75	500
2601.54	524
2603.33	494
2605.12	510
2606.91	498
2608.7	512
2610.49	472
2612.27	488
2614.06	486
2615.85	492
2617.63	490
2619.42	486
2621.2	478
2622.99	452
2624.77	478
2626.55	458
2628.34	446
2630.12	462
2631.9	462
2633.68	446
2635.46	442
2637.24	448
2639.02	458
2640.8	456
2642.58	438
2644.36	448
2646.14	446
2647.91	422
2649.69	426
2651.46	438
2653.24	452
2655.01	1894
2656.79	424
2658.56	438
2660.34	430
2662.11	446
2663.88	418
2665.65	426
2667.42	426
2669.2	440
2670.96	428
2672.73	392
2674.5	418
2676.27	398
2678.04	404
2679.81	392
2681.58	410
2683.34	402
2685.11	390
2686.87	412
2688.64	406
2690.4	408
2692.17	398
2693.93	382
2695.69	376
2697.46	380
2699.22	394
2700.98	376
2702.74	382
2704.5	390
2706.26	370
2708.02	362
2709.78	384
2711.54	392
2713.3	378
2715.05	378
2716.81	370
2718.57	372
2720.32	358
2722.08	342
2723.83	366
2725.59	336
2727.34	364
2729.09	376
2730.85	366
2732.6	370
2734.35	368
2736.1	364
2737.85	320
2739.6	342
2741.35	350
2743.1	308
2744.85	346
2746.6	330
2748.35	340
2750.09	334
2751.84	336
2753.59	336
2755.33	326
2757.08	336
2758.82	334
2760.57	328
2762.31	322
2764.05	326
2765.79	318
2767.54	314
2769.28	320
2771.02	292
2772.76	306
2774.5	306
2776.24	320
2777.98	304
2779.72	298
2781.46	304
2783.19	294
2784.93	284
2786.67	302
2788.4	308
2790.14	300
2791.87	298
2793.61	288
2795.34	284
2797.07	308
2798.81	294
2800.54	296
2802.27	272
2804	288
2805.74	266
2807.47	282
2809.2	288
2810.93	268
2812.65	282
2814.38	274
2816.11	260
2817.84	274
2819.56	262
2821.29	250
2823.02	288
2824.74	272
2826.47	252
2828.19	244
2829.92	264
2831.64	248
2833.36	254
2835.09	258
2836.81	248
2838.53	258
2840.25	232
2841.97	232
2843.69	248
2845.41	254
2847.13	252
2848.85	250
2850.57	232
2852.28	238
2854	240
2855.72	240
2857.43	248
2859.15	230
2860.86	240
2862.58	234
2864.29	240
2866.01	244
2867.72	244
2869.43	240
2871.14	220
2872.86	226
2874.57	232
2876.28	230
2877.99	220
2879.7	210
2881.41	226
2883.11	222
2884.82	222
2886.53	206
2888.24	202
2889.94	214
2891.65	218
2893.36	216
2895.06	212
2896.77	216
2898.47	218
2900.17	220
2901.88	198
2903.58	218
2905.28	200
2906.98	204
2908.69	210
2910.39	214
2912.09	194
2913.79	196
2915.49	214
2917.19	210
2918.88	188
2920.58	188
2922.28	216
2923.98	204
2925.67	202
2927.37	212
2929.06	208
2930.76	198
2932.45	212
2934.15	194
2935.84	194
2937.53	188
2939.23	202
2940.92	184
2942.61	200
2944.3	170
2945.99	176
2947.68	182
2949.37	174
2951.06	184
2952.75	186
2954.44	180
2956.12	182
2957.81	178
2959.5	176
2961.18	176
2962.87	174
2964.56	184
2966.24	166
2967.92	186
2969.61	184
2971.29	186
2972.97	166
2974.66	158
2976.34	174
2978.02	180
2979.7	162
2981.38	166
2983.06	180
2984.74	170
2986.42	162
2988.1	154
2989.78	184
2991.45	180
2993.13	172
2994.81	164
2996.48	150
2998.16	166
2999.83	166