File: muestras/nopal/inside_prf_06.txt
#Acq. time (s)=	15
#Accumulations=	2
#Range (cm-¹)=	200...3000
#Windows=	3
#Autofocus=	Off
#AutoExposure=	Off
#Spike filter=	Multiple accum.
#Delay time (s)=	0
#Binning=	1
#Readout mode=	Signal
#DeNoise=	Off
#ICS correction=	Off
#Dark correction=	Off
#Inst. Process=	Off
#Instrument=	LabRAM HR Evol
#Detector=	Syncerity OE
#Objective=	x100_VIS
#Grating=	600 (500nm)
#ND Filter=	10%
#Laser=	633nm_Edge
#Hole=	9.98375
#Range=	Visible
#Project=	Omar
#Sample=	03-07-23
#Site=	nop
#Title=	inside_prf
#Remark=
#Date=	03.07.2023 14:23
#Acquired=	03.07.2023 14:23:55
201.713	52
204.247	60
206.778	62
209.311	54
211.84	62
214.371	58
216.899	58
219.428	64
221.955	56
224.482	60
227.007	64
229.531	66
232.055	52
234.579	64
237.1	58
239.621	70
242.141	60
244.661	58
247.179	62
249.698	62
252.215	66
254.731	56
257.246	60
259.761	70
262.273	62
264.786	64
267.298	56
269.809	62
272.319	60
274.828	64
277.336	68
279.844	70
282.351	70
284.855	66
287.361	60
289.866	66
292.368	72
294.871	64
297.372	68
299.873	64
302.372	70
304.872	60
307.37	68
309.866	68
312.364	68
314.859	72
317.353	62
319.848	72
322.341	60
324.833	76
327.324	74
329.814	74
332.304	70
334.792	64
337.28	62
339.767	70
342.254	64
344.739	70
347.224	72
349.708	72
352.191	68
354.673	66
357.155	66
359.634	60
362.114	72
364.593	74
367.07	80
369.548	66
372.024	68
374.499	72
376.974	66
379.447	68
381.92	62
384.392	78
386.864	64
389.333	70
391.802	72
394.272	74
396.739	78
399.206	78
401.673	76
404.138	78
406.602	70
409.066	80
411.528	76
413.99	72
416.451	76
418.911	72
421.371	74
423.83	76
426.288	80
428.745	90
431.201	78
433.657	82
436.111	72
438.565	80
441.017	80
443.469	76
445.921	76
448.37	84
450.821	82
453.27	80
455.717	88
458.165	86
460.61	84
463.056	88
465.5	86
467.945	80
470.387	94
472.829	90
475.271	84
477.711	84
480.15	74
482.589	80
485.027	84
487.465	88
489.901	84
492.337	84
494.771	82
497.205	80
499.638	92
502.07	82
504.502	78
506.933	88
509.363	86
511.792	98
514.219	92
516.647	90
519.073	88
521.5	84
523.924	92
526.348	90
528.772	90
531.194	88
533.616	90
536.036	90
538.457	90
540.875	90
543.294	86
545.712	94
548.128	90
550.545	92
552.959	92
555.373	96
557.788	94
560.2	78
562.612	90
565.023	88
567.433	98
569.843	96
572.251	96
574.659	84
577.066	98
579.472	96
581.878	100
584.283	98
586.687	96
589.09	102
591.493	96
593.893	96
596.294	98
598.694	106
601.093	98
603.491	98
605.889	96
608.285	112
610.682	104
613.076	102
615.471	96
617.864	106
620.256	106
622.648	112
625.039	108
627.429	110
629.819	118
632.208	116
634.595	106
636.982	106
639.369	102
641.755	98
644.139	104
646.523	112
648.906	106
651.288	106
653.67	112
656.051	116
658.429	116
660.808	110
663.187	122
665.565	102
667.942	108
670.317	106
672.692	114
675.067	114
677.44	108
679.813	126
682.184	120
684.556	108
686.926	120
689.296	120
691.664	114
694.033	126
696.4	114
698.766	118
701.133	112
703.497	102
705.861	126
708.224	112
710.586	110
712.949	126
715.31	124
717.67	118
720.029	134
722.388	128
724.746	128
727.103	130
729.458	126
731.814	132
734.168	138
736.523	136
738.876	140
741.227	130
743.579	126
745.931	128
748.28	132
750.629	130
752.977	132
755.325	132
757.672	144
760.018	126
762.363	140
764.708	142
767.052	136
769.394	146
771.737	142
774.078	138
776.419	150
778.758	158
781.097	142
783.435	142
785.773	154
788.11	134
790.446	150
792.781	148
795.115	144
797.449	150
799.782	154
802.115	160
804.446	150
806.777	154
809.106	152
811.435	166
813.764	168
816.091	158
818.418	162
820.743	166
823.069	158
825.393	164
827.717	170
830.039	164
832.362	172
834.683	168
837.003	168
839.324	174
841.643	180
843.961	176
846.278	172
848.594	180
850.91	172
853.227	176
855.541	184
857.855	184
860.168	178
862.48	186
864.79	182
867.101	186
869.411	204
871.721	186
874.029	188
876.336	188
878.643	202
880.95	182
883.254	204
885.559	196
887.862	194
890.166	204
892.467	208
894.77	200
897.07	192
899.371	206
901.669	218
903.968	212
906.266	224
908.563	198
910.859	224
913.154	210
915.449	232
917.742	198
920.036	228
922.329	230
924.621	240
926.911	212
929.201	240
931.49	236
933.779	216
936.068	214
938.355	234
940.64	232
942.926	238
945.212	240
947.495	246
949.779	242
952.062	222
954.344	250
956.625	238
958.905	254
961.184	238
963.464	256
965.742	256
968.02	250
970.296	250
972.572	264
974.847	256
977.121	286
979.396	282
981.669	274
983.941	268
986.212	284
988.483	262
990.753	280
993.022	290
995.29	290
997.558	266
999.825	284
1002.09	290
1004.36	274
1006.62	280
1008.89	292
1011.15	290
1013.41	280
1015.67	290
1017.93	274
1020.19	282
1022.45	298
1024.71	292
1026.97	300
1029.23	288
1031.49	306
1033.74	310
1036	320
1038.25	308
1040.5	344
1042.76	326
1045.01	334
1047.26	338
1049.51	340
1051.76	328
1054.01	340
1056.26	326
1058.51	350
1060.75	336
1063	334
1065.25	346
1067.49	348
1069.73	324
1071.98	360
1074.22	364
1076.46	362
1078.7	358
1080.94	346
1083.18	370
1085.42	350
1087.66	346
1089.9	368
1092.14	348
1094.37	380
1096.61	358
1098.84	358
1101.08	378
1103.31	366
1105.54	378
1107.77	374
1110	382
1112.23	372
1114.46	382
1116.69	394
1118.92	384
1121.15	396
1123.37	384
1125.6	382
1127.83	386
1130.05	400
1132.27	426
1134.5	394
1136.72	398
1138.94	368
1141.16	394
1143.38	412
1145.6	408
1147.82	390
1150.04	376
1152.26	436
1154.47	432
1156.69	410
1158.9	420
1161.12	428
1163.33	416
1165.54	416
1167.76	420
1169.97	428
1172.18	420
1174.39	438
1176.6	412
1178.81	424
1181.02	410
1183.22	422
1185.43	428
1187.63	400
1189.84	410
1192.04	408
1194.25	398
1196.45	424
1198.65	426
1200.85	444
1203.05	434
1205.25	416
1207.45	420
1209.65	446
1211.85	426
1214.05	440
1216.24	430
1218.44	430
1220.64	442
1222.83	430
1225.02	414
1227.22	410
1229.41	410
1231.6	408
1233.79	396
1235.98	416
1238.17	428
1240.36	406
1242.55	406
1244.73	420
1246.92	386
1249.11	422
1251.29	420
1253.48	414
1255.66	402
1257.84	390
1260.03	412
1262.21	394
1264.39	406
1266.57	380
1268.75	404
1270.93	406
1273.11	406
1275.28	390
1277.46	406
1279.64	388
1281.81	392
1283.98	388.952
1286.16	376.552
1288.33	405.031
1290.5	412.456
1292.68	392.73
1294.85	405.63
1297.02	429.136
1299.19	404.813
1301.36	399.925
1303.53	408.515
1305.69	420.54
1307.86	420.42
1310.03	418.748
1312.19	422.974
1314.36	419.441
1316.52	434.972
1318.68	433.353
1320.85	437.556
1323.01	437.702
1325.17	429.836
1327.33	454.456
1329.49	436
1331.65	437.375
1333.81	451.248
1335.97	451.882
1338.12	453.064
1340.28	440.786
1342.44	444.055
1344.59	457.391
1346.75	460.9
1348.9	449.106
1351.05	450.061
1353.2	455.592
1355.36	448.373
1357.51	468.983
1359.66	464.793
1361.81	466.569
1363.96	474.654
1366.1	456.138
1368.25	461.214
1370.4	458.546
1372.54	459.308
1374.69	477.137
1376.83	475.494
1378.98	491.21
1381.12	488.778
1383.26	505.734
1385.41	477.324
1387.55	487.071
1389.69	495.469
1391.83	479.745
1393.02	482
1395.17	468
1397.32	462
1399.47	474
1401.62	476
1403.77	492
1405.91	494
1408.06	448
1410.2	464
1412.35	444
1414.49	464
1416.63	466
1418.78	472
1420.92	458
1423.06	474
1425.2	488
1427.34	460
1429.48	456
1431.61	432
1433.75	464
1435.89	446
1438.02	444
1440.16	470
1442.3	448
1444.43	460
1446.56	452
1448.7	442
1450.83	468
1452.96	442
1455.09	440
1457.22	462
1459.35	442
1461.48	430
1463.61	446
1465.73	418
1467.86	450
1469.98	464
1472.11	424
1474.24	448
1476.36	442
1478.48	450
1480.6	458
1482.73	442
1484.85	414
1486.97	434
1489.09	424
1491.21	422
1493.33	436
1495.44	428
1497.56	418
1499.68	426
1501.79	418
1503.91	426
1506.02	426
1508.14	414
1510.25	428
1512.36	418
1514.48	394
1516.59	426
1518.7	414
1520.81	420
1522.92	424
1525.02	392
1527.13	426
1529.24	424
1531.35	416
1533.45	428
1535.56	416
1537.66	428
1539.77	426
1541.87	388
1543.97	418
1546.08	428
1548.18	404
1550.28	390
1552.38	400
1554.48	394
1556.57	412
1558.67	404
1560.77	408
1562.87	388
1564.96	400
1567.06	412
1569.15	396
1571.25	416
1573.34	404
1575.43	392
1577.53	410
1579.62	412
1581.71	386
1583.8	390
1585.89	370
1587.98	388
1590.06	364
1592.15	362
1594.24	388
1596.33	374
1598.41	382
1600.5	400
1602.58	388
1604.66	396
1606.75	374
1608.83	396
1610.91	382
1612.99	384
1615.07	394
1617.15	386
1619.23	394
1621.31	378
1623.39	384
1625.46	364
1627.54	366
1629.62	368
1631.69	374
1633.77	370
1635.84	394
1637.91	404
1639.99	382
1642.06	380
1644.13	396
1646.2	362
1648.27	366
1650.34	396
1652.41	352
1654.47	380
1656.54	374
1658.61	384
1660.67	386
1662.74	376
1664.81	374
1666.87	378
1668.93	374
1671	376
1673.06	370
1675.12	360
1677.18	380
1679.24	372
1681.3	364
1683.36	378
1685.42	364
1687.47	358
1689.53	352
1691.59	356
1693.64	368
1695.7	358
1697.75	366
1699.81	364
1701.86	352
1703.91	364
1705.97	344
1708.02	352
1710.07	354
1712.12	352
1714.17	356
1716.22	364
1718.26	366
1720.31	368
1722.36	348
1724.4	352
1726.45	358
1728.49	362
1730.54	362
1732.58	368
1734.63	332
1736.67	352
1738.71	348
1740.75	358
1742.79	370
1744.83	326
1746.87	360
1748.91	360
1750.95	330
1752.98	340
1755.02	336
1757.06	342
1759.09	362
1761.13	364
1763.16	374
1765.19	358
1767.23	334
1769.26	356
1771.29	360
1773.32	356
1775.35	332
1777.38	370
1779.41	348
1781.44	346
1783.47	356
1785.49	358
1787.52	338
1789.55	348
1791.57	332
1793.6	352
1795.62	358
1797.64	336
1799.67	344
1801.69	348
1803.71	340
1805.73	324
1807.75	340
1809.77	374
1811.79	354
1813.81	334
1815.83	350
1817.84	350
1819.86	364
1821.88	356
1823.89	348
1825.91	340
1827.92	372
1829.93	344
1831.95	348
1833.96	348
1835.97	350
1837.98	344
1839.99	340
1842	350
1844.01	344
1846.02	334
1848.03	328
1850.03	334
1852.04	332
1854.05	360
1856.05	356
1858.06	346
1860.06	322
1862.06	324
1864.07	356
1866.07	326
1868.07	316
1870.07	348
1872.07	328
1874.07	338
1876.07	326
1878.07	326
1880.07	336
1882.07	320
1884.06	340
1886.06	328
1888.05	370
1890.05	336
1892.04	346
1894.04	326
1896.03	338
1898.02	352
1900.01	354
1902	326
1903.99	350
1905.98	344
1907.97	334
1909.96	360
1911.95	314
1913.94	328
1915.93	324
1917.91	326
1919.9	332
1921.88	348
1923.87	338
1925.85	336
1927.83	334
1929.82	338
1931.8	340
1933.78	340
1935.76	336
1937.74	348
1939.72	336
1941.7	342
1943.68	342
1945.65	326
1947.63	334
1949.61	322
1951.58	324
1953.56	338
1955.53	344
1957.51	324
1959.48	352
1961.45	338
1963.43	328
1965.4	324
1967.37	348
1969.34	330
1971.31	316
1973.28	324
1975.25	326
1977.22	328
1979.18	328
1981.15	340
1983.12	342
1985.08	336
1987.05	326
1989.01	328
1990.97	322
1992.94	320
1994.9	348
1996.86	302
1998.82	338
2000.78	312
2002.74	332
2004.7	298
2006.66	330
2008.62	336
2010.58	322
2012.54	348
2014.49	316
2016.45	328
2018.4	338
2020.36	322
2022.31	342
2024.27	310
2026.22	328
2028.17	324
2030.12	320
2032.07	338
2034.03	334
2035.98	308
2037.93	322
2039.87	332
2041.82	336
2043.77	338
2045.72	320
2047.66	314
2049.61	332
2051.55	330
2053.5	316
2055.44	330
2057.39	328
2059.33	342
2061.27	346
2063.21	340
2065.15	332
2067.09	352
2069.03	340
2070.97	346
2072.91	312
2074.85	340
2076.79	332
2078.73	328
2080.66	332
2082.6	316
2084.53	344
2086.47	334
2088.4	338
2090.33	320
2092.27	324
2094.2	322
2096.13	320
2098.06	332
2099.99	318
2101.92	318
2103.85	338
2105.78	344
2107.71	312
2109.64	306
2111.56	318
2113.49	340
2115.41	318
2117.34	302
2119.26	304
2121.19	338
2123.11	300
2125.03	332
2126.96	338
2128.88	332
2130.8	332
2132.72	302
2134.64	304
2136.56	302
2138.48	320
2140.4	318
2142.31	324
2144.23	318
2146.15	318
2148.06	318
2149.98	296
2151.89	340
2153.81	304
2155.72	322
2157.63	316
2159.55	312
2161.46	316
2163.37	334
2165.28	330
2167.19	308
2169.1	328
2171.01	314
2172.91	302
2174.82	312
2176.73	312
2178.64	334
2180.54	306
2182.45	308
2184.35	318
2186.26	304
2188.16	346
2190.06	292
2191.96	296
2193.87	316
2195.77	296
2197.67	300
2199.57	304
2201.47	320
2203.37	300
2205.27	316
2207.16	314
2209.06	282
2210.96	312
2212.85	302
2214.75	300
2216.64	304
2218.54	300
2220.43	314
2222.33	306
2224.22	305.142
2226.11	306.873
2228	300.198
2229.89	327.213
2231.78	307.985
2233.67	309.2
2235.56	314.796
2237.45	297.681
2239.34	311.07
2241.23	329.136
2243.11	327.997
2245	323.162
2246.89	329.415
2248.77	334.562
2250.66	303.337
2252.54	334.788
2254.42	331.251
2256.31	318.615
2258.19	335.8
2260.07	337.269
2261.95	343.866
2263.83	333.85
2265.71	333.123
2267.59	343.494
2269.47	350.996
2271.35	336.628
2273.23	344.703
2275.1	345.522
2276.98	351.118
2278.86	335.251
2280.73	359.019
2282.61	356.612
2284.48	347.384
2286.36	346.6
2288.23	349.017
2290.1	349.347
2291.98	343.92
2293.85	360.394
2295.72	356.736
2297.59	351.66
2299.46	359.666
2301.33	360.291
2303.2	367.892
2305.06	363.725
2306.93	369.686
2308.8	357.391
2310.67	372.31
2312.53	373.01
2314.4	373.421
2316.26	338.358
2317.62	354
2319.5	368
2321.37	356
2323.24	354
2325.12	368
2326.99	384
2328.86	368
2330.73	370
2332.6	370
2334.47	370
2336.34	356
2338.2	352
2340.07	350
2341.94	364
2343.81	352
2345.67	354
2347.54	354
2349.4	342
2351.27	372
2353.13	368
2354.99	348
2356.86	358
2358.72	354
2360.58	368
2362.44	368
2364.3	354
2366.16	354
2368.02	340
2369.88	380
2371.74	368
2373.6	352
2375.45	358
2377.31	344
2379.17	346
2381.02	366
2382.88	350
2384.73	362
2386.58	348
2388.44	340
2390.29	342
2392.14	358
2393.99	334
2395.85	332
2397.7	332
2399.55	352
2401.4	338
2403.25	318
2405.09	346
2406.94	342
2408.79	342
2410.63	326
2412.48	340
2414.33	312
2416.17	348
2418.02	328
2419.86	330
2421.7	344
2423.55	316
2425.39	354
2427.23	324
2429.07	328
2430.91	322
2432.75	318
2434.59	322
2436.43	328
2438.27	336
2440.11	332
2441.95	330
2443.78	326
2445.62	328
2447.46	324
2449.29	328
2451.13	306
2452.96	320
2454.79	292
2456.63	312
2458.46	306
2460.29	320
2462.12	294
2463.95	316
2465.78	320
2467.61	310
2469.44	298
2471.27	316
2473.1	322
2474.93	326
2476.76	312
2478.58	322
2480.41	296
2482.23	308
2484.06	304
2485.88	312
2487.71	284
2489.53	314
2491.35	306
2493.18	288
2495	316
2496.82	304
2498.64	298
2500.46	284
2502.28	288
2504.1	264
2505.92	280
2507.74	296
2509.55	306
2511.37	300
2513.19	290
2515	294
2516.82	284
2518.63	266
2520.45	288
2522.26	298
2524.07	292
2525.89	278
2527.7	284
2529.51	272
2531.32	290
2533.13	280
2534.94	264
2536.75	258
2538.56	278
2540.37	272
2542.18	272
2543.98	292
2545.79	284
2547.6	270
2549.4	280
2551.21	258
2553.01	284
2554.82	282
2556.62	268
2558.42	256
2560.23	266
2562.03	276
2563.83	270
2565.63	238
2567.43	272
2569.23	258
2571.03	276
2572.83	264
2574.63	284
2576.43	264
2578.22	262
2580.02	260
2581.82	260
2583.61	256
2585.41	268
2587.2	248
2589	244
2590.79	258
2592.58	270
2594.38	250
2596.17	244
2597.96	262
2599.75	242
2601.54	246
2603.33	260
2605.12	264
2606.91	252
2608.7	236
2610.49	254
2612.27	242
2614.06	250
2615.85	238
2617.63	246
2619.42	240
2621.2	250
2622.99	244
2624.77	254
2626.55	252
2628.34	252
2630.12	260
2631.9	250
2633.68	222
2635.46	238
2637.24	230
2639.02	242
2640.8	246
2642.58	226
2644.36	242
2646.14	226
2647.91	232
2649.69	234
2651.46	230
2653.24	240
2655.01	216
2656.79	238
2658.56	206
2660.34	228
2662.11	222
2663.88	236
2665.65	230
2667.42	220
2669.2	208
2670.96	224
2672.73	232
2674.5	226
2676.27	222
2678.04	226
2679.81	222
2681.58	224
2683.34	206
2685.11	218
2686.87	218
2688.64	210
2690.4	198
2692.17	196
2693.93	210
2695.69	212
2697.46	220
2699.22	230
2700.98	218
2702.74	216
2704.5	196
2706.26	200
2708.02	214
2709.78	200
2711.54	206
2713.3	218
2715.05	214
2716.81	216
2718.57	196
2720.32	206
2722.08	202
2723.83	210
2725.59	196
2727.34	210
2729.09	202
2730.85	218
2732.6	200
2734.35	214
2736.1	194
2737.85	208
2739.6	190
2741.35	198
2743.1	192
2744.85	184
2746.6	196
2748.35	186
2750.09	178
2751.84	188
2753.59	198
2755.33	188
2757.08	186
2758.82	182
2760.57	194
2762.31	178
2764.05	188
2765.79	194
2767.54	188
2769.28	184
2771.02	202
2772.76	170
2774.5	180
2776.24	176
2777.98	190
2779.72	182
2781.46	192
2783.19	190
2784.93	180
2786.67	180
2788.4	188
2790.14	198
2791.87	180
2793.61	176
2795.34	170
2797.07	192
2798.81	178
2800.54	170
2802.27	174
2804	174
2805.74	176
2807.47	176
2809.2	168
2810.93	186
2812.65	168
2814.38	174
2816.11	172
2817.84	178
2819.56	174
2821.29	168
2823.02	160
2824.74	178
2826.47	164
2828.19	174
2829.92	168
2831.64	160
2833.36	178
2835.09	148
2836.81	172
2838.53	166
2840.25	164
2841.97	158
2843.69	166
2845.41	152
2847.13	166
2848.85	154
2850.57	156
2852.28	150
2854	162
2855.72	152
2857.43	150
2859.15	148
2860.86	170
2862.58	158
2864.29	150
2866.01	164
2867.72	158
2869.43	154
2871.14	150
2872.86	164
2874.57	138
2876.28	144
2877.99	158
2879.7	164
2881.41	156
2883.11	154
2884.82	146
2886.53	150
2888.24	146
2889.94	150
2891.65	156
2893.36	138
2895.06	142
2896.77	152
2898.47	158
2900.17	138
2901.88	130
2903.58	150
2905.28	142
2906.98	142
2908.69	152
2910.39	144
2912.09	146
2913.79	152
2915.49	140
2917.19	138
2918.88	136
2920.58	134
2922.28	136
2923.98	136
2925.67	136
2927.37	136
2929.06	146
2930.76	140
2932.45	136
2934.15	130
2935.84	126
2937.53	140
2939.23	140
2940.92	140
2942.61	148
2944.3	130
2945.99	134
2947.68	140
2949.37	134
2951.06	126
2952.75	144
2954.44	128
2956.12	136
2957.81	136
2959.5	142
2961.18	140
2962.87	134
2964.56	128
2966.24	124
2967.92	118
2969.61	140
2971.29	132
2972.97	130
2974.66	124
2976.34	124
2978.02	134
2979.7	128
2981.38	142
2983.06	136
2984.74	114
2986.42	134
2988.1	128
2989.78	128
2991.45	126
2993.13	120
2994.81	122
2996.48	130
2998.16	114
2999.83	120