File: muestras/cafe_/Organic_11.txt
#Acq. time (s)=	10
#Accumulations=	1
#Range (cm-¹)=	100...2000
#Windows=	2
#Autofocus=	Off
#AutoExposure=	Off
#Spike filter=	Off
#Delay time (s)=	0
#Binning=	1
#Readout mode=	Signal
#DeNoise=	Off
#ICS correction=	Off
#Dark correction=	Off
#Inst. Process=	Off
#Instrument=	LabRAM HR Evol
#Detector=	Syncerity OE
#Objective=	x100_VIS
#Grating=	600 (500nm)
#ND Filter=	5%
#Laser=	633nm_Edge
#Hole=	24.99
#Range=	Visible
#Project=	Omar
#Sample=	20-06-23
#Site=	1
#Title=	Organic
#Remark=
#Date=	20.06.2023 11:38
#Acquired=	20.06.2023 11:38:25
101.054	7674
103.621	7800
106.187	7722
108.752	7798
111.317	7798
113.881	7822
116.443	7904
119.005	7984
121.566	7972
124.126	7930
126.685	7954
129.243	7988
131.801	7934
134.356	7974
136.911	8036
139.466	7948
142.021	8134
144.574	8084
147.125	8040
149.676	8160
152.227	8200
154.776	8198
157.325	8314
159.873	8130
162.419	8336
164.966	8320
167.51	8258
170.055	8300
172.598	8300
175.141	8344
177.682	8238
180.222	8278
182.763	8410
185.302	8322
187.839	8382
190.376	8432
192.914	8490
195.449	8508
197.983	8632
200.517	8630
203.05	8738
205.582	8658
208.113	8578
210.643	8670
213.173	8810
215.701	8720
218.229	8778
220.756	8758
223.282	8806
225.808	8992
228.331	8824
230.855	8900
233.378	8944
235.898	9032
238.419	9048
240.94	9144
243.458	9180
245.977	9066
248.495	9194
251.011	9232
253.527	9194
256.041	9132
258.555	9166
261.068	9058
263.58	9398
266.092	9106
268.603	9100
271.112	9192
273.62	9184
276.129	9250
278.636	9146
281.142	9150
283.647	9278
286.152	9224
288.655	9288
291.158	9358
293.66	9394
296.161	9452
298.661	9548
301.161	9548
303.66	9596
306.158	9652
308.655	9572
311.15	9784
313.645	9670
316.14	9644
318.634	9740
321.125	9658
323.618	9788
326.109	9582
328.598	9702
331.088	9734
333.576	9684
336.064	9860
338.55	9888
341.037	9794
343.521	9862
346.005	9866
348.489	9940
350.971	10024
353.453	10090
355.933	10010
358.414	10112
360.893	10080
363.371	10010
365.848	9988
368.325	10014
370.801	10064
373.275	10016
375.75	9990
378.223	10036
380.695	10110
383.167	10032
385.638	9978
388.108	10060
390.577	9990
393.044	10094
395.512	9984
397.979	10036
400.444	10206
402.909	10242
405.374	10234
407.836	10246
410.299	10294
412.76	10302
415.221	10382
417.681	10434
420.141	10520
422.598	10642
425.057	10568
427.513	10748
429.968	10504
432.422	10598
434.878	10588
437.33	10808
439.783	10770
442.234	10756
444.685	10624
447.134	10608
449.583	10658
452.032	10708
454.479	10778
456.926	10596
459.372	10596
461.817	10670
464.261	10648
466.705	10802
469.147	10750
471.588	10650
474.029	10892
476.47	10814
478.909	10848
481.347	10850
483.785	10806
486.221	10782
488.657	10938
491.092	10884
493.527	11012
495.96	11042
498.393	10932
500.824	10934
503.255	11076
505.686	11064
508.115	10984
510.543	10920
512.972	11100
515.399	11044
517.825	10980
520.25	10984
522.674	10886
525.097	11032
527.52	11092
529.942	10926
532.364	10966
534.784	11040
537.204	10814
539.623	11032
542.041	10886
544.457	10976
546.874	10890
549.289	11108
551.705	10944
554.118	11012
556.531	10860
558.943	11126
561.355	11054
563.766	11032
566.175	11008
568.585	10986
570.992	11096
573.399	11184
575.807	11104
578.212	11106
580.617	11066
583.022	11078
585.425	11060
587.827	11222
590.229	11192
592.63	11096
595.03	11184
597.43	11154
599.829	11190
602.226	11170
604.623	11228
607.02	11374
609.414	11320
611.808	11360
614.202	11338
616.596	11344
618.988	11444
621.378	11420
623.769	11458
626.159	11328
628.548	11460
630.936	11536
633.324	11554
635.71	11574
638.096	11526
640.481	11692
642.866	11576
645.248	11518
647.63	11662
650.013	11648
652.394	11662
654.773	11638
657.154	11594
659.532	11634
661.91	11668
664.286	11568
666.663	11700
669.038	11528
671.412	11614
673.786	11570
676.159	11560
678.532	11540
680.903	11640
683.274	11634
685.644	11696
688.014	11566
690.381	11542
692.749	11598
695.116	11492
697.481	11718
699.846	11558
702.211	11606
704.574	11668
706.938	11794
709.299	11708
711.661	11764
714.021	11684
716.381	11808
718.739	11702
721.097	11746
723.455	11840
725.811	11692
728.167	11774
730.521	11898
732.875	11782
735.23	11786
737.582	11752
739.934	11824
742.285	11630
744.635	11882
746.985	11756
749.332	11668
751.68	11612
754.028	11716
756.374	11718
758.72	11658
761.065	11714
763.408	11690
765.752	11654
768.095	11784
770.436	11630
772.777	11672
775.116	11608
777.456	11672
779.794	11684
782.133	11686
784.469	11654
786.805	11738
789.141	11598
791.476	11700
793.809	11802
796.142	11712
798.476	11750
800.807	11728
803.138	11858
805.468	11644
807.797	11702
810.125	11736
812.453	11774
814.78	11966
817.106	11932
819.432	11846
821.757	11956
824.08	11990
826.403	11864
828.726	11860
831.048	11928
833.368	11878
835.688	11888
838.007	11990
840.326	11878
842.644	11968
844.96	11942
847.276	11944
849.592	11918
851.906	12008
854.221	12112
856.534	12092
858.846	12054
861.157	12072
863.469	12222
865.779	12026
868.088	11976
870.396	11916
872.704	12076
875.011	12142
877.318	11996
879.623	12132
881.928	11922
884.232	12086
886.536	11868
888.837	11924
891.139	11960
893.44	11794
895.741	11956
898.039	11892
900.339	11966
902.637	11880
904.933	11714
907.231	11810
909.526	11854
911.821	11858
914.115	11874
916.408	11754
918.701	11878
920.993	11828
923.283	11712
925.573	11832
927.864	11736
930.153	11798
932.441	11774
934.728	11838
937.014	11832
939.3	11952
941.585	11816
943.87	11838
946.154	11792
948.437	11918
950.719	11968
952.999	11864
955.28	11960
957.56	11820
959.84	11900
962.117	11938
964.395	12158
966.671	11968
968.948	11848
971.223	11908
973.498	12032
975.771	11946
978.045	11974
980.317	12000
982.588	12042
984.86	11778
987.13	11826
989.399	11728
991.667	11920
993.937	11976
996.204	12068
998.47	11928
1000.74	11738
1003	11990
1005.26	11898
1007.53	11818
1009.79	11904
1012.05	12024
1014.31	11876
1016.57	11832
1018.83	11942
1021.09	11942
1023.35	11956
1025.61	11900
1027.87	11954
1030.12	11878
1032.38	11860
1034.63	12008
1036.88	11936
1039.14	12058
1041.39	12030
1043.64	12044
1045.89	12098
1048.14	12136
1050.39	12050
1052.64	12130
1054.89	12040
1057.14	12176
1059.38	12044
1061.63	12142
1063.87	11982
1066.12	11968
1068.36	12160
1070.6	12126
1072.85	12024
1075.09	11978
1077.33	11968
1079.57	12108
1081.81	12004
1084.05	11816
1086.28	12008
1088.52	11904
1090.76	12024
1092.99	11860
1095.23	11994
1097.46	11860
1099.69	11814
1101.93	11864
1104.16	11906
1106.39	11750
1108.62	11808
1110.85	11886
1113.08	11680
1115.31	11760
1117.53	11718
1119.76	11810
1121.99	11830
1124.21	11742
1126.44	11784
1128.66	11816
1130.88	11908
1133.11	11856
1135.33	11808
1137.55	11892
1139.77	11922
1141.99	11832
1144.21	11752
1146.43	12020
1148.64	11832
1150.86	11846
1153.08	11834
1155.29	11852
1157.51	11832
1159.72	11876
1161.93	11842
1164.14	12026
1166.36	11810
1168.57	11950
1170.78	11806
1172.99	11886
1175.2	11812
1177.4	11882
1179.61	11958
1181.82	11924
1184.02	11972
1186.23	11960
1188.43	11766
1190.64	11744
1192.84	11842
1195.04	11884
1197.24	11766
1199.45	11833.1
1201.64	11712.2
1203.84	11720
1206.04	11731.8
1208.24	11837.8
1210.44	11723.1
1212.64	11661.6
1214.83	11702.8
1217.03	11763.2
1219.22	11732.7
1221.41	11688.6
1223.61	11701.9
1225.8	11729.4
1227.99	11747.9
1230.18	11632.4
1232.37	11730.8
1234.56	11615.6
1236.75	11773.4
1238.94	11782.2
1241.13	11802.7
1243.31	11771.3
1245.5	11860.5
1247.68	11836.9
1249.87	11865.3
1252.05	11922.6
1254.24	11902.6
1256.42	11882.6
1258.6	11898.5
1260.78	11929.1
1262.96	11992.3
1265.14	11899
1267.32	12012.8
1269.5	12045.3
1271.67	12072.1
1273.85	11995.4
1276.03	12100.3
1278.2	12120.6
1280.38	12086.4
1282.55	12038.1
1284.72	12138.8
1286.9	11989.4
1289.07	12105.1
1291.24	12167.6
1293.41	12259.8
1295.58	12157.2
1297.75	12118
1299.92	12173.1
1302.09	12201.3
1304.25	12154
1306.42	12217.1
1308.46	12204
1310.63	12106
1312.81	12328
1314.98	12186
1317.16	12172
1319.33	12128
1321.5	12102
1323.67	12044
1325.85	12010
1328.02	12072
1330.19	12152
1332.35	12234
1334.52	12068
1336.69	12042
1338.86	11972
1341.02	12282
1343.19	12080
1345.35	12000
1347.52	11872
1349.68	12042
1351.84	12020
1354	12082
1356.17	11894
1358.33	11902
1360.49	12002
1362.65	11970
1364.8	11934
1366.96	11832
1369.12	11980
1371.28	11874
1373.43	11846
1375.59	11946
1377.74	11868
1379.89	11858
1382.05	11938
1384.2	11854
1386.35	11812
1388.5	11830
1390.65	11928
1392.8	11842
1394.95	11836
1397.1	11798
1399.25	11890
1401.4	11840
1403.54	11848
1405.69	11796
1407.83	11744
1409.98	11684
1412.12	11784
1414.26	11658
1416.4	11714
1418.55	11738
1420.69	11818
1422.83	11656
1424.97	11608
1427.1	11698
1429.24	11676
1431.38	11746
1433.52	11516
1435.65	11622
1437.79	11674
1439.92	11628
1442.06	11530
1444.19	11488
1446.32	11722
1448.46	11716
1450.59	11556
1452.72	11584
1454.85	11544
1456.98	11548
1459.11	11576
1461.23	11710
1463.36	11534
1465.49	11620
1467.61	11462
1469.74	11636
1471.86	11498
1473.99	11508
1476.11	11562
1478.23	11588
1480.36	11492
1482.48	11700
1484.6	11424
1486.72	11500
1488.84	11548
1490.96	11626
1493.07	11518
1495.19	11432
1497.31	11470
1499.42	11516
1501.54	11572
1503.65	11380
1505.77	11500
1507.88	11500
1509.99	11386
1512.1	11256
1514.22	11444
1516.33	11392
1518.44	11384
1520.55	11386
1522.65	11248
1524.76	11220
1526.87	11216
1528.98	11012
1531.08	11176
1533.19	11070
1535.29	11190
1537.4	11096
1539.5	10968
1541.6	11062
1543.7	11210
1545.8	11028
1547.91	11062
1550.01	11086
1552.11	11090
1554.2	11018
1556.3	11074
1558.4	10884
1560.5	10914
1562.59	10970
1564.69	10926
1566.78	10786
1568.88	10826
1570.97	10818
1573.06	10776
1575.15	10836
1577.25	10926
1579.34	10902
1581.43	10912
1583.52	10926
1585.6	10972
1587.69	10744
1589.78	10778
1591.87	10790
1593.95	10804
1596.04	10718
1598.12	10664
1600.21	10780
1602.29	10746
1604.37	10740
1606.46	10754
1608.54	10864
1610.62	10838
1612.7	10874
1614.78	10864
1616.86	10748
1618.94	10660
1621.01	10710
1623.09	10680
1625.17	10756
1627.24	10728
1629.32	10798
1631.39	10722
1633.47	10708
1635.54	10714
1637.61	10584
1639.68	10594
1641.76	10648
1643.83	10600
1645.9	10624
1647.96	10646
1650.03	10678
1652.1	10542
1654.17	10602
1656.24	10394
1658.3	10506
1660.37	10574
1662.43	10450
1664.5	10406
1666.56	10384
1668.62	10410
1670.68	10410
1672.75	10386
1674.81	10360
1676.87	10198
1678.93	10376
1680.99	10356
1683.04	10378
1685.1	10200
1687.16	10188
1689.21	10244
1691.27	10168
1693.33	10254
1695.38	10152
1697.43	10098
1699.49	10178
1701.54	10098
1703.59	10028
1705.64	10062
1707.69	9960
1709.74	9960
1711.79	9978
1713.84	10118
1715.89	9864
1717.94	9986
1719.98	10106
1722.03	9902
1724.07	9926
1726.12	9826
1728.16	9888
1730.21	9910
1732.25	9868
1734.29	9814
1736.33	9844
1738.37	9846
1740.41	9712
1742.45	9910
1744.49	9772
1746.53	9848
1748.57	9626
1750.61	9736
1752.64	9730
1754.68	9800
1756.71	9686
1758.75	9660
1760.78	9620
1762.82	9644
1764.85	9670
1766.88	9656
1768.91	9676
1770.94	9694
1772.97	9518
1775	9556
1777.03	9530
1779.06	9548
1781.09	9608
1783.12	9566
1785.14	9656
1787.17	9690
1789.19	9508
1791.22	9508
1793.24	9656
1795.27	9414
1797.29	9332
1799.31	9326
1801.33	9484
1803.35	9356
1805.37	9458
1807.39	9378
1809.41	9260
1811.43	9384
1813.45	9316
1815.46	9490
1817.48	9306
1819.5	9344
1821.51	9354
1823.53	9366
1825.54	9150
1827.55	9136
1829.57	9212
1831.58	9078
1833.59	9114
1835.6	9090
1837.61	9134
1839.62	9046
1841.63	9138
1843.64	9092
1845.65	8948
1847.65	8870
1849.66	8942
1851.66	8954
1853.67	8962
1855.67	8904
1857.68	8898
1859.68	8752
1861.68	8742
1863.69	8820
1865.69	8754
1867.69	8876
1869.69	8842
1871.69	8804
1873.69	8702
1875.69	8776
1877.68	8674
1879.68	8622
1881.68	8726
1883.67	8678
1885.67	8688
1887.66	8600
1889.66	8676
1891.65	8638
1893.64	8584
1895.64	8722
1897.63	8702
1899.62	8596
1901.61	8532
1903.6	8568
1905.59	8582
1907.58	8648
1909.56	8626
1911.55	8630
1913.54	8454
1915.53	8432
1917.51	8352
1919.5	8402
1921.48	8498
1923.46	8494
1925.45	8342
1927.43	8514
1929.41	8452
1931.39	8368
1933.37	8362
1935.35	8418
1937.33	8476
1939.31	8368
1941.29	8304
1943.27	8264
1945.24	8310
1947.22	8332
1949.2	8238
1951.17	8264
1953.14	8269
1955.12	8088
1957.09	8216
1959.06	8022
1961.04	8158
1963.01	8058
1964.98	8116
1966.95	8214
1968.92	8014
1970.89	8174
1972.86	8010
1974.82	7974
1976.79	8048
1978.76	7864
1980.72	7884
1982.69	8076
1984.65	7892
1986.62	8022
1988.58	8028
1990.54	7964
1992.51	7862
1994.47	7886
1996.43	7840
1998.39	7808
1999.37	7836