File: muestras/cafe_/Organic_07.txt
#Acq. time (s)=	10
#Accumulations=	2
#Range (cm-¹)=	100...2000
#Windows=	2
#Autofocus=	Off
#AutoExposure=	Off
#Spike filter=	Multiple accum.
#Delay time (s)=	0
#Binning=	1
#Readout mode=	Signal
#DeNoise=	Off
#ICS correction=	Off
#Dark correction=	Off
#Inst. Process=	Off
#Instrument=	LabRAM HR Evol
#Detector=	Syncerity OE
#Objective=	x100_VIS
#Grating=	600 (500nm)
#ND Filter=	5%
#Laser=	633nm_Edge
#Hole=	24.99
#Range=	Visible
#Project=	Omar
#Sample=	20-06-23
#Site=	1
#Title=	Organic
#Remark=
#Date=	20.06.2023 11:31
#Acquired=	20.06.2023 11:31:08
101.054	7638
103.621	7562
106.187	7748
108.752	7600
111.317	7646
113.881	7734
116.443	7754
119.005	7678
121.566	7842
124.126	7834
126.685	7752
129.243	7806
131.801	7944
134.356	7960
136.911	8100
139.466	7876
142.021	8036
144.574	7970
147.125	8002
149.676	8096
152.227	8018
154.776	8016
157.325	8100
159.873	8010
162.419	8056
164.966	8216
167.51	8142
170.055	8292
172.598	8242
175.141	8188
177.682	8174
180.222	8192
182.763	8340
185.302	8260
187.839	8162
190.376	8422
192.914	8200
195.449	8382
197.983	8334
200.517	8552
203.05	8458
205.582	8602
208.113	8570
210.643	8626
213.173	8558
215.701	8570
218.229	8566
220.756	8604
223.282	8666
225.808	8802
228.331	8824
230.855	8724
233.378	8960
235.898	8858
238.419	8998
240.94	8934
243.458	9002
245.977	8974
248.495	9076
251.011	9024
253.527	9054
256.041	9080
258.555	9082
261.068	8994
263.58	9054
266.092	8996
268.603	9166
271.112	8994
273.62	9018
276.129	9008
278.636	9064
281.142	9102
283.647	9112
286.152	9108
288.655	9172
291.158	9252
293.66	9324
296.161	9276
298.661	9472
301.161	9320
303.66	9358
306.158	9524
308.655	9586
311.15	9526
313.645	9706
316.14	9592
318.634	9600
321.125	9498
323.618	9580
326.109	9550
328.598	9566
331.088	9616
333.576	9646
336.064	9790
338.55	9616
341.037	9670
343.521	9774
346.005	9730
348.489	9774
350.971	9872
353.453	9868
355.933	9730
358.414	9912
360.893	9894
363.371	9936
365.848	10056
368.325	10080
370.801	9878
373.275	9836
375.75	10076
378.223	9922
380.695	9924
383.167	9922
385.638	9900
388.108	9938
390.577	10004
393.044	9916
395.512	10052
397.979	10028
400.444	9942
402.909	10050
405.374	10214
407.836	10120
410.299	10120
412.76	10330
415.221	10378
417.681	10308
420.141	10492
422.598	10430
425.057	10606
427.513	10652
429.968	10542
432.422	10646
434.878	10676
437.33	10558
439.783	10588
442.234	10686
444.685	10686
447.134	10706
449.583	10636
452.032	10636
454.479	10562
456.926	10638
459.372	10752
461.817	10654
464.261	10644
466.705	10664
469.147	10680
471.588	10656
474.029	10734
476.47	10654
478.909	10806
481.347	10770
483.785	10768
486.221	10790
488.657	10874
491.092	10856
493.527	10982
495.96	10870
498.393	11088
500.824	10950
503.255	10946
505.686	11006
508.115	10972
510.543	11028
512.972	11034
515.399	11150
517.825	10966
520.25	10868
522.674	10974
525.097	10992
527.52	10920
529.942	11008
532.364	10988
534.784	11046
537.204	11024
539.623	11066
542.041	10922
544.457	11010
546.874	11030
549.289	10982
551.705	11072
554.118	10910
556.531	10946
558.943	11108
561.355	11080
563.766	11082
566.175	11146
568.585	11094
570.992	10934
573.399	11176
575.807	11074
578.212	11198
580.617	11082
583.022	11086
585.425	11194
587.827	11244
590.229	11148
592.63	11248
595.03	11114
597.43	11236
599.829	11204
602.226	11472
604.623	11166
607.02	11272
609.414	11310
611.808	11164
614.202	11230
616.596	11426
618.988	11276
621.378	11454
623.769	11546
626.159	11466
628.548	11616
630.936	11464
633.324	11612
635.71	11530
638.096	11682
640.481	11628
642.866	11780
645.248	11580
647.63	11722
650.013	11816
652.394	11804
654.773	11698
657.154	11720
659.532	11708
661.91	11770
664.286	11656
666.663	11632
669.038	11598
671.412	11822
673.786	11666
676.159	11666
678.532	11676
680.903	11654
683.274	11722
685.644	11796
688.014	11698
690.381	11684
692.749	11852
695.116	11616
697.481	11552
699.846	11654
702.211	11598
704.574	11670
706.938	11730
709.299	11798
711.661	11698
714.021	11716
716.381	11786
718.739	11750
721.097	11798
723.455	11894
725.811	11762
728.167	11888
730.521	11824
732.875	11868
735.23	11948
737.582	11746
739.934	11714
742.285	11826
744.635	11874
746.985	11836
749.332	11768
751.68	11850
754.028	11870
756.374	11854
758.72	11794
761.065	11894
763.408	11730
765.752	11864
768.095	11850
770.436	11710
772.777	11938
775.116	11892
777.456	11914
779.794	11816
782.133	11778
784.469	11794
786.805	11912
789.141	11780
791.476	11766
793.809	11760
796.142	11876
798.476	11982
800.807	11808
803.138	11842
805.468	11968
807.797	11970
810.125	11894
812.453	11906
814.78	11920
817.106	12048
819.432	11848
821.757	11858
824.08	11952
826.403	12116
828.726	12024
831.048	12050
833.368	12276
835.688	11998
838.007	12222
840.326	12148
842.644	12346
844.96	12108
847.276	12082
849.592	12198
851.906	12090
854.221	12206
856.534	12156
858.846	12298
861.157	12236
863.469	12174
865.779	12192
868.088	12314
870.396	12128
872.704	12320
875.011	12138
877.318	12028
879.623	12172
881.928	12152
884.232	12044
886.536	12158
888.837	12216
891.139	12232
893.44	12088
895.741	12030
898.039	12074
900.339	12130
902.637	12042
904.933	11938
907.231	11974
909.526	12002
911.821	11958
914.115	12138
916.408	11978
918.701	11954
920.993	12010
923.283	12160
925.573	12100
927.864	12004
930.153	12014
932.441	12200
934.728	12182
937.014	12072
939.3	12132
941.585	12100
943.87	12140
946.154	12124
948.437	12084
950.719	12192
952.999	12142
955.28	12346
957.56	12356
959.84	12182
962.117	12430
964.395	12320
966.671	12264
968.948	12242
971.223	12338
973.498	12380
975.771	12312
978.045	12396
980.317	12136
982.588	12116
984.86	12362
987.13	12336
989.399	12240
991.667	12258
993.937	12364
996.204	12254
998.47	12162
1000.74	12226
1003	12314
1005.26	12308
1007.53	12080
1009.79	12166
1012.05	12122
1014.31	12374
1016.57	12178
1018.83	12006
1021.09	12276
1023.35	12072
1025.61	12306
1027.87	12282
1030.12	12166
1032.38	12230
1034.63	12410
1036.88	12378
1039.14	12414
1041.39	12494
1043.64	12370
1045.89	12382
1048.14	12380
1050.39	12366
1052.64	12400
1054.89	12426
1057.14	12412
1059.38	12510
1061.63	12610
1063.87	12454
1066.12	12416
1068.36	12384
1070.6	12376
1072.85	12404
1075.09	12306
1077.33	12398
1079.57	12354
1081.81	12230
1084.05	12350
1086.28	12336
1088.52	12202
1090.76	12160
1092.99	12012
1095.23	12200
1097.46	12256
1099.69	12146
1101.93	12188
1104.16	12146
1106.39	12098
1108.62	12140
1110.85	11934
1113.08	12128
1115.31	12032
1117.53	11974
1119.76	11966
1121.99	12066
1124.21	12090
1126.44	12072
1128.66	12078
1130.88	12022
1133.11	12146
1135.33	12152
1137.55	12306
1139.77	12058
1141.99	12196
1144.21	12194
1146.43	12214
1148.64	12068
1150.86	12128
1153.08	12168
1155.29	12276
1157.51	12060
1159.72	12202
1161.93	12298
1164.14	12226
1166.36	12386
1168.57	12462
1170.78	12188
1172.99	12372
1175.2	12148
1177.4	12240
1179.61	12168
1181.82	12194
1184.02	12164
1186.23	12222
1188.43	12108
1190.64	12046
1192.84	12140
1195.04	12182
1197.24	12094
1199.45	12132.5
1201.64	11975.6
1203.84	11882.7
1206.04	11871.9
1208.24	11683.7
1210.44	11677.8
1212.64	11476.7
1214.83	11390.5
1217.03	11386.1
1219.22	11286.2
1221.41	11125.1
1223.61	11144.2
1225.8	11021.8
1227.99	11053.3
1230.18	10875.1
1232.37	10832.4
1234.56	10677.9
1236.75	10602.4
1238.94	10607
1241.13	10519.1
1243.31	10464.6
1245.5	10395.9
1247.68	10376
1249.87	10272.5
1252.05	10193.9
1254.24	10219
1256.42	10019.3
1258.6	9997.54
1260.78	9979.7
1262.96	9912.48
1265.14	9844.88
1267.32	9867.36
1269.5	9749.5
1271.67	9722.42
1273.85	9631.23
1276.03	9592.05
1278.2	9487.29
1280.38	9357.71
1282.55	9392.09
1284.72	9321.65
1286.9	9251.91
1289.07	9149.09
1291.24	9186.83
1293.41	9052.14
1295.58	8987.42
1297.75	8989.35
1299.92	8796.71
1302.09	8813.21
1304.25	8744.91
1306.42	8710.12
1308.46	8740
1310.63	8590
1312.81	8520
1314.98	8538
1317.16	8556
1319.33	8630
1321.5	8586
1323.67	8544
1325.85	8516
1328.02	8548
1330.19	8468
1332.35	8592
1334.52	8504
1336.69	8514
1338.86	8516
1341.02	8486
1343.19	8568
1345.35	8502
1347.52	8472
1349.68	8466
1351.84	8528
1354	8426
1356.17	8440
1358.33	8398
1360.49	8474
1362.65	8496
1364.8	8540
1366.96	8398
1369.12	8508
1371.28	8442
1373.43	8508
1375.59	8522
1377.74	8522
1379.89	8412
1382.05	8464
1384.2	8514
1386.35	8490
1388.5	8360
1390.65	8410
1392.8	8432
1394.95	8544
1397.1	8394
1399.25	8464
1401.4	8430
1403.54	8502
1405.69	8502
1407.83	8408
1409.98	8410
1412.12	8456
1414.26	8440
1416.4	8342
1418.55	8408
1420.69	8486
1422.83	8350
1424.97	8348
1427.1	8496
1429.24	8416
1431.38	8368
1433.52	8376
1435.65	8426
1437.79	8400
1439.92	8304
1442.06	8366
1444.19	8326
1446.32	8400
1448.46	8386
1450.59	8344
1452.72	8406
1454.85	8478
1456.98	8278
1459.11	8302
1461.23	8314
1463.36	8562
1465.49	8460
1467.61	8328
1469.74	8322
1471.86	8412
1473.99	8440
1476.11	8448
1478.23	8366
1480.36	8402
1482.48	8352
1484.6	8342
1486.72	8408
1488.84	8442
1490.96	8390
1493.07	8416
1495.19	8312
1497.31	8356
1499.42	8374
1501.54	8296
1503.65	8462
1505.77	8400
1507.88	8270
1509.99	8278
1512.1	8214
1514.22	8248
1516.33	8298
1518.44	8226
1520.55	8202
1522.65	8274
1524.76	8350
1526.87	8224
1528.98	8260
1531.08	8148
1533.19	8230
1535.29	8206
1537.4	8156
1539.5	8104
1541.6	8180
1543.7	8098
1545.8	8186
1547.91	8136
1550.01	8094
1552.11	8170
1554.2	8010
1556.3	8094
1558.4	8180
1560.5	8004
1562.59	7970
1564.69	8200
1566.78	8022
1568.88	8020
1570.97	8032
1573.06	8064
1575.15	8092
1577.25	7966
1579.34	8040
1581.43	7992
1583.52	7910
1585.6	8038
1587.69	7872
1589.78	8012
1591.87	7960
1593.95	8020
1596.04	7882
1598.12	8116
1600.21	7992
1602.29	7984
1604.37	7962
1606.46	8054
1608.54	7924
1610.62	7854
1612.7	7942
1614.78	7976
1616.86	7882
1618.94	7976
1621.01	8082
1623.09	8042
1625.17	7902
1627.24	7982
1629.32	7962
1631.39	8046
1633.47	7962
1635.54	7970
1637.61	8054
1639.68	7904
1641.76	7956
1643.83	7950
1645.9	7912
1647.96	7976
1650.03	7988
1652.1	7952
1654.17	7850
1656.24	7958
1658.3	7814
1660.37	7802
1662.43	7852
1664.5	7792
1666.56	7962
1668.62	7822
1670.68	7840
1672.75	7786
1674.81	7744
1676.87	7828
1678.93	7834
1680.99	7858
1683.04	7750
1685.1	7726
1687.16	7710
1689.21	7688
1691.27	7722
1693.33	7670
1695.38	7658
1697.43	7650
1699.49	7660
1701.54	7610
1703.59	7730
1705.64	7560
1707.69	7568
1709.74	7564
1711.79	7490
1713.84	7546
1715.89	7558
1717.94	7498
1719.98	7618
1722.03	7572
1724.07	7488
1726.12	7436
1728.16	7502
1730.21	7512
1732.25	7598
1734.29	7436
1736.33	7530
1738.37	7464
1740.41	7488
1742.45	7514
1744.49	7500
1746.53	7438
1748.57	7410
1750.61	7418
1752.64	7474
1754.68	7452
1756.71	7416
1758.75	7326
1760.78	7434
1762.82	7352
1764.85	7466
1766.88	7438
1768.91	7400
1770.94	7394
1772.97	7378
1775	7356
1777.03	7348
1779.06	7424
1781.09	7272
1783.12	7416
1785.14	7414
1787.17	7390
1789.19	7402
1791.22	7344
1793.24	7350
1795.27	7344
1797.29	7332
1799.31	7302
1801.33	7410
1803.35	7360
1805.37	7250
1807.39	7142
1809.41	7350
1811.43	7284
1813.45	7182
1815.46	7194
1817.48	7208
1819.5	7154
1821.51	7134
1823.53	7196
1825.54	7184
1827.55	7226
1829.57	7058
1831.58	7104
1833.59	7134
1835.6	7120
1837.61	7024
1839.62	7046
1841.63	7120
1843.64	6858
1845.65	6960
1847.65	7096
1849.66	6982
1851.66	6914
1853.67	6914
1855.67	6932
1857.68	6964
1859.68	6894
1861.68	6902
1863.69	6986
1865.69	6952
1867.69	6880
1869.69	6868
1871.69	7016
1873.69	6814
1875.69	6922
1877.68	6878
1879.68	6860
1881.68	6888
1883.67	6720
1885.67	6812
1887.66	6780
1889.66	6818
1891.65	6790
1893.64	6850
1895.64	6834
1897.63	6726
1899.62	6820
1901.61	6742
1903.6	6762
1905.59	6794
1907.58	6762
1909.56	6774
1911.55	6734
1913.54	6818
1915.53	6798
1917.51	6870
1919.5	6698
1921.48	6756
1923.46	6754
1925.45	6680
1927.43	6730
1929.41	6604
1931.39	6574
1933.37	6660
1935.35	6716
1937.33	6654
1939.31	6648
1941.29	6588
1943.27	6536
1945.24	6632
1947.22	6618
1949.2	6616
1951.17	6616
1953.14	6569
1955.12	6468
1957.09	6592
1959.06	6518
1961.04	6470
1963.01	6508
1964.98	6402
1966.95	6340
1968.92	6394
1970.89	6518
1972.86	6424
1974.82	6434
1976.79	6442
1978.76	6408
1980.72	6236
1982.69	6390
1984.65	6364
1986.62	6440
1988.58	6328
1990.54	6326
1992.51	6270
1994.47	6314
1996.43	6304
1998.39	6196
1999.37	6292