File: muestras/cafe_/Organic_14.txt
#Acq. time (s)=	10
#Accumulations=	1
#Range (cm-¹)=	100...2000
#Windows=	2
#Autofocus=	Off
#AutoExposure=	Off
#Spike filter=	Off
#Delay time (s)=	0
#Binning=	1
#Readout mode=	Signal
#DeNoise=	Off
#ICS correction=	Off
#Dark correction=	Off
#Inst. Process=	Off
#Instrument=	LabRAM HR Evol
#Detector=	Syncerity OE
#Objective=	x100_VIS
#Grating=	600 (500nm)
#ND Filter=	5%
#Laser=	633nm_Edge
#Hole=	24.99
#Range=	Visible
#Project=	Omar
#Sample=	20-06-23
#Site=	1
#Title=	Organic
#Remark=
#Date=	20.06.2023 11:43
#Acquired=	20.06.2023 11:43:59
101.054	3732
103.621	3762
106.187	3788
108.752	3762
111.317	3734
113.881	3812
116.443	3826
119.005	3776
121.566	3766
124.126	3714
126.685	3830
129.243	3848
131.801	3836
134.356	3838
136.911	3832
139.466	3844
142.021	3906
144.574	4018
147.125	3984
149.676	3924
152.227	3896
154.776	4020
157.325	3916
159.873	4008
162.419	3988
164.966	3926
167.51	3990
170.055	3958
172.598	4012
175.141	3982
177.682	3998
180.222	3986
182.763	4044
185.302	4078
187.839	3994
190.376	4076
192.914	4072
195.449	4146
197.983	4190
200.517	4150
203.05	4240
205.582	4166
208.113	4222
210.643	4106
213.173	4208
215.701	4256
218.229	4178
220.756	4316
223.282	4276
225.808	4210
228.331	4216
230.855	4392
233.378	4348
235.898	4358
238.419	4388
240.94	4322
243.458	4374
245.977	4378
248.495	4440
251.011	4450
253.527	4438
256.041	4484
258.555	4436
261.068	4442
263.58	4368
266.092	4392
268.603	4508
271.112	4484
273.62	4436
276.129	4434
278.636	4448
281.142	4442
283.647	4488
286.152	4532
288.655	4588
291.158	4560
293.66	4552
296.161	4594
298.661	4580
301.161	4574
303.66	4612
306.158	4630
308.655	4702
311.15	4740
313.645	4686
316.14	4740
318.634	4594
321.125	4690
323.618	4640
326.109	4720
328.598	4658
331.088	4856
333.576	4670
336.064	4754
338.55	4752
341.037	4708
343.521	4678
346.005	4792
348.489	4766
350.971	4848
353.453	4842
355.933	4862
358.414	4896
360.893	4868
363.371	4808
365.848	4742
368.325	4958
370.801	4784
373.275	4896
375.75	4828
378.223	4834
380.695	4792
383.167	4842
385.638	4940
388.108	4868
390.577	4936
393.044	4830
395.512	4940
397.979	4938
400.444	4886
402.909	4868
405.374	4990
407.836	4896
410.299	5050
412.76	4994
415.221	5006
417.681	5082
420.141	5140
422.598	5168
425.057	5182
427.513	5072
429.968	5238
432.422	5178
434.878	5270
437.33	5192
439.783	5272
442.234	5106
444.685	5170
447.134	5248
449.583	5256
452.032	5254
454.479	5208
456.926	5126
459.372	5174
461.817	5128
464.261	5232
466.705	5152
469.147	5154
471.588	5250
474.029	5262
476.47	5224
478.909	5232
481.347	5230
483.785	5280
486.221	5358
488.657	5358
491.092	5252
493.527	5338
495.96	5326
498.393	5320
500.824	5388
503.255	5332
505.686	5368
508.115	5326
510.543	5388
512.972	5280
515.399	5336
517.825	5366
520.25	5452
522.674	5282
525.097	5382
527.52	5346
529.942	5348
532.364	5406
534.784	5330
537.204	5336
539.623	5168
542.041	5366
544.457	5294
546.874	5304
549.289	5274
551.705	5392
554.118	5370
556.531	5394
558.943	5390
561.355	5408
563.766	5304
566.175	5444
568.585	5254
570.992	5392
573.399	5352
575.807	5336
578.212	5384
580.617	5426
583.022	5510
585.425	5438
587.827	5356
590.229	5460
592.63	5482
595.03	5362
597.43	5416
599.829	5446
602.226	5512
604.623	5498
607.02	5506
609.414	5500
611.808	5572
614.202	5488
616.596	5502
618.988	5566
621.378	5600
623.769	5546
626.159	5752
628.548	5586
630.936	5590
633.324	5588
635.71	5654
638.096	5704
640.481	5700
642.866	5592
645.248	5596
647.63	5714
650.013	5722
652.394	5670
654.773	5728
657.154	5708
659.532	5714
661.91	5682
664.286	5746
666.663	5752
669.038	5704
671.412	5700
673.786	5688
676.159	5652
678.532	5560
680.903	5676
683.274	5692
685.644	5720
688.014	5650
690.381	5648
692.749	5660
695.116	5570
697.481	5624
699.846	5692
702.211	5726
704.574	5656
706.938	5644
709.299	5716
711.661	5760
714.021	5716
716.381	5694
718.739	5836
721.097	5664
723.455	5796
725.811	5756
728.167	5668
730.521	5872
732.875	5780
735.23	5826
737.582	5804
739.934	5782
742.285	5750
744.635	5816
746.985	5732
749.332	5674
751.68	5672
754.028	5736
756.374	5712
758.72	5728
761.065	5738
763.408	5740
765.752	5618
768.095	5716
770.436	5742
772.777	5714
775.116	5658
777.456	5696
779.794	5744
782.133	5618
784.469	5674
786.805	5602
789.141	5710
791.476	5742
793.809	5664
796.142	5676
798.476	5780
800.807	5710
803.138	5738
805.468	5750
807.797	5762
810.125	5776
812.453	5860
814.78	5776
817.106	5812
819.432	5864
821.757	5804
824.08	5756
826.403	5846
828.726	5826
831.048	5822
833.368	5894
835.688	5942
838.007	5878
840.326	5940
842.644	5840
844.96	5846
847.276	5860
849.592	5866
851.906	5850
854.221	5858
856.534	5890
858.846	5888
861.157	5904
863.469	5880
865.779	5898
868.088	5878
870.396	6002
872.704	5904
875.011	5864
877.318	5846
879.623	5922
881.928	6010
884.232	5962
886.536	5794
888.837	5858
891.139	5852
893.44	5868
895.741	5784
898.039	5914
900.339	5738
902.637	5754
904.933	5832
907.231	5800
909.526	5732
911.821	5802
914.115	5858
916.408	5756
918.701	5862
920.993	5812
923.283	5816
925.573	5892
927.864	5748
930.153	5772
932.441	5820
934.728	5842
937.014	5856
939.3	5826
941.585	5894
943.87	5872
946.154	5768
948.437	5874
950.719	5910
952.999	5854
955.28	5864
957.56	5982
959.84	5874
962.117	5910
964.395	5938
966.671	6016
968.948	5930
971.223	5904
973.498	5868
975.771	6012
978.045	5854
980.317	5944
982.588	5858
984.86	5798
987.13	5888
989.399	5968
991.667	5940
993.937	6040
996.204	5926
998.47	5828
1000.74	5872
1003	5850
1005.26	5932
1007.53	5872
1009.79	5874
1012.05	5956
1014.31	5834
1016.57	5938
1018.83	5888
1021.09	5902
1023.35	5902
1025.61	5954
1027.87	6004
1030.12	5916
1032.38	5946
1034.63	5924
1036.88	6030
1039.14	6018
1041.39	6052
1043.64	5998
1045.89	6044
1048.14	5972
1050.39	6080
1052.64	6062
1054.89	6092
1057.14	6044
1059.38	6090
1061.63	6094
1063.87	5944
1066.12	5994
1068.36	6120
1070.6	6074
1072.85	5984
1075.09	6026
1077.33	5998
1079.57	5992
1081.81	5996
1084.05	6082
1086.28	5978
1088.52	6018
1090.76	5956
1092.99	5972
1095.23	5900
1097.46	6002
1099.69	5954
1101.93	5874
1104.16	5978
1106.39	5908
1108.62	6012
1110.85	5908
1113.08	5906
1115.31	5860
1117.53	5864
1119.76	5740
1121.99	5944
1124.21	5878
1126.44	5934
1128.66	5772
1130.88	5916
1133.11	5890
1135.33	5918
1137.55	5914
1139.77	5964
1141.99	5916
1144.21	5918
1146.43	5876
1148.64	5938
1150.86	5980
1153.08	5918
1155.29	6080
1157.51	6036
1159.72	5956
1161.93	6038
1164.14	6044
1166.36	6010
1168.57	5984
1170.78	5952
1172.99	6040
1175.2	6024
1177.4	5882
1179.61	5998
1181.82	5994
1184.02	6016
1186.23	5914
1188.43	5882
1190.64	5866
1192.84	5858
1195.04	5788
1197.24	5950
1199.45	5879.05
1201.64	5923.83
1203.84	5861.47
1206.04	5846.1
1208.24	5776.28
1210.44	5766.73
1212.64	5803.69
1214.83	5786.93
1217.03	5758.61
1219.22	5701.5
1221.41	5712.04
1223.61	5682.28
1225.8	5699.55
1227.99	5647.16
1230.18	5581.49
1232.37	5689.05
1234.56	5589.13
1236.75	5508.49
1238.94	5540.32
1241.13	5550.24
1243.31	5578.58
1245.5	5552.96
1247.68	5549.09
1249.87	5470.86
1252.05	5509.47
1254.24	5476.93
1256.42	5400.03
1258.6	5492.93
1260.78	5490.09
1262.96	5435.96
1265.14	5450.06
1267.32	5457.25
1269.5	5393.36
1271.67	5410.45
1273.85	5379.75
1276.03	5368.77
1278.2	5366.87
1280.38	5370.1
1282.55	5406.68
1284.72	5368.35
1286.9	5316.2
1289.07	5274.58
1291.24	5309.86
1293.41	5298.99
1295.58	5272.74
1297.75	5283.82
1299.92	5164.62
1302.09	5217.88
1304.25	5240.59
1306.42	5224.19
1308.46	5104
1310.63	5198
1312.81	5146
1314.98	5098
1317.16	5184
1319.33	5206
1321.5	5170
1323.67	5024
1325.85	5082
1328.02	5090
1330.19	5118
1332.35	5142
1334.52	5190
1336.69	5098
1338.86	5136
1341.02	5152
1343.19	5208
1345.35	5118
1347.52	5100
1349.68	5092
1351.84	5108
1354	4990
1356.17	5088
1358.33	5004
1360.49	5034
1362.65	5036
1364.8	5012
1366.96	5128
1369.12	5056
1371.28	5044
1373.43	5042
1375.59	5010
1377.74	5014
1379.89	5010
1382.05	5022
1384.2	5076
1386.35	4932
1388.5	4928
1390.65	5020
1392.8	5010
1394.95	5022
1397.1	4892
1399.25	4952
1401.4	5078
1403.54	4978
1405.69	5040
1407.83	4942
1409.98	4980
1412.12	4914
1414.26	4872
1416.4	4902
1418.55	5008
1420.69	4950
1422.83	4848
1424.97	4932
1427.1	4902
1429.24	4852
1431.38	4924
1433.52	4884
1435.65	4958
1437.79	4876
1439.92	4976
1442.06	4916
1444.19	4890
1446.32	4910
1448.46	4872
1450.59	4868
1452.72	4942
1454.85	4902
1456.98	4890
1459.11	4874
1461.23	4896
1463.36	4870
1465.49	4938
1467.61	4882
1469.74	4878
1471.86	4888
1473.99	4872
1476.11	4842
1478.23	4882
1480.36	4936
1482.48	4914
1484.6	4846
1486.72	4850
1488.84	4902
1490.96	4896
1493.07	4830
1495.19	4896
1497.31	4858
1499.42	4808
1501.54	4804
1503.65	4782
1505.77	4834
1507.88	4836
1509.99	4790
1512.1	4856
1514.22	4892
1516.33	4772
1518.44	4786
1520.55	4718
1522.65	4674
1524.76	4698
1526.87	4774
1528.98	4754
1531.08	4728
1533.19	4680
1535.29	4704
1537.4	4766
1539.5	4640
1541.6	4730
1543.7	4642
1545.8	4654
1547.91	4664
1550.01	4658
1552.11	4626
1554.2	4632
1556.3	4598
1558.4	4600
1560.5	4646
1562.59	4654
1564.69	4566
1566.78	4482
1568.88	4640
1570.97	4614
1573.06	4588
1575.15	4506
1577.25	4564
1579.34	4584
1581.43	4590
1583.52	4596
1585.6	4600
1587.69	4580
1589.78	4624
1591.87	4570
1593.95	4638
1596.04	4598
1598.12	4566
1600.21	4544
1602.29	4534
1604.37	4536
1606.46	4606
1608.54	4622
1610.62	4490
1612.7	4590
1614.78	4508
1616.86	4604
1618.94	4476
1621.01	4616
1623.09	4522
1625.17	4584
1627.24	4504
1629.32	4498
1631.39	4648
1633.47	4494
1635.54	4522
1637.61	4494
1639.68	4628
1641.76	4412
1643.83	4538
1645.9	4446
1647.96	4538
1650.03	4486
1652.1	4474
1654.17	4460
1656.24	4446
1658.3	4518
1660.37	4464
1662.43	4408
1664.5	4378
1666.56	4398
1668.62	4470
1670.68	4408
1672.75	4406
1674.81	4426
1676.87	4358
1678.93	4356
1680.99	4360
1683.04	4334
1685.1	4304
1687.16	4334
1689.21	4268
1691.27	4286
1693.33	4202
1695.38	4286
1697.43	4296
1699.49	4296
1701.54	4262
1703.59	4238
1705.64	4288
1707.69	4264
1709.74	4262
1711.79	4152
1713.84	4266
1715.89	4302
1717.94	4178
1719.98	4166
1722.03	4138
1724.07	4194
1726.12	4182
1728.16	4144
1730.21	4162
1732.25	4146
1734.29	4198
1736.33	4108
1738.37	4158
1740.41	4174
1742.45	4064
1744.49	4108
1746.53	4084
1748.57	4158
1750.61	4166
1752.64	4106
1754.68	4130
1756.71	4102
1758.75	4058
1760.78	4116
1762.82	4082
1764.85	4130
1766.88	4066
1768.91	4086
1770.94	4062
1772.97	4058
1775	4102
1777.03	4128
1779.06	4038
1781.09	4064
1783.12	4062
1785.14	4076
1787.17	4026
1789.19	4136
1791.22	4038
1793.24	4038
1795.27	4014
1797.29	4016
1799.31	4002
1801.33	3998
1803.35	4028
1805.37	3968
1807.39	4012
1809.41	3950
1811.43	3984
1813.45	3964
1815.46	3948
1817.48	3914
1819.5	3928
1821.51	3942
1823.53	4036
1825.54	3852
1827.55	3882
1829.57	3902
1831.58	3950
1833.59	3936
1835.6	3930
1837.61	3868
1839.62	3884
1841.63	3810
1843.64	3848
1845.65	3840
1847.65	3822
1849.66	3808
1851.66	3928
1853.67	3802
1855.67	3774
1857.68	3828
1859.68	3778
1861.68	3782
1863.69	3794
1865.69	3742
1867.69	3734
1869.69	3682
1871.69	3644
1873.69	3702
1875.69	3664
1877.68	3704
1879.68	3754
1881.68	3692
1883.67	3708
1885.67	3654
1887.66	3672
1889.66	3664
1891.65	3676
1893.64	3688
1895.64	3646
1897.63	3682
1899.62	3640
1901.61	3686
1903.6	3710
1905.59	3638
1907.58	3622
1909.56	3632
1911.55	3678
1913.54	3598
1915.53	3588
1917.51	3638
1919.5	3608
1921.48	3604
1923.46	3630
1925.45	3558
1927.43	3556
1929.41	3610
1931.39	3532
1933.37	3564
1935.35	3626
1937.33	3548
1939.31	3560
1941.29	3522
1943.27	3462
1945.24	3506
1947.22	3490
1949.2	3574
1951.17	3500
1953.14	3517
1955.12	3500
1957.09	3480
1959.06	3456
1961.04	3426
1963.01	3510
1964.98	3458
1966.95	3466
1968.92	3526
1970.89	3426
1972.86	3444
1974.82	3418
1976.79	3410
1978.76	3406
1980.72	3402
1982.69	3400
1984.65	3366
1986.62	3420
1988.58	3350
1990.54	3434
1992.51	3414
1994.47	3328
1996.43	3270
1998.39	3336
1999.37	3252