File: muestras/cafe_/Organic_08.txt
#Acq. time (s)=	10
#Accumulations=	2
#Range (cm-¹)=	100...2000
#Windows=	2
#Autofocus=	Off
#AutoExposure=	Off
#Spike filter=	Multiple accum.
#Delay time (s)=	0
#Binning=	1
#Readout mode=	Signal
#DeNoise=	Off
#ICS correction=	Off
#Dark correction=	Off
#Inst. Process=	Off
#Instrument=	LabRAM HR Evol
#Detector=	Syncerity OE
#Objective=	x100_VIS
#Grating=	600 (500nm)
#ND Filter=	5%
#Laser=	633nm_Edge
#Hole=	24.99
#Range=	Visible
#Project=	Omar
#Sample=	20-06-23
#Site=	1
#Title=	Organic
#Remark=
#Date=	20.06.2023 11:32
#Acquired=	20.06.2023 11:32:25
101.054	2734
103.621	2786
106.187	2836
108.752	2850
111.317	2800
113.881	2782
116.443	2892
119.005	2852
121.566	2838
124.126	2828
126.685	2860
129.243	2874
131.801	2852
134.356	2874
136.911	2926
139.466	2912
142.021	2924
144.574	2860
147.125	2918
149.676	2974
152.227	2998
154.776	2992
157.325	3006
159.873	2960
162.419	2948
164.966	3016
167.51	2970
170.055	2940
172.598	3010
175.141	2998
177.682	2974
180.222	2956
182.763	3076
185.302	2968
187.839	3088
190.376	3010
192.914	3066
195.449	3012
197.983	3086
200.517	3160
203.05	3154
205.582	3186
208.113	3066
210.643	3124
213.173	3140
215.701	3120
218.229	3246
220.756	3222
223.282	3248
225.808	3224
228.331	3218
230.855	3194
233.378	3262
235.898	3288
238.419	3310
240.94	3286
243.458	3346
245.977	3326
248.495	3260
251.011	3334
253.527	3296
256.041	3268
258.555	3280
261.068	3324
263.58	3250
266.092	3350
268.603	3244
271.112	3292
273.62	3388
276.129	3356
278.636	3272
281.142	3296
283.647	3354
286.152	3366
288.655	3330
291.158	3402
293.66	3376
296.161	3504
298.661	3458
301.161	3456
303.66	3510
306.158	3374
308.655	3522
311.15	3500
313.645	3556
316.14	3512
318.634	3536
321.125	3498
323.618	3494
326.109	3534
328.598	3532
331.088	3522
333.576	3548
336.064	3538
338.55	3580
341.037	3560
343.521	3652
346.005	3618
348.489	3704
350.971	3672
353.453	3630
355.933	3554
358.414	3626
360.893	3636
363.371	3690
365.848	3636
368.325	3682
370.801	3666
373.275	3742
375.75	3748
378.223	3694
380.695	3674
383.167	3684
385.638	3650
388.108	3600
390.577	3766
393.044	3704
395.512	3718
397.979	3696
400.444	3678
402.909	3792
405.374	3834
407.836	3836
410.299	3782
412.76	3904
415.221	3790
417.681	3800
420.141	3820
422.598	3906
425.057	3924
427.513	3914
429.968	3834
432.422	3952
434.878	3958
437.33	3974
439.783	3932
442.234	3966
444.685	4004
447.134	3960
449.583	3846
452.032	3864
454.479	3946
456.926	3958
459.372	4028
461.817	4000
464.261	3870
466.705	3984
469.147	3902
471.588	3882
474.029	3970
476.47	3962
478.909	3956
481.347	3978
483.785	4012
486.221	4120
488.657	4030
491.092	4016
493.527	4004
495.96	4042
498.393	4038
500.824	4010
503.255	4074
505.686	4032
508.115	4070
510.543	4114
512.972	4068
515.399	4038
517.825	4066
520.25	4050
522.674	4116
525.097	4058
527.52	4102
529.942	4098
532.364	4132
534.784	4034
537.204	4038
539.623	4052
542.041	4066
544.457	4026
546.874	4062
549.289	4032
551.705	4036
554.118	4024
556.531	4088
558.943	4076
561.355	4036
563.766	4076
566.175	4086
568.585	4084
570.992	4104
573.399	4088
575.807	4140
578.212	4134
580.617	4136
583.022	4090
585.425	4124
587.827	4060
590.229	4150
592.63	4178
595.03	4142
597.43	4160
599.829	4122
602.226	4182
604.623	4170
607.02	4144
609.414	4130
611.808	4192
614.202	4184
616.596	4196
618.988	4216
621.378	4254
623.769	4154
626.159	4306
628.548	4314
630.936	4360
633.324	4252
635.71	4350
638.096	4242
640.481	4250
642.866	4272
645.248	4340
647.63	4360
650.013	4262
652.394	4350
654.773	4366
657.154	4278
659.532	4314
661.91	4392
664.286	4372
666.663	4298
669.038	4380
671.412	4360
673.786	4242
676.159	4294
678.532	4372
680.903	4448
683.274	4312
685.644	4338
688.014	4320
690.381	4376
692.749	4356
695.116	4298
697.481	4338
699.846	4258
702.211	4408
704.574	4368
706.938	4366
709.299	4400
711.661	4296
714.021	4402
716.381	4404
718.739	4440
721.097	4418
723.455	4416
725.811	4390
728.167	4448
730.521	4448
732.875	4424
735.23	4408
737.582	4426
739.934	4434
742.285	4436
744.635	4526
746.985	4396
749.332	4390
751.68	4310
754.028	4396
756.374	4458
758.72	4346
761.065	4404
763.408	4434
765.752	4424
768.095	4406
770.436	4400
772.777	4430
775.116	4384
777.456	4450
779.794	4458
782.133	4432
784.469	4416
786.805	4370
789.141	4372
791.476	4382
793.809	4386
796.142	4430
798.476	4452
800.807	4400
803.138	4390
805.468	4398
807.797	4450
810.125	4434
812.453	4460
814.78	4400
817.106	4448
819.432	4506
821.757	4446
824.08	4562
826.403	4480
828.726	4514
831.048	4540
833.368	4496
835.688	4570
838.007	4562
840.326	4526
842.644	4534
844.96	4506
847.276	4634
849.592	4608
851.906	4520
854.221	4640
856.534	4548
858.846	4530
861.157	4548
863.469	4596
865.779	4498
868.088	4568
870.396	4572
872.704	4564
875.011	4578
877.318	4522
879.623	4576
881.928	4640
884.232	4430
886.536	4562
888.837	4656
891.139	4492
893.44	4560
895.741	4604
898.039	4508
900.339	4550
902.637	4514
904.933	4526
907.231	4490
909.526	4550
911.821	4496
914.115	4550
916.408	4468
918.701	4536
920.993	4514
923.283	4548
925.573	4572
927.864	4544
930.153	4526
932.441	4516
934.728	4542
937.014	4532
939.3	4560
941.585	4608
943.87	4658
946.154	4562
948.437	4582
950.719	4646
952.999	4652
955.28	4594
957.56	4624
959.84	4590
962.117	4550
964.395	4718
966.671	4584
968.948	4600
971.223	4642
973.498	4632
975.771	4598
978.045	4614
980.317	4640
982.588	4664
984.86	4644
987.13	4706
989.399	4640
991.667	4560
993.937	4590
996.204	4558
998.47	4604
1000.74	4602
1003	4566
1005.26	4622
1007.53	4580
1009.79	4668
1012.05	4696
1014.31	4648
1016.57	4648
1018.83	4622
1021.09	4618
1023.35	4650
1025.61	4652
1027.87	4658
1030.12	4626
1032.38	4620
1034.63	4666
1036.88	4596
1039.14	4668
1041.39	4660
1043.64	4764
1045.89	4688
1048.14	4684
1050.39	4652
1052.64	4776
1054.89	4758
1057.14	4674
1059.38	4766
1061.63	4704
1063.87	4748
1066.12	4696
1068.36	4768
1070.6	4712
1072.85	4674
1075.09	4798
1077.33	4694
1079.57	4786
1081.81	4684
1084.05	4816
1086.28	4720
1088.52	4634
1090.76	4636
1092.99	4638
1095.23	4662
1097.46	4596
1099.69	4588
1101.93	4664
1104.16	4574
1106.39	4630
1108.62	4624
1110.85	4570
1113.08	4674
1115.31	4614
1117.53	4698
1119.76	4568
1121.99	4560
1124.21	4648
1126.44	4660
1128.66	4632
1130.88	4630
1133.11	4698
1135.33	4712
1137.55	4558
1139.77	4720
1141.99	4732
1144.21	4672
1146.43	4618
1148.64	4684
1150.86	4730
1153.08	4734
1155.29	4680
1157.51	4714
1159.72	4690
1161.93	4756
1164.14	4700
1166.36	4726
1168.57	4728
1170.78	4680
1172.99	4724
1175.2	4654
1177.4	4696
1179.61	4668
1181.82	4682
1184.02	4716
1186.23	4654
1188.43	4618
1190.64	4722
1192.84	4718
1195.04	4616
1197.24	4664
1199.45	4637.73
1201.64	4614.92
1203.84	4597.37
1206.04	4600.58
1208.24	4525.58
1210.44	4561.53
1212.64	4480.74
1214.83	4482.8
1217.03	4446.11
1219.22	4408.12
1221.41	4431.46
1223.61	4402.9
1225.8	4342.99
1227.99	4368.57
1230.18	4332.1
1232.37	4364.2
1234.56	4315.31
1236.75	4261.13
1238.94	4278.69
1241.13	4316.79
1243.31	4266.41
1245.5	4262.69
1247.68	4171.52
1249.87	4203.11
1252.05	4166.22
1254.24	4218.56
1256.42	4208.38
1258.6	4130.3
1260.78	4114.23
1262.96	4089.67
1265.14	4102.88
1267.32	4068.99
1269.5	4076.13
1271.67	4064.38
1273.85	3983.71
1276.03	4003.41
1278.2	3995.73
1280.38	3995.87
1282.55	3972.84
1284.72	3920.98
1286.9	3921.92
1289.07	3942.98
1291.24	3866.04
1293.41	3828.34
1295.58	3838.46
1297.75	3871.34
1299.92	3788.87
1302.09	3784.55
1304.25	3796.46
1306.42	3792.78
1308.46	3754
1310.63	3746
1312.81	3744
1314.98	3626
1317.16	3818
1319.33	3764
1321.5	3738
1323.67	3752
1325.85	3692
1328.02	3784
1330.19	3674
1332.35	3758
1334.52	3766
1336.69	3722
1338.86	3716
1341.02	3714
1343.19	3706
1345.35	3718
1347.52	3696
1349.68	3736
1351.84	3784
1354	3712
1356.17	3656
1358.33	3676
1360.49	3670
1362.65	3740
1364.8	3664
1366.96	3714
1369.12	3738
1371.28	3736
1373.43	3670
1375.59	3792
1377.74	3660
1379.89	3716
1382.05	3624
1384.2	3730
1386.35	3666
1388.5	3714
1390.65	3676
1392.8	3698
1394.95	3586
1397.1	3566
1399.25	3618
1401.4	3626
1403.54	3628
1405.69	3628
1407.83	3694
1409.98	3658
1412.12	3646
1414.26	3606
1416.4	3622
1418.55	3600
1420.69	3568
1422.83	3664
1424.97	3634
1427.1	3648
1429.24	3568
1431.38	3640
1433.52	3600
1435.65	3628
1437.79	3676
1439.92	3596
1442.06	3614
1444.19	3598
1446.32	3658
1448.46	3606
1450.59	3650
1452.72	3568
1454.85	3604
1456.98	3664
1459.11	3576
1461.23	3604
1463.36	3604
1465.49	3650
1467.61	3626
1469.74	3622
1471.86	3634
1473.99	3660
1476.11	3614
1478.23	3590
1480.36	3684
1482.48	3654
1484.6	3590
1486.72	3640
1488.84	3618
1490.96	3656
1493.07	3570
1495.19	3666
1497.31	3574
1499.42	3644
1501.54	3516
1503.65	3632
1505.77	3542
1507.88	3584
1509.99	3484
1512.1	3662
1514.22	3562
1516.33	3548
1518.44	3560
1520.55	3556
1522.65	3508
1524.76	3490
1526.87	3548
1528.98	3506
1531.08	3512
1533.19	3512
1535.29	3528
1537.4	3410
1539.5	3530
1541.6	3468
1543.7	3506
1545.8	3464
1547.91	3484
1550.01	3462
1552.11	3462
1554.2	3462
1556.3	3412
1558.4	3440
1560.5	3472
1562.59	3438
1564.69	3468
1566.78	3454
1568.88	3416
1570.97	3462
1573.06	3478
1575.15	3378
1577.25	3434
1579.34	3394
1581.43	3426
1583.52	3460
1585.6	3364
1587.69	3420
1589.78	3442
1591.87	3380
1593.95	3422
1596.04	3408
1598.12	3414
1600.21	3408
1602.29	3370
1604.37	3440
1606.46	3456
1608.54	3420
1610.62	3434
1612.7	3434
1614.78	3306
1616.86	3392
1618.94	3402
1621.01	3438
1623.09	3392
1625.17	3448
1627.24	3334
1629.32	3356
1631.39	3432
1633.47	3412
1635.54	3410
1637.61	3404
1639.68	3362
1641.76	3394
1643.83	3372
1645.9	3420
1647.96	3366
1650.03	3386
1652.1	3476
1654.17	3362
1656.24	3466
1658.3	3314
1660.37	3340
1662.43	3308
1664.5	3330
1666.56	3272
1668.62	3340
1670.68	3298
1672.75	3350
1674.81	3286
1676.87	3314
1678.93	3340
1680.99	3332
1683.04	3276
1685.1	3254
1687.16	3258
1689.21	3282
1691.27	3268
1693.33	3266
1695.38	3288
1697.43	3246
1699.49	3266
1701.54	3210
1703.59	3260
1705.64	3242
1707.69	3186
1709.74	3242
1711.79	3276
1713.84	3174
1715.89	3222
1717.94	3172
1719.98	3170
1722.03	3198
1724.07	3222
1726.12	3094
1728.16	3218
1730.21	3146
1732.25	3236
1734.29	3196
1736.33	3180
1738.37	3174
1740.41	3196
1742.45	3110
1744.49	3132
1746.53	3112
1748.57	3122
1750.61	3122
1752.64	3134
1754.68	3128
1756.71	3098
1758.75	3130
1760.78	3092
1762.82	3140
1764.85	3092
1766.88	3140
1768.91	3068
1770.94	3138
1772.97	3148
1775	3112
1777.03	3136
1779.06	3092
1781.09	3182
1783.12	3136
1785.14	3172
1787.17	3106
1789.19	3110
1791.22	3092
1793.24	3066
1795.27	3084
1797.29	3068
1799.31	3092
1801.33	3102
1803.35	2952
1805.37	3110
1807.39	3028
1809.41	3116
1811.43	3012
1813.45	3020
1815.46	2956
1817.48	3020
1819.5	3006
1821.51	3038
1823.53	3072
1825.54	2984
1827.55	2914
1829.57	3026
1831.58	2988
1833.59	2976
1835.6	3034
1837.61	2960
1839.62	2964
1841.63	2994
1843.64	2950
1845.65	2952
1847.65	2938
1849.66	2918
1851.66	2894
1853.67	2864
1855.67	2880
1857.68	2894
1859.68	2938
1861.68	2898
1863.69	2886
1865.69	2892
1867.69	2878
1869.69	2864
1871.69	2912
1873.69	2900
1875.69	2882
1877.68	2854
1879.68	2868
1881.68	2836
1883.67	2840
1885.67	2822
1887.66	2822
1889.66	2846
1891.65	2848
1893.64	2762
1895.64	2862
1897.63	2858
1899.62	2810
1901.61	2856
1903.6	2860
1905.59	2806
1907.58	2814
1909.56	2820
1911.55	2844
1913.54	2832
1915.53	2772
1917.51	2792
1919.5	2744
1921.48	2832
1923.46	2808
1925.45	2770
1927.43	2790
1929.41	2778
1931.39	2770
1933.37	2812
1935.35	2772
1937.33	2772
1939.31	2816
1941.29	2774
1943.27	2786
1945.24	2770
1947.22	2772
1949.2	2732
1951.17	2772
1953.14	2756
1955.12	2768
1957.09	2760
1959.06	2708
1961.04	2738
1963.01	2704
1964.98	2670
1966.95	2722
1968.92	2644
1970.89	2676
1972.86	2712
1974.82	2710
1976.79	2634
1978.76	2704
1980.72	2606
1982.69	2664
1984.65	2638
1986.62	2674
1988.58	2634
1990.54	2670
1992.51	2670
1994.47	2660
1996.43	2654
1998.39	2630
1999.37	2644