File: muestras/tallo/2/Organic_04.txt
#Acq. time (s)=	10
#Accumulations=	1
#Range (cm-¹)=	100...3000
#Windows=	3
#Autofocus=	Off
#AutoExposure=	Off
#Spike filter=	Off
#Delay time (s)=	0
#Binning=	1
#Readout mode=	Signal
#DeNoise=	Off
#ICS correction=	Off
#Dark correction=	Off
#Inst. Process=	Off
#Instrument=	LabRAM HR Evol
#Detector=	Syncerity OE
#Objective=	x100_VIS
#Grating=	600 (500nm)
#ND Filter=	3.2%
#Laser=	633nm_Edge
#Hole=	100.021
#Range=	Visible
#Project=	Omar
#Sample=	26-06-23
#Site=	2
#Title=	Organic
#Remark=
#Date=	26.06.2023 16:19
#Acquired=	26.06.2023 16:19:00
101.018	4200
103.586	4290
106.152	4298
108.717	4248
111.281	4312
113.845	4288
116.407	4340
118.969	4360
121.53	4442
124.09	4352
126.649	4400
129.207	4464
131.765	4468
134.321	4428
136.877	4526
139.432	4480
141.985	4484
144.538	4514
147.09	4484
149.641	4550
152.191	4540
154.741	4568
157.289	4560
159.837	4574
162.385	4652
164.93	4598
167.476	4654
170.019	4684
172.562	4662
175.105	4662
177.646	4588
180.188	4640
182.727	4744
185.266	4806
187.804	4728
190.342	4790
192.878	4766
195.413	4896
197.948	4830
200.481	4860
203.014	4936
205.546	4918
208.077	4982
210.608	4938
213.137	5028
215.666	5058
218.194	4944
220.721	5036
223.247	5034
225.772	5032
228.295	5106
230.819	5022
233.342	5074
235.864	5194
238.384	5128
240.904	5154
243.423	5278
245.941	5232
248.46	5168
250.975	5220
253.492	5330
256.006	5248
258.519	5336
261.033	5332
263.545	5246
266.057	5256
268.567	5294
271.076	5410
273.585	5276
276.094	5268
278.601	5374
281.107	5460
283.612	5430
286.116	5454
288.62	5498
291.123	5552
293.625	5540
296.126	5548
298.626	5630
301.126	5566
303.625	5620
306.122	5690
308.62	5668
311.114	5728
313.61	5646
316.105	5722
318.599	5720
321.09	5756
323.583	5716
326.073	5826
328.563	5878
331.053	5804
333.541	5898
336.029	5888
338.515	5780
341.001	5890
343.486	5936
345.97	5890
348.453	6012
350.936	5938
353.418	5892
355.898	6062
358.378	6150
360.858	6040
363.336	6068
365.813	6138
368.29	6132
370.766	6052
373.241	6064
375.715	6132
378.188	6158
380.66	6218
383.132	6094
385.603	6138
388.072	6156
390.541	6238
393.01	6210
395.477	6142
397.943	6258
400.409	6264
402.875	6234
405.338	6288
407.802	6406
410.263	6478
412.725	6436
415.185	6482
417.646	6438
420.104	6570
422.564	6594
425.02	6690
427.477	6662
429.933	6782
432.388	6698
434.841	6752
437.294	6828
439.748	6790
442.199	6762
444.65	6884
447.1	6806
449.549	6736
451.997	6762
454.445	6820
456.891	6878
459.337	6914
461.782	6856
464.227	6918
466.669	6980
469.112	6960
471.554	6972
473.995	7134
476.434	7088
478.874	7138
481.312	7024
483.749	7098
486.186	7226
488.622	7128
491.057	7190
493.491	7168
495.925	7320
498.357	7300
500.789	7296
503.221	7328
505.65	7406
508.079	7378
510.509	7370
512.936	7548
515.363	7438
517.789	7496
520.214	7440
522.638	7486
525.062	7476
527.485	7484
529.907	7380
532.328	7486
534.748	7554
537.168	7590
539.587	7546
542.005	7604
544.423	7634
546.838	7650
549.254	7618
551.669	7722
554.082	7690
556.496	7716
558.909	7692
561.319	7756
563.731	7786
566.14	7780
568.549	8028
570.957	7834
573.364	7930
575.771	7994
578.177	8080
580.581	8082
582.987	8126
585.39	8112
587.792	8072
590.193	8118
592.594	8212
594.996	8228
597.395	8414
599.793	8276
602.191	8480
604.588	8432
606.984	8484
609.378	8508
611.773	8546
614.167	8622
616.56	8646
618.953	8686
621.343	8806
623.734	8852
626.124	8956
628.512	8908
630.901	8904
633.289	8960
635.675	9080
638.061	9242
640.446	9124
642.831	9182
645.213	9228
647.595	9396
649.978	9370
652.359	9496
654.738	9408
657.117	9566
659.497	9522
661.875	9478
664.252	9652
666.628	9722
669.003	9720
671.378	9740
673.751	9858
676.124	9676
678.497	9764
680.868	9928
683.239	9850
685.609	10018
687.977	10218
690.346	10086
692.714	10104
695.081	10122
697.446	10034
699.812	10324
702.175	10366
704.539	10238
706.901	10448
709.264	10376
711.625	10500
713.986	10700
716.345	10610
718.705	10598
721.062	10784
723.419	10782
725.775	11000
728.132	11032
730.487	11038
732.841	11050
735.194	11114
737.546	11326
739.898	11218
742.249	11456
744.599	11502
746.949	11412
749.298	11494
751.646	11552
753.993	11558
756.34	11620
758.684	11754
761.029	11652
763.374	11778
765.716	11950
768.059	11966
770.401	11962
772.741	12088
775.082	12140
777.421	12134
779.76	12278
782.097	12224
784.434	12454
786.771	12398
789.106	12662
791.44	12498
793.775	12688
796.108	12804
798.44	12854
800.771	12950
803.102	12984
805.432	13008
807.761	13074
810.09	13342
812.417	13380
814.744	13400
817.071	13678
819.396	13430
821.721	13694
824.045	13764
826.367	13960
828.69	13878
831.012	14056
833.332	14308
835.653	14326
837.972	14442
840.29	14534
842.609	14684
844.925	14834
847.242	14770
849.557	14750
851.871	15008
854.186	15058
856.498	15080
858.81	15306
861.122	15294
863.434	15538
865.744	15618
868.053	15578
870.361	15754
872.669	15842
874.976	15916
877.282	16068
879.588	15886
881.893	16114
884.197	16070
886.5	16242
888.802	16190
891.104	16440
893.405	16428
895.706	16430
898.004	16674
900.303	16716
902.6	16882
904.898	16686
907.194	16842
909.49	16944
911.785	16958
914.08	17224
916.372	17186
918.666	17168
920.957	17248
923.248	17542
925.538	17628
927.828	17692
930.118	17968
932.406	17888
934.693	18050
936.979	18200
939.265	18290
941.55	18234
943.835	18506
946.118	18666
948.401	18652
950.682	18712
952.964	18828
955.245	18958
957.525	19156
959.803	19296
962.082	19436
964.36	19412
966.636	19432
968.913	19664
971.188	19726
973.463	19712
975.736	19944
978.009	19984
980.282	19990
982.554	20128
984.824	20184
987.095	20352
989.364	20458
991.633	20508
993.9	20782
996.167	20666
998.434	20670
1000.7	20742
1002.96	20882
1005.23	21066
1007.49	20928
1009.76	21220
1012.02	21368
1014.28	21434
1016.54	21510
1018.8	21560
1021.06	21690
1023.32	21714
1025.57	21784
1027.83	22034
1030.09	22420
1032.34	22294
1034.6	22304
1036.85	22400
1039.1	22538
1041.35	22578
1043.61	22842
1045.86	23082
1048.11	23050
1050.36	22990
1052.61	23250
1054.85	23240
1057.1	23340
1059.35	23492
1061.59	23564
1063.84	23712
1066.08	23798
1068.33	23748
1070.57	23636
1072.81	23636
1075.05	23888
1077.29	24192
1079.53	23870
1081.77	24018
1084.01	23850
1086.25	23880
1088.48	23896
1090.72	23966
1092.96	23856
1095.19	23960
1097.43	24074
1099.66	24038
1101.89	23928
1104.12	23942
1106.35	24018
1108.59	24086
1110.81	24124
1113.04	24166
1115.27	24188
1117.5	24304
1119.73	24132
1121.95	24274
1124.18	24160
1126.4	24278
1128.63	24216
1130.85	24100
1133.07	24318
1135.29	24470
1137.51	24254
1139.73	24456
1141.95	24534
1144.17	24532
1146.39	24440
1148.61	24508
1150.82	24764
1153.04	24652
1155.26	24746
1157.47	24694
1159.68	24870
1161.9	24788
1164.11	24752
1166.32	24672
1168.53	24712
1170.74	24582
1172.95	24506
1175.16	24522
1177.37	24570
1179.58	24340
1181.78	24414
1183.99	24368
1186.19	24268
1188.4	24260
1190.6	24168
1192.8	23920
1195.01	23878
1197.21	23917.6
1199.41	23720.1
1201.61	23428.3
1203.81	23429.5
1206.01	23453.5
1208.2	23505.8
1210.4	23318.1
1212.6	23252.9
1214.8	23217.4
1216.99	23377.5
1219.18	22945.4
1221.38	22925.3
1223.57	22907.1
1225.76	22710.2
1227.96	22642
1230.15	22683.4
1232.34	22599.6
1234.53	22435.4
1236.71	22403
1238.9	22361.4
1241.09	22245.7
1243.28	22228.3
1245.46	21955.3
1247.65	21977.6
1249.83	21912.2
1252.02	21913.2
1254.2	21936.2
1256.38	21785.7
1258.56	21589
1260.74	21659.3
1262.92	21541
1265.1	21462.4
1267.28	21482.9
1269.46	21365
1271.64	21337.5
1273.82	21236.6
1275.99	21063.2
1278.17	20991.3
1280.34	21084.6
1282.52	21048
1284.69	20719.6
1286.86	20851
1289.03	20600.4
1291.21	20677.7
1293.38	20526.8
1295.55	20445
1297.71	20373.5
1299.88	20205.8
1302.05	20121.6
1304.22	19960.2
1306.38	19917.6
1308.43	19892
1310.61	19702
1312.78	19594
1314.96	19488
1317.13	19324
1319.3	19388
1321.48	19104
1323.65	18996
1325.82	18814
1327.99	18900
1330.16	18694
1332.33	18620
1334.5	18684
1336.66	18370
1338.83	18130
1341	18254
1343.16	18080
1345.33	18074
1347.49	17858
1349.65	17756
1351.82	17742
1353.98	17600
1356.14	17544
1358.3	17364
1360.46	17360
1362.62	17270
1364.78	17408
1366.94	17034
1369.09	16962
1371.25	16936
1373.41	16926
1375.56	16864
1377.72	16706
1379.87	16666
1382.02	16574
1384.17	16470
1386.33	16670
1388.48	16554
1390.63	16122
1392.78	16304
1394.93	16108
1397.07	16040
1399.22	16142
1401.37	15896
1403.52	15980
1405.66	15776
1407.81	15726
1409.95	15544
1412.09	15454
1414.24	15464
1416.38	15284
1418.52	15374
1420.66	15312
1422.8	15176
1424.94	15154
1427.08	15084
1429.22	15074
1431.35	15006
1433.49	14998
1435.63	14860
1437.76	14948
1439.9	15012
1442.03	14800
1444.17	14564
1446.3	14684
1448.43	14598
1450.56	14538
1452.69	14470
1454.82	14454
1456.95	14422
1459.08	14390
1461.21	14222
1463.34	14248
1465.46	14272
1467.59	14142
1469.71	14030
1471.84	14048
1473.96	14068
1476.08	14002
1478.21	13956
1480.33	13972
1482.45	13824
1484.57	13994
1486.69	13832
1488.81	13716
1490.93	13718
1493.05	13580
1495.16	13550
1497.28	13606
1499.4	13542
1501.51	13530
1503.63	13544
1505.74	13218
1507.85	13378
1509.97	13216
1512.08	13156
1514.19	13146
1516.3	13364
1518.41	13196
1520.52	13084
1522.63	12976
1524.73	12994
1526.84	12960
1528.95	12928
1531.06	12764
1533.16	12710
1535.26	12750
1537.37	12564
1539.47	12634
1541.57	12650
1543.68	12596
1545.78	12576
1547.88	12380
1549.98	12448
1552.08	12354
1554.18	12460
1556.27	12276
1558.37	12282
1560.47	12276
1562.56	12308
1564.66	12262
1566.75	12104
1568.85	12102
1570.94	12250
1573.03	12052
1575.13	12010
1577.22	12062
1579.31	12092
1581.4	11944
1583.49	11986
1585.58	11946
1587.66	11976
1589.75	11872
1591.84	11940
1593.93	11886
1596.01	11832
1598.1	11906
1600.18	11744
1602.26	11832
1604.35	11838
1606.43	11774
1608.51	11710
1610.59	11706
1612.67	11676
1614.75	11808
1616.83	11662
1618.91	11768
1620.99	11644
1623.06	11662
1625.14	11462
1627.21	11564
1629.29	11540
1631.36	11526
1633.44	11532
1635.51	11484
1637.58	11612
1639.66	11370
1641.73	11440
1643.8	11414
1645.87	11448
1647.94	11332
1650	11220
1652.07	11410
1654.14	11300
1656.21	11236
1658.27	11372
1660.34	11330
1662.4	11008
1664.47	11194
1666.53	10956
1668.59	11060
1670.66	11082
1672.72	10972
1674.78	10958
1676.84	10984
1678.9	10842
1680.96	10800
1683.01	10804
1685.07	10830
1687.13	10810
1689.19	10742
1691.24	10826
1693.3	10758
1695.35	10746
1697.4	10710
1699.46	10582
1701.51	10738
1703.56	10566
1705.61	10482
1707.66	10542
1709.71	10482
1711.76	10544
1713.81	10416
1715.86	10558
1717.91	10336
1719.95	10330
1722	10278
1724.04	10444
1726.09	10316
1728.13	10384
1730.18	10400
1732.22	10294
1734.26	10282
1736.3	10220
1738.34	10306
1740.38	10206
1742.42	10264
1744.46	10224
1746.5	10066
1748.54	10182
1750.58	10138
1752.61	10158
1754.65	10112
1756.68	10030
1758.72	10244
1760.75	10168
1762.79	10202
1764.82	10100
1766.85	10060
1768.88	10018
1770.91	10094
1772.94	10152
1774.97	10008
1777	10116
1779.03	9976
1781.06	9948
1783.09	9996
1785.11	10100
1787.14	9884
1789.16	9974
1791.19	9932
1793.21	9894
1795.23	9892
1797.26	9932
1799.28	9798
1801.3	9866
1803.32	9818
1805.34	9864
1807.36	9750
1809.38	9826
1811.4	9688
1813.42	9776
1815.43	9760
1817.45	9738
1819.47	9692
1821.48	9708
1823.49	9696
1825.51	9536
1827.52	9596
1829.54	9812
1831.55	9690
1833.56	9686
1835.57	9620
1837.58	9456
1839.59	9598
1841.6	9608
1843.61	9462
1845.61	9498
1847.62	9340
1849.63	9384
1851.63	9418
1853.64	9340
1855.64	9406
1857.65	9402
1859.65	9466
1861.65	9404
1863.65	9196
1865.66	9196
1867.66	9252
1869.66	9292
1871.66	9324
1873.66	9240
1875.65	9266
1877.65	9202
1879.65	9284
1881.65	9144
1883.64	9104
1885.64	9296
1887.63	9272
1889.63	9234
1891.62	9044
1893.61	9098
1895.6	9084
1897.6	9036
1899.59	9116
1901.58	9134
1903.57	9192
1905.56	9154
1907.54	9146
1909.53	9102
1911.52	9008
1913.51	9118
1915.49	9090
1917.48	9092
1919.46	9076
1921.45	9100
1923.43	9096
1925.41	8978
1927.4	9108
1929.38	9036
1931.36	9062
1933.34	9048
1935.32	8882
1937.3	8956
1939.28	8868
1941.26	8938
1943.23	8820
1945.21	8870
1947.19	8838
1949.16	8936
1951.14	8916
1953.11	8850
1955.09	8858
1957.06	8930
1959.03	8846
1961	8874
1962.98	8836
1964.95	8714
1966.92	8702
1968.89	8770
1970.85	8692
1972.82	8714
1974.79	8692
1976.76	8630
1978.73	8600
1980.69	8660
1982.66	8688
1984.62	8792
1986.59	8724
1988.55	8604
1990.51	8656
1992.47	8624
1994.44	8542
1996.4	8548
1998.36	8558
2000.32	8576
2002.28	8530
2004.24	8522
2006.19	8504
2008.15	8690
2010.11	8432
2012.06	8620
2014.02	8584
2015.98	8398
2017.93	8558
2019.88	8638
2021.84	8494
2023.79	8510
2025.74	8448
2027.69	8486
2029.65	8440
2031.6	8468
2033.55	8326
2035.5	8434
2037.44	8424
2039.39	8352
2041.34	8438
2043.29	8344
2045.23	8352
2047.18	8336
2049.12	8368
2051.07	8270
2053.01	8396
2054.95	8354
2056.9	8246
2058.84	8370
2060.78	8184
2062.72	8238
2064.66	8190
2066.6	8306
2068.54	8278
2070.48	8154
2072.42	8250
2074.35	8222
2076.29	8202
2078.23	8156
2080.16	8128
2082.1	8166
2084.03	8080
2085.96	8124
2087.9	8186
2089.83	8094
2091.76	8148
2093.69	8076
2095.62	8114
2097.55	8052
2099.48	8038
2101.41	7962
2103.34	8000
2105.27	8022
2107.2	8068
2109.12	8056
2111.05	7964
2112.98	8004
2114.9	7880
2116.82	7912
2118.75	7968
2120.67	8016
2122.59	8048
2124.52	7882
2126.44	7942
2128.36	7920
2130.28	7940
2132.2	7916
2134.12	7842
2136.04	7962
2137.95	7886
2139.87	7954
2141.79	7936
2143.7	7810
2145.62	7823.01
2147.53	7821.15
2149.45	7782.35
2151.36	7632.09
2153.28	7794.54
2155.19	7721.95
2157.1	7721.11
2159.01	7675.94
2160.92	7645.17
2162.83	7637.66
2164.74	7672.44
2166.65	7607.06
2168.56	7603.97
2170.47	7616.67
2172.38	7608.18
2174.28	7609
2176.19	7604.45
2178.09	7577.95
2180	7506.34
2181.9	7552.45
2183.81	7516.18
2185.71	7477.52
2187.61	7453.47
2189.52	7514.74
2191.42	7455.35
2193.32	7419.16
2195.22	7421.36
2197.12	7439.46
2199.02	7446.93
2200.92	7374.04
2202.82	7387.17
2204.71	7353.79
2206.61	7484.46
2208.51	7483.54
2210.4	7345.91
2212.3	7359.7
2214.19	7334.83
2216.09	7316.28
2217.98	7375.03
2219.87	7309.05
2221.77	7295
2223.66	7370.03
2225.55	7357.04
2227.44	7350.98
2229.33	7391.41
2231.22	7388.82
2233.11	7310.21
2235	7367.7
2236.88	7363.56
2238.77	7312.01
2240.66	7374.23
2242.07	7330
2243.97	7248
2245.87	7456
2247.76	7390
2249.65	7374
2251.55	7386
2253.44	7382
2255.33	7296
2257.22	7340
2259.12	7420
2261.01	7216
2262.9	7278
2264.78	7246
2266.67	7252
2268.56	7290
2270.45	7286
2272.34	7302
2274.22	7238
2276.11	7324
2277.99	7266
2279.88	7132
2281.76	7210
2283.65	7122
2285.53	7298
2287.41	7148
2289.3	7150
2291.18	7240
2293.06	7108
2294.94	7040
2296.82	7040
2298.7	7118
2300.58	7118
2302.46	7014
2304.33	7050
2306.21	7088
2308.09	6942
2309.96	7100
2311.84	7056
2313.71	7052
2315.59	7126
2317.46	7020
2319.33	7048
2321.21	6928
2323.08	7032
2324.95	7074
2326.82	6930
2328.69	6896
2330.56	6916
2332.43	6912
2334.3	6868
2336.17	6848
2338.03	6940
2339.9	6872
2341.77	7024
2343.63	6816
2345.5	6872
2347.36	6936
2349.23	6820
2351.09	6856
2352.95	6824
2354.82	6850
2356.68	6940
2358.54	6882
2360.4	6882
2362.26	6746
2364.12	6930
2365.98	6692
2367.84	6816
2369.7	6834
2371.56	6754
2373.41	6778
2375.27	6786
2377.12	6754
2378.98	6686
2380.84	6772
2382.69	6722
2384.54	6660
2386.4	6650
2388.25	6636
2390.1	6750
2391.95	6694
2393.8	6654
2395.65	6674
2397.5	6620
2399.35	6648
2401.2	6668
2403.05	6588
2404.9	6586
2406.75	6564
2408.59	6634
2410.44	6568
2412.28	6570
2414.13	6570
2415.97	6552
2417.82	6542
2419.66	6554
2421.5	6490
2423.35	6484
2425.19	6502
2427.03	6482
2428.87	6384
2430.71	6388
2432.55	6414
2434.39	6518
2436.23	6364
2438.06	6318
2439.9	6428
2441.74	6394
2443.57	6390
2445.41	6358
2447.24	6398
2449.08	6304
2450.91	6342
2452.75	6180
2454.58	6316
2456.41	6278
2458.24	6230
2460.08	6244
2461.91	6284
2463.74	6230
2465.57	6298
2467.4	6288
2469.22	6198
2471.05	6256
2472.88	6182
2474.71	6252
2476.53	6138
2478.36	6192
2480.19	6110
2482.01	6230
2483.83	6130
2485.66	6182
2487.48	6046
2489.3	6260
2491.13	6060
2492.95	6096
2494.77	6080
2496.59	6110
2498.41	6062
2500.23	6074
2502.05	5942
2503.87	6024
2505.68	6038
2507.5	6060
2509.32	5960
2511.14	5986
2512.95	5900
2514.77	5942
2516.58	5954
2518.39	5930
2520.21	5916
2522.02	5986
2523.83	5796
2525.65	5912
2527.46	5842
2529.27	5770
2531.08	5890
2532.89	5800
2534.7	5746
2536.51	5740
2538.32	5766
2540.12	5720
2541.93	5772
2543.74	5696
2545.54	5750
2547.35	5640
2549.15	5670
2550.96	5600
2552.76	5608
2554.56	5714
2556.37	5652
2558.17	5654
2559.97	5640
2561.77	5628
2563.58	5596
2565.38	5592
2567.18	5578
2568.97	5420
2570.77	5554
2572.57	5456
2574.37	5520
2576.17	5524
2577.96	5520
2579.76	5458
2581.55	5406
2583.35	5482
2585.14	5418
2586.94	5368
2588.73	5438
2590.52	5466
2592.32	5330
2594.11	5366
2595.9	5358
2597.69	5326
2599.48	5310
2601.27	5338
2603.06	5308
2604.85	5294
2606.64	5338
2608.42	5384
2610.21	5224
2612	5200
2613.78	5194
2615.57	5178
2617.36	5216
2619.14	5162
2620.92	5212
2622.71	5190
2624.49	5178
2626.27	5184
2628.05	5176
2629.84	5128
2631.62	5042
2633.4	5084
2635.18	5092
2636.96	5040
2638.74	5126
2640.51	4988
2642.29	5018
2644.07	4924
2645.85	4974
2647.62	4896
2649.4	4916
2651.17	4974
2652.95	4922
2654.72	4918
2656.5	4896
2658.27	4886
2660.04	4962
2661.81	4842
2663.58	4942
2665.35	4852
2667.13	4836
2668.9	4864
2670.66	4848
2672.43	4788
2674.2	4834
2675.97	4794
2677.74	4874
2679.5	4980
2681.27	4688
2683.04	4788
2684.8	4782
2686.57	4748
2688.33	4748
2690.09	4760
2691.86	4716
2693.62	4680
2695.38	4670
2697.15	4706
2698.91	4712
2700.67	4694
2702.43	4580
2704.19	4676
2705.95	4574
2707.7	4566
2709.46	4612
2711.22	4594
2712.98	4542
2714.73	4510
2716.49	4570
2718.25	4538
2720	4506
2721.76	4516
2723.51	4556
2725.26	4494
2727.02	4482
2728.77	4474
2730.52	4446
2732.27	4474
2734.02	4464
2735.77	4412
2737.52	4380
2739.27	4420
2741.02	4340
2742.77	4342
2744.52	4334
2746.27	4288
2748.01	4294
2749.76	4338
2751.51	4360
2753.25	4318
2755	4282
2756.74	4276
2758.48	4266
2760.23	4182
2761.97	4254
2763.71	4242
2765.45	4180
2767.19	4216
2768.94	4160
2770.68	4192
2772.42	4152
2774.16	4128
2775.89	4070
2777.63	4168
2779.37	4090
2781.11	4112
2782.84	4134
2784.58	4010
2786.32	4072
2788.05	4006
2789.79	4010
2791.52	4098
2793.25	4002
2794.99	4066
2796.72	3970
2798.45	4004
2800.18	4026
2801.92	4052
2803.65	3988
2805.38	3972
2807.11	3936
2808.84	3940
2810.57	3926
2812.29	4008
2814.02	3900
2815.75	3894
2817.47	3846
2819.2	3914
2820.93	3868
2822.65	3788
2824.38	3838
2826.1	3828
2827.82	3860
2829.55	3852
2831.27	3714
2832.99	3778
2834.71	3792
2836.44	3718
2838.16	3752
2839.88	3694
2841.6	3782
2843.32	3724
2845.03	3622
2846.75	3672
2848.47	3728
2850.19	3720
2851.9	3610
2853.62	3678
2855.34	3600
2857.05	3654
2858.77	3548
2860.48	3616
2862.19	3556
2863.91	3598
2865.62	3528
2867.33	3570
2869.04	3560
2870.76	3540
2872.47	3540
2874.18	3482
2875.89	3498
2877.6	3460
2879.31	3390
2881.01	3394
2882.72	3526
2884.43	3444
2886.14	3424
2887.84	3368
2889.55	3462
2891.25	3340
2892.96	3474
2894.66	3456
2896.37	3368
2898.07	3428
2899.77	3324
2901.48	3304
2903.18	3376
2904.88	3390
2906.58	3300
2908.28	3368
2909.98	3276
2911.68	3328
2913.38	3300
2915.08	3296
2916.78	3280
2918.47	3236
2920.17	3324
2921.87	3324
2923.56	3278
2925.26	3246
2926.95	3354
2928.65	3252
2930.34	3226
2932.04	3286
2933.73	3228
2935.42	3184
2937.11	3204
2938.81	3230
2940.5	3214
2942.19	3174
2943.88	3190
2945.57	3186
2947.26	3138
2948.95	3138
2950.64	3126
2952.32	3150
2954.01	3122
2955.7	3166
2957.38	3124
2959.07	3126
2960.75	3122
2962.44	3154
2964.12	3050
2965.81	3106
2967.49	3020
2969.17	3126
2970.86	3058
2972.54	2970
2974.22	2946
2975.9	3016
2977.58	3024
2979.26	2988
2980.94	2994
2982.62	2954
2984.3	2940
2985.98	2944
2987.66	2914
2989.33	2974
2991.01	2872
2992.69	2892
2994.36	2886
2996.04	2940
2997.71	2914
2999.39	2954