File: muestras/tallo/2/Organic_01.txt
#Acq. time (s)=	10
#Accumulations=	1
#Range (cm-¹)=	100...3000
#Windows=	3
#Autofocus=	Off
#AutoExposure=	Off
#Spike filter=	Off
#Delay time (s)=	0
#Binning=	1
#Readout mode=	Signal
#DeNoise=	Off
#ICS correction=	Off
#Dark correction=	Off
#Inst. Process=	Off
#Instrument=	LabRAM HR Evol
#Detector=	Syncerity OE
#Objective=	x100_VIS
#Grating=	600 (500nm)
#ND Filter=	3.2%
#Laser=	633nm_Edge
#Hole=	100.021
#Range=	Visible
#Project=	Omar
#Sample=	26-06-23
#Site=	2
#Title=	Organic
#Remark=
#Date=	26.06.2023 16:16
#Acquired=	26.06.2023 16:16:04
101.018	4652
103.586	4610
106.152	4612
108.717	4668
111.281	4740
113.845	4684
116.407	4756
118.969	4670
121.53	4674
124.09	4758
126.649	4852
129.207	4780
131.765	4864
134.321	4842
136.877	4884
139.432	4886
141.985	4872
144.538	4806
147.09	4914
149.641	4996
152.191	4950
154.741	4960
157.289	4998
159.837	5030
162.385	5018
164.93	4990
167.476	5046
170.019	5066
172.562	5094
175.105	5050
177.646	5118
180.188	4984
182.727	5124
185.266	5070
187.804	5118
190.342	5202
192.878	5172
195.413	5196
197.948	5292
200.481	5284
203.014	5308
205.546	5342
208.077	5400
210.608	5374
213.137	5394
215.666	5426
218.194	5396
220.721	5454
223.247	5548
225.772	5524
228.295	5592
230.819	5544
233.342	5572
235.864	5574
238.384	5590
240.904	5634
243.423	5714
245.941	5716
248.46	5686
250.975	5658
253.492	5730
256.006	5794
258.519	5708
261.033	5774
263.545	5740
266.057	5834
268.567	5724
271.076	5688
273.585	5726
276.094	5802
278.601	5726
281.107	5764
283.612	5952
286.116	5978
288.62	5956
291.123	5928
293.625	5954
296.126	6024
298.626	6176
301.126	6168
303.625	6134
306.122	6096
308.62	6190
311.114	6142
313.61	6166
316.105	6298
318.599	6272
321.09	6330
323.583	6302
326.073	6270
328.563	6180
331.053	6314
333.541	6278
336.029	6388
338.515	6356
341.001	6364
343.486	6442
345.97	6378
348.453	6458
350.936	6468
353.418	6452
355.898	6560
358.378	6580
360.858	6646
363.336	6560
365.813	6618
368.29	6548
370.766	6676
373.241	6578
375.715	6640
378.188	6670
380.66	6596
383.132	6772
385.603	6672
388.072	6748
390.541	6786
393.01	6730
395.477	6808
397.943	6784
400.409	6846
402.875	6826
405.338	6878
407.802	6846
410.263	6890
412.725	6990
415.185	6984
417.646	7096
420.104	7136
422.564	7132
425.02	7258
427.477	7222
429.933	7282
432.388	7292
434.841	7358
437.294	7392
439.748	7464
442.199	7506
444.65	7354
447.1	7278
449.549	7372
451.997	7382
454.445	7414
456.891	7378
459.337	7442
461.782	7482
464.227	7528
466.669	7548
469.112	7514
471.554	7568
473.995	7630
476.434	7600
478.874	7638
481.312	7630
483.749	7638
486.186	7596
488.622	7770
491.057	7848
493.491	7808
495.925	7854
498.357	7962
500.789	7870
503.221	7966
505.65	8012
508.079	7946
510.509	7982
512.936	8078
515.363	8090
517.789	8120
520.214	8074
522.638	8250
525.062	8126
527.485	8170
529.907	8296
532.328	8142
534.748	8186
537.168	8042
539.587	8220
542.005	8302
544.423	8134
546.838	8330
549.254	8296
551.669	8376
554.082	8418
556.496	8376
558.909	8440
561.319	8390
563.731	8574
566.14	8610
568.549	8528
570.957	8564
573.364	8628
575.771	8560
578.177	8786
580.581	8748
582.987	8764
585.39	8788
587.792	8788
590.193	8810
592.594	8902
594.996	8842
597.395	8956
599.793	9048
602.191	8962
604.588	9084
606.984	9116
609.378	9212
611.773	9210
614.167	9342
616.56	9384
618.953	9356
621.343	9434
623.734	9456
626.124	9614
628.512	9638
630.901	9686
633.289	9710
635.675	9710
638.061	9864
640.446	9876
642.831	9972
645.213	10060
647.595	10074
649.978	10136
652.359	10102
654.738	10308
657.117	10296
659.497	10374
661.875	10146
664.252	10340
666.628	10344
669.003	10406
671.378	10520
673.751	10532
676.124	10656
678.497	10590
680.868	10616
683.239	10646
685.609	10720
687.977	10774
690.346	10836
692.714	10938
695.081	10998
697.446	10932
699.812	11042
702.175	10986
704.539	11062
706.901	11316
709.264	11288
711.625	11452
713.986	11492
716.345	11536
718.705	11560
721.062	11618
723.419	11752
725.775	11930
728.132	11778
730.487	11756
732.841	11960
735.194	11964
737.546	12024
739.898	12110
742.249	12112
744.599	12200
746.949	12224
749.298	12452
751.646	12446
753.993	12534
756.34	12588
758.684	12518
761.029	12538
763.374	12726
765.716	12752
768.059	12948
770.401	12952
772.741	13992
775.082	13146
777.421	13074
779.76	13234
782.097	13332
784.434	13166
786.771	13346
789.106	13574
791.44	13546
793.775	13650
796.108	13706
798.44	13774
800.771	13854
803.102	13954
805.432	14120
807.761	14196
810.09	14204
812.417	14436
814.744	14372
817.071	14546
819.396	14582
821.721	15022
824.045	14840
826.367	14934
828.69	15150
831.012	15284
833.332	15276
835.653	15374
837.972	15640
840.29	15558
842.609	15588
844.925	15846
847.242	15944
849.557	15950
851.871	16188
854.186	16176
856.498	16260
858.81	16424
861.122	16312
863.434	16568
865.744	16644
868.053	16780
870.361	16786
872.669	16954
874.976	16948
877.282	17110
879.588	17306
881.893	17228
884.197	17484
886.5	17342
888.802	17500
891.104	17540
893.405	17642
895.706	17626
898.004	17718
900.303	17886
902.6	17866
904.898	18076
907.194	18084
909.49	18158
911.785	18090
914.08	18388
916.372	18326
918.666	18384
920.957	18646
923.248	18644
925.538	18828
927.828	18878
930.118	19046
932.406	19198
934.693	19302
936.979	19158
939.265	19668
941.55	19608
943.835	19846
946.118	19880
948.401	20038
950.682	20018
952.964	20302
955.245	20442
957.525	20316
959.803	20564
962.082	20652
964.36	20742
966.636	20736
968.913	20898
971.188	20979
973.463	21040
975.736	21350
978.009	21398
980.282	21478
982.554	21390
984.824	21582
987.095	21648
989.364	21690
991.633	21920
993.9	21932
996.167	22104
998.434	22118
1000.7	22330
1002.96	22226
1005.23	22290
1007.49	22370
1009.76	22572
1012.02	22482
1014.28	22722
1016.54	22730
1018.8	22902
1021.06	22820
1023.32	23052
1025.57	23126
1027.83	23358
1030.09	23472
1032.34	23348
1034.6	23772
1036.85	23838
1039.1	23766
1041.35	23856
1043.61	24320
1045.86	24144
1048.11	24162
1050.36	24596
1052.61	24542
1054.85	24304
1057.1	24650
1059.35	24734
1061.59	24944
1063.84	24944
1066.08	24962
1068.33	25260
1070.57	25024
1072.81	25348
1075.05	25112
1077.29	25174
1079.53	25246
1081.77	25332
1084.01	25300
1086.25	25336
1088.48	25028
1090.72	25352
1092.96	25292
1095.19	25356
1097.43	25210
1099.66	25008
1101.89	25202
1104.12	25356
1106.35	25406
1108.59	25410
1110.81	25230
1113.04	25226
1115.27	25486
1117.5	25340
1119.73	25302
1121.95	25234
1124.18	25640
1126.4	25462
1128.63	25638
1130.85	25618
1133.07	25462
1135.29	25424
1137.51	25564
1139.73	25600
1141.95	25500
1144.17	25782
1146.39	25798
1148.61	25816
1150.82	25756
1153.04	25728
1155.26	25980
1157.47	25800
1159.68	25704
1161.9	25780
1164.11	25790
1166.32	25614
1168.53	25772
1170.74	25614
1172.95	25808
1175.16	25630
1177.37	25616
1179.58	25602
1181.78	25336
1183.99	25268
1186.19	25374
1188.4	25298
1190.6	25170
1192.8	25004
1195.01	25014
1197.21	25051.5
1199.41	24805.2
1201.61	24856.9
1203.81	24744.8
1206.01	24560.3
1208.2	24452.7
1210.4	24412.5
1212.6	24276.4
1214.8	24417.7
1216.99	24238.7
1219.18	24099.7
1221.38	24003.8
1223.57	23706.6
1225.76	23809.6
1227.96	23753.7
1230.15	23658.9
1232.34	23599.1
1234.53	23468.2
1236.71	23388.3
1238.9	23415.8
1241.09	23400.7
1243.28	23105.1
1245.46	23293.6
1247.65	23052
1249.83	23079.9
1252.02	23015.7
1254.2	22984
1256.38	22992.7
1258.56	22723.1
1260.74	22675.6
1262.92	22693.9
1265.1	22622.3
1267.28	22505.1
1269.46	22578.7
1271.64	22344.1
1273.82	22365.5
1275.99	22249.6
1278.17	22338.4
1280.34	22024.7
1282.52	22023.9
1284.69	21864.1
1286.86	21841.4
1289.03	21695.7
1291.21	21626.8
1293.38	21666.7
1295.55	21344.3
1297.71	21414.6
1299.88	21261.4
1302.05	21311.6
1304.22	20968.7
1306.38	21019
1308.43	20834
1310.61	20914
1312.78	20754
1314.96	20896
1317.13	20420
1319.3	20320
1321.48	20460
1323.65	20140
1325.82	20142
1327.99	20008
1330.16	19774
1332.33	19788
1334.5	19546
1336.66	19482
1338.83	19374
1341	19332
1343.16	19094
1345.33	18924
1347.49	18880
1349.65	18908
1351.82	18680
1353.98	18804
1356.14	18544
1358.3	18402
1360.46	18474
1362.62	18284
1364.78	18188
1366.94	18192
1369.09	17794
1371.25	17954
1373.41	17902
1375.56	17758
1377.72	17938
1379.87	17618
1382.02	17540
1384.17	17450
1386.33	17498
1388.48	17236
1390.63	17252
1392.78	17210
1394.93	17056
1397.07	16982
1399.22	16924
1401.37	16832
1403.52	16868
1405.66	16658
1407.81	16560
1409.95	16426
1412.09	16576
1414.24	16406
1416.38	16302
1418.52	16290
1420.66	16256
1422.8	16054
1424.94	15970
1427.08	16030
1429.22	15968
1431.35	15768
1433.49	15734
1435.63	15772
1437.76	15612
1439.9	15670
1442.03	15508
1444.17	15788
1446.3	15414
1448.43	15532
1450.56	15478
1452.69	15288
1454.82	15258
1456.95	15144
1459.08	15152
1461.21	15228
1463.34	15034
1465.46	15046
1467.59	15104
1469.71	14908
1471.84	14772
1473.96	14902
1476.08	14914
1478.21	14878
1480.33	14656
1482.45	14730
1484.57	14868
1486.69	14544
1488.81	14544
1490.93	14484
1493.05	14538
1495.16	14498
1497.28	14366
1499.4	14178
1501.51	14214
1503.63	14268
1505.74	14204
1507.85	14142
1509.97	14256
1512.08	14112
1514.19	13978
1516.3	14000
1518.41	13944
1520.52	13966
1522.63	13704
1524.73	13736
1526.84	13724
1528.95	13590
1531.06	13586
1533.16	13528
1535.26	13494
1537.37	13398
1539.47	13414
1541.57	13370
1543.68	13284
1545.78	13278
1547.88	13274
1549.98	13188
1552.08	12998
1554.18	13252
1556.27	12994
1558.37	13010
1560.47	13060
1562.56	12930
1564.66	12858
1566.75	12944
1568.85	12762
1570.94	12762
1573.03	12674
1575.13	12862
1577.22	12778
1579.31	12794
1581.4	12864
1583.49	12804
1585.58	12766
1587.66	12704
1589.75	12650
1591.84	12668
1593.93	12570
1596.01	12492
1598.1	12648
1600.18	12426
1602.26	12576
1604.35	12374
1606.43	12442
1608.51	12356
1610.59	12316
1612.67	12470
1614.75	12348
1616.83	12482
1618.91	12396
1620.99	12314
1623.06	12296
1625.14	12318
1627.21	12248
1629.29	12374
1631.36	12212
1633.44	12260
1635.51	12082
1637.58	12214
1639.66	12168
1641.73	12086
1643.8	12090
1645.87	12078
1647.94	12166
1650	11946
1652.07	12050
1654.14	11952
1656.21	11842
1658.27	11852
1660.34	11836
1662.4	11768
1664.47	11796
1666.53	11778
1668.59	11852
1670.66	11706
1672.72	11624
1674.78	11582
1676.84	11596
1678.9	11450
1680.96	11522
1683.01	11578
1685.07	11394
1687.13	11450
1689.19	11534
1691.24	11434
1693.3	11338
1695.35	11298
1697.4	11324
1699.46	11254
1701.51	11140
1703.56	11106
1705.61	11134
1707.66	11212
1709.71	11166
1711.76	11188
1713.81	10978
1715.86	11028
1717.91	11070
1719.95	10946
1722	11002
1724.04	11082
1726.09	11084
1728.13	10974
1730.18	10834
1732.22	10908
1734.26	10840
1736.3	10812
1738.34	10888
1740.38	10846
1742.42	10892
1744.46	10918
1746.5	10844
1748.54	10870
1750.58	10828
1752.61	10732
1754.65	10732
1756.68	10610
1758.72	10836
1760.75	10738
1762.79	10608
1764.82	10804
1766.85	10550
1768.88	10784
1770.91	10568
1772.94	10612
1774.97	10602
1777	10680
1779.03	10636
1781.06	10638
1783.09	10502
1785.11	10706
1787.14	10624
1789.16	10612
1791.19	10562
1793.21	10538
1795.23	10658
1797.26	10376
1799.28	10416
1801.3	10510
1803.32	10470
1805.34	10398
1807.36	10360
1809.38	10362
1811.4	10460
1813.42	10398
1815.43	10392
1817.45	10410
1819.47	10258
1821.48	10158
1823.49	10246
1825.51	10240
1827.52	10216
1829.54	10204
1831.55	10242
1833.56	10118
1835.57	10154
1837.58	10100
1839.59	10118
1841.6	10030
1843.61	10092
1845.61	10008
1847.62	9966
1849.63	10084
1851.63	9888
1853.64	9842
1855.64	10024
1857.65	10030
1859.65	9876
1861.65	9802
1863.65	9934
1865.66	9962
1867.66	9766
1869.66	9768
1871.66	9770
1873.66	9832
1875.65	9868
1877.65	9796
1879.65	9834
1881.65	9834
1883.64	9678
1885.64	9718
1887.63	9660
1889.63	9568
1891.62	9650
1893.61	9686
1895.6	9622
1897.6	9660
1899.59	9702
1901.58	9672
1903.57	9698
1905.56	9690
1907.54	9720
1909.53	9608
1911.52	9566
1913.51	9682
1915.49	9566
1917.48	9566
1919.46	9638
1921.45	9638
1923.43	9570
1925.41	9600
1927.4	9490
1929.38	9614
1931.36	9512
1933.34	9568
1935.32	9606
1937.3	9482
1939.28	9438
1941.26	9604
1943.23	9430
1945.21	9492
1947.19	9544
1949.16	9392
1951.14	9512
1953.11	9302
1955.09	9422
1957.06	9388
1959.03	9424
1961	9412
1962.98	9378
1964.95	9286
1966.92	9280
1968.89	9306
1970.85	9288
1972.82	9216
1974.79	9184
1976.76	9226
1978.73	9270
1980.69	9270
1982.66	9260
1984.62	9258
1986.59	9166
1988.55	9244
1990.51	9142
1992.47	9156
1994.44	8912
1996.4	9166
1998.36	9124
2000.32	9130
2002.28	9134
2004.24	9064
2006.19	9012
2008.15	9064
2010.11	9220
2012.06	9096
2014.02	9004
2015.98	9018
2017.93	9020
2019.88	9030
2021.84	8934
2023.79	8916
2025.74	8894
2027.69	8950
2029.65	8960
2031.6	9070
2033.55	8906
2035.5	9050
2037.44	8856
2039.39	8982
2041.34	9066
2043.29	8936
2045.23	8968
2047.18	8820
2049.12	8812
2051.07	9000
2053.01	8800
2054.95	8872
2056.9	8896
2058.84	8768
2060.78	8692
2062.72	8806
2064.66	8806
2066.6	8744
2068.54	8732
2070.48	8772
2072.42	8736
2074.35	8760
2076.29	8610
2078.23	8590
2080.16	8660
2082.1	8598
2084.03	8598
2085.96	8662
2087.9	8550
2089.83	8694
2091.76	8520
2093.69	8584
2095.62	8544
2097.55	8462
2099.48	8640
2101.41	8588
2103.34	8558
2105.27	8474
2107.2	8548
2109.12	8462
2111.05	8490
2112.98	8536
2114.9	8546
2116.82	8434
2118.75	8454
2120.67	8458
2122.59	8320
2124.52	8428
2126.44	8302
2128.36	8420
2130.28	8398
2132.2	8316
2134.12	8334
2136.04	8356
2137.95	8420
2139.87	8290
2141.79	8320
2143.7	8208
2145.62	8219.57
2147.53	8225.65
2149.45	8191.6
2151.36	8126.96
2153.28	8149.2
2155.19	8212.41
2157.1	8196.19
2159.01	8066
2160.92	8151.69
2162.83	8097.28
2164.74	8119.41
2166.65	8050.76
2168.56	8016
2170.47	8098.42
2172.38	8046.42
2174.28	8043.17
2176.19	8001.34
2178.09	8035.14
2180	7973.34
2181.9	7962.51
2183.81	7945.21
2185.71	7979.21
2187.61	7880.87
2189.52	7966.38
2191.42	7880.62
2193.32	7946.55
2195.22	7953.08
2197.12	7868.52
2199.02	7837.18
2200.92	7883.02
2202.82	7834.11
2204.71	7842.53
2206.61	7835.01
2208.51	7806.32
2210.4	7794.14
2212.3	7781.97
2214.19	7795.29
2216.09	7727.38
2217.98	7780.37
2219.87	7794.72
2221.77	7808.06
2223.66	7744.64
2225.55	7705.35
2227.44	7775.64
2229.33	7778.62
2231.22	7766.12
2233.11	7772.52
2235	7771.37
2236.88	7795.23
2238.77	7751.37
2240.66	7787.34
2242.07	7828
2243.97	7780
2245.87	7904
2247.76	7836
2249.65	7768
2251.55	7720
2253.44	7826
2255.33	7764
2257.22	7658
2259.12	7754
2261.01	7678
2262.9	7766
2264.78	7696
2266.67	7616
2268.56	7604
2270.45	7548
2272.34	7652
2274.22	7608
2276.11	7534
2277.99	7566
2279.88	7606
2281.76	7606
2283.65	7614
2285.53	7638
2287.41	7596
2289.3	7436
2291.18	7570
2293.06	7558
2294.94	7540
2296.82	7700
2298.7	7536
2300.58	7396
2302.46	7476
2304.33	7400
2306.21	7510
2308.09	7504
2309.96	7446
2311.84	7422
2313.71	7336
2315.59	7394
2317.46	7416
2319.33	7348
2321.21	7402
2323.08	7258
2324.95	7254
2326.82	7262
2328.69	7262
2330.56	7294
2332.43	7316
2334.3	7268
2336.17	7284
2338.03	7262
2339.9	7380
2341.77	7288
2343.63	7350
2345.5	7176
2347.36	7386
2349.23	7158
2351.09	7228
2352.95	7222
2354.82	7214
2356.68	7134
2358.54	7228
2360.4	7148
2362.26	7144
2364.12	7030
2365.98	7186
2367.84	7094
2369.7	7188
2371.56	7116
2373.41	7082
2375.27	7076
2377.12	7188
2378.98	7058
2380.84	7100
2382.69	7102
2384.54	6988
2386.4	7016
2388.25	7082
2390.1	7016
2391.95	7026
2393.8	6946
2395.65	6952
2397.5	6948
2399.35	6992
2401.2	6958
2403.05	6876
2404.9	6928
2406.75	6874
2408.59	6916
2410.44	6946
2412.28	6854
2414.13	6856
2415.97	6784
2417.82	6884
2419.66	6866
2421.5	6828
2423.35	6796
2425.19	6792
2427.03	6816
2428.87	6692
2430.71	6774
2432.55	6712
2434.39	6738
2436.23	6614
2438.06	6708
2439.9	6736
2441.74	6628
2443.57	6744
2445.41	6778
2447.24	6612
2449.08	6630
2450.91	6636
2452.75	6564
2454.58	6680
2456.41	6738
2458.24	6614
2460.08	6650
2461.91	6612
2463.74	6506
2465.57	6570
2467.4	6536
2469.22	6496
2471.05	6588
2472.88	6536
2474.71	6528
2476.53	6506
2478.36	6480
2480.19	6438
2482.01	6458
2483.83	6414
2485.66	6426
2487.48	6450
2489.3	6382
2491.13	6462
2492.95	6356
2494.77	6310
2496.59	6326
2498.41	6266
2500.23	6340
2502.05	6262
2503.87	6334
2505.68	6256
2507.5	6286
2509.32	6176
2511.14	6216
2512.95	6300
2514.77	6216
2516.58	6206
2518.39	6192
2520.21	6162
2522.02	6224
2523.83	6236
2525.65	6174
2527.46	6024
2529.27	6128
2531.08	6150
2532.89	6122
2534.7	6080
2536.51	6094
2538.32	6038
2540.12	6120
2541.93	6026
2543.74	5934
2545.54	5926
2547.35	5866
2549.15	5920
2550.96	5926
2552.76	5954
2554.56	5956
2556.37	6038
2558.17	5902
2559.97	5868
2561.77	5900
2563.58	5816
2565.38	5904
2567.18	5806
2568.97	5876
2570.77	5850
2572.57	5788
2574.37	5828
2576.17	5778
2577.96	5784
2579.76	5792
2581.55	5842
2583.35	5646
2585.14	5718
2586.94	5584
2588.73	5744
2590.52	5634
2592.32	5646
2594.11	5696
2595.9	5700
2597.69	5638
2599.48	5670
2601.27	5568
2603.06	5468
2604.85	5536
2606.64	5552
2608.42	5504
2610.21	5466
2612	5450
2613.78	5514
2615.57	5482
2617.36	5440
2619.14	5518
2620.92	5434
2622.71	5424
2624.49	5446
2626.27	5330
2628.05	5474
2629.84	5398
2631.62	5408
2633.4	5326
2635.18	5258
2636.96	5212
2638.74	5240
2640.51	5248
2642.29	5282
2644.07	5234
2645.85	5210
2647.62	5190
2649.4	5240
2651.17	5226
2652.95	5138
2654.72	5158
2656.5	5140
2658.27	5172
2660.04	5160
2661.81	5162
2663.58	5072
2665.35	5132
2667.13	5072
2668.9	5066
2670.66	5170
2672.43	5034
2674.2	5166
2675.97	5116
2677.74	5006
2679.5	5080
2681.27	5012
2683.04	5074
2684.8	5036
2686.57	5070
2688.33	5046
2690.09	4996
2691.86	5034
2693.62	4754
2695.38	4892
2697.15	4914
2698.91	4904
2700.67	4952
2702.43	4808
2704.19	4940
2705.95	4818
2707.7	4828
2709.46	4848
2711.22	4790
2712.98	4738
2714.73	4858
2716.49	4794
2718.25	4832
2720	4750
2721.76	4684
2723.51	4774
2725.26	4756
2727.02	4638
2728.77	4590
2730.52	4584
2732.27	4676
2734.02	4618
2735.77	4628
2737.52	4718
2739.27	4610
2741.02	4634
2742.77	4516
2744.52	4512
2746.27	4558
2748.01	4462
2749.76	4572
2751.51	4580
2753.25	4444
2755	4488
2756.74	4356
2758.48	4490
2760.23	4492
2761.97	4524
2763.71	4364
2765.45	4416
2767.19	4352
2768.94	4402
2770.68	4330
2772.42	4344
2774.16	4352
2775.89	4334
2777.63	4324
2779.37	4330
2781.11	4294
2782.84	4408
2784.58	4234
2786.32	4256
2788.05	4210
2789.79	4266
2791.52	4250
2793.25	4182
2794.99	4234
2796.72	4236
2798.45	4142
2800.18	4202
2801.92	4080
2803.65	4087
2805.38	4110
2807.11	4110
2808.84	4150
2810.57	4154
2812.29	4104
2814.02	4076
2815.75	4156
2817.47	4024
2819.2	4064
2820.93	4036
2822.65	3998
2824.38	4024
2826.1	3954
2827.82	3994
2829.55	4006
2831.27	4000
2832.99	3948
2834.71	3970
2836.44	3928
2838.16	3984
2839.88	3928
2841.6	3888
2843.32	3914
2845.03	3894
2846.75	3908
2848.47	3826
2850.19	3808
2851.9	3808
2853.62	3820
2855.34	3892
2857.05	3764
2858.77	3792
2860.48	3750
2862.19	3756
2863.91	3672
2865.62	3750
2867.33	3688
2869.04	3738
2870.76	3710
2872.47	3724
2874.18	3662
2875.89	3720
2877.6	3690
2879.31	3680
2881.01	3650
2882.72	3644
2884.43	3598
2886.14	3612
2887.84	3548
2889.55	3530
2891.25	3564
2892.96	3480
2894.66	3558
2896.37	3584
2898.07	3532
2899.77	3600
2901.48	3544
2903.18	3564
2904.88	3550
2906.58	3598
2908.28	3508
2909.98	3420
2911.68	3492
2913.38	3444
2915.08	3512
2916.78	3470
2918.47	3458
2920.17	3432
2921.87	3506
2923.56	3412
2925.26	3426
2926.95	3394
2928.65	3412
2930.34	3406
2932.04	3372
2933.73	3402
2935.42	3462
2937.11	3346
2938.81	3392
2940.5	3388
2942.19	3362
2943.88	3304
2945.57	3350
2947.26	3330
2948.95	3312
2950.64	3358
2952.32	3322
2954.01	3294
2955.7	3310
2957.38	3292
2959.07	3228
2960.75	3298
2962.44	3272
2964.12	3272
2965.81	3188
2967.49	3250
2969.17	3188
2970.86	3188
2972.54	3196
2974.22	3202
2975.9	3160
2977.58	3152
2979.26	3122
2980.94	3140
2982.62	3134
2984.3	3182
2985.98	3118
2987.66	3130
2989.33	3058
2991.01	3154
2992.69	3058
2994.36	3060
2996.04	3058
2997.71	3100
2999.39	2968