File: muestras/tallo/2/Organic_20.txt
#Acq. time (s)=	10
#Accumulations=	1
#Range (cm-¹)=	100...3000
#Windows=	3
#Autofocus=	Off
#AutoExposure=	Off
#Spike filter=	Off
#Delay time (s)=	0
#Binning=	1
#Readout mode=	Signal
#DeNoise=	Off
#ICS correction=	Off
#Dark correction=	Off
#Inst. Process=	Off
#Instrument=	LabRAM HR Evol
#Detector=	Syncerity OE
#Objective=	x100_VIS
#Grating=	600 (500nm)
#ND Filter=	3.2%
#Laser=	633nm_Edge
#Hole=	100.021
#Range=	Visible
#Project=	Omar
#Sample=	26-06-23
#Site=	2
#Title=	Organic
#Remark=
#Date=	26.06.2023 16:34
#Acquired=	26.06.2023 16:34:20
101.018	3522
103.586	3474
106.152	3492
108.717	3568
111.281	3580
113.845	3582
116.407	3472
118.969	3584
121.53	3624
124.09	3646
126.649	3594
129.207	3622
131.765	3642
134.321	3652
136.877	3636
139.432	3678
141.985	3728
144.538	3678
147.09	3792
149.641	3780
152.191	3764
154.741	3684
157.289	3774
159.837	3742
162.385	3820
164.93	3840
167.476	3838
170.019	3788
172.562	3734
175.105	3764
177.646	3862
180.188	3822
182.727	3878
185.266	3868
187.804	3828
190.342	3888
192.878	3908
195.413	3894
197.948	3986
200.481	3970
203.014	3974
205.546	4048
208.077	3978
210.608	4096
213.137	4034
215.666	3990
218.194	4148
220.721	4020
223.247	4142
225.772	4168
228.295	4134
230.819	4126
233.342	4174
235.864	4192
238.384	4236
240.904	4222
243.423	4218
245.941	4166
248.46	4246
250.975	4232
253.492	4290
256.006	4278
258.519	4204
261.033	4204
263.545	4312
266.057	4290
268.567	4368
271.076	4354
273.585	4364
276.094	4294
278.601	4360
281.107	4312
283.612	4336
286.116	4374
288.62	4426
291.123	4486
293.625	4488
296.126	4474
298.626	4520
301.126	4558
303.625	4562
306.122	4660
308.62	4582
311.114	4600
313.61	4650
316.105	4570
318.599	4614
321.09	4634
323.583	4650
326.073	4608
328.563	4722
331.053	4664
333.541	4688
336.029	4720
338.515	4684
341.001	4750
343.486	4734
345.97	4690
348.453	4764
350.936	4820
353.418	4812
355.898	4828
358.378	4798
360.858	4882
363.336	4908
365.813	4900
368.29	4824
370.766	4930
373.241	4804
375.715	4946
378.188	4856
380.66	4826
383.132	4900
385.603	4902
388.072	4968
390.541	4952
393.01	4930
395.477	4970
397.943	4906
400.409	4956
402.875	4968
405.338	5128
407.802	5090
410.263	5130
412.725	5124
415.185	5146
417.646	5164
420.104	5308
422.564	5232
425.02	5348
427.477	5226
429.933	5290
432.388	5440
434.841	5322
437.294	5320
439.748	5456
442.199	5470
444.65	5412
447.1	5398
449.549	5440
451.997	5436
454.445	5454
456.891	5490
459.337	5410
461.782	5448
464.227	5472
466.669	5496
469.112	5488
471.554	5542
473.995	5566
476.434	5494
478.874	5546
481.312	5612
483.749	5616
486.186	5610
488.622	5612
491.057	5734
493.491	5620
495.925	5788
498.357	5706
500.789	5696
503.221	5804
505.65	5736
508.079	5756
510.509	5840
512.936	5852
515.363	5814
517.789	5804
520.214	5918
522.638	5820
525.062	5738
527.485	5886
529.907	5854
532.328	5928
534.748	5830
537.168	5864
539.587	5812
542.005	5842
544.423	5952
546.838	5976
549.254	6036
551.669	5966
554.082	6030
556.496	5956
558.909	6050
561.319	5908
563.731	6062
566.14	6080
568.549	6070
570.957	6044
573.364	6228
575.771	6074
578.177	6212
580.581	6158
582.987	6092
585.39	6270
587.792	6274
590.193	6234
592.594	6340
594.996	6378
597.395	6336
599.793	6314
602.191	6474
604.588	6420
606.984	6466
609.378	6510
611.773	6518
614.167	6574
616.56	6430
618.953	6660
621.343	6676
623.734	6658
626.124	6632
628.512	6732
630.901	6780
633.289	6820
635.675	6834
638.061	6876
640.446	6888
642.831	6940
645.213	6996
647.595	7082
649.978	7116
652.359	7126
654.738	7070
657.117	7144
659.497	7054
661.875	7200
664.252	7274
666.628	7208
669.003	7174
671.378	7264
673.751	7258
676.124	7286
678.497	7230
680.868	7452
683.239	7420
685.609	7400
687.977	7448
690.346	7466
692.714	7476
695.081	7530
697.446	7536
699.812	7544
702.175	7600
704.539	7592
706.901	7654
709.264	7680
711.625	7746
713.986	7734
716.345	7888
718.705	7776
721.062	7884
723.419	7964
725.775	8024
728.132	7986
730.487	8094
732.841	8118
735.194	8126
737.546	8212
739.898	8206
742.249	8242
744.599	8366
746.949	8370
749.298	8404
751.646	8304
753.993	8496
756.34	8352
758.684	8450
761.029	8512
763.374	8454
765.716	8396
768.059	8616
770.401	8618
772.741	8770
775.082	8734
777.421	8820
779.76	8678
782.097	8866
784.434	8958
786.771	8836
789.106	8964
791.44	9052
793.775	9036
796.108	9082
798.44	9182
800.771	9166
803.102	9218
805.432	9202
807.761	9408
810.09	9398
812.417	9472
814.744	9500
817.071	9696
819.396	9628
821.721	9692
824.045	9762
826.367	9786
828.69	10000
831.012	10084
833.332	10056
835.653	10014
837.972	10090
840.29	10256
842.609	10250
844.925	10202
847.242	10392
849.557	10378
851.871	10482
854.186	10492
856.498	10616
858.81	10682
861.122	10702
863.434	10858
865.744	10840
868.053	10894
870.361	10884
872.669	10966
874.976	10930
877.282	10954
879.588	11128
881.893	11024
884.197	11020
886.5	11212
888.802	11254
891.104	11294
893.405	11314
895.706	11424
898.004	11414
900.303	11508
902.6	11536
904.898	11562
907.194	11720
909.49	11564
911.785	11664
914.08	11670
916.372	11748
918.666	11806
920.957	12016
923.248	11928
925.538	11926
927.828	11952
930.118	12094
932.406	12188
934.693	12226
936.979	12404
939.265	12496
941.55	12608
943.835	12610
946.118	12734
948.401	12666
950.682	12826
952.964	12864
955.245	12740
957.525	12956
959.803	13112
962.082	13122
964.36	13148
966.636	13304
968.913	13392
971.188	13381
973.463	13502
975.736	13404
978.009	13666
980.282	13466
982.554	13720
984.824	13600
987.095	13796
989.364	13730
991.633	13844
993.9	13994
996.167	13964
998.434	14018
1000.7	14138
1002.96	14240
1005.23	14104
1007.49	14142
1009.76	14238
1012.02	14412
1014.28	14342
1016.54	14492
1018.8	14350
1021.06	14638
1023.32	14654
1025.57	14542
1027.83	14738
1030.09	14726
1032.34	14970
1034.6	14872
1036.85	15000
1039.1	15228
1041.35	15384
1043.61	15208
1045.86	15216
1048.11	15414
1050.36	15384
1052.61	15508
1054.85	15604
1057.1	15574
1059.35	15620
1061.59	15602
1063.84	15602
1066.08	15832
1068.33	15786
1070.57	15824
1072.81	15834
1075.05	16034
1077.29	15848
1079.53	16082
1081.77	16142
1084.01	16018
1086.25	15810
1088.48	16056
1090.72	15988
1092.96	15932
1095.19	16020
1097.43	16030
1099.66	16050
1101.89	15976
1104.12	16024
1106.35	16114
1108.59	16108
1110.81	15902
1113.04	15870
1115.27	16066
1117.5	16020
1119.73	16174
1121.95	16048
1124.18	16430
1126.4	16298
1128.63	16018
1130.85	16194
1133.07	16214
1135.29	16186
1137.51	16260
1139.73	16320
1141.95	16248
1144.17	16344
1146.39	16262
1148.61	16482
1150.82	16482
1153.04	16424
1155.26	16550
1157.47	16502
1159.68	16454
1161.9	16478
1164.11	16424
1166.32	16492
1168.53	16416
1170.74	16378
1172.95	16434
1175.16	16502
1177.37	16284
1179.58	16468
1181.78	16284
1183.99	16254
1186.19	16284
1188.4	16202
1190.6	16142
1192.8	16122
1195.01	16076
1197.21	16193.7
1199.41	16016
1201.61	15842.6
1203.81	15908.6
1206.01	15783.9
1208.2	15763.1
1210.4	15698.4
1212.6	15710.1
1214.8	15650.3
1216.99	15452.7
1219.18	15442.9
1221.38	15364.3
1223.57	15369.1
1225.76	15304.7
1227.96	15265.2
1230.15	15299.7
1232.34	15201.6
1234.53	15178.4
1236.71	15214.1
1238.9	15140.4
1241.09	15133
1243.28	15108.8
1245.46	14901.5
1247.65	14931.5
1249.83	14926.6
1252.02	14900.8
1254.2	14848.8
1256.38	14890.4
1258.56	14729
1260.74	14745.7
1262.92	14681.4
1265.1	14663.3
1267.28	14652.1
1269.46	14619.8
1271.64	14509.4
1273.82	14476.4
1275.99	14546.8
1278.17	14423.2
1280.34	14387.6
1282.52	14439.9
1284.69	14359.1
1286.86	14291.8
1289.03	14359.5
1291.21	14199.8
1293.38	14171.1
1295.55	13997.8
1297.71	14032.9
1299.88	13941
1302.05	13971.4
1304.22	13810.6
1306.38	13943.2
1308.43	13832
1310.61	13780
1312.78	13728
1314.96	13598
1317.13	13516
1319.3	13540
1321.48	13388
1323.65	13186
1325.82	13244
1327.99	13234
1330.16	13006
1332.33	13068
1334.5	12934
1336.66	12970
1338.83	12808
1341	12820
1343.16	12748
1345.33	12654
1347.49	12610
1349.65	12474
1351.82	12542
1353.98	12318
1356.14	12416
1358.3	12454
1360.46	12338
1362.62	12210
1364.78	12312
1366.94	12098
1369.09	12068
1371.25	12008
1373.41	12028
1375.56	11948
1377.72	12030
1379.87	11762
1382.02	11884
1384.17	11758
1386.33	11764
1388.48	11538
1390.63	11616
1392.78	11638
1394.93	11604
1397.07	11442
1399.22	11430
1401.37	11384
1403.52	11372
1405.66	11322
1407.81	11264
1409.95	11168
1412.09	11238
1414.24	11084
1416.38	11080
1418.52	11020
1420.66	11166
1422.8	10906
1424.94	11040
1427.08	10964
1429.22	10714
1431.35	10922
1433.49	10816
1435.63	10730
1437.76	10672
1439.9	10702
1442.03	10732
1444.17	10488
1446.3	10700
1448.43	10618
1450.56	10538
1452.69	10458
1454.82	10452
1456.95	10490
1459.08	10640
1461.21	10366
1463.34	10390
1465.46	10334
1467.59	10372
1469.71	10296
1471.84	10340
1473.96	10262
1476.08	10268
1478.21	10214
1480.33	10290
1482.45	10134
1484.57	10112
1486.69	10162
1488.81	10146
1490.93	10108
1493.05	10004
1495.16	10182
1497.28	9996
1499.4	9916
1501.51	10022
1503.63	9910
1505.74	9854
1507.85	9788
1509.97	9854
1512.08	9806
1514.19	9750
1516.3	9708
1518.41	9700
1520.52	9654
1522.63	9652
1524.73	9736
1526.84	9662
1528.95	9478
1531.06	9440
1533.16	9564
1535.26	9526
1537.37	9460
1539.47	9436
1541.57	9398
1543.68	9326
1545.78	9344
1547.88	9200
1549.98	9238
1552.08	9248
1554.18	9170
1556.27	9130
1558.37	9242
1560.47	9170
1562.56	9212
1564.66	9052
1566.75	9132
1568.85	9184
1570.94	9110
1573.03	9106
1575.13	9072
1577.22	9030
1579.31	9208
1581.4	8968
1583.49	8994
1585.58	8932
1587.66	8930
1589.75	8984
1591.84	8964
1593.93	8996
1596.01	8958
1598.1	8946
1600.18	8750
1602.26	8862
1604.35	8960
1606.43	8894
1608.51	8816
1610.59	8894
1612.67	8876
1614.75	8770
1616.83	8846
1618.91	8732
1620.99	8764
1623.06	8830
1625.14	8784
1627.21	8630
1629.29	8794
1631.36	8586
1633.44	8684
1635.51	8766
1637.58	8650
1639.66	8634
1641.73	8592
1643.8	8608
1645.87	8726
1647.94	8642
1650	8572
1652.07	8556
1654.14	8448
1656.21	8494
1658.27	8588
1660.34	8416
1662.4	8490
1664.47	8304
1666.53	8404
1668.59	8426
1670.66	8338
1672.72	8256
1674.78	8242
1676.84	8388
1678.9	8242
1680.96	8296
1683.01	8100
1685.07	8278
1687.13	8270
1689.19	7982
1691.24	8122
1693.3	8174
1695.35	8122
1697.4	8114
1699.46	8144
1701.51	7976
1703.56	8024
1705.61	8006
1707.66	7992
1709.71	8044
1711.76	8018
1713.81	7944
1715.86	8000
1717.91	7890
1719.95	7880
1722	7940
1724.04	7938
1726.09	7872
1728.13	7854
1730.18	7834
1732.22	7840
1734.26	7750
1736.3	7764
1738.34	7890
1740.38	7854
1742.42	7748
1744.46	7716
1746.5	7708
1748.54	7702
1750.58	7726
1752.61	7708
1754.65	7818
1756.68	7644
1758.72	7744
1760.75	7810
1762.79	7724
1764.82	7624
1766.85	7772
1768.88	7666
1770.91	7650
1772.94	7606
1774.97	7690
1777	7620
1779.03	7644
1781.06	7642
1783.09	7594
1785.11	7544
1787.14	7692
1789.16	7558
1791.19	7628
1793.21	7592
1795.23	7530
1797.26	7524
1799.28	7458
1801.3	7508
1803.32	7496
1805.34	7550
1807.36	7456
1809.38	7492
1811.4	7414
1813.42	7348
1815.43	7498
1817.45	7410
1819.47	7550
1821.48	7312
1823.49	7384
1825.51	7416
1827.52	7472
1829.54	7354
1831.55	7378
1833.56	7226
1835.57	7144
1837.58	7292
1839.59	7360
1841.6	7226
1843.61	7266
1845.61	7266
1847.62	7156
1849.63	7194
1851.63	7244
1853.64	7294
1855.64	7170
1857.65	7144
1859.65	7014
1861.65	7152
1863.65	7024
1865.66	7220
1867.66	7046
1869.66	7090
1871.66	7080
1873.66	7082
1875.65	7174
1877.65	7096
1879.65	6942
1881.65	7008
1883.64	6916
1885.64	6956
1887.63	6918
1889.63	6910
1891.62	6976
1893.61	6986
1895.6	7010
1897.6	6968
1899.59	6964
1901.58	6966
1903.57	6858
1905.56	6938
1907.54	6942
1909.53	6978
1911.52	6942
1913.51	6814
1915.49	6954
1917.48	6962
1919.46	6970
1921.45	6888
1923.43	6768
1925.41	6822
1927.4	6906
1929.38	6848
1931.36	6842
1933.34	6816
1935.32	6894
1937.3	6926
1939.28	6824
1941.26	6782
1943.23	6848
1945.21	6794
1947.19	6732
1949.16	6878
1951.14	6750
1953.11	6836
1955.09	6742
1957.06	6758
1959.03	6748
1961	6704
1962.98	6734
1964.95	6730
1966.92	6698
1968.89	6634
1970.85	6638
1972.82	6746
1974.79	6504
1976.76	6654
1978.73	6598
1980.69	6660
1982.66	6574
1984.62	6514
1986.59	6672
1988.55	6602
1990.51	6584
1992.47	6530
1994.44	6604
1996.4	6568
1998.36	6616
2000.32	6468
2002.28	6558
2004.24	6474
2006.19	6572
2008.15	6466
2010.11	6434
2012.06	6514
2014.02	6442
2015.98	6482
2017.93	6372
2019.88	6384
2021.84	6416
2023.79	6402
2025.74	6444
2027.69	6472
2029.65	6450
2031.6	6478
2033.55	6382
2035.5	6462
2037.44	6304
2039.39	6380
2041.34	6328
2043.29	6324
2045.23	6372
2047.18	6350
2049.12	6380
2051.07	6316
2053.01	6242
2054.95	6310
2056.9	6206
2058.84	6222
2060.78	6304
2062.72	6224
2064.66	6268
2066.6	6272
2068.54	6310
2070.48	6228
2072.42	6254
2074.35	6208
2076.29	6226
2078.23	6212
2080.16	6228
2082.1	6096
2084.03	6152
2085.96	6162
2087.9	6190
2089.83	6088
2091.76	6172
2093.69	6124
2095.62	6134
2097.55	6156
2099.48	6036
2101.41	6072
2103.34	6040
2105.27	6100
2107.2	5970
2109.12	6112
2111.05	6068
2112.98	6026
2114.9	5996
2116.82	6106
2118.75	5992
2120.67	6010
2122.59	5942
2124.52	6010
2126.44	5944
2128.36	6074
2130.28	6050
2132.2	5918
2134.12	5994
2136.04	6026
2137.95	5846
2139.87	5900
2141.79	5972
2143.7	5856
2145.62	5939.42
2147.53	5762.75
2149.45	5838.01
2151.36	5854.94
2153.28	5772.18
2155.19	5827.64
2157.1	5870.21
2159.01	5875.21
2160.92	5703.59
2162.83	5719.05
2164.74	5692.11
2166.65	5834.35
2168.56	5824.66
2170.47	5787.83
2172.38	5722.85
2174.28	5813.32
2176.19	5641.93
2178.09	5708.87
2180	5653.04
2181.9	5705.54
2183.81	5707.62
2185.71	5677.17
2187.61	5688.1
2189.52	5642.92
2191.42	5645.27
2193.32	5676.65
2195.22	5611.46
2197.12	5611.94
2199.02	5583.51
2200.92	5594.97
2202.82	5607.24
2204.71	5595.7
2206.61	5573.52
2208.51	5540.18
2210.4	5636.59
2212.3	5578.69
2214.19	5538.72
2216.09	5596.95
2217.98	5571.71
2219.87	5589.77
2221.77	5615.8
2223.66	5575.7
2225.55	5593.12
2227.44	5576.28
2229.33	5581.65
2231.22	5588.9
2233.11	5560.54
2235	5570.64
2236.88	5608.89
2238.77	5605.45
2240.66	5573.01
2242.07	5662
2243.97	5628
2245.87	5610
2247.76	5540
2249.65	5570
2251.55	5564
2253.44	5520
2255.33	5486
2257.22	5494
2259.12	5534
2261.01	5540
2262.9	5520
2264.78	5464
2266.67	5522
2268.56	5476
2270.45	5506
2272.34	5418
2274.22	5460
2276.11	5562
2277.99	5518
2279.88	5502
2281.76	5484
2283.65	5526
2285.53	5490
2287.41	5442
2289.3	5352
2291.18	5512
2293.06	5424
2294.94	5422
2296.82	5342
2298.7	5366
2300.58	5374
2302.46	5346
2304.33	5386
2306.21	5256
2308.09	5438
2309.96	5358
2311.84	5248
2313.71	5354
2315.59	5288
2317.46	5342
2319.33	5308
2321.21	5342
2323.08	5356
2324.95	5168
2326.82	5266
2328.69	5234
2330.56	5272
2332.43	5356
2334.3	5220
2336.17	5380
2338.03	5228
2339.9	5298
2341.77	5192
2343.63	5234
2345.5	5260
2347.36	5152
2349.23	5156
2351.09	5140
2352.95	5166
2354.82	5232
2356.68	5252
2358.54	5170
2360.4	5164
2362.26	5234
2364.12	5084
2365.98	5254
2367.84	5192
2369.7	5190
2371.56	5164
2373.41	5192
2375.27	5146
2377.12	5192
2378.98	5154
2380.84	5110
2382.69	5172
2384.54	5122
2386.4	5122
2388.25	5040
2390.1	5094
2391.95	5016
2393.8	5062
2395.65	5000
2397.5	5010
2399.35	5044
2401.2	4898
2403.05	5086
2404.9	4994
2406.75	4964
2408.59	4970
2410.44	4966
2412.28	5050
2414.13	4900
2415.97	5018
2417.82	4936
2419.66	4930
2421.5	4970
2423.35	4892
2425.19	4918
2427.03	4834
2428.87	4914
2430.71	4894
2432.55	4872
2434.39	4830
2436.23	4890
2438.06	4816
2439.9	4978
2441.74	4842
2443.57	4838
2445.41	4862
2447.24	4758
2449.08	4844
2450.91	4836
2452.75	4812
2454.58	4808
2456.41	4746
2458.24	4802
2460.08	4864
2461.91	4852
2463.74	4694
2465.57	4848
2467.4	4698
2469.22	4782
2471.05	4780
2472.88	4700
2474.71	4692
2476.53	4730
2478.36	4640
2480.19	4698
2482.01	4768
2483.83	4646
2485.66	4592
2487.48	4636
2489.3	4652
2491.13	4570
2492.95	4646
2494.77	4728
2496.59	4574
2498.41	4558
2500.23	4574
2502.05	4554
2503.87	4540
2505.68	4508
2507.5	4508
2509.32	4556
2511.14	4480
2512.95	4424
2514.77	4504
2516.58	4450
2518.39	4488
2520.21	4536
2522.02	4506
2523.83	4438
2525.65	4458
2527.46	4352
2529.27	4358
2531.08	4460
2532.89	4368
2534.7	4494
2536.51	4378
2538.32	4370
2540.12	4364
2541.93	4384
2543.74	4332
2545.54	4342
2547.35	4340
2549.15	4292
2550.96	4296
2552.76	4280
2554.56	4240
2556.37	4254
2558.17	4178
2559.97	4274
2561.77	4218
2563.58	4174
2565.38	4188
2567.18	4278
2568.97	4202
2570.77	4232
2572.57	4166
2574.37	4060
2576.17	4150
2577.96	4094
2579.76	4092
2581.55	4124
2583.35	4112
2585.14	4120
2586.94	4112
2588.73	4024
2590.52	4088
2592.32	4046
2594.11	4074
2595.9	4054
2597.69	4046
2599.48	4018
2601.27	4022
2603.06	3952
2604.85	3924
2606.64	4038
2608.42	3956
2610.21	3934
2612	3922
2613.78	4042
2615.57	3982
2617.36	3904
2619.14	3984
2620.92	3836
2622.71	3946
2624.49	3996
2626.27	3876
2628.05	3930
2629.84	3860
2631.62	3824
2633.4	3826
2635.18	3810
2636.96	3846
2638.74	3818
2640.51	3758
2642.29	3806
2644.07	3808
2645.85	3776
2647.62	3676
2649.4	3818
2651.17	3762
2652.95	3796
2654.72	3718
2656.5	3794
2658.27	3702
2660.04	3798
2661.81	3756
2663.58	3742
2665.35	3704
2667.13	3678
2668.9	3766
2670.66	3682
2672.43	3630
2674.2	3644
2675.97	3676
2677.74	3644
2679.5	3642
2681.27	3684
2683.04	3682
2684.8	3618
2686.57	3616
2688.33	3608
2690.09	3570
2691.86	3540
2693.62	3562
2695.38	3652
2697.15	3538
2698.91	3554
2700.67	3458
2702.43	3534
2704.19	3588
2705.95	3462
2707.7	3468
2709.46	3538
2711.22	3590
2712.98	3414
2714.73	3496
2716.49	3430
2718.25	3430
2720	3444
2721.76	3450
2723.51	3446
2725.26	3454
2727.02	3354
2728.77	3378
2730.52	3402
2732.27	3376
2734.02	3396
2735.77	3262
2737.52	3316
2739.27	3288
2741.02	3340
2742.77	3288
2744.52	3294
2746.27	3260
2748.01	3284
2749.76	3270
2751.51	3310
2753.25	3234
2755	3204
2756.74	3248
2758.48	3248
2760.23	3254
2761.97	3158
2763.71	3194
2765.45	3144
2767.19	3252
2768.94	3246
2770.68	3154
2772.42	3164
2774.16	3116
2775.89	3122
2777.63	3160
2779.37	3088
2781.11	3168
2782.84	3176
2784.58	3084
2786.32	3064
2788.05	3110
2789.79	3134
2791.52	3112
2793.25	3068
2794.99	3048
2796.72	3080
2798.45	3058
2800.18	3104
2801.92	3030
2803.65	3032
2805.38	3038
2807.11	3024
2808.84	2954
2810.57	2980
2812.29	3028
2814.02	2978
2815.75	2966
2817.47	2918
2819.2	2992
2820.93	2928
2822.65	2928
2824.38	2934
2826.1	2910
2827.82	2878
2829.55	2890
2831.27	2886
2832.99	2828
2834.71	2848
2836.44	2852
2838.16	2842
2839.88	2822
2841.6	2796
2843.32	2910
2845.03	2838
2846.75	2844
2848.47	2796
2850.19	2778
2851.9	2782
2853.62	2824
2855.34	2804
2857.05	2814
2858.77	2736
2860.48	2724
2862.19	2794
2863.91	2734
2865.62	2686
2867.33	2674
2869.04	2632
2870.76	2680
2872.47	2658
2874.18	2660
2875.89	2664
2877.6	2690
2879.31	2644
2881.01	2612
2882.72	2596
2884.43	2624
2886.14	2608
2887.84	2578
2889.55	2646
2891.25	2584
2892.96	2594
2894.66	2560
2896.37	2634
2898.07	2630
2899.77	2526
2901.48	2520
2903.18	2616
2904.88	2594
2906.58	2512
2908.28	2542
2909.98	2548
2911.68	2550
2913.38	2524
2915.08	2540
2916.78	2506
2918.47	2500
2920.17	2508
2921.87	2566
2923.56	2526
2925.26	2516
2926.95	2502
2928.65	2492
2930.34	2502
2932.04	2528
2933.73	2472
2935.42	2464
2937.11	2440
2938.81	2444
2940.5	2410
2942.19	2442
2943.88	2534
2945.57	2366
2947.26	2404
2948.95	2448
2950.64	2468
2952.32	2444
2954.01	2376
2955.7	2374
2957.38	2346
2959.07	2340
2960.75	2316
2962.44	2332
2964.12	2294
2965.81	2352
2967.49	2334
2969.17	2348
2970.86	2324
2972.54	2358
2974.22	2316
2975.9	2318
2977.58	2288
2979.26	2296
2980.94	2286
2982.62	2336
2984.3	2246
2985.98	2210
2987.66	2250
2989.33	2196
2991.01	2220
2992.69	2250
2994.36	2232
2996.04	2180
2997.71	2230
2999.39	2168