File: muestras/tallo/2/Organic_16.txt
#Acq. time (s)=	10
#Accumulations=	1
#Range (cm-¹)=	100...3000
#Windows=	3
#Autofocus=	Off
#AutoExposure=	Off
#Spike filter=	Off
#Delay time (s)=	0
#Binning=	1
#Readout mode=	Signal
#DeNoise=	Off
#ICS correction=	Off
#Dark correction=	Off
#Inst. Process=	Off
#Instrument=	LabRAM HR Evol
#Detector=	Syncerity OE
#Objective=	x100_VIS
#Grating=	600 (500nm)
#ND Filter=	3.2%
#Laser=	633nm_Edge
#Hole=	100.021
#Range=	Visible
#Project=	Omar
#Sample=	26-06-23
#Site=	2
#Title=	Organic
#Remark=
#Date=	26.06.2023 16:30
#Acquired=	26.06.2023 16:30:37
101.018	3556
103.586	3654
106.152	3720
108.717	3688
111.281	3642
113.845	3676
116.407	3694
118.969	3716
121.53	3720
124.09	3674
126.649	3740
129.207	3734
131.765	3768
134.321	3814
136.877	3788
139.432	3830
141.985	3780
144.538	3858
147.09	3766
149.641	3876
152.191	3836
154.741	3856
157.289	3904
159.837	3846
162.385	3972
164.93	3912
167.476	3948
170.019	3864
172.562	4038
175.105	3886
177.646	3894
180.188	3954
182.727	3974
185.266	3896
187.804	3958
190.342	4048
192.878	4024
195.413	3960
197.948	4100
200.481	4068
203.014	4132
205.546	4158
208.077	4120
210.608	4146
213.137	4124
215.666	4232
218.194	4160
220.721	4362
223.247	4338
225.772	4308
228.295	4250
230.819	4334
233.342	4386
235.864	4298
238.384	4390
240.904	4340
243.423	4392
245.941	4460
248.46	4398
250.975	4380
253.492	4410
256.006	4400
258.519	4530
261.033	4462
263.545	4444
266.057	4574
268.567	4520
271.076	4472
273.585	4514
276.094	4524
278.601	4544
281.107	4504
283.612	4520
286.116	4558
288.62	4556
291.123	4566
293.625	4670
296.126	4654
298.626	4668
301.126	4704
303.625	4710
306.122	4778
308.62	4812
311.114	4760
313.61	4854
316.105	4760
318.599	4822
321.09	4816
323.583	4792
326.073	4860
328.563	4872
331.053	4872
333.541	4812
336.029	4890
338.515	4858
341.001	4930
343.486	4906
345.97	4926
348.453	4986
350.936	4968
353.418	5028
355.898	5036
358.378	5130
360.858	5098
363.336	5084
365.813	5034
368.29	5018
370.766	5038
373.241	5098
375.715	5110
378.188	5052
380.66	5120
383.132	5068
385.603	5138
388.072	5092
390.541	5094
393.01	5112
395.477	5248
397.943	5126
400.409	5252
402.875	5272
405.338	5248
407.802	5268
410.263	5384
412.725	5456
415.185	5504
417.646	5420
420.104	5480
422.564	5472
425.02	5410
427.477	5514
429.933	5492
432.388	5616
434.841	5600
437.294	5592
439.748	5668
442.199	5672
444.65	5622
447.1	5618
449.549	5742
451.997	5684
454.445	5638
456.891	5684
459.337	5692
461.782	5686
464.227	5688
466.669	5688
469.112	5732
471.554	5786
473.995	5686
476.434	5696
478.874	5842
481.312	5770
483.749	5840
486.186	5818
488.622	5894
491.057	5920
493.491	5998
495.925	5910
498.357	6098
500.789	6024
503.221	6028
505.65	5970
508.079	6014
510.509	6198
512.936	6134
515.363	6120
517.789	6070
520.214	6120
522.638	6116
525.062	6066
527.485	5974
529.907	6140
532.328	6122
534.748	6184
537.168	6094
539.587	6110
542.005	6230
544.423	6188
546.838	6242
549.254	6218
551.669	6180
554.082	6228
556.496	6242
558.909	6220
561.319	6180
563.731	6348
566.14	6326
568.549	6460
570.957	6382
573.364	6368
575.771	6324
578.177	6538
580.581	6504
582.987	6568
585.39	6496
587.792	6486
590.193	6556
592.594	6542
594.996	6696
597.395	6734
599.793	6724
602.191	6724
604.588	6684
606.984	6742
609.378	6818
611.773	6880
614.167	6924
616.56	6998
618.953	7042
621.343	7012
623.734	7062
626.124	7200
628.512	7096
630.901	7254
633.289	7150
635.675	7172
638.061	7288
640.446	7280
642.831	7450
645.213	7414
647.595	7410
649.978	7430
652.359	7416
654.738	7544
657.117	7580
659.497	7484
661.875	7576
664.252	7700
666.628	7568
669.003	7658
671.378	7640
673.751	7706
676.124	7686
678.497	7742
680.868	7750
683.239	7854
685.609	7784
687.977	7864
690.346	7934
692.714	7888
695.081	7906
697.446	7978
699.812	8146
702.175	8114
704.539	8186
706.901	8158
709.264	8146
711.625	8268
713.986	8396
716.345	8332
718.705	8484
721.062	8434
723.419	8482
725.775	8604
728.132	8552
730.487	8610
732.841	8596
735.194	8648
737.546	8664
739.898	8862
742.249	8812
744.599	9026
746.949	8880
749.298	8974
751.646	8844
753.993	8952
756.34	8968
758.684	8994
761.029	9136
763.374	9076
765.716	9310
768.059	9310
770.401	9272
772.741	9264
775.082	9322
777.421	9340
779.76	9440
782.097	9548
784.434	9620
786.771	9606
789.106	9536
791.44	9604
793.775	9812
796.108	9756
798.44	9912
800.771	9802
803.102	9814
805.432	9932
807.761	10050
810.09	10114
812.417	10114
814.744	10218
817.071	10124
819.396	10316
821.721	10396
824.045	10548
826.367	10544
828.69	10548
831.012	10752
833.332	10744
835.653	10740
837.972	10940
840.29	11020
842.609	11200
844.925	11060
847.242	11144
849.557	11424
851.871	11300
854.186	11312
856.498	11392
858.81	11470
861.122	11508
863.434	11632
865.744	11604
868.053	11692
870.361	12002
872.669	11926
874.976	11964
877.282	12130
879.588	12126
881.893	12030
884.197	12160
886.5	12150
888.802	12154
891.104	12452
893.405	12254
895.706	12152
898.004	12376
900.303	12532
902.6	12454
904.898	12572
907.194	12738
909.49	12528
911.785	12644
914.08	12690
916.372	12776
918.666	12926
920.957	12952
923.248	13112
925.538	13124
927.828	13280
930.118	13272
932.406	13352
934.693	13264
936.979	13512
939.265	13342
941.55	13672
943.835	13558
946.118	13790
948.401	13876
950.682	14014
952.964	14042
955.245	14130
957.525	14244
959.803	14194
962.082	14258
964.36	14348
966.636	14516
968.913	14492
971.188	14574
973.463	14742
975.736	14770
978.009	14858
980.282	14972
982.554	14856
984.824	14842
987.095	14944
989.364	14990
991.633	15084
993.9	15154
996.167	15128
998.434	15292
1000.7	15414
1002.96	15338
1005.23	15460
1007.49	15394
1009.76	15806
1012.02	15678
1014.28	15736
1016.54	15806
1018.8	15788
1021.06	16044
1023.32	16014
1025.57	16174
1027.83	16058
1030.09	16246
1032.34	16310
1034.6	16392
1036.85	16538
1039.1	16452
1041.35	16688
1043.61	16690
1045.86	16952
1048.11	17168
1050.36	16852
1052.61	16982
1054.85	17226
1057.1	17136
1059.35	17178
1061.59	17322
1063.84	17386
1066.08	17322
1068.33	17340
1070.57	17244
1072.81	17538
1075.05	17332
1077.29	17588
1079.53	17486
1081.77	17410
1084.01	17518
1086.25	17638
1088.48	17568
1090.72	17586
1092.96	17672
1095.19	17802
1097.43	17706
1099.66	17712
1101.89	17598
1104.12	17562
1106.35	17560
1108.59	17834
1110.81	17714
1113.04	17802
1115.27	17708
1117.5	17794
1119.73	17666
1121.95	17574
1124.18	17796
1126.4	17928
1128.63	17876
1130.85	18006
1133.07	17708
1135.29	17868
1137.51	18074
1139.73	17916
1141.95	18024
1144.17	18080
1146.39	17994
1148.61	18104
1150.82	17926
1153.04	18094
1155.26	18202
1157.47	18172
1159.68	18104
1161.9	18188
1164.11	18266
1166.32	18212
1168.53	17928
1170.74	18224
1172.95	18192
1175.16	17898
1177.37	17958
1179.58	17928
1181.78	17946
1183.99	18018
1186.19	17724
1188.4	17926
1190.6	17736
1192.8	17788
1195.01	17710
1197.21	17602.9
1199.41	17461.8
1201.61	17443.6
1203.81	17320.1
1206.01	17233.3
1208.2	17348
1210.4	17441.8
1212.6	17169.2
1214.8	17064.8
1216.99	17181.5
1219.18	17018.4
1221.38	16922.7
1223.57	16847.8
1225.76	16841
1227.96	16777.6
1230.15	16737.4
1232.34	16689.7
1234.53	16645.9
1236.71	16625.3
1238.9	16557.2
1241.09	16554.9
1243.28	16433.4
1245.46	16330
1247.65	16324.6
1249.83	16271
1252.02	16300.4
1254.2	16259.4
1256.38	16160.3
1258.56	16208.7
1260.74	16122.4
1262.92	16030.2
1265.1	16054.3
1267.28	16033.3
1269.46	15938
1271.64	15924.2
1273.82	15791.3
1275.99	15884.4
1278.17	15766
1280.34	15693.1
1282.52	15675
1284.69	15687.1
1286.86	15529.4
1289.03	15564
1291.21	15429.2
1293.38	15474.5
1295.55	15324.4
1297.71	15353.4
1299.88	15201.5
1302.05	15065.2
1304.22	15048.6
1306.38	15056.2
1308.43	15012
1310.61	15050
1312.78	14824
1314.96	14760
1317.13	14884
1319.3	14642
1321.48	14646
1323.65	14460
1325.82	14414
1327.99	14418
1330.16	14264
1332.33	14258
1334.5	14166
1336.66	14002
1338.83	13940
1341	13806
1343.16	13986
1345.33	13818
1347.49	13752
1349.65	13634
1351.82	13646
1353.98	13670
1356.14	13516
1358.3	13406
1360.46	13294
1362.62	13254
1364.78	13210
1366.94	13070
1369.09	13078
1371.25	13158
1373.41	12906
1375.56	12862
1377.72	13048
1379.87	12896
1382.02	12880
1384.17	12802
1386.33	12736
1388.48	12520
1390.63	12452
1392.78	12542
1394.93	12588
1397.07	12478
1399.22	12362
1401.37	12268
1403.52	12230
1405.66	12076
1407.81	12180
1409.95	12192
1412.09	12082
1414.24	12064
1416.38	12054
1418.52	12016
1420.66	11954
1422.8	11764
1424.94	11818
1427.08	11678
1429.22	11592
1431.35	11754
1433.49	11706
1435.63	11546
1437.76	11628
1439.9	11528
1442.03	11504
1444.17	11500
1446.3	11362
1448.43	11458
1450.56	11364
1452.69	11392
1454.82	11054
1456.95	11160
1459.08	11124
1461.21	11192
1463.34	11200
1465.46	11158
1467.59	11146
1469.71	11122
1471.84	10906
1473.96	10950
1476.08	11028
1478.21	11096
1480.33	10964
1482.45	10944
1484.57	10802
1486.69	10962
1488.81	10824
1490.93	10680
1493.05	10896
1495.16	10780
1497.28	10790
1499.4	10686
1501.51	10626
1503.63	10682
1505.74	10582
1507.85	10464
1509.97	10440
1512.08	10444
1514.19	10408
1516.3	10432
1518.41	10478
1520.52	10340
1522.63	10346
1524.73	10358
1526.84	10238
1528.95	10198
1531.06	10198
1533.16	10170
1535.26	10262
1537.37	10020
1539.47	10080
1541.57	10102
1543.68	10030
1545.78	10026
1547.88	9904
1549.98	9868
1552.08	9788
1554.18	9902
1556.27	9858
1558.37	9708
1560.47	9760
1562.56	9664
1564.66	9654
1566.75	9730
1568.85	9648
1570.94	9690
1573.03	9814
1575.13	9622
1577.22	9754
1579.31	9658
1581.4	9580
1583.49	9582
1585.58	9568
1587.66	9544
1589.75	9492
1591.84	9480
1593.93	9412
1596.01	9554
1598.1	9482
1600.18	9476
1602.26	9500
1604.35	9458
1606.43	9424
1608.51	9430
1610.59	9484
1612.67	9434
1614.75	9464
1616.83	9420
1618.91	9412
1620.99	9372
1623.06	9334
1625.14	9388
1627.21	9166
1629.29	9352
1631.36	9258
1633.44	9300
1635.51	9358
1637.58	9262
1639.66	9052
1641.73	9150
1643.8	9078
1645.87	9072
1647.94	9176
1650	9026
1652.07	9062
1654.14	9022
1656.21	9080
1658.27	9044
1660.34	9068
1662.4	8992
1664.47	9058
1666.53	9040
1668.59	8916
1670.66	8910
1672.72	8988
1674.78	8764
1676.84	8784
1678.9	8796
1680.96	8656
1683.01	8794
1685.07	8792
1687.13	8690
1689.19	8718
1691.24	8664
1693.3	8680
1695.35	8674
1697.4	8670
1699.46	8572
1701.51	8618
1703.56	8506
1705.61	8518
1707.66	8520
1709.71	8582
1711.76	8456
1713.81	8564
1715.86	8510
1717.91	8324
1719.95	8398
1722	8418
1724.04	8462
1726.09	8316
1728.13	8264
1730.18	8368
1732.22	8230
1734.26	8296
1736.3	8234
1738.34	8314
1740.38	8274
1742.42	8282
1744.46	8236
1746.5	8204
1748.54	8240
1750.58	8208
1752.61	8226
1754.65	8198
1756.68	8136
1758.72	8120
1760.75	8108
1762.79	8240
1764.82	8266
1766.85	8082
1768.88	8158
1770.91	8146
1772.94	8218
1774.97	8188
1777	8186
1779.03	8198
1781.06	8104
1783.09	8008
1785.11	8110
1787.14	8034
1789.16	8084
1791.19	8102
1793.21	8040
1795.23	8048
1797.26	8120
1799.28	7960
1801.3	8032
1803.32	8028
1805.34	7948
1807.36	8018
1809.38	7818
1811.4	8000
1813.42	7902
1815.43	7898
1817.45	7922
1819.47	7898
1821.48	7884
1823.49	7868
1825.51	7738
1827.52	7786
1829.54	7742
1831.55	7816
1833.56	7690
1835.57	7732
1837.58	7680
1839.59	7692
1841.6	7660
1843.61	7646
1845.61	7568
1847.62	7698
1849.63	7596
1851.63	7670
1853.64	7536
1855.64	7616
1857.65	7498
1859.65	7516
1861.65	7624
1863.65	7556
1865.66	7530
1867.66	7532
1869.66	7630
1871.66	7480
1873.66	7450
1875.65	7404
1877.65	7568
1879.65	7462
1881.65	7470
1883.64	7302
1885.64	7468
1887.63	7394
1889.63	7354
1891.62	7462
1893.61	7436
1895.6	7504
1897.6	7342
1899.59	7332
1901.58	7408
1903.57	7480
1905.56	7350
1907.54	7364
1909.53	7330
1911.52	7352
1913.51	7352
1915.49	7340
1917.48	7298
1919.46	7300
1921.45	7284
1923.43	7432
1925.41	7276
1927.4	7352
1929.38	7320
1931.36	7294
1933.34	7350
1935.32	7132
1937.3	7218
1939.28	7286
1941.26	7226
1943.23	7358
1945.21	7252
1947.19	7220
1949.16	7174
1951.14	7110
1953.11	7178
1955.09	7268
1957.06	7190
1959.03	7098
1961	7098
1962.98	7048
1964.95	7018
1966.92	6998
1968.89	7040
1970.85	7066
1972.82	7108
1974.79	6968
1976.76	7072
1978.73	7010
1980.69	6970
1982.66	6942
1984.62	7020
1986.59	7022
1988.55	6974
1990.51	7014
1992.47	6936
1994.44	6984
1996.4	6980
1998.36	6930
2000.32	7000
2002.28	6904
2004.24	6984
2006.19	6898
2008.15	6988
2010.11	6886
2012.06	6942
2014.02	6924
2015.98	6852
2017.93	6844
2019.88	6882
2021.84	6880
2023.79	6784
2025.74	6852
2027.69	6798
2029.65	6746
2031.6	6860
2033.55	6752
2035.5	6746
2037.44	6878
2039.39	6824
2041.34	6770
2043.29	6788
2045.23	6694
2047.18	6730
2049.12	6642
2051.07	6750
2053.01	6710
2054.95	6656
2056.9	6732
2058.84	6604
2060.78	6710
2062.72	6706
2064.66	6640
2066.6	6630
2068.54	6682
2070.48	6626
2072.42	6636
2074.35	6590
2076.29	6578
2078.23	6522
2080.16	6498
2082.1	6476
2084.03	6516
2085.96	6654
2087.9	6624
2089.83	6530
2091.76	6500
2093.69	6452
2095.62	6462
2097.55	6476
2099.48	6606
2101.41	6564
2103.34	6442
2105.27	6560
2107.2	6526
2109.12	6412
2111.05	6394
2112.98	6416
2114.9	6486
2116.82	6460
2118.75	6344
2120.67	6398
2122.59	6434
2124.52	6482
2126.44	6408
2128.36	6462
2130.28	6332
2132.2	6374
2134.12	6296
2136.04	6356
2137.95	6370
2139.87	6242
2141.79	6322
2143.7	6290
2145.62	6337.76
2147.53	6295.99
2149.45	6273.55
2151.36	6313.4
2153.28	6265.59
2155.19	6261.27
2157.1	6173.15
2159.01	6218.4
2160.92	6223.75
2162.83	6131.64
2164.74	6129.62
2166.65	6185.75
2168.56	6052.62
2170.47	6133.64
2172.38	6053.93
2174.28	6123.3
2176.19	6125.17
2178.09	6059.11
2180	6081.91
2181.9	6098.65
2183.81	6024.99
2185.71	6055.38
2187.61	5963.72
2189.52	6045.76
2191.42	5996.02
2193.32	6007.44
2195.22	5965.89
2197.12	6005.3
2199.02	5936.57
2200.92	5926.02
2202.82	5956.65
2204.71	5966.21
2206.61	5931.08
2208.51	5976.55
2210.4	5944.83
2212.3	5971.73
2214.19	5922.41
2216.09	6001.31
2217.98	5935.14
2219.87	5934.01
2221.77	5939.35
2223.66	5935.25
2225.55	5976.13
2227.44	5913.68
2229.33	5914.81
2231.22	5954.28
2233.11	5996.9
2235	5925.51
2236.88	5916.27
2238.77	5924.59
2240.66	5905.92
2242.07	5944
2243.97	5984
2245.87	5864
2247.76	5904
2249.65	5832
2251.55	5894
2253.44	6008
2255.33	5870
2257.22	5830
2259.12	5784
2261.01	5920
2262.9	5846
2264.78	5906
2266.67	5930
2268.56	5912
2270.45	5934
2272.34	5904
2274.22	5898
2276.11	5886
2277.99	5756
2279.88	5748
2281.76	5904
2283.65	5720
2285.53	5856
2287.41	5810
2289.3	5726
2291.18	5734
2293.06	5778
2294.94	5754
2296.82	5698
2298.7	5776
2300.58	5760
2302.46	5748
2304.33	5704
2306.21	5774
2308.09	5754
2309.96	5636
2311.84	5672
2313.71	5728
2315.59	5724
2317.46	5608
2319.33	5486
2321.21	5668
2323.08	5584
2324.95	5690
2326.82	5518
2328.69	5602
2330.56	5632
2332.43	5604
2334.3	5588
2336.17	5550
2338.03	5562
2339.9	5594
2341.77	5526
2343.63	5530
2345.5	5482
2347.36	5560
2349.23	5496
2351.09	5560
2352.95	5554
2354.82	5486
2356.68	5594
2358.54	5574
2360.4	5626
2362.26	5528
2364.12	5488
2365.98	5536
2367.84	5428
2369.7	5546
2371.56	5442
2373.41	5476
2375.27	5516
2377.12	5512
2378.98	5524
2380.84	5504
2382.69	5508
2384.54	5414
2386.4	5486
2388.25	5354
2390.1	5384
2391.95	5320
2393.8	5346
2395.65	5472
2397.5	5316
2399.35	5430
2401.2	5330
2403.05	5286
2404.9	5382
2406.75	5318
2408.59	5350
2410.44	5344
2412.28	5352
2414.13	5384
2415.97	5220
2417.82	5216
2419.66	5294
2421.5	5224
2423.35	5288
2425.19	5192
2427.03	5214
2428.87	5328
2430.71	5258
2432.55	5240
2434.39	5260
2436.23	5256
2438.06	5168
2439.9	5200
2441.74	5156
2443.57	5142
2445.41	5172
2447.24	5168
2449.08	5086
2450.91	5140
2452.75	5086
2454.58	5064
2456.41	5016
2458.24	5126
2460.08	5088
2461.91	5162
2463.74	5060
2465.57	5080
2467.4	5042
2469.22	5070
2471.05	4988
2472.88	5022
2474.71	5018
2476.53	4986
2478.36	4998
2480.19	5006
2482.01	4990
2483.83	4982
2485.66	4890
2487.48	4960
2489.3	4904
2491.13	4968
2492.95	4954
2494.77	4940
2496.59	4900
2498.41	4866
2500.23	4828
2502.05	4862
2503.87	4868
2505.68	4752
2507.5	4882
2509.32	4796
2511.14	4718
2512.95	4802
2514.77	4838
2516.58	4868
2518.39	4826
2520.21	4738
2522.02	4648
2523.83	4718
2525.65	4776
2527.46	4706
2529.27	4658
2531.08	4670
2532.89	4772
2534.7	4628
2536.51	4756
2538.32	4622
2540.12	4620
2541.93	4598
2543.74	4676
2545.54	4634
2547.35	4606
2549.15	4566
2550.96	4556
2552.76	4644
2554.56	4616
2556.37	4636
2558.17	4448
2559.97	4522
2561.77	4528
2563.58	4538
2565.38	4516
2567.18	4536
2568.97	4484
2570.77	4510
2572.57	4456
2574.37	4374
2576.17	4442
2577.96	4432
2579.76	4378
2581.55	4386
2583.35	4464
2585.14	4338
2586.94	4444
2588.73	4334
2590.52	4424
2592.32	4374
2594.11	4262
2595.9	4392
2597.69	4326
2599.48	4346
2601.27	4330
2603.06	4338
2604.85	4278
2606.64	4270
2608.42	4304
2610.21	4246
2612	4224
2613.78	4312
2615.57	4240
2617.36	4230
2619.14	4240
2620.92	4254
2622.71	4218
2624.49	4184
2626.27	4262
2628.05	4176
2629.84	4086
2631.62	4120
2633.4	4100
2635.18	4142
2636.96	4052
2638.74	4132
2640.51	4020
2642.29	4034
2644.07	3998
2645.85	4038
2647.62	4018
2649.4	4022
2651.17	4072
2652.95	3968
2654.72	3924
2656.5	4008
2658.27	3998
2660.04	3976
2661.81	4066
2663.58	3914
2665.35	3932
2667.13	3994
2668.9	3924
2670.66	3898
2672.43	3964
2674.2	3900
2675.97	3920
2677.74	3908
2679.5	3866
2681.27	3860
2683.04	3858
2684.8	3898
2686.57	3742
2688.33	3818
2690.09	3864
2691.86	3772
2693.62	3760
2695.38	3782
2697.15	3672
2698.91	3754
2700.67	3702
2702.43	3680
2704.19	3734
2705.95	3664
2707.7	3704
2709.46	3734
2711.22	3742
2712.98	3708
2714.73	3680
2716.49	3684
2718.25	3664
2720	3684
2721.76	3640
2723.51	3712
2725.26	3630
2727.02	3662
2728.77	3600
2730.52	3584
2732.27	3558
2734.02	3576
2735.77	3648
2737.52	3576
2739.27	3558
2741.02	3516
2742.77	3548
2744.52	3540
2746.27	3492
2748.01	3512
2749.76	3472
2751.51	3484
2753.25	3452
2755	3470
2756.74	3474
2758.48	3410
2760.23	3468
2761.97	3442
2763.71	3368
2765.45	3448
2767.19	3406
2768.94	3360
2770.68	3402
2772.42	3380
2774.16	3358
2775.89	3402
2777.63	3358
2779.37	3322
2781.11	3328
2782.84	3256
2784.58	3302
2786.32	3302
2788.05	3302
2789.79	3290
2791.52	3322
2793.25	3282
2794.99	3176
2796.72	3230
2798.45	3180
2800.18	3278
2801.92	3186
2803.65	3221
2805.38	3250
2807.11	3166
2808.84	3216
2810.57	3222
2812.29	3188
2814.02	3140
2815.75	3138
2817.47	3160
2819.2	3124
2820.93	3096
2822.65	3076
2824.38	3058
2826.1	3036
2827.82	3138
2829.55	3098
2831.27	3108
2832.99	3054
2834.71	3068
2836.44	2954
2838.16	3072
2839.88	3026
2841.6	3000
2843.32	3096
2845.03	3042
2846.75	2964
2848.47	3012
2850.19	2956
2851.9	2878
2853.62	2984
2855.34	2926
2857.05	2956
2858.77	2940
2860.48	2898
2862.19	2932
2863.91	2842
2865.62	2932
2867.33	2850
2869.04	2926
2870.76	2862
2872.47	2848
2874.18	2826
2875.89	2892
2877.6	2774
2879.31	2826
2881.01	2816
2882.72	2750
2884.43	2748
2886.14	2728
2887.84	2750
2889.55	2744
2891.25	2774
2892.96	2728
2894.66	2738
2896.37	2740
2898.07	2706
2899.77	2744
2901.48	2718
2903.18	2712
2904.88	2760
2906.58	2694
2908.28	2670
2909.98	2754
2911.68	2720
2913.38	2680
2915.08	2670
2916.78	2700
2918.47	2622
2920.17	2666
2921.87	2652
2923.56	2620
2925.26	2664
2926.95	2638
2928.65	2590
2930.34	2642
2932.04	2614
2933.73	2590
2935.42	2620
2937.11	2638
2938.81	2556
2940.5	2618
2942.19	2644
2943.88	2578
2945.57	2630
2947.26	2532
2948.95	2534
2950.64	2518
2952.32	2506
2954.01	2496
2955.7	2538
2957.38	2556
2959.07	2466
2960.75	2508
2962.44	2504
2964.12	2454
2965.81	2484
2967.49	2478
2969.17	2510
2970.86	2530
2972.54	2474
2974.22	2422
2975.9	2490
2977.58	2404
2979.26	2416
2980.94	2434
2982.62	2334
2984.3	2428
2985.98	2408
2987.66	2358
2989.33	2358
2991.01	2350
2992.69	2388
2994.36	2346
2996.04	2398
2997.71	2372
2999.39	2320