File: muestras/tallo/2/Organic_08.txt
#Acq. time (s)=	10
#Accumulations=	1
#Range (cm-¹)=	100...3000
#Windows=	3
#Autofocus=	Off
#AutoExposure=	Off
#Spike filter=	Off
#Delay time (s)=	0
#Binning=	1
#Readout mode=	Signal
#DeNoise=	Off
#ICS correction=	Off
#Dark correction=	Off
#Inst. Process=	Off
#Instrument=	LabRAM HR Evol
#Detector=	Syncerity OE
#Objective=	x100_VIS
#Grating=	600 (500nm)
#ND Filter=	3.2%
#Laser=	633nm_Edge
#Hole=	100.021
#Range=	Visible
#Project=	Omar
#Sample=	26-06-23
#Site=	2
#Title=	Organic
#Remark=
#Date=	26.06.2023 16:22
#Acquired=	26.06.2023 16:22:48
101.018	3874
103.586	3972
106.152	3938
108.717	3930
111.281	3974
113.845	3992
116.407	3938
118.969	4050
121.53	4018
124.09	4078
126.649	4074
129.207	4112
131.765	4156
134.321	4160
136.877	4124
139.432	4110
141.985	4120
144.538	4138
147.09	4158
149.641	4206
152.191	4174
154.741	4220
157.289	4238
159.837	4238
162.385	4256
164.93	4332
167.476	4368
170.019	4198
172.562	4242
175.105	4298
177.646	4244
180.188	4314
182.727	4384
185.266	4370
187.804	4398
190.342	4442
192.878	4410
195.413	4432
197.948	4414
200.481	4434
203.014	4442
205.546	4522
208.077	4536
210.608	4440
213.137	4598
215.666	4626
218.194	4540
220.721	4572
223.247	4562
225.772	4604
228.295	4732
230.819	4698
233.342	4700
235.864	4728
238.384	4810
240.904	4782
243.423	4808
245.941	4822
248.46	4830
250.975	4900
253.492	4876
256.006	4790
258.519	4796
261.033	4794
263.545	4906
266.057	4906
268.567	4868
271.076	4844
273.585	4854
276.094	4840
278.601	4938
281.107	4996
283.612	5028
286.116	5032
288.62	4984
291.123	5074
293.625	5060
296.126	5090
298.626	5112
301.126	5114
303.625	5206
306.122	5156
308.62	5160
311.114	5236
313.61	5306
316.105	5272
318.599	5352
321.09	5238
323.583	5338
326.073	5292
328.563	5290
331.053	5288
333.541	5338
336.029	5342
338.515	5392
341.001	5400
343.486	5452
345.97	5510
348.453	5522
350.936	5492
353.418	5438
355.898	5536
358.378	5536
360.858	5542
363.336	5536
365.813	5584
368.29	5582
370.766	5548
373.241	5478
375.715	5524
378.188	5604
380.66	5736
383.132	5610
385.603	5624
388.072	5696
390.541	5634
393.01	5738
395.477	5800
397.943	5816
400.409	5740
402.875	5844
405.338	5676
407.802	5898
410.263	5932
412.725	5916
415.185	5916
417.646	5900
420.104	6034
422.564	6014
425.02	6130
427.477	6114
429.933	6184
432.388	6136
434.841	6166
437.294	6126
439.748	6316
442.199	6238
444.65	6290
447.1	6296
449.549	6312
451.997	6258
454.445	6280
456.891	6254
459.337	6290
461.782	6448
464.227	6330
466.669	6292
469.112	6362
471.554	6370
473.995	6380
476.434	6410
478.874	6428
481.312	6474
483.749	6550
486.186	6534
488.622	6610
491.057	6658
493.491	6558
495.925	6598
498.357	6618
500.789	6636
503.221	6730
505.65	6754
508.079	6832
510.509	6802
512.936	6852
515.363	6756
517.789	6780
520.214	6864
522.638	6842
525.062	6780
527.485	6854
529.907	6862
532.328	6894
534.748	6848
537.168	6890
539.587	6820
542.005	6928
544.423	6944
546.838	7026
549.254	6916
551.669	7022
554.082	7016
556.496	7100
558.909	7104
561.319	7206
563.731	7156
566.14	7114
568.549	7202
570.957	7238
573.364	7190
575.771	7342
578.177	7310
580.581	7340
582.987	7350
585.39	7456
587.792	7346
590.193	7366
592.594	7532
594.996	7540
597.395	7608
599.793	7636
602.191	7576
604.588	7572
606.984	7606
609.378	7684
611.773	7708
614.167	7754
616.56	7922
618.953	7850
621.343	7836
623.734	8066
626.124	8112
628.512	8066
630.901	8180
633.289	8212
635.675	8184
638.061	8310
640.446	8258
642.831	8402
645.213	8412
647.595	8352
649.978	8488
652.359	8532
654.738	8484
657.117	8672
659.497	8576
661.875	8810
664.252	8676
666.628	8722
669.003	8768
671.378	8802
673.751	8824
676.124	8780
678.497	8804
680.868	8916
683.239	8868
685.609	9004
687.977	9178
690.346	9142
692.714	9104
695.081	9182
697.446	9226
699.812	9192
702.175	9284
704.539	9328
706.901	9342
709.264	9490
711.625	9590
713.986	9446
716.345	9670
718.705	9604
721.062	9644
723.419	9900
725.775	9858
728.132	9846
730.487	9898
732.841	9874
735.194	10180
737.546	10076
739.898	10178
742.249	10178
744.599	10314
746.949	10368
749.298	10402
751.646	10326
753.993	10556
756.34	10646
758.684	10476
761.029	10584
763.374	10690
765.716	10848
768.059	10656
770.401	10808
772.741	10768
775.082	10902
777.421	11070
779.76	11054
782.097	11206
784.434	11068
786.771	11076
789.106	11338
791.44	11314
793.775	11210
796.108	11388
798.44	11618
800.771	11518
803.102	11652
805.432	11604
807.761	11876
810.09	11994
812.417	11884
814.744	12026
817.071	12216
819.396	12178
821.721	12210
824.045	12312
826.367	12284
828.69	12624
831.012	12582
833.332	12836
835.653	12764
837.972	12832
840.29	12922
842.609	13130
844.925	13244
847.242	13202
849.557	13294
851.871	13428
854.186	13450
856.498	13414
858.81	13596
861.122	13606
863.434	13898
865.744	13958
868.053	13988
870.361	14036
872.669	14162
874.976	14070
877.282	14198
879.588	14252
881.893	14312
884.197	14374
886.5	14490
888.802	14640
891.104	14590
893.405	14630
895.706	14880
898.004	14880
900.303	14882
902.6	14966
904.898	14984
907.194	15070
909.49	15116
911.785	15036
914.08	15240
916.372	15278
918.666	15440
920.957	15512
923.248	15506
925.538	15616
927.828	15844
930.118	15796
932.406	15988
934.693	16044
936.979	16102
939.265	16146
941.55	16310
943.835	16388
946.118	16528
948.401	16650
950.682	16792
952.964	16934
955.245	16878
957.525	16976
959.803	17116
962.082	17130
964.36	17378
966.636	17434
968.913	17390
971.188	17594
973.463	17624
975.736	17750
978.009	17804
980.282	18020
982.554	17924
984.824	17974
987.095	18072
989.364	18162
991.633	18248
993.9	18464
996.167	18408
998.434	18492
1000.7	18392
1002.96	18620
1005.23	18886
1007.49	18880
1009.76	19016
1012.02	18726
1014.28	19006
1016.54	18962
1018.8	19248
1021.06	19314
1023.32	19296
1025.57	19430
1027.83	19676
1030.09	19656
1032.34	19716
1034.6	20006
1036.85	19834
1039.1	20080
1041.35	20150
1043.61	20438
1045.86	20294
1048.11	20462
1050.36	20498
1052.61	20596
1054.85	20842
1057.1	20698
1059.35	20934
1061.59	20836
1063.84	21066
1066.08	21110
1068.33	21130
1070.57	21088
1072.81	21176
1075.05	21426
1077.29	21386
1079.53	21410
1081.77	21242
1084.01	21380
1086.25	21370
1088.48	21414
1090.72	21478
1092.96	21544
1095.19	21316
1097.43	21464
1099.66	21366
1101.89	21468
1104.12	21432
1106.35	21684
1108.59	21548
1110.81	21390
1113.04	21512
1115.27	21484
1117.5	21492
1119.73	21534
1121.95	21572
1124.18	21568
1126.4	21630
1128.63	21558
1130.85	21708
1133.07	21664
1135.29	21818
1137.51	21686
1139.73	21850
1141.95	21944
1144.17	21768
1146.39	21920
1148.61	22056
1150.82	22122
1153.04	21944
1155.26	22100
1157.47	21890
1159.68	22244
1161.9	21978
1164.11	22072
1166.32	21738
1168.53	22064
1170.74	21880
1172.95	21878
1175.16	21806
1177.37	21856
1179.58	21916
1181.78	21920
1183.99	21752
1186.19	21720
1188.4	21494
1190.6	21548
1192.8	21274
1195.01	21400
1197.21	21280.9
1199.41	21209.9
1201.61	21057.9
1203.81	21068.4
1206.01	21003.8
1208.2	21038.2
1210.4	20931.9
1212.6	20813.2
1214.8	20781.4
1216.99	20804.9
1219.18	20541.6
1221.38	20492.8
1223.57	20306.7
1225.76	20298.7
1227.96	20236.1
1230.15	20336.8
1232.34	20112.8
1234.53	20142.5
1236.71	20196.3
1238.9	20005.9
1241.09	19925
1243.28	19845.7
1245.46	19809.9
1247.65	19739
1249.83	19765.3
1252.02	19710.1
1254.2	19581.8
1256.38	19591.3
1258.56	19364.7
1260.74	19378.6
1262.92	19319.2
1265.1	19213.8
1267.28	19217.1
1269.46	19235.1
1271.64	19187.3
1273.82	19122.9
1275.99	19022.6
1278.17	18974.1
1280.34	18830.2
1282.52	18720
1284.69	18635.9
1286.86	18608.6
1289.03	18579.7
1291.21	18626.3
1293.38	18591.4
1295.55	18495.2
1297.71	18347.1
1299.88	18298.1
1302.05	18200.4
1304.22	18048.2
1306.38	17924.8
1308.43	17760
1310.61	17780
1312.78	17676
1314.96	17656
1317.13	17580
1319.3	17180
1321.48	17378
1323.65	17116
1325.82	17174
1327.99	17082
1330.16	16930
1332.33	16622
1334.5	16814
1336.66	16626
1338.83	16590
1341	16582
1343.16	16344
1345.33	16312
1347.49	16140
1349.65	16224
1351.82	16000
1353.98	15986
1356.14	15922
1358.3	15708
1360.46	15628
1362.62	15588
1364.78	15574
1366.94	15434
1369.09	15458
1371.25	15326
1373.41	15392
1375.56	15132
1377.72	15180
1379.87	15094
1382.02	14992
1384.17	14906
1386.33	14844
1388.48	14752
1390.63	14842
1392.78	14618
1394.93	14520
1397.07	14642
1399.22	14506
1401.37	14394
1403.52	14394
1405.66	14282
1407.81	14282
1409.95	14144
1412.09	14220
1414.24	14080
1416.38	14014
1418.52	14022
1420.66	13900
1422.8	13902
1424.94	13896
1427.08	13750
1429.22	13592
1431.35	13620
1433.49	13486
1435.63	13462
1437.76	13472
1439.9	13494
1442.03	13406
1444.17	13440
1446.3	13310
1448.43	13222
1450.56	13388
1452.69	13176
1454.82	13062
1456.95	13104
1459.08	12958
1461.21	13090
1463.34	13002
1465.46	12796
1467.59	12950
1469.71	12814
1471.84	12842
1473.96	12820
1476.08	12792
1478.21	12700
1480.33	12840
1482.45	12666
1484.57	12634
1486.69	12546
1488.81	12600
1490.93	12506
1493.05	12530
1495.16	12486
1497.28	12372
1499.4	12302
1501.51	12274
1503.63	12166
1505.74	12300
1507.85	12146
1509.97	12166
1512.08	12086
1514.19	12126
1516.3	11976
1518.41	11976
1520.52	11908
1522.63	11866
1524.73	11974
1526.84	11730
1528.95	11896
1531.06	11716
1533.16	11676
1535.26	11690
1537.37	11512
1539.47	11506
1541.57	11414
1543.68	11472
1545.78	11488
1547.88	11414
1549.98	11288
1552.08	11396
1554.18	11284
1556.27	11222
1558.37	11186
1560.47	11264
1562.56	11184
1564.66	11206
1566.75	11104
1568.85	11190
1570.94	11158
1573.03	11070
1575.13	11016
1577.22	11082
1579.31	11078
1581.4	11158
1583.49	10960
1585.58	10942
1587.66	10954
1589.75	11014
1591.84	10894
1593.93	10998
1596.01	10880
1598.1	10888
1600.18	10838
1602.26	10928
1604.35	10872
1606.43	10702
1608.51	10864
1610.59	10590
1612.67	10804
1614.75	10716
1616.83	10790
1618.91	10752
1620.99	10754
1623.06	10548
1625.14	10694
1627.21	10662
1629.29	10620
1631.36	10620
1633.44	10714
1635.51	10502
1637.58	10610
1639.66	10520
1641.73	10510
1643.8	10458
1645.87	10574
1647.94	10506
1650	10406
1652.07	10318
1654.14	10406
1656.21	10274
1658.27	10346
1660.34	10304
1662.4	10214
1664.47	10224
1666.53	10098
1668.59	10172
1670.66	10034
1672.72	10152
1674.78	10122
1676.84	10006
1678.9	9938
1680.96	10126
1683.01	9982
1685.07	9956
1687.13	9906
1689.19	9882
1691.24	9952
1693.3	9890
1695.35	9862
1697.4	9802
1699.46	9706
1701.51	9720
1703.56	9778
1705.61	9684
1707.66	9768
1709.71	9700
1711.76	9730
1713.81	9652
1715.86	9598
1717.91	9600
1719.95	9620
1722	9566
1724.04	9560
1726.09	9688
1728.13	9504
1730.18	9462
1732.22	9544
1734.26	9526
1736.3	9424
1738.34	9428
1740.38	9384
1742.42	9392
1744.46	9298
1746.5	9288
1748.54	9274
1750.58	9382
1752.61	9298
1754.65	9432
1756.68	9336
1758.72	9334
1760.75	9312
1762.79	9262
1764.82	9364
1766.85	9354
1768.88	9262
1770.91	9250
1772.94	9298
1774.97	9122
1777	9286
1779.03	9326
1781.06	9262
1783.09	9376
1785.11	9152
1787.14	9282
1789.16	9184
1791.19	9132
1793.21	9108
1795.23	9152
1797.26	9072
1799.28	9160
1801.3	9112
1803.32	9040
1805.34	8964
1807.36	9172
1809.38	9102
1811.4	8986
1813.42	8984
1815.43	8984
1817.45	9030
1819.47	8924
1821.48	8928
1823.49	8910
1825.51	8856
1827.52	8876
1829.54	8904
1831.55	8654
1833.56	8824
1835.57	8694
1837.58	8828
1839.59	8856
1841.6	8674
1843.61	8734
1845.61	8672
1847.62	8678
1849.63	8624
1851.63	8698
1853.64	8734
1855.64	8620
1857.65	8658
1859.65	8550
1861.65	8692
1863.65	8500
1865.66	8528
1867.66	8504
1869.66	8474
1871.66	8596
1873.66	8580
1875.65	8392
1877.65	8494
1879.65	8400
1881.65	8426
1883.64	8332
1885.64	8462
1887.63	8476
1889.63	8408
1891.62	8360
1893.61	8480
1895.6	8326
1897.6	8462
1899.59	8378
1901.58	8382
1903.57	8356
1905.56	8308
1907.54	8528
1909.53	8392
1911.52	8282
1913.51	8364
1915.49	8530
1917.48	8344
1919.46	8320
1921.45	8330
1923.43	8428
1925.41	8230
1927.4	8392
1929.38	8308
1931.36	8280
1933.34	8324
1935.32	8218
1937.3	8204
1939.28	8236
1941.26	8242
1943.23	8256
1945.21	8270
1947.19	8206
1949.16	8140
1951.14	8108
1953.11	8158
1955.09	8142
1957.06	8148
1959.03	8012
1961	8160
1962.98	7998
1964.95	8050
1966.92	7992
1968.89	8118
1970.85	8080
1972.82	8100
1974.79	8170
1976.76	7984
1978.73	8102
1980.69	8024
1982.66	7920
1984.62	7972
1986.59	8060
1988.55	7982
1990.51	7904
1992.47	7906
1994.44	7956
1996.4	7924
1998.36	7930
2000.32	7854
2002.28	8004
2004.24	7904
2006.19	7840
2008.15	7958
2010.11	7762
2012.06	7786
2014.02	7812
2015.98	7852
2017.93	7844
2019.88	7938
2021.84	7832
2023.79	7836
2025.74	7760
2027.69	7776
2029.65	7732
2031.6	7758
2033.55	7732
2035.5	7766
2037.44	7762
2039.39	7794
2041.34	7702
2043.29	7602
2045.23	7672
2047.18	7614
2049.12	7558
2051.07	7692
2053.01	7704
2054.95	7608
2056.9	7520
2058.84	7624
2060.78	7520
2062.72	7496
2064.66	7548
2066.6	7554
2068.54	7600
2070.48	7496
2072.42	7578
2074.35	7502
2076.29	7478
2078.23	7616
2080.16	7508
2082.1	7418
2084.03	7460
2085.96	7468
2087.9	7502
2089.83	7564
2091.76	7476
2093.69	7514
2095.62	7454
2097.55	7448
2099.48	7406
2101.41	7332
2103.34	7432
2105.27	7364
2107.2	7358
2109.12	7428
2111.05	7428
2112.98	7398
2114.9	7360
2116.82	7322
2118.75	7288
2120.67	7444
2122.59	7342
2124.52	7388
2126.44	7252
2128.36	7234
2130.28	7334
2132.2	7250
2134.12	7234
2136.04	7276
2137.95	7298
2139.87	7188
2141.79	7176
2143.7	7246
2145.62	7159.81
2147.53	7211.11
2149.45	7134.87
2151.36	7102.48
2153.28	7164.42
2155.19	7129.02
2157.1	7082.53
2159.01	7160.38
2160.92	7057.69
2162.83	7063.56
2164.74	7067.67
2166.65	6988.72
2168.56	6984.76
2170.47	7012.53
2172.38	7049.97
2174.28	7018
2176.19	6920.66
2178.09	6981.08
2180	6961.21
2181.9	6897.18
2183.81	6973.78
2185.71	6949.02
2187.61	6870.62
2189.52	6882.97
2191.42	6853.43
2193.32	6844
2195.22	6870.43
2197.12	6864.99
2199.02	6874.24
2200.92	6732.41
2202.82	6770.39
2204.71	6823.85
2206.61	6811.93
2208.51	6877.86
2210.4	6813.05
2212.3	6820.78
2214.19	6802.76
2216.09	6790.65
2217.98	6851.48
2219.87	6768.05
2221.77	6819.7
2223.66	6768.43
2225.55	6776.77
2227.44	6758
2229.33	6797.61
2231.22	6824.38
2233.11	6840.78
2235	6811.34
2236.88	6826.16
2238.77	6753.98
2240.66	6848.39
2242.07	6716
2243.97	6810
2245.87	6720
2247.76	6734
2249.65	6810
2251.55	6840
2253.44	6700
2255.33	6724
2257.22	6708
2259.12	6670
2261.01	6708
2262.9	6660
2264.78	6728
2266.67	6654
2268.56	6666
2270.45	6696
2272.34	6622
2274.22	6668
2276.11	6778
2277.99	6640
2279.88	6684
2281.76	6682
2283.65	6710
2285.53	6594
2287.41	6680
2289.3	6660
2291.18	6692
2293.06	6508
2294.94	6582
2296.82	6574
2298.7	6612
2300.58	6598
2302.46	6504
2304.33	6606
2306.21	6524
2308.09	6544
2309.96	6570
2311.84	6584
2313.71	6470
2315.59	6486
2317.46	6488
2319.33	6322
2321.21	6386
2323.08	6466
2324.95	6442
2326.82	6468
2328.69	6446
2330.56	6356
2332.43	6412
2334.3	6416
2336.17	6454
2338.03	6384
2339.9	6386
2341.77	6426
2343.63	6402
2345.5	6436
2347.36	6398
2349.23	6374
2351.09	6416
2352.95	6294
2354.82	6384
2356.68	6370
2358.54	6396
2360.4	6442
2362.26	6252
2364.12	6272
2365.98	6284
2367.84	6322
2369.7	6226
2371.56	6172
2373.41	6298
2375.27	6342
2377.12	6284
2378.98	6206
2380.84	6250
2382.69	6236
2384.54	6224
2386.4	6226
2388.25	6196
2390.1	6220
2391.95	6172
2393.8	6248
2395.65	6180
2397.5	6122
2399.35	6108
2401.2	6202
2403.05	6132
2404.9	6122
2406.75	6090
2408.59	6048
2410.44	6178
2412.28	6094
2414.13	6088
2415.97	6114
2417.82	6020
2419.66	6050
2421.5	5982
2423.35	6102
2425.19	6032
2427.03	5986
2428.87	5916
2430.71	5996
2432.55	5996
2434.39	5944
2436.23	5944
2438.06	5886
2439.9	5968
2441.74	5908
2443.57	5862
2445.41	5936
2447.24	5906
2449.08	5798
2450.91	5804
2452.75	5886
2454.58	5908
2456.41	5850
2458.24	5796
2460.08	5858
2461.91	5828
2463.74	5758
2465.57	5828
2467.4	5742
2469.22	5798
2471.05	5720
2472.88	5790
2474.71	5742
2476.53	5660
2478.36	5654
2480.19	5624
2482.01	5620
2483.83	5678
2485.66	5756
2487.48	5686
2489.3	5682
2491.13	5628
2492.95	5666
2494.77	5608
2496.59	5618
2498.41	5584
2500.23	5600
2502.05	5540
2503.87	5518
2505.68	5572
2507.5	5560
2509.32	5544
2511.14	5460
2512.95	5514
2514.77	5472
2516.58	5462
2518.39	5422
2520.21	5394
2522.02	5424
2523.83	5378
2525.65	5360
2527.46	5394
2529.27	5388
2531.08	5320
2532.89	5330
2534.7	5312
2536.51	5418
2538.32	5318
2540.12	5262
2541.93	5260
2543.74	5284
2545.54	5290
2547.35	5228
2549.15	5230
2550.96	5236
2552.76	5306
2554.56	5188
2556.37	5216
2558.17	5176
2559.97	5236
2561.77	5180
2563.58	5214
2565.38	5144
2567.18	5148
2568.97	5116
2570.77	5112
2572.57	5086
2574.37	5100
2576.17	5060
2577.96	5070
2579.76	5014
2581.55	5040
2583.35	5008
2585.14	5082
2586.94	5128
2588.73	4974
2590.52	4904
2592.32	4972
2594.11	5012
2595.9	4992
2597.69	4910
2599.48	4936
2601.27	4958
2603.06	4950
2604.85	4906
2606.64	4846
2608.42	4826
2610.21	4902
2612	4850
2613.78	4846
2615.57	4788
2617.36	4814
2619.14	4786
2620.92	4774
2622.71	4714
2624.49	4786
2626.27	4832
2628.05	4834
2629.84	4752
2631.62	4752
2633.4	4784
2635.18	4696
2636.96	4712
2638.74	4650
2640.51	4730
2642.29	4656
2644.07	4624
2645.85	4664
2647.62	4566
2649.4	4646
2651.17	4508
2652.95	4504
2654.72	4570
2656.5	4526
2658.27	4540
2660.04	4566
2661.81	4486
2663.58	4552
2665.35	4556
2667.13	4512
2668.9	4604
2670.66	4474
2672.43	4488
2674.2	4520
2675.97	4402
2677.74	4488
2679.5	4414
2681.27	4382
2683.04	4344
2684.8	4390
2686.57	4348
2688.33	4338
2690.09	4390
2691.86	4388
2693.62	4424
2695.38	4292
2697.15	4302
2698.91	4284
2700.67	4324
2702.43	4364
2704.19	4312
2705.95	4284
2707.7	4258
2709.46	4270
2711.22	4232
2712.98	4220
2714.73	4162
2716.49	4216
2718.25	4212
2720	4214
2721.76	4196
2723.51	4152
2725.26	4168
2727.02	4142
2728.77	4134
2730.52	4096
2732.27	4048
2734.02	4084
2735.77	4076
2737.52	4116
2739.27	4114
2741.02	4016
2742.77	3970
2744.52	4064
2746.27	3952
2748.01	4046
2749.76	4012
2751.51	3972
2753.25	3938
2755	3942
2756.74	3984
2758.48	3918
2760.23	3834
2761.97	3936
2763.71	3860
2765.45	3860
2767.19	3894
2768.94	3872
2770.68	3810
2772.42	3848
2774.16	3868
2775.89	3820
2777.63	3834
2779.37	3768
2781.11	3764
2782.84	3766
2784.58	3758
2786.32	3780
2788.05	3796
2789.79	3740
2791.52	3754
2793.25	3720
2794.99	3704
2796.72	3672
2798.45	3726
2800.18	3676
2801.92	3674
2803.65	3660
2805.38	3624
2807.11	3654
2808.84	3620
2810.57	3692
2812.29	3658
2814.02	3550
2815.75	3586
2817.47	3560
2819.2	3514
2820.93	3494
2822.65	3558
2824.38	3584
2826.1	3544
2827.82	3630
2829.55	3534
2831.27	3524
2832.99	3510
2834.71	3476
2836.44	3406
2838.16	3462
2839.88	3442
2841.6	3426
2843.32	3430
2845.03	3426
2846.75	3488
2848.47	3418
2850.19	3380
2851.9	3406
2853.62	3384
2855.34	3336
2857.05	3334
2858.77	3332
2860.48	3336
2862.19	3274
2863.91	3226
2865.62	3236
2867.33	3278
2869.04	3238
2870.76	3274
2872.47	3282
2874.18	3272
2875.89	3218
2877.6	3260
2879.31	3208
2881.01	3176
2882.72	3234
2884.43	3150
2886.14	3162
2887.84	3178
2889.55	3182
2891.25	3202
2892.96	3144
2894.66	3138
2896.37	3186
2898.07	3072
2899.77	3146
2901.48	3170
2903.18	3112
2904.88	3042
2906.58	3044
2908.28	3112
2909.98	3086
2911.68	3068
2913.38	2988
2915.08	3056
2916.78	3018
2918.47	3094
2920.17	3056
2921.87	3064
2923.56	2998
2925.26	3030
2926.95	3026
2928.65	3002
2930.34	3046
2932.04	3058
2933.73	2986
2935.42	2912
2937.11	2970
2938.81	2982
2940.5	3000
2942.19	2980
2943.88	2902
2945.57	2882
2947.26	2930
2948.95	2936
2950.64	2924
2952.32	2902
2954.01	2890
2955.7	2904
2957.38	2904
2959.07	2856
2960.75	2878
2962.44	2878
2964.12	2882
2965.81	2816
2967.49	2788
2969.17	2836
2970.86	2788
2972.54	2792
2974.22	2780
2975.9	2764
2977.58	2734
2979.26	2796
2980.94	2736
2982.62	2706
2984.3	2686
2985.98	2782
2987.66	2690
2989.33	2672
2991.01	2720
2992.69	2772
2994.36	2734
2996.04	2680
2997.71	2690
2999.39	2646