File: muestras/tallo/2/Organic_07.txt
#Acq. time (s)=	10
#Accumulations=	1
#Range (cm-¹)=	100...3000
#Windows=	3
#Autofocus=	Off
#AutoExposure=	Off
#Spike filter=	Off
#Delay time (s)=	0
#Binning=	1
#Readout mode=	Signal
#DeNoise=	Off
#ICS correction=	Off
#Dark correction=	Off
#Inst. Process=	Off
#Instrument=	LabRAM HR Evol
#Detector=	Syncerity OE
#Objective=	x100_VIS
#Grating=	600 (500nm)
#ND Filter=	3.2%
#Laser=	633nm_Edge
#Hole=	100.021
#Range=	Visible
#Project=	Omar
#Sample=	26-06-23
#Site=	2
#Title=	Organic
#Remark=
#Date=	26.06.2023 16:21
#Acquired=	26.06.2023 16:21:54
101.018	3948
103.586	3968
106.152	3948
108.717	4028
111.281	4020
113.845	4202
116.407	4088
118.969	4108
121.53	4124
124.09	4190
126.649	4112
129.207	4260
131.765	4196
134.321	4184
136.877	4274
139.432	4204
141.985	4210
144.538	4196
147.09	4324
149.641	4338
152.191	4272
154.741	4244
157.289	4356
159.837	4318
162.385	4326
164.93	4358
167.476	4392
170.019	4368
172.562	4476
175.105	4432
177.646	4394
180.188	4338
182.727	4422
185.266	4378
187.804	4412
190.342	4392
192.878	4426
195.413	4444
197.948	4562
200.481	4532
203.014	4574
205.546	4598
208.077	4578
210.608	4664
213.137	4704
215.666	4654
218.194	4690
220.721	4680
223.247	4686
225.772	4716
228.295	4772
230.819	4824
233.342	4908
235.864	4852
238.384	4804
240.904	4894
243.423	4968
245.941	4830
248.46	4936
250.975	4930
253.492	4948
256.006	5008
258.519	4982
261.033	4968
263.545	4968
266.057	4872
268.567	4946
271.076	4952
273.585	4930
276.094	5006
278.601	5004
281.107	5014
283.612	5144
286.116	5154
288.62	5174
291.123	5056
293.625	5068
296.126	5178
298.626	5360
301.126	5216
303.625	5234
306.122	5310
308.62	5332
311.114	5294
313.61	5400
316.105	5340
318.599	5332
321.09	5420
323.583	5342
326.073	5426
328.563	5344
331.053	5516
333.541	5366
336.029	5386
338.515	5468
341.001	5510
343.486	5520
345.97	5626
348.453	5512
350.936	5538
353.418	5646
355.898	5644
358.378	5648
360.858	5678
363.336	5674
365.813	5762
368.29	5720
370.766	5716
373.241	5708
375.715	5756
378.188	5588
380.66	5730
383.132	5804
385.603	5740
388.072	5680
390.541	5676
393.01	5878
395.477	5750
397.943	5892
400.409	5844
402.875	5822
405.338	5928
407.802	6070
410.263	5942
412.725	6036
415.185	6114
417.646	6084
420.104	6158
422.564	6162
425.02	6158
427.477	6290
429.933	6238
432.388	6342
434.841	6204
437.294	6216
439.748	6272
442.199	6294
444.65	6402
447.1	6372
449.549	6332
451.997	6418
454.445	6422
456.891	6420
459.337	6368
461.782	6444
464.227	6560
466.669	6394
469.112	6456
471.554	6518
473.995	6568
476.434	6614
478.874	6552
481.312	6718
483.749	6612
486.186	6618
488.622	6754
491.057	6636
493.491	6698
495.925	6716
498.357	6808
500.789	6740
503.221	6848
505.65	6892
508.079	6882
510.509	6944
512.936	6790
515.363	6910
517.789	6942
520.214	6898
522.638	6998
525.062	6958
527.485	6934
529.907	6946
532.328	6932
534.748	6938
537.168	7022
539.587	7034
542.005	7110
544.423	7162
546.838	7042
549.254	7200
551.669	7170
554.082	7102
556.496	7190
558.909	7248
561.319	7140
563.731	7230
566.14	7342
568.549	7316
570.957	7292
573.364	7342
575.771	7348
578.177	7386
580.581	7568
582.987	7472
585.39	7532
587.792	7598
590.193	7640
592.594	7502
594.996	7550
597.395	7768
599.793	7662
602.191	7702
604.588	7850
606.984	7878
609.378	7836
611.773	7850
614.167	8014
616.56	8074
618.953	8086
621.343	8118
623.734	8176
626.124	8198
628.512	8378
630.901	8218
633.289	8282
635.675	8330
638.061	8488
640.446	8446
642.831	8396
645.213	8526
647.595	8728
649.978	8682
652.359	8688
654.738	8766
657.117	8854
659.497	8902
661.875	8830
664.252	8796
666.628	8852
669.003	8992
671.378	8990
673.751	9024
676.124	9132
678.497	9130
680.868	9128
683.239	9196
685.609	9180
687.977	9250
690.346	9200
692.714	9374
695.081	9366
697.446	9454
699.812	9472
702.175	9502
704.539	9456
706.901	9720
709.264	9572
711.625	9652
713.986	9744
716.345	9858
718.705	9960
721.062	10060
723.419	9918
725.775	10028
728.132	10082
730.487	10248
732.841	10258
735.194	10316
737.546	10404
739.898	10376
742.249	10382
744.599	10530
746.949	10554
749.298	10512
751.646	10596
753.993	10632
756.34	10722
758.684	10852
761.029	10774
763.374	10898
765.716	11022
768.059	11098
770.401	11054
772.741	11106
775.082	11160
777.421	11260
779.76	11258
782.097	11328
784.434	11320
786.771	11446
789.106	11402
791.44	11488
793.775	11688
796.108	11752
798.44	11794
800.771	11884
803.102	11896
805.432	12024
807.761	12082
810.09	12162
812.417	12222
814.744	12356
817.071	12446
819.396	12520
821.721	12444
824.045	12630
826.367	12776
828.69	12934
831.012	12918
833.332	13076
835.653	13172
837.972	13268
840.29	13304
842.609	13368
844.925	13526
847.242	13694
849.557	13706
851.871	13626
854.186	13810
856.498	13836
858.81	13862
861.122	14184
863.434	14292
865.744	14262
868.053	14324
870.361	14546
872.669	14368
874.976	14524
877.282	14556
879.588	14692
881.893	14872
884.197	14830
886.5	14838
888.802	14782
891.104	14922
893.405	15044
895.706	15242
898.004	15130
900.303	15306
902.6	15348
904.898	15376
907.194	15268
909.49	15522
911.785	15606
914.08	15650
916.372	15730
918.666	15896
920.957	16054
923.248	16038
925.538	16026
927.828	16154
930.118	16370
932.406	16480
934.693	16438
936.979	16748
939.265	16770
941.55	16758
943.835	16964
946.118	17056
948.401	17048
950.682	17338
952.964	17294
955.245	17506
957.525	17482
959.803	17474
962.082	17796
964.36	17860
966.636	17942
968.913	18016
971.188	18155
973.463	18252
975.736	18296
978.009	18410
980.282	18300
982.554	18568
984.824	18580
987.095	18562
989.364	18620
991.633	18796
993.9	18818
996.167	18762
998.434	18952
1000.7	19144
1002.96	19082
1005.23	19278
1007.49	19268
1009.76	19406
1012.02	19654
1014.28	19512
1016.54	19798
1018.8	19824
1021.06	19876
1023.32	19964
1025.57	19966
1027.83	20314
1030.09	20208
1032.34	20252
1034.6	20364
1036.85	20522
1039.1	20650
1041.35	20660
1043.61	20788
1045.86	20846
1048.11	21128
1050.36	20988
1052.61	21144
1054.85	21300
1057.1	21262
1059.35	21526
1061.59	21474
1063.84	21458
1066.08	21560
1068.33	21550
1070.57	21702
1072.81	21876
1075.05	21788
1077.29	21860
1079.53	22094
1081.77	21728
1084.01	21972
1086.25	21850
1088.48	21960
1090.72	21928
1092.96	21988
1095.19	21800
1097.43	21948
1099.66	22028
1101.89	21964
1104.12	22160
1106.35	22086
1108.59	21892
1110.81	22018
1113.04	22252
1115.27	22062
1117.5	22188
1119.73	22106
1121.95	22198
1124.18	22174
1126.4	22332
1128.63	22220
1130.85	22408
1133.07	22492
1135.29	22338
1137.51	22554
1139.73	22616
1141.95	22578
1144.17	22428
1146.39	22490
1148.61	22634
1150.82	22304
1153.04	22670
1155.26	22656
1157.47	22744
1159.68	22550
1161.9	22566
1164.11	22694
1166.32	22706
1168.53	22820
1170.74	22484
1172.95	22562
1175.16	22566
1177.37	22564
1179.58	22278
1181.78	22258
1183.99	22324
1186.19	22282
1188.4	22200
1190.6	22098
1192.8	21950
1195.01	22016
1197.21	21942.4
1199.41	21845.2
1201.61	21651.1
1203.81	21825
1206.01	21708.3
1208.2	21691.5
1210.4	21429.4
1212.6	21249.8
1214.8	21323.9
1216.99	21143.5
1219.18	21132.3
1221.38	21069.4
1223.57	21029.8
1225.76	20872.9
1227.96	20714.3
1230.15	20701.5
1232.34	20810.9
1234.53	20734.1
1236.71	20623.1
1238.9	20607.6
1241.09	20458.5
1243.28	20408.6
1245.46	20407.6
1247.65	20319
1249.83	20220.8
1252.02	20271.6
1254.2	20136.3
1256.38	20077.8
1258.56	20089.4
1260.74	19941.4
1262.92	19941.8
1265.1	19759.5
1267.28	19699.7
1269.46	19703.8
1271.64	19674.9
1273.82	19541.4
1275.99	19518.2
1278.17	19539.1
1280.34	19313.7
1282.52	19318.1
1284.69	19230.6
1286.86	19197.7
1289.03	19061.6
1291.21	19127.9
1293.38	18936.8
1295.55	18760.2
1297.71	18798.6
1299.88	18733.6
1302.05	18629.2
1304.22	18475.7
1306.38	18409.2
1308.43	18326
1310.61	18362
1312.78	18164
1314.96	18060
1317.13	17916
1319.3	17864
1321.48	17872
1323.65	17684
1325.82	17704
1327.99	17524
1330.16	17338
1332.33	17176
1334.5	17282
1336.66	17140
1338.83	16930
1341	16946
1343.16	16814
1345.33	16652
1347.49	16610
1349.65	16610
1351.82	16464
1353.98	16348
1356.14	16470
1358.3	16224
1360.46	15784
1362.62	15980
1364.78	16166
1366.94	15906
1369.09	15630
1371.25	15772
1373.41	15724
1375.56	15520
1377.72	15632
1379.87	15428
1382.02	15408
1384.17	15472
1386.33	15242
1388.48	15230
1390.63	15158
1392.78	15072
1394.93	15016
1397.07	14926
1399.22	14766
1401.37	14868
1403.52	14676
1405.66	14708
1407.81	14764
1409.95	14682
1412.09	14502
1414.24	14492
1416.38	14274
1418.52	14140
1420.66	14176
1422.8	14236
1424.94	14204
1427.08	14140
1429.22	13944
1431.35	13834
1433.49	14018
1435.63	13940
1437.76	13952
1439.9	13798
1442.03	13834
1444.17	13744
1446.3	13472
1448.43	13612
1450.56	13572
1452.69	13498
1454.82	13492
1456.95	13406
1459.08	13450
1461.21	13372
1463.34	13388
1465.46	13222
1467.59	13300
1469.71	13078
1471.84	13124
1473.96	13122
1476.08	13078
1478.21	12950
1480.33	13040
1482.45	12948
1484.57	12924
1486.69	12932
1488.81	13016
1490.93	12900
1493.05	12888
1495.16	12748
1497.28	12684
1499.4	12514
1501.51	12738
1503.63	12540
1505.74	12508
1507.85	12464
1509.97	12422
1512.08	12454
1514.19	12318
1516.3	12362
1518.41	12260
1520.52	12192
1522.63	12302
1524.73	12230
1526.84	11950
1528.95	12006
1531.06	12130
1533.16	11866
1535.26	11934
1537.37	11910
1539.47	11860
1541.57	11818
1543.68	11730
1545.78	11806
1547.88	11664
1549.98	11586
1552.08	11678
1554.18	11658
1556.27	11566
1558.37	11450
1560.47	11494
1562.56	11486
1564.66	11322
1566.75	11440
1568.85	11484
1570.94	11254
1573.03	11406
1575.13	11200
1577.22	11298
1579.31	11306
1581.4	11444
1583.49	11214
1585.58	11204
1587.66	11076
1589.75	11186
1591.84	10976
1593.93	10950
1596.01	11166
1598.1	10960
1600.18	11188
1602.26	11024
1604.35	11114
1606.43	11056
1608.51	11040
1610.59	10876
1612.67	11106
1614.75	10990
1616.83	11066
1618.91	10976
1620.99	10928
1623.06	10940
1625.14	11000
1627.21	10852
1629.29	10906
1631.36	10802
1633.44	10818
1635.51	10754
1637.58	10646
1639.66	10772
1641.73	10718
1643.8	10686
1645.87	10592
1647.94	10626
1650	10614
1652.07	10428
1654.14	10568
1656.21	10496
1658.27	10604
1660.34	10490
1662.4	10384
1664.47	10396
1666.53	10440
1668.59	10250
1670.66	10316
1672.72	10280
1674.78	10308
1676.84	10300
1678.9	10224
1680.96	10324
1683.01	10066
1685.07	10180
1687.13	10088
1689.19	10104
1691.24	10066
1693.3	10020
1695.35	9986
1697.4	10012
1699.46	9976
1701.51	10008
1703.56	9754
1705.61	9814
1707.66	9918
1709.71	9880
1711.76	9890
1713.81	9912
1715.86	9862
1717.91	9882
1719.95	9770
1722	9692
1724.04	9806
1726.09	9544
1728.13	9618
1730.18	9696
1732.22	9608
1734.26	9650
1736.3	9694
1738.34	9546
1740.38	9774
1742.42	9554
1744.46	9636
1746.5	9596
1748.54	9552
1750.58	9598
1752.61	9438
1754.65	9638
1756.68	9486
1758.72	9508
1760.75	9496
1762.79	9550
1764.82	9610
1766.85	9526
1768.88	9532
1770.91	9454
1772.94	9380
1774.97	9520
1777	9382
1779.03	9366
1781.06	9366
1783.09	9368
1785.11	9472
1787.14	9456
1789.16	9518
1791.19	9366
1793.21	9228
1795.23	9276
1797.26	9446
1799.28	9232
1801.3	9194
1803.32	9262
1805.34	9252
1807.36	9296
1809.38	9206
1811.4	9174
1813.42	9222
1815.43	9142
1817.45	9046
1819.47	9034
1821.48	9084
1823.49	8956
1825.51	9116
1827.52	9104
1829.54	9048
1831.55	8936
1833.56	9014
1835.57	8906
1837.58	9002
1839.59	9004
1841.6	8986
1843.61	8914
1845.61	8874
1847.62	8866
1849.63	8850
1851.63	8916
1853.64	8858
1855.64	8704
1857.65	8736
1859.65	8696
1861.65	8834
1863.65	8764
1865.66	8734
1867.66	8828
1869.66	8582
1871.66	8688
1873.66	8668
1875.65	8674
1877.65	8662
1879.65	8614
1881.65	8618
1883.64	8644
1885.64	8646
1887.63	8692
1889.63	8624
1891.62	8482
1893.61	8718
1895.6	8606
1897.6	8490
1899.59	8512
1901.58	8482
1903.57	8568
1905.56	8596
1907.54	8566
1909.53	8594
1911.52	8594
1913.51	8562
1915.49	8480
1917.48	8464
1919.46	8554
1921.45	8548
1923.43	8418
1925.41	8406
1927.4	8366
1929.38	8470
1931.36	8544
1933.34	8480
1935.32	8494
1937.3	8410
1939.28	8510
1941.26	8312
1943.23	8290
1945.21	8404
1947.19	8334
1949.16	8266
1951.14	8342
1953.11	8396
1955.09	8316
1957.06	8296
1959.03	8334
1961	8202
1962.98	8240
1964.95	8254
1966.92	8222
1968.89	8220
1970.85	8270
1972.82	8118
1974.79	8048
1976.76	8218
1978.73	8222
1980.69	8148
1982.66	7976
1984.62	8214
1986.59	8200
1988.55	8192
1990.51	8146
1992.47	8118
1994.44	7980
1996.4	8000
1998.36	8042
2000.32	8106
2002.28	7996
2004.24	8048
2006.19	8026
2008.15	7950
2010.11	8070
2012.06	8114
2014.02	8014
2015.98	8040
2017.93	8002
2019.88	8078
2021.84	7974
2023.79	7952
2025.74	7936
2027.69	7854
2029.65	7972
2031.6	7890
2033.55	7912
2035.5	7858
2037.44	7832
2039.39	7870
2041.34	8016
2043.29	7746
2045.23	7848
2047.18	7686
2049.12	7896
2051.07	7866
2053.01	7866
2054.95	7816
2056.9	7756
2058.84	7748
2060.78	7824
2062.72	7740
2064.66	7698
2066.6	7748
2068.54	7830
2070.48	7810
2072.42	7662
2074.35	7592
2076.29	7612
2078.23	7772
2080.16	7678
2082.1	7526
2084.03	7648
2085.96	7718
2087.9	7632
2089.83	7556
2091.76	7570
2093.69	7610
2095.62	7630
2097.55	7556
2099.48	7600
2101.41	7552
2103.34	7492
2105.27	7624
2107.2	7594
2109.12	7514
2111.05	7484
2112.98	7478
2114.9	7514
2116.82	7438
2118.75	7400
2120.67	7390
2122.59	7354
2124.52	7442
2126.44	7390
2128.36	7508
2130.28	7426
2132.2	7592
2134.12	7400
2136.04	7406
2137.95	7346
2139.87	7356
2141.79	7364
2143.7	7400
2145.62	7343.81
2147.53	7352.48
2149.45	7351.32
2151.36	7293.75
2153.28	7317.75
2155.19	7240.15
2157.1	7169.18
2159.01	7169.35
2160.92	7234
2162.83	7203.17
2164.74	7133.46
2166.65	7076.47
2168.56	7122.77
2170.47	7107.52
2172.38	7159.79
2174.28	7150.47
2176.19	7077.36
2178.09	7020.44
2180	7075.41
2181.9	7100.21
2183.81	7047.68
2185.71	7013.09
2187.61	7014.04
2189.52	7037.21
2191.42	6995.43
2193.32	7048.58
2195.22	7000.94
2197.12	7013.63
2199.02	6989.07
2200.92	6938.86
2202.82	6981.15
2204.71	6933.11
2206.61	6885.87
2208.51	6965.21
2210.4	6966.55
2212.3	6911.52
2214.19	6957.69
2216.09	6909.01
2217.98	6903.57
2219.87	6905.72
2221.77	6977.7
2223.66	6962.33
2225.55	6934.95
2227.44	6959.56
2229.33	6935.85
2231.22	6902.46
2233.11	6946.97
2235	6967.83
2236.88	6950.19
2238.77	6965.43
2240.66	6987.83
2242.07	6868
2243.97	6864
2245.87	7000
2247.76	6964
2249.65	6958
2251.55	6846
2253.44	6934
2255.33	6818
2257.22	6812
2259.12	6922
2261.01	6872
2262.9	6856
2264.78	6922
2266.67	6848
2268.56	6750
2270.45	6764
2272.34	6874
2274.22	6750
2276.11	6814
2277.99	6824
2279.88	6804
2281.76	6704
2283.65	6778
2285.53	6788
2287.41	6838
2289.3	6692
2291.18	6804
2293.06	6762
2294.94	6690
2296.82	6674
2298.7	6704
2300.58	6622
2302.46	6728
2304.33	6592
2306.21	6664
2308.09	6616
2309.96	6612
2311.84	6580
2313.71	6628
2315.59	6532
2317.46	6548
2319.33	6556
2321.21	6588
2323.08	6576
2324.95	6430
2326.82	6538
2328.69	6506
2330.56	6486
2332.43	6418
2334.3	6600
2336.17	6600
2338.03	6536
2339.9	6484
2341.77	6494
2343.63	6512
2345.5	6528
2347.36	6604
2349.23	6424
2351.09	6492
2352.95	6548
2354.82	6472
2356.68	6448
2358.54	6460
2360.4	6502
2362.26	6494
2364.12	6472
2365.98	6382
2367.84	6392
2369.7	6458
2371.56	6390
2373.41	6426
2375.27	6354
2377.12	6354
2378.98	6304
2380.84	6324
2382.69	6390
2384.54	6364
2386.4	6232
2388.25	6326
2390.1	6324
2391.95	6302
2393.8	6278
2395.65	6258
2397.5	6252
2399.35	6260
2401.2	6268
2403.05	6138
2404.9	6220
2406.75	6182
2408.59	6154
2410.44	6204
2412.28	6102
2414.13	6150
2415.97	6186
2417.82	6126
2419.66	6128
2421.5	6180
2423.35	6090
2425.19	6152
2427.03	6064
2428.87	6162
2430.71	6086
2432.55	5952
2434.39	6014
2436.23	6058
2438.06	6038
2439.9	6050
2441.74	6020
2443.57	6036
2445.41	6000
2447.24	6128
2449.08	5948
2450.91	5912
2452.75	6016
2454.58	5930
2456.41	5950
2458.24	5870
2460.08	5906
2461.91	5852
2463.74	5834
2465.57	5908
2467.4	5836
2469.22	5824
2471.05	5764
2472.88	5866
2474.71	5804
2476.53	5808
2478.36	5894
2480.19	5830
2482.01	5868
2483.83	5826
2485.66	5756
2487.48	5736
2489.3	5744
2491.13	5704
2492.95	5676
2494.77	5688
2496.59	5668
2498.41	5664
2500.23	5654
2502.05	5600
2503.87	5676
2505.68	5560
2507.5	5574
2509.32	5664
2511.14	5620
2512.95	5676
2514.77	5564
2516.58	5626
2518.39	5586
2520.21	5596
2522.02	5438
2523.83	5554
2525.65	5528
2527.46	5550
2529.27	5528
2531.08	5432
2532.89	5482
2534.7	5488
2536.51	5412
2538.32	5350
2540.12	5482
2541.93	5468
2543.74	5414
2545.54	5430
2547.35	5420
2549.15	5368
2550.96	5358
2552.76	5334
2554.56	5296
2556.37	5302
2558.17	5320
2559.97	5274
2561.77	5272
2563.58	5272
2565.38	5226
2567.18	5246
2568.97	5234
2570.77	5200
2572.57	5244
2574.37	5114
2576.17	5222
2577.96	5146
2579.76	5116
2581.55	5140
2583.35	5136
2585.14	5106
2586.94	5052
2588.73	5026
2590.52	5052
2592.32	5054
2594.11	5112
2595.9	5020
2597.69	5044
2599.48	5040
2601.27	5060
2603.06	5022
2604.85	4958
2606.64	5084
2608.42	4944
2610.21	4924
2612	4948
2613.78	4958
2615.57	4922
2617.36	4900
2619.14	4928
2620.92	4900
2622.71	4884
2624.49	4890
2626.27	4826
2628.05	4840
2629.84	4814
2631.62	4798
2633.4	4716
2635.18	4790
2636.96	4772
2638.74	4712
2640.51	4722
2642.29	4668
2644.07	4744
2645.85	4616
2647.62	4674
2649.4	4668
2651.17	4640
2652.95	4686
2654.72	4584
2656.5	4590
2658.27	4634
2660.04	4684
2661.81	4606
2663.58	4588
2665.35	4554
2667.13	4508
2668.9	4556
2670.66	4560
2672.43	4546
2674.2	4656
2675.97	4534
2677.74	4514
2679.5	4458
2681.27	4442
2683.04	4538
2684.8	4508
2686.57	4414
2688.33	4438
2690.09	4412
2691.86	4420
2693.62	4378
2695.38	4410
2697.15	4390
2698.91	4406
2700.67	4360
2702.43	4342
2704.19	4362
2705.95	4428
2707.7	4356
2709.46	4294
2711.22	4360
2712.98	4228
2714.73	4288
2716.49	4296
2718.25	4230
2720	4286
2721.76	4318
2723.51	4198
2725.26	4194
2727.02	4204
2728.77	4128
2730.52	4188
2732.27	4128
2734.02	4228
2735.77	4134
2737.52	4110
2739.27	4118
2741.02	4108
2742.77	4070
2744.52	4138
2746.27	4110
2748.01	4086
2749.76	4014
2751.51	4096
2753.25	4030
2755	4006
2756.74	3960
2758.48	3980
2760.23	3958
2761.97	3964
2763.71	3952
2765.45	3964
2767.19	3994
2768.94	3930
2770.68	4000
2772.42	3804
2774.16	3862
2775.89	3938
2777.63	3888
2779.37	3844
2781.11	3870
2782.84	3848
2784.58	3778
2786.32	3822
2788.05	3872
2789.79	3754
2791.52	3884
2793.25	3752
2794.99	3852
2796.72	3738
2798.45	3740
2800.18	3760
2801.92	3794
2803.65	3766
2805.38	3712
2807.11	3750
2808.84	3706
2810.57	3770
2812.29	3724
2814.02	3646
2815.75	3660
2817.47	3602
2819.2	3662
2820.93	3580
2822.65	3662
2824.38	3610
2826.1	3572
2827.82	3660
2829.55	3584
2831.27	3532
2832.99	3554
2834.71	3532
2836.44	3568
2838.16	3518
2839.88	3524
2841.6	3522
2843.32	3488
2845.03	3504
2846.75	3440
2848.47	3496
2850.19	3454
2851.9	3430
2853.62	3330
2855.34	3320
2857.05	3404
2858.77	3312
2860.48	3390
2862.19	3446
2863.91	3352
2865.62	3282
2867.33	3352
2869.04	3292
2870.76	3330
2872.47	3388
2874.18	3308
2875.89	3354
2877.6	3326
2879.31	3286
2881.01	3278
2882.72	3290
2884.43	3258
2886.14	3232
2887.84	3208
2889.55	3182
2891.25	3216
2892.96	3186
2894.66	3158
2896.37	3178
2898.07	3166
2899.77	3068
2901.48	3138
2903.18	3110
2904.88	3168
2906.58	3204
2908.28	3182
2909.98	3220
2911.68	3126
2913.38	3084
2915.08	3092
2916.78	3154
2918.47	3076
2920.17	3088
2921.87	3076
2923.56	3054
2925.26	3072
2926.95	3092
2928.65	3106
2930.34	3056
2932.04	3032
2933.73	3062
2935.42	2962
2937.11	3042
2938.81	3056
2940.5	2946
2942.19	2958
2943.88	3018
2945.57	2934
2947.26	2984
2948.95	2992
2950.64	2956
2952.32	2942
2954.01	2970
2955.7	2976
2957.38	2956
2959.07	2966
2960.75	2906
2962.44	2934
2964.12	2898
2965.81	2914
2967.49	2826
2969.17	2844
2970.86	2816
2972.54	2864
2974.22	2850
2975.9	2830
2977.58	2786
2979.26	2826
2980.94	2834
2982.62	2822
2984.3	2834
2985.98	2838
2987.66	2706
2989.33	2762
2991.01	2814
2992.69	2758
2994.36	2722
2996.04	2698
2997.71	2736
2999.39	2750