File: muestras/tallo/2/Organic_17.txt
#Acq. time (s)=	10
#Accumulations=	1
#Range (cm-¹)=	100...3000
#Windows=	3
#Autofocus=	Off
#AutoExposure=	Off
#Spike filter=	Off
#Delay time (s)=	0
#Binning=	1
#Readout mode=	Signal
#DeNoise=	Off
#ICS correction=	Off
#Dark correction=	Off
#Inst. Process=	Off
#Instrument=	LabRAM HR Evol
#Detector=	Syncerity OE
#Objective=	x100_VIS
#Grating=	600 (500nm)
#ND Filter=	3.2%
#Laser=	633nm_Edge
#Hole=	100.021
#Range=	Visible
#Project=	Omar
#Sample=	26-06-23
#Site=	2
#Title=	Organic
#Remark=
#Date=	26.06.2023 16:31
#Acquired=	26.06.2023 16:31:30
101.018	3610
103.586	3506
106.152	3652
108.717	3592
111.281	3688
113.845	3680
116.407	3770
118.969	3652
121.53	3620
124.09	3666
126.649	3742
129.207	3780
131.765	3680
134.321	3754
136.877	3754
139.432	3774
141.985	3704
144.538	3774
147.09	3762
149.641	3760
152.191	3824
154.741	3832
157.289	3830
159.837	3836
162.385	3802
164.93	3898
167.476	3904
170.019	3896
172.562	3982
175.105	3900
177.646	3892
180.188	3948
182.727	3896
185.266	4004
187.804	3996
190.342	3984
192.878	3986
195.413	4000
197.948	3952
200.481	3998
203.014	4032
205.546	4070
208.077	4116
210.608	4090
213.137	4136
215.666	4128
218.194	4104
220.721	4118
223.247	4258
225.772	4194
228.295	4270
230.819	4290
233.342	4296
235.864	4294
238.384	4270
240.904	4334
243.423	4314
245.941	4352
248.46	4340
250.975	4338
253.492	4392
256.006	4322
258.519	4416
261.033	4466
263.545	4400
266.057	4352
268.567	4416
271.076	4482
273.585	4430
276.094	4448
278.601	4468
281.107	4534
283.612	4474
286.116	4504
288.62	4540
291.123	4542
293.625	4582
296.126	4674
298.626	4700
301.126	4738
303.625	4678
306.122	4642
308.62	4702
311.114	4692
313.61	4734
316.105	4716
318.599	4754
321.09	4792
323.583	4708
326.073	4802
328.563	4794
331.053	4734
333.541	4756
336.029	4764
338.515	4886
341.001	4816
343.486	4898
345.97	4880
348.453	4934
350.936	4970
353.418	4920
355.898	5050
358.378	4948
360.858	4998
363.336	5042
365.813	5016
368.29	5090
370.766	4968
373.241	4962
375.715	5088
378.188	5100
380.66	5018
383.132	4990
385.603	5108
388.072	5098
390.541	5110
393.01	5038
395.477	5096
397.943	5120
400.409	5198
402.875	5170
405.338	5200
407.802	5272
410.263	5324
412.725	5280
415.185	5244
417.646	5328
420.104	5408
422.564	5420
425.02	5522
427.477	5476
429.933	5474
432.388	5484
434.841	5444
437.294	5534
439.748	5540
442.199	5654
444.65	5558
447.1	5484
449.549	5632
451.997	5554
454.445	5614
456.891	5638
459.337	5602
461.782	5672
464.227	5628
466.669	5624
469.112	5654
471.554	5682
473.995	5664
476.434	5762
478.874	5720
481.312	5730
483.749	5832
486.186	5766
488.622	5864
491.057	5864
493.491	5808
495.925	5878
498.357	5940
500.789	5988
503.221	5900
505.65	5970
508.079	5966
510.509	5846
512.936	6002
515.363	6008
517.789	6098
520.214	6062
522.638	6030
525.062	6066
527.485	6026
529.907	6084
532.328	6124
534.748	6098
537.168	6112
539.587	6060
542.005	6146
544.423	6072
546.838	6056
549.254	6252
551.669	6190
554.082	6130
556.496	6256
558.909	6182
561.319	6250
563.731	6274
566.14	6284
568.549	6232
570.957	6396
573.364	6360
575.771	6376
578.177	6426
580.581	6400
582.987	6392
585.39	6450
587.792	6468
590.193	6484
592.594	6454
594.996	6600
597.395	6614
599.793	6528
602.191	6530
604.588	6632
606.984	6682
609.378	6674
611.773	6784
614.167	6794
616.56	6796
618.953	6888
621.343	6914
623.734	6924
626.124	7104
628.512	7028
630.901	7012
633.289	7100
635.675	7134
638.061	7194
640.446	7264
642.831	7332
645.213	7298
647.595	7366
649.978	7344
652.359	7406
654.738	7430
657.117	7396
659.497	7508
661.875	7402
664.252	7512
666.628	7494
669.003	7478
671.378	7616
673.751	7666
676.124	7660
678.497	7676
680.868	7720
683.239	7584
685.609	7670
687.977	7666
690.346	7794
692.714	7912
695.081	7816
697.446	7898
699.812	7896
702.175	7932
704.539	8076
706.901	8090
709.264	8060
711.625	8046
713.986	8138
716.345	8264
718.705	8232
721.062	8326
723.419	8256
725.775	8380
728.132	8440
730.487	8474
732.841	8468
735.194	8550
737.546	8530
739.898	8668
742.249	8736
744.599	8724
746.949	8796
749.298	8742
751.646	8752
753.993	8772
756.34	8842
758.684	8908
761.029	8936
763.374	9052
765.716	8982
768.059	9090
770.401	9084
772.741	9146
775.082	9156
777.421	9196
779.76	9216
782.097	9406
784.434	9314
786.771	9372
789.106	9440
791.44	9490
793.775	9586
796.108	9668
798.44	9676
800.771	9676
803.102	9766
805.432	9736
807.761	9752
810.09	9912
812.417	9970
814.744	10040
817.071	10160
819.396	10180
821.721	10136
824.045	10382
826.367	10328
828.69	10504
831.012	10512
833.332	10596
835.653	10696
837.972	10756
840.29	10898
842.609	10840
844.925	10832
847.242	10992
849.557	11034
851.871	11206
854.186	11132
856.498	11202
858.81	11320
861.122	11316
863.434	11410
865.744	11548
868.053	11510
870.361	11512
872.669	11604
874.976	11670
877.282	11776
879.588	11692
881.893	11782
884.197	11900
886.5	11884
888.802	11946
891.104	12106
893.405	11956
895.706	12258
898.004	12198
900.303	12308
902.6	12218
904.898	12334
907.194	12418
909.49	12236
911.785	12462
914.08	12508
916.372	12612
918.666	12602
920.957	12560
923.248	12782
925.538	12760
927.828	12848
930.118	12954
932.406	13004
934.693	13130
936.979	13210
939.265	13286
941.55	13292
943.835	13354
946.118	13342
948.401	13580
950.682	13670
952.964	13686
955.245	13678
957.525	13754
959.803	13928
962.082	14036
964.36	14232
966.636	14040
968.913	14162
971.188	14264
973.463	14472
975.736	14510
978.009	14420
980.282	14462
982.554	14622
984.824	14486
987.095	14768
989.364	14712
991.633	14844
993.9	14840
996.167	15004
998.434	14830
1000.7	15056
1002.96	15076
1005.23	15282
1007.49	15266
1009.76	15306
1012.02	15292
1014.28	15290
1016.54	15444
1018.8	15548
1021.06	15564
1023.32	15550
1025.57	15682
1027.83	15786
1030.09	15942
1032.34	16022
1034.6	15930
1036.85	16080
1039.1	16130
1041.35	16208
1043.61	16350
1045.86	16314
1048.11	16466
1050.36	16468
1052.61	16566
1054.85	16594
1057.1	16680
1059.35	16788
1061.59	16784
1063.84	16880
1066.08	17026
1068.33	17044
1070.57	17128
1072.81	16902
1075.05	16908
1077.29	17098
1079.53	17178
1081.77	16998
1084.01	17060
1086.25	17342
1088.48	17086
1090.72	17068
1092.96	17212
1095.19	17142
1097.43	17092
1099.66	17182
1101.89	17038
1104.12	17250
1106.35	17188
1108.59	17350
1110.81	17262
1113.04	17444
1115.27	17126
1117.5	17556
1119.73	17240
1121.95	17308
1124.18	17432
1126.4	17288
1128.63	17502
1130.85	17344
1133.07	17400
1135.29	17442
1137.51	17630
1139.73	17554
1141.95	17596
1144.17	17520
1146.39	17556
1148.61	17556
1150.82	17482
1153.04	17652
1155.26	17778
1157.47	17544
1159.68	17628
1161.9	17640
1164.11	17520
1166.32	17660
1168.53	17656
1170.74	17700
1172.95	17744
1175.16	17480
1177.37	17342
1179.58	17480
1181.78	17494
1183.99	17508
1186.19	17378
1188.4	17386
1190.6	17156
1192.8	17238
1195.01	17070
1197.21	17154.8
1199.41	17129.7
1201.61	17133.6
1203.81	17015.7
1206.01	16864.6
1208.2	16953.4
1210.4	16739
1212.6	16820.6
1214.8	16747.3
1216.99	16637.1
1219.18	16674
1221.38	16422.3
1223.57	16481.1
1225.76	16441.6
1227.96	16475.8
1230.15	16391.7
1232.34	16284
1234.53	16378.4
1236.71	16188.1
1238.9	16142.3
1241.09	16176.4
1243.28	16100.5
1245.46	16134.9
1247.65	16054.7
1249.83	15933.7
1252.02	15956.8
1254.2	15891.1
1256.38	15928.3
1258.56	15834.9
1260.74	15679.4
1262.92	15737.6
1265.1	15663.4
1267.28	15743.9
1269.46	15634.5
1271.64	15610.9
1273.82	15515
1275.99	15422.3
1278.17	15386.2
1280.34	15429.6
1282.52	15216.2
1284.69	15301
1286.86	15182.2
1289.03	15128.8
1291.21	15050.5
1293.38	15039.6
1295.55	15079.4
1297.71	14962.4
1299.88	14905.5
1302.05	14877.5
1304.22	14713.3
1306.38	14765.7
1308.43	14674
1310.61	14582
1312.78	14638
1314.96	14442
1317.13	14332
1319.3	14256
1321.48	14232
1323.65	14124
1325.82	14084
1327.99	14042
1330.16	13920
1332.33	13868
1334.5	13948
1336.66	13832
1338.83	13620
1341	13528
1343.16	13536
1345.33	13446
1347.49	13404
1349.65	13388
1351.82	13260
1353.98	13244
1356.14	12948
1358.3	13054
1360.46	12920
1362.62	13002
1364.78	12904
1366.94	12840
1369.09	12764
1371.25	12816
1373.41	12658
1375.56	12620
1377.72	12644
1379.87	12414
1382.02	12570
1384.17	12450
1386.33	12466
1388.48	12358
1390.63	12306
1392.78	12326
1394.93	12140
1397.07	12240
1399.22	12172
1401.37	12082
1403.52	11914
1405.66	12090
1407.81	11956
1409.95	11890
1412.09	11812
1414.24	11848
1416.38	11558
1418.52	11682
1420.66	11798
1422.8	11624
1424.94	11708
1427.08	11572
1429.22	11470
1431.35	11284
1433.49	11416
1435.63	11472
1437.76	11312
1439.9	11298
1442.03	11382
1444.17	11204
1446.3	11186
1448.43	11166
1450.56	11268
1452.69	11144
1454.82	11038
1456.95	11060
1459.08	10986
1461.21	10944
1463.34	10924
1465.46	11000
1467.59	10850
1469.71	10826
1471.84	10848
1473.96	10898
1476.08	10860
1478.21	10804
1480.33	10758
1482.45	10738
1484.57	10732
1486.69	10586
1488.81	10574
1490.93	10638
1493.05	10428
1495.16	10536
1497.28	10606
1499.4	10452
1501.51	10394
1503.63	10412
1505.74	10430
1507.85	10280
1509.97	10378
1512.08	10382
1514.19	10356
1516.3	10194
1518.41	10176
1520.52	10148
1522.63	10164
1524.73	10116
1526.84	10222
1528.95	10104
1531.06	9996
1533.16	9908
1535.26	9862
1537.37	10014
1539.47	9828
1541.57	9856
1543.68	9730
1545.78	9794
1547.88	9726
1549.98	9684
1552.08	9798
1554.18	9660
1556.27	9696
1558.37	9682
1560.47	9610
1562.56	9526
1564.66	9650
1566.75	9552
1568.85	9464
1570.94	9498
1573.03	9484
1575.13	9472
1577.22	9354
1579.31	9456
1581.4	9392
1583.49	9410
1585.58	9370
1587.66	9268
1589.75	9454
1591.84	9410
1593.93	9388
1596.01	9282
1598.1	9414
1600.18	9320
1602.26	9352
1604.35	9262
1606.43	9308
1608.51	9230
1610.59	9248
1612.67	9250
1614.75	9280
1616.83	9202
1618.91	9224
1620.99	9190
1623.06	9320
1625.14	9154
1627.21	9174
1629.29	9178
1631.36	9152
1633.44	9152
1635.51	8930
1637.58	9064
1639.66	9100
1641.73	9168
1643.8	9102
1645.87	8930
1647.94	9094
1650	8958
1652.07	9052
1654.14	8978
1656.21	9014
1658.27	8844
1660.34	8872
1662.4	8708
1664.47	8910
1666.53	8836
1668.59	8768
1670.66	8696
1672.72	8730
1674.78	8700
1676.84	8664
1678.9	8668
1680.96	8686
1683.01	8658
1685.07	8592
1687.13	8606
1689.19	8430
1691.24	8726
1693.3	8478
1695.35	8538
1697.4	8396
1699.46	8482
1701.51	8480
1703.56	8382
1705.61	8340
1707.66	8422
1709.71	8316
1711.76	8460
1713.81	8296
1715.86	8398
1717.91	8304
1719.95	8352
1722	8320
1724.04	8278
1726.09	8258
1728.13	8144
1730.18	8222
1732.22	8174
1734.26	8180
1736.3	8132
1738.34	8130
1740.38	8098
1742.42	8190
1744.46	8020
1746.5	8176
1748.54	8078
1750.58	8056
1752.61	8028
1754.65	8056
1756.68	8124
1758.72	7972
1760.75	8100
1762.79	7994
1764.82	8062
1766.85	8092
1768.88	7988
1770.91	7990
1772.94	8126
1774.97	8046
1777	7948
1779.03	7990
1781.06	8018
1783.09	7892
1785.11	7974
1787.14	7980
1789.16	7880
1791.19	7944
1793.21	7970
1795.23	7814
1797.26	7902
1799.28	7856
1801.3	7838
1803.32	7882
1805.34	7868
1807.36	7792
1809.38	7816
1811.4	7740
1813.42	7826
1815.43	7786
1817.45	7762
1819.47	7708
1821.48	7602
1823.49	7744
1825.51	7662
1827.52	7724
1829.54	7674
1831.55	7694
1833.56	7546
1835.57	7640
1837.58	7544
1839.59	7630
1841.6	7486
1843.61	7564
1845.61	7552
1847.62	7518
1849.63	7512
1851.63	7474
1853.64	7490
1855.64	7550
1857.65	7398
1859.65	7474
1861.65	7540
1863.65	7490
1865.66	7286
1867.66	7382
1869.66	7438
1871.66	7314
1873.66	7342
1875.65	7354
1877.65	7260
1879.65	7332
1881.65	7340
1883.64	7330
1885.64	7244
1887.63	7394
1889.63	7342
1891.62	7420
1893.61	7324
1895.6	7230
1897.6	7262
1899.59	7224
1901.58	7214
1903.57	7288
1905.56	7272
1907.54	7190
1909.53	7294
1911.52	7202
1913.51	7328
1915.49	7244
1917.48	7268
1919.46	7216
1921.45	7182
1923.43	7144
1925.41	7204
1927.4	7182
1929.38	7216
1931.36	7186
1933.34	7206
1935.32	7066
1937.3	7226
1939.28	7138
1941.26	7106
1943.23	7164
1945.21	7078
1947.19	7178
1949.16	7090
1951.14	7022
1953.11	7040
1955.09	7082
1957.06	6982
1959.03	7086
1961	7034
1962.98	6938
1964.95	7054
1966.92	6938
1968.89	7046
1970.85	6982
1972.82	7058
1974.79	6896
1976.76	6952
1978.73	6892
1980.69	6844
1982.66	6930
1984.62	6894
1986.59	6934
1988.55	6950
1990.51	6814
1992.47	6874
1994.44	6948
1996.4	6864
1998.36	6778
2000.32	6900
2002.28	6770
2004.24	6812
2006.19	6722
2008.15	6862
2010.11	6692
2012.06	6654
2014.02	6810
2015.98	6746
2017.93	6732
2019.88	6652
2021.84	6680
2023.79	6722
2025.74	6790
2027.69	6828
2029.65	6678
2031.6	6702
2033.55	6702
2035.5	6714
2037.44	6742
2039.39	6678
2041.34	6716
2043.29	6622
2045.23	6584
2047.18	6582
2049.12	6614
2051.07	6664
2053.01	6640
2054.95	6644
2056.9	6586
2058.84	6626
2060.78	6552
2062.72	6600
2064.66	6582
2066.6	6644
2068.54	6542
2070.48	6504
2072.42	6526
2074.35	6538
2076.29	6508
2078.23	6458
2080.16	6506
2082.1	6394
2084.03	6524
2085.96	6476
2087.9	6510
2089.83	6448
2091.76	6480
2093.69	6344
2095.62	6370
2097.55	6390
2099.48	6430
2101.41	6364
2103.34	6346
2105.27	6376
2107.2	6384
2109.12	6306
2111.05	6210
2112.98	6384
2114.9	6378
2116.82	6318
2118.75	6288
2120.67	6310
2122.59	6276
2124.52	6280
2126.44	6254
2128.36	6352
2130.28	6262
2132.2	6244
2134.12	6312
2136.04	6280
2137.95	6222
2139.87	6212
2141.79	6258
2143.7	6096
2145.62	6215.67
2147.53	6211.07
2149.45	6126.66
2151.36	6147.83
2153.28	6120.94
2155.19	6161.71
2157.1	6085.41
2159.01	6109.89
2160.92	6010.56
2162.83	6040
2164.74	6100.18
2166.65	6058.64
2168.56	6050.57
2170.47	6036.03
2172.38	5961.02
2174.28	6028.28
2176.19	5987.02
2178.09	5969.04
2180	5929.84
2181.9	5966.19
2183.81	5942.34
2185.71	5927.65
2187.61	5910.12
2189.52	5846.63
2191.42	5921.66
2193.32	5900.35
2195.22	5920.75
2197.12	5905.41
2199.02	5884.72
2200.92	5894.92
2202.82	5883.98
2204.71	5892.16
2206.61	5866.06
2208.51	5891.09
2210.4	5837.61
2212.3	5852.18
2214.19	5840.19
2216.09	5822.35
2217.98	5852.42
2219.87	5831.5
2221.77	5829.25
2223.66	5830.91
2225.55	5835.82
2227.44	5877.04
2229.33	5865.39
2231.22	5804.7
2233.11	5854.71
2235	5769.67
2236.88	5880.42
2238.77	5901.14
2240.66	5824.65
2242.07	5836
2243.97	5874
2245.87	5922
2247.76	5812
2249.65	5796
2251.55	5918
2253.44	5820
2255.33	5842
2257.22	5772
2259.12	5808
2261.01	5898
2262.9	5762
2264.78	5834
2266.67	5798
2268.56	5708
2270.45	5790
2272.34	5698
2274.22	5594
2276.11	5732
2277.99	5790
2279.88	5740
2281.76	5702
2283.65	5798
2285.53	5738
2287.41	5686
2289.3	5768
2291.18	5632
2293.06	5806
2294.94	5586
2296.82	5682
2298.7	5636
2300.58	5582
2302.46	5670
2304.33	5688
2306.21	5700
2308.09	5592
2309.96	5612
2311.84	5602
2313.71	5616
2315.59	5600
2317.46	5568
2319.33	5490
2321.21	5544
2323.08	5562
2324.95	5550
2326.82	5510
2328.69	5526
2330.56	5544
2332.43	5462
2334.3	5580
2336.17	5526
2338.03	5526
2339.9	5586
2341.77	5484
2343.63	5472
2345.5	5444
2347.36	5460
2349.23	5530
2351.09	5432
2352.95	5400
2354.82	5468
2356.68	5350
2358.54	5472
2360.4	5410
2362.26	5522
2364.12	5510
2365.98	5398
2367.84	5386
2369.7	5378
2371.56	5376
2373.41	5270
2375.27	5430
2377.12	5356
2378.98	5346
2380.84	5336
2382.69	5324
2384.54	5318
2386.4	5350
2388.25	5352
2390.1	5296
2391.95	5384
2393.8	5328
2395.65	5354
2397.5	5276
2399.35	5312
2401.2	5362
2403.05	5314
2404.9	5240
2406.75	5284
2408.59	5274
2410.44	5192
2412.28	5264
2414.13	5204
2415.97	5230
2417.82	5124
2419.66	5236
2421.5	5254
2423.35	5150
2425.19	5200
2427.03	5148
2428.87	5158
2430.71	5092
2432.55	5092
2434.39	5152
2436.23	5066
2438.06	5070
2439.9	5068
2441.74	5074
2443.57	5050
2445.41	5070
2447.24	5102
2449.08	4990
2450.91	5062
2452.75	5118
2454.58	5060
2456.41	5080
2458.24	5018
2460.08	5026
2461.91	4934
2463.74	4990
2465.57	4912
2467.4	5002
2469.22	4952
2471.05	4908
2472.88	4974
2474.71	4886
2476.53	4936
2478.36	4906
2480.19	4920
2482.01	4934
2483.83	4912
2485.66	4870
2487.48	4750
2489.3	4828
2491.13	4886
2492.95	4758
2494.77	4824
2496.59	4834
2498.41	4750
2500.23	4810
2502.05	4766
2503.87	4784
2505.68	4720
2507.5	4852
2509.32	4666
2511.14	4700
2512.95	4654
2514.77	4776
2516.58	4698
2518.39	4634
2520.21	4738
2522.02	4598
2523.83	4664
2525.65	4686
2527.46	4578
2529.27	4640
2531.08	4576
2532.89	4610
2534.7	4678
2536.51	4484
2538.32	4516
2540.12	4450
2541.93	4468
2543.74	4604
2545.54	4482
2547.35	4588
2549.15	4482
2550.96	4586
2552.76	4526
2554.56	4468
2556.37	4440
2558.17	4524
2559.97	4464
2561.77	4442
2563.58	4442
2565.38	4460
2567.18	4444
2568.97	4358
2570.77	4368
2572.57	4398
2574.37	4416
2576.17	4432
2577.96	4410
2579.76	4324
2581.55	4298
2583.35	4306
2585.14	4374
2586.94	4288
2588.73	4326
2590.52	4320
2592.32	4232
2594.11	4180
2595.9	4296
2597.69	4224
2599.48	4266
2601.27	4214
2603.06	4146
2604.85	4132
2606.64	4172
2608.42	4168
2610.21	4226
2612	4220
2613.78	4202
2615.57	4188
2617.36	4202
2619.14	4128
2620.92	4098
2622.71	4074
2624.49	4142
2626.27	4124
2628.05	4132
2629.84	4096
2631.62	4072
2633.4	4132
2635.18	4064
2636.96	4052
2638.74	4026
2640.51	4012
2642.29	4020
2644.07	4034
2645.85	4006
2647.62	3994
2649.4	3944
2651.17	3916
2652.95	3876
2654.72	3898
2656.5	3840
2658.27	3854
2660.04	3936
2661.81	3886
2663.58	3964
2665.35	3920
2667.13	3808
2668.9	3876
2670.66	3900
2672.43	3786
2674.2	3798
2675.97	3884
2677.74	3792
2679.5	3862
2681.27	3876
2683.04	3792
2684.8	3758
2686.57	3808
2688.33	3760
2690.09	3816
2691.86	3694
2693.62	3774
2695.38	3734
2697.15	3704
2698.91	3728
2700.67	3668
2702.43	3724
2704.19	3746
2705.95	3636
2707.7	3650
2709.46	3610
2711.22	3734
2712.98	3652
2714.73	3562
2716.49	3630
2718.25	3582
2720	3566
2721.76	3546
2723.51	3620
2725.26	3644
2727.02	3542
2728.77	3536
2730.52	3524
2732.27	3508
2734.02	3496
2735.77	3568
2737.52	3490
2739.27	3466
2741.02	3520
2742.77	3486
2744.52	3444
2746.27	3466
2748.01	3428
2749.76	3390
2751.51	3434
2753.25	3442
2755	3394
2756.74	3406
2758.48	3364
2760.23	3492
2761.97	3320
2763.71	3316
2765.45	3348
2767.19	3310
2768.94	3332
2770.68	3308
2772.42	3302
2774.16	3358
2775.89	3332
2777.63	3244
2779.37	3298
2781.11	3300
2782.84	3276
2784.58	3254
2786.32	3196
2788.05	3276
2789.79	3270
2791.52	3138
2793.25	3218
2794.99	3180
2796.72	3200
2798.45	3172
2800.18	3264
2801.92	3204
2803.65	3093
2805.38	3148
2807.11	3150
2808.84	3146
2810.57	3172
2812.29	3106
2814.02	3116
2815.75	3098
2817.47	3090
2819.2	3122
2820.93	3040
2822.65	3108
2824.38	3042
2826.1	3064
2827.82	3000
2829.55	2982
2831.27	3064
2832.99	3010
2834.71	3026
2836.44	2958
2838.16	2986
2839.88	2950
2841.6	3028
2843.32	2918
2845.03	2932
2846.75	3034
2848.47	2934
2850.19	2928
2851.9	2912
2853.62	2954
2855.34	2924
2857.05	2830
2858.77	2944
2860.48	2838
2862.19	2846
2863.91	2866
2865.62	2802
2867.33	2818
2869.04	2816
2870.76	2786
2872.47	2812
2874.18	2836
2875.89	2786
2877.6	2854
2879.31	2764
2881.01	2762
2882.72	2784
2884.43	2700
2886.14	2732
2887.84	2732
2889.55	2728
2891.25	2660
2892.96	2714
2894.66	2712
2896.37	2684
2898.07	2718
2899.77	2712
2901.48	2746
2903.18	2696
2904.88	2688
2906.58	2688
2908.28	2692
2909.98	2636
2911.68	2594
2913.38	2642
2915.08	2554
2916.78	2584
2918.47	2670
2920.17	2614
2921.87	2624
2923.56	2638
2925.26	2552
2926.95	2636
2928.65	2582
2930.34	2588
2932.04	2592
2933.73	2572
2935.42	2558
2937.11	2604
2938.81	2530
2940.5	2552
2942.19	2522
2943.88	2550
2945.57	2542
2947.26	2544
2948.95	2520
2950.64	2468
2952.32	2496
2954.01	2426
2955.7	2560
2957.38	2496
2959.07	2484
2960.75	2518
2962.44	2536
2964.12	2460
2965.81	2438
2967.49	2446
2969.17	2436
2970.86	2388
2972.54	2382
2974.22	2460
2975.9	2354
2977.58	2410
2979.26	2440
2980.94	2432
2982.62	2354
2984.3	2426
2985.98	2346
2987.66	2360
2989.33	2342
2991.01	2312
2992.69	2360
2994.36	2326
2996.04	2304
2997.71	2352
2999.39	2330