File: muestras/tallo/2/Organic_13.txt
#Acq. time (s)=	10
#Accumulations=	1
#Range (cm-¹)=	100...3000
#Windows=	3
#Autofocus=	Off
#AutoExposure=	Off
#Spike filter=	Off
#Delay time (s)=	0
#Binning=	1
#Readout mode=	Signal
#DeNoise=	Off
#ICS correction=	Off
#Dark correction=	Off
#Inst. Process=	Off
#Instrument=	LabRAM HR Evol
#Detector=	Syncerity OE
#Objective=	x100_VIS
#Grating=	600 (500nm)
#ND Filter=	3.2%
#Laser=	633nm_Edge
#Hole=	100.021
#Range=	Visible
#Project=	Omar
#Sample=	26-06-23
#Site=	2
#Title=	Organic
#Remark=
#Date=	26.06.2023 16:27
#Acquired=	26.06.2023 16:27:51
101.018	3694
103.586	3712
106.152	3754
108.717	3774
111.281	3814
113.845	3810
116.407	3764
118.969	3796
121.53	3848
124.09	3854
126.649	3902
129.207	3836
131.765	3892
134.321	3952
136.877	3920
139.432	3916
141.985	3984
144.538	3956
147.09	3914
149.641	3986
152.191	3924
154.741	3970
157.289	3998
159.837	3998
162.385	3988
164.93	4022
167.476	4100
170.019	3970
172.562	4056
175.105	4100
177.646	3994
180.188	4118
182.727	4084
185.266	4120
187.804	4130
190.342	4154
192.878	4098
195.413	4196
197.948	4190
200.481	4100
203.014	4318
205.546	4282
208.077	4306
210.608	4216
213.137	4258
215.666	4384
218.194	4422
220.721	4390
223.247	4348
225.772	4522
228.295	4420
230.819	4348
233.342	4430
235.864	4456
238.384	4490
240.904	4456
243.423	4446
245.941	4578
248.46	4566
250.975	4588
253.492	4614
256.006	4654
258.519	4586
261.033	4568
263.545	4546
266.057	4706
268.567	4580
271.076	4602
273.585	4666
276.094	4628
278.601	4656
281.107	4696
283.612	4710
286.116	4756
288.62	4690
291.123	4792
293.625	4784
296.126	4836
298.626	4812
301.126	4838
303.625	4936
306.122	4888
308.62	4942
311.114	4940
313.61	4948
316.105	4946
318.599	5014
321.09	4962
323.583	4890
326.073	5062
328.563	4946
331.053	4960
333.541	5036
336.029	5062
338.515	4994
341.001	5118
343.486	5118
345.97	5150
348.453	5106
350.936	5184
353.418	5204
355.898	5242
358.378	5172
360.858	5254
363.336	5244
365.813	5238
368.29	5310
370.766	5274
373.241	5286
375.715	5252
378.188	5296
380.66	5288
383.132	5270
385.603	5222
388.072	5324
390.541	5312
393.01	5346
395.477	5328
397.943	5374
400.409	5474
402.875	5472
405.338	5420
407.802	5444
410.263	5544
412.725	5578
415.185	5658
417.646	5604
420.104	5682
422.564	5662
425.02	5662
427.477	5742
429.933	5728
432.388	5732
434.841	5826
437.294	5882
439.748	5820
442.199	5830
444.65	5814
447.1	5848
449.549	5920
451.997	5832
454.445	5902
456.891	5980
459.337	5836
461.782	5870
464.227	5868
466.669	5928
469.112	5866
471.554	6018
473.995	5908
476.434	5972
478.874	6090
481.312	6064
483.749	6042
486.186	6108
488.622	6122
491.057	6144
493.491	6132
495.925	6144
498.357	6208
500.789	6240
503.221	6288
505.65	6314
508.079	6318
510.509	6380
512.936	6220
515.363	6218
517.789	6288
520.214	6394
522.638	6322
525.062	6432
527.485	6280
529.907	6380
532.328	6338
534.748	6396
537.168	6464
539.587	6410
542.005	6352
544.423	6454
546.838	6498
549.254	6394
551.669	6448
554.082	6490
556.496	6504
558.909	6612
561.319	6560
563.731	6664
566.14	6568
568.549	6618
570.957	6580
573.364	6730
575.771	6800
578.177	6782
580.581	6764
582.987	6752
585.39	6786
587.792	6886
590.193	6904
592.594	6988
594.996	6908
597.395	7014
599.793	7140
602.191	7154
604.588	7104
606.984	7064
609.378	7260
611.773	7172
614.167	7166
616.56	7262
618.953	7308
621.343	7392
623.734	7414
626.124	7424
628.512	7434
630.901	7482
633.289	7484
635.675	7540
638.061	7662
640.446	7606
642.831	7764
645.213	7728
647.595	7722
649.978	7790
652.359	7940
654.738	7814
657.117	7922
659.497	8006
661.875	8002
664.252	7944
666.628	7992
669.003	8098
671.378	8154
673.751	8044
676.124	8138
678.497	8122
680.868	8296
683.239	8238
685.609	8228
687.977	8334
690.346	8400
692.714	8412
695.081	8378
697.446	8292
699.812	8586
702.175	8508
704.539	8564
706.901	8604
709.264	8688
711.625	8696
713.986	8728
716.345	8724
718.705	8834
721.062	8824
723.419	8958
725.775	8952
728.132	8976
730.487	8934
732.841	9130
735.194	9254
737.546	9196
739.898	9166
742.249	9294
744.599	9228
746.949	9384
749.298	9436
751.646	9494
753.993	9594
756.34	9666
758.684	9542
761.029	9668
763.374	9552
765.716	9628
768.059	9788
770.401	9840
772.741	9728
775.082	9824
777.421	10030
779.76	10062
782.097	10056
784.434	10020
786.771	10112
789.106	10326
791.44	10234
793.775	10360
796.108	10324
798.44	10348
800.771	10456
803.102	10524
805.432	10464
807.761	10598
810.09	10806
812.417	10776
814.744	10940
817.071	10902
819.396	11024
821.721	11102
824.045	11168
826.367	11150
828.69	11354
831.012	11498
833.332	11408
835.653	11546
837.972	11488
840.29	11844
842.609	11630
844.925	11728
847.242	11722
849.557	11910
851.871	12056
854.186	12204
856.498	12082
858.81	12262
861.122	12306
863.434	12372
865.744	12430
868.053	12604
870.361	12612
872.669	12498
874.976	12850
877.282	12772
879.588	12830
881.893	12922
884.197	12878
886.5	13064
888.802	13060
891.104	13126
893.405	13140
895.706	13240
898.004	13186
900.303	13192
902.6	13346
904.898	13238
907.194	13540
909.49	13344
911.785	13658
914.08	13740
916.372	13686
918.666	13754
920.957	13912
923.248	13874
925.538	13900
927.828	14050
930.118	14258
932.406	14192
934.693	14368
936.979	14458
939.265	14494
941.55	14552
943.835	14588
946.118	14702
948.401	14900
950.682	14830
952.964	14980
955.245	15230
957.525	15230
959.803	15272
962.082	15348
964.36	15500
966.636	15558
968.913	15572
971.188	15637
973.463	15746
975.736	15864
978.009	15934
980.282	15980
982.554	15912
984.824	15996
987.095	16106
989.364	16188
991.633	16276
993.9	16350
996.167	16196
998.434	16368
1000.7	16484
1002.96	16510
1005.23	16486
1007.49	16640
1009.76	16742
1012.02	16750
1014.28	16890
1016.54	17050
1018.8	17112
1021.06	17148
1023.32	17196
1025.57	17324
1027.83	17428
1030.09	17614
1032.34	17428
1034.6	17708
1036.85	17738
1039.1	17806
1041.35	17866
1043.61	17834
1045.86	18056
1048.11	18082
1050.36	18178
1052.61	18234
1054.85	18458
1057.1	18256
1059.35	18434
1061.59	18642
1063.84	18690
1066.08	18482
1068.33	18658
1070.57	18530
1072.81	18874
1075.05	18870
1077.29	18832
1079.53	18954
1081.77	18884
1084.01	18988
1086.25	18986
1088.48	19032
1090.72	18976
1092.96	18916
1095.19	18902
1097.43	19008
1099.66	18872
1101.89	18956
1104.12	18980
1106.35	18936
1108.59	19004
1110.81	19070
1113.04	18984
1115.27	19058
1117.5	19104
1119.73	19064
1121.95	19144
1124.18	19308
1126.4	19148
1128.63	19230
1130.85	19254
1133.07	19100
1135.29	19280
1137.51	19572
1139.73	19288
1141.95	19380
1144.17	19304
1146.39	19420
1148.61	19466
1150.82	19484
1153.04	19558
1155.26	19442
1157.47	19470
1159.68	19512
1161.9	19656
1164.11	19592
1166.32	19400
1168.53	19606
1170.74	19452
1172.95	19342
1175.16	19452
1177.37	19420
1179.58	19598
1181.78	19320
1183.99	19294
1186.19	19090
1188.4	19104
1190.6	19060
1192.8	19114
1195.01	19040
1197.21	18899.8
1199.41	18898.8
1201.61	18722.6
1203.81	18871.5
1206.01	18579
1208.2	18563
1210.4	18517.5
1212.6	18376.8
1214.8	18421.9
1216.99	18436.5
1219.18	18280
1221.38	18158.4
1223.57	18204.2
1225.76	18100.2
1227.96	18140.7
1230.15	18096
1232.34	17962
1234.53	17904.5
1236.71	17749.9
1238.9	17928.6
1241.09	17753.7
1243.28	17741.9
1245.46	17604.1
1247.65	17630.2
1249.83	17594
1252.02	17586.1
1254.2	17405.5
1256.38	17390.9
1258.56	17396
1260.74	17249.9
1262.92	17298
1265.1	17143.6
1267.28	17174.6
1269.46	17145.6
1271.64	17004.3
1273.82	17004.9
1275.99	16978.7
1278.17	16980
1280.34	16787.5
1282.52	16826.3
1284.69	16753.3
1286.86	16745.7
1289.03	16606.3
1291.21	16550.3
1293.38	16529.5
1295.55	16371.6
1297.71	16380.4
1299.88	16381.1
1302.05	16256.1
1304.22	16138.5
1306.38	16211.3
1308.43	15964
1310.61	15944
1312.78	16012
1314.96	15814
1317.13	15690
1319.3	15816
1321.48	15536
1323.65	15410
1325.82	15310
1327.99	15432
1330.16	15100
1332.33	15176
1334.5	15126
1336.66	14914
1338.83	14944
1341	14870
1343.16	14628
1345.33	14720
1347.49	14482
1349.65	14446
1351.82	14440
1353.98	14482
1356.14	14318
1358.3	14250
1360.46	14106
1362.62	14026
1364.78	13956
1366.94	14034
1369.09	13842
1371.25	13802
1373.41	13792
1375.56	13712
1377.72	13826
1379.87	13730
1382.02	13410
1384.17	13502
1386.33	13580
1388.48	13432
1390.63	13184
1392.78	13290
1394.93	13164
1397.07	13288
1399.22	13132
1401.37	13060
1403.52	13004
1405.66	13038
1407.81	13040
1409.95	12776
1412.09	12848
1414.24	12722
1416.38	12808
1418.52	12526
1420.66	12632
1422.8	12506
1424.94	12598
1427.08	12368
1429.22	12458
1431.35	12244
1433.49	12384
1435.63	12284
1437.76	12222
1439.9	12230
1442.03	12236
1444.17	12202
1446.3	12064
1448.43	11892
1450.56	12022
1452.69	12000
1454.82	12036
1456.95	12034
1459.08	12008
1461.21	11882
1463.34	11766
1465.46	11694
1467.59	11694
1469.71	11716
1471.84	11808
1473.96	11696
1476.08	11648
1478.21	11572
1480.33	11528
1482.45	11458
1484.57	11478
1486.69	11438
1488.81	11498
1490.93	11498
1493.05	11470
1495.16	11308
1497.28	11198
1499.4	11182
1501.51	11166
1503.63	11194
1505.74	11228
1507.85	11146
1509.97	11072
1512.08	11064
1514.19	11060
1516.3	10916
1518.41	10938
1520.52	10932
1522.63	10958
1524.73	10906
1526.84	10762
1528.95	10770
1531.06	10666
1533.16	10678
1535.26	10678
1537.37	10690
1539.47	10608
1541.57	10586
1543.68	10470
1545.78	10584
1547.88	10452
1549.98	10546
1552.08	10360
1554.18	10366
1556.27	10368
1558.37	10318
1560.47	10336
1562.56	10210
1564.66	10354
1566.75	10110
1568.85	10334
1570.94	10056
1573.03	10164
1575.13	10210
1577.22	10144
1579.31	10056
1581.4	10094
1583.49	10170
1585.58	10048
1587.66	9988
1589.75	10046
1591.84	10018
1593.93	9980
1596.01	9896
1598.1	10022
1600.18	10052
1602.26	10000
1604.35	10078
1606.43	9824
1608.51	10000
1610.59	9984
1612.67	9838
1614.75	9796
1616.83	9804
1618.91	9722
1620.99	9716
1623.06	9790
1625.14	9784
1627.21	9790
1629.29	9788
1631.36	9800
1633.44	9768
1635.51	9760
1637.58	9738
1639.66	9708
1641.73	9760
1643.8	9586
1645.87	9538
1647.94	9690
1650	9526
1652.07	9458
1654.14	9512
1656.21	9570
1658.27	9536
1660.34	9376
1662.4	9368
1664.47	9296
1666.53	9516
1668.59	9272
1670.66	9342
1672.72	9286
1674.78	9266
1676.84	9210
1678.9	9300
1680.96	9264
1683.01	9234
1685.07	9052
1687.13	9130
1689.19	9112
1691.24	9060
1693.3	9146
1695.35	9040
1697.4	8986
1699.46	9096
1701.51	8964
1703.56	8978
1705.61	9064
1707.66	9044
1709.71	9054
1711.76	8924
1713.81	8832
1715.86	8770
1717.91	8890
1719.95	8778
1722	8878
1724.04	8802
1726.09	8770
1728.13	8744
1730.18	8794
1732.22	8686
1734.26	8580
1736.3	8696
1738.34	8690
1740.38	8726
1742.42	8692
1744.46	8604
1746.5	8700
1748.54	8590
1750.58	8556
1752.61	8666
1754.65	8670
1756.68	8604
1758.72	8484
1760.75	8558
1762.79	8626
1764.82	8490
1766.85	8502
1768.88	8646
1770.91	8472
1772.94	8548
1774.97	8528
1777	8392
1779.03	8508
1781.06	8532
1783.09	8518
1785.11	8414
1787.14	8532
1789.16	8436
1791.19	8464
1793.21	8384
1795.23	8410
1797.26	8384
1799.28	8364
1801.3	8444
1803.32	8374
1805.34	8372
1807.36	8522
1809.38	8278
1811.4	8338
1813.42	8266
1815.43	8272
1817.45	8276
1819.47	8224
1821.48	8298
1823.49	8230
1825.51	8130
1827.52	8196
1829.54	8160
1831.55	8142
1833.56	8216
1835.57	8204
1837.58	8070
1839.59	8084
1841.6	8062
1843.61	8000
1845.61	7954
1847.62	7944
1849.63	8000
1851.63	7996
1853.64	8044
1855.64	7910
1857.65	7934
1859.65	7944
1861.65	7988
1863.65	7872
1865.66	7940
1867.66	7914
1869.66	7856
1871.66	7888
1873.66	7836
1875.65	7750
1877.65	7822
1879.65	7844
1881.65	7802
1883.64	7774
1885.64	7800
1887.63	7776
1889.63	7740
1891.62	7758
1893.61	7786
1895.6	7776
1897.6	7684
1899.59	7726
1901.58	7894
1903.57	7796
1905.56	7782
1907.54	7804
1909.53	7720
1911.52	7652
1913.51	7614
1915.49	7686
1917.48	7716
1919.46	7658
1921.45	7730
1923.43	7774
1925.41	7604
1927.4	7652
1929.38	7722
1931.36	7642
1933.34	7684
1935.32	7580
1937.3	7610
1939.28	7514
1941.26	7584
1943.23	7570
1945.21	7612
1947.19	7642
1949.16	7516
1951.14	7546
1953.11	7362
1955.09	7468
1957.06	7546
1959.03	7558
1961	7414
1962.98	7434
1964.95	7360
1966.92	7434
1968.89	7410
1970.85	7452
1972.82	7386
1974.79	7402
1976.76	7420
1978.73	7366
1980.69	7324
1982.66	7314
1984.62	7346
1986.59	7410
1988.55	8184
1990.51	7376
1992.47	7430
1994.44	7394
1996.4	7240
1998.36	7310
2000.32	7250
2002.28	7206
2004.24	7262
2006.19	7228
2008.15	7166
2010.11	7280
2012.06	7216
2014.02	7256
2015.98	7212
2017.93	7228
2019.88	7164
2021.84	7264
2023.79	7080
2025.74	7226
2027.69	7090
2029.65	7102
2031.6	7080
2033.55	7160
2035.5	7118
2037.44	7102
2039.39	7090
2041.34	7110
2043.29	7080
2045.23	7130
2047.18	6966
2049.12	7108
2051.07	7066
2053.01	7126
2054.95	7090
2056.9	6980
2058.84	7036
2060.78	7022
2062.72	6940
2064.66	6946
2066.6	7052
2068.54	6936
2070.48	6980
2072.42	6934
2074.35	6878
2076.29	6876
2078.23	6890
2080.16	6874
2082.1	6854
2084.03	6850
2085.96	6792
2087.9	7032
2089.83	6906
2091.76	6806
2093.69	6858
2095.62	6918
2097.55	6724
2099.48	6816
2101.41	6718
2103.34	6870
2105.27	6816
2107.2	6866
2109.12	6832
2111.05	6810
2112.98	6752
2114.9	6674
2116.82	6826
2118.75	6794
2120.67	6702
2122.59	6650
2124.52	6612
2126.44	6688
2128.36	6602
2130.28	6652
2132.2	6666
2134.12	6530
2136.04	6722
2137.95	6636
2139.87	6678
2141.79	6574
2143.7	6572
2145.62	6623.49
2147.53	6618.14
2149.45	6580.63
2151.36	6537.12
2153.28	6559.78
2155.19	6547.12
2157.1	6501.62
2159.01	6427.64
2160.92	6519
2162.83	6511.09
2164.74	6475.41
2166.65	6509.03
2168.56	6365.58
2170.47	6445.09
2172.38	6426.6
2174.28	6335.92
2176.19	6360.37
2178.09	6358.83
2180	6296.08
2181.9	6353.32
2183.81	6374.89
2185.71	6374.02
2187.61	6373.12
2189.52	6361.95
2191.42	6338.25
2193.32	6384.2
2195.22	6281.95
2197.12	6245.09
2199.02	6268.18
2200.92	6290.17
2202.82	6268.5
2204.71	6256.95
2206.61	6244.67
2208.51	6247.49
2210.4	6201.43
2212.3	6252.42
2214.19	6237.95
2216.09	6218.77
2217.98	6259.03
2219.87	6276.83
2221.77	6292.66
2223.66	6282.57
2225.55	6250.22
2227.44	6231.8
2229.33	6278.22
2231.22	6226.75
2233.11	6271.36
2235	6236.05
2236.88	6306.16
2238.77	6287.51
2240.66	6278.4
2242.07	6250
2243.97	6236
2245.87	6274
2247.76	6302
2249.65	6188
2251.55	6216
2253.44	6186
2255.33	6162
2257.22	6264
2259.12	6140
2261.01	6250
2262.9	6150
2264.78	6108
2266.67	6176
2268.56	6260
2270.45	6082
2272.34	6130
2274.22	6176
2276.11	6178
2277.99	6162
2279.88	6128
2281.76	6056
2283.65	6182
2285.53	6140
2287.41	6068
2289.3	6058
2291.18	6044
2293.06	6116
2294.94	6114
2296.82	6028
2298.7	6030
2300.58	5994
2302.46	6018
2304.33	5992
2306.21	6030
2308.09	5978
2309.96	5972
2311.84	5952
2313.71	5888
2315.59	5954
2317.46	6050
2319.33	6044
2321.21	6014
2323.08	5970
2324.95	5970
2326.82	5976
2328.69	5892
2330.56	5904
2332.43	5968
2334.3	5900
2336.17	5802
2338.03	5922
2339.9	5858
2341.77	5922
2343.63	5820
2345.5	5880
2347.36	5910
2349.23	5856
2351.09	5784
2352.95	5798
2354.82	5842
2356.68	5738
2358.54	5854
2360.4	5898
2362.26	5830
2364.12	5796
2365.98	5822
2367.84	5780
2369.7	5908
2371.56	5708
2373.41	5816
2375.27	5768
2377.12	5772
2378.98	5764
2380.84	5712
2382.69	5772
2384.54	5714
2386.4	5674
2388.25	5664
2390.1	5738
2391.95	5714
2393.8	5582
2395.65	5656
2397.5	5604
2399.35	5626
2401.2	5614
2403.05	5594
2404.9	5584
2406.75	5564
2408.59	5514
2410.44	5608
2412.28	5566
2414.13	5620
2415.97	5510
2417.82	5582
2419.66	5634
2421.5	5464
2423.35	5482
2425.19	5450
2427.03	5558
2428.87	5532
2430.71	5406
2432.55	5524
2434.39	5448
2436.23	5474
2438.06	5550
2439.9	5546
2441.74	5360
2443.57	5444
2445.41	5346
2447.24	5416
2449.08	5372
2450.91	5314
2452.75	5396
2454.58	5396
2456.41	5416
2458.24	5346
2460.08	5428
2461.91	5314
2463.74	5394
2465.57	5252
2467.4	5254
2469.22	5268
2471.05	5326
2472.88	5278
2474.71	5290
2476.53	5284
2478.36	5220
2480.19	5220
2482.01	5250
2483.83	5204
2485.66	5260
2487.48	5238
2489.3	5206
2491.13	5200
2492.95	5136
2494.77	5178
2496.59	5154
2498.41	5132
2500.23	5104
2502.05	5158
2503.87	5190
2505.68	5102
2507.5	5142
2509.32	5042
2511.14	4964
2512.95	5104
2514.77	5024
2516.58	5030
2518.39	5030
2520.21	4978
2522.02	4962
2523.83	5016
2525.65	4910
2527.46	4948
2529.27	4984
2531.08	4864
2532.89	4982
2534.7	4922
2536.51	4894
2538.32	4800
2540.12	4886
2541.93	4874
2543.74	4894
2545.54	4864
2547.35	4892
2549.15	4848
2550.96	4848
2552.76	4820
2554.56	4868
2556.37	4828
2558.17	4766
2559.97	4846
2561.77	4806
2563.58	4736
2565.38	4760
2567.18	4748
2568.97	4656
2570.77	4662
2572.57	4702
2574.37	4618
2576.17	4718
2577.96	4652
2579.76	4670
2581.55	4560
2583.35	4566
2585.14	4704
2586.94	4560
2588.73	4560
2590.52	4580
2592.32	4596
2594.11	4630
2595.9	4468
2597.69	4560
2599.48	4464
2601.27	4466
2603.06	4524
2604.85	4572
2606.64	4452
2608.42	4476
2610.21	4444
2612	4564
2613.78	4464
2615.57	4494
2617.36	4504
2619.14	4414
2620.92	4432
2622.71	4368
2624.49	4418
2626.27	4398
2628.05	4364
2629.84	4378
2631.62	4348
2633.4	4338
2635.18	4246
2636.96	4282
2638.74	4306
2640.51	4144
2642.29	4292
2644.07	4202
2645.85	4252
2647.62	4198
2649.4	4192
2651.17	4238
2652.95	4232
2654.72	4180
2656.5	4248
2658.27	4182
2660.04	4256
2661.81	4100
2663.58	4142
2665.35	4130
2667.13	4158
2668.9	4182
2670.66	4108
2672.43	4058
2674.2	4080
2675.97	4110
2677.74	4100
2679.5	4060
2681.27	4090
2683.04	4084
2684.8	4124
2686.57	4042
2688.33	3936
2690.09	4018
2691.86	4030
2693.62	4014
2695.38	3910
2697.15	4036
2698.91	4076
2700.67	3972
2702.43	3982
2704.19	3934
2705.95	3930
2707.7	3948
2709.46	3952
2711.22	3918
2712.98	3904
2714.73	3794
2716.49	3830
2718.25	3892
2720	3830
2721.76	3798
2723.51	3792
2725.26	3848
2727.02	3784
2728.77	3754
2730.52	3800
2732.27	3718
2734.02	3754
2735.77	3736
2737.52	3740
2739.27	3734
2741.02	3658
2742.77	3694
2744.52	3698
2746.27	3752
2748.01	3596
2749.76	3622
2751.51	3622
2753.25	3686
2755	3620
2756.74	3576
2758.48	3620
2760.23	3574
2761.97	3554
2763.71	3630
2765.45	3494
2767.19	3516
2768.94	3550
2770.68	3482
2772.42	3578
2774.16	3538
2775.89	3554
2777.63	3472
2779.37	3462
2781.11	3492
2782.84	3448
2784.58	3494
2786.32	3492
2788.05	3468
2789.79	3428
2791.52	3498
2793.25	3444
2794.99	3458
2796.72	3420
2798.45	3468
2800.18	3326
2801.92	3386
2803.65	3334
2805.38	3386
2807.11	3364
2808.84	3342
2810.57	3432
2812.29	3308
2814.02	3290
2815.75	3364
2817.47	3304
2819.2	3284
2820.93	3370
2822.65	3244
2824.38	3260
2826.1	3280
2827.82	3296
2829.55	3286
2831.27	3250
2832.99	3198
2834.71	3242
2836.44	3148
2838.16	3214
2839.88	3156
2841.6	3120
2843.32	3170
2845.03	3168
2846.75	3078
2848.47	3156
2850.19	3138
2851.9	3116
2853.62	3080
2855.34	3028
2857.05	3026
2858.77	3090
2860.48	3038
2862.19	3116
2863.91	3028
2865.62	3004
2867.33	3028
2869.04	3108
2870.76	2998
2872.47	2980
2874.18	2950
2875.89	2984
2877.6	2966
2879.31	2970
2881.01	3018
2882.72	2934
2884.43	2972
2886.14	2886
2887.84	2944
2889.55	2920
2891.25	2932
2892.96	2812
2894.66	2828
2896.37	2922
2898.07	2906
2899.77	2870
2901.48	2828
2903.18	2926
2904.88	2890
2906.58	2832
2908.28	2874
2909.98	2894
2911.68	2816
2913.38	2864
2915.08	2776
2916.78	2780
2918.47	2782
2920.17	2770
2921.87	2806
2923.56	2792
2925.26	2836
2926.95	2686
2928.65	2704
2930.34	2718
2932.04	2764
2933.73	2754
2935.42	2726
2937.11	2736
2938.81	2754
2940.5	2674
2942.19	2674
2943.88	2714
2945.57	2718
2947.26	2664
2948.95	2656
2950.64	2698
2952.32	2592
2954.01	2632
2955.7	2694
2957.38	2610
2959.07	2662
2960.75	2660
2962.44	2686
2964.12	2616
2965.81	2594
2967.49	2592
2969.17	2630
2970.86	2628
2972.54	2554
2974.22	2568
2975.9	2526
2977.58	2620
2979.26	2558
2980.94	2566
2982.62	2592
2984.3	2500
2985.98	2536
2987.66	2540
2989.33	2484
2991.01	2490
2992.69	2454
2994.36	2480
2996.04	2480
2997.71	2470
2999.39	2430