File: muestras/tallo/2/Organic_12.txt
#Acq. time (s)=	10
#Accumulations=	1
#Range (cm-¹)=	100...3000
#Windows=	3
#Autofocus=	Off
#AutoExposure=	Off
#Spike filter=	Off
#Delay time (s)=	0
#Binning=	1
#Readout mode=	Signal
#DeNoise=	Off
#ICS correction=	Off
#Dark correction=	Off
#Inst. Process=	Off
#Instrument=	LabRAM HR Evol
#Detector=	Syncerity OE
#Objective=	x100_VIS
#Grating=	600 (500nm)
#ND Filter=	3.2%
#Laser=	633nm_Edge
#Hole=	100.021
#Range=	Visible
#Project=	Omar
#Sample=	26-06-23
#Site=	2
#Title=	Organic
#Remark=
#Date=	26.06.2023 16:26
#Acquired=	26.06.2023 16:26:54
101.018	3746
103.586	3768
106.152	3806
108.717	3826
111.281	3818
113.845	3746
116.407	3832
118.969	3846
121.53	3844
124.09	3904
126.649	3882
129.207	3926
131.765	3928
134.321	3934
136.877	3914
139.432	3996
141.985	3906
144.538	3972
147.09	3994
149.641	4008
152.191	4048
154.741	4028
157.289	4094
159.837	4012
162.385	4032
164.93	4060
167.476	4050
170.019	4054
172.562	4140
175.105	4056
177.646	4138
180.188	4068
182.727	4126
185.266	4162
187.804	4050
190.342	4106
192.878	4184
195.413	4222
197.948	4372
200.481	4288
203.014	4282
205.546	4366
208.077	4356
210.608	4348
213.137	4384
215.666	4428
218.194	4438
220.721	4370
223.247	4394
225.772	4484
228.295	4530
230.819	4562
233.342	4622
235.864	4468
238.384	4518
240.904	4624
243.423	4620
245.941	4508
248.46	4594
250.975	4638
253.492	4644
256.006	4648
258.519	4724
261.033	4654
263.545	4684
266.057	4602
268.567	4688
271.076	4632
273.585	4650
276.094	4750
278.601	4632
281.107	4788
283.612	4732
286.116	4706
288.62	4858
291.123	4810
293.625	4872
296.126	4912
298.626	4890
301.126	4946
303.625	4952
306.122	4988
308.62	5014
311.114	5006
313.61	5068
316.105	4986
318.599	5116
321.09	4982
323.583	5120
326.073	5022
328.563	5020
331.053	5106
333.541	5050
336.029	5074
338.515	5128
341.001	5114
343.486	5152
345.97	5130
348.453	5212
350.936	5206
353.418	5244
355.898	5232
358.378	5254
360.858	5350
363.336	5320
365.813	5288
368.29	5258
370.766	5352
373.241	5462
375.715	5222
378.188	5268
380.66	5396
383.132	5394
385.603	5262
388.072	5398
390.541	5428
393.01	5344
395.477	5404
397.943	5418
400.409	5362
402.875	5486
405.338	5472
407.802	5546
410.263	5544
412.725	5614
415.185	5716
417.646	5762
420.104	5754
422.564	5806
425.02	5754
427.477	5746
429.933	5860
432.388	5884
434.841	5906
437.294	5846
439.748	5920
442.199	5964
444.65	5984
447.1	5956
449.549	5974
451.997	5964
454.445	6020
456.891	5998
459.337	5994
461.782	6012
464.227	6008
466.669	6012
469.112	6156
471.554	6034
473.995	6072
476.434	6120
478.874	6152
481.312	6094
483.749	6162
486.186	6158
488.622	6142
491.057	6324
493.491	6248
495.925	6370
498.357	6366
500.789	6402
503.221	6280
505.65	6376
508.079	6364
510.509	6372
512.936	6440
515.363	6418
517.789	6386
520.214	6530
522.638	6482
525.062	6446
527.485	6476
529.907	6540
532.328	6364
534.748	6516
537.168	6456
539.587	6540
542.005	6476
544.423	6426
546.838	6606
549.254	6532
551.669	6644
554.082	6710
556.496	6706
558.909	6588
561.319	6730
563.731	6748
566.14	6760
568.549	6842
570.957	6768
573.364	6884
575.771	6848
578.177	6908
580.581	6870
582.987	6984
585.39	6996
587.792	7048
590.193	6986
592.594	7106
594.996	7064
597.395	7068
599.793	7116
602.191	7054
604.588	7220
606.984	7222
609.378	7306
611.773	7382
614.167	7330
616.56	7422
618.953	7402
621.343	7400
623.734	7432
626.124	7538
628.512	7584
630.901	7620
633.289	7732
635.675	7610
638.061	7822
640.446	7682
642.831	7832
645.213	7926
647.595	7858
649.978	8016
652.359	7966
654.738	8002
657.117	8056
659.497	8176
661.875	8112
664.252	8190
666.628	8292
669.003	8174
671.378	8244
673.751	8322
676.124	8246
678.497	8280
680.868	8352
683.239	8250
685.609	8414
687.977	8400
690.346	8496
692.714	8488
695.081	8566
697.446	8580
699.812	8598
702.175	8680
704.539	8776
706.901	8676
709.264	8860
711.625	8836
713.986	8858
716.345	8934
718.705	9106
721.062	9108
723.419	9158
725.775	9160
728.132	9112
730.487	9242
732.841	9286
735.194	9336
737.546	9382
739.898	9460
742.249	9450
744.599	9494
746.949	9484
749.298	9668
751.646	9560
753.993	9742
756.34	9664
758.684	9816
761.029	9890
763.374	9856
765.716	9948
768.059	9940
770.401	10072
772.741	10046
775.082	10050
777.421	10180
779.76	10318
782.097	10276
784.434	10184
786.771	10314
789.106	10450
791.44	10434
793.775	10534
796.108	10640
798.44	10732
800.771	10600
803.102	10664
805.432	10776
807.761	10960
810.09	10982
812.417	11088
814.744	11194
817.071	11028
819.396	11228
821.721	11270
824.045	11428
826.367	11498
828.69	11580
831.012	11676
833.332	11720
835.653	11668
837.972	11860
840.29	12016
842.609	12086
844.925	12118
847.242	12098
849.557	12194
851.871	12424
854.186	12380
856.498	12426
858.81	12590
861.122	12616
863.434	12530
865.744	12714
868.053	12804
870.361	12828
872.669	12974
874.976	13012
877.282	13186
879.588	13038
881.893	13074
884.197	13128
886.5	13256
888.802	13208
891.104	13352
893.405	13486
895.706	13490
898.004	13582
900.303	13524
902.6	13510
904.898	13744
907.194	13852
909.49	13788
911.785	13858
914.08	13730
916.372	14228
918.666	14082
920.957	14212
923.248	14348
925.538	14244
927.828	14498
930.118	14486
932.406	14640
934.693	14762
936.979	14780
939.265	14902
941.55	14910
943.835	15032
946.118	15154
948.401	15156
950.682	15420
952.964	15352
955.245	15466
957.525	15626
959.803	15450
962.082	15810
964.36	15742
966.636	15820
968.913	16104
971.188	16006
973.463	16098
975.736	16174
978.009	16282
980.282	16214
982.554	16368
984.824	16510
987.095	16474
989.364	16496
991.633	16696
993.9	16852
996.167	16744
998.434	16856
1000.7	16908
1002.96	17040
1005.23	17018
1007.49	17138
1009.76	17272
1012.02	17184
1014.28	17378
1016.54	17434
1018.8	17576
1021.06	17388
1023.32	17648
1025.57	17674
1027.83	17660
1030.09	17922
1032.34	18026
1034.6	18000
1036.85	18382
1039.1	18378
1041.35	18328
1043.61	18586
1045.86	18458
1048.11	18680
1050.36	18534
1052.61	18730
1054.85	18840
1057.1	18958
1059.35	18816
1061.59	19044
1063.84	18992
1066.08	19046
1068.33	19240
1070.57	19114
1072.81	19332
1075.05	19440
1077.29	19288
1079.53	19166
1081.77	19610
1084.01	19420
1086.25	19070
1088.48	19394
1090.72	19418
1092.96	19400
1095.19	19384
1097.43	19424
1099.66	19400
1101.89	19486
1104.12	19464
1106.35	19492
1108.59	19522
1110.81	19600
1113.04	19440
1115.27	19468
1117.5	19594
1119.73	19304
1121.95	19720
1124.18	19788
1126.4	19874
1128.63	19812
1130.85	19840
1133.07	19654
1135.29	19610
1137.51	19844
1139.73	19726
1141.95	19878
1144.17	19778
1146.39	19868
1148.61	20074
1150.82	20168
1153.04	20190
1155.26	20056
1157.47	19890
1159.68	19944
1161.9	19916
1164.11	19874
1166.32	19978
1168.53	19848
1170.74	19902
1172.95	19844
1175.16	20038
1177.37	19988
1179.58	19764
1181.78	19764
1183.99	19896
1186.19	19620
1188.4	19674
1190.6	19480
1192.8	19484
1195.01	19260
1197.21	19511.3
1199.41	19329.4
1201.61	19252.7
1203.81	19212.1
1206.01	19161.8
1208.2	19093.4
1210.4	18979.8
1212.6	18926.2
1214.8	18844.9
1216.99	18709.1
1219.18	18646.3
1221.38	18821.1
1223.57	18563.5
1225.76	18570.6
1227.96	18517.4
1230.15	18375.6
1232.34	18302.1
1234.53	18378.6
1236.71	18300.9
1238.9	18271.5
1241.09	18216.1
1243.28	18128.9
1245.46	18080.1
1247.65	18149.3
1249.83	17952.4
1252.02	17962.6
1254.2	17928.3
1256.38	17883.2
1258.56	17705.7
1260.74	17660.5
1262.92	17654
1265.1	17561.6
1267.28	17520
1269.46	17540.2
1271.64	17603.5
1273.82	17383.8
1275.99	17321.2
1278.17	17331.8
1280.34	17164
1282.52	17255.5
1284.69	17114.1
1286.86	17110.2
1289.03	17033.6
1291.21	17017.5
1293.38	16921.2
1295.55	16847.2
1297.71	16794.4
1299.88	16713.5
1302.05	16717.9
1304.22	16550.5
1306.38	16350.4
1308.43	16460
1310.61	16342
1312.78	16412
1314.96	16108
1317.13	16056
1319.3	15884
1321.48	15890
1323.65	15694
1325.82	15716
1327.99	15646
1330.16	15644
1332.33	15530
1334.5	15472
1336.66	15228
1338.83	15324
1341	15174
1343.16	15194
1345.33	14932
1347.49	14972
1349.65	14936
1351.82	14858
1353.98	14706
1356.14	14696
1358.3	14568
1360.46	14470
1362.62	14364
1364.78	14276
1366.94	14386
1369.09	14218
1371.25	13932
1373.41	14076
1375.56	14024
1377.72	14048
1379.87	13988
1382.02	13714
1384.17	13820
1386.33	13786
1388.48	13716
1390.63	13624
1392.78	13496
1394.93	13520
1397.07	13584
1399.22	13416
1401.37	13340
1403.52	13336
1405.66	13232
1407.81	13268
1409.95	13162
1412.09	13088
1414.24	12910
1416.38	12986
1418.52	12894
1420.66	12874
1422.8	12930
1424.94	12850
1427.08	12670
1429.22	12632
1431.35	12654
1433.49	12462
1435.63	12538
1437.76	12562
1439.9	12500
1442.03	12402
1444.17	12394
1446.3	12374
1448.43	12290
1450.56	12416
1452.69	12240
1454.82	12166
1456.95	12100
1459.08	12208
1461.21	12106
1463.34	12062
1465.46	11992
1467.59	12078
1469.71	11974
1471.84	11908
1473.96	11976
1476.08	11830
1478.21	11890
1480.33	11846
1482.45	11794
1484.57	11648
1486.69	11628
1488.81	11638
1490.93	11742
1493.05	11680
1495.16	11496
1497.28	11518
1499.4	11644
1501.51	11304
1503.63	11402
1505.74	11400
1507.85	11454
1509.97	11214
1512.08	11224
1514.19	11166
1516.3	11162
1518.41	11174
1520.52	11114
1522.63	11118
1524.73	11020
1526.84	10910
1528.95	10852
1531.06	10928
1533.16	10954
1535.26	10872
1537.37	10962
1539.47	10742
1541.57	10720
1543.68	10714
1545.78	10650
1547.88	10650
1549.98	10600
1552.08	10534
1554.18	10600
1556.27	10628
1558.37	10508
1560.47	10452
1562.56	10410
1564.66	10552
1566.75	10428
1568.85	10316
1570.94	10404
1573.03	10360
1575.13	10216
1577.22	10256
1579.31	10280
1581.4	10264
1583.49	10226
1585.58	10286
1587.66	10222
1589.75	10326
1591.84	10264
1593.93	10148
1596.01	10174
1598.1	10068
1600.18	10086
1602.26	10014
1604.35	10084
1606.43	10098
1608.51	10050
1610.59	9998
1612.67	10068
1614.75	10162
1616.83	10076
1618.91	10052
1620.99	9938
1623.06	10046
1625.14	9966
1627.21	9900
1629.29	9904
1631.36	9908
1633.44	9856
1635.51	9968
1637.58	9860
1639.66	9908
1641.73	9786
1643.8	9858
1645.87	9812
1647.94	9630
1650	9764
1652.07	9774
1654.14	9660
1656.21	9638
1658.27	9692
1660.34	9576
1662.4	9596
1664.47	9586
1666.53	9564
1668.59	9580
1670.66	9464
1672.72	9510
1674.78	9486
1676.84	9440
1678.9	9404
1680.96	9322
1683.01	9368
1685.07	9240
1687.13	9212
1689.19	9272
1691.24	9322
1693.3	9310
1695.35	9164
1697.4	9198
1699.46	9170
1701.51	9152
1703.56	9090
1705.61	9124
1707.66	9026
1709.71	9106
1711.76	8844
1713.81	9048
1715.86	9002
1717.91	8992
1719.95	8928
1722	8940
1724.04	9046
1726.09	8964
1728.13	9034
1730.18	8938
1732.22	8808
1734.26	8902
1736.3	8864
1738.34	8862
1740.38	8876
1742.42	8696
1744.46	8828
1746.5	8836
1748.54	8740
1750.58	8714
1752.61	8850
1754.65	8822
1756.68	8760
1758.72	8798
1760.75	8702
1762.79	8636
1764.82	8728
1766.85	8656
1768.88	8768
1770.91	8650
1772.94	8776
1774.97	8658
1777	8664
1779.03	8648
1781.06	8650
1783.09	8690
1785.11	8596
1787.14	8694
1789.16	8728
1791.19	8716
1793.21	8650
1795.23	8660
1797.26	8532
1799.28	8500
1801.3	8486
1803.32	8564
1805.34	8518
1807.36	8460
1809.38	8432
1811.4	8402
1813.42	8410
1815.43	8518
1817.45	8426
1819.47	8398
1821.48	8364
1823.49	8322
1825.51	8416
1827.52	8270
1829.54	8266
1831.55	8238
1833.56	8304
1835.57	8248
1837.58	8256
1839.59	8222
1841.6	8164
1843.61	8216
1845.61	8176
1847.62	8174
1849.63	8152
1851.63	8098
1853.64	8068
1855.64	8128
1857.65	7974
1859.65	8126
1861.65	8038
1863.65	8058
1865.66	8126
1867.66	7994
1869.66	8038
1871.66	8016
1873.66	7986
1875.65	7996
1877.65	8020
1879.65	7980
1881.65	7902
1883.64	7936
1885.64	7908
1887.63	7880
1889.63	7838
1891.62	7826
1893.61	7888
1895.6	7952
1897.6	7932
1899.59	7840
1901.58	7790
1903.57	7892
1905.56	7820
1907.54	7788
1909.53	7698
1911.52	7910
1913.51	7922
1915.49	7864
1917.48	7756
1919.46	7756
1921.45	7796
1923.43	7772
1925.41	7792
1927.4	7888
1929.38	7724
1931.36	7782
1933.34	7912
1935.32	7802
1937.3	7826
1939.28	7666
1941.26	7726
1943.23	7684
1945.21	7704
1947.19	7718
1949.16	7684
1951.14	7580
1953.11	7616
1955.09	7644
1957.06	7600
1959.03	7576
1961	7660
1962.98	7696
1964.95	7498
1966.92	7670
1968.89	7574
1970.85	7474
1972.82	7526
1974.79	7494
1976.76	7466
1978.73	7426
1980.69	7514
1982.66	7500
1984.62	7476
1986.59	7402
1988.55	7428
1990.51	7482
1992.47	7386
1994.44	7420
1996.4	7450
1998.36	7382
2000.32	7270
2002.28	7392
2004.24	7424
2006.19	7370
2008.15	7326
2010.11	7458
2012.06	7306
2014.02	7408
2015.98	7366
2017.93	7348
2019.88	7266
2021.84	7262
2023.79	7366
2025.74	7306
2027.69	7298
2029.65	7272
2031.6	7222
2033.55	7220
2035.5	7274
2037.44	7324
2039.39	7256
2041.34	7168
2043.29	7206
2045.23	7202
2047.18	7096
2049.12	7162
2051.07	7210
2053.01	7210
2054.95	7148
2056.9	7232
2058.84	7082
2060.78	7084
2062.72	7124
2064.66	7202
2066.6	7104
2068.54	7106
2070.48	7030
2072.42	7156
2074.35	7056
2076.29	6960
2078.23	7006
2080.16	6984
2082.1	7084
2084.03	7070
2085.96	7070
2087.9	7018
2089.83	6950
2091.76	7050
2093.69	6922
2095.62	6948
2097.55	7020
2099.48	7048
2101.41	6950
2103.34	6958
2105.27	6848
2107.2	6986
2109.12	6892
2111.05	6888
2112.98	6944
2114.9	6922
2116.82	6894
2118.75	6872
2120.67	6738
2122.59	6884
2124.52	6804
2126.44	6836
2128.36	6792
2130.28	6794
2132.2	6728
2134.12	6778
2136.04	6732
2137.95	6810
2139.87	6558
2141.79	6768
2143.7	6786
2145.62	6712.23
2147.53	6792.48
2149.45	6631.17
2151.36	6711.92
2153.28	6707.72
2155.19	6726.35
2157.1	6615.46
2159.01	6637.09
2160.92	6590.8
2162.83	6593.5
2164.74	6657.9
2166.65	6626.62
2168.56	6589.41
2170.47	6468.33
2172.38	6549.76
2174.28	6551.03
2176.19	6517.2
2178.09	6502.85
2180	6428.72
2181.9	6425.78
2183.81	6468.43
2185.71	6422.89
2187.61	6400.32
2189.52	6510.68
2191.42	6392.46
2193.32	6408.47
2195.22	6416.33
2197.12	6447.25
2199.02	6445.91
2200.92	6338.59
2202.82	6399.56
2204.71	6436.24
2206.61	6397.84
2208.51	6297.27
2210.4	6374.49
2212.3	6340.2
2214.19	6398.75
2216.09	6336.37
2217.98	6313.24
2219.87	6324.74
2221.77	6397.72
2223.66	6344.35
2225.55	6363.15
2227.44	6344.37
2229.33	6373.01
2231.22	6316.85
2233.11	6308.56
2235	6394.56
2236.88	6374.91
2238.77	6303.16
2240.66	6336.85
2242.07	6358
2243.97	6364
2245.87	6236
2247.76	6360
2249.65	6356
2251.55	6304
2253.44	6354
2255.33	6326
2257.22	6392
2259.12	6310
2261.01	6298
2262.9	6392
2264.78	6254
2266.67	6326
2268.56	6334
2270.45	6326
2272.34	6230
2274.22	6292
2276.11	6198
2277.99	6286
2279.88	6292
2281.76	6204
2283.65	6258
2285.53	6280
2287.41	6190
2289.3	6162
2291.18	6212
2293.06	6128
2294.94	6088
2296.82	6126
2298.7	6190
2300.58	6226
2302.46	6158
2304.33	6224
2306.21	6180
2308.09	6174
2309.96	6088
2311.84	5986
2313.71	6154
2315.59	5962
2317.46	6132
2319.33	6082
2321.21	6112
2323.08	6052
2324.95	6048
2326.82	5922
2328.69	6000
2330.56	6094
2332.43	6054
2334.3	6050
2336.17	5970
2338.03	5982
2339.9	5976
2341.77	5974
2343.63	5974
2345.5	5908
2347.36	5986
2349.23	6004
2351.09	5920
2352.95	5844
2354.82	5952
2356.68	6020
2358.54	5916
2360.4	5866
2362.26	6032
2364.12	5872
2365.98	5900
2367.84	5920
2369.7	5932
2371.56	5856
2373.41	5868
2375.27	5840
2377.12	5846
2378.98	5840
2380.84	5960
2382.69	5850
2384.54	5726
2386.4	5790
2388.25	5866
2390.1	5786
2391.95	5796
2393.8	5744
2395.65	5690
2397.5	5842
2399.35	5664
2401.2	5632
2403.05	5796
2404.9	5688
2406.75	5728
2408.59	5728
2410.44	5698
2412.28	5682
2414.13	5654
2415.97	5688
2417.82	5694
2419.66	5658
2421.5	5686
2423.35	5616
2425.19	5592
2427.03	5664
2428.87	5498
2430.71	5550
2432.55	5660
2434.39	5534
2436.23	5472
2438.06	5562
2439.9	5424
2441.74	5514
2443.57	5426
2445.41	5494
2447.24	5522
2449.08	5438
2450.91	5504
2452.75	5490
2454.58	5442
2456.41	5462
2458.24	5490
2460.08	5340
2461.91	5418
2463.74	5408
2465.57	5434
2467.4	5336
2469.22	5320
2471.05	5456
2472.88	5434
2474.71	5352
2476.53	5446
2478.36	5342
2480.19	5362
2482.01	5376
2483.83	5364
2485.66	5334
2487.48	5280
2489.3	5278
2491.13	5268
2492.95	5248
2494.77	5200
2496.59	5246
2498.41	5088
2500.23	5208
2502.05	5182
2503.87	5176
2505.68	5194
2507.5	5182
2509.32	5194
2511.14	5158
2512.95	5176
2514.77	5182
2516.58	5088
2518.39	5136
2520.21	5078
2522.02	5038
2523.83	5014
2525.65	5088
2527.46	5098
2529.27	4972
2531.08	5072
2532.89	5076
2534.7	5066
2536.51	5034
2538.32	4974
2540.12	4922
2541.93	4948
2543.74	4924
2545.54	4860
2547.35	5002
2549.15	4900
2550.96	4922
2552.76	4796
2554.56	4838
2556.37	4880
2558.17	4912
2559.97	4786
2561.77	4860
2563.58	4822
2565.38	4870
2567.18	4716
2568.97	4796
2570.77	4770
2572.57	4774
2574.37	4788
2576.17	4816
2577.96	4678
2579.76	4790
2581.55	4746
2583.35	4728
2585.14	4774
2586.94	4636
2588.73	4588
2590.52	4730
2592.32	4606
2594.11	4646
2595.9	4630
2597.69	4546
2599.48	4578
2601.27	4646
2603.06	4476
2604.85	4576
2606.64	4572
2608.42	4614
2610.21	4518
2612	4564
2613.78	4530
2615.57	4494
2617.36	4472
2619.14	4562
2620.92	4454
2622.71	4514
2624.49	4410
2626.27	4410
2628.05	4422
2629.84	4414
2631.62	4398
2633.4	4440
2635.18	4400
2636.96	4388
2638.74	4382
2640.51	4268
2642.29	4310
2644.07	4360
2645.85	4324
2647.62	4304
2649.4	4328
2651.17	4238
2652.95	4310
2654.72	4256
2656.5	4280
2658.27	4318
2660.04	4228
2661.81	4208
2663.58	4242
2665.35	4222
2667.13	4280
2668.9	4298
2670.66	4142
2672.43	4224
2674.2	4198
2675.97	4184
2677.74	4082
2679.5	4214
2681.27	4124
2683.04	4122
2684.8	4150
2686.57	4186
2688.33	4068
2690.09	4108
2691.86	4030
2693.62	4012
2695.38	4102
2697.15	3980
2698.91	4022
2700.67	4030
2702.43	4018
2704.19	4014
2705.95	3998
2707.7	3912
2709.46	3938
2711.22	3942
2712.98	3896
2714.73	3944
2716.49	3998
2718.25	3904
2720	3896
2721.76	3858
2723.51	3842
2725.26	3894
2727.02	3920
2728.77	3846
2730.52	3874
2732.27	3900
2734.02	3872
2735.77	3824
2737.52	3752
2739.27	3744
2741.02	3786
2742.77	3736
2744.52	3704
2746.27	3714
2748.01	3678
2749.76	3740
2751.51	3670
2753.25	3732
2755	3648
2756.74	3656
2758.48	3732
2760.23	3648
2761.97	3672
2763.71	3704
2765.45	3586
2767.19	3604
2768.94	3664
2770.68	3638
2772.42	3628
2774.16	3642
2775.89	3528
2777.63	3604
2779.37	3548
2781.11	3592
2782.84	3482
2784.58	3574
2786.32	3532
2788.05	3510
2789.79	3458
2791.52	3542
2793.25	3490
2794.99	3422
2796.72	3464
2798.45	3462
2800.18	3360
2801.92	3474
2803.65	3377
2805.38	3474
2807.11	3386
2808.84	3402
2810.57	3296
2812.29	3426
2814.02	3400
2815.75	3376
2817.47	3346
2819.2	3364
2820.93	3250
2822.65	3262
2824.38	3322
2826.1	3306
2827.82	3328
2829.55	3298
2831.27	3250
2832.99	3220
2834.71	3294
2836.44	3266
2838.16	3276
2839.88	3240
2841.6	3188
2843.32	3286
2845.03	3148
2846.75	3152
2848.47	3126
2850.19	3164
2851.9	3156
2853.62	3128
2855.34	3110
2857.05	3112
2858.77	3060
2860.48	3148
2862.19	3066
2863.91	3110
2865.62	3006
2867.33	3122
2869.04	3022
2870.76	3036
2872.47	3066
2874.18	3048
2875.89	2992
2877.6	3062
2879.31	3036
2881.01	2986
2882.72	2952
2884.43	3004
2886.14	2992
2887.84	2934
2889.55	2920
2891.25	2944
2892.96	2942
2894.66	2962
2896.37	2974
2898.07	2868
2899.77	2940
2901.48	2820
2903.18	2934
2904.88	2864
2906.58	2874
2908.28	2884
2909.98	2858
2911.68	2880
2913.38	2848
2915.08	2854
2916.78	2894
2918.47	2862
2920.17	2822
2921.87	2770
2923.56	2770
2925.26	2846
2926.95	2748
2928.65	2800
2930.34	2872
2932.04	2788
2933.73	2780
2935.42	2746
2937.11	2728
2938.81	2790
2940.5	2812
2942.19	2764
2943.88	2754
2945.57	2694
2947.26	2746
2948.95	2718
2950.64	2722
2952.32	2686
2954.01	2724
2955.7	2736
2957.38	2740
2959.07	2690
2960.75	2648
2962.44	2596
2964.12	2686
2965.81	2624
2967.49	2562
2969.17	2616
2970.86	2662
2972.54	2696
2974.22	2594
2975.9	2592
2977.58	2594
2979.26	2642
2980.94	2610
2982.62	2606
2984.3	2598
2985.98	2570
2987.66	2572
2989.33	2548
2991.01	2576
2992.69	2522
2994.36	2566
2996.04	2550
2997.71	2548
2999.39	2520