File: muestras/tallo/2/Organic_19.txt
#Acq. time (s)=	10
#Accumulations=	1
#Range (cm-¹)=	100...3000
#Windows=	3
#Autofocus=	Off
#AutoExposure=	Off
#Spike filter=	Off
#Delay time (s)=	0
#Binning=	1
#Readout mode=	Signal
#DeNoise=	Off
#ICS correction=	Off
#Dark correction=	Off
#Inst. Process=	Off
#Instrument=	LabRAM HR Evol
#Detector=	Syncerity OE
#Objective=	x100_VIS
#Grating=	600 (500nm)
#ND Filter=	3.2%
#Laser=	633nm_Edge
#Hole=	100.021
#Range=	Visible
#Project=	Omar
#Sample=	26-06-23
#Site=	2
#Title=	Organic
#Remark=
#Date=	26.06.2023 16:33
#Acquired=	26.06.2023 16:33:25
101.018	3476
103.586	3498
106.152	3542
108.717	3582
111.281	3600
113.845	3618
116.407	3528
118.969	3644
121.53	3622
124.09	3652
126.649	3696
129.207	3702
131.765	3648
134.321	3646
136.877	3708
139.432	3680
141.985	3714
144.538	3734
147.09	3632
149.641	3802
152.191	3730
154.741	3854
157.289	3812
159.837	3812
162.385	3812
164.93	3856
167.476	3876
170.019	3854
172.562	3836
175.105	3928
177.646	3894
180.188	3808
182.727	3892
185.266	3916
187.804	3908
190.342	3870
192.878	4004
195.413	3952
197.948	4020
200.481	4054
203.014	4034
205.546	4038
208.077	4012
210.608	4004
213.137	4064
215.666	4088
218.194	4086
220.721	4162
223.247	4154
225.772	4082
228.295	4158
230.819	4304
233.342	4206
235.864	4292
238.384	4288
240.904	4270
243.423	4234
245.941	4306
248.46	4338
250.975	4274
253.492	4342
256.006	4424
258.519	4410
261.033	4312
263.545	4332
266.057	4316
268.567	4354
271.076	4388
273.585	4360
276.094	4314
278.601	4308
281.107	4424
283.612	4408
286.116	4462
288.62	4494
291.123	4516
293.625	4564
296.126	4632
298.626	4518
301.126	4614
303.625	4590
306.122	4648
308.62	4718
311.114	4704
313.61	4682
316.105	4666
318.599	4616
321.09	4660
323.583	4702
326.073	4684
328.563	4774
331.053	4746
333.541	4654
336.029	4762
338.515	4766
341.001	4796
343.486	4736
345.97	4782
348.453	4794
350.936	4822
353.418	4834
355.898	4838
358.378	4914
360.858	4976
363.336	4900
365.813	4958
368.29	4880
370.766	4936
373.241	4896
375.715	4938
378.188	4960
380.66	4932
383.132	4982
385.603	5020
388.072	4934
390.541	4982
393.01	4976
395.477	5080
397.943	5048
400.409	5034
402.875	5194
405.338	5080
407.802	5062
410.263	5134
412.725	5166
415.185	5246
417.646	5278
420.104	5360
422.564	5300
425.02	5334
427.477	5452
429.933	5474
432.388	5418
434.841	5460
437.294	5468
439.748	5450
442.199	5394
444.65	5496
447.1	5552
449.549	5484
451.997	5468
454.445	5530
456.891	5454
459.337	5600
461.782	5608
464.227	5556
466.669	5640
469.112	5574
471.554	5596
473.995	5582
476.434	5628
478.874	5698
481.312	5690
483.749	5668
486.186	5720
488.622	5714
491.057	5796
493.491	5800
495.925	5764
498.357	5832
500.789	5718
503.221	5892
505.65	5820
508.079	5852
510.509	5774
512.936	5906
515.363	5920
517.789	5892
520.214	5920
522.638	5948
525.062	5914
527.485	5960
529.907	5894
532.328	6016
534.748	5970
537.168	5994
539.587	6004
542.005	6072
544.423	5926
546.838	6076
549.254	6036
551.669	6120
554.082	6054
556.496	6046
558.909	6004
561.319	6170
563.731	6198
566.14	6216
568.549	6138
570.957	6162
573.364	6210
575.771	6302
578.177	6182
580.581	6304
582.987	6354
585.39	6274
587.792	6382
590.193	6308
592.594	6356
594.996	6366
597.395	6508
599.793	6570
602.191	6374
604.588	6552
606.984	6598
609.378	6590
611.773	6566
614.167	6608
616.56	6730
618.953	6718
621.343	6786
623.734	6782
626.124	6818
628.512	6918
630.901	6952
633.289	6894
635.675	6888
638.061	6980
640.446	7146
642.831	7032
645.213	7162
647.595	7178
649.978	7244
652.359	7190
654.738	7184
657.117	7250
659.497	7290
661.875	7360
664.252	7378
666.628	7362
669.003	7344
671.378	7422
673.751	7336
676.124	7270
678.497	7456
680.868	7488
683.239	7482
685.609	7520
687.977	7592
690.346	7638
692.714	7650
695.081	7516
697.446	7654
699.812	7598
702.175	7770
704.539	7768
706.901	7836
709.264	7798
711.625	7824
713.986	7940
716.345	7968
718.705	7956
721.062	8150
723.419	8120
725.775	8250
728.132	8278
730.487	8244
732.841	8246
735.194	8210
737.546	8362
739.898	8380
742.249	8346
744.599	8514
746.949	8600
749.298	8538
751.646	8542
753.993	8540
756.34	8670
758.684	8672
761.029	8610
763.374	8748
765.716	8748
768.059	8684
770.401	8794
772.741	8800
775.082	8838
777.421	8920
779.76	9004
782.097	9012
784.434	8994
786.771	9140
789.106	9060
791.44	9108
793.775	9280
796.108	9442
798.44	9346
800.771	9396
803.102	9414
805.432	9472
807.761	9544
810.09	9574
812.417	9670
814.744	9824
817.071	9744
819.396	9704
821.721	9938
824.045	9930
826.367	9954
828.69	10082
831.012	10142
833.332	10276
835.653	10282
837.972	10488
840.29	10498
842.609	10516
844.925	10498
847.242	10698
849.557	10610
851.871	10724
854.186	10866
856.498	10836
858.81	10844
861.122	10898
863.434	10934
865.744	11102
868.053	10964
870.361	11172
872.669	11254
874.976	11212
877.282	11362
879.588	11194
881.893	11432
884.197	11320
886.5	11544
888.802	11544
891.104	11542
893.405	11574
895.706	11724
898.004	11690
900.303	11812
902.6	11868
904.898	11830
907.194	11876
909.49	11950
911.785	12040
914.08	11916
916.372	12178
918.666	12202
920.957	12106
923.248	12272
925.538	12310
927.828	12344
930.118	12460
932.406	12586
934.693	12552
936.979	12674
939.265	12648
941.55	12804
943.835	12926
946.118	12996
948.401	13062
950.682	13126
952.964	13262
955.245	13300
957.525	13308
959.803	13470
962.082	13402
964.36	13376
966.636	13498
968.913	13558
971.188	13722
973.463	13700
975.736	13922
978.009	13874
980.282	13994
982.554	13934
984.824	13954
987.095	13944
989.364	14104
991.633	14292
993.9	14240
996.167	14250
998.434	14420
1000.7	14374
1002.96	14460
1005.23	14548
1007.49	14646
1009.76	14560
1012.02	14778
1014.28	14732
1016.54	14838
1018.8	14884
1021.06	14932
1023.32	14976
1025.57	15044
1027.83	15180
1030.09	15098
1032.34	15210
1034.6	15326
1036.85	15270
1039.1	15390
1041.35	15548
1043.61	15622
1045.86	15670
1048.11	15792
1050.36	15712
1052.61	15900
1054.85	16072
1057.1	15854
1059.35	16176
1061.59	15826
1063.84	16066
1066.08	16222
1068.33	16080
1070.57	16272
1072.81	16340
1075.05	16408
1077.29	16358
1079.53	16534
1081.77	16488
1084.01	16354
1086.25	16428
1088.48	16480
1090.72	16316
1092.96	16338
1095.19	16408
1097.43	16514
1099.66	16478
1101.89	16378
1104.12	16438
1106.35	16460
1108.59	16466
1110.81	16520
1113.04	16588
1115.27	16544
1117.5	16512
1119.73	16476
1121.95	16596
1124.18	16572
1126.4	16596
1128.63	16676
1130.85	16648
1133.07	16740
1135.29	16710
1137.51	16782
1139.73	16682
1141.95	16856
1144.17	16682
1146.39	16842
1148.61	16882
1150.82	16862
1153.04	16806
1155.26	16982
1157.47	16814
1159.68	16952
1161.9	16994
1164.11	16978
1166.32	16888
1168.53	16858
1170.74	16922
1172.95	16988
1175.16	16650
1177.37	16830
1179.58	16826
1181.78	16788
1183.99	16590
1186.19	16590
1188.4	16498
1190.6	16590
1192.8	16408
1195.01	16556
1197.21	16382.5
1199.41	16430.1
1201.61	16280.4
1203.81	16409.5
1206.01	16169.5
1208.2	16137.5
1210.4	16114.4
1212.6	16060.3
1214.8	15946
1216.99	15891.4
1219.18	15897.6
1221.38	15795.6
1223.57	15748
1225.76	15616.8
1227.96	15683.3
1230.15	15582.5
1232.34	15585.6
1234.53	15578.3
1236.71	15605.5
1238.9	15474.6
1241.09	15444.5
1243.28	15424.8
1245.46	15373.4
1247.65	15332.1
1249.83	15322.3
1252.02	15292.1
1254.2	15262.1
1256.38	15130.4
1258.56	15181.8
1260.74	15085.9
1262.92	15099.2
1265.1	15014.3
1267.28	15050
1269.46	15013.6
1271.64	15011.8
1273.82	14920.1
1275.99	14877.6
1278.17	14776.2
1280.34	14677.3
1282.52	14737.9
1284.69	14696.9
1286.86	14593.1
1289.03	14530.3
1291.21	14523.3
1293.38	14471.9
1295.55	14421.8
1297.71	14383
1299.88	14387
1302.05	14162.7
1304.22	14231.1
1306.38	14235
1308.43	14200
1310.61	14040
1312.78	13970
1314.96	13840
1317.13	13844
1319.3	13802
1321.48	13718
1323.65	13496
1325.82	13548
1327.99	13266
1330.16	13394
1332.33	13332
1334.5	13182
1336.66	13212
1338.83	13132
1341	13004
1343.16	12988
1345.33	13084
1347.49	12920
1349.65	12790
1351.82	12780
1353.98	12734
1356.14	12748
1358.3	12720
1360.46	12518
1362.62	12638
1364.78	12366
1366.94	12336
1369.09	12324
1371.25	12294
1373.41	12220
1375.56	12192
1377.72	12200
1379.87	12030
1382.02	11972
1384.17	11976
1386.33	11970
1388.48	11996
1390.63	11828
1392.78	11820
1394.93	11690
1397.07	11726
1399.22	11598
1401.37	11626
1403.52	11604
1405.66	11532
1407.81	11330
1409.95	11552
1412.09	11422
1414.24	11348
1416.38	11220
1418.52	11150
1420.66	11262
1422.8	11176
1424.94	11312
1427.08	11110
1429.22	10986
1431.35	11030
1433.49	10892
1435.63	10882
1437.76	11014
1439.9	11030
1442.03	10854
1444.17	10822
1446.3	10744
1448.43	10898
1450.56	10736
1452.69	10628
1454.82	10742
1456.95	10738
1459.08	10746
1461.21	10626
1463.34	10734
1465.46	10672
1467.59	10592
1469.71	10478
1471.84	10544
1473.96	10406
1476.08	10538
1478.21	10400
1480.33	10430
1482.45	10390
1484.57	10464
1486.69	10478
1488.81	10422
1490.93	10148
1493.05	10292
1495.16	10250
1497.28	10244
1499.4	10178
1501.51	10148
1503.63	10090
1505.74	10082
1507.85	9988
1509.97	10008
1512.08	9928
1514.19	10064
1516.3	9912
1518.41	9926
1520.52	9938
1522.63	9896
1524.73	9840
1526.84	9726
1528.95	9714
1531.06	9708
1533.16	9676
1535.26	9662
1537.37	9550
1539.47	9568
1541.57	9628
1543.68	9716
1545.78	9516
1547.88	9442
1549.98	9422
1552.08	9374
1554.18	9434
1556.27	9336
1558.37	9238
1560.47	9286
1562.56	9350
1564.66	9250
1566.75	9400
1568.85	9246
1570.94	9190
1573.03	9106
1575.13	9142
1577.22	9166
1579.31	9154
1581.4	9214
1583.49	9080
1585.58	9170
1587.66	9098
1589.75	9024
1591.84	9130
1593.93	9106
1596.01	9040
1598.1	9016
1600.18	8968
1602.26	9084
1604.35	9008
1606.43	8934
1608.51	8938
1610.59	8932
1612.67	8976
1614.75	8956
1616.83	9006
1618.91	8954
1620.99	8868
1623.06	8870
1625.14	9018
1627.21	8830
1629.29	8878
1631.36	8806
1633.44	8988
1635.51	8948
1637.58	8828
1639.66	8816
1641.73	8810
1643.8	8824
1645.87	8816
1647.94	8770
1650	8786
1652.07	8686
1654.14	8722
1656.21	8746
1658.27	8610
1660.34	8682
1662.4	8638
1664.47	8582
1666.53	8644
1668.59	8686
1670.66	8594
1672.72	8404
1674.78	8528
1676.84	8480
1678.9	8372
1680.96	8450
1683.01	8338
1685.07	8314
1687.13	8380
1689.19	8386
1691.24	8346
1693.3	8192
1695.35	8248
1697.4	8262
1699.46	8146
1701.51	8164
1703.56	8182
1705.61	8080
1707.66	8150
1709.71	8206
1711.76	8104
1713.81	8134
1715.86	8080
1717.91	7960
1719.95	8002
1722	7986
1724.04	8044
1726.09	8112
1728.13	7942
1730.18	7956
1732.22	7958
1734.26	7948
1736.3	7884
1738.34	7924
1740.38	7874
1742.42	7932
1744.46	7894
1746.5	7844
1748.54	7856
1750.58	7896
1752.61	7866
1754.65	7860
1756.68	7798
1758.72	7886
1760.75	7786
1762.79	7760
1764.82	7790
1766.85	7814
1768.88	7856
1770.91	7826
1772.94	7840
1774.97	7790
1777	7792
1779.03	7668
1781.06	7766
1783.09	7782
1785.11	7740
1787.14	7662
1789.16	7782
1791.19	7674
1793.21	7636
1795.23	7630
1797.26	7624
1799.28	7666
1801.3	7640
1803.32	7644
1805.34	7674
1807.36	7686
1809.38	7630
1811.4	7548
1813.42	7646
1815.43	7606
1817.45	7584
1819.47	7588
1821.48	7564
1823.49	7522
1825.51	7580
1827.52	7452
1829.54	7354
1831.55	7504
1833.56	7370
1835.57	7358
1837.58	7378
1839.59	7312
1841.6	7364
1843.61	7318
1845.61	7272
1847.62	7404
1849.63	7350
1851.63	7354
1853.64	7228
1855.64	7256
1857.65	7344
1859.65	7322
1861.65	7240
1863.65	7170
1865.66	7220
1867.66	7210
1869.66	7214
1871.66	7110
1873.66	7144
1875.65	7202
1877.65	7120
1879.65	7148
1881.65	7094
1883.64	7200
1885.64	7090
1887.63	7128
1889.63	7018
1891.62	7128
1893.61	7110
1895.6	7016
1897.6	7056
1899.59	7222
1901.58	7014
1903.57	7012
1905.56	7058
1907.54	7064
1909.53	7084
1911.52	7052
1913.51	7000
1915.49	6924
1917.48	7054
1919.46	6954
1921.45	6956
1923.43	7054
1925.41	6958
1927.4	6964
1929.38	7034
1931.36	6922
1933.34	6948
1935.32	6876
1937.3	6948
1939.28	6806
1941.26	6992
1943.23	6940
1945.21	6942
1947.19	6892
1949.16	6936
1951.14	6868
1953.11	6834
1955.09	6876
1957.06	6794
1959.03	6758
1961	6804
1962.98	6862
1964.95	6812
1966.92	6874
1968.89	6750
1970.85	6764
1972.82	6782
1974.79	6788
1976.76	6688
1978.73	6628
1980.69	6732
1982.66	6730
1984.62	6756
1986.59	6672
1988.55	6680
1990.51	6664
1992.47	6674
1994.44	6674
1996.4	6476
1998.36	6650
2000.32	6636
2002.28	6564
2004.24	6636
2006.19	6644
2008.15	6530
2010.11	6580
2012.06	6564
2014.02	6648
2015.98	6540
2017.93	6558
2019.88	6516
2021.84	6538
2023.79	6548
2025.74	6524
2027.69	6458
2029.65	6434
2031.6	6508
2033.55	6548
2035.5	6552
2037.44	6542
2039.39	6494
2041.34	6450
2043.29	6436
2045.23	6464
2047.18	6352
2049.12	6460
2051.07	6396
2053.01	6396
2054.95	6468
2056.9	6450
2058.84	6324
2060.78	6362
2062.72	6372
2064.66	6356
2066.6	6342
2068.54	6324
2070.48	6360
2072.42	6338
2074.35	6334
2076.29	6364
2078.23	6340
2080.16	6308
2082.1	6222
2084.03	6278
2085.96	6258
2087.9	6232
2089.83	6304
2091.76	6162
2093.69	6316
2095.62	6186
2097.55	6140
2099.48	6250
2101.41	6202
2103.34	6160
2105.27	6160
2107.2	6094
2109.12	6224
2111.05	6090
2112.98	6128
2114.9	6246
2116.82	6198
2118.75	6134
2120.67	6074
2122.59	6178
2124.52	6140
2126.44	6046
2128.36	6020
2130.28	6100
2132.2	6058
2134.12	6070
2136.04	6042
2137.95	6048
2139.87	6052
2141.79	5998
2143.7	5976
2145.62	6045.6
2147.53	6000.38
2149.45	5977.64
2151.36	5968.36
2153.28	5887.47
2155.19	5950.61
2157.1	5920.37
2159.01	5875.16
2160.92	5918.96
2162.83	5853.89
2164.74	5875.94
2166.65	5789.02
2168.56	5810.13
2170.47	5764.66
2172.38	5855.51
2174.28	5879
2176.19	5773.92
2178.09	5781.93
2180	5784.46
2181.9	5778.52
2183.81	5791.47
2185.71	5842.69
2187.61	5723.27
2189.52	5793.44
2191.42	5733.14
2193.32	5698.43
2195.22	5738.51
2197.12	5768.8
2199.02	5725.82
2200.92	5733.38
2202.82	5689.73
2204.71	5733.8
2206.61	5696.78
2208.51	5702.92
2210.4	5668.9
2212.3	5658.77
2214.19	5703.04
2216.09	5666.3
2217.98	5689.44
2219.87	5682.87
2221.77	5701.96
2223.66	5717.07
2225.55	5755.16
2227.44	5692.67
2229.33	5695.89
2231.22	5674.89
2233.11	5679.49
2235	5677.15
2236.88	5701.29
2238.77	5693.77
2240.66	5687.66
2242.07	5646
2243.97	5696
2245.87	5658
2247.76	5770
2249.65	5756
2251.55	5684
2253.44	5674
2255.33	5608
2257.22	5612
2259.12	5624
2261.01	5686
2262.9	5656
2264.78	5612
2266.67	5554
2268.56	5600
2270.45	5634
2272.34	5620
2274.22	5628
2276.11	5586
2277.99	5560
2279.88	5550
2281.76	5612
2283.65	5514
2285.53	5414
2287.41	5546
2289.3	5508
2291.18	5500
2293.06	5498
2294.94	5532
2296.82	5478
2298.7	5476
2300.58	5460
2302.46	5432
2304.33	5500
2306.21	5468
2308.09	5390
2309.96	5418
2311.84	5466
2313.71	5476
2315.59	5418
2317.46	5460
2319.33	5374
2321.21	5378
2323.08	5440
2324.95	5364
2326.82	5426
2328.69	5360
2330.56	5328
2332.43	5398
2334.3	5324
2336.17	5374
2338.03	5292
2339.9	5402
2341.77	5296
2343.63	5348
2345.5	5296
2347.36	5414
2349.23	5278
2351.09	5326
2352.95	5264
2354.82	5262
2356.68	5338
2358.54	5312
2360.4	5296
2362.26	5244
2364.12	5278
2365.98	5230
2367.84	5182
2369.7	5298
2371.56	5232
2373.41	5258
2375.27	5256
2377.12	5218
2378.98	5204
2380.84	5258
2382.69	5254
2384.54	5254
2386.4	5156
2388.25	5118
2390.1	5208
2391.95	5236
2393.8	5144
2395.65	5106
2397.5	5136
2399.35	5114
2401.2	5082
2403.05	5022
2404.9	5076
2406.75	5034
2408.59	5048
2410.44	5114
2412.28	5034
2414.13	5028
2415.97	5048
2417.82	4962
2419.66	5032
2421.5	4996
2423.35	5062
2425.19	4992
2427.03	4914
2428.87	4932
2430.71	4904
2432.55	4962
2434.39	4928
2436.23	4998
2438.06	4924
2439.9	5018
2441.74	4870
2443.57	4928
2445.41	4918
2447.24	4956
2449.08	4944
2450.91	4904
2452.75	4912
2454.58	4850
2456.41	4858
2458.24	4880
2460.08	4794
2461.91	4902
2463.74	4780
2465.57	4794
2467.4	4842
2469.22	4736
2471.05	4826
2472.88	4776
2474.71	4746
2476.53	4768
2478.36	4740
2480.19	4770
2482.01	4816
2483.83	4702
2485.66	4724
2487.48	4750
2489.3	4714
2491.13	4664
2492.95	4668
2494.77	4590
2496.59	4724
2498.41	4644
2500.23	4604
2502.05	4692
2503.87	4606
2505.68	4646
2507.5	4640
2509.32	4574
2511.14	4548
2512.95	4610
2514.77	4560
2516.58	4616
2518.39	4624
2520.21	4498
2522.02	4456
2523.83	4546
2525.65	4534
2527.46	4520
2529.27	4512
2531.08	4470
2532.89	4434
2534.7	4392
2536.51	4432
2538.32	4492
2540.12	4420
2541.93	4444
2543.74	4436
2545.54	4376
2547.35	4424
2549.15	4402
2550.96	4386
2552.76	4308
2554.56	4336
2556.37	4288
2558.17	4408
2559.97	4328
2561.77	4332
2563.58	4308
2565.38	4380
2567.18	4292
2568.97	4222
2570.77	4310
2572.57	4244
2574.37	4266
2576.17	4200
2577.96	4224
2579.76	4178
2581.55	4190
2583.35	4146
2585.14	4124
2586.94	4206
2588.73	4110
2590.52	4134
2592.32	4182
2594.11	4092
2595.9	4140
2597.69	4170
2599.48	4068
2601.27	4100
2603.06	4126
2604.85	4146
2606.64	3984
2608.42	4032
2610.21	3968
2612	4042
2613.78	3986
2615.57	3988
2617.36	4006
2619.14	4090
2620.92	3992
2622.71	4006
2624.49	3942
2626.27	3938
2628.05	3982
2629.84	3908
2631.62	3968
2633.4	3892
2635.18	3874
2636.96	3968
2638.74	3930
2640.51	3832
2642.29	3818
2644.07	3900
2645.85	3944
2647.62	3842
2649.4	3862
2651.17	3782
2652.95	3788
2654.72	3750
2656.5	3726
2658.27	3806
2660.04	3836
2661.81	3762
2663.58	3768
2665.35	3800
2667.13	3764
2668.9	3760
2670.66	3718
2672.43	3756
2674.2	3722
2675.97	3726
2677.74	3678
2679.5	3660
2681.27	3684
2683.04	3602
2684.8	3686
2686.57	3678
2688.33	3704
2690.09	3740
2691.86	3654
2693.62	3580
2695.38	3648
2697.15	3500
2698.91	3636
2700.67	3564
2702.43	3594
2704.19	3618
2705.95	3518
2707.7	3572
2709.46	3514
2711.22	3500
2712.98	3488
2714.73	3482
2716.49	3472
2718.25	3562
2720	3438
2721.76	3434
2723.51	3520
2725.26	3418
2727.02	3408
2728.77	3414
2730.52	3344
2732.27	3440
2734.02	3352
2735.77	3400
2737.52	3338
2739.27	3408
2741.02	3400
2742.77	3378
2744.52	3410
2746.27	3348
2748.01	3264
2749.76	3334
2751.51	3354
2753.25	3282
2755	3304
2756.74	3286
2758.48	3298
2760.23	3222
2761.97	3250
2763.71	3218
2765.45	3284
2767.19	3258
2768.94	3232
2770.68	3204
2772.42	3218
2774.16	3168
2775.89	3226
2777.63	3212
2779.37	3138
2781.11	3196
2782.84	3128
2784.58	3182
2786.32	3144
2788.05	3136
2789.79	3176
2791.52	3170
2793.25	3108
2794.99	3118
2796.72	3112
2798.45	3090
2800.18	3050
2801.92	3140
2803.65	3073
2805.38	3046
2807.11	3094
2808.84	3076
2810.57	3062
2812.29	3022
2814.02	3074
2815.75	3042
2817.47	3012
2819.2	2976
2820.93	3006
2822.65	3002
2824.38	2978
2826.1	3004
2827.82	2926
2829.55	2892
2831.27	2888
2832.99	2928
2834.71	2892
2836.44	2934
2838.16	2958
2839.88	2852
2841.6	2904
2843.32	2868
2845.03	2934
2846.75	2858
2848.47	2870
2850.19	2806
2851.9	2754
2853.62	2832
2855.34	2842
2857.05	2780
2858.77	2834
2860.48	2694
2862.19	2730
2863.91	2710
2865.62	2720
2867.33	2720
2869.04	2776
2870.76	2742
2872.47	2760
2874.18	2696
2875.89	2676
2877.6	2782
2879.31	2708
2881.01	2706
2882.72	2688
2884.43	2654
2886.14	2692
2887.84	2630
2889.55	2672
2891.25	2654
2892.96	2662
2894.66	2576
2896.37	2622
2898.07	2692
2899.77	2574
2901.48	2560
2903.18	2610
2904.88	2532
2906.58	2612
2908.28	2608
2909.98	2604
2911.68	2568
2913.38	2534
2915.08	2608
2916.78	2558
2918.47	2544
2920.17	2572
2921.87	2548
2923.56	2492
2925.26	2554
2926.95	2570
2928.65	2492
2930.34	2528
2932.04	2524
2933.73	2522
2935.42	2488
2937.11	2482
2938.81	2428
2940.5	2454
2942.19	2462
2943.88	2474
2945.57	2520
2947.26	2440
2948.95	2444
2950.64	2420
2952.32	2430
2954.01	2438
2955.7	2442
2957.38	2436
2959.07	2502
2960.75	2428
2962.44	2338
2964.12	2388
2965.81	2410
2967.49	2394
2969.17	2398
2970.86	2324
2972.54	2346
2974.22	2350
2975.9	2378
2977.58	2350
2979.26	2312
2980.94	2346
2982.62	2316
2984.3	2304
2985.98	2314
2987.66	2246
2989.33	2344
2991.01	2242
2992.69	2254
2994.36	2266
2996.04	2172
2997.71	2302
2999.39	2282