File: muestras/tallo/2/Organic_02.txt
#Acq. time (s)=	10
#Accumulations=	1
#Range (cm-¹)=	100...3000
#Windows=	3
#Autofocus=	Off
#AutoExposure=	Off
#Spike filter=	Off
#Delay time (s)=	0
#Binning=	1
#Readout mode=	Signal
#DeNoise=	Off
#ICS correction=	Off
#Dark correction=	Off
#Inst. Process=	Off
#Instrument=	LabRAM HR Evol
#Detector=	Syncerity OE
#Objective=	x100_VIS
#Grating=	600 (500nm)
#ND Filter=	3.2%
#Laser=	633nm_Edge
#Hole=	100.021
#Range=	Visible
#Project=	Omar
#Sample=	26-06-23
#Site=	2
#Title=	Organic
#Remark=
#Date=	26.06.2023 16:17
#Acquired=	26.06.2023 16:17:00
101.018	4436
103.586	4444
106.152	4492
108.717	4560
111.281	4560
113.845	4480
116.407	4492
118.969	4566
121.53	4612
124.09	4606
126.649	4654
129.207	4616
131.765	4686
134.321	4662
136.877	4674
139.432	4698
141.985	4674
144.538	4638
147.09	4654
149.641	4736
152.191	4690
154.741	4824
157.289	4804
159.837	4812
162.385	4898
164.93	4862
167.476	4910
170.019	4868
172.562	4810
175.105	4922
177.646	4878
180.188	4890
182.727	4984
185.266	4996
187.804	4988
190.342	4928
192.878	5112
195.413	5004
197.948	5090
200.481	5052
203.014	5152
205.546	5144
208.077	5162
210.608	5162
213.137	5224
215.666	5186
218.194	5206
220.721	5294
223.247	5282
225.772	5388
228.295	5336
230.819	5400
233.342	5492
235.864	5370
238.384	5406
240.904	5428
243.423	5458
245.941	5444
248.46	5554
250.975	5494
253.492	5608
256.006	5546
258.519	5518
261.033	5556
263.545	5500
266.057	5516
268.567	5614
271.076	5580
273.585	5476
276.094	5568
278.601	5612
281.107	5724
283.612	5676
286.116	5648
288.62	5820
291.123	5784
293.625	5822
296.126	5816
298.626	5724
301.126	5918
303.625	5956
306.122	5940
308.62	5976
311.114	5964
313.61	6002
316.105	6052
318.599	5990
321.09	6010
323.583	6068
326.073	6112
328.563	6038
331.053	6142
333.541	6028
336.029	6098
338.515	6088
341.001	6208
343.486	6236
345.97	6206
348.453	6230
350.936	6254
353.418	6250
355.898	6382
358.378	6414
360.858	6452
363.336	6352
365.813	6388
368.29	6446
370.766	6376
373.241	6454
375.715	6426
378.188	6456
380.66	6346
383.132	6500
385.603	6468
388.072	6508
390.541	6494
393.01	6540
395.477	6556
397.943	6600
400.409	6660
402.875	6544
405.338	6636
407.802	6728
410.263	6676
412.725	6662
415.185	6748
417.646	6810
420.104	6976
422.564	6990
425.02	6954
427.477	6930
429.933	7020
432.388	7094
434.841	7064
437.294	7114
439.748	7176
442.199	7186
444.65	7070
447.1	7208
449.549	7156
451.997	7240
454.445	7192
456.891	7188
459.337	7264
461.782	7146
464.227	7236
466.669	7196
469.112	7318
471.554	7258
473.995	7270
476.434	7448
478.874	7474
481.312	7462
483.749	7462
486.186	7480
488.622	7526
491.057	7544
493.491	7606
495.925	7588
498.357	7672
500.789	7668
503.221	7720
505.65	7714
508.079	7742
510.509	7748
512.936	7740
515.363	7796
517.789	7744
520.214	7744
522.638	7836
525.062	7874
527.485	7906
529.907	7840
532.328	7882
534.748	7954
537.168	7954
539.587	7966
542.005	7928
544.423	7970
546.838	7990
549.254	8136
551.669	8008
554.082	7926
556.496	8068
558.909	8242
561.319	8224
563.731	8194
566.14	8350
568.549	8184
570.957	8246
573.364	8362
575.771	8378
578.177	8348
580.581	8516
582.987	8360
585.39	8524
587.792	8456
590.193	8544
592.594	8590
594.996	8552
597.395	8570
599.793	8650
602.191	8746
604.588	8826
606.984	8870
609.378	8992
611.773	9030
614.167	8938
616.56	9088
618.953	9200
621.343	9186
623.734	9236
626.124	9288
628.512	9472
630.901	9332
633.289	9498
635.675	9532
638.061	9662
640.446	9628
642.831	9710
645.213	9686
647.595	9826
649.978	9764
652.359	9904
654.738	9966
657.117	9916
659.497	10074
661.875	9880
664.252	10104
666.628	10200
669.003	10054
671.378	10216
673.751	10316
676.124	10388
678.497	10194
680.868	10374
683.239	10412
685.609	10408
687.977	10408
690.346	10664
692.714	10498
695.081	10590
697.446	10610
699.812	10714
702.175	10926
704.539	10856
706.901	10926
709.264	10948
711.625	11082
713.986	11150
716.345	11228
718.705	11242
721.062	11264
723.419	11406
725.775	11380
728.132	11512
730.487	11600
732.841	11632
735.194	11700
737.546	11728
739.898	11820
742.249	11846
744.599	11938
746.949	12042
749.298	12008
751.646	12132
753.993	12204
756.34	12198
758.684	12366
761.029	12402
763.374	12420
765.716	12676
768.059	12566
770.401	12638
772.741	12726
775.082	12522
777.421	12774
779.76	12866
782.097	12928
784.434	13044
786.771	13036
789.106	13240
791.44	13194
793.775	13354
796.108	13552
798.44	13402
800.771	13578
803.102	13578
805.432	13550
807.761	13830
810.09	14026
812.417	13990
814.744	14162
817.071	14294
819.396	14352
821.721	14500
824.045	14510
826.367	14508
828.69	14712
831.012	14760
833.332	14790
835.653	14784
837.972	15134
840.29	15200
842.609	15218
844.925	15344
847.242	15596
849.557	15456
851.871	15736
854.186	15800
856.498	15920
858.81	15982
861.122	16040
863.434	16152
865.744	16338
868.053	16384
870.361	16576
872.669	16376
874.976	16650
877.282	16554
879.588	16866
881.893	16842
884.197	16862
886.5	17042
888.802	17204
891.104	17094
893.405	17122
895.706	17400
898.004	17420
900.303	17590
902.6	17472
904.898	17554
907.194	17666
909.49	17806
911.785	17832
914.08	17896
916.372	18052
918.666	18130
920.957	18346
923.248	18380
925.538	18480
927.828	18564
930.118	18694
932.406	18816
934.693	19004
936.979	18860
939.265	19122
941.55	19290
943.835	19302
946.118	19396
948.401	19556
950.682	19886
952.964	19768
955.245	19886
957.525	20022
959.803	20138
962.082	20240
964.36	20442
966.636	20624
968.913	20688
971.188	20763
973.463	20640
975.736	21014
978.009	20702
980.282	20970
982.554	21258
984.824	21040
987.095	21368
989.364	21432
991.633	21420
993.9	21414
996.167	21584
998.434	21760
1000.7	21816
1002.96	21928
1005.23	22074
1007.49	22042
1009.76	22138
1012.02	22276
1014.28	22348
1016.54	22400
1018.8	22492
1021.06	22724
1023.32	22724
1025.57	22926
1027.83	22922
1030.09	23130
1032.34	23104
1034.6	23304
1036.85	23474
1039.1	23704
1041.35	23706
1043.61	23958
1045.86	23848
1048.11	24066
1050.36	23954
1052.61	24120
1054.85	24344
1057.1	24558
1059.35	24552
1061.59	24510
1063.84	24674
1066.08	24608
1068.33	24614
1070.57	24668
1072.81	24778
1075.05	24788
1077.29	25022
1079.53	24932
1081.77	24858
1084.01	24966
1086.25	25038
1088.48	24972
1090.72	25036
1092.96	24946
1095.19	25062
1097.43	25014
1099.66	24894
1101.89	25006
1104.12	25064
1106.35	25204
1108.59	25046
1110.81	25028
1113.04	24948
1115.27	25298
1117.5	25238
1119.73	25162
1121.95	25232
1124.18	25116
1126.4	25274
1128.63	25320
1130.85	25416
1133.07	25286
1135.29	25310
1137.51	25516
1139.73	25506
1141.95	25374
1144.17	25394
1146.39	25528
1148.61	25544
1150.82	25720
1153.04	25646
1155.26	25692
1157.47	25644
1159.68	25494
1161.9	25648
1164.11	25542
1166.32	25650
1168.53	25622
1170.74	25490
1172.95	25366
1175.16	25324
1177.37	25472
1179.58	25496
1181.78	25286
1183.99	25336
1186.19	25108
1188.4	25216
1190.6	24906
1192.8	24802
1195.01	24828
1197.21	24906.5
1199.41	24689.5
1201.61	24442.6
1203.81	24278.1
1206.01	24322.9
1208.2	24375.2
1210.4	24211.3
1212.6	24145
1214.8	24101.8
1216.99	23892.2
1219.18	23979.7
1221.38	23620.8
1223.57	23593.2
1225.76	23680
1227.96	23609.8
1230.15	23383.6
1232.34	23502.6
1234.53	23419.7
1236.71	23331.5
1238.9	23186.2
1241.09	23164.9
1243.28	23173.8
1245.46	23015.1
1247.65	22783.4
1249.83	22880.9
1252.02	22769.8
1254.2	22689.7
1256.38	22709.8
1258.56	22463.9
1260.74	22515.3
1262.92	22460
1265.1	22325
1267.28	22282.5
1269.46	22391
1271.64	22143.2
1273.82	22162.2
1275.99	22078.3
1278.17	21941.8
1280.34	21856.9
1282.52	21761.8
1284.69	21792.9
1286.86	21708.7
1289.03	21514.9
1291.21	21541.5
1293.38	21365.8
1295.55	21212.2
1297.71	21181.4
1299.88	21003.5
1302.05	20961.9
1304.22	20869.9
1306.38	20809.1
1308.43	20604
1310.61	20616
1312.78	20470
1314.96	20432
1317.13	20292
1319.3	20130
1321.48	20016
1323.65	19974
1325.82	19914
1327.99	19650
1330.16	19584
1332.33	19562
1334.5	19500
1336.66	19324
1338.83	19148
1341	19008
1343.16	19028
1345.33	18656
1347.49	18686
1349.65	18548
1351.82	18486
1353.98	18364
1356.14	18292
1358.3	18394
1360.46	18158
1362.62	18150
1364.78	18074
1366.94	17864
1369.09	17854
1371.25	17596
1373.41	17626
1375.56	17702
1377.72	17460
1379.87	17240
1382.02	17150
1384.17	17202
1386.33	17260
1388.48	17052
1390.63	17044
1392.78	17058
1394.93	16840
1397.07	16776
1399.22	16834
1401.37	16620
1403.52	16398
1405.66	16368
1407.81	16420
1409.95	16270
1412.09	16340
1414.24	16098
1416.38	16214
1418.52	16018
1420.66	15862
1422.8	15968
1424.94	15818
1427.08	15624
1429.22	15730
1431.35	15588
1433.49	15652
1435.63	15596
1437.76	15462
1439.9	15390
1442.03	15406
1444.17	15308
1446.3	15250
1448.43	15218
1450.56	15190
1452.69	15164
1454.82	15060
1456.95	15012
1459.08	14778
1461.21	14928
1463.34	15038
1465.46	14934
1467.59	14802
1469.71	14750
1471.84	14678
1473.96	14714
1476.08	14772
1478.21	14578
1480.33	14416
1482.45	14448
1484.57	14488
1486.69	14358
1488.81	14418
1490.93	14284
1493.05	14216
1495.16	14186
1497.28	14066
1499.4	14248
1501.51	14172
1503.63	14276
1505.74	13904
1507.85	13938
1509.97	13964
1512.08	13822
1514.19	13776
1516.3	13704
1518.41	13728
1520.52	13542
1522.63	13690
1524.73	13494
1526.84	13534
1528.95	13438
1531.06	13480
1533.16	13296
1535.26	13306
1537.37	13208
1539.47	13254
1541.57	13260
1543.68	13166
1545.78	13086
1547.88	13030
1549.98	13032
1552.08	12918
1554.18	12994
1556.27	12882
1558.37	12850
1560.47	12764
1562.56	12630
1564.66	12674
1566.75	12836
1568.85	12650
1570.94	12654
1573.03	12558
1575.13	12620
1577.22	12644
1579.31	12586
1581.4	12492
1583.49	12582
1585.58	12376
1587.66	12482
1589.75	12408
1591.84	12404
1593.93	12402
1596.01	12398
1598.1	12284
1600.18	12352
1602.26	12340
1604.35	12376
1606.43	12150
1608.51	12246
1610.59	12200
1612.67	12362
1614.75	12236
1616.83	12226
1618.91	12130
1620.99	12196
1623.06	11990
1625.14	12080
1627.21	12124
1629.29	12232
1631.36	12104
1633.44	11998
1635.51	12022
1637.58	12066
1639.66	11930
1641.73	11932
1643.8	11890
1645.87	11918
1647.94	11856
1650	11868
1652.07	11758
1654.14	11968
1656.21	11808
1658.27	11612
1660.34	11720
1662.4	11582
1664.47	11606
1666.53	11532
1668.59	11504
1670.66	11444
1672.72	11430
1674.78	11364
1676.84	11642
1678.9	11368
1680.96	11380
1683.01	11346
1685.07	11298
1687.13	11462
1689.19	11240
1691.24	11252
1693.3	11170
1695.35	11162
1697.4	11124
1699.46	11132
1701.51	11058
1703.56	10948
1705.61	11024
1707.66	10862
1709.71	11090
1711.76	10848
1713.81	10924
1715.86	10842
1717.91	10960
1719.95	10760
1722	10772
1724.04	10816
1726.09	10864
1728.13	10780
1730.18	10814
1732.22	10746
1734.26	10804
1736.3	10838
1738.34	10786
1740.38	10676
1742.42	10714
1744.46	10594
1746.5	10570
1748.54	10642
1750.58	10620
1752.61	10584
1754.65	10628
1756.68	10604
1758.72	10596
1760.75	10592
1762.79	10500
1764.82	10634
1766.85	10598
1768.88	10454
1770.91	10588
1772.94	10560
1774.97	10456
1777	10420
1779.03	10364
1781.06	10426
1783.09	10380
1785.11	10458
1787.14	10412
1789.16	10370
1791.19	10400
1793.21	10304
1795.23	10430
1797.26	10304
1799.28	10360
1801.3	10344
1803.32	10222
1805.34	10372
1807.36	10292
1809.38	10210
1811.4	10160
1813.42	10324
1815.43	10046
1817.45	10356
1819.47	10132
1821.48	9964
1823.49	10080
1825.51	10182
1827.52	10040
1829.54	9954
1831.55	10042
1833.56	10034
1835.57	9938
1837.58	9998
1839.59	9878
1841.6	9890
1843.61	9844
1845.61	9820
1847.62	9890
1849.63	9794
1851.63	9708
1853.64	9816
1855.64	9676
1857.65	9714
1859.65	9830
1861.65	9692
1863.65	9770
1865.66	9590
1867.66	9644
1869.66	9644
1871.66	9834
1873.66	9744
1875.65	9596
1877.65	9536
1879.65	9660
1881.65	9670
1883.64	9556
1885.64	9488
1887.63	9520
1889.63	9552
1891.62	9546
1893.61	9614
1895.6	9534
1897.6	9532
1899.59	9522
1901.58	9480
1903.57	9480
1905.56	9380
1907.54	9554
1909.53	9538
1911.52	9494
1913.51	9416
1915.49	9486
1917.48	9400
1919.46	9418
1921.45	9456
1923.43	9428
1925.41	9464
1927.4	9404
1929.38	9428
1931.36	9462
1933.34	9344
1935.32	9340
1937.3	9370
1939.28	9324
1941.26	9358
1943.23	9264
1945.21	9180
1947.19	9216
1949.16	9290
1951.14	9148
1953.11	9204
1955.09	9250
1957.06	9316
1959.03	9132
1961	9248
1962.98	9176
1964.95	9134
1966.92	9214
1968.89	9168
1970.85	9196
1972.82	9088
1974.79	9054
1976.76	9036
1978.73	9074
1980.69	8938
1982.66	9044
1984.62	9138
1986.59	8970
1988.55	9038
1990.51	8984
1992.47	8898
1994.44	8946
1996.4	8936
1998.36	8934
2000.32	9028
2002.28	8918
2004.24	8990
2006.19	8888
2008.15	8914
2010.11	8960
2012.06	8946
2014.02	8876
2015.98	8896
2017.93	8972
2019.88	8852
2021.84	8818
2023.79	8652
2025.74	8828
2027.69	8904
2029.65	8772
2031.6	8908
2033.55	8848
2035.5	8726
2037.44	8942
2039.39	8746
2041.34	8772
2043.29	8694
2045.23	8750
2047.18	8702
2049.12	8770
2051.07	8670
2053.01	8682
2054.95	8786
2056.9	8514
2058.84	8712
2060.78	8632
2062.72	8574
2064.66	8560
2066.6	8466
2068.54	8536
2070.48	8678
2072.42	8464
2074.35	8572
2076.29	8520
2078.23	8542
2080.16	8530
2082.1	8516
2084.03	8586
2085.96	8496
2087.9	8442
2089.83	8446
2091.76	8422
2093.69	8472
2095.62	8404
2097.55	8414
2099.48	8428
2101.41	8380
2103.34	8284
2105.27	8390
2107.2	8400
2109.12	8378
2111.05	8446
2112.98	8336
2114.9	8316
2116.82	8296
2118.75	8364
2120.67	8320
2122.59	8380
2124.52	8240
2126.44	8244
2128.36	8378
2130.28	8208
2132.2	8244
2134.12	8222
2136.04	8312
2137.95	8208
2139.87	8264
2141.79	8236
2143.7	8104
2145.62	8131.29
2147.53	8143.44
2149.45	8057.18
2151.36	8167.8
2153.28	8119.23
2155.19	7971.97
2157.1	8005.44
2159.01	8031.79
2160.92	8008.23
2162.83	7963.58
2164.74	7912.81
2166.65	7838.06
2168.56	7910.56
2170.47	7921.18
2172.38	7860.37
2174.28	7870.28
2176.19	7882.8
2178.09	7891.89
2180	7807.73
2181.9	7903.31
2183.81	7761.38
2185.71	7845.16
2187.61	7776.11
2189.52	7768.98
2191.42	7752.95
2193.32	7809.65
2195.22	7750.05
2197.12	7747.46
2199.02	7707.54
2200.92	7729.81
2202.82	7660.69
2204.71	7740.6
2206.61	7714.08
2208.51	7717.75
2210.4	7663.21
2212.3	7674.01
2214.19	7685.4
2216.09	7610.73
2217.98	7653.78
2219.87	7664.75
2221.77	7698.14
2223.66	7664
2225.55	7578.95
2227.44	7651.73
2229.33	7690.18
2231.22	7674.34
2233.11	7709.82
2235	7673.28
2236.88	7673.13
2238.77	7640.04
2240.66	7673.69
2242.07	7658
2243.97	7680
2245.87	7658
2247.76	7576
2249.65	7588
2251.55	7616
2253.44	7648
2255.33	7520
2257.22	7668
2259.12	7606
2261.01	7548
2262.9	7562
2264.78	7482
2266.67	7622
2268.56	7546
2270.45	7476
2272.34	7582
2274.22	7508
2276.11	7456
2277.99	7450
2279.88	7628
2281.76	7566
2283.65	7492
2285.53	7548
2287.41	7460
2289.3	7538
2291.18	7418
2293.06	7374
2294.94	7454
2296.82	7378
2298.7	7364
2300.58	7162
2302.46	7366
2304.33	7370
2306.21	7400
2308.09	7242
2309.96	7366
2311.84	7250
2313.71	7370
2315.59	7312
2317.46	7420
2319.33	7184
2321.21	7304
2323.08	7264
2324.95	7208
2326.82	7304
2328.69	7258
2330.56	7208
2332.43	7180
2334.3	7138
2336.17	7150
2338.03	7244
2339.9	7260
2341.77	7212
2343.63	7190
2345.5	7114
2347.36	7184
2349.23	7220
2351.09	7214
2352.95	7116
2354.82	7110
2356.68	7054
2358.54	7168
2360.4	7186
2362.26	7064
2364.12	7132
2365.98	7142
2367.84	7112
2369.7	7124
2371.56	7032
2373.41	7008
2375.27	7004
2377.12	6996
2378.98	7012
2380.84	6970
2382.69	6970
2384.54	6900
2386.4	6950
2388.25	7056
2390.1	6932
2391.95	6826
2393.8	6800
2395.65	6964
2397.5	6836
2399.35	6898
2401.2	6928
2403.05	6920
2404.9	6788
2406.75	6792
2408.59	6834
2410.44	6776
2412.28	6770
2414.13	6770
2415.97	6720
2417.82	6794
2419.66	6760
2421.5	6682
2423.35	6768
2425.19	6740
2427.03	6662
2428.87	6738
2430.71	6644
2432.55	6636
2434.39	6746
2436.23	6666
2438.06	6694
2439.9	6712
2441.74	6546
2443.57	6698
2445.41	6622
2447.24	6556
2449.08	6518
2450.91	6608
2452.75	6558
2454.58	6528
2456.41	6522
2458.24	6502
2460.08	6482
2461.91	6516
2463.74	6480
2465.57	6482
2467.4	6412
2469.22	6440
2471.05	6430
2472.88	6424
2474.71	6420
2476.53	6388
2478.36	6296
2480.19	6344
2482.01	6436
2483.83	6314
2485.66	6298
2487.48	6258
2489.3	6372
2491.13	6290
2492.95	6326
2494.77	6320
2496.59	6162
2498.41	6284
2500.23	6300
2502.05	6170
2503.87	6122
2505.68	6160
2507.5	6074
2509.32	6150
2511.14	6196
2512.95	6170
2514.77	6116
2516.58	6126
2518.39	6166
2520.21	6184
2522.02	6072
2523.83	6150
2525.65	5962
2527.46	6056
2529.27	6066
2531.08	5962
2532.89	5996
2534.7	5998
2536.51	6014
2538.32	5980
2540.12	5862
2541.93	5970
2543.74	5952
2545.54	5978
2547.35	5902
2549.15	5860
2550.96	5822
2552.76	5940
2554.56	5830
2556.37	5788
2558.17	5890
2559.97	5854
2561.77	5752
2563.58	5738
2565.38	5784
2567.18	5836
2568.97	5720
2570.77	5762
2572.57	5644
2574.37	5674
2576.17	5808
2577.96	5716
2579.76	5692
2581.55	5624
2583.35	5678
2585.14	5684
2586.94	5602
2588.73	5580
2590.52	5576
2592.32	5604
2594.11	5488
2595.9	5576
2597.69	5510
2599.48	5534
2601.27	5524
2603.06	5458
2604.85	5448
2606.64	5532
2608.42	5482
2610.21	5412
2612	5404
2613.78	5436
2615.57	5458
2617.36	5440
2619.14	5384
2620.92	5410
2622.71	5412
2624.49	5388
2626.27	5302
2628.05	5246
2629.84	5218
2631.62	5346
2633.4	5270
2635.18	5330
2636.96	5326
2638.74	5176
2640.51	5250
2642.29	5164
2644.07	5170
2645.85	5146
2647.62	5256
2649.4	5144
2651.17	5086
2652.95	5158
2654.72	5182
2656.5	5060
2658.27	5098
2660.04	5096
2661.81	5008
2663.58	5038
2665.35	5134
2667.13	5016
2668.9	4960
2670.66	5028
2672.43	4932
2674.2	5014
2675.97	5044
2677.74	4990
2679.5	4998
2681.27	4996
2683.04	4944
2684.8	4952
2686.57	4992
2688.33	4838
2690.09	4886
2691.86	4852
2693.62	4934
2695.38	4842
2697.15	4780
2698.91	4796
2700.67	4822
2702.43	4930
2704.19	4832
2705.95	4768
2707.7	4714
2709.46	4840
2711.22	4804
2712.98	4734
2714.73	4758
2716.49	4710
2718.25	4776
2720	4694
2721.76	4650
2723.51	4822
2725.26	4612
2727.02	4690
2728.77	4644
2730.52	4552
2732.27	4568
2734.02	4586
2735.77	4646
2737.52	4536
2739.27	4514
2741.02	4548
2742.77	4604
2744.52	4506
2746.27	4484
2748.01	4530
2749.76	4494
2751.51	4420
2753.25	4414
2755	4482
2756.74	4342
2758.48	4394
2760.23	4342
2761.97	4370
2763.71	4308
2765.45	4368
2767.19	4330
2768.94	4334
2770.68	4304
2772.42	4346
2774.16	4230
2775.89	4288
2777.63	4312
2779.37	4274
2781.11	4268
2782.84	4252
2784.58	4270
2786.32	4272
2788.05	4230
2789.79	4144
2791.52	4090
2793.25	4164
2794.99	4168
2796.72	4152
2798.45	4144
2800.18	4128
2801.92	4230
2803.65	4141
2805.38	4118
2807.11	4140
2808.84	4106
2810.57	4078
2812.29	4066
2814.02	3990
2815.75	4052
2817.47	4000
2819.2	4016
2820.93	3990
2822.65	3904
2824.38	3976
2826.1	3960
2827.82	3926
2829.55	4014
2831.27	3936
2832.99	3934
2834.71	3878
2836.44	3934
2838.16	3920
2839.88	3844
2841.6	3844
2843.32	3842
2845.03	3722
2846.75	3868
2848.47	3830
2850.19	3770
2851.9	3670
2853.62	3748
2855.34	3828
2857.05	3714
2858.77	3700
2860.48	3758
2862.19	3738
2863.91	3610
2865.62	3722
2867.33	3678
2869.04	3696
2870.76	3622
2872.47	3638
2874.18	3674
2875.89	3640
2877.6	3634
2879.31	3546
2881.01	3560
2882.72	3534
2884.43	3586
2886.14	3564
2887.84	3568
2889.55	3550
2891.25	3476
2892.96	3478
2894.66	3490
2896.37	3528
2898.07	3520
2899.77	3402
2901.48	3536
2903.18	3476
2904.88	3492
2906.58	3468
2908.28	3464
2909.98	3434
2911.68	3452
2913.38	3488
2915.08	3434
2916.78	3416
2918.47	3398
2920.17	3436
2921.87	3406
2923.56	3386
2925.26	3458
2926.95	3358
2928.65	3310
2930.34	3324
2932.04	3368
2933.73	3288
2935.42	3344
2937.11	3284
2938.81	3290
2940.5	3348
2942.19	3270
2943.88	3294
2945.57	3260
2947.26	3304
2948.95	3322
2950.64	3236
2952.32	3246
2954.01	3254
2955.7	3236
2957.38	3244
2959.07	3250
2960.75	3220
2962.44	3242
2964.12	3248
2965.81	3216
2967.49	3166
2969.17	3130
2970.86	3058
2972.54	3144
2974.22	3068
2975.9	3154
2977.58	3122
2979.26	3118
2980.94	3134
2982.62	3076
2984.3	3094
2985.98	3062
2987.66	3072
2989.33	3042
2991.01	3034
2992.69	3000
2994.36	3048
2996.04	2996
2997.71	2998
2999.39	2938