File: muestras/tallo/2/Organic_11.txt
#Acq. time (s)=	10
#Accumulations=	1
#Range (cm-¹)=	100...3000
#Windows=	3
#Autofocus=	Off
#AutoExposure=	Off
#Spike filter=	Off
#Delay time (s)=	0
#Binning=	1
#Readout mode=	Signal
#DeNoise=	Off
#ICS correction=	Off
#Dark correction=	Off
#Inst. Process=	Off
#Instrument=	LabRAM HR Evol
#Detector=	Syncerity OE
#Objective=	x100_VIS
#Grating=	600 (500nm)
#ND Filter=	3.2%
#Laser=	633nm_Edge
#Hole=	100.021
#Range=	Visible
#Project=	Omar
#Sample=	26-06-23
#Site=	2
#Title=	Organic
#Remark=
#Date=	26.06.2023 16:25
#Acquired=	26.06.2023 16:25:58
101.018	3820
103.586	3924
106.152	3882
108.717	3848
111.281	3876
113.845	3868
116.407	3904
118.969	3960
121.53	3990
124.09	3998
126.649	3986
129.207	3978
131.765	4100
134.321	4018
136.877	4000
139.432	3992
141.985	3992
144.538	4064
147.09	4108
149.641	4026
152.191	4040
154.741	4130
157.289	4094
159.837	4052
162.385	4220
164.93	4194
167.476	4172
170.019	4246
172.562	4158
175.105	4206
177.646	4158
180.188	4266
182.727	4258
185.266	4208
187.804	4172
190.342	4294
192.878	4196
195.413	4344
197.948	4314
200.481	4320
203.014	4340
205.546	4456
208.077	4372
210.608	4482
213.137	4394
215.666	4418
218.194	4412
220.721	4494
223.247	4562
225.772	4598
228.295	4594
230.819	4554
233.342	4638
235.864	4682
238.384	4656
240.904	4574
243.423	4598
245.941	4782
248.46	4688
250.975	4750
253.492	4828
256.006	4722
258.519	4738
261.033	4714
263.545	4736
266.057	4838
268.567	4802
271.076	4764
273.585	4820
276.094	4910
278.601	4766
281.107	4806
283.612	4838
286.116	4834
288.62	4896
291.123	4884
293.625	4944
296.126	4978
298.626	4938
301.126	5040
303.625	5070
306.122	5028
308.62	5218
311.114	5080
313.61	5014
316.105	5114
318.599	5114
321.09	5130
323.583	5158
326.073	5098
328.563	5118
331.053	5226
333.541	5170
336.029	5248
338.515	5258
341.001	5244
343.486	5322
345.97	5322
348.453	5252
350.936	5338
353.418	5402
355.898	5352
358.378	5310
360.858	5386
363.336	5426
365.813	5420
368.29	5548
370.766	5538
373.241	5472
375.715	5372
378.188	5370
380.66	5508
383.132	5440
385.603	5350
388.072	5518
390.541	5442
393.01	5578
395.477	5582
397.943	5646
400.409	5512
402.875	5558
405.338	5618
407.802	5598
410.263	5634
412.725	5696
415.185	5802
417.646	5772
420.104	5814
422.564	5798
425.02	5876
427.477	5822
429.933	5872
432.388	5996
434.841	6064
437.294	6014
439.748	6030
442.199	6116
444.65	6090
447.1	6068
449.549	6066
451.997	6048
454.445	6070
456.891	6150
459.337	6074
461.782	6060
464.227	6102
466.669	6102
469.112	6100
471.554	6174
473.995	6150
476.434	6228
478.874	6288
481.312	6282
483.749	6310
486.186	6170
488.622	6390
491.057	6448
493.491	6340
495.925	6392
498.357	6448
500.789	6412
503.221	6422
505.65	6562
508.079	6566
510.509	6550
512.936	6516
515.363	6564
517.789	6518
520.214	6648
522.638	6582
525.062	6616
527.485	6688
529.907	6640
532.328	6750
534.748	6648
537.168	6634
539.587	6696
542.005	6628
544.423	6748
546.838	6764
549.254	6666
551.669	6700
554.082	6802
556.496	6848
558.909	6792
561.319	6806
563.731	6886
566.14	6884
568.549	6852
570.957	6900
573.364	6882
575.771	7072
578.177	7004
580.581	7042
582.987	7098
585.39	7060
587.792	7028
590.193	7106
592.594	7144
594.996	7232
597.395	7244
599.793	7310
602.191	7202
604.588	7322
606.984	7354
609.378	7516
611.773	7518
614.167	7440
616.56	7600
618.953	7532
621.343	7634
623.734	7694
626.124	7704
628.512	7746
630.901	7786
633.289	7762
635.675	7832
638.061	7974
640.446	8018
642.831	8068
645.213	8028
647.595	8120
649.978	8172
652.359	8176
654.738	8088
657.117	8266
659.497	8256
661.875	8280
664.252	8424
666.628	8262
669.003	8338
671.378	8364
673.751	8476
676.124	8526
678.497	8574
680.868	8586
683.239	8622
685.609	8692
687.977	8572
690.346	8740
692.714	8790
695.081	8688
697.446	8778
699.812	8858
702.175	8866
704.539	8924
706.901	9018
709.264	9098
711.625	9046
713.986	9118
716.345	9234
718.705	9216
721.062	9274
723.419	9410
725.775	9390
728.132	9402
730.487	9564
732.841	9482
735.194	9658
737.546	9702
739.898	9696
742.249	9664
744.599	9734
746.949	9804
749.298	9860
751.646	9826
753.993	9926
756.34	9930
758.684	9932
761.029	9994
763.374	10112
765.716	10190
768.059	10128
770.401	10146
772.741	10238
775.082	10472
777.421	10460
779.76	10412
782.097	10534
784.434	10658
786.771	10586
789.106	10728
791.44	10674
793.775	10738
796.108	10760
798.44	10880
800.771	11060
803.102	10966
805.432	11094
807.761	11132
810.09	11238
812.417	11382
814.744	11300
817.071	11466
819.396	11562
821.721	11452
824.045	11544
826.367	11748
828.69	11922
831.012	11968
833.332	12062
835.653	12120
837.972	12288
840.29	12284
842.609	12416
844.925	12634
847.242	12558
849.557	12586
851.871	12758
854.186	12574
856.498	12762
858.81	12890
861.122	12868
863.434	12876
865.744	13100
868.053	13332
870.361	13196
872.669	13264
874.976	13456
877.282	13432
879.588	13508
881.893	13616
884.197	13568
886.5	13588
888.802	13694
891.104	13760
893.405	13636
895.706	13912
898.004	13974
900.303	14006
902.6	14182
904.898	14164
907.194	14142
909.49	14414
911.785	14284
914.08	14300
916.372	14566
918.666	14542
920.957	14584
923.248	14646
925.538	14786
927.828	14926
930.118	14868
932.406	14974
934.693	15170
936.979	15198
939.265	15236
941.55	15320
943.835	15444
946.118	15404
948.401	15548
950.682	15694
952.964	15736
955.245	15962
957.525	16168
959.803	16162
962.082	16320
964.36	16100
966.636	16332
968.913	16432
971.188	16523
973.463	16596
975.736	16780
978.009	16818
980.282	16652
982.554	16806
984.824	16836
987.095	16954
989.364	17076
991.633	17100
993.9	17166
996.167	17274
998.434	17476
1000.7	17350
1002.96	17498
1005.23	17550
1007.49	17624
1009.76	17784
1012.02	17836
1014.28	17760
1016.54	17916
1018.8	18084
1021.06	18182
1023.32	18202
1025.57	18282
1027.83	18606
1030.09	18420
1032.34	18564
1034.6	18490
1036.85	18664
1039.1	18832
1041.35	18956
1043.61	18986
1045.86	18990
1048.11	19232
1050.36	19260
1052.61	19370
1054.85	19440
1057.1	19498
1059.35	19692
1061.59	19652
1063.84	19694
1066.08	19734
1068.33	19666
1070.57	19924
1072.81	19886
1075.05	19996
1077.29	19846
1079.53	19864
1081.77	19990
1084.01	19836
1086.25	20140
1088.48	20086
1090.72	19862
1092.96	19990
1095.19	20080
1097.43	20026
1099.66	20102
1101.89	20064
1104.12	20080
1106.35	20282
1108.59	20312
1110.81	20022
1113.04	20060
1115.27	20180
1117.5	20302
1119.73	20324
1121.95	20156
1124.18	20220
1126.4	20336
1128.63	20190
1130.85	20324
1133.07	20320
1135.29	20492
1137.51	20472
1139.73	20484
1141.95	20204
1144.17	20520
1146.39	20406
1148.61	20476
1150.82	20614
1153.04	20580
1155.26	20540
1157.47	20674
1159.68	20722
1161.9	20694
1164.11	20588
1166.32	20498
1168.53	20630
1170.74	20580
1172.95	20488
1175.16	20514
1177.37	20454
1179.58	20540
1181.78	20428
1183.99	20374
1186.19	20284
1188.4	20154
1190.6	20274
1192.8	20064
1195.01	19974
1197.21	20031
1199.41	20006.2
1201.61	19806
1203.81	19821.1
1206.01	19729.3
1208.2	19828.5
1210.4	19469.4
1212.6	19636.4
1214.8	19292.9
1216.99	19412.1
1219.18	19187
1221.38	19248.5
1223.57	19166.6
1225.76	19064
1227.96	19132.9
1230.15	19019.1
1232.34	18986.4
1234.53	18797
1236.71	18856.6
1238.9	18647.6
1241.09	18607.2
1243.28	18659.3
1245.46	18519.1
1247.65	18639
1249.83	18467.8
1252.02	18489.1
1254.2	18491.7
1256.38	18393.4
1258.56	18310.3
1260.74	18228
1262.92	18124.8
1265.1	18019.5
1267.28	18047.3
1269.46	18073.3
1271.64	17991.2
1273.82	17912
1275.99	17921.8
1278.17	17782.2
1280.34	17685.2
1282.52	17576.7
1284.69	17657.4
1286.86	17452.5
1289.03	17495.2
1291.21	17360
1293.38	17270
1295.55	17309.5
1297.71	17262.4
1299.88	17162.5
1302.05	17128.7
1304.22	16997.5
1306.38	16947.3
1308.43	16802
1310.61	16674
1312.78	16654
1314.96	16602
1317.13	16580
1319.3	16406
1321.48	16308
1323.65	16140
1325.82	16072
1327.99	15992
1330.16	16098
1332.33	15834
1334.5	15744
1336.66	15694
1338.83	15650
1341	15530
1343.16	15504
1345.33	15344
1347.49	15190
1349.65	15200
1351.82	15176
1353.98	15146
1356.14	15022
1358.3	14850
1360.46	14944
1362.62	14746
1364.78	14620
1366.94	14676
1369.09	14472
1371.25	14314
1373.41	14460
1375.56	14412
1377.72	14208
1379.87	14282
1382.02	14142
1384.17	14238
1386.33	13980
1388.48	13966
1390.63	13980
1392.78	13962
1394.93	13796
1397.07	13914
1399.22	13764
1401.37	13638
1403.52	13652
1405.66	13632
1407.81	13530
1409.95	13544
1412.09	13432
1414.24	13222
1416.38	13246
1418.52	13200
1420.66	13070
1422.8	13182
1424.94	13138
1427.08	13072
1429.22	13030
1431.35	12896
1433.49	12978
1435.63	12892
1437.76	12766
1439.9	12672
1442.03	12590
1444.17	12668
1446.3	12634
1448.43	12414
1450.56	12450
1452.69	12422
1454.82	12442
1456.95	12360
1459.08	12396
1461.21	12326
1463.34	12384
1465.46	12250
1467.59	12252
1469.71	12328
1471.84	12332
1473.96	12078
1476.08	12052
1478.21	12040
1480.33	12108
1482.45	12066
1484.57	12006
1486.69	11930
1488.81	11990
1490.93	11856
1493.05	11852
1495.16	11920
1497.28	11742
1499.4	11676
1501.51	11834
1503.63	11596
1505.74	11662
1507.85	11654
1509.97	11602
1512.08	11428
1514.19	11374
1516.3	11486
1518.41	11454
1520.52	11304
1522.63	11294
1524.73	11300
1526.84	11306
1528.95	11234
1531.06	11320
1533.16	11148
1535.26	11228
1537.37	11136
1539.47	10906
1541.57	10980
1543.68	11014
1545.78	10938
1547.88	10980
1549.98	10810
1552.08	10922
1554.18	10882
1556.27	10718
1558.37	10708
1560.47	10716
1562.56	10644
1564.66	10576
1566.75	10702
1568.85	10604
1570.94	10678
1573.03	10610
1575.13	10606
1577.22	10638
1579.31	10546
1581.4	10466
1583.49	10494
1585.58	10458
1587.66	10362
1589.75	10502
1591.84	10328
1593.93	10398
1596.01	10440
1598.1	10346
1600.18	10472
1602.26	10338
1604.35	10508
1606.43	10436
1608.51	10222
1610.59	10312
1612.67	10186
1614.75	10336
1616.83	10284
1618.91	10232
1620.99	10208
1623.06	10238
1625.14	10228
1627.21	10098
1629.29	10244
1631.36	10124
1633.44	10002
1635.51	10106
1637.58	10180
1639.66	10018
1641.73	10046
1643.8	9936
1645.87	10060
1647.94	9838
1650	9918
1652.07	9902
1654.14	9874
1656.21	9892
1658.27	9922
1660.34	9864
1662.4	9858
1664.47	9682
1666.53	9728
1668.59	9628
1670.66	9660
1672.72	9666
1674.78	9602
1676.84	9636
1678.9	9704
1680.96	9546
1683.01	9594
1685.07	9550
1687.13	9446
1689.19	9450
1691.24	9460
1693.3	9364
1695.35	9362
1697.4	9484
1699.46	9412
1701.51	9310
1703.56	9218
1705.61	9360
1707.66	9406
1709.71	9246
1711.76	9194
1713.81	9262
1715.86	9122
1717.91	9118
1719.95	9144
1722	9154
1724.04	9004
1726.09	9124
1728.13	9088
1730.18	9018
1732.22	9190
1734.26	9066
1736.3	8982
1738.34	9012
1740.38	8892
1742.42	8930
1744.46	9014
1746.5	8928
1748.54	8960
1750.58	8934
1752.61	8856
1754.65	8972
1756.68	8758
1758.72	8898
1760.75	8932
1762.79	8994
1764.82	8960
1766.85	8942
1768.88	8726
1770.91	8956
1772.94	8858
1774.97	8814
1777	8698
1779.03	8778
1781.06	8888
1783.09	8790
1785.11	8824
1787.14	8686
1789.16	8742
1791.19	8710
1793.21	8768
1795.23	8722
1797.26	8844
1799.28	8634
1801.3	8744
1803.32	8656
1805.34	8620
1807.36	8706
1809.38	8606
1811.4	8524
1813.42	8538
1815.43	8642
1817.45	8672
1819.47	8538
1821.48	8480
1823.49	8536
1825.51	8486
1827.52	8366
1829.54	8432
1831.55	8482
1833.56	8548
1835.57	8378
1837.58	8376
1839.59	8420
1841.6	8348
1843.61	8292
1845.61	8384
1847.62	8288
1849.63	8322
1851.63	8246
1853.64	8260
1855.64	8196
1857.65	8260
1859.65	8246
1861.65	8246
1863.65	8276
1865.66	8144
1867.66	8294
1869.66	8132
1871.66	8228
1873.66	8268
1875.65	8186
1877.65	8110
1879.65	8154
1881.65	8158
1883.64	8084
1885.64	8052
1887.63	8078
1889.63	8068
1891.62	7938
1893.61	8002
1895.6	8020
1897.6	7978
1899.59	7996
1901.58	8018
1903.57	8122
1905.56	8060
1907.54	7982
1909.53	7888
1911.52	7934
1913.51	8044
1915.49	7932
1917.48	7954
1919.46	7908
1921.45	7904
1923.43	7898
1925.41	7920
1927.4	7884
1929.38	7934
1931.36	7954
1933.34	7766
1935.32	7806
1937.3	7926
1939.28	7826
1941.26	8036
1943.23	7782
1945.21	7798
1947.19	7820
1949.16	7728
1951.14	7736
1953.11	7738
1955.09	7730
1957.06	7652
1959.03	7768
1961	7648
1962.98	7742
1964.95	7768
1966.92	7742
1968.89	7636
1970.85	7666
1972.82	7720
1974.79	7560
1976.76	7656
1978.73	7514
1980.69	7710
1982.66	7600
1984.62	7646
1986.59	7642
1988.55	7616
1990.51	7622
1992.47	7568
1994.44	7598
1996.4	7608
1998.36	7514
2000.32	7520
2002.28	7564
2004.24	7526
2006.19	7406
2008.15	7540
2010.11	7526
2012.06	7550
2014.02	7444
2015.98	7454
2017.93	7442
2019.88	7448
2021.84	7530
2023.79	7388
2025.74	7404
2027.69	7340
2029.65	7460
2031.6	7348
2033.55	7446
2035.5	7486
2037.44	7320
2039.39	7396
2041.34	7360
2043.29	7398
2045.23	7398
2047.18	7392
2049.12	7328
2051.07	7358
2053.01	7354
2054.95	7330
2056.9	7252
2058.84	7240
2060.78	7284
2062.72	7184
2064.66	7208
2066.6	7188
2068.54	7178
2070.48	7244
2072.42	7174
2074.35	7214
2076.29	7292
2078.23	7146
2080.16	7252
2082.1	7156
2084.03	7174
2085.96	7124
2087.9	7092
2089.83	7154
2091.76	7096
2093.69	7176
2095.62	7080
2097.55	7080
2099.48	7036
2101.41	7170
2103.34	7002
2105.27	7056
2107.2	6948
2109.12	7042
2111.05	7078
2112.98	7098
2114.9	7050
2116.82	7038
2118.75	6962
2120.67	7016
2122.59	7012
2124.52	6964
2126.44	6864
2128.36	6984
2130.28	7006
2132.2	7012
2134.12	7036
2136.04	6884
2137.95	6928
2139.87	6946
2141.79	6880
2143.7	6954
2145.62	6913.04
2147.53	6910.73
2149.45	6856.14
2151.36	6811.76
2153.28	6820.83
2155.19	6768.56
2157.1	6732.97
2159.01	6710
2160.92	6768.83
2162.83	6848.72
2164.74	6716
2166.65	6777.18
2168.56	6690.46
2170.47	6694.05
2172.38	6636.05
2174.28	6686.31
2176.19	6590.81
2178.09	6635.53
2180	6565.04
2181.9	6600.54
2183.81	6588.01
2185.71	6598.54
2187.61	6609.37
2189.52	6501.47
2191.42	6592.22
2193.32	6593.27
2195.22	6508.86
2197.12	6540.61
2199.02	6547.63
2200.92	6466.02
2202.82	6529.67
2204.71	6547.17
2206.61	6510.06
2208.51	6524.23
2210.4	6530.49
2212.3	6528.09
2214.19	6512.3
2216.09	6506.12
2217.98	6469.16
2219.87	6489.1
2221.77	6542.87
2223.66	6448.95
2225.55	6520.19
2227.44	6477.44
2229.33	6460.56
2231.22	6513.57
2233.11	6502.03
2235	6484.46
2236.88	6521.25
2238.77	6517.24
2240.66	6499.04
2242.07	6494
2243.97	6494
2245.87	6444
2247.76	6470
2249.65	6496
2251.55	6484
2253.44	6458
2255.33	6472
2257.22	6474
2259.12	6394
2261.01	6396
2262.9	6418
2264.78	6396
2266.67	6474
2268.56	6306
2270.45	6388
2272.34	6420
2274.22	6496
2276.11	6344
2277.99	6252
2279.88	6318
2281.76	6330
2283.65	6354
2285.53	6310
2287.41	6320
2289.3	6336
2291.18	6228
2293.06	6258
2294.94	6250
2296.82	6340
2298.7	6166
2300.58	6242
2302.46	6242
2304.33	6248
2306.21	6200
2308.09	6238
2309.96	6198
2311.84	6194
2313.71	6212
2315.59	6218
2317.46	6240
2319.33	6134
2321.21	6098
2323.08	6190
2324.95	6182
2326.82	6194
2328.69	6116
2330.56	6048
2332.43	6134
2334.3	6070
2336.17	6192
2338.03	6068
2339.9	6126
2341.77	6030
2343.63	6154
2345.5	6030
2347.36	6128
2349.23	5998
2351.09	6018
2352.95	6112
2354.82	6056
2356.68	6118
2358.54	5998
2360.4	6122
2362.26	6128
2364.12	6016
2365.98	6046
2367.84	5968
2369.7	5956
2371.56	6078
2373.41	5936
2375.27	5922
2377.12	5944
2378.98	6022
2380.84	6006
2382.69	5864
2384.54	5802
2386.4	5882
2388.25	5960
2390.1	5888
2391.95	5866
2393.8	5944
2395.65	5834
2397.5	5880
2399.35	5918
2401.2	5792
2403.05	5868
2404.9	5838
2406.75	5808
2408.59	5702
2410.44	5824
2412.28	5810
2414.13	5708
2415.97	5852
2417.82	5728
2419.66	5698
2421.5	5790
2423.35	5740
2425.19	5766
2427.03	5744
2428.87	5612
2430.71	5740
2432.55	5730
2434.39	5690
2436.23	5642
2438.06	5662
2439.9	5632
2441.74	5674
2443.57	5686
2445.41	5570
2447.24	5602
2449.08	5570
2450.91	5560
2452.75	5618
2454.58	5598
2456.41	5560
2458.24	5560
2460.08	5542
2461.91	5500
2463.74	5518
2465.57	5524
2467.4	5430
2469.22	5502
2471.05	5524
2472.88	5512
2474.71	5438
2476.53	5482
2478.36	5482
2480.19	5406
2482.01	5446
2483.83	5358
2485.66	5382
2487.48	5360
2489.3	5388
2491.13	5378
2492.95	5354
2494.77	5328
2496.59	5426
2498.41	5476
2500.23	5370
2502.05	5322
2503.87	5274
2505.68	5266
2507.5	5310
2509.32	5334
2511.14	5254
2512.95	5282
2514.77	5260
2516.58	5148
2518.39	5208
2520.21	5164
2522.02	5150
2523.83	5212
2525.65	5070
2527.46	5168
2529.27	5130
2531.08	5026
2532.89	5140
2534.7	5188
2536.51	5168
2538.32	5068
2540.12	4984
2541.93	5086
2543.74	5074
2545.54	4944
2547.35	5016
2549.15	4910
2550.96	5104
2552.76	5008
2554.56	4932
2556.37	4930
2558.17	4880
2559.97	4832
2561.77	4912
2563.58	4930
2565.38	4902
2567.18	4856
2568.97	4874
2570.77	4786
2572.57	4886
2574.37	4872
2576.17	4898
2577.96	4810
2579.76	4810
2581.55	4800
2583.35	4868
2585.14	4784
2586.94	4802
2588.73	4778
2590.52	4732
2592.32	4736
2594.11	4732
2595.9	4640
2597.69	4774
2599.48	4638
2601.27	4696
2603.06	4694
2604.85	4688
2606.64	4596
2608.42	4718
2610.21	4616
2612	4664
2613.78	4588
2615.57	4612
2617.36	4598
2619.14	4550
2620.92	4522
2622.71	4546
2624.49	4534
2626.27	4568
2628.05	4470
2629.84	4552
2631.62	4518
2633.4	4444
2635.18	4474
2636.96	4486
2638.74	4534
2640.51	4458
2642.29	4438
2644.07	4480
2645.85	4326
2647.62	4308
2649.4	4342
2651.17	4362
2652.95	4360
2654.72	4366
2656.5	4376
2658.27	4290
2660.04	4304
2661.81	4376
2663.58	4292
2665.35	4332
2667.13	4276
2668.9	4282
2670.66	4282
2672.43	4292
2674.2	4272
2675.97	4240
2677.74	4168
2679.5	4292
2681.27	4302
2683.04	4188
2684.8	4146
2686.57	4220
2688.33	4182
2690.09	4228
2691.86	4126
2693.62	4096
2695.38	4152
2697.15	4086
2698.91	4124
2700.67	4114
2702.43	4106
2704.19	4104
2705.95	4044
2707.7	4110
2709.46	4044
2711.22	4108
2712.98	4052
2714.73	3984
2716.49	4010
2718.25	3988
2720	3996
2721.76	3934
2723.51	3942
2725.26	3956
2727.02	3976
2728.77	3938
2730.52	3898
2732.27	3890
2734.02	3906
2735.77	3940
2737.52	3972
2739.27	3816
2741.02	3912
2742.77	3856
2744.52	3778
2746.27	3818
2748.01	3796
2749.76	3804
2751.51	3836
2753.25	3790
2755	3756
2756.74	3730
2758.48	3688
2760.23	3716
2761.97	3750
2763.71	3686
2765.45	3626
2767.19	3712
2768.94	3672
2770.68	3630
2772.42	3664
2774.16	3682
2775.89	3584
2777.63	3690
2779.37	3600
2781.11	3638
2782.84	3678
2784.58	3580
2786.32	3588
2788.05	3620
2789.79	3644
2791.52	3524
2793.25	3578
2794.99	3534
2796.72	3524
2798.45	3510
2800.18	3592
2801.92	3484
2803.65	3501
2805.38	3566
2807.11	3468
2808.84	3474
2810.57	3442
2812.29	3444
2814.02	3480
2815.75	3386
2817.47	3420
2819.2	3414
2820.93	3346
2822.65	3388
2824.38	3386
2826.1	3414
2827.82	3392
2829.55	3318
2831.27	3400
2832.99	3342
2834.71	3262
2836.44	3308
2838.16	3334
2839.88	3292
2841.6	3288
2843.32	3208
2845.03	3256
2846.75	3234
2848.47	3240
2850.19	3288
2851.9	3212
2853.62	3234
2855.34	3142
2857.05	3192
2858.77	3164
2860.48	3188
2862.19	3130
2863.91	3136
2865.62	3118
2867.33	3184
2869.04	3120
2870.76	3084
2872.47	3132
2874.18	3142
2875.89	3140
2877.6	3052
2879.31	3028
2881.01	3052
2882.72	3042
2884.43	3004
2886.14	3026
2887.84	2990
2889.55	3084
2891.25	3002
2892.96	3000
2894.66	3002
2896.37	2990
2898.07	2962
2899.77	2986
2901.48	2958
2903.18	2958
2904.88	2958
2906.58	2918
2908.28	2922
2909.98	3018
2911.68	2868
2913.38	2956
2915.08	2922
2916.78	2964
2918.47	2906
2920.17	2914
2921.87	2872
2923.56	2874
2925.26	2916
2926.95	2922
2928.65	2844
2930.34	2896
2932.04	2886
2933.73	2754
2935.42	2868
2937.11	2846
2938.81	2856
2940.5	2832
2942.19	2774
2943.88	2810
2945.57	2760
2947.26	2720
2948.95	2796
2950.64	2788
2952.32	2744
2954.01	2740
2955.7	2744
2957.38	2758
2959.07	2744
2960.75	2782
2962.44	2774
2964.12	2768
2965.81	2786
2967.49	2720
2969.17	2768
2970.86	2672
2972.54	2716
2974.22	2620
2975.9	2686
2977.58	2640
2979.26	2610
2980.94	2632
2982.62	2636
2984.3	2692
2985.98	2678
2987.66	2576
2989.33	2588
2991.01	2588
2992.69	2530
2994.36	2584
2996.04	2636
2997.71	2586
2999.39	2540