File: muestras/tallo/2/Organic_09.txt
#Acq. time (s)=	10
#Accumulations=	1
#Range (cm-¹)=	100...3000
#Windows=	3
#Autofocus=	Off
#AutoExposure=	Off
#Spike filter=	Off
#Delay time (s)=	0
#Binning=	1
#Readout mode=	Signal
#DeNoise=	Off
#ICS correction=	Off
#Dark correction=	Off
#Inst. Process=	Off
#Instrument=	LabRAM HR Evol
#Detector=	Syncerity OE
#Objective=	x100_VIS
#Grating=	600 (500nm)
#ND Filter=	3.2%
#Laser=	633nm_Edge
#Hole=	100.021
#Range=	Visible
#Project=	Omar
#Sample=	26-06-23
#Site=	2
#Title=	Organic
#Remark=
#Date=	26.06.2023 16:23
#Acquired=	26.06.2023 16:23:43
101.018	3968
103.586	3938
106.152	3922
108.717	3978
111.281	3980
113.845	3956
116.407	3978
118.969	4036
121.53	4046
124.09	3994
126.649	4004
129.207	3970
131.765	4118
134.321	4074
136.877	4178
139.432	4122
141.985	4162
144.538	4106
147.09	4154
149.641	4180
152.191	4158
154.741	4188
157.289	4182
159.837	4136
162.385	4202
164.93	4208
167.476	4234
170.019	4166
172.562	4240
175.105	4250
177.646	4236
180.188	4380
182.727	4258
185.266	4326
187.804	4288
190.342	4304
192.878	4318
195.413	4416
197.948	4372
200.481	4414
203.014	4526
205.546	4464
208.077	4502
210.608	4472
213.137	4504
215.666	4502
218.194	4574
220.721	4568
223.247	4624
225.772	4588
228.295	4598
230.819	4674
233.342	4660
235.864	4628
238.384	4602
240.904	4772
243.423	4786
245.941	4804
248.46	4802
250.975	4826
253.492	4778
256.006	4736
258.519	4830
261.033	4778
263.545	4818
266.057	4846
268.567	4758
271.076	4858
273.585	4868
276.094	4772
278.601	4914
281.107	4896
283.612	4906
286.116	4810
288.62	4960
291.123	4964
293.625	5040
296.126	4998
298.626	5070
301.126	5044
303.625	5066
306.122	5170
308.62	5126
311.114	5206
313.61	5086
316.105	5118
318.599	5218
321.09	5262
323.583	5296
326.073	5120
328.563	5248
331.053	5360
333.541	5234
336.029	5346
338.515	5336
341.001	5294
343.486	5386
345.97	5380
348.453	5414
350.936	5380
353.418	5398
355.898	5438
358.378	5534
360.858	5454
363.336	5546
365.813	5526
368.29	5504
370.766	5570
373.241	5494
375.715	5624
378.188	5502
380.66	5562
383.132	5558
385.603	5602
388.072	5602
390.541	5508
393.01	5654
395.477	5576
397.943	5688
400.409	5798
402.875	5652
405.338	5706
407.802	5792
410.263	5734
412.725	5814
415.185	5856
417.646	5816
420.104	5884
422.564	6030
425.02	5922
427.477	6052
429.933	6108
432.388	6070
434.841	6228
437.294	6106
439.748	6186
442.199	6108
444.65	6186
447.1	6202
449.549	6136
451.997	6194
454.445	6124
456.891	6228
459.337	6244
461.782	6254
464.227	6170
466.669	6238
469.112	6266
471.554	6374
473.995	6382
476.434	6370
478.874	6392
481.312	6316
483.749	6406
486.186	6432
488.622	6392
491.057	6494
493.491	6478
495.925	6512
498.357	6692
500.789	6624
503.221	6718
505.65	6628
508.079	6706
510.509	6618
512.936	6708
515.363	6676
517.789	6756
520.214	6758
522.638	6794
525.062	6776
527.485	6734
529.907	6778
532.328	6724
534.748	6786
537.168	6862
539.587	6780
542.005	6776
544.423	6878
546.838	6816
549.254	6882
551.669	6888
554.082	6852
556.496	7016
558.909	6908
561.319	7002
563.731	7008
566.14	6946
568.549	7112
570.957	7040
573.364	7188
575.771	7112
578.177	7290
580.581	7206
582.987	7276
585.39	7348
587.792	7226
590.193	7338
592.594	7316
594.996	7338
597.395	7520
599.793	7414
602.191	7564
604.588	7532
606.984	7556
609.378	7598
611.773	7616
614.167	7706
616.56	7708
618.953	7814
621.343	7736
623.734	7876
626.124	7868
628.512	8018
630.901	8062
633.289	7998
635.675	8064
638.061	8022
640.446	8124
642.831	8272
645.213	8250
647.595	8290
649.978	8392
652.359	8322
654.738	8344
657.117	8342
659.497	8430
661.875	8532
664.252	8464
666.628	8524
669.003	8662
671.378	8614
673.751	8606
676.124	8658
678.497	8800
680.868	8838
683.239	8744
685.609	8820
687.977	8950
690.346	8860
692.714	9042
695.081	8994
697.446	9090
699.812	8974
702.175	9138
704.539	9182
706.901	9246
709.264	9424
711.625	9306
713.986	9382
716.345	9438
718.705	9448
721.062	9492
723.419	9544
725.775	9756
728.132	9674
730.487	9746
732.841	9828
735.194	9774
737.546	10002
739.898	10010
742.249	10074
744.599	10134
746.949	9956
749.298	10060
751.646	10104
753.993	10260
756.34	10348
758.684	10340
761.029	10302
763.374	10488
765.716	10558
768.059	10496
770.401	10732
772.741	10718
775.082	10676
777.421	10636
779.76	10824
782.097	10880
784.434	10910
786.771	10956
789.106	11012
791.44	11118
793.775	11086
796.108	11188
798.44	11360
800.771	11246
803.102	11372
805.432	11448
807.761	11606
810.09	11600
812.417	11824
814.744	11826
817.071	11858
819.396	12012
821.721	11940
824.045	12106
826.367	12176
828.69	12320
831.012	12478
833.332	12562
835.653	12498
837.972	12606
840.29	12678
842.609	12800
844.925	12748
847.242	12920
849.557	12788
851.871	13052
854.186	13146
856.498	13300
858.81	13396
861.122	13416
863.434	13484
865.744	13532
868.053	13758
870.361	13650
872.669	13574
874.976	13846
877.282	13906
879.588	13956
881.893	13942
884.197	14252
886.5	14104
888.802	14206
891.104	14398
893.405	14220
895.706	14416
898.004	14442
900.303	14554
902.6	14652
904.898	14704
907.194	14546
909.49	14676
911.785	14812
914.08	14906
916.372	14908
918.666	14864
920.957	15014
923.248	15240
925.538	15392
927.828	15312
930.118	15600
932.406	15494
934.693	15718
936.979	15790
939.265	15960
941.55	15952
943.835	16078
946.118	16132
948.401	16246
950.682	16268
952.964	16398
955.245	16752
957.525	16684
959.803	16742
962.082	16854
964.36	16978
966.636	17014
968.913	17030
971.188	17230
973.463	17454
975.736	17380
978.009	17370
980.282	17560
982.554	17560
984.824	17514
987.095	17672
989.364	17700
991.633	17830
993.9	17944
996.167	17992
998.434	18100
1000.7	18094
1002.96	18210
1005.23	18218
1007.49	18330
1009.76	18416
1012.02	18478
1014.28	18680
1016.54	18728
1018.8	18696
1021.06	18880
1023.32	19104
1025.57	19140
1027.83	19074
1030.09	19136
1032.34	19204
1034.6	19218
1036.85	19626
1039.1	19626
1041.35	19668
1043.61	19888
1045.86	19834
1048.11	20302
1050.36	20082
1052.61	20092
1054.85	20256
1057.1	20382
1059.35	20496
1061.59	20562
1063.84	20426
1066.08	20542
1068.33	20750
1070.57	20606
1072.81	20938
1075.05	20884
1077.29	20650
1079.53	20814
1081.77	20734
1084.01	20954
1086.25	20912
1088.48	20846
1090.72	20742
1092.96	20786
1095.19	20770
1097.43	20782
1099.66	20678
1101.89	20734
1104.12	21002
1106.35	20968
1108.59	20918
1110.81	21086
1113.04	21024
1115.27	21184
1117.5	20958
1119.73	21140
1121.95	21034
1124.18	21006
1126.4	21072
1128.63	20938
1130.85	21162
1133.07	21138
1135.29	21278
1137.51	21358
1139.73	21230
1141.95	21352
1144.17	21344
1146.39	21484
1148.61	21302
1150.82	21554
1153.04	21342
1155.26	21458
1157.47	21544
1159.68	21356
1161.9	21474
1164.11	21424
1166.32	21526
1168.53	21594
1170.74	21498
1172.95	21474
1175.16	21462
1177.37	21422
1179.58	21354
1181.78	21346
1183.99	21332
1186.19	21072
1188.4	21128
1190.6	20840
1192.8	20862
1195.01	20934
1197.21	20617.2
1199.41	20839
1201.61	20669.6
1203.81	20633
1206.01	20448.2
1208.2	20538.2
1210.4	20199.8
1212.6	20308.2
1214.8	20369.6
1216.99	20240.5
1219.18	20168.7
1221.38	19948.1
1223.57	20065.8
1225.76	19887.5
1227.96	19813.7
1230.15	19747.2
1232.34	19792.2
1234.53	19576.6
1236.71	19684.6
1238.9	19483.7
1241.09	19543.1
1243.28	19438.3
1245.46	19318.8
1247.65	19354
1249.83	19388
1252.02	19200.5
1254.2	19278.2
1256.38	19090.1
1258.56	18937.6
1260.74	19094.8
1262.92	18889
1265.1	18846.3
1267.28	18846.3
1269.46	18847.9
1271.64	18688.1
1273.82	18701.3
1275.99	18561.7
1278.17	18439.8
1280.34	18425.5
1282.52	18429.6
1284.69	18234
1286.86	18268.9
1289.03	18193.4
1291.21	17993.3
1293.38	18006.8
1295.55	17988.4
1297.71	17836.4
1299.88	17716.5
1302.05	17828.3
1304.22	17693.4
1306.38	17666.1
1308.43	17536
1310.61	17372
1312.78	17446
1314.96	17318
1317.13	17090
1319.3	17076
1321.48	17012
1323.65	16976
1325.82	16732
1327.99	16684
1330.16	16612
1332.33	16518
1334.5	16348
1336.66	16264
1338.83	16372
1341	16190
1343.16	16078
1345.33	15892
1347.49	15842
1349.65	15888
1351.82	15640
1353.98	15678
1356.14	15578
1358.3	15444
1360.46	15288
1362.62	15364
1364.78	15160
1366.94	15100
1369.09	15020
1371.25	15006
1373.41	15006
1375.56	14898
1377.72	14882
1379.87	14790
1382.02	14754
1384.17	14724
1386.33	14590
1388.48	14566
1390.63	14366
1392.78	14422
1394.93	14190
1397.07	14376
1399.22	14138
1401.37	14208
1403.52	14204
1405.66	13996
1407.81	14034
1409.95	13814
1412.09	13946
1414.24	13888
1416.38	13664
1418.52	13676
1420.66	13744
1422.8	13706
1424.94	13436
1427.08	13442
1429.22	13438
1431.35	13346
1433.49	13460
1435.63	13432
1437.76	13172
1439.9	13228
1442.03	13164
1444.17	13138
1446.3	13088
1448.43	12956
1450.56	12930
1452.69	12986
1454.82	12880
1456.95	12856
1459.08	12834
1461.21	12756
1463.34	12810
1465.46	12482
1467.59	12638
1469.71	12642
1471.84	12584
1473.96	12522
1476.08	12486
1478.21	12506
1480.33	12456
1482.45	12398
1484.57	12416
1486.69	12338
1488.81	12276
1490.93	12292
1493.05	12292
1495.16	12144
1497.28	12248
1499.4	12128
1501.51	12078
1503.63	12088
1505.74	12096
1507.85	12002
1509.97	11986
1512.08	11786
1514.19	11846
1516.3	11892
1518.41	11882
1520.52	11750
1522.63	11754
1524.73	11594
1526.84	11654
1528.95	11604
1531.06	11526
1533.16	11526
1535.26	11456
1537.37	11378
1539.47	11406
1541.57	11314
1543.68	11246
1545.78	11278
1547.88	11238
1549.98	11260
1552.08	11082
1554.18	11008
1556.27	11140
1558.37	11022
1560.47	10994
1562.56	11034
1564.66	11076
1566.75	10946
1568.85	10852
1570.94	10898
1573.03	10854
1575.13	10856
1577.22	10760
1579.31	10788
1581.4	10786
1583.49	10854
1585.58	10682
1587.66	10478
1589.75	10808
1591.84	10650
1593.93	10738
1596.01	10656
1598.1	10682
1600.18	10712
1602.26	10640
1604.35	10666
1606.43	10604
1608.51	10634
1610.59	10528
1612.67	10454
1614.75	10542
1616.83	10526
1618.91	10538
1620.99	10472
1623.06	10608
1625.14	10498
1627.21	10546
1629.29	10562
1631.36	10420
1633.44	10458
1635.51	10366
1637.58	10196
1639.66	10304
1641.73	10466
1643.8	10224
1645.87	10212
1647.94	10230
1650	10252
1652.07	10164
1654.14	10192
1656.21	10108
1658.27	10042
1660.34	10014
1662.4	10012
1664.47	10038
1666.53	9896
1668.59	9954
1670.66	9938
1672.72	10012
1674.78	9960
1676.84	9836
1678.9	9846
1680.96	9820
1683.01	9778
1685.07	9658
1687.13	9746
1689.19	9752
1691.24	9764
1693.3	9648
1695.35	9636
1697.4	9654
1699.46	9506
1701.51	9708
1703.56	9534
1705.61	9590
1707.66	9588
1709.71	9448
1711.76	9510
1713.81	9406
1715.86	9474
1717.91	9512
1719.95	9416
1722	9476
1724.04	9296
1726.09	9404
1728.13	9254
1730.18	9330
1732.22	9220
1734.26	9288
1736.3	9174
1738.34	9280
1740.38	9216
1742.42	9250
1744.46	9226
1746.5	9294
1748.54	9282
1750.58	9200
1752.61	9332
1754.65	9152
1756.68	9078
1758.72	9160
1760.75	9114
1762.79	9154
1764.82	9126
1766.85	9134
1768.88	9190
1770.91	9078
1772.94	9086
1774.97	9214
1777	9122
1779.03	9094
1781.06	9014
1783.09	9054
1785.11	9000
1787.14	8914
1789.16	8960
1791.19	8864
1793.21	9002
1795.23	8946
1797.26	9080
1799.28	8848
1801.3	8790
1803.32	8904
1805.34	8786
1807.36	8954
1809.38	8902
1811.4	8770
1813.42	8888
1815.43	8794
1817.45	8758
1819.47	8794
1821.48	8816
1823.49	8782
1825.51	8738
1827.52	8754
1829.54	8674
1831.55	8592
1833.56	8676
1835.57	8650
1837.58	8578
1839.59	8590
1841.6	8586
1843.61	8516
1845.61	8554
1847.62	8594
1849.63	8512
1851.63	8480
1853.64	8414
1855.64	8492
1857.65	8556
1859.65	8270
1861.65	8520
1863.65	8348
1865.66	8436
1867.66	8396
1869.66	8446
1871.66	8514
1873.66	8344
1875.65	8324
1877.65	8328
1879.65	8246
1881.65	8444
1883.64	8340
1885.64	8370
1887.63	8290
1889.63	8272
1891.62	8366
1893.61	8168
1895.6	8378
1897.6	8172
1899.59	8214
1901.58	8144
1903.57	8202
1905.56	8376
1907.54	8160
1909.53	8182
1911.52	8258
1913.51	8266
1915.49	8172
1917.48	8150
1919.46	8248
1921.45	8104
1923.43	8076
1925.41	8214
1927.4	8100
1929.38	8016
1931.36	8230
1933.34	8160
1935.32	8112
1937.3	8104
1939.28	8058
1941.26	8072
1943.23	7994
1945.21	8092
1947.19	7976
1949.16	8118
1951.14	8118
1953.11	7988
1955.09	7906
1957.06	7958
1959.03	8050
1961	7952
1962.98	7914
1964.95	7970
1966.92	7928
1968.89	7944
1970.85	8082
1972.82	7966
1974.79	7940
1976.76	7936
1978.73	7874
1980.69	7816
1982.66	7858
1984.62	7912
1986.59	7786
1988.55	7996
1990.51	7896
1992.47	7790
1994.44	7744
1996.4	7782
1998.36	7772
2000.32	7764
2002.28	7680
2004.24	7752
2006.19	7614
2008.15	7750
2010.11	7600
2012.06	7654
2014.02	7834
2015.98	7764
2017.93	7662
2019.88	7702
2021.84	7640
2023.79	7662
2025.74	7532
2027.69	7598
2029.65	7648
2031.6	7532
2033.55	7538
2035.5	7562
2037.44	7590
2039.39	7560
2041.34	7580
2043.29	7644
2045.23	7480
2047.18	7542
2049.12	7460
2051.07	7378
2053.01	7510
2054.95	7580
2056.9	7468
2058.84	7534
2060.78	7364
2062.72	7442
2064.66	7474
2066.6	7430
2068.54	7504
2070.48	7538
2072.42	7318
2074.35	7400
2076.29	7328
2078.23	7274
2080.16	7396
2082.1	7442
2084.03	7358
2085.96	7366
2087.9	7418
2089.83	7332
2091.76	7364
2093.69	7408
2095.62	7242
2097.55	7252
2099.48	7370
2101.41	7294
2103.34	7232
2105.27	7266
2107.2	7112
2109.12	7240
2111.05	7218
2112.98	7216
2114.9	7248
2116.82	7154
2118.75	7198
2120.67	7104
2122.59	7030
2124.52	7156
2126.44	7142
2128.36	7202
2130.28	7236
2132.2	7090
2134.12	7108
2136.04	7084
2137.95	7142
2139.87	7042
2141.79	7118
2143.7	7038
2145.62	7079.52
2147.53	6990.87
2149.45	7044.56
2151.36	7079.92
2153.28	6993.16
2155.19	6993.86
2157.1	6958.71
2159.01	6945.62
2160.92	6915.61
2162.83	6905.7
2164.74	6944.38
2166.65	6905.38
2168.56	6946.91
2170.47	6901.54
2172.38	6911.87
2174.28	6829.06
2176.19	6840.09
2178.09	6817.15
2180	6787.12
2181.9	6835.61
2183.81	6827.57
2185.71	6715.08
2187.61	6723.14
2189.52	6790.75
2191.42	6741.31
2193.32	6762.93
2195.22	6751.28
2197.12	6771.2
2199.02	6679.28
2200.92	6668.39
2202.82	6744.62
2204.71	6738.74
2206.61	6729.37
2208.51	6709.23
2210.4	6694.66
2212.3	6647.35
2214.19	6707.92
2216.09	6715.31
2217.98	6705.14
2219.87	6677.14
2221.77	6696.76
2223.66	6697.06
2225.55	6755.76
2227.44	6662.66
2229.33	6636.28
2231.22	6657.96
2233.11	6674.52
2235	6624.4
2236.88	6682.3
2238.77	6665.84
2240.66	6628.33
2242.07	6652
2243.97	6678
2245.87	6584
2247.76	6714
2249.65	6724
2251.55	6586
2253.44	6634
2255.33	6652
2257.22	6590
2259.12	6604
2261.01	6720
2262.9	6654
2264.78	6560
2266.67	6624
2268.56	6710
2270.45	6578
2272.34	6606
2274.22	6604
2276.11	6606
2277.99	6614
2279.88	6486
2281.76	6574
2283.65	6596
2285.53	6592
2287.41	6508
2289.3	6468
2291.18	6500
2293.06	6526
2294.94	6522
2296.82	6444
2298.7	6440
2300.58	6476
2302.46	6500
2304.33	6440
2306.21	6364
2308.09	6400
2309.96	6464
2311.84	6366
2313.71	6406
2315.59	6342
2317.46	6408
2319.33	6394
2321.21	6380
2323.08	6384
2324.95	6322
2326.82	6370
2328.69	6300
2330.56	6376
2332.43	6344
2334.3	6262
2336.17	6264
2338.03	6294
2339.9	6382
2341.77	6316
2343.63	6312
2345.5	6410
2347.36	6294
2349.23	6204
2351.09	6270
2352.95	6254
2354.82	6236
2356.68	6206
2358.54	6256
2360.4	6108
2362.26	6250
2364.12	6160
2365.98	6212
2367.84	6218
2369.7	6164
2371.56	6146
2373.41	6156
2375.27	6186
2377.12	6124
2378.98	6186
2380.84	6102
2382.69	6058
2384.54	6054
2386.4	6030
2388.25	6024
2390.1	6058
2391.95	6046
2393.8	5974
2395.65	6142
2397.5	6106
2399.35	5878
2401.2	5986
2403.05	5982
2404.9	6036
2406.75	5922
2408.59	5950
2410.44	5934
2412.28	5926
2414.13	5892
2415.97	5916
2417.82	6012
2419.66	5866
2421.5	5868
2423.35	5806
2425.19	5922
2427.03	5882
2428.87	5902
2430.71	5898
2432.55	5904
2434.39	5878
2436.23	5756
2438.06	5926
2439.9	5834
2441.74	5804
2443.57	5766
2445.41	5736
2447.24	5814
2449.08	5648
2450.91	5756
2452.75	5774
2454.58	5758
2456.41	5664
2458.24	5676
2460.08	5838
2461.91	5666
2463.74	5720
2465.57	5720
2467.4	5674
2469.22	5794
2471.05	5818
2472.88	5674
2474.71	5556
2476.53	5584
2478.36	5618
2480.19	5604
2482.01	5584
2483.83	5548
2485.66	5640
2487.48	5546
2489.3	5590
2491.13	5548
2492.95	5410
2494.77	5474
2496.59	5490
2498.41	5538
2500.23	5500
2502.05	5554
2503.87	5420
2505.68	5484
2507.5	5442
2509.32	5366
2511.14	5338
2512.95	5532
2514.77	5350
2516.58	5398
2518.39	5336
2520.21	5340
2522.02	5360
2523.83	5324
2525.65	5358
2527.46	5318
2529.27	5304
2531.08	5262
2532.89	5330
2534.7	5284
2536.51	5198
2538.32	5316
2540.12	5206
2541.93	5198
2543.74	5254
2545.54	5256
2547.35	5230
2549.15	5122
2550.96	5110
2552.76	5032
2554.56	5080
2556.37	5136
2558.17	5088
2559.97	5112
2561.77	5082
2563.58	5106
2565.38	5058
2567.18	5124
2568.97	5060
2570.77	5096
2572.57	4978
2574.37	5068
2576.17	4970
2577.96	5002
2579.76	5000
2581.55	5004
2583.35	4986
2585.14	4906
2586.94	4922
2588.73	4972
2590.52	4896
2592.32	4936
2594.11	4974
2595.9	4906
2597.69	4932
2599.48	4904
2601.27	4864
2603.06	4768
2604.85	4848
2606.64	4764
2608.42	4820
2610.21	4732
2612	4760
2613.78	4746
2615.57	4704
2617.36	4738
2619.14	4736
2620.92	4668
2622.71	4696
2624.49	4670
2626.27	4716
2628.05	4684
2629.84	4692
2631.62	4712
2633.4	4670
2635.18	4562
2636.96	4576
2638.74	4648
2640.51	4654
2642.29	4494
2644.07	4608
2645.85	4486
2647.62	4478
2649.4	4484
2651.17	4476
2652.95	4508
2654.72	4518
2656.5	4418
2658.27	4486
2660.04	4454
2661.81	4440
2663.58	4424
2665.35	4428
2667.13	4480
2668.9	4394
2670.66	4394
2672.43	4410
2674.2	4386
2675.97	4380
2677.74	4444
2679.5	4404
2681.27	4380
2683.04	4380
2684.8	4268
2686.57	4272
2688.33	4296
2690.09	4292
2691.86	4326
2693.62	4226
2695.38	4188
2697.15	4208
2698.91	4264
2700.67	4230
2702.43	4220
2704.19	4144
2705.95	4144
2707.7	4136
2709.46	4180
2711.22	4188
2712.98	4144
2714.73	4126
2716.49	4108
2718.25	4082
2720	4028
2721.76	4086
2723.51	4010
2725.26	4086
2727.02	4078
2728.77	3990
2730.52	4068
2732.27	4032
2734.02	4006
2735.77	4054
2737.52	3974
2739.27	3946
2741.02	3930
2742.77	3978
2744.52	3954
2746.27	3930
2748.01	3958
2749.76	3872
2751.51	3890
2753.25	3948
2755	3864
2756.74	3886
2758.48	3806
2760.23	3918
2761.97	3828
2763.71	3798
2765.45	3828
2767.19	3844
2768.94	3828
2770.68	3772
2772.42	3774
2774.16	3760
2775.89	3742
2777.63	3686
2779.37	3662
2781.11	3700
2782.84	3742
2784.58	3766
2786.32	3770
2788.05	3676
2789.79	3678
2791.52	3732
2793.25	3726
2794.99	3636
2796.72	3612
2798.45	3658
2800.18	3618
2801.92	3646
2803.65	3590
2805.38	3590
2807.11	3546
2808.84	3512
2810.57	3580
2812.29	3534
2814.02	3582
2815.75	3520
2817.47	3500
2819.2	3450
2820.93	3514
2822.65	3530
2824.38	3464
2826.1	3464
2827.82	3456
2829.55	3410
2831.27	3406
2832.99	3454
2834.71	3382
2836.44	3406
2838.16	3452
2839.88	3396
2841.6	3406
2843.32	3276
2845.03	3328
2846.75	3310
2848.47	3288
2850.19	3348
2851.9	3288
2853.62	3376
2855.34	3306
2857.05	3244
2858.77	3338
2860.48	3254
2862.19	3184
2863.91	3200
2865.62	3198
2867.33	3236
2869.04	3176
2870.76	3276
2872.47	3248
2874.18	3194
2875.89	3148
2877.6	3192
2879.31	3162
2881.01	3146
2882.72	3132
2884.43	3122
2886.14	3112
2887.84	3126
2889.55	3142
2891.25	3124
2892.96	3156
2894.66	3108
2896.37	3038
2898.07	3098
2899.77	3066
2901.48	3088
2903.18	3016
2904.88	3016
2906.58	3034
2908.28	3016
2909.98	3058
2911.68	2996
2913.38	3046
2915.08	3072
2916.78	3002
2918.47	3030
2920.17	3054
2921.87	3042
2923.56	2966
2925.26	2904
2926.95	3010
2928.65	2910
2930.34	2984
2932.04	2870
2933.73	2942
2935.42	2936
2937.11	2868
2938.81	2956
2940.5	2944
2942.19	2866
2943.88	2868
2945.57	2856
2947.26	2852
2948.95	2842
2950.64	2904
2952.32	2854
2954.01	2822
2955.7	2852
2957.38	2832
2959.07	2864
2960.75	2784
2962.44	2874
2964.12	2798
2965.81	2776
2967.49	2778
2969.17	2746
2970.86	2774
2972.54	2784
2974.22	2766
2975.9	2754
2977.58	2716
2979.26	2714
2980.94	2718
2982.62	2758
2984.3	2804
2985.98	2706
2987.66	2716
2989.33	2650
2991.01	2702
2992.69	2632
2994.36	2658
2996.04	2646
2997.71	2580
2999.39	2618