File: muestras/tallo/2/Organic_14.txt
#Acq. time (s)=	10
#Accumulations=	1
#Range (cm-¹)=	100...3000
#Windows=	3
#Autofocus=	Off
#AutoExposure=	Off
#Spike filter=	Off
#Delay time (s)=	0
#Binning=	1
#Readout mode=	Signal
#DeNoise=	Off
#ICS correction=	Off
#Dark correction=	Off
#Inst. Process=	Off
#Instrument=	LabRAM HR Evol
#Detector=	Syncerity OE
#Objective=	x100_VIS
#Grating=	600 (500nm)
#ND Filter=	3.2%
#Laser=	633nm_Edge
#Hole=	100.021
#Range=	Visible
#Project=	Omar
#Sample=	26-06-23
#Site=	2
#Title=	Organic
#Remark=
#Date=	26.06.2023 16:28
#Acquired=	26.06.2023 16:28:47
101.018	3728
103.586	3692
106.152	3686
108.717	3644
111.281	3746
113.845	3730
116.407	3736
118.969	3810
121.53	3766
124.09	3830
126.649	3776
129.207	3888
131.765	3836
134.321	3838
136.877	3882
139.432	3960
141.985	3876
144.538	3928
147.09	3886
149.641	3930
152.191	3926
154.741	3950
157.289	3890
159.837	3908
162.385	3934
164.93	3976
167.476	3918
170.019	3964
172.562	3982
175.105	4050
177.646	4104
180.188	4016
182.727	4004
185.266	4066
187.804	4036
190.342	4172
192.878	4068
195.413	4150
197.948	4144
200.481	4192
203.014	4164
205.546	4258
208.077	4246
210.608	4200
213.137	4204
215.666	4270
218.194	4294
220.721	4352
223.247	4364
225.772	4250
228.295	4378
230.819	4382
233.342	4430
235.864	4424
238.384	4434
240.904	4498
243.423	4458
245.941	4518
248.46	4588
250.975	4446
253.492	4616
256.006	4538
258.519	4560
261.033	4630
263.545	4620
266.057	4568
268.567	4480
271.076	4564
273.585	4548
276.094	4612
278.601	4594
281.107	4638
283.612	4602
286.116	4568
288.62	4682
291.123	4722
293.625	4718
296.126	4748
298.626	4830
301.126	4798
303.625	4866
306.122	4708
308.62	4892
311.114	4824
313.61	4856
316.105	4826
318.599	4952
321.09	4930
323.583	4974
326.073	4986
328.563	4934
331.053	4988
333.541	4966
336.029	5050
338.515	5066
341.001	4944
343.486	4948
345.97	5082
348.453	5086
350.936	5056
353.418	5120
355.898	5194
358.378	5076
360.858	5124
363.336	5114
365.813	5046
368.29	5092
370.766	5170
373.241	5158
375.715	5202
378.188	5136
380.66	5154
383.132	5138
385.603	5184
388.072	5218
390.541	5322
393.01	5334
395.477	5276
397.943	5318
400.409	5324
402.875	5392
405.338	5428
407.802	5402
410.263	5422
412.725	5426
415.185	5522
417.646	5570
420.104	5492
422.564	5660
425.02	5652
427.477	5720
429.933	5736
432.388	5704
434.841	5682
437.294	5778
439.748	5776
442.199	5804
444.65	5734
447.1	5810
449.549	5762
451.997	5726
454.445	5844
456.891	5832
459.337	5732
461.782	5776
464.227	5878
466.669	5904
469.112	5838
471.554	5818
473.995	5928
476.434	5908
478.874	6000
481.312	5914
483.749	5924
486.186	6090
488.622	5996
491.057	6032
493.491	6130
495.925	6082
498.357	6096
500.789	6136
503.221	6142
505.65	6302
508.079	6216
510.509	6240
512.936	6122
515.363	6270
517.789	6180
520.214	6278
522.638	6288
525.062	6284
527.485	6296
529.907	6214
532.328	6336
534.748	6240
537.168	6312
539.587	6418
542.005	6284
544.423	6404
546.838	6318
549.254	6332
551.669	6440
554.082	6524
556.496	6418
558.909	6410
561.319	6468
563.731	6436
566.14	6502
568.549	6560
570.957	6630
573.364	6568
575.771	6622
578.177	6718
580.581	6682
582.987	6650
585.39	6676
587.792	6744
590.193	6802
592.594	6774
594.996	6896
597.395	6918
599.793	6872
602.191	6918
604.588	6984
606.984	6980
609.378	7054
611.773	7172
614.167	7094
616.56	7132
618.953	7134
621.343	7186
623.734	7254
626.124	7330
628.512	7292
630.901	7370
633.289	7476
635.675	7586
638.061	7544
640.446	7560
642.831	7568
645.213	7674
647.595	7734
649.978	7642
652.359	7796
654.738	7728
657.117	7688
659.497	7860
661.875	7762
664.252	7860
666.628	7878
669.003	7954
671.378	7994
673.751	7856
676.124	7962
678.497	8052
680.868	8076
683.239	8078
685.609	8108
687.977	8300
690.346	8152
692.714	8186
695.081	8158
697.446	8242
699.812	8272
702.175	8322
704.539	8344
706.901	8528
709.264	8470
711.625	8484
713.986	8500
716.345	8610
718.705	8786
721.062	8638
723.419	8762
725.775	8690
728.132	8844
730.487	8952
732.841	8880
735.194	9066
737.546	9172
739.898	9026
742.249	9180
744.599	9180
746.949	9156
749.298	9272
751.646	9180
753.993	9358
756.34	9378
758.684	9406
761.029	9394
763.374	9342
765.716	9588
768.059	9570
770.401	9654
772.741	9650
775.082	9596
777.421	9764
779.76	9752
782.097	9824
784.434	9814
786.771	9894
789.106	10022
791.44	9940
793.775	9958
796.108	10148
798.44	10220
800.771	10158
803.102	10120
805.432	10374
807.761	10328
810.09	10438
812.417	10482
814.744	10756
817.071	10818
819.396	10680
821.721	10798
824.045	10814
826.367	10916
828.69	11144
831.012	11088
833.332	11162
835.653	11262
837.972	11416
840.29	11482
842.609	11406
844.925	11618
847.242	11756
849.557	11682
851.871	11732
854.186	11848
856.498	11834
858.81	11920
861.122	11970
863.434	12062
865.744	12228
868.053	12328
870.361	12270
872.669	12432
874.976	12396
877.282	12528
879.588	12508
881.893	12616
884.197	12626
886.5	12814
888.802	12708
891.104	12832
893.405	12792
895.706	12782
898.004	12898
900.303	13034
902.6	13008
904.898	13234
907.194	13094
909.49	13176
911.785	13176
914.08	13286
916.372	13420
918.666	13522
920.957	13548
923.248	13584
925.538	13616
927.828	13848
930.118	13636
932.406	13912
934.693	13912
936.979	14052
939.265	13998
941.55	14158
943.835	14372
946.118	14412
948.401	14498
950.682	14470
952.964	14754
955.245	14726
957.525	14808
959.803	14784
962.082	14856
964.36	15048
966.636	15202
968.913	15146
971.188	15231
973.463	15352
975.736	15358
978.009	15264
980.282	15518
982.554	15618
984.824	15528
987.095	15776
989.364	15860
991.633	15780
993.9	15780
996.167	16090
998.434	16150
1000.7	15894
1002.96	16168
1005.23	16188
1007.49	16352
1009.76	16384
1012.02	16434
1014.28	16518
1016.54	16476
1018.8	16684
1021.06	16674
1023.32	16782
1025.57	16956
1027.83	16808
1030.09	17110
1032.34	17032
1034.6	17234
1036.85	17276
1039.1	17342
1041.35	17340
1043.61	17668
1045.86	17474
1048.11	17748
1050.36	17844
1052.61	17776
1054.85	17822
1057.1	17970
1059.35	17946
1061.59	18162
1063.84	18134
1066.08	18020
1068.33	18336
1070.57	18294
1072.81	18240
1075.05	18348
1077.29	18464
1079.53	18294
1081.77	18352
1084.01	18454
1086.25	18460
1088.48	18326
1090.72	18424
1092.96	18508
1095.19	18582
1097.43	18384
1099.66	18570
1101.89	18604
1104.12	18492
1106.35	18434
1108.59	18478
1110.81	18586
1113.04	18772
1115.27	18720
1117.5	18622
1119.73	18746
1121.95	18604
1124.18	18564
1126.4	18782
1128.63	18656
1130.85	18772
1133.07	18682
1135.29	18752
1137.51	18858
1139.73	18812
1141.95	18790
1144.17	18948
1146.39	18836
1148.61	18960
1150.82	19032
1153.04	18830
1155.26	19084
1157.47	18968
1159.68	18972
1161.9	19122
1164.11	18872
1166.32	18974
1168.53	19188
1170.74	18992
1172.95	18820
1175.16	18994
1177.37	18890
1179.58	18820
1181.78	18722
1183.99	18776
1186.19	18854
1188.4	18658
1190.6	18454
1192.8	18644
1195.01	18412
1197.21	18349.8
1199.41	18291.6
1201.61	18291.5
1203.81	18154.9
1206.01	18301.4
1208.2	18087.7
1210.4	18213.8
1212.6	18016.3
1214.8	17936.2
1216.99	17998.7
1219.18	17713.7
1221.38	17739.4
1223.57	17784.6
1225.76	17570.1
1227.96	17481.1
1230.15	17557.7
1232.34	17582.8
1234.53	17364.8
1236.71	17364.2
1238.9	17377.9
1241.09	17286.8
1243.28	17268.7
1245.46	17110.1
1247.65	17224.9
1249.83	17158.2
1252.02	17021.7
1254.2	17016.7
1256.38	17017.7
1258.56	16940.9
1260.74	16924
1262.92	16764.4
1265.1	16707.5
1267.28	16709.7
1269.46	16749.1
1271.64	16715.6
1273.82	16553
1275.99	16458.8
1278.17	16508.6
1280.34	16454.1
1282.52	16395.2
1284.69	16350.3
1286.86	16329.6
1289.03	16274.9
1291.21	16157.1
1293.38	16086.3
1295.55	15931.8
1297.71	15911.4
1299.88	15909.2
1302.05	15992.1
1304.22	15817.4
1306.38	15753.1
1308.43	15682
1310.61	15670
1312.78	15442
1314.96	15248
1317.13	15318
1319.3	15344
1321.48	15096
1323.65	14990
1325.82	15026
1327.99	14822
1330.16	14878
1332.33	14868
1334.5	14602
1336.66	14624
1338.83	14522
1341	14398
1343.16	14404
1345.33	14358
1347.49	14220
1349.65	14102
1351.82	14108
1353.98	14068
1356.14	14166
1358.3	13982
1360.46	13794
1362.62	13692
1364.78	13682
1366.94	13650
1369.09	13594
1371.25	13562
1373.41	13422
1375.56	13462
1377.72	13350
1379.87	13400
1382.02	13268
1384.17	13258
1386.33	13074
1388.48	13062
1390.63	13068
1392.78	13080
1394.93	12804
1397.07	12926
1399.22	12780
1401.37	12814
1403.52	12800
1405.66	12810
1407.81	12594
1409.95	12520
1412.09	12598
1414.24	12500
1416.38	12466
1418.52	12426
1420.66	12284
1422.8	12200
1424.94	12232
1427.08	12138
1429.22	12224
1431.35	12152
1433.49	12026
1435.63	12050
1437.76	11964
1439.9	12118
1442.03	11992
1444.17	11808
1446.3	11800
1448.43	11768
1450.56	11808
1452.69	11702
1454.82	11740
1456.95	11606
1459.08	11650
1461.21	11574
1463.34	11686
1465.46	11520
1467.59	11582
1469.71	11558
1471.84	11394
1473.96	11480
1476.08	11374
1478.21	11422
1480.33	11248
1482.45	11306
1484.57	11364
1486.69	11182
1488.81	11116
1490.93	11224
1493.05	11188
1495.16	11256
1497.28	11062
1499.4	11060
1501.51	10992
1503.63	11002
1505.74	10920
1507.85	10852
1509.97	10928
1512.08	10884
1514.19	10830
1516.3	10684
1518.41	10706
1520.52	10668
1522.63	10752
1524.73	10598
1526.84	10528
1528.95	10440
1531.06	10498
1533.16	10502
1535.26	10478
1537.37	10494
1539.47	10430
1541.57	10318
1543.68	10296
1545.78	10306
1547.88	10104
1549.98	10226
1552.08	10268
1554.18	10096
1556.27	10048
1558.37	10130
1560.47	10024
1562.56	10062
1564.66	10000
1566.75	9862
1568.85	9990
1570.94	10048
1573.03	9820
1575.13	9902
1577.22	9862
1579.31	9910
1581.4	9900
1583.49	9790
1585.58	9818
1587.66	9786
1589.75	9860
1591.84	9786
1593.93	9728
1596.01	9762
1598.1	9764
1600.18	9790
1602.26	9742
1604.35	9806
1606.43	9776
1608.51	9728
1610.59	9648
1612.67	9712
1614.75	9674
1616.83	9792
1618.91	9682
1620.99	9576
1623.06	9558
1625.14	9716
1627.21	9582
1629.29	9634
1631.36	9752
1633.44	9360
1635.51	9466
1637.58	9628
1639.66	9492
1641.73	9424
1643.8	9490
1645.87	9424
1647.94	9352
1650	9254
1652.07	9414
1654.14	9506
1656.21	9480
1658.27	9414
1660.34	9232
1662.4	9158
1664.47	9242
1666.53	9238
1668.59	9198
1670.66	9134
1672.72	9084
1674.78	9084
1676.84	9028
1678.9	9168
1680.96	9040
1683.01	9052
1685.07	8988
1687.13	8962
1689.19	9064
1691.24	8856
1693.3	8872
1695.35	8928
1697.4	8950
1699.46	8812
1701.51	8804
1703.56	8872
1705.61	8772
1707.66	8744
1709.71	8708
1711.76	8814
1713.81	8536
1715.86	8666
1717.91	8736
1719.95	8610
1722	8652
1724.04	8564
1726.09	8678
1728.13	8740
1730.18	8590
1732.22	8612
1734.26	8436
1736.3	8616
1738.34	8478
1740.38	8566
1742.42	8602
1744.46	8464
1746.5	8514
1748.54	8438
1750.58	8340
1752.61	8428
1754.65	8568
1756.68	8508
1758.72	8506
1760.75	8328
1762.79	8450
1764.82	8416
1766.85	8446
1768.88	8332
1770.91	8348
1772.94	8386
1774.97	8376
1777	8420
1779.03	8384
1781.06	8230
1783.09	8344
1785.11	8416
1787.14	8208
1789.16	8294
1791.19	8266
1793.21	8312
1795.23	8408
1797.26	8326
1799.28	8174
1801.3	8230
1803.32	8340
1805.34	8152
1807.36	8216
1809.38	8250
1811.4	8128
1813.42	8108
1815.43	8146
1817.45	8144
1819.47	8168
1821.48	8138
1823.49	8124
1825.51	8080
1827.52	7930
1829.54	8030
1831.55	7910
1833.56	7934
1835.57	7938
1837.58	7896
1839.59	8008
1841.6	7840
1843.61	7908
1845.61	7956
1847.62	7870
1849.63	7858
1851.63	7842
1853.64	7860
1855.64	7800
1857.65	7828
1859.65	7820
1861.65	7718
1863.65	7716
1865.66	7740
1867.66	7760
1869.66	7758
1871.66	7788
1873.66	7650
1875.65	7730
1877.65	7798
1879.65	7798
1881.65	7660
1883.64	7718
1885.64	7688
1887.63	7664
1889.63	7682
1891.62	7762
1893.61	7614
1895.6	7598
1897.6	7652
1899.59	7638
1901.58	7510
1903.57	7642
1905.56	7672
1907.54	7662
1909.53	7560
1911.52	7468
1913.51	7548
1915.49	7614
1917.48	7578
1919.46	7592
1921.45	7578
1923.43	7538
1925.41	7456
1927.4	7566
1929.38	7466
1931.36	7584
1933.34	7514
1935.32	7370
1937.3	7484
1939.28	7604
1941.26	7518
1943.23	7400
1945.21	7356
1947.19	7414
1949.16	7380
1951.14	7548
1953.11	7370
1955.09	7384
1957.06	7418
1959.03	7226
1961	7360
1962.98	7366
1964.95	7382
1966.92	7308
1968.89	7296
1970.85	7220
1972.82	7172
1974.79	7308
1976.76	7178
1978.73	7216
1980.69	7126
1982.66	7194
1984.62	7194
1986.59	7274
1988.55	7196
1990.51	7252
1992.47	7214
1994.44	7256
1996.4	7202
1998.36	7168
2000.32	7050
2002.28	7020
2004.24	7080
2006.19	7086
2008.15	7154
2010.11	7190
2012.06	7066
2014.02	7050
2015.98	7134
2017.93	7116
2019.88	7084
2021.84	7046
2023.79	7100
2025.74	7012
2027.69	6964
2029.65	7112
2031.6	7040
2033.55	7016
2035.5	6924
2037.44	7004
2039.39	7022
2041.34	6906
2043.29	6932
2045.23	6852
2047.18	6960
2049.12	6958
2051.07	6884
2053.01	6928
2054.95	6848
2056.9	6914
2058.84	6914
2060.78	6840
2062.72	6918
2064.66	6778
2066.6	6808
2068.54	6846
2070.48	6790
2072.42	6902
2074.35	6800
2076.29	6862
2078.23	6710
2080.16	6808
2082.1	6682
2084.03	6764
2085.96	6682
2087.9	6716
2089.83	6736
2091.76	6756
2093.69	6598
2095.62	6772
2097.55	6670
2099.48	6714
2101.41	6662
2103.34	6658
2105.27	6646
2107.2	6698
2109.12	6706
2111.05	6714
2112.98	6626
2114.9	6554
2116.82	6616
2118.75	6674
2120.67	6646
2122.59	6686
2124.52	6628
2126.44	6604
2128.36	6576
2130.28	6586
2132.2	6534
2134.12	6636
2136.04	6548
2137.95	6494
2139.87	6536
2141.79	6502
2143.7	6554
2145.62	6435.75
2147.53	6500.67
2149.45	6343.39
2151.36	6422.26
2153.28	6416.5
2155.19	6373.41
2157.1	6386.44
2159.01	6340.01
2160.92	6375.66
2162.83	6323.33
2164.74	6381.51
2166.65	6368.28
2168.56	6280.13
2170.47	6249.96
2172.38	6358.03
2174.28	6248.75
2176.19	6265.4
2178.09	6264.68
2180	6347.04
2181.9	6287.67
2183.81	6266.57
2185.71	6232.34
2187.61	6162.37
2189.52	6219.73
2191.42	6262.86
2193.32	6211.83
2195.22	6185.2
2197.12	6202.32
2199.02	6195.95
2200.92	6212.36
2202.82	6109.49
2204.71	6183.75
2206.61	6154.2
2208.51	6168.35
2210.4	6167.26
2212.3	6125.07
2214.19	6152.19
2216.09	6170.82
2217.98	6071.12
2219.87	6098.22
2221.77	6139.01
2223.66	6137.65
2225.55	6158.18
2227.44	6109.41
2229.33	6081.07
2231.22	6146.67
2233.11	6160.41
2235	6115.07
2236.88	6125.82
2238.77	6132.15
2240.66	6144.79
2242.07	6246
2243.97	6104
2245.87	6130
2247.76	6198
2249.65	6110
2251.55	6092
2253.44	6234
2255.33	6096
2257.22	6156
2259.12	6170
2261.01	6088
2262.9	6056
2264.78	6096
2266.67	6054
2268.56	6014
2270.45	6130
2272.34	6116
2274.22	6124
2276.11	6076
2277.99	5954
2279.88	5988
2281.76	6002
2283.65	6002
2285.53	6000
2287.41	5978
2289.3	5946
2291.18	6032
2293.06	5914
2294.94	5928
2296.82	5958
2298.7	5946
2300.58	5906
2302.46	5926
2304.33	5908
2306.21	5876
2308.09	5840
2309.96	5856
2311.84	5836
2313.71	5900
2315.59	5932
2317.46	5758
2319.33	5940
2321.21	5908
2323.08	5796
2324.95	5780
2326.82	5728
2328.69	5856
2330.56	5814
2332.43	5722
2334.3	5800
2336.17	5792
2338.03	5802
2339.9	5810
2341.77	5734
2343.63	5804
2345.5	5822
2347.36	5740
2349.23	5716
2351.09	5790
2352.95	5758
2354.82	5712
2356.68	5734
2358.54	5780
2360.4	5618
2362.26	5822
2364.12	5658
2365.98	5676
2367.84	5786
2369.7	5632
2371.56	5546
2373.41	5622
2375.27	5656
2377.12	5724
2378.98	5636
2380.84	5680
2382.69	5564
2384.54	5524
2386.4	5570
2388.25	5652
2390.1	5672
2391.95	5512
2393.8	5584
2395.65	5480
2397.5	5494
2399.35	5562
2401.2	5472
2403.05	5472
2404.9	5620
2406.75	5454
2408.59	5522
2410.44	5560
2412.28	5488
2414.13	5492
2415.97	5438
2417.82	5460
2419.66	5450
2421.5	5436
2423.35	5396
2425.19	5468
2427.03	5298
2428.87	5348
2430.71	5354
2432.55	5402
2434.39	5402
2436.23	5336
2438.06	5362
2439.9	5344
2441.74	5386
2443.57	5358
2445.41	5320
2447.24	5250
2449.08	5346
2450.91	5262
2452.75	5274
2454.58	5312
2456.41	5340
2458.24	5236
2460.08	5202
2461.91	5264
2463.74	5272
2465.57	5262
2467.4	5142
2469.22	5202
2471.05	5236
2472.88	5268
2474.71	5162
2476.53	5176
2478.36	5176
2480.19	5084
2482.01	5122
2483.83	5168
2485.66	5144
2487.48	5122
2489.3	5172
2491.13	5026
2492.95	5000
2494.77	5010
2496.59	5114
2498.41	5116
2500.23	5098
2502.05	5030
2503.87	5010
2505.68	5040
2507.5	5036
2509.32	5046
2511.14	5014
2512.95	5000
2514.77	4896
2516.58	4876
2518.39	4914
2520.21	4818
2522.02	4940
2523.83	4886
2525.65	4876
2527.46	4826
2529.27	4840
2531.08	4860
2532.89	4904
2534.7	4940
2536.51	4852
2538.32	4770
2540.12	4774
2541.93	4722
2543.74	4740
2545.54	4712
2547.35	4746
2549.15	4714
2550.96	4748
2552.76	4690
2554.56	4740
2556.37	4696
2558.17	4768
2559.97	4734
2561.77	4692
2563.58	4612
2565.38	4738
2567.18	4632
2568.97	4596
2570.77	4666
2572.57	4632
2574.37	4622
2576.17	4656
2577.96	4618
2579.76	4588
2581.55	4562
2583.35	4560
2585.14	4484
2586.94	4528
2588.73	4544
2590.52	4456
2592.32	4480
2594.11	4506
2595.9	4442
2597.69	4482
2599.48	4464
2601.27	4424
2603.06	4514
2604.85	4346
2606.64	4402
2608.42	4432
2610.21	4414
2612	4412
2613.78	4378
2615.57	4424
2617.36	4398
2619.14	4348
2620.92	4378
2622.71	4368
2624.49	4242
2626.27	4226
2628.05	4264
2629.84	4262
2631.62	4266
2633.4	4222
2635.18	4288
2636.96	4200
2638.74	4142
2640.51	4124
2642.29	4166
2644.07	4072
2645.85	4136
2647.62	4156
2649.4	4158
2651.17	4032
2652.95	4152
2654.72	4146
2656.5	4194
2658.27	4140
2660.04	4082
2661.81	4122
2663.58	4016
2665.35	4066
2667.13	4042
2668.9	4082
2670.66	4016
2672.43	4044
2674.2	4052
2675.97	4002
2677.74	4018
2679.5	4014
2681.27	4022
2683.04	3976
2684.8	3976
2686.57	3954
2688.33	4000
2690.09	4026
2691.86	3868
2693.62	3980
2695.38	4000
2697.15	3880
2698.91	3878
2700.67	3880
2702.43	3894
2704.19	3840
2705.95	3896
2707.7	3824
2709.46	3792
2711.22	3810
2712.98	3738
2714.73	3708
2716.49	3810
2718.25	3800
2720	3782
2721.76	3754
2723.51	3720
2725.26	3746
2727.02	3742
2728.77	3730
2730.52	3622
2732.27	3684
2734.02	3620
2735.77	3718
2737.52	3626
2739.27	3570
2741.02	3576
2742.77	3640
2744.52	3622
2746.27	3618
2748.01	3656
2749.76	3568
2751.51	3572
2753.25	3558
2755	3522
2756.74	3602
2758.48	3568
2760.23	3542
2761.97	3524
2763.71	3564
2765.45	3494
2767.19	3526
2768.94	3462
2770.68	3494
2772.42	3418
2774.16	3520
2775.89	3422
2777.63	3424
2779.37	3382
2781.11	3448
2782.84	3432
2784.58	3358
2786.32	3380
2788.05	3442
2789.79	3386
2791.52	3392
2793.25	3306
2794.99	3316
2796.72	3318
2798.45	3370
2800.18	3272
2801.92	3244
2803.65	3270
2805.38	3336
2807.11	3316
2808.84	3286
2810.57	3302
2812.29	3268
2814.02	3246
2815.75	3290
2817.47	3198
2819.2	3224
2820.93	3150
2822.65	3156
2824.38	3178
2826.1	3186
2827.82	3140
2829.55	3168
2831.27	3124
2832.99	3168
2834.71	3152
2836.44	3172
2838.16	3108
2839.88	3142
2841.6	3056
2843.32	3086
2845.03	3088
2846.75	3056
2848.47	3098
2850.19	3028
2851.9	3072
2853.62	3010
2855.34	3010
2857.05	3022
2858.77	3008
2860.48	3008
2862.19	2988
2863.91	3048
2865.62	3014
2867.33	2962
2869.04	2936
2870.76	2920
2872.47	2962
2874.18	2888
2875.89	2908
2877.6	2896
2879.31	2878
2881.01	2880
2882.72	2838
2884.43	2948
2886.14	2866
2887.84	2868
2889.55	2860
2891.25	2886
2892.96	2834
2894.66	2838
2896.37	2818
2898.07	2776
2899.77	2786
2901.48	2824
2903.18	2838
2904.88	2838
2906.58	2830
2908.28	2764
2909.98	2848
2911.68	2728
2913.38	2748
2915.08	2754
2916.78	2704
2918.47	2726
2920.17	2820
2921.87	2738
2923.56	2748
2925.26	2722
2926.95	2730
2928.65	2698
2930.34	2654
2932.04	2758
2933.73	2796
2935.42	2712
2937.11	2646
2938.81	2618
2940.5	2652
2942.19	2682
2943.88	2678
2945.57	2650
2947.26	2702
2948.95	2620
2950.64	2622
2952.32	2586
2954.01	2640
2955.7	2652
2957.38	2698
2959.07	2624
2960.75	2616
2962.44	2636
2964.12	2562
2965.81	2574
2967.49	2500
2969.17	2562
2970.86	2600
2972.54	2556
2974.22	2494
2975.9	2512
2977.58	2572
2979.26	2508
2980.94	2542
2982.62	2480
2984.3	2468
2985.98	2488
2987.66	2496
2989.33	2476
2991.01	2482
2992.69	2516
2994.36	2474
2996.04	2458
2997.71	2462
2999.39	2374