File: muestras/tallo/2/Organic_21.txt
#Acq. time (s)=	10
#Accumulations=	1
#Range (cm-¹)=	100...3000
#Windows=	3
#Autofocus=	Off
#AutoExposure=	Off
#Spike filter=	Off
#Delay time (s)=	0
#Binning=	1
#Readout mode=	Signal
#DeNoise=	Off
#ICS correction=	Off
#Dark correction=	Off
#Inst. Process=	Off
#Instrument=	LabRAM HR Evol
#Detector=	Syncerity OE
#Objective=	x100_VIS
#Grating=	600 (500nm)
#ND Filter=	3.2%
#Laser=	633nm_Edge
#Hole=	100.021
#Range=	Visible
#Project=	Omar
#Sample=	26-06-23
#Site=	2
#Title=	Organic
#Remark=
#Date=	26.06.2023 16:35
#Acquired=	26.06.2023 16:35:16
101.018	3392
103.586	3394
106.152	3414
108.717	3404
111.281	3474
113.845	3558
116.407	3546
118.969	3524
121.53	3470
124.09	3548
126.649	3538
129.207	3510
131.765	3584
134.321	3620
136.877	3612
139.432	3624
141.985	3614
144.538	3554
147.09	3716
149.641	3688
152.191	3648
154.741	3708
157.289	3692
159.837	3696
162.385	3722
164.93	3748
167.476	3742
170.019	3778
172.562	3766
175.105	3730
177.646	3742
180.188	3664
182.727	3800
185.266	3782
187.804	3802
190.342	3802
192.878	3900
195.413	3922
197.948	3872
200.481	3884
203.014	3846
205.546	3870
208.077	3970
210.608	3896
213.137	3930
215.666	4020
218.194	3996
220.721	4038
223.247	4062
225.772	4034
228.295	4086
230.819	4128
233.342	4130
235.864	4104
238.384	4186
240.904	4162
243.423	4180
245.941	4206
248.46	4186
250.975	4264
253.492	4222
256.006	4192
258.519	4266
261.033	4218
263.545	4300
266.057	4218
268.567	4212
271.076	4306
273.585	4258
276.094	4154
278.601	4298
281.107	4290
283.612	4346
286.116	4262
288.62	4320
291.123	4372
293.625	4434
296.126	4464
298.626	4454
301.126	4522
303.625	4456
306.122	4478
308.62	4474
311.114	4464
313.61	4508
316.105	4500
318.599	4500
321.09	4624
323.583	4580
326.073	4626
328.563	4598
331.053	4574
333.541	4660
336.029	4600
338.515	4688
341.001	4592
343.486	4674
345.97	4672
348.453	4704
350.936	4700
353.418	4700
355.898	4776
358.378	4778
360.858	4744
363.336	4762
365.813	4684
368.29	4924
370.766	4842
373.241	4818
375.715	4940
378.188	4784
380.66	4822
383.132	4888
385.603	4826
388.072	4928
390.541	4936
393.01	4884
395.477	4906
397.943	4892
400.409	4910
402.875	4982
405.338	4948
407.802	5026
410.263	5058
412.725	4960
415.185	5050
417.646	5136
420.104	5088
422.564	5266
425.02	5204
427.477	5226
429.933	5266
432.388	5248
434.841	5302
437.294	5348
439.748	5308
442.199	5286
444.65	5286
447.1	5286
449.549	5350
451.997	5348
454.445	5520
456.891	5370
459.337	5278
461.782	5272
464.227	5388
466.669	5322
469.112	5450
471.554	5494
473.995	5452
476.434	5462
478.874	5514
481.312	5550
483.749	5436
486.186	5544
488.622	5536
491.057	5632
493.491	5566
495.925	5660
498.357	5690
500.789	5622
503.221	5586
505.65	5696
508.079	5622
510.509	5750
512.936	5686
515.363	5704
517.789	5664
520.214	5772
522.638	5696
525.062	5690
527.485	5772
529.907	5752
532.328	5764
534.748	5808
537.168	5764
539.587	5870
542.005	5808
544.423	5774
546.838	5832
549.254	5810
551.669	5840
554.082	5848
556.496	5878
558.909	5886
561.319	5914
563.731	5916
566.14	5914
568.549	6064
570.957	6012
573.364	6008
575.771	5968
578.177	6134
580.581	6116
582.987	6128
585.39	6130
587.792	6136
590.193	6212
592.594	6100
594.996	6170
597.395	6248
599.793	6308
602.191	6312
604.588	6292
606.984	6354
609.378	6388
611.773	6330
614.167	6484
616.56	6492
618.953	6424
621.343	6524
623.734	6492
626.124	6576
628.512	6678
630.901	6648
633.289	6704
635.675	6728
638.061	6788
640.446	6870
642.831	6828
645.213	6832
647.595	6880
649.978	6914
652.359	6930
654.738	7016
657.117	7038
659.497	7144
661.875	7040
664.252	6956
666.628	7010
669.003	7080
671.378	7224
673.751	7182
676.124	7160
678.497	7152
680.868	7274
683.239	7318
685.609	7248
687.977	7398
690.346	7274
692.714	7202
695.081	7338
697.446	7390
699.812	7396
702.175	7470
704.539	7472
706.901	7522
709.264	7630
711.625	7526
713.986	7602
716.345	7616
718.705	7786
721.062	7746
723.419	7816
725.775	7796
728.132	7926
730.487	7914
732.841	7958
735.194	7990
737.546	8022
739.898	8106
742.249	8034
744.599	8110
746.949	8096
749.298	8204
751.646	8168
753.993	8172
756.34	8222
758.684	8274
761.029	8314
763.374	8372
765.716	8424
768.059	8494
770.401	8504
772.741	8484
775.082	8518
777.421	8616
779.76	8632
782.097	8690
784.434	8750
786.771	8724
789.106	8752
791.44	8818
793.775	8902
796.108	8986
798.44	8974
800.771	8956
803.102	9040
805.432	9006
807.761	9120
810.09	9208
812.417	9170
814.744	9324
817.071	9372
819.396	9490
821.721	9468
824.045	9562
826.367	9586
828.69	9720
831.012	9810
833.332	9768
835.653	9812
837.972	9848
840.29	10080
842.609	10190
844.925	10110
847.242	10020
849.557	10182
851.871	10288
854.186	10380
856.498	10438
858.81	10392
861.122	10496
863.434	10620
865.744	10696
868.053	10650
870.361	10628
872.669	10742
874.976	10802
877.282	10626
879.588	10860
881.893	10916
884.197	10970
886.5	10930
888.802	11062
891.104	11058
893.405	11160
895.706	11102
898.004	11204
900.303	11254
902.6	11284
904.898	11260
907.194	11234
909.49	11398
911.785	11484
914.08	11466
916.372	11518
918.666	11698
920.957	11586
923.248	11622
925.538	11736
927.828	11842
930.118	11888
932.406	11896
934.693	11940
936.979	11998
939.265	12096
941.55	12310
943.835	12326
946.118	12378
948.401	12348
950.682	12528
952.964	12590
955.245	12612
957.525	12710
959.803	12728
962.082	12770
964.36	13016
966.636	13038
968.913	13004
971.188	13095
973.463	13082
975.736	13200
978.009	13124
980.282	13314
982.554	13370
984.824	13286
987.095	13290
989.364	13482
991.633	13476
993.9	13602
996.167	13656
998.434	13636
1000.7	13792
1002.96	13824
1005.23	13788
1007.49	13708
1009.76	13902
1012.02	14018
1014.28	14076
1016.54	14060
1018.8	14198
1021.06	14200
1023.32	14316
1025.57	14302
1027.83	14408
1030.09	14506
1032.34	14416
1034.6	14718
1036.85	14744
1039.1	14628
1041.35	14842
1043.61	14852
1045.86	14970
1048.11	14918
1050.36	15066
1052.61	14946
1054.85	15260
1057.1	15282
1059.35	15324
1061.59	15306
1063.84	15340
1066.08	15392
1068.33	15312
1070.57	15460
1072.81	15532
1075.05	15384
1077.29	15582
1079.53	15518
1081.77	15592
1084.01	15624
1086.25	15550
1088.48	15718
1090.72	15494
1092.96	15582
1095.19	15740
1097.43	15596
1099.66	15532
1101.89	15694
1104.12	15674
1106.35	15528
1108.59	15646
1110.81	15758
1113.04	15688
1115.27	15632
1117.5	15828
1119.73	15708
1121.95	15768
1124.18	15870
1126.4	15836
1128.63	16032
1130.85	15684
1133.07	15578
1135.29	15916
1137.51	15938
1139.73	16040
1141.95	15962
1144.17	15934
1146.39	16010
1148.61	16022
1150.82	16042
1153.04	16116
1155.26	16188
1157.47	16060
1159.68	16098
1161.9	16018
1164.11	16030
1166.32	15960
1168.53	16030
1170.74	16122
1172.95	16050
1175.16	15940
1177.37	16010
1179.58	15988
1181.78	15812
1183.99	15770
1186.19	15874
1188.4	15822
1190.6	15694
1192.8	15702
1195.01	15530
1197.21	15646.6
1199.41	15509.6
1201.61	15379.5
1203.81	15440.8
1206.01	15306.6
1208.2	15349.4
1210.4	15469
1212.6	15223
1214.8	15175.9
1216.99	15112.6
1219.18	15097.9
1221.38	15084.3
1223.57	14911.6
1225.76	14889.8
1227.96	14873.5
1230.15	14918.1
1232.34	14826
1234.53	14691.7
1236.71	14782.5
1238.9	14743.6
1241.09	14659.1
1243.28	14633.4
1245.46	14630.7
1247.65	14632.4
1249.83	14611.6
1252.02	14575.5
1254.2	14591.7
1256.38	14512.7
1258.56	14354.8
1260.74	14474.6
1262.92	14425.5
1265.1	14334.5
1267.28	14335.3
1269.46	14201.4
1271.64	14132.6
1273.82	14124.8
1275.99	14178.6
1278.17	14181.3
1280.34	14069.2
1282.52	14068.4
1284.69	14093.1
1286.86	13909.1
1289.03	13895.7
1291.21	13828.6
1293.38	13790.7
1295.55	13703.6
1297.71	13725.2
1299.88	13649.6
1302.05	13699.2
1304.22	13526.7
1306.38	13630.5
1308.43	13452
1310.61	13342
1312.78	13262
1314.96	13192
1317.13	13144
1319.3	13134
1321.48	13146
1323.65	12934
1325.82	12972
1327.99	12752
1330.16	12804
1332.33	12726
1334.5	12658
1336.66	12706
1338.83	12616
1341	12544
1343.16	12458
1345.33	12400
1347.49	12414
1349.65	12392
1351.82	12142
1353.98	12224
1356.14	12110
1358.3	12030
1360.46	11990
1362.62	11994
1364.78	12022
1366.94	11852
1369.09	11744
1371.25	11862
1373.41	11750
1375.56	11694
1377.72	11556
1379.87	11482
1382.02	11512
1384.17	11336
1386.33	11524
1388.48	11454
1390.63	11358
1392.78	11366
1394.93	11326
1397.07	11184
1399.22	11110
1401.37	11220
1403.52	11282
1405.66	10946
1407.81	11048
1409.95	11088
1412.09	10912
1414.24	10934
1416.38	10896
1418.52	10796
1420.66	10748
1422.8	10786
1424.94	10718
1427.08	10696
1429.22	10742
1431.35	10552
1433.49	10628
1435.63	10628
1437.76	10590
1439.9	10516
1442.03	10458
1444.17	10464
1446.3	10352
1448.43	10242
1450.56	10308
1452.69	10402
1454.82	10252
1456.95	10302
1459.08	10248
1461.21	10156
1463.34	10282
1465.46	10150
1467.59	10104
1469.71	10108
1471.84	10058
1473.96	10186
1476.08	10046
1478.21	10138
1480.33	9860
1482.45	10008
1484.57	10000
1486.69	9992
1488.81	9998
1490.93	9776
1493.05	9804
1495.16	9898
1497.28	9760
1499.4	9820
1501.51	9806
1503.63	9764
1505.74	9806
1507.85	9600
1509.97	9806
1512.08	9626
1514.19	9534
1516.3	9580
1518.41	9544
1520.52	9448
1522.63	9492
1524.73	9492
1526.84	9406
1528.95	9438
1531.06	9360
1533.16	9330
1535.26	9276
1537.37	9280
1539.47	9286
1541.57	9240
1543.68	9146
1545.78	9220
1547.88	9240
1549.98	9066
1552.08	9102
1554.18	9074
1556.27	9112
1558.37	9032
1560.47	9024
1562.56	8996
1564.66	8966
1566.75	8978
1568.85	9070
1570.94	8856
1573.03	8764
1575.13	8886
1577.22	8970
1579.31	8826
1581.4	8882
1583.49	8844
1585.58	8734
1587.66	8792
1589.75	8856
1591.84	8662
1593.93	8754
1596.01	8778
1598.1	8820
1600.18	8740
1602.26	8768
1604.35	8688
1606.43	8778
1608.51	8672
1610.59	8712
1612.67	8758
1614.75	8750
1616.83	8666
1618.91	8630
1620.99	8586
1623.06	8626
1625.14	8664
1627.21	8616
1629.29	8574
1631.36	8528
1633.44	8484
1635.51	8576
1637.58	8530
1639.66	8530
1641.73	8508
1643.8	8430
1645.87	8476
1647.94	8436
1650	8370
1652.07	8404
1654.14	8346
1656.21	8364
1658.27	8342
1660.34	8412
1662.4	8202
1664.47	8262
1666.53	8302
1668.59	8280
1670.66	8188
1672.72	8186
1674.78	8146
1676.84	8080
1678.9	8054
1680.96	8170
1683.01	8118
1685.07	8006
1687.13	7918
1689.19	7998
1691.24	8022
1693.3	7990
1695.35	7942
1697.4	8032
1699.46	8018
1701.51	7904
1703.56	7872
1705.61	8048
1707.66	7904
1709.71	7780
1711.76	7726
1713.81	7758
1715.86	7798
1717.91	7826
1719.95	7792
1722	7778
1724.04	7824
1726.09	7744
1728.13	7726
1730.18	7762
1732.22	7766
1734.26	7674
1736.3	7702
1738.34	7752
1740.38	7598
1742.42	7646
1744.46	7608
1746.5	7598
1748.54	7618
1750.58	7626
1752.61	7604
1754.65	7524
1756.68	7552
1758.72	7602
1760.75	7566
1762.79	7540
1764.82	7606
1766.85	7538
1768.88	7542
1770.91	7534
1772.94	7586
1774.97	7476
1777	7514
1779.03	7486
1781.06	7628
1783.09	7520
1785.11	7480
1787.14	7566
1789.16	7450
1791.19	7550
1793.21	7516
1795.23	7594
1797.26	7390
1799.28	7436
1801.3	7350
1803.32	7374
1805.34	7470
1807.36	7394
1809.38	7404
1811.4	7188
1813.42	7332
1815.43	7324
1817.45	7270
1819.47	7218
1821.48	7224
1823.49	7302
1825.51	7264
1827.52	7146
1829.54	7228
1831.55	7240
1833.56	7220
1835.57	7178
1837.58	7206
1839.59	7118
1841.6	7134
1843.61	7206
1845.61	7090
1847.62	7108
1849.63	7066
1851.63	7066
1853.64	6996
1855.64	7034
1857.65	6994
1859.65	7006
1861.65	6974
1863.65	6960
1865.66	6984
1867.66	7154
1869.66	6962
1871.66	6952
1873.66	6850
1875.65	6810
1877.65	7000
1879.65	6858
1881.65	6856
1883.64	6926
1885.64	6950
1887.63	6900
1889.63	6762
1891.62	6924
1893.61	6890
1895.6	6892
1897.6	6854
1899.59	6910
1901.58	6768
1903.57	6832
1905.56	6790
1907.54	6742
1909.53	6800
1911.52	6798
1913.51	6822
1915.49	6850
1917.48	6768
1919.46	6704
1921.45	6674
1923.43	6824
1925.41	6738
1927.4	6732
1929.38	6748
1931.36	6686
1933.34	6682
1935.32	6722
1937.3	6602
1939.28	6650
1941.26	6770
1943.23	6758
1945.21	6612
1947.19	6640
1949.16	6728
1951.14	6610
1953.11	6668
1955.09	6664
1957.06	6550
1959.03	6716
1961	6584
1962.98	6594
1964.95	6514
1966.92	6584
1968.89	6618
1970.85	6560
1972.82	6514
1974.79	6670
1976.76	6490
1978.73	6514
1980.69	6480
1982.66	6472
1984.62	6514
1986.59	6574
1988.55	6400
1990.51	6522
1992.47	6538
1994.44	6478
1996.4	6472
1998.36	6500
2000.32	6384
2002.28	6394
2004.24	6292
2006.19	6436
2008.15	6376
2010.11	6354
2012.06	6380
2014.02	6362
2015.98	6392
2017.93	6338
2019.88	6282
2021.84	6358
2023.79	6336
2025.74	6306
2027.69	6378
2029.65	6304
2031.6	6282
2033.55	6282
2035.5	6248
2037.44	6224
2039.39	6104
2041.34	6246
2043.29	6284
2045.23	6236
2047.18	6242
2049.12	6300
2051.07	6320
2053.01	6128
2054.95	6176
2056.9	6090
2058.84	6232
2060.78	6158
2062.72	6170
2064.66	6156
2066.6	6174
2068.54	6100
2070.48	6226
2072.42	6126
2074.35	6098
2076.29	6078
2078.23	6010
2080.16	6176
2082.1	6048
2084.03	6108
2085.96	6072
2087.9	6072
2089.83	5974
2091.76	5956
2093.69	6066
2095.62	6046
2097.55	6050
2099.48	6002
2101.41	6018
2103.34	6008
2105.27	5940
2107.2	5948
2109.12	5978
2111.05	5976
2112.98	5950
2114.9	5938
2116.82	5902
2118.75	5918
2120.67	5984
2122.59	5942
2124.52	5922
2126.44	5932
2128.36	5892
2130.28	5866
2132.2	5868
2134.12	5866
2136.04	5864
2137.95	5814
2139.87	5796
2141.79	5830
2143.7	5802
2145.62	5804.06
2147.53	5759.71
2149.45	5758.55
2151.36	5788.71
2153.28	5716.28
2155.19	5695.03
2157.1	5660.47
2159.01	5675.46
2160.92	5710.5
2162.83	5657.59
2164.74	5626.11
2166.65	5656.43
2168.56	5703.45
2170.47	5717.86
2172.38	5669.93
2174.28	5581.39
2176.19	5651.91
2178.09	5603.12
2180	5643.31
2181.9	5663.44
2183.81	5576.7
2185.71	5573
2187.61	5620.53
2189.52	5562.33
2191.42	5520.44
2193.32	5531.48
2195.22	5565.4
2197.12	5541.69
2199.02	5575.53
2200.92	5608.44
2202.82	5537.35
2204.71	5626.35
2206.61	5517.49
2208.51	5503.11
2210.4	5553.87
2212.3	5520.27
2214.19	5488.19
2216.09	5510.81
2217.98	5535.98
2219.87	5488.08
2221.77	5513.53
2223.66	5538.28
2225.55	5542.06
2227.44	5537.71
2229.33	5537.19
2231.22	5547.04
2233.11	5486.31
2235	5553.16
2236.88	5517.66
2238.77	5509.26
2240.66	5614.12
2242.07	5480
2243.97	5584
2245.87	5530
2247.76	5468
2249.65	5452
2251.55	5606
2253.44	5426
2255.33	5528
2257.22	5436
2259.12	5524
2261.01	5526
2262.9	5480
2264.78	5454
2266.67	5416
2268.56	5450
2270.45	5418
2272.34	5396
2274.22	5360
2276.11	5418
2277.99	5386
2279.88	5438
2281.76	5328
2283.65	5444
2285.53	5436
2287.41	5342
2289.3	5358
2291.18	5430
2293.06	5372
2294.94	5314
2296.82	5406
2298.7	5356
2300.58	5358
2302.46	5270
2304.33	5304
2306.21	5370
2308.09	5298
2309.96	5234
2311.84	5286
2313.71	5332
2315.59	5228
2317.46	5244
2319.33	5176
2321.21	5232
2323.08	5210
2324.95	5342
2326.82	5256
2328.69	5176
2330.56	5276
2332.43	5204
2334.3	5160
2336.17	5300
2338.03	5204
2339.9	5196
2341.77	5228
2343.63	5214
2345.5	5178
2347.36	5222
2349.23	5096
2351.09	5244
2352.95	5132
2354.82	5092
2356.68	5166
2358.54	5144
2360.4	5098
2362.26	5106
2364.12	5088
2365.98	5142
2367.84	5192
2369.7	5108
2371.56	5042
2373.41	5070
2375.27	5114
2377.12	5038
2378.98	5118
2380.84	5114
2382.69	5146
2384.54	5034
2386.4	4978
2388.25	4978
2390.1	5094
2391.95	5030
2393.8	4996
2395.65	4938
2397.5	4926
2399.35	4942
2401.2	4900
2403.05	5056
2404.9	5028
2406.75	4846
2408.59	4930
2410.44	4858
2412.28	4918
2414.13	4908
2415.97	4948
2417.82	4900
2419.66	4898
2421.5	4824
2423.35	4770
2425.19	4782
2427.03	4832
2428.87	4800
2430.71	4804
2432.55	4806
2434.39	4830
2436.23	4836
2438.06	4788
2439.9	4782
2441.74	4774
2443.57	4720
2445.41	4786
2447.24	4828
2449.08	4706
2450.91	4708
2452.75	4768
2454.58	4664
2456.41	4794
2458.24	4800
2460.08	4728
2461.91	4778
2463.74	4674
2465.57	4664
2467.4	4552
2469.22	4742
2471.05	4676
2472.88	4710
2474.71	4630
2476.53	4600
2478.36	4656
2480.19	4708
2482.01	4596
2483.83	4640
2485.66	4582
2487.48	4520
2489.3	4598
2491.13	4602
2492.95	4590
2494.77	4540
2496.59	4584
2498.41	4496
2500.23	4536
2502.05	4464
2503.87	4492
2505.68	4494
2507.5	4522
2509.32	4376
2511.14	4404
2512.95	4382
2514.77	4450
2516.58	4452
2518.39	4458
2520.21	4418
2522.02	4402
2523.83	4390
2525.65	4380
2527.46	4432
2529.27	4358
2531.08	4380
2532.89	4362
2534.7	4332
2536.51	4376
2538.32	4322
2540.12	4310
2541.93	4334
2543.74	4252
2545.54	4262
2547.35	4358
2549.15	4250
2550.96	4240
2552.76	4294
2554.56	4216
2556.37	4270
2558.17	4184
2559.97	4190
2561.77	4202
2563.58	4212
2565.38	4218
2567.18	4102
2568.97	4192
2570.77	4116
2572.57	4158
2574.37	4114
2576.17	4180
2577.96	4170
2579.76	4048
2581.55	4122
2583.35	4068
2585.14	4062
2586.94	4072
2588.73	4024
2590.52	4086
2592.32	4096
2594.11	4016
2595.9	4036
2597.69	4024
2599.48	4026
2601.27	3958
2603.06	4020
2604.85	3982
2606.64	3936
2608.42	3950
2610.21	3950
2612	3942
2613.78	3936
2615.57	3922
2617.36	4016
2619.14	3866
2620.92	3848
2622.71	3852
2624.49	3860
2626.27	3888
2628.05	3864
2629.84	3882
2631.62	3828
2633.4	3778
2635.18	3778
2636.96	3754
2638.74	3724
2640.51	3792
2642.29	3774
2644.07	3792
2645.85	3642
2647.62	3750
2649.4	3750
2651.17	3658
2652.95	3686
2654.72	3694
2656.5	3672
2658.27	3696
2660.04	3708
2661.81	3642
2663.58	3606
2665.35	3680
2667.13	3658
2668.9	3650
2670.66	3526
2672.43	3668
2674.2	3614
2675.97	3672
2677.74	3650
2679.5	3614
2681.27	3610
2683.04	3656
2684.8	3574
2686.57	3568
2688.33	3638
2690.09	3524
2691.86	3508
2693.62	3482
2695.38	3524
2697.15	3464
2698.91	3526
2700.67	3466
2702.43	3546
2704.19	3440
2705.95	3446
2707.7	3426
2709.46	3436
2711.22	3404
2712.98	3390
2714.73	3496
2716.49	3400
2718.25	3340
2720	3426
2721.76	3320
2723.51	3370
2725.26	3366
2727.02	3408
2728.77	3286
2730.52	3326
2732.27	3344
2734.02	3364
2735.77	3390
2737.52	3264
2739.27	3216
2741.02	3286
2742.77	3252
2744.52	3260
2746.27	3282
2748.01	3262
2749.76	3260
2751.51	3200
2753.25	3218
2755	3196
2756.74	3228
2758.48	3222
2760.23	3202
2761.97	3188
2763.71	3156
2765.45	3128
2767.19	3096
2768.94	3146
2770.68	3164
2772.42	3084
2774.16	3112
2775.89	3086
2777.63	3080
2779.37	3126
2781.11	3126
2782.84	3136
2784.58	3046
2786.32	3066
2788.05	3042
2789.79	3038
2791.52	3038
2793.25	2984
2794.99	2994
2796.72	3056
2798.45	3032
2800.18	3062
2801.92	3048
2803.65	2991
2805.38	2972
2807.11	2982
2808.84	2930
2810.57	2998
2812.29	2942
2814.02	2850
2815.75	2894
2817.47	2868
2819.2	2914
2820.93	2878
2822.65	2918
2824.38	2920
2826.1	2980
2827.82	2834
2829.55	2890
2831.27	2796
2832.99	2880
2834.71	2802
2836.44	2828
2838.16	2810
2839.88	2814
2841.6	2878
2843.32	2794
2845.03	2776
2846.75	2824
2848.47	2734
2850.19	2834
2851.9	2792
2853.62	2770
2855.34	2712
2857.05	2764
2858.77	2706
2860.48	2752
2862.19	2720
2863.91	2628
2865.62	2718
2867.33	2638
2869.04	2728
2870.76	2648
2872.47	2640
2874.18	2704
2875.89	2610
2877.6	2656
2879.31	2598
2881.01	2600
2882.72	2602
2884.43	2638
2886.14	2566
2887.84	2634
2889.55	2568
2891.25	2572
2892.96	2562
2894.66	2540
2896.37	2562
2898.07	2540
2899.77	2512
2901.48	2526
2903.18	2550
2904.88	2542
2906.58	2524
2908.28	2486
2909.98	2526
2911.68	2568
2913.38	2472
2915.08	2470
2916.78	2500
2918.47	2534
2920.17	2516
2921.87	2448
2923.56	2454
2925.26	2524
2926.95	2496
2928.65	2394
2930.34	2440
2932.04	2442
2933.73	2416
2935.42	2446
2937.11	2440
2938.81	2416
2940.5	2470
2942.19	2438
2943.88	2402
2945.57	2400
2947.26	2374
2948.95	2400
2950.64	2378
2952.32	2398
2954.01	2390
2955.7	2360
2957.38	2380
2959.07	2376
2960.75	2296
2962.44	2296
2964.12	2372
2965.81	2314
2967.49	2302
2969.17	2334
2970.86	2310
2972.54	2302
2974.22	2302
2975.9	2340
2977.58	2268
2979.26	2254
2980.94	2232
2982.62	2260
2984.3	2278
2985.98	2240
2987.66	2250
2989.33	2242
2991.01	2230
2992.69	2166
2994.36	2228
2996.04	2232
2997.71	2208
2999.39	2164