File: muestras/tallo/2/Organic_15.txt
#Acq. time (s)=	10
#Accumulations=	1
#Range (cm-¹)=	100...3000
#Windows=	3
#Autofocus=	Off
#AutoExposure=	Off
#Spike filter=	Off
#Delay time (s)=	0
#Binning=	1
#Readout mode=	Signal
#DeNoise=	Off
#ICS correction=	Off
#Dark correction=	Off
#Inst. Process=	Off
#Instrument=	LabRAM HR Evol
#Detector=	Syncerity OE
#Objective=	x100_VIS
#Grating=	600 (500nm)
#ND Filter=	3.2%
#Laser=	633nm_Edge
#Hole=	100.021
#Range=	Visible
#Project=	Omar
#Sample=	26-06-23
#Site=	2
#Title=	Organic
#Remark=
#Date=	26.06.2023 16:29
#Acquired=	26.06.2023 16:29:40
101.018	3686
103.586	3646
106.152	3730
108.717	3694
111.281	3776
113.845	3740
116.407	3796
118.969	3812
121.53	3770
124.09	3722
126.649	3742
129.207	3764
131.765	3776
134.321	3798
136.877	3794
139.432	3906
141.985	3882
144.538	3844
147.09	3888
149.641	3894
152.191	3858
154.741	3880
157.289	3932
159.837	3942
162.385	3974
164.93	3994
167.476	3938
170.019	3938
172.562	3972
175.105	4006
177.646	3990
180.188	3994
182.727	4082
185.266	3980
187.804	4018
190.342	4110
192.878	4060
195.413	4082
197.948	4108
200.481	4074
203.014	4170
205.546	4220
208.077	4182
210.608	4242
213.137	4240
215.666	4242
218.194	4254
220.721	4296
223.247	4298
225.772	4282
228.295	4284
230.819	4356
233.342	4402
235.864	4384
238.384	4430
240.904	4420
243.423	4468
245.941	4438
248.46	4478
250.975	4470
253.492	4492
256.006	4540
258.519	4404
261.033	4572
263.545	4510
266.057	4488
268.567	4508
271.076	4488
273.585	4528
276.094	4566
278.601	4598
281.107	4584
283.612	4468
286.116	4508
288.62	4628
291.123	4600
293.625	4672
296.126	4766
298.626	4752
301.126	4794
303.625	4732
306.122	4792
308.62	4858
311.114	4878
313.61	4888
316.105	4832
318.599	4918
321.09	4876
323.583	4896
326.073	4842
328.563	4870
331.053	4846
333.541	4932
336.029	4990
338.515	4902
341.001	4972
343.486	4890
345.97	4950
348.453	5010
350.936	5016
353.418	5070
355.898	5120
358.378	5050
360.858	5152
363.336	5092
365.813	5164
368.29	5152
370.766	5182
373.241	5224
375.715	5182
378.188	5104
380.66	5072
383.132	5182
385.603	5178
388.072	5182
390.541	5204
393.01	5118
395.477	5260
397.943	5296
400.409	5322
402.875	5336
405.338	5398
407.802	5326
410.263	5322
412.725	5520
415.185	5474
417.646	5470
420.104	5518
422.564	5544
425.02	5566
427.477	5640
429.933	5612
432.388	5600
434.841	5682
437.294	5700
439.748	5692
442.199	5696
444.65	5638
447.1	5642
449.549	5740
451.997	5658
454.445	5778
456.891	5706
459.337	5720
461.782	5768
464.227	5836
466.669	5808
469.112	5892
471.554	5872
473.995	5912
476.434	5838
478.874	5904
481.312	5994
483.749	5858
486.186	5886
488.622	5980
491.057	6102
493.491	6060
495.925	6034
498.357	6046
500.789	6084
503.221	6058
505.65	6132
508.079	6096
510.509	6124
512.936	6062
515.363	6216
517.789	6128
520.214	6202
522.638	6182
525.062	6190
527.485	6274
529.907	6254
532.328	6350
534.748	6198
537.168	6238
539.587	6300
542.005	6392
544.423	6260
546.838	6280
549.254	6186
551.669	6288
554.082	6380
556.496	6274
558.909	6394
561.319	6516
563.731	6318
566.14	6356
568.549	6444
570.957	6548
573.364	6458
575.771	6502
578.177	6616
580.581	6608
582.987	6650
585.39	6624
587.792	6686
590.193	6680
592.594	6710
594.996	6692
597.395	6744
599.793	6820
602.191	6790
604.588	6870
606.984	6970
609.378	7004
611.773	6892
614.167	7042
616.56	6986
618.953	6980
621.343	7166
623.734	7164
626.124	7266
628.512	7214
630.901	7318
633.289	7398
635.675	7484
638.061	7420
640.446	7466
642.831	7496
645.213	7508
647.595	7478
649.978	7598
652.359	7454
654.738	7726
657.117	7492
659.497	7656
661.875	7716
664.252	7826
666.628	7694
669.003	7778
671.378	7814
673.751	7852
676.124	7800
678.497	7914
680.868	7860
683.239	7812
685.609	7966
687.977	7998
690.346	7938
692.714	8094
695.081	8076
697.446	8212
699.812	8152
702.175	8262
704.539	8392
706.901	8338
709.264	8318
711.625	8440
713.986	8446
716.345	8478
718.705	8570
721.062	8602
723.419	8648
725.775	8668
728.132	8630
730.487	8756
732.841	8692
735.194	8720
737.546	8864
739.898	8946
742.249	9014
744.599	8922
746.949	8992
749.298	9074
751.646	9072
753.993	9194
756.34	9200
758.684	9264
761.029	9230
763.374	9224
765.716	9264
768.059	9380
770.401	9546
772.741	9468
775.082	9424
777.421	9448
779.76	9698
782.097	9618
784.434	9638
786.771	9718
789.106	9786
791.44	9944
793.775	9926
796.108	10036
798.44	10054
800.771	9948
803.102	10154
805.432	10196
807.761	10338
810.09	10314
812.417	10506
814.744	10536
817.071	10576
819.396	10574
821.721	10678
824.045	10728
826.367	10782
828.69	10932
831.012	10884
833.332	11054
835.653	11080
837.972	11232
840.29	11190
842.609	11288
844.925	11486
847.242	11456
849.557	11496
851.871	11526
854.186	11726
856.498	11770
858.81	11798
861.122	11748
863.434	11918
865.744	11916
868.053	11964
870.361	12084
872.669	12110
874.976	12204
877.282	12238
879.588	12382
881.893	12404
884.197	12306
886.5	12504
888.802	12478
891.104	12408
893.405	12482
895.706	12508
898.004	12696
900.303	12756
902.6	12748
904.898	12942
907.194	12878
909.49	12838
911.785	13042
914.08	12962
916.372	13120
918.666	13204
920.957	13236
923.248	13436
925.538	13444
927.828	13580
930.118	13540
932.406	13648
934.693	13812
936.979	13862
939.265	13842
941.55	13712
943.835	14006
946.118	14094
948.401	14196
950.682	14416
952.964	14388
955.245	14344
957.525	14584
959.803	14602
962.082	14614
964.36	14858
966.636	14892
968.913	14948
971.188	14991
973.463	14836
975.736	15092
978.009	15202
980.282	15250
982.554	15252
984.824	15248
987.095	15326
989.364	15340
991.633	15484
993.9	15550
996.167	15554
998.434	15760
1000.7	15726
1002.96	15590
1005.23	15826
1007.49	15900
1009.76	16002
1012.02	16072
1014.28	16118
1016.54	16152
1018.8	16268
1021.06	16188
1023.32	16346
1025.57	16598
1027.83	16498
1030.09	16600
1032.34	16902
1034.6	16844
1036.85	16748
1039.1	17172
1041.35	17050
1043.61	17350
1045.86	17282
1048.11	17232
1050.36	17408
1052.61	17406
1054.85	17492
1057.1	17498
1059.35	17702
1061.59	17622
1063.84	17704
1066.08	17850
1068.33	18008
1070.57	17950
1072.81	17950
1075.05	17958
1077.29	17968
1079.53	18008
1081.77	18066
1084.01	17930
1086.25	18134
1088.48	18056
1090.72	18008
1092.96	18104
1095.19	18038
1097.43	18056
1099.66	18012
1101.89	17994
1104.12	17958
1106.35	18112
1108.59	18124
1110.81	18134
1113.04	18154
1115.27	18188
1117.5	18192
1119.73	18204
1121.95	18176
1124.18	18152
1126.4	18382
1128.63	18304
1130.85	18134
1133.07	18234
1135.29	18276
1137.51	18516
1139.73	18480
1141.95	18472
1144.17	18460
1146.39	18514
1148.61	18682
1150.82	18582
1153.04	18528
1155.26	18684
1157.47	18550
1159.68	18714
1161.9	18458
1164.11	18600
1166.32	18658
1168.53	18666
1170.74	18532
1172.95	18436
1175.16	18622
1177.37	18444
1179.58	18692
1181.78	18394
1183.99	18260
1186.19	18316
1188.4	18270
1190.6	17992
1192.8	18104
1195.01	18044
1197.21	17915.9
1199.41	17832.3
1201.61	17903.6
1203.81	17921.3
1206.01	17814.4
1208.2	17745
1210.4	17583.4
1212.6	17582.5
1214.8	17458
1216.99	17653.2
1219.18	17421.5
1221.38	17343.9
1223.57	17369.4
1225.76	17192
1227.96	17175.3
1230.15	17088.1
1232.34	17095.2
1234.53	17104.7
1236.71	16980.2
1238.9	16965.1
1241.09	16931.7
1243.28	16886.7
1245.46	16767.4
1247.65	16697.4
1249.83	16737.7
1252.02	16684.4
1254.2	16709.1
1256.38	16546.9
1258.56	16596.7
1260.74	16493.1
1262.92	16448.8
1265.1	16399.6
1267.28	16381
1269.46	16367.6
1271.64	16371.2
1273.82	16231.6
1275.99	16201.4
1278.17	16113.1
1280.34	16180.7
1282.52	16065.8
1284.69	15996.7
1286.86	16016.5
1289.03	15850.6
1291.21	15932
1293.38	15734.5
1295.55	15766.3
1297.71	15652.6
1299.88	15529.8
1302.05	15452.5
1304.22	15573.9
1306.38	15473
1308.43	15270
1310.61	15318
1312.78	15278
1314.96	15080
1317.13	14904
1319.3	14984
1321.48	14756
1323.65	14778
1325.82	14744
1327.99	14576
1330.16	14522
1332.33	14562
1334.5	14430
1336.66	14322
1338.83	14242
1341	14248
1343.16	14128
1345.33	14104
1347.49	14072
1349.65	13904
1351.82	13860
1353.98	13768
1356.14	13466
1358.3	13630
1360.46	13566
1362.62	13504
1364.78	13424
1366.94	13384
1369.09	13406
1371.25	13320
1373.41	13084
1375.56	13142
1377.72	13172
1379.87	13124
1382.02	13030
1384.17	12934
1386.33	12852
1388.48	12766
1390.63	12886
1392.78	12568
1394.93	12708
1397.07	12680
1399.22	12698
1401.37	12400
1403.52	12464
1405.66	12410
1407.81	12430
1409.95	12316
1412.09	12252
1414.24	12164
1416.38	12208
1418.52	12238
1420.66	12168
1422.8	12010
1424.94	12096
1427.08	12038
1429.22	11864
1431.35	12040
1433.49	11890
1435.63	11678
1437.76	11718
1439.9	11790
1442.03	11650
1444.17	11694
1446.3	11802
1448.43	11552
1450.56	11606
1452.69	11516
1454.82	11544
1456.95	11538
1459.08	11366
1461.21	11408
1463.34	11268
1465.46	11256
1467.59	11396
1469.71	11268
1471.84	11184
1473.96	11334
1476.08	11164
1478.21	11298
1480.33	11098
1482.45	11062
1484.57	11206
1486.69	11100
1488.81	11072
1490.93	11040
1493.05	10910
1495.16	11000
1497.28	10958
1499.4	10942
1501.51	10860
1503.63	10870
1505.74	10828
1507.85	10602
1509.97	10700
1512.08	10648
1514.19	10644
1516.3	10602
1518.41	10490
1520.52	10514
1522.63	10608
1524.73	10322
1526.84	10512
1528.95	10336
1531.06	10284
1533.16	10370
1535.26	10396
1537.37	10246
1539.47	10176
1541.57	10280
1543.68	10136
1545.78	10190
1547.88	10132
1549.98	10038
1552.08	10036
1554.18	9984
1556.27	9986
1558.37	9890
1560.47	9910
1562.56	9932
1564.66	9862
1566.75	9974
1568.85	9922
1570.94	9700
1573.03	9698
1575.13	9926
1577.22	9760
1579.31	9630
1581.4	9888
1583.49	9766
1585.58	9734
1587.66	9710
1589.75	9720
1591.84	9530
1593.93	9598
1596.01	9616
1598.1	9694
1600.18	9632
1602.26	9772
1604.35	9680
1606.43	9596
1608.51	9550
1610.59	9506
1612.67	9526
1614.75	9672
1616.83	9500
1618.91	9554
1620.99	9468
1623.06	9520
1625.14	9564
1627.21	9420
1629.29	9458
1631.36	9410
1633.44	9320
1635.51	9408
1637.58	9392
1639.66	9276
1641.73	9386
1643.8	9294
1645.87	9306
1647.94	9248
1650	9252
1652.07	9204
1654.14	9204
1656.21	9148
1658.27	9170
1660.34	9152
1662.4	9070
1664.47	9230
1666.53	8952
1668.59	9054
1670.66	9078
1672.72	8976
1674.78	9010
1676.84	9042
1678.9	8882
1680.96	8924
1683.01	8926
1685.07	8878
1687.13	8702
1689.19	8762
1691.24	8808
1693.3	8780
1695.35	8840
1697.4	8782
1699.46	8738
1701.51	8776
1703.56	8550
1705.61	8686
1707.66	8634
1709.71	8628
1711.76	8616
1713.81	8456
1715.86	8558
1717.91	8666
1719.95	8498
1722	8522
1724.04	8424
1726.09	8360
1728.13	8472
1730.18	8374
1732.22	8442
1734.26	8460
1736.3	8310
1738.34	8330
1740.38	8466
1742.42	8346
1744.46	8380
1746.5	8390
1748.54	8458
1750.58	8342
1752.61	8398
1754.65	8354
1756.68	8380
1758.72	8352
1760.75	8302
1762.79	8226
1764.82	8226
1766.85	8330
1768.88	8234
1770.91	8284
1772.94	8288
1774.97	8224
1777	8254
1779.03	8354
1781.06	8236
1783.09	8208
1785.11	8244
1787.14	8228
1789.16	8266
1791.19	8174
1793.21	8086
1795.23	8132
1797.26	8118
1799.28	8040
1801.3	8088
1803.32	8098
1805.34	8006
1807.36	8152
1809.38	8046
1811.4	7986
1813.42	7964
1815.43	8078
1817.45	8086
1819.47	7996
1821.48	7998
1823.49	7952
1825.51	7894
1827.52	7940
1829.54	7990
1831.55	7976
1833.56	7834
1835.57	7866
1837.58	7888
1839.59	7888
1841.6	7828
1843.61	7862
1845.61	7732
1847.62	7642
1849.63	7792
1851.63	7712
1853.64	7734
1855.64	7780
1857.65	7724
1859.65	7698
1861.65	7692
1863.65	7756
1865.66	7760
1867.66	7568
1869.66	7592
1871.66	7534
1873.66	7606
1875.65	7506
1877.65	7608
1879.65	7532
1881.65	7582
1883.64	7538
1885.64	7626
1887.63	7578
1889.63	7634
1891.62	7510
1893.61	7448
1895.6	7466
1897.6	7458
1899.59	7442
1901.58	7486
1903.57	7538
1905.56	7560
1907.54	7504
1909.53	7388
1911.52	7618
1913.51	7590
1915.49	7560
1917.48	7470
1919.46	7410
1921.45	7380
1923.43	7436
1925.41	7380
1927.4	7428
1929.38	7314
1931.36	7390
1933.34	7332
1935.32	7438
1937.3	7362
1939.28	7422
1941.26	7264
1943.23	7388
1945.21	7302
1947.19	7336
1949.16	7438
1951.14	7208
1953.11	7222
1955.09	7346
1957.06	7294
1959.03	7156
1961	7248
1962.98	7224
1964.95	7188
1966.92	7216
1968.89	7216
1970.85	7168
1972.82	7268
1974.79	7246
1976.76	7080
1978.73	7120
1980.69	7054
1982.66	7132
1984.62	7200
1986.59	7166
1988.55	7154
1990.51	7098
1992.47	7120
1994.44	6984
1996.4	6996
1998.36	7060
2000.32	7058
2002.28	6936
2004.24	7084
2006.19	6994
2008.15	7004
2010.11	7004
2012.06	7034
2014.02	6950
2015.98	7048
2017.93	6876
2019.88	6894
2021.84	6976
2023.79	6932
2025.74	6928
2027.69	7098
2029.65	7002
2031.6	6912
2033.55	6896
2035.5	6814
2037.44	6798
2039.39	6848
2041.34	6872
2043.29	7028
2045.23	6872
2047.18	6904
2049.12	6910
2051.07	6816
2053.01	6762
2054.95	6796
2056.9	6770
2058.84	6752
2060.78	6772
2062.72	6826
2064.66	6832
2066.6	6760
2068.54	6818
2070.48	6604
2072.42	6672
2074.35	6712
2076.29	6666
2078.23	6694
2080.16	6658
2082.1	6676
2084.03	6702
2085.96	6674
2087.9	6670
2089.83	6554
2091.76	6586
2093.69	6740
2095.62	6640
2097.55	6618
2099.48	6568
2101.41	6642
2103.34	6636
2105.27	6558
2107.2	6522
2109.12	6518
2111.05	6594
2112.98	6528
2114.9	6510
2116.82	6556
2118.75	6542
2120.67	6502
2122.59	6534
2124.52	6630
2126.44	6522
2128.36	6460
2130.28	6520
2132.2	6338
2134.12	6510
2136.04	6466
2137.95	6490
2139.87	6430
2141.79	6490
2143.7	6450
2145.62	6424.02
2147.53	6403.47
2149.45	6325.65
2151.36	6268.63
2153.28	6359.88
2155.19	6299.35
2157.1	6290.01
2159.01	6361.59
2160.92	6277.29
2162.83	6266.75
2164.74	6319.48
2166.65	6274.68
2168.56	6210.09
2170.47	6241.24
2172.38	6229.06
2174.28	6195.07
2176.19	6205.37
2178.09	6146.3
2180	6156.81
2181.9	6160.35
2183.81	6165.94
2185.71	6120.9
2187.61	6145.68
2189.52	6108.81
2191.42	6083.5
2193.32	6050.89
2195.22	6114.89
2197.12	6075.34
2199.02	6048.23
2200.92	6132.02
2202.82	6082.39
2204.71	6068.94
2206.61	6120.81
2208.51	6097.34
2210.4	6069.66
2212.3	6086.06
2214.19	5994.34
2216.09	6049.9
2217.98	6028.67
2219.87	6010.11
2221.77	6041.37
2223.66	6025.9
2225.55	6014.73
2227.44	6067.32
2229.33	6023.38
2231.22	6049.03
2233.11	6074.18
2235	6050.27
2236.88	6025.51
2238.77	6058.55
2240.66	6055.07
2242.07	6112
2243.97	6052
2245.87	5990
2247.76	5964
2249.65	6018
2251.55	5982
2253.44	6058
2255.33	6048
2257.22	6044
2259.12	5952
2261.01	5950
2262.9	6016
2264.78	5982
2266.67	5892
2268.56	5984
2270.45	5906
2272.34	5962
2274.22	5986
2276.11	5928
2277.99	5988
2279.88	5950
2281.76	6036
2283.65	5894
2285.53	5856
2287.41	5936
2289.3	5904
2291.18	5908
2293.06	5858
2294.94	5820
2296.82	5986
2298.7	5812
2300.58	5902
2302.46	5814
2304.33	5764
2306.21	5788
2308.09	5836
2309.96	5760
2311.84	5812
2313.71	5816
2315.59	5758
2317.46	5802
2319.33	5842
2321.21	5714
2323.08	5756
2324.95	5744
2326.82	5810
2328.69	5782
2330.56	5670
2332.43	5720
2334.3	5734
2336.17	5744
2338.03	5710
2339.9	5706
2341.77	5790
2343.63	5678
2345.5	5620
2347.36	5680
2349.23	5594
2351.09	5636
2352.95	5574
2354.82	5668
2356.68	5612
2358.54	5638
2360.4	5652
2362.26	5582
2364.12	5724
2365.98	5626
2367.84	5574
2369.7	5560
2371.56	5532
2373.41	5588
2375.27	5552
2377.12	5532
2378.98	5498
2380.84	5528
2382.69	5548
2384.54	5538
2386.4	5444
2388.25	5404
2390.1	5458
2391.95	5454
2393.8	5434
2395.65	5358
2397.5	5462
2399.35	5396
2401.2	5400
2403.05	5384
2404.9	5464
2406.75	5436
2408.59	5466
2410.44	5430
2412.28	5464
2414.13	5406
2415.97	5384
2417.82	5258
2419.66	5314
2421.5	5402
2423.35	5378
2425.19	5290
2427.03	5260
2428.87	5330
2430.71	5258
2432.55	5252
2434.39	5408
2436.23	5222
2438.06	5194
2439.9	5330
2441.74	5252
2443.57	5112
2445.41	5228
2447.24	5268
2449.08	5176
2450.91	5190
2452.75	5232
2454.58	5178
2456.41	5198
2458.24	5144
2460.08	5162
2461.91	5178
2463.74	5142
2465.57	5144
2467.4	5106
2469.22	5050
2471.05	5178
2472.88	5058
2474.71	5082
2476.53	5206
2478.36	5098
2480.19	5076
2482.01	5084
2483.83	5056
2485.66	5074
2487.48	5078
2489.3	4996
2491.13	5006
2492.95	5038
2494.77	4964
2496.59	4992
2498.41	4940
2500.23	4994
2502.05	4956
2503.87	4838
2505.68	5014
2507.5	4852
2509.32	4884
2511.14	4904
2512.95	4836
2514.77	4860
2516.58	4826
2518.39	4850
2520.21	4818
2522.02	4822
2523.83	4782
2525.65	4878
2527.46	4802
2529.27	4742
2531.08	4816
2532.89	4806
2534.7	4766
2536.51	4766
2538.32	4694
2540.12	4744
2541.93	4728
2543.74	4700
2545.54	4804
2547.35	4620
2549.15	4658
2550.96	4654
2552.76	4694
2554.56	4566
2556.37	4642
2558.17	4622
2559.97	4600
2561.77	4620
2563.58	4672
2565.38	4544
2567.18	4554
2568.97	4540
2570.77	4536
2572.57	4564
2574.37	4528
2576.17	4594
2577.96	4428
2579.76	4528
2581.55	4500
2583.35	4508
2585.14	4388
2586.94	4432
2588.73	4454
2590.52	4414
2592.32	4448
2594.11	4348
2595.9	4404
2597.69	4312
2599.48	4404
2601.27	4450
2603.06	4416
2604.85	4334
2606.64	4360
2608.42	4364
2610.21	4320
2612	4374
2613.78	4256
2615.57	4328
2617.36	4248
2619.14	4326
2620.92	4190
2622.71	4230
2624.49	4186
2626.27	4212
2628.05	4216
2629.84	4260
2631.62	4242
2633.4	4132
2635.18	4170
2636.96	4162
2638.74	4156
2640.51	4158
2642.29	4130
2644.07	4096
2645.85	4110
2647.62	4074
2649.4	4064
2651.17	4098
2652.95	4086
2654.72	4082
2656.5	3992
2658.27	3998
2660.04	4044
2661.81	4012
2663.58	4054
2665.35	4036
2667.13	3986
2668.9	4036
2670.66	4016
2672.43	4020
2674.2	3938
2675.97	3956
2677.74	3916
2679.5	3926
2681.27	4038
2683.04	3962
2684.8	3890
2686.57	3962
2688.33	3908
2690.09	3848
2691.86	3844
2693.62	3786
2695.38	3854
2697.15	3828
2698.91	3768
2700.67	3910
2702.43	3914
2704.19	3754
2705.95	3782
2707.7	3740
2709.46	3766
2711.22	3790
2712.98	3808
2714.73	3722
2716.49	3724
2718.25	3754
2720	3666
2721.76	3748
2723.51	3658
2725.26	3776
2727.02	3580
2728.77	3642
2730.52	3710
2732.27	3646
2734.02	3584
2735.77	3640
2737.52	3688
2739.27	3552
2741.02	3576
2742.77	3596
2744.52	3518
2746.27	3596
2748.01	3524
2749.76	3552
2751.51	3456
2753.25	3454
2755	3494
2756.74	3528
2758.48	3520
2760.23	3472
2761.97	3450
2763.71	3476
2765.45	3422
2767.19	3426
2768.94	3438
2770.68	3400
2772.42	3430
2774.16	3466
2775.89	3402
2777.63	3392
2779.37	3420
2781.11	3370
2782.84	3422
2784.58	3388
2786.32	3356
2788.05	3294
2789.79	3398
2791.52	3326
2793.25	3322
2794.99	3310
2796.72	3288
2798.45	3240
2800.18	3266
2801.92	3264
2803.65	3243
2805.38	3204
2807.11	3276
2808.84	3170
2810.57	3242
2812.29	3242
2814.02	3214
2815.75	3238
2817.47	3084
2819.2	3200
2820.93	3108
2822.65	3146
2824.38	3204
2826.1	3140
2827.82	3144
2829.55	3172
2831.27	3102
2832.99	3066
2834.71	3096
2836.44	3080
2838.16	3072
2839.88	3142
2841.6	3056
2843.32	2992
2845.03	3058
2846.75	3040
2848.47	3032
2850.19	2970
2851.9	3068
2853.62	3000
2855.34	2940
2857.05	2962
2858.77	2958
2860.48	2934
2862.19	2944
2863.91	2962
2865.62	2860
2867.33	2878
2869.04	2914
2870.76	2898
2872.47	2906
2874.18	2940
2875.89	2918
2877.6	2858
2879.31	2852
2881.01	2874
2882.72	2828
2884.43	2850
2886.14	2850
2887.84	2816
2889.55	2808
2891.25	2810
2892.96	2780
2894.66	2704
2896.37	2800
2898.07	2766
2899.77	2770
2901.48	2796
2903.18	2832
2904.88	2734
2906.58	2784
2908.28	2770
2909.98	2718
2911.68	2738
2913.38	2698
2915.08	2712
2916.78	2728
2918.47	2724
2920.17	2706
2921.87	2684
2923.56	2694
2925.26	2724
2926.95	2684
2928.65	2652
2930.34	2662
2932.04	2666
2933.73	2688
2935.42	2642
2937.11	2608
2938.81	2682
2940.5	2676
2942.19	2694
2943.88	2648
2945.57	2576
2947.26	2652
2948.95	2602
2950.64	2570
2952.32	2594
2954.01	2570
2955.7	2598
2957.38	2590
2959.07	2590
2960.75	2570
2962.44	2516
2964.12	2504
2965.81	2520
2967.49	2500
2969.17	2502
2970.86	2516
2972.54	2464
2974.22	2468
2975.9	2480
2977.58	2474
2979.26	2456
2980.94	2468
2982.62	2432
2984.3	2416
2985.98	2410
2987.66	2440
2989.33	2424
2991.01	2346
2992.69	2416
2994.36	2372
2996.04	2424
2997.71	2452
2999.39	2404