File: muestras/tallo/2/Organic_05.txt
#Acq. time (s)=	10
#Accumulations=	1
#Range (cm-¹)=	100...3000
#Windows=	3
#Autofocus=	Off
#AutoExposure=	Off
#Spike filter=	Off
#Delay time (s)=	0
#Binning=	1
#Readout mode=	Signal
#DeNoise=	Off
#ICS correction=	Off
#Dark correction=	Off
#Inst. Process=	Off
#Instrument=	LabRAM HR Evol
#Detector=	Syncerity OE
#Objective=	x100_VIS
#Grating=	600 (500nm)
#ND Filter=	3.2%
#Laser=	633nm_Edge
#Hole=	100.021
#Range=	Visible
#Project=	Omar
#Sample=	26-06-23
#Site=	2
#Title=	Organic
#Remark=
#Date=	26.06.2023 16:19
#Acquired=	26.06.2023 16:19:57
101.018	4142
103.586	4152
106.152	4180
108.717	4182
111.281	4214
113.845	4264
116.407	4208
118.969	4270
121.53	4230
124.09	4232
126.649	4226
129.207	4262
131.765	4368
134.321	4306
136.877	4446
139.432	4410
141.985	4354
144.538	4354
147.09	4352
149.641	4426
152.191	4438
154.741	4504
157.289	4548
159.837	4450
162.385	4472
164.93	4416
167.476	4562
170.019	4572
172.562	4530
175.105	4504
177.646	4500
180.188	4636
182.727	4570
185.266	4618
187.804	4558
190.342	4570
192.878	4644
195.413	4762
197.948	4732
200.481	4742
203.014	4700
205.546	4758
208.077	4786
210.608	4810
213.137	4874
215.666	4910
218.194	4886
220.721	4862
223.247	4870
225.772	4966
228.295	4874
230.819	4938
233.342	5026
235.864	5026
238.384	5040
240.904	5056
243.423	5074
245.941	5140
248.46	5156
250.975	5204
253.492	5160
256.006	5120
258.519	5110
261.033	5168
263.545	5216
266.057	5116
268.567	5156
271.076	5200
273.585	5180
276.094	5130
278.601	5140
281.107	5226
283.612	5288
286.116	5264
288.62	5302
291.123	5376
293.625	5362
296.126	5380
298.626	5412
301.126	5418
303.625	5380
306.122	5484
308.62	5540
311.114	5572
313.61	5564
316.105	5562
318.599	5586
321.09	5582
323.583	5536
326.073	5706
328.563	5572
331.053	5552
333.541	5680
336.029	5696
338.515	5664
341.001	5852
343.486	5726
345.97	5770
348.453	5742
350.936	5750
353.418	5844
355.898	5826
358.378	5872
360.858	5836
363.336	6024
365.813	5734
368.29	5968
370.766	5928
373.241	5922
375.715	5928
378.188	5914
380.66	5962
383.132	5962
385.603	5972
388.072	5988
390.541	5978
393.01	6002
395.477	6050
397.943	6096
400.409	6038
402.875	6094
405.338	6182
407.802	6124
410.263	6254
412.725	6206
415.185	6302
417.646	6370
420.104	6394
422.564	6438
425.02	6462
427.477	6504
429.933	6476
432.388	6580
434.841	6612
437.294	6590
439.748	6694
442.199	6582
444.65	6694
447.1	6660
449.549	6632
451.997	6690
454.445	6726
456.891	6632
459.337	6696
461.782	6748
464.227	6674
466.669	6804
469.112	6692
471.554	6718
473.995	6748
476.434	6836
478.874	6892
481.312	6920
483.749	6884
486.186	7068
488.622	7016
491.057	6986
493.491	7032
495.925	7100
498.357	7004
500.789	7166
503.221	7124
505.65	7116
508.079	7172
510.509	7264
512.936	7238
515.363	7210
517.789	7286
520.214	7386
522.638	7226
525.062	7402
527.485	7216
529.907	7360
532.328	7308
534.748	7326
537.168	7370
539.587	7334
542.005	7472
544.423	7432
546.838	7470
549.254	7444
551.669	7558
554.082	7554
556.496	7474
558.909	7524
561.319	7466
563.731	7660
566.14	7620
568.549	7654
570.957	7700
573.364	7744
575.771	7684
578.177	7722
580.581	7852
582.987	7848
585.39	7876
587.792	7828
590.193	7950
592.594	8036
594.996	8008
597.395	8128
599.793	8188
602.191	8222
604.588	8176
606.984	8172
609.378	8352
611.773	8200
614.167	8362
616.56	8234
618.953	8314
621.343	8592
623.734	8508
626.124	8572
628.512	8598
630.901	8722
633.289	8764
635.675	8940
638.061	8916
640.446	8816
642.831	8986
645.213	9012
647.595	9004
649.978	9028
652.359	8954
654.738	9094
657.117	9150
659.497	9206
661.875	9208
664.252	9398
666.628	9336
669.003	9406
671.378	9322
673.751	9530
676.124	9518
678.497	9524
680.868	9684
683.239	9498
685.609	9608
687.977	9632
690.346	9780
692.714	9780
695.081	9800
697.446	9862
699.812	9978
702.175	10020
704.539	10100
706.901	10140
709.264	10070
711.625	10302
713.986	10196
716.345	10380
718.705	10472
721.062	10472
723.419	10632
725.775	10638
728.132	10538
730.487	10624
732.841	10784
735.194	10766
737.546	10786
739.898	10998
742.249	10936
744.599	11032
746.949	10948
749.298	11192
751.646	11160
753.993	11120
756.34	11262
758.684	11420
761.029	11456
763.374	11474
765.716	11526
768.059	11446
770.401	11600
772.741	11636
775.082	11818
777.421	11902
779.76	11928
782.097	11956
784.434	11942
786.771	12158
789.106	12116
791.44	12252
793.775	12294
796.108	12356
798.44	12366
800.771	12544
803.102	12660
805.432	12816
807.761	12722
810.09	12852
812.417	12828
814.744	12992
817.071	13406
819.396	13348
821.721	13232
824.045	13440
826.367	13446
828.69	13562
831.012	13678
833.332	13830
835.653	13852
837.972	13982
840.29	14100
842.609	14240
844.925	14292
847.242	14290
849.557	14324
851.871	14510
854.186	14556
856.498	14618
858.81	14802
861.122	14818
863.434	15040
865.744	14998
868.053	15138
870.361	15272
872.669	15312
874.976	15350
877.282	15248
879.588	15396
881.893	15692
884.197	15776
886.5	15800
888.802	15908
891.104	15844
893.405	15814
895.706	15926
898.004	16066
900.303	16162
902.6	16324
904.898	16352
907.194	16334
909.49	16360
911.785	16502
914.08	16450
916.372	16760
918.666	16618
920.957	16972
923.248	16818
925.538	17086
927.828	17328
930.118	17250
932.406	17328
934.693	17378
936.979	17630
939.265	17584
941.55	17680
943.835	17956
946.118	17944
948.401	18152
950.682	18090
952.964	18290
955.245	18554
957.525	18564
959.803	18618
962.082	18678
964.36	18778
966.636	18890
968.913	19092
971.188	19122
973.463	19230
975.736	19214
978.009	19342
980.282	19636
982.554	19516
984.824	19524
987.095	19506
989.364	19846
991.633	19890
993.9	19724
996.167	20096
998.434	20084
1000.7	20172
1002.96	20480
1005.23	20346
1007.49	20318
1009.76	20504
1012.02	20440
1014.28	20820
1016.54	20920
1018.8	20870
1021.06	21132
1023.32	21092
1025.57	21236
1027.83	21344
1030.09	21284
1032.34	21578
1034.6	21478
1036.85	21664
1039.1	21712
1041.35	22014
1043.61	22098
1045.86	22246
1048.11	22444
1050.36	22194
1052.61	22484
1054.85	22554
1057.1	22616
1059.35	22618
1061.59	22852
1063.84	23028
1066.08	22838
1068.33	22854
1070.57	23166
1072.81	23144
1075.05	23068
1077.29	23226
1079.53	23200
1081.77	23186
1084.01	23078
1086.25	23136
1088.48	23156
1090.72	23182
1092.96	23152
1095.19	23268
1097.43	23172
1099.66	23126
1101.89	23220
1104.12	23248
1106.35	23222
1108.59	23384
1110.81	23340
1113.04	23230
1115.27	23256
1117.5	23594
1119.73	23608
1121.95	23352
1124.18	23422
1126.4	23532
1128.63	23770
1130.85	23690
1133.07	23718
1135.29	23894
1137.51	23780
1139.73	23734
1141.95	23816
1144.17	23660
1146.39	23708
1148.61	23878
1150.82	23896
1153.04	23914
1155.26	24000
1157.47	23992
1159.68	23774
1161.9	24046
1164.11	24028
1166.32	24040
1168.53	23836
1170.74	23988
1172.95	23778
1175.16	23728
1177.37	23656
1179.58	23782
1181.78	23770
1183.99	23454
1186.19	23560
1188.4	23360
1190.6	23316
1192.8	23460
1195.01	23086
1197.21	23092.2
1199.41	23087.3
1201.61	22949.5
1203.81	22831.7
1206.01	22832.1
1208.2	22789.8
1210.4	22552.7
1212.6	22429.1
1214.8	22439.5
1216.99	22362.1
1219.18	22205
1221.38	22100
1223.57	22061.5
1225.76	22080.5
1227.96	22014.2
1230.15	21866.7
1232.34	21890
1234.53	21767.4
1236.71	21690.7
1238.9	21602.4
1241.09	21596.3
1243.28	21551.3
1245.46	21413
1247.65	21349.3
1249.83	21314.1
1252.02	21272.2
1254.2	21147.6
1256.38	21137.3
1258.56	21061
1260.74	21046.3
1262.92	21008.9
1265.1	20784.7
1267.28	20739.6
1269.46	20802.4
1271.64	20684.4
1273.82	20616.6
1275.99	20550.6
1278.17	20502.7
1280.34	20277.5
1282.52	20236.6
1284.69	20236.1
1286.86	20166.5
1289.03	19997.3
1291.21	19909
1293.38	19932.5
1295.55	19844.9
1297.71	19807.6
1299.88	19511.8
1302.05	19644.1
1304.22	19262.1
1306.38	19283.6
1308.43	19286
1310.61	19300
1312.78	19080
1314.96	18842
1317.13	18888
1319.3	18596
1321.48	18660
1323.65	18474
1325.82	18514
1327.99	18334
1330.16	18188
1332.33	18066
1334.5	17992
1336.66	17770
1338.83	17804
1341	17590
1343.16	17474
1345.33	17460
1347.49	17346
1349.65	17410
1351.82	17286
1353.98	17096
1356.14	17230
1358.3	17012
1360.46	16904
1362.62	16830
1364.78	16622
1366.94	16836
1369.09	16496
1371.25	16438
1373.41	16288
1375.56	16376
1377.72	16182
1379.87	16180
1382.02	16122
1384.17	15972
1386.33	15956
1388.48	15686
1390.63	15840
1392.78	15810
1394.93	15674
1397.07	15688
1399.22	15592
1401.37	15430
1403.52	15486
1405.66	15326
1407.81	15374
1409.95	15194
1412.09	15008
1414.24	15096
1416.38	15054
1418.52	14912
1420.66	14948
1422.8	14730
1424.94	14784
1427.08	14636
1429.22	14654
1431.35	14662
1433.49	14490
1435.63	14562
1437.76	14374
1439.9	14366
1442.03	14254
1444.17	14264
1446.3	14420
1448.43	14166
1450.56	14190
1452.69	14196
1454.82	14042
1456.95	14002
1459.08	13932
1461.21	13952
1463.34	14230
1465.46	13840
1467.59	13854
1469.71	13762
1471.84	13780
1473.96	13726
1476.08	13766
1478.21	13520
1480.33	13704
1482.45	13504
1484.57	13372
1486.69	13450
1488.81	13414
1490.93	13284
1493.05	13374
1495.16	13334
1497.28	13220
1499.4	13228
1501.51	13184
1503.63	13054
1505.74	13090
1507.85	12826
1509.97	12938
1512.08	12844
1514.19	12816
1516.3	12746
1518.41	12704
1520.52	12826
1522.63	12670
1524.73	12612
1526.84	12598
1528.95	12640
1531.06	12444
1533.16	12386
1535.26	12356
1537.37	12358
1539.47	12384
1541.57	12292
1543.68	12230
1545.78	12110
1547.88	12040
1549.98	12054
1552.08	12108
1554.18	12158
1556.27	12076
1558.37	12040
1560.47	12030
1562.56	11932
1564.66	11884
1566.75	11834
1568.85	11958
1570.94	11774
1573.03	11634
1575.13	11608
1577.22	11712
1579.31	11694
1581.4	11718
1583.49	11754
1585.58	11582
1587.66	11528
1589.75	11628
1591.84	11644
1593.93	11542
1596.01	11572
1598.1	11490
1600.18	11532
1602.26	11492
1604.35	11524
1606.43	11542
1608.51	11386
1610.59	11456
1612.67	11398
1614.75	11410
1616.83	11424
1618.91	11556
1620.99	11456
1623.06	11228
1625.14	11322
1627.21	11388
1629.29	11304
1631.36	11328
1633.44	11266
1635.51	11266
1637.58	11172
1639.66	11288
1641.73	11106
1643.8	11086
1645.87	11174
1647.94	11212
1650	10928
1652.07	11044
1654.14	10916
1656.21	11002
1658.27	10898
1660.34	11032
1662.4	10824
1664.47	10832
1666.53	10732
1668.59	10892
1670.66	10758
1672.72	10708
1674.78	10594
1676.84	10722
1678.9	10700
1680.96	10430
1683.01	10502
1685.07	10608
1687.13	10568
1689.19	10594
1691.24	10592
1693.3	10516
1695.35	10452
1697.4	10360
1699.46	10484
1701.51	10232
1703.56	10476
1705.61	10238
1707.66	10128
1709.71	10216
1711.76	10292
1713.81	10276
1715.86	10206
1717.91	10238
1719.95	10198
1722	10154
1724.04	10168
1726.09	10118
1728.13	10110
1730.18	10000
1732.22	10032
1734.26	9980
1736.3	10048
1738.34	10042
1740.38	10028
1742.42	9956
1744.46	9938
1746.5	10044
1748.54	9888
1750.58	9938
1752.61	10112
1754.65	9926
1756.68	9858
1758.72	9962
1760.75	9924
1762.79	9786
1764.82	9914
1766.85	9856
1768.88	9796
1770.91	9884
1772.94	9806
1774.97	9870
1777	9672
1779.03	9746
1781.06	9666
1783.09	9820
1785.11	9742
1787.14	9656
1789.16	9768
1791.19	9766
1793.21	9650
1795.23	9754
1797.26	9514
1799.28	9606
1801.3	9682
1803.32	9556
1805.34	9624
1807.36	9612
1809.38	9616
1811.4	9520
1813.42	9540
1815.43	9508
1817.45	9476
1819.47	9428
1821.48	9556
1823.49	9348
1825.51	9466
1827.52	9436
1829.54	9376
1831.55	9274
1833.56	9248
1835.57	9252
1837.58	9240
1839.59	9324
1841.6	9352
1843.61	9180
1845.61	9184
1847.62	9210
1849.63	9204
1851.63	9210
1853.64	9154
1855.64	9222
1857.65	9102
1859.65	9146
1861.65	9124
1863.65	9068
1865.66	9174
1867.66	9062
1869.66	9040
1871.66	9088
1873.66	9018
1875.65	9018
1877.65	8950
1879.65	8958
1881.65	8910
1883.64	8938
1885.64	9028
1887.63	8902
1889.63	8938
1891.62	8916
1893.61	8818
1895.6	8804
1897.6	8748
1899.59	8950
1901.58	8964
1903.57	8906
1905.56	8912
1907.54	8906
1909.53	8946
1911.52	8904
1913.51	8898
1915.49	8876
1917.48	8908
1919.46	8828
1921.45	8798
1923.43	8820
1925.41	8748
1927.4	8720
1929.38	8744
1931.36	8778
1933.34	8800
1935.32	8744
1937.3	8860
1939.28	8714
1941.26	8670
1943.23	8622
1945.21	8744
1947.19	8740
1949.16	8750
1951.14	8632
1953.11	8688
1955.09	8668
1957.06	8628
1959.03	8492
1961	8640
1962.98	8638
1964.95	8532
1966.92	8532
1968.89	8510
1970.85	8422
1972.82	8452
1974.79	8594
1976.76	8420
1978.73	8530
1980.69	8522
1982.66	8478
1984.62	8474
1986.59	8550
1988.55	8348
1990.51	8498
1992.47	8464
1994.44	8434
1996.4	8470
1998.36	8326
2000.32	8372
2002.28	8370
2004.24	8312
2006.19	8322
2008.15	8328
2010.11	8368
2012.06	8326
2014.02	8352
2015.98	8238
2017.93	8272
2019.88	8374
2021.84	8218
2023.79	8232
2025.74	8142
2027.69	8232
2029.65	8144
2031.6	8278
2033.55	8160
2035.5	8170
2037.44	8106
2039.39	8204
2041.34	8238
2043.29	8196
2045.23	8132
2047.18	8088
2049.12	8090
2051.07	8270
2053.01	8270
2054.95	8178
2056.9	8044
2058.84	8102
2060.78	8156
2062.72	8112
2064.66	8016
2066.6	7964
2068.54	7884
2070.48	7894
2072.42	7938
2074.35	7926
2076.29	7982
2078.23	8008
2080.16	8044
2082.1	7920
2084.03	7994
2085.96	7978
2087.9	7938
2089.83	7918
2091.76	7954
2093.69	7836
2095.62	7782
2097.55	7936
2099.48	7858
2101.41	7850
2103.34	7870
2105.27	7734
2107.2	7844
2109.12	7834
2111.05	7822
2112.98	7784
2114.9	7818
2116.82	7712
2118.75	7690
2120.67	7782
2122.59	7770
2124.52	7748
2126.44	7822
2128.36	7684
2130.28	7770
2132.2	7708
2134.12	7712
2136.04	7730
2137.95	7792
2139.87	7686
2141.79	7704
2143.7	7504
2145.62	7559.72
2147.53	7696.22
2149.45	7552.63
2151.36	7577.56
2153.28	7606.33
2155.19	7581.52
2157.1	7513.07
2159.01	7456.99
2160.92	7449.6
2162.83	7462.43
2164.74	7378.13
2166.65	7402.5
2168.56	7438.7
2170.47	7456.13
2172.38	7454.82
2174.28	7430.5
2176.19	7436.81
2178.09	7359.08
2180	7354.23
2181.9	7366.49
2183.81	7309.8
2185.71	7251.64
2187.61	7318.4
2189.52	7276.87
2191.42	7321.02
2193.32	7238.05
2195.22	7255.48
2197.12	7204.21
2199.02	7303.12
2200.92	7231.89
2202.82	7303.43
2204.71	7210.43
2206.61	7234.86
2208.51	7195.34
2210.4	7247.96
2212.3	7158
2214.19	7234.61
2216.09	7150.03
2217.98	7165.27
2219.87	7178.34
2221.77	7181.51
2223.66	7180.98
2225.55	7190.28
2227.44	7153.74
2229.33	7192.05
2231.22	7218.87
2233.11	7162.56
2235	7166.34
2236.88	7119.8
2238.77	7212.33
2240.66	7150.95
2242.07	7244
2243.97	7130
2245.87	7280
2247.76	7148
2249.65	7192
2251.55	7160
2253.44	7090
2255.33	7074
2257.22	7182
2259.12	7130
2261.01	7222
2262.9	7016
2264.78	7076
2266.67	7098
2268.56	7108
2270.45	7006
2272.34	7120
2274.22	7156
2276.11	7016
2277.99	7104
2279.88	7116
2281.76	7114
2283.65	7014
2285.53	7036
2287.41	7050
2289.3	6984
2291.18	6982
2293.06	6874
2294.94	6958
2296.82	6944
2298.7	7024
2300.58	6870
2302.46	6906
2304.33	6972
2306.21	6940
2308.09	6938
2309.96	6856
2311.84	6860
2313.71	6908
2315.59	6760
2317.46	6908
2319.33	6834
2321.21	6828
2323.08	6742
2324.95	6934
2326.82	6826
2328.69	6766
2330.56	6848
2332.43	6764
2334.3	6764
2336.17	6852
2338.03	6774
2339.9	6778
2341.77	6796
2343.63	6812
2345.5	6704
2347.36	6764
2349.23	6724
2351.09	6722
2352.95	6694
2354.82	6662
2356.68	6844
2358.54	6744
2360.4	6716
2362.26	6712
2364.12	6666
2365.98	6598
2367.84	6610
2369.7	6588
2371.56	6616
2373.41	6656
2375.27	6518
2377.12	6608
2378.98	6490
2380.84	6530
2382.69	6564
2384.54	6556
2386.4	6584
2388.25	6452
2390.1	6560
2391.95	6548
2393.8	6626
2395.65	6508
2397.5	6478
2399.35	6440
2401.2	6556
2403.05	6452
2404.9	6462
2406.75	6402
2408.59	6444
2410.44	6420
2412.28	6320
2414.13	6338
2415.97	6296
2417.82	6344
2419.66	6438
2421.5	6320
2423.35	6290
2425.19	6334
2427.03	6246
2428.87	6252
2430.71	6290
2432.55	6268
2434.39	6248
2436.23	6208
2438.06	6242
2439.9	6248
2441.74	6238
2443.57	6258
2445.41	6300
2447.24	6176
2449.08	6146
2450.91	6160
2452.75	6188
2454.58	6112
2456.41	6154
2458.24	6200
2460.08	6170
2461.91	6088
2463.74	6194
2465.57	6118
2467.4	6032
2469.22	6098
2471.05	6140
2472.88	6050
2474.71	6090
2476.53	6062
2478.36	6118
2480.19	6106
2482.01	6052
2483.83	6046
2485.66	5998
2487.48	5936
2489.3	6000
2491.13	6050
2492.95	6024
2494.77	5850
2496.59	5968
2498.41	6016
2500.23	5852
2502.05	5786
2503.87	5822
2505.68	5828
2507.5	5816
2509.32	5742
2511.14	5840
2512.95	5784
2514.77	5766
2516.58	5712
2518.39	5766
2520.21	5750
2522.02	5804
2523.83	5788
2525.65	5778
2527.46	5664
2529.27	5628
2531.08	5604
2532.89	5660
2534.7	5684
2536.51	5610
2538.32	5640
2540.12	5666
2541.93	5670
2543.74	5626
2545.54	5600
2547.35	5556
2549.15	5620
2550.96	5512
2552.76	5424
2554.56	5562
2556.37	5580
2558.17	5440
2559.97	5526
2561.77	5426
2563.58	5480
2565.38	5464
2567.18	5390
2568.97	5382
2570.77	5506
2572.57	5376
2574.37	5430
2576.17	5408
2577.96	5344
2579.76	5290
2581.55	5308
2583.35	5312
2585.14	5318
2586.94	5258
2588.73	5284
2590.52	5260
2592.32	5236
2594.11	5314
2595.9	5214
2597.69	5200
2599.48	5144
2601.27	5160
2603.06	5188
2604.85	5188
2606.64	5208
2608.42	5132
2610.21	5102
2612	5088
2613.78	5174
2615.57	5042
2617.36	5062
2619.14	5182
2620.92	5066
2622.71	5104
2624.49	5032
2626.27	5080
2628.05	4954
2629.84	5018
2631.62	4948
2633.4	4968
2635.18	4976
2636.96	4972
2638.74	4906
2640.51	4942
2642.29	4904
2644.07	4828
2645.85	4864
2647.62	4828
2649.4	4958
2651.17	4852
2652.95	4848
2654.72	4884
2656.5	4782
2658.27	4836
2660.04	4758
2661.81	4794
2663.58	4754
2665.35	4732
2667.13	4758
2668.9	4722
2670.66	4718
2672.43	4736
2674.2	4824
2675.97	4724
2677.74	4634
2679.5	4804
2681.27	4712
2683.04	4664
2684.8	4686
2686.57	4696
2688.33	4626
2690.09	4584
2691.86	4660
2693.62	4592
2695.38	4600
2697.15	4522
2698.91	4506
2700.67	4598
2702.43	4580
2704.19	4534
2705.95	4484
2707.7	4536
2709.46	4486
2711.22	4392
2712.98	4468
2714.73	4414
2716.49	4382
2718.25	4452
2720	4464
2721.76	4376
2723.51	4376
2725.26	4292
2727.02	4510
2728.77	4292
2730.52	4294
2732.27	4324
2734.02	4320
2735.77	4274
2737.52	4322
2739.27	4306
2741.02	4210
2742.77	4296
2744.52	4234
2746.27	4202
2748.01	4182
2749.76	4230
2751.51	4196
2753.25	4202
2755	4154
2756.74	4100
2758.48	4144
2760.23	4128
2761.97	4132
2763.71	4136
2765.45	4122
2767.19	4044
2768.94	4042
2770.68	4034
2772.42	4070
2774.16	4048
2775.89	4104
2777.63	3998
2779.37	3996
2781.11	4058
2782.84	4050
2784.58	4012
2786.32	3966
2788.05	3880
2789.79	4014
2791.52	3960
2793.25	3990
2794.99	3948
2796.72	3914
2798.45	3952
2800.18	3878
2801.92	3874
2803.65	3873
2805.38	3812
2807.11	3928
2808.84	3862
2810.57	3764
2812.29	3900
2814.02	3846
2815.75	3750
2817.47	3774
2819.2	3830
2820.93	3740
2822.65	3710
2824.38	3802
2826.1	3764
2827.82	3678
2829.55	3698
2831.27	3654
2832.99	3626
2834.71	3652
2836.44	3634
2838.16	3690
2839.88	3662
2841.6	3628
2843.32	3624
2845.03	3544
2846.75	3558
2848.47	3516
2850.19	3634
2851.9	3580
2853.62	3562
2855.34	3522
2857.05	3514
2858.77	3498
2860.48	3538
2862.19	3532
2863.91	3496
2865.62	3380
2867.33	3378
2869.04	3454
2870.76	3500
2872.47	3396
2874.18	3400
2875.89	3408
2877.6	3372
2879.31	3414
2881.01	3390
2882.72	3352
2884.43	3388
2886.14	3360
2887.84	3318
2889.55	3364
2891.25	3310
2892.96	3306
2894.66	3300
2896.37	3286
2898.07	3336
2899.77	3264
2901.48	3266
2903.18	3294
2904.88	3254
2906.58	3266
2908.28	3266
2909.98	3320
2911.68	3204
2913.38	3236
2915.08	3224
2916.78	3192
2918.47	3224
2920.17	3258
2921.87	3214
2923.56	3152
2925.26	3130
2926.95	3128
2928.65	3120
2930.34	3184
2932.04	3164
2933.73	3070
2935.42	3156
2937.11	3126
2938.81	3118
2940.5	3134
2942.19	3076
2943.88	3094
2945.57	3066
2947.26	3094
2948.95	3028
2950.64	3036
2952.32	3044
2954.01	3042
2955.7	3038
2957.38	3010
2959.07	3014
2960.75	3034
2962.44	2992
2964.12	3038
2965.81	2888
2967.49	2944
2969.17	2992
2970.86	2890
2972.54	2962
2974.22	2930
2975.9	2962
2977.58	2944
2979.26	2994
2980.94	2972
2982.62	2958
2984.3	2916
2985.98	2890
2987.66	2874
2989.33	2942
2991.01	2840
2992.69	2820
2994.36	2794
2996.04	2836
2997.71	2818
2999.39	2768