File: muestras/tallo/2/Organic_18.txt
#Acq. time (s)=	10
#Accumulations=	1
#Range (cm-¹)=	100...3000
#Windows=	3
#Autofocus=	Off
#AutoExposure=	Off
#Spike filter=	Off
#Delay time (s)=	0
#Binning=	1
#Readout mode=	Signal
#DeNoise=	Off
#ICS correction=	Off
#Dark correction=	Off
#Inst. Process=	Off
#Instrument=	LabRAM HR Evol
#Detector=	Syncerity OE
#Objective=	x100_VIS
#Grating=	600 (500nm)
#ND Filter=	3.2%
#Laser=	633nm_Edge
#Hole=	100.021
#Range=	Visible
#Project=	Omar
#Sample=	26-06-23
#Site=	2
#Title=	Organic
#Remark=
#Date=	26.06.2023 16:32
#Acquired=	26.06.2023 16:32:27
101.018	3486
103.586	3552
106.152	3546
108.717	3554
111.281	3606
113.845	3590
116.407	3610
118.969	3676
121.53	3704
124.09	3718
126.649	3732
129.207	3682
131.765	3644
134.321	3724
136.877	3812
139.432	3696
141.985	3776
144.538	3750
147.09	3748
149.641	3756
152.191	3776
154.741	3858
157.289	3842
159.837	3900
162.385	3822
164.93	3836
167.476	3892
170.019	3860
172.562	3908
175.105	3980
177.646	3910
180.188	3868
182.727	3892
185.266	3890
187.804	3938
190.342	3862
192.878	3970
195.413	3980
197.948	4000
200.481	4018
203.014	4034
205.546	4008
208.077	4110
210.608	4116
213.137	4140
215.666	4176
218.194	4094
220.721	4136
223.247	4264
225.772	4164
228.295	4212
230.819	4190
233.342	4250
235.864	4266
238.384	4342
240.904	4320
243.423	4386
245.941	4396
248.46	4376
250.975	4364
253.492	4438
256.006	4394
258.519	4378
261.033	4344
263.545	4326
266.057	4324
268.567	4410
271.076	4448
273.585	4360
276.094	4408
278.601	4380
281.107	4426
283.612	4520
286.116	4484
288.62	4500
291.123	4530
293.625	4506
296.126	4552
298.626	4602
301.126	4618
303.625	4530
306.122	4658
308.62	4766
311.114	4636
313.61	4692
316.105	4590
318.599	4656
321.09	4682
323.583	4720
326.073	4728
328.563	4782
331.053	4702
333.541	4748
336.029	4836
338.515	4778
341.001	4902
343.486	4762
345.97	4886
348.453	4884
350.936	4936
353.418	4876
355.898	4902
358.378	4864
360.858	4940
363.336	5012
365.813	4960
368.29	5004
370.766	4974
373.241	5032
375.715	5014
378.188	4974
380.66	4956
383.132	4938
385.603	5038
388.072	5002
390.541	5032
393.01	4924
395.477	5054
397.943	5124
400.409	5062
402.875	5172
405.338	5146
407.802	5128
410.263	5254
412.725	5312
415.185	5262
417.646	5346
420.104	5276
422.564	5420
425.02	5386
427.477	5478
429.933	5450
432.388	5466
434.841	5464
437.294	5452
439.748	5482
442.199	5532
444.65	5584
447.1	5582
449.549	5552
451.997	5554
454.445	5538
456.891	5568
459.337	5604
461.782	5494
464.227	5596
466.669	5520
469.112	5578
471.554	5576
473.995	5630
476.434	5656
478.874	5682
481.312	5660
483.749	5744
486.186	5712
488.622	5814
491.057	5752
493.491	5826
495.925	5896
498.357	5850
500.789	5908
503.221	5922
505.65	5890
508.079	5918
510.509	5972
512.936	5942
515.363	5840
517.789	5898
520.214	6054
522.638	6022
525.062	5998
527.485	5890
529.907	6000
532.328	6034
534.748	6054
537.168	6058
539.587	6076
542.005	6030
544.423	6116
546.838	6134
549.254	6088
551.669	6074
554.082	6086
556.496	6056
558.909	6160
561.319	6202
563.731	6198
566.14	6206
568.549	6282
570.957	6234
573.364	6332
575.771	6236
578.177	6300
580.581	6254
582.987	6264
585.39	6394
587.792	6420
590.193	6418
592.594	6374
594.996	6508
597.395	6564
599.793	6460
602.191	6560
604.588	6684
606.984	6676
609.378	6614
611.773	6716
614.167	6692
616.56	6816
618.953	6762
621.343	6798
623.734	6820
626.124	6858
628.512	6946
630.901	6830
633.289	6964
635.675	7084
638.061	7070
640.446	7136
642.831	7108
645.213	7192
647.595	7220
649.978	7216
652.359	7374
654.738	7430
657.117	7320
659.497	7346
661.875	7360
664.252	7500
666.628	7436
669.003	7508
671.378	7566
673.751	7560
676.124	7418
678.497	7354
680.868	7608
683.239	7570
685.609	7694
687.977	7598
690.346	7702
692.714	7724
695.081	7812
697.446	7824
699.812	7802
702.175	7878
704.539	7864
706.901	7946
709.264	7922
711.625	8032
713.986	8018
716.345	8034
718.705	8172
721.062	8236
723.419	8236
725.775	8226
728.132	8260
730.487	8430
732.841	8290
735.194	8504
737.546	8502
739.898	8480
742.249	8516
744.599	8542
746.949	8640
749.298	8714
751.646	8730
753.993	8706
756.34	8702
758.684	8780
761.029	8782
763.374	8818
765.716	8758
768.059	8908
770.401	8946
772.741	8940
775.082	9024
777.421	9082
779.76	9018
782.097	9152
784.434	9134
786.771	9236
789.106	9360
791.44	9274
793.775	9320
796.108	9480
798.44	9512
800.771	9460
803.102	9586
805.432	9676
807.761	9746
810.09	9744
812.417	9778
814.744	10022
817.071	9988
819.396	10134
821.721	9984
824.045	10116
826.367	10236
828.69	10350
831.012	10278
833.332	10368
835.653	10538
837.972	10506
840.29	10622
842.609	10566
844.925	10784
847.242	10708
849.557	10828
851.871	10846
854.186	11072
856.498	10988
858.81	11030
861.122	10980
863.434	11160
865.744	11362
868.053	11394
870.361	11438
872.669	11428
874.976	11506
877.282	11510
879.588	11572
881.893	11580
884.197	11682
886.5	11740
888.802	11696
891.104	11780
893.405	11892
895.706	11778
898.004	11832
900.303	11954
902.6	12038
904.898	12112
907.194	12126
909.49	12056
911.785	12056
914.08	12208
916.372	12464
918.666	12440
920.957	12432
923.248	12532
925.538	12510
927.828	12622
930.118	12678
932.406	12772
934.693	12950
936.979	13058
939.265	13054
941.55	13064
943.835	13056
946.118	13250
948.401	13408
950.682	13412
952.964	13378
955.245	13524
957.525	13642
959.803	13620
962.082	13740
964.36	13752
966.636	13870
968.913	13946
971.188	13962
973.463	13962
975.736	14084
978.009	14100
980.282	14254
982.554	14322
984.824	14214
987.095	14308
989.364	14394
991.633	14498
993.9	14534
996.167	14556
998.434	14568
1000.7	14614
1002.96	14810
1005.23	14772
1007.49	14954
1009.76	14884
1012.02	14956
1014.28	15010
1016.54	14990
1018.8	15082
1021.06	15008
1023.32	15440
1025.57	15312
1027.83	15344
1030.09	15454
1032.34	15582
1034.6	15758
1036.85	15842
1039.1	16002
1041.35	15886
1043.61	16026
1045.86	16014
1048.11	16134
1050.36	16178
1052.61	16262
1054.85	16288
1057.1	16224
1059.35	16516
1061.59	16552
1063.84	16586
1066.08	16606
1068.33	16444
1070.57	16670
1072.81	16644
1075.05	16576
1077.29	16732
1079.53	16690
1081.77	16806
1084.01	16768
1086.25	16640
1088.48	16792
1090.72	16654
1092.96	16778
1095.19	16760
1097.43	16786
1099.66	16836
1101.89	16844
1104.12	16912
1106.35	16882
1108.59	17002
1110.81	16748
1113.04	16794
1115.27	16762
1117.5	17032
1119.73	16804
1121.95	16898
1124.18	16982
1126.4	16958
1128.63	16832
1130.85	16962
1133.07	17126
1135.29	17014
1137.51	17198
1139.73	17220
1141.95	17226
1144.17	17392
1146.39	17160
1148.61	17296
1150.82	17174
1153.04	17120
1155.26	17310
1157.47	17274
1159.68	17428
1161.9	17254
1164.11	17558
1166.32	17206
1168.53	17292
1170.74	17284
1172.95	17180
1175.16	17258
1177.37	17114
1179.58	17264
1181.78	17204
1183.99	17124
1186.19	16954
1188.4	16862
1190.6	16946
1192.8	16884
1195.01	17028
1197.21	16846.9
1199.41	16678.9
1201.61	16737.4
1203.81	16742.6
1206.01	16558
1208.2	16502.3
1210.4	16390.8
1212.6	16398.3
1214.8	16305.5
1216.99	16296.4
1219.18	16340.3
1221.38	16192.8
1223.57	16037.5
1225.76	16268.6
1227.96	16068.5
1230.15	16046
1232.34	15951.8
1234.53	15920.9
1236.71	15967.2
1238.9	15901.7
1241.09	15712.9
1243.28	15739.2
1245.46	15737.5
1247.65	15557.3
1249.83	15582.2
1252.02	15589.3
1254.2	15619.7
1256.38	15519.2
1258.56	15452.2
1260.74	15404.5
1262.92	15464.5
1265.1	15378.3
1267.28	15309
1269.46	15377.8
1271.64	15307.5
1273.82	15175.9
1275.99	15194.8
1278.17	15122.5
1280.34	15045.9
1282.52	15048.8
1284.69	14874.2
1286.86	14856.8
1289.03	14882
1291.21	14829.5
1293.38	14797.8
1295.55	14652.4
1297.71	14623.7
1299.88	14567.5
1302.05	14552.1
1304.22	14485.2
1306.38	14344.1
1308.43	14330
1310.61	14314
1312.78	14342
1314.96	14160
1317.13	14100
1319.3	13930
1321.48	14036
1323.65	14018
1325.82	13552
1327.99	13658
1330.16	13596
1332.33	13722
1334.5	13660
1336.66	13572
1338.83	13380
1341	13224
1343.16	13220
1345.33	13088
1347.49	13180
1349.65	13012
1351.82	12932
1353.98	12900
1356.14	12852
1358.3	12820
1360.46	12758
1362.62	12730
1364.78	12700
1366.94	12566
1369.09	12572
1371.25	12444
1373.41	12462
1375.56	12336
1377.72	12424
1379.87	12468
1382.02	12148
1384.17	12272
1386.33	12272
1388.48	12024
1390.63	12044
1392.78	11950
1394.93	12154
1397.07	11940
1399.22	11938
1401.37	11846
1403.52	11972
1405.66	11786
1407.81	11750
1409.95	11712
1412.09	11802
1414.24	11684
1416.38	11636
1418.52	11528
1420.66	11462
1422.8	11364
1424.94	11456
1427.08	11206
1429.22	11324
1431.35	11274
1433.49	11240
1435.63	11088
1437.76	11116
1439.9	11066
1442.03	11276
1444.17	11158
1446.3	11062
1448.43	10846
1450.56	10812
1452.69	10942
1454.82	10920
1456.95	10878
1459.08	10852
1461.21	10844
1463.34	10836
1465.46	10782
1467.59	10708
1469.71	10724
1471.84	10694
1473.96	10578
1476.08	10654
1478.21	10710
1480.33	10770
1482.45	10478
1484.57	10506
1486.69	10508
1488.81	10520
1490.93	10598
1493.05	10406
1495.16	10382
1497.28	10446
1499.4	10366
1501.51	10366
1503.63	10322
1505.74	10178
1507.85	10262
1509.97	10182
1512.08	10206
1514.19	10124
1516.3	10090
1518.41	9968
1520.52	9984
1522.63	10046
1524.73	9982
1526.84	9908
1528.95	9978
1531.06	9874
1533.16	9822
1535.26	9736
1537.37	9702
1539.47	9654
1541.57	9788
1543.68	9668
1545.78	9822
1547.88	9598
1549.98	9594
1552.08	9414
1554.18	9514
1556.27	9518
1558.37	9520
1560.47	9366
1562.56	9536
1564.66	9346
1566.75	9202
1568.85	9444
1570.94	9250
1573.03	9414
1575.13	9256
1577.22	9324
1579.31	9260
1581.4	9218
1583.49	9182
1585.58	9198
1587.66	9186
1589.75	9322
1591.84	9238
1593.93	9160
1596.01	9238
1598.1	9206
1600.18	9178
1602.26	9248
1604.35	9214
1606.43	9096
1608.51	9134
1610.59	9068
1612.67	9078
1614.75	9214
1616.83	9064
1618.91	9060
1620.99	9104
1623.06	9196
1625.14	9054
1627.21	8994
1629.29	8952
1631.36	9006
1633.44	8992
1635.51	9112
1637.58	8932
1639.66	8972
1641.73	8836
1643.8	8880
1645.87	8820
1647.94	8804
1650	8816
1652.07	8786
1654.14	8710
1656.21	8754
1658.27	8714
1660.34	8734
1662.4	8744
1664.47	8724
1666.53	8656
1668.59	8644
1670.66	8724
1672.72	8600
1674.78	8506
1676.84	8562
1678.9	8586
1680.96	8538
1683.01	8434
1685.07	8424
1687.13	8412
1689.19	8422
1691.24	8490
1693.3	8332
1695.35	8424
1697.4	8334
1699.46	8238
1701.51	8452
1703.56	8180
1705.61	8374
1707.66	8204
1709.71	8200
1711.76	8096
1713.81	8088
1715.86	8140
1717.91	8176
1719.95	8174
1722	8100
1724.04	8126
1726.09	8176
1728.13	8046
1730.18	8044
1732.22	7958
1734.26	8060
1736.3	8052
1738.34	8032
1740.38	8100
1742.42	7966
1744.46	8060
1746.5	7900
1748.54	8024
1750.58	7902
1752.61	8058
1754.65	7952
1756.68	7840
1758.72	7978
1760.75	7858
1762.79	7880
1764.82	7976
1766.85	7922
1768.88	7882
1770.91	7868
1772.94	7926
1774.97	7834
1777	8010
1779.03	7900
1781.06	7844
1783.09	7878
1785.11	7888
1787.14	7926
1789.16	7910
1791.19	7846
1793.21	7948
1795.23	7812
1797.26	7708
1799.28	7618
1801.3	7814
1803.32	7822
1805.34	7746
1807.36	7750
1809.38	7802
1811.4	7648
1813.42	7628
1815.43	7656
1817.45	7686
1819.47	7634
1821.48	7582
1823.49	7474
1825.51	7616
1827.52	7652
1829.54	7494
1831.55	7482
1833.56	7610
1835.57	7518
1837.58	7492
1839.59	7500
1841.6	7392
1843.61	7440
1845.61	7400
1847.62	7416
1849.63	7444
1851.63	7370
1853.64	7278
1855.64	7348
1857.65	7446
1859.65	7372
1861.65	7206
1863.65	7418
1865.66	7358
1867.66	7380
1869.66	7330
1871.66	7326
1873.66	7284
1875.65	7174
1877.65	7204
1879.65	7342
1881.65	7212
1883.64	7226
1885.64	7148
1887.63	7246
1889.63	7252
1891.62	7188
1893.61	7126
1895.6	7188
1897.6	7192
1899.59	7094
1901.58	7076
1903.57	7238
1905.56	7188
1907.54	7124
1909.53	7168
1911.52	7180
1913.51	7134
1915.49	7050
1917.48	7122
1919.46	6998
1921.45	7186
1923.43	7168
1925.41	7132
1927.4	7038
1929.38	7068
1931.36	7104
1933.34	7030
1935.32	6950
1937.3	7088
1939.28	6958
1941.26	7122
1943.23	7012
1945.21	7022
1947.19	6958
1949.16	7046
1951.14	7034
1953.11	6938
1955.09	6886
1957.06	6936
1959.03	7014
1961	6888
1962.98	6864
1964.95	6998
1966.92	6792
1968.89	6966
1970.85	6868
1972.82	6906
1974.79	6840
1976.76	6848
1978.73	6752
1980.69	6714
1982.66	6756
1984.62	6922
1986.59	6728
1988.55	6824
1990.51	6606
1992.47	6630
1994.44	6696
1996.4	6728
1998.36	6736
2000.32	6670
2002.28	6640
2004.24	6760
2006.19	6576
2008.15	6780
2010.11	6722
2012.06	6734
2014.02	6646
2015.98	6652
2017.93	6620
2019.88	6664
2021.84	6574
2023.79	6580
2025.74	6576
2027.69	6570
2029.65	6602
2031.6	6550
2033.55	6584
2035.5	6542
2037.44	6538
2039.39	6560
2041.34	6556
2043.29	6612
2045.23	6612
2047.18	6550
2049.12	6472
2051.07	6572
2053.01	6550
2054.95	6474
2056.9	6430
2058.84	6506
2060.78	6478
2062.72	6394
2064.66	6496
2066.6	6364
2068.54	6520
2070.48	6370
2072.42	6464
2074.35	6378
2076.29	6312
2078.23	6462
2080.16	6480
2082.1	6334
2084.03	6352
2085.96	6302
2087.9	6312
2089.83	6354
2091.76	6352
2093.69	6238
2095.62	6436
2097.55	6368
2099.48	6286
2101.41	6278
2103.34	6348
2105.27	6334
2107.2	6246
2109.12	6200
2111.05	6220
2112.98	6260
2114.9	6202
2116.82	6178
2118.75	6190
2120.67	6314
2122.59	6262
2124.52	6264
2126.44	6198
2128.36	6180
2130.28	6290
2132.2	6156
2134.12	6100
2136.04	6152
2137.95	6060
2139.87	6206
2141.79	6162
2143.7	6134
2145.62	6006.24
2147.53	6076.61
2149.45	6180.49
2151.36	6041.83
2153.28	6021.81
2155.19	5990.66
2157.1	6041.09
2159.01	6024.62
2160.92	5970.46
2162.83	5965.88
2164.74	5973.91
2166.65	5956.03
2168.56	5939.92
2170.47	5922.68
2172.38	5889.54
2174.28	5879.72
2176.19	5880.18
2178.09	5874.43
2180	5892.62
2181.9	5844.6
2183.81	5914.69
2185.71	5828.13
2187.61	5832.28
2189.52	5853.76
2191.42	5816.83
2193.32	5812.8
2195.22	5833.43
2197.12	5769.33
2199.02	5827.43
2200.92	5797.51
2202.82	5795.71
2204.71	5764.35
2206.61	5787.19
2208.51	5783.25
2210.4	5752.4
2212.3	5808.74
2214.19	5761.07
2216.09	5781.43
2217.98	5763.97
2219.87	5749.19
2221.77	5756.46
2223.66	5767.37
2225.55	5780.54
2227.44	5781.86
2229.33	5766
2231.22	5733.03
2233.11	5819.28
2235	5731.65
2236.88	5777.51
2238.77	5767.86
2240.66	5730.35
2242.07	5782
2243.97	5746
2245.87	5744
2247.76	5800
2249.65	5672
2251.55	5802
2253.44	5836
2255.33	5716
2257.22	5644
2259.12	5670
2261.01	5752
2262.9	5668
2264.78	5770
2266.67	5702
2268.56	5574
2270.45	5660
2272.34	5760
2274.22	5668
2276.11	5718
2277.99	5682
2279.88	5714
2281.76	5568
2283.65	5586
2285.53	5608
2287.41	5630
2289.3	5638
2291.18	5562
2293.06	5484
2294.94	5628
2296.82	5616
2298.7	5490
2300.58	5600
2302.46	5536
2304.33	5516
2306.21	5538
2308.09	5516
2309.96	5558
2311.84	5582
2313.71	5458
2315.59	5480
2317.46	5502
2319.33	5446
2321.21	5474
2323.08	5472
2324.95	5426
2326.82	5344
2328.69	5516
2330.56	5464
2332.43	5410
2334.3	5460
2336.17	5404
2338.03	5432
2339.9	5356
2341.77	5404
2343.63	5370
2345.5	5400
2347.36	5400
2349.23	5338
2351.09	5484
2352.95	5338
2354.82	5304
2356.68	5336
2358.54	5448
2360.4	5404
2362.26	5332
2364.12	5294
2365.98	5292
2367.84	5270
2369.7	5262
2371.56	5288
2373.41	5278
2375.27	5216
2377.12	5292
2378.98	5248
2380.84	5204
2382.69	5218
2384.54	5216
2386.4	5272
2388.25	5220
2390.1	5224
2391.95	5238
2393.8	5198
2395.65	5252
2397.5	5220
2399.35	5222
2401.2	5186
2403.05	5156
2404.9	5150
2406.75	5176
2408.59	5170
2410.44	5064
2412.28	5212
2414.13	5162
2415.97	5072
2417.82	5152
2419.66	5072
2421.5	5104
2423.35	5014
2425.19	5036
2427.03	4952
2428.87	4966
2430.71	5050
2432.55	5052
2434.39	5016
2436.23	4976
2438.06	5032
2439.9	5020
2441.74	5010
2443.57	4948
2445.41	5000
2447.24	5010
2449.08	4928
2450.91	5014
2452.75	4990
2454.58	4884
2456.41	4928
2458.24	4928
2460.08	4910
2461.91	4980
2463.74	4932
2465.57	4842
2467.4	4878
2469.22	4908
2471.05	4864
2472.88	4894
2474.71	4836
2476.53	4834
2478.36	4860
2480.19	4814
2482.01	4842
2483.83	4850
2485.66	4722
2487.48	4784
2489.3	4736
2491.13	4716
2492.95	4700
2494.77	4752
2496.59	4768
2498.41	4794
2500.23	4710
2502.05	4788
2503.87	4722
2505.68	4610
2507.5	4624
2509.32	4664
2511.14	4678
2512.95	4700
2514.77	4686
2516.58	4604
2518.39	4666
2520.21	4646
2522.02	4672
2523.83	4560
2525.65	4452
2527.46	4554
2529.27	4620
2531.08	4500
2532.89	4516
2534.7	4516
2536.51	4526
2538.32	4496
2540.12	4494
2541.93	4466
2543.74	4446
2545.54	4442
2547.35	4472
2549.15	4458
2550.96	4472
2552.76	4396
2554.56	4356
2556.37	4428
2558.17	4392
2559.97	4388
2561.77	4466
2563.58	4408
2565.38	4366
2567.18	4308
2568.97	4234
2570.77	4340
2572.57	4340
2574.37	4316
2576.17	4272
2577.96	4286
2579.76	4326
2581.55	4230
2583.35	4268
2585.14	4234
2586.94	4254
2588.73	4236
2590.52	4288
2592.32	4184
2594.11	4200
2595.9	4230
2597.69	4158
2599.48	4148
2601.27	4108
2603.06	4122
2604.85	4116
2606.64	4092
2608.42	4110
2610.21	4132
2612	4128
2613.78	4074
2615.57	4108
2617.36	4124
2619.14	4078
2620.92	4042
2622.71	4048
2624.49	4024
2626.27	4018
2628.05	4088
2629.84	4018
2631.62	3992
2633.4	3978
2635.18	3904
2636.96	3980
2638.74	3952
2640.51	3938
2642.29	3908
2644.07	3960
2645.85	3934
2647.62	3850
2649.4	3834
2651.17	3866
2652.95	3932
2654.72	3790
2656.5	3866
2658.27	3814
2660.04	3922
2661.81	3864
2663.58	3810
2665.35	3812
2667.13	3752
2668.9	3732
2670.66	3770
2672.43	3842
2674.2	3770
2675.97	3862
2677.74	3784
2679.5	3756
2681.27	3682
2683.04	3716
2684.8	3740
2686.57	3736
2688.33	3626
2690.09	3682
2691.86	3702
2693.62	3652
2695.38	3660
2697.15	3712
2698.91	3644
2700.67	3644
2702.43	3644
2704.19	3614
2705.95	3560
2707.7	3628
2709.46	3698
2711.22	3590
2712.98	3534
2714.73	3580
2716.49	3518
2718.25	3522
2720	3548
2721.76	3508
2723.51	3570
2725.26	3514
2727.02	3476
2728.77	3416
2730.52	3458
2732.27	3416
2734.02	3482
2735.77	3406
2737.52	3440
2739.27	3470
2741.02	3462
2742.77	3442
2744.52	3386
2746.27	3434
2748.01	3408
2749.76	3402
2751.51	3370
2753.25	3326
2755	3322
2756.74	3330
2758.48	3372
2760.23	3294
2761.97	3336
2763.71	3368
2765.45	3314
2767.19	3296
2768.94	3292
2770.68	3264
2772.42	3296
2774.16	3258
2775.89	3276
2777.63	3238
2779.37	3216
2781.11	3170
2782.84	3228
2784.58	3186
2786.32	3218
2788.05	3198
2789.79	3136
2791.52	3126
2793.25	3172
2794.99	3146
2796.72	3140
2798.45	3160
2800.18	3144
2801.92	3034
2803.65	3083
2805.38	3104
2807.11	3080
2808.84	3012
2810.57	3144
2812.29	3046
2814.02	3092
2815.75	3078
2817.47	2964
2819.2	3036
2820.93	3074
2822.65	2996
2824.38	3048
2826.1	2938
2827.82	2994
2829.55	2994
2831.27	2984
2832.99	2942
2834.71	2964
2836.44	2962
2838.16	2920
2839.88	2986
2841.6	2892
2843.32	2904
2845.03	2888
2846.75	2880
2848.47	2894
2850.19	2878
2851.9	2916
2853.62	2908
2855.34	2788
2857.05	2844
2858.77	2862
2860.48	2792
2862.19	2774
2863.91	2788
2865.62	2804
2867.33	2754
2869.04	2756
2870.76	2730
2872.47	2690
2874.18	2784
2875.89	2676
2877.6	2760
2879.31	2742
2881.01	2804
2882.72	2728
2884.43	2760
2886.14	2710
2887.84	2710
2889.55	2704
2891.25	2656
2892.96	2618
2894.66	2686
2896.37	2672
2898.07	2572
2899.77	2622
2901.48	2570
2903.18	2648
2904.88	2670
2906.58	2640
2908.28	2582
2909.98	2624
2911.68	2608
2913.38	2608
2915.08	2608
2916.78	2592
2918.47	2602
2920.17	2564
2921.87	2670
2923.56	2566
2925.26	2556
2926.95	2574
2928.65	2576
2930.34	2516
2932.04	2560
2933.73	2566
2935.42	2526
2937.11	2522
2938.81	2478
2940.5	2514
2942.19	2512
2943.88	2500
2945.57	2496
2947.26	2456
2948.95	2510
2950.64	2486
2952.32	2490
2954.01	2420
2955.7	2470
2957.38	2448
2959.07	2420
2960.75	2454
2962.44	2428
2964.12	2382
2965.81	2340
2967.49	2492
2969.17	2472
2970.86	2424
2972.54	2370
2974.22	2388
2975.9	2372
2977.58	2362
2979.26	2324
2980.94	2402
2982.62	2374
2984.3	2390
2985.98	2324
2987.66	2320
2989.33	2302
2991.01	2322
2992.69	2300
2994.36	2368
2996.04	2346
2997.71	2302
2999.39	2212