File: muestras/tallo/2/Organic_10.txt
#Acq. time (s)=	10
#Accumulations=	1
#Range (cm-¹)=	100...3000
#Windows=	3
#Autofocus=	Off
#AutoExposure=	Off
#Spike filter=	Off
#Delay time (s)=	0
#Binning=	1
#Readout mode=	Signal
#DeNoise=	Off
#ICS correction=	Off
#Dark correction=	Off
#Inst. Process=	Off
#Instrument=	LabRAM HR Evol
#Detector=	Syncerity OE
#Objective=	x100_VIS
#Grating=	600 (500nm)
#ND Filter=	3.2%
#Laser=	633nm_Edge
#Hole=	100.021
#Range=	Visible
#Project=	Omar
#Sample=	26-06-23
#Site=	2
#Title=	Organic
#Remark=
#Date=	26.06.2023 16:24
#Acquired=	26.06.2023 16:24:36
101.018	3824
103.586	3954
106.152	3836
108.717	3814
111.281	3880
113.845	3830
116.407	3836
118.969	3916
121.53	3942
124.09	4026
126.649	3960
129.207	3952
131.765	4010
134.321	3960
136.877	3994
139.432	4028
141.985	4044
144.538	4034
147.09	4002
149.641	4052
152.191	4096
154.741	4114
157.289	4110
159.837	4034
162.385	4080
164.93	4112
167.476	4158
170.019	4192
172.562	4212
175.105	4166
177.646	4180
180.188	4138
182.727	4202
185.266	4214
187.804	4304
190.342	4246
192.878	4254
195.413	4378
197.948	4364
200.481	4312
203.014	4410
205.546	4426
208.077	4404
210.608	4466
213.137	4482
215.666	4444
218.194	4496
220.721	4486
223.247	4538
225.772	4536
228.295	4596
230.819	4540
233.342	4520
235.864	4672
238.384	4670
240.904	4662
243.423	4720
245.941	4654
248.46	4740
250.975	4674
253.492	4720
256.006	4748
258.519	4698
261.033	4690
263.545	4652
266.057	4738
268.567	4828
271.076	4776
273.585	4882
276.094	4734
278.601	4868
281.107	4880
283.612	4930
286.116	4786
288.62	4902
291.123	4966
293.625	4968
296.126	4976
298.626	4976
301.126	5040
303.625	4924
306.122	5062
308.62	5108
311.114	5086
313.61	5134
316.105	5120
318.599	5082
321.09	5134
323.583	5118
326.073	5176
328.563	5178
331.053	5252
333.541	5208
336.029	5196
338.515	5248
341.001	5216
343.486	5154
345.97	5256
348.453	5364
350.936	5364
353.418	5316
355.898	5392
358.378	5332
360.858	5356
363.336	5432
365.813	5400
368.29	5436
370.766	5480
373.241	5424
375.715	5376
378.188	5474
380.66	5462
383.132	5428
385.603	5498
388.072	5556
390.541	5500
393.01	5476
395.477	5536
397.943	5508
400.409	5622
402.875	5540
405.338	5564
407.802	5654
410.263	5622
412.725	5844
415.185	5786
417.646	5780
420.104	5832
422.564	5946
425.02	5888
427.477	5972
429.933	5966
432.388	6038
434.841	5976
437.294	5984
439.748	6022
442.199	6146
444.65	6054
447.1	6078
449.549	6072
451.997	6186
454.445	6072
456.891	6130
459.337	6066
461.782	6018
464.227	6112
466.669	6074
469.112	6128
471.554	6162
473.995	6208
476.434	6260
478.874	6252
481.312	6214
483.749	6350
486.186	6268
488.622	6474
491.057	6310
493.491	6428
495.925	6532
498.357	6484
500.789	6526
503.221	6592
505.65	6516
508.079	6610
510.509	6570
512.936	6646
515.363	6616
517.789	6512
520.214	6586
522.638	6566
525.062	6606
527.485	6684
529.907	6616
532.328	6598
534.748	6694
537.168	6706
539.587	6666
542.005	6650
544.423	6802
546.838	6818
549.254	6762
551.669	6792
554.082	6852
556.496	6688
558.909	6870
561.319	6774
563.731	6798
566.14	6854
568.549	6952
570.957	7016
573.364	7030
575.771	7064
578.177	7032
580.581	7070
582.987	7156
585.39	7176
587.792	7080
590.193	7210
592.594	7204
594.996	7126
597.395	7270
599.793	7350
602.191	7308
604.588	7334
606.984	7418
609.378	7438
611.773	7464
614.167	7532
616.56	7594
618.953	7594
621.343	7732
623.734	7738
626.124	7900
628.512	7874
630.901	7802
633.289	7910
635.675	7968
638.061	8046
640.446	7966
642.831	7942
645.213	7988
647.595	8118
649.978	8256
652.359	8336
654.738	8314
657.117	8302
659.497	8226
661.875	8398
664.252	8390
666.628	8348
669.003	8460
671.378	8406
673.751	8522
676.124	8444
678.497	8514
680.868	8670
683.239	8646
685.609	8626
687.977	8584
690.346	8758
692.714	8754
695.081	8850
697.446	8804
699.812	8908
702.175	8946
704.539	8986
706.901	8948
709.264	9158
711.625	9038
713.986	9230
716.345	9228
718.705	9274
721.062	9304
723.419	9384
725.775	9448
728.132	9576
730.487	9494
732.841	9638
735.194	9678
737.546	9692
739.898	9640
742.249	9914
744.599	9756
746.949	9912
749.298	10012
751.646	9982
753.993	10036
756.34	10004
758.684	10018
761.029	10034
763.374	10156
765.716	10160
768.059	10358
770.401	10348
772.741	10476
775.082	10540
777.421	10560
779.76	10548
782.097	10598
784.434	10714
786.771	10604
789.106	10790
791.44	10836
793.775	10964
796.108	10940
798.44	11048
800.771	11088
803.102	11182
805.432	11226
807.761	11382
810.09	11308
812.417	11444
814.744	11484
817.071	11554
819.396	11756
821.721	11758
824.045	11750
826.367	11928
828.69	11978
831.012	12102
833.332	12192
835.653	12440
837.972	12364
840.29	12432
842.609	12510
844.925	12456
847.242	12576
849.557	12660
851.871	12766
854.186	12888
856.498	12788
858.81	13076
861.122	12960
863.434	13200
865.744	13322
868.053	13336
870.361	13290
872.669	13424
874.976	13558
877.282	13566
879.588	13670
881.893	13812
884.197	13818
886.5	13810
888.802	13916
891.104	13874
893.405	14018
895.706	14056
898.004	14002
900.303	14066
902.6	14194
904.898	14258
907.194	14366
909.49	14508
911.785	14428
914.08	14700
916.372	14570
918.666	14768
920.957	14744
923.248	14882
925.538	15002
927.828	15096
930.118	15264
932.406	15302
934.693	15402
936.979	15352
939.265	15708
941.55	15512
943.835	15676
946.118	15708
948.401	15804
950.682	15968
952.964	16132
955.245	16086
957.525	16118
959.803	16358
962.082	16398
964.36	16492
966.636	16624
968.913	16738
971.188	16701
973.463	16856
975.736	17010
978.009	16968
980.282	17014
982.554	17140
984.824	17144
987.095	17138
989.364	17366
991.633	17294
993.9	17542
996.167	17486
998.434	17552
1000.7	17722
1002.96	17846
1005.23	17732
1007.49	17818
1009.76	17882
1012.02	18072
1014.28	18078
1016.54	18222
1018.8	18350
1021.06	18366
1023.32	18428
1025.57	18506
1027.83	18676
1030.09	18780
1032.34	18716
1034.6	18832
1036.85	19228
1039.1	19030
1041.35	19106
1043.61	19328
1045.86	19382
1048.11	19420
1050.36	19526
1052.61	19604
1054.85	19506
1057.1	19770
1059.35	19814
1061.59	19810
1063.84	19992
1066.08	19884
1068.33	20100
1070.57	20082
1072.81	20252
1075.05	20148
1077.29	20264
1079.53	20368
1081.77	20338
1084.01	20196
1086.25	20322
1088.48	20462
1090.72	20450
1092.96	20360
1095.19	20496
1097.43	20358
1099.66	20328
1101.89	20156
1104.12	20460
1106.35	20508
1108.59	20380
1110.81	20302
1113.04	20444
1115.27	20356
1117.5	20588
1119.73	20570
1121.95	20582
1124.18	20506
1126.4	20642
1128.63	20496
1130.85	20620
1133.07	20696
1135.29	20518
1137.51	20696
1139.73	20790
1141.95	20676
1144.17	20720
1146.39	20882
1148.61	20950
1150.82	20826
1153.04	21032
1155.26	20980
1157.47	20846
1159.68	20814
1161.9	20976
1164.11	21078
1166.32	20888
1168.53	21058
1170.74	21062
1172.95	21046
1175.16	20832
1177.37	20846
1179.58	20858
1181.78	20906
1183.99	20654
1186.19	20746
1188.4	20636
1190.6	20634
1192.8	20522
1195.01	20536
1197.21	20399.3
1199.41	20332.3
1201.61	20189.9
1203.81	20026.2
1206.01	20064.8
1208.2	20017.8
1210.4	19857.3
1212.6	19806.4
1214.8	19700.6
1216.99	19756
1219.18	19592.3
1221.38	19461.7
1223.57	19471.8
1225.76	19433.9
1227.96	19372.6
1230.15	19254.6
1232.34	19363.2
1234.53	19197.3
1236.71	19149.7
1238.9	18975.3
1241.09	19010.6
1243.28	18944.8
1245.46	18935.7
1247.65	18825.5
1249.83	18722.2
1252.02	18694.5
1254.2	18666.1
1256.38	18632.7
1258.56	18597.5
1260.74	18496
1262.92	18503.1
1265.1	18384.2
1267.28	18417.2
1269.46	18263.1
1271.64	18276.2
1273.82	18237.5
1275.99	18124.5
1278.17	18117.2
1280.34	17987.9
1282.52	17845.9
1284.69	17916.3
1286.86	17864.7
1289.03	17866.8
1291.21	17764.6
1293.38	17717.5
1295.55	17638.1
1297.71	17395.6
1299.88	17403.7
1302.05	17335.1
1304.22	17311.9
1306.38	17293
1308.43	17054
1310.61	17158
1312.78	16996
1314.96	16812
1317.13	16846
1319.3	16682
1321.48	16572
1323.65	16334
1325.82	16442
1327.99	16290
1330.16	16200
1332.33	16180
1334.5	16082
1336.66	15920
1338.83	15920
1341	15704
1343.16	15846
1345.33	15360
1347.49	15550
1349.65	15440
1351.82	15350
1353.98	15408
1356.14	15132
1358.3	15152
1360.46	15088
1362.62	15120
1364.78	14822
1366.94	14880
1369.09	14760
1371.25	14796
1373.41	14630
1375.56	14590
1377.72	14554
1379.87	14410
1382.02	14318
1384.17	14558
1386.33	14262
1388.48	14200
1390.63	14028
1392.78	14108
1394.93	14134
1397.07	13896
1399.22	13928
1401.37	13852
1403.52	13644
1405.66	13614
1407.81	13604
1409.95	13610
1412.09	13586
1414.24	13430
1416.38	13560
1418.52	13426
1420.66	13438
1422.8	13276
1424.94	13274
1427.08	13148
1429.22	13170
1431.35	13142
1433.49	13036
1435.63	12920
1437.76	12956
1439.9	12918
1442.03	13030
1444.17	12764
1446.3	12854
1448.43	12736
1450.56	12542
1452.69	12710
1454.82	12656
1456.95	12578
1459.08	12584
1461.21	12592
1463.34	12464
1465.46	12564
1467.59	12456
1469.71	12332
1471.84	12434
1473.96	12274
1476.08	12352
1478.21	12204
1480.33	12120
1482.45	12096
1484.57	12206
1486.69	12154
1488.81	12084
1490.93	12002
1493.05	11922
1495.16	12044
1497.28	11884
1499.4	12048
1501.51	11912
1503.63	11840
1505.74	11818
1507.85	11622
1509.97	11740
1512.08	11634
1514.19	11598
1516.3	11692
1518.41	11680
1520.52	11548
1522.63	11526
1524.73	11428
1526.84	11360
1528.95	11378
1531.06	11294
1533.16	11282
1535.26	11198
1537.37	11264
1539.47	11216
1541.57	11176
1543.68	11120
1545.78	11102
1547.88	10964
1549.98	11174
1552.08	10944
1554.18	11010
1556.27	10830
1558.37	10908
1560.47	10780
1562.56	10844
1564.66	10710
1566.75	10604
1568.85	10786
1570.94	10862
1573.03	10578
1575.13	10692
1577.22	10622
1579.31	10560
1581.4	10586
1583.49	10552
1585.58	10450
1587.66	10550
1589.75	10462
1591.84	10462
1593.93	10524
1596.01	10488
1598.1	10504
1600.18	10582
1602.26	10458
1604.35	10424
1606.43	10388
1608.51	10404
1610.59	10422
1612.67	10348
1614.75	10354
1616.83	10408
1618.91	10444
1620.99	10384
1623.06	10260
1625.14	10240
1627.21	10246
1629.29	10122
1631.36	10232
1633.44	10164
1635.51	10232
1637.58	10304
1639.66	10056
1641.73	10240
1643.8	10104
1645.87	9982
1647.94	9976
1650	9990
1652.07	10038
1654.14	10098
1656.21	9850
1658.27	10012
1660.34	9900
1662.4	9832
1664.47	9824
1666.53	9770
1668.59	9972
1670.66	9864
1672.72	9856
1674.78	9724
1676.84	9802
1678.9	9716
1680.96	9672
1683.01	9748
1685.07	9662
1687.13	9482
1689.19	9718
1691.24	9568
1693.3	9500
1695.35	9482
1697.4	9582
1699.46	9414
1701.51	9478
1703.56	9326
1705.61	9420
1707.66	9318
1709.71	9230
1711.76	9260
1713.81	9424
1715.86	9348
1717.91	9234
1719.95	9238
1722	9220
1724.04	9196
1726.09	9252
1728.13	9082
1730.18	9218
1732.22	9018
1734.26	9160
1736.3	9120
1738.34	9102
1740.38	9126
1742.42	9066
1744.46	9022
1746.5	8994
1748.54	8990
1750.58	9048
1752.61	9168
1754.65	9000
1756.68	8906
1758.72	8922
1760.75	9048
1762.79	8908
1764.82	8918
1766.85	8968
1768.88	8952
1770.91	8970
1772.94	9020
1774.97	8912
1777	8774
1779.03	8882
1781.06	8832
1783.09	8886
1785.11	8950
1787.14	8830
1789.16	8848
1791.19	8884
1793.21	8842
1795.23	8850
1797.26	8790
1799.28	8720
1801.3	8908
1803.32	8830
1805.34	8816
1807.36	8770
1809.38	8766
1811.4	8724
1813.42	8710
1815.43	8606
1817.45	8690
1819.47	8666
1821.48	8672
1823.49	8504
1825.51	8568
1827.52	8646
1829.54	8586
1831.55	8572
1833.56	8650
1835.57	8496
1837.58	8498
1839.59	8498
1841.6	8472
1843.61	8444
1845.61	8450
1847.62	8464
1849.63	8438
1851.63	8394
1853.64	8334
1855.64	8352
1857.65	8368
1859.65	8392
1861.65	8274
1863.65	8156
1865.66	8392
1867.66	8302
1869.66	8266
1871.66	8328
1873.66	8198
1875.65	8200
1877.65	8242
1879.65	8144
1881.65	8216
1883.64	8254
1885.64	8244
1887.63	8186
1889.63	8136
1891.62	8230
1893.61	8058
1895.6	8168
1897.6	8050
1899.59	8100
1901.58	7976
1903.57	8132
1905.56	7998
1907.54	7976
1909.53	8074
1911.52	8162
1913.51	8072
1915.49	7988
1917.48	8044
1919.46	8076
1921.45	7926
1923.43	7970
1925.41	8060
1927.4	8000
1929.38	8128
1931.36	8022
1933.34	8076
1935.32	7952
1937.3	7948
1939.28	7884
1941.26	7802
1943.23	7912
1945.21	7966
1947.19	7902
1949.16	7874
1951.14	7884
1953.11	7818
1955.09	7840
1957.06	7888
1959.03	7798
1961	7800
1962.98	7870
1964.95	7772
1966.92	7794
1968.89	7690
1970.85	7798
1972.82	7620
1974.79	7644
1976.76	7836
1978.73	7788
1980.69	7538
1982.66	7690
1984.62	7778
1986.59	7708
1988.55	7704
1990.51	7700
1992.47	7568
1994.44	7596
1996.4	7726
1998.36	7682
2000.32	7546
2002.28	7558
2004.24	7446
2006.19	7582
2008.15	7598
2010.11	7600
2012.06	7604
2014.02	7528
2015.98	7598
2017.93	7554
2019.88	7650
2021.84	7596
2023.79	7502
2025.74	7528
2027.69	7582
2029.65	7558
2031.6	7586
2033.55	7548
2035.5	7460
2037.44	7466
2039.39	7374
2041.34	7480
2043.29	7474
2045.23	7420
2047.18	7388
2049.12	7396
2051.07	7428
2053.01	7326
2054.95	7438
2056.9	7220
2058.84	7360
2060.78	7320
2062.72	7462
2064.66	7270
2066.6	7354
2068.54	7212
2070.48	7284
2072.42	7332
2074.35	7266
2076.29	7268
2078.23	7308
2080.16	7348
2082.1	7278
2084.03	7190
2085.96	7194
2087.9	7176
2089.83	7242
2091.76	7162
2093.69	7210
2095.62	7178
2097.55	7228
2099.48	7074
2101.41	7252
2103.34	7162
2105.27	7192
2107.2	7184
2109.12	7106
2111.05	7202
2112.98	7170
2114.9	7198
2116.82	7048
2118.75	7094
2120.67	7046
2122.59	7114
2124.52	7082
2126.44	7110
2128.36	7108
2130.28	6980
2132.2	6936
2134.12	7094
2136.04	6952
2137.95	6980
2139.87	7028
2141.79	7024
2143.7	6912
2145.62	6951.85
2147.53	6987.55
2149.45	6779.89
2151.36	6793.4
2153.28	6923.38
2155.19	6777.42
2157.1	6902.49
2159.01	6876.09
2160.92	6898.69
2162.83	6829.85
2164.74	6805.87
2166.65	6773.73
2168.56	6760.94
2170.47	6769.54
2172.38	6784.38
2174.28	6692.17
2176.19	6734.37
2178.09	6686.54
2180	6715.48
2181.9	6663.01
2183.81	6606.46
2185.71	6723.95
2187.61	6621.06
2189.52	6634.7
2191.42	6664.95
2193.32	6670.86
2195.22	6671.21
2197.12	6671.19
2199.02	6621.91
2200.92	6570.23
2202.82	6585.79
2204.71	6565.01
2206.61	6529.25
2208.51	6573.08
2210.4	6554.2
2212.3	6570.28
2214.19	6557.97
2216.09	6640.61
2217.98	6579.9
2219.87	6551.94
2221.77	6560.71
2223.66	6593.04
2225.55	6508.33
2227.44	6588.71
2229.33	6587.3
2231.22	6546.86
2233.11	6566.65
2235	6560.46
2236.88	6531.57
2238.77	6558.31
2240.66	6610.55
2242.07	6500
2243.97	6520
2245.87	6632
2247.76	6512
2249.65	6622
2251.55	6492
2253.44	6472
2255.33	6542
2257.22	6502
2259.12	6478
2261.01	6566
2262.9	6568
2264.78	6440
2266.67	6496
2268.56	6410
2270.45	6530
2272.34	6440
2274.22	6462
2276.11	6380
2277.99	6438
2279.88	6476
2281.76	6472
2283.65	6450
2285.53	6282
2287.41	6352
2289.3	6360
2291.18	6392
2293.06	6342
2294.94	6316
2296.82	6382
2298.7	6378
2300.58	6338
2302.46	6392
2304.33	6382
2306.21	6310
2308.09	6196
2309.96	6392
2311.84	6336
2313.71	6330
2315.59	6292
2317.46	6246
2319.33	6300
2321.21	6238
2323.08	6272
2324.95	6350
2326.82	6268
2328.69	6222
2330.56	6206
2332.43	6176
2334.3	6212
2336.17	6220
2338.03	6210
2339.9	6204
2341.77	6210
2343.63	6302
2345.5	6170
2347.36	6112
2349.23	6092
2351.09	6168
2352.95	6136
2354.82	6196
2356.68	6148
2358.54	6128
2360.4	6088
2362.26	6136
2364.12	6162
2365.98	6222
2367.84	5994
2369.7	6102
2371.56	6030
2373.41	6002
2375.27	6062
2377.12	6064
2378.98	6044
2380.84	6026
2382.69	6062
2384.54	6074
2386.4	5926
2388.25	5998
2390.1	5976
2391.95	5994
2393.8	5946
2395.65	6006
2397.5	5964
2399.35	5940
2401.2	5976
2403.05	5906
2404.9	5978
2406.75	5878
2408.59	5788
2410.44	5850
2412.28	5782
2414.13	5826
2415.97	5842
2417.82	5768
2419.66	5752
2421.5	5786
2423.35	5770
2425.19	5774
2427.03	5850
2428.87	5658
2430.71	5886
2432.55	5734
2434.39	5730
2436.23	5718
2438.06	5618
2439.9	5686
2441.74	5690
2443.57	5690
2445.41	5588
2447.24	5838
2449.08	5678
2450.91	5726
2452.75	5682
2454.58	5642
2456.41	5634
2458.24	5510
2460.08	5644
2461.91	5574
2463.74	5542
2465.57	5528
2467.4	5486
2469.22	5592
2471.05	5602
2472.88	5480
2474.71	5494
2476.53	5562
2478.36	5428
2480.19	5508
2482.01	5452
2483.83	5458
2485.66	5468
2487.48	5476
2489.3	5414
2491.13	5444
2492.95	5566
2494.77	5406
2496.59	5410
2498.41	5386
2500.23	5406
2502.05	5424
2503.87	5402
2505.68	5262
2507.5	5404
2509.32	5342
2511.14	5346
2512.95	5340
2514.77	5398
2516.58	5388
2518.39	5220
2520.21	5234
2522.02	5262
2523.83	5192
2525.65	5328
2527.46	5212
2529.27	5206
2531.08	5244
2532.89	5216
2534.7	5202
2536.51	5086
2538.32	5102
2540.12	5182
2541.93	5160
2543.74	5170
2545.54	5042
2547.35	5168
2549.15	5074
2550.96	5054
2552.76	4988
2554.56	5072
2556.37	5120
2558.17	4996
2559.97	4984
2561.77	4966
2563.58	5016
2565.38	4990
2567.18	4938
2568.97	4928
2570.77	4978
2572.57	4956
2574.37	4922
2576.17	4992
2577.96	4968
2579.76	4960
2581.55	4856
2583.35	4890
2585.14	4878
2586.94	4886
2588.73	4912
2590.52	4804
2592.32	4748
2594.11	4792
2595.9	4826
2597.69	4784
2599.48	4722
2601.27	4760
2603.06	4720
2604.85	4696
2606.64	4768
2608.42	4718
2610.21	4724
2612	4716
2613.78	4712
2615.57	4644
2617.36	4594
2619.14	4640
2620.92	4668
2622.71	4628
2624.49	4572
2626.27	4614
2628.05	4616
2629.84	4578
2631.62	4588
2633.4	4580
2635.18	4564
2636.96	4562
2638.74	4444
2640.51	4532
2642.29	4482
2644.07	4472
2645.85	4414
2647.62	4412
2649.4	4332
2651.17	4384
2652.95	4436
2654.72	4422
2656.5	4356
2658.27	4360
2660.04	4402
2661.81	4380
2663.58	4276
2665.35	4330
2667.13	4284
2668.9	4294
2670.66	4296
2672.43	4352
2674.2	4332
2675.97	4356
2677.74	4246
2679.5	4366
2681.27	4292
2683.04	4276
2684.8	4276
2686.57	4368
2688.33	4246
2690.09	4216
2691.86	4156
2693.62	4174
2695.38	4186
2697.15	4150
2698.91	4120
2700.67	4150
2702.43	4204
2704.19	4136
2705.95	4158
2707.7	4040
2709.46	4126
2711.22	4150
2712.98	4146
2714.73	4004
2716.49	4056
2718.25	4090
2720	4070
2721.76	4026
2723.51	4072
2725.26	4024
2727.02	3978
2728.77	4008
2730.52	3928
2732.27	4004
2734.02	3970
2735.77	3950
2737.52	3934
2739.27	3870
2741.02	3942
2742.77	3902
2744.52	3876
2746.27	3880
2748.01	3814
2749.76	3804
2751.51	3894
2753.25	3840
2755	3776
2756.74	3868
2758.48	3848
2760.23	3782
2761.97	3830
2763.71	3778
2765.45	3750
2767.19	3684
2768.94	3740
2770.68	3686
2772.42	3676
2774.16	3724
2775.89	3728
2777.63	3622
2779.37	3712
2781.11	3618
2782.84	3672
2784.58	3626
2786.32	3664
2788.05	3610
2789.79	3602
2791.52	3612
2793.25	3516
2794.99	3574
2796.72	3588
2798.45	3644
2800.18	3542
2801.92	3526
2803.65	3541
2805.38	3544
2807.11	3502
2808.84	3528
2810.57	3552
2812.29	3462
2814.02	3478
2815.75	3532
2817.47	3474
2819.2	3446
2820.93	3394
2822.65	3428
2824.38	3418
2826.1	3460
2827.82	3474
2829.55	3388
2831.27	3340
2832.99	3414
2834.71	3350
2836.44	3384
2838.16	3402
2839.88	3352
2841.6	3272
2843.32	3308
2845.03	3348
2846.75	3268
2848.47	3326
2850.19	3246
2851.9	3266
2853.62	3202
2855.34	3236
2857.05	3244
2858.77	3252
2860.48	3248
2862.19	3218
2863.91	3206
2865.62	3158
2867.33	3138
2869.04	3174
2870.76	3152
2872.47	3166
2874.18	3114
2875.89	3158
2877.6	3108
2879.31	3158
2881.01	3096
2882.72	3126
2884.43	3048
2886.14	3056
2887.84	3082
2889.55	3068
2891.25	3082
2892.96	3044
2894.66	2990
2896.37	3024
2898.07	2994
2899.77	2992
2901.48	2992
2903.18	3002
2904.88	2972
2906.58	3014
2908.28	3004
2909.98	2960
2911.68	3024
2913.38	2988
2915.08	2938
2916.78	2914
2918.47	2970
2920.17	2936
2921.87	2926
2923.56	2842
2925.26	2922
2926.95	2934
2928.65	2882
2930.34	2842
2932.04	2880
2933.73	2858
2935.42	2828
2937.11	2882
2938.81	2868
2940.5	2914
2942.19	2826
2943.88	2864
2945.57	2872
2947.26	2842
2948.95	2806
2950.64	2862
2952.32	2894
2954.01	2838
2955.7	2766
2957.38	2748
2959.07	2810
2960.75	2756
2962.44	2736
2964.12	2754
2965.81	2718
2967.49	2782
2969.17	2782
2970.86	2702
2972.54	2698
2974.22	2758
2975.9	2738
2977.58	2608
2979.26	2684
2980.94	2716
2982.62	2556
2984.3	2642
2985.98	2604
2987.66	2654
2989.33	2612
2991.01	2600
2992.69	2548
2994.36	2620
2996.04	2598
2997.71	2540
2999.39	2602