File: muestras/tallo/2/Organic_06.txt
#Acq. time (s)=	10
#Accumulations=	1
#Range (cm-¹)=	100...3000
#Windows=	3
#Autofocus=	Off
#AutoExposure=	Off
#Spike filter=	Off
#Delay time (s)=	0
#Binning=	1
#Readout mode=	Signal
#DeNoise=	Off
#ICS correction=	Off
#Dark correction=	Off
#Inst. Process=	Off
#Instrument=	LabRAM HR Evol
#Detector=	Syncerity OE
#Objective=	x100_VIS
#Grating=	600 (500nm)
#ND Filter=	3.2%
#Laser=	633nm_Edge
#Hole=	100.021
#Range=	Visible
#Project=	Omar
#Sample=	26-06-23
#Site=	2
#Title=	Organic
#Remark=
#Date=	26.06.2023 16:20
#Acquired=	26.06.2023 16:20:51
101.018	4068
103.586	4062
106.152	4066
108.717	4058
111.281	4098
113.845	4148
116.407	4086
118.969	4128
121.53	4122
124.09	4224
126.649	4218
129.207	4278
131.765	4156
134.321	4264
136.877	4262
139.432	4264
141.985	4240
144.538	4416
147.09	4318
149.641	4316
152.191	4430
154.741	4304
157.289	4336
159.837	4436
162.385	4436
164.93	4380
167.476	4476
170.019	4394
172.562	4474
175.105	4432
177.646	4386
180.188	4514
182.727	4504
185.266	4450
187.804	4470
190.342	4508
192.878	4640
195.413	4540
197.948	4580
200.481	4594
203.014	4636
205.546	4568
208.077	4716
210.608	4728
213.137	4736
215.666	4622
218.194	4770
220.721	4702
223.247	4766
225.772	4870
228.295	4898
230.819	4910
233.342	4898
235.864	4876
238.384	4952
240.904	4970
243.423	4956
245.941	4924
248.46	4966
250.975	4970
253.492	5074
256.006	4992
258.519	4996
261.033	5004
263.545	5046
266.057	5082
268.567	5012
271.076	5038
273.585	5112
276.094	5074
278.601	5060
281.107	5146
283.612	5062
286.116	5084
288.62	5072
291.123	5166
293.625	5254
296.126	5252
298.626	5286
301.126	5392
303.625	5322
306.122	5342
308.62	5398
311.114	5470
313.61	5336
316.105	5488
318.599	5512
321.09	5466
323.583	5434
326.073	5540
328.563	5486
331.053	5432
333.541	5602
336.029	5608
338.515	5590
341.001	5584
343.486	5642
345.97	5594
348.453	5636
350.936	5648
353.418	5764
355.898	5700
358.378	5770
360.858	5844
363.336	5714
365.813	5758
368.29	5724
370.766	5742
373.241	5766
375.715	5784
378.188	5786
380.66	5778
383.132	5928
385.603	5832
388.072	5836
390.541	5840
393.01	5834
395.477	5852
397.943	5898
400.409	5978
402.875	5984
405.338	6008
407.802	6044
410.263	6034
412.725	6048
415.185	6150
417.646	6192
420.104	6296
422.564	6264
425.02	6264
427.477	6320
429.933	6372
432.388	6416
434.841	6436
437.294	6406
439.748	6456
442.199	6416
444.65	6454
447.1	6402
449.549	6426
451.997	6532
454.445	6606
456.891	6492
459.337	6550
461.782	6576
464.227	6574
466.669	6498
469.112	6716
471.554	6592
473.995	6692
476.434	6658
478.874	6746
481.312	6680
483.749	6842
486.186	6784
488.622	6808
491.057	6886
493.491	6886
495.925	6852
498.357	7036
500.789	6882
503.221	6940
505.65	7004
508.079	7066
510.509	6866
512.936	6918
515.363	7060
517.789	7010
520.214	7110
522.638	7094
525.062	7146
527.485	7202
529.907	7280
532.328	7070
534.748	7156
537.168	7230
539.587	7136
542.005	7146
544.423	7258
546.838	7340
549.254	7294
551.669	7378
554.082	7332
556.496	7312
558.909	7250
561.319	7382
563.731	7334
566.14	7492
568.549	7544
570.957	7510
573.364	7578
575.771	7608
578.177	7602
580.581	7560
582.987	7562
585.39	7684
587.792	7722
590.193	7786
592.594	7802
594.996	7794
597.395	7868
599.793	7890
602.191	7878
604.588	7912
606.984	7936
609.378	8052
611.773	8000
614.167	8156
616.56	8196
618.953	8194
621.343	8168
623.734	8262
626.124	8376
628.512	8362
630.901	8476
633.289	8614
635.675	8550
638.061	8608
640.446	8814
642.831	8752
645.213	8720
647.595	8810
649.978	8798
652.359	8918
654.738	8970
657.117	8940
659.497	8992
661.875	9068
664.252	9096
666.628	9090
669.003	9100
671.378	9204
673.751	9268
676.124	9166
678.497	9286
680.868	9338
683.239	9282
685.609	9432
687.977	9470
690.346	9526
692.714	9340
695.081	9460
697.446	9540
699.812	9674
702.175	9726
704.539	9812
706.901	9914
709.264	9880
711.625	9848
713.986	9978
716.345	10094
718.705	10040
721.062	10164
723.419	10204
725.775	10428
728.132	10428
730.487	10420
732.841	10424
735.194	10526
737.546	10696
739.898	10688
742.249	10616
744.599	10800
746.949	10926
749.298	10802
751.646	10920
753.993	10828
756.34	10868
758.684	10966
761.029	11104
763.374	11058
765.716	11190
768.059	11324
770.401	11398
772.741	11328
775.082	11374
777.421	11592
779.76	11532
782.097	11640
784.434	11864
786.771	11810
789.106	11704
791.44	11654
793.775	11982
796.108	12158
798.44	12076
800.771	12194
803.102	12180
805.432	12244
807.761	12364
810.09	12534
812.417	12636
814.744	12526
817.071	12756
819.396	12776
821.721	12878
824.045	13078
826.367	13168
828.69	13186
831.012	13342
833.332	13430
835.653	13574
837.972	13530
840.29	13732
842.609	13560
844.925	13822
847.242	14002
849.557	13972
851.871	14058
854.186	14146
856.498	14348
858.81	14330
861.122	14354
863.434	14330
865.744	14560
868.053	14790
870.361	14714
872.669	14886
874.976	14886
877.282	14944
879.588	15062
881.893	15038
884.197	15128
886.5	15112
888.802	15238
891.104	15314
893.405	15422
895.706	15358
898.004	15460
900.303	15496
902.6	15782
904.898	15726
907.194	15850
909.49	15816
911.785	15982
914.08	15908
916.372	16210
918.666	16266
920.957	16308
923.248	16510
925.538	16528
927.828	16712
930.118	16486
932.406	16578
934.693	17064
936.979	16962
939.265	17210
941.55	17228
943.835	17414
946.118	17570
948.401	17470
950.682	17762
952.964	17816
955.245	17772
957.525	17960
959.803	18014
962.082	18098
964.36	18352
966.636	18450
968.913	18416
971.188	18591
973.463	18628
975.736	18634
978.009	18824
980.282	19022
982.554	19026
984.824	18912
987.095	19262
989.364	19202
991.633	19316
993.9	19226
996.167	19412
998.434	19518
1000.7	19512
1002.96	19720
1005.23	19644
1007.49	19654
1009.76	19940
1012.02	19862
1014.28	20026
1016.54	19974
1018.8	20192
1021.06	20312
1023.32	20438
1025.57	20664
1027.83	20708
1030.09	20784
1032.34	20886
1034.6	20738
1036.85	21052
1039.1	21112
1041.35	21280
1043.61	21384
1045.86	21328
1048.11	21612
1050.36	21658
1052.61	21808
1054.85	21784
1057.1	21964
1059.35	21918
1061.59	22172
1063.84	22150
1066.08	22086
1068.33	22210
1070.57	22456
1072.81	22292
1075.05	22426
1077.29	22414
1079.53	22636
1081.77	22350
1084.01	22514
1086.25	22640
1088.48	22520
1090.72	22656
1092.96	22590
1095.19	22382
1097.43	22626
1099.66	22584
1101.89	22544
1104.12	22662
1106.35	22718
1108.59	22668
1110.81	22640
1113.04	22562
1115.27	22626
1117.5	22684
1119.73	22876
1121.95	22786
1124.18	22754
1126.4	22692
1128.63	22752
1130.85	22574
1133.07	22856
1135.29	22942
1137.51	22874
1139.73	22958
1141.95	23166
1144.17	22938
1146.39	23166
1148.61	23160
1150.82	23386
1153.04	23160
1155.26	23324
1157.47	23300
1159.68	23182
1161.9	23136
1164.11	23306
1166.32	23202
1168.53	23242
1170.74	23008
1172.95	23164
1175.16	23116
1177.37	22986
1179.58	22900
1181.78	22960
1183.99	22996
1186.19	22870
1188.4	22790
1190.6	22676
1192.8	22408
1195.01	22266
1197.21	22342.9
1199.41	22224.2
1201.61	22231.9
1203.81	22381.4
1206.01	22091.6
1208.2	22159.7
1210.4	21937
1212.6	21875.4
1214.8	21797.9
1216.99	21780
1219.18	21748.7
1221.38	21696.4
1223.57	21370.2
1225.76	21491.3
1227.96	21338.9
1230.15	21136.2
1232.34	21249.6
1234.53	21086.7
1236.71	21121.9
1238.9	20977.7
1241.09	20970.4
1243.28	20893.5
1245.46	20884.3
1247.65	20755.5
1249.83	20677.7
1252.02	20703.4
1254.2	20533.7
1256.38	20528.3
1258.56	20393.1
1260.74	20381.1
1262.92	20311.3
1265.1	20296.6
1267.28	20178.4
1269.46	20158.2
1271.64	20088.7
1273.82	20014.7
1275.99	19950.2
1278.17	19917.6
1280.34	19881.2
1282.52	19753.3
1284.69	19535.4
1286.86	19600.3
1289.03	19542.2
1291.21	19355.4
1293.38	19194.4
1295.55	19257.1
1297.71	19412.6
1299.88	19099.1
1302.05	19052
1304.22	18899.4
1306.38	18879.9
1308.43	18704
1310.61	18692
1312.78	18530
1314.96	18442
1317.13	18398
1319.3	18310
1321.48	18346
1323.65	18142
1325.82	17966
1327.99	18012
1330.16	17748
1332.33	17574
1334.5	17534
1336.66	17390
1338.83	17468
1341	17162
1343.16	17196
1345.33	17224
1347.49	16900
1349.65	16824
1351.82	16956
1353.98	16620
1356.14	16556
1358.3	16598
1360.46	16536
1362.62	16382
1364.78	16312
1366.94	16298
1369.09	16176
1371.25	15976
1373.41	15946
1375.56	15904
1377.72	15838
1379.87	15806
1382.02	15522
1384.17	15608
1386.33	15570
1388.48	15600
1390.63	15482
1392.78	15408
1394.93	15138
1397.07	15218
1399.22	15218
1401.37	15084
1403.52	14990
1405.66	14992
1407.81	14826
1409.95	14656
1412.09	14596
1414.24	14636
1416.38	14674
1418.52	14516
1420.66	14484
1422.8	14436
1424.94	14374
1427.08	14384
1429.22	14258
1431.35	14064
1433.49	14130
1435.63	14178
1437.76	13948
1439.9	14078
1442.03	13954
1444.17	13934
1446.3	13936
1448.43	13798
1450.56	13700
1452.69	13714
1454.82	13704
1456.95	13624
1459.08	13638
1461.21	13656
1463.34	13512
1465.46	13576
1467.59	13410
1469.71	13416
1471.84	13404
1473.96	13380
1476.08	13272
1478.21	13336
1480.33	13260
1482.45	13138
1484.57	13110
1486.69	13082
1488.81	13024
1490.93	12974
1493.05	12888
1495.16	12994
1497.28	12848
1499.4	12848
1501.51	12842
1503.63	12692
1505.74	12798
1507.85	12646
1509.97	12758
1512.08	12552
1514.19	12488
1516.3	12594
1518.41	12456
1520.52	12460
1522.63	12380
1524.73	12458
1526.84	12206
1528.95	12270
1531.06	12032
1533.16	12048
1535.26	12260
1537.37	12042
1539.47	12018
1541.57	11930
1543.68	11982
1545.78	11944
1547.88	11802
1549.98	11848
1552.08	11738
1554.18	11810
1556.27	11714
1558.37	11598
1560.47	11694
1562.56	11650
1564.66	11594
1566.75	11602
1568.85	11534
1570.94	11516
1573.03	11536
1575.13	11408
1577.22	11424
1579.31	11590
1581.4	11506
1583.49	11428
1585.58	11262
1587.66	11416
1589.75	11346
1591.84	11348
1593.93	11366
1596.01	11280
1598.1	11212
1600.18	11284
1602.26	11212
1604.35	11224
1606.43	11156
1608.51	11228
1610.59	11208
1612.67	11210
1614.75	11274
1616.83	11232
1618.91	11102
1620.99	11086
1623.06	11066
1625.14	11150
1627.21	11018
1629.29	11036
1631.36	11150
1633.44	10962
1635.51	10930
1637.58	10992
1639.66	11084
1641.73	10930
1643.8	10932
1645.87	10856
1647.94	10866
1650	10830
1652.07	10764
1654.14	10710
1656.21	10664
1658.27	10726
1660.34	10676
1662.4	10664
1664.47	10524
1666.53	10600
1668.59	10640
1670.66	10462
1672.72	10540
1674.78	10410
1676.84	10368
1678.9	10402
1680.96	10370
1683.01	10350
1685.07	10382
1687.13	10374
1689.19	10214
1691.24	10228
1693.3	10126
1695.35	10270
1697.4	10154
1699.46	9988
1701.51	10146
1703.56	10104
1705.61	10148
1707.66	10144
1709.71	9960
1711.76	10082
1713.81	9962
1715.86	10174
1717.91	9874
1719.95	9874
1722	9904
1724.04	9752
1726.09	9844
1728.13	9892
1730.18	9854
1732.22	9808
1734.26	9814
1736.3	9898
1738.34	9772
1740.38	9842
1742.42	9744
1744.46	9746
1746.5	9706
1748.54	9640
1750.58	9678
1752.61	9516
1754.65	9756
1756.68	9598
1758.72	9568
1760.75	9606
1762.79	9698
1764.82	9632
1766.85	9582
1768.88	9682
1770.91	9668
1772.94	9694
1774.97	9704
1777	9654
1779.03	9556
1781.06	9648
1783.09	9460
1785.11	9536
1787.14	9544
1789.16	9518
1791.19	9454
1793.21	9454
1795.23	9548
1797.26	9462
1799.28	9444
1801.3	9316
1803.32	9504
1805.34	9382
1807.36	9374
1809.38	9320
1811.4	9330
1813.42	9286
1815.43	9284
1817.45	9220
1819.47	9300
1821.48	9260
1823.49	9198
1825.51	9050
1827.52	9188
1829.54	9236
1831.55	9084
1833.56	9190
1835.57	9084
1837.58	9178
1839.59	9046
1841.6	8988
1843.61	8922
1845.61	8966
1847.62	8992
1849.63	9042
1851.63	8934
1853.64	8996
1855.64	8952
1857.65	8966
1859.65	9010
1861.65	8844
1863.65	8866
1865.66	8888
1867.66	8770
1869.66	8924
1871.66	8990
1873.66	8818
1875.65	8846
1877.65	8932
1879.65	8726
1881.65	8778
1883.64	8722
1885.64	8730
1887.63	8726
1889.63	8792
1891.62	8758
1893.61	8780
1895.6	8708
1897.6	8716
1899.59	8692
1901.58	8736
1903.57	8760
1905.56	8756
1907.54	8648
1909.53	8672
1911.52	8642
1913.51	8654
1915.49	8634
1917.48	8640
1919.46	8694
1921.45	8724
1923.43	8606
1925.41	8560
1927.4	8616
1929.38	8466
1931.36	8676
1933.34	8562
1935.32	8526
1937.3	8482
1939.28	8592
1941.26	8684
1943.23	8546
1945.21	8552
1947.19	8468
1949.16	8440
1951.14	8390
1953.11	8488
1955.09	8404
1957.06	8474
1959.03	8410
1961	8380
1962.98	8440
1964.95	8340
1966.92	8274
1968.89	8364
1970.85	8334
1972.82	8396
1974.79	8384
1976.76	8376
1978.73	8286
1980.69	8242
1982.66	8246
1984.62	8230
1986.59	8352
1988.55	8292
1990.51	8198
1992.47	8202
1994.44	8196
1996.4	8134
1998.36	8184
2000.32	8130
2002.28	8116
2004.24	8174
2006.19	8198
2008.15	8258
2010.11	8096
2012.06	8134
2014.02	8178
2015.98	8116
2017.93	8068
2019.88	8156
2021.84	7988
2023.79	8176
2025.74	8086
2027.69	8018
2029.65	8048
2031.6	8096
2033.55	8086
2035.5	8042
2037.44	7996
2039.39	8036
2041.34	7990
2043.29	8130
2045.23	7968
2047.18	7932
2049.12	7966
2051.07	7952
2053.01	7960
2054.95	7958
2056.9	7888
2058.84	7954
2060.78	7874
2062.72	7754
2064.66	7830
2066.6	7864
2068.54	7826
2070.48	7796
2072.42	7836
2074.35	7844
2076.29	7838
2078.23	7794
2080.16	7722
2082.1	7778
2084.03	7758
2085.96	7830
2087.9	7758
2089.83	7816
2091.76	7694
2093.69	7680
2095.62	7826
2097.55	7800
2099.48	7690
2101.41	7736
2103.34	7712
2105.27	7726
2107.2	7698
2109.12	7604
2111.05	7680
2112.98	7606
2114.9	7658
2116.82	7544
2118.75	7556
2120.67	7598
2122.59	7588
2124.52	7578
2126.44	7558
2128.36	7616
2130.28	7462
2132.2	7530
2134.12	7496
2136.04	7510
2137.95	7572
2139.87	7506
2141.79	7430
2143.7	7498
2145.62	7419.58
2147.53	7358.57
2149.45	7499.21
2151.36	7421.79
2153.28	7337.18
2155.19	7341.98
2157.1	7381.09
2159.01	7363.36
2160.92	7281.52
2162.83	7344.52
2164.74	7318.34
2166.65	7302.34
2168.56	7326.6
2170.47	7328.23
2172.38	7226.05
2174.28	7208.74
2176.19	7201.18
2178.09	7249.2
2180	7225.26
2181.9	7237.37
2183.81	7109.64
2185.71	7215.15
2187.61	7214.76
2189.52	7179.82
2191.42	7146.94
2193.32	7179.07
2195.22	7087.88
2197.12	7079.93
2199.02	7150.81
2200.92	7092.4
2202.82	7062.72
2204.71	7109.05
2206.61	7050
2208.51	7135.82
2210.4	7095.38
2212.3	7053.34
2214.19	7053.38
2216.09	7080.44
2217.98	7009.05
2219.87	7057.57
2221.77	6959.01
2223.66	7001.44
2225.55	7009.18
2227.44	7003.85
2229.33	6989.58
2231.22	6976.96
2233.11	7068.8
2235	7090.64
2236.88	7010.7
2238.77	6990.67
2240.66	7033.72
2242.07	7038
2243.97	7032
2245.87	7070
2247.76	7056
2249.65	6980
2251.55	7142
2253.44	6874
2255.33	7014
2257.22	7036
2259.12	6944
2261.01	7046
2262.9	6988
2264.78	7070
2266.67	6952
2268.56	7024
2270.45	6916
2272.34	6914
2274.22	6944
2276.11	6946
2277.99	6884
2279.88	6830
2281.76	6766
2283.65	6814
2285.53	6958
2287.41	6754
2289.3	6890
2291.18	6874
2293.06	6916
2294.94	6834
2296.82	6870
2298.7	6862
2300.58	6802
2302.46	6854
2304.33	6758
2306.21	6790
2308.09	6796
2309.96	6790
2311.84	6860
2313.71	6714
2315.59	6700
2317.46	6742
2319.33	6720
2321.21	6678
2323.08	6654
2324.95	6724
2326.82	6636
2328.69	6570
2330.56	6640
2332.43	6618
2334.3	6680
2336.17	6684
2338.03	6678
2339.9	6638
2341.77	6502
2343.63	6576
2345.5	6594
2347.36	6558
2349.23	6586
2351.09	6638
2352.95	6598
2354.82	6550
2356.68	6476
2358.54	6528
2360.4	6464
2362.26	6630
2364.12	6484
2365.98	6412
2367.84	6514
2369.7	6584
2371.56	6538
2373.41	6450
2375.27	6428
2377.12	6430
2378.98	6376
2380.84	6532
2382.69	6366
2384.54	6402
2386.4	6422
2388.25	6382
2390.1	6398
2391.95	6442
2393.8	6342
2395.65	6338
2397.5	6366
2399.35	6336
2401.2	6328
2403.05	6324
2404.9	6292
2406.75	6246
2408.59	6340
2410.44	6256
2412.28	6298
2414.13	6430
2415.97	6206
2417.82	6158
2419.66	6170
2421.5	6130
2423.35	6264
2425.19	6282
2427.03	6184
2428.87	6150
2430.71	6180
2432.55	6206
2434.39	6130
2436.23	6134
2438.06	6046
2439.9	6236
2441.74	6196
2443.57	6066
2445.41	6142
2447.24	6140
2449.08	6010
2450.91	6008
2452.75	6016
2454.58	6052
2456.41	6012
2458.24	6048
2460.08	5962
2461.91	5970
2463.74	5998
2465.57	6098
2467.4	5964
2469.22	6020
2471.05	5990
2472.88	5992
2474.71	5900
2476.53	5892
2478.36	5944
2480.19	5936
2482.01	5950
2483.83	5850
2485.66	5860
2487.48	5914
2489.3	5760
2491.13	5762
2492.95	5760
2494.77	5756
2496.59	5846
2498.41	5774
2500.23	5788
2502.05	5754
2503.87	5664
2505.68	5636
2507.5	5668
2509.32	5732
2511.14	5652
2512.95	5664
2514.77	5568
2516.58	5626
2518.39	5658
2520.21	5666
2522.02	5562
2523.83	5578
2525.65	5610
2527.46	5568
2529.27	5566
2531.08	5592
2532.89	5550
2534.7	5622
2536.51	5594
2538.32	5526
2540.12	5576
2541.93	5500
2543.74	5456
2545.54	5548
2547.35	5418
2549.15	5326
2550.96	5338
2552.76	5380
2554.56	5352
2556.37	5434
2558.17	5310
2559.97	5368
2561.77	5280
2563.58	5340
2565.38	5298
2567.18	5296
2568.97	5314
2570.77	5254
2572.57	5290
2574.37	5292
2576.17	5270
2577.96	5218
2579.76	5222
2581.55	5230
2583.35	5296
2585.14	5232
2586.94	5190
2588.73	5240
2590.52	5264
2592.32	5226
2594.11	5174
2595.9	5120
2597.69	5138
2599.48	5036
2601.27	5112
2603.06	5120
2604.85	5092
2606.64	5082
2608.42	5072
2610.21	5064
2612	5066
2613.78	4972
2615.57	4966
2617.36	4932
2619.14	4906
2620.92	5004
2622.71	4966
2624.49	4920
2626.27	4864
2628.05	4860
2629.84	4894
2631.62	4820
2633.4	4950
2635.18	4900
2636.96	4914
2638.74	4812
2640.51	4754
2642.29	4738
2644.07	4720
2645.85	4710
2647.62	4696
2649.4	4766
2651.17	4704
2652.95	4668
2654.72	4722
2656.5	4756
2658.27	4734
2660.04	4688
2661.81	4692
2663.58	4606
2665.35	4612
2667.13	4734
2668.9	4610
2670.66	4594
2672.43	4646
2674.2	4676
2675.97	4662
2677.74	4606
2679.5	4600
2681.27	4630
2683.04	4588
2684.8	4588
2686.57	4506
2688.33	4542
2690.09	4484
2691.86	4508
2693.62	4408
2695.38	4546
2697.15	4522
2698.91	4360
2700.67	4434
2702.43	4456
2704.19	4406
2705.95	4486
2707.7	4400
2709.46	4352
2711.22	4392
2712.98	4384
2714.73	4328
2716.49	4370
2718.25	4354
2720	4362
2721.76	4290
2723.51	4364
2725.26	4280
2727.02	4238
2728.77	4226
2730.52	4206
2732.27	4248
2734.02	4150
2735.77	4272
2737.52	4186
2739.27	4096
2741.02	4234
2742.77	4148
2744.52	4098
2746.27	4168
2748.01	4112
2749.76	4082
2751.51	4102
2753.25	4082
2755	3992
2756.74	4034
2758.48	4034
2760.23	4086
2761.97	3964
2763.71	4024
2765.45	3980
2767.19	4040
2768.94	3982
2770.68	3990
2772.42	3998
2774.16	3994
2775.89	3970
2777.63	3962
2779.37	3980
2781.11	3914
2782.84	3896
2784.58	3912
2786.32	3932
2788.05	4016
2789.79	3882
2791.52	3866
2793.25	3830
2794.99	3828
2796.72	3830
2798.45	3800
2800.18	3824
2801.92	3796
2803.65	3812
2805.38	3812
2807.11	3744
2808.84	3794
2810.57	3816
2812.29	3716
2814.02	3708
2815.75	3676
2817.47	3722
2819.2	3752
2820.93	3716
2822.65	3656
2824.38	3620
2826.1	3710
2827.82	3622
2829.55	3660
2831.27	3546
2832.99	3654
2834.71	3564
2836.44	3572
2838.16	3630
2839.88	3630
2841.6	3522
2843.32	3550
2845.03	3560
2846.75	3540
2848.47	3418
2850.19	3474
2851.9	3494
2853.62	3494
2855.34	3490
2857.05	3452
2858.77	3452
2860.48	3426
2862.19	3426
2863.91	3408
2865.62	3378
2867.33	3350
2869.04	3364
2870.76	3248
2872.47	3358
2874.18	3340
2875.89	3288
2877.6	3370
2879.31	3314
2881.01	3270
2882.72	3318
2884.43	3342
2886.14	3336
2887.84	3288
2889.55	3288
2891.25	3182
2892.96	3304
2894.66	3268
2896.37	3218
2898.07	3240
2899.77	3240
2901.48	3254
2903.18	3178
2904.88	3252
2906.58	3242
2908.28	3172
2909.98	3224
2911.68	3176
2913.38	3142
2915.08	3120
2916.78	3174
2918.47	3170
2920.17	3108
2921.87	3136
2923.56	3146
2925.26	3106
2926.95	3126
2928.65	3074
2930.34	3122
2932.04	3028
2933.73	3036
2935.42	3104
2937.11	3084
2938.81	3000
2940.5	3024
2942.19	3068
2943.88	3034
2945.57	3040
2947.26	3008
2948.95	3008
2950.64	2940
2952.32	3046
2954.01	2904
2955.7	3048
2957.38	3058
2959.07	3014
2960.75	2972
2962.44	2948
2964.12	2970
2965.81	2908
2967.49	2918
2969.17	2886
2970.86	2924
2972.54	2882
2974.22	2894
2975.9	2890
2977.58	2852
2979.26	2892
2980.94	2874
2982.62	2896
2984.3	2884
2985.98	2846
2987.66	2866
2989.33	2816
2991.01	2854
2992.69	2794
2994.36	2810
2996.04	2802
2997.71	2820
2999.39	2732