File: muestras/tallo/2/Organic_03.txt
#Acq. time (s)=	10
#Accumulations=	1
#Range (cm-¹)=	100...3000
#Windows=	3
#Autofocus=	Off
#AutoExposure=	Off
#Spike filter=	Off
#Delay time (s)=	0
#Binning=	1
#Readout mode=	Signal
#DeNoise=	Off
#ICS correction=	Off
#Dark correction=	Off
#Inst. Process=	Off
#Instrument=	LabRAM HR Evol
#Detector=	Syncerity OE
#Objective=	x100_VIS
#Grating=	600 (500nm)
#ND Filter=	3.2%
#Laser=	633nm_Edge
#Hole=	100.021
#Range=	Visible
#Project=	Omar
#Sample=	26-06-23
#Site=	2
#Title=	Organic
#Remark=
#Date=	26.06.2023 16:17
#Acquired=	26.06.2023 16:17:54
101.018	4328
103.586	4332
106.152	4302
108.717	4374
111.281	4358
113.845	4458
116.407	4414
118.969	4412
121.53	4516
124.09	4466
126.649	4478
129.207	4522
131.765	4534
134.321	4576
136.877	4612
139.432	4548
141.985	4658
144.538	4594
147.09	4526
149.641	4610
152.191	4662
154.741	4662
157.289	4620
159.837	4664
162.385	4788
164.93	4722
167.476	4780
170.019	4796
172.562	4818
175.105	4782
177.646	4794
180.188	4756
182.727	4754
185.266	4704
187.804	4852
190.342	4864
192.878	4906
195.413	4934
197.948	4918
200.481	4834
203.014	5026
205.546	4940
208.077	5038
210.608	5014
213.137	5058
215.666	4968
218.194	5050
220.721	5058
223.247	5062
225.772	5168
228.295	5206
230.819	5264
233.342	5172
235.864	5294
238.384	5316
240.904	5366
243.423	5388
245.941	5296
248.46	5332
250.975	5470
253.492	5400
256.006	5326
258.519	5370
261.033	5384
263.545	5342
266.057	5342
268.567	5322
271.076	5412
273.585	5392
276.094	5438
278.601	5570
281.107	5502
283.612	5572
286.116	5500
288.62	5572
291.123	5486
293.625	5666
296.126	5636
298.626	5686
301.126	5710
303.625	5740
306.122	5820
308.62	5800
311.114	5780
313.61	5882
316.105	5894
318.599	5800
321.09	5954
323.583	5894
326.073	5932
328.563	5934
331.053	5818
333.541	6006
336.029	5962
338.515	6030
341.001	5950
343.486	6070
345.97	6058
348.453	5994
350.936	6182
353.418	6112
355.898	6150
358.378	6188
360.858	6142
363.336	6158
365.813	6216
368.29	6096
370.766	6148
373.241	6146
375.715	6310
378.188	6244
380.66	6182
383.132	6282
385.603	6252
388.072	6394
390.541	6260
393.01	6316
395.477	6322
397.943	6420
400.409	6390
402.875	6360
405.338	6358
407.802	6584
410.263	6426
412.725	6508
415.185	6730
417.646	6618
420.104	6626
422.564	6864
425.02	6742
427.477	6848
429.933	6912
432.388	6946
434.841	6940
437.294	6994
439.748	6908
442.199	6992
444.65	6882
447.1	6992
449.549	6922
451.997	6926
454.445	7022
456.891	7004
459.337	6954
461.782	7030
464.227	7224
466.669	7066
469.112	7010
471.554	7238
473.995	7184
476.434	7228
478.874	7262
481.312	7282
483.749	7214
486.186	7306
488.622	7318
491.057	7422
493.491	7434
495.925	7380
498.357	7360
500.789	7426
503.221	7418
505.65	7570
508.079	7538
510.509	7646
512.936	7576
515.363	7620
517.789	7634
520.214	7620
522.638	7662
525.062	7660
527.485	7608
529.907	7646
532.328	7718
534.748	7710
537.168	7796
539.587	7738
542.005	7650
544.423	7768
546.838	7762
549.254	7906
551.669	7882
554.082	7860
556.496	7960
558.909	8056
561.319	7878
563.731	8006
566.14	8076
568.549	8128
570.957	8106
573.364	8116
575.771	8126
578.177	8216
580.581	8190
582.987	8130
585.39	8224
587.792	8368
590.193	8312
592.594	8360
594.996	8512
597.395	8522
599.793	8390
602.191	8552
604.588	8470
606.984	8618
609.378	8736
611.773	8786
614.167	8822
616.56	8794
618.953	8756
621.343	8970
623.734	9030
626.124	9026
628.512	9236
630.901	9170
633.289	9226
635.675	9336
638.061	9394
640.446	9278
642.831	9412
645.213	9506
647.595	9430
649.978	9596
652.359	9772
654.738	9726
657.117	9690
659.497	9764
661.875	9722
664.252	9926
666.628	9790
669.003	9862
671.378	9974
673.751	9972
676.124	9818
678.497	10064
680.868	10064
683.239	10036
685.609	10220
687.977	10128
690.346	10254
692.714	10384
695.081	10398
697.446	10428
699.812	10536
702.175	10582
704.539	10592
706.901	10780
709.264	10790
711.625	10712
713.986	10710
716.345	10784
718.705	10936
721.062	10896
723.419	11114
725.775	11126
728.132	11176
730.487	11340
732.841	11272
735.194	11344
737.546	11460
739.898	11540
742.249	11460
744.599	11642
746.949	11866
749.298	11786
751.646	11670
753.993	11858
756.34	11920
758.684	11850
761.029	11914
763.374	12068
765.716	12192
768.059	12330
770.401	12340
772.741	12382
775.082	12440
777.421	12314
779.76	12528
782.097	12520
784.434	12654
786.771	12716
789.106	12800
791.44	12780
793.775	12972
796.108	13110
798.44	13178
800.771	13182
803.102	13344
805.432	13288
807.761	13460
810.09	13416
812.417	13662
814.744	13716
817.071	13754
819.396	14036
821.721	13910
824.045	14144
826.367	14214
828.69	14504
831.012	14516
833.332	14434
835.653	14542
837.972	14738
840.29	14992
842.609	15020
844.925	15004
847.242	15088
849.557	15350
851.871	15236
854.186	15468
856.498	15502
858.81	15576
861.122	15814
863.434	15814
865.744	15724
868.053	16008
870.361	16000
872.669	16116
874.976	16284
877.282	16264
879.588	16344
881.893	16590
884.197	16604
886.5	16612
888.802	16588
891.104	16668
893.405	16674
895.706	16914
898.004	16936
900.303	16986
902.6	17124
904.898	17186
907.194	17328
909.49	17354
911.785	17452
914.08	17568
916.372	17560
918.666	17772
920.957	17804
923.248	17902
925.538	17944
927.828	18086
930.118	18070
932.406	18090
934.693	18194
936.979	18504
939.265	18646
941.55	18780
943.835	18938
946.118	19222
948.401	19228
950.682	19208
952.964	19398
955.245	19506
957.525	19666
959.803	19704
962.082	19634
964.36	19772
966.636	19966
968.913	20036
971.188	20138
973.463	20360
975.736	20418
978.009	20328
980.282	20518
982.554	20548
984.824	20720
987.095	20918
989.364	20770
991.633	20852
993.9	20992
996.167	20950
998.434	21300
1000.7	21270
1002.96	21590
1005.23	21604
1007.49	21410
1009.76	21580
1012.02	21934
1014.28	21736
1016.54	21858
1018.8	22102
1021.06	22154
1023.32	22188
1025.57	22400
1027.83	22492
1030.09	22566
1032.34	22692
1034.6	22886
1036.85	23028
1039.1	23066
1041.35	23146
1043.61	23284
1045.86	23288
1048.11	23462
1050.36	23386
1052.61	23728
1054.85	23808
1057.1	23746
1059.35	23986
1061.59	23962
1063.84	24060
1066.08	24170
1068.33	24042
1070.57	23994
1072.81	24210
1075.05	24202
1077.29	24278
1079.53	24284
1081.77	24458
1084.01	24528
1086.25	24600
1088.48	24484
1090.72	24640
1092.96	24332
1095.19	24486
1097.43	24476
1099.66	24526
1101.89	24364
1104.12	24368
1106.35	24534
1108.59	24520
1110.81	24504
1113.04	24570
1115.27	24680
1117.5	24826
1119.73	24670
1121.95	24466
1124.18	24554
1126.4	24640
1128.63	24912
1130.85	24808
1133.07	25040
1135.29	25010
1137.51	25106
1139.73	24960
1141.95	25056
1144.17	25036
1146.39	25110
1148.61	25108
1150.82	25318
1153.04	25216
1155.26	25254
1157.47	25184
1159.68	25180
1161.9	25176
1164.11	25096
1166.32	24990
1168.53	25034
1170.74	25088
1172.95	25062
1175.16	25028
1177.37	25038
1179.58	24784
1181.78	25074
1183.99	24834
1186.19	24696
1188.4	24616
1190.6	24396
1192.8	24560
1195.01	24260
1197.21	24280.4
1199.41	24148.7
1201.61	24034.3
1203.81	24125.6
1206.01	23719.3
1208.2	23939.5
1210.4	23797.2
1212.6	23655.7
1214.8	23520.9
1216.99	23646.6
1219.18	23557.6
1221.38	23363.5
1223.57	23231.1
1225.76	23135.7
1227.96	23102.9
1230.15	23198.3
1232.34	22890.7
1234.53	22881.1
1236.71	22937
1238.9	22807.5
1241.09	22550.2
1243.28	22657.4
1245.46	22471.6
1247.65	22405.5
1249.83	22424.7
1252.02	22370.4
1254.2	22217.3
1256.38	22173.8
1258.56	22092.8
1260.74	22071.9
1262.92	22016.4
1265.1	21905.4
1267.28	21893.5
1269.46	21750.5
1271.64	21679.5
1273.82	21577.8
1275.99	21675.7
1278.17	21496.7
1280.34	21349.1
1282.52	21392.2
1284.69	21151.8
1286.86	21139.9
1289.03	21094.9
1291.21	20850.9
1293.38	20933.2
1295.55	20891.2
1297.71	20648.5
1299.88	20762.8
1302.05	20705.6
1304.22	20410.2
1306.38	20371.6
1308.43	20382
1310.61	20136
1312.78	20120
1314.96	19878
1317.13	19764
1319.3	19554
1321.48	19430
1323.65	19470
1325.82	19432
1327.99	19250
1330.16	19182
1332.33	19066
1334.5	18838
1336.66	18870
1338.83	18908
1341	18610
1343.16	18570
1345.33	18328
1347.49	18272
1349.65	18262
1351.82	18282
1353.98	18044
1356.14	17940
1358.3	17806
1360.46	17774
1362.62	17728
1364.78	17478
1366.94	17362
1369.09	17388
1371.25	17332
1373.41	17244
1375.56	17042
1377.72	17008
1379.87	17064
1382.02	16942
1384.17	16840
1386.33	16706
1388.48	16716
1390.63	16574
1392.78	16596
1394.93	16308
1397.07	16298
1399.22	16256
1401.37	16154
1403.52	16184
1405.66	16192
1407.81	15998
1409.95	15992
1412.09	15944
1414.24	15734
1416.38	15640
1418.52	15644
1420.66	15564
1422.8	15468
1424.94	15428
1427.08	15496
1429.22	15180
1431.35	15352
1433.49	15122
1435.63	15216
1437.76	15280
1439.9	15226
1442.03	14998
1444.17	14998
1446.3	14882
1448.43	14984
1450.56	14860
1452.69	14796
1454.82	14546
1456.95	14848
1459.08	14624
1461.21	14666
1463.34	14714
1465.46	14508
1467.59	14500
1469.71	14494
1471.84	14338
1473.96	14334
1476.08	14210
1478.21	14326
1480.33	14278
1482.45	14162
1484.57	14208
1486.69	13936
1488.81	14046
1490.93	14068
1493.05	13942
1495.16	13924
1497.28	13912
1499.4	13794
1501.51	13702
1503.63	13812
1505.74	13756
1507.85	13638
1509.97	13612
1512.08	13470
1514.19	13512
1516.3	13568
1518.41	13404
1520.52	13464
1522.63	13252
1524.73	13256
1526.84	13266
1528.95	13142
1531.06	13104
1533.16	13058
1535.26	13042
1537.37	12982
1539.47	12848
1541.57	12960
1543.68	12756
1545.78	12668
1547.88	12696
1549.98	12614
1552.08	12760
1554.18	12642
1556.27	12588
1558.37	12438
1560.47	12546
1562.56	12478
1564.66	12406
1566.75	12504
1568.85	12290
1570.94	12320
1573.03	12414
1575.13	12288
1577.22	12250
1579.31	12408
1581.4	12138
1583.49	12256
1585.58	12132
1587.66	12168
1589.75	12104
1591.84	11984
1593.93	12000
1596.01	11998
1598.1	12132
1600.18	12072
1602.26	12042
1604.35	12044
1606.43	12028
1608.51	12064
1610.59	12010
1612.67	11966
1614.75	11958
1616.83	11960
1618.91	11988
1620.99	11896
1623.06	11972
1625.14	11866
1627.21	11826
1629.29	11738
1631.36	11824
1633.44	11652
1635.51	11738
1637.58	11650
1639.66	11742
1641.73	11696
1643.8	11600
1645.87	11588
1647.94	11664
1650	11476
1652.07	11438
1654.14	11514
1656.21	11476
1658.27	11482
1660.34	11536
1662.4	11276
1664.47	11230
1666.53	11326
1668.59	11352
1670.66	11234
1672.72	11150
1674.78	11094
1676.84	11246
1678.9	11178
1680.96	11086
1683.01	10970
1685.07	10946
1687.13	11026
1689.19	10890
1691.24	11020
1693.3	10890
1695.35	10986
1697.4	10844
1699.46	10806
1701.51	10648
1703.56	10864
1705.61	10854
1707.66	10708
1709.71	10748
1711.76	10716
1713.81	10634
1715.86	10596
1717.91	10672
1719.95	10646
1722	10626
1724.04	10590
1726.09	10550
1728.13	10580
1730.18	10538
1732.22	10524
1734.26	10502
1736.3	10436
1738.34	10510
1740.38	10426
1742.42	10506
1744.46	10374
1746.5	10462
1748.54	10282
1750.58	10400
1752.61	10450
1754.65	10356
1756.68	10280
1758.72	10282
1760.75	10246
1762.79	10416
1764.82	10362
1766.85	10340
1768.88	10300
1770.91	10332
1772.94	10014
1774.97	10228
1777	10248
1779.03	10156
1781.06	10162
1783.09	10062
1785.11	10242
1787.14	10180
1789.16	10230
1791.19	10184
1793.21	10142
1795.23	10058
1797.26	10100
1799.28	10142
1801.3	9942
1803.32	9946
1805.34	10106
1807.36	9944
1809.38	9992
1811.4	10084
1813.42	9944
1815.43	9962
1817.45	9978
1819.47	9988
1821.48	9900
1823.49	9940
1825.51	9898
1827.52	9792
1829.54	9832
1831.55	9872
1833.56	9798
1835.57	9776
1837.58	9716
1839.59	9628
1841.6	9522
1843.61	9752
1845.61	9668
1847.62	9556
1849.63	9564
1851.63	9484
1853.64	9620
1855.64	9640
1857.65	9566
1859.65	9484
1861.65	9392
1863.65	9468
1865.66	9434
1867.66	9418
1869.66	9360
1871.66	9458
1873.66	9374
1875.65	9432
1877.65	9422
1879.65	9456
1881.65	9370
1883.64	9322
1885.64	9400
1887.63	9272
1889.63	9408
1891.62	9294
1893.61	9464
1895.6	9352
1897.6	9384
1899.59	9242
1901.58	9204
1903.57	9296
1905.56	9314
1907.54	9368
1909.53	9282
1911.52	9304
1913.51	9406
1915.49	9246
1917.48	9262
1919.46	9300
1921.45	9186
1923.43	9172
1925.41	9206
1927.4	9152
1929.38	9190
1931.36	9224
1933.34	8946
1935.32	9108
1937.3	9150
1939.28	9158
1941.26	9162
1943.23	9132
1945.21	9148
1947.19	9038
1949.16	9036
1951.14	9058
1953.11	9028
1955.09	9044
1957.06	9046
1959.03	8912
1961	8826
1962.98	9048
1964.95	9016
1966.92	9032
1968.89	8936
1970.85	8898
1972.82	8956
1974.79	8930
1976.76	8846
1978.73	8914
1980.69	8864
1982.66	8780
1984.62	8892
1986.59	8728
1988.55	8814
1990.51	8828
1992.47	8848
1994.44	8706
1996.4	8692
1998.36	8680
2000.32	8852
2002.28	8688
2004.24	8606
2006.19	8678
2008.15	8704
2010.11	8714
2012.06	8758
2014.02	8682
2015.98	8632
2017.93	8686
2019.88	8636
2021.84	8540
2023.79	8676
2025.74	8656
2027.69	8564
2029.65	8616
2031.6	8484
2033.55	8504
2035.5	8648
2037.44	8550
2039.39	8550
2041.34	8550
2043.29	8514
2045.23	8536
2047.18	8480
2049.12	8546
2051.07	8450
2053.01	8496
2054.95	8544
2056.9	8458
2058.84	8454
2060.78	8480
2062.72	8380
2064.66	8452
2066.6	8582
2068.54	8414
2070.48	8306
2072.42	8482
2074.35	8356
2076.29	8370
2078.23	8304
2080.16	8358
2082.1	8168
2084.03	8352
2085.96	8308
2087.9	8270
2089.83	8270
2091.76	8358
2093.69	8204
2095.62	8236
2097.55	8304
2099.48	8210
2101.41	8202
2103.34	8254
2105.27	8136
2107.2	8214
2109.12	8138
2111.05	8172
2112.98	8150
2114.9	8152
2116.82	8086
2118.75	8068
2120.67	8098
2122.59	8212
2124.52	8238
2126.44	8066
2128.36	8146
2130.28	8060
2132.2	8060
2134.12	7962
2136.04	8012
2137.95	7998
2139.87	8038
2141.79	8074
2143.7	8016
2145.62	7996.86
2147.53	8043.16
2149.45	8035.06
2151.36	7988.51
2153.28	7898.95
2155.19	7871.3
2157.1	7807.43
2159.01	7906.87
2160.92	7896.8
2162.83	7877.46
2164.74	7797.13
2166.65	7760.67
2168.56	7773.98
2170.47	7840.7
2172.38	7670.58
2174.28	7773.6
2176.19	7736.72
2178.09	7672.24
2180	7794.98
2181.9	7587.73
2183.81	7632.2
2185.71	7634.39
2187.61	7616.7
2189.52	7593.13
2191.42	7652.96
2193.32	7571.56
2195.22	7572.63
2197.12	7557.09
2199.02	7593.16
2200.92	7508.61
2202.82	7549.84
2204.71	7481.65
2206.61	7499.04
2208.51	7551.77
2210.4	7442.96
2212.3	7515.87
2214.19	7490.24
2216.09	7524
2217.98	7456.91
2219.87	7497.73
2221.77	7457.52
2223.66	7538.2
2225.55	7440.78
2227.44	7447.13
2229.33	7480.35
2231.22	7486.96
2233.11	7481.97
2235	7522.34
2236.88	7565.62
2238.77	7515.88
2240.66	7490.31
2242.07	7486
2243.97	7440
2245.87	7482
2247.76	7524
2249.65	7474
2251.55	7478
2253.44	7468
2255.33	7418
2257.22	7416
2259.12	7422
2261.01	7434
2262.9	7292
2264.78	7432
2266.67	7352
2268.56	7386
2270.45	7462
2272.34	7414
2274.22	7340
2276.11	7370
2277.99	7358
2279.88	7384
2281.76	7480
2283.65	7294
2285.53	7400
2287.41	7318
2289.3	7236
2291.18	7244
2293.06	7310
2294.94	7326
2296.82	7224
2298.7	7164
2300.58	7246
2302.46	7198
2304.33	7090
2306.21	7090
2308.09	7250
2309.96	7190
2311.84	7208
2313.71	7108
2315.59	7082
2317.46	7196
2319.33	7072
2321.21	7216
2323.08	7162
2324.95	7070
2326.82	7108
2328.69	7074
2330.56	7040
2332.43	7076
2334.3	7092
2336.17	7030
2338.03	7008
2339.9	7030
2341.77	7040
2343.63	7038
2345.5	7054
2347.36	7076
2349.23	6988
2351.09	7098
2352.95	7032
2354.82	7020
2356.68	6900
2358.54	6932
2360.4	6946
2362.26	6932
2364.12	6932
2365.98	6976
2367.84	7010
2369.7	6934
2371.56	6780
2373.41	6830
2375.27	6894
2377.12	6852
2378.98	6960
2380.84	6856
2382.69	6766
2384.54	6830
2386.4	6830
2388.25	6786
2390.1	6782
2391.95	6834
2393.8	6884
2395.65	6794
2397.5	6726
2399.35	6792
2401.2	6696
2403.05	6724
2404.9	6700
2406.75	6668
2408.59	6688
2410.44	6740
2412.28	6704
2414.13	6726
2415.97	6678
2417.82	6570
2419.66	6642
2421.5	6550
2423.35	6588
2425.19	6642
2427.03	6698
2428.87	6510
2430.71	6560
2432.55	6444
2434.39	6534
2436.23	6472
2438.06	6600
2439.9	6560
2441.74	6460
2443.57	6550
2445.41	6458
2447.24	6450
2449.08	6450
2450.91	6442
2452.75	6392
2454.58	6510
2456.41	6504
2458.24	6282
2460.08	6414
2461.91	6362
2463.74	6452
2465.57	6354
2467.4	6366
2469.22	6334
2471.05	6212
2472.88	6266
2474.71	6292
2476.53	6262
2478.36	6366
2480.19	6202
2482.01	6298
2483.83	6238
2485.66	6212
2487.48	6246
2489.3	6202
2491.13	6222
2492.95	6268
2494.77	6172
2496.59	6144
2498.41	6102
2500.23	6150
2502.05	6112
2503.87	6150
2505.68	6058
2507.5	6018
2509.32	5992
2511.14	6034
2512.95	6060
2514.77	6044
2516.58	5966
2518.39	5932
2520.21	5952
2522.02	5910
2523.83	5916
2525.65	5936
2527.46	5942
2529.27	5968
2531.08	5928
2532.89	5948
2534.7	5828
2536.51	5754
2538.32	5854
2540.12	5794
2541.93	5850
2543.74	5866
2545.54	5840
2547.35	5818
2549.15	5820
2550.96	5778
2552.76	5798
2554.56	5776
2556.37	5730
2558.17	5714
2559.97	5736
2561.77	5706
2563.58	5688
2565.38	5640
2567.18	5566
2568.97	5624
2570.77	5562
2572.57	5586
2574.37	5590
2576.17	5578
2577.96	5516
2579.76	5620
2581.55	5584
2583.35	5584
2585.14	5530
2586.94	5550
2588.73	5558
2590.52	5540
2592.32	5450
2594.11	5478
2595.9	5442
2597.69	5434
2599.48	5460
2601.27	5406
2603.06	5380
2604.85	5368
2606.64	5328
2608.42	5308
2610.21	5334
2612	5418
2613.78	5300
2615.57	5378
2617.36	5314
2619.14	5312
2620.92	5276
2622.71	5300
2624.49	5260
2626.27	5202
2628.05	5172
2629.84	5194
2631.62	5246
2633.4	5198
2635.18	5198
2636.96	5108
2638.74	5182
2640.51	5062
2642.29	5032
2644.07	5080
2645.85	5148
2647.62	5052
2649.4	5046
2651.17	4994
2652.95	4966
2654.72	5108
2656.5	4956
2658.27	4996
2660.04	4928
2661.81	5004
2663.58	4956
2665.35	4962
2667.13	4964
2668.9	4912
2670.66	5006
2672.43	4904
2674.2	4920
2675.97	4920
2677.74	4868
2679.5	4854
2681.27	4920
2683.04	4900
2684.8	4820
2686.57	4836
2688.33	4796
2690.09	4834
2691.86	4724
2693.62	4728
2695.38	4778
2697.15	4724
2698.91	4756
2700.67	4664
2702.43	4734
2704.19	4670
2705.95	4694
2707.7	4668
2709.46	4670
2711.22	4730
2712.98	4616
2714.73	4654
2716.49	4568
2718.25	4602
2720	4584
2721.76	4550
2723.51	4524
2725.26	4548
2727.02	4528
2728.77	4488
2730.52	4528
2732.27	4418
2734.02	4426
2735.77	4506
2737.52	4456
2739.27	4418
2741.02	4420
2742.77	4388
2744.52	4436
2746.27	4402
2748.01	4364
2749.76	4368
2751.51	4358
2753.25	4330
2755	4314
2756.74	4318
2758.48	4328
2760.23	4274
2761.97	4286
2763.71	4314
2765.45	4328
2767.19	4294
2768.94	4304
2770.68	4182
2772.42	4152
2774.16	4222
2775.89	4138
2777.63	4156
2779.37	4214
2781.11	4150
2782.84	4096
2784.58	4100
2786.32	4148
2788.05	4184
2789.79	4030
2791.52	4020
2793.25	4104
2794.99	4122
2796.72	4198
2798.45	4050
2800.18	4092
2801.92	4050
2803.65	4048
2805.38	4032
2807.11	4036
2808.84	4028
2810.57	3986
2812.29	4054
2814.02	3956
2815.75	3990
2817.47	3962
2819.2	3918
2820.93	3906
2822.65	3954
2824.38	3882
2826.1	3900
2827.82	3854
2829.55	3858
2831.27	3898
2832.99	3824
2834.71	3808
2836.44	3810
2838.16	3878
2839.88	3758
2841.6	3796
2843.32	3822
2845.03	3810
2846.75	3690
2848.47	3818
2850.19	3752
2851.9	3792
2853.62	3694
2855.34	3682
2857.05	3670
2858.77	3680
2860.48	3712
2862.19	3596
2863.91	3564
2865.62	3590
2867.33	3560
2869.04	3582
2870.76	3616
2872.47	3592
2874.18	3612
2875.89	3544
2877.6	3532
2879.31	3474
2881.01	3476
2882.72	3476
2884.43	3490
2886.14	3558
2887.84	3474
2889.55	3454
2891.25	3488
2892.96	3456
2894.66	3484
2896.37	3414
2898.07	3462
2899.77	3398
2901.48	3420
2903.18	3400
2904.88	3344
2906.58	3394
2908.28	3360
2909.98	3468
2911.68	3326
2913.38	3382
2915.08	3356
2916.78	3344
2918.47	3380
2920.17	3306
2921.87	3344
2923.56	3316
2925.26	3326
2926.95	3244
2928.65	3296
2930.34	3278
2932.04	3276
2933.73	3332
2935.42	3264
2937.11	3264
2938.81	3238
2940.5	3212
2942.19	3260
2943.88	3246
2945.57	3252
2947.26	3268
2948.95	3266
2950.64	3182
2952.32	3252
2954.01	3230
2955.7	3192
2957.38	3212
2959.07	3148
2960.75	3148
2962.44	3158
2964.12	3078
2965.81	3078
2967.49	3098
2969.17	3150
2970.86	3044
2972.54	3094
2974.22	3080
2975.9	3032
2977.58	3136
2979.26	3058
2980.94	3022
2982.62	3056
2984.3	3084
2985.98	3048
2987.66	3006
2989.33	3016
2991.01	3030
2992.69	2978
2994.36	3018
2996.04	2996
2997.71	2974
2999.39	2924