File: muestras/magnetita1/roy_mg_08.txt
#Acq. time (s)=	25
#Accumulations=	3
#Range (cm-¹)=	100...4000
#Windows=	3
#Autofocus=	Off
#AutoExposure=	Off
#Spike filter=	Multiple accum.
#Delay time (s)=	0
#Binning=	1
#Readout mode=	Signal
#DeNoise=	Off
#ICS correction=	Off
#Dark correction=	Off
#Inst. Process=	Off
#Instrument=	LabRAM HR Evol
#Detector=	Syncerity OE
#Objective=	x100_VIS
#Grating=	600 (500nm)
#ND Filter=	50%
#Laser=	532nm_Edge
#Hole=	150.001
#Range=	Visible
#Project=	Omar
#Sample=
#Site=	27-04-23
#Title=	roy_mg
#Remark=
#Date=	27.04.2023 16:28
#Acquired=	27.04.2023 16:28:02
101.48	284
105.149	357.966
108.817	325.933
112.483	296.899
116.148	325.865
119.811	309.832
123.471	321.798
127.131	285.764
130.79	295.73
134.448	281.697
138.102	325.663
141.757	285.629
145.41	291.596
149.059	292.562
152.71	301.528
156.357	287.495
160.004	293.461
163.648	286.427
167.293	266.393
170.934	290.36
174.576	287.326
178.214	293.292
181.851	282.259
185.489	305.225
189.123	287.191
192.755	281.158
196.389	283.124
200.018	295.09
203.647	302.056
207.274	301.023
210.899	312.989
214.525	318.955
218.148	328.922
221.769	315.888
225.389	296.854
229.008	297.82
232.625	309.787
236.24	292.753
239.855	302.719
243.468	297.686
247.079	320.652
250.689	315.618
254.295	302.585
257.903	298.551
261.509	306.517
265.113	312.483
268.716	300.45
272.315	299.416
275.916	308.382
279.514	315.349
283.11	316.315
286.706	296.281
290.3	310.248
293.891	310.214
297.483	290.18
301.072	296.146
304.661	285.113
308.246	298.079
311.832	292.045
315.415	272.012
318.997	287.978
322.579	279.944
326.157	251.911
329.734	256.877
333.312	253.843
336.887	262.81
340.46	241.776
344.032	259.742
347.602	251.708
351.173	251.675
354.74	257.641
358.307	247.607
361.871	242.574
365.435	251.54
368.997	257.506
372.557	249.473
376.117	246.439
379.675	241.405
383.231	255.371
386.786	251.338
390.338	245.304
393.89	240.27
397.441	247.237
400.991	251.203
404.537	245.169
408.084	241.136
411.63	242.102
415.174	227.068
418.715	247.034
422.256	235.001
425.794	236.967
429.333	242.933
432.868	254.9
436.404	244.866
439.937	235.832
443.47	248.799
447	244.765
450.53	246.731
454.058	246.697
457.583	244.664
461.11	258.63
464.633	255.596
468.155	246.563
471.675	236.529
475.196	253.495
478.714	261.462
482.23	250.428
485.745	253.394
489.259	244.36
492.771	248.327
496.282	251.293
499.791	238.259
503.3	242.226
506.807	249.192
510.312	248.158
513.816	250.125
517.319	244.091
520.821	242.057
524.319	245.023
527.818	251.99
531.315	249.956
534.811	247.922
538.304	262.889
541.798	251.855
545.29	253.821
548.778	259.788
552.268	262.754
555.754	269.72
559.241	266.686
562.724	267.653
566.208	287.619
569.689	287.585
573.171	265.552
576.649	259.518
580.126	280.484
583.603	273.451
587.077	263.417
590.55	280.383
594.023	299.349
597.494	297.316
600.962	279.282
604.43	289.248
607.896	293.215
611.361	293.181
614.825	293.147
618.287	305.114
621.748	303.08
625.207	293.046
628.666	306.012
632.123	286.979
635.578	320.945
639.033	306.911
642.486	304.878
645.937	305.844
649.388	302.81
652.835	318.777
656.283	320.743
659.729	290.709
663.172	310.675
666.616	316.642
670.059	304.608
673.498	312.574
676.938	323.541
680.374	316.507
683.812	302.473
687.246	298.44
690.68	321.406
694.112	300.372
697.544	303.338
700.973	314.305
704.4	301.271
707.828	320.237
711.253	306.204
714.677	316.17
718.099	306.136
721.522	306.103
724.942	302.069
728.36	307.035
731.777	327.001
735.193	313.968
738.608	303.934
742.021	315.9
745.433	287.867
748.844	313.833
752.253	297.799
755.661	311.766
759.068	324.732
762.474	297.698
765.876	311.664
769.279	320.631
772.68	319.597
776.081	307.563
779.478	321.53
782.876	314.496
786.272	323.462
789.666	325.429
793.06	293.395
796.45	312.361
799.842	307.327
803.23	289.294
806.619	319.26
810.004	334.226
813.391	315.193
816.774	317.159
820.156	303.125
823.538	332.092
826.917	291.058
830.295	323.024
833.672	302.99
837.047	296.957
840.424	317.923
843.797	313.889
847.168	310.856
850.539	306.822
853.908	298.788
857.275	315.755
860.642	297.721
864.007	294.687
867.371	290.653
870.734	304.62
874.096	295.586
877.454	284.552
880.813	300.519
884.171	290.485
887.527	290.451
890.881	329.418
894.235	296.384
897.587	304.35
900.937	284.316
904.287	286.283
907.634	288.249
910.982	282.215
914.326	297.182
917.671	285.148
921.013	260.114
924.356	282.081
927.696	276.047
931.034	268.013
934.373	290.979
937.708	289.946
941.043	294.912
944.378	285.878
947.71	285.845
951.041	281.811
954.371	277.777
957.699	277.744
961.026	281.71
964.352	273.676
967.676	284.642
971	269.609
974.322	285.575
977.642	263.541
980.962	285.508
984.28	263.474
987.598	266.44
990.912	290.407
994.226	280.373
997.54	279.339
1000.85	273.305
1004.16	273.272
1007.47	285.238
1010.78	279.204
1014.08	285.171
1017.39	279.137
1020.69	272.103
1024	285.07
1027.3	265.036
1030.6	285.002
1033.9	289.968
1037.19	274.935
1040.49	280.901
1043.79	286.867
1047.08	264.834
1050.37	268.8
1053.66	285.766
1056.95	268.733
1060.24	280.699
1063.53	289.665
1066.81	280.631
1070.1	277.598
1073.38	276.564
1076.66	277.53
1079.94	276.497
1083.22	293.463
1086.5	266.429
1089.78	288.396
1093.06	266.362
1096.33	274.328
1099.6	276.294
1102.87	272.261
1106.15	275.227
1109.41	262.193
1112.68	286.16
1115.95	288.126
1119.21	294.092
1122.48	276.059
1125.74	266.025
1129	283.991
1132.26	271.957
1135.52	293.924
1138.78	291.89
1142.04	288.856
1145.29	290.823
1148.55	273.789
1151.8	269.755
1155.05	287.722
1158.3	299.688
1161.55	283.654
1164.8	289.62
1168.05	279.587
1171.29	291.553
1174.54	276.519
1177.78	275.486
1181.02	295.452
1184.26	299.418
1187.5	275.385
1190.74	305.351
1193.97	306.317
1197.21	297.283
1200.44	291.25
1203.68	295.216
1206.91	303.182
1210.14	301.149
1213.37	297.115
1216.59	293.081
1219.82	316.048
1223.05	307.014
1226.27	292.98
1229.49	292.946
1232.72	308.913
1235.94	296.879
1239.16	301.845
1242.37	292.812
1245.59	305.778
1248.81	297.744
1252.02	290.711
1255.23	308.677
1258.44	308.643
1261.66	298.609
1264.86	300.576
1268.07	300.542
1271.28	306.508
1274.48	296.475
1277.69	300.441
1280.89	322.407
1284.09	317.374
1287.29	320.34
1290.49	322.306
1293.69	320.272
1296.89	330.239
1300.08	320.205
1303.28	314.171
1306.47	309.138
1309.66	318.104
1312.85	312.07
1316.04	332.037
1319.23	336.003
1322.42	331.969
1325.61	326.935
1328.79	322.902
1331.97	342.368
1335.15	336.834
1338.34	319.801
1341.52	333.767
1344.69	337.733
1347.87	330.7
1351.05	328.666
1354.22	318.632
1357.4	323.598
1360.57	327.565
1363.74	352.531
1366.91	330.497
1370.08	340.464
1373.25	334.43
1376.41	326.396
1379.58	327.363
1382.74	309.329
1385.9	333.295
1389.07	349.261
1392.23	319.228
1395.39	325.194
1398.54	341.16
1401.7	349.127
1404.86	331.093
1408.01	348.059
1411.16	330.026
1414.32	330.992
1417.47	342.958
1420.62	328.924
1423.76	339.891
1426.91	322.857
1430.06	350.823
1433.2	339.79
1436.35	338.756
1439.49	339.722
1442.63	362.689
1445.77	349.655
1448.91	360.621
1452.04	352.587
1455.18	357.554
1458.31	340.52
1461.45	341.486
1464.58	340.453
1467.71	348.419
1470.84	342.385
1473.97	350.352
1477.1	352.318
1480.23	340.284
1483.35	348.25
1486.48	339.217
1489.6	356.183
1492.72	348.149
1495.84	360.116
1498.96	358.082
1502.08	359.048
1505.2	352.015
1508.31	345.981
1511.43	373.947
1514.54	364.913
1517.65	347.88
1520.77	349.846
1523.88	359.812
1526.99	357.779
1530.09	377.745
1533.2	335.711
1536.3	354.678
1539.41	378.644
1542.51	357.61
1545.61	347.576
1548.71	366.543
1551.81	374.509
1554.91	375.475
1558.01	379.442
1561.1	388.408
1564.2	364.374
1567.29	383.341
1570.39	391.307
1573.48	382.273
1576.57	381.239
1579.66	369.206
1582.74	377.172
1585.83	372.138
1588.91	367.105
1592	369.071
1595.08	375.037
1598.16	368.004
1601.24	362.97
1604.32	342.936
1607.4	351.902
1610.48	368.869
1613.56	376.835
1616.63	350.801
1619.71	348.768
1622.78	352.734
1625.85	368.7
1628.92	350.667
1631.99	324.633
1635.06	356.599
1638.12	358.565
1641.19	362.532
1644.25	343.498
1647.32	360.44
1650.38	340.693
1653.44	341.313
1656.5	353.671
1659.56	334.641
1662.61	356.149
1665.67	345.324
1668.73	349.915
1671.78	360.944
1674.83	357.079
1677.89	351.23
1680.93	347.083
1683.98	346.052
1687.03	356.177
1690.08	367.554
1693.13	360.26
1696.17	351.32
1699.21	351.327
1702.26	343.427
1705.3	352.351
1708.34	349.441
1711.38	349.371
1714.42	348.694
1717.45	350.308
1720.49	363.93
1723.52	358.222
1726.56	340.572
1729.59	345.542
1732.62	349.039
1735.65	349.636
1738.68	361.818
1741.71	346.883
1744.73	339.973
1747.76	341.845
1750.78	356.08
1753.81	353.885
1756.83	351.884
1759.85	342.773
1762.87	351.373
1765.89	353.635
1768.9	365.088
1771.92	353.835
1774.94	343.33
1777.95	346.969
1780.96	348.825
1783.98	361.121
1786.99	355.582
1789.99	358.637
1793	355.422
1796.01	353.149
1799.02	350.076
1801	366.25
1804.02	336.248
1807.04	368.247
1810.05	364.245
1813.07	344.244
1816.08	344.242
1819.09	356.24
1822.1	342.239
1825.11	358.237
1828.12	362.236
1831.13	354.234
1834.14	361.233
1837.14	359.231
1840.14	338.23
1843.15	358.228
1846.15	352.226
1849.15	352.225
1852.15	372.223
1855.15	362.222
1858.15	352.22
1861.14	356.219
1864.14	352.217
1867.13	334.216
1870.13	365.214
1873.12	354.212
1876.11	358.211
1879.1	357.209
1882.09	347.208
1885.08	359.206
1888.06	364.205
1891.05	357.203
1894.03	359.285
1897.02	364.367
1900	374.449
1902.98	352.531
1905.96	362.613
1908.94	369.695
1911.92	354.777
1914.89	374.859
1917.87	369.941
1920.84	381.023
1923.82	368.105
1926.79	376.187
1929.76	375.269
1932.73	365.351
1935.7	365.433
1938.67	359.515
1941.63	390.597
1944.6	387.679
1947.56	380.761
1950.53	369.843
1953.49	383.925
1956.45	368.007
1959.41	368.09
1962.37	359.172
1965.33	385.254
1968.29	380.336
1971.24	370.418
1974.2	391.5
1977.15	378.582
1980.1	372.664
1983.05	358.746
1986.01	368.828
1988.95	390.91
1991.9	356.992
1994.85	377.074
1997.79	377.156
2000.74	378.238
2003.68	349.32
2006.63	368.402
2009.57	379.484
2012.51	365.566
2015.45	376.648
2018.39	384.73
2021.33	385.812
2024.26	384.894
2027.2	378.976
2030.13	373.058
2033.06	396.14
2036	391.222
2038.93	392.304
2041.86	396.386
2044.79	372.468
2047.71	376.55
2050.64	386.632
2053.56	385.714
2056.49	385.796
2059.41	378.878
2062.34	394.96
2065.26	393.042
2068.18	375.124
2071.1	394.206
2074.01	368.288
2076.93	375.37
2079.85	380.452
2082.76	385.534
2085.68	389.616
2088.59	381.698
2091.5	366.78
2094.41	369.862
2097.32	385.944
2100.23	372.026
2103.14	379.108
2106.04	383.19
2108.95	386.272
2111.85	386.354
2114.76	407.436
2117.66	380.518
2120.56	393.6
2123.46	366.682
2126.36	366.764
2129.25	382.846
2132.15	387.929
2135.05	381.011
2137.94	385.093
2140.84	378.175
2143.73	381.257
2146.62	397.339
2149.51	390.421
2152.4	396.503
2155.29	391.585
2158.18	389.667
2161.06	391.749
2163.95	379.831
2166.83	378.913
2169.71	392.995
2172.6	389.077
2175.48	401.159
2178.36	383.241
2181.24	406.323
2184.11	390.405
2186.99	381.487
2189.87	380.569
2192.74	382.651
2195.61	389.733
2198.49	390.815
2201.36	390.897
2204.23	382.979
2207.1	387.061
2209.97	385.143
2212.84	389.225
2215.7	382.307
2218.57	390.389
2221.43	394.471
2224.29	378.553
2227.16	387.635
2230.02	396.717
2232.88	379.799
2235.74	383.881
2238.59	383.963
2241.45	386.045
2244.31	356.127
2247.16	377.209
2250.02	374.291
2252.87	372.373
2255.72	390.455
2258.57	375.537
2261.42	375.619
2264.27	384.701
2267.12	382.783
2269.96	384.865
2272.81	383.947
2275.65	385.029
2278.5	397.111
2281.34	381.193
2284.18	383.275
2287.02	389.357
2289.86	373.439
2292.7	391.521
2295.54	406.603
2298.37	391.686
2301.21	400.768
2304.04	407.85
2306.88	375.932
2309.71	391.014
2312.54	390.096
2315.37	399.178
2318.2	408.26
2321.03	393.342
2323.85	399.424
2326.68	425.506
2329.5	429.588
2332.33	416.67
2335.15	400.752
2337.97	394.834
2340.79	383.916
2343.61	394.998
2346.43	389.08
2349.25	389.162
2352.07	401.244
2354.88	389.326
2357.7	394.408
2360.51	378.49
2363.32	379.572
2366.14	381.654
2368.95	400.736
2371.76	393.818
2374.57	395.9
2377.37	378.982
2380.18	388.064
2382.99	370.146
2385.79	404.228
2388.59	396.31
2391.4	392.392
2394.2	385.474
2397	380.556
2399.8	388.638
2402.6	392.72
2405.4	384.802
2408.19	390.884
2410.99	384.966
2413.78	398.048
2416.57	389.13
2419.37	388.212
2422.16	398.294
2424.95	402.376
2427.74	393.458
2430.53	406.54
2433.32	403.622
2436.1	385.704
2438.89	406.786
2441.67	405.868
2444.46	391.95
2447.24	408.032
2450.02	411.114
2452.8	388.196
2455.58	392.278
2458.36	404.36
2461.14	418.443
2463.91	402.525
2466.69	407.607
2469.46	415.689
2472.24	413.771
2475.01	411.853
2477.78	405.935
2480.55	418.017
2483.32	421.099
2486.09	419.181
2488.86	425.263
2491.62	408.345
2494.39	415.427
2497.15	403.509
2499.92	417.591
2502.68	422.673
2505.44	411.755
2508.2	404.837
2510.96	426.919
2513.72	412.001
2516.48	406.083
2519.23	426.165
2521.99	426.247
2524.74	402.329
2527.5	380.411
2530.25	412.493
2533	419.575
2535.75	404.657
2538.5	416.739
2541.25	394.821
2544	421.903
2546.75	405.985
2549.49	429.067
2552.24	403.149
2554.98	411.231
2557.72	405.313
2560.47	420.395
2563.21	427.477
2565.95	409.559
2568.69	425.641
2571.42	421.723
2574.16	403.805
2576.9	419.887
2579.63	423.969
2582.37	424.051
2585.1	414.133
2587.83	421.215
2590.56	428.297
2593.29	435.379
2596.02	419.461
2598.75	414.543
2601.48	416.625
2604.2	412.707
2606.93	441.789
2609.65	413.871
2612.38	396.953
2615.1	442.035
2617.82	434.117
2620.54	426.199
2623.26	425.281
2625.98	429.364
2628.7	437.445
2631.41	447.528
2634.13	419.61
2636.84	432.692
2639.56	448.774
2642.27	419.856
2644.98	451.938
2647.69	443.02
2650.4	430.102
2653.11	426.184
2655.82	443.266
2658.53	447.348
2661.23	440.43
2663.94	424.512
2666.64	430.594
2669.34	430.676
2672.05	434.758
2674.75	445.84
2677.45	446.922
2680.15	453.004
2682.85	440.086
2685.54	438.168
2688.24	433.25
2690.93	417.332
2693.63	444.414
2696.32	451.496
2699.02	435.578
2701.71	444.66
2704.4	438.742
2707.09	439.824
2709.78	443.906
2712.46	429.988
2715.15	452.07
2717.84	453.152
2720.52	446.234
2723.21	438.316
2725.89	427.398
2728.57	449.48
2731.25	445.562
2733.93	439.644
2736.61	457.726
2739.29	448.808
2741.97	453.89
2744.64	447.972
2747.32	471.054
2749.99	468.136
2752.67	465.218
2755.34	427.3
2758.01	453.382
2760.68	457.464
2763.35	471.546
2766.02	437.628
2768.69	440.71
2771.35	457.792
2774.02	464.874
2776.68	454.956
2779.35	456.039
2782.01	446.121
2784.67	455.203
2787.34	458.285
2790	448.367
2792.66	448.449
2795.31	464.531
2797.97	466.613
2800.63	463.695
2803.28	463.777
2805.94	462.859
2808.59	475.941
2811.24	467.023
2813.9	475.105
2816.55	475.187
2819.2	449.269
2821.85	465.351
2824.5	471.433
2827.14	471.515
2829.79	447.597
2832.43	470.679
2835.08	475.761
2837.72	464.843
2840.36	477.925
2843.01	462.007
2845.65	448.089
2848.29	470.171
2850.92	448.253
2853.56	490.335
2856.2	450.417
2858.84	460.499
2861.47	472.581
2864.1	492.663
2866.74	468.745
2869.37	479.827
2872	460.909
2874.63	467.991
2877.26	469.073
2879.89	465.155
2882.52	461.237
2885.15	476.319
2887.77	470.401
2890.4	483.483
2893.02	483.565
2895.64	458.647
2898.27	470.729
2900.89	479.811
2903.51	471.893
2906.13	473.975
2908.74	482.057
2911.36	470.139
2913.98	487.221
2916.59	482.303
2919.21	482.385
2921.82	478.467
2924.44	477.549
2927.05	478.631
2929.66	486.713
2932.27	476.796
2934.88	484.878
2937.49	491.96
2940.09	467.042
2942.7	473.124
2945.31	485.206
2947.91	487.288
2950.52	479.37
2953.12	470.534
2955.72	485.786
2958.32	468.328
2960.92	478.434
2963.52	481.139
2966.12	481.169
2968.72	474.993
2971.31	462.783
2973.91	492.463
2976.5	476.694
2979.1	488.861
2981.69	489.113
2984.28	480.633
2986.87	467.047
2989.46	488.388
2992.05	491.407
2994.64	500.013
2997.23	499.832
2999.82	476.851
3002.4	492.495
3004.98	497.499
3007.57	492.19
3010.15	481.418
3012.73	494.642
3015.32	493.919
3017.9	488.798
3020.48	493.748
3023.05	497.561
3025.63	496.993
3028.21	500.248
3030.78	491.515
3033.36	497.822
3035.93	502.403
3038.51	496.041
3041.08	495.136
3043.65	481.257
3046.22	489.868
3048.79	500.36
3051.36	488.916
3053.92	510.204
3056.49	472.403
3059.06	500.665
3061.62	486.623
3064.19	503.67
3066.75	481.713
3069.31	497.662
3071.87	501.68
3074.43	496.565
3076.99	480.717
3079.55	480.648
3082.11	485.357
3083.54	473.526
3086.11	497.585
3088.68	510.644
3091.24	483.703
3093.81	491.762
3096.38	483.822
3098.94	487.881
3101.5	500.94
3104.07	487.999
3106.63	498.058
3109.19	502.117
3111.75	510.176
3114.31	493.235
3116.86	504.294
3119.42	500.353
3121.98	493.413
3124.53	504.472
3127.09	506.531
3129.64	508.59
3132.19	497.649
3134.75	516.708
3137.3	507.767
3139.85	510.826
3142.4	504.885
3144.95	510.944
3147.49	497.004
3150.04	507.063
3152.58	499.122
3155.13	502.181
3157.67	479.24
3160.22	509.299
3162.76	505.358
3165.3	509.417
3167.84	492.476
3170.38	507.535
3172.92	496.595
3175.46	495.654
3177.99	495.713
3180.53	513.772
3183.07	486.831
3185.6	513.89
3188.13	488.949
3190.67	504.008
3193.2	506.067
3195.73	517.127
3198.26	501.186
3200.79	510.245
3203.32	503.304
3205.84	521.363
3208.37	511.422
3210.9	482.481
3213.42	517.54
3215.95	509.599
3218.47	484.658
3220.99	508.718
3223.51	500.777
3226.03	513.836
3228.55	492.895
3231.07	507.954
3233.59	513.013
3236.11	504.072
3238.62	492.131
3241.14	505.19
3243.65	489.249
3246.17	493.309
3248.68	491.368
3251.19	501.427
3253.7	487.486
3256.21	505.545
3258.72	491.604
3261.23	492.663
3263.74	523.722
3266.25	495.781
3268.75	491.841
3271.26	503.9
3273.76	503.959
3276.26	506.018
3278.77	507.077
3281.27	498.136
3283.77	504.195
3286.27	503.254
3288.77	499.313
3291.27	520.372
3293.76	490.432
3296.26	522.491
3298.76	508.55
3301.25	505.609
3303.74	502.668
3306.24	509.727
3308.73	519.786
3311.22	510.845
3313.71	495.904
3316.2	526.964
3318.69	490.023
3321.18	525.082
3323.67	515.141
3326.15	495.2
3328.64	520.259
3331.12	499.318
3333.61	516.377
3336.09	505.436
3338.57	504.495
3341.05	501.555
3343.53	505.614
3346.01	511.673
3348.49	513.732
3350.97	504.791
3353.45	501.85
3355.92	493.909
3358.4	506.968
3360.87	489.027
3363.35	498.086
3365.82	496.146
3368.29	489.205
3370.76	481.264
3373.24	502.323
3375.7	494.382
3378.17	490.441
3380.64	482.5
3383.11	510.559
3385.57	510.618
3388.04	511.677
3390.5	497.737
3392.97	507.796
3395.43	495.855
3397.89	495.914
3400.35	504.973
3402.81	494.032
3405.27	499.091
3407.73	506.15
3410.19	497.209
3412.65	522.268
3415.1	503.328
3417.56	503.387
3420.01	501.446
3422.47	513.505
3424.92	503.564
3427.37	513.623
3429.82	502.682
3432.27	481.741
3434.72	522.8
3437.17	521.859
3439.62	520.919
3442.07	528.978
3444.51	520.037
3446.96	518.096
3449.4	511.155
3451.85	526.214
3454.29	505.273
3456.73	519.332
3459.17	519.391
3461.61	513.451
3464.05	519.51
3466.49	529.569
3468.93	523.628
3471.37	496.687
3473.8	528.746
3476.24	510.805
3478.68	529.864
3481.11	523.923
3483.54	517.983
3485.97	491.042
3488.41	493.101
3490.84	512.16
3493.27	503.219
3495.7	515.278
3498.12	515.337
3500.55	501.396
3502.98	516.455
3505.4	508.514
3507.83	508.574
3510.25	510.633
3512.68	499.692
3515.1	501.751
3517.52	498.81
3519.94	512.869
3522.36	503.928
3524.78	509.987
3527.2	502.046
3529.62	509.105
3532.03	496.165
3534.45	519.224
3536.86	497.283
3539.28	510.342
3541.69	518.401
3544.1	500.46
3546.52	510.519
3548.93	514.578
3551.34	508.637
3553.75	490.696
3556.16	511.756
3558.56	502.815
3560.97	495.874
3563.38	503.933
3565.78	504.992
3568.19	523.051
3570.59	512.11
3572.99	520.169
3575.4	505.228
3577.8	505.288
3580.2	504.347
3582.6	506.406
3585	509.465
3587.4	516.524
3589.79	502.583
3592.19	510.642
3594.58	518.701
3596.98	522.76
3599.37	518.819
3601.77	523.879
3604.16	533.938
3606.55	528.997
3608.94	521.056
3611.33	504.115
3613.72	521.174
3616.11	533.233
3618.5	502.292
3620.88	505.351
3623.27	524.411
3625.66	532.47
3628.04	521.529
3630.42	524.588
3632.81	509.647
3635.19	502.706
3637.57	510.765
3639.95	519.824
3642.33	508.883
3644.71	512.942
3647.09	531.002
3649.47	512.061
3651.84	510.12
3654.22	518.179
3656.59	516.238
3658.97	511.297
3661.34	494.356
3663.71	522.415
3666.09	500.474
3668.46	524.533
3670.83	511.593
3673.2	498.652
3675.56	508.711
3677.93	483.77
3680.3	491.829
3682.67	501.888
3685.03	505.947
3687.4	511.006
3689.76	525.065
3692.12	498.125
3694.49	514.184
3696.85	497.243
3699.21	509.302
3701.57	500.361
3703.93	510.42
3706.28	485.479
3708.64	525.538
3711	506.597
3713.36	497.656
3715.71	504.716
3718.07	506.775
3720.42	505.834
3722.77	508.893
3725.12	514.952
3727.48	517.011
3729.83	523.07
3732.18	497.129
3734.53	497.188
3736.87	529.247
3739.22	515.307
3741.57	506.366
3743.91	525.425
3746.26	498.484
3748.6	531.543
3750.95	522.602
3753.29	508.661
3755.63	508.72
3757.97	512.779
3760.31	506.839
3762.65	517.898
3764.99	503.957
3767.33	520.016
3769.67	517.075
3772	522.134
3774.34	513.193
3776.67	525.252
3779.01	524.311
3781.34	510.37
3783.67	508.43
3786.01	504.489
3788.34	504.548
3790.67	505.607
3793	507.666
3795.33	526.725
3797.65	510.784
3799.98	508.843
3802.31	520.902
3804.63	508.961
3806.96	513.021
3809.28	518.08
3811.61	499.139
3813.93	521.198
3816.25	495.257
3818.57	517.316
3820.89	487.375
3823.21	527.434
3825.53	513.493
3827.85	489.552
3830.17	498.612
3832.48	509.671
3834.8	483.73
3837.11	492.789
3839.43	503.848
3841.74	509.907
3844.05	483.966
3846.36	490.025
3848.68	508.084
3850.99	516.143
3853.29	499.203
3855.6	499.262
3857.91	506.321
3860.22	505.38
3862.53	492.439
3864.83	502.498
3867.14	510.557
3869.44	511.616
3871.74	500.675
3874.05	497.735
3876.35	497.794
3878.65	511.853
3880.95	514.912
3883.25	515.971
3885.55	508.03
3887.85	494.089
3890.14	511.148
3892.44	494.207
3894.74	498.266
3897.03	500.326
3899.33	513.385
3901.62	501.444
3903.91	511.503
3906.21	509.562
3908.5	502.621
3910.79	514.68
3913.08	523.739
3915.37	518.798
3917.66	529.858
3919.94	521.917
3922.23	514.976
3924.52	513.035
3926.8	503.094
3929.09	519.153
3931.37	523.212
3933.65	507.271
3935.93	512.33
3938.22	505.389
3940.5	506.449
3942.78	511.508
3945.06	507.567
3947.33	518.626
3949.61	502.685
3951.89	482.744
3954.17	505.803
3956.44	502.862
3958.72	503.921
3960.99	520.98
3963.26	505.04
3965.54	488.099
3967.81	525.158
3970.08	498.217
3972.35	483.276
3974.62	504.335
3976.89	505.394
3979.16	499.453
3981.42	501.512
3983.69	498.572
3985.96	488.631
3988.22	502.69
3990.49	508.749
3992.75	494.808
3995.01	479.867
3997.27	501.926
3999.54	503.985