File: muestras/magnetita1/roy_mg_10.txt
#Acq. time (s)=	25
#Accumulations=	3
#Range (cm-¹)=	100...4000
#Windows=	3
#Autofocus=	Off
#AutoExposure=	Off
#Spike filter=	Multiple accum.
#Delay time (s)=	0
#Binning=	1
#Readout mode=	Signal
#DeNoise=	Off
#ICS correction=	Off
#Dark correction=	Off
#Inst. Process=	Off
#Instrument=	LabRAM HR Evol
#Detector=	Syncerity OE
#Objective=	x100_VIS
#Grating=	600 (500nm)
#ND Filter=	100%
#Laser=	532nm_Edge
#Hole=	150.001
#Range=	Visible
#Project=	Omar
#Sample=
#Site=	27-04-23
#Title=	roy_mg
#Remark=
#Date=	27.04.2023 16:40
#Acquired=	27.04.2023 16:40:58
101.48	567
105.149	688.833
108.817	623.666
112.483	584.498
116.148	627.331
119.811	588.164
123.471	622.997
127.131	564.83
130.79	579.663
134.448	549.495
138.102	618.328
141.757	584.161
145.41	548.994
149.059	575.827
152.71	598.66
156.357	576.492
160.004	551.325
163.648	565.158
167.293	570.991
170.934	583.824
174.576	553.657
178.214	568.489
181.851	560.322
185.489	569.155
189.123	585.988
192.755	555.821
196.389	566.654
200.018	591.486
203.647	565.319
207.274	597.152
210.899	598.985
214.525	604.818
218.148	629.651
221.769	572.483
225.389	577.316
229.008	584.149
232.625	579.982
236.24	589.815
239.855	589.648
243.468	601.48
247.079	598.313
250.689	612.146
254.295	601.979
257.903	591.812
261.509	592.645
265.113	609.477
268.716	600.31
272.315	596.143
275.916	602.976
279.514	611.809
283.11	593.642
286.706	589.474
290.3	578.307
293.891	567.14
297.483	580.973
301.072	568.806
304.661	577.638
308.246	564.471
311.832	550.304
315.415	558.137
318.997	570.97
322.579	541.803
326.157	521.635
329.734	510.468
333.312	513.301
336.887	498.134
340.46	487.967
344.032	502.8
347.602	486.632
351.173	480.465
354.74	467.298
358.307	464.131
361.871	454.964
365.435	475.797
368.997	467.629
372.557	481.462
376.117	488.295
379.675	495.128
383.231	482.961
386.786	493.794
390.338	493.626
393.89	472.459
397.441	481.292
400.991	472.125
404.537	479.958
408.084	483.791
411.63	466.623
415.174	472.456
418.715	465.289
422.256	457.122
425.794	448.955
429.333	456.788
432.868	457.62
436.404	456.453
439.937	474.286
443.47	444.119
447	459.952
450.53	455.784
454.058	479.617
457.583	472.45
461.11	483.283
464.633	494.116
468.155	482.949
471.675	473.781
475.196	485.614
478.714	491.447
482.23	492.28
485.745	489.113
489.259	481.946
492.771	481.778
496.282	459.611
499.791	479.444
503.3	475.277
506.807	445.11
510.312	468.943
513.816	445.775
517.319	457.608
520.821	471.441
524.319	432.274
527.818	462.107
531.315	468.94
534.811	472.772
538.304	484.605
541.798	480.438
545.29	482.271
548.778	484.104
552.268	506.937
555.754	496.769
559.241	520.602
562.724	515.435
566.208	523.268
569.689	526.101
573.171	512.934
576.649	521.766
580.126	526.599
583.603	537.432
587.077	548.265
590.55	524.098
594.023	563.93
597.494	543.763
600.962	536.596
604.43	544.429
607.896	542.262
611.361	555.095
614.825	556.927
618.287	561.76
621.748	541.593
625.207	571.426
628.666	566.259
632.123	589.092
635.578	571.924
639.033	554.757
642.486	604.59
645.937	554.423
649.388	585.256
652.835	585.089
656.283	567.921
659.729	593.754
663.172	587.587
666.616	591.42
670.059	601.253
673.498	571.086
676.938	594.918
680.374	610.751
683.812	588.584
687.246	595.417
690.68	577.25
694.112	562.083
697.544	584.915
700.973	579.748
704.4	583.581
707.828	576.414
711.253	573.247
714.677	592.08
718.099	584.912
721.522	611.745
724.942	564.578
728.36	579.411
731.777	566.244
735.193	583.077
738.608	586.909
742.021	601.742
745.433	576.575
748.844	594.408
752.253	599.241
755.661	586.074
759.068	575.906
762.474	597.739
765.876	600.572
769.279	587.405
772.68	621.238
776.081	596.07
779.478	604.903
782.876	589.736
786.272	599.569
789.666	595.402
793.06	586.235
796.45	614.067
799.842	634.9
803.23	608.733
806.619	616.566
810.004	638.399
813.391	603.232
816.774	584.064
820.156	602.897
823.538	582.73
826.917	621.563
830.295	595.396
833.672	606.229
837.047	614.061
840.424	601.894
843.797	574.727
847.168	569.56
850.539	584.393
853.908	588.226
857.275	578.058
860.642	559.891
864.007	575.724
867.371	572.557
870.734	563.39
874.096	562.223
877.454	540.055
880.813	550.888
884.171	570.721
887.527	550.554
890.881	582.387
894.235	561.219
897.587	536.052
900.937	548.885
904.287	558.718
907.634	578.551
910.982	533.384
914.326	554.216
917.671	562.049
921.013	532.882
924.356	529.715
927.696	536.548
931.034	534.381
934.373	531.214
937.708	546.046
941.043	504.879
944.378	522.712
947.71	542.545
951.041	518.378
954.371	512.21
957.699	520.043
961.026	516.876
964.352	519.709
967.676	521.542
971	513.375
974.322	514.207
977.642	526.04
980.962	511.873
984.28	515.706
987.598	530.539
990.912	518.372
994.226	493.204
997.54	492.037
1000.85	516.87
1004.16	493.703
1007.47	504.536
1010.78	501.369
1014.08	509.201
1017.39	509.034
1020.69	523.867
1024	534.7
1027.3	508.533
1030.6	504.366
1033.9	511.198
1037.19	520.031
1040.49	495.864
1043.79	505.697
1047.08	519.53
1050.37	529.363
1053.66	526.195
1056.95	502.028
1060.24	528.861
1063.53	518.694
1066.81	507.527
1070.1	519.359
1073.38	489.192
1076.66	497.025
1079.94	497.858
1083.22	516.691
1086.5	510.524
1089.78	513.357
1093.06	519.189
1096.33	511.022
1099.6	504.855
1102.87	506.688
1106.15	514.521
1109.41	514.353
1112.68	503.186
1115.95	506.019
1119.21	507.852
1122.48	503.685
1125.74	516.518
1129	498.35
1132.26	507.183
1135.52	473.016
1138.78	505.849
1142.04	501.682
1145.29	517.515
1148.55	529.347
1151.8	501.18
1155.05	513.013
1158.3	509.846
1161.55	508.679
1164.8	518.512
1168.05	527.344
1171.29	515.177
1174.54	518.01
1177.78	522.843
1181.02	522.676
1184.26	527.509
1187.5	524.341
1190.74	525.174
1193.97	528.007
1197.21	527.84
1200.44	522.673
1203.68	525.506
1206.91	523.338
1210.14	540.171
1213.37	538.004
1216.59	551.837
1219.82	509.67
1223.05	524.503
1226.27	520.335
1229.49	527.168
1232.72	518.001
1235.94	519.834
1239.16	550.667
1242.37	543.499
1245.59	549.332
1248.81	520.165
1252.02	528.998
1255.23	539.831
1258.44	540.664
1261.66	522.496
1264.86	532.329
1268.07	556.162
1271.28	547.995
1274.48	556.828
1277.69	549.661
1280.89	577.493
1284.09	546.326
1287.29	562.159
1290.49	561.992
1293.69	575.825
1296.89	555.658
1300.08	564.49
1303.28	572.323
1306.47	565.156
1309.66	552.989
1312.85	595.822
1316.04	583.655
1319.23	567.487
1322.42	577.32
1325.61	588.153
1328.79	572.986
1331.97	591.819
1335.15	560.652
1338.34	586.484
1341.52	597.317
1344.69	560.15
1347.87	577.983
1351.05	575.816
1354.22	585.648
1357.4	567.481
1360.57	573.314
1363.74	561.147
1366.91	573.98
1370.08	591.813
1373.25	575.646
1376.41	572.478
1379.58	579.311
1382.74	589.144
1385.9	578.977
1389.07	554.81
1392.23	579.643
1395.39	590.475
1398.54	574.308
1401.7	570.141
1404.86	601.974
1408.01	580.807
1411.16	603.639
1414.32	596.472
1417.47	580.305
1420.62	595.138
1423.76	601.971
1426.91	611.804
1430.06	583.636
1433.2	598.469
1436.35	595.302
1439.49	592.135
1442.63	600.968
1445.77	581.801
1448.91	586.633
1452.04	582.466
1455.18	603.299
1458.31	582.132
1461.45	592.965
1464.58	577.798
1467.71	602.63
1470.84	578.463
1473.97	581.296
1477.1	585.129
1480.23	586.962
1483.35	593.795
1486.48	597.627
1489.6	592.46
1492.72	627.293
1495.84	608.126
1498.96	600.959
1502.08	605.792
1505.2	611.624
1508.31	610.457
1511.43	604.29
1514.54	624.123
1517.65	645.956
1520.77	613.789
1523.88	636.621
1526.99	622.454
1530.09	620.287
1533.2	620.12
1536.3	661.953
1539.41	628.786
1542.51	644.618
1545.61	640.451
1548.71	631.284
1551.81	633.117
1554.91	676.95
1558.01	653.782
1561.1	636.615
1564.2	664.448
1567.29	640.281
1570.39	670.114
1573.48	631.947
1576.57	636.779
1579.66	630.612
1582.74	620.445
1585.83	621.278
1588.91	645.111
1592	652.944
1595.08	630.776
1598.16	597.609
1601.24	638.442
1604.32	599.275
1607.4	619.108
1610.48	636.941
1613.56	611.773
1616.63	636.606
1619.71	631.439
1622.78	623.272
1625.85	615.105
1628.92	617.938
1631.99	613.77
1635.06	628.603
1638.12	593.436
1641.19	590.269
1644.25	600.102
1647.32	610.902
1650.38	599.756
1653.44	594.041
1656.5	611.144
1659.56	604.656
1662.61	615.758
1665.67	601.994
1668.73	593.769
1671.78	600.41
1674.83	601.572
1677.89	607.112
1680.93	613.301
1683.98	607.584
1687.03	598.126
1690.08	607.371
1693.13	620.578
1696.17	596.077
1699.21	599.81
1702.26	618.352
1705.3	601.885
1708.34	592.946
1711.38	602.123
1714.42	598.101
1717.45	611.162
1720.49	614.103
1723.52	609.837
1726.56	607.153
1729.59	606.045
1732.62	606.543
1735.65	593.674
1738.68	590.036
1741.71	602.048
1744.73	597.309
1747.76	603.483
1750.78	602.32
1753.81	590.829
1756.83	596.046
1759.85	591.071
1762.87	606.715
1765.89	597.981
1768.9	596.925
1771.92	597.773
1774.94	620.476
1777.95	606.984
1780.96	614.077
1783.98	615.32
1786.99	594.99
1789.99	613.722
1793	618.154
1796.01	600.648
1799.02	606.928
1801	599.955
1804.02	621.855
1807.04	590.755
1810.05	592.655
1813.07	628.555
1816.08	613.455
1819.09	622.355
1822.1	616.254
1825.11	596.154
1828.12	613.054
1831.13	609.954
1834.14	610.854
1837.14	587.754
1840.14	611.654
1843.15	621.554
1846.15	615.453
1849.15	627.353
1852.15	607.253
1855.15	602.153
1858.15	587.053
1861.14	594.953
1864.14	613.853
1867.13	611.753
1870.13	622.652
1873.12	606.552
1876.11	602.452
1879.1	606.352
1882.09	619.252
1885.08	622.152
1888.06	592.052
1891.05	609.952
1894.03	625.873
1897.02	605.795
1900	629.717
1902.98	608.639
1905.96	607.56
1908.94	620.482
1911.92	633.404
1914.89	608.326
1917.87	617.248
1920.84	627.169
1923.82	609.091
1926.79	623.013
1929.76	623.935
1932.73	615.856
1935.7	621.778
1938.67	627.7
1941.63	615.622
1944.6	606.543
1947.56	622.465
1950.53	614.387
1953.49	628.309
1956.45	619.23
1959.41	618.152
1962.37	614.074
1965.33	607.996
1968.29	613.917
1971.24	617.839
1974.2	620.761
1977.15	615.683
1980.1	600.604
1983.05	615.526
1986.01	605.448
1988.95	633.37
1991.9	613.291
1994.85	605.213
1997.79	618.135
2000.74	607.057
2003.68	634.979
2006.63	612.9
2009.57	622.822
2012.51	619.744
2015.45	608.666
2018.39	632.587
2021.33	623.509
2024.26	628.431
2027.2	603.353
2030.13	592.274
2033.06	612.196
2036	616.118
2038.93	631.04
2041.86	615.961
2044.79	623.883
2047.71	611.805
2050.64	631.727
2053.56	629.648
2056.49	636.57
2059.41	624.492
2062.34	613.414
2065.26	629.335
2068.18	633.257
2071.1	623.179
2074.01	629.101
2076.93	607.022
2079.85	609.944
2082.76	608.866
2085.68	604.788
2088.59	619.709
2091.5	604.631
2094.41	612.553
2097.32	625.475
2100.23	600.397
2103.14	613.318
2106.04	610.24
2108.95	620.162
2111.85	600.084
2114.76	624.005
2117.66	624.927
2120.56	615.849
2123.46	615.771
2126.36	619.692
2129.25	609.614
2132.15	603.536
2135.05	604.458
2137.94	617.379
2140.84	613.301
2143.73	617.223
2146.62	613.145
2149.51	622.066
2152.4	626.988
2155.29	601.91
2158.18	602.832
2161.06	602.753
2163.95	622.675
2166.83	615.597
2169.71	627.519
2172.6	623.44
2175.48	629.362
2178.36	610.284
2181.24	600.206
2184.11	615.128
2186.99	630.049
2189.87	608.971
2192.74	601.893
2195.61	625.815
2198.49	606.736
2201.36	622.658
2204.23	617.58
2207.1	619.502
2209.97	619.423
2212.84	624.345
2215.7	615.267
2218.57	627.189
2221.43	602.11
2224.29	612.032
2227.16	616.954
2230.02	615.876
2232.88	590.797
2235.74	594.719
2238.59	598.641
2241.45	613.563
2244.31	611.484
2247.16	598.406
2250.02	593.328
2252.87	576.25
2255.72	592.171
2258.57	591.093
2261.42	580.015
2264.27	599.937
2267.12	583.859
2269.96	569.78
2272.81	591.702
2275.65	581.624
2278.5	605.546
2281.34	569.467
2284.18	611.389
2287.02	585.311
2289.86	588.233
2292.7	600.154
2295.54	581.076
2298.37	586.998
2301.21	583.92
2304.04	596.841
2306.88	588.763
2309.71	598.685
2312.54	610.607
2315.37	592.528
2318.2	592.45
2321.03	600.372
2323.85	622.294
2326.68	659.215
2329.5	694.137
2332.33	600.059
2335.15	595.981
2337.97	603.902
2340.79	632.824
2343.61	590.746
2346.43	604.668
2349.25	607.59
2352.07	608.511
2354.88	615.433
2357.7	600.355
2360.51	603.277
2363.32	592.198
2366.14	602.12
2368.95	618.042
2371.76	580.964
2374.57	595.885
2377.37	596.807
2380.18	613.729
2382.99	578.651
2385.79	590.572
2388.59	577.494
2391.4	570.416
2394.2	592.338
2397	587.259
2399.8	604.181
2402.6	564.103
2405.4	598.025
2408.19	584.946
2410.99	581.868
2413.78	593.79
2416.57	576.712
2419.37	597.633
2422.16	582.555
2424.95	619.477
2427.74	588.399
2430.53	594.321
2433.32	586.242
2436.1	593.164
2438.89	588.086
2441.67	607.008
2444.46	584.929
2447.24	600.851
2450.02	614.773
2452.8	604.695
2455.58	614.616
2458.36	597.538
2461.14	586.46
2463.91	618.382
2466.69	619.303
2469.46	588.225
2472.24	614.147
2475.01	599.069
2477.78	594.99
2480.55	619.912
2483.32	623.834
2486.09	615.756
2488.86	609.677
2491.62	621.599
2494.39	586.521
2497.15	607.443
2499.92	612.365
2502.68	596.286
2505.44	623.208
2508.2	600.13
2510.96	613.052
2513.72	608.973
2516.48	598.895
2519.23	580.817
2521.99	608.739
2524.74	606.66
2527.5	599.582
2530.25	589.504
2533	592.426
2535.75	614.347
2538.5	596.269
2541.25	588.191
2544	603.113
2546.75	607.034
2549.49	607.956
2552.24	611.878
2554.98	590.8
2557.72	587.721
2560.47	611.643
2563.21	600.565
2565.95	598.487
2568.69	583.408
2571.42	607.33
2574.16	611.252
2576.9	607.174
2579.63	620.096
2582.37	615.017
2585.1	615.939
2587.83	625.861
2590.56	600.783
2593.29	629.704
2596.02	602.626
2598.75	612.548
2601.48	614.47
2604.2	629.391
2606.93	623.313
2609.65	590.235
2612.38	630.157
2615.1	640.078
2617.82	620
2620.54	631.922
2623.26	633.844
2625.98	621.765
2628.7	623.687
2631.41	618.609
2634.13	621.531
2636.84	633.452
2639.56	603.374
2642.27	647.296
2644.98	627.218
2647.69	618.139
2650.4	641.061
2653.11	616.983
2655.82	611.905
2658.53	606.827
2661.23	604.748
2663.94	611.67
2666.64	612.592
2669.34	619.514
2672.05	641.435
2674.75	598.357
2677.45	605.279
2680.15	632.201
2682.85	621.122
2685.54	631.044
2688.24	620.966
2690.93	631.888
2693.63	616.809
2696.32	613.731
2699.02	613.653
2701.71	619.575
2704.4	605.496
2707.09	617.418
2709.78	615.34
2712.46	593.262
2715.15	628.183
2717.84	631.105
2720.52	637.027
2723.21	618.949
2725.89	620.871
2728.57	618.792
2731.25	623.714
2733.93	620.636
2736.61	625.558
2739.29	620.479
2741.97	638.401
2744.64	603.323
2747.32	628.245
2749.99	632.166
2752.67	625.088
2755.34	611.01
2758.01	638.932
2760.68	637.853
2763.35	639.775
2766.02	656.697
2768.69	620.619
2771.35	647.54
2774.02	639.462
2776.68	597.384
2779.35	613.306
2782.01	632.227
2784.67	641.149
2787.34	635.071
2790	639.993
2792.66	655.914
2795.31	643.836
2797.97	623.758
2800.63	646.68
2803.28	648.602
2805.94	636.523
2808.59	632.445
2811.24	618.367
2813.9	641.289
2816.55	616.21
2819.2	630.132
2821.85	642.054
2824.5	639.976
2827.14	657.897
2829.79	647.819
2832.43	652.741
2835.08	641.663
2837.72	650.584
2840.36	638.506
2843.01	631.428
2845.65	654.35
2848.29	641.271
2850.92	639.193
2853.56	631.115
2856.2	658.037
2858.84	643.958
2861.47	635.88
2864.1	672.802
2866.74	653.724
2869.37	653.645
2872	618.567
2874.63	629.489
2877.26	631.411
2879.89	638.333
2882.52	646.254
2885.15	630.176
2887.77	646.098
2890.4	642.02
2893.02	657.941
2895.64	625.863
2898.27	615.785
2900.89	649.707
2903.51	639.628
2906.13	659.55
2908.74	666.472
2911.36	652.394
2913.98	664.315
2916.59	671.237
2919.21	666.159
2921.82	654.081
2924.44	619.002
2927.05	643.924
2929.66	668.846
2932.27	654.768
2934.88	642.689
2937.49	638.611
2940.09	646.533
2942.7	657.455
2945.31	622.376
2947.91	646.298
2950.52	660.22
2953.12	629.22
2955.72	659.714
2958.32	649.505
2960.92	624.804
2963.52	650.11
2966.12	665.806
2968.72	641.4
2971.31	633.999
2973.91	642.652
2976.5	648.783
2979.1	645.649
2981.69	643.291
2984.28	643.336
2986.87	646.486
2989.46	633.123
2992.05	647.761
2994.64	629.966
2997.23	645.44
2999.82	623.407
3002.4	634.987
3004.98	643.929
3007.57	644.064
3010.15	661.153
3012.73	653.305
3015.32	634.887
3017.9	656.681
3020.48	648.866
3023.05	645.096
3025.63	640.793
3028.21	646.409
3030.78	641.661
3033.36	643.493
3035.93	640.599
3038.51	642.589
3041.08	645.065
3043.65	642.365
3046.22	644.913
3048.79	642.008
3051.36	649.165
3053.92	639.42
3056.49	622.831
3059.06	640.913
3061.62	646.808
3064.19	649.483
3066.75	641.561
3069.31	643.941
3071.87	649.818
3074.43	650.324
3076.99	631.154
3079.55	654.63
3082.11	646.173
3083.54	644.417
3086.11	644.404
3088.68	647.392
3091.24	636.379
3093.81	645.366
3096.38	626.353
3098.94	630.341
3101.5	626.328
3104.07	624.315
3106.63	648.302
3109.19	658.29
3111.75	646.277
3114.31	648.264
3116.86	651.251
3119.42	674.239
3121.98	645.226
3124.53	664.213
3127.09	657.2
3129.64	660.188
3132.19	638.175
3134.75	647.162
3137.3	625.149
3139.85	666.137
3142.4	645.124
3144.95	650.111
3147.49	642.098
3150.04	670.086
3152.58	648.073
3155.13	635.06
3157.67	646.047
3160.22	638.035
3162.76	643.022
3165.3	674.009
3167.84	663.996
3170.38	645.984
3172.92	641.971
3175.46	651.958
3177.99	653.945
3180.53	635.933
3183.07	649.92
3185.6	630.907
3188.13	645.894
3190.67	649.882
3193.2	655.869
3195.73	661.856
3198.26	627.843
3200.79	645.831
3203.32	634.818
3205.84	627.805
3208.37	621.792
3210.9	640.78
3213.42	613.767
3215.95	615.754
3218.47	630.741
3220.99	626.729
3223.51	648.716
3226.03	601.703
3228.55	632.69
3231.07	631.677
3233.59	631.665
3236.11	623.652
3238.62	627.639
3241.14	613.626
3243.65	623.614
3246.17	626.601
3248.68	629.588
3251.19	624.575
3253.7	610.563
3256.21	623.55
3258.72	627.537
3261.23	622.524
3263.74	638.512
3266.25	630.499
3268.75	624.486
3271.26	625.473
3273.76	643.461
3276.26	637.448
3278.77	629.435
3281.27	665.422
3283.77	633.41
3286.27	624.397
3288.77	625.384
3291.27	635.371
3293.76	661.359
3296.26	660.346
3298.76	627.333
3301.25	640.32
3303.74	625.308
3306.24	649.295
3308.73	626.282
3311.22	623.269
3313.71	646.257
3316.2	615.244
3318.69	657.231
3321.18	635.218
3323.67	633.206
3326.15	633.193
3328.64	631.18
3331.12	631.167
3333.61	631.155
3336.09	638.142
3338.57	628.129
3341.05	638.116
3343.53	632.104
3346.01	632.091
3348.49	639.078
3350.97	627.065
3353.45	636.053
3355.92	616.04
3358.4	601.027
3360.87	632.014
3363.35	629.002
3365.82	598.989
3368.29	622.976
3370.76	592.963
3373.24	610.951
3375.7	627.938
3378.17	600.925
3380.64	582.912
3383.11	619.9
3385.57	623.887
3388.04	612.874
3390.5	615.861
3392.97	609.849
3395.43	616.836
3397.89	606.823
3400.35	620.81
3402.81	620.797
3405.27	616.785
3407.73	607.772
3410.19	632.759
3412.65	628.746
3415.1	580.734
3417.56	623.721
3420.01	627.708
3422.47	608.695
3424.92	634.683
3427.37	631.67
3429.82	624.657
3432.27	620.644
3434.72	613.632
3437.17	638.619
3439.62	614.606
3442.07	636.593
3444.51	604.581
3446.96	621.568
3449.4	612.555
3451.85	642.542
3454.29	614.53
3456.73	635.517
3459.17	640.504
3461.61	606.491
3464.05	626.479
3466.49	636.466
3468.93	607.453
3471.37	636.44
3473.8	637.428
3476.24	621.415
3478.68	610.402
3481.11	642.389
3483.54	632.377
3485.97	622.364
3488.41	637.351
3490.84	611.338
3493.27	626.326
3495.7	621.313
3498.12	618.3
3500.55	621.287
3502.98	594.275
3505.4	608.262
3507.83	628.249
3510.25	605.236
3512.68	618.224
3515.1	619.211
3517.52	602.198
3519.94	617.185
3522.36	627.173
3524.78	597.16
3527.2	617.147
3529.62	612.134
3532.03	607.122
3534.45	610.109
3536.86	624.096
3539.28	596.083
3541.69	592.07
3544.1	607.058
3546.52	586.045
3548.93	595.032
3551.34	604.02
3553.75	613.007
3556.16	597.994
3558.56	605.981
3560.97	605.969
3563.38	603.956
3565.78	599.943
3568.19	601.93
3570.59	601.917
3572.99	597.905
3575.4	601.892
3577.8	607.879
3580.2	595.866
3582.6	610.854
3585	593.841
3587.4	609.828
3589.79	598.815
3592.19	605.803
3594.58	628.79
3596.98	616.777
3599.37	620.764
3601.77	614.752
3604.16	609.739
3606.55	609.726
3608.94	611.713
3611.33	617.701
3613.72	608.688
3616.11	610.675
3618.5	599.662
3620.88	593.65
3623.27	609.637
3625.66	621.624
3628.04	619.611
3630.42	628.599
3632.81	600.586
3635.19	607.573
3637.57	618.56
3639.95	604.548
3642.33	606.535
3644.71	617.522
3647.09	618.509
3649.47	606.497
3651.84	605.484
3654.22	596.471
3656.59	608.458
3658.97	593.446
3661.34	604.433
3663.71	609.42
3666.09	584.407
3668.46	588.395
3670.83	592.382
3673.2	589.369
3675.56	617.356
3677.93	597.344
3680.3	590.331
3682.67	600.318
3685.03	593.305
3687.4	586.293
3689.76	575.28
3692.12	571.267
3694.49	597.254
3696.85	585.242
3699.21	591.229
3701.57	582.216
3703.93	581.203
3706.28	577.19
3708.64	582.178
3711	573.165
3713.36	586.152
3715.71	589.14
3718.07	592.127
3720.42	589.114
3722.77	581.101
3725.12	589.089
3727.48	590.076
3729.83	605.063
3732.18	595.05
3734.53	596.037
3736.87	593.025
3739.22	605.012
3741.57	615.999
3743.91	599.986
3746.26	596.974
3748.6	614.961
3750.95	586.948
3753.29	588.935
3755.63	596.923
3757.97	580.91
3760.31	606.897
3762.65	602.884
3764.99	610.872
3767.33	599.859
3769.67	602.846
3772	592.833
3774.34	576.821
3776.67	582.808
3779.01	601.795
3781.34	580.782
3783.67	611.77
3786.01	576.757
3788.34	599.744
3790.67	562.731
3793	600.719
3795.33	580.706
3797.65	596.693
3799.98	572.68
3802.31	589.668
3804.63	574.655
3806.96	576.642
3809.28	574.629
3811.61	587.617
3813.93	594.604
3816.25	596.591
3818.57	582.578
3820.89	577.566
3823.21	566.553
3825.53	574.54
3827.85	572.527
3830.17	578.515
3832.48	582.502
3834.8	562.489
3837.11	573.476
3839.43	559.464
3841.74	564.451
3844.05	588.438
3846.36	584.425
3848.68	572.412
3850.99	554.4
3853.29	572.387
3855.6	567.374
3857.91	573.362
3860.22	568.349
3862.53	556.336
3864.83	581.323
3867.14	578.31
3869.44	568.298
3871.74	574.285
3874.05	573.272
3876.35	578.259
3878.65	586.247
3880.95	563.234
3883.25	572.221
3885.55	572.208
3887.85	579.196
3890.14	588.183
3892.44	568.17
3894.74	564.157
3897.03	580.145
3899.33	567.132
3901.62	564.119
3903.91	574.106
3906.21	573.094
3908.5	566.081
3910.79	573.068
3913.08	602.055
3915.37	576.043
3917.66	589.03
3919.94	583.017
3922.23	566.004
3924.52	571.992
3926.8	584.979
3929.09	553.966
3931.37	579.953
3933.65	563.941
3935.93	575.928
3938.22	587.915
3940.5	573.902
3942.78	571.89
3945.06	561.877
3947.33	557.864
3949.61	567.851
3951.89	585.839
3954.17	561.826
3956.44	537.813
3958.72	580.8
3960.99	565.788
3963.26	574.775
3965.54	560.762
3967.81	545.749
3970.08	555.737
3972.35	541.724
3974.62	553.711
3976.89	551.698
3979.16	544.686
3981.42	566.673
3983.69	553.66
3985.96	558.647
3988.22	537.635
3990.49	549.622
3992.75	565.609
3995.01	547.596
3997.27	541.583
3999.54	538.571