File: muestras/magnetita1/roy_mg_09.txt
#Acq. time (s)=	25
#Accumulations=	3
#Range (cm-¹)=	100...4000
#Windows=	3
#Autofocus=	Off
#AutoExposure=	Off
#Spike filter=	Multiple accum.
#Delay time (s)=	0
#Binning=	1
#Readout mode=	Signal
#DeNoise=	Off
#ICS correction=	Off
#Dark correction=	Off
#Inst. Process=	Off
#Instrument=	LabRAM HR Evol
#Detector=	Syncerity OE
#Objective=	x100_VIS
#Grating=	600 (500nm)
#ND Filter=	100%
#Laser=	532nm_Edge
#Hole=	150.001
#Range=	Visible
#Project=	Omar
#Sample=
#Site=	27-04-23
#Title=	roy_mg
#Remark=
#Date=	27.04.2023 16:34
#Acquired=	27.04.2023 16:34:43
101.48	436
105.149	551.872
108.817	493.743
112.483	443.615
116.148	487.487
119.811	465.358
123.471	475.23
127.131	444.101
130.79	420.973
134.448	425.845
138.102	488.716
141.757	440.588
145.41	414.46
149.059	424.331
152.71	419.203
156.357	439.075
160.004	424.946
163.648	423.818
167.293	426.689
170.934	442.561
174.576	415.433
178.214	403.304
181.851	407.176
185.489	432.048
189.123	417.919
192.755	414.791
196.389	434.663
200.018	426.534
203.647	440.406
207.274	432.277
210.899	446.149
214.525	441.021
218.148	435.892
221.769	435.764
225.389	449.636
229.008	415.507
232.625	438.379
236.24	433.251
239.855	436.122
243.468	451.994
247.079	437.865
250.689	451.737
254.295	442.609
257.903	423.48
261.509	430.352
265.113	453.224
268.716	440.095
272.315	420.967
275.916	433.839
279.514	446.71
283.11	443.582
286.706	412.453
290.3	431.325
293.891	415.197
297.483	417.068
301.072	405.94
304.661	413.812
308.246	405.683
311.832	412.555
315.415	416.427
318.997	389.298
322.579	399.17
326.157	363.041
329.734	325.913
333.312	355.785
336.887	348.656
340.46	336.528
344.032	336.4
347.602	323.271
351.173	327.143
354.74	329.015
358.307	314.886
361.871	323.758
365.435	306.629
368.997	311.501
372.557	316.373
376.117	312.244
379.675	316.116
383.231	314.988
386.786	297.859
390.338	298.731
393.89	294.603
397.441	305.474
400.991	313.346
404.537	317.217
408.084	308.089
411.63	314.961
415.174	303.832
418.715	316.704
422.256	295.576
425.794	295.447
429.333	299.319
432.868	299.191
436.404	288.062
439.937	300.934
443.47	306.805
447	306.677
450.53	288.549
454.058	305.42
457.583	311.292
461.11	293.164
464.633	309.035
468.155	312.907
471.675	299.779
475.196	319.65
478.714	298.522
482.23	320.393
485.745	320.265
489.259	300.137
492.771	314.008
496.282	301.88
499.791	289.752
503.3	285.623
506.807	290.495
510.312	271.367
513.816	295.238
517.319	287.11
520.821	282.981
524.319	288.853
527.818	287.725
531.315	292.596
534.811	299.468
538.304	306.34
541.798	307.211
545.29	305.083
548.778	329.955
552.268	323.826
555.754	332.698
559.241	317.569
562.724	340.441
566.208	334.313
569.689	329.184
573.171	348.056
576.649	354.928
580.126	352.799
583.603	354.671
587.077	360.543
590.55	364.414
594.023	364.286
597.494	360.157
600.962	362.029
604.43	367.901
607.896	365.772
611.361	379.644
614.825	379.516
618.287	385.387
621.748	377.259
625.207	388.131
628.666	389.002
632.123	389.874
635.578	398.745
639.033	395.617
642.486	400.489
645.937	366.36
649.388	376.232
652.835	384.104
656.283	391.975
659.729	404.847
663.172	402.719
666.616	391.59
670.059	384.462
673.498	394.333
676.938	379.205
680.374	392.077
683.812	391.948
687.246	401.82
690.68	390.692
694.112	383.563
697.544	386.435
700.973	380.307
704.4	404.178
707.828	384.05
711.253	379.921
714.677	393.793
718.099	390.665
721.522	382.536
724.942	415.408
728.36	387.28
731.777	387.151
735.193	393.023
738.608	392.895
742.021	388.766
745.433	404.638
748.844	408.509
752.253	402.381
755.661	383.253
759.068	406.124
762.474	382.996
765.876	386.868
769.279	402.739
772.68	410.611
776.081	402.483
779.478	412.354
782.876	423.226
786.272	407.097
789.666	402.969
793.06	400.841
796.45	393.712
799.842	408.584
803.23	404.456
806.619	397.327
810.004	410.199
813.391	395.071
816.774	391.942
820.156	400.814
823.538	401.685
826.917	414.557
830.295	404.429
833.672	391.3
837.047	411.172
840.424	376.044
843.797	388.915
847.168	373.787
850.539	367.659
853.908	382.53
857.275	354.402
860.642	357.273
864.007	364.145
867.371	358.017
870.734	362.888
874.096	358.76
877.454	362.632
880.813	329.503
884.171	354.375
887.527	352.247
890.881	362.118
894.235	352.99
897.587	346.861
900.937	370.733
904.287	336.605
907.634	339.476
910.982	348.348
914.326	342.22
917.671	349.091
921.013	341.963
924.356	319.835
927.696	325.706
931.034	327.578
934.373	299.449
937.708	307.321
941.043	310.193
944.378	293.064
947.71	296.936
951.041	313.808
954.371	303.679
957.699	303.551
961.026	305.423
964.352	307.294
967.676	313.166
971	293.037
974.322	304.909
977.642	319.781
980.962	313.652
984.28	294.524
987.598	301.396
990.912	292.267
994.226	300.139
997.54	312.011
1000.85	305.882
1004.16	312.754
1007.47	302.625
1010.78	303.497
1014.08	309.369
1017.39	298.24
1020.69	290.112
1024	295.984
1027.3	305.855
1030.6	313.727
1033.9	286.599
1037.19	285.47
1040.49	303.342
1043.79	294.213
1047.08	287.085
1050.37	292.957
1053.66	290.828
1056.95	302.7
1060.24	304.572
1063.53	293.443
1066.81	289.315
1070.1	310.187
1073.38	288.058
1076.66	276.93
1079.94	292.801
1083.22	287.673
1086.5	277.545
1089.78	279.416
1093.06	290.288
1096.33	279.16
1099.6	283.031
1102.87	278.903
1106.15	261.775
1109.41	269.646
1112.68	295.518
1115.95	281.389
1119.21	290.261
1122.48	281.133
1125.74	284.004
1129	288.876
1132.26	268.748
1135.52	286.619
1138.78	287.491
1142.04	280.363
1145.29	271.234
1148.55	287.106
1151.8	272.977
1155.05	283.849
1158.3	279.721
1161.55	270.592
1164.8	287.464
1168.05	286.336
1171.29	296.207
1174.54	288.079
1177.78	291.951
1181.02	296.822
1184.26	270.694
1187.5	292.565
1190.74	289.437
1193.97	286.309
1197.21	275.18
1200.44	293.052
1203.68	290.924
1206.91	290.795
1210.14	307.667
1213.37	286.539
1216.59	299.41
1219.82	289.282
1223.05	293.153
1226.27	300.025
1229.49	302.897
1232.72	289.768
1235.94	288.64
1239.16	278.512
1242.37	289.383
1245.59	301.255
1248.81	293.127
1252.02	303.998
1255.23	311.87
1258.44	289.741
1261.66	305.613
1264.86	298.485
1268.07	311.356
1271.28	300.228
1274.48	301.1
1277.69	309.971
1280.89	303.843
1284.09	297.715
1287.29	308.586
1290.49	313.458
1293.69	294.329
1296.89	297.201
1300.08	314.073
1303.28	308.944
1306.47	314.816
1309.66	318.688
1312.85	303.559
1316.04	318.431
1319.23	312.303
1322.42	316.174
1325.61	327.046
1328.79	331.917
1331.97	324.289
1335.15	310.661
1338.34	321.532
1341.52	331.404
1344.69	325.276
1347.87	323.147
1351.05	322.019
1354.22	314.891
1357.4	309.762
1360.57	313.634
1363.74	313.505
1366.91	326.377
1370.08	332.249
1373.25	312.12
1376.41	325.992
1379.58	319.864
1382.74	315.735
1385.9	321.607
1389.07	326.479
1392.23	307.35
1395.39	318.222
1398.54	321.093
1401.7	330.965
1404.86	329.837
1408.01	334.708
1411.16	323.58
1414.32	323.452
1417.47	336.323
1420.62	323.195
1423.76	322.067
1426.91	326.938
1430.06	325.81
1433.2	314.681
1436.35	321.553
1439.49	334.425
1442.63	335.296
1445.77	331.168
1448.91	331.04
1452.04	336.911
1455.18	328.783
1458.31	331.655
1461.45	325.526
1464.58	327.398
1467.71	328.269
1470.84	339.141
1473.97	327.013
1477.1	323.884
1480.23	334.756
1483.35	341.628
1486.48	348.499
1489.6	341.371
1492.72	346.243
1495.84	330.114
1498.96	348.986
1502.08	329.857
1505.2	325.729
1508.31	331.601
1511.43	337.472
1514.54	354.344
1517.65	350.216
1520.77	339.087
1523.88	356.959
1526.99	337.831
1530.09	348.702
1533.2	347.574
1536.3	357.445
1539.41	361.317
1542.51	353.189
1545.61	367.06
1548.71	357.932
1551.81	356.804
1554.91	371.675
1558.01	369.547
1561.1	354.419
1564.2	356.29
1567.29	381.162
1570.39	349.033
1573.48	370.905
1576.57	353.777
1579.66	369.648
1582.74	361.52
1585.83	362.392
1588.91	345.263
1592	342.135
1595.08	382.007
1598.16	360.878
1601.24	368.75
1604.32	340.621
1607.4	360.493
1610.48	352.365
1613.56	350.236
1616.63	346.108
1619.71	336.98
1622.78	342.851
1625.85	352.723
1628.92	330.595
1631.99	366.466
1635.06	326.338
1638.12	355.209
1641.19	356.081
1644.25	339.953
1647.32	353.751
1650.38	340.335
1653.44	335.786
1656.5	351.458
1659.56	335.738
1662.61	344.231
1665.67	357.971
1668.73	337.156
1671.78	350.249
1674.83	344.323
1677.89	335.542
1680.93	348.018
1683.98	337.98
1687.03	337.554
1690.08	352.075
1693.13	340.073
1696.17	350.018
1699.21	341.363
1702.26	345.271
1705.3	349.466
1708.34	341.231
1711.38	340.375
1714.42	344.313
1717.45	342.267
1720.49	350.092
1723.52	347.073
1726.56	335.511
1729.59	343.167
1732.62	336.177
1735.65	342.827
1738.68	343.769
1741.71	345.812
1744.73	329.815
1747.76	342.155
1750.78	335.958
1753.81	335.118
1756.83	348.018
1759.85	335.651
1762.87	333.457
1765.89	346.706
1768.9	338.495
1771.92	339.582
1774.94	336.46
1777.95	352.992
1780.96	345.769
1783.98	345.189
1786.99	347.236
1789.99	345.65
1793	331.544
1796.01	346.751
1799.02	345.598
1801	349.225
1804.02	355.176
1807.04	342.127
1810.05	349.077
1813.07	356.028
1816.08	348.979
1819.09	352.929
1822.1	359.88
1825.11	352.831
1828.12	339.781
1831.13	351.732
1834.14	349.683
1837.14	340.633
1840.14	351.584
1843.15	353.535
1846.15	348.485
1849.15	342.436
1852.15	350.387
1855.15	346.337
1858.15	341.288
1861.14	355.239
1864.14	345.19
1867.13	358.14
1870.13	341.091
1873.12	344.042
1876.11	355.992
1879.1	357.943
1882.09	348.893
1885.08	338.844
1888.06	347.795
1891.05	352.746
1894.03	346.723
1897.02	338.7
1900	359.677
1902.98	343.655
1905.96	350.632
1908.94	345.609
1911.92	348.587
1914.89	356.564
1917.87	348.541
1920.84	362.518
1923.82	356.496
1926.79	354.473
1929.76	352.45
1932.73	350.428
1935.7	334.405
1938.67	344.382
1941.63	350.36
1944.6	369.337
1947.56	358.314
1950.53	344.291
1953.49	350.269
1956.45	355.246
1959.41	346.223
1962.37	348.201
1965.33	356.178
1968.29	344.155
1971.24	358.133
1974.2	356.11
1977.15	350.087
1980.1	352.064
1983.05	370.042
1986.01	364.019
1988.95	348.996
1991.9	356.974
1994.85	349.951
1997.79	358.928
2000.74	362.906
2003.68	361.883
2006.63	365.86
2009.57	333.837
2012.51	348.815
2015.45	348.792
2018.39	365.769
2021.33	335.747
2024.26	365.724
2027.2	351.701
2030.13	364.679
2033.06	341.656
2036	349.633
2038.93	363.61
2041.86	360.588
2044.79	346.565
2047.71	358.542
2050.64	360.52
2053.56	379.497
2056.49	335.474
2059.41	347.452
2062.34	345.429
2065.26	351.406
2068.18	357.383
2071.1	357.361
2074.01	355.338
2076.93	348.315
2079.85	355.293
2082.76	360.27
2085.68	344.247
2088.59	347.225
2091.5	345.202
2094.41	353.179
2097.32	337.156
2100.23	325.134
2103.14	357.111
2106.04	333.088
2108.95	335.066
2111.85	349.043
2114.76	361.02
2117.66	350.997
2120.56	361.975
2123.46	346.952
2126.36	350.929
2129.25	346.907
2132.15	340.884
2135.05	340.861
2137.94	344.839
2140.84	354.816
2143.73	350.793
2146.62	331.77
2149.51	344.748
2152.4	348.725
2155.29	342.702
2158.18	352.68
2161.06	340.657
2163.95	358.634
2166.83	350.612
2169.71	344.589
2172.6	359.566
2175.48	339.543
2178.36	367.521
2181.24	352.498
2184.11	353.475
2186.99	349.453
2189.87	350.43
2192.74	358.407
2195.61	360.385
2198.49	349.362
2201.36	363.339
2204.23	349.316
2207.1	352.294
2209.97	356.271
2212.84	362.248
2215.7	344.226
2218.57	354.203
2221.43	337.18
2224.29	345.158
2227.16	366.135
2230.02	346.112
2232.88	355.089
2235.74	330.067
2238.59	347.044
2241.45	362.021
2244.31	357.999
2247.16	348.976
2250.02	344.953
2252.87	327.931
2255.72	332.908
2258.57	337.885
2261.42	341.862
2264.27	345.84
2267.12	333.817
2269.96	345.794
2272.81	344.772
2275.65	322.749
2278.5	327.726
2281.34	340.704
2284.18	354.681
2287.02	348.658
2289.86	337.635
2292.7	331.613
2295.54	336.59
2298.37	350.567
2301.21	341.545
2304.04	353.522
2306.88	351.499
2309.71	342.476
2312.54	354.454
2315.37	341.431
2318.2	351.408
2321.03	359.386
2323.85	337.363
2326.68	401.34
2329.5	429.318
2332.33	357.295
2335.15	349.272
2337.97	358.249
2340.79	347.227
2343.61	338.204
2346.43	348.181
2349.25	331.159
2352.07	361.136
2354.88	350.113
2357.7	335.091
2360.51	329.068
2363.32	356.045
2366.14	361.022
2368.95	346
2371.76	354.977
2374.57	354.954
2377.37	354.932
2380.18	340.909
2382.99	342.886
2385.79	345.864
2388.59	324.841
2391.4	352.818
2394.2	344.795
2397	341.773
2399.8	335.75
2402.6	342.727
2405.4	338.705
2408.19	358.682
2410.99	326.659
2413.78	324.637
2416.57	356.614
2419.37	345.591
2422.16	345.568
2424.95	345.546
2427.74	320.523
2430.53	349.5
2433.32	342.478
2436.1	348.455
2438.89	344.432
2441.67	336.409
2444.46	352.387
2447.24	353.364
2450.02	343.341
2452.8	336.319
2455.58	350.296
2458.36	344.273
2461.14	344.251
2463.91	362.228
2466.69	346.205
2469.46	352.183
2472.24	350.16
2475.01	341.137
2477.78	358.114
2480.55	343.092
2483.32	352.069
2486.09	349.046
2488.86	363.024
2491.62	342.001
2494.39	349.978
2497.15	350.956
2499.92	347.933
2502.68	351.91
2505.44	344.887
2508.2	353.865
2510.96	354.842
2513.72	336.819
2516.48	355.797
2519.23	347.774
2521.99	351.751
2524.74	335.728
2527.5	345.706
2530.25	348.683
2533	363.66
2535.75	361.638
2538.5	339.615
2541.25	332.592
2544	344.57
2546.75	343.547
2549.49	346.524
2552.24	331.501
2554.98	340.479
2557.72	335.456
2560.47	357.433
2563.21	331.411
2565.95	345.388
2568.69	319.365
2571.42	346.343
2574.16	362.32
2576.9	346.297
2579.63	359.274
2582.37	339.252
2585.1	358.229
2587.83	343.206
2590.56	362.184
2593.29	344.161
2596.02	361.138
2598.75	367.116
2601.48	355.093
2604.2	347.07
2606.93	359.047
2609.65	353.025
2612.38	348.002
2615.1	358.979
2617.82	361.957
2620.54	359.934
2623.26	363.911
2625.98	354.889
2628.7	344.866
2631.41	352.843
2634.13	370.82
2636.84	358.798
2639.56	356.775
2642.27	368.752
2644.98	362.73
2647.69	351.707
2650.4	349.684
2653.11	371.661
2655.82	356.639
2658.53	354.616
2661.23	364.593
2663.94	368.571
2666.64	351.548
2669.34	363.525
2672.05	356.503
2674.75	363.48
2677.45	342.457
2680.15	354.434
2682.85	354.412
2685.54	365.889
2688.24	350.366
2690.93	358.344
2693.63	344.321
2696.32	364.298
2699.02	359.276
2701.71	357.253
2704.4	364.23
2707.09	359.207
2709.78	363.185
2712.46	354.162
2715.15	348.139
2717.84	369.117
2720.52	367.094
2723.21	346.071
2725.89	350.049
2728.57	377.026
2731.25	350.003
2733.93	351.98
2736.61	366.958
2739.29	350.935
2741.97	370.912
2744.64	379.89
2747.32	363.867
2749.99	359.844
2752.67	369.822
2755.34	373.799
2758.01	375.776
2760.68	369.753
2763.35	369.731
2766.02	359.708
2768.69	363.685
2771.35	367.663
2774.02	376.64
2776.68	371.617
2779.35	375.595
2782.01	373.572
2784.67	367.549
2787.34	357.526
2790	374.504
2792.66	383.481
2795.31	375.458
2797.97	373.436
2800.63	357.413
2803.28	371.39
2805.94	382.368
2808.59	371.345
2811.24	373.322
2813.9	367.299
2816.55	373.277
2819.2	376.254
2821.85	376.231
2824.5	378.209
2827.14	375.186
2829.79	373.163
2832.43	373.141
2835.08	364.118
2837.72	369.095
2840.36	365.072
2843.01	380.05
2845.65	372.027
2848.29	381.004
2850.92	380.982
2853.56	378.959
2856.2	374.936
2858.84	383.913
2861.47	370.891
2864.1	390.868
2866.74	395.845
2869.37	362.823
2872	376.8
2874.63	376.777
2877.26	383.755
2879.89	377.732
2882.52	386.709
2885.15	376.686
2887.77	375.664
2890.4	372.641
2893.02	374.618
2895.64	399.596
2898.27	386.573
2900.89	373.55
2903.51	372.528
2906.13	373.505
2908.74	393.482
2911.36	370.459
2913.98	370.437
2916.59	378.414
2919.21	392.391
2921.82	380.369
2924.44	356.346
2927.05	387.323
2929.66	367.301
2932.27	358.278
2934.88	378.255
2937.49	385.232
2940.09	380.21
2942.7	388.187
2945.31	398.164
2947.91	384.142
2950.52	370.119
2953.12	384.041
2955.72	372.424
2958.32	381.148
2960.92	395.168
2963.52	382.106
2966.12	387.026
2968.72	384.277
2971.31	386.739
2973.91	374.865
2976.5	382.361
2979.1	377.109
2981.69	363.954
2984.28	369.779
2986.87	382.324
2989.46	387.99
2992.05	374.276
2994.64	377.677
2997.23	364.817
2999.82	389.14
3002.4	374.519
3004.98	379.675
3007.57	383.123
3010.15	382.535
3012.73	371.647
3015.32	378.526
3017.9	379.863
3020.48	394.203
3023.05	374.234
3025.63	381.211
3028.21	369.224
3030.78	367.716
3033.36	382.567
3035.93	374.183
3038.51	384.388
3041.08	381.055
3043.65	384.072
3046.22	382.82
3048.79	387.655
3051.36	379.734
3053.92	379.597
3056.49	389.48
3059.06	387.853
3061.62	393.351
3064.19	387.401
3066.75	384.659
3069.31	370.12
3071.87	386.037
3074.43	381.552
3076.99	377.877
3079.55	374.175
3082.11	385.964
3083.54	375.201
3086.11	383.193
3088.68	387.184
3091.24	369.176
3093.81	387.168
3096.38	378.159
3098.94	379.151
3101.5	375.143
3104.07	367.134
3106.63	377.126
3109.19	382.118
3111.75	378.109
3114.31	386.101
3116.86	379.093
3119.42	374.084
3121.98	377.076
3124.53	386.068
3127.09	373.059
3129.64	381.051
3132.19	387.043
3134.75	383.034
3137.3	371.026
3139.85	380.018
3142.4	386.009
3144.95	395.001
3147.49	382.993
3150.04	394.984
3152.58	381.976
3155.13	392.968
3157.67	374.959
3160.22	396.951
3162.76	371.943
3165.3	401.934
3167.84	372.926
3170.38	378.918
3172.92	384.909
3175.46	378.901
3177.99	374.893
3180.53	380.884
3183.07	385.876
3185.6	377.867
3188.13	386.859
3190.67	368.851
3193.2	380.842
3195.73	380.834
3198.26	384.826
3200.79	360.817
3203.32	388.809
3205.84	376.801
3208.37	372.792
3210.9	382.784
3213.42	374.776
3215.95	366.767
3218.47	388.759
3220.99	378.751
3223.51	376.742
3226.03	356.734
3228.55	374.726
3231.07	373.717
3233.59	371.709
3236.11	372.701
3238.62	366.692
3241.14	358.684
3243.65	379.676
3246.17	358.667
3248.68	382.659
3251.19	378.651
3253.7	376.642
3256.21	368.634
3258.72	364.626
3261.23	348.617
3263.74	376.609
3266.25	387.601
3268.75	372.592
3271.26	356.584
3273.76	370.576
3276.26	372.567
3278.77	368.559
3281.27	370.551
3283.77	386.542
3286.27	367.534
3288.77	386.526
3291.27	370.517
3293.76	387.509
3296.26	363.501
3298.76	366.492
3301.25	372.484
3303.74	366.476
3306.24	392.467
3308.73	376.459
3311.22	386.451
3313.71	380.442
3316.2	390.434
3318.69	357.426
3321.18	368.417
3323.67	386.409
3326.15	374.401
3328.64	388.392
3331.12	378.384
3333.61	378.376
3336.09	374.367
3338.57	382.359
3341.05	391.351
3343.53	348.342
3346.01	361.334
3348.49	380.326
3350.97	362.317
3353.45	376.309
3355.92	376.301
3358.4	364.292
3360.87	360.284
3363.35	392.276
3365.82	364.267
3368.29	367.259
3370.76	389.25
3373.24	356.242
3375.7	371.234
3378.17	362.225
3380.64	364.217
3383.11	362.209
3385.57	356.2
3388.04	350.192
3390.5	369.184
3392.97	359.175
3395.43	359.167
3397.89	364.159
3400.35	362.15
3402.81	360.142
3405.27	356.134
3407.73	372.125
3410.19	368.117
3412.65	380.109
3415.1	358.1
3417.56	364.092
3420.01	378.084
3422.47	362.075
3424.92	368.067
3427.37	367.059
3429.82	361.05
3432.27	374.042
3434.72	365.034
3437.17	370.025
3439.62	362.017
3442.07	368.009
3444.51	366
3446.96	374.992
3449.4	380.984
3451.85	365.975
3454.29	371.967
3456.73	387.959
3459.17	383.95
3461.61	369.942
3464.05	372.934
3466.49	360.925
3468.93	373.917
3471.37	373.909
3473.8	387.9
3476.24	362.892
3478.68	384.884
3481.11	351.875
3483.54	385.867
3485.97	381.859
3488.41	367.85
3490.84	365.842
3493.27	367.834
3495.7	353.825
3498.12	362.817
3500.55	351.809
3502.98	377.8
3505.4	363.792
3507.83	355.784
3510.25	372.775
3512.68	360.767
3515.1	366.759
3517.52	351.75
3519.94	362.742
3522.36	360.734
3524.78	355.725
3527.2	367.717
3529.62	357.709
3532.03	361.7
3534.45	351.692
3536.86	351.684
3539.28	348.675
3541.69	357.667
3544.1	355.659
3546.52	357.65
3548.93	345.642
3551.34	349.633
3553.75	357.625
3556.16	362.617
3558.56	364.608
3560.97	339.6
3563.38	359.592
3565.78	357.583
3568.19	347.575
3570.59	367.567
3572.99	368.558
3575.4	367.55
3577.8	353.542
3580.2	371.533
3582.6	339.525
3585	347.517
3587.4	341.508
3589.79	341.5
3592.19	347.492
3594.58	358.483
3596.98	359.475
3599.37	363.467
3601.77	387.458
3604.16	358.45
3606.55	370.442
3608.94	363.433
3611.33	374.425
3613.72	369.417
3616.11	351.408
3618.5	369.4
3620.88	361.392
3623.27	371.383
3625.66	372.375
3628.04	371.367
3630.42	362.358
3632.81	349.35
3635.19	365.342
3637.57	367.333
3639.95	368.325
3642.33	361.317
3644.71	370.308
3647.09	371.3
3649.47	363.292
3651.84	369.283
3654.22	367.275
3656.59	350.267
3658.97	357.258
3661.34	357.25
3663.71	354.242
3666.09	353.233
3668.46	341.225
3670.83	355.217
3673.2	351.208
3675.56	341.2
3677.93	347.192
3680.3	355.183
3682.67	372.175
3685.03	349.167
3687.4	339.158
3689.76	341.15
3692.12	362.142
3694.49	343.133
3696.85	359.125
3699.21	348.117
3701.57	355.108
3703.93	368.1
3706.28	349.092
3708.64	349.083
3711	353.075
3713.36	356.067
3715.71	367.058
3718.07	364.05
3720.42	351.042
3722.77	359.033
3725.12	360.025
3727.48	357.016
3729.83	348.008
3732.18	346
3734.53	363.991
3736.87	349.983
3739.22	360.975
3741.57	360.966
3743.91	348.958
3746.26	362.95
3748.6	351.941
3750.95	355.933
3753.29	362.925
3755.63	366.916
3757.97	355.908
3760.31	366.9
3762.65	357.891
3764.99	366.883
3767.33	341.875
3769.67	368.866
3772	347.858
3774.34	349.85
3776.67	357.841
3779.01	344.833
3781.34	359.825
3783.67	371.816
3786.01	354.808
3788.34	360.8
3790.67	359.791
3793	354.783
3795.33	357.775
3797.65	344.766
3799.98	366.758
3802.31	366.75
3804.63	350.741
3806.96	344.733
3809.28	345.725
3811.61	344.716
3813.93	349.708
3816.25	348.7
3818.57	349.691
3820.89	346.683
3823.21	352.675
3825.53	326.666
3827.85	347.658
3830.17	346.65
3832.48	356.641
3834.8	337.633
3837.11	339.625
3839.43	350.616
3841.74	338.608
3844.05	349.6
3846.36	343.591
3848.68	346.583
3850.99	340.575
3853.29	348.566
3855.6	351.558
3857.91	354.55
3860.22	344.541
3862.53	339.533
3864.83	331.525
3867.14	336.516
3869.44	338.508
3871.74	348.5
3874.05	341.491
3876.35	351.483
3878.65	335.475
3880.95	351.466
3883.25	347.458
3885.55	358.45
3887.85	358.441
3890.14	344.433
3892.44	354.424
3894.74	356.416
3897.03	344.408
3899.33	348.399
3901.62	351.391
3903.91	349.383
3906.21	362.374
3908.5	357.366
3910.79	338.358
3913.08	350.349
3915.37	360.341
3917.66	360.333
3919.94	339.324
3922.23	362.316
3924.52	348.308
3926.8	346.299
3929.09	352.291
3931.37	347.283
3933.65	362.274
3935.93	340.266
3938.22	362.258
3940.5	334.249
3942.78	356.241
3945.06	343.233
3947.33	342.224
3949.61	346.216
3951.89	356.208
3954.17	326.199
3956.44	345.191
3958.72	341.183
3960.99	346.174
3963.26	356.166
3965.54	360.158
3967.81	345.149
3970.08	342.141
3972.35	322.133
3974.62	326.124
3976.89	316.116
3979.16	337.108
3981.42	326.099
3983.69	345.091
3985.96	334.083
3988.22	364.074
3990.49	330.066
3992.75	339.058
3995.01	329.049
3997.27	324.041
3999.54	338.033