File: muestras/magnetita1/roy_mg_07.txt
#Acq. time (s)=	25
#Accumulations=	3
#Range (cm-¹)=	100...2000
#Windows=	2
#Autofocus=	Off
#AutoExposure=	Off
#Spike filter=	Multiple accum.
#Delay time (s)=	0
#Binning=	1
#Readout mode=	Signal
#DeNoise=	Off
#ICS correction=	Off
#Dark correction=	Off
#Inst. Process=	Off
#Instrument=	LabRAM HR Evol
#Detector=	Syncerity OE
#Objective=	x100_VIS
#Grating=	600 (500nm)
#ND Filter=	100%
#Laser=	532nm_Edge
#Hole=	150.001
#Range=	Visible
#Project=	Omar
#Sample=
#Site=	27-04-23
#Title=	roy_mg
#Remark=
#Date=	27.04.2023 16:17
#Acquired=	27.04.2023 16:17:42
101.269	436
103.103	486
104.938	534
106.771	545
108.606	470
110.438	424
112.272	433
114.104	446
115.935	460
117.768	446
119.598	457
121.431	468
123.26	473
125.09	448
126.921	414
128.749	429
130.578	418
132.408	401
134.235	386
136.063	435
137.892	448
139.718	453
141.544	402
143.372	407
145.198	401
147.023	410
148.849	414
150.674	427
152.498	434
154.324	435
156.147	396
157.97	383
159.792	396
161.617	411
163.439	402
165.26	403
167.081	403
168.904	405
170.725	409
172.545	414
174.364	411
176.184	392
178.005	403
179.824	384
181.642	386
183.46	386
185.277	415
187.095	406
188.914	382
190.73	380
192.546	411
194.362	400
196.178	409
197.993	407
199.807	400
201.624	399
203.438	402
205.252	392
207.065	402
208.878	415
210.691	420
212.503	404
214.315	422
216.126	422
217.938	428
219.748	418
221.559	412
223.369	413
225.179	409
226.988	404
228.797	410
230.606	408
232.415	390
234.223	417
236.03	418
237.838	398
239.645	433
241.451	413
243.258	400
245.063	398
246.869	398
248.674	414
250.479	420
252.284	417
254.088	418
255.892	401
257.695	422
259.498	408
261.301	408
263.103	406
264.903	422
266.705	406
268.506	404
270.307	410
272.108	432
273.908	410
275.708	429
277.506	416
279.305	404
281.104	421
282.903	398
284.701	406
286.499	413
288.294	414
290.091	406
291.888	397
293.685	388
295.479	400
297.274	401
299.07	402
300.865	404
302.66	384
304.452	395
306.246	377
308.04	382
309.831	390
311.624	396
313.417	383
315.209	374
316.999	384
318.79	384
320.582	377
322.37	360
324.161	355
325.951	337
327.739	336
329.529	335
331.318	326
333.104	310
334.893	336
336.679	323
338.467	329
340.254	320
342.039	311
343.826	324
345.61	296
347.396	312
349.182	298
350.965	304
352.75	313
354.533	302
356.317	298
358.099	314
359.883	301
361.664	310
363.447	296
365.227	314
367.01	295
368.79	303
370.571	304
372.35	306
374.131	303
375.91	294
377.69	299
379.468	292
381.247	299
383.024	316
384.803	302
386.579	292
388.358	294
390.133	310
391.909	308
393.686	308
395.46	310
397.237	292
399.011	286
400.785	300
402.56	294
404.333	292
406.106	283
407.88	294
409.652	294
411.423	309
413.197	294
414.968	295
416.738	289
418.511	295
420.281	290
422.05	286
423.821	292
425.59	297
427.359	294
429.127	286
430.897	286
432.664	282
434.432	290
436.201	311
437.967	286
439.733	294
441.499	290
443.265	290
445.032	292
446.797	291
448.561	272
450.325	299
452.089	274
453.854	295
455.617	298
457.38	290
459.143	293
460.905	310
462.667	300
464.428	296
466.191	296
467.952	285
469.712	300
471.472	326
473.232	305
474.991	294
476.75	315
478.509	288
480.267	298
482.025	304
483.785	278
485.543	301
487.3	289
489.056	286
490.813	291
492.569	286
494.324	294
496.08	293
497.835	291
499.589	294
501.344	272
503.098	271
504.851	292
506.605	288
508.358	272
510.11	260
511.862	294
513.612	262
515.364	278
517.115	274
518.866	284
520.617	281
522.367	276
524.117	278
525.867	284
527.616	281
529.365	285
531.112	300
532.86	291
534.608	280
536.355	295
538.103	298
539.85	303
541.596	294
543.341	304
545.086	300
546.832	296
548.577	312
550.322	318
552.065	318
553.809	306
555.553	319
557.297	304
559.038	316
560.781	315
562.523	328
564.266	330
566.006	328
567.747	334
569.488	337
571.229	347
572.968	329
574.708	334
576.448	330
578.186	310
579.925	341
581.664	345
583.401	356
585.139	340
586.877	344
588.612	340
590.35	351
592.087	338
593.821	344
595.558	363
597.292	350
599.027	356
600.763	354
602.495	359
604.23	348
605.962	360
607.696	360
609.428	357
611.161	362
612.894	366
614.625	369
616.357	365
618.087	369
619.819	365
621.548	393
623.279	383
625.008	373
626.738	381
628.466	374
630.196	376
631.923	376
633.652	375
635.379	354
637.105	396
638.833	378
640.559	384
642.287	384
644.012	388
645.738	378
647.463	373
649.187	384
650.913	378
652.636	380
654.359	384
656.084	393
657.806	374
659.528	387
661.252	382
662.974	395
664.697	393
666.417	386
668.138	390
669.858	388
671.58	380
673.299	389
675.019	401
676.739	382
678.458	383
680.176	367
681.894	374
683.613	388
685.331	384
687.048	386
688.764	396
690.482	389
692.198	377
693.914	365
695.629	374
697.344	390
699.061	393
700.775	360
702.489	382
704.202	380
705.916	380
707.629	383
709.341	377
711.056	384
712.768	366
714.479	393
716.191	390
717.902	392
719.612	387
721.323	376
723.033	386
724.743	400
726.452	382
728.163	384
729.872	392
731.58	380
733.288	396
734.996	394
736.704	385
738.411	392
740.118	402
741.824	386
743.53	398
745.236	391
746.942	400
748.647	380
750.352	392
752.056	400
753.761	395
755.465	400
757.166	403
758.87	378
760.573	393
762.275	390
763.977	396
765.679	392
767.381	419
769.082	374
770.784	390
772.484	408
774.183	398
775.883	407
777.582	413
779.282	390
780.981	380
782.68	392
784.376	394
786.074	414
787.772	416
789.47	400
791.167	414
792.862	394
794.558	420
796.255	398
797.951	410
799.644	403
801.339	400
803.034	405
804.729	416
806.421	397
808.115	392
809.809	414
811.502	384
813.193	422
814.886	411
816.579	400
818.269	410
819.96	378
821.652	396
823.341	396
825.032	400
826.722	403
828.411	410
830.1	407
831.788	386
833.477	391
835.166	400
836.853	390
838.541	386
840.227	394
841.915	394
843.6	380
845.287	386
846.974	368
848.658	380
850.344	373
852.028	364
853.713	371
855.396	374
857.081	375
858.764	380
860.448	379
862.13	378
863.813	357
865.494	375
867.177	362
868.858	368
870.538	372
872.22	359
873.9	364
875.581	363
877.26	364
878.939	372
880.619	360
882.297	361
883.977	367
885.654	356
887.332	365
889.01	366
890.687	340
892.363	351
894.041	360
895.717	336
897.392	356
899.069	368
900.743	342
902.418	350
904.094	358
905.767	361
907.441	344
909.114	349
910.788	348
912.461	334
914.133	330
915.805	334
917.478	341
919.149	330
920.82	331
922.491	337
924.161	328
925.833	306
927.503	310
929.172	324
930.841	294
932.51	326
934.18	317
935.848	320
937.516	300
939.183	316
940.85	313
942.517	298
944.184	306
945.85	305
947.516	316
949.183	296
950.849	314
952.514	299
954.178	307
955.843	304
957.507	301
959.17	299
960.834	288
962.497	306
964.16	300
965.822	310
967.484	303
969.146	298
970.808	302
972.469	315
974.13	304
975.79	300
977.451	293
979.111	302
980.77	302
982.43	305
984.089	300
985.746	314
987.404	302
989.062	309
990.72	298
992.378	306
994.035	294
995.692	313
997.348	308
999.003	318
1000.66	302
1002.31	302
1003.97	310
1005.62	288
1007.28	302
1008.93	302
1010.59	305
1012.24	298
1013.89	283
1015.55	276
1017.2	309
1018.85	310
1020.5	292
1022.15	298
1023.8	292
1025.46	291
1027.11	298
1028.76	304
1030.41	310
1032.06	280
1033.71	284
1035.35	284
1037	284
1038.65	289
1040.3	312
1041.95	302
1043.59	301
1045.24	287
1046.89	294
1048.53	284
1050.18	302
1051.83	292
1053.47	296
1055.12	288
1056.76	290
1058.41	280
1060.05	300
1061.69	290
1063.34	289
1064.98	288
1066.62	297
1068.26	303
1069.91	287
1071.55	272
1073.19	282
1074.83	288
1076.47	282
1078.11	276
1079.75	301
1081.39	286
1083.03	291
1084.67	294
1086.31	289
1087.95	299
1089.59	272
1091.23	284
1092.86	278
1094.5	288
1096.14	289
1097.78	276
1099.41	296
1101.05	279
1102.69	283
1104.32	281
1105.95	296
1107.59	288
1109.22	302
1110.86	271
1112.49	289
1114.13	280
1115.76	275
1117.39	292
1119.03	292
1120.66	282
1122.29	292
1123.92	293
1125.55	278
1127.18	290
1128.81	288
1130.45	293
1132.08	282
1133.7	291
1135.33	276
1136.96	279
1138.59	285
1140.22	281
1141.85	286
1143.48	280
1145.1	289
1146.73	286
1148.36	274
1149.99	281
1151.61	281
1153.24	271
1154.86	290
1156.49	283
1158.11	295
1159.74	296
1161.36	292
1162.99	305
1164.61	285
1166.24	292
1167.86	274
1169.48	287
1171.1	276
1172.73	288
1174.35	296
1175.97	292
1177.59	310
1179.21	291
1180.83	292
1182.45	292
1184.07	286
1185.69	290
1187.31	286
1188.93	277
1190.55	278
1192.17	293
1193.79	288
1195.4	291
1197.02	294
1198.64	290
1200.26	288
1201.87	292
1203.49	282
1205.1	304
1206.72	299
1208.34	293
1209.95	287
1211.57	289
1213.18	295
1214.79	296
1216.41	291
1218.02	293
1219.64	276
1221.25	284
1222.86	291
1224.47	284
1226.08	289
1227.7	285
1229.31	290
1230.92	303
1232.53	298
1234.14	290
1235.75	284
1237.36	293
1238.97	302
1240.58	294
1242.19	306
1243.8	299
1245.4	292
1247.01	300
1248.62	300
1250.23	296
1251.83	298
1253.44	294
1255.05	304
1256.65	288
1258.26	288
1259.86	306
1261.47	316
1263.07	307
1264.68	297
1266.28	276
1267.89	302
1269.49	296
1271.09	307
1272.7	307
1274.3	311
1275.9	303
1277.5	302
1279.1	318
1280.71	319
1282.31	304
1283.91	308
1285.51	301
1287.11	308
1288.71	317
1290.31	306
1291.91	296
1293.51	306
1295.11	305
1296.7	326
1298.3	313
1299.9	306
1301.5	317
1303.09	304
1304.69	320
1306.29	306
1307.88	318
1309.48	319
1311.07	336
1312.67	296
1314.26	320
1315.86	332
1317.45	329
1319.05	330
1320.64	320
1322.23	310
1323.83	319
1325.42	326
1327.01	333
1328.6	330
1330.2	309
1331.79	312.5
1333.38	316
1334.97	316
1336.56	317
1338.15	320
1339.74	304
1341.33	324
1342.92	333
1344.51	316
1346.1	306
1347.69	342
1349.28	323
1350.86	320
1352.45	306
1354.04	326
1355.63	337
1357.21	314
1358.8	315
1360.38	319
1361.97	318
1363.56	336
1365.14	324
1366.73	318
1368.31	316
1369.89	330
1371.48	306
1373.06	325
1374.65	322
1376.23	318
1377.81	325
1379.39	308
1380.98	312
1382.56	334
1384.14	324
1385.72	326
1387.3	322
1388.88	318
1390.46	320
1392.04	316
1393.62	318
1395.2	325
1396.78	314
1398.36	326
1399.94	334
1401.52	331
1403.1	328
1404.67	330
1406.25	316
1407.83	306
1409.4	314
1410.98	325
1412.56	320
1414.13	329
1415.71	314
1417.28	326
1418.86	334
1420.43	300
1422.01	343
1423.58	330
1425.16	322
1426.73	332
1428.3	352
1429.87	330
1431.45	328
1433.02	345
1434.59	343
1436.16	334
1437.73	320
1439.3	332
1440.87	345.912
1442.45	336.824
1444.02	327.737
1445.58	341.649
1447.16	328.561
1448.73	319.473
1450.29	327.385
1451.86	327.298
1453.43	339.21
1455	315.122
1456.57	317.034
1458.13	343.946
1459.7	348.858
1461.27	323.771
1462.83	333.683
1464.4	346.595
1465.97	334.507
1467.53	333.419
1469.1	334.332
1470.66	317.244
1472.23	322.156
1473.79	354.068
1475.35	333.98
1476.92	321.893
1478.48	330.805
1480.05	336.717
1481.61	330.629
1483.17	325.541
1484.73	335.453
1486.3	338.366
1487.86	337.278
1489.42	321.19
1490.98	345.102
1492.54	338.014
1494.1	344.927
1495.66	336.839
1497.22	322.751
1498.78	340.663
1500.34	337.575
1501.9	324.488
1503.46	336.4
1505.02	342.312
1506.58	342.224
1508.13	335.136
1509.69	356.048
1511.25	348.961
1512.81	338.873
1514.36	345.785
1515.92	340.697
1517.47	337.609
1519.03	348.522
1520.59	341.434
1522.14	343.346
1523.7	345.258
1525.25	343.17
1526.8	350.083
1528.36	359.995
1529.91	353.907
1531.47	344.819
1533.02	352.731
1534.57	352.643
1536.12	348.556
1537.68	348.468
1539.23	354.38
1540.78	353.292
1542.33	350.204
1543.88	354.117
1545.43	360.029
1546.98	348.941
1548.53	355.853
1550.08	362.765
1551.63	357.678
1553.18	370.59
1554.73	381.502
1556.28	379.414
1557.83	359.326
1559.38	357.239
1560.93	356.151
1562.47	361.063
1564.02	362.975
1565.57	336.887
1567.11	356.799
1568.66	351.712
1570.21	362.624
1571.75	361.536
1573.3	361.448
1574.84	356.36
1576.39	356.273
1577.93	357.185
1579.48	358.097
1581.02	344.009
1582.56	353.921
1584.11	355.834
1585.65	335.746
1587.19	341.658
1588.74	353.57
1590.28	364.482
1591.82	348.395
1593.36	341.307
1594.9	354.219
1596.44	353.131
1597.99	362.043
1599.53	334.955
1601.07	348.868
1602.61	362.78
1604.15	340.692
1605.69	334.604
1607.22	349.516
1608.76	332.429
1610.3	340.341
1611.84	336.253
1613.38	338.165
1614.92	334.077
1616.45	336.99
1617.99	337.902
1619.53	321.814
1621.06	322.726
1622.6	326.638
1624.14	335.55
1625.67	347.463
1627.21	346.375
1628.74	328.287
1630.28	340.199
1631.81	338.111
1633.34	334.024
1634.88	356.936
1636.41	336.848
1637.95	334.76
1639.48	327.672
1641.01	329.585
1642.54	340.497
1644.08	328.409
1645.61	334.321
1647.14	318.233
1648.67	320.199
1650.2	322.303
1651.73	337.7
1653.26	336.84
1654.79	337.155
1656.32	326.515
1657.85	344.058
1659.38	349.735
1660.91	343.232
1662.44	332.74
1663.97	328.467
1665.49	336.031
1667.02	342.947
1668.55	333.845
1670.08	325.55
1671.6	327.135
1673.13	336.566
1674.66	336.231
1676.18	338.76
1677.71	337.438
1679.23	338.697
1680.76	325.158
1682.28	348.267
1683.81	323.747
1685.33	327.19
1686.86	322.421
1688.38	338.15
1689.9	337.96
1691.43	329.007
1692.95	328.972
1694.47	318.606
1695.99	344.455
1697.52	326.876
1699.04	324.639
1700.56	334.152
1702.08	326.361
1703.6	333.301
1705.12	337.48
1706.64	326.275
1708.16	318.301
1709.68	328.526
1711.2	339.884
1712.72	336.823
1714.24	337.109
1715.76	337.881
1717.28	328.105
1718.79	330.813
1720.31	313.689
1721.83	320.736
1723.35	318.522
1724.86	320.468
1726.38	331.263
1727.9	329.18
1729.41	336.16
1730.93	326.819
1732.44	323.545
1733.96	328.951
1735.47	319.44
1736.99	325.266
1738.5	328.597
1740.02	323.598
1741.53	317.461
1743.04	336.511
1744.56	334.958
1746.07	323.412
1747.58	328.933
1749.09	322.752
1750.61	324.961
1752.12	327.908
1753.63	321.454
1755.14	323.154
1756.65	324.588
1758.16	320.374
1759.67	335.07
1761.18	329.256
1762.69	327.291
1764.2	317.611
1765.71	328.026
1767.22	324.508
1768.73	326.163
1770.24	327.418
1771.75	320.953
1773.25	321.08
1774.76	327.221
1776.27	327.131
1777.78	336.878
1779.28	339.077
1780.79	328.213
1782.29	326.443
1783.8	322.499
1785.3	328.383
1786.81	327.886
1788.32	333.705
1789.82	326.508
1791.32	336.118
1792.83	331.696
1794.33	332.377
1795.84	326.196
1797.34	331.076
1798.84	327.186
1799.21	325.226
1800.72	336.178
1802.23	341.13
1803.74	323.081
1805.25	331.033
1806.75	337.984
1808.26	326.936
1809.77	337.888
1811.28	335.839
1812.78	332.791
1814.29	326.743
1815.8	334.694
1817.3	356.646
1818.81	341.598
1820.32	302.549
1821.82	337.501
1823.33	336.453
1824.83	350.404
1826.34	332.356
1827.84	350.308
1829.34	325.26
1830.85	339.211
1832.35	327.163
1833.85	329.115
1835.36	336.066
1836.86	340.018
1838.36	327.969
1839.86	335.921
1841.37	335.873
1842.87	332.824
1844.37	327.776
1845.87	309.728
1847.37	334.68
1848.87	324.631
1850.37	326.583
1851.87	333.535
1853.37	342.486
1854.87	340.438
1856.37	325.39
1857.87	341.341
1859.36	329.293
1860.86	321.245
1862.36	317.196
1863.86	337.148
1865.36	329.1
1866.85	337.051
1868.35	319.003
1869.85	327.955
1871.34	326.906
1872.84	322.858
1874.33	331.81
1875.83	318.761
1877.32	338.713
1878.82	337.665
1880.31	344.616
1881.81	332.568
1883.3	302.52
1884.8	336.471
1886.29	334.423
1887.78	334.375
1889.28	324.326
1890.77	338.278
1892.26	328.23
1893.75	311.181
1895.24	334.133
1896.74	324.085
1898.23	342.036
1899.72	332.988
1901.21	349.94
1902.7	323.891
1904.19	339.843
1905.68	317.795
1907.17	324.746
1908.66	356.698
1910.15	333.65
1911.64	321.601
1913.13	337.553
1914.61	335.505
1916.1	345.456
1917.59	344.408
1919.08	327.36
1920.57	339.311
1922.05	332.263
1923.54	341.215
1925.02	344.166
1926.51	340.118
1928	338.07
1929.48	337.021
1930.97	336.973
1932.45	341.925
1933.94	318.876
1935.42	326.828
1936.91	346.78
1938.39	322.731
1939.87	348.683
1941.36	332.635
1942.84	331.586
1944.32	337.538
1945.8	336.49
1947.29	324.441
1948.77	349.393
1950.25	320.345
1951.73	344.296
1953.21	339.248
1954.69	344.2
1956.17	346.151
1957.65	335.103
1959.13	320.055
1960.61	331.006
1962.09	342.958
1963.57	338.91
1965.05	311.861
1966.53	343.813
1968.01	335.765
1969.49	341.716
1970.96	345.668
1972.44	355.62
1973.92	321.571
1975.4	330.523
1976.87	335.475
1978.35	318.426
1979.83	330.378
1981.3	339.33
1982.78	328.281
1984.25	333.233
1985.73	307.185
1987.2	322.136
1988.68	333.088
1990.15	329.04
1991.63	326.991
1993.1	308.943
1994.57	342.895
1996.05	328.846
1997.52	330.798
1998.99	315.75