File: 1/Organic_10.txt
#Acq. time (s)=	10
#Accumulations=	1
#Range (cm-¹)=	100...2000
#Windows=	2
#Autofocus=	Off
#AutoExposure=	Off
#Spike filter=	Off
#Delay time (s)=	0
#Binning=	1
#Readout mode=	Signal
#DeNoise=	Off
#ICS correction=	Off
#Dark correction=	Off
#Inst. Process=	Off
#Instrument=	LabRAM HR Evol
#Detector=	Syncerity OE
#Objective=	x100_VIS
#Grating=	600 (500nm)
#ND Filter=	5%
#Laser=	633nm_Edge
#Hole=	24.99
#Range=	Visible
#Project=	Omar
#Sample=	20-06-23
#Site=	1
#Title=	Organic
#Remark=
#Date=	20.06.2023 11:37
#Acquired=	20.06.2023 11:37:41
101.054	9232
103.621	9086
106.187	9216
108.752	9320
111.317	9248
113.881	9256
116.443	9360
119.005	9336
121.566	9418
124.126	9516
126.685	9462
129.243	9538
131.801	9566
134.356	9610
136.911	9620
139.466	9502
142.021	9644
144.574	9602
147.125	9794
149.676	9704
152.227	9782
154.776	9656
157.325	9722
159.873	9906
162.419	9764
164.966	10022
167.51	9902
170.055	9868
172.598	9944
175.141	9826
177.682	9900
180.222	9890
182.763	9924
185.302	9952
187.839	10024
190.376	10174
192.914	10198
195.449	10246
197.983	10184
200.517	10296
203.05	10316
205.582	10286
208.113	10396
210.643	10416
213.173	10444
215.701	10470
218.229	10560
220.756	10460
223.282	10692
225.808	10626
228.331	10688
230.855	10656
233.378	10762
235.898	10858
238.419	10766
240.94	10784
243.458	10934
245.977	11000
248.495	10950
251.011	11066
253.527	10974
256.041	11044
258.555	11058
261.068	10980
263.58	10948
266.092	10930
268.603	10950
271.112	10882
273.62	11008
276.129	11062
278.636	10934
281.142	11160
283.647	11310
286.152	11146
288.655	11246
291.158	11202
293.66	11348
296.161	11356
298.661	11478
301.161	11414
303.66	11506
306.158	11476
308.655	11552
311.15	11542
313.645	11680
316.14	11566
318.634	11594
321.125	11536
323.618	11702
326.109	11484
328.598	11702
331.088	11660
333.576	11664
336.064	11950
338.55	11724
341.037	11850
343.521	11838
346.005	11850
348.489	11736
350.971	11856
353.453	11994
355.933	11968
358.414	11974
360.893	11990
363.371	11894
365.848	12060
368.325	12018
370.801	12142
373.275	12076
375.75	12122
378.223	12062
380.695	11884
383.167	11902
385.638	11990
388.108	12062
390.577	12012
393.044	11928
395.512	11908
397.979	12124
400.444	12220
402.909	12162
405.374	12238
407.836	12282
410.299	12366
412.76	12456
415.221	12454
417.681	12564
420.141	12604
422.598	12536
425.057	12632
427.513	12524
429.968	12710
432.422	12614
434.878	12758
437.33	12756
439.783	12894
442.234	12714
444.685	12872
447.134	12780
449.583	12680
452.032	12754
454.479	12800
456.926	12784
459.372	12742
461.817	12690
464.261	12798
466.705	12770
469.147	12688
471.588	12774
474.029	12778
476.47	12812
478.909	12956
481.347	12840
483.785	12916
486.221	13008
488.657	12990
491.092	12992
493.527	13062
495.96	13024
498.393	13028
500.824	13176
503.255	13102
505.686	13136
508.115	13216
510.543	13088
512.972	13040
515.399	13150
517.825	13170
520.25	13144
522.674	13016
525.097	12968
527.52	13048
529.942	12932
532.364	12976
534.784	13150
537.204	13086
539.623	12852
542.041	13014
544.457	13006
546.874	12940
549.289	13046
551.705	12968
554.118	12884
556.531	12886
558.943	13058
561.355	13078
563.766	13070
566.175	13038
568.585	13034
570.992	13150
573.399	13134
575.807	13062
578.212	13092
580.617	13102
583.022	13268
585.425	13036
587.827	13176
590.229	13176
592.63	13176
595.03	13192
597.43	13138
599.829	13284
602.226	13272
604.623	13234
607.02	13254
609.414	13296
611.808	13320
614.202	13380
616.596	13318
618.988	13418
621.378	13528
623.769	13532
626.159	13452
628.548	13548
630.936	13526
633.324	13566
635.71	13692
638.096	13664
640.481	13644
642.866	13758
645.248	13780
647.63	13690
650.013	13740
652.394	13878
654.773	13874
657.154	13834
659.532	13680
661.91	13736
664.286	13710
666.663	13716
669.038	13710
671.412	13742
673.786	13690
676.159	13758
678.532	13706
680.903	13822
683.274	13614
685.644	13636
688.014	13730
690.381	13562
692.749	13760
695.116	13714
697.481	13734
699.846	13730
702.211	13768
704.574	13852
706.938	13734
709.299	13888
711.661	13698
714.021	13802
716.381	13790
718.739	13908
721.097	13768
723.455	13856
725.811	13828
728.167	13802
730.521	13834
732.875	13828
735.23	13878
737.582	13898
739.934	13770
742.285	13836
744.635	13910
746.985	13910
749.332	13850
751.68	13868
754.028	13854
756.374	13834
758.72	13732
761.065	13818
763.408	13788
765.752	13782
768.095	13842
770.436	13760
772.777	13802
775.116	13808
777.456	13776
779.794	13896
782.133	13774
784.469	13790
786.805	13698
789.141	13632
791.476	13704
793.809	13854
796.142	13894
798.476	13940
800.807	13880
803.138	13772
805.468	13830
807.797	13756
810.125	15782
812.453	13920
814.78	13870
817.106	14002
819.432	13980
821.757	14108
824.08	13860
826.403	13808
828.726	14234
831.048	14046
833.368	14052
835.688	14050
838.007	14146
840.326	14250
842.644	14158
844.96	14204
847.276	14088
849.592	14232
851.906	14088
854.221	14146
856.534	14010
858.846	14058
861.157	14078
863.469	14146
865.779	14060
868.088	14298
870.396	14184
872.704	13988
875.011	14120
877.318	14142
879.623	14148
881.928	14134
884.232	14156
886.536	13936
888.837	14072
891.139	13912
893.44	14034
895.741	13980
898.039	13952
900.339	13924
902.637	13830
904.933	13836
907.231	13974
909.526	13954
911.821	13888
914.115	13884
916.408	13912
918.701	13914
920.993	13784
923.283	13746
925.573	13756
927.864	13714
930.153	13788
932.441	13676
934.728	13892
937.014	13962
939.3	13916
941.585	13850
943.87	13840
946.154	13948
948.437	13970
950.719	13940
952.999	14090
955.28	13852
957.56	14026
959.84	14040
962.117	13894
964.395	13830
966.671	13912
968.948	14038
971.223	13918
973.498	13960
975.771	14164
978.045	14134
980.317	13898
982.588	13856
984.86	13938
987.13	13970
989.399	13874
991.667	13938
993.937	13944
996.204	13976
998.47	13944
1000.74	13772
1003	13968
1005.26	13892
1007.53	14012
1009.79	13880
1012.05	13838
1014.31	13804
1016.57	13888
1018.83	13858
1021.09	13846
1023.35	13936
1025.61	13966
1027.87	13848
1030.12	13872
1032.38	13972
1034.63	14014
1036.88	14058
1039.14	13900
1041.39	14054
1043.64	14222
1045.89	13998
1048.14	14218
1050.39	14128
1052.64	14198
1054.89	14062
1057.14	14128
1059.38	14030
1061.63	14272
1063.87	14062
1066.12	14030
1068.36	14038
1070.6	14192
1072.85	14128
1075.09	14034
1077.33	14048
1079.57	13914
1081.81	14006
1084.05	13870
1086.28	13922
1088.52	13944
1090.76	13824
1092.99	13908
1095.23	13770
1097.46	13660
1099.69	13680
1101.93	13728
1104.16	13726
1106.39	13770
1108.62	13632
1110.85	13814
1113.08	13718
1115.31	13602
1117.53	13712
1119.76	13580
1121.99	13710
1124.21	13694
1126.44	13576
1128.66	13600
1130.88	13690
1133.11	13676
1135.33	13792
1137.55	13756
1139.77	13646
1141.99	13692
1144.21	13808
1146.43	13676
1148.64	13842
1150.86	13780
1153.08	13890
1155.29	13914
1157.51	13828
1159.72	13842
1161.93	13658
1164.14	13814
1166.36	13920
1168.57	13838
1170.78	13832
1172.99	13888
1175.2	13896
1177.4	13864
1179.61	14024
1181.82	13854
1184.02	13762
1186.23	13776
1188.43	13832
1190.64	13730
1192.84	13652
1195.04	13676
1197.24	13680
1199.45	13519.3
1201.64	13550.2
1203.84	13419.9
1206.04	13392.6
1208.24	13504.1
1210.44	13439.2
1212.64	13334.8
1214.83	13211
1217.03	13370.5
1219.22	13224.4
1221.41	13270.6
1223.61	13202.1
1225.8	13007.9
1227.99	12983.6
1230.18	13139.9
1232.37	12991.9
1234.56	12918.8
1236.75	12902.7
1238.94	12979
1241.13	12840.5
1243.31	12818.5
1245.5	12855.8
1247.68	12912.1
1249.87	12737
1252.05	12892.8
1254.24	12820.1
1256.42	12688.6
1258.6	12733.1
1260.78	12748.3
1262.96	12769
1265.14	12819.2
1267.32	12599.6
1269.5	12674.7
1271.67	12706.2
1273.85	12672.3
1276.03	12552.1
1278.2	12639.4
1280.38	12473.2
1282.55	12552.3
1284.72	12570
1286.9	12496.8
1289.07	12569
1291.24	12466.1
1293.41	12404
1295.58	12428.8
1297.75	12557.5
1299.92	12402.2
1302.09	12292.3
1304.25	12307.5
1306.42	12346.9
1308.46	12334
1310.63	12188
1312.81	12106
1314.98	12184
1317.16	12102
1319.33	12214
1321.5	12102
1323.67	12178
1325.85	12298
1328.02	11972
1330.19	12152
1332.35	12114
1334.52	12204
1336.69	12014
1338.86	12126
1341.02	12068
1343.19	12056
1345.35	11924
1347.52	11930
1349.68	12144
1351.84	11896
1354	12018
1356.17	12114
1358.33	11870
1360.49	11976
1362.65	12106
1364.8	11898
1366.96	12078
1369.12	12072
1371.28	11976
1373.43	11942
1375.59	11984
1377.74	12048
1379.89	11912
1382.05	11832
1384.2	11926
1386.35	11940
1388.5	11964
1390.65	11858
1392.8	11788
1394.95	11872
1397.1	11778
1399.25	11858
1401.4	11732
1403.54	12060
1405.69	11926
1407.83	11734
1409.98	11794
1412.12	11692
1414.26	11846
1416.4	11848
1418.55	11784
1420.69	11692
1422.83	11852
1424.97	11684
1427.1	11780
1429.24	11696
1431.38	11670
1433.52	11666
1435.65	11892
1437.79	11672
1439.92	11578
1442.06	11546
1444.19	11694
1446.32	11854
1448.46	11806
1450.59	11576
1452.72	11650
1454.85	11682
1456.98	11638
1459.11	11562
1461.23	11760
1463.36	11594
1465.49	11628
1467.61	11742
1469.74	11598
1471.86	11648
1473.99	11666
1476.11	11582
1478.23	11536
1480.36	11644
1482.48	11694
1484.6	11388
1486.72	11594
1488.84	11484
1490.96	11426
1493.07	11496
1495.19	11442
1497.31	11618
1499.42	11584
1501.54	11512
1503.65	11474
1505.77	11422
1507.88	11448
1509.99	11476
1512.1	11286
1514.22	11374
1516.33	11330
1518.44	11444
1520.55	11390
1522.65	11436
1524.76	11240
1526.87	11236
1528.98	11268
1531.08	11316
1533.19	11128
1535.29	11226
1537.4	11102
1539.5	11088
1541.6	11132
1543.7	11154
1545.8	11118
1547.91	11126
1550.01	11202
1552.11	10944
1554.2	11068
1556.3	11006
1558.4	10924
1560.5	10816
1562.59	10964
1564.69	10974
1566.78	10916
1568.88	10998
1570.97	10972
1573.06	10992
1575.15	10872
1577.25	10860
1579.34	10862
1581.43	10892
1583.52	10916
1585.6	10940
1587.69	10936
1589.78	10928
1591.87	10870
1593.95	10914
1596.04	10826
1598.12	10910
1600.21	10916
1602.29	10874
1604.37	10826
1606.46	10884
1608.54	11002
1610.62	10830
1612.7	10756
1614.78	10844
1616.86	10788
1618.94	10916
1621.01	10912
1623.09	10750
1625.17	10842
1627.24	10730
1629.32	10792
1631.39	10784
1633.47	10656
1635.54	10688
1637.61	10808
1639.68	10748
1641.76	10736
1643.83	10700
1645.9	10684
1647.96	10826
1650.03	10492
1652.1	10746
1654.17	10510
1656.24	10696
1658.3	10542
1660.37	10522
1662.43	10518
1664.5	10474
1666.56	10394
1668.62	10480
1670.68	10324
1672.75	10530
1674.81	10402
1676.87	10458
1678.93	10336
1680.99	10374
1683.04	10260
1685.1	10322
1687.16	10280
1689.21	10422
1691.27	10222
1693.33	10146
1695.38	10278
1697.43	10178
1699.49	10116
1701.54	10186
1703.59	10206
1705.64	10148
1707.69	10174
1709.74	10140
1711.79	10104
1713.84	9848
1715.89	9960
1717.94	10026
1719.98	9974
1722.03	10004
1724.07	9938
1726.12	9896
1728.16	9984
1730.21	9996
1732.25	9990
1734.29	9950
1736.33	9870
1738.37	9870
1740.41	9880
1742.45	10004
1744.49	9906
1746.53	9800
1748.57	9896
1750.61	9862
1752.64	9748
1754.68	9822
1756.71	9896
1758.75	9794
1760.78	9822
1762.82	9688
1764.85	9744
1766.88	9706
1768.91	9740
1770.94	9666
1772.97	9638
1775	9704
1777.03	9684
1779.06	9674
1781.09	9592
1783.12	9722
1785.14	9626
1787.17	9658
1789.19	9712
1791.22	9526
1793.24	9692
1795.27	9562
1797.29	9528
1799.31	9530
1801.33	9596
1803.35	9528
1805.37	9450
1807.39	9518
1809.41	9430
1811.43	9540
1813.45	9506
1815.46	9412
1817.48	9384
1819.5	9306
1821.51	9384
1823.53	9286
1825.54	9220
1827.55	9172
1829.57	9214
1831.58	9288
1833.59	9286
1835.6	9140
1837.61	9112
1839.62	9018
1841.63	9124
1843.64	9118
1845.65	9032
1847.65	9056
1849.66	9026
1851.66	9060
1853.67	9074
1855.67	8990
1857.68	8994
1859.68	8894
1861.68	8914
1863.69	8912
1865.69	8874
1867.69	8842
1869.69	8842
1871.69	8960
1873.69	8962
1875.69	8690
1877.68	8790
1879.68	8678
1881.68	8848
1883.67	8714
1885.67	8616
1887.66	8666
1889.66	8732
1891.65	8716
1893.64	8572
1895.64	8674
1897.63	8590
1899.62	8712
1901.61	8640
1903.6	8754
1905.59	8714
1907.58	8656
1909.56	8512
1911.55	8530
1913.54	8606
1915.53	8508
1917.51	8548
1919.5	8522
1921.48	8438
1923.46	8466
1925.45	8416
1927.43	8436
1929.41	8464
1931.39	8440
1933.37	8330
1935.35	8414
1937.33	8468
1939.31	8402
1941.29	8420
1943.27	8382
1945.24	8322
1947.22	8344
1949.2	8286
1951.17	8280
1953.14	8335
1955.12	8246
1957.09	8140
1959.06	8176
1961.04	8136
1963.01	8226
1964.98	8244
1966.95	8054
1968.92	8080
1970.89	7972
1972.86	7958
1974.82	8040
1976.79	8072
1978.76	8016
1980.72	7972
1982.69	8018
1984.65	7978
1986.62	7912
1988.58	7890
1990.54	7888
1992.51	7922
1994.47	7892
1996.43	7808
1998.39	7898
1999.37	7832