File: 1/Organic_05.txt
#Acq. time (s)=	10
#Accumulations=	2
#Range (cm-¹)=	100...2000
#Windows=	2
#Autofocus=	Off
#AutoExposure=	Off
#Spike filter=	Multiple accum.
#Delay time (s)=	0
#Binning=	1
#Readout mode=	Signal
#DeNoise=	Off
#ICS correction=	Off
#Dark correction=	Off
#Inst. Process=	Off
#Instrument=	LabRAM HR Evol
#Detector=	Syncerity OE
#Objective=	x100_VIS
#Grating=	600 (500nm)
#ND Filter=	10%
#Laser=	633nm_Edge
#Hole=	24.99
#Range=	Visible
#Project=	Omar
#Sample=	20-06-23
#Site=	1
#Title=	Organic
#Remark=
#Date=	20.06.2023 11:27
#Acquired=	20.06.2023 11:27:28
101.054	4580
103.621	4690
106.187	4606
108.752	4722
111.317	4710
113.881	4684
116.443	4714
119.005	4714
121.566	4734
124.126	4744
126.685	4794
129.243	4828
131.801	4812
134.356	4812
136.911	4808
139.466	4800
142.021	4828
144.574	4962
147.125	4960
149.676	4902
152.227	4898
154.776	4904
157.325	4898
159.873	4960
162.419	4930
164.966	4966
167.51	4922
170.055	5030
172.598	4970
175.141	5030
177.682	4928
180.222	4956
182.763	4960
185.302	5070
187.839	5048
190.376	5202
192.914	5108
195.449	5156
197.983	5148
200.517	5198
203.05	5178
205.582	5192
208.113	5254
210.643	5180
213.173	5312
215.701	5240
218.229	5294
220.756	5414
223.282	5352
225.808	5422
228.331	5406
230.855	5440
233.378	5404
235.898	5450
238.419	5404
240.94	5534
243.458	5520
245.977	5508
248.495	5566
251.011	5576
253.527	5518
256.041	5516
258.555	5568
261.068	5554
263.58	5628
266.092	5548
268.603	5590
271.112	5530
273.62	5634
276.129	5576
278.636	5600
281.142	5472
283.647	5656
286.152	5640
288.655	5640
291.158	5800
293.66	5698
296.161	5740
298.661	5778
301.161	5774
303.66	5788
306.158	5806
308.655	5846
311.15	5824
313.645	5858
316.14	5908
318.634	5862
321.125	5798
323.618	5998
326.109	5878
328.598	5862
331.088	5872
333.576	5938
336.064	5988
338.55	5872
341.037	6026
343.521	5952
346.005	5982
348.489	6058
350.971	6090
353.453	6026
355.933	6178
358.414	6028
360.893	6078
363.371	6022
365.848	6128
368.325	6194
370.801	6008
373.275	6154
375.75	6012
378.223	6070
380.695	6036
383.167	6080
385.638	6040
388.108	6164
390.577	6080
393.044	6096
395.512	6160
397.979	6140
400.444	6180
402.909	6148
405.374	6230
407.836	6284
410.299	6208
412.76	6356
415.221	6322
417.681	6412
420.141	6498
422.598	6390
425.057	6458
427.513	6384
429.968	6490
432.422	6454
434.878	6478
437.33	6556
439.783	6520
442.234	6572
444.685	6474
447.134	6496
449.583	6590
452.032	6562
454.479	6610
456.926	6560
459.372	6452
461.817	6520
464.261	6520
466.705	6528
469.147	6566
471.588	6604
474.029	6568
476.47	6442
478.909	6526
481.347	6590
483.785	6554
486.221	6762
488.657	6590
491.092	6630
493.527	6634
495.96	6762
498.393	6632
500.824	6774
503.255	6734
505.686	6684
508.115	6746
510.543	6748
512.972	6752
515.399	6742
517.825	6674
520.25	6792
522.674	6620
525.097	6700
527.52	6710
529.942	6678
532.364	6830
534.784	6604
537.204	6712
539.623	6688
542.041	6690
544.457	6768
546.874	6666
549.289	6720
551.705	6536
554.118	6618
556.531	6704
558.943	6638
561.355	6636
563.766	6748
566.175	6776
568.585	6736
570.992	6704
573.399	6724
575.807	6804
578.212	6680
580.617	6744
583.022	6660
585.425	6700
587.827	6686
590.229	6782
592.63	6770
595.03	6744
597.43	6822
599.829	6802
602.226	6750
604.623	6934
607.02	6852
609.414	6870
611.808	6914
614.202	6906
616.596	6936
618.988	6968
621.378	6898
623.769	7010
626.159	7048
628.548	7094
630.936	7064
633.324	6996
635.71	7090
638.096	7176
640.481	6972
642.866	7040
645.248	7056
647.63	7110
650.013	7050
652.394	7010
654.773	7090
657.154	7062
659.532	7136
661.91	7104
664.286	7066
666.663	7118
669.038	7142
671.412	7110
673.786	7100
676.159	7118
678.532	6970
680.903	7064
683.274	7068
685.644	6992
688.014	7098
690.381	7158
692.749	7090
695.116	7100
697.481	7056
699.846	7064
702.211	7156
704.574	7026
706.938	7064
709.299	7138
711.661	7152
714.021	7216
716.381	7182
718.739	7180
721.097	7162
723.455	7224
725.811	7198
728.167	7050
730.521	7280
732.875	7146
735.23	7182
737.582	7110
739.934	7152
742.285	7166
744.635	7126
746.985	7176
749.332	7156
751.68	7086
754.028	7080
756.374	7172
758.72	7078
761.065	7098
763.408	7092
765.752	7048
768.095	7174
770.436	7070
772.777	7066
775.116	7160
777.456	7106
779.794	7070
782.133	7038
784.469	7210
786.805	7158
789.141	7050
791.476	7170
793.809	7072
796.142	7108
798.476	7136
800.807	7100
803.138	7166
805.468	7090
807.797	7182
810.125	7252
812.453	7134
814.78	7136
817.106	7258
819.432	7246
821.757	7232
824.08	7182
826.403	7220
828.726	7246
831.048	7242
833.368	7334
835.688	7232
838.007	7278
840.326	7264
842.644	7310
844.96	7310
847.276	7410
849.592	7332
851.906	7440
854.221	7318
856.534	7382
858.846	7288
861.157	7444
863.469	7350
865.779	7310
868.088	7346
870.396	7376
872.704	7330
875.011	7350
877.318	7314
879.623	7302
881.928	7244
884.232	7278
886.536	7270
888.837	7222
891.139	7262
893.44	7280
895.741	7196
898.039	7188
900.339	7212
902.637	7244
904.933	7196
907.231	7176
909.526	7224
911.821	7178
914.115	7172
916.408	7206
918.701	7250
920.993	7152
923.283	7170
925.573	7262
927.864	7182
930.153	7170
932.441	7228
934.728	7290
937.014	7228
939.3	7276
941.585	7272
943.87	7304
946.154	7208
948.437	7284
950.719	7214
952.999	7240
955.28	7250
957.56	7320
959.84	7250
962.117	7230
964.395	7402
966.671	7396
968.948	7266
971.223	7306
973.498	7252
975.771	7212
978.045	7210
980.317	7284
982.588	7280
984.86	7276
987.13	7274
989.399	7176
991.667	7352
993.937	7190
996.204	7206
998.47	7186
1000.74	7186
1003	7312
1005.26	7278
1007.53	7228
1009.79	7204
1012.05	7222
1014.31	7176
1016.57	7256
1018.83	7272
1021.09	7356
1023.35	7316
1025.61	7314
1027.87	7326
1030.12	7326
1032.38	7312
1034.63	7272
1036.88	7256
1039.14	7394
1041.39	7340
1043.64	7304
1045.89	7368
1048.14	7412
1050.39	7440
1052.64	7314
1054.89	7424
1057.14	7304
1059.38	7394
1061.63	7386
1063.87	7364
1066.12	7468
1068.36	7360
1070.6	7398
1072.85	7344
1075.09	7322
1077.33	7310
1079.57	7298
1081.81	7278
1084.05	7328
1086.28	7266
1088.52	7362
1090.76	7360
1092.99	7262
1095.23	7146
1097.46	7266
1099.69	7172
1101.93	7250
1104.16	7214
1106.39	7218
1108.62	7142
1110.85	7194
1113.08	7134
1115.31	7164
1117.53	7162
1119.76	7118
1121.99	7214
1124.21	7164
1126.44	7064
1128.66	7154
1130.88	7190
1133.11	7156
1135.33	7234
1137.55	7168
1139.77	7118
1141.99	7172
1144.21	7126
1146.43	7230
1148.64	7338
1150.86	7146
1153.08	7182
1155.29	7118
1157.51	7310
1159.72	7126
1161.93	7286
1164.14	7336
1166.36	7250
1168.57	7174
1170.78	7232
1172.99	7304
1175.2	7326
1177.4	7180
1179.61	7166
1181.82	7226
1184.02	7284
1186.23	7192
1188.43	7200
1190.64	7224
1192.84	7224
1195.04	7226
1197.24	7190
1199.45	7187.23
1201.64	7110.35
1203.84	7165.75
1206.04	7187.89
1208.24	7126.05
1210.44	7107.57
1212.64	7021.18
1214.83	6981.48
1217.03	6980.35
1219.22	6920.03
1221.41	6855.08
1223.61	6890.98
1225.8	6891.45
1227.99	6844.91
1230.18	6765.35
1232.37	6882.8
1234.56	6830.78
1236.75	6810.77
1238.94	6772.46
1241.13	6840.25
1243.31	6765.54
1245.5	6780.52
1247.68	6816.9
1249.87	6795.11
1252.05	6676.53
1254.24	6713.76
1256.42	6713.75
1258.6	6751.76
1260.78	6718.94
1262.96	6680.99
1265.14	6720.8
1267.32	6681.22
1269.5	6716.02
1271.67	6726.13
1273.85	6703.14
1276.03	6632.19
1278.2	6626.84
1280.38	6661.9
1282.55	6605.28
1284.72	6608.81
1286.9	6543.77
1289.07	6597.4
1291.24	6647.01
1293.41	6543.71
1295.58	6479.4
1297.75	6507.89
1299.92	6528.33
1302.09	6513.41
1304.25	6554.35
1306.42	6530.34
1308.46	6408
1310.63	6400
1312.81	6540
1314.98	6416
1317.16	6444
1319.33	6546
1321.5	6452
1323.67	6374
1325.85	6418
1328.02	6430
1330.19	6348
1332.35	6404
1334.52	6380
1336.69	6504
1338.86	6424
1341.02	6314
1343.19	6320
1345.35	6422
1347.52	6374
1349.68	6514
1351.84	6354
1354	6332
1356.17	6356
1358.33	6376
1360.49	6384
1362.65	6344
1364.8	6350
1366.96	6372
1369.12	6462
1371.28	6380
1373.43	6434
1375.59	6432
1377.74	6352
1379.89	6264
1382.05	6400
1384.2	6276
1386.35	6292
1388.5	6282
1390.65	6298
1392.8	6218
1394.95	6324
1397.1	6264
1399.25	6302
1401.4	6320
1403.54	6328
1405.69	6360
1407.83	6280
1409.98	6332
1412.12	6310
1414.26	6324
1416.4	6284
1418.55	6294
1420.69	6274
1422.83	6268
1424.97	6318
1427.1	6338
1429.24	6258
1431.38	6254
1433.52	6204
1435.65	6216
1437.79	6274
1439.92	6152
1442.06	6210
1444.19	6182
1446.32	6296
1448.46	6304
1450.59	6222
1452.72	6248
1454.85	6290
1456.98	6178
1459.11	6194
1461.23	6268
1463.36	6222
1465.49	6252
1467.61	6210
1469.74	6250
1471.86	6202
1473.99	6190
1476.11	6320
1478.23	6286
1480.36	6190
1482.48	6212
1484.6	6134
1486.72	6292
1488.84	6182
1490.96	6278
1493.07	6126
1495.19	6142
1497.31	6142
1499.42	6214
1501.54	6108
1503.65	6124
1505.77	6140
1507.88	6104
1509.99	6144
1512.1	6012
1514.22	6132
1516.33	5954
1518.44	6044
1520.55	6044
1522.65	6068
1524.76	6062
1526.87	6034
1528.98	6090
1531.08	6030
1533.19	6064
1535.29	6016
1537.4	6004
1539.5	5994
1541.6	5970
1543.7	5972
1545.8	5866
1547.91	5844
1550.01	5918
1552.11	5992
1554.2	5880
1556.3	6000
1558.4	5864
1560.5	5948
1562.59	5868
1564.69	5838
1566.78	5810
1568.88	5876
1570.97	5902
1573.06	5806
1575.15	5832
1577.25	5834
1579.34	5892
1581.43	5896
1583.52	5856
1585.6	5830
1587.69	5782
1589.78	5822
1591.87	5772
1593.95	5778
1596.04	5758
1598.12	5846
1600.21	5800
1602.29	5788
1604.37	5822
1606.46	5838
1608.54	5756
1610.62	5856
1612.7	5820
1614.78	5760
1616.86	5882
1618.94	5784
1621.01	5720
1623.09	5798
1625.17	5880
1627.24	5784
1629.32	5802
1631.39	5752
1633.47	5724
1635.54	5718
1637.61	5842
1639.68	5740
1641.76	5790
1643.83	5756
1645.9	5638
1647.96	5762
1650.03	5730
1652.1	5794
1654.17	5628
1656.24	5716
1658.3	5618
1660.37	5642
1662.43	5674
1664.5	5636
1666.56	5718
1668.62	5670
1670.68	5620
1672.75	5614
1674.81	5572
1676.87	5610
1678.93	5620
1680.99	5578
1683.04	5544
1685.1	5550
1687.16	5522
1689.21	5472
1691.27	5500
1693.33	5502
1695.38	5438
1697.43	5498
1699.49	5506
1701.54	5432
1703.59	5514
1705.64	5416
1707.69	5416
1709.74	5356
1711.79	5374
1713.84	5384
1715.89	5472
1717.94	5328
1719.98	5324
1722.03	5442
1724.07	5360
1726.12	5312
1728.16	5378
1730.21	5370
1732.25	5400
1734.29	5378
1736.33	5354
1738.37	5358
1740.41	5366
1742.45	5318
1744.49	5294
1746.53	5304
1748.57	5290
1750.61	5342
1752.64	5252
1754.68	5252
1756.71	5290
1758.75	5308
1760.78	5272
1762.82	5286
1764.85	5274
1766.88	5230
1768.91	5280
1770.94	5230
1772.97	5188
1775	5262
1777.03	5214
1779.06	5262
1781.09	5242
1783.12	5214
1785.14	5200
1787.17	5230
1789.19	5170
1791.22	5150
1793.24	5176
1795.27	5192
1797.29	5168
1799.31	5094
1801.33	5184
1803.35	5178
1805.37	5086
1807.39	5188
1809.41	5130
1811.43	5086
1813.45	5116
1815.46	5078
1817.48	5074
1819.5	5108
1821.51	5036
1823.53	5154
1825.54	5012
1827.55	4952
1829.57	4990
1831.58	5056
1833.59	4996
1835.6	4996
1837.61	4972
1839.62	5012
1841.63	5016
1843.64	4882
1845.65	4984
1847.65	4824
1849.66	4896
1851.66	4864
1853.67	4928
1855.67	4850
1857.68	4774
1859.68	4898
1861.68	4774
1863.69	4834
1865.69	4826
1867.69	4802
1869.69	4770
1871.69	4772
1873.69	4842
1875.69	4770
1877.68	4726
1879.68	4788
1881.68	4748
1883.67	4720
1885.67	4814
1887.66	4738
1889.66	4720
1891.65	4790
1893.64	4736
1895.64	4708
1897.63	4722
1899.62	4712
1901.61	4696
1903.6	4728
1905.59	4696
1907.58	4730
1909.56	4750
1911.55	4652
1913.54	4660
1915.53	4644
1917.51	4586
1919.5	4690
1921.48	4692
1923.46	4680
1925.45	4542
1927.43	4514
1929.41	4580
1931.39	4614
1933.37	4590
1935.35	4554
1937.33	4642
1939.31	4582
1941.29	4448
1943.27	4482
1945.24	4506
1947.22	4588
1949.2	4524
1951.17	4504
1953.14	4480
1955.12	4526
1957.09	4502
1959.06	4470
1961.04	4480
1963.01	4426
1964.98	4426
1966.95	4338
1968.92	4450
1970.89	4384
1972.86	4448
1974.82	4374
1976.79	4336
1978.76	4314
1980.72	4342
1982.69	4292
1984.65	4350
1986.62	4444
1988.58	4316
1990.54	4360
1992.51	4324
1994.47	4278
1996.43	4360
1998.39	4276
1999.37	4270