File: 1/Organic_12.txt
#Acq. time (s)=	10
#Accumulations=	1
#Range (cm-¹)=	100...2000
#Windows=	2
#Autofocus=	Off
#AutoExposure=	Off
#Spike filter=	Off
#Delay time (s)=	0
#Binning=	1
#Readout mode=	Signal
#DeNoise=	Off
#ICS correction=	Off
#Dark correction=	Off
#Inst. Process=	Off
#Instrument=	LabRAM HR Evol
#Detector=	Syncerity OE
#Objective=	x100_VIS
#Grating=	600 (500nm)
#ND Filter=	5%
#Laser=	633nm_Edge
#Hole=	24.99
#Range=	Visible
#Project=	Omar
#Sample=	20-06-23
#Site=	1
#Title=	Organic
#Remark=
#Date=	20.06.2023 11:42
#Acquired=	20.06.2023 11:42:10
101.054	8330
103.621	8380
106.187	8456
108.752	8408
111.317	8466
113.881	8352
116.443	8488
119.005	8478
121.566	8514
124.126	8580
126.685	8590
129.243	8760
131.801	8630
134.356	8682
136.911	8566
139.466	8616
142.021	8664
144.574	8752
147.125	8646
149.676	8742
152.227	8768
154.776	8756
157.325	8828
159.873	8724
162.419	8844
164.966	8888
167.51	8988
170.055	8828
172.598	8800
175.141	8938
177.682	8786
180.222	8906
182.763	8934
185.302	8972
187.839	8964
190.376	9060
192.914	9104
195.449	9184
197.983	9194
200.517	9160
203.05	9370
205.582	9312
208.113	9288
210.643	9368
213.173	9318
215.701	9352
218.229	9502
220.756	9504
223.282	9552
225.808	9554
228.331	9500
230.855	9384
233.378	9512
235.898	9772
238.419	9682
240.94	9796
243.458	9782
245.977	9848
248.495	9846
251.011	9804
253.527	9854
256.041	9872
258.555	9938
261.068	9942
263.58	9814
266.092	9764
268.603	9936
271.112	9778
273.62	9796
276.129	9818
278.636	9870
281.142	9828
283.647	9748
286.152	10070
288.655	9954
291.158	10048
293.66	10090
296.161	10180
298.661	10096
301.161	10248
303.66	10230
306.158	10304
308.655	10272
311.15	10342
313.645	10334
316.14	10310
318.634	10240
321.125	10386
323.618	10524
326.109	10458
328.598	10308
331.088	10290
333.576	10466
336.064	10514
338.55	10506
341.037	10434
343.521	10658
346.005	10650
348.489	10632
350.971	10592
353.453	10698
355.933	10614
358.414	10764
360.893	10776
363.371	10770
365.848	10774
368.325	10662
370.801	10732
373.275	10700
375.75	10774
378.223	10700
380.695	10700
383.167	10830
385.638	10640
388.108	10760
390.577	10768
393.044	10724
395.512	10812
397.979	10792
400.444	10862
402.909	10854
405.374	10924
407.836	11058
410.299	11082
412.76	11204
415.221	11240
417.681	11244
420.141	11136
422.598	11266
425.057	11246
427.513	11322
429.968	11456
432.422	11354
434.878	11484
437.33	11298
439.783	11382
442.234	11398
444.685	11378
447.134	11342
449.583	11334
452.032	11380
454.479	11508
456.926	11428
459.372	11524
461.817	11336
464.261	11460
466.705	11488
469.147	11432
471.588	11462
474.029	11528
476.47	11422
478.909	11560
481.347	11650
483.785	11602
486.221	11580
488.657	11644
491.092	11716
493.527	11702
495.96	11650
498.393	11690
500.824	11536
503.255	11696
505.686	11652
508.115	11784
510.543	11840
512.972	11816
515.399	11838
517.825	11722
520.25	11896
522.674	11830
525.097	11730
527.52	11698
529.942	11702
532.364	11658
534.784	11600
537.204	11640
539.623	11680
542.041	11704
544.457	11838
546.874	11616
549.289	11704
551.705	11656
554.118	11666
556.531	11722
558.943	11792
561.355	11778
563.766	11700
566.175	11926
568.585	11712
570.992	11800
573.399	11850
575.807	11966
578.212	11870
580.617	11846
583.022	11902
585.425	12012
587.827	11862
590.229	11814
592.63	11784
595.03	12066
597.43	11944
599.829	11984
602.226	12104
604.623	12058
607.02	12130
609.414	11936
611.808	12142
614.202	11982
616.596	12164
618.988	12148
621.378	12032
623.769	12218
626.159	12428
628.548	12380
630.936	12304
633.324	12392
635.71	12296
638.096	12398
640.481	12366
642.866	12484
645.248	12506
647.63	12434
650.013	12424
652.394	12502
654.773	12476
657.154	12460
659.532	12510
661.91	12378
664.286	12452
666.663	12506
669.038	12474
671.412	12416
673.786	12294
676.159	12528
678.532	12510
680.903	12428
683.274	12396
685.644	12388
688.014	12366
690.381	12346
692.749	12342
695.116	12534
697.481	12326
699.846	12450
702.211	12392
704.574	12456
706.938	12532
709.299	12484
711.661	12492
714.021	12468
716.381	12458
718.739	12628
721.097	12504
723.455	12476
725.811	12500
728.167	12550
730.521	12518
732.875	12548
735.23	12478
737.582	12622
739.934	12534
742.285	12646
744.635	12504
746.985	12438
749.332	12590
751.68	12588
754.028	12432
756.374	12482
758.72	12470
761.065	12402
763.408	12574
765.752	12448
768.095	12448
770.436	12536
772.777	12534
775.116	12462
777.456	12426
779.794	12484
782.133	12422
784.469	12450
786.805	12476
789.141	12478
791.476	12482
793.809	12540
796.142	12618
798.476	12492
800.807	12482
803.138	12526
805.468	12522
807.797	12516
810.125	12756
812.453	12634
814.78	12592
817.106	12636
819.432	12734
821.757	12466
824.08	12740
826.403	12710
828.726	12786
831.048	12694
833.368	12814
835.688	12712
838.007	12762
840.326	12870
842.644	12732
844.96	12988
847.276	12912
849.592	12990
851.906	12858
854.221	12854
856.534	12720
858.846	12764
861.157	12752
863.469	12834
865.779	12764
868.088	12804
870.396	12952
872.704	12848
875.011	12828
877.318	12784
879.623	12798
881.928	12880
884.232	12786
886.536	12796
888.837	12634
891.139	12692
893.44	12662
895.741	12758
898.039	12672
900.339	12598
902.637	12734
904.933	12474
907.231	12596
909.526	12620
911.821	12586
914.115	12474
916.408	12612
918.701	12636
920.993	12706
923.283	12474
925.573	12630
927.864	12600
930.153	12588
932.441	12590
934.728	12610
937.014	12604
939.3	12690
941.585	12644
943.87	12652
946.154	12728
948.437	12674
950.719	12756
952.999	12626
955.28	12636
957.56	12790
959.84	12746
962.117	12868
964.395	12814
966.671	12868
968.948	12738
971.223	12838
973.498	12804
975.771	12820
978.045	12864
980.317	12848
982.588	12876
984.86	12602
987.13	12856
989.399	12810
991.667	12744
993.937	12716
996.204	12660
998.47	12648
1000.74	12812
1003	12798
1005.26	12684
1007.53	12714
1009.79	12762
1012.05	12748
1014.31	12782
1016.57	12736
1018.83	12624
1021.09	12740
1023.35	12778
1025.61	12844
1027.87	12864
1030.12	12956
1032.38	12874
1034.63	12754
1036.88	12684
1039.14	12864
1041.39	12832
1043.64	12866
1045.89	12804
1048.14	12890
1050.39	12854
1052.64	12978
1054.89	12990
1057.14	12910
1059.38	12896
1061.63	13064
1063.87	12932
1066.12	13086
1068.36	12994
1070.6	12870
1072.85	12740
1075.09	12834
1077.33	12900
1079.57	12920
1081.81	12890
1084.05	12836
1086.28	12772
1088.52	12782
1090.76	12702
1092.99	12656
1095.23	12856
1097.46	12734
1099.69	12746
1101.93	12592
1104.16	12668
1106.39	12590
1108.62	12468
1110.85	12542
1113.08	12556
1115.31	12500
1117.53	12666
1119.76	12496
1121.99	12658
1124.21	12632
1126.44	12608
1128.66	12542
1130.88	12608
1133.11	12668
1135.33	12598
1137.55	12714
1139.77	12682
1141.99	12648
1144.21	12620
1146.43	12776
1148.64	12810
1150.86	12624
1153.08	12722
1155.29	12844
1157.51	12746
1159.72	12778
1161.93	12938
1164.14	12860
1166.36	12796
1168.57	12710
1170.78	12888
1172.99	12884
1175.2	12714
1177.4	12692
1179.61	12840
1181.82	12674
1184.02	12810
1186.23	12748
1188.43	12594
1190.64	12722
1192.84	12562
1195.04	12636
1197.24	12518
1199.45	12670.1
1201.64	12646.9
1203.84	12479.3
1206.04	12364.6
1208.24	12430.6
1210.44	12274.7
1212.64	12167.1
1214.83	12212.2
1217.03	12183.4
1219.22	12040.4
1221.41	12086.8
1223.61	12027.5
1225.8	11979.9
1227.99	11878.8
1230.18	11928.6
1232.37	11882.7
1234.56	11893.7
1236.75	11800.4
1238.94	11787.3
1241.13	11693.5
1243.31	11751.8
1245.5	11667.7
1247.68	11632.5
1249.87	11656.8
1252.05	11518.3
1254.24	11518.3
1256.42	11564.3
1258.6	11534.8
1260.78	11537.9
1262.96	11540.4
1265.14	11556.3
1267.32	11471.5
1269.5	11372.4
1271.67	11401.3
1273.85	11378
1276.03	11330.7
1278.2	11211.5
1280.38	11301.2
1282.55	11252.9
1284.72	11225.2
1286.9	11173.3
1289.07	11168
1291.24	11063
1293.41	11167.7
1295.58	11049.5
1297.75	11084.9
1299.92	10979.6
1302.09	10964.2
1304.25	10879.9
1306.42	10867.1
1308.46	10830
1310.63	10794
1312.81	10706
1314.98	10800
1317.16	10786
1319.33	10748
1321.5	10830
1323.67	10820
1325.85	10584
1328.02	10764
1330.19	10840
1332.35	10850
1334.52	10822
1336.69	10674
1338.86	10676
1341.02	10866
1343.19	10686
1345.35	10700
1347.52	10752
1349.68	10642
1351.84	10652
1354	10568
1356.17	10674
1358.33	10666
1360.49	10688
1362.65	10712
1364.8	10610
1366.96	10614
1369.12	10496
1371.28	10670
1373.43	10642
1375.59	10644
1377.74	10502
1379.89	10478
1382.05	10664
1384.2	10580
1386.35	10592
1388.5	10642
1390.65	10708
1392.8	10502
1394.95	10566
1397.1	10592
1399.25	10530
1401.4	10570
1403.54	10580
1405.69	10644
1407.83	10434
1409.98	10524
1412.12	10418
1414.26	10442
1416.4	10464
1418.55	10434
1420.69	10380
1422.83	10508
1424.97	10444
1427.1	10362
1429.24	10456
1431.38	10384
1433.52	10512
1435.65	10472
1437.79	10354
1439.92	10264
1442.06	10426
1444.19	10568
1446.32	10428
1448.46	10422
1450.59	10462
1452.72	10368
1454.85	10440
1456.98	10480
1459.11	10382
1461.23	10344
1463.36	10390
1465.49	10452
1467.61	10362
1469.74	10400
1471.86	10384
1473.99	10416
1476.11	10490
1478.23	10322
1480.36	10366
1482.48	10376
1484.6	10268
1486.72	10400
1488.84	10302
1490.96	10408
1493.07	10366
1495.19	10224
1497.31	10234
1499.42	10456
1501.54	10282
1503.65	10344
1505.77	10290
1507.88	10322
1509.99	10228
1512.1	10306
1514.22	10336
1516.33	10118
1518.44	10214
1520.55	10254
1522.65	10122
1524.76	10156
1526.87	10168
1528.98	10040
1531.08	10230
1533.19	10076
1535.29	10002
1537.4	10024
1539.5	10104
1541.6	10076
1543.7	9888
1545.8	9936
1547.91	9932
1550.01	9918
1552.11	9908
1554.2	9938
1556.3	10000
1558.4	9894
1560.5	9832
1562.59	9738
1564.69	9792
1566.78	9724
1568.88	9806
1570.97	9836
1573.06	9716
1575.15	9758
1577.25	9852
1579.34	9744
1581.43	9780
1583.52	9902
1585.6	9862
1587.69	9762
1589.78	9756
1591.87	9874
1593.95	9686
1596.04	9828
1598.12	9772
1600.21	9826
1602.29	9794
1604.37	9782
1606.46	9894
1608.54	9874
1610.62	9768
1612.7	9732
1614.78	9698
1616.86	9828
1618.94	9892
1621.01	9768
1623.09	9826
1625.17	9744
1627.24	9838
1629.32	9770
1631.39	9786
1633.47	9892
1635.54	9548
1637.61	9696
1639.68	9680
1641.76	9622
1643.83	9772
1645.9	9632
1647.96	9656
1650.03	9612
1652.1	9598
1654.17	9620
1656.24	9614
1658.3	9542
1660.37	9510
1662.43	9452
1664.5	9562
1666.56	9536
1668.62	9516
1670.68	9372
1672.75	9458
1674.81	9484
1676.87	9410
1678.93	9352
1680.99	9368
1683.04	9320
1685.1	9384
1687.16	9310
1689.21	9272
1691.27	9348
1693.33	9212
1695.38	9246
1697.43	9122
1699.49	9102
1701.54	9216
1703.59	9182
1705.64	9242
1707.69	9178
1709.74	9146
1711.79	9166
1713.84	9180
1715.89	8990
1717.94	9092
1719.98	9008
1722.03	9014
1724.07	8940
1726.12	9024
1728.16	8994
1730.21	9156
1732.25	9060
1734.29	9058
1736.33	8906
1738.37	9068
1740.41	8978
1742.45	9068
1744.49	8854
1746.53	8900
1748.57	8776
1750.61	8950
1752.64	8872
1754.68	8970
1756.71	8914
1758.75	8902
1760.78	8772
1762.82	8976
1764.85	8936
1766.88	8918
1768.91	8926
1770.94	8800
1772.97	8874
1775	8746
1777.03	8766
1779.06	8836
1781.09	8792
1783.12	8794
1785.14	8886
1787.17	8680
1789.19	8818
1791.22	8760
1793.24	8786
1795.27	8730
1797.29	8708
1799.31	8642
1801.33	8692
1803.35	8664
1805.37	8684
1807.39	8662
1809.41	8588
1811.43	8630
1813.45	8714
1815.46	8568
1817.48	8548
1819.5	8450
1821.51	8598
1823.53	8464
1825.54	8472
1827.55	8504
1829.57	8500
1831.58	8402
1833.59	8432
1835.6	8312
1837.61	8334
1839.62	8332
1841.63	8324
1843.64	8332
1845.65	8290
1847.65	8156
1849.66	8222
1851.66	8244
1853.67	8256
1855.67	8240
1857.68	8162
1859.68	8186
1861.68	8098
1863.69	8188
1865.69	8122
1867.69	8108
1869.69	8080
1871.69	8232
1873.69	8116
1875.69	8068
1877.68	8024
1879.68	8022
1881.68	7928
1883.67	7990
1885.67	7910
1887.66	7952
1889.66	8024
1891.65	7976
1893.64	7818
1895.64	7846
1897.63	7870
1899.62	7916
1901.61	7928
1903.6	7950
1905.59	7882
1907.58	7878
1909.56	7826
1911.55	7934
1913.54	7766
1915.53	7840
1917.51	7918
1919.5	7836
1921.48	7778
1923.46	7760
1925.45	7698
1927.43	7864
1929.41	7826
1931.39	7760
1933.37	7684
1935.35	7648
1937.33	7778
1939.31	7632
1941.29	7624
1943.27	7650
1945.24	7604
1947.22	7606
1949.2	7612
1951.17	7526
1953.14	7564
1955.12	7546
1957.09	7536
1959.06	7528
1961.04	7458
1963.01	7400
1964.98	7508
1966.95	7484
1968.92	7514
1970.89	7446
1972.86	7404
1974.82	7328
1976.79	7380
1978.76	7438
1980.72	7426
1982.69	7330
1984.65	7340
1986.62	7382
1988.58	7276
1990.54	7408
1992.51	7212
1994.47	7242
1996.43	7210
1998.39	7190
1999.37	7222