File: 1/Organic_09.txt
#Acq. time (s)=	10
#Accumulations=	1
#Range (cm-¹)=	100...2000
#Windows=	2
#Autofocus=	Off
#AutoExposure=	Off
#Spike filter=	Off
#Delay time (s)=	0
#Binning=	1
#Readout mode=	Signal
#DeNoise=	Off
#ICS correction=	Off
#Dark correction=	Off
#Inst. Process=	Off
#Instrument=	LabRAM HR Evol
#Detector=	Syncerity OE
#Objective=	x100_VIS
#Grating=	600 (500nm)
#ND Filter=	5%
#Laser=	633nm_Edge
#Hole=	24.99
#Range=	Visible
#Project=	Omar
#Sample=	20-06-23
#Site=	1
#Title=	Organic
#Remark=
#Date=	20.06.2023 11:33
#Acquired=	20.06.2023 11:33:32
101.054	2088
103.621	2154
106.187	2066
108.752	2078
111.317	2038
113.881	2044
116.443	2076
119.005	2122
121.566	2136
124.126	2170
126.685	2072
129.243	2070
131.801	2164
134.356	2198
136.911	2176
139.466	2172
142.021	2170
144.574	2104
147.125	2142
149.676	2180
152.227	2180
154.776	2196
157.325	2270
159.873	2218
162.419	2220
164.966	2260
167.51	2232
170.055	2202
172.598	2186
175.141	2272
177.682	2242
180.222	2248
182.763	2224
185.302	2204
187.839	2182
190.376	2230
192.914	2292
195.449	2320
197.983	2326
200.517	2372
203.05	2294
205.582	2372
208.113	2332
210.643	2376
213.173	2360
215.701	2362
218.229	2326
220.756	2370
223.282	2396
225.808	2378
228.331	2408
230.855	2446
233.378	2434
235.898	2422
238.419	2472
240.94	2514
243.458	2454
245.977	2436
248.495	2526
251.011	2474
253.527	2444
256.041	2476
258.555	2532
261.068	2428
263.58	2510
266.092	2450
268.603	2500
271.112	2500
273.62	2436
276.129	2528
278.636	2540
281.142	2496
283.647	2450
286.152	2512
288.655	2564
291.158	2482
293.66	2586
296.161	2578
298.661	2578
301.161	2558
303.66	2602
306.158	2630
308.655	2608
311.15	2566
313.645	2616
316.14	2632
318.634	2622
321.125	2662
323.618	2542
326.109	2662
328.598	2616
331.088	2670
333.576	2690
336.064	2678
338.55	2618
341.037	2754
343.521	2640
346.005	2718
348.489	2616
350.971	2656
353.453	2682
355.933	2732
358.414	2698
360.893	2748
363.371	2696
365.848	2692
368.325	2664
370.801	2722
373.275	2686
375.75	2756
378.223	2680
380.695	2640
383.167	2764
385.638	2728
388.108	2718
390.577	2714
393.044	2762
395.512	2724
397.979	2708
400.444	2696
402.909	2774
405.374	2800
407.836	2834
410.299	2810
412.76	2762
415.221	2830
417.681	2884
420.141	2872
422.598	2886
425.057	2866
427.513	2874
429.968	2966
432.422	2848
434.878	2864
437.33	2904
439.783	2920
442.234	2830
444.685	2876
447.134	2882
449.583	2906
452.032	2858
454.479	2852
456.926	2926
459.372	2874
461.817	2870
464.261	2930
466.705	2836
469.147	2910
471.588	2896
474.029	2864
476.47	2872
478.909	2926
481.347	2950
483.785	2890
486.221	2992
488.657	2924
491.092	2894
493.527	2966
495.96	2938
498.393	2978
500.824	3012
503.255	3010
505.686	3012
508.115	2982
510.543	3040
512.972	2942
515.399	2972
517.825	2996
520.25	3028
522.674	2954
525.097	3040
527.52	2908
529.942	2978
532.364	2962
534.784	2926
537.204	2956
539.623	2978
542.041	2938
544.457	2884
546.874	2992
549.289	2948
551.705	3040
554.118	3020
556.531	2998
558.943	2936
561.355	2942
563.766	2908
566.175	2970
568.585	2912
570.992	2992
573.399	2968
575.807	3020
578.212	2944
580.617	2966
583.022	2966
585.425	2988
587.827	3000
590.229	2972
592.63	2898
595.03	2996
597.43	2968
599.829	3030
602.226	3052
604.623	3060
607.02	3066
609.414	3098
611.808	3092
614.202	2988
616.596	2998
618.988	3066
621.378	3060
623.769	3082
626.159	3120
628.548	3132
630.936	3040
633.324	3070
635.71	3136
638.096	3092
640.481	3050
642.866	3186
645.248	3186
647.63	3114
650.013	3102
652.394	3174
654.773	3172
657.154	3080
659.532	3230
661.91	3118
664.286	3214
666.663	3128
669.038	3178
671.412	3126
673.786	3132
676.159	3136
678.532	3114
680.903	3058
683.274	3144
685.644	3122
688.014	3112
690.381	3092
692.749	3130
695.116	3168
697.481	3062
699.846	3114
702.211	3112
704.574	3048
706.938	3134
709.299	3150
711.661	3108
714.021	3154
716.381	3096
718.739	3202
721.097	3084
723.455	3172
725.811	3156
728.167	3124
730.521	3132
732.875	3182
735.23	3134
737.582	3152
739.934	3176
742.285	3118
744.635	3190
746.985	3148
749.332	3128
751.68	3144
754.028	3156
756.374	3074
758.72	3126
761.065	3102
763.408	3120
765.752	3184
768.095	3146
770.436	3126
772.777	3144
775.116	3134
777.456	3232
779.794	3106
782.133	3128
784.469	3124
786.805	3158
789.141	3158
791.476	3162
793.809	3214
796.142	3144
798.476	3140
800.807	3134
803.138	3036
805.468	3112
807.797	3096
810.125	3196
812.453	3130
814.78	3186
817.106	3174
819.432	3164
821.757	3126
824.08	3190
826.403	3164
828.726	3176
831.048	3124
833.368	3196
835.688	3154
838.007	3222
840.326	3212
842.644	3182
844.96	3288
847.276	3186
849.592	3122
851.906	3276
854.221	3246
856.534	3154
858.846	3210
861.157	3214
863.469	3274
865.779	3178
868.088	3248
870.396	3220
872.704	3228
875.011	3212
877.318	3174
879.623	3184
881.928	3176
884.232	3220
886.536	3216
888.837	3160
891.139	3160
893.44	3180
895.741	3138
898.039	3152
900.339	3158
902.637	3134
904.933	3108
907.231	3168
909.526	3102
911.821	3116
914.115	3178
916.408	3138
918.701	3202
920.993	3088
923.283	3222
925.573	3134
927.864	3158
930.153	3196
932.441	3196
934.728	3130
937.014	3238
939.3	3136
941.585	3232
943.87	3162
946.154	3280
948.437	3202
950.719	3238
952.999	3156
955.28	3186
957.56	3216
959.84	3244
962.117	3204
964.395	3264
966.671	3108
968.948	3198
971.223	3202
973.498	3266
975.771	3214
978.045	3212
980.317	3256
982.588	3210
984.86	3160
987.13	3232
989.399	3210
991.667	3180
993.937	3242
996.204	3210
998.47	3194
1000.74	3230
1003	3188
1005.26	3210
1007.53	3260
1009.79	3208
1012.05	3194
1014.31	3194
1016.57	3134
1018.83	3222
1021.09	3190
1023.35	3180
1025.61	3202
1027.87	3220
1030.12	3234
1032.38	3154
1034.63	3210
1036.88	3232
1039.14	3274
1041.39	3262
1043.64	3282
1045.89	3150
1048.14	3302
1050.39	3300
1052.64	3254
1054.89	3272
1057.14	3286
1059.38	3230
1061.63	3326
1063.87	3270
1066.12	3238
1068.36	3240
1070.6	3258
1072.85	3248
1075.09	3232
1077.33	3150
1079.57	3270
1081.81	3206
1084.05	3302
1086.28	3184
1088.52	3178
1090.76	3236
1092.99	3164
1095.23	3200
1097.46	3240
1099.69	3202
1101.93	3208
1104.16	3246
1106.39	3080
1108.62	3156
1110.85	3078
1113.08	3218
1115.31	3174
1117.53	3132
1119.76	3174
1121.99	3152
1124.21	3184
1126.44	3170
1128.66	3206
1130.88	3210
1133.11	3222
1135.33	3160
1137.55	3138
1139.77	3130
1141.99	3114
1144.21	3194
1146.43	3198
1148.64	3230
1150.86	3148
1153.08	3188
1155.29	3206
1157.51	3114
1159.72	3168
1161.93	3174
1164.14	3170
1166.36	3142
1168.57	3214
1170.78	3146
1172.99	3192
1175.2	3264
1177.4	3154
1179.61	3214
1181.82	3208
1184.02	3144
1186.23	3158
1188.43	3192
1190.64	3136
1192.84	3180
1195.04	3090
1197.24	3158
1199.45	3168.52
1201.64	3166.3
1203.84	3117.17
1206.04	3129.47
1208.24	3123.19
1210.44	3166.38
1212.64	3097.88
1214.83	3140.33
1217.03	3128.07
1219.22	3106.93
1221.41	3115.84
1223.61	3131.02
1225.8	3083.31
1227.99	3089.85
1230.18	3112.93
1232.37	3095.41
1234.56	3094.51
1236.75	3114.2
1238.94	3127.93
1241.13	3157.13
1243.31	3139.58
1245.5	3157.97
1247.68	3140.91
1249.87	3130.66
1252.05	3114.45
1254.24	3112.24
1256.42	3192.3
1258.6	3165.68
1260.78	3167.21
1262.96	3167.37
1265.14	3153.71
1267.32	3130.79
1269.5	3143.04
1271.67	3145.38
1273.85	3171.42
1276.03	3196.7
1278.2	3173.62
1280.38	3199.89
1282.55	3152.98
1284.72	3166.22
1286.9	3145.68
1289.07	3175
1291.24	3146.32
1293.41	3240.3
1295.58	3179.09
1297.75	3204.12
1299.92	3172.43
1302.09	3173.43
1304.25	3186.01
1306.42	3201.28
1308.46	3156
1310.63	3156
1312.81	3166
1314.98	3194
1317.16	3170
1319.33	3154
1321.5	3170
1323.67	3170
1325.85	3154
1328.02	3214
1330.19	3124
1332.35	3092
1334.52	3218
1336.69	3136
1338.86	3184
1341.02	3126
1343.19	3176
1345.35	3174
1347.52	3158
1349.68	3182
1351.84	3234
1354	3106
1356.17	3148
1358.33	3162
1360.49	3108
1362.65	3146
1364.8	3086
1366.96	3168
1369.12	3118
1371.28	3132
1373.43	3172
1375.59	3148
1377.74	3122
1379.89	3064
1382.05	3146
1384.2	3100
1386.35	3134
1388.5	3164
1390.65	3086
1392.8	3186
1394.95	3078
1397.1	3146
1399.25	3070
1401.4	3174
1403.54	3066
1405.69	3094
1407.83	3142
1409.98	3076
1412.12	3120
1414.26	3154
1416.4	2992
1418.55	3108
1420.69	3116
1422.83	3034
1424.97	3128
1427.1	3028
1429.24	3098
1431.38	3038
1433.52	3022
1435.65	3018
1437.79	3028
1439.92	3040
1442.06	3070
1444.19	3058
1446.32	3094
1448.46	3058
1450.59	3106
1452.72	3076
1454.85	3072
1456.98	3028
1459.11	3032
1461.23	3086
1463.36	3038
1465.49	2990
1467.61	3074
1469.74	2988
1471.86	2994
1473.99	3074
1476.11	3014
1478.23	2972
1480.36	3018
1482.48	3066
1484.6	3020
1486.72	3038
1488.84	3044
1490.96	3068
1493.07	2998
1495.19	3012
1497.31	3044
1499.42	2982
1501.54	2994
1503.65	2986
1505.77	3042
1507.88	2984
1509.99	3000
1512.1	3000
1514.22	3044
1516.33	2948
1518.44	2972
1520.55	2944
1522.65	2940
1524.76	2990
1526.87	2950
1528.98	2944
1531.08	2892
1533.19	2944
1535.29	2994
1537.4	2974
1539.5	2862
1541.6	2872
1543.7	2910
1545.8	2898
1547.91	2890
1550.01	2870
1552.11	2934
1554.2	2880
1556.3	2868
1558.4	2886
1560.5	2834
1562.59	2814
1564.69	2828
1566.78	2828
1568.88	2852
1570.97	2904
1573.06	2864
1575.15	2858
1577.25	2830
1579.34	2790
1581.43	2850
1583.52	2858
1585.6	2914
1587.69	2866
1589.78	2940
1591.87	2868
1593.95	2812
1596.04	2850
1598.12	2890
1600.21	2876
1602.29	2874
1604.37	2862
1606.46	2780
1608.54	2894
1610.62	2890
1612.7	2810
1614.78	2824
1616.86	2872
1618.94	2818
1621.01	2858
1623.09	2790
1625.17	2752
1627.24	2846
1629.32	2830
1631.39	2862
1633.47	2792
1635.54	2872
1637.61	2782
1639.68	2802
1641.76	2812
1643.83	2758
1645.9	2832
1647.96	2830
1650.03	2822
1652.1	2864
1654.17	2832
1656.24	2784
1658.3	2794
1660.37	2766
1662.43	2810
1664.5	2808
1666.56	2766
1668.62	2786
1670.68	2844
1672.75	2786
1674.81	2700
1676.87	2772
1678.93	2744
1680.99	2732
1683.04	2740
1685.1	2730
1687.16	2710
1689.21	2698
1691.27	2698
1693.33	2696
1695.38	2744
1697.43	2692
1699.49	2688
1701.54	2666
1703.59	2746
1705.64	2670
1707.69	2632
1709.74	2666
1711.79	2666
1713.84	2668
1715.89	2692
1717.94	2698
1719.98	2690
1722.03	2608
1724.07	2612
1726.12	2600
1728.16	2652
1730.21	2658
1732.25	2608
1734.29	2660
1736.33	2648
1738.37	2628
1740.41	2608
1742.45	2622
1744.49	2628
1746.53	2638
1748.57	2548
1750.61	2618
1752.64	2610
1754.68	2622
1756.71	2608
1758.75	2608
1760.78	2636
1762.82	2628
1764.85	2618
1766.88	2594
1768.91	2544
1770.94	2576
1772.97	2582
1775	2534
1777.03	2602
1779.06	2546
1781.09	2566
1783.12	2570
1785.14	2558
1787.17	2552
1789.19	2546
1791.22	2558
1793.24	2476
1795.27	2486
1797.29	2556
1799.31	2488
1801.33	2572
1803.35	2552
1805.37	2546
1807.39	2502
1809.41	2524
1811.43	2494
1813.45	2528
1815.46	2524
1817.48	2486
1819.5	2510
1821.51	2502
1823.53	2496
1825.54	2516
1827.55	2462
1829.57	2486
1831.58	2466
1833.59	2392
1835.6	2442
1837.61	2484
1839.62	2458
1841.63	2434
1843.64	2390
1845.65	2380
1847.65	2446
1849.66	2384
1851.66	2448
1853.67	2416
1855.67	2406
1857.68	2462
1859.68	2424
1861.68	2402
1863.69	2364
1865.69	2396
1867.69	2358
1869.69	2354
1871.69	2374
1873.69	2326
1875.69	2316
1877.68	2360
1879.68	2318
1881.68	2404
1883.67	2384
1885.67	2356
1887.66	2304
1889.66	2326
1891.65	2382
1893.64	2366
1895.64	2304
1897.63	2346
1899.62	2348
1901.61	2304
1903.6	2304
1905.59	2362
1907.58	2322
1909.56	2272
1911.55	2366
1913.54	2376
1915.53	2314
1917.51	2328
1919.5	2300
1921.48	2282
1923.46	2238
1925.45	2344
1927.43	2290
1929.41	2232
1931.39	2296
1933.37	2318
1935.35	2246
1937.33	2320
1939.31	2266
1941.29	2236
1943.27	2228
1945.24	2248
1947.22	2280
1949.2	2266
1951.17	2250
1953.14	2191
1955.12	2198
1957.09	2252
1959.06	2236
1961.04	2228
1963.01	2210
1964.98	2246
1966.95	2176
1968.92	2234
1970.89	2168
1972.86	2224
1974.82	2140
1976.79	2170
1978.76	2154
1980.72	2200
1982.69	2192
1984.65	2186
1986.62	2224
1988.58	2188
1990.54	2164
1992.51	2098
1994.47	2142
1996.43	2138
1998.39	2090
1999.37	2212