File: 1/Organic_06.txt
#Acq. time (s)=	10
#Accumulations=	2
#Range (cm-¹)=	100...2000
#Windows=	2
#Autofocus=	Off
#AutoExposure=	Off
#Spike filter=	Multiple accum.
#Delay time (s)=	0
#Binning=	1
#Readout mode=	Signal
#DeNoise=	Off
#ICS correction=	Off
#Dark correction=	Off
#Inst. Process=	Off
#Instrument=	LabRAM HR Evol
#Detector=	Syncerity OE
#Objective=	x100_VIS
#Grating=	600 (500nm)
#ND Filter=	5%
#Laser=	633nm_Edge
#Hole=	49.98
#Range=	Visible
#Project=	Omar
#Sample=	20-06-23
#Site=	1
#Title=	Organic
#Remark=
#Date=	20.06.2023 11:29
#Acquired=	20.06.2023 11:29:51
101.054	46256
103.621	46496
106.187	46730
108.752	46662
111.317	46702
113.881	46862
116.443	47164
119.005	46930
121.566	47642
124.126	47766
126.685	47474
129.243	48308
131.801	48058
134.356	48168
136.911	48506
139.466	48344
142.021	48602
144.574	48406
147.125	48602
149.676	48952
152.227	49100
154.776	49368
157.325	49670
159.873	49686
162.419	49600
164.966	49866
167.51	49774
170.055	49732
172.598	49900
175.141	49990
177.682	49866
180.222	50130
182.763	50096
185.302	50636
187.839	50534
190.376	50682
192.914	51068
195.449	51094
197.983	51544
200.517	51644
203.05	51882
205.582	52096
208.113	52306
210.643	52522
213.173	52682
215.701	52836
218.229	52826
220.756	52716
223.282	53308
225.808	53158
228.331	53610
230.855	54176
233.378	54018
235.898	54278
238.419	54526
240.94	54588
243.458	55282
245.977	55196
248.495	55496
251.011	55250
253.527	55438
256.041	55320
258.555	55506
261.068	55228
263.58	55134
266.092	55480
268.603	55294
271.112	55242
273.62	55308
276.129	55584
278.636	55602
281.142	55568
283.647	55924
286.152	56318
288.655	56464
291.158	56894
293.66	57138
296.161	57306
298.661	57526
301.161	57706
303.66	57982
306.158	58120
308.655	58168
311.15	58484
313.645	58592
316.14	58620
318.634	58904
321.125	58802
323.618	58836
326.109	58956
328.598	58774
331.088	59142
333.576	58684
336.064	59326
338.55	59130
341.037	59490
343.521	59642
346.005	59820
348.489	59914
350.971	60088
353.453	60162
355.933	60214
358.414	60524
360.893	60424
363.371	60662
365.848	60578
368.325	60856
370.801	60642
373.275	60816
375.75	60468
378.223	60874
380.695	60600
383.167	60836
385.638	60606
388.108	60734
390.577	60842
393.044	60740
395.512	60948
397.979	61188
400.444	61424
402.909	61294
405.374	61734
407.836	62024
410.299	62316
412.76	62940
415.221	63072
417.681	63350
420.141	63514
422.598	63670
425.057	63954
427.513	64294
429.968	64508
432.422	64535
434.878	64535
437.33	64535
439.783	64535
442.234	64535
444.685	64535
447.134	64535
449.583	64535
452.032	64535
454.479	64535
456.926	64535
459.372	64535
461.817	64535
464.261	64535
466.705	64535
469.147	64535
471.588	64535
474.029	64535
476.47	64535
478.909	64535
481.347	64535
483.785	64535
486.221	64535
488.657	64535
491.092	64535
493.527	64535
495.96	64535
498.393	64535
500.824	64535
503.255	64535
505.686	64535
508.115	64535
510.543	64535
512.972	64535
515.399	64535
517.825	64535
520.25	64535
522.674	64535
525.097	64535
527.52	64535
529.942	64535
532.364	64535
534.784	64535
537.204	64535
539.623	64535
542.041	64535
544.457	64535
546.874	64535
549.289	64535
551.705	64535
554.118	64535
556.531	64535
558.943	64535
561.355	64535
563.766	64535
566.175	64535
568.585	64535
570.992	64535
573.399	64535
575.807	64535
578.212	64535
580.617	64535
583.022	64535
585.425	64535
587.827	64535
590.229	64535
592.63	64535
595.03	64535
597.43	64535
599.829	64535
602.226	64535
604.623	64535
607.02	64535
609.414	64535
611.808	64535
614.202	64535
616.596	64535
618.988	64535
621.378	64535
623.769	64535
626.159	64535
628.548	64535
630.936	64535
633.324	64535
635.71	64535
638.096	64535
640.481	64535
642.866	64535
645.248	64535
647.63	64535
650.013	64535
652.394	64535
654.773	64535
657.154	64535
659.532	64535
661.91	64535
664.286	64535
666.663	64535
669.038	64535
671.412	64535
673.786	64535
676.159	64535
678.532	64535
680.903	64535
683.274	64535
685.644	64535
688.014	64535
690.381	64535
692.749	64535
695.116	64535
697.481	64535
699.846	64535
702.211	64535
704.574	64535
706.938	64535
709.299	64535
711.661	64535
714.021	64535
716.381	64535
718.739	64535
721.097	64535
723.455	64535
725.811	64535
728.167	64535
730.521	64535
732.875	64535
735.23	64535
737.582	64535
739.934	64535
742.285	64535
744.635	64535
746.985	64535
749.332	64535
751.68	64535
754.028	64535
756.374	64535
758.72	64535
761.065	64535
763.408	64535
765.752	64535
768.095	64535
770.436	64535
772.777	64535
775.116	64535
777.456	64535
779.794	64535
782.133	64535
784.469	64535
786.805	64535
789.141	64535
791.476	64535
793.809	64535
796.142	64535
798.476	64535
800.807	64535
803.138	64535
805.468	64535
807.797	64535
810.125	64535
812.453	64535
814.78	64535
817.106	64535
819.432	64535
821.757	64535
824.08	64535
826.403	64535
828.726	64535
831.048	64535
833.368	64535
835.688	64535
838.007	64535
840.326	64535
842.644	64535
844.96	64535
847.276	64535
849.592	64535
851.906	64535
854.221	64535
856.534	64535
858.846	64535
861.157	64535
863.469	64535
865.779	64535
868.088	64535
870.396	64535
872.704	64535
875.011	64535
877.318	64535
879.623	64535
881.928	64535
884.232	64535
886.536	64535
888.837	64535
891.139	64535
893.44	64535
895.741	64535
898.039	64535
900.339	64535
902.637	64535
904.933	64535
907.231	64535
909.526	64535
911.821	64535
914.115	64535
916.408	64535
918.701	64535
920.993	64535
923.283	64535
925.573	64535
927.864	64535
930.153	64535
932.441	64535
934.728	64535
937.014	64535
939.3	64535
941.585	64535
943.87	64535
946.154	64535
948.437	64535
950.719	64535
952.999	64535
955.28	64535
957.56	64535
959.84	64535
962.117	64535
964.395	64535
966.671	64535
968.948	64535
971.223	64535
973.498	64535
975.771	64535
978.045	64535
980.317	64535
982.588	64535
984.86	64535
987.13	64535
989.399	64535
991.667	64535
993.937	64535
996.204	64535
998.47	64535
1000.74	64535
1003	64535
1005.26	64535
1007.53	64535
1009.79	64535
1012.05	64535
1014.31	64535
1016.57	64535
1018.83	64535
1021.09	64535
1023.35	64535
1025.61	64535
1027.87	64535
1030.12	64535
1032.38	64535
1034.63	64535
1036.88	64535
1039.14	64535
1041.39	64535
1043.64	64535
1045.89	64535
1048.14	64535
1050.39	64535
1052.64	64535
1054.89	64535
1057.14	64535
1059.38	64535
1061.63	64535
1063.87	64535
1066.12	64535
1068.36	64535
1070.6	64535
1072.85	64535
1075.09	64535
1077.33	64535
1079.57	64535
1081.81	64535
1084.05	64535
1086.28	64535
1088.52	64535
1090.76	64535
1092.99	64535
1095.23	64535
1097.46	64535
1099.69	64535
1101.93	64535
1104.16	64535
1106.39	64535
1108.62	64535
1110.85	64535
1113.08	64535
1115.31	64535
1117.53	64535
1119.76	64535
1121.99	64535
1124.21	64535
1126.44	64535
1128.66	64535
1130.88	64535
1133.11	64535
1135.33	64535
1137.55	64535
1139.77	64535
1141.99	64535
1144.21	64535
1146.43	64535
1148.64	64535
1150.86	64535
1153.08	64535
1155.29	64535
1157.51	64535
1159.72	64535
1161.93	64535
1164.14	64535
1166.36	64535
1168.57	64535
1170.78	64535
1172.99	64535
1175.2	64535
1177.4	64535
1179.61	64535
1181.82	64535
1184.02	64535
1186.23	64535
1188.43	64535
1190.64	64535
1192.84	64535
1195.04	64535
1197.24	64535
1199.45	64535
1201.64	64535
1203.84	64535
1206.04	64535
1208.24	64535
1210.44	64535
1212.64	64535
1214.83	64535
1217.03	64535
1219.22	64535
1221.41	64535
1223.61	64535
1225.8	64535
1227.99	64535
1230.18	64535
1232.37	64535
1234.56	64535
1236.75	64535
1238.94	64535
1241.13	64535
1243.31	64535
1245.5	64535
1247.68	64535
1249.87	64535
1252.05	64535
1254.24	64535
1256.42	64535
1258.6	64535
1260.78	64535
1262.96	64535
1265.14	64535
1267.32	64535
1269.5	64535
1271.67	64535
1273.85	64535
1276.03	64535
1278.2	64535
1280.38	64535
1282.55	64535
1284.72	64535
1286.9	64535
1289.07	64535
1291.24	64535
1293.41	64535
1295.58	64535
1297.75	64535
1299.92	64535
1302.09	64535
1304.25	64535
1306.42	64535
1308.46	64535
1310.63	64535
1312.81	64535
1314.98	64535
1317.16	64535
1319.33	64535
1321.5	64535
1323.67	64535
1325.85	64535
1328.02	64535
1330.19	64535
1332.35	64535
1334.52	64535
1336.69	64535
1338.86	64535
1341.02	64535
1343.19	64535
1345.35	64535
1347.52	64535
1349.68	64535
1351.84	64535
1354	64535
1356.17	64535
1358.33	64535
1360.49	64535
1362.65	64535
1364.8	64535
1366.96	64535
1369.12	64535
1371.28	64535
1373.43	64535
1375.59	64535
1377.74	64535
1379.89	64535
1382.05	64535
1384.2	64535
1386.35	64535
1388.5	64535
1390.65	64535
1392.8	64535
1394.95	64535
1397.1	64535
1399.25	64384
1401.4	64535
1403.54	64535
1405.69	64478
1407.83	64535
1409.98	64484
1412.12	64386
1414.26	64366
1416.4	64535
1418.55	64535
1420.69	63986
1422.83	64096
1424.97	64014
1427.1	64196
1429.24	64330
1431.38	63904
1433.52	64038
1435.65	63842
1437.79	64056
1439.92	64030
1442.06	63912
1444.19	63726
1446.32	63624
1448.46	64010
1450.59	63352
1452.72	63494
1454.85	63678
1456.98	63982
1459.11	63614
1461.23	63828
1463.36	63526
1465.49	63852
1467.61	63544
1469.74	63730
1471.86	63452
1473.99	63336
1476.11	63456
1478.23	63302
1480.36	63398
1482.48	63404
1484.6	63342
1486.72	63200
1488.84	63072
1490.96	63288
1493.07	63402
1495.19	63028
1497.31	63098
1499.42	63054
1501.54	62830
1503.65	62828
1505.77	62664
1507.88	62648
1509.99	62550
1512.1	62504
1514.22	62148
1516.33	61934
1518.44	62016
1520.55	61934
1522.65	61732
1524.76	62094
1526.87	61796
1528.98	61660
1531.08	61476
1533.19	61346
1535.29	61284
1537.4	61330
1539.5	60878
1541.6	60704
1543.7	60990
1545.8	60792
1547.91	60656
1550.01	60420
1552.11	60566
1554.2	60400
1556.3	60070
1558.4	60310
1560.5	60058
1562.59	59768
1564.69	60098
1566.78	59890
1568.88	60032
1570.97	60228
1573.06	59874
1575.15	59922
1577.25	60036
1579.34	59652
1581.43	59794
1583.52	59988
1585.6	59900
1587.69	59732
1589.78	59676
1591.87	59514
1593.95	59556
1596.04	59372
1598.12	59696
1600.21	59516
1602.29	59370
1604.37	59558
1606.46	59478
1608.54	59486
1610.62	59426
1612.7	59628
1614.78	59160
1616.86	59126
1618.94	59196
1621.01	59208
1623.09	59436
1625.17	59088
1627.24	58960
1629.32	58920
1631.39	59016
1633.47	58928
1635.54	58968
1637.61	58688
1639.68	58832
1641.76	58894
1643.83	58518
1645.9	58492
1647.96	58152
1650.03	58498
1652.1	58412
1654.17	58126
1656.24	58056
1658.3	57692
1660.37	57982
1662.43	57642
1664.5	57346
1666.56	57296
1668.62	57154
1670.68	57338
1672.75	57010
1674.81	56872
1676.87	57000
1678.93	56168
1680.99	57090
1683.04	56484
1685.1	56276
1687.16	55828
1689.21	55844
1691.27	56052
1693.33	55882
1695.38	55920
1697.43	55614
1699.49	55758
1701.54	55444
1703.59	55602
1705.64	55244
1707.69	54890
1709.74	54944
1711.79	55092
1713.84	54750
1715.89	54848
1717.94	54728
1719.98	54616
1722.03	54460
1724.07	54468
1726.12	54388
1728.16	54052
1730.21	53782
1732.25	54088
1734.29	54052
1736.33	53890
1738.37	54004
1740.41	53880
1742.45	53882
1744.49	53928
1746.53	53606
1748.57	53314
1750.61	53640
1752.64	53482
1754.68	53208
1756.71	53600
1758.75	53272
1760.78	53446
1762.82	53392
1764.85	53408
1766.88	53162
1768.91	53160
1770.94	52904
1772.97	53020
1775	53132
1777.03	52696
1779.06	52738
1781.09	52810
1783.12	52570
1785.14	52458
1787.17	52758
1789.19	52322
1791.22	52486
1793.24	52426
1795.27	52454
1797.29	52108
1799.31	52034
1801.33	52026
1803.35	51840
1805.37	51816
1807.39	51678
1809.41	51666
1811.43	51650
1813.45	51442
1815.46	51532
1817.48	51502
1819.5	50906
1821.51	51308
1823.53	50990
1825.54	50758
1827.55	50646
1829.57	50470
1831.58	50258
1833.59	50176
1835.6	50190
1837.61	49992
1839.62	50332
1841.63	50258
1843.64	49632
1845.65	49428
1847.65	49456
1849.66	49428
1851.66	49156
1853.67	49412
1855.67	49016
1857.68	48942
1859.68	48672
1861.68	48956
1863.69	48572
1865.69	48710
1867.69	48574
1869.69	48108
1871.69	48566
1873.69	48216
1875.69	48460
1877.68	47780
1879.68	48218
1881.68	47980
1883.67	47608
1885.67	47838
1887.66	47744
1889.66	47616
1891.65	47634
1893.64	47636
1895.64	47498
1897.63	47556
1899.62	47448
1901.61	47396
1903.6	47334
1905.59	47654
1907.58	47430
1909.56	47256
1911.55	47256
1913.54	46690
1915.53	46980
1917.51	46842
1919.5	47004
1921.48	46778
1923.46	46768
1925.45	46484
1927.43	46468
1929.41	46464
1931.39	46064
1933.37	46416
1935.35	46164
1937.33	46294
1939.31	46012
1941.29	45850
1943.27	45942
1945.24	45808
1947.22	46020
1949.2	45622
1951.17	45438
1953.14	45395
1955.12	45058
1957.09	45416
1959.06	44822
1961.04	45054
1963.01	44692
1964.98	44902
1966.95	44768
1968.92	44390
1970.89	44414
1972.86	44604
1974.82	44700
1976.79	44426
1978.76	44168
1980.72	44090
1982.69	44032
1984.65	44050
1986.62	43710
1988.58	43908
1990.54	43542
1992.51	43496
1994.47	43180
1996.43	43380
1998.39	43434
1999.37	43336