File: 1/Organic_13.txt
#Acq. time (s)=	10
#Accumulations=	1
#Range (cm-¹)=	100...2000
#Windows=	2
#Autofocus=	Off
#AutoExposure=	Off
#Spike filter=	Off
#Delay time (s)=	0
#Binning=	1
#Readout mode=	Signal
#DeNoise=	Off
#ICS correction=	Off
#Dark correction=	Off
#Inst. Process=	Off
#Instrument=	LabRAM HR Evol
#Detector=	Syncerity OE
#Objective=	x100_VIS
#Grating=	600 (500nm)
#ND Filter=	5%
#Laser=	633nm_Edge
#Hole=	24.99
#Range=	Visible
#Project=	Omar
#Sample=	20-06-23
#Site=	1
#Title=	Organic
#Remark=
#Date=	20.06.2023 11:43
#Acquired=	20.06.2023 11:43:20
101.054	4766
103.621	4774
106.187	4752
108.752	4728
111.317	4728
113.881	4760
116.443	4814
119.005	4740
121.566	4840
124.126	4812
126.685	4934
129.243	4938
131.801	4858
134.356	4876
136.911	4872
139.466	4872
142.021	4964
144.574	4916
147.125	4968
149.676	4986
152.227	5046
154.776	4994
157.325	4964
159.873	5054
162.419	5010
164.966	5038
167.51	5072
170.055	5022
172.598	5092
175.141	5110
177.682	5044
180.222	5028
182.763	5016
185.302	5118
187.839	5110
190.376	5136
192.914	5180
195.449	5166
197.983	5152
200.517	5234
203.05	5250
205.582	5326
208.113	5272
210.643	5336
213.173	5202
215.701	5394
218.229	5392
220.756	5366
223.282	5420
225.808	5378
228.331	5428
230.855	5386
233.378	5488
235.898	5472
238.419	5526
240.94	5534
243.458	5610
245.977	5598
248.495	5564
251.011	5608
253.527	5580
256.041	5580
258.555	5648
261.068	5604
263.58	5610
266.092	5632
268.603	5602
271.112	5632
273.62	5550
276.129	5580
278.636	5590
281.142	5668
283.647	5594
286.152	5778
288.655	5666
291.158	5710
293.66	5776
296.161	5796
298.661	5854
301.161	5926
303.66	5966
306.158	5998
308.655	5912
311.15	5920
313.645	5878
316.14	5952
318.634	5936
321.125	6096
323.618	5974
326.109	5946
328.598	5902
331.088	6058
333.576	5918
336.064	5984
338.55	6018
341.037	6048
343.521	6092
346.005	6056
348.489	6078
350.971	6088
353.453	6128
355.933	6178
358.414	6170
360.893	6146
363.371	6172
365.848	6198
368.325	6204
370.801	6216
373.275	6148
375.75	6214
378.223	6122
380.695	6156
383.167	6118
385.638	6228
388.108	6216
390.577	6178
393.044	6186
395.512	6324
397.979	6242
400.444	6244
402.909	6314
405.374	6314
407.836	6290
410.299	6304
412.76	6372
415.221	6350
417.681	6478
420.141	6532
422.598	6450
425.057	6496
427.513	6526
429.968	6722
432.422	6538
434.878	6654
437.33	6634
439.783	6742
442.234	6586
444.685	6658
447.134	6608
449.583	6582
452.032	6632
454.479	6652
456.926	6576
459.372	6608
461.817	6612
464.261	6604
466.705	6524
469.147	6656
471.588	6678
474.029	6710
476.47	6666
478.909	6692
481.347	6734
483.785	6826
486.221	6754
488.657	6766
491.092	6764
493.527	6770
495.96	6780
498.393	6800
500.824	6788
503.255	6964
505.686	6832
508.115	6908
510.543	6796
512.972	6848
515.399	6842
517.825	6892
520.25	6780
522.674	6948
525.097	6874
527.52	6918
529.942	6790
532.364	6900
534.784	6840
537.204	6798
539.623	6822
542.041	6858
544.457	6892
546.874	6788
549.289	6868
551.705	6834
554.118	6812
556.531	6972
558.943	6922
561.355	6958
563.766	6838
566.175	6950
568.585	6800
570.992	6910
573.399	6928
575.807	6854
578.212	6964
580.617	6930
583.022	7026
585.425	6906
587.827	7046
590.229	6924
592.63	6930
595.03	7026
597.43	7006
599.829	6990
602.226	7050
604.623	6996
607.02	7066
609.414	7008
611.808	7176
614.202	7174
616.596	7052
618.988	7176
621.378	7138
623.769	7180
626.159	7208
628.548	7308
630.936	7270
633.324	7302
635.71	7290
638.096	7194
640.481	7276
642.866	7308
645.248	7334
647.63	7422
650.013	7312
652.394	7324
654.773	7304
657.154	7326
659.532	7410
661.91	7314
664.286	7318
666.663	7310
669.038	7334
671.412	7310
673.786	7266
676.159	7356
678.532	7302
680.903	7286
683.274	7268
685.644	7296
688.014	7444
690.381	7444
692.749	7332
695.116	7342
697.481	7390
699.846	7310
702.211	7350
704.574	7396
706.938	7466
709.299	7370
711.661	7474
714.021	7400
716.381	7436
718.739	7422
721.097	7428
723.455	7442
725.811	7352
728.167	7368
730.521	7402
732.875	7406
735.23	7374
737.582	7394
739.934	7510
742.285	7518
744.635	7528
746.985	7340
749.332	7456
751.68	7348
754.028	7524
756.374	7470
758.72	7426
761.065	7416
763.408	7372
765.752	7412
768.095	7476
770.436	7332
772.777	7384
775.116	7440
777.456	7428
779.794	7436
782.133	7462
784.469	7408
786.805	7378
789.141	7414
791.476	7490
793.809	7508
796.142	7488
798.476	7506
800.807	7460
803.138	7482
805.468	7456
807.797	7516
810.125	7470
812.453	7452
814.78	7532
817.106	7572
819.432	7500
821.757	7538
824.08	7512
826.403	7636
828.726	7666
831.048	7642
833.368	7404
835.688	7600
838.007	7596
840.326	7710
842.644	7664
844.96	7700
847.276	7670
849.592	7824
851.906	7600
854.221	7646
856.534	7754
858.846	7630
861.157	7766
863.469	7696
865.779	7696
868.088	7716
870.396	7798
872.704	7850
875.011	7692
877.318	7730
879.623	7652
881.928	7614
884.232	7672
886.536	7596
888.837	7454
891.139	7548
893.44	7702
895.741	7772
898.039	7600
900.339	7642
902.637	7632
904.933	7558
907.231	7666
909.526	7704
911.821	7638
914.115	7580
916.408	7638
918.701	7610
920.993	7502
923.283	7572
925.573	7600
927.864	7524
930.153	7578
932.441	7554
934.728	7666
937.014	7710
939.3	7640
941.585	7668
943.87	7634
946.154	7578
948.437	7664
950.719	7756
952.999	7684
955.28	7726
957.56	7782
959.84	7716
962.117	7750
964.395	7814
966.671	7740
968.948	7756
971.223	7778
973.498	7724
975.771	7694
978.045	7782
980.317	7890
982.588	7700
984.86	7646
987.13	7736
989.399	7712
991.667	7734
993.937	7656
996.204	7740
998.47	7720
1000.74	7732
1003	7684
1005.26	7788
1007.53	7678
1009.79	7750
1012.05	7632
1014.31	7770
1016.57	7856
1018.83	7770
1021.09	7758
1023.35	7812
1025.61	7714
1027.87	7820
1030.12	7834
1032.38	7776
1034.63	7856
1036.88	7876
1039.14	7772
1041.39	7842
1043.64	7930
1045.89	7966
1048.14	7930
1050.39	7934
1052.64	7872
1054.89	7890
1057.14	8086
1059.38	7908
1061.63	7946
1063.87	7980
1066.12	7974
1068.36	8014
1070.6	8030
1072.85	7934
1075.09	7958
1077.33	7872
1079.57	7856
1081.81	7870
1084.05	7826
1086.28	7892
1088.52	7812
1090.76	7772
1092.99	7816
1095.23	7836
1097.46	7694
1099.69	7756
1101.93	7802
1104.16	7824
1106.39	7796
1108.62	7616
1110.85	7814
1113.08	7740
1115.31	7726
1117.53	7766
1119.76	7740
1121.99	7634
1124.21	7724
1126.44	7728
1128.66	7670
1130.88	7810
1133.11	7716
1135.33	7714
1137.55	7840
1139.77	7762
1141.99	7688
1144.21	7736
1146.43	7780
1148.64	7770
1150.86	7810
1153.08	7858
1155.29	7824
1157.51	7822
1159.72	7938
1161.93	7916
1164.14	7836
1166.36	7852
1168.57	7878
1170.78	7974
1172.99	7872
1175.2	7880
1177.4	7820
1179.61	7856
1181.82	7920
1184.02	7832
1186.23	7828
1188.43	7916
1190.64	7788
1192.84	7808
1195.04	7722
1197.24	7850
1199.45	7830.32
1201.64	7677.77
1203.84	7674.31
1206.04	7773.6
1208.24	7763.25
1210.44	7619.62
1212.64	7690.81
1214.83	7656.31
1217.03	7653.26
1219.22	7697.97
1221.41	7707.85
1223.61	7607.16
1225.8	7717.18
1227.99	7576.39
1230.18	7616.85
1232.37	7616.83
1234.56	7611.75
1236.75	7641.55
1238.94	7580.23
1241.13	7610.53
1243.31	7658.66
1245.5	7604.58
1247.68	7581.85
1249.87	7565.87
1252.05	7600.86
1254.24	7607.77
1256.42	7610.58
1258.6	7637.13
1260.78	7610.81
1262.96	7627.06
1265.14	7620.59
1267.32	7647.18
1269.5	7661.32
1271.67	7573.9
1273.85	7655.62
1276.03	7582.87
1278.2	7632.47
1280.38	7563.55
1282.55	7697.87
1284.72	7644.36
1286.9	7554.22
1289.07	7664.57
1291.24	7628.48
1293.41	7598.8
1295.58	7539.82
1297.75	7606.94
1299.92	7509.78
1302.09	7579.12
1304.25	7595.36
1306.42	7639.07
1308.46	7532
1310.63	7564
1312.81	7522
1314.98	7548
1317.16	7532
1319.33	7512
1321.5	7644
1323.67	7488
1325.85	7588
1328.02	7578
1330.19	7498
1332.35	7432
1334.52	7624
1336.69	7554
1338.86	7480
1341.02	7414
1343.19	7458
1345.35	7424
1347.52	7658
1349.68	7480
1351.84	7542
1354	7486
1356.17	7446
1358.33	7458
1360.49	7414
1362.65	7488
1364.8	7522
1366.96	7430
1369.12	7444
1371.28	7492
1373.43	7424
1375.59	7470
1377.74	7504
1379.89	7410
1382.05	7408
1384.2	7380
1386.35	7522
1388.5	7496
1390.65	7486
1392.8	7412
1394.95	7410
1397.1	7454
1399.25	7424
1401.4	7488
1403.54	7428
1405.69	7446
1407.83	7454
1409.98	7518
1412.12	7412
1414.26	7510
1416.4	7384
1418.55	7478
1420.69	7468
1422.83	7406
1424.97	7458
1427.1	7412
1429.24	7384
1431.38	7360
1433.52	7412
1435.65	7370
1437.79	7378
1439.92	7316
1442.06	7354
1444.19	7350
1446.32	7484
1448.46	7430
1450.59	7378
1452.72	7328
1454.85	7390
1456.98	7476
1459.11	7364
1461.23	7364
1463.36	7342
1465.49	7268
1467.61	7372
1469.74	7484
1471.86	7366
1473.99	7480
1476.11	7406
1478.23	7322
1480.36	7328
1482.48	7336
1484.6	7338
1486.72	7308
1488.84	7404
1490.96	7366
1493.07	7258
1495.19	7318
1497.31	7354
1499.42	7392
1501.54	7318
1503.65	7278
1505.77	7346
1507.88	7358
1509.99	7330
1512.1	7302
1514.22	7334
1516.33	7240
1518.44	7290
1520.55	7194
1522.65	7236
1524.76	7214
1526.87	7216
1528.98	7244
1531.08	7264
1533.19	7058
1535.29	7182
1537.4	7264
1539.5	7040
1541.6	7076
1543.7	7162
1545.8	7118
1547.91	7018
1550.01	7162
1552.11	7028
1554.2	7012
1556.3	7046
1558.4	7014
1560.5	7018
1562.59	7034
1564.69	6976
1566.78	6980
1568.88	7022
1570.97	6910
1573.06	7176
1575.15	7010
1577.25	6992
1579.34	6980
1581.43	6920
1583.52	6994
1585.6	7102
1587.69	7012
1589.78	7094
1591.87	7032
1593.95	7058
1596.04	6970
1598.12	6990
1600.21	7064
1602.29	6984
1604.37	6992
1606.46	7036
1608.54	7014
1610.62	7158
1612.7	7038
1614.78	7176
1616.86	7084
1618.94	7056
1621.01	7068
1623.09	7094
1625.17	6954
1627.24	7096
1629.32	7182
1631.39	6978
1633.47	6994
1635.54	6962
1637.61	7020
1639.68	7012
1641.76	7054
1643.83	6960
1645.9	6922
1647.96	6924
1650.03	7128
1652.1	6898
1654.17	6968
1656.24	6998
1658.3	6960
1660.37	6744
1662.43	6974
1664.5	6860
1666.56	6860
1668.62	6838
1670.68	6946
1672.75	6898
1674.81	6940
1676.87	6870
1678.93	6806
1680.99	6912
1683.04	6804
1685.1	6738
1687.16	6748
1689.21	6790
1691.27	6888
1693.33	6756
1695.38	6776
1697.43	6716
1699.49	6728
1701.54	6656
1703.59	6634
1705.64	6716
1707.69	6632
1709.74	6658
1711.79	6674
1713.84	6652
1715.89	6614
1717.94	6604
1719.98	6624
1722.03	6500
1724.07	6622
1726.12	6554
1728.16	6678
1730.21	6538
1732.25	6598
1734.29	6444
1736.33	6524
1738.37	6480
1740.41	6520
1742.45	6520
1744.49	6440
1746.53	6586
1748.57	6468
1750.61	6554
1752.64	6570
1754.68	6496
1756.71	6600
1758.75	6486
1760.78	6470
1762.82	6552
1764.85	6458
1766.88	6498
1768.91	6498
1770.94	6510
1772.97	6478
1775	6434
1777.03	6458
1779.06	6446
1781.09	6438
1783.12	6490
1785.14	6440
1787.17	6506
1789.19	6572
1791.22	6514
1793.24	6364
1795.27	6456
1797.29	6414
1799.31	6290
1801.33	6446
1803.35	6432
1805.37	6378
1807.39	6406
1809.41	6368
1811.43	6430
1813.45	6360
1815.46	6330
1817.48	6288
1819.5	6332
1821.51	6264
1823.53	6370
1825.54	6228
1827.55	6344
1829.57	6290
1831.58	6204
1833.59	6276
1835.6	6296
1837.61	6200
1839.62	6238
1841.63	6048
1843.64	6142
1845.65	6202
1847.65	6104
1849.66	6108
1851.66	6146
1853.67	6080
1855.67	6140
1857.68	6030
1859.68	6160
1861.68	6118
1863.69	6200
1865.69	6076
1867.69	6134
1869.69	6010
1871.69	6026
1873.69	6050
1875.69	6010
1877.68	6020
1879.68	6024
1881.68	5996
1883.67	6052
1885.67	5842
1887.66	5922
1889.66	5976
1891.65	5870
1893.64	5988
1895.64	5942
1897.63	5934
1899.62	5900
1901.61	5832
1903.6	5838
1905.59	5972
1907.58	5878
1909.56	5758
1911.55	5916
1913.54	5822
1915.53	5886
1917.51	5854
1919.5	5932
1921.48	5832
1923.46	5762
1925.45	5904
1927.43	5806
1929.41	5884
1931.39	5848
1933.37	5758
1935.35	5756
1937.33	5824
1939.31	5816
1941.29	5794
1943.27	5750
1945.24	5768
1947.22	5766
1949.2	5762
1951.17	5732
1953.14	5667
1955.12	5666
1957.09	5648
1959.06	5634
1961.04	5678
1963.01	5648
1964.98	5564
1966.95	5714
1968.92	5690
1970.89	5642
1972.86	5598
1974.82	5630
1976.79	5622
1978.76	5604
1980.72	5588
1982.69	5518
1984.65	5554
1986.62	5596
1988.58	5530
1990.54	5500
1992.51	5532
1994.47	5570
1996.43	5544
1998.39	5530
1999.37	5552