File: 1/Organic_04.txt
#Acq. time (s)=	10
#Accumulations=	2
#Range (cm-¹)=	100...2000
#Windows=	2
#Autofocus=	Off
#AutoExposure=	Off
#Spike filter=	Multiple accum.
#Delay time (s)=	0
#Binning=	1
#Readout mode=	Signal
#DeNoise=	Off
#ICS correction=	Off
#Dark correction=	Off
#Inst. Process=	Off
#Instrument=	LabRAM HR Evol
#Detector=	Syncerity OE
#Objective=	x100_VIS
#Grating=	600 (500nm)
#ND Filter=	25%
#Laser=	633nm_Edge
#Hole=	24.99
#Range=	Visible
#Project=	Omar
#Sample=	20-06-23
#Site=	1
#Title=	Organic
#Remark=
#Date=	20.06.2023 11:23
#Acquired=	20.06.2023 11:23:42
101.054	1614
103.621	1598
106.187	1622
108.752	1672
111.317	1654
113.881	1620
116.443	1624
119.005	1618
121.566	1660
124.126	1636
126.685	1696
129.243	1708
131.801	1706
134.356	1772
136.911	1646
139.466	1694
142.021	1696
144.574	1660
147.125	1632
149.676	1676
152.227	1732
154.776	1702
157.325	1664
159.873	1710
162.419	1694
164.966	1710
167.51	1730
170.055	1712
172.598	1742
175.141	1670
177.682	1716
180.222	1700
182.763	1734
185.302	1730
187.839	1744
190.376	1784
192.914	1784
195.449	1790
197.983	1802
200.517	1766
203.05	1838
205.582	1786
208.113	1828
210.643	1768
213.173	1790
215.701	1822
218.229	1816
220.756	1878
223.282	1838
225.808	1888
228.331	1866
230.855	1880
233.378	1854
235.898	1894
238.419	1846
240.94	1850
243.458	1858
245.977	1894
248.495	1880
251.011	1844
253.527	1920
256.041	1912
258.555	1874
261.068	1926
263.58	1932
266.092	1892
268.603	1900
271.112	1884
273.62	1868
276.129	1838
278.636	1880
281.142	1902
283.647	1966
286.152	2000
288.655	1956
291.158	1968
293.66	1956
296.161	2002
298.661	1964
301.161	1968
303.66	2000
306.158	1950
308.655	1998
311.15	1942
313.645	2008
316.14	2020
318.634	2006
321.125	2010
323.618	2020
326.109	2010
328.598	2032
331.088	2010
333.576	2022
336.064	2072
338.55	2048
341.037	2050
343.521	2084
346.005	2012
348.489	2050
350.971	2010
353.453	2060
355.933	2076
358.414	2080
360.893	2126
363.371	2038
365.848	2062
368.325	2048
370.801	2038
373.275	2072
375.75	2074
378.223	2022
380.695	2116
383.167	2094
385.638	2064
388.108	2120
390.577	2074
393.044	2096
395.512	2132
397.979	2044
400.444	2130
402.909	2158
405.374	2116
407.836	2090
410.299	2168
412.76	2134
415.221	2166
417.681	2176
420.141	2176
422.598	2158
425.057	2246
427.513	2188
429.968	2166
432.422	2178
434.878	2224
437.33	2238
439.783	2256
442.234	2248
444.685	2224
447.134	2196
449.583	2186
452.032	2196
454.479	2240
456.926	2150
459.372	2138
461.817	2180
464.261	2230
466.705	2284
469.147	2174
471.588	2202
474.029	2200
476.47	2202
478.909	2230
481.347	2268
483.785	2186
486.221	2216
488.657	2212
491.092	2258
493.527	2224
495.96	2254
498.393	2232
500.824	2306
503.255	2258
505.686	2252
508.115	2248
510.543	2274
512.972	2238
515.399	2258
517.825	2278
520.25	2290
522.674	2248
525.097	2240
527.52	2268
529.942	2314
532.364	2250
534.784	2226
537.204	2222
539.623	2286
542.041	2252
544.457	2216
546.874	2318
549.289	2276
551.705	2294
554.118	2248
556.531	2260
558.943	2234
561.355	2290
563.766	2246
566.175	2320
568.585	2262
570.992	2238
573.399	2304
575.807	2202
578.212	2250
580.617	2274
583.022	2266
585.425	2286
587.827	2314
590.229	2258
592.63	2250
595.03	2274
597.43	2344
599.829	2280
602.226	2302
604.623	2300
607.02	2312
609.414	2360
611.808	2336
614.202	2326
616.596	2316
618.988	2304
621.378	2358
623.769	2410
626.159	2378
628.548	2370
630.936	2340
633.324	2394
635.71	2390
638.096	2340
640.481	2366
642.866	2418
645.248	2390
647.63	2424
650.013	2448
652.394	2364
654.773	2386
657.154	2362
659.532	2342
661.91	2372
664.286	2446
666.663	2382
669.038	2386
671.412	2374
673.786	2382
676.159	2366
678.532	2422
680.903	2402
683.274	2360
685.644	2328
688.014	2310
690.381	2352
692.749	2386
695.116	2340
697.481	2332
699.846	2348
702.211	2386
704.574	2356
706.938	2404
709.299	2328
711.661	2324
714.021	2372
716.381	2434
718.739	2440
721.097	2478
723.455	2392
725.811	2424
728.167	2362
730.521	2362
732.875	2452
735.23	2364
737.582	2434
739.934	2390
742.285	2416
744.635	2400
746.985	2396
749.332	2470
751.68	2404
754.028	2350
756.374	2456
758.72	2410
761.065	2432
763.408	2404
765.752	2412
768.095	2364
770.436	2362
772.777	2372
775.116	2354
777.456	2390
779.794	2416
782.133	2326
784.469	2404
786.805	2356
789.141	2354
791.476	2384
793.809	2396
796.142	2304
798.476	2332
800.807	2382
803.138	2364
805.468	2396
807.797	2384
810.125	2352
812.453	2396
814.78	2414
817.106	2416
819.432	2422
821.757	2340
824.08	2410
826.403	2352
828.726	2388
831.048	2438
833.368	2396
835.688	2428
838.007	2404
840.326	2390
842.644	2428
844.96	2364
847.276	2442
849.592	2420
851.906	2422
854.221	2418
856.534	2434
858.846	2362
861.157	2464
863.469	2430
865.779	2380
868.088	2468
870.396	2480
872.704	2422
875.011	2412
877.318	2444
879.623	2420
881.928	2386
884.232	2418
886.536	2394
888.837	2436
891.139	2368
893.44	2368
895.741	2436
898.039	2384
900.339	2418
902.637	2440
904.933	2420
907.231	2386
909.526	2408
911.821	2388
914.115	2358
916.408	2360
918.701	2372
920.993	2376
923.283	2428
925.573	2406
927.864	2330
930.153	2346
932.441	2440
934.728	2402
937.014	2422
939.3	2300
941.585	2342
943.87	2362
946.154	2444
948.437	2356
950.719	2404
952.999	2454
955.28	2402
957.56	2434
959.84	2410
962.117	2342
964.395	2414
966.671	2394
968.948	2426
971.223	2406
973.498	2424
975.771	2366
978.045	2438
980.317	2444
982.588	2396
984.86	2434
987.13	2344
989.399	2362
991.667	2386
993.937	2426
996.204	2370
998.47	2356
1000.74	2352
1003	2378
1005.26	2374
1007.53	2370
1009.79	2362
1012.05	2394
1014.31	2364
1016.57	2412
1018.83	2396
1021.09	2388
1023.35	2396
1025.61	2390
1027.87	2374
1030.12	2404
1032.38	2416
1034.63	2378
1036.88	2410
1039.14	2372
1041.39	2428
1043.64	2460
1045.89	2378
1048.14	2326
1050.39	2412
1052.64	2378
1054.89	2434
1057.14	2358
1059.38	2456
1061.63	2380
1063.87	2468
1066.12	2428
1068.36	2412
1070.6	2406
1072.85	2416
1075.09	2346
1077.33	2438
1079.57	2466
1081.81	2406
1084.05	2378
1086.28	2374
1088.52	2354
1090.76	2354
1092.99	2380
1095.23	2326
1097.46	2364
1099.69	2336
1101.93	2376
1104.16	2340
1106.39	2382
1108.62	2364
1110.85	2348
1113.08	2354
1115.31	2346
1117.53	2330
1119.76	2356
1121.99	2368
1124.21	2324
1126.44	2344
1128.66	2370
1130.88	2332
1133.11	2386
1135.33	2416
1137.55	2336
1139.77	2296
1141.99	2380
1144.21	2404
1146.43	2304
1148.64	2322
1150.86	2404
1153.08	2338
1155.29	2404
1157.51	2394
1159.72	2422
1161.93	2346
1164.14	2406
1166.36	2380
1168.57	2410
1170.78	2362
1172.99	2344
1175.2	2380
1177.4	2394
1179.61	2378
1181.82	2352
1184.02	2330
1186.23	2378
1188.43	2400
1190.64	2344
1192.84	2354
1195.04	2238
1197.24	2316
1199.45	2323.21
1201.64	2316.91
1203.84	2329.52
1206.04	2322.72
1208.24	2368.13
1210.44	2396.19
1212.64	2385.42
1214.83	2366.57
1217.03	2364.76
1219.22	2324.54
1221.41	2399.5
1223.61	2358.9
1225.8	2343.02
1227.99	2381.98
1230.18	2362.8
1232.37	2409.28
1234.56	2359.81
1236.75	2378.27
1238.94	2352.65
1241.13	2387.52
1243.31	2405.19
1245.5	2383.41
1247.68	2423.96
1249.87	2423.84
1252.05	2416.65
1254.24	2422.71
1256.42	2421.01
1258.6	2415.11
1260.78	2430.61
1262.96	2456.96
1265.14	2430.55
1267.32	2420.17
1269.5	2492.19
1271.67	2498.61
1273.85	2505.79
1276.03	2481.45
1278.2	2510.88
1280.38	2527.48
1282.55	2516.13
1284.72	2511
1286.9	2541.77
1289.07	2521.84
1291.24	2535.98
1293.41	2541.62
1295.58	2558.28
1297.75	2546.39
1299.92	2546.04
1302.09	2586.69
1304.25	2523.52
1306.42	2556.77
1308.46	2554
1310.63	2538
1312.81	2506
1314.98	2558
1317.16	2582
1319.33	2538
1321.5	2546
1323.67	2544
1325.85	2532
1328.02	2526
1330.19	2476
1332.35	2534
1334.52	2578
1336.69	2530
1338.86	2528
1341.02	2540
1343.19	2510
1345.35	2564
1347.52	2496
1349.68	2488
1351.84	2564
1354	2486
1356.17	2530
1358.33	2524
1360.49	2536
1362.65	2502
1364.8	2512
1366.96	2528
1369.12	2584
1371.28	2502
1373.43	2462
1375.59	2468
1377.74	2524
1379.89	2550
1382.05	2520
1384.2	2508
1386.35	2518
1388.5	2466
1390.65	2416
1392.8	2448
1394.95	2504
1397.1	2496
1399.25	2504
1401.4	2486
1403.54	2456
1405.69	2494
1407.83	2452
1409.98	2456
1412.12	2468
1414.26	2452
1416.4	2468
1418.55	2452
1420.69	2486
1422.83	2418
1424.97	2456
1427.1	2458
1429.24	2492
1431.38	2398
1433.52	2470
1435.65	2478
1437.79	2472
1439.92	2452
1442.06	2456
1444.19	2406
1446.32	2456
1448.46	2454
1450.59	2486
1452.72	2416
1454.85	2488
1456.98	2462
1459.11	2476
1461.23	2462
1463.36	2468
1465.49	2492
1467.61	2420
1469.74	2448
1471.86	2424
1473.99	2426
1476.11	2434
1478.23	2414
1480.36	2490
1482.48	2424
1484.6	2464
1486.72	2436
1488.84	2502
1490.96	2440
1493.07	2472
1495.19	2424
1497.31	2372
1499.42	2418
1501.54	2410
1503.65	2398
1505.77	2412
1507.88	2360
1509.99	2396
1512.1	2360
1514.22	2454
1516.33	2406
1518.44	2406
1520.55	2406
1522.65	2410
1524.76	2376
1526.87	2428
1528.98	2404
1531.08	2398
1533.19	2354
1535.29	2338
1537.4	2330
1539.5	2382
1541.6	2302
1543.7	2376
1545.8	2296
1547.91	2288
1550.01	2240
1552.11	2298
1554.2	2312
1556.3	2296
1558.4	2296
1560.5	2282
1562.59	2268
1564.69	2310
1566.78	2326
1568.88	2276
1570.97	2322
1573.06	2300
1575.15	2258
1577.25	2280
1579.34	2286
1581.43	2276
1583.52	2296
1585.6	2324
1587.69	2288
1589.78	2298
1591.87	2282
1593.95	2284
1596.04	2274
1598.12	2290
1600.21	2282
1602.29	2292
1604.37	2204
1606.46	2252
1608.54	2250
1610.62	2310
1612.7	2280
1614.78	2260
1616.86	2284
1618.94	2276
1621.01	2260
1623.09	2306
1625.17	2274
1627.24	2234
1629.32	2336
1631.39	2230
1633.47	2248
1635.54	2246
1637.61	2246
1639.68	2250
1641.76	2176
1643.83	2268
1645.9	2266
1647.96	2224
1650.03	2180
1652.1	2268
1654.17	2246
1656.24	2254
1658.3	2270
1660.37	2256
1662.43	2208
1664.5	2238
1666.56	2236
1668.62	2178
1670.68	2224
1672.75	2152
1674.81	2172
1676.87	2166
1678.93	2160
1680.99	2214
1683.04	2154
1685.1	2180
1687.16	2150
1689.21	2208
1691.27	2180
1693.33	2160
1695.38	2102
1697.43	2108
1699.49	2098
1701.54	2138
1703.59	2088
1705.64	2112
1707.69	2102
1709.74	2104
1711.79	2126
1713.84	2074
1715.89	2144
1717.94	2120
1719.98	2086
1722.03	2094
1724.07	2060
1726.12	2080
1728.16	2082
1730.21	2072
1732.25	2098
1734.29	2102
1736.33	2060
1738.37	2072
1740.41	2072
1742.45	2074
1744.49	2086
1746.53	2046
1748.57	2104
1750.61	2080
1752.64	2078
1754.68	2046
1756.71	2086
1758.75	2066
1760.78	2054
1762.82	2028
1764.85	2024
1766.88	2040
1768.91	2036
1770.94	2034
1772.97	2004
1775	2070
1777.03	2046
1779.06	2036
1781.09	2048
1783.12	2002
1785.14	2036
1787.17	2022
1789.19	2012
1791.22	2032
1793.24	2006
1795.27	2022
1797.29	2032
1799.31	1988
1801.33	1958
1803.35	1984
1805.37	1966
1807.39	1982
1809.41	2002
1811.43	1964
1813.45	1978
1815.46	2030
1817.48	1998
1819.5	1984
1821.51	1962
1823.53	1984
1825.54	1936
1827.55	1964
1829.57	1954
1831.58	1970
1833.59	1974
1835.6	1894
1837.61	1982
1839.62	1910
1841.63	1914
1843.64	1906
1845.65	1864
1847.65	1898
1849.66	1878
1851.66	1868
1853.67	1918
1855.67	1884
1857.68	1938
1859.68	1866
1861.68	1846
1863.69	1872
1865.69	1844
1867.69	1816
1869.69	1882
1871.69	1882
1873.69	1888
1875.69	1850
1877.68	1860
1879.68	1808
1881.68	1832
1883.67	1814
1885.67	1892
1887.66	1858
1889.66	1794
1891.65	1794
1893.64	1826
1895.64	1838
1897.63	1870
1899.62	1840
1901.61	1796
1903.6	1818
1905.59	1778
1907.58	1818
1909.56	1836
1911.55	1820
1913.54	1810
1915.53	1806
1917.51	1756
1919.5	1804
1921.48	1802
1923.46	1748
1925.45	1784
1927.43	1802
1929.41	1794
1931.39	1772
1933.37	1766
1935.35	1776
1937.33	1776
1939.31	1736
1941.29	1774
1943.27	1786
1945.24	1730
1947.22	1746
1949.2	1782
1951.17	1736
1953.14	1750
1955.12	1720
1957.09	1720
1959.06	1744
1961.04	1730
1963.01	1728
1964.98	1732
1966.95	1722
1968.92	1698
1970.89	1734
1972.86	1690
1974.82	1704
1976.79	1674
1978.76	1652
1980.72	1714
1982.69	1662
1984.65	1710
1986.62	1652
1988.58	1658
1990.54	1666
1992.51	1660
1994.47	1660
1996.43	1646
1998.39	1680
1999.37	1648