File: 1/Organic_01.txt
#Acq. time (s)=	15
#Accumulations=	5
#Range (cm-¹)=	100...3000
#Windows=	3
#Autofocus=	Off
#AutoExposure=	Off
#Spike filter=	Multiple accum.
#Delay time (s)=	0
#Binning=	1
#Readout mode=	Signal
#DeNoise=	Off
#ICS correction=	Off
#Dark correction=	Off
#Inst. Process=	Off
#Instrument=	LabRAM HR Evol
#Detector=	Syncerity OE
#Objective=	x100_VIS
#Grating=	600 (500nm)
#ND Filter=	25%
#Laser=	633nm_Edge
#Hole=	100.021
#Range=	Visible
#Project=	Omar
#Sample=	20-06-23
#Site=	1
#Title=	Organic
#Remark=
#Date=	20.06.2023 11:19
#Acquired=	20.06.2023 11:19:25
100.991	64535
103.558	64535
106.124	64535
108.689	64535
111.253	64535
113.818	64535
116.38	64535
118.942	64535
121.503	64535
124.063	64535
126.622	64535
129.18	64535
131.736	64535
134.293	64535
136.849	64535
139.404	64535
141.958	64535
144.509	64535
147.062	64535
149.614	64535
152.164	64535
154.713	64535
157.262	64535
159.809	64535
162.356	64535
164.902	64535
167.447	64535
169.991	64535
172.535	64535
175.077	64535
177.619	64535
180.16	64535
182.699	64535
185.239	64535
187.777	64535
190.314	64535
192.85	64535
195.385	64535
197.921	64535
200.455	64535
202.987	64535
205.519	64535
208.051	64535
210.581	64535
213.11	64535
215.639	64535
218.167	64535
220.692	64535
223.219	64535
225.744	64535
228.269	64535
230.792	64535
233.314	64535
235.836	64535
238.357	64535
240.876	64535
243.396	64535
245.913	64535
248.431	64535
250.949	64535
253.464	64535
255.978	64535
258.493	64535
261.005	64535
263.518	64535
266.029	64535
268.539	64535
271.05	64535
273.558	64535
276.066	64535
278.573	64535
281.079	64535
283.584	64535
286.09	64535
288.594	64535
291.096	64535
293.598	64535
296.099	64535
298.6	64535
301.098	64535
303.597	64535
306.095	64535
308.592	64535
311.088	64535
313.584	64535
316.077	64535
318.571	64535
321.064	64535
323.555	64535
326.046	64535
328.536	64535
331.026	64535
333.513	64535
336.001	64535
338.488	64535
340.974	64535
343.459	64535
345.944	64535
348.427	64535
350.909	64535
353.39	64535
355.872	64535
358.352	64535
360.831	64535
363.309	64535
365.786	64535
368.262	64535
370.738	64535
373.213	64535
375.687	64535
378.16	64535
380.633	64535
383.105	64535
385.576	64535
388.046	64535
390.515	64535
392.982	64535
395.45	64535
397.917	64535
400.383	64535
402.847	64535
405.312	64535
407.774	64535
410.237	64535
412.698	64535
415.159	64535
417.619	64535
420.078	64535
422.536	64535
424.994	64535
427.451	64535
429.906	64535
432.36	64535
434.816	64535
437.268	64535
439.721	64535
442.172	64535
444.623	64535
447.072	64535
449.522	64535
451.97	64535
454.417	64535
456.864	64535
459.31	64535
461.755	64535
464.199	64535
466.643	64535
469.086	64535
471.526	64535
473.968	64535
476.408	64535
478.846	64535
481.285	64535
483.723	64535
486.159	64535
488.596	64535
491.03	64535
493.465	64535
495.898	64535
498.332	64535
500.763	64535
503.193	64535
505.625	64535
508.054	64535
510.482	64535
512.909	64535
515.336	64535
517.763	64535
520.188	64535
522.613	64535
525.036	64535
527.459	64535
529.881	64535
532.302	64535
534.723	64535
537.143	64535
539.56	64535
541.978	64535
544.396	64535
546.813	64535
549.227	64535
551.642	64535
554.057	64535
556.469	64535
558.882	64535
561.294	64535
563.704	64535
566.114	64535
568.523	64535
570.932	64535
573.338	64535
575.745	64535
578.151	64535
580.556	64535
582.96	64535
585.363	64535
587.766	64535
590.168	64535
592.569	64535
594.969	64535
597.368	64535
599.767	64535
602.164	64535
604.561	64535
606.958	64535
609.353	64535
611.748	64535
614.142	64535
616.534	64535
618.926	64535
621.318	64535
623.709	64535
626.098	64535
628.487	64535
630.874	64535
633.262	64535
635.65	64535
638.035	64535
640.42	64535
642.804	64535
645.187	64535
647.57	64535
649.951	64535
652.332	64535
654.713	64535
657.092	64535
659.471	64535
661.848	64535
664.225	64535
666.601	64535
668.978	64535
671.352	64535
673.726	64535
676.098	64535
678.47	64535
680.842	64535
683.213	64535
685.583	64535
687.952	64535
690.321	64535
692.687	64535
695.054	64535
697.421	64535
699.785	64535
702.15	64535
704.513	64535
706.876	64535
709.238	64535
711.6	64535
713.959	64535
716.32	64535
718.678	64535
721.036	64535
723.394	64535
725.75	64535
728.106	64535
730.46	64535
732.814	64535
735.169	64535
737.521	64535
739.873	64535
742.224	64535
744.574	64535
746.924	64535
749.271	64535
751.619	64535
753.967	64535
756.313	64535
758.659	64535
761.003	64535
763.347	64535
765.691	64535
768.033	64535
770.375	64535
772.716	64535
775.056	64535
777.396	64535
779.734	64535
782.071	64535
784.409	64535
786.745	64535
789.081	64535
791.415	64535
793.749	64535
796.082	64535
798.414	64535
800.747	64535
803.077	64535
805.407	64535
807.736	64535
810.065	64535
812.393	64535
814.72	64535
817.046	64535
819.37	64535
821.695	64535
824.019	64535
826.343	64535
828.665	64535
830.986	64535
833.307	64535
835.627	64535
837.946	64535
840.266	64535
842.583	64535
844.9	64535
847.216	64535
849.531	64535
851.846	64535
854.16	64535
856.472	64535
858.786	64535
861.097	64535
863.408	64535
865.718	64535
868.027	64535
870.335	64535
872.644	64535
874.951	64535
877.258	64535
879.562	64535
881.867	64535
884.171	64535
886.474	64535
888.777	64535
891.079	64535
893.379	64535
895.68	64535
897.98	64535
900.278	64535
902.576	64535
904.872	64535
907.17	64535
909.465	64535
911.76	64535
914.054	64535
916.348	64535
918.64	64535
920.932	64535
923.224	64535
925.514	64535
927.803	64535
930.092	64535
932.38	64535
934.667	64535
936.954	64535
939.24	64535
941.525	64535
943.809	64535
946.093	64535
948.376	64535
950.658	64535
952.94	64535
955.219	64535
957.5	64535
959.779	64535
962.057	64535
964.335	64535
966.612	64535
968.888	64535
971.164	64535
973.438	64535
975.711	64535
977.985	64535
980.257	64535
982.529	64535
984.8	64535
987.07	64535
989.339	64535
991.607	64535
993.876	64535
996.143	64535
998.41	64535
1000.68	64535
1002.94	64535
1005.2	64535
1007.47	64535
1009.73	64535
1011.99	64535
1014.25	64535
1016.51	64535
1018.77	64535
1021.03	64535
1023.29	64535
1025.55	64535
1027.81	64535
1030.06	64535
1032.32	64535
1034.57	64535
1036.82	64535
1039.08	64535
1041.33	64535
1043.58	64535
1045.83	64535
1048.08	64535
1050.33	64535
1052.58	64535
1054.83	64535
1057.08	64535
1059.32	64535
1061.57	64535
1063.81	64535
1066.06	64535
1068.3	64535
1070.54	64535
1072.79	64535
1075.03	64535
1077.27	64535
1079.51	64535
1081.75	64535
1083.99	64535
1086.22	64535
1088.46	64535
1090.7	64535
1092.93	64535
1095.17	64535
1097.4	64535
1099.63	64535
1101.87	64535
1104.1	64535
1106.33	64535
1108.56	64535
1110.79	64535
1113.02	64535
1115.25	64535
1117.48	64535
1119.7	64535
1121.93	64535
1124.15	64535
1126.38	64535
1128.6	64535
1130.82	64535
1133.05	64535
1135.27	64535
1137.49	64535
1139.71	64535
1141.93	64535
1144.15	64535
1146.37	64535
1148.58	64535
1150.8	64535
1153.02	64535
1155.23	64535
1157.45	64535
1159.66	64535
1161.87	64535
1164.08	64535
1166.3	64535
1168.51	64535
1170.72	64535
1172.93	64535
1175.14	64535
1177.34	64535
1179.55	64535
1181.76	64535
1183.96	64535
1186.17	64535
1188.37	64535
1190.58	64535
1192.78	64535
1194.98	64535
1197.18	64535
1199.39	64535
1201.58	64535
1203.78	64535
1205.98	64535
1208.18	64535
1210.38	64535
1212.58	64535
1214.77	64535
1216.97	64535
1219.16	64535
1221.35	64535
1223.55	64535
1225.74	64535
1227.93	64535
1230.12	64535
1232.31	64535
1234.5	64535
1236.69	64535
1238.88	64535
1241.07	64535
1243.25	64535
1245.44	64535
1247.62	64535
1249.81	64535
1251.99	64535
1254.18	64535
1256.36	64535
1258.54	64535
1260.72	64535
1262.9	64535
1265.08	64535
1267.26	64535
1269.44	64535
1271.62	64535
1273.79	64535
1275.97	64535
1278.14	64535
1280.32	64535
1282.49	64535
1284.67	64535
1286.84	64535
1289.01	64535
1291.18	64535
1293.35	64535
1295.52	64535
1297.69	64535
1299.86	64535
1302.03	64535
1304.19	64535
1306.36	64535
1308.41	64535
1310.58	64535
1312.76	64535
1314.93	64535
1317.11	64535
1319.28	64535
1321.45	64535
1323.62	64535
1325.79	64535
1327.96	64535
1330.13	64535
1332.3	64535
1334.47	64535
1336.64	64535
1338.81	64535
1340.97	64535
1343.14	64535
1345.3	64535
1347.47	64535
1349.63	64535
1351.79	64535
1353.95	64535
1356.12	64535
1358.28	64535
1360.44	64535
1362.59	64535
1364.75	64535
1366.91	64535
1369.07	64535
1371.22	64535
1373.38	64535
1375.54	64535
1377.69	64535
1379.84	64535
1382	64535
1384.15	64535
1386.3	64535
1388.45	64535
1390.6	64535
1392.75	64535
1394.9	64535
1397.05	64535
1399.2	64535
1401.34	64535
1403.49	64535
1405.64	64535
1407.78	64535
1409.92	64535
1412.07	64535
1414.21	64535
1416.35	64535
1418.5	64535
1420.64	64535
1422.78	64535
1424.92	64535
1427.05	64535
1429.19	64535
1431.33	64535
1433.47	64535
1435.6	64535
1437.74	64535
1439.87	64535
1442.01	64535
1444.14	64535
1446.27	64535
1448.4	64535
1450.54	64535
1452.67	64535
1454.8	64535
1456.93	64535
1459.05	64535
1461.18	64535
1463.31	64535
1465.44	64535
1467.56	64535
1469.69	64535
1471.81	64535
1473.94	64535
1476.06	64535
1478.18	64535
1480.3	64535
1482.43	64535
1484.55	64535
1486.67	64535
1488.78	64535
1490.9	64535
1493.02	64535
1495.14	64535
1497.26	64535
1499.37	64535
1501.49	64535
1503.6	64535
1505.72	64535
1507.83	64535
1509.94	64535
1512.05	64535
1514.16	64535
1516.27	64535
1518.38	64535
1520.49	64535
1522.6	64535
1524.71	64535
1526.82	64535
1528.92	64535
1531.03	64535
1533.13	64535
1535.24	64535
1537.34	64535
1539.45	64535
1541.55	64535
1543.65	64535
1545.75	64535
1547.85	64535
1549.95	64535
1552.05	64535
1554.15	64535
1556.25	64535
1558.35	64535
1560.44	64535
1562.54	64535
1564.64	64535
1566.73	64535
1568.82	64535
1570.92	64535
1573.01	64535
1575.1	64535
1577.19	64535
1579.28	64535
1581.37	64535
1583.46	64535
1585.55	64535
1587.64	64535
1589.73	64535
1591.81	64535
1593.9	64535
1595.99	64535
1598.07	64535
1600.16	64535
1602.24	64535
1604.32	64535
1606.4	64535
1608.49	64535
1610.57	64535
1612.65	64535
1614.73	64535
1616.81	64535
1618.88	64535
1620.96	64535
1623.04	64535
1625.11	64535
1627.19	64535
1629.27	64535
1631.34	64535
1633.41	64535
1635.49	64535
1637.56	64535
1639.63	64535
1641.7	64535
1643.77	64535
1645.84	64535
1647.91	64535
1649.98	64535
1652.05	64535
1654.12	64535
1656.18	64535
1658.25	64535
1660.31	64535
1662.38	64535
1664.44	64535
1666.51	64535
1668.57	64535
1670.63	64535
1672.69	64535
1674.75	64535
1676.81	64535
1678.87	64535
1680.93	64535
1682.99	64535
1685.05	64535
1687.1	64535
1689.16	64535
1691.22	64535
1693.27	64535
1695.33	64535
1697.38	64535
1699.43	64535
1701.49	64535
1703.54	64535
1705.59	64535
1707.64	64535
1709.69	64535
1711.74	64535
1713.79	64535
1715.84	64535
1717.88	64535
1719.93	64535
1721.98	64535
1724.02	64535
1726.07	64535
1728.11	64535
1730.15	64535
1732.2	64535
1734.24	64535
1736.28	64535
1738.32	64535
1740.36	64535
1742.4	64535
1744.44	64535
1746.48	64535
1748.52	64535
1750.55	64535
1752.59	64535
1754.63	64535
1756.66	64535
1758.7	64535
1760.73	64535
1762.76	64535
1764.8	64535
1766.83	64535
1768.86	64535
1770.89	64535
1772.92	64535
1774.95	64535
1776.98	64535
1779.01	64535
1781.03	64535
1783.06	64535
1785.09	64535
1787.11	64535
1789.14	64535
1791.16	64535
1793.19	64535
1795.21	64535
1797.23	64535
1799.26	64535
1801.28	64535
1803.3	64535
1805.32	64535
1807.34	64535
1809.36	64535
1811.37	64535
1813.39	64535
1815.41	64535
1817.43	64535
1819.44	64535
1821.46	64535
1823.47	64535
1825.49	64535
1827.5	64535
1829.51	64535
1831.52	64535
1833.54	64535
1835.55	64535
1837.56	64535
1839.56	64535
1841.57	64535
1843.58	64535
1845.59	64535
1847.6	64535
1849.6	64535
1851.61	64535
1853.61	64535
1855.62	64535
1857.62	64535
1859.63	64535
1861.63	64535
1863.63	64535
1865.63	64535
1867.63	64535
1869.63	64535
1871.63	64535
1873.63	64535
1875.63	64535
1877.63	64535
1879.63	64535
1881.62	64535
1883.62	64535
1885.61	64535
1887.61	64535
1889.6	64535
1891.6	64535
1893.59	64535
1895.58	64535
1897.57	64535
1899.56	64535
1901.55	64535
1903.54	64535
1905.53	64535
1907.52	64535
1909.51	64535
1911.5	64535
1913.48	64535
1915.47	64535
1917.46	64535
1919.44	64535
1921.42	64535
1923.41	64535
1925.39	64535
1927.37	64535
1929.35	64535
1931.34	64535
1933.32	64535
1935.3	64535
1937.28	64535
1939.26	64535
1941.23	64535
1943.21	64535
1945.19	64535
1947.16	64535
1949.14	64535
1951.11	64535
1953.09	64535
1955.06	64535
1957.04	64535
1959.01	64535
1960.98	64535
1962.95	64535
1964.92	64535
1966.89	64535
1968.86	64535
1970.83	64535
1972.8	64535
1974.77	64535
1976.74	64535
1978.7	64535
1980.67	64535
1982.63	64535
1984.6	64535
1986.56	64535
1988.53	64535
1990.49	64535
1992.45	64535
1994.41	64535
1996.37	64535
1998.33	64535
2000.3	64535
2002.25	64535
2004.21	64535
2006.17	64535
2008.13	64535
2010.09	64535
2012.04	64535
2014	64535
2015.95	64535
2017.91	64535
2019.86	64535
2021.82	64535
2023.77	64535
2025.72	64535
2027.67	64535
2029.62	64535
2031.57	64535
2033.52	64535
2035.47	64535
2037.42	64535
2039.37	64535
2041.32	64535
2043.26	64535
2045.21	64535
2047.15	64535
2049.1	64535
2051.04	64535
2052.99	64535
2054.93	64535
2056.87	64535
2058.82	64535
2060.76	64535
2062.7	64535
2064.64	64535
2066.58	64535
2068.52	64535
2070.46	64535
2072.39	64535
2074.33	64535
2076.27	64535
2078.2	64535
2080.14	64535
2082.07	64535
2084.01	64535
2085.94	64535
2087.88	64535
2089.81	64535
2091.74	64535
2093.67	64198
2095.6	64274
2097.53	64204
2099.46	63908
2101.39	63594
2103.32	63498
2105.25	63476
2107.17	63518
2109.1	63052
2111.03	63252
2112.95	63154
2114.88	63002
2116.8	62738
2118.73	62620
2120.65	62270
2122.57	62306
2124.49	62198
2126.42	61952
2128.34	62232
2130.26	62148
2132.18	61620
2134.09	61742
2136.01	61168
2137.93	61416
2139.85	61136
2141.76	60856
2143.68	60632
2145.6	60696
2147.51	60708
2149.43	60392
2151.34	59962
2153.25	59638
2155.17	59336
2157.08	59964
2158.99	59130
2160.9	59104
2162.81	59146
2164.72	58492
2166.63	58604
2168.54	58382
2170.45	58374
2172.35	57974
2174.26	57976
2176.17	57966
2178.07	57782
2179.98	57622
2181.88	57324
2183.79	57216
2185.69	57070
2187.59	56830
2189.49	56570
2191.4	56812
2193.3	56348
2195.2	56448
2197.1	56164
2199	56110
2200.89	55746
2202.79	55802
2204.69	55786
2206.59	55258
2208.48	55330
2210.38	55362
2212.28	55290
2214.17	54794
2216.06	54466
2217.96	54712
2219.85	54380
2221.74	54200
2223.64	54168
2225.53	54170
2227.42	54014
2229.31	53616
2231.2	53858
2233.09	53938
2234.97	53490
2236.86	53604
2238.75	53664
2240.64	53130
2241.58	53300