File: muestras/ogompa/nsno_19.txt
#Acq. time (s)=	5
#Accumulations=	5
#Range (cm-¹)=	100...3000
#Windows=	3
#Autofocus=	Off
#AutoExposure=	Off
#Spike filter=	Multiple accum.
#Delay time (s)=	0
#Binning=	1
#Readout mode=	Signal
#DeNoise=	Off
#ICS correction=	Off
#Dark correction=	Off
#Inst. Process=	Off
#Instrument=	LabRAM HR Evol
#Detector=	Syncerity OE
#Objective=	x100_VIS_LWD
#Grating=	600 (500nm)
#ND Filter=	100%
#Laser=	633nm_Edge
#Hole=	100.021
#Range=	Visible
#Project=	Omar
#Sample=	chi
#Site=	f
#Title=	nsno
#Remark=
#Date=	12.09.2023 17:46
#Acquired=	12.09.2023 17:46:51
101.026	2415
103.592	2349
106.158	2330
108.723	2280.5
111.289	2248
113.852	2172.5
116.415	2161
118.976	2138
121.537	2093
124.097	2079
126.656	2059.5
129.215	2032.5
131.772	2015.5
134.327	1976.5
136.883	1945
139.438	1903
141.992	1872.5
144.545	1860
147.096	1815.5
149.648	1762.5
152.199	1742
154.747	1703.5
157.296	1674.5
159.843	1669
162.391	1646
164.937	1640
167.482	1622
170.025	1612.5
172.569	1626
175.111	1595
177.654	1582
180.194	1572
182.733	1559
185.273	1567.5
187.811	1564
190.348	1569.5
192.884	1571.5
195.419	1576
197.955	1577.5
200.489	1575.5
203.022	1593
205.554	1584
208.085	1570.5
210.615	1602.5
213.144	1586
215.673	1595.5
218.201	1617.5
220.728	1613
223.253	1601.5
225.778	1618
228.303	1627
230.826	1626.5
233.348	1639
235.87	1635
238.391	1638
240.91	1654
243.43	1662.5
245.949	1648
248.465	1638
250.983	1645.5
253.498	1646
256.013	1676
258.526	1660.5
261.039	1687
263.552	1650.5
266.063	1673.5
268.573	1672.5
271.084	1677.5
273.592	1673
276.1	1662
278.607	1678.5
281.113	1662
283.619	1666
286.124	1672
288.627	1701.5
291.13	1708
293.632	1693
296.133	1698
298.634	1726
301.133	1721.5
303.63	1707.5
306.128	1720.5
308.625	1677.5
311.122	1675.5
313.617	1712.5
316.111	1676
318.604	1688.5
321.098	1658
323.588	1643.5
326.08	1652.5
328.569	1622
331.059	1612.5
333.548	1640
336.035	1631
338.521	1596.5
341.008	1602.5
343.492	1583.5
345.977	1580.5
348.46	1604
350.942	1586.5
353.425	1629.5
355.905	1617
358.385	1611
360.864	1603
363.342	1602
365.819	1609
368.296	1618
370.771	1598
373.246	1605.5
375.72	1600.5
378.194	1606.5
380.666	1591
383.138	1601
385.609	1609
388.079	1597.5
390.548	1611
393.016	1595
395.483	1604
397.95	1584.5
400.416	1594.5
402.88	1631.5
405.345	1589.5
407.807	1598
410.27	1621.5
412.731	1611.5
415.193	1642.5
417.652	1645
420.112	1650
422.569	1650.5
425.028	1652
427.484	1628
429.939	1687
432.394	1696.5
434.849	1667
437.302	1705
439.754	1668
442.205	1678.5
444.656	1671.5
447.106	1677
449.555	1680
452.003	1684.5
454.45	1663
456.897	1636
459.343	1629.5
461.788	1638
464.232	1649
466.676	1667.5
469.119	1657.5
471.559	1643
474.001	1666
476.441	1669
478.879	1664
481.318	1645
483.756	1664
486.192	1638.5
488.629	1655
491.063	1671.5
493.498	1682
495.931	1659.5
498.365	1711
500.796	1700.5
503.226	1707
505.657	1719.5
508.086	1708
510.515	1709.5
512.942	1693.5
515.369	1712
517.796	1738
520.221	1700
522.645	1707
525.069	1718
527.492	1708.5
529.914	1702.5
532.335	1717.5
534.756	1700.5
537.175	1690.5
539.593	1687.5
542.011	1693.5
544.429	1712
546.845	1697
549.261	1708.5
551.675	1690
554.089	1689
556.503	1669.5
558.914	1705
561.326	1684
563.736	1668.5
566.147	1705
568.555	1676
570.964	1694.5
573.371	1713.5
575.777	1704.5
578.184	1682.5
580.588	1692
582.992	1707.5
585.395	1701
587.799	1685.5
590.201	1696
592.601	1733
595.001	1661
597.401	1700
599.799	1712
602.197	1721.5
604.594	1745
606.99	1730
609.386	1703.5
611.78	1728.5
614.174	1750
616.566	1726
618.958	1746
621.35	1766.5
623.741	1747
626.13	1741
628.519	1783
630.908	1773
633.295	1789.5
635.682	1752.5
638.067	1789.5
640.453	1785
642.836	1801
645.219	1791.5
647.602	1792.5
649.984	1784.5
652.364	1765
654.745	1800
657.124	1772.5
659.503	1758.5
661.88	1757.5
664.257	1768
666.635	1785
669.01	1748.5
671.384	1752
673.758	1764.5
676.131	1760
678.502	1757
680.874	1739.5
683.245	1752
685.615	1733
687.984	1729.5
690.353	1748
692.719	1745.5
695.086	1717
697.453	1709.5
699.817	1740.5
702.182	1735.5
704.545	1701
706.908	1737
709.27	1725.5
711.632	1719.5
713.991	1730
716.352	1740
718.71	1720
721.068	1729.5
723.426	1712
725.782	1748
728.138	1729.5
730.492	1690.5
732.846	1729.5
735.201	1732
737.553	1743
739.905	1742
742.256	1755.5
744.606	1736
746.956	1737
749.303	1757.5
751.651	1725.5
753.999	1727
756.345	1754
758.691	1769
761.035	1741
763.379	1760
765.723	1732
768.064	1727.5
770.407	1752
772.748	1709.5
775.088	1722
777.427	1722.5
779.765	1737.5
782.104	1734.5
784.44	1732.5
786.776	1725
789.113	1722.5
791.447	1705.5
793.78	1698.5
796.113	1730.5
798.445	1745.5
800.778	1736.5
803.109	1733
805.439	1731
807.768	1747.5
810.096	1740.5
812.424	1747
814.751	1769.5
817.078	1740.5
819.402	1773
821.727	1747
824.051	1781.5
826.374	1779
828.697	1740
831.018	1766.5
833.339	1771
835.659	1778
837.978	1782
840.297	1788
842.614	1777
844.932	1788.5
847.247	1776
849.562	1788
851.878	1793
854.191	1806.5
856.504	1800
858.817	1803.5
861.129	1808
863.439	1805
865.749	1773
868.058	1748
870.367	1770
872.676	1744.5
874.983	1789
877.289	1754
879.593	1746
881.898	1723
884.202	1730.5
886.506	1727.5
888.808	1748.5
891.11	1725
893.41	1761.5
895.711	1698.5
898.011	1718.5
900.309	1714.5
902.607	1684.5
904.904	1753.5
907.201	1732.5
909.496	1705.5
911.791	1687
914.085	1693.5
916.379	1703.5
918.671	1703.5
920.963	1710
923.255	1695
925.545	1695.5
927.834	1695.5
930.123	1703.5
932.411	1694.5
934.698	1687
936.985	1701
939.271	1735.5
941.556	1702
943.84	1720.5
946.124	1706
948.407	1688.5
950.689	1670
952.971	1710.5
955.25	1704
957.531	1713.5
959.81	1706
962.088	1729.5
964.366	1725.5
966.643	1716
968.919	1714.5
971.195	1724.5
973.469	1724
975.743	1732
978.016	1733.5
980.288	1736.5
982.56	1746.5
984.831	1766.5
987.101	1762.5
989.37	1752.5
991.638	1715
993.907	1726.5
996.174	1767.5
998.44	1787
1000.71	1799
1002.97	1756
1005.24	1711.5
1007.5	1724.5
1009.76	1720.5
1012.02	1709
1014.28	1708.5
1016.54	1741
1018.8	1707
1021.06	1723.5
1023.32	1701.5
1025.58	1684
1027.84	1736.5
1030.09	1739.5
1032.35	1710.5
1034.6	1718.5
1036.86	1742.5
1039.11	1701
1041.36	1741
1043.61	1736
1045.86	1743.5
1048.11	1759
1050.36	1752
1052.61	1750
1054.86	1767.5
1057.11	1750
1059.35	1756.5
1061.6	1750.5
1063.84	1778.5
1066.09	1756.5
1068.33	1750.5
1070.57	1717.5
1072.82	1718
1075.06	1745.5
1077.3	1735
1079.54	1730
1081.78	1739
1084.02	1718
1086.25	1754
1088.49	1733.5
1090.73	1729
1092.96	1725
1095.2	1722.5
1097.43	1740
1099.66	1699
1101.9	1710.5
1104.13	1713.5
1106.36	1727.5
1108.59	1723
1110.82	1735
1113.05	1730
1115.28	1704.5
1117.51	1704
1119.73	1702.5
1121.96	1728.5
1124.18	1703
1126.41	1715
1128.63	1717.5
1130.85	1716.5
1133.08	1723
1135.3	1685.5
1137.52	1700
1139.74	1734.5
1141.96	1739.5
1144.18	1737
1146.4	1743.5
1148.61	1781.5
1150.83	1759.5
1153.05	1748
1155.26	1789
1157.48	1784.5
1159.69	1794.5
1161.9	1804.5
1164.11	1809.5
1166.33	1820.5
1168.54	1826
1170.75	1849.5
1172.96	1830
1175.17	1842
1177.37	1842
1179.58	1819.5
1181.79	1813.5
1183.99	1787.5
1186.2	1795.5
1188.4	1789
1190.61	1758
1192.81	1803.5
1195.01	1800
1197.21	1794.11
1199.42	1783.23
1201.61	1778.71
1203.81	1779.06
1206.01	1759.07
1208.21	1794.44
1210.41	1780.97
1212.61	1755.64
1214.8	1777.3
1217	1778.12
1219.19	1763.94
1221.38	1767.91
1223.58	1764.56
1225.77	1758.49
1227.96	1762.85
1230.15	1788.02
1232.34	1816.82
1234.53	1801.85
1236.72	1799.59
1238.91	1804.42
1241.1	1784.65
1243.28	1774.82
1245.47	1769.67
1247.65	1788.84
1249.84	1762.52
1252.02	1777.58
1254.21	1787.59
1256.39	1785.7
1258.57	1789.25
1260.75	1796.45
1262.93	1798.16
1265.11	1815.72
1267.29	1812.14
1269.47	1826.63
1271.65	1810.17
1273.82	1835.32
1276	1830.56
1278.17	1819.84
1280.35	1816.17
1282.52	1802.88
1284.69	1804.21
1286.87	1811.12
1289.04	1812.35
1291.21	1824.96
1293.38	1860.38
1295.55	1840.43
1297.72	1836.47
1299.89	1849.33
1302.06	1840.54
1304.22	1840.77
1306.39	1854.31
1308.43	1829.5
1310.6	1832
1312.78	1836
1314.96	1807
1317.13	1794.5
1319.3	1797.5
1321.47	1784.5
1323.65	1807.5
1325.82	1787.5
1327.99	1783.5
1330.16	1757.5
1332.32	1768
1334.49	1769
1336.66	1774
1338.83	1758.5
1340.99	1767.5
1343.16	1721
1345.32	1757.5
1347.49	1735.5
1349.65	1741
1351.81	1766
1353.98	1710
1356.14	1728.5
1358.3	1727.5
1360.46	1713
1362.62	1730
1364.78	1734.5
1366.93	1677
1369.09	1694.5
1371.25	1708
1373.4	1709
1375.56	1712.5
1377.71	1697.5
1379.87	1688
1382.02	1695.5
1384.17	1694.5
1386.32	1688
1388.47	1644
1390.63	1693.5
1392.77	1683.5
1394.92	1667.5
1397.07	1669.5
1399.22	1674.5
1401.37	1651
1403.51	1655
1405.66	1660
1407.8	1653
1409.95	1630.5
1412.09	1663.5
1414.23	1649.5
1416.38	1635.5
1418.52	1650
1420.66	1658
1422.8	1647
1424.94	1673
1427.08	1649
1429.21	1652
1431.35	1650.5
1433.49	1668
1435.63	1679
1437.76	1668
1439.89	1692.5
1442.03	1676.5
1444.16	1719
1446.3	1705
1448.43	1696
1450.56	1684.5
1452.69	1680
1454.82	1644
1456.95	1683
1459.08	1655
1461.2	1656.5
1463.33	1698
1465.46	1662
1467.58	1704.5
1469.71	1661.5
1471.83	1665.5
1473.96	1669.5
1476.08	1665
1478.2	1670
1480.33	1673
1482.45	1651.5
1484.57	1690
1486.69	1646
1488.81	1659.5
1490.93	1652.5
1493.04	1703
1495.16	1688.5
1497.28	1660.5
1499.39	1698
1501.51	1667.5
1503.62	1682.5
1505.74	1703.5
1507.85	1699.5
1509.96	1721
1512.07	1702
1514.19	1690.5
1516.3	1718.5
1518.41	1726.5
1520.52	1711.5
1522.62	1723.5
1524.73	1733.5
1526.84	1733.5
1528.95	1725.5
1531.05	1742
1533.16	1730
1535.26	1760
1537.37	1742
1539.47	1746
1541.57	1740.5
1543.67	1737
1545.78	1726.5
1547.88	1697
1549.98	1716.5
1552.07	1719.5
1554.17	1722.5
1556.27	1728.5
1558.37	1721.5
1560.47	1729
1562.56	1719
1564.66	1739
1566.75	1751.5
1568.85	1734
1570.94	1723.5
1573.03	1726.5
1575.12	1737
1577.21	1736.5
1579.31	1753
1581.4	1765
1583.49	1732
1585.57	1720.5
1587.66	1729
1589.75	1749.5
1591.84	1747
1593.92	1755.5
1596.01	1735
1598.09	1734.5
1600.18	1721
1602.26	1707.5
1604.34	1675
1606.43	1654
1608.51	1651
1610.59	1629.5
1612.67	1570
1614.75	1558.5
1616.83	1514.5
1618.91	1525.5
1620.98	1479
1623.06	1491
1625.14	1444.5
1627.21	1407
1629.29	1388.5
1631.36	1381.5
1633.43	1339
1635.51	1326.5
1637.58	1314
1639.65	1321
1641.72	1290.5
1643.79	1266.5
1645.86	1258.5
1647.93	1241
1650	1222.5
1652.07	1244.5
1654.14	1214
1656.2	1198.5
1658.27	1180.5
1660.34	1185.5
1662.4	1168
1664.46	1143
1666.53	1146
1668.59	1136
1670.65	1102.5
1672.71	1111
1674.77	1091
1676.83	1097.5
1678.89	1063
1680.95	1079.5
1683.01	1076
1685.07	1070.5
1687.13	1064
1689.18	1056
1691.24	1045.5
1693.29	1048
1695.35	1037.5
1697.4	1046
1699.45	1021.5
1701.51	1027
1703.56	1029
1705.61	1026.5
1707.66	991.5
1709.71	1005
1711.76	1010.5
1713.81	993.5
1715.86	992
1717.9	994
1719.95	989.5
1722	957
1724.04	985
1726.09	952
1728.13	974
1730.17	970.5
1732.22	951.5
1734.26	951.5
1736.3	942
1738.34	956.5
1740.38	958
1742.42	937.5
1744.46	948.5
1746.5	929.5
1748.54	923
1750.57	924.5
1752.61	907.5
1754.65	946
1756.68	916.5
1758.72	905.5
1760.75	920
1762.78	899
1764.82	902.5
1766.85	900
1768.88	885.5
1770.91	891.5
1772.94	879.5
1774.97	892.5
1777	879
1779.03	895
1781.06	869
1783.08	851
1785.11	856.5
1787.14	864.5
1789.16	861.5
1791.18	877
1793.21	838
1795.23	860
1797.26	843.5
1799.28	842
1801.3	834
1803.32	840.5
1805.34	856
1807.36	852
1809.38	837.5
1811.4	833.5
1813.41	817
1815.43	820.5
1817.45	815.5
1819.46	813.5
1821.48	799
1823.49	803.5
1825.51	816.5
1827.52	794
1829.53	791.5
1831.54	768.5
1833.56	787
1835.57	798.5
1837.58	808
1839.59	795.5
1841.59	786.5
1843.6	769
1845.61	770
1847.62	749
1849.62	787.5
1851.63	766
1853.64	764
1855.64	775.5
1857.64	762.5
1859.65	760
1861.65	759
1863.65	761
1865.65	749
1867.65	747
1869.65	756
1871.65	736.5
1873.65	758
1875.65	731
1877.65	735
1879.65	729
1881.64	739
1883.64	730
1885.63	729
1887.63	731
1889.62	717.5
1891.62	718
1893.61	733.5
1895.6	720
1897.59	715.5
1899.58	734
1901.57	718
1903.56	715.5
1905.55	723
1907.54	725
1909.53	727
1911.52	715
1913.5	709
1915.49	716.5
1917.48	708
1919.46	719
1921.44	692.5
1923.43	694.5
1925.41	709.5
1927.39	697
1929.38	708
1931.36	697
1933.34	718
1935.32	696
1937.3	688.5
1939.28	698.5
1941.25	669.5
1943.23	705
1945.21	693
1947.18	691
1949.16	697.5
1951.13	679
1953.11	679
1955.08	681
1957.06	673.5
1959.03	653.5
1961	689
1962.97	673
1964.94	665.5
1966.91	673
1968.88	647
1970.85	666
1972.82	655
1974.79	649.5
1976.76	664.5
1978.72	646
1980.69	649.5
1982.65	653.5
1984.62	664.5
1986.58	637.5
1988.55	649
1990.51	638.5
1992.47	653.5
1994.43	644.5
1996.39	646
1998.36	630
2000.31	625
2002.27	641
2004.23	649.5
2006.19	641.5
2008.15	630
2010.11	637
2012.06	621
2014.02	619.5
2015.97	629
2017.93	626
2019.88	619.5
2021.83	621.5
2023.79	623.5
2025.74	623
2027.69	636
2029.64	623
2031.59	622
2033.54	596
2035.49	610.5
2037.44	617
2039.39	595
2041.34	606
2043.28	616
2045.23	621.5
2047.17	593
2049.12	600.5
2051.06	601
2053.01	606.5
2054.95	605
2056.89	598
2058.84	591
2060.78	579
2062.72	581.5
2064.66	584
2066.6	601
2068.54	581
2070.48	595
2072.41	585
2074.35	587
2076.29	581.5
2078.22	599
2080.16	567
2082.09	582
2084.03	594
2085.96	579.5
2087.9	585
2089.83	588
2091.76	578
2093.69	574
2095.62	564.5
2097.55	580
2099.48	579.5
2101.41	588
2103.34	601.5
2105.27	581.5
2107.19	601.5
2109.12	601
2111.05	622
2112.97	634
2114.9	642.5
2116.82	659.5
2118.75	676
2120.67	696
2122.59	730
2124.51	721
2126.43	744
2128.36	730
2130.28	722
2132.2	721.5
2134.11	720.5
2136.03	714.5
2137.95	704
2139.87	677.5
2141.78	676
2143.7	665
2145.62	652.601
2147.53	646.104
2149.45	643.157
2151.36	634.827
2153.27	642.843
2155.19	622.886
2157.1	619.939
2159.01	622.358
2160.92	607.96
2162.83	587.156
2164.74	568.564
2166.65	573.44
2168.56	563.212
2170.47	559.531
2172.37	542.513
2174.28	555.045
2176.19	544.842
2178.09	532.04
2180	521.909
2181.9	515.163
2183.81	530.564
2185.71	521.241
2187.61	508.969
2189.51	511.463
2191.42	515.49
2193.32	508.86
2195.22	505.588
2197.12	509.037
2199.02	507.008
2200.92	511.134
2202.81	494.045
2204.71	505.273
2206.61	501.894
2208.5	502.124
2210.4	496.876
2212.3	505.567
2214.19	501.741
2216.08	494.094
2217.98	497.881
2219.87	492.925
2221.76	485.108
2223.65	499.025
2225.55	499.113
2227.44	493.887
2229.33	493.117
2231.22	492.192
2233.11	488.166
2234.99	489.632
2236.88	492.937
2238.77	492.861
2240.66	495.86
2242.06	505.5
2243.96	493
2245.85	493.5
2247.75	497.5
2249.64	497.5
2251.54	493
2253.43	489
2255.32	487.5
2257.21	469.5
2259.1	479
2260.99	493.5
2262.89	455.5
2264.77	448
2266.66	468
2268.55	471
2270.44	461
2272.33	441
2274.21	454
2276.1	451
2277.98	464.5
2279.87	447.5
2281.75	439.5
2283.64	453.5
2285.52	454.5
2287.4	455.5
2289.29	447.5
2291.17	440.5
2293.05	438
2294.93	435
2296.81	440
2298.69	428.5
2300.57	435.5
2302.44	431.5
2304.32	444.5
2306.2	424
2308.08	440.5
2309.95	429.5
2311.83	437
2313.7	426
2315.58	439.5
2317.45	433.5
2319.32	426
2321.2	442
2323.07	419
2324.94	422.5
2326.81	433
2328.68	432
2330.55	432.5
2332.42	430
2334.29	412
2336.16	419
2338.02	422.5
2339.89	408.5
2341.76	427.5
2343.62	417
2345.49	419.5
2347.35	407
2349.22	398
2351.08	414.5
2352.94	418
2354.81	416
2356.67	413.5
2358.53	398.5
2360.39	413.5
2362.25	405.5
2364.11	409
2365.97	413.5
2367.83	411.5
2369.69	405.5
2371.55	399
2373.4	412
2375.26	410.5
2377.11	400
2378.97	409
2380.83	407.5
2382.68	396
2384.53	387
2386.39	395
2388.24	405.5
2390.09	402
2391.94	397.5
2393.79	398
2395.64	392.5
2397.49	396
2399.34	392
2401.19	402
2403.04	394
2404.89	385
2406.74	395
2408.58	383
2410.43	386
2412.27	398.5
2414.12	387
2415.96	388
2417.81	378
2419.65	366
2421.49	384.5
2423.34	396
2425.18	391.5
2427.02	384.5
2428.86	380.5
2430.7	384.5
2432.54	388
2434.38	376
2436.22	374.5
2438.05	374.5
2439.89	374
2441.73	379
2443.56	369.5
2445.4	377
2447.24	369
2449.07	385
2450.9	369.5
2452.74	367
2454.57	377.5
2456.4	359.5
2458.23	366
2460.07	365.5
2461.9	371.5
2463.73	361
2465.56	374
2467.39	369
2469.21	372.5
2471.04	380.5
2472.87	380
2474.7	372
2476.52	358.5
2478.35	363.5
2480.17	361
2482	367.5
2483.82	372.5
2485.65	350.5
2487.47	371
2489.29	359.5
2491.12	360
2492.94	351
2494.76	358
2496.58	357
2498.4	355.5
2500.22	348.5
2502.04	358.5
2503.86	361
2505.67	354
2507.49	337.5
2509.31	342
2511.12	356.5
2512.94	361.5
2514.76	345.5
2516.57	335.5
2518.38	343
2520.2	348
2522.01	347.5
2523.82	347
2525.64	351
2527.45	334.5
2529.26	348
2531.07	336.5
2532.88	333.5
2534.69	332
2536.5	336.5
2538.31	337
2540.11	341.5
2541.92	331
2543.73	330
2545.53	335
2547.34	331.5
2549.14	322
2550.95	337.5
2552.75	333
2554.56	351
2556.36	315
2558.16	339.5
2559.96	329
2561.76	333.5
2563.57	316.5
2565.37	334.5
2567.17	312
2568.96	324
2570.76	330
2572.56	329
2574.36	320.5
2576.16	321
2577.95	324.5
2579.75	315.5
2581.54	320
2583.34	328.5
2585.13	330
2586.93	311
2588.72	322
2590.51	322.5
2592.31	324
2594.1	325
2595.89	315
2597.68	308.5
2599.47	321.5
2601.26	316.5
2603.05	306.5
2604.84	306.5
2606.63	312.5
2608.42	314
2610.2	310
2611.99	313
2613.78	312
2615.56	316
2617.35	309.5
2619.13	315.5
2620.91	307.5
2622.7	303
2624.48	302
2626.26	305
2628.04	301
2629.83	305
2631.61	294.5
2633.39	316
2635.17	294
2636.95	301.5
2638.73	301.5
2640.5	290.5
2642.28	301
2644.06	299.5
2645.84	295
2647.61	290.5
2649.39	297.5
2651.16	295
2652.94	297
2654.71	292
2656.49	294
2658.26	301
2660.03	291
2661.8	302
2663.57	299.5
2665.35	290
2667.12	301.5
2668.89	286
2670.66	289
2672.42	289
2674.19	295.5
2675.96	291.5
2677.73	283
2679.49	289
2681.26	287
2683.03	291.5
2684.79	277.5
2686.56	285.5
2688.32	285
2690.09	289.5
2691.85	287.5
2693.61	286
2695.37	282.5
2697.14	276.5
2698.9	278.5
2700.66	275
2702.42	274.5
2704.18	283
2705.94	287.5
2707.7	268
2709.45	272.5
2711.21	279
2712.97	282.5
2714.72	280
2716.48	275.5
2718.24	276.5
2719.99	279
2721.75	273
2723.5	270
2725.25	268
2727.01	272.5
2728.76	276
2730.51	272.5
2732.26	266.5
2734.01	275.5
2735.76	273
2737.51	263.5
2739.26	269
2741.01	268.5
2742.76	273.5
2744.51	267.5
2746.26	274
2748	268
2749.75	267
2751.5	266.5
2753.24	264
2754.99	262.5
2756.73	266
2758.47	263.5
2760.22	261
2761.96	270.5
2763.7	259
2765.44	260.5
2767.19	264.5
2768.93	260
2770.67	259
2772.41	255
2774.15	247
2775.89	256
2777.62	249
2779.36	260.5
2781.1	258
2782.84	258.5
2784.57	262
2786.31	247
2788.04	256
2789.78	252
2791.51	260
2793.24	246.5
2794.98	248.5
2796.71	252
2798.44	252.5
2800.18	248.5
2801.91	254.5
2803.64	250
2805.37	250.5
2807.1	249.5
2808.83	253
2810.55	248
2812.28	249.5
2814.01	250.5
2815.74	243.5
2817.46	236.5
2819.19	246
2820.92	250
2822.64	237.5
2824.37	232.5
2826.09	247
2827.81	247.5
2829.54	243
2831.26	246.5
2832.98	241
2834.71	238
2836.43	250
2838.15	254.5
2839.87	244
2841.59	248
2843.31	243.5
2845.02	243
2846.74	260.5
2848.46	241
2850.18	258
2851.9	266
2853.61	255
2855.33	257.5
2857.04	255
2858.76	251
2860.47	254
2862.19	255
2863.9	254
2865.61	252.5
2867.32	257
2869.04	251.5
2870.75	254
2872.46	253.5
2874.17	246.5
2875.88	256
2877.59	248
2879.3	258.5
2881	256.5
2882.71	258
2884.42	245.5
2886.13	251
2887.83	255.5
2889.54	251.5
2891.24	260.5
2892.95	253
2894.65	257
2896.36	266.5
2898.06	257
2899.76	259
2901.47	259
2903.17	258.5
2904.87	259.5
2906.57	260
2908.27	260.5
2909.97	264.5
2911.67	268.5
2913.37	252.5
2915.07	268
2916.77	269
2918.47	263
2920.16	267
2921.86	263
2923.55	256.5
2925.25	271
2926.94	254
2928.64	258.5
2930.33	264
2932.03	273
2933.72	276
2935.41	268.5
2937.11	266
2938.8	262
2940.49	253
2942.18	254
2943.87	262.5
2945.56	261
2947.25	236.5
2948.94	233
2950.63	230
2952.31	233
2954	234
2955.69	242.5
2957.37	228.5
2959.06	228.5
2960.75	225
2962.43	237
2964.11	215
2965.8	225
2967.48	233.5
2969.16	224.5
2970.85	226
2972.53	222
2974.21	220
2975.89	207.5
2977.57	207.5
2979.25	212.5
2980.93	219.5
2982.61	210
2984.29	205.5
2985.97	208.5
2987.65	199.5
2989.32	203
2991	199.5
2992.68	208
2994.35	199
2996.03	208.5
2997.7	198.5
2999.38	196.5