File: muestras/ogompa/nsno_02.txt
#Acq. time (s)=	5
#Accumulations=	5
#Range (cm-¹)=	100...3000
#Windows=	3
#Autofocus=	Off
#AutoExposure=	Off
#Spike filter=	Multiple accum.
#Delay time (s)=	0
#Binning=	1
#Readout mode=	Signal
#DeNoise=	Off
#ICS correction=	Off
#Dark correction=	Off
#Inst. Process=	Off
#Instrument=	LabRAM HR Evol
#Detector=	Syncerity OE
#Objective=	x100_VIS_LWD
#Grating=	600 (500nm)
#ND Filter=	100%
#Laser=	633nm_Edge
#Hole=	100.021
#Range=	Visible
#Project=	Omar
#Sample=	chi
#Site=	f
#Title=	nsno
#Remark=
#Date=	12.09.2023 16:45
#Acquired=	12.09.2023 16:45:21
101.026	2620.5
103.592	2563
106.158	2511
108.723	2464.5
111.289	2449
113.852	2387.5
116.415	2352.5
118.976	2297
121.537	2284
124.097	2246.5
126.656	2213.5
129.215	2193
131.772	2140.5
134.327	2142.5
136.883	2098.5
139.438	2051.5
141.992	2034.5
144.545	1964.5
147.096	1977
149.648	1921.5
152.199	1913
154.747	1875
157.296	1832.5
159.843	1844
162.391	1815
164.937	1797.5
167.482	1787.5
170.025	1743
172.569	1736
175.111	1729.5
177.654	1716
180.194	1711.5
182.733	1712
185.273	1712.5
187.811	1704.5
190.348	1683
192.884	1727.5
195.419	1715.5
197.955	1734.5
200.489	1725
203.022	1739.5
205.554	1725
208.085	1747
210.615	1755.5
213.144	1760
215.673	1749.5
218.201	1759
220.728	1742.5
223.253	1774.5
225.778	1763
228.303	1761
230.826	1760.5
233.348	1768
235.87	1761
238.391	1782
240.91	1784
243.43	1809.5
245.949	1829.5
248.465	1786.5
250.983	1817
253.498	1824.5
256.013	1794
258.526	1836.5
261.039	1831
263.552	1818
266.063	1818.5
268.573	1820
271.084	1837.5
273.592	1834.5
276.1	1823
278.607	1868.5
281.113	1857.5
283.619	1885.5
286.124	1855
288.627	1893
291.13	1911.5
293.632	1919.5
296.133	1915.5
298.634	1902
301.133	1937.5
303.63	1921
306.128	1911.5
308.625	1897
311.122	1909
313.617	1902.5
316.111	1899
318.604	1874
321.098	1880
323.588	1876.5
326.08	1849.5
328.569	1830
331.059	1821
333.548	1806
336.035	1822
338.521	1817
341.008	1819.5
343.492	1807.5
345.977	1791
348.46	1790
350.942	1791.5
353.425	1797.5
355.905	1788.5
358.385	1777
360.864	1788.5
363.342	1792
365.819	1805
368.296	1787
370.771	1780.5
373.246	1792
375.72	1784
378.194	1766.5
380.666	1750.5
383.138	1767
385.609	1774
388.079	1756
390.548	1771.5
393.016	1769
395.483	1763
397.95	1747.5
400.416	1785
402.88	1818
405.345	1783.5
407.807	1826.5
410.27	1802.5
412.731	1836
415.193	1849.5
417.652	1838.5
420.112	1845.5
422.569	1846.5
425.028	1876
427.484	1851
429.939	1851
432.394	1867
434.849	1858
437.302	1876
439.754	1885
442.205	1852.5
444.656	1871
447.106	1887
449.555	1843.5
452.003	1836
454.45	1854
456.897	1858.5
459.343	1857
461.788	1863.5
464.232	1853
466.676	1839.5
469.119	1871.5
471.559	1858
474.001	1819
476.441	1862.5
478.879	1866
481.318	1880
483.756	1869
486.192	1868
488.629	1871
491.063	1905
493.498	1900.5
495.931	1902
498.365	1879.5
500.796	1921.5
503.226	1909.5
505.657	1911
508.086	1917.5
510.515	1901
512.942	1892
515.369	1930
517.796	1925.5
520.221	1916
522.645	1923.5
525.069	1915.5
527.492	1901
529.914	1928.5
532.335	1924
534.756	1925
537.175	1916.5
539.593	1908
542.011	1909.5
544.429	1902.5
546.845	1915
549.261	1924
551.675	1934
554.089	1912
556.503	1891
558.914	1900.5
561.326	1912
563.736	1920
566.147	1932.5
568.555	1918
570.964	1927.5
573.371	1930
575.777	1919
578.184	1932.5
580.588	1921
582.992	1918
585.395	1933.5
587.799	1925
590.201	1935
592.601	1960
595.001	1931
597.401	1965
599.799	1955
602.197	1981.5
604.594	1965
606.99	1969.5
609.386	1988
611.78	1979.5
614.174	1991.5
616.566	2006
618.958	2006.5
621.35	1991
623.741	2003.5
626.13	2013.5
628.519	2029.5
630.908	2017.5
633.295	2040
635.682	2073.5
638.067	2044.5
640.453	2042
642.836	2071
645.219	2054.5
647.602	2060
649.984	2039
652.364	2038.5
654.745	2036.5
657.124	2052
659.503	2059.5
661.88	2006
664.257	2041
666.635	2019.5
669.01	2033
671.384	2008
673.758	2002.5
676.131	2010
678.502	2043.5
680.874	1982
683.245	2005
685.615	1998
687.984	1991
690.353	1980
692.719	2003.5
695.086	1973.5
697.453	1981.5
699.817	1972
702.182	2009
704.545	1973.5
706.908	1965
709.27	1972
711.632	1981
713.991	1999
716.352	1978.5
718.71	2004
721.068	1997.5
723.426	1996.5
725.782	1978.5
728.138	1994.5
730.492	2025
732.846	2004
735.201	2008.5
737.553	2003
739.905	2004
742.256	1982
744.606	2003
746.956	2001.5
749.303	2009.5
751.651	2014
753.999	1999.5
756.345	1989
758.691	2006.5
761.035	1977.5
763.379	2012.5
765.723	2006.5
768.064	1995
770.407	2037
772.748	2009
775.088	2012
777.427	1984
779.765	1957.5
782.104	2005
784.44	2014.5
786.776	1996
789.113	1978.5
791.447	2000
793.78	1974
796.113	1979.5
798.445	1996
800.778	2025
803.109	2009.5
805.439	2010
807.768	2048
810.096	2038.5
812.424	2017
814.751	2063
817.078	2056
819.402	2021
821.727	2052
824.051	2052
826.374	2053.5
828.697	2078.5
831.018	2048
833.339	2094.5
835.659	2038.5
837.978	2121
840.297	2094
842.614	2077
844.932	2083.5
847.247	2098.5
849.562	2088
851.878	2073.5
854.191	2073
856.504	2068.5
858.817	2076.5
861.129	2077
863.439	2099.5
865.749	2071
868.058	2085.5
870.367	2084.5
872.676	2026.5
874.983	2048.5
877.289	2075.5
879.593	2067.5
881.898	2065.5
884.202	2011
886.506	2008
888.808	2052
891.11	2020
893.41	2008
895.711	2015
898.011	2006.5
900.309	2009
902.607	2001.5
904.904	2014.5
907.201	1990
909.496	1973.5
911.791	1980
914.085	1992
916.379	1981.5
918.671	2001
920.963	1997.5
923.255	2015
925.545	1997
927.834	1986.5
930.123	2005
932.411	2005
934.698	1993.5
936.985	1991.5
939.271	1991
941.556	2006
943.84	2029.5
946.124	2010
948.407	1994.5
950.689	2024.5
952.971	2009.5
955.25	2044.5
957.531	2023
959.81	2020
962.088	2029
964.366	2029.5
966.643	2039
968.919	2019
971.195	2027.25
973.469	2046
975.743	2018
978.016	2017
980.288	2036
982.56	2038.5
984.831	2048
987.101	2032
989.37	2032
991.638	2040.5
993.907	2037.5
996.174	2077.5
998.44	2133
1000.71	2118.5
1002.97	2047
1005.24	2039.5
1007.5	2036.5
1009.76	2034
1012.02	2024.5
1014.28	2031
1016.54	2040
1018.8	2058.5
1021.06	2004
1023.32	2044
1025.58	2056.5
1027.84	2020
1030.09	2017
1032.35	2053.5
1034.6	2031
1036.86	2045.5
1039.11	2046
1041.36	2012
1043.61	2047
1045.86	2044
1048.11	2064.5
1050.36	2070
1052.61	2051
1054.86	2068.5
1057.11	2052.5
1059.35	2058.5
1061.6	2086
1063.84	2097.5
1066.09	2090.5
1068.33	2061.5
1070.57	2034.5
1072.82	2067.5
1075.06	2080.5
1077.3	2044.5
1079.54	2056
1081.78	2048.5
1084.02	2026
1086.25	2026.5
1088.49	2039.5
1090.73	2040
1092.96	2022
1095.2	1997
1097.43	2028
1099.66	2022
1101.9	2020.5
1104.13	2030
1106.36	2031
1108.59	2006
1110.82	2012.5
1113.05	2045
1115.28	2016
1117.51	2038
1119.73	2025
1121.96	2055
1124.18	2018.5
1126.41	2039
1128.63	2023.5
1130.85	2037
1133.08	2063.5
1135.3	2081.5
1137.52	2045
1139.74	2041.5
1141.96	2068
1144.18	2087
1146.4	2086
1148.61	2123
1150.83	2107.5
1153.05	2115.5
1155.26	2175.5
1157.48	2178
1159.69	2167
1161.9	2205
1164.11	2200.5
1166.33	2211.5
1168.54	2237
1170.75	2227
1172.96	2227
1175.17	2184.5
1177.37	2178
1179.58	2136
1181.79	2158
1183.99	2140
1186.2	2163.5
1188.4	2152
1190.61	2121.5
1192.81	2127
1195.01	2128.5
1197.21	2108.71
1199.42	2128.18
1201.61	2129.42
1203.81	2151.63
1206.01	2111.22
1208.21	2100.86
1210.41	2117.88
1212.61	2103.48
1214.8	2109.58
1217	2097.79
1219.19	2116.03
1221.38	2104.04
1223.58	2095.73
1225.77	2109.93
1227.96	2100.65
1230.15	2115.72
1232.34	2107.87
1234.53	2111.58
1236.72	2109.94
1238.91	2098.6
1241.1	2121.62
1243.28	2118.24
1245.47	2138.9
1247.65	2141.7
1249.84	2119.46
1252.02	2125.05
1254.21	2141.96
1256.39	2153.25
1258.57	2142.88
1260.75	2156.7
1262.93	2154.79
1265.11	2171.22
1267.29	2188.32
1269.47	2179.14
1271.65	2182.64
1273.82	2180.29
1276	2175.57
1278.17	2184.61
1280.35	2189.85
1282.52	2182.7
1284.69	2161.98
1286.87	2177.44
1289.04	2183.67
1291.21	2195.22
1293.38	2179.43
1295.55	2196.33
1297.72	2198.48
1299.89	2184.69
1302.06	2176.37
1304.22	2181.13
1306.39	2173.3
1308.43	2152.5
1310.6	2187.5
1312.78	2176.5
1314.96	2178.5
1317.13	2203
1319.3	2174
1321.47	2153
1323.65	2178
1325.82	2158.5
1327.99	2147.5
1330.16	2141.5
1332.32	2137.5
1334.49	2135
1336.66	2136
1338.83	2110.5
1340.99	2123.5
1343.16	2127
1345.32	2124.5
1347.49	2066
1349.65	2054.5
1351.81	2064
1353.98	2067
1356.14	2077.5
1358.3	2061
1360.46	2035.5
1362.62	2069.5
1364.78	2064
1366.93	2045
1369.09	2041.5
1371.25	2046.5
1373.4	2023
1375.56	2028.5
1377.71	2052.5
1379.87	2032
1382.02	2059.5
1384.17	2037
1386.32	2041
1388.47	2034
1390.63	2021.5
1392.77	2025.5
1394.92	1995.5
1397.07	2015
1399.22	2035.5
1401.37	2045.5
1403.51	2028
1405.66	2013
1407.8	2063.5
1409.95	2061.5
1412.09	2016.5
1414.23	2061.5
1416.38	2042.5
1418.52	2048
1420.66	2047.5
1422.8	2054
1424.94	2075
1427.08	2064
1429.21	2073.5
1431.35	2036
1433.49	2074
1435.63	2085.5
1437.76	2070
1439.89	2087
1442.03	2106
1444.16	2111.5
1446.3	2105
1448.43	2075.5
1450.56	2094.5
1452.69	2096.5
1454.82	2094
1456.95	2110.5
1459.08	2082
1461.2	2119
1463.33	2147.5
1465.46	2106.5
1467.58	2126
1469.71	2122.5
1471.83	2133.5
1473.96	2135.5
1476.08	2123
1478.2	2124.5
1480.33	2169.5
1482.45	2136.5
1484.57	2128
1486.69	2139
1488.81	2154
1490.93	2125.5
1493.04	2136.5
1495.16	2126
1497.28	2132.5
1499.39	2171
1501.51	2115
1503.62	2117
1505.74	2102
1507.85	2103
1509.96	2127.5
1512.07	2114.5
1514.19	2110.5
1516.3	2104.5
1518.41	2123
1520.52	2097
1522.62	2156
1524.73	2159.5
1526.84	2126
1528.95	2129.5
1531.05	2132.5
1533.16	2109
1535.26	2135.5
1537.37	2134
1539.47	2119
1541.57	2082.5
1543.67	2127.5
1545.78	2102
1547.88	2094.5
1549.98	2104.5
1552.07	2119
1554.17	2090
1556.27	2107
1558.37	2055
1560.47	2096
1562.56	2067.5
1564.66	2099
1566.75	2067
1568.85	2080.5
1570.94	2047.5
1573.03	2061
1575.12	2064.5
1577.21	2081.5
1579.31	2061.5
1581.4	2077
1583.49	2084.5
1585.57	2045
1587.66	2094
1589.75	2086.5
1591.84	2064
1593.92	2092
1596.01	2099.5
1598.09	2072.5
1600.18	2065.5
1602.26	2031.5
1604.34	1999.5
1606.43	1966
1608.51	1913.5
1610.59	1883.5
1612.67	1862.5
1614.75	1850
1616.83	1805
1618.91	1805.5
1620.98	1745.5
1623.06	1746.5
1625.14	1710.5
1627.21	1708
1629.29	1688
1631.36	1636
1633.43	1630.5
1635.51	1625.5
1637.58	1608.5
1639.65	1569.5
1641.72	1578.5
1643.79	1528.5
1645.86	1535.5
1647.93	1507
1650	1515
1652.07	1493.5
1654.14	1480.5
1656.2	1450
1658.27	1424
1660.34	1429
1662.4	1425
1664.46	1401
1666.53	1399.5
1668.59	1389.5
1670.65	1406
1672.71	1345.5
1674.77	1360.5
1676.83	1355.5
1678.89	1344.5
1680.95	1350.5
1683.01	1349.5
1685.07	1314.5
1687.13	1330.5
1689.18	1301
1691.24	1294.5
1693.29	1294.5
1695.35	1289
1697.4	1262
1699.45	1275
1701.51	1287.5
1703.56	1273
1705.61	1255
1707.66	1261.5
1709.71	1244
1711.76	1260.5
1713.81	1234.5
1715.86	1245
1717.9	1242
1719.95	1252
1722	1239
1724.04	1248.5
1726.09	1225
1728.13	1223
1730.17	1199
1732.22	1211
1734.26	1209
1736.3	1211.5
1738.34	1196.5
1740.38	1202.5
1742.42	1174.5
1744.46	1191
1746.5	1180.5
1748.54	1168.5
1750.57	1182
1752.61	1156.5
1754.65	1165
1756.68	1166
1758.72	1150
1760.75	1123.5
1762.78	1161
1764.82	1148
1766.85	1127
1768.88	1126.5
1770.91	1125.5
1772.94	1138
1774.97	1132
1777	1131.5
1779.03	1096.5
1781.06	1110.5
1783.08	1106
1785.11	1095
1787.14	1103
1789.16	1099.5
1791.18	1079
1793.21	1082
1795.23	1068.5
1797.26	1051.5
1799.28	1101
1801.3	1071.5
1803.32	1075
1805.34	1072.5
1807.36	1069
1809.38	1061
1811.4	1037.5
1813.41	1052
1815.43	1042.5
1817.45	1057.5
1819.46	1040.5
1821.48	1056.5
1823.49	1038.5
1825.51	1026.5
1827.52	1035.5
1829.53	1028.5
1831.54	1036.5
1833.56	1014
1835.57	1020.5
1837.58	998.5
1839.59	1008.5
1841.59	981.5
1843.6	1015
1845.61	999.5
1847.62	987.5
1849.62	995.5
1851.63	991.5
1853.64	980.5
1855.64	1000
1857.64	985
1859.65	974
1861.65	998.5
1863.65	969.5
1865.65	960.5
1867.65	978.5
1869.65	979
1871.65	963
1873.65	929
1875.65	959
1877.65	963
1879.65	958.5
1881.64	946
1883.64	943
1885.63	953.5
1887.63	949
1889.62	955.5
1891.62	953
1893.61	949
1895.6	946
1897.59	943.5
1899.58	929
1901.57	921.5
1903.56	945.5
1905.55	941.5
1907.54	922
1909.53	936
1911.52	918.5
1913.5	930.5
1915.49	932
1917.48	927
1919.46	908
1921.44	888.5
1923.43	912
1925.41	916
1927.39	917
1929.38	898.5
1931.36	912
1933.34	893
1935.32	908
1937.3	896.5
1939.28	878
1941.25	894.5
1943.23	871
1945.21	879.5
1947.18	874
1949.16	888
1951.13	882
1953.11	875.5
1955.08	878
1957.06	869.5
1959.03	889
1961	882
1962.97	873.5
1964.94	848.5
1966.91	833
1968.88	870
1970.85	860
1972.82	838
1974.79	853
1976.76	859
1978.72	844.5
1980.69	852
1982.65	851.5
1984.62	860
1986.58	852.5
1988.55	858
1990.51	832
1992.47	858
1994.43	833
1996.39	828.5
1998.36	825.5
2000.31	824
2002.27	834.5
2004.23	802
2006.19	814.5
2008.15	818
2010.11	824
2012.06	816
2014.02	830.5
2015.97	796.5
2017.93	809
2019.88	810.5
2021.83	809
2023.79	797
2025.74	818
2027.69	785
2029.64	796
2031.59	805
2033.54	804
2035.49	783
2037.44	775.5
2039.39	806
2041.34	782
2043.28	780
2045.23	799
2047.17	790
2049.12	779
2051.06	799
2053.01	776
2054.95	782
2056.89	786
2058.84	764.5
2060.78	743.5
2062.72	760.5
2064.66	775
2066.6	767.5
2068.54	780.5
2070.48	778
2072.41	767.5
2074.35	763.5
2076.29	754
2078.22	764
2080.16	755
2082.09	751.5
2084.03	753
2085.96	753.5
2087.9	750
2089.83	751
2091.76	723.5
2093.69	750
2095.62	761.5
2097.55	752
2099.48	726
2101.41	753.5
2103.34	746
2105.27	730.5
2107.19	743.5
2109.12	770.5
2111.05	751.5
2112.97	775
2114.9	769.5
2116.82	786.5
2118.75	800
2120.67	796.5
2122.59	810
2124.51	832.5
2126.43	835.5
2128.36	837.5
2130.28	836
2132.2	823
2134.11	792
2136.03	799.5
2137.95	750.5
2139.87	770.5
2141.78	770
2143.7	749
2145.62	740.918
2147.53	733.143
2149.45	734.151
2151.36	718.827
2153.27	732.838
2155.19	711.319
2157.1	698.848
2159.01	700.753
2160.92	694.721
2162.83	688.3
2164.74	700.048
2166.65	687.514
2168.56	669.178
2170.47	666.201
2172.37	668.208
2174.28	672.421
2176.19	673.088
2178.09	665.653
2180	660.711
2181.9	650.983
2183.81	647.198
2185.71	648.521
2187.61	638.14
2189.51	650.752
2191.42	648.953
2193.32	661.514
2195.22	631.992
2197.12	643.109
2199.02	641.549
2200.92	635.885
2202.81	639.199
2204.71	634.884
2206.61	638.438
2208.5	643.972
2210.4	635.206
2212.3	624.621
2214.19	624.926
2216.08	633.611
2217.98	628.117
2219.87	623.68
2221.76	621.188
2223.65	621.761
2225.55	623.199
2227.44	617.602
2229.33	624.766
2231.22	618.991
2233.11	629.066
2234.99	625.274
2236.88	615.193
2238.77	620.238
2240.66	624.266
2242.06	639
2243.96	618
2245.85	626
2247.75	628
2249.64	615
2251.54	626.5
2253.43	608
2255.32	610.5
2257.21	611
2259.1	603.5
2260.99	601
2262.89	613.5
2264.77	599.5
2266.66	589
2268.55	583
2270.44	575.5
2272.33	599.5
2274.21	600
2276.1	589
2277.98	583
2279.87	587.5
2281.75	585
2283.64	581
2285.52	585
2287.4	568
2289.29	583.5
2291.17	577
2293.05	572.5
2294.93	576.5
2296.81	567
2298.69	574.5
2300.57	548
2302.44	569
2304.32	568
2306.2	571
2308.08	565.5
2309.95	572
2311.83	560.5
2313.7	556
2315.58	554
2317.45	544
2319.32	556.5
2321.2	555
2323.07	549.5
2324.94	563.5
2326.81	554.5
2328.68	553
2330.55	547
2332.42	543
2334.29	545.5
2336.16	530.5
2338.02	542.5
2339.89	536
2341.76	534
2343.62	549
2345.49	541.5
2347.35	530.5
2349.22	542
2351.08	537
2352.94	536
2354.81	531.5
2356.67	535
2358.53	530.5
2360.39	552.5
2362.25	550.5
2364.11	539.5
2365.97	535.5
2367.83	515
2369.69	548
2371.55	523
2373.4	527
2375.26	515
2377.11	523.5
2378.97	532.5
2380.83	518
2382.68	520
2384.53	528.5
2386.39	522
2388.24	511
2390.09	517.5
2391.94	524.5
2393.79	516.5
2395.64	517
2397.49	514
2399.34	512
2401.19	513
2403.04	500
2404.89	504
2406.74	513.5
2408.58	528
2410.43	519
2412.27	503.5
2414.12	510
2415.96	504
2417.81	500
2419.65	490
2421.49	486
2423.34	495
2425.18	491.5
2427.02	493
2428.86	496.5
2430.7	477.5
2432.54	495
2434.38	493
2436.22	492.5
2438.05	482.5
2439.89	496
2441.73	500
2443.56	478.5
2445.4	487.5
2447.24	485
2449.07	475
2450.9	477.5
2452.74	490
2454.57	480
2456.4	472.5
2458.23	478.5
2460.07	486.5
2461.9	469
2463.73	482.5
2465.56	477
2467.39	481.5
2469.21	483
2471.04	481.5
2472.87	484.5
2474.7	479
2476.52	471.5
2478.35	463
2480.17	477
2482	470
2483.82	467.5
2485.65	463
2487.47	455.5
2489.29	463.5
2491.12	459
2492.94	469
2494.76	464
2496.58	473
2498.4	478.5
2500.22	459
2502.04	472
2503.86	449
2505.67	460.5
2507.49	452.5
2509.31	442
2511.12	452
2512.94	446
2514.76	450.5
2516.57	452
2518.38	454.5
2520.2	447
2522.01	445.5
2523.82	449.5
2525.64	451.5
2527.45	448
2529.26	453.5
2531.07	447.5
2532.88	433.5
2534.69	447.5
2536.5	443
2538.31	443
2540.11	452
2541.92	456
2543.73	430.5
2545.53	438.5
2547.34	451
2549.14	432.5
2550.95	432
2552.75	436
2554.56	443.5
2556.36	422
2558.16	444.5
2559.96	430
2561.76	428
2563.57	439
2565.37	417
2567.17	425.5
2568.96	422
2570.76	423.5
2572.56	422
2574.36	433
2576.16	419.5
2577.95	414
2579.75	427
2581.54	425.5
2583.34	424.5
2585.13	425.5
2586.93	404
2588.72	417.5
2590.51	424
2592.31	419.5
2594.1	425.5
2595.89	411.5
2597.68	408.5
2599.47	410
2601.26	408
2603.05	421
2604.84	408.5
2606.63	411
2608.42	418
2610.2	403.5
2611.99	402
2613.78	410
2615.56	401.5
2617.35	401.5
2619.13	402
2620.91	404.5
2622.7	408.5
2624.48	413
2626.26	398.5
2628.04	398
2629.83	401
2631.61	407
2633.39	392
2635.17	397
2636.95	402.5
2638.73	400.5
2640.5	382.5
2642.28	385
2644.06	391
2645.84	396.5
2647.61	387.5
2649.39	379
2651.16	391
2652.94	382
2654.71	375
2656.49	382.5
2658.26	391
2660.03	401.5
2661.8	388.5
2663.57	386.5
2665.35	371.5
2667.12	375.5
2668.89	386
2670.66	379
2672.42	376
2674.19	384.5
2675.96	391
2677.73	379.5
2679.49	381
2681.26	385.5
2683.03	371
2684.79	379.5
2686.56	376.5
2688.32	383.5
2690.09	373.5
2691.85	373
2693.61	373
2695.37	350
2697.14	361
2698.9	368
2700.66	370.5
2702.42	372.5
2704.18	370.5
2705.94	363.5
2707.7	375.5
2709.45	371
2711.21	369.5
2712.97	368.5
2714.72	366
2716.48	364.5
2718.24	369.5
2719.99	370
2721.75	376.5
2723.5	361.5
2725.25	362.5
2727.01	359.5
2728.76	375
2730.51	356
2732.26	354
2734.01	365
2735.76	364.5
2737.51	355.5
2739.26	354
2741.01	366.5
2742.76	358.5
2744.51	356
2746.26	346
2748	359.5
2749.75	348.5
2751.5	359
2753.24	347.5
2754.99	347
2756.73	348.5
2758.47	338
2760.22	351
2761.96	345
2763.7	347
2765.44	338.5
2767.19	341
2768.93	334.5
2770.67	347
2772.41	331.5
2774.15	346.5
2775.89	332.5
2777.62	319
2779.36	326
2781.1	330
2782.84	328.5
2784.57	333
2786.31	328
2788.04	340
2789.78	324
2791.51	328.5
2793.24	334.5
2794.98	317.5
2796.71	328
2798.44	327.5
2800.18	324.5
2801.91	327
2803.64	326
2805.37	334.5
2807.1	331
2808.83	322.5
2810.55	331.5
2812.28	334
2814.01	319
2815.74	325
2817.46	329.5
2819.19	327
2820.92	317.5
2822.64	326
2824.37	324.5
2826.09	329
2827.81	326.5
2829.54	326
2831.26	321
2832.98	328
2834.71	326
2836.43	323
2838.15	326.5
2839.87	333
2841.59	324
2843.31	331
2845.02	348
2846.74	347
2848.46	349
2850.18	360.5
2851.9	364
2853.61	357.5
2855.33	354
2857.04	353
2858.76	346
2860.47	358
2862.19	352
2863.9	354.5
2865.61	351
2867.32	359
2869.04	364.5
2870.75	349
2872.46	348
2874.17	357
2875.88	341
2877.59	345.5
2879.3	349
2881	348.5
2882.71	347
2884.42	347.5
2886.13	350.5
2887.83	349.5
2889.54	355.5
2891.24	352.5
2892.95	349
2894.65	355
2896.36	357.5
2898.06	351.5
2899.76	358
2901.47	361.5
2903.17	348
2904.87	354.5
2906.57	354
2908.27	359.5
2909.97	352.5
2911.67	351.5
2913.37	364
2915.07	364.5
2916.77	349
2918.47	356
2920.16	359.5
2921.86	363.5
2923.55	361
2925.25	367.5
2926.94	374
2928.64	353
2930.33	360.5
2932.03	357.5
2933.72	364
2935.41	360
2937.11	348
2938.8	350.5
2940.49	341
2942.18	342.5
2943.87	350.5
2945.56	340.5
2947.25	329.5
2948.94	320.5
2950.63	330.5
2952.31	326.5
2954	316.5
2955.69	308
2957.37	304
2959.06	300
2960.75	301
2962.43	305
2964.11	301
2965.8	292
2967.48	298.5
2969.16	299
2970.85	294
2972.53	289
2974.21	294.5
2975.89	300
2977.57	287.5
2979.25	274
2980.93	288
2982.61	286
2984.29	275.5
2985.97	281
2987.65	284
2989.32	271
2991	268
2992.68	272
2994.35	260.5
2996.03	257
2997.7	275
2999.38	255