File: muestras/ogompa/nsno_13.txt
#Acq. time (s)=	5
#Accumulations=	5
#Range (cm-¹)=	100...3000
#Windows=	3
#Autofocus=	Off
#AutoExposure=	Off
#Spike filter=	Multiple accum.
#Delay time (s)=	0
#Binning=	1
#Readout mode=	Signal
#DeNoise=	Off
#ICS correction=	Off
#Dark correction=	Off
#Inst. Process=	Off
#Instrument=	LabRAM HR Evol
#Detector=	Syncerity OE
#Objective=	x100_VIS_LWD
#Grating=	600 (500nm)
#ND Filter=	100%
#Laser=	633nm_Edge
#Hole=	100.021
#Range=	Visible
#Project=	Omar
#Sample=	chi
#Site=	f
#Title=	nsno
#Remark=
#Date=	12.09.2023 17:22
#Acquired=	12.09.2023 17:22:41
101.026	2398
103.592	2353.5
106.158	2314
108.723	2257.5
111.289	2222.5
113.852	2212
116.415	2187.5
118.976	2153.5
121.537	2100
124.097	2102
126.656	2099.5
129.215	2066.5
131.772	2039
134.327	2026.5
136.883	1964
139.438	1941
141.992	1927.5
144.545	1886
147.096	1847
149.648	1818
152.199	1801.5
154.747	1767.5
157.296	1734.5
159.843	1730
162.391	1697
164.937	1687.5
167.482	1687.5
170.025	1667.5
172.569	1660.5
175.111	1644.5
177.654	1640.5
180.194	1625.5
182.733	1617
185.273	1604.5
187.811	1615.5
190.348	1607
192.884	1586.5
195.419	1610.5
197.955	1610
200.489	1625
203.022	1597.5
205.554	1627
208.085	1623.5
210.615	1637.5
213.144	1629
215.673	1648.5
218.201	1618
220.728	1635
223.253	1625
225.778	1649.5
228.303	1629.5
230.826	1669
233.348	1651
235.87	1651.5
238.391	1667
240.91	1662.5
243.43	1675.5
245.949	1695
248.465	1658
250.983	1674.5
253.498	1684
256.013	1702
258.526	1694
261.039	1683.5
263.552	1714.5
266.063	1670
268.573	1682
271.084	1721.5
273.592	1698
276.1	1695
278.607	1688
281.113	1690.5
283.619	1692
286.124	1710
288.627	1722.5
291.13	1726.5
293.632	1724
296.133	1735.5
298.634	1740.5
301.133	1737.5
303.63	1742.5
306.128	1740.5
308.625	1734.5
311.122	1762.5
313.617	1740
316.111	1742.5
318.604	1720
321.098	1722
323.588	1703.5
326.08	1698
328.569	1679.5
331.059	1688.5
333.548	1694.5
336.035	1702
338.521	1666
341.008	1669
343.492	1661
345.977	1670.5
348.46	1676
350.942	1684.5
353.425	1648
355.905	1670.5
358.385	1670.5
360.864	1655.5
363.342	1685.5
365.819	1673.5
368.296	1674
370.771	1670.5
373.246	1630.5
375.72	1674.5
378.194	1679.5
380.666	1634.5
383.138	1664.5
385.609	1654.5
388.079	1674.5
390.548	1651
393.016	1673.5
395.483	1664.5
397.95	1644
400.416	1660
402.88	1651
405.345	1662
407.807	1679.5
410.27	1692.5
412.731	1687.5
415.193	1697.5
417.652	1730
420.112	1710.5
422.569	1724.5
425.028	1746
427.484	1739.5
429.939	1710
432.394	1744.5
434.849	1739.5
437.302	1736
439.754	1733
442.205	1758.5
444.656	1739.5
447.106	1728.5
449.555	1768.5
452.003	1748
454.45	1761
456.897	1731.5
459.343	1759
461.788	1734
464.232	1739.5
466.676	1743.5
469.119	1733.5
471.559	1748
474.001	1736
476.441	1731.5
478.879	1737.5
481.318	1756.5
483.756	1755.5
486.192	1774
488.629	1800.5
491.063	1793
493.498	1783.5
495.931	1769
498.365	1822
500.796	1803.5
503.226	1831.5
505.657	1811
508.086	1802
510.515	1801
512.942	1818
515.369	1787
517.796	1770.5
520.221	1786
522.645	1776
525.069	1756.5
527.492	1776
529.914	1780.5
532.335	1769.5
534.756	1765
537.175	1768
539.593	1768
542.011	1770.5
544.429	1764
546.845	1757
549.261	1779.5
551.675	1769.5
554.089	1773.5
556.503	1760
558.914	1759
561.326	1769
563.736	1768.5
566.147	1784
568.555	1789
570.964	1723
573.371	1771.5
575.777	1754
578.184	1768
580.588	1774.5
582.992	1805.5
585.395	1763.5
587.799	1783.5
590.201	1762.5
592.601	1785
595.001	1777
597.401	1806.5
599.799	1787
602.197	1784
604.594	1812
606.99	1805.5
609.386	1834
611.78	1840
614.174	1831
616.566	1837.5
618.958	1826
621.35	1837.5
623.741	1824
626.13	1837
628.519	1850.5
630.908	1866.5
633.295	1866
635.682	1865
638.067	1855.5
640.453	1887.5
642.836	1863.5
645.219	1894
647.602	1853.5
649.984	1861.5
652.364	1857.5
654.745	1880.5
657.124	1861.5
659.503	1838.5
661.88	1845.5
664.257	1856
666.635	1863.5
669.01	1862
671.384	1858
673.758	1835
676.131	1838
678.502	1817
680.874	1853.5
683.245	1831.5
685.615	1796.5
687.984	1828
690.353	1814
692.719	1808.5
695.086	1808
697.453	1833
699.817	1819.5
702.182	1799.5
704.545	1814
706.908	1838.5
709.27	1792
711.632	1808.5
713.991	1831.5
716.352	1825
718.71	1845
721.068	1828.5
723.426	1821.5
725.782	1826
728.138	1831.5
730.492	1868.5
732.846	1847.5
735.201	1839.5
737.553	1833
739.905	1819.5
742.256	1813.5
744.606	1829
746.956	1827.5
749.303	1831
751.651	1818.5
753.999	1825.5
756.345	1815
758.691	1790
761.035	1798.5
763.379	1788
765.723	1800.5
768.064	1825.5
770.407	1798
772.748	1822.5
775.088	1811
777.427	1810.5
779.765	1810
782.104	1811.5
784.44	1816.5
786.776	1812
789.113	1786.5
791.447	1806
793.78	1794.5
796.113	1803
798.445	1811.5
800.778	1822
803.109	1822
805.439	1825.5
807.768	1832
810.096	1820
812.424	1821.5
814.751	1872
817.078	1866
819.402	1872.5
821.727	1883.5
824.051	1887
826.374	1895
828.697	1876.5
831.018	1870
833.339	1862.5
835.659	1868
837.978	1896.5
840.297	1863.5
842.614	1857
844.932	1892.5
847.247	1879.5
849.562	1863.5
851.878	1869.5
854.191	1876
856.504	1886.5
858.817	1894
861.129	1874.5
863.439	1868
865.749	1858
868.058	1869.5
870.367	1858
872.676	1844.5
874.983	1848.5
877.289	1831.5
879.593	1822.5
881.898	1817
884.202	1818
886.506	1820
888.808	1803
891.11	1826.5
893.41	1804.5
895.711	1784
898.011	1809
900.309	1769.5
902.607	1796.5
904.904	1783
907.201	1770
909.496	1774.5
911.791	1769.5
914.085	1759
916.379	1808
918.671	1791
920.963	1784.5
923.255	1783.5
925.545	1777
927.834	1784
930.123	1798.5
932.411	1764.5
934.698	1809.5
936.985	1775
939.271	1786.5
941.556	1798
943.84	1801
946.124	1791.5
948.407	1795
950.689	1812.5
952.971	1813
955.25	1772.5
957.531	1803.5
959.81	1781.5
962.088	1797
964.366	1808.5
966.643	1815
968.919	1790
971.195	1824.5
973.469	1820.5
975.743	1796.5
978.016	1807
980.288	1772.5
982.56	1828
984.831	1799
987.101	1805.5
989.37	1804
991.638	1821
993.907	1810
996.174	1811
998.44	1859.5
1000.71	1835.5
1002.97	1833
1005.24	1810
1007.5	1804
1009.76	1788.5
1012.02	1810
1014.28	1761.5
1016.54	1776
1018.8	1788
1021.06	1797
1023.32	1810.5
1025.58	1819
1027.84	1817
1030.09	1800
1032.35	1814
1034.6	1808.5
1036.86	1802.5
1039.11	1798
1041.36	1808.5
1043.61	1809.5
1045.86	1797
1048.11	1798
1050.36	1826.5
1052.61	1836
1054.86	1807.5
1057.11	1809
1059.35	1784
1061.6	1784.5
1063.84	1807.5
1066.09	1803
1068.33	1781.5
1070.57	1796.5
1072.82	1819
1075.06	1807
1077.3	1803.5
1079.54	1801
1081.78	1764.5
1084.02	1772.5
1086.25	1814
1088.49	1780
1090.73	1767
1092.96	1773.5
1095.2	1765.5
1097.43	1727
1099.66	1774
1101.9	1779.5
1104.13	1778
1106.36	1761.5
1108.59	1763.5
1110.82	1778
1113.05	1761.5
1115.28	1776.5
1117.51	1771.5
1119.73	1760
1121.96	1778
1124.18	1772
1126.41	1752
1128.63	1762.5
1130.85	1785.5
1133.08	1796
1135.3	1785
1137.52	1802.5
1139.74	1803.5
1141.96	1830.5
1144.18	1814
1146.4	1822
1148.61	1843
1150.83	1826
1153.05	1842
1155.26	1865
1157.48	1891
1159.69	1889.5
1161.9	1891
1164.11	1898
1166.33	1892
1168.54	1940
1170.75	1899
1172.96	1910
1175.17	1915.5
1177.37	1854.5
1179.58	1869
1181.79	1838.5
1183.99	1862.5
1186.2	1828.5
1188.4	1832.5
1190.61	1847
1192.81	1826
1195.01	1849.5
1197.21	1831.2
1199.42	1843.14
1201.61	1820.98
1203.81	1813.1
1206.01	1783.52
1208.21	1799.45
1210.41	1804.26
1212.61	1808.43
1214.8	1809.55
1217	1779.51
1219.19	1804.34
1221.38	1801.39
1223.58	1787.43
1225.77	1805.5
1227.96	1805.59
1230.15	1803.64
1232.34	1780.82
1234.53	1809.54
1236.72	1794.28
1238.91	1790.23
1241.1	1798.49
1243.28	1796.82
1245.47	1807.13
1247.65	1783.42
1249.84	1787.61
1252.02	1795.02
1254.21	1799.33
1256.39	1807.06
1258.57	1834.67
1260.75	1819.05
1262.93	1813.97
1265.11	1797.88
1267.29	1823.59
1269.47	1818.17
1271.65	1826.02
1273.82	1820.95
1276	1839.72
1278.17	1828.33
1280.35	1821.08
1282.52	1832.04
1284.69	1833.08
1286.87	1833.79
1289.04	1844.57
1291.21	1826.9
1293.38	1825.53
1295.55	1849.47
1297.72	1836.68
1299.89	1829.53
1302.06	1850.55
1304.22	1821.62
1306.39	1808.05
1308.43	1813
1310.6	1828.5
1312.78	1805.5
1314.96	1778.5
1317.13	1802
1319.3	1783
1321.47	1772.5
1323.65	1755.5
1325.82	1788
1327.99	1767.5
1330.16	1768
1332.32	1759.5
1334.49	1763
1336.66	1780.5
1338.83	1755
1340.99	1731.5
1343.16	1753
1345.32	1769
1347.49	1738
1349.65	1725
1351.81	1743
1353.98	1711.5
1356.14	1724.5
1358.3	1724.5
1360.46	1726.5
1362.62	1743
1364.78	1730
1366.93	1711.5
1369.09	1709.5
1371.25	1729.5
1373.4	1725.5
1375.56	1674
1377.71	1706
1379.87	1691.5
1382.02	1708.5
1384.17	1683
1386.32	1668
1388.47	1696
1390.63	1665
1392.77	1685
1394.92	1672
1397.07	1694
1399.22	1692.5
1401.37	1693
1403.51	1682.5
1405.66	1675
1407.8	1703.5
1409.95	1700
1412.09	1690
1414.23	1693
1416.38	1693
1418.52	1683
1420.66	1681
1422.8	1682.5
1424.94	1688.5
1427.08	1660
1429.21	1697.5
1431.35	1707
1433.49	1722
1435.63	1685.5
1437.76	1684
1439.89	1712
1442.03	1707.5
1444.16	1692
1446.3	1718.5
1448.43	1716
1450.56	1672
1452.69	1722.5
1454.82	1723
1456.95	1720.5
1459.08	1695
1461.2	1732.5
1463.33	1716
1465.46	1733.5
1467.58	1711.5
1469.71	1723.5
1471.83	1708.5
1473.96	1696
1476.08	1742.5
1478.2	1731
1480.33	1746.5
1482.45	1755
1484.57	1724.5
1486.69	1725.5
1488.81	1760.5
1490.93	1731
1493.04	1713
1495.16	1745.5
1497.28	1728
1499.39	1702.5
1501.51	1745.5
1503.62	1730.5
1505.74	1748
1507.85	1763.5
1509.96	1741
1512.07	1744
1514.19	1754.5
1516.3	1766.5
1518.41	1761
1520.52	1766.5
1522.62	1758
1524.73	1733.5
1526.84	1760.5
1528.95	1771
1531.05	1757
1533.16	1766
1535.26	1789.5
1537.37	1772
1539.47	1756
1541.57	1752.5
1543.67	1722.5
1545.78	1749
1547.88	1740
1549.98	1753
1552.07	1747.5
1554.17	1734
1556.27	1780
1558.37	1776
1560.47	1733
1562.56	1768.5
1564.66	1752
1566.75	1760
1568.85	1777.5
1570.94	1750.5
1573.03	1764.5
1575.12	1765.5
1577.21	1756.5
1579.31	1728.5
1581.4	1764
1583.49	1766
1585.57	1772.5
1587.66	1762.5
1589.75	1753.5
1591.84	1763
1593.92	1780.5
1596.01	1773.5
1598.09	1768
1600.18	1765
1602.26	1746
1604.34	1716.5
1606.43	1707.5
1608.51	1682.5
1610.59	1637.5
1612.67	1591.5
1614.75	1584.5
1616.83	1588
1618.91	1543
1620.98	1516
1623.06	1506.5
1625.14	1496.5
1627.21	1475.5
1629.29	1463.5
1631.36	1428.5
1633.43	1417.5
1635.51	1380.5
1637.58	1363.5
1639.65	1367
1641.72	1351
1643.79	1302
1645.86	1309.5
1647.93	1312
1650	1321
1652.07	1279.5
1654.14	1289
1656.2	1246
1658.27	1237.5
1660.34	1234.5
1662.4	1218.5
1664.46	1249
1666.53	1172
1668.59	1196.5
1670.65	1202.5
1672.71	1163
1674.77	1168
1676.83	1171
1678.89	1157.5
1680.95	1156
1683.01	1127
1685.07	1125
1687.13	1135.5
1689.18	1117
1691.24	1093.5
1693.29	1111.5
1695.35	1090.5
1697.4	1102.5
1699.45	1077
1701.51	1072
1703.56	1075.5
1705.61	1068
1707.66	1085
1709.71	1066.5
1711.76	1059.5
1713.81	1031
1715.86	1076
1717.9	1048
1719.95	1065
1722	1040.5
1724.04	1037
1726.09	1033
1728.13	1031
1730.17	1034.5
1732.22	1036
1734.26	1033.5
1736.3	996.5
1738.34	1009.5
1740.38	1015.5
1742.42	995
1744.46	996
1746.5	984.5
1748.54	976.5
1750.57	982
1752.61	1009
1754.65	988
1756.68	986
1758.72	968.5
1760.75	958
1762.78	966
1764.82	951.5
1766.85	950.5
1768.88	952.5
1770.91	944
1772.94	936
1774.97	947
1777	927
1779.03	947.5
1781.06	917.5
1783.08	925.5
1785.11	925.5
1787.14	903.5
1789.16	900
1791.18	918
1793.21	917
1795.23	901.5
1797.26	894.5
1799.28	901
1801.3	870
1803.32	879
1805.34	903
1807.36	905
1809.38	881.5
1811.4	878.5
1813.41	867.5
1815.43	857.5
1817.45	885.5
1819.46	867.5
1821.48	867
1823.49	858
1825.51	854
1827.52	842
1829.53	853
1831.54	861.5
1833.56	846
1835.57	840.5
1837.58	837.5
1839.59	841
1841.59	821.5
1843.6	823.5
1845.61	835.5
1847.62	814
1849.62	822
1851.63	816
1853.64	812.5
1855.64	806.5
1857.64	805.5
1859.65	818.5
1861.65	789
1863.65	818
1865.65	803.5
1867.65	792
1869.65	791
1871.65	808.5
1873.65	799.5
1875.65	799
1877.65	781
1879.65	790
1881.64	768.5
1883.64	802.5
1885.63	778
1887.63	793
1889.62	796
1891.62	765
1893.61	777.5
1895.6	788
1897.59	756
1899.58	766
1901.57	757.5
1903.56	748.5
1905.55	762
1907.54	775.5
1909.53	772.5
1911.52	753.5
1913.5	754
1915.49	753.5
1917.48	763.5
1919.46	768
1921.44	735
1923.43	763.5
1925.41	752
1927.39	749.5
1929.38	742
1931.36	736.5
1933.34	742.5
1935.32	754
1937.3	725
1939.28	747
1941.25	733.5
1943.23	757.5
1945.21	704.5
1947.18	743
1949.16	708.5
1951.13	728
1953.11	726.5
1955.08	724
1957.06	725.5
1959.03	712
1961	712
1962.97	722
1964.94	708
1966.91	708
1968.88	699.5
1970.85	708.5
1972.82	696
1974.79	688.5
1976.76	707.5
1978.72	706.5
1980.69	691.5
1982.65	691
1984.62	707.5
1986.58	710.5
1988.55	698.5
1990.51	697
1992.47	696
1994.43	696.5
1996.39	677
1998.36	685
2000.31	678
2002.27	682.5
2004.23	677
2006.19	678
2008.15	675.5
2010.11	663
2012.06	662
2014.02	677
2015.97	670
2017.93	662
2019.88	681
2021.83	662.5
2023.79	663.5
2025.74	654
2027.69	649
2029.64	641.5
2031.59	660
2033.54	667.5
2035.49	659
2037.44	664
2039.39	649
2041.34	639.5
2043.28	630
2045.23	653
2047.17	656.5
2049.12	659
2051.06	645
2053.01	652.5
2054.95	627
2056.89	634
2058.84	649.5
2060.78	623
2062.72	631.5
2064.66	634
2066.6	637
2068.54	632.5
2070.48	639
2072.41	644.5
2074.35	642.5
2076.29	627.5
2078.22	622
2080.16	636.5
2082.09	635
2084.03	618
2085.96	606
2087.9	621.5
2089.83	638
2091.76	634.5
2093.69	623
2095.62	628
2097.55	619.5
2099.48	635
2101.41	644
2103.34	645.5
2105.27	649
2107.19	658
2109.12	663.5
2111.05	662.5
2112.97	686.5
2114.9	684
2116.82	706.5
2118.75	750
2120.67	747
2122.59	769
2124.51	787
2126.43	821.5
2128.36	816.5
2130.28	836.5
2132.2	852.5
2134.11	877
2136.03	886.5
2137.95	885.5
2139.87	883
2141.78	901.5
2143.7	885.5
2145.62	906.272
2147.53	925.959
2149.45	914.934
2151.36	941.096
2153.27	923.914
2155.19	932.783
2157.1	926.032
2159.01	950.669
2160.92	938.189
2162.83	952.326
2164.74	966.299
2166.65	954.349
2168.56	951.918
2170.47	933.951
2172.37	928.904
2174.28	907.205
2176.19	889.199
2178.09	866.95
2180	841.379
2181.9	832.139
2183.81	793.074
2185.71	771.406
2187.61	741.333
2189.51	709.222
2191.42	694.265
2193.32	672.351
2195.22	656.202
2197.12	642.129
2199.02	619.841
2200.92	608.575
2202.81	593.711
2204.71	596.554
2206.61	566.755
2208.5	557.855
2210.4	564.173
2212.3	555.043
2214.19	551.593
2216.08	536.966
2217.98	543.069
2219.87	546.107
2221.76	545.294
2223.65	538.213
2225.55	528.868
2227.44	539.931
2229.33	539.508
2231.22	531.417
2233.11	537.489
2234.99	532.386
2236.88	534.054
2238.77	527.628
2240.66	539.875
2242.06	537.5
2243.96	550
2245.85	553
2247.75	534
2249.64	553
2251.54	552
2253.43	533.5
2255.32	524.5
2257.21	523
2259.1	523
2260.99	523
2262.89	510
2264.77	515.5
2266.66	486
2268.55	499
2270.44	504.5
2272.33	505
2274.21	501
2276.1	513.5
2277.98	502
2279.87	495
2281.75	494
2283.64	500.5
2285.52	495
2287.4	476
2289.29	498.5
2291.17	496
2293.05	480.5
2294.93	495
2296.81	488
2298.69	489
2300.57	485.5
2302.44	498
2304.32	490
2306.2	479.5
2308.08	470
2309.95	471
2311.83	462.5
2313.7	473
2315.58	474
2317.45	449
2319.32	469
2321.2	460.5
2323.07	467
2324.94	468
2326.81	461.5
2328.68	456.5
2330.55	464
2332.42	465.5
2334.29	467
2336.16	463
2338.02	479.5
2339.89	454
2341.76	456
2343.62	458
2345.49	462
2347.35	458
2349.22	451
2351.08	450
2352.94	456.5
2354.81	452.5
2356.67	459
2358.53	460.5
2360.39	448.5
2362.25	463
2364.11	448
2365.97	445.5
2367.83	464
2369.69	453
2371.55	453
2373.4	462
2375.26	457.5
2377.11	451
2378.97	463
2380.83	444
2382.68	453
2384.53	442.5
2386.39	439
2388.24	450.5
2390.09	451
2391.94	429
2393.79	437
2395.64	435
2397.49	438.5
2399.34	448.5
2401.19	437.5
2403.04	425.5
2404.89	431.5
2406.74	451.5
2408.58	444
2410.43	445
2412.27	430
2414.12	422
2415.96	434.5
2417.81	429
2419.65	442.5
2421.49	418
2423.34	409
2425.18	449
2427.02	411
2428.86	415
2430.7	409
2432.54	415
2434.38	410.5
2436.22	440
2438.05	428.5
2439.89	416
2441.73	417.5
2443.56	419
2445.4	426
2447.24	414.5
2449.07	409
2450.9	426
2452.74	422.5
2454.57	415.5
2456.4	420.5
2458.23	407
2460.07	405.5
2461.9	412
2463.73	413
2465.56	410
2467.39	411
2469.21	418
2471.04	404.5
2472.87	404
2474.7	397.5
2476.52	408
2478.35	399.5
2480.17	406
2482	412.5
2483.82	390
2485.65	397.5
2487.47	408
2489.29	397.5
2491.12	406
2492.94	401
2494.76	387
2496.58	388
2498.4	402.5
2500.22	398
2502.04	397.5
2503.86	402
2505.67	397
2507.49	399.5
2509.31	402
2511.12	396
2512.94	389.5
2514.76	404
2516.57	384
2518.38	385
2520.2	376
2522.01	385.5
2523.82	390
2525.64	374
2527.45	390.5
2529.26	396
2531.07	394.5
2532.88	391.5
2534.69	391.5
2536.5	382.5
2538.31	372
2540.11	388
2541.92	378.5
2543.73	383
2545.53	390
2547.34	375
2549.14	388.5
2550.95	385
2552.75	365.5
2554.56	387
2556.36	376
2558.16	369
2559.96	369
2561.76	361.5
2563.57	362.5
2565.37	383
2567.17	381.5
2568.96	376.5
2570.76	367
2572.56	360
2574.36	364
2576.16	381
2577.95	368
2579.75	350
2581.54	348.5
2583.34	362
2585.13	381.5
2586.93	368.5
2588.72	366
2590.51	356.5
2592.31	357
2594.1	355.5
2595.89	347.5
2597.68	357
2599.47	354.5
2601.26	363
2603.05	360
2604.84	349.5
2606.63	355
2608.42	354.5
2610.2	349.5
2611.99	343
2613.78	352
2615.56	346
2617.35	357
2619.13	348
2620.91	349
2622.7	343
2624.48	340
2626.26	339
2628.04	359
2629.83	342.5
2631.61	333
2633.39	342
2635.17	353
2636.95	344
2638.73	333
2640.5	339.5
2642.28	357
2644.06	338
2645.84	344.5
2647.61	329
2649.39	338
2651.16	337.5
2652.94	337.5
2654.71	332
2656.49	331
2658.26	331
2660.03	346
2661.8	330.5
2663.57	332
2665.35	325.5
2667.12	332.5
2668.89	329
2670.66	329.5
2672.42	330
2674.19	322.5
2675.96	326
2677.73	309.5
2679.49	334.5
2681.26	320
2683.03	332
2684.79	329
2686.56	317.5
2688.32	325
2690.09	322.5
2691.85	315.5
2693.61	321.5
2695.37	320.5
2697.14	325.5
2698.9	326
2700.66	328
2702.42	307
2704.18	325.5
2705.94	325
2707.7	324
2709.45	301.5
2711.21	328.5
2712.97	316.5
2714.72	317
2716.48	324.5
2718.24	323.5
2719.99	314.5
2721.75	315
2723.5	324.5
2725.25	315.5
2727.01	312
2728.76	321
2730.51	298
2732.26	308
2734.01	312.5
2735.76	300
2737.51	305
2739.26	298
2741.01	299
2742.76	307
2744.51	306.5
2746.26	308.5
2748	310.5
2749.75	295.5
2751.5	300.5
2753.24	307
2754.99	290.5
2756.73	290
2758.47	309
2760.22	295
2761.96	296
2763.7	300.5
2765.44	307.5
2767.19	298.5
2768.93	299.5
2770.67	293.5
2772.41	302.5
2774.15	293
2775.89	275
2777.62	304
2779.36	283
2781.1	288.5
2782.84	292.5
2784.57	286
2786.31	297.5
2788.04	282
2789.78	287.5
2791.51	282.5
2793.24	287
2794.98	288
2796.71	279.5
2798.44	296
2800.18	293.5
2801.91	283
2803.64	288
2805.37	284
2807.1	278
2808.83	284.5
2810.55	277
2812.28	289
2814.01	281
2815.74	285.5
2817.46	274.5
2819.19	279.5
2820.92	280
2822.64	276
2824.37	289
2826.09	274
2827.81	287.5
2829.54	277.5
2831.26	276
2832.98	283.5
2834.71	280
2836.43	274.5
2838.15	277
2839.87	281
2841.59	270
2843.31	274
2845.02	287.5
2846.74	286
2848.46	303
2850.18	291
2851.9	297.5
2853.61	295.5
2855.33	283
2857.04	296.5
2858.76	289.5
2860.47	284
2862.19	298.5
2863.9	282
2865.61	294
2867.32	293
2869.04	297.5
2870.75	294.5
2872.46	299
2874.17	291.5
2875.88	300
2877.59	287.5
2879.3	288
2881	302
2882.71	288
2884.42	297
2886.13	293
2887.83	289
2889.54	286
2891.24	284.5
2892.95	296
2894.65	290
2896.36	298.5
2898.06	290
2899.76	298.5
2901.47	309.5
2903.17	304
2904.87	297.5
2906.57	303.5
2908.27	311
2909.97	319.5
2911.67	307
2913.37	300
2915.07	303
2916.77	306.5
2918.47	308.5
2920.16	305.5
2921.86	308
2923.55	304
2925.25	307.5
2926.94	307
2928.64	316.5
2930.33	312
2932.03	316
2933.72	314.5
2935.41	302
2937.11	300
2938.8	308
2940.49	304
2942.18	315.5
2943.87	299
2945.56	294.5
2947.25	280
2948.94	286.5
2950.63	274.5
2952.31	273
2954	274.5
2955.69	268
2957.37	264
2959.06	266.5
2960.75	260.5
2962.43	260.5
2964.11	269.5
2965.8	266
2967.48	262
2969.16	265.5
2970.85	259
2972.53	265
2974.21	261
2975.89	259
2977.57	247
2979.25	249
2980.93	246
2982.61	246
2984.29	233
2985.97	242
2987.65	238
2989.32	243
2991	234.5
2992.68	242
2994.35	241.5
2996.03	225.5
2997.7	219.5
2999.38	223.5