File: muestras/ogompa/nsno_01.txt
#Acq. time (s)=	5
#Accumulations=	5
#Range (cm-¹)=	100...3000
#Windows=	3
#Autofocus=	Off
#AutoExposure=	Off
#Spike filter=	Multiple accum.
#Delay time (s)=	0
#Binning=	1
#Readout mode=	Signal
#DeNoise=	Off
#ICS correction=	Off
#Dark correction=	Off
#Inst. Process=	Off
#Instrument=	LabRAM HR Evol
#Detector=	Syncerity OE
#Objective=	x100_VIS_LWD
#Grating=	600 (500nm)
#ND Filter=	100%
#Laser=	633nm_Edge
#Hole=	100.021
#Range=	Visible
#Project=	Omar
#Sample=	chi
#Site=	f
#Title=	nsno
#Remark=
#Date=	12.09.2023 16:36
#Acquired=	12.09.2023 16:36:38
101.026	5992.5
103.592	5895
106.158	5778
108.723	5657.5
111.289	5577.5
113.852	5530.5
116.415	5414.5
118.976	5341
121.537	5286
124.097	5195
126.656	5177.5
129.215	5065.5
131.772	5029.5
134.327	4952.5
136.883	4878.5
139.438	4814
141.992	4785.5
144.545	4689.5
147.096	4612
149.648	4538
152.199	4488.5
154.747	4416
157.296	4324.5
159.843	4331
162.391	4250
164.937	4245.5
167.482	4202
170.025	4180.5
172.569	4065.5
175.111	4035.5
177.654	4006
180.194	3994
182.733	3990
185.273	4029
187.811	3974
190.348	3947
192.884	3957.5
195.419	3973
197.955	4015.5
200.489	3993
203.022	3988.5
205.554	3999
208.085	4028.5
210.615	4018
213.144	4053
215.673	4021
218.201	4013
220.728	4006
223.253	4034.5
225.778	4061.5
228.303	3994.5
230.826	4033
233.348	4043
235.87	4061.5
238.391	4083
240.91	4108
243.43	4114.5
245.949	4122.5
248.465	4138.5
250.983	4112.5
253.498	4150
256.013	4118
258.526	4153
261.039	4149
263.552	4141
266.063	4101
268.573	4136.5
271.084	4129
273.592	4131
276.1	4112.5
278.607	4139
281.113	4146.5
283.619	4153
286.124	4212.5
288.627	4244.5
291.13	4256.5
293.632	4264.5
296.133	4279.5
298.634	4310.5
301.133	4359
303.63	4335
306.128	4332
308.625	4329
311.122	4317.5
313.617	4340
316.111	4261.5
318.604	4309.5
321.098	4279
323.588	4238
326.08	4223
328.569	4187
331.059	4143
333.548	4162
336.035	4124.5
338.521	4103
341.008	4125.5
343.492	4084
345.977	4110.5
348.46	4104
350.942	4086.5
353.425	4137.5
355.905	4130
358.385	4173.5
360.864	4146
363.342	4138.5
365.819	4137.5
368.296	4125.5
370.771	4158.5
373.246	4096.5
375.72	4133
378.194	4108
380.666	4076.5
383.138	4103
385.609	4108
388.079	4083
390.548	4119.5
393.016	4121.5
395.483	4086.5
397.95	4083
400.416	4067.5
402.88	4103
405.345	4112.5
407.807	4153.5
410.27	4135.5
412.731	4192.5
415.193	4207
417.652	4219
420.112	4242
422.569	4243.5
425.028	4260
427.484	4277.5
429.939	4275
432.394	4306
434.849	4280.5
437.302	4327
439.754	4320
442.205	4341.5
444.656	4319.5
447.106	4316.5
449.555	4327.5
452.003	4279
454.45	4327
456.897	4340.5
459.343	4334
461.788	4270
464.232	4311.5
466.676	4311.5
469.119	4317
471.559	4319.5
474.001	4281.5
476.441	4329.5
478.879	4315.5
481.318	4350.5
483.756	4370
486.192	4325.5
488.629	4384.5
491.063	4345
493.498	4360
495.931	4423.5
498.365	4378
500.796	4401
503.226	4437
505.657	4428.5
508.086	4393
510.515	4411
512.942	4403.5
515.369	4395
517.796	4367.5
520.221	4402
522.645	4384.5
525.069	4383
527.492	4393.5
529.914	4393
532.335	4393.5
534.756	4404.5
537.175	4373
539.593	4361.5
542.011	4370
544.429	4360
546.845	4394
549.261	4390
551.675	4359
554.089	4353
556.503	4394
558.914	4370.5
561.326	4406
563.736	4390.5
566.147	4403.5
568.555	4407.5
570.964	4432
573.371	4413.5
575.777	4425.5
578.184	4380.5
580.588	4424
582.992	4411
585.395	4428.5
587.799	4421.5
590.201	4472
592.601	4417.5
595.001	4477.5
597.401	4464.5
599.799	4489.5
602.197	4495.5
604.594	4474.5
606.99	4513.5
609.386	4489.5
611.78	4538
614.174	4521
616.566	4518
618.958	4550
621.35	4574.5
623.741	4579
626.13	4620
628.519	4650.5
630.908	4659
633.295	4634.5
635.682	4702
638.067	4702.5
640.453	4694
642.836	4678.5
645.219	4714.5
647.602	4741.5
649.984	4702.5
652.364	4670.5
654.745	4704
657.124	4678.5
659.503	4654
661.88	4684
664.257	4707
666.635	4674.5
669.01	4627.5
671.384	4613
673.758	4629
676.131	4614
678.502	4553.5
680.874	4566
683.245	4613.5
685.615	4589
687.984	4546
690.353	4554
692.719	4565.5
695.086	4533
697.453	4558.5
699.817	4568
702.182	4570.5
704.545	4562
706.908	4546.5
709.27	4575
711.632	4569
713.991	4575.5
716.352	4543.5
718.71	4551.5
721.068	4578.5
723.426	4595
725.782	4549
728.138	4587.5
730.492	4565
732.846	4552.5
735.201	4586.5
737.553	4582
739.905	4582
742.256	4545
744.606	4590.5
746.956	4601
749.303	4592
751.651	4607
753.999	4556
756.345	4578.5
758.691	4523
761.035	4556
763.379	4555.5
765.723	4514
768.064	4591
770.407	4585
772.748	4561
775.088	4533.5
777.427	4504.5
779.765	4542
782.104	4567
784.44	4537
786.776	4564.5
789.113	4532.5
791.447	4490
793.78	4537.5
796.113	4584.5
798.445	4594.5
800.778	4556.5
803.109	4578.5
805.439	4594.5
807.768	4578
810.096	4609.5
812.424	4610
814.751	4581.5
817.078	4656
819.402	4655.5
821.727	4669.5
824.051	4670
826.374	4640.5
828.697	4695.5
831.018	4689.5
833.339	4705.5
835.659	4689.5
837.978	4721
840.297	4712
842.614	4722
844.932	4694.5
847.247	4711.5
849.562	4740
851.878	4733.5
854.191	4758.5
856.504	4742
858.817	4840
861.129	4781
863.439	4752.5
865.749	4741.5
868.058	4705.5
870.367	4736.5
872.676	4668.5
874.983	4723
877.289	4688.5
879.593	4672
881.898	4642.5
884.202	4655.5
886.506	4633
888.808	4625.5
891.11	4579
893.41	4638
895.711	4558.5
898.011	4598.5
900.309	4602
902.607	4594
904.904	4567.5
907.201	4521
909.496	4495.5
911.791	4494.5
914.085	4571
916.379	4574.5
918.671	4562
920.963	4530.5
923.255	4529
925.545	4495
927.834	4520
930.123	4567
932.411	4576.5
934.698	4571.5
936.985	4585.5
939.271	4580.5
941.556	4621
943.84	4609.5
946.124	4573.5
948.407	4577
950.689	4594
952.971	4599.5
955.25	4597.5
957.531	4614.5
959.81	4640.5
962.088	4652.5
964.366	4639
966.643	4635.5
968.919	4660
971.195	4638.25
973.469	4643
975.743	4611.5
978.016	4655
980.288	4663
982.56	4651.5
984.831	4619.5
987.101	4644
989.37	4613.5
991.638	4668
993.907	4650
996.174	4698.5
998.44	4781
1000.71	4823.5
1002.97	4723
1005.24	4699
1007.5	4659
1009.76	4664
1012.02	4651.5
1014.28	4656.5
1016.54	4630.5
1018.8	4655
1021.06	4675.5
1023.32	4644.5
1025.58	4705
1027.84	4655.5
1030.09	4703.5
1032.35	4718
1034.6	4699
1036.86	4693.5
1039.11	4717.5
1041.36	4735
1043.61	4706.5
1045.86	4674
1048.11	4756.5
1050.36	4726.5
1052.61	4701.5
1054.86	4732.5
1057.11	4741.5
1059.35	4738
1061.6	4774
1063.84	4784.5
1066.09	4787.5
1068.33	4732.5
1070.57	4785.5
1072.82	4785
1075.06	4760.5
1077.3	4751
1079.54	4746.5
1081.78	4752
1084.02	4710.5
1086.25	4743
1088.49	4706
1090.73	4704
1092.96	4752
1095.2	4711.5
1097.43	4682.5
1099.66	4721.5
1101.9	4678
1104.13	4676
1106.36	4730.5
1108.59	4690
1110.82	4728
1113.05	4714.5
1115.28	4762
1117.51	4716
1119.73	4710
1121.96	4746.5
1124.18	4746.5
1126.41	4758.5
1128.63	4781.5
1130.85	4822.5
1133.08	4780.5
1135.3	4845.5
1137.52	4821.5
1139.74	4870.5
1141.96	4906.5
1144.18	4851
1146.4	4897
1148.61	4964.5
1150.83	4985
1153.05	5035.5
1155.26	5048
1157.48	5056.5
1159.69	5116.5
1161.9	5147
1164.11	5192
1166.33	5194.5
1168.54	5231
1170.75	5242
1172.96	5223
1175.17	5259.5
1177.37	5201.5
1179.58	5152
1181.79	5181
1183.99	5132
1186.2	5147.5
1188.4	5124
1190.61	5167.5
1192.81	5114
1195.01	5099.5
1197.21	5126.15
1199.42	5138.88
1201.61	5103.44
1203.81	5159.23
1206.01	5159.29
1208.21	5130.98
1210.41	5162.33
1212.61	5148.14
1214.8	5154.19
1217	5188.31
1219.19	5205.83
1221.38	5150.97
1223.58	5204.88
1225.77	5224.51
1227.96	5280.28
1230.15	5211.81
1232.34	5286.61
1234.53	5284.3
1236.72	5309.88
1238.91	5317.12
1241.1	5347.47
1243.28	5343.86
1245.47	5378.84
1247.65	5380.44
1249.84	5449.09
1252.02	5425.74
1254.21	5487.35
1256.39	5477.01
1258.57	5482.48
1260.75	5512.56
1262.93	5582.84
1265.11	5564.63
1267.29	5585.7
1269.47	5616.99
1271.65	5650.42
1273.82	5641.18
1276	5674.1
1278.17	5727.24
1280.35	5738.8
1282.52	5710.24
1284.69	5770.81
1286.87	5769.17
1289.04	5816.3
1291.21	5816.84
1293.38	5878.87
1295.55	5870.52
1297.72	5900.2
1299.89	5875.77
1302.06	5907.37
1304.22	5930.8
1306.39	5916.02
1308.43	5974.5
1310.6	5932.5
1312.78	5929
1314.96	5895.5
1317.13	5854
1319.3	5875
1321.47	5874.5
1323.65	5861
1325.82	5846
1327.99	5858
1330.16	5805
1332.32	5806
1334.49	5818.5
1336.66	5793
1338.83	5800
1340.99	5723
1343.16	5740
1345.32	5756
1347.49	5739
1349.65	5676
1351.81	5624
1353.98	5702.5
1356.14	5782
1358.3	5727.5
1360.46	5760
1362.62	5754.5
1364.78	5740
1366.93	5767.5
1369.09	5764.5
1371.25	5699
1373.4	5707.5
1375.56	5749.5
1377.71	5718
1379.87	5746
1382.02	5669.5
1384.17	5685
1386.32	5704.5
1388.47	5654
1390.63	5663
1392.77	5676.5
1394.92	5651.5
1397.07	5692
1399.22	5621.5
1401.37	5670.5
1403.51	5664.5
1405.66	5637
1407.8	5666.5
1409.95	5665
1412.09	5669.5
1414.23	5606
1416.38	5606
1418.52	5693.5
1420.66	5678.5
1422.8	5644
1424.94	5635
1427.08	5673.5
1429.21	5697
1431.35	5653
1433.49	5692.5
1435.63	5736.5
1437.76	5713.5
1439.89	5727.5
1442.03	5793.5
1444.16	5803.5
1446.3	5788
1448.43	5809
1450.56	5811.5
1452.69	5776
1454.82	5823.5
1456.95	5782.5
1459.08	5812
1461.2	5845
1463.33	5858.5
1465.46	5807.5
1467.58	5764.5
1469.71	5849.5
1471.83	5826
1473.96	5870
1476.08	5902.5
1478.2	5910.5
1480.33	5922.5
1482.45	5968.5
1484.57	5921
1486.69	5981
1488.81	5955.5
1490.93	6024.5
1493.04	5980.5
1495.16	5989
1497.28	5976
1499.39	6033
1501.51	6009.5
1503.62	6046.5
1505.74	6037
1507.85	6080
1509.96	6040.5
1512.07	6113
1514.19	6099
1516.3	6146.5
1518.41	6007
1520.52	6121.5
1522.62	6041
1524.73	6244
1526.84	6131
1528.95	6194
1531.05	6136.5
1533.16	6158.5
1535.26	6168.5
1537.37	6152
1539.47	6147
1541.57	6087
1543.67	6143
1545.78	6154.5
1547.88	6135
1549.98	6150.5
1552.07	6096.5
1554.17	6113.5
1556.27	6154
1558.37	6092
1560.47	6132.5
1562.56	6102
1564.66	6158.5
1566.75	6096.5
1568.85	6174
1570.94	6129
1573.03	6097.5
1575.12	6080.5
1577.21	6110.5
1579.31	6095
1581.4	6056
1583.49	6066.5
1585.57	6090
1587.66	6011
1589.75	6049
1591.84	6023.5
1593.92	6036.5
1596.01	6025.5
1598.09	6020.5
1600.18	5982.5
1602.26	5908.5
1604.34	5821
1606.43	5783.5
1608.51	5718.5
1610.59	5567.5
1612.67	5516
1614.75	5408.5
1616.83	5382
1618.91	5307.5
1620.98	5226.5
1623.06	5079.5
1625.14	5044.5
1627.21	4958
1629.29	4894.5
1631.36	4812
1633.43	4734.5
1635.51	4626
1637.58	4605
1639.65	4525
1641.72	4434
1643.79	4392
1645.86	4318
1647.93	4306
1650	4231
1652.07	4141
1654.14	4093
1656.2	4021
1658.27	3988.5
1660.34	3919
1662.4	3882.5
1664.46	3843.5
1666.53	3796.5
1668.59	3746.5
1670.65	3721
1672.71	3678.5
1674.77	3653.5
1676.83	3673
1678.89	3617
1680.95	3554
1683.01	3556
1685.07	3481
1687.13	3513.5
1689.18	3475.5
1691.24	3474
1693.29	3397.5
1695.35	3433
1697.4	3370
1699.45	3350
1701.51	3361.5
1703.56	3312
1705.61	3328.5
1707.66	3298
1709.71	3302
1711.76	3269
1713.81	3237
1715.86	3232
1717.9	3293
1719.95	3209.5
1722	3212.5
1724.04	3165
1726.09	3211.5
1728.13	3173
1730.17	3173
1732.22	3111.5
1734.26	3146
1736.3	3095.5
1738.34	3056.5
1740.38	3104.5
1742.42	3052
1744.46	3079.5
1746.5	3062
1748.54	3032
1750.57	3004
1752.61	2997
1754.65	2994
1756.68	2947
1758.72	2969.5
1760.75	2972.5
1762.78	2958.5
1764.82	2915
1766.85	2906
1768.88	2905.5
1770.91	2893.5
1772.94	2867.5
1774.97	2873.5
1777	2882
1779.03	2844.5
1781.06	2825
1783.08	2818.5
1785.11	2853.5
1787.14	2774.5
1789.16	2815.5
1791.18	2818.5
1793.21	2773
1795.23	2750
1797.26	2777.5
1799.28	2738.5
1801.3	2710.5
1803.32	2748
1805.34	2749.5
1807.36	2697.5
1809.38	2681.5
1811.4	2662.5
1813.41	2639.5
1815.43	2630.5
1817.45	2654
1819.46	2652
1821.48	2620
1823.49	2629
1825.51	2636.5
1827.52	2593.5
1829.53	2611.5
1831.54	2564.5
1833.56	2553
1835.57	2580.5
1837.58	2536
1839.59	2544
1841.59	2544.5
1843.6	2539
1845.61	2492
1847.62	2543.5
1849.62	2494
1851.63	2483.5
1853.64	2513
1855.64	2455
1857.64	2467
1859.65	2458.5
1861.65	2444.5
1863.65	2422
1865.65	2418
1867.65	2398.5
1869.65	2417.5
1871.65	2421.5
1873.65	2401
1875.65	2380.5
1877.65	2359.5
1879.65	2350.5
1881.64	2355
1883.64	2370
1885.63	2347
1887.63	2354
1889.62	2369
1891.62	2339.5
1893.61	2337
1895.6	2341.5
1897.59	2312.5
1899.58	2319.5
1901.57	2323
1903.56	2330.5
1905.55	2321.5
1907.54	2317.5
1909.53	2301.5
1911.52	2320.5
1913.5	2271
1915.49	2275.5
1917.48	2250
1919.46	2276.5
1921.44	2252.5
1923.43	2244.5
1925.41	2240.5
1927.39	2237.5
1929.38	2255.5
1931.36	2232.5
1933.34	2204
1935.32	2213.5
1937.3	2189.5
1939.28	2202
1941.25	2210
1943.23	2193
1945.21	2182.5
1947.18	2201
1949.16	2172
1951.13	2160.5
1953.11	2170
1955.08	2170
1957.06	2160
1959.03	2139.5
1961	2157
1962.97	2137.5
1964.94	2107
1966.91	2127.5
1968.88	2119.5
1970.85	2092.5
1972.82	2093
1974.79	2096.5
1976.76	2096
1978.72	2057.5
1980.69	2079
1982.65	2072
1984.62	2069.5
1986.58	2056.5
1988.55	2053.5
1990.51	2053
1992.47	2051.5
1994.43	2019.5
1996.39	2020.5
1998.36	2012
2000.31	2024.5
2002.27	2002
2004.23	2032.5
2006.19	2011
2008.15	1969
2010.11	1981
2012.06	1966
2014.02	1989.5
2015.97	1978.5
2017.93	1988
2019.88	1945.5
2021.83	1953
2023.79	1932
2025.74	1960.5
2027.69	1935
2029.64	1937.5
2031.59	1952.5
2033.54	1905.5
2035.49	1911.5
2037.44	1901.5
2039.39	1892.5
2041.34	1936.5
2043.28	1913.5
2045.23	1877
2047.17	1890.5
2049.12	1898.5
2051.06	1894
2053.01	1862
2054.95	1884.5
2056.89	1856.5
2058.84	1865.5
2060.78	1857
2062.72	1864
2064.66	1845.5
2066.6	1852
2068.54	1825
2070.48	1832
2072.41	1814.5
2074.35	1808
2076.29	1819.5
2078.22	1808
2080.16	1784.5
2082.09	1797.5
2084.03	1788.5
2085.96	1798.5
2087.9	1799.5
2089.83	1786
2091.76	1808.5
2093.69	1771
2095.62	1775.5
2097.55	1823
2099.48	1791
2101.41	1762.5
2103.34	1774.5
2105.27	1768
2107.19	1784
2109.12	1770.5
2111.05	1755
2112.97	1785.5
2114.9	1793.5
2116.82	1819.5
2118.75	1810
2120.67	1819
2122.59	1845
2124.51	1856.5
2126.43	1866
2128.36	1861
2130.28	1878
2132.2	1874.5
2134.11	1872.5
2136.03	1847.5
2137.95	1829
2139.87	1869
2141.78	1869.5
2143.7	1842
2145.62	1859.82
2147.53	1853.73
2149.45	1837.38
2151.36	1814.48
2153.27	1780.99
2155.19	1791.04
2157.1	1771.99
2159.01	1776.89
2160.92	1739.19
2162.83	1742.35
2164.74	1733.51
2166.65	1699.75
2168.56	1683.9
2170.47	1678.5
2172.37	1640.01
2174.28	1639.93
2176.19	1634.86
2178.09	1621.39
2180	1590.27
2181.9	1563.93
2183.81	1552.17
2185.71	1538.07
2187.61	1532.71
2189.51	1527.23
2191.42	1499.47
2193.32	1478.4
2195.22	1492.86
2197.12	1500.17
2199.02	1490.04
2200.92	1467.07
2202.81	1455.75
2204.71	1442.99
2206.61	1454.65
2208.5	1445.26
2210.4	1429.38
2212.3	1422.22
2214.19	1446.32
2216.08	1428.73
2217.98	1420.58
2219.87	1421.37
2221.76	1407.77
2223.65	1411.13
2225.55	1425.53
2227.44	1401.99
2229.33	1421.32
2231.22	1392.76
2233.11	1402.62
2234.99	1390.27
2236.88	1401.36
2238.77	1381.24
2240.66	1390.13
2242.06	1386
2243.96	1417.5
2245.85	1405.5
2247.75	1388
2249.64	1377
2251.54	1378
2253.43	1351
2255.32	1341.5
2257.21	1320.5
2259.1	1323
2260.99	1328.5
2262.89	1301
2264.77	1288
2266.66	1300
2268.55	1291
2270.44	1295
2272.33	1259
2274.21	1252
2276.1	1263
2277.98	1285
2279.87	1240
2281.75	1248
2283.64	1261.5
2285.52	1247
2287.4	1256.5
2289.29	1239
2291.17	1269.5
2293.05	1241
2294.93	1249
2296.81	1209.5
2298.69	1203
2300.57	1205.5
2302.44	1235.5
2304.32	1207
2306.2	1230
2308.08	1216.5
2309.95	1196
2311.83	1208.5
2313.7	1213.5
2315.58	1167
2317.45	1179
2319.32	1171
2321.2	1174
2323.07	1178
2324.94	1190
2326.81	1168
2328.68	1179
2330.55	1158
2332.42	1164
2334.29	1166
2336.16	1160
2338.02	1147
2339.89	1159
2341.76	1136
2343.62	1153.5
2345.49	1127
2347.35	1161
2349.22	1142
2351.08	1138
2352.94	1111
2354.81	1124
2356.67	1130.5
2358.53	1128
2360.39	1150
2362.25	1108
2364.11	1128
2365.97	1108
2367.83	1108
2369.69	1099
2371.55	1110.5
2373.4	1080.5
2375.26	1111.5
2377.11	1086
2378.97	1107
2380.83	1085
2382.68	1119
2384.53	1078
2386.39	1079.5
2388.24	1072.5
2390.09	1101
2391.94	1066
2393.79	1067
2395.64	1092
2397.49	1055
2399.34	1076
2401.19	1068.5
2403.04	1076.5
2404.89	1056.5
2406.74	1059
2408.58	1059
2410.43	1060
2412.27	1039
2414.12	1036.5
2415.96	1041.5
2417.81	1044
2419.65	1017
2421.49	1034
2423.34	1020
2425.18	1020
2427.02	1019
2428.86	1032.5
2430.7	1014.5
2432.54	1009.5
2434.38	1011
2436.22	1019.5
2438.05	1014
2439.89	1009.5
2441.73	1003
2443.56	1007.5
2445.4	985.5
2447.24	997.5
2449.07	993.5
2450.9	1010.5
2452.74	998
2454.57	989.5
2456.4	978
2458.23	989
2460.07	964
2461.9	978
2463.73	980.5
2465.56	980.5
2467.39	971.5
2469.21	987
2471.04	948
2472.87	956
2474.7	978
2476.52	966
2478.35	963
2480.17	955.5
2482	969.5
2483.82	958
2485.65	963
2487.47	947
2489.29	897
2491.12	940.5
2492.94	942
2494.76	926.5
2496.58	932.5
2498.4	933.5
2500.22	928
2502.04	929.5
2503.86	915
2505.67	914
2507.49	916.5
2509.31	937
2511.12	920
2512.94	916.5
2514.76	906.5
2516.57	907
2518.38	898.5
2520.2	907
2522.01	910
2523.82	870
2525.64	872
2527.45	875
2529.26	878
2531.07	880.5
2532.88	867
2534.69	876
2536.5	864.5
2538.31	872
2540.11	877
2541.92	869.5
2543.73	885
2545.53	871
2547.34	858
2549.14	878
2550.95	862
2552.75	856
2554.56	859
2556.36	853
2558.16	833
2559.96	856
2561.76	842
2563.57	825
2565.37	831.5
2567.17	824
2568.96	826.5
2570.76	813
2572.56	818
2574.36	834.5
2576.16	839
2577.95	828.5
2579.75	817.5
2581.54	816
2583.34	828
2585.13	799
2586.93	808
2588.72	813.5
2590.51	825.5
2592.31	801
2594.1	806.5
2595.89	795
2597.68	803
2599.47	798
2601.26	800
2603.05	775
2604.84	798
2606.63	797
2608.42	787
2610.2	794.5
2611.99	790.5
2613.78	778.5
2615.56	778
2617.35	782
2619.13	776
2620.91	775
2622.7	778.5
2624.48	768.5
2626.26	752
2628.04	752.5
2629.83	755
2631.61	757
2633.39	749
2635.17	740.5
2636.95	744
2638.73	753
2640.5	734.5
2642.28	736.5
2644.06	732
2645.84	725
2647.61	723.5
2649.39	729
2651.16	727
2652.94	733.5
2654.71	718.5
2656.49	717
2658.26	723
2660.03	735
2661.8	737
2663.57	706
2665.35	740.5
2667.12	692.5
2668.89	708
2670.66	698
2672.42	722
2674.19	710
2675.96	725
2677.73	716.5
2679.49	712.5
2681.26	695.5
2683.03	703
2684.79	710
2686.56	705.5
2688.32	702
2690.09	691
2691.85	690
2693.61	693
2695.37	703.5
2697.14	693
2698.9	675
2700.66	660.5
2702.42	675.5
2704.18	672.5
2705.94	658.5
2707.7	668.5
2709.45	677
2711.21	674
2712.97	670
2714.72	638
2716.48	658
2718.24	686.5
2719.99	648
2721.75	668.5
2723.5	664
2725.25	667.5
2727.01	665.5
2728.76	654
2730.51	633
2732.26	649
2734.01	650.5
2735.76	633
2737.51	653
2739.26	641.5
2741.01	640
2742.76	646.5
2744.51	658
2746.26	617.5
2748	621
2749.75	631.5
2751.5	641.5
2753.24	638
2754.99	631
2756.73	632
2758.47	625
2760.22	620
2761.96	629.5
2763.7	611
2765.44	609.5
2767.19	609
2768.93	602
2770.67	612
2772.41	588.5
2774.15	585
2775.89	593
2777.62	599
2779.36	596
2781.1	594.5
2782.84	592
2784.57	600
2786.31	574
2788.04	600
2789.78	592
2791.51	585.5
2793.24	592
2794.98	589
2796.71	578.5
2798.44	572
2800.18	563.5
2801.91	590.5
2803.64	587
2805.37	572
2807.1	582
2808.83	559
2810.55	560.5
2812.28	569.5
2814.01	576.5
2815.74	564.5
2817.46	572
2819.19	553.5
2820.92	560
2822.64	554
2824.37	561.5
2826.09	556
2827.81	549
2829.54	552
2831.26	557.5
2832.98	558.5
2834.71	546
2836.43	554
2838.15	553.5
2839.87	541.5
2841.59	557
2843.31	541
2845.02	559
2846.74	561.5
2848.46	568
2850.18	571
2851.9	561.5
2853.61	563
2855.33	558.5
2857.04	559
2858.76	566
2860.47	557
2862.19	553
2863.9	550
2865.61	556.5
2867.32	537.5
2869.04	544
2870.75	555
2872.46	553
2874.17	552
2875.88	542.5
2877.59	555
2879.3	543
2881	538
2882.71	533
2884.42	533
2886.13	530.5
2887.83	546
2889.54	546
2891.24	550.5
2892.95	529
2894.65	540
2896.36	554.5
2898.06	540
2899.76	535
2901.47	533.5
2903.17	542
2904.87	523.5
2906.57	541.5
2908.27	539.5
2909.97	526
2911.67	531.5
2913.37	541
2915.07	540.5
2916.77	530
2918.47	557
2920.16	532.5
2921.86	534
2923.55	546
2925.25	559
2926.94	539.5
2928.64	543
2930.33	557.5
2932.03	539
2933.72	561.5
2935.41	558
2937.11	541
2938.8	549.5
2940.49	538.5
2942.18	538
2943.87	539
2945.56	522.5
2947.25	512.5
2948.94	512.5
2950.63	501
2952.31	502
2954	486
2955.69	497
2957.37	498
2959.06	494
2960.75	481
2962.43	486
2964.11	479
2965.8	470
2967.48	474.5
2969.16	471
2970.85	469.5
2972.53	460
2974.21	466.5
2975.89	450
2977.57	455.5
2979.25	463
2980.93	442.5
2982.61	457
2984.29	440
2985.97	443.5
2987.65	438
2989.32	424.5
2991	417.5
2992.68	434
2994.35	426.5
2996.03	429.5
2997.7	417
2999.38	405.5