File: muestras/ogompa/nsno_16.txt
#Acq. time (s)=	5
#Accumulations=	5
#Range (cm-¹)=	100...3000
#Windows=	3
#Autofocus=	Off
#AutoExposure=	Off
#Spike filter=	Multiple accum.
#Delay time (s)=	0
#Binning=	1
#Readout mode=	Signal
#DeNoise=	Off
#ICS correction=	Off
#Dark correction=	Off
#Inst. Process=	Off
#Instrument=	LabRAM HR Evol
#Detector=	Syncerity OE
#Objective=	x100_VIS_LWD
#Grating=	600 (500nm)
#ND Filter=	100%
#Laser=	633nm_Edge
#Hole=	100.021
#Range=	Visible
#Project=	Omar
#Sample=	chi
#Site=	f
#Title=	nsno
#Remark=
#Date=	12.09.2023 17:38
#Acquired=	12.09.2023 17:38:09
101.026	9124
103.592	9021.5
106.158	9003
108.723	8936
111.289	8754
113.852	8745.5
116.415	8599.5
118.976	8520.5
121.537	8551
124.097	8488
126.656	8416.5
129.215	8422
131.772	8340
134.327	8244.5
136.883	8252.5
139.438	8124.5
141.992	8132.5
144.545	8071.5
147.096	7998
149.648	7924.5
152.199	7902
154.747	7876.5
157.296	7816.5
159.843	7877.5
162.391	7847.5
164.937	7850.5
167.482	7834
170.025	7848.5
172.569	7827.5
175.111	7885
177.654	7883
180.194	7955.5
182.733	8042
185.273	8147
187.811	8194
190.348	8228.5
192.884	8364.5
195.419	8478.5
197.955	8616.5
200.489	8673
203.022	8749
205.554	8800.5
208.085	8795
210.615	8800
213.144	8809
215.673	8870
218.201	8890.5
220.728	8835.5
223.253	8761.5
225.778	8733.5
228.303	8590.5
230.826	8513
233.348	8498.5
235.87	8462
238.391	8392.5
240.91	8364
243.43	8286.5
245.949	8238
248.465	8181
250.983	8110.5
253.498	8088.5
256.013	8032.5
258.526	8002.5
261.039	7974.5
263.552	7843
266.063	7804.5
268.573	7823.5
271.084	7761
273.592	7802
276.1	7755
278.607	7693
281.113	7739.5
283.619	7751.5
286.124	7750
288.627	7681.5
291.13	7830.5
293.632	7698
296.133	7805.5
298.634	7842.5
301.133	7827
303.63	7774
306.128	7787
308.625	7833.5
311.122	7830
313.617	7842
316.111	7798.5
318.604	7839
321.098	7802
323.588	7709
326.08	7744.5
328.569	7707.5
331.059	7703.5
333.548	7734
336.035	7698
338.521	7703.5
341.008	7661.5
343.492	7659.5
345.977	7711
348.46	7705
350.942	7680
353.425	7666
355.905	7615
358.385	7582
360.864	7626
363.342	7649.5
365.819	7580
368.296	7596.5
370.771	7576.5
373.246	7567.5
375.72	7528
378.194	7517.5
380.666	7514.5
383.138	7516.5
385.609	7540
388.079	7498
390.548	7469
393.016	7511
395.483	7564
397.95	7571
400.416	7614.5
402.88	7691.5
405.345	7773.5
407.807	7929.5
410.27	8052
412.731	8239.5
415.193	8507
417.652	8539
420.112	8632.5
422.569	8605.5
425.028	8515.5
427.484	8522
429.939	8518
432.394	8759.5
434.849	9001.5
437.302	9057
439.754	8941.5
442.205	8619
444.656	8400.5
447.106	8185
449.555	8122.5
452.003	7969.5
454.45	7952
456.897	7923.5
459.343	7828.5
461.788	7817.5
464.232	7791
466.676	7771.5
469.119	7797.5
471.559	7750
474.001	7700.5
476.441	7759.5
478.879	7819.5
481.318	7732.5
483.756	7798.5
486.192	7737
488.629	7850
491.063	7793.5
493.498	7832
495.931	7769.5
498.365	7801
500.796	7823
503.226	7890
505.657	7866.5
508.086	7837
510.515	7870
512.942	7876
515.369	7879.5
517.796	7966.5
520.221	7981.5
522.645	7999.5
525.069	8024.5
527.492	7998
529.914	7978.5
532.335	7965.5
534.756	7842.5
537.175	7789.5
539.593	7687.5
542.011	7661.5
544.429	7630.5
546.845	7694
549.261	7671
551.675	7602.5
554.089	7593.5
556.503	7623.5
558.914	7659
561.326	7668.5
563.736	7682
566.147	7591
568.555	7644
570.964	7595.5
573.371	7681.5
575.777	7563
578.184	7523.5
580.588	7519.5
582.992	7542
585.395	7566.5
587.799	7554
590.201	7551
592.601	7492.5
595.001	7550
597.401	7555
599.799	7525.5
602.197	7552.5
604.594	7547
606.99	7620.5
609.386	7610
611.78	7619
614.174	7643.5
616.566	7664
618.958	7712
621.35	7694.5
623.741	7718.5
626.13	7724
628.519	7752
630.908	7773
633.295	7751
635.682	7785
638.067	7755.5
640.453	7787
642.836	7810
645.219	7792
647.602	7779
649.984	7727
652.364	7734.5
654.745	7708.5
657.124	7720.5
659.503	7676.5
661.88	7687
664.257	7718.5
666.635	7712
669.01	7667
671.384	7677.5
673.758	7640.5
676.131	7629.5
678.502	7674
680.874	7584
683.245	7573
685.615	7576
687.984	7522.5
690.353	7533
692.719	7483.5
695.086	7488.5
697.453	7457.5
699.817	7486.5
702.182	7487.5
704.545	7437
706.908	7485.5
709.27	7457
711.632	7467
713.991	7515.5
716.352	7506.5
718.71	7524
721.068	7593.5
723.426	7637.5
725.782	7640.5
728.138	7742
730.492	7719
732.846	7706.5
735.201	7592
737.553	7571.5
739.905	7503.5
742.256	7530
744.606	7549
746.956	7607
749.303	7528
751.651	7439
753.999	7504.5
756.345	7708
758.691	7746
761.035	7600.5
763.379	7507
765.723	7325.5
768.064	7357
770.407	7413
772.748	7364.5
775.088	7351
777.427	7313
779.765	7421
782.104	7442.5
784.44	7522
786.776	7619
789.113	7759
791.447	7776.5
793.78	7833
796.113	7933.5
798.445	7951
800.778	7984.5
803.109	7962
805.439	7983.5
807.768	7948
810.096	7772
812.424	7646
814.751	7616
817.078	7613.5
819.402	7568.5
821.727	7536
824.051	7536.5
826.374	7557.5
828.697	7549.5
831.018	7527.5
833.339	7526
835.659	7527
837.978	7480.5
840.297	7446
842.614	7490.5
844.932	7459.5
847.247	7481
849.562	7400
851.878	7399
854.191	7411
856.504	7433.5
858.817	7472.5
861.129	7422
863.439	7359
865.749	7375
868.058	7373
870.367	7291.5
872.676	7259
874.983	7258
877.289	7236
879.593	7252
881.898	7194
884.202	7194
886.506	7104.5
888.808	7191
891.11	7107.5
893.41	7093.5
895.711	7109.5
898.011	7058
900.309	7126
902.607	7136
904.904	7222
907.201	7289
909.496	7324
911.791	7458.5
914.085	7571
916.379	7621.5
918.671	7539.5
920.963	7329.5
923.255	7144
925.545	7058.5
927.834	7097
930.123	6958
932.411	7043.5
934.698	7065.5
936.985	7116.5
939.271	7032
941.556	7082.5
943.84	7008.5
946.124	7057.5
948.407	6992
950.689	6991.5
952.971	7029.5
955.25	7021
957.531	7084.5
959.81	7059.5
962.088	7042.5
964.366	7119.5
966.643	7090.5
968.919	7139.5
971.195	7111.25
973.469	7138.5
975.743	7095
978.016	7054
980.288	7048.5
982.56	7074
984.831	7062
987.101	7004
989.37	6961
991.638	6966
993.907	6971.5
996.174	6964.5
998.44	7053
1000.71	7102
1002.97	6957
1005.24	6892
1007.5	6849.5
1009.76	6810
1012.02	6795
1014.28	6763.5
1016.54	6832.5
1018.8	6785
1021.06	6808.5
1023.32	6737.5
1025.58	6809
1027.84	6805.5
1030.09	6818
1032.35	6783
1034.6	6772.5
1036.86	6788
1039.11	6778
1041.36	6785.5
1043.61	6827
1045.86	6835
1048.11	6841
1050.36	6778.5
1052.61	6851.5
1054.86	6796.5
1057.11	6843
1059.35	6830
1061.6	6807.5
1063.84	6790.5
1066.09	6809
1068.33	6845
1070.57	6811.5
1072.82	6792.5
1075.06	6776
1077.3	6734.5
1079.54	6770
1081.78	6793.5
1084.02	6741.5
1086.25	6736.5
1088.49	6754
1090.73	6716.5
1092.96	6717
1095.2	6729
1097.43	6722
1099.66	6723.5
1101.9	6693.5
1104.13	6698
1106.36	6755
1108.59	6702
1110.82	6695
1113.05	6630
1115.28	6688.5
1117.51	6683.5
1119.73	6671.5
1121.96	6652.5
1124.18	6653.5
1126.41	6610.5
1128.63	6695.5
1130.85	6723.5
1133.08	6729
1135.3	6756
1137.52	6804
1139.74	6843
1141.96	6855.5
1144.18	6846
1146.4	6906
1148.61	6850
1150.83	6931
1153.05	6998
1155.26	7056
1157.48	7174
1159.69	7238.5
1161.9	7444.5
1164.11	7616
1166.33	7765
1168.54	7851.5
1170.75	7981.5
1172.96	8064
1175.17	8071.5
1177.37	8106
1179.58	8011
1181.79	7857.5
1183.99	7644.5
1186.2	7489
1188.4	7430.5
1190.61	7330.5
1192.81	7191.5
1195.01	7151.5
1197.21	7046.38
1199.42	6951.63
1201.61	6873.35
1203.81	6899.03
1206.01	6842.2
1208.21	6841.43
1210.41	6729.75
1212.61	6753.48
1214.8	6626.56
1217	6686.18
1219.19	6551.75
1221.38	6499.68
1223.58	6407.83
1225.77	6354.29
1227.96	6328
1230.15	6316.05
1232.34	6336.85
1234.53	6261.72
1236.72	6267.59
1238.91	6254.67
1241.1	6178.48
1243.28	6149.43
1245.47	6153.21
1247.65	6138.96
1249.84	6173.58
1252.02	6124.92
1254.21	6146.08
1256.39	6087.98
1258.57	6093.54
1260.75	6099.38
1262.93	6090.43
1265.11	6090.33
1267.29	6083.71
1269.47	6058.6
1271.65	6059.81
1273.82	6020.35
1276	6038.9
1278.17	5993.96
1280.35	6027
1282.52	6015.48
1284.69	6013.27
1286.87	6056.93
1289.04	6050.67
1291.21	6069.41
1293.38	6132.26
1295.55	6093.44
1297.72	6095.69
1299.89	6058.09
1302.06	6017.98
1304.22	5942.64
1306.39	5840.98
1308.43	5761
1310.6	5828.5
1312.78	5753
1314.96	5677.5
1317.13	5716.5
1319.3	5630.5
1321.47	5708
1323.65	5656.5
1325.82	5656.5
1327.99	5729.5
1330.16	5707
1332.32	5782
1334.49	5803
1336.66	5792.5
1338.83	5792
1340.99	5842
1343.16	5831
1345.32	5771.5
1347.49	5783
1349.65	5807.5
1351.81	5847.5
1353.98	5846.5
1356.14	5861
1358.3	5955.5
1360.46	5991
1362.62	6013
1364.78	6075.5
1366.93	6064.5
1369.09	6103.5
1371.25	6124
1373.4	6100
1375.56	6025
1377.71	6072.5
1379.87	6085
1382.02	6007
1384.17	5953.5
1386.32	5926
1388.47	5856.5
1390.63	5859.5
1392.77	5783.5
1394.92	5687
1397.07	5667.5
1399.22	5597.5
1401.37	5558.5
1403.51	5528
1405.66	5472.5
1407.8	5399.5
1409.95	5450.5
1412.09	5348.5
1414.23	5414.5
1416.38	5350
1418.52	5354.5
1420.66	5410.5
1422.8	5427
1424.94	5407.5
1427.08	5402.5
1429.21	5431.5
1431.35	5465.5
1433.49	5515.5
1435.63	5490.5
1437.76	5447
1439.89	5442.5
1442.03	5477.5
1444.16	5524
1446.3	5503
1448.43	5542
1450.56	5472
1452.69	5476.5
1454.82	5459.5
1456.95	5452.5
1459.08	5451.5
1461.2	5455.5
1463.33	5501
1465.46	5562
1467.58	5500.5
1469.71	5543.5
1471.83	5624
1473.96	5595.5
1476.08	5607
1478.2	5617.5
1480.33	5605
1482.45	5577
1484.57	5500
1486.69	5559
1488.81	5523.5
1490.93	5470.5
1493.04	5471
1495.16	5547.5
1497.28	5487.5
1499.39	5545.5
1501.51	5576
1503.62	5535
1505.74	5562.5
1507.85	5514.5
1509.96	5514.5
1512.07	5506.5
1514.19	5515.5
1516.3	5555
1518.41	5487.5
1520.52	5532
1522.62	5566
1524.73	5657
1526.84	5657
1528.95	5547.5
1531.05	5604
1533.16	5586.5
1535.26	5532
1537.37	5567.5
1539.47	5545
1541.57	5513
1543.67	5408.5
1545.78	5483
1547.88	5496.5
1549.98	5491.5
1552.07	5427
1554.17	5472.5
1556.27	5500
1558.37	5459.5
1560.47	5445
1562.56	5467
1564.66	5430
1566.75	5465
1568.85	5516.5
1570.94	5483
1573.03	5462
1575.12	5511.5
1577.21	5537
1579.31	5635
1581.4	5664.5
1583.49	5738.5
1585.57	5674
1587.66	5609.5
1589.75	5683.5
1591.84	5613
1593.92	5553.5
1596.01	5552.5
1598.09	5502.5
1600.18	5540
1602.26	5424
1604.34	5450.5
1606.43	5387.5
1608.51	5410.5
1610.59	5525
1612.67	5619
1614.75	5637.5
1616.83	5660
1618.91	5453.5
1620.98	5224.5
1623.06	5056
1625.14	4911.5
1627.21	4764
1629.29	4640.5
1631.36	4584
1633.43	4492.5
1635.51	4421.5
1637.58	4347.5
1639.65	4286
1641.72	4238
1643.79	4164.5
1645.86	4111.5
1647.93	4096
1650	4046.5
1652.07	4034
1654.14	3980
1656.2	3939
1658.27	3951
1660.34	3895
1662.4	3803
1664.46	3790.5
1666.53	3779.5
1668.59	3737.5
1670.65	3690.5
1672.71	3652.5
1674.77	3682
1676.83	3686.5
1678.89	3612
1680.95	3606.5
1683.01	3571
1685.07	3625.5
1687.13	3567
1689.18	3525
1691.24	3496.5
1693.29	3470.5
1695.35	3472
1697.4	3491
1699.45	3485.5
1701.51	3445
1703.56	3437
1705.61	3466
1707.66	3445
1709.71	3419.5
1711.76	3407.5
1713.81	3401
1715.86	3319
1717.9	3328.5
1719.95	3357.5
1722	3323.5
1724.04	3300.5
1726.09	3313.5
1728.13	3322
1730.17	3287
1732.22	3266
1734.26	3246.5
1736.3	3239.5
1738.34	3224.5
1740.38	3221.5
1742.42	3190
1744.46	3206.5
1746.5	3170.5
1748.54	3155.5
1750.57	3149.5
1752.61	3121
1754.65	3154.5
1756.68	3092.5
1758.72	3110.5
1760.75	3072
1762.78	3051
1764.82	3129
1766.85	3071
1768.88	3031.5
1770.91	3046.5
1772.94	3048.5
1774.97	3064
1777	3023.5
1779.03	3021.5
1781.06	3028.5
1783.08	3010.5
1785.11	2987.5
1787.14	2950
1789.16	2969
1791.18	2975.5
1793.21	2959
1795.23	2925
1797.26	2934.5
1799.28	2947.5
1801.3	2929.5
1803.32	2908
1805.34	2932
1807.36	2920
1809.38	2908.5
1811.4	2866.5
1813.41	2852.5
1815.43	2889.5
1817.45	2848
1819.46	2857
1821.48	2834.5
1823.49	2832.5
1825.51	2815.5
1827.52	2777
1829.53	2856
1831.54	2770
1833.56	2769
1835.57	2785.5
1837.58	2782.5
1839.59	2725.5
1841.59	2737.5
1843.6	2728.5
1845.61	2723
1847.62	2710.5
1849.62	2694.5
1851.63	2684
1853.64	2695
1855.64	2669.5
1857.64	2673.5
1859.65	2636.5
1861.65	2659.5
1863.65	2631
1865.65	2623.5
1867.65	2592
1869.65	2599.5
1871.65	2637
1873.65	2608.5
1875.65	2591.5
1877.65	2587
1879.65	2578
1881.64	2610.5
1883.64	2556
1885.63	2556.5
1887.63	2575.5
1889.62	2571.5
1891.62	2544
1893.61	2540
1895.6	2530
1897.59	2537.5
1899.58	2525
1901.57	2522
1903.56	2541
1905.55	2485
1907.54	2513
1909.53	2510.5
1911.52	2532
1913.5	2513.5
1915.49	2510.5
1917.48	2511
1919.46	2511.5
1921.44	2475
1923.43	2476
1925.41	2513.5
1927.39	2472
1929.38	2426
1931.36	2461.5
1933.34	2469
1935.32	2430.5
1937.3	2442.5
1939.28	2470
1941.25	2444.5
1943.23	2402.5
1945.21	2410.5
1947.18	2419.5
1949.16	2425
1951.13	2415.5
1953.11	2432.5
1955.08	2398
1957.06	2399.5
1959.03	2350
1961	2358
1962.97	2338.5
1964.94	2331.5
1966.91	2334.5
1968.88	2337
1970.85	2336.5
1972.82	2344
1974.79	2310.5
1976.76	2311.5
1978.72	2320
1980.69	2313
1982.65	2298
1984.62	2277.5
1986.58	2323
1988.55	2284
1990.51	2295
1992.47	2293.5
1994.43	2245.5
1996.39	2269
1998.36	2223.5
2000.31	2297.5
2002.27	2285
2004.23	2280
2006.19	2239
2008.15	2231
2010.11	2229.5
2012.06	2236
2014.02	2220
2015.97	2249
2017.93	2226
2019.88	2231
2021.83	2215.5
2023.79	2195
2025.74	2143.5
2027.69	2183
2029.64	2202.5
2031.59	2168
2033.54	2175.5
2035.49	2171
2037.44	2151.5
2039.39	2158
2041.34	2179.5
2043.28	2149.5
2045.23	2147.5
2047.17	2141
2049.12	2144
2051.06	2144.5
2053.01	2165.5
2054.95	2138.5
2056.89	2109.5
2058.84	2115
2060.78	2088
2062.72	2108
2064.66	2095.5
2066.6	2062.5
2068.54	2096
2070.48	2033
2072.41	2044
2074.35	2092
2076.29	2057
2078.22	2048.5
2080.16	2050.5
2082.09	2054.5
2084.03	2066
2085.96	2014
2087.9	2069.5
2089.83	2034.5
2091.76	2055
2093.69	2016.5
2095.62	2015.5
2097.55	2050.5
2099.48	1999
2101.41	1993.5
2103.34	2013
2105.27	2022
2107.19	2014.5
2109.12	2018.5
2111.05	2039.5
2112.97	2028.5
2114.9	2022
2116.82	2036
2118.75	2040
2120.67	2078.5
2122.59	2073
2124.51	2074
2126.43	2087.5
2128.36	2073.5
2130.28	2057
2132.2	2048
2134.11	2070
2136.03	2035
2137.95	2016
2139.87	2042
2141.78	1969
2143.7	1994.5
2145.62	1959.23
2147.53	1968.44
2149.45	1959.66
2151.36	1915.39
2153.27	1932.07
2155.19	1898.99
2157.1	1899.55
2159.01	1851.64
2160.92	1847.05
2162.83	1840.88
2164.74	1824.56
2166.65	1800.01
2168.56	1802
2170.47	1800.31
2172.37	1801.59
2174.28	1793.17
2176.19	1783.49
2178.09	1740.7
2180	1750.6
2181.9	1750.51
2183.81	1716.09
2185.71	1720.58
2187.61	1725.02
2189.51	1704.92
2191.42	1708.78
2193.32	1692.99
2195.22	1673.51
2197.12	1683.1
2199.02	1663.37
2200.92	1674.6
2202.81	1662.57
2204.71	1637.31
2206.61	1634.63
2208.5	1630.77
2210.4	1637.11
2212.3	1622.16
2214.19	1631.76
2216.08	1618.34
2217.98	1620.88
2219.87	1594.68
2221.76	1583.95
2223.65	1597.72
2225.55	1582.33
2227.44	1596.43
2229.33	1576.04
2231.22	1570.01
2233.11	1577.21
2234.99	1579
2236.88	1581.31
2238.77	1584
2240.66	1557.21
2242.06	1566.5
2243.96	1574
2245.85	1573.5
2247.75	1566.5
2249.64	1578.5
2251.54	1543.5
2253.43	1531.5
2255.32	1513
2257.21	1539
2259.1	1508.5
2260.99	1506.5
2262.89	1495.5
2264.77	1509
2266.66	1497.5
2268.55	1504
2270.44	1467.5
2272.33	1460
2274.21	1463
2276.1	1439
2277.98	1462
2279.87	1429.5
2281.75	1432.5
2283.64	1450.5
2285.52	1427.5
2287.4	1411
2289.29	1455
2291.17	1428
2293.05	1407
2294.93	1421.5
2296.81	1420.5
2298.69	1403.5
2300.57	1392
2302.44	1402
2304.32	1392.5
2306.2	1421.5
2308.08	1376.5
2309.95	1408.5
2311.83	1408
2313.7	1364
2315.58	1381.5
2317.45	1389.5
2319.32	1362
2321.2	1355.5
2323.07	1390.5
2324.94	1358.5
2326.81	1368
2328.68	1364.5
2330.55	1364
2332.42	1365
2334.29	1339
2336.16	1366.5
2338.02	1363.5
2339.89	1335
2341.76	1338
2343.62	1340.5
2345.49	1345
2347.35	1330
2349.22	1341.5
2351.08	1351.5
2352.94	1344.5
2354.81	1322
2356.67	1345
2358.53	1321
2360.39	1336
2362.25	1322.5
2364.11	1300
2365.97	1297.5
2367.83	1306.5
2369.69	1282.5
2371.55	1297
2373.4	1293.5
2375.26	1324.5
2377.11	1312.5
2378.97	1312.5
2380.83	1269
2382.68	1311
2384.53	1274
2386.39	1267
2388.24	1274
2390.09	1263.5
2391.94	1262.5
2393.79	1249
2395.64	1260.5
2397.49	1264
2399.34	1249
2401.19	1245.5
2403.04	1253
2404.89	1258
2406.74	1258
2408.58	1246.5
2410.43	1250
2412.27	1239
2414.12	1223.5
2415.96	1226.5
2417.81	1217.5
2419.65	1216.5
2421.49	1234.5
2423.34	1234
2425.18	1224
2427.02	1188
2428.86	1213.5
2430.7	1196
2432.54	1210
2434.38	1180.5
2436.22	1192
2438.05	1176
2439.89	1206.5
2441.73	1204.5
2443.56	1195.5
2445.4	1180.5
2447.24	1176.5
2449.07	1170
2450.9	1163
2452.74	1182
2454.57	1182.5
2456.4	1169
2458.23	1154
2460.07	1167
2461.9	1163
2463.73	1162
2465.56	1185
2467.39	1168.5
2469.21	1148
2471.04	1145
2472.87	1156
2474.7	1174
2476.52	1129.5
2478.35	1138.5
2480.17	1134
2482	1168.5
2483.82	1123.5
2485.65	1126.5
2487.47	1130
2489.29	1134
2491.12	1113
2492.94	1127.5
2494.76	1128
2496.58	1110.5
2498.4	1117.5
2500.22	1124.5
2502.04	1130
2503.86	1094.5
2505.67	1096.5
2507.49	1103.5
2509.31	1078
2511.12	1108.5
2512.94	1088
2514.76	1091
2516.57	1104.5
2518.38	1086
2520.2	1087.5
2522.01	1082
2523.82	1080.5
2525.64	1102
2527.45	1066.5
2529.26	1079.5
2531.07	1079.5
2532.88	1075
2534.69	1080
2536.5	1072
2538.31	1050
2540.11	1057.5
2541.92	1057
2543.73	1066
2545.53	1050
2547.34	1065
2549.14	1065
2550.95	1045.5
2552.75	1049
2554.56	1053.5
2556.36	1040.5
2558.16	1051
2559.96	1035.5
2561.76	1028.5
2563.57	1028
2565.37	1020
2567.17	1018.5
2568.96	1030.5
2570.76	1027.5
2572.56	1008.5
2574.36	1012
2576.16	994
2577.95	1003
2579.75	1001.5
2581.54	1015
2583.34	1004
2585.13	992
2586.93	1000
2588.72	1005.5
2590.51	986
2592.31	999
2594.1	989.5
2595.89	970
2597.68	985.5
2599.47	989.5
2601.26	984.5
2603.05	974
2604.84	965
2606.63	965
2608.42	978
2610.2	980.5
2611.99	951
2613.78	952.5
2615.56	963.5
2617.35	966
2619.13	964.5
2620.91	952
2622.7	943.5
2624.48	944.5
2626.26	967
2628.04	966
2629.83	948.5
2631.61	958.5
2633.39	956.5
2635.17	940
2636.95	916.5
2638.73	907
2640.5	927
2642.28	919
2644.06	905
2645.84	930
2647.61	935
2649.39	903
2651.16	927.5
2652.94	917.5
2654.71	903.5
2656.49	895.5
2658.26	910.5
2660.03	902
2661.8	909.5
2663.57	912.5
2665.35	904.5
2667.12	888
2668.89	880
2670.66	916.5
2672.42	897
2674.19	888.5
2675.96	894.5
2677.73	884
2679.49	883.5
2681.26	893
2683.03	883.5
2684.79	894.5
2686.56	877
2688.32	880.5
2690.09	860
2691.85	872.5
2693.61	883.5
2695.37	864
2697.14	868
2698.9	868.5
2700.66	853.5
2702.42	855
2704.18	854.5
2705.94	864.5
2707.7	851.5
2709.45	853.5
2711.21	851
2712.97	838
2714.72	850.5
2716.48	856
2718.24	850.5
2719.99	841.5
2721.75	843.5
2723.5	833.5
2725.25	832.5
2727.01	841
2728.76	818
2730.51	827
2732.26	826
2734.01	807.5
2735.76	813
2737.51	822.5
2739.26	805
2741.01	812
2742.76	829
2744.51	812
2746.26	810
2748	790.5
2749.75	804.5
2751.5	817.5
2753.24	795
2754.99	800
2756.73	791.5
2758.47	796
2760.22	785
2761.96	791
2763.7	786.5
2765.44	783
2767.19	777.5
2768.93	791.5
2770.67	767
2772.41	773.5
2774.15	778.5
2775.89	766
2777.62	764.5
2779.36	770
2781.1	770
2782.84	764.5
2784.57	784
2786.31	736.5
2788.04	781.5
2789.78	776
2791.51	772.5
2793.24	757
2794.98	762
2796.71	764
2798.44	740.5
2800.18	746
2801.91	739
2803.64	748.5
2805.37	731
2807.1	744
2808.83	736
2810.55	716
2812.28	746
2814.01	732
2815.74	719.5
2817.46	719
2819.19	718
2820.92	717
2822.64	718.5
2824.37	724.5
2826.09	720
2827.81	708.5
2829.54	711
2831.26	718
2832.98	721
2834.71	721.5
2836.43	699.5
2838.15	705.5
2839.87	725
2841.59	710
2843.31	721.5
2845.02	724
2846.74	713
2848.46	727
2850.18	728
2851.9	715
2853.61	715
2855.33	715
2857.04	708.5
2858.76	722
2860.47	721.5
2862.19	738.5
2863.9	710.5
2865.61	722.5
2867.32	725
2869.04	697
2870.75	716
2872.46	729.5
2874.17	725.5
2875.88	709
2877.59	720
2879.3	702
2881	717.5
2882.71	719
2884.42	703.5
2886.13	712
2887.83	702.5
2889.54	707
2891.24	718.5
2892.95	706.5
2894.65	715
2896.36	708
2898.06	686.5
2899.76	702.5
2901.47	723
2903.17	720.5
2904.87	706
2906.57	716
2908.27	709.5
2909.97	707.5
2911.67	719.5
2913.37	710
2915.07	709
2916.77	706.5
2918.47	728.5
2920.16	700
2921.86	705
2923.55	721.5
2925.25	725
2926.94	723.5
2928.64	730
2930.33	722
2932.03	728
2933.72	728
2935.41	704.5
2937.11	717.5
2938.8	712
2940.49	721
2942.18	716
2943.87	697
2945.56	687.5
2947.25	690.5
2948.94	656
2950.63	681.5
2952.31	650.5
2954	659.5
2955.69	649
2957.37	628
2959.06	637
2960.75	620
2962.43	616.5
2964.11	637.5
2965.8	609.5
2967.48	637
2969.16	615
2970.85	610
2972.53	611.5
2974.21	615.5
2975.89	603.5
2977.57	606.5
2979.25	588.5
2980.93	588
2982.61	566.5
2984.29	591
2985.97	594
2987.65	566.5
2989.32	562.5
2991	571.5
2992.68	568.5
2994.35	556
2996.03	564.5
2997.7	546
2999.38	561.5