File: muestras/ogompa/nsno_12.txt
#Acq. time (s)=	5
#Accumulations=	5
#Range (cm-¹)=	100...3000
#Windows=	3
#Autofocus=	Off
#AutoExposure=	Off
#Spike filter=	Multiple accum.
#Delay time (s)=	0
#Binning=	1
#Readout mode=	Signal
#DeNoise=	Off
#ICS correction=	Off
#Dark correction=	Off
#Inst. Process=	Off
#Instrument=	LabRAM HR Evol
#Detector=	Syncerity OE
#Objective=	x100_VIS_LWD
#Grating=	600 (500nm)
#ND Filter=	100%
#Laser=	633nm_Edge
#Hole=	100.021
#Range=	Visible
#Project=	Omar
#Sample=	chi
#Site=	f
#Title=	nsno
#Remark=
#Date=	12.09.2023 17:20
#Acquired=	12.09.2023 17:20:18
101.026	3219
103.592	3164.5
106.158	3112
108.723	3031.5
111.289	2945.5
113.852	2976
116.415	2934.5
118.976	2885
121.537	2802.5
124.097	2810
126.656	2769
129.215	2765.5
131.772	2736.5
134.327	2708
136.883	2663
139.438	2637.5
141.992	2615
144.545	2523
147.096	2508.5
149.648	2466
152.199	2443.5
154.747	2394
157.296	2388
159.843	2327
162.391	2307
164.937	2280.5
167.482	2261.5
170.025	2267
172.569	2244.5
175.111	2230.5
177.654	2196
180.194	2223
182.733	2196.5
185.273	2177.5
187.811	2213.5
190.348	2168
192.884	2182.5
195.419	2186.5
197.955	2185
200.489	2215
203.022	2234
205.554	2230.5
208.085	2242.5
210.615	2224.5
213.144	2230
215.673	2242
218.201	2222.5
220.728	2260.5
223.253	2297
225.778	2255
228.303	2239
230.826	2281
233.348	2271
235.87	2271
238.391	2303.5
240.91	2294.5
243.43	2293.5
245.949	2333
248.465	2334
250.983	2331
253.498	2334
256.013	2324
258.526	2324.5
261.039	2305.5
263.552	2318
266.063	2339.5
268.573	2319
271.084	2314.5
273.592	2318.5
276.1	2304.5
278.607	2306.5
281.113	2343.5
283.619	2337.5
286.124	2378.5
288.627	2355.5
291.13	2357.5
293.632	2347.5
296.133	2385
298.634	2383.5
301.133	2449.5
303.63	2414
306.128	2426
308.625	2398
311.122	2419.5
313.617	2385.5
316.111	2390
318.604	2355.5
321.098	2351
323.588	2354.5
326.08	2358.5
328.569	2320.5
331.059	2313.5
333.548	2309
336.035	2297
338.521	2297
341.008	2295.5
343.492	2310
345.977	2314
348.46	2300
350.942	2324.5
353.425	2323
355.905	2337.5
358.385	2322
360.864	2347.5
363.342	2309.5
365.819	2335
368.296	2297.5
370.771	2309.5
373.246	2311.5
375.72	2304.5
378.194	2278.5
380.666	2324.5
383.138	2265.5
385.609	2271.5
388.079	2275.5
390.548	2281.5
393.016	2286
395.483	2274
397.95	2269
400.416	2288.5
402.88	2255.5
405.345	2298
407.807	2317
410.27	2301.5
412.731	2317.5
415.193	2295
417.652	2344
420.112	2336.5
422.569	2358
425.028	2359.5
427.484	2354
429.939	2374
432.394	2408
434.849	2401.5
437.302	2382.5
439.754	2413
442.205	2378
444.656	2362.5
447.106	2389.5
449.555	2395.5
452.003	2359.5
454.45	2408
456.897	2394.5
459.343	2395.5
461.788	2366.5
464.232	2370
466.676	2353.5
469.119	2393.5
471.559	2367.5
474.001	2391
476.441	2412.5
478.879	2379
481.318	2440
483.756	2401
486.192	2399
488.629	2443.5
491.063	2414
493.498	2432.5
495.931	2407
498.365	2442.5
500.796	2430
503.226	2453
505.657	2422
508.086	2411.5
510.515	2433
512.942	2459
515.369	2438.5
517.796	2461
520.221	2469.5
522.645	2446
525.069	2403.5
527.492	2454
529.914	2433
532.335	2441
534.756	2427.5
537.175	2410.5
539.593	2415.5
542.011	2406
544.429	2444.5
546.845	2396
549.261	2417
551.675	2442
554.089	2447.5
556.503	2431
558.914	2421.5
561.326	2437
563.736	2467
566.147	2449
568.555	2443
570.964	2453.5
573.371	2417
575.777	2437.5
578.184	2461
580.588	2465.5
582.992	2439
585.395	2459
587.799	2427
590.201	2468.5
592.601	2456
595.001	2422.5
597.401	2476.5
599.799	2445
602.197	2474.5
604.594	2492.5
606.99	2489
609.386	2509
611.78	2481.5
614.174	2485
616.566	2502.5
618.958	2529
621.35	2518
623.741	2516
626.13	2503.5
628.519	2512.5
630.908	2554
633.295	2547
635.682	2533.5
638.067	2555
640.453	2599
642.836	2563
645.219	2553
647.602	2569.5
649.984	2548
652.364	2584
654.745	2565.5
657.124	2521
659.503	2518
661.88	2551
664.257	2548.5
666.635	2541
669.01	2524
671.384	2565
673.758	2554.5
676.131	2523.5
678.502	2527
680.874	2541.5
683.245	2549
685.615	2555.5
687.984	2526
690.353	2512.5
692.719	2498
695.086	2491.5
697.453	2509.5
699.817	2541
702.182	2500.5
704.545	2508.5
706.908	2535
709.27	2505
711.632	2514.5
713.991	2562
716.352	2513
718.71	2575.5
721.068	2477
723.426	2522.5
725.782	2542.5
728.138	2556.5
730.492	2567.5
732.846	2543
735.201	2543
737.553	2569
739.905	2525
742.256	2537
744.606	2539.5
746.956	2553.5
749.303	2505
751.651	2520.5
753.999	2506
756.345	2512
758.691	2494
761.035	2506
763.379	2509
765.723	2523.5
768.064	2507
770.407	2493.5
772.748	2515
775.088	2517
777.427	2539.5
779.765	2529
782.104	2545.5
784.44	2520
786.776	2508
789.113	2525.5
791.447	2523
793.78	2553
796.113	2544.5
798.445	2496
800.778	2533.5
803.109	2514.5
805.439	2515.5
807.768	2511.5
810.096	2530.5
812.424	2552
814.751	2565
817.078	2540.5
819.402	2544
821.727	2558.5
824.051	2605
826.374	2556
828.697	2558
831.018	2585
833.339	2597
835.659	2582
837.978	2564
840.297	2579
842.614	2585
844.932	2613.5
847.247	2578.5
849.562	2575.5
851.878	2612
854.191	2625
856.504	2610
858.817	2613.5
861.129	2611
863.439	2610
865.749	2596.5
868.058	2582
870.367	2569.5
872.676	2584
874.983	2549.5
877.289	2577
879.593	2555
881.898	2533.5
884.202	2526
886.506	2524
888.808	2510
891.11	2501
893.41	2476.5
895.711	2504.5
898.011	2465.5
900.309	2487
902.607	2496
904.904	2476
907.201	2477.5
909.496	2469
911.791	2449
914.085	2422.5
916.379	2485
918.671	2475
920.963	2462
923.255	2487.5
925.545	2491.5
927.834	2493.5
930.123	2465
932.411	2481
934.698	2507.5
936.985	2515
939.271	2504
941.556	2474.5
943.84	2500.5
946.124	2471
948.407	2467
950.689	2463
952.971	2433
955.25	2482
957.531	2526
959.81	2491
962.088	2495.5
964.366	2507.5
966.643	2530.5
968.919	2497.5
971.195	2497.75
973.469	2559
975.743	2517.5
978.016	2480.5
980.288	2492.5
982.56	2486.5
984.831	2504.5
987.101	2467
989.37	2481.5
991.638	2447
993.907	2482.5
996.174	2503.5
998.44	2549.5
1000.71	2572.5
1002.97	2489.5
1005.24	2485
1007.5	2459.5
1009.76	2465.5
1012.02	2448.5
1014.28	2478.5
1016.54	2493.5
1018.8	2432.5
1021.06	2473.5
1023.32	2457
1025.58	2454.5
1027.84	2464
1030.09	2455
1032.35	2493
1034.6	2455.5
1036.86	2479
1039.11	2465
1041.36	2471.5
1043.61	2477
1045.86	2477.5
1048.11	2440
1050.36	2482.5
1052.61	2470.5
1054.86	2464.5
1057.11	2475.5
1059.35	2443.5
1061.6	2450
1063.84	2497
1066.09	2511.5
1068.33	2485.5
1070.57	2446
1072.82	2487
1075.06	2491.5
1077.3	2479
1079.54	2470.5
1081.78	2448
1084.02	2470.5
1086.25	2460.5
1088.49	2454
1090.73	2440
1092.96	2470.5
1095.2	2436.5
1097.43	2467.5
1099.66	2435.5
1101.9	2438
1104.13	2409.5
1106.36	2435
1108.59	2433
1110.82	2414.5
1113.05	2431
1115.28	2405
1117.51	2420.5
1119.73	2435.5
1121.96	2415
1124.18	2411.5
1126.41	2425
1128.63	2446
1130.85	2409.5
1133.08	2419.5
1135.3	2417.5
1137.52	2432.5
1139.74	2424
1141.96	2434
1144.18	2433.5
1146.4	2451
1148.61	2512.5
1150.83	2447.5
1153.05	2477
1155.26	2478
1157.48	2505.5
1159.69	2492.5
1161.9	2519
1164.11	2531.5
1166.33	2529
1168.54	2520
1170.75	2549
1172.96	2532
1175.17	2527.5
1177.37	2522.5
1179.58	2502.5
1181.79	2490.5
1183.99	2495.5
1186.2	2473
1188.4	2511.5
1190.61	2484
1192.81	2497
1195.01	2456.5
1197.21	2470.64
1199.42	2450.05
1201.61	2473.1
1203.81	2461.94
1206.01	2432.08
1208.21	2424.49
1210.41	2470.35
1212.61	2397.7
1214.8	2429.1
1217	2438.24
1219.19	2433.34
1221.38	2413.46
1223.58	2395.87
1225.77	2409.61
1227.96	2398.69
1230.15	2443.05
1232.34	2425.14
1234.53	2435.2
1236.72	2414.5
1238.91	2429.07
1241.1	2455.81
1243.28	2452.87
1245.47	2443.28
1247.65	2451.81
1249.84	2449.83
1252.02	2451.85
1254.21	2456.88
1256.39	2460.03
1258.57	2459.71
1260.75	2445.16
1262.93	2467.81
1265.11	2463.65
1267.29	2466.63
1269.47	2460.94
1271.65	2471.6
1273.82	2498.62
1276	2501.48
1278.17	2489.82
1280.35	2510.32
1282.52	2507.5
1284.69	2501.48
1286.87	2467.57
1289.04	2479.12
1291.21	2513.51
1293.38	2488.73
1295.55	2468.16
1297.72	2492.22
1299.89	2481.7
1302.06	2477.48
1304.22	2458.79
1306.39	2476.4
1308.43	2467.5
1310.6	2448.5
1312.78	2429
1314.96	2460
1317.13	2437
1319.3	2457
1321.47	2430.5
1323.65	2408
1325.82	2386
1327.99	2412
1330.16	2376
1332.32	2402.5
1334.49	2380.5
1336.66	2423.5
1338.83	2410
1340.99	2373
1343.16	2395
1345.32	2387.5
1347.49	2388
1349.65	2359.5
1351.81	2338
1353.98	2341.5
1356.14	2368
1358.3	2369
1360.46	2300
1362.62	2341.5
1364.78	2320.5
1366.93	2331
1369.09	2326.5
1371.25	2302.5
1373.4	2323
1375.56	2346.5
1377.71	2328.5
1379.87	2289.5
1382.02	2309.5
1384.17	2320
1386.32	2264.5
1388.47	2310
1390.63	2270.5
1392.77	2272
1394.92	2260.5
1397.07	2311
1399.22	2275.5
1401.37	2292
1403.51	2285.5
1405.66	2309.5
1407.8	2274.5
1409.95	2281
1412.09	2283.5
1414.23	2261
1416.38	2282
1418.52	2263
1420.66	2259.5
1422.8	2261
1424.94	2270.5
1427.08	2276
1429.21	2274.5
1431.35	2284
1433.49	2304
1435.63	2316.5
1437.76	2309
1439.89	2320
1442.03	2309.5
1444.16	2338
1446.3	2344.5
1448.43	2300
1450.56	2316.5
1452.69	2304.5
1454.82	2288.5
1456.95	2277
1459.08	2299
1461.2	2274.5
1463.33	2286.5
1465.46	2294
1467.58	2268
1469.71	2312.5
1471.83	2300
1473.96	2273.5
1476.08	2287
1478.2	2288.5
1480.33	2293
1482.45	2284.5
1484.57	2286.5
1486.69	2303
1488.81	2291.5
1490.93	2287
1493.04	2291
1495.16	2313
1497.28	2301
1499.39	2318
1501.51	2309.5
1503.62	2311.5
1505.74	2308
1507.85	2315.5
1509.96	2282
1512.07	2296.5
1514.19	2302.5
1516.3	2310
1518.41	2283.5
1520.52	2321.5
1522.62	2297
1524.73	2274.5
1526.84	2319.5
1528.95	2264
1531.05	2272
1533.16	2286.5
1535.26	2272
1537.37	2270
1539.47	2269
1541.57	2249
1543.67	2273
1545.78	2263
1547.88	2263
1549.98	2280
1552.07	2252
1554.17	2256.5
1556.27	2246.5
1558.37	2210
1560.47	2241
1562.56	2255.5
1564.66	2254
1566.75	2225.5
1568.85	2252
1570.94	2236.5
1573.03	2227
1575.12	2217.5
1577.21	2238
1579.31	2208
1581.4	2251.5
1583.49	2193
1585.57	2241
1587.66	2232.5
1589.75	2264
1591.84	2286
1593.92	2279
1596.01	2276.5
1598.09	2239
1600.18	2264
1602.26	2235
1604.34	2211
1606.43	2178.5
1608.51	2154
1610.59	2116
1612.67	2094
1614.75	2044
1616.83	2033.5
1618.91	2006
1620.98	1960
1623.06	1957.5
1625.14	1946
1627.21	1910.5
1629.29	1912
1631.36	1873.5
1633.43	1857.5
1635.51	1829.5
1637.58	1805
1639.65	1796.5
1641.72	1767.5
1643.79	1748.5
1645.86	1727
1647.93	1733
1650	1701
1652.07	1693
1654.14	1667
1656.2	1678
1658.27	1632.5
1660.34	1633
1662.4	1635
1664.46	1617
1666.53	1583
1668.59	1598.5
1670.65	1584.5
1672.71	1589.5
1674.77	1549.5
1676.83	1540.5
1678.89	1548
1680.95	1536.5
1683.01	1532.5
1685.07	1524.5
1687.13	1488
1689.18	1509
1691.24	1500
1693.29	1477
1695.35	1476.5
1697.4	1460.5
1699.45	1497.5
1701.51	1461
1703.56	1466.5
1705.61	1438
1707.66	1463.5
1709.71	1448
1711.76	1436
1713.81	1447
1715.86	1417.5
1717.9	1415.5
1719.95	1393
1722	1401
1724.04	1411.5
1726.09	1411.5
1728.13	1393
1730.17	1368
1732.22	1393
1734.26	1388
1736.3	1385
1738.34	1376
1740.38	1372.5
1742.42	1366.5
1744.46	1371
1746.5	1333.5
1748.54	1332.5
1750.57	1316
1752.61	1357.5
1754.65	1325
1756.68	1348
1758.72	1309.5
1760.75	1291.5
1762.78	1316.5
1764.82	1292
1766.85	1302.5
1768.88	1275
1770.91	1285.5
1772.94	1284.5
1774.97	1292
1777	1284.5
1779.03	1271.5
1781.06	1279.5
1783.08	1249
1785.11	1266
1787.14	1254
1789.16	1263
1791.18	1245
1793.21	1232
1795.23	1232.5
1797.26	1224.5
1799.28	1241.5
1801.3	1216.5
1803.32	1206
1805.34	1214.5
1807.36	1201.5
1809.38	1204.5
1811.4	1200.5
1813.41	1222.5
1815.43	1196.5
1817.45	1204.5
1819.46	1189
1821.48	1181.5
1823.49	1193
1825.51	1189.5
1827.52	1186
1829.53	1175.5
1831.54	1154
1833.56	1177.5
1835.57	1171
1837.58	1156
1839.59	1141
1841.59	1133
1843.6	1170
1845.61	1122
1847.62	1131
1849.62	1148
1851.63	1133.5
1853.64	1127
1855.64	1152
1857.64	1137.5
1859.65	1144.5
1861.65	1119
1863.65	1128.5
1865.65	1101
1867.65	1084
1869.65	1105
1871.65	1094
1873.65	1087
1875.65	1084.5
1877.65	1083
1879.65	1056.5
1881.64	1073
1883.64	1078
1885.63	1065
1887.63	1082.5
1889.62	1070.5
1891.62	1079
1893.61	1066.5
1895.6	1049.5
1897.59	1051
1899.58	1053.5
1901.57	1057
1903.56	1055
1905.55	1065.5
1907.54	1051.5
1909.53	1053.5
1911.52	1029.5
1913.5	1045.5
1915.49	1041.5
1917.48	1023.5
1919.46	1038
1921.44	1032
1923.43	1066.5
1925.41	1024.5
1927.39	1036.5
1929.38	1021.5
1931.36	1012
1933.34	1012
1935.32	1009.5
1937.3	994.5
1939.28	1000.5
1941.25	996
1943.23	1000.5
1945.21	1006
1947.18	1015.5
1949.16	993.5
1951.13	998.5
1953.11	995.5
1955.08	982.5
1957.06	986
1959.03	988.5
1961	991.5
1962.97	972
1964.94	972.5
1966.91	959
1968.88	982
1970.85	971.5
1972.82	962.5
1974.79	945.5
1976.76	967
1978.72	949
1980.69	960
1982.65	957.5
1984.62	942.5
1986.58	963.5
1988.55	943.5
1990.51	946.5
1992.47	947.5
1994.43	944.5
1996.39	939
1998.36	930
2000.31	923
2002.27	943.5
2004.23	944
2006.19	923
2008.15	935.5
2010.11	901.5
2012.06	909.5
2014.02	922
2015.97	926.5
2017.93	917.5
2019.88	901
2021.83	911.5
2023.79	911.5
2025.74	917
2027.69	892.5
2029.64	894.5
2031.59	893.5
2033.54	904
2035.49	901
2037.44	901.5
2039.39	881
2041.34	895
2043.28	866.5
2045.23	899
2047.17	875.5
2049.12	883
2051.06	867
2053.01	873
2054.95	861
2056.89	873.5
2058.84	874.5
2060.78	870
2062.72	872
2064.66	853
2066.6	862.5
2068.54	857
2070.48	863
2072.41	864
2074.35	839.5
2076.29	853
2078.22	854
2080.16	844
2082.09	853
2084.03	857
2085.96	860
2087.9	859
2089.83	827
2091.76	842
2093.69	826.5
2095.62	842.5
2097.55	849.5
2099.48	827
2101.41	827.5
2103.34	826.5
2105.27	842.5
2107.19	830.5
2109.12	847
2111.05	859.5
2112.97	868.5
2114.9	862.5
2116.82	873.5
2118.75	895.5
2120.67	919.5
2122.59	902.5
2124.51	917.5
2126.43	945.5
2128.36	930.5
2130.28	942
2132.2	941
2134.11	939.5
2136.03	918
2137.95	926.5
2139.87	919
2141.78	902.5
2143.7	910
2145.62	874.002
2147.53	871.058
2149.45	856.653
2151.36	863.946
2153.27	864.445
2155.19	850.092
2157.1	841.066
2159.01	823.308
2160.92	807.943
2162.83	809.371
2164.74	828.549
2166.65	804.717
2168.56	808.375
2170.47	795.614
2172.37	785.31
2174.28	791.363
2176.19	783.7
2178.09	772.989
2180	769.034
2181.9	761.619
2183.81	767.005
2185.71	749.117
2187.61	744.653
2189.51	752.254
2191.42	734.564
2193.32	737.952
2195.22	739.56
2197.12	733.637
2199.02	730.758
2200.92	733.104
2202.81	726.451
2204.71	724.126
2206.61	716.534
2208.5	717.324
2210.4	723.354
2212.3	709.946
2214.19	718.082
2216.08	719.697
2217.98	708.593
2219.87	723.884
2221.76	705.198
2223.65	713.395
2225.55	717.608
2227.44	720.246
2229.33	717.986
2231.22	718.826
2233.11	710.197
2234.99	717.895
2236.88	714.565
2238.77	713.841
2240.66	711.102
2242.06	733
2243.96	741.5
2245.85	738
2247.75	756
2249.64	759.5
2251.54	742.5
2253.43	744.5
2255.32	720.5
2257.21	693.5
2259.1	707.5
2260.99	703.5
2262.89	695
2264.77	709.5
2266.66	690.5
2268.55	669
2270.44	680.5
2272.33	660
2274.21	665
2276.1	679
2277.98	657
2279.87	653.5
2281.75	644.5
2283.64	666.5
2285.52	645.5
2287.4	657.5
2289.29	660
2291.17	650
2293.05	653.5
2294.93	653.5
2296.81	653
2298.69	637
2300.57	644.5
2302.44	652.5
2304.32	658.5
2306.2	649
2308.08	636
2309.95	650
2311.83	647.5
2313.7	632.5
2315.58	638
2317.45	634.5
2319.32	635
2321.2	634.5
2323.07	629
2324.94	618.5
2326.81	630
2328.68	636.5
2330.55	624
2332.42	638.5
2334.29	614
2336.16	617
2338.02	623
2339.89	618.5
2341.76	623.5
2343.62	609
2345.49	612.5
2347.35	613
2349.22	612
2351.08	595
2352.94	605
2354.81	627
2356.67	616
2358.53	607
2360.39	604.5
2362.25	606
2364.11	606
2365.97	597.5
2367.83	595
2369.69	598
2371.55	601.5
2373.4	597.5
2375.26	590.5
2377.11	597
2378.97	598.5
2380.83	603
2382.68	605
2384.53	595
2386.39	589.5
2388.24	594
2390.09	605
2391.94	591.5
2393.79	581.5
2395.64	586.5
2397.49	587.5
2399.34	569
2401.19	574
2403.04	578.5
2404.89	569
2406.74	564
2408.58	580.5
2410.43	573.5
2412.27	596
2414.12	573
2415.96	578
2417.81	562
2419.65	573
2421.49	572
2423.34	568
2425.18	564
2427.02	558
2428.86	572.5
2430.7	553
2432.54	575
2434.38	549
2436.22	562
2438.05	555
2439.89	568.5
2441.73	568
2443.56	562.5
2445.4	554
2447.24	549
2449.07	528
2450.9	541.5
2452.74	555
2454.57	545
2456.4	544
2458.23	536
2460.07	550
2461.9	541
2463.73	539
2465.56	559.5
2467.39	551
2469.21	554
2471.04	527
2472.87	537.5
2474.7	535
2476.52	539.5
2478.35	530
2480.17	532
2482	538.5
2483.82	532
2485.65	520
2487.47	538
2489.29	531.5
2491.12	531.5
2492.94	522
2494.76	529
2496.58	519
2498.4	531.5
2500.22	519
2502.04	523.5
2503.86	521.5
2505.67	508.5
2507.49	517.5
2509.31	514.5
2511.12	531
2512.94	512
2514.76	529.5
2516.57	513
2518.38	505.5
2520.2	509
2522.01	510.5
2523.82	505
2525.64	511
2527.45	517.5
2529.26	507
2531.07	510.5
2532.88	497.5
2534.69	519.5
2536.5	506.5
2538.31	505.5
2540.11	512
2541.92	506
2543.73	484
2545.53	497
2547.34	509.5
2549.14	493
2550.95	490
2552.75	486.5
2554.56	490.5
2556.36	501
2558.16	499.5
2559.96	482
2561.76	487.5
2563.57	477
2565.37	483
2567.17	490
2568.96	494
2570.76	488.5
2572.56	483
2574.36	483.5
2576.16	468.5
2577.95	460
2579.75	475
2581.54	475
2583.34	475.5
2585.13	470
2586.93	482.5
2588.72	490
2590.51	467
2592.31	488
2594.1	478.5
2595.89	461.5
2597.68	455
2599.47	461
2601.26	465.5
2603.05	467.5
2604.84	460
2606.63	444.5
2608.42	466.5
2610.2	449
2611.99	450
2613.78	460
2615.56	457
2617.35	459
2619.13	450
2620.91	448
2622.7	449.5
2624.48	461
2626.26	433.5
2628.04	454.5
2629.83	440.5
2631.61	444.5
2633.39	442
2635.17	437.5
2636.95	443.5
2638.73	434.5
2640.5	449
2642.28	433
2644.06	441.5
2645.84	429
2647.61	420
2649.39	435.5
2651.16	421
2652.94	428
2654.71	410.5
2656.49	426
2658.26	434
2660.03	442
2661.8	421
2663.57	416.5
2665.35	403
2667.12	421.5
2668.89	432
2670.66	422.5
2672.42	424
2674.19	423
2675.96	419.5
2677.73	418
2679.49	404
2681.26	419.5
2683.03	424
2684.79	418.5
2686.56	408
2688.32	418.5
2690.09	402.5
2691.85	402
2693.61	414.5
2695.37	409
2697.14	409
2698.9	404
2700.66	402
2702.42	399.5
2704.18	409
2705.94	400
2707.7	403.5
2709.45	398.5
2711.21	401
2712.97	396
2714.72	397
2716.48	402.5
2718.24	407.5
2719.99	393.5
2721.75	400
2723.5	405.5
2725.25	386.5
2727.01	400
2728.76	391
2730.51	386
2732.26	390
2734.01	389.5
2735.76	389
2737.51	390
2739.26	372.5
2741.01	390
2742.76	380
2744.51	376
2746.26	393
2748	388
2749.75	382.5
2751.5	384
2753.24	363
2754.99	368
2756.73	368.5
2758.47	381
2760.22	371.5
2761.96	380
2763.7	384
2765.44	372
2767.19	368.5
2768.93	370.5
2770.67	373.5
2772.41	363
2774.15	361.5
2775.89	362.5
2777.62	356.5
2779.36	370
2781.1	373.5
2782.84	360.5
2784.57	372
2786.31	356.5
2788.04	355.5
2789.78	362.5
2791.51	349
2793.24	361
2794.98	357
2796.71	354
2798.44	358
2800.18	349
2801.91	358.5
2803.64	351
2805.37	348
2807.1	357.5
2808.83	342
2810.55	343
2812.28	351.5
2814.01	356.5
2815.74	346.5
2817.46	341
2819.19	350
2820.92	338.5
2822.64	345
2824.37	342
2826.09	330
2827.81	354.5
2829.54	340.5
2831.26	332
2832.98	331
2834.71	345.5
2836.43	335
2838.15	341
2839.87	337.5
2841.59	354.5
2843.31	347.5
2845.02	356.5
2846.74	360
2848.46	362
2850.18	351
2851.9	350.5
2853.61	366.5
2855.33	356
2857.04	357
2858.76	358.5
2860.47	353
2862.19	353.5
2863.9	348
2865.61	351
2867.32	344.5
2869.04	351
2870.75	356
2872.46	359.5
2874.17	352.5
2875.88	358.5
2877.59	343
2879.3	356.5
2881	359.5
2882.71	358.5
2884.42	344
2886.13	357.5
2887.83	346
2889.54	342.5
2891.24	356
2892.95	361
2894.65	341
2896.36	360.5
2898.06	349.5
2899.76	351.5
2901.47	353
2903.17	349
2904.87	347.5
2906.57	347
2908.27	359
2909.97	346
2911.67	369.5
2913.37	356.5
2915.07	352
2916.77	355.5
2918.47	358
2920.16	368
2921.86	358
2923.55	361
2925.25	378
2926.94	364.5
2928.64	369.5
2930.33	371
2932.03	364
2933.72	374
2935.41	381.5
2937.11	380
2938.8	374
2940.49	367
2942.18	364
2943.87	365.5
2945.56	353.5
2947.25	345
2948.94	344
2950.63	348.5
2952.31	333
2954	331
2955.69	327.5
2957.37	328
2959.06	325.5
2960.75	316.5
2962.43	317.5
2964.11	324.5
2965.8	312
2967.48	301
2969.16	312.5
2970.85	315
2972.53	317
2974.21	313
2975.89	313.5
2977.57	306
2979.25	303
2980.93	298
2982.61	283.5
2984.29	280
2985.97	297.5
2987.65	285.5
2989.32	284
2991	287.5
2992.68	276.5
2994.35	272
2996.03	282.5
2997.7	275
2999.38	268.5