File: muestras/ogompa/nsno_06.txt
#Acq. time (s)=	5
#Accumulations=	5
#Range (cm-¹)=	100...3000
#Windows=	3
#Autofocus=	Off
#AutoExposure=	Off
#Spike filter=	Multiple accum.
#Delay time (s)=	0
#Binning=	1
#Readout mode=	Signal
#DeNoise=	Off
#ICS correction=	Off
#Dark correction=	Off
#Inst. Process=	Off
#Instrument=	LabRAM HR Evol
#Detector=	Syncerity OE
#Objective=	x100_VIS_LWD
#Grating=	600 (500nm)
#ND Filter=	100%
#Laser=	633nm_Edge
#Hole=	100.021
#Range=	Visible
#Project=	Omar
#Sample=	chi
#Site=	f
#Title=	nsno
#Remark=
#Date=	12.09.2023 17:00
#Acquired=	12.09.2023 17:00:33
101.026	11658
103.592	11483.5
106.158	11260
108.723	11066.5
111.289	10853.5
113.852	10596.5
116.415	10463
118.976	10376
121.537	10156
124.097	10079
126.656	9969
129.215	9825.5
131.772	9748.5
134.327	9609.5
136.883	9429
139.438	9308.5
141.992	9219
144.545	9079.5
147.096	8974
149.648	8852.5
152.199	8775
154.747	8643.5
157.296	8533
159.843	8383
162.391	8304
164.937	8148
167.482	8116.5
170.025	8074.5
172.569	7928
175.111	7906
177.654	7882.5
180.194	7798.5
182.733	7880.5
185.273	7815
187.811	7794
190.348	7843
192.884	7875
195.419	7974.5
197.955	7935
200.489	8002.5
203.022	8096.5
205.554	8073.5
208.085	8136.5
210.615	8162.5
213.144	8099.5
215.673	8184
218.201	8172.5
220.728	8191.5
223.253	8201.5
225.778	8189.5
228.303	8221
230.826	8194
233.348	8301.5
235.87	8234.5
238.391	8247.5
240.91	8211
243.43	8212.5
245.949	8116.5
248.465	8101
250.983	8019.5
253.498	8022
256.013	7854
258.526	7743.5
261.039	7671
263.552	7516
266.063	7505.5
268.573	7371.5
271.084	7291
273.592	7110
276.1	7051.5
278.607	6928
281.113	6831.5
283.619	6854
286.124	6774
288.627	6726.5
291.13	6669
293.632	6611
296.133	6587
298.634	6579.5
301.133	6544
303.63	6538
306.128	6410
308.625	6495
311.122	6436.5
313.617	6426.5
316.111	6329.5
318.604	6288
321.098	6214
323.588	6204
326.08	6103.5
328.569	6115
331.059	6101
333.548	6068.5
336.035	6025.5
338.521	6033
341.008	6028
343.492	6001
345.977	6008.5
348.46	6020.5
350.942	5938
353.425	6002.5
355.905	5991
358.385	5983
360.864	5985.5
363.342	5998
365.819	6028
368.296	6001.5
370.771	5961
373.246	5992.5
375.72	5960
378.194	5974.5
380.666	5997.5
383.138	6002.5
385.609	6034
388.079	6003.5
390.548	5981.5
393.016	5981
395.483	5923
397.95	5963
400.416	5941.5
402.88	5935
405.345	6006.5
407.807	6020.5
410.27	6049.5
412.731	6039.5
415.193	6092.5
417.652	6045
420.112	6106
422.569	6146.5
425.028	6172.5
427.484	6166
429.939	6119.5
432.394	6171
434.849	6105.5
437.302	6118.5
439.754	6110
442.205	6110
444.656	6108.5
447.106	6169.5
449.555	6135.5
452.003	6080
454.45	6159
456.897	6089.5
459.343	6050
461.788	6061
464.232	6051.5
466.676	5971
469.119	6047
471.559	6063
474.001	6051.5
476.441	6053
478.879	6083
481.318	6090
483.756	6074
486.192	6092.5
488.629	6131
491.063	6197
493.498	6158.5
495.931	6151.5
498.365	6171.5
500.796	6154
503.226	6116.5
505.657	6202
508.086	6181.5
510.515	6121
512.942	6150
515.369	6111
517.796	6097.5
520.221	6136.5
522.645	6066
525.069	6128
527.492	6127.5
529.914	6092
532.335	6129
534.756	6090.5
537.175	6064.5
539.593	6032.5
542.011	5996
544.429	6006
546.845	6105
549.261	6032.5
551.675	6111.5
554.089	6059
556.503	6005
558.914	6059.5
561.326	6072.5
563.736	6079.5
566.147	6110
568.555	6094
570.964	6073.5
573.371	6080
575.777	6131
578.184	6123
580.588	6110.5
582.992	6130.5
585.395	6120.5
587.799	6139.5
590.201	6115.5
592.601	6094.5
595.001	6058
597.401	6085
599.799	6137.5
602.197	6137
604.594	6146
606.99	6156
609.386	6175
611.78	6197
614.174	6256.5
616.566	6244.5
618.958	6310.5
621.35	6299.5
623.741	6352
626.13	6356
628.519	6414
630.908	6396
633.295	6379.5
635.682	6422.5
638.067	6438.5
640.453	6410.5
642.836	6386.5
645.219	6424
647.602	6421.5
649.984	6363
652.364	6377
654.745	6340.5
657.124	6366.5
659.503	6363.5
661.88	6326.5
664.257	6305
666.635	6255.5
669.01	6246.5
671.384	6178
673.758	6187
676.131	6154
678.502	6215
680.874	6206
683.245	6197
685.615	6198
687.984	6147.5
690.353	6167
692.719	6123.5
695.086	6139.5
697.453	6065.5
699.817	6094.5
702.182	6121.5
704.545	6121.5
706.908	6063.5
709.27	6036.5
711.632	6101
713.991	6091
716.352	6079
718.71	6027.5
721.068	6054
723.426	6058
725.782	6079
728.138	6045.5
730.492	6053.5
732.846	6047.5
735.201	6068.5
737.553	6029.5
739.905	5965.5
742.256	6013
744.606	6074
746.956	5987
749.303	6025
751.651	6008
753.999	6011.5
756.345	5983.5
758.691	6000
761.035	5996.5
763.379	5957.5
765.723	5948
768.064	5962
770.407	5970.5
772.748	5958
775.088	5956.5
777.427	5918.5
779.765	5952
782.104	5910.5
784.44	5914.5
786.776	5946.5
789.113	5946.5
791.447	5919.5
793.78	5950
796.113	5921
798.445	5945
800.778	5934.5
803.109	5979
805.439	6014.5
807.768	6056.5
810.096	6004
812.424	6096.5
814.751	6132.5
817.078	6109
819.402	6172.5
821.727	6139
824.051	6173
826.374	6210.5
828.697	6179
831.018	6256
833.339	6262.5
835.659	6283.5
837.978	6291.5
840.297	6276.5
842.614	6260.5
844.932	6305.5
847.247	6244
849.562	6234.5
851.878	6268.5
854.191	6271
856.504	6278
858.817	6273.5
861.129	6349.5
863.439	6267
865.749	6266.5
868.058	6297.5
870.367	6240.5
872.676	6284
874.983	6205.5
877.289	6164
879.593	6191.5
881.898	6208.5
884.202	6157
886.506	6096.5
888.808	6117.5
891.11	6087
893.41	6119.5
895.711	6031.5
898.011	6050
900.309	6008.5
902.607	6054.5
904.904	6024
907.201	5985.5
909.496	6010
911.791	5989
914.085	5971
916.379	6024
918.671	6017.5
920.963	5985
923.255	6050
925.545	5991
927.834	5994
930.123	5998.5
932.411	6078.5
934.698	6055.5
936.985	6066.5
939.271	6084
941.556	6085.5
943.84	6061.5
946.124	6089
948.407	6103
950.689	6120.5
952.971	6124
955.25	6166.5
957.531	6131.5
959.81	6172.5
962.088	6237.5
964.366	6202
966.643	6229.5
968.919	6157
971.195	6207.5
973.469	6208.5
975.743	6195
978.016	6162
980.288	6191
982.56	6183
984.831	6193
987.101	6220.5
989.37	6167
991.638	6230
993.907	6263
996.174	6309.5
998.44	6376
1000.71	6312.5
1002.97	6243.5
1005.24	6190.5
1007.5	6143.5
1009.76	6180.5
1012.02	6074.5
1014.28	6161
1016.54	6108
1018.8	6233
1021.06	6216.5
1023.32	6276.5
1025.58	6254
1027.84	6272
1030.09	6295
1032.35	6302
1034.6	6308.5
1036.86	6355.5
1039.11	6349.5
1041.36	6367
1043.61	6353
1045.86	6330
1048.11	6355.5
1050.36	6341.5
1052.61	6409
1054.86	6391
1057.11	6423.5
1059.35	6431.5
1061.6	6409
1063.84	6458.5
1066.09	6447.5
1068.33	6435
1070.57	6445
1072.82	6477.5
1075.06	6480
1077.3	6481
1079.54	6483
1081.78	6510.5
1084.02	6520
1086.25	6445.5
1088.49	6466
1090.73	6474.5
1092.96	6458
1095.2	6532
1097.43	6498.5
1099.66	6531.5
1101.9	6535.5
1104.13	6486.5
1106.36	6539
1108.59	6574
1110.82	6557.5
1113.05	6602
1115.28	6594
1117.51	6603
1119.73	6669.5
1121.96	6705.5
1124.18	6729
1126.41	6803.5
1128.63	6813
1130.85	6848
1133.08	6884.5
1135.3	6858
1137.52	6967
1139.74	6974
1141.96	7032
1144.18	7174
1146.4	7254
1148.61	7299.5
1150.83	7375
1153.05	7465.5
1155.26	7607.5
1157.48	7656
1159.69	7712
1161.9	7742.5
1164.11	7775
1166.33	7853.5
1168.54	7840
1170.75	7909.5
1172.96	7858
1175.17	7793
1177.37	7803
1179.58	7673.5
1181.79	7652.5
1183.99	7629.5
1186.2	7633
1188.4	7604.5
1190.61	7578
1192.81	7559.5
1195.01	7646
1197.21	7665.08
1199.42	7617.36
1201.61	7688.65
1203.81	7680.3
1206.01	7657.79
1208.21	7646.49
1210.41	7692.92
1212.61	7643.69
1214.8	7651.45
1217	7654.19
1219.19	7672.63
1221.38	7661.22
1223.58	7654
1225.77	7717.56
1227.96	7685.64
1230.15	7746.47
1232.34	7800.9
1234.53	7782.62
1236.72	7850.09
1238.91	7824.39
1241.1	7798.92
1243.28	7852.13
1245.47	7880.81
1247.65	7886.28
1249.84	7938
1252.02	7932.46
1254.21	8000.29
1256.39	8043.72
1258.57	8082.33
1260.75	8118.04
1262.93	8170.87
1265.11	8217.22
1267.29	8234.13
1269.47	8298.31
1271.65	8288.38
1273.82	8267.81
1276	8368.12
1278.17	8298.7
1280.35	8366.32
1282.52	8396.21
1284.69	8443.15
1286.87	8456.36
1289.04	8472.18
1291.21	8474.1
1293.38	8552.57
1295.55	8468.45
1297.72	8502.19
1299.89	8474.79
1302.06	8434.28
1304.22	8502.35
1306.39	8525.11
1308.43	8588.5
1310.6	8584.5
1312.78	8639
1314.96	8567
1317.13	8669
1319.3	8621.5
1321.47	8615.5
1323.65	8608
1325.82	8602
1327.99	8587.5
1330.16	8569.5
1332.32	8605
1334.49	8585.5
1336.66	8601
1338.83	8586.5
1340.99	8552.5
1343.16	8579
1345.32	8612.5
1347.49	8574
1349.65	8626
1351.81	8521.5
1353.98	8573
1356.14	8624.5
1358.3	8511.5
1360.46	8493
1362.62	8536.5
1364.78	8551
1366.93	8485
1369.09	8380
1371.25	8378
1373.4	8291.5
1375.56	8335.5
1377.71	8282.5
1379.87	8251
1382.02	8283.5
1384.17	8376.5
1386.32	8305
1388.47	8234
1390.63	8194
1392.77	8238
1394.92	8172
1397.07	8172.5
1399.22	8221.5
1401.37	8234.5
1403.51	8248.5
1405.66	8268.5
1407.8	8213.5
1409.95	8221
1412.09	8239
1414.23	8268
1416.38	8324.5
1418.52	8306.5
1420.66	8245
1422.8	8328
1424.94	8396
1427.08	8419
1429.21	8447.5
1431.35	8517.5
1433.49	8496.5
1435.63	8456.5
1437.76	8562
1439.89	8546
1442.03	8671.5
1444.16	8690
1446.3	8662
1448.43	8686
1450.56	8723.5
1452.69	8823.5
1454.82	8860
1456.95	8901
1459.08	8978
1461.2	9019.5
1463.33	9146
1465.46	9145.5
1467.58	9202
1469.71	9266.5
1471.83	9399
1473.96	9405
1476.08	9507
1478.2	9506
1480.33	9523.5
1482.45	9581
1484.57	9576.5
1486.69	9617.5
1488.81	9579.5
1490.93	9570.5
1493.04	9556
1495.16	9533
1497.28	9485
1499.39	9476
1501.51	9437.5
1503.62	9338.5
1505.74	9308.5
1507.85	9251
1509.96	9184.5
1512.07	9247
1514.19	9179.5
1516.3	9263
1518.41	9358.5
1520.52	9352
1522.62	9355
1524.73	9452.5
1526.84	9467
1528.95	9511.5
1531.05	9543
1533.16	9549
1535.26	9586.5
1537.37	9554.5
1539.47	9547.5
1541.57	9522
1543.67	9544.5
1545.78	9582
1547.88	9507
1549.98	9563.5
1552.07	9535.5
1554.17	9572
1556.27	9511
1558.37	9551
1560.47	9520.5
1562.56	9443
1564.66	9459.5
1566.75	9434.5
1568.85	9472
1570.94	9404
1573.03	9381.5
1575.12	9424
1577.21	9390
1579.31	9336
1581.4	9268.5
1583.49	9300
1585.57	9267
1587.66	9256
1589.75	9203.5
1591.84	9199
1593.92	9152
1596.01	9097
1598.09	9022.5
1600.18	8884
1602.26	8686.5
1604.34	8519.5
1606.43	8363.5
1608.51	8147.5
1610.59	7920
1612.67	7675
1614.75	7543.5
1616.83	7366
1618.91	7238.5
1620.98	7096
1623.06	6845.5
1625.14	6749.5
1627.21	6598.5
1629.29	6400.5
1631.36	6316.5
1633.43	6180
1635.51	6041.5
1637.58	5916.5
1639.65	5771
1641.72	5719
1643.79	5541
1645.86	5506.5
1647.93	5343.5
1650	5330.5
1652.07	5265
1654.14	5174
1656.2	5117.5
1658.27	5026
1660.34	4938
1662.4	4860.5
1664.46	4837.5
1666.53	4816.5
1668.59	4729.5
1670.65	4668.5
1672.71	4609.5
1674.77	4545
1676.83	4535.5
1678.89	4534.5
1680.95	4460
1683.01	4474
1685.07	4445
1687.13	4397
1689.18	4336.5
1691.24	4297
1693.29	4296
1695.35	4263
1697.4	4241.5
1699.45	4236.5
1701.51	4182
1703.56	4116
1705.61	4134.5
1707.66	4138.5
1709.71	4077
1711.76	4039
1713.81	4000
1715.86	4018.5
1717.9	3971
1719.95	3956.5
1722	3916.5
1724.04	3949
1726.09	3895
1728.13	3905
1730.17	3840
1732.22	3795
1734.26	3802
1736.3	3761
1738.34	3796.5
1740.38	3732
1742.42	3733
1744.46	3720.5
1746.5	3702.5
1748.54	3686
1750.57	3650
1752.61	3623
1754.65	3614.5
1756.68	3582
1758.72	3602
1760.75	3566.5
1762.78	3602
1764.82	3526.5
1766.85	3529
1768.88	3498
1770.91	3505.5
1772.94	3505
1774.97	3488.5
1777	3423
1779.03	3447.5
1781.06	3403.5
1783.08	3411
1785.11	3420
1787.14	3430
1789.16	3391.5
1791.18	3424
1793.21	3349
1795.23	3353
1797.26	3335.5
1799.28	3372
1801.3	3337
1803.32	3263.5
1805.34	3282
1807.36	3255.5
1809.38	3248
1811.4	3252
1813.41	3250.5
1815.43	3223
1817.45	3233.5
1819.46	3205.5
1821.48	3210
1823.49	3190
1825.51	3164.5
1827.52	3157.5
1829.53	3180.5
1831.54	3148
1833.56	3129
1835.57	3148
1837.58	3091.5
1839.59	3111.5
1841.59	3111
1843.6	3071.5
1845.61	3088
1847.62	3019.5
1849.62	3029.5
1851.63	3031
1853.64	3003
1855.64	3015.5
1857.64	3021.5
1859.65	2977.5
1861.65	2967
1863.65	2977
1865.65	2969
1867.65	2969
1869.65	2959
1871.65	2938.5
1873.65	2970.5
1875.65	2929
1877.65	2905.5
1879.65	2886.5
1881.64	2895
1883.64	2899.5
1885.63	2910.5
1887.63	2903.5
1889.62	2894.5
1891.62	2883
1893.61	2859
1895.6	2816.5
1897.59	2858.5
1899.58	2838.5
1901.57	2838
1903.56	2828.5
1905.55	2849
1907.54	2810.5
1909.53	2813.5
1911.52	2785.5
1913.5	2803
1915.49	2794
1917.48	2828.5
1919.46	2817.5
1921.44	2763.5
1923.43	2784
1925.41	2794.5
1927.39	2769
1929.38	2750
1931.36	2778
1933.34	2753.5
1935.32	2735
1937.3	2745
1939.28	2737.5
1941.25	2733
1943.23	2725
1945.21	2709.5
1947.18	2723.5
1949.16	2697.5
1951.13	2713
1953.11	2704.5
1955.08	2664.5
1957.06	2655
1959.03	2671
1961	2696
1962.97	2621
1964.94	2637
1966.91	2642
1968.88	2622
1970.85	2654
1972.82	2619
1974.79	2618.5
1976.76	2575
1978.72	2592
1980.69	2597
1982.65	2598.5
1984.62	2604.5
1986.58	2569
1988.55	2603.5
1990.51	2583.5
1992.47	2544.5
1994.43	2539.5
1996.39	2566
1998.36	2559
2000.31	2547.5
2002.27	2524
2004.23	2536.5
2006.19	2523
2008.15	2541
2010.11	2506
2012.06	2539
2014.02	2508.5
2015.97	2504.5
2017.93	2494
2019.88	2514
2021.83	2486.5
2023.79	2477.5
2025.74	2477.5
2027.69	2431.5
2029.64	2458.5
2031.59	2469
2033.54	2455.5
2035.49	2414
2037.44	2416
2039.39	2443.5
2041.34	2394
2043.28	2416
2045.23	2406
2047.17	2409.5
2049.12	2417
2051.06	2411
2053.01	2406
2054.95	2404.5
2056.89	2363
2058.84	2390.5
2060.78	2376.5
2062.72	2352
2064.66	2374
2066.6	2357
2068.54	2365.5
2070.48	2335.5
2072.41	2371
2074.35	2326.5
2076.29	2334
2078.22	2344.5
2080.16	2315
2082.09	2306
2084.03	2284
2085.96	2282
2087.9	2293.5
2089.83	2320
2091.76	2276.5
2093.69	2267.5
2095.62	2282
2097.55	2318.5
2099.48	2294
2101.41	2297
2103.34	2284.5
2105.27	2261.5
2107.19	2314
2109.12	2245
2111.05	2259.5
2112.97	2261
2114.9	2249.5
2116.82	2279
2118.75	2257.5
2120.67	2257
2122.59	2253.5
2124.51	2266.5
2126.43	2245.5
2128.36	2229.5
2130.28	2251
2132.2	2229.5
2134.11	2228
2136.03	2198.5
2137.95	2199.5
2139.87	2203
2141.78	2213
2143.7	2189
2145.62	2188.45
2147.53	2150.4
2149.45	2185.94
2151.36	2143.28
2153.27	2122.96
2155.19	2139.39
2157.1	2091.51
2159.01	2097.56
2160.92	2078.37
2162.83	2091.24
2164.74	2068.71
2166.65	2059.36
2168.56	2051.7
2170.47	2036.66
2172.37	2007.3
2174.28	2028
2176.19	2022.77
2178.09	2016.7
2180	1990.72
2181.9	2015.89
2183.81	1977.39
2185.71	1967.47
2187.61	1983.63
2189.51	1978.24
2191.42	1989.17
2193.32	1966.31
2195.22	1984.32
2197.12	1944.56
2199.02	1957.93
2200.92	1972.31
2202.81	1946.47
2204.71	1945.11
2206.61	1952.34
2208.5	1958.02
2210.4	1956.1
2212.3	1934.88
2214.19	1932.58
2216.08	1951.48
2217.98	1925.58
2219.87	1922.98
2221.76	1912.01
2223.65	1921.24
2225.55	1924.09
2227.44	1917.08
2229.33	1917.22
2231.22	1903.25
2233.11	1888.22
2234.99	1889.92
2236.88	1903.36
2238.77	1866.09
2240.66	1851.15
2242.06	1860.5
2243.96	1886.5
2245.85	1857.5
2247.75	1863
2249.64	1836
2251.54	1872.5
2253.43	1801.5
2255.32	1827
2257.21	1834
2259.1	1777.5
2260.99	1780.5
2262.89	1751
2264.77	1804.5
2266.66	1783.5
2268.55	1799
2270.44	1764.5
2272.33	1750
2274.21	1753
2276.1	1748.5
2277.98	1729
2279.87	1716.5
2281.75	1762
2283.64	1756
2285.52	1715.5
2287.4	1736.5
2289.29	1740
2291.17	1710
2293.05	1706
2294.93	1723.5
2296.81	1709
2298.69	1697.5
2300.57	1684
2302.44	1723
2304.32	1679.5
2306.2	1703.5
2308.08	1668.5
2309.95	1667
2311.83	1690
2313.7	1688
2315.58	1717
2317.45	1680.5
2319.32	1639.5
2321.2	1688.5
2323.07	1654
2324.94	1656
2326.81	1667.5
2328.68	1643
2330.55	1664
2332.42	1673
2334.29	1655
2336.16	1648
2338.02	1624
2339.89	1654
2341.76	1617
2343.62	1648
2345.49	1664
2347.35	1627
2349.22	1638
2351.08	1623.5
2352.94	1627.5
2354.81	1613
2356.67	1612
2358.53	1614
2360.39	1618
2362.25	1595
2364.11	1604
2365.97	1616.5
2367.83	1616
2369.69	1574
2371.55	1607.5
2373.4	1579
2375.26	1612
2377.11	1592
2378.97	1583
2380.83	1567.5
2382.68	1583
2384.53	1551
2386.39	1548.5
2388.24	1573.5
2390.09	1568.5
2391.94	1569
2393.79	1566
2395.64	1560.5
2397.49	1542.5
2399.34	1539
2401.19	1542.5
2403.04	1554.5
2404.89	1546.5
2406.74	1529
2408.58	1539
2410.43	1568
2412.27	1564
2414.12	1516.5
2415.96	1545
2417.81	1545
2419.65	1523
2421.49	1511.5
2423.34	1526.5
2425.18	1520
2427.02	1510
2428.86	1517.5
2430.7	1543
2432.54	1515
2434.38	1531
2436.22	1477.5
2438.05	1515
2439.89	1480
2441.73	1494
2443.56	1500
2445.4	1500.5
2447.24	1485
2449.07	1485.5
2450.9	1490
2452.74	1482
2454.57	1468
2456.4	1487
2458.23	1490.5
2460.07	1459.5
2461.9	1451.5
2463.73	1443
2465.56	1458
2467.39	1462
2469.21	1462
2471.04	1479
2472.87	1465.5
2474.7	1462.5
2476.52	1440.5
2478.35	1425
2480.17	1447
2482	1467
2483.82	1434
2485.65	1425
2487.47	1447.5
2489.29	1418
2491.12	1404
2492.94	1461
2494.76	1428
2496.58	1433.5
2498.4	1436.5
2500.22	1446.5
2502.04	1422
2503.86	1421.5
2505.67	1408.5
2507.49	1406
2509.31	1392
2511.12	1423.5
2512.94	1411
2514.76	1413.5
2516.57	1384
2518.38	1404
2520.2	1389.5
2522.01	1395.5
2523.82	1394
2525.64	1407
2527.45	1369.5
2529.26	1372
2531.07	1379.5
2532.88	1373.5
2534.69	1376
2536.5	1344.5
2538.31	1302
2540.11	1377.5
2541.92	1343
2543.73	1384
2545.53	1334
2547.34	1354
2549.14	1361
2550.95	1337
2552.75	1343.5
2554.56	1356
2556.36	1371
2558.16	1360
2559.96	1366
2561.76	1363.5
2563.57	1317.5
2565.37	1359.5
2567.17	1318.5
2568.96	1299
2570.76	1331
2572.56	1305
2574.36	1330.5
2576.16	1335
2577.95	1336.5
2579.75	1313.5
2581.54	1290
2583.34	1314
2585.13	1344
2586.93	1309.5
2588.72	1296.5
2590.51	1302
2592.31	1297.5
2594.1	1307.5
2595.89	1303.5
2597.68	1294.5
2599.47	1283
2601.26	1283.5
2603.05	1298
2604.84	1310
2606.63	1284
2608.42	1257
2610.2	1257
2611.99	1286
2613.78	1286
2615.56	1281.5
2617.35	1254
2619.13	1260
2620.91	1292.5
2622.7	1274
2624.48	1259
2626.26	1260
2628.04	1255
2629.83	1261.5
2631.61	1254
2633.39	1238
2635.17	1254.5
2636.95	1248.5
2638.73	1231
2640.5	1239
2642.28	1241
2644.06	1210
2645.84	1234
2647.61	1228
2649.39	1218
2651.16	1237
2652.94	1217.5
2654.71	1232
2656.49	1227
2658.26	1244.5
2660.03	1235
2661.8	1206
2663.57	1223
2665.35	1210
2667.12	1186
2668.89	1194.5
2670.66	1227.5
2672.42	1174
2674.19	1184
2675.96	1215.5
2677.73	1195
2679.49	1210
2681.26	1221
2683.03	1197.5
2684.79	1192.5
2686.56	1208
2688.32	1215.5
2690.09	1189.5
2691.85	1183
2693.61	1189.5
2695.37	1159
2697.14	1170
2698.9	1186
2700.66	1175
2702.42	1162.5
2704.18	1180.5
2705.94	1169.5
2707.7	1161
2709.45	1157
2711.21	1160
2712.97	1139
2714.72	1152
2716.48	1136.5
2718.24	1164
2719.99	1138
2721.75	1144.5
2723.5	1163.5
2725.25	1144
2727.01	1143
2728.76	1134
2730.51	1147.5
2732.26	1118
2734.01	1137
2735.76	1131
2737.51	1115
2739.26	1122
2741.01	1100
2742.76	1121
2744.51	1100
2746.26	1094
2748	1116.5
2749.75	1083.5
2751.5	1141.5
2753.24	1107
2754.99	1104
2756.73	1106
2758.47	1083
2760.22	1079
2761.96	1077
2763.7	1105
2765.44	1080
2767.19	1086
2768.93	1081
2770.67	1052.5
2772.41	1040
2774.15	1096
2775.89	1067
2777.62	1062.5
2779.36	1064
2781.1	1044
2782.84	1060
2784.57	1039
2786.31	1068
2788.04	1066.5
2789.78	1040
2791.51	1054
2793.24	1047.5
2794.98	1034
2796.71	1047
2798.44	1027
2800.18	1019
2801.91	1058.5
2803.64	1030.25
2805.37	1037
2807.1	1024
2808.83	1022.5
2810.55	996
2812.28	1021
2814.01	1006
2815.74	1011
2817.46	1024.5
2819.19	1013
2820.92	997
2822.64	1011
2824.37	1000
2826.09	999
2827.81	997
2829.54	981
2831.26	1009
2832.98	987
2834.71	983.5
2836.43	974
2838.15	987
2839.87	994
2841.59	976.5
2843.31	993.5
2845.02	999.5
2846.74	994
2848.46	988.5
2850.18	1008.5
2851.9	971
2853.61	984.5
2855.33	961.5
2857.04	973
2858.76	965
2860.47	985.5
2862.19	962
2863.9	977
2865.61	991
2867.32	954
2869.04	951
2870.75	970
2872.46	966
2874.17	979
2875.88	978
2877.59	948.5
2879.3	964
2881	975
2882.71	947
2884.42	962
2886.13	956
2887.83	951
2889.54	963.5
2891.24	955
2892.95	978.5
2894.65	958.5
2896.36	953
2898.06	963.5
2899.76	944.5
2901.47	978
2903.17	962
2904.87	951
2906.57	960.5
2908.27	942
2909.97	950
2911.67	958.5
2913.37	955
2915.07	970
2916.77	956
2918.47	945
2920.16	964.5
2921.86	955
2923.55	945
2925.25	974
2926.94	928
2928.64	960
2930.33	951
2932.03	943.5
2933.72	946
2935.41	933
2937.11	919
2938.8	916
2940.49	918
2942.18	900
2943.87	919
2945.56	912.5
2947.25	885
2948.94	894.5
2950.63	869
2952.31	863
2954	854.5
2955.69	886
2957.37	863.5
2959.06	858
2960.75	865.5
2962.43	860
2964.11	831
2965.8	854.5
2967.48	834
2969.16	840
2970.85	809
2972.53	819
2974.21	811
2975.89	851.5
2977.57	828
2979.25	838.5
2980.93	814
2982.61	832
2984.29	795
2985.97	814.5
2987.65	811
2989.32	790
2991	795.5
2992.68	788
2994.35	765
2996.03	760
2997.7	771.5
2999.38	755