File: muestras/ogompa/nsno_05.txt
#Acq. time (s)=	5
#Accumulations=	5
#Range (cm-¹)=	100...3000
#Windows=	3
#Autofocus=	Off
#AutoExposure=	Off
#Spike filter=	Multiple accum.
#Delay time (s)=	0
#Binning=	1
#Readout mode=	Signal
#DeNoise=	Off
#ICS correction=	Off
#Dark correction=	Off
#Inst. Process=	Off
#Instrument=	LabRAM HR Evol
#Detector=	Syncerity OE
#Objective=	x100_VIS_LWD
#Grating=	600 (500nm)
#ND Filter=	100%
#Laser=	633nm_Edge
#Hole=	100.021
#Range=	Visible
#Project=	Omar
#Sample=	chi
#Site=	f
#Title=	nsno
#Remark=
#Date=	12.09.2023 16:57
#Acquired=	12.09.2023 16:57:52
101.026	10288.5
103.592	10199
106.158	10036
108.723	9881.5
111.289	9753.5
113.852	9657
116.415	9564.5
118.976	9446
121.537	9381
124.097	9312
126.656	9174
129.215	9103.5
131.772	9057
134.327	8962.5
136.883	8710
139.438	8751
141.992	8526
144.545	8456
147.096	8382
149.648	8262
152.199	8189
154.747	8092
157.296	8050.5
159.843	7996
162.391	7994
164.937	7879
167.482	7834.5
170.025	7749.5
172.569	7612
175.111	7634.5
177.654	7604
180.194	7561
182.733	7542
185.273	7503.5
187.811	7478.5
190.348	7498.5
192.884	7516
195.419	7536.5
197.955	7471.5
200.489	7540
203.022	7559.5
205.554	7621.5
208.085	7540.5
210.615	7567
213.144	7547
215.673	7594
218.201	7605.5
220.728	7591
223.253	7600.5
225.778	7624.5
228.303	7645.5
230.826	7692.5
233.348	7692
235.87	7663.5
238.391	7718
240.91	7764
243.43	7794
245.949	7828
248.465	7846.5
250.983	7857.5
253.498	7825.5
256.013	7850.5
258.526	7880
261.039	7856.5
263.552	7805.5
266.063	7769.5
268.573	7875.5
271.084	7807.5
273.592	7838
276.1	7872.5
278.607	7887.5
281.113	7963
283.619	8009
286.124	8061
288.627	8150
291.13	8096
293.632	8184.5
296.133	8184.5
298.634	8220.5
301.133	8183.5
303.63	8100
306.128	8126
308.625	8123.5
311.122	8115.5
313.617	8099.5
316.111	8078.5
318.604	8038.5
321.098	8021.5
323.588	7932.5
326.08	7925.5
328.569	7882.5
331.059	7875.5
333.548	7850
336.035	7849
338.521	7865
341.008	7881.5
343.492	7914.5
345.977	7859
348.46	7927
350.942	7922.5
353.425	7934
355.905	7961
358.385	7944.5
360.864	7974.5
363.342	8017.5
365.819	7980
368.296	8026.5
370.771	7958.5
373.246	8034.5
375.72	7985
378.194	8009
380.666	7995
383.138	7966.5
385.609	7920.5
388.079	7971
390.548	7900.5
393.016	7905.5
395.483	7906
397.95	7894.5
400.416	7885
402.88	7930.5
405.345	7981.5
407.807	7977
410.27	7989
412.731	8004
415.193	8065
417.652	8138.5
420.112	8103.5
422.569	8147
425.028	8147.5
427.484	8182
429.939	8253
432.394	8244.5
434.849	8244.5
437.302	8257
439.754	8283
442.205	8191
444.656	8238.5
447.106	8197.5
449.555	8204.5
452.003	8195
454.45	8176.5
456.897	8209
459.343	8104.5
461.788	8196
464.232	8171
466.676	8222
469.119	8144
471.559	8181.5
474.001	8101.5
476.441	8156.5
478.879	8189.5
481.318	8168
483.756	8202
486.192	8180.5
488.629	8193
491.063	8144.5
493.498	8181.5
495.931	8193
498.365	8216.5
500.796	8212.5
503.226	8188.5
505.657	8217
508.086	8163
510.515	8190
512.942	8175
515.369	8174
517.796	8085.5
520.221	8066.5
522.645	8063
525.069	8094
527.492	8139.5
529.914	8051.5
532.335	8098
534.756	8043
537.175	8041.5
539.593	8035
542.011	8008
544.429	8042.5
546.845	8074
549.261	8026
551.675	8000
554.089	8018.5
556.503	7968.5
558.914	7997
561.326	8052.5
563.736	8048
566.147	8071
568.555	8013.5
570.964	8009.5
573.371	8025.5
575.777	8056
578.184	7965
580.588	8026
582.992	7930
585.395	7962
587.799	8014
590.201	7984
592.601	8059.5
595.001	7986.5
597.401	8011
599.799	8027
602.197	8084.5
604.594	8053.5
606.99	8123
609.386	8106.5
611.78	8150.5
614.174	8098
616.566	8112
618.958	8100
621.35	8072
623.741	8184
626.13	8207
628.519	8195
630.908	8187
633.295	8174
635.682	8256
638.067	8255.5
640.453	8272.5
642.836	8238.5
645.219	8227.5
647.602	8270.5
649.984	8247.5
652.364	8276.5
654.745	8160
657.124	8219
659.503	8201.5
661.88	8197
664.257	8156
666.635	8115
669.01	8116.5
671.384	8047.5
673.758	8074
676.131	8100
678.502	8050.5
680.874	8018.5
683.245	8038.5
685.615	8039.5
687.984	7949.5
690.353	7975.5
692.719	8002.5
695.086	7932
697.453	7944.5
699.817	7981
702.182	7995.5
704.545	7898.5
706.908	7897
709.27	7914
711.632	7930.5
713.991	7943
716.352	7939.5
718.71	7998.5
721.068	7985.5
723.426	7999
725.782	7984.5
728.138	8009.5
730.492	7980
732.846	7930.5
735.201	8006
737.553	7969
739.905	7907
742.256	7961
744.606	7914.5
746.956	7892
749.303	7906.5
751.651	7915
753.999	7872.5
756.345	7816
758.691	7816
761.035	7834.5
763.379	7757
765.723	7753
768.064	7779
770.407	7831.5
772.748	7813.5
775.088	7727
777.427	7729
779.765	7783
782.104	7765
784.44	7738.5
786.776	7721
789.113	7708
791.447	7671
793.78	7733
796.113	7699
798.445	7735
800.778	7763
803.109	7755
805.439	7792
807.768	7777
810.096	7727
812.424	7751
814.751	7775.5
817.078	7785
819.402	7856
821.727	7886
824.051	7934.5
826.374	7900
828.697	7841.5
831.018	7843
833.339	7821.5
835.659	7813.5
837.978	7810.5
840.297	7804.5
842.614	7823
844.932	7827.5
847.247	7824
849.562	7800
851.878	7827
854.191	7793.5
856.504	7813.5
858.817	7817.5
861.129	7778
863.439	7787.5
865.749	7783
868.058	7747
870.367	7759
872.676	7692
874.983	7665
877.289	7651
879.593	7642.5
881.898	7667.5
884.202	7680
886.506	7621.5
888.808	7607
891.11	7589
893.41	7558.5
895.711	7541
898.011	7465
900.309	7555
902.607	7512
904.904	7463
907.201	7403.5
909.496	7406
911.791	7380
914.085	7355.5
916.379	7454.5
918.671	7395
920.963	7396.5
923.255	7400
925.545	7349
927.834	7374
930.123	7338
932.411	7343
934.698	7373.5
936.985	7341
939.271	7317.5
941.556	7355
943.84	7394.5
946.124	7371
948.407	7395.5
950.689	7370.5
952.971	7407
955.25	7374.5
957.531	7404
959.81	7397
962.088	7425
964.366	7438
966.643	7467.5
968.919	7418
971.195	7394
973.469	7412.5
975.743	7414.5
978.016	7400
980.288	7428.5
982.56	7410.5
984.831	7415.5
987.101	7390.5
989.37	7424
991.638	7409
993.907	7440
996.174	7436
998.44	7431.5
1000.71	7483.5
1002.97	7360.5
1005.24	7354.5
1007.5	7280.5
1009.76	7252.5
1012.02	7260
1014.28	7275
1016.54	7250
1018.8	7273.5
1021.06	7215.5
1023.32	7220.5
1025.58	7195.5
1027.84	7264
1030.09	7270.5
1032.35	7248.5
1034.6	7195
1036.86	7247
1039.11	7252.5
1041.36	7270
1043.61	7301.5
1045.86	7255.5
1048.11	7304.5
1050.36	7310.5
1052.61	7328.5
1054.86	7307
1057.11	7289.5
1059.35	7298
1061.6	7280.5
1063.84	7249.5
1066.09	7287
1068.33	7299
1070.57	7252.5
1072.82	7297
1075.06	7180.5
1077.3	7245.5
1079.54	7207
1081.78	7179.5
1084.02	7159
1086.25	7208
1088.49	7201
1090.73	7152.5
1092.96	7187
1095.2	7179
1097.43	7119
1099.66	7095.5
1101.9	7103
1104.13	7039
1106.36	7075.5
1108.59	7098.5
1110.82	7041.5
1113.05	7086.5
1115.28	7040.5
1117.51	7003.5
1119.73	7057
1121.96	7048.5
1124.18	7028
1126.41	7062
1128.63	7067.5
1130.85	7102
1133.08	7088.5
1135.3	7111
1137.52	7135
1139.74	7126
1141.96	7163.5
1144.18	7146
1146.4	7200
1148.61	7213.5
1150.83	7242.5
1153.05	7223.5
1155.26	7284.5
1157.48	7303.5
1159.69	7297
1161.9	7241.5
1164.11	7289.5
1166.33	7276.5
1168.54	7321
1170.75	7323.5
1172.96	7329.5
1175.17	7306.5
1177.37	7305.5
1179.58	7237.5
1181.79	7250
1183.99	7320.5
1186.2	7203.5
1188.4	7225
1190.61	7179.5
1192.81	7211.5
1195.01	7235.5
1197.21	7157.85
1199.42	7125.97
1201.61	7155.22
1203.81	7103.01
1206.01	7104.73
1208.21	7084.96
1210.41	7098.2
1212.61	7098.21
1214.8	7072.69
1217	7067.5
1219.19	7056.5
1221.38	7038.42
1223.58	7043.86
1225.77	7097.29
1227.96	7077.74
1230.15	7078.29
1232.34	7098.49
1234.53	7096.3
1236.72	7100.85
1238.91	7091.03
1241.1	7110.36
1243.28	7090.31
1245.47	7058.73
1247.65	7083.01
1249.84	7137.96
1252.02	7132.23
1254.21	7156.71
1256.39	7157.75
1258.57	7145.75
1260.75	7224.85
1262.93	7173.31
1265.11	7204.78
1267.29	7249.77
1269.47	7251.08
1271.65	7268.15
1273.82	7253.16
1276	7275.24
1278.17	7284.69
1280.35	7287.71
1282.52	7306.19
1284.69	7293.37
1286.87	7386.59
1289.04	7349.08
1291.21	7334.35
1293.38	7433.19
1295.55	7429.84
1297.72	7401.2
1299.89	7358.2
1302.06	7452.89
1304.22	7373.27
1306.39	7364.46
1308.43	7378
1310.6	7378
1312.78	7392
1314.96	7362.5
1317.13	7248.5
1319.3	7319
1321.47	7389
1323.65	7347.5
1325.82	7320
1327.99	7304
1330.16	7400.5
1332.32	7357
1334.49	7375.5
1336.66	7404.5
1338.83	7354.5
1340.99	7286
1343.16	7312
1345.32	7310.5
1347.49	7277.5
1349.65	7270
1351.81	7260
1353.98	7226
1356.14	7265.5
1358.3	7297
1360.46	7224
1362.62	7239
1364.78	7255.5
1366.93	7259.5
1369.09	7245.5
1371.25	7319.5
1373.4	7284
1375.56	7196.5
1377.71	7180
1379.87	7137.5
1382.02	7110
1384.17	7127.5
1386.32	7058
1388.47	7072
1390.63	7097.5
1392.77	7105
1394.92	6996
1397.07	7117.5
1399.22	7007.5
1401.37	7102.5
1403.51	7029
1405.66	7034
1407.8	7019
1409.95	7059.5
1412.09	6985.5
1414.23	7009.5
1416.38	6977.5
1418.52	6990
1420.66	7009
1422.8	6930.5
1424.94	6941
1427.08	6947.5
1429.21	6937.5
1431.35	6930.5
1433.49	6905
1435.63	6936.5
1437.76	6932.5
1439.89	6836
1442.03	6876
1444.16	6835
1446.3	6828.5
1448.43	6840
1450.56	6884
1452.69	6880
1454.82	6881.5
1456.95	6860.5
1459.08	6901.5
1461.2	6848
1463.33	6882
1465.46	6863.5
1467.58	6880
1469.71	6970
1471.83	6884
1473.96	6860
1476.08	6876
1478.2	6954.5
1480.33	6877.5
1482.45	6965
1484.57	6883
1486.69	6918
1488.81	6822
1490.93	6892.5
1493.04	6873
1495.16	6851
1497.28	6955
1499.39	6862.5
1501.51	6944.5
1503.62	6971
1505.74	6948
1507.85	6896
1509.96	6964.5
1512.07	6893.5
1514.19	6879.5
1516.3	6955.5
1518.41	6953.5
1520.52	6999
1522.62	6967.5
1524.73	7008
1526.84	6928
1528.95	7020.5
1531.05	6992.5
1533.16	7043
1535.26	6972.5
1537.37	7071.5
1539.47	7065
1541.57	7035
1543.67	7020.5
1545.78	7073
1547.88	7031
1549.98	7083
1552.07	6998
1554.17	6964.5
1556.27	6947.5
1558.37	7009
1560.47	6919.5
1562.56	6810.5
1564.66	6887.5
1566.75	6885.5
1568.85	6898
1570.94	6841
1573.03	6857.5
1575.12	6894
1577.21	6850
1579.31	6856.5
1581.4	6814.5
1583.49	6822
1585.57	6859
1587.66	6727
1589.75	6715.5
1591.84	6693
1593.92	6616
1596.01	6686
1598.09	6574
1600.18	6532
1602.26	6479.5
1604.34	6409.5
1606.43	6363.5
1608.51	6232
1610.59	6240
1612.67	6218.5
1614.75	6077.5
1616.83	6088
1618.91	5994.5
1620.98	5996
1623.06	5850.5
1625.14	5812.5
1627.21	5769
1629.29	5625.5
1631.36	5567.5
1633.43	5467.5
1635.51	5418
1637.58	5391.5
1639.65	5293.5
1641.72	5282.5
1643.79	5267.5
1645.86	5152
1647.93	5099
1650	5036
1652.07	5019.5
1654.14	5000.5
1656.2	4956.5
1658.27	4921.5
1660.34	4936.5
1662.4	4819.5
1664.46	4829.5
1666.53	4786
1668.59	4784.5
1670.65	4713.5
1672.71	4704
1674.77	4690
1676.83	4597
1678.89	4616
1680.95	4552.5
1683.01	4538.5
1685.07	4505.5
1687.13	4480
1689.18	4486.5
1691.24	4456
1693.29	4429
1695.35	4376
1697.4	4409.5
1699.45	4413
1701.51	4298.5
1703.56	4315.5
1705.61	4310.5
1707.66	4287.5
1709.71	4282
1711.76	4255
1713.81	4192.5
1715.86	4241
1717.9	4203.5
1719.95	4194.5
1722	4139
1724.04	4167.5
1726.09	4153.5
1728.13	4136.5
1730.17	4147
1732.22	4140
1734.26	4117.5
1736.3	4078
1738.34	4082.5
1740.38	4041.5
1742.42	4049
1744.46	4061
1746.5	4008
1748.54	4041
1750.57	4009
1752.61	3967
1754.65	3986
1756.68	3994
1758.72	3948
1760.75	3969
1762.78	3977
1764.82	3898
1766.85	3921
1768.88	3909.5
1770.91	3851.5
1772.94	3847
1774.97	3887.5
1777	3871.5
1779.03	3859.5
1781.06	3809.5
1783.08	3822.5
1785.11	3854.5
1787.14	3825.5
1789.16	3812
1791.18	3791
1793.21	3776.5
1795.23	3772
1797.26	3771.5
1799.28	3713.5
1801.3	3762.5
1803.32	3733
1805.34	3741.5
1807.36	3702.5
1809.38	3668
1811.4	3660.5
1813.41	3690
1815.43	3658.5
1817.45	3712
1819.46	3636
1821.48	3685.5
1823.49	3606
1825.51	3628.5
1827.52	3603.5
1829.53	3590.5
1831.54	3577
1833.56	3575.5
1835.57	3566
1837.58	3545
1839.59	3552
1841.59	3522
1843.6	3522.5
1845.61	3492
1847.62	3452.5
1849.62	3459.5
1851.63	3468
1853.64	3464.5
1855.64	3469
1857.64	3455.5
1859.65	3426
1861.65	3458.5
1863.65	3440.5
1865.65	3375.5
1867.65	3383
1869.65	3394
1871.65	3371
1873.65	3376
1875.65	3373
1877.65	3340
1879.65	3313
1881.64	3341.5
1883.64	3358
1885.63	3315
1887.63	3324
1889.62	3299.5
1891.62	3315
1893.61	3264
1895.6	3296.5
1897.59	3292.5
1899.58	3303
1901.57	3265.5
1903.56	3285.5
1905.55	3297
1907.54	3270.5
1909.53	3245
1911.52	3238
1913.5	3279
1915.49	3236.5
1917.48	3254.5
1919.46	3247
1921.44	3229
1923.43	3220.5
1925.41	3187.5
1927.39	3179
1929.38	3210.5
1931.36	3183.5
1933.34	3171
1935.32	3172
1937.3	3160
1939.28	3163
1941.25	3155.5
1943.23	3178.5
1945.21	3151
1947.18	3101.5
1949.16	3125.5
1951.13	3080
1953.11	3097.5
1955.08	3093
1957.06	3098.5
1959.03	3094
1961	3062
1962.97	3029.5
1964.94	3061
1966.91	3002.5
1968.88	3026
1970.85	2999.5
1972.82	3024.5
1974.79	3006.5
1976.76	2979
1978.72	2971
1980.69	3006.5
1982.65	3010.5
1984.62	2987
1986.58	2974.5
1988.55	2937.5
1990.51	2961.5
1992.47	2947
1994.43	2935
1996.39	2930
1998.36	2930
2000.31	2932.5
2002.27	2959
2004.23	2891.5
2006.19	2892
2008.15	2912
2010.11	2868.5
2012.06	2907.5
2014.02	2894
2015.97	2849.5
2017.93	2857
2019.88	2823
2021.83	2874
2023.79	2851.5
2025.74	2834.5
2027.69	2849.5
2029.64	2849
2031.59	2788.5
2033.54	2815
2035.49	2808.5
2037.44	2804.5
2039.39	2793.5
2041.34	2820.5
2043.28	2774.5
2045.23	2757.5
2047.17	2756
2049.12	2757
2051.06	2769.5
2053.01	2744.5
2054.95	2770.5
2056.89	2713.5
2058.84	2734
2060.78	2711.5
2062.72	2747.5
2064.66	2689.5
2066.6	2698
2068.54	2711
2070.48	2706
2072.41	2689
2074.35	2677.5
2076.29	2686
2078.22	2679.5
2080.16	2677
2082.09	2674.5
2084.03	2668
2085.96	2674.5
2087.9	2659.5
2089.83	2683
2091.76	2693
2093.69	2695
2095.62	2689.5
2097.55	2704.5
2099.48	2716.5
2101.41	2706
2103.34	2738
2105.27	2785
2107.19	2837.5
2109.12	2901.5
2111.05	2903
2112.97	3000
2114.9	3041
2116.82	3147
2118.75	3238.5
2120.67	3300
2122.59	3327
2124.51	3397.5
2126.43	3414
2128.36	3394
2130.28	3309.5
2132.2	3277
2134.11	3214.5
2136.03	3102
2137.95	3047
2139.87	2954.5
2141.78	2896.5
2143.7	2837
2145.62	2764.63
2147.53	2704.67
2149.45	2732.34
2151.36	2692.59
2153.27	2636.17
2155.19	2614.31
2157.1	2593.19
2159.01	2506.41
2160.92	2533.58
2162.83	2479.98
2164.74	2456.08
2166.65	2426.7
2168.56	2402.75
2170.47	2363.4
2172.37	2369.77
2174.28	2346.57
2176.19	2336.82
2178.09	2318.88
2180	2297.53
2181.9	2281.39
2183.81	2265.57
2185.71	2245.72
2187.61	2220.57
2189.51	2213.6
2191.42	2194.52
2193.32	2202.48
2195.22	2172.62
2197.12	2164.29
2199.02	2146.83
2200.92	2129.52
2202.81	2130.13
2204.71	2106.19
2206.61	2084.48
2208.5	2098.45
2210.4	2087.96
2212.3	2071.72
2214.19	2065.8
2216.08	2054.43
2217.98	2046.88
2219.87	2019.3
2221.76	2043.41
2223.65	2042.2
2225.55	2009.41
2227.44	2025.23
2229.33	2026.35
2231.22	2011.57
2233.11	2006.51
2234.99	2003.12
2236.88	2000.86
2238.77	2003.56
2240.66	2004.24
2242.06	2018.5
2243.96	2013.5
2245.85	1997
2247.75	2015.5
2249.64	2002.5
2251.54	2002.5
2253.43	1950.5
2255.32	1990.5
2257.21	1955.5
2259.1	1930.5
2260.99	1931
2262.89	1950.5
2264.77	1939
2266.66	1942
2268.55	1925
2270.44	1924
2272.33	1899
2274.21	1899.5
2276.1	1928
2277.98	1895
2279.87	1853
2281.75	1902
2283.64	1878
2285.52	1876.5
2287.4	1860.5
2289.29	1855.5
2291.17	1877.5
2293.05	1869
2294.93	1867
2296.81	1828
2298.69	1837
2300.57	1856
2302.44	1802
2304.32	1855.5
2306.2	1849.5
2308.08	1817
2309.95	1829
2311.83	1856.5
2313.7	1812
2315.58	1820.5
2317.45	1828
2319.32	1795.5
2321.2	1796.5
2323.07	1820
2324.94	1805
2326.81	1822.5
2328.68	1817.5
2330.55	1797
2332.42	1763
2334.29	1797
2336.16	1779
2338.02	1763
2339.89	1761
2341.76	1784.5
2343.62	1760
2345.49	1767.5
2347.35	1758
2349.22	1719.5
2351.08	1765.5
2352.94	1776.5
2354.81	1749
2356.67	1754
2358.53	1745.5
2360.39	1771.5
2362.25	1738
2364.11	1733
2365.97	1758.5
2367.83	1729.5
2369.69	1745
2371.55	1716
2373.4	1714
2375.26	1722
2377.11	1747.5
2378.97	1761.5
2380.83	1719
2382.68	1692
2384.53	1689
2386.39	1680
2388.24	1693.5
2390.09	1722
2391.94	1686
2393.79	1665
2395.64	1685
2397.49	1689.5
2399.34	1687.5
2401.19	1663
2403.04	1683
2404.89	1667.5
2406.74	1662
2408.58	1669.5
2410.43	1694.5
2412.27	1685.5
2414.12	1645.5
2415.96	1637.5
2417.81	1639.5
2419.65	1643
2421.49	1660
2423.34	1634
2425.18	1634
2427.02	1603
2428.86	1614.5
2430.7	1651
2432.54	1621
2434.38	1620.5
2436.22	1630
2438.05	1621.5
2439.89	1613.5
2441.73	1599
2443.56	1622
2445.4	1610.5
2447.24	1592.5
2449.07	1591.5
2450.9	1581.5
2452.74	1584.5
2454.57	1595
2456.4	1592.5
2458.23	1595
2460.07	1590.5
2461.9	1592.5
2463.73	1588.5
2465.56	1580
2467.39	1555.5
2469.21	1565.5
2471.04	1581.5
2472.87	1571.5
2474.7	1564
2476.52	1579.5
2478.35	1565
2480.17	1555.5
2482	1601
2483.82	1541
2485.65	1566
2487.47	1543
2489.29	1552
2491.12	1516.5
2492.94	1544.5
2494.76	1524
2496.58	1502
2498.4	1533
2500.22	1523
2502.04	1515
2503.86	1521
2505.67	1496
2507.49	1494.5
2509.31	1481.5
2511.12	1478.5
2512.94	1488
2514.76	1489
2516.57	1473.5
2518.38	1485.5
2520.2	1451.5
2522.01	1458
2523.82	1472
2525.64	1480
2527.45	1458.5
2529.26	1439.5
2531.07	1459
2532.88	1470
2534.69	1477
2536.5	1421
2538.31	1444
2540.11	1434.5
2541.92	1439
2543.73	1433.5
2545.53	1428.5
2547.34	1416
2549.14	1428
2550.95	1434.5
2552.75	1414.5
2554.56	1422
2556.36	1410
2558.16	1406
2559.96	1416
2561.76	1404
2563.57	1428
2565.37	1392
2567.17	1416.5
2568.96	1376.5
2570.76	1375.5
2572.56	1401.5
2574.36	1389
2576.16	1385
2577.95	1424.5
2579.75	1375
2581.54	1358.5
2583.34	1366
2585.13	1370
2586.93	1379
2588.72	1390
2590.51	1355
2592.31	1370
2594.1	1358
2595.89	1355
2597.68	1355.5
2599.47	1382
2601.26	1328
2603.05	1355
2604.84	1337.5
2606.63	1335
2608.42	1350
2610.2	1323.5
2611.99	1323
2613.78	1319
2615.56	1330
2617.35	1302
2619.13	1308
2620.91	1319
2622.7	1321.5
2624.48	1318
2626.26	1293.5
2628.04	1277.5
2629.83	1284.5
2631.61	1296.5
2633.39	1274.5
2635.17	1286.5
2636.95	1274.5
2638.73	1242
2640.5	1256.5
2642.28	1289.5
2644.06	1265
2645.84	1277.5
2647.61	1218
2649.39	1243
2651.16	1267
2652.94	1224.5
2654.71	1275.5
2656.49	1254.5
2658.26	1284.5
2660.03	1252.5
2661.8	1222
2663.57	1227.5
2665.35	1216
2667.12	1210
2668.89	1227
2670.66	1241
2672.42	1208
2674.19	1230
2675.96	1210
2677.73	1226
2679.49	1221.5
2681.26	1196
2683.03	1206
2684.79	1227
2686.56	1191.5
2688.32	1215.5
2690.09	1207.5
2691.85	1174.5
2693.61	1202.5
2695.37	1192.5
2697.14	1179.5
2698.9	1141
2700.66	1177
2702.42	1173.5
2704.18	1158.5
2705.94	1168.5
2707.7	1167.5
2709.45	1182.5
2711.21	1142.5
2712.97	1151
2714.72	1151
2716.48	1162
2718.24	1175.5
2719.99	1162
2721.75	1159.5
2723.5	1137
2725.25	1146
2727.01	1118
2728.76	1130.5
2730.51	1127.5
2732.26	1118
2734.01	1137
2735.76	1109
2737.51	1108
2739.26	1118.5
2741.01	1115
2742.76	1120.5
2744.51	1105
2746.26	1095
2748	1107.5
2749.75	1102.5
2751.5	1100.5
2753.24	1073
2754.99	1067
2756.73	1066.5
2758.47	1072
2760.22	1064
2761.96	1083
2763.7	1068.5
2765.44	1068
2767.19	1084
2768.93	1068.5
2770.67	1054.5
2772.41	1049
2774.15	1061.5
2775.89	1031.5
2777.62	1057.5
2779.36	1048.5
2781.1	1046
2782.84	1019
2784.57	1031.5
2786.31	1030
2788.04	1015.5
2789.78	1029.5
2791.51	1011
2793.24	1035
2794.98	1024.5
2796.71	1024.5
2798.44	1037.5
2800.18	1020
2801.91	1016.5
2803.64	1010.75
2805.37	994
2807.1	993
2808.83	992.5
2810.55	1001
2812.28	995
2814.01	989
2815.74	989.5
2817.46	992
2819.19	991.5
2820.92	993.5
2822.64	994.5
2824.37	1005.5
2826.09	980
2827.81	974
2829.54	986
2831.26	982
2832.98	982
2834.71	958
2836.43	1005
2838.15	989
2839.87	986.5
2841.59	985
2843.31	1018.5
2845.02	1016
2846.74	1036
2848.46	1032.5
2850.18	1048.5
2851.9	1049
2853.61	1019
2855.33	1022.5
2857.04	1018.5
2858.76	1054.5
2860.47	1020.5
2862.19	996.5
2863.9	1000.5
2865.61	992.5
2867.32	1005
2869.04	998.5
2870.75	1000.5
2872.46	993.5
2874.17	1007
2875.88	1007
2877.59	989
2879.3	989.5
2881	999
2882.71	992.5
2884.42	970
2886.13	981
2887.83	960
2889.54	985.5
2891.24	994
2892.95	983.5
2894.65	992.5
2896.36	964
2898.06	966.5
2899.76	983
2901.47	996
2903.17	962
2904.87	984.5
2906.57	985.5
2908.27	978.5
2909.97	969
2911.67	982
2913.37	984
2915.07	956
2916.77	968.5
2918.47	977
2920.16	985
2921.86	995.5
2923.55	971
2925.25	965.5
2926.94	970.5
2928.64	981.5
2930.33	977
2932.03	986
2933.72	966
2935.41	975.5
2937.11	939
2938.8	987.5
2940.49	954.5
2942.18	934
2943.87	939
2945.56	913
2947.25	918
2948.94	895.5
2950.63	873.5
2952.31	872.5
2954	862
2955.69	868
2957.37	869.5
2959.06	838
2960.75	845
2962.43	833
2964.11	861
2965.8	838
2967.48	844.5
2969.16	841
2970.85	819.5
2972.53	823
2974.21	802.5
2975.89	809.5
2977.57	793
2979.25	788
2980.93	797
2982.61	781.5
2984.29	780.5
2985.97	769
2987.65	760
2989.32	756.5
2991	783
2992.68	746.5
2994.35	759
2996.03	739.5
2997.7	744.5
2999.38	744.5