File: muestras/ogompa/nsno_20.txt
#Acq. time (s)=	5
#Accumulations=	5
#Range (cm-¹)=	100...3000
#Windows=	3
#Autofocus=	Off
#AutoExposure=	Off
#Spike filter=	Multiple accum.
#Delay time (s)=	0
#Binning=	1
#Readout mode=	Signal
#DeNoise=	Off
#ICS correction=	Off
#Dark correction=	Off
#Inst. Process=	Off
#Instrument=	LabRAM HR Evol
#Detector=	Syncerity OE
#Objective=	x100_VIS_LWD
#Grating=	600 (500nm)
#ND Filter=	100%
#Laser=	633nm_Edge
#Hole=	100.021
#Range=	Visible
#Project=	Omar
#Sample=	chi
#Site=	f
#Title=	nsno
#Remark=
#Date=	12.09.2023 17:49
#Acquired=	12.09.2023 17:49:15
101.026	3171.5
103.592	3103
106.158	3057.5
108.723	3002.5
111.289	2952
113.852	2908.5
116.415	2839.5
118.976	2841
121.537	2822.5
124.097	2786
126.656	2791.5
129.215	2685
131.772	2687
134.327	2670
136.883	2626.5
139.438	2573
141.992	2509.5
144.545	2490
147.096	2440.5
149.648	2397.5
152.199	2382
154.747	2318
157.296	2324.5
159.843	2303.5
162.391	2242
164.937	2213
167.482	2205.5
170.025	2210
172.569	2198
175.111	2197
177.654	2178.5
180.194	2160
182.733	2199
185.273	2156
187.811	2166
190.348	2168.5
192.884	2180.5
195.419	2178.5
197.955	2183.5
200.489	2192.5
203.022	2219.5
205.554	2200
208.085	2192
210.615	2219
213.144	2245
215.673	2215.5
218.201	2246.5
220.728	2228
223.253	2263.5
225.778	2240
228.303	2282.5
230.826	2271.5
233.348	2278.5
235.87	2298
238.391	2270.5
240.91	2307
243.43	2308
245.949	2299.5
248.465	2323
250.983	2318
253.498	2323
256.013	2329
258.526	2348.5
261.039	2311
263.552	2312
266.063	2336.5
268.573	2313.5
271.084	2327
273.592	2319
276.1	2319.5
278.607	2339
281.113	2356.5
283.619	2423.5
286.124	2362.5
288.627	2411
291.13	2365.5
293.632	2384
296.133	2413.5
298.634	2384
301.133	2425
303.63	2383
306.128	2432
308.625	2416
311.122	2364
313.617	2379
316.111	2424.5
318.604	2373
321.098	2376
323.588	2377.5
326.08	2329.5
328.569	2323
331.059	2343.5
333.548	2301
336.035	2299.5
338.521	2312.5
341.008	2289
343.492	2307
345.977	2330.5
348.46	2277
350.942	2300.5
353.425	2324
355.905	2303
358.385	2287.5
360.864	2298
363.342	2286
365.819	2315.5
368.296	2300.5
370.771	2269
373.246	2297
375.72	2291
378.194	2296.5
380.666	2303
383.138	2269
385.609	2273
388.079	2299
390.548	2264
393.016	2281
395.483	2286
397.95	2308.5
400.416	2272
402.88	2291
405.345	2310
407.807	2326.5
410.27	2325.5
412.731	2316
415.193	2363.5
417.652	2393.5
420.112	2388.5
422.569	2360
425.028	2356
427.484	2365
429.939	2419.5
432.394	2405.5
434.849	2362.5
437.302	2416.5
439.754	2451
442.205	2441.5
444.656	2434
447.106	2414.5
449.555	2370
452.003	2397
454.45	2400
456.897	2416.5
459.343	2380.5
461.788	2372
464.232	2407
466.676	2386
469.119	2391.5
471.559	2412.5
474.001	2443.5
476.441	2408.5
478.879	2434.5
481.318	2408
483.756	2436.5
486.192	2412
488.629	2484.5
491.063	2419
493.498	2455
495.931	2449
498.365	2467.5
500.796	2460.5
503.226	2496
505.657	2464
508.086	2515
510.515	2515
512.942	2498.5
515.369	2490
517.796	2480.5
520.221	2481
522.645	2501
525.069	2494
527.492	2497.5
529.914	2495
532.335	2521.5
534.756	2478.5
537.175	2484.5
539.593	2459.5
542.011	2521
544.429	2485.5
546.845	2498.5
549.261	2442
551.675	2482.5
554.089	2451.5
556.503	2477
558.914	2483
561.326	2489.5
563.736	2521
566.147	2509
568.555	2496
570.964	2508
573.371	2476.5
575.777	2493
578.184	2497.5
580.588	2518
582.992	2504.5
585.395	2503
587.799	2507.5
590.201	2490
592.601	2465.5
595.001	2506
597.401	2521
599.799	2518
602.197	2517
604.594	2517
606.99	2577.5
609.386	2535.5
611.78	2587
614.174	2589.5
616.566	2563.5
618.958	2585.5
621.35	2548.5
623.741	2591.5
626.13	2588.5
628.519	2628
630.908	2603.5
633.295	2599
635.682	2647.5
638.067	2681
640.453	2671
642.836	2656
645.219	2646.5
647.602	2657.5
649.984	2682.5
652.364	2655
654.745	2631.5
657.124	2635.5
659.503	2592
661.88	2656
664.257	2591
666.635	2621
669.01	2603.5
671.384	2630
673.758	2589
676.131	2625
678.502	2599.5
680.874	2576.5
683.245	2624
685.615	2586.5
687.984	2594.5
690.353	2609
692.719	2598
695.086	2596
697.453	2617
699.817	2578.5
702.182	2588.5
704.545	2555
706.908	2569.5
709.27	2589.5
711.632	2583
713.991	2614
716.352	2594
718.71	2613.5
721.068	2612.5
723.426	2611
725.782	2603.5
728.138	2618.5
730.492	2593.5
732.846	2626.5
735.201	2592.5
737.553	2627
739.905	2626
742.256	2618.5
744.606	2597
746.956	2642.5
749.303	2629
751.651	2607.5
753.999	2592
756.345	2589
758.691	2598.5
761.035	2595
763.379	2616.5
765.723	2600.5
768.064	2615.5
770.407	2609
772.748	2604
775.088	2597.5
777.427	2605
779.765	2590
782.104	2599.5
784.44	2626.5
786.776	2603.5
789.113	2598.5
791.447	2580
793.78	2581
796.113	2605
798.445	2621
800.778	2611.5
803.109	2586
805.439	2630
807.768	2631.5
810.096	2632.5
812.424	2617.5
814.751	2662
817.078	2691
819.402	2669.5
821.727	2658.5
824.051	2683
826.374	2678
828.697	2691
831.018	2663
833.339	2704.5
835.659	2698.5
837.978	2678
840.297	2694
842.614	2694
844.932	2686.5
847.247	2683.5
849.562	2675
851.878	2666
854.191	2716
856.504	2717.5
858.817	2722
861.129	2734
863.439	2651
865.749	2690
868.058	2662.5
870.367	2663.5
872.676	2645
874.983	2663
877.289	2641.5
879.593	2648
881.898	2632
884.202	2632.5
886.506	2586
888.808	2612.5
891.11	2612
893.41	2562.5
895.711	2600.5
898.011	2593.5
900.309	2578.5
902.607	2592
904.904	2554.5
907.201	2558.5
909.496	2528
911.791	2584.5
914.085	2553.5
916.379	2565.5
918.671	2586.5
920.963	2547
923.255	2598.5
925.545	2568
927.834	2579
930.123	2574.5
932.411	2592
934.698	2566
936.985	2573
939.271	2573.5
941.556	2534.5
943.84	2578
946.124	2598
948.407	2546
950.689	2568
952.971	2551
955.25	2527.5
957.531	2590.5
959.81	2597
962.088	2595.5
964.366	2557.5
966.643	2586
968.919	2607
971.195	2592.25
973.469	2602
975.743	2571.5
978.016	2624
980.288	2574
982.56	2628.5
984.831	2607.5
987.101	2606
989.37	2593
991.638	2590.5
993.907	2591
996.174	2640.5
998.44	2667.5
1000.71	2681.5
1002.97	2639
1005.24	2592.5
1007.5	2545.5
1009.76	2559.5
1012.02	2529
1014.28	2569
1016.54	2574
1018.8	2563.5
1021.06	2536.5
1023.32	2562.5
1025.58	2559
1027.84	2620
1030.09	2579
1032.35	2567.5
1034.6	2576
1036.86	2592.5
1039.11	2568.5
1041.36	2602
1043.61	2614
1045.86	2624.5
1048.11	2609
1050.36	2616
1052.61	2600
1054.86	2602.5
1057.11	2596
1059.35	2620.5
1061.6	2601.5
1063.84	2590.5
1066.09	2597.5
1068.33	2578
1070.57	2596.5
1072.82	2614.5
1075.06	2618
1077.3	2586
1079.54	2565
1081.78	2570
1084.02	2543
1086.25	2570.5
1088.49	2556.5
1090.73	2551.5
1092.96	2552
1095.2	2551.5
1097.43	2546
1099.66	2542.5
1101.9	2535
1104.13	2571.5
1106.36	2503.5
1108.59	2529.5
1110.82	2537
1113.05	2521
1115.28	2536
1117.51	2556.5
1119.73	2537
1121.96	2526.5
1124.18	2537.5
1126.41	2516
1128.63	2537.5
1130.85	2501
1133.08	2529
1135.3	2534.5
1137.52	2545.5
1139.74	2525.5
1141.96	2568
1144.18	2556.5
1146.4	2579
1148.61	2592
1150.83	2602
1153.05	2617.5
1155.26	2619
1157.48	2637.5
1159.69	2628
1161.9	2622.5
1164.11	2624.5
1166.33	2651.5
1168.54	2658
1170.75	2656.5
1172.96	2627.5
1175.17	2688
1177.37	2647.5
1179.58	2629
1181.79	2591
1183.99	2595
1186.2	2586.5
1188.4	2586
1190.61	2588.5
1192.81	2602.5
1195.01	2563
1197.21	2588.9
1199.42	2572.61
1201.61	2558.05
1203.81	2576.05
1206.01	2563.35
1208.21	2588.67
1210.41	2595.36
1212.61	2583.79
1214.8	2551.76
1217	2557.61
1219.19	2570.7
1221.38	2543.3
1223.58	2570.68
1225.77	2589.97
1227.96	2558.41
1230.15	2544.16
1232.34	2585.48
1234.53	2558.64
1236.72	2582.98
1238.91	2568.2
1241.1	2573.96
1243.28	2590.14
1245.47	2598.47
1247.65	2594.73
1249.84	2597.3
1252.02	2605.22
1254.21	2632.26
1256.39	2623.96
1258.57	2624.3
1260.75	2627.64
1262.93	2632.24
1265.11	2633.98
1267.29	2655.83
1269.47	2651.58
1271.65	2651.35
1273.82	2671.71
1276	2658.28
1278.17	2663.12
1280.35	2685.31
1282.52	2675.92
1284.69	2690.06
1286.87	2675.39
1289.04	2690
1291.21	2672.98
1293.38	2687.22
1295.55	2663.77
1297.72	2691.22
1299.89	2687.57
1302.06	2694.11
1304.22	2670.71
1306.39	2656.83
1308.43	2688.5
1310.6	2662.5
1312.78	2719
1314.96	2668.5
1317.13	2649
1319.3	2682.5
1321.47	2628
1323.65	2613.5
1325.82	2617.5
1327.99	2671
1330.16	2646
1332.32	2649.5
1334.49	2630
1336.66	2670.5
1338.83	2635.5
1340.99	2641.5
1343.16	2645.5
1345.32	2583
1347.49	2613
1349.65	2577
1351.81	2569
1353.98	2547.5
1356.14	2550.5
1358.3	2565
1360.46	2531
1362.62	2506.5
1364.78	2579
1366.93	2560.5
1369.09	2485
1371.25	2541.5
1373.4	2517.5
1375.56	2495.5
1377.71	2506.5
1379.87	2493
1382.02	2516
1384.17	2529.5
1386.32	2472.5
1388.47	2513.5
1390.63	2513
1392.77	2448.5
1394.92	2509.5
1397.07	2476
1399.22	2509
1401.37	2496
1403.51	2482.5
1405.66	2460.5
1407.8	2484.5
1409.95	2499.5
1412.09	2458.5
1414.23	2467.5
1416.38	2461.5
1418.52	2498
1420.66	2473
1422.8	2491
1424.94	2488
1427.08	2461.5
1429.21	2478
1431.35	2474.5
1433.49	2462
1435.63	2462
1437.76	2466.5
1439.89	2468
1442.03	2495
1444.16	2482
1446.3	2517.5
1448.43	2464.5
1450.56	2497
1452.69	2491
1454.82	2513
1456.95	2456
1459.08	2505
1461.2	2511
1463.33	2437.5
1465.46	2502
1467.58	2482.5
1469.71	2470.5
1471.83	2514
1473.96	2459
1476.08	2486
1478.2	2517.5
1480.33	2449.5
1482.45	2531.5
1484.57	2464.5
1486.69	2506
1488.81	2501.5
1490.93	2489
1493.04	2464
1495.16	2502
1497.28	2497.5
1499.39	2471
1501.51	2496.5
1503.62	2483.5
1505.74	2489
1507.85	2461.5
1509.96	2517.5
1512.07	2448.5
1514.19	2464
1516.3	2476.5
1518.41	2457
1520.52	2420.5
1522.62	2494
1524.73	2463
1526.84	2450.5
1528.95	2481
1531.05	2483
1533.16	2497.5
1535.26	2488.5
1537.37	2517.5
1539.47	2447
1541.57	2465.5
1543.67	2427.5
1545.78	2483.5
1547.88	2453.5
1549.98	2472
1552.07	2463.5
1554.17	2480
1556.27	2462
1558.37	2446
1560.47	2449.5
1562.56	2453
1564.66	2484.5
1566.75	2461
1568.85	2467
1570.94	2435
1573.03	2458.5
1575.12	2451.5
1577.21	2434
1579.31	2476.5
1581.4	2453
1583.49	2449
1585.57	2446
1587.66	2459
1589.75	2459
1591.84	2456.5
1593.92	2459.5
1596.01	2483
1598.09	2433.5
1600.18	2421.5
1602.26	2442.5
1604.34	2380.5
1606.43	2359
1608.51	2310.5
1610.59	2285
1612.67	2264.5
1614.75	2251.5
1616.83	2196.5
1618.91	2174.5
1620.98	2157.5
1623.06	2081
1625.14	2107.5
1627.21	2082.5
1629.29	2047
1631.36	2041.5
1633.43	2030
1635.51	2002.5
1637.58	1971
1639.65	1976
1641.72	1936.5
1643.79	1931
1645.86	1887.5
1647.93	1881
1650	1876
1652.07	1872
1654.14	1844.5
1656.2	1842.5
1658.27	1790.5
1660.34	1756
1662.4	1760
1664.46	1763
1666.53	1737
1668.59	1706.5
1670.65	1711.5
1672.71	1695
1674.77	1678.5
1676.83	1693.5
1678.89	1651
1680.95	1633.5
1683.01	1639
1685.07	1630
1687.13	1634
1689.18	1594
1691.24	1613.5
1693.29	1571.5
1695.35	1594
1697.4	1555.5
1699.45	1585
1701.51	1570.5
1703.56	1579.5
1705.61	1549
1707.66	1529
1709.71	1536
1711.76	1550.5
1713.81	1517.5
1715.86	1517
1717.9	1548.5
1719.95	1530
1722	1511
1724.04	1517.5
1726.09	1484
1728.13	1522
1730.17	1496
1732.22	1456.5
1734.26	1449.5
1736.3	1472.5
1738.34	1467
1740.38	1461.5
1742.42	1449
1744.46	1437
1746.5	1431
1748.54	1437.5
1750.57	1442
1752.61	1427
1754.65	1412.5
1756.68	1401
1758.72	1380
1760.75	1402
1762.78	1379.5
1764.82	1392.5
1766.85	1394.5
1768.88	1373
1770.91	1372
1772.94	1351
1774.97	1346
1777	1355.5
1779.03	1358.5
1781.06	1361.5
1783.08	1316
1785.11	1343
1787.14	1333.5
1789.16	1336.5
1791.18	1317.5
1793.21	1320
1795.23	1318
1797.26	1297
1799.28	1316
1801.3	1298.5
1803.32	1302.5
1805.34	1303.5
1807.36	1293
1809.38	1279.5
1811.4	1282
1813.41	1272
1815.43	1275.5
1817.45	1264.5
1819.46	1249
1821.48	1249
1823.49	1254.5
1825.51	1252
1827.52	1244.5
1829.53	1242
1831.54	1235
1833.56	1245.5
1835.57	1232.5
1837.58	1234.5
1839.59	1214.5
1841.59	1203.5
1843.6	1224
1845.61	1192
1847.62	1190.5
1849.62	1192.5
1851.63	1197
1853.64	1178.5
1855.64	1155.5
1857.64	1193.5
1859.65	1193.5
1861.65	1179.5
1863.65	1177.5
1865.65	1175
1867.65	1172
1869.65	1149.5
1871.65	1157
1873.65	1152
1875.65	1157.5
1877.65	1159.5
1879.65	1164.5
1881.64	1174.5
1883.64	1154
1885.63	1137.5
1887.63	1137
1889.62	1138
1891.62	1135.5
1893.61	1138.5
1895.6	1130.5
1897.59	1145
1899.58	1123
1901.57	1132
1903.56	1153.5
1905.55	1131.5
1907.54	1137.5
1909.53	1115
1911.52	1116
1913.5	1108.5
1915.49	1090.5
1917.48	1103.5
1919.46	1088
1921.44	1102.5
1923.43	1108.5
1925.41	1076.5
1927.39	1099
1929.38	1084
1931.36	1079.5
1933.34	1066.5
1935.32	1083
1937.3	1068.5
1939.28	1092
1941.25	1084.5
1943.23	1080
1945.21	1081
1947.18	1078
1949.16	1072.5
1951.13	1049.5
1953.11	1058.5
1955.08	1059
1957.06	1059.5
1959.03	1050
1961	1043.5
1962.97	1011.5
1964.94	1028
1966.91	1018
1968.88	1003
1970.85	1034
1972.82	1015.5
1974.79	1005
1976.76	1031
1978.72	1013
1980.69	1015
1982.65	1002
1984.62	1005
1986.58	1017.5
1988.55	993.5
1990.51	1001
1992.47	994
1994.43	983.5
1996.39	1000
1998.36	983.5
2000.31	996.5
2002.27	991
2004.23	977.5
2006.19	970.5
2008.15	991.5
2010.11	960.5
2012.06	969
2014.02	999
2015.97	973.5
2017.93	941
2019.88	980.5
2021.83	958
2023.79	962
2025.74	953
2027.69	956
2029.64	939.5
2031.59	960
2033.54	951
2035.49	957.5
2037.44	949
2039.39	933.5
2041.34	936.5
2043.28	930
2045.23	935
2047.17	948.5
2049.12	932
2051.06	943
2053.01	913
2054.95	917.5
2056.89	902
2058.84	929
2060.78	906.5
2062.72	887
2064.66	903.5
2066.6	903.5
2068.54	904.5
2070.48	904
2072.41	923
2074.35	887.5
2076.29	891
2078.22	908.5
2080.16	885.5
2082.09	878
2084.03	894
2085.96	882.5
2087.9	880.5
2089.83	865
2091.76	889.5
2093.69	884.5
2095.62	863.5
2097.55	879.5
2099.48	874.5
2101.41	882
2103.34	883.5
2105.27	894
2107.19	902.5
2109.12	904.5
2111.05	931.5
2112.97	940.5
2114.9	958.5
2116.82	981
2118.75	977.5
2120.67	1028.5
2122.59	1059
2124.51	1049.5
2126.43	1050.5
2128.36	1059
2130.28	1053.5
2132.2	1024.5
2134.11	1015.5
2136.03	988
2137.95	938
2139.87	929.5
2141.78	906
2143.7	885
2145.62	864.971
2147.53	858.829
2149.45	881.322
2151.36	851.076
2153.27	850.227
2155.19	836.392
2157.1	823.829
2159.01	832.785
2160.92	836.469
2162.83	821.413
2164.74	812.653
2166.65	811.367
2168.56	802.928
2170.47	802.317
2172.37	802.863
2174.28	791.672
2176.19	783.101
2178.09	782.141
2180	783.042
2181.9	769.799
2183.81	778.095
2185.71	771.702
2187.61	756.493
2189.51	755.711
2191.42	757.11
2193.32	757.798
2195.22	761.893
2197.12	758.471
2199.02	754.303
2200.92	753.64
2202.81	758.512
2204.71	760.518
2206.61	749.105
2208.5	744.633
2210.4	743.303
2212.3	752.68
2214.19	744.263
2216.08	744.287
2217.98	736.77
2219.87	753.871
2221.76	733.233
2223.65	741.534
2225.55	736.6
2227.44	741.159
2229.33	741.654
2231.22	746.692
2233.11	744.425
2234.99	745.446
2236.88	734.275
2238.77	741.312
2240.66	739.366
2242.06	752.5
2243.96	755
2245.85	768.5
2247.75	754
2249.64	763
2251.54	749.5
2253.43	748.5
2255.32	742
2257.21	711.5
2259.1	718.5
2260.99	706
2262.89	701
2264.77	704.5
2266.66	702.5
2268.55	703
2270.44	707.5
2272.33	689.5
2274.21	700
2276.1	679
2277.98	688.5
2279.87	697.5
2281.75	711
2283.64	686.5
2285.52	694.5
2287.4	682
2289.29	668
2291.17	668
2293.05	669
2294.93	685
2296.81	681.5
2298.69	669.5
2300.57	661
2302.44	666.5
2304.32	686.5
2306.2	657.5
2308.08	681
2309.95	671.5
2311.83	666.5
2313.7	654.5
2315.58	670.5
2317.45	661.5
2319.32	652
2321.2	650
2323.07	656.5
2324.94	637
2326.81	660
2328.68	663
2330.55	651
2332.42	660.5
2334.29	646
2336.16	641
2338.02	645
2339.89	643.5
2341.76	628.5
2343.62	643.5
2345.49	638
2347.35	651
2349.22	621.5
2351.08	639
2352.94	624
2354.81	623
2356.67	627.5
2358.53	636.5
2360.39	626
2362.25	612
2364.11	627.5
2365.97	610.5
2367.83	622
2369.69	629.5
2371.55	607.5
2373.4	608
2375.26	593.5
2377.11	622
2378.97	633
2380.83	598
2382.68	619.5
2384.53	611.5
2386.39	618
2388.24	601
2390.09	614.5
2391.94	607
2393.79	602
2395.64	616.5
2397.49	604
2399.34	601.5
2401.19	603
2403.04	593
2404.89	599
2406.74	601
2408.58	601
2410.43	601.5
2412.27	609.5
2414.12	595
2415.96	593.5
2417.81	583
2419.65	593
2421.49	571.5
2423.34	581
2425.18	580
2427.02	574.5
2428.86	584
2430.7	584.5
2432.54	571.5
2434.38	562
2436.22	583
2438.05	558.5
2439.89	579.5
2441.73	573
2443.56	580.5
2445.4	572
2447.24	576
2449.07	570
2450.9	573
2452.74	576
2454.57	578
2456.4	572.5
2458.23	568
2460.07	566
2461.9	557
2463.73	553
2465.56	563
2467.39	552.5
2469.21	556.5
2471.04	569.5
2472.87	548
2474.7	544
2476.52	550.5
2478.35	558
2480.17	559.5
2482	550.5
2483.82	547.5
2485.65	539
2487.47	546
2489.29	547.5
2491.12	536
2492.94	541
2494.76	545.5
2496.58	544
2498.4	537
2500.22	544
2502.04	554.5
2503.86	533.5
2505.67	531.5
2507.49	515.5
2509.31	519
2511.12	527.5
2512.94	531
2514.76	523
2516.57	535
2518.38	526
2520.2	512
2522.01	512.5
2523.82	525
2525.64	513.5
2527.45	505
2529.26	513.5
2531.07	522
2532.88	512.5
2534.69	508.5
2536.5	508.5
2538.31	501.5
2540.11	501
2541.92	509
2543.73	507
2545.53	506.5
2547.34	500.5
2549.14	511
2550.95	510
2552.75	507
2554.56	517
2556.36	489
2558.16	485.5
2559.96	498.5
2561.76	491.5
2563.57	493.5
2565.37	483.5
2567.17	486
2568.96	496
2570.76	487.5
2572.56	484.5
2574.36	483.5
2576.16	482.5
2577.95	498
2579.75	493
2581.54	486
2583.34	497.5
2585.13	485
2586.93	482.5
2588.72	494
2590.51	468.5
2592.31	485.5
2594.1	469.5
2595.89	465
2597.68	481
2599.47	482
2601.26	470
2603.05	470.5
2604.84	480
2606.63	456.5
2608.42	462
2610.2	457.5
2611.99	470.5
2613.78	449.5
2615.56	465.5
2617.35	456.5
2619.13	463.5
2620.91	468
2622.7	455.5
2624.48	463.5
2626.26	454.5
2628.04	453.5
2629.83	447
2631.61	462.5
2633.39	459.5
2635.17	435.5
2636.95	440.5
2638.73	451
2640.5	442
2642.28	450
2644.06	434.5
2645.84	451
2647.61	439
2649.39	437.5
2651.16	449
2652.94	433.5
2654.71	437.5
2656.49	426
2658.26	445.5
2660.03	441.5
2661.8	434
2663.57	427.5
2665.35	434
2667.12	440.5
2668.89	442.5
2670.66	437.5
2672.42	440
2674.19	428
2675.96	419.5
2677.73	432
2679.49	440.5
2681.26	428
2683.03	436
2684.79	427
2686.56	423.5
2688.32	436
2690.09	423
2691.85	404.5
2693.61	422.5
2695.37	422
2697.14	418
2698.9	432.5
2700.66	421.5
2702.42	435
2704.18	416.5
2705.94	408.5
2707.7	418
2709.45	405
2711.21	412.5
2712.97	424.5
2714.72	419
2716.48	407.5
2718.24	412.5
2719.99	415
2721.75	422
2723.5	412.5
2725.25	410
2727.01	409
2728.76	398
2730.51	408.5
2732.26	411.5
2734.01	396
2735.76	405.5
2737.51	407.5
2739.26	407
2741.01	399
2742.76	389.5
2744.51	391.5
2746.26	396.5
2748	397.5
2749.75	381
2751.5	393.5
2753.24	394
2754.99	384
2756.73	395.5
2758.47	382.5
2760.22	377
2761.96	382.5
2763.7	383.5
2765.44	384.5
2767.19	386.5
2768.93	382.5
2770.67	396.5
2772.41	372.5
2774.15	374
2775.89	389
2777.62	374
2779.36	380.5
2781.1	379.5
2782.84	380
2784.57	373
2786.31	377.5
2788.04	377.5
2789.78	378.5
2791.51	377
2793.24	359
2794.98	365.5
2796.71	363
2798.44	377
2800.18	370
2801.91	362
2803.64	367.25
2805.37	379.5
2807.1	380
2808.83	357
2810.55	368
2812.28	373
2814.01	362.5
2815.74	355.5
2817.46	372
2819.19	348.5
2820.92	365.5
2822.64	364.5
2824.37	356.5
2826.09	365
2827.81	353.5
2829.54	360
2831.26	367.5
2832.98	353.5
2834.71	360
2836.43	366
2838.15	351.5
2839.87	351
2841.59	354.5
2843.31	375
2845.02	358.5
2846.74	367.5
2848.46	355
2850.18	360
2851.9	363
2853.61	379
2855.33	363
2857.04	355
2858.76	365
2860.47	363
2862.19	365
2863.9	373
2865.61	355
2867.32	350
2869.04	354
2870.75	359.5
2872.46	367
2874.17	364.5
2875.88	363.5
2877.59	366
2879.3	357.5
2881	356
2882.71	361.5
2884.42	373.5
2886.13	366
2887.83	355.5
2889.54	366
2891.24	356
2892.95	373
2894.65	363.5
2896.36	380
2898.06	364.5
2899.76	372
2901.47	364.5
2903.17	376
2904.87	379.5
2906.57	375.5
2908.27	373.5
2909.97	366.5
2911.67	374
2913.37	371.5
2915.07	377
2916.77	368.5
2918.47	356
2920.16	367.5
2921.86	369.5
2923.55	378.5
2925.25	389.5
2926.94	374.5
2928.64	375.5
2930.33	384
2932.03	382
2933.72	383.5
2935.41	385
2937.11	386.5
2938.8	376.5
2940.49	380.5
2942.18	372
2943.87	356.5
2945.56	352
2947.25	364
2948.94	344
2950.63	340.5
2952.31	330.5
2954	344
2955.69	340.5
2957.37	343
2959.06	314.5
2960.75	343
2962.43	333
2964.11	335.5
2965.8	321
2967.48	327.5
2969.16	325
2970.85	325
2972.53	324.5
2974.21	321
2975.89	323.5
2977.57	317.5
2979.25	313.5
2980.93	320
2982.61	312
2984.29	306.5
2985.97	304
2987.65	308
2989.32	315.5
2991	299.5
2992.68	301.5
2994.35	286
2996.03	291
2997.7	292.5
2999.38	284