File: muestras/ogompa/nsno_09.txt
#Acq. time (s)=	5
#Accumulations=	5
#Range (cm-¹)=	100...3000
#Windows=	3
#Autofocus=	Off
#AutoExposure=	Off
#Spike filter=	Multiple accum.
#Delay time (s)=	0
#Binning=	1
#Readout mode=	Signal
#DeNoise=	Off
#ICS correction=	Off
#Dark correction=	Off
#Inst. Process=	Off
#Instrument=	LabRAM HR Evol
#Detector=	Syncerity OE
#Objective=	x100_VIS_LWD
#Grating=	600 (500nm)
#ND Filter=	100%
#Laser=	633nm_Edge
#Hole=	100.021
#Range=	Visible
#Project=	Omar
#Sample=	chi
#Site=	f
#Title=	nsno
#Remark=
#Date=	12.09.2023 17:09
#Acquired=	12.09.2023 17:09:02
101.026	3504.5
103.592	3493.5
106.158	3444.5
108.723	3392.5
111.289	3317
113.852	3299.5
116.415	3243.5
118.976	3204.5
121.537	3179
124.097	3149
126.656	3113
129.215	3082
131.772	3041
134.327	3035
136.883	2971.5
139.438	2919.5
141.992	2888
144.545	2879
147.096	2808.5
149.648	2767.5
152.199	2732
154.747	2688.5
157.296	2674
159.843	2642
162.391	2642
164.937	2588
167.482	2613.5
170.025	2585.5
172.569	2552
175.111	2538
177.654	2524
180.194	2531
182.733	2537
185.273	2527.5
187.811	2491
190.348	2532
192.884	2534.5
195.419	2551
197.955	2569.5
200.489	2562.5
203.022	2611
205.554	2570
208.085	2586
210.615	2606.5
213.144	2588.5
215.673	2593
218.201	2594
220.728	2596
223.253	2591
225.778	2595.5
228.303	2614
230.826	2610.5
233.348	2609
235.87	2604
238.391	2629.5
240.91	2629
243.43	2640.5
245.949	2668
248.465	2626
250.983	2601.5
253.498	2655.5
256.013	2646.5
258.526	2666.5
261.039	2619.5
263.552	2623
266.063	2644.5
268.573	2638
271.084	2611
273.592	2627
276.1	2622.5
278.607	2655.5
281.113	2662
283.619	2667
286.124	2674.5
288.627	2693.5
291.13	2701.5
293.632	2689
296.133	2719.5
298.634	2709.5
301.133	2674
303.63	2710
306.128	2719
308.625	2717.5
311.122	2701
313.617	2716
316.111	2695.5
318.604	2718.5
321.098	2703
323.588	2672.5
326.08	2663.5
328.569	2620.5
331.059	2627
333.548	2620.5
336.035	2598.5
338.521	2573.5
341.008	2606
343.492	2579
345.977	2580.5
348.46	2595.5
350.942	2606.5
353.425	2616
355.905	2627
358.385	2608
360.864	2607
363.342	2615.5
365.819	2604
368.296	2616.5
370.771	2601
373.246	2584
375.72	2592
378.194	2573
380.666	2610
383.138	2595.5
385.609	2563.5
388.079	2584.5
390.548	2577.5
393.016	2587.5
395.483	2592
397.95	2590
400.416	2580.5
402.88	2584.5
405.345	2636
407.807	2645
410.27	2648.5
412.731	2663
415.193	2740.5
417.652	2712
420.112	2708
422.569	2757.5
425.028	2728.5
427.484	2729
429.939	2756
432.394	2792
434.849	2789
437.302	2777
439.754	2741.5
442.205	2761.5
444.656	2737.5
447.106	2721.5
449.555	2707.5
452.003	2718.5
454.45	2691.5
456.897	2705.5
459.343	2703
461.788	2662
464.232	2722.5
466.676	2694
469.119	2671.5
471.559	2734
474.001	2722
476.441	2688.5
478.879	2708
481.318	2711
483.756	2728
486.192	2736
488.629	2752
491.063	2756
493.498	2742
495.931	2787.5
498.365	2752.5
500.796	2765.5
503.226	2796.5
505.657	2800
508.086	2758.5
510.515	2786
512.942	2753
515.369	2767.5
517.796	2786.5
520.221	2826
522.645	2767
525.069	2783
527.492	2779.5
529.914	2772
532.335	2810.5
534.756	2757
537.175	2770
539.593	2753
542.011	2755.5
544.429	2739.5
546.845	2752.5
549.261	2754.5
551.675	2738
554.089	2744.5
556.503	2755
558.914	2755
561.326	2752.5
563.736	2786
566.147	2754.5
568.555	2746
570.964	2756
573.371	2757
575.777	2796.5
578.184	2784
580.588	2780.5
582.992	2747.5
585.395	2768.5
587.799	2794.5
590.201	2772.5
592.601	2728.5
595.001	2743
597.401	2779
599.799	2761.5
602.197	2771.5
604.594	2821
606.99	2777.5
609.386	2783
611.78	2785.5
614.174	2823.5
616.566	2832
618.958	2842
621.35	2841.5
623.741	2825
626.13	2838
628.519	2856.5
630.908	2873.5
633.295	2892.5
635.682	2874.5
638.067	2877.5
640.453	2861
642.836	2896
645.219	2889
647.602	2886.5
649.984	2877.5
652.364	2871
654.745	2860.5
657.124	2903.5
659.503	2865
661.88	2831
664.257	2842.5
666.635	2900.5
669.01	2877
671.384	2828.5
673.758	2847.5
676.131	2836.5
678.502	2819.5
680.874	2848.5
683.245	2847
685.615	2840
687.984	2823.5
690.353	2796.5
692.719	2810.5
695.086	2840
697.453	2804
699.817	2809
702.182	2811
704.545	2803
706.908	2807.5
709.27	2812
711.632	2823.5
713.991	2808.5
716.352	2835
718.71	2814.5
721.068	2812
723.426	2810.5
725.782	2811
728.138	2819
730.492	2841
732.846	2797
735.201	2804.5
737.553	2780
739.905	2797
742.256	2796.5
744.606	2835
746.956	2799.5
749.303	2800.5
751.651	2824.5
753.999	2798
756.345	2835
758.691	2824.5
761.035	2855
763.379	2771
765.723	2799
768.064	2804
770.407	2790
772.748	2776
775.088	2755.5
777.427	2770
779.765	2809.5
782.104	2825
784.44	2779.5
786.776	2820
789.113	2816.5
791.447	2789
793.78	2808
796.113	2819
798.445	2847.5
800.778	2832.5
803.109	2806
805.439	2858.5
807.768	2861.5
810.096	2858.5
812.424	2839
814.751	2860
817.078	2840
819.402	2868.5
821.727	2882.5
824.051	2855
826.374	2896
828.697	2842.5
831.018	2850.5
833.339	2854
835.659	2854.5
837.978	2903
840.297	2856
842.614	2892
844.932	2863.5
847.247	2899.5
849.562	2877
851.878	2898.5
854.191	2916
856.504	2898.5
858.817	2906
861.129	2891.5
863.439	2853
865.749	2882
868.058	2833
870.367	2848.5
872.676	2836
874.983	2818
877.289	2820
879.593	2792.5
881.898	2804.5
884.202	2826.5
886.506	2772
888.808	2779
891.11	2766
893.41	2777
895.711	2764.5
898.011	2801.5
900.309	2767.5
902.607	2746.5
904.904	2749.5
907.201	2729.5
909.496	2745.5
911.791	2764.5
914.085	2764.5
916.379	2769
918.671	2790
920.963	2753.5
923.255	2739
925.545	2721
927.834	2717
930.123	2709
932.411	2721.5
934.698	2767.5
936.985	2758
939.271	2723
941.556	2739
943.84	2733.5
946.124	2739
948.407	2712.5
950.689	2741.5
952.971	2758
955.25	2761
957.531	2784
959.81	2738
962.088	2784
964.366	2785.5
966.643	2749.5
968.919	2818
971.195	2785.5
973.469	2738
975.743	2786
978.016	2731.5
980.288	2767
982.56	2766.5
984.831	2739
987.101	2744.5
989.37	2750.5
991.638	2737
993.907	2735
996.174	2781
998.44	2793
1000.71	2799.5
1002.97	2738
1005.24	2733.5
1007.5	2719
1009.76	2723.5
1012.02	2725.5
1014.28	2746
1016.54	2724
1018.8	2702.5
1021.06	2703
1023.32	2724
1025.58	2754
1027.84	2725.5
1030.09	2750
1032.35	2733.5
1034.6	2755.5
1036.86	2732
1039.11	2720
1041.36	2725
1043.61	2738.5
1045.86	2780
1048.11	2775
1050.36	2751.5
1052.61	2778.5
1054.86	2777
1057.11	2721
1059.35	2775
1061.6	2769.5
1063.84	2779.5
1066.09	2745
1068.33	2764
1070.57	2740.5
1072.82	2755
1075.06	2783.5
1077.3	2762.5
1079.54	2734
1081.78	2752
1084.02	2702.5
1086.25	2762
1088.49	2717.5
1090.73	2698.5
1092.96	2716.5
1095.2	2723.5
1097.43	2736.5
1099.66	2743
1101.9	2700
1104.13	2693
1106.36	2704.5
1108.59	2702.5
1110.82	2727
1113.05	2752
1115.28	2697
1117.51	2691
1119.73	2693.5
1121.96	2682.5
1124.18	2701
1126.41	2711.5
1128.63	2732
1130.85	2732.5
1133.08	2750
1135.3	2730
1137.52	2736
1139.74	2719.5
1141.96	2756
1144.18	2750.5
1146.4	2785
1148.61	2801
1150.83	2792.5
1153.05	2806
1155.26	2864.5
1157.48	2866.5
1159.69	2895
1161.9	2903.5
1164.11	2877.5
1166.33	2961.5
1168.54	2942.5
1170.75	2959
1172.96	2937.5
1175.17	2926
1177.37	2946
1179.58	2920.5
1181.79	2903.5
1183.99	2854
1186.2	2882.5
1188.4	2891
1190.61	2829
1192.81	2857.5
1195.01	2803
1197.21	2811
1199.42	2781.74
1201.61	2832.82
1203.81	2832.65
1206.01	2796.05
1208.21	2805.82
1210.41	2794.17
1212.61	2782.31
1214.8	2784.72
1217	2780.89
1219.19	2731.03
1221.38	2744.54
1223.58	2722.04
1225.77	2748.26
1227.96	2734.82
1230.15	2709.67
1232.34	2750.44
1234.53	2758.35
1236.72	2734.24
1238.91	2740.36
1241.1	2729.87
1243.28	2732.86
1245.47	2736.53
1247.65	2737.64
1249.84	2738.25
1252.02	2742.06
1254.21	2749.3
1256.39	2762.02
1258.57	2757.25
1260.75	2736.12
1262.93	2761.87
1265.11	2754.72
1267.29	2749.15
1269.47	2769.17
1271.65	2772.15
1273.82	2770.1
1276	2767.58
1278.17	2761.64
1280.35	2741.11
1282.52	2754.73
1284.69	2771.08
1286.87	2772.65
1289.04	2755.12
1291.21	2767.39
1293.38	2770.48
1295.55	2746.58
1297.72	2747.99
1299.89	2726.8
1302.06	2750.66
1304.22	2724.09
1306.39	2723.38
1308.43	2696
1310.6	2732
1312.78	2692
1314.96	2702.5
1317.13	2691.5
1319.3	2666.5
1321.47	2659.5
1323.65	2687
1325.82	2668
1327.99	2694
1330.16	2658
1332.32	2682
1334.49	2694.5
1336.66	2675
1338.83	2667
1340.99	2670.5
1343.16	2658.5
1345.32	2649.5
1347.49	2614
1349.65	2604.5
1351.81	2658
1353.98	2608
1356.14	2622
1358.3	2596
1360.46	2634.5
1362.62	2609
1364.78	2585.5
1366.93	2598.5
1369.09	2592.5
1371.25	2573.5
1373.4	2593
1375.56	2612
1377.71	2556
1379.87	2597.5
1382.02	2566.5
1384.17	2543.5
1386.32	2583
1388.47	2568
1390.63	2552
1392.77	2545
1394.92	2494
1397.07	2519
1399.22	2518.5
1401.37	2535.5
1403.51	2527
1405.66	2531.5
1407.8	2548
1409.95	2539.5
1412.09	2531
1414.23	2517.5
1416.38	2516
1418.52	2548
1420.66	2524
1422.8	2524.5
1424.94	2530
1427.08	2559
1429.21	2560.5
1431.35	2511.5
1433.49	2577.5
1435.63	2564.5
1437.76	2579
1439.89	2597
1442.03	2577
1444.16	2633.5
1446.3	2617.5
1448.43	2611.5
1450.56	2643.5
1452.69	2630
1454.82	2596.5
1456.95	2567
1459.08	2563.5
1461.2	2581
1463.33	2627
1465.46	2566
1467.58	2574
1469.71	2626.5
1471.83	2581
1473.96	2571.5
1476.08	2590.5
1478.2	2601
1480.33	2591
1482.45	2618
1484.57	2617.5
1486.69	2637
1488.81	2601.5
1490.93	2607
1493.04	2639.5
1495.16	2634
1497.28	2676.5
1499.39	2644
1501.51	2686.5
1503.62	2668.5
1505.74	2668.5
1507.85	2662.5
1509.96	2618.5
1512.07	2643.5
1514.19	2628.5
1516.3	2634.5
1518.41	2577
1520.52	2617.5
1522.62	2623.5
1524.73	2628
1526.84	2609
1528.95	2635.5
1531.05	2607.5
1533.16	2613
1535.26	2650
1537.37	2639
1539.47	2576.5
1541.57	2620.5
1543.67	2652
1545.78	2574
1547.88	2562.5
1549.98	2632
1552.07	2600
1554.17	2597.5
1556.27	2572.5
1558.37	2632
1560.47	2613.5
1562.56	2568.5
1564.66	2576.5
1566.75	2601
1568.85	2612
1570.94	2563
1573.03	2563
1575.12	2574.5
1577.21	2609.5
1579.31	2582.5
1581.4	2565
1583.49	2607.5
1585.57	2620.5
1587.66	2621.5
1589.75	2577.5
1591.84	2591
1593.92	2600.5
1596.01	2566.5
1598.09	2600
1600.18	2590.5
1602.26	2605
1604.34	2573.5
1606.43	2507
1608.51	2473.5
1610.59	2426
1612.67	2423.5
1614.75	2359.5
1616.83	2369
1618.91	2326
1620.98	2280.5
1623.06	2245.5
1625.14	2201
1627.21	2175
1629.29	2172
1631.36	2105.5
1633.43	2104
1635.51	2102
1637.58	2050.5
1639.65	2056
1641.72	2015.5
1643.79	2019.5
1645.86	1956
1647.93	1945
1650	1936
1652.07	1919
1654.14	1916.5
1656.2	1886.5
1658.27	1851.5
1660.34	1844.5
1662.4	1829
1664.46	1781.5
1666.53	1798.5
1668.59	1783.5
1670.65	1788
1672.71	1756.5
1674.77	1760.5
1676.83	1755
1678.89	1726
1680.95	1712
1683.01	1710
1685.07	1713.5
1687.13	1705
1689.18	1681.5
1691.24	1661.5
1693.29	1681
1695.35	1672.5
1697.4	1655
1699.45	1673.5
1701.51	1617
1703.56	1632.5
1705.61	1624.5
1707.66	1608.5
1709.71	1605.5
1711.76	1592
1713.81	1571.5
1715.86	1609.5
1717.9	1596
1719.95	1580.5
1722	1574
1724.04	1569
1726.09	1557
1728.13	1536.5
1730.17	1557.5
1732.22	1561
1734.26	1554.5
1736.3	1542.5
1738.34	1533
1740.38	1528.5
1742.42	1551
1744.46	1530
1746.5	1512
1748.54	1505.5
1750.57	1470.5
1752.61	1495
1754.65	1474
1756.68	1465
1758.72	1494
1760.75	1475.5
1762.78	1461.5
1764.82	1454.5
1766.85	1450.5
1768.88	1450
1770.91	1424
1772.94	1421
1774.97	1431.5
1777	1414.5
1779.03	1433.5
1781.06	1422
1783.08	1423.5
1785.11	1430
1787.14	1420.5
1789.16	1437.5
1791.18	1400.5
1793.21	1378.5
1795.23	1383.5
1797.26	1364
1799.28	1356.5
1801.3	1377.5
1803.32	1379.5
1805.34	1393
1807.36	1375
1809.38	1362.5
1811.4	1351.5
1813.41	1353
1815.43	1345
1817.45	1347
1819.46	1350
1821.48	1334.5
1823.49	1296.5
1825.51	1318
1827.52	1295.5
1829.53	1333
1831.54	1313
1833.56	1311
1835.57	1296
1837.58	1278
1839.59	1294.5
1841.59	1272.5
1843.6	1287
1845.61	1275.5
1847.62	1282
1849.62	1278.5
1851.63	1266
1853.64	1268.5
1855.64	1250
1857.64	1253.5
1859.65	1238.5
1861.65	1267
1863.65	1245
1865.65	1254.5
1867.65	1235.5
1869.65	1233.5
1871.65	1243
1873.65	1240
1875.65	1237
1877.65	1226
1879.65	1207
1881.64	1228
1883.64	1193
1885.63	1217.5
1887.63	1218
1889.62	1211.5
1891.62	1186
1893.61	1199.5
1895.6	1197
1897.59	1212
1899.58	1195.5
1901.57	1192.5
1903.56	1210.5
1905.55	1211
1907.54	1197.5
1909.53	1178.5
1911.52	1201
1913.5	1186
1915.49	1181.5
1917.48	1176
1919.46	1150.5
1921.44	1162.5
1923.43	1163
1925.41	1145
1927.39	1177.5
1929.38	1173.5
1931.36	1149
1933.34	1131
1935.32	1161.5
1937.3	1157.5
1939.28	1136
1941.25	1147
1943.23	1142.5
1945.21	1125.5
1947.18	1136
1949.16	1129
1951.13	1109.5
1953.11	1128.5
1955.08	1121.5
1957.06	1118
1959.03	1105
1961	1113
1962.97	1118.5
1964.94	1100.5
1966.91	1102
1968.88	1094
1970.85	1080
1972.82	1096
1974.79	1120.5
1976.76	1062
1978.72	1098
1980.69	1086
1982.65	1086
1984.62	1085.5
1986.58	1092
1988.55	1103.5
1990.51	1072
1992.47	1076.5
1994.43	1084
1996.39	1059
1998.36	1066
2000.31	1057.5
2002.27	1071
2004.23	1057
2006.19	1059.5
2008.15	1064.5
2010.11	1049.5
2012.06	1060.5
2014.02	1040.5
2015.97	1052.5
2017.93	1055
2019.88	1038.5
2021.83	1018
2023.79	1043
2025.74	1032.5
2027.69	1035.5
2029.64	1014.5
2031.59	1028.5
2033.54	1029.5
2035.49	1031
2037.44	1009
2039.39	1015
2041.34	1009
2043.28	984.5
2045.23	1033.5
2047.17	1008.5
2049.12	986.5
2051.06	979.5
2053.01	985.5
2054.95	986
2056.89	995.5
2058.84	997
2060.78	1005
2062.72	995.5
2064.66	966
2066.6	969
2068.54	982
2070.48	982.5
2072.41	985
2074.35	980
2076.29	982
2078.22	987.5
2080.16	975
2082.09	955.5
2084.03	979
2085.96	947.5
2087.9	969.5
2089.83	958
2091.76	965
2093.69	940
2095.62	963.5
2097.55	941
2099.48	951
2101.41	956
2103.34	975
2105.27	974
2107.19	991.5
2109.12	974
2111.05	1005.5
2112.97	1006.5
2114.9	1030.5
2116.82	1055
2118.75	1046
2120.67	1060
2122.59	1092.5
2124.51	1090
2126.43	1136.5
2128.36	1132.5
2130.28	1158.5
2132.2	1146
2134.11	1144
2136.03	1131.5
2137.95	1101
2139.87	1075
2141.78	1065.5
2143.7	1025
2145.62	1067.17
2147.53	1018.39
2149.45	1012.01
2151.36	1001.4
2153.27	993.745
2155.19	987.224
2157.1	985.259
2159.01	976.899
2160.92	963.422
2162.83	948.962
2164.74	954.875
2166.65	937.775
2168.56	924.635
2170.47	919.025
2172.37	917.849
2174.28	917.081
2176.19	901.591
2178.09	907.817
2180	879.308
2181.9	879.602
2183.81	863.195
2185.71	863.581
2187.61	844.161
2189.51	839.629
2191.42	834.127
2193.32	826.94
2195.22	814.723
2197.12	825.068
2199.02	811.524
2200.92	804.296
2202.81	815.561
2204.71	815.446
2206.61	804.073
2208.5	803.075
2210.4	805.161
2212.3	797.4
2214.19	798.151
2216.08	788.03
2217.98	789.129
2219.87	782.738
2221.76	784.377
2223.65	783.734
2225.55	770.054
2227.44	785.93
2229.33	786.361
2231.22	780.812
2233.11	787.134
2234.99	779.037
2236.88	776.277
2238.77	773.495
2240.66	771.06
2242.06	786.5
2243.96	802
2245.85	815.5
2247.75	806.5
2249.64	793
2251.54	784.5
2253.43	787.5
2255.32	780
2257.21	761
2259.1	765.5
2260.99	770
2262.89	740.5
2264.77	726
2266.66	728
2268.55	735
2270.44	735
2272.33	719.5
2274.21	743.5
2276.1	727.5
2277.98	726
2279.87	712
2281.75	731
2283.64	718
2285.52	717.5
2287.4	691
2289.29	713
2291.17	699
2293.05	704
2294.93	706
2296.81	693
2298.69	695
2300.57	717
2302.44	705
2304.32	698.5
2306.2	706
2308.08	691
2309.95	672
2311.83	677.5
2313.7	691
2315.58	685
2317.45	684.5
2319.32	671
2321.2	678
2323.07	685.5
2324.94	686.5
2326.81	670
2328.68	665.5
2330.55	663.5
2332.42	672
2334.29	679
2336.16	676.5
2338.02	655
2339.89	675
2341.76	664
2343.62	654
2345.49	660.5
2347.35	662.5
2349.22	665
2351.08	648
2352.94	673
2354.81	649.5
2356.67	664.5
2358.53	653.5
2360.39	670
2362.25	645.5
2364.11	650.5
2365.97	652
2367.83	663
2369.69	639
2371.55	653
2373.4	640
2375.26	659.5
2377.11	645.5
2378.97	631
2380.83	642.5
2382.68	636
2384.53	625
2386.39	631
2388.24	626
2390.09	633
2391.94	626.5
2393.79	639.5
2395.64	626
2397.49	625.5
2399.34	614.5
2401.19	624.5
2403.04	612
2404.89	607
2406.74	627.5
2408.58	614
2410.43	617
2412.27	620
2414.12	617.5
2415.96	585.5
2417.81	604.5
2419.65	603
2421.49	610
2423.34	606.5
2425.18	601.5
2427.02	613
2428.86	597.5
2430.7	605.5
2432.54	597.5
2434.38	566
2436.22	596
2438.05	589.5
2439.89	602
2441.73	584
2443.56	598.5
2445.4	579
2447.24	572.5
2449.07	591
2450.9	599
2452.74	577.5
2454.57	575
2456.4	567.5
2458.23	585.5
2460.07	594.5
2461.9	566.5
2463.73	580.5
2465.56	589
2467.39	577.5
2469.21	574
2471.04	582.5
2472.87	565
2474.7	565
2476.52	563
2478.35	575.5
2480.17	568.5
2482	574
2483.82	560
2485.65	560
2487.47	559.5
2489.29	562
2491.12	571
2492.94	552
2494.76	566
2496.58	539
2498.4	551
2500.22	556.5
2502.04	554
2503.86	573
2505.67	553.5
2507.49	544
2509.31	524.5
2511.12	551.5
2512.94	531
2514.76	553.5
2516.57	555
2518.38	537
2520.2	545
2522.01	547
2523.82	539.5
2525.64	531
2527.45	542.5
2529.26	533
2531.07	519
2532.88	529.5
2534.69	526.5
2536.5	520
2538.31	527
2540.11	529.5
2541.92	527
2543.73	523
2545.53	521.5
2547.34	518
2549.14	520
2550.95	515
2552.75	523
2554.56	507.5
2556.36	509
2558.16	504.5
2559.96	507.5
2561.76	512.5
2563.57	505.5
2565.37	519
2567.17	500
2568.96	525
2570.76	516.5
2572.56	509
2574.36	506
2576.16	499.5
2577.95	496
2579.75	513.5
2581.54	489
2583.34	493.5
2585.13	509.5
2586.93	489.5
2588.72	488.5
2590.51	497.5
2592.31	494
2594.1	499
2595.89	484.5
2597.68	497.5
2599.47	496.5
2601.26	479.5
2603.05	494
2604.84	486
2606.63	471.5
2608.42	496
2610.2	478.5
2611.99	455
2613.78	484.5
2615.56	486
2617.35	465
2619.13	473
2620.91	472.5
2622.7	468.5
2624.48	473.5
2626.26	482
2628.04	468.5
2629.83	467
2631.61	476
2633.39	468
2635.17	472.5
2636.95	463
2638.73	461.5
2640.5	440.5
2642.28	464
2644.06	457
2645.84	456.5
2647.61	452.5
2649.39	447.5
2651.16	446.5
2652.94	442
2654.71	461
2656.49	445
2658.26	459.5
2660.03	450
2661.8	455.5
2663.57	443.5
2665.35	440.5
2667.12	432
2668.89	446.5
2670.66	440.5
2672.42	448.5
2674.19	453
2675.96	451
2677.73	448
2679.49	449
2681.26	443.5
2683.03	429
2684.79	447.5
2686.56	442.5
2688.32	436.5
2690.09	425.5
2691.85	416.5
2693.61	417.5
2695.37	423
2697.14	444.5
2698.9	428.5
2700.66	428.5
2702.42	433
2704.18	423
2705.94	424
2707.7	434.5
2709.45	427
2711.21	436
2712.97	412
2714.72	423
2716.48	426
2718.24	422
2719.99	416
2721.75	416
2723.5	415.5
2725.25	418
2727.01	426
2728.76	430.5
2730.51	400.5
2732.26	404
2734.01	397
2735.76	406
2737.51	403
2739.26	404
2741.01	411.5
2742.76	399
2744.51	402.5
2746.26	410
2748	404.5
2749.75	389
2751.5	395
2753.24	415
2754.99	374
2756.73	389.5
2758.47	399
2760.22	393
2761.96	390
2763.7	411
2765.44	393
2767.19	398
2768.93	388
2770.67	380
2772.41	372.5
2774.15	391.5
2775.89	383.5
2777.62	391
2779.36	385.5
2781.1	389
2782.84	383.5
2784.57	383.5
2786.31	379
2788.04	392
2789.78	375
2791.51	388.5
2793.24	382
2794.98	378
2796.71	385.5
2798.44	374.5
2800.18	377
2801.91	380.5
2803.64	365.5
2805.37	356
2807.1	373.5
2808.83	376.5
2810.55	371
2812.28	367
2814.01	371
2815.74	366
2817.46	361
2819.19	366
2820.92	367.5
2822.64	379
2824.37	362.5
2826.09	365
2827.81	350.5
2829.54	363.5
2831.26	368.5
2832.98	348
2834.71	365
2836.43	364.5
2838.15	363.5
2839.87	364.5
2841.59	351
2843.31	351.5
2845.02	363
2846.74	351
2848.46	358
2850.18	360
2851.9	373.5
2853.61	367
2855.33	346
2857.04	358.5
2858.76	361.5
2860.47	358.5
2862.19	349.5
2863.9	348
2865.61	356
2867.32	360
2869.04	362
2870.75	365
2872.46	370
2874.17	364.5
2875.88	358.5
2877.59	362.5
2879.3	342
2881	353.5
2882.71	365
2884.42	352
2886.13	361
2887.83	349.5
2889.54	340
2891.24	366.5
2892.95	361.5
2894.65	349
2896.36	355
2898.06	353.5
2899.76	371.5
2901.47	361
2903.17	356
2904.87	366.5
2906.57	356
2908.27	347
2909.97	371.5
2911.67	364
2913.37	372
2915.07	362.5
2916.77	368
2918.47	364
2920.16	366.5
2921.86	365.5
2923.55	363.5
2925.25	363.5
2926.94	384.5
2928.64	382
2930.33	375.5
2932.03	371
2933.72	378.5
2935.41	375
2937.11	372
2938.8	380
2940.49	371.5
2942.18	379
2943.87	375.5
2945.56	364
2947.25	356
2948.94	357.5
2950.63	357
2952.31	346.5
2954	345
2955.69	339
2957.37	338
2959.06	329.5
2960.75	320
2962.43	328.5
2964.11	316
2965.8	330.5
2967.48	328
2969.16	317.5
2970.85	323
2972.53	319
2974.21	317.5
2975.89	315.5
2977.57	314.5
2979.25	314.5
2980.93	323
2982.61	304
2984.29	319.5
2985.97	295
2987.65	304
2989.32	303.5
2991	301
2992.68	295
2994.35	292.5
2996.03	292
2997.7	295
2999.38	285.5