File: muestras/ogompa/nsno_15.txt
#Acq. time (s)=	5
#Accumulations=	5
#Range (cm-¹)=	100...3000
#Windows=	3
#Autofocus=	Off
#AutoExposure=	Off
#Spike filter=	Multiple accum.
#Delay time (s)=	0
#Binning=	1
#Readout mode=	Signal
#DeNoise=	Off
#ICS correction=	Off
#Dark correction=	Off
#Inst. Process=	Off
#Instrument=	LabRAM HR Evol
#Detector=	Syncerity OE
#Objective=	x100_VIS_LWD
#Grating=	600 (500nm)
#ND Filter=	100%
#Laser=	633nm_Edge
#Hole=	100.021
#Range=	Visible
#Project=	Omar
#Sample=	chi
#Site=	f
#Title=	nsno
#Remark=
#Date=	12.09.2023 17:30
#Acquired=	12.09.2023 17:30:41
101.026	2121
103.592	2110
106.158	2025
108.723	2008.5
111.289	1966.5
113.852	1926.5
116.415	1895
118.976	1898
121.537	1888.5
124.097	1864.5
126.656	1829.5
129.215	1790
131.772	1778.5
134.327	1749
136.883	1749
139.438	1724.5
141.992	1709
144.545	1661.5
147.096	1631.5
149.648	1598
152.199	1576
154.747	1559
157.296	1541.5
159.843	1489
162.391	1508
164.937	1477.5
167.482	1476.5
170.025	1464
172.569	1429
175.111	1442.5
177.654	1419.5
180.194	1410.5
182.733	1429
185.273	1410
187.811	1432.5
190.348	1397.5
192.884	1401
195.419	1398
197.955	1431.5
200.489	1400
203.022	1434
205.554	1425
208.085	1449
210.615	1438
213.144	1437.5
215.673	1430
218.201	1441.5
220.728	1428
223.253	1448
225.778	1444.5
228.303	1436
230.826	1455
233.348	1466
235.87	1449
238.391	1450.5
240.91	1454.5
243.43	1469.5
245.949	1459
248.465	1475.5
250.983	1477.5
253.498	1472.5
256.013	1493
258.526	1485.5
261.039	1489.5
263.552	1457.5
266.063	1454
268.573	1486.5
271.084	1475
273.592	1505.5
276.1	1497
278.607	1497.5
281.113	1510.5
283.619	1499
286.124	1525.5
288.627	1504.5
291.13	1517.5
293.632	1527
296.133	1556.5
298.634	1551
301.133	1547
303.63	1554.5
306.128	1552.5
308.625	1537
311.122	1523
313.617	1529
316.111	1537
318.604	1511
321.098	1519.5
323.588	1499
326.08	1509
328.569	1497
331.059	1481.5
333.548	1501
336.035	1473.5
338.521	1486.5
341.008	1462.5
343.492	1478
345.977	1474
348.46	1475
350.942	1476.5
353.425	1471
355.905	1470
358.385	1468
360.864	1481
363.342	1486
365.819	1473.5
368.296	1459
370.771	1501.5
373.246	1457.5
375.72	1469
378.194	1451
380.666	1450
383.138	1455
385.609	1446.5
388.079	1431.5
390.548	1449
393.016	1457
395.483	1434
397.95	1443
400.416	1440.5
402.88	1480.5
405.345	1473
407.807	1463.5
410.27	1496.5
412.731	1515.5
415.193	1514
417.652	1515
420.112	1547
422.569	1534
425.028	1512
427.484	1530
429.939	1540
432.394	1525
434.849	1509.5
437.302	1566
439.754	1519.5
442.205	1525
444.656	1515
447.106	1516
449.555	1540.5
452.003	1526
454.45	1516.5
456.897	1571
459.343	1535
461.788	1533
464.232	1532.5
466.676	1525
469.119	1544
471.559	1544.5
474.001	1528.5
476.441	1547
478.879	1545
481.318	1558.5
483.756	1541.5
486.192	1555
488.629	1547
491.063	1556
493.498	1538
495.931	1563.5
498.365	1598.5
500.796	1595
503.226	1590
505.657	1573.5
508.086	1576.5
510.515	1583.5
512.942	1575
515.369	1595
517.796	1568
520.221	1580.5
522.645	1557
525.069	1587
527.492	1558
529.914	1562.5
532.335	1574.5
534.756	1557
537.175	1577
539.593	1557.5
542.011	1565.5
544.429	1547
546.845	1559
549.261	1554.5
551.675	1555
554.089	1556
556.503	1562
558.914	1563.5
561.326	1568
563.736	1526.5
566.147	1573
568.555	1544
570.964	1558.5
573.371	1551
575.777	1552.5
578.184	1563
580.588	1582
582.992	1566.5
585.395	1568
587.799	1550
590.201	1555
592.601	1579.5
595.001	1573
597.401	1570
599.799	1559.5
602.197	1579
604.594	1578
606.99	1581.5
609.386	1566.5
611.78	1589.5
614.174	1565
616.566	1606.5
618.958	1618
621.35	1609.5
623.741	1629
626.13	1606.5
628.519	1617
630.908	1611.5
633.295	1621
635.682	1641.5
638.067	1614
640.453	1652
642.836	1639.5
645.219	1622
647.602	1611
649.984	1640
652.364	1626.5
654.745	1662.5
657.124	1637
659.503	1627.5
661.88	1640
664.257	1636
666.635	1610
669.01	1640
671.384	1620.5
673.758	1611
676.131	1624.5
678.502	1612
680.874	1597.5
683.245	1589.5
685.615	1606
687.984	1578.5
690.353	1589.5
692.719	1600.5
695.086	1595
697.453	1566.5
699.817	1586
702.182	1577
704.545	1602
706.908	1568.5
709.27	1607
711.632	1587.5
713.991	1619
716.352	1602
718.71	1593
721.068	1602.5
723.426	1596.5
725.782	1597
728.138	1613.5
730.492	1588
732.846	1592.5
735.201	1604.5
737.553	1607
739.905	1586.5
742.256	1593.5
744.606	1594
746.956	1614
749.303	1588.5
751.651	1579
753.999	1584
756.345	1598
758.691	1606.5
761.035	1608.5
763.379	1586
765.723	1605
768.064	1609
770.407	1579.5
772.748	1590
775.088	1570
777.427	1592
779.765	1603
782.104	1579.5
784.44	1594
786.776	1579.5
789.113	1570.5
791.447	1566.5
793.78	1613.5
796.113	1603
798.445	1583.5
800.778	1611
803.109	1604.5
805.439	1595
807.768	1606
810.096	1616
812.424	1607
814.751	1611
817.078	1635
819.402	1630.5
821.727	1615.5
824.051	1637.5
826.374	1636
828.697	1622
831.018	1666.5
833.339	1667
835.659	1626
837.978	1656.5
840.297	1649
842.614	1650.5
844.932	1661
847.247	1652
849.562	1652
851.878	1646
854.191	1655.5
856.504	1669.5
858.817	1658
861.129	1642.5
863.439	1665
865.749	1637.5
868.058	1635.5
870.367	1592.5
872.676	1637
874.983	1603
877.289	1629.5
879.593	1601.5
881.898	1606.5
884.202	1609.5
886.506	1608.5
888.808	1604.5
891.11	1588.5
893.41	1594
895.711	1563.5
898.011	1584.5
900.309	1577
902.607	1577.5
904.904	1589.5
907.201	1559.5
909.496	1587.5
911.791	1552.5
914.085	1548
916.379	1561.5
918.671	1551.5
920.963	1540
923.255	1562.5
925.545	1556.5
927.834	1540
930.123	1574
932.411	1560
934.698	1582.5
936.985	1560
939.271	1564.5
941.556	1560
943.84	1564.5
946.124	1561
948.407	1550
950.689	1579
952.971	1570.5
955.25	1572.5
957.531	1599.5
959.81	1592
962.088	1587
964.366	1562
966.643	1579
968.919	1588.5
971.195	1582
973.469	1555.5
975.743	1583
978.016	1568.5
980.288	1570
982.56	1588.5
984.831	1575.5
987.101	1591.5
989.37	1579
991.638	1591
993.907	1586
996.174	1617.5
998.44	1648.5
1000.71	1644
1002.97	1617.5
1005.24	1586.5
1007.5	1595
1009.76	1571.5
1012.02	1546.5
1014.28	1579.5
1016.54	1544.5
1018.8	1581
1021.06	1570
1023.32	1555.5
1025.58	1568
1027.84	1564.5
1030.09	1558.5
1032.35	1560.5
1034.6	1587.5
1036.86	1573.5
1039.11	1597.5
1041.36	1590.5
1043.61	1592.5
1045.86	1574
1048.11	1581.5
1050.36	1582
1052.61	1604
1054.86	1589.5
1057.11	1584
1059.35	1556
1061.6	1596
1063.84	1586.5
1066.09	1602
1068.33	1572.5
1070.57	1592.5
1072.82	1586
1075.06	1571.5
1077.3	1581.5
1079.54	1572
1081.78	1574.5
1084.02	1568.5
1086.25	1554.5
1088.49	1570
1090.73	1564.5
1092.96	1556
1095.2	1569
1097.43	1564
1099.66	1564.5
1101.9	1568
1104.13	1551.5
1106.36	1556
1108.59	1544.5
1110.82	1555.5
1113.05	1541.5
1115.28	1538.5
1117.51	1520
1119.73	1526
1121.96	1562.5
1124.18	1563
1126.41	1578.5
1128.63	1566
1130.85	1573
1133.08	1577.5
1135.3	1564.5
1137.52	1604.5
1139.74	1565
1141.96	1591.5
1144.18	1564
1146.4	1591
1148.61	1613
1150.83	1591.5
1153.05	1602
1155.26	1584
1157.48	1619.5
1159.69	1632
1161.9	1635
1164.11	1630.5
1166.33	1649
1168.54	1647.5
1170.75	1630
1172.96	1647
1175.17	1637.5
1177.37	1599.5
1179.58	1635.5
1181.79	1631
1183.99	1626.5
1186.2	1599.5
1188.4	1602.5
1190.61	1582
1192.81	1592
1195.01	1579
1197.21	1606.24
1199.42	1620.22
1201.61	1592.38
1203.81	1582.51
1206.01	1581.42
1208.21	1589.74
1210.41	1570.68
1212.61	1603.08
1214.8	1595.79
1217	1574.83
1219.19	1586.61
1221.38	1576.87
1223.58	1578.14
1225.77	1587.37
1227.96	1579.8
1230.15	1586.82
1232.34	1578.27
1234.53	1583.89
1236.72	1606.26
1238.91	1595.22
1241.1	1603.14
1243.28	1608.5
1245.47	1613.31
1247.65	1589.76
1249.84	1600.6
1252.02	1602.11
1254.21	1618.88
1256.39	1619.35
1258.57	1597.8
1260.75	1613.75
1262.93	1627.7
1265.11	1625.57
1267.29	1640.04
1269.47	1627.65
1271.65	1638.28
1273.82	1642
1276	1655.42
1278.17	1668.82
1280.35	1648.98
1282.52	1658.59
1284.69	1654.95
1286.87	1650.37
1289.04	1649.41
1291.21	1655.99
1293.38	1658.51
1295.55	1659.15
1297.72	1659.57
1299.89	1676.14
1302.06	1651.49
1304.22	1660.85
1306.39	1641.45
1308.43	1659.5
1310.6	1643
1312.78	1642
1314.96	1633
1317.13	1619.5
1319.3	1629
1321.47	1623.5
1323.65	1632
1325.82	1642
1327.99	1604
1330.16	1623
1332.32	1634
1334.49	1640
1336.66	1637.5
1338.83	1592.5
1340.99	1598.5
1343.16	1601.5
1345.32	1608
1347.49	1582
1349.65	1575
1351.81	1575.5
1353.98	1527.5
1356.14	1571
1358.3	1566.5
1360.46	1556.5
1362.62	1541
1364.78	1538.5
1366.93	1522
1369.09	1550
1371.25	1506.5
1373.4	1507
1375.56	1517
1377.71	1509
1379.87	1517.5
1382.02	1496
1384.17	1526
1386.32	1510
1388.47	1477.5
1390.63	1510.5
1392.77	1509.5
1394.92	1479.5
1397.07	1493.5
1399.22	1477
1401.37	1481.5
1403.51	1503
1405.66	1490.5
1407.8	1495
1409.95	1501.5
1412.09	1508
1414.23	1509
1416.38	1515.5
1418.52	1500
1420.66	1492.5
1422.8	1499.5
1424.94	1503
1427.08	1524
1429.21	1524
1431.35	1519
1433.49	1499
1435.63	1498.5
1437.76	1496.5
1439.89	1495.5
1442.03	1514
1444.16	1531.5
1446.3	1513.5
1448.43	1535
1450.56	1530
1452.69	1532.5
1454.82	1529
1456.95	1529
1459.08	1536
1461.2	1529.5
1463.33	1509.5
1465.46	1523.5
1467.58	1517.5
1469.71	1521.5
1471.83	1518
1473.96	1525
1476.08	1522
1478.2	1552.5
1480.33	1551
1482.45	1549.5
1484.57	1557
1486.69	1547
1488.81	1540
1490.93	1576
1493.04	1586
1495.16	1575.5
1497.28	1572.5
1499.39	1542.5
1501.51	1599.5
1503.62	1581
1505.74	1582.5
1507.85	1570
1509.96	1590
1512.07	1605
1514.19	1602
1516.3	1589
1518.41	1646.5
1520.52	1624
1522.62	1627
1524.73	1631
1526.84	1648.5
1528.95	1635.5
1531.05	1607
1533.16	1646.5
1535.26	1617
1537.37	1641.5
1539.47	1603
1541.57	1597
1543.67	1602
1545.78	1624
1547.88	1635.5
1549.98	1602
1552.07	1586.5
1554.17	1600.5
1556.27	1585
1558.37	1602.5
1560.47	1578.5
1562.56	1555
1564.66	1575.5
1566.75	1571.5
1568.85	1569.5
1570.94	1575
1573.03	1578
1575.12	1564.5
1577.21	1597
1579.31	1592
1581.4	1604.5
1583.49	1586
1585.57	1599
1587.66	1606.5
1589.75	1616
1591.84	1599
1593.92	1598.5
1596.01	1610
1598.09	1569.5
1600.18	1584
1602.26	1562.5
1604.34	1519
1606.43	1511
1608.51	1499.5
1610.59	1463
1612.67	1438.5
1614.75	1409
1616.83	1397.5
1618.91	1383.5
1620.98	1371.5
1623.06	1333
1625.14	1329.5
1627.21	1298
1629.29	1290
1631.36	1244.5
1633.43	1239.5
1635.51	1234.5
1637.58	1216.5
1639.65	1199.5
1641.72	1210.5
1643.79	1160
1645.86	1176.5
1647.93	1126.5
1650	1147.5
1652.07	1130
1654.14	1113.5
1656.2	1130
1658.27	1107
1660.34	1090.5
1662.4	1088
1664.46	1069
1666.53	1077
1668.59	1061
1670.65	1055.5
1672.71	1050.5
1674.77	1030.5
1676.83	1030
1678.89	1035
1680.95	1036
1683.01	1021.5
1685.07	1011
1687.13	1004.5
1689.18	1004
1691.24	996
1693.29	998.5
1695.35	1005
1697.4	987.5
1699.45	989.5
1701.51	971
1703.56	979.5
1705.61	946
1707.66	963
1709.71	936
1711.76	954.5
1713.81	952
1715.86	920
1717.9	938.5
1719.95	940.5
1722	933.5
1724.04	935
1726.09	930.5
1728.13	937.5
1730.17	923
1732.22	923
1734.26	909.5
1736.3	897.5
1738.34	883
1740.38	903
1742.42	894.5
1744.46	898
1746.5	895
1748.54	886
1750.57	892
1752.61	890.5
1754.65	874
1756.68	865
1758.72	858
1760.75	863.5
1762.78	864
1764.82	877.5
1766.85	866
1768.88	846
1770.91	848
1772.94	851.5
1774.97	827
1777	838
1779.03	830.5
1781.06	833.5
1783.08	822.5
1785.11	852
1787.14	814
1789.16	827
1791.18	814
1793.21	811.5
1795.23	819
1797.26	817
1799.28	814.5
1801.3	816
1803.32	805
1805.34	784
1807.36	795
1809.38	816
1811.4	776
1813.41	807
1815.43	784
1817.45	795
1819.46	777
1821.48	782.5
1823.49	757
1825.51	773.5
1827.52	775.5
1829.53	768.5
1831.54	774.5
1833.56	768
1835.57	759
1837.58	746.5
1839.59	755
1841.59	746
1843.6	736
1845.61	759
1847.62	732.5
1849.62	735.5
1851.63	750.5
1853.64	739
1855.64	724
1857.64	736.5
1859.65	738
1861.65	734.5
1863.65	728
1865.65	735.5
1867.65	694
1869.65	715.5
1871.65	725
1873.65	705.5
1875.65	719
1877.65	710.5
1879.65	716
1881.64	700.5
1883.64	719
1885.63	712.5
1887.63	689
1889.62	704.5
1891.62	693
1893.61	700.5
1895.6	696
1897.59	701
1899.58	694
1901.57	702.5
1903.56	688
1905.55	697.5
1907.54	696
1909.53	683
1911.52	681.5
1913.5	671.5
1915.49	672
1917.48	685
1919.46	690.5
1921.44	685
1923.43	674
1925.41	669.5
1927.39	674
1929.38	668.5
1931.36	637.5
1933.34	655
1935.32	650
1937.3	668
1939.28	668.5
1941.25	656
1943.23	654
1945.21	651.5
1947.18	654
1949.16	641.5
1951.13	650
1953.11	651
1955.08	648
1957.06	633
1959.03	652
1961	649
1962.97	657
1964.94	644
1966.91	642.5
1968.88	658
1970.85	625
1972.82	630
1974.79	631
1976.76	626.5
1978.72	623.5
1980.69	636
1982.65	615
1984.62	607.5
1986.58	631.5
1988.55	623
1990.51	610.5
1992.47	603.5
1994.43	634
1996.39	626.5
1998.36	609
2000.31	621.5
2002.27	599.5
2004.23	613.5
2006.19	616
2008.15	608.5
2010.11	598.5
2012.06	595.5
2014.02	615.5
2015.97	614
2017.93	582.5
2019.88	608
2021.83	606
2023.79	604
2025.74	605.5
2027.69	601.5
2029.64	604.5
2031.59	593
2033.54	592.5
2035.49	588.5
2037.44	596.5
2039.39	599.5
2041.34	579
2043.28	578.5
2045.23	583.5
2047.17	587.5
2049.12	576.5
2051.06	572.5
2053.01	576
2054.95	577.5
2056.89	579.5
2058.84	583
2060.78	583.5
2062.72	574
2064.66	569.5
2066.6	582.5
2068.54	573
2070.48	572
2072.41	569.5
2074.35	572
2076.29	568
2078.22	560
2080.16	555
2082.09	564
2084.03	551
2085.96	554.5
2087.9	565
2089.83	544.5
2091.76	563.5
2093.69	550.5
2095.62	558
2097.55	554
2099.48	549
2101.41	576.5
2103.34	573
2105.27	572.5
2107.19	572.5
2109.12	583.5
2111.05	590.5
2112.97	598
2114.9	594.5
2116.82	603.5
2118.75	613
2120.67	635.5
2122.59	638
2124.51	651
2126.43	674
2128.36	668.5
2130.28	672.5
2132.2	653.5
2134.11	690
2136.03	696.5
2137.95	697.5
2139.87	682.5
2141.78	688.5
2143.7	709
2145.62	686.816
2147.53	736.258
2149.45	709.818
2151.36	749.901
2153.27	727.426
2155.19	740.66
2157.1	738.898
2159.01	764.341
2160.92	754.428
2162.83	765.683
2164.74	769.769
2166.65	753.573
2168.56	751.601
2170.47	730.028
2172.37	737.566
2174.28	727.053
2176.19	720.62
2178.09	711.129
2180	710.105
2181.9	706.924
2183.81	690.668
2185.71	669.544
2187.61	663.748
2189.51	629.906
2191.42	616.483
2193.32	594.153
2195.22	583.956
2197.12	565.314
2199.02	545.847
2200.92	525.213
2202.81	510.17
2204.71	512.363
2206.61	511.247
2208.5	498.148
2210.4	489.103
2212.3	494.18
2214.19	478.078
2216.08	478.76
2217.98	470.903
2219.87	472.822
2221.76	475.026
2223.65	474.795
2225.55	481.265
2227.44	477.772
2229.33	476.574
2231.22	473.71
2233.11	465.913
2234.99	467.987
2236.88	472.055
2238.77	472.49
2240.66	475.226
2242.06	486
2243.96	498
2245.85	491.5
2247.75	495
2249.64	484
2251.54	497.5
2253.43	475.5
2255.32	469.5
2257.21	458.5
2259.1	468
2260.99	456.5
2262.89	456.5
2264.77	463
2266.66	460
2268.55	434
2270.44	427.5
2272.33	440.5
2274.21	447
2276.1	434
2277.98	427.5
2279.87	423.5
2281.75	430
2283.64	434
2285.52	420
2287.4	431
2289.29	433
2291.17	420.5
2293.05	433
2294.93	416
2296.81	426.5
2298.69	424
2300.57	414
2302.44	420
2304.32	414
2306.2	420
2308.08	432
2309.95	414
2311.83	406
2313.7	407
2315.58	414.5
2317.45	409
2319.32	421
2321.2	406.5
2323.07	421.5
2324.94	412
2326.81	396
2328.68	405
2330.55	413
2332.42	404.5
2334.29	403
2336.16	415
2338.02	408
2339.89	395
2341.76	401
2343.62	390
2345.49	397
2347.35	405
2349.22	404.5
2351.08	393
2352.94	398
2354.81	404.5
2356.67	407.5
2358.53	403
2360.39	402.5
2362.25	402
2364.11	390
2365.97	403
2367.83	399.5
2369.69	385
2371.55	392
2373.4	388
2375.26	390
2377.11	388.5
2378.97	395.5
2380.83	387.5
2382.68	396.5
2384.53	384
2386.39	372
2388.24	389
2390.09	377
2391.94	383
2393.79	382.5
2395.64	385
2397.49	387.5
2399.34	371
2401.19	376
2403.04	369.5
2404.89	377.5
2406.74	379
2408.58	369
2410.43	380
2412.27	376
2414.12	369.5
2415.96	369.5
2417.81	363
2419.65	369
2421.49	377
2423.34	366
2425.18	372
2427.02	368
2428.86	358.5
2430.7	361
2432.54	358
2434.38	364
2436.22	353.5
2438.05	363.5
2439.89	365
2441.73	363
2443.56	368.5
2445.4	365
2447.24	358
2449.07	363
2450.9	353
2452.74	352
2454.57	352
2456.4	365
2458.23	357.5
2460.07	356
2461.9	354
2463.73	354
2465.56	351.5
2467.39	352.5
2469.21	350
2471.04	360.5
2472.87	351
2474.7	336
2476.52	353
2478.35	352.5
2480.17	333.5
2482	338
2483.82	350
2485.65	345
2487.47	329
2489.29	351.5
2491.12	340
2492.94	342.5
2494.76	345
2496.58	334
2498.4	345
2500.22	339
2502.04	325
2503.86	338
2505.67	335.5
2507.49	331.5
2509.31	327.5
2511.12	327.5
2512.94	336.5
2514.76	331
2516.57	332.5
2518.38	330.5
2520.2	327.5
2522.01	330.5
2523.82	322.5
2525.64	329
2527.45	327
2529.26	342
2531.07	334.5
2532.88	329.5
2534.69	331
2536.5	325.5
2538.31	319
2540.11	312.5
2541.92	319
2543.73	338
2545.53	318
2547.34	318
2549.14	321
2550.95	312
2552.75	329
2554.56	314
2556.36	321.5
2558.16	312
2559.96	318
2561.76	318.5
2563.57	311
2565.37	315
2567.17	311
2568.96	317
2570.76	315
2572.56	306
2574.36	314
2576.16	309
2577.95	309.5
2579.75	311
2581.54	311
2583.34	303
2585.13	297
2586.93	297
2588.72	302.5
2590.51	304.5
2592.31	304.5
2594.1	303
2595.89	312
2597.68	306
2599.47	289.5
2601.26	302
2603.05	290.5
2604.84	307
2606.63	301
2608.42	311
2610.2	313
2611.99	299
2613.78	296
2615.56	295
2617.35	293
2619.13	300
2620.91	297
2622.7	298.5
2624.48	302.5
2626.26	292.5
2628.04	300
2629.83	284.5
2631.61	279
2633.39	297
2635.17	287
2636.95	282
2638.73	292
2640.5	291
2642.28	284.5
2644.06	293
2645.84	277.5
2647.61	282.5
2649.39	289
2651.16	279
2652.94	287.5
2654.71	277.5
2656.49	278.5
2658.26	291.5
2660.03	285
2661.8	288
2663.57	281.5
2665.35	284
2667.12	267.5
2668.89	287
2670.66	276
2672.42	273
2674.19	281.5
2675.96	269
2677.73	274
2679.49	274
2681.26	272.5
2683.03	266.5
2684.79	263
2686.56	280
2688.32	279.5
2690.09	273
2691.85	272.5
2693.61	272
2695.37	272
2697.14	267
2698.9	271.5
2700.66	280
2702.42	268
2704.18	268
2705.94	277.5
2707.7	269
2709.45	258
2711.21	263.5
2712.97	269
2714.72	273
2716.48	266
2718.24	265
2719.99	265
2721.75	269.5
2723.5	267
2725.25	268
2727.01	268
2728.76	267
2730.51	264
2732.26	257
2734.01	269.5
2735.76	274
2737.51	260
2739.26	248.5
2741.01	259
2742.76	257.5
2744.51	265
2746.26	262
2748	267
2749.75	258
2751.5	257.5
2753.24	250
2754.99	244
2756.73	256
2758.47	249.5
2760.22	252
2761.96	257
2763.7	255.5
2765.44	249.5
2767.19	252
2768.93	249.5
2770.67	251.5
2772.41	241
2774.15	257
2775.89	240
2777.62	245.5
2779.36	247.5
2781.1	254.5
2782.84	241
2784.57	240.5
2786.31	248.5
2788.04	246
2789.78	239
2791.51	245
2793.24	237
2794.98	249.5
2796.71	241
2798.44	242.5
2800.18	251
2801.91	243.5
2803.64	236.75
2805.37	233
2807.1	239
2808.83	233
2810.55	236.5
2812.28	241.5
2814.01	227
2815.74	236
2817.46	242.5
2819.19	236
2820.92	243.5
2822.64	229
2824.37	231
2826.09	233
2827.81	236
2829.54	235.5
2831.26	233
2832.98	237.5
2834.71	237.5
2836.43	235
2838.15	234
2839.87	235
2841.59	237
2843.31	237.5
2845.02	232
2846.74	238.5
2848.46	244.5
2850.18	235
2851.9	242.5
2853.61	251
2855.33	240
2857.04	240.5
2858.76	232.5
2860.47	244.5
2862.19	232.5
2863.9	243
2865.61	240
2867.32	229
2869.04	239
2870.75	237
2872.46	246
2874.17	241
2875.88	240.5
2877.59	238.5
2879.3	243
2881	250
2882.71	235
2884.42	245.5
2886.13	237.5
2887.83	232.5
2889.54	235.5
2891.24	253
2892.95	234
2894.65	232.5
2896.36	239
2898.06	244
2899.76	245
2901.47	246.5
2903.17	237.5
2904.87	235.5
2906.57	240
2908.27	249
2909.97	246
2911.67	250.5
2913.37	242.5
2915.07	246.5
2916.77	239.5
2918.47	249.5
2920.16	244.5
2921.86	267
2923.55	254
2925.25	251
2926.94	257
2928.64	255
2930.33	253.5
2932.03	263.5
2933.72	246.5
2935.41	260
2937.11	247
2938.8	246.5
2940.49	260
2942.18	254
2943.87	254
2945.56	253
2947.25	234.5
2948.94	235.5
2950.63	235
2952.31	235
2954	235
2955.69	224
2957.37	216.5
2959.06	211
2960.75	218.5
2962.43	228
2964.11	227
2965.8	213.5
2967.48	221
2969.16	215.5
2970.85	214.5
2972.53	211
2974.21	216
2975.89	207
2977.57	205.5
2979.25	215
2980.93	212.5
2982.61	208
2984.29	206.5
2985.97	212.5
2987.65	196.5
2989.32	194.5
2991	199
2992.68	200.5
2994.35	195
2996.03	200.5
2997.7	179.5
2999.38	196