File: muestras/ogompa/nsno_14.txt
#Acq. time (s)=	5
#Accumulations=	5
#Range (cm-¹)=	100...3000
#Windows=	3
#Autofocus=	Off
#AutoExposure=	Off
#Spike filter=	Multiple accum.
#Delay time (s)=	0
#Binning=	1
#Readout mode=	Signal
#DeNoise=	Off
#ICS correction=	Off
#Dark correction=	Off
#Inst. Process=	Off
#Instrument=	LabRAM HR Evol
#Detector=	Syncerity OE
#Objective=	x100_VIS_LWD
#Grating=	600 (500nm)
#ND Filter=	100%
#Laser=	633nm_Edge
#Hole=	100.021
#Range=	Visible
#Project=	Omar
#Sample=	chi
#Site=	f
#Title=	nsno
#Remark=
#Date=	12.09.2023 17:25
#Acquired=	12.09.2023 17:25:13
101.026	3201.5
103.592	3110.5
106.158	3084.5
108.723	3041.5
111.289	2966
113.852	2928
116.415	2895
118.976	2900
121.537	2865.5
124.097	2818.5
126.656	2745
129.215	2729
131.772	2696
134.327	2699.5
136.883	2605
139.438	2579
141.992	2579.5
144.545	2518.5
147.096	2485
149.648	2454
152.199	2430.5
154.747	2393
157.296	2338
159.843	2325.5
162.391	2348.5
164.937	2278.5
167.482	2266.5
170.025	2250
172.569	2286
175.111	2257
177.654	2263
180.194	2191
182.733	2232
185.273	2182
187.811	2212.5
190.348	2218.5
192.884	2225.5
195.419	2209.5
197.955	2244
200.489	2248
203.022	2275.5
205.554	2274
208.085	2268
210.615	2260.5
213.144	2272
215.673	2263
218.201	2246
220.728	2261
223.253	2261
225.778	2279
228.303	2258.5
230.826	2285.5
233.348	2279
235.87	2298
238.391	2283
240.91	2305.5
243.43	2332.5
245.949	2315.5
248.465	2320
250.983	2329
253.498	2293
256.013	2337
258.526	2335
261.039	2341.5
263.552	2333.5
266.063	2305
268.573	2313
271.084	2320.5
273.592	2332
276.1	2309
278.607	2289.5
281.113	2285.5
283.619	2311
286.124	2269.5
288.627	2291
291.13	2326
293.632	2330.5
296.133	2340.5
298.634	2360
301.133	2359.5
303.63	2356.5
306.128	2350
308.625	2366.5
311.122	2407
313.617	2344
316.111	2358.5
318.604	2322
321.098	2339.5
323.588	2329.5
326.08	2315.5
328.569	2311.5
331.059	2292
333.548	2291.5
336.035	2269.5
338.521	2294
341.008	2228
343.492	2258.5
345.977	2262
348.46	2255.5
350.942	2267.5
353.425	2267
355.905	2297
358.385	2271
360.864	2278
363.342	2319.5
365.819	2277.5
368.296	2290
370.771	2295
373.246	2281
375.72	2240.5
378.194	2248
380.666	2226
383.138	2210.5
385.609	2241.5
388.079	2248
390.548	2231
393.016	2220
395.483	2264.5
397.95	2237.5
400.416	2271
402.88	2273.5
405.345	2276
407.807	2283
410.27	2295.5
412.731	2280.5
415.193	2322
417.652	2301.5
420.112	2327
422.569	2327
425.028	2350
427.484	2307
429.939	2369
432.394	2351
434.849	2347.5
437.302	2353
439.754	2389
442.205	2331
444.656	2371.5
447.106	2336.5
449.555	2356
452.003	2369.5
454.45	2347
456.897	2340
459.343	2318
461.788	2395.5
464.232	2339.5
466.676	2345
469.119	2345
471.559	2340
474.001	2334.5
476.441	2362.5
478.879	2386.5
481.318	2363
483.756	2373.5
486.192	2343
488.629	2376.5
491.063	2388
493.498	2406
495.931	2402
498.365	2369
500.796	2409.5
503.226	2429.5
505.657	2426
508.086	2407.5
510.515	2408
512.942	2440
515.369	2430.5
517.796	2399.5
520.221	2400.5
522.645	2402
525.069	2402.5
527.492	2421
529.914	2431
532.335	2372
534.756	2386.5
537.175	2347.5
539.593	2424.5
542.011	2396.5
544.429	2423
546.845	2434.5
549.261	2421
551.675	2415.5
554.089	2393.5
556.503	2406
558.914	2413.5
561.326	2423
563.736	2388.5
566.147	2424.5
568.555	2409
570.964	2423
573.371	2475.5
575.777	2410.5
578.184	2424.5
580.588	2435
582.992	2450
585.395	2421.5
587.799	2439
590.201	2447.5
592.601	2432
595.001	2435.5
597.401	2430
599.799	2453
602.197	2453.5
604.594	2424
606.99	2467.5
609.386	2468
611.78	2448.5
614.174	2484.5
616.566	2483.5
618.958	2488.5
621.35	2516
623.741	2500.5
626.13	2488.5
628.519	2494.5
630.908	2497.5
633.295	2535.5
635.682	2573.5
638.067	2547
640.453	2564
642.836	2556
645.219	2556
647.602	2565
649.984	2564
652.364	2551.5
654.745	2531.5
657.124	2537
659.503	2543.5
661.88	2534
664.257	2497.5
666.635	2488.5
669.01	2511.5
671.384	2514
673.758	2508
676.131	2522.5
678.502	2460.5
680.874	2468
683.245	2466.5
685.615	2511.5
687.984	2486
690.353	2502
692.719	2501
695.086	2475
697.453	2500.5
699.817	2480.5
702.182	2465
704.545	2476.5
706.908	2467.5
709.27	2481.5
711.632	2485
713.991	2466.5
716.352	2469
718.71	2471
721.068	2444.5
723.426	2468.5
725.782	2517
728.138	2493.5
730.492	2480.5
732.846	2474.5
735.201	2504
737.553	2488
739.905	2485
742.256	2472
744.606	2477
746.956	2491
749.303	2497.5
751.651	2430.5
753.999	2474
756.345	2448.5
758.691	2467
761.035	2485.5
763.379	2494.5
765.723	2446.5
768.064	2470.5
770.407	2467.5
772.748	2472.5
775.088	2441
777.427	2463
779.765	2468.5
782.104	2474
784.44	2485
786.776	2482
789.113	2445
791.447	2439
793.78	2448.5
796.113	2441.5
798.445	2469.5
800.778	2495
803.109	2465
805.439	2496
807.768	2471.5
810.096	2521
812.424	2497
814.751	2505
817.078	2530
819.402	2532
821.727	2530
824.051	2499
826.374	2521.5
828.697	2510
831.018	2533
833.339	2526.5
835.659	2547
837.978	2568
840.297	2575
842.614	2536
844.932	2541
847.247	2534
849.562	2558
851.878	2546
854.191	2548.5
856.504	2599.5
858.817	2592.5
861.129	2552
863.439	2565
865.749	2515.5
868.058	2537
870.367	2559.5
872.676	2492.5
874.983	2521
877.289	2447
879.593	2493
881.898	2485
884.202	2481.5
886.506	2483.5
888.808	2456.5
891.11	2413
893.41	2431.5
895.711	2466
898.011	2443
900.309	2435.5
902.607	2428
904.904	2413
907.201	2416.5
909.496	2404
911.791	2409
914.085	2415
916.379	2434.5
918.671	2408.5
920.963	2410.5
923.255	2418
925.545	2385
927.834	2385
930.123	2432
932.411	2419
934.698	2410.5
936.985	2413
939.271	2433
941.556	2426.5
943.84	2421
946.124	2436
948.407	2435
950.689	2412.5
952.971	2439.5
955.25	2442.5
957.531	2476.5
959.81	2453
962.088	2461
964.366	2467
966.643	2446.5
968.919	2475
971.195	2454.5
973.469	2424.5
975.743	2480.5
978.016	2482
980.288	2474.5
982.56	2452.5
984.831	2468
987.101	2422.5
989.37	2453
991.638	2474
993.907	2458.5
996.174	2494
998.44	2533.5
1000.71	2512.5
1002.97	2490
1005.24	2458.5
1007.5	2485
1009.76	2438.5
1012.02	2426.5
1014.28	2471
1016.54	2467.5
1018.8	2460.5
1021.06	2422
1023.32	2456.5
1025.58	2466.5
1027.84	2435.5
1030.09	2447
1032.35	2460
1034.6	2508.5
1036.86	2437.5
1039.11	2455
1041.36	2446.5
1043.61	2460
1045.86	2479
1048.11	2467.5
1050.36	2490
1052.61	2452
1054.86	2456.5
1057.11	2462.5
1059.35	2437.5
1061.6	2469.5
1063.84	2465
1066.09	2468
1068.33	2459.5
1070.57	2441
1072.82	2462
1075.06	2460
1077.3	2500.5
1079.54	2481.5
1081.78	2465.5
1084.02	2467.5
1086.25	2429
1088.49	2434.5
1090.73	2435
1092.96	2443.5
1095.2	2393.5
1097.43	2448.5
1099.66	2398
1101.9	2437.5
1104.13	2412
1106.36	2439
1108.59	2428
1110.82	2432
1113.05	2438
1115.28	2446.5
1117.51	2444.5
1119.73	2394
1121.96	2438
1124.18	2463
1126.41	2439.5
1128.63	2454.5
1130.85	2452
1133.08	2428
1135.3	2466
1137.52	2476.5
1139.74	2515.5
1141.96	2479.5
1144.18	2500
1146.4	2512.5
1148.61	2555.5
1150.83	2534
1153.05	2561
1155.26	2537.5
1157.48	2545
1159.69	2570.5
1161.9	2571.5
1164.11	2636.5
1166.33	2621
1168.54	2607
1170.75	2623.5
1172.96	2605.5
1175.17	2623.5
1177.37	2622
1179.58	2587
1181.79	2553.5
1183.99	2564.5
1186.2	2567.5
1188.4	2537.5
1190.61	2543.5
1192.81	2526
1195.01	2544.5
1197.21	2523.31
1199.42	2563.9
1201.61	2548.1
1203.81	2533.81
1206.01	2528.48
1208.21	2522.5
1210.41	2504.8
1212.61	2526.23
1214.8	2513.64
1217	2528.4
1219.19	2490.51
1221.38	2503.04
1223.58	2518.16
1225.77	2500.65
1227.96	2489.46
1230.15	2522.05
1232.34	2516.99
1234.53	2513.02
1236.72	2517.7
1238.91	2524.21
1241.1	2511.12
1243.28	2523.94
1245.47	2533.31
1247.65	2518.57
1249.84	2539.26
1252.02	2560.24
1254.21	2558.84
1256.39	2559.5
1258.57	2547.19
1260.75	2574.21
1262.93	2573.98
1265.11	2580.92
1267.29	2578.58
1269.47	2586.1
1271.65	2564.75
1273.82	2558.29
1276	2566.29
1278.17	2578.8
1280.35	2592.83
1282.52	2559.11
1284.69	2562.73
1286.87	2593.15
1289.04	2564.05
1291.21	2562.02
1293.38	2555.96
1295.55	2570.47
1297.72	2579.69
1299.89	2554.35
1302.06	2560.07
1304.22	2574.97
1306.39	2542.79
1308.43	2561.5
1310.6	2570.5
1312.78	2570
1314.96	2557
1317.13	2518.5
1319.3	2513.5
1321.47	2516
1323.65	2542.5
1325.82	2508
1327.99	2530
1330.16	2511.5
1332.32	2526.5
1334.49	2522.5
1336.66	2535
1338.83	2504.5
1340.99	2484.5
1343.16	2472
1345.32	2467
1347.49	2460.5
1349.65	2426.5
1351.81	2419
1353.98	2469.5
1356.14	2436
1358.3	2430.5
1360.46	2410.5
1362.62	2438
1364.78	2380
1366.93	2421
1369.09	2415
1371.25	2414
1373.4	2408.5
1375.56	2385
1377.71	2379
1379.87	2401
1382.02	2374.5
1384.17	2377.5
1386.32	2362.5
1388.47	2375
1390.63	2374.5
1392.77	2347
1394.92	2351
1397.07	2344
1399.22	2357
1401.37	2375.5
1403.51	2397.5
1405.66	2365.5
1407.8	2362
1409.95	2349
1412.09	2338.5
1414.23	2366.5
1416.38	2375
1418.52	2357
1420.66	2368.5
1422.8	2378
1424.94	2401
1427.08	2369.5
1429.21	2377
1431.35	2384
1433.49	2396
1435.63	2376
1437.76	2385.5
1439.89	2397.5
1442.03	2393
1444.16	2410.5
1446.3	2415
1448.43	2409
1450.56	2406
1452.69	2403
1454.82	2427.5
1456.95	2388
1459.08	2390
1461.2	2382.5
1463.33	2399.5
1465.46	2393.5
1467.58	2387.5
1469.71	2344
1471.83	2425.5
1473.96	2392.5
1476.08	2399
1478.2	2412
1480.33	2379
1482.45	2367
1484.57	2405.5
1486.69	2382
1488.81	2395
1490.93	2374
1493.04	2367.5
1495.16	2398
1497.28	2379.5
1499.39	2414
1501.51	2394
1503.62	2356
1505.74	2397
1507.85	2372
1509.96	2398
1512.07	2413.5
1514.19	2407
1516.3	2411
1518.41	2400.5
1520.52	2382
1522.62	2390.5
1524.73	2400
1526.84	2359.5
1528.95	2412
1531.05	2396
1533.16	2399
1535.26	2395.5
1537.37	2411.5
1539.47	2356.5
1541.57	2387
1543.67	2373.5
1545.78	2419
1547.88	2360
1549.98	2380
1552.07	2414.5
1554.17	2397.5
1556.27	2366.5
1558.37	2408
1560.47	2430.5
1562.56	2405
1564.66	2431
1566.75	2374.5
1568.85	2405.5
1570.94	2351
1573.03	2361
1575.12	2326
1577.21	2351.5
1579.31	2370
1581.4	2370
1583.49	2396
1585.57	2319
1587.66	2323.5
1589.75	2342
1591.84	2376
1593.92	2384.5
1596.01	2358
1598.09	2365
1600.18	2296
1602.26	2296
1604.34	2287
1606.43	2248
1608.51	2228.5
1610.59	2184.5
1612.67	2133.5
1614.75	2092
1616.83	2055.5
1618.91	2041
1620.98	2020.5
1623.06	1994.5
1625.14	1964
1627.21	1920.5
1629.29	1903.5
1631.36	1920
1633.43	1846.5
1635.51	1828
1637.58	1807
1639.65	1781.5
1641.72	1772.5
1643.79	1713.5
1645.86	1729
1647.93	1671
1650	1687
1652.07	1661.5
1654.14	1632
1656.2	1626
1658.27	1599.5
1660.34	1573.5
1662.4	1553
1664.46	1534.5
1666.53	1538.5
1668.59	1529.5
1670.65	1498.5
1672.71	1474.5
1674.77	1494.5
1676.83	1469
1678.89	1474
1680.95	1463
1683.01	1448.5
1685.07	1452
1687.13	1451.5
1689.18	1440
1691.24	1412.5
1693.29	1386.5
1695.35	1380.5
1697.4	1386.5
1699.45	1376.5
1701.51	1385
1703.56	1365.5
1705.61	1364
1707.66	1359.5
1709.71	1354.5
1711.76	1330.5
1713.81	1329
1715.86	1326.5
1717.9	1314
1719.95	1315
1722	1289
1724.04	1298.5
1726.09	1296
1728.13	1311
1730.17	1289.5
1732.22	1295
1734.26	1287
1736.3	1270.5
1738.34	1269.5
1740.38	1255.5
1742.42	1281.5
1744.46	1242.5
1746.5	1242.5
1748.54	1252.5
1750.57	1247.5
1752.61	1221.5
1754.65	1214
1756.68	1228.5
1758.72	1195.5
1760.75	1209.5
1762.78	1211
1764.82	1209
1766.85	1196.5
1768.88	1197
1770.91	1178.5
1772.94	1177.5
1774.97	1169.5
1777	1153.5
1779.03	1137
1781.06	1149
1783.08	1162.5
1785.11	1143
1787.14	1157
1789.16	1138.5
1791.18	1147.5
1793.21	1134.5
1795.23	1104.5
1797.26	1101
1799.28	1118.5
1801.3	1116.5
1803.32	1115
1805.34	1105
1807.36	1120
1809.38	1106.5
1811.4	1091
1813.41	1096
1815.43	1086
1817.45	1075
1819.46	1095
1821.48	1054.5
1823.49	1057.5
1825.51	1087.5
1827.52	1082
1829.53	1069
1831.54	1052
1833.56	1054
1835.57	1026.5
1837.58	1032
1839.59	1029
1841.59	1035
1843.6	1023
1845.61	1020
1847.62	1031
1849.62	1004
1851.63	1005.5
1853.64	1002
1855.64	991.5
1857.64	996
1859.65	1004.5
1861.65	995.5
1863.65	1011.5
1865.65	1003.5
1867.65	987
1869.65	962.5
1871.65	987
1873.65	966
1875.65	985
1877.65	954
1879.65	957.5
1881.64	972
1883.64	943
1885.63	964
1887.63	957
1889.62	951
1891.62	945.5
1893.61	932.5
1895.6	938
1897.59	930.5
1899.58	920
1901.57	922.5
1903.56	958
1905.55	937.5
1907.54	950
1909.53	909
1911.52	931.5
1913.5	920
1915.49	928
1917.48	921
1919.46	915.5
1921.44	922
1923.43	921.5
1925.41	907.5
1927.39	906
1929.38	899.5
1931.36	890
1933.34	906
1935.32	904
1937.3	895.5
1939.28	888
1941.25	880.5
1943.23	897
1945.21	886.5
1947.18	877
1949.16	872.5
1951.13	875
1953.11	860
1955.08	877
1957.06	846
1959.03	865
1961	874.5
1962.97	848
1964.94	849.5
1966.91	863
1968.88	840
1970.85	875
1972.82	848.5
1974.79	835
1976.76	869
1978.72	844.5
1980.69	838
1982.65	839.5
1984.62	843.5
1986.58	824
1988.55	831
1990.51	833
1992.47	839.5
1994.43	835.5
1996.39	834.5
1998.36	797
2000.31	829.5
2002.27	823.5
2004.23	813.5
2006.19	818.5
2008.15	810.5
2010.11	817
2012.06	800.5
2014.02	809
2015.97	813
2017.93	804.5
2019.88	821
2021.83	801
2023.79	805.5
2025.74	785
2027.69	801.5
2029.64	792.5
2031.59	787.5
2033.54	776
2035.49	784
2037.44	783.5
2039.39	780
2041.34	790.5
2043.28	770
2045.23	762
2047.17	761
2049.12	771
2051.06	768
2053.01	764.5
2054.95	768
2056.89	763.5
2058.84	746.5
2060.78	748.5
2062.72	738.5
2064.66	730
2066.6	734.5
2068.54	752
2070.48	757
2072.41	743
2074.35	745
2076.29	743.5
2078.22	741.5
2080.16	722
2082.09	728.5
2084.03	727
2085.96	703
2087.9	715.5
2089.83	732.5
2091.76	704
2093.69	704.5
2095.62	726
2097.55	712
2099.48	713.5
2101.41	717
2103.34	707.5
2105.27	728
2107.19	706
2109.12	712
2111.05	714
2112.97	702.5
2114.9	695.5
2116.82	717.5
2118.75	722
2120.67	731.5
2122.59	715
2124.51	703.5
2126.43	701.5
2128.36	708.5
2130.28	689.5
2132.2	715.5
2134.11	718
2136.03	697.5
2137.95	703
2139.87	698
2141.78	693.5
2143.7	678
2145.62	689.516
2147.53	686.306
2149.45	666.518
2151.36	679.092
2153.27	668.738
2155.19	661.387
2157.1	685.236
2159.01	677.155
2160.92	666.588
2162.83	658.366
2164.74	657.057
2166.65	647.384
2168.56	640.365
2170.47	647.912
2172.37	630.881
2174.28	645.642
2176.19	638.538
2178.09	635.883
2180	634.536
2181.9	626.748
2183.81	629.983
2185.71	620.347
2187.61	619.958
2189.51	614.997
2191.42	619.627
2193.32	626.911
2195.22	617.259
2197.12	597.348
2199.02	609.475
2200.92	617.125
2202.81	613.18
2204.71	615.897
2206.61	615.903
2208.5	617.126
2210.4	610.916
2212.3	607.632
2214.19	613.483
2216.08	607.848
2217.98	601.328
2219.87	615.213
2221.76	616.85
2223.65	607.858
2225.55	609.841
2227.44	611.182
2229.33	607.742
2231.22	608.974
2233.11	608.247
2234.99	606.36
2236.88	612.363
2238.77	616.821
2240.66	616.21
2242.06	625.5
2243.96	630
2245.85	634
2247.75	640.5
2249.64	665
2251.54	645
2253.43	621
2255.32	624
2257.21	594
2259.1	587
2260.99	589.5
2262.89	584
2264.77	564
2266.66	576.5
2268.55	572.5
2270.44	571
2272.33	572
2274.21	557.5
2276.1	554
2277.98	552
2279.87	549
2281.75	535.5
2283.64	559.5
2285.52	557
2287.4	547.5
2289.29	547.5
2291.17	541
2293.05	551
2294.93	529
2296.81	550.5
2298.69	542.5
2300.57	531
2302.44	543.5
2304.32	544
2306.2	531.5
2308.08	532
2309.95	533
2311.83	517
2313.7	543.5
2315.58	530
2317.45	524
2319.32	508
2321.2	520.5
2323.07	521
2324.94	533
2326.81	510
2328.68	513.5
2330.55	510
2332.42	527.5
2334.29	522
2336.16	511
2338.02	513.5
2339.89	520
2341.76	509.5
2343.62	516
2345.49	512
2347.35	511
2349.22	493
2351.08	503.5
2352.94	489
2354.81	509
2356.67	496.5
2358.53	498
2360.39	500.5
2362.25	488.5
2364.11	495
2365.97	503
2367.83	493.5
2369.69	478.5
2371.55	479
2373.4	487
2375.26	472.5
2377.11	484
2378.97	488.5
2380.83	479.5
2382.68	484
2384.53	503
2386.39	501.5
2388.24	475
2390.09	487.5
2391.94	475.5
2393.79	477
2395.64	468
2397.49	483
2399.34	470
2401.19	483
2403.04	486.5
2404.89	479.5
2406.74	474.5
2408.58	469
2410.43	470
2412.27	486.5
2414.12	479
2415.96	459
2417.81	473.5
2419.65	459
2421.49	461
2423.34	470.5
2425.18	467.5
2427.02	457
2428.86	472
2430.7	461.5
2432.54	450
2434.38	452
2436.22	447.5
2438.05	443
2439.89	460
2441.73	464
2443.56	447.5
2445.4	454.5
2447.24	455
2449.07	440.5
2450.9	457
2452.74	449
2454.57	449
2456.4	444
2458.23	451
2460.07	450
2461.9	449
2463.73	435
2465.56	444.5
2467.39	446
2469.21	425
2471.04	436.5
2472.87	447
2474.7	438.5
2476.52	430
2478.35	439
2480.17	442
2482	434.5
2483.82	443.5
2485.65	427.5
2487.47	442.5
2489.29	423
2491.12	425
2492.94	429
2494.76	426
2496.58	424
2498.4	422.5
2500.22	442.5
2502.04	428.5
2503.86	430.5
2505.67	418
2507.49	417.5
2509.31	410
2511.12	407.5
2512.94	426
2514.76	419
2516.57	419
2518.38	413
2520.2	409.5
2522.01	400.5
2523.82	402.5
2525.64	418
2527.45	408.5
2529.26	405.5
2531.07	412
2532.88	411.5
2534.69	416
2536.5	401
2538.31	396
2540.11	400
2541.92	410.5
2543.73	394.5
2545.53	401
2547.34	400.5
2549.14	415
2550.95	400.5
2552.75	405.5
2554.56	400
2556.36	386
2558.16	404
2559.96	398
2561.76	395.5
2563.57	395
2565.37	392.5
2567.17	393
2568.96	383
2570.76	390
2572.56	394
2574.36	382
2576.16	392
2577.95	376.5
2579.75	376
2581.54	384
2583.34	385.5
2585.13	372.5
2586.93	377
2588.72	375.5
2590.51	374
2592.31	381.5
2594.1	380.5
2595.89	378
2597.68	383.5
2599.47	376
2601.26	377
2603.05	374
2604.84	372
2606.63	364
2608.42	379
2610.2	379.5
2611.99	363
2613.78	375
2615.56	367
2617.35	372
2619.13	382.5
2620.91	370
2622.7	366
2624.48	379
2626.26	376
2628.04	353
2629.83	357
2631.61	370
2633.39	356.5
2635.17	347
2636.95	358.5
2638.73	342
2640.5	347.5
2642.28	356
2644.06	341
2645.84	347.5
2647.61	342.5
2649.39	350.5
2651.16	361.5
2652.94	356.5
2654.71	351
2656.49	350.5
2658.26	352
2660.03	346
2661.8	336
2663.57	354.5
2665.35	343
2667.12	350
2668.89	350.5
2670.66	347.5
2672.42	328
2674.19	334.5
2675.96	341.5
2677.73	347
2679.49	331
2681.26	335.5
2683.03	338
2684.79	335
2686.56	335
2688.32	327.5
2690.09	334
2691.85	331.5
2693.61	326.5
2695.37	340.5
2697.14	333.5
2698.9	337
2700.66	333
2702.42	333
2704.18	314
2705.94	345
2707.7	334
2709.45	336
2711.21	337
2712.97	325.5
2714.72	315.5
2716.48	327.5
2718.24	335
2719.99	313
2721.75	329.5
2723.5	325.5
2725.25	328
2727.01	329.5
2728.76	319.5
2730.51	331.5
2732.26	308.5
2734.01	322.5
2735.76	321.5
2737.51	333
2739.26	325.5
2741.01	317
2742.76	319.5
2744.51	309
2746.26	318
2748	305.5
2749.75	318.5
2751.5	303
2753.24	310
2754.99	318.5
2756.73	317.5
2758.47	300.5
2760.22	311.5
2761.96	313
2763.7	298.5
2765.44	308.5
2767.19	308
2768.93	295
2770.67	303
2772.41	306.5
2774.15	301.5
2775.89	301
2777.62	304
2779.36	296.5
2781.1	299
2782.84	305
2784.57	300.5
2786.31	287.5
2788.04	298
2789.78	292
2791.51	299.5
2793.24	296
2794.98	279.5
2796.71	289.5
2798.44	289
2800.18	268
2801.91	290.5
2803.64	291.25
2805.37	283
2807.1	287
2808.83	299
2810.55	285.5
2812.28	282.5
2814.01	283.5
2815.74	279.5
2817.46	291
2819.19	272.5
2820.92	294
2822.64	274
2824.37	285
2826.09	278
2827.81	284
2829.54	278.5
2831.26	281.5
2832.98	285
2834.71	294.5
2836.43	287.5
2838.15	283.5
2839.87	274
2841.59	272
2843.31	275
2845.02	283.5
2846.74	279
2848.46	284.5
2850.18	289
2851.9	281.5
2853.61	294
2855.33	279.5
2857.04	274.5
2858.76	277
2860.47	282.5
2862.19	299
2863.9	281.5
2865.61	284
2867.32	281.5
2869.04	280
2870.75	274.5
2872.46	288.5
2874.17	298
2875.88	291.5
2877.59	295.5
2879.3	290
2881	277.5
2882.71	280
2884.42	279
2886.13	287.5
2887.83	278.5
2889.54	280.5
2891.24	288
2892.95	291.5
2894.65	291
2896.36	289.5
2898.06	282
2899.76	280
2901.47	291
2903.17	290
2904.87	290
2906.57	288
2908.27	285.5
2909.97	297
2911.67	290
2913.37	281.5
2915.07	289
2916.77	288
2918.47	285.5
2920.16	285
2921.86	303.5
2923.55	299
2925.25	298
2926.94	309.5
2928.64	317.5
2930.33	305.5
2932.03	300
2933.72	296
2935.41	309
2937.11	312.5
2938.8	313
2940.49	302.5
2942.18	300.5
2943.87	298
2945.56	289
2947.25	280
2948.94	284.5
2950.63	288
2952.31	278
2954	287
2955.69	269
2957.37	267.5
2959.06	276
2960.75	270.5
2962.43	263
2964.11	252
2965.8	258
2967.48	270
2969.16	276
2970.85	268
2972.53	266.5
2974.21	249.5
2975.89	258.5
2977.57	252.5
2979.25	249.5
2980.93	262.5
2982.61	252
2984.29	243
2985.97	248
2987.65	240
2989.32	250
2991	227
2992.68	233
2994.35	238.5
2996.03	233
2997.7	227.5
2999.38	232