File: muestras/ogompa/nsno_11.txt
#Acq. time (s)=	5
#Accumulations=	5
#Range (cm-¹)=	100...3000
#Windows=	3
#Autofocus=	Off
#AutoExposure=	Off
#Spike filter=	Multiple accum.
#Delay time (s)=	0
#Binning=	1
#Readout mode=	Signal
#DeNoise=	Off
#ICS correction=	Off
#Dark correction=	Off
#Inst. Process=	Off
#Instrument=	LabRAM HR Evol
#Detector=	Syncerity OE
#Objective=	x100_VIS_LWD
#Grating=	600 (500nm)
#ND Filter=	100%
#Laser=	633nm_Edge
#Hole=	100.021
#Range=	Visible
#Project=	Omar
#Sample=	chi
#Site=	f
#Title=	nsno
#Remark=
#Date=	12.09.2023 17:16
#Acquired=	12.09.2023 17:16:33
101.026	2152
103.592	2133.5
106.158	2079
108.723	2041.5
111.289	2024.5
113.852	1998
116.415	1940.5
118.976	1915.5
121.537	1900
124.097	1908
126.656	1890.5
129.215	1878
131.772	1842.5
134.327	1822.5
136.883	1785.5
139.438	1770
141.992	1696
144.545	1742
147.096	1688.5
149.648	1679
152.199	1619.5
154.747	1588.5
157.296	1577.5
159.843	1563
162.391	1554.5
164.937	1565.5
167.482	1562
170.025	1516
172.569	1494
175.111	1504.5
177.654	1471
180.194	1482
182.733	1471.5
185.273	1460
187.811	1490.5
190.348	1479.5
192.884	1477
195.419	1493
197.955	1481.5
200.489	1507.5
203.022	1489.5
205.554	1497.5
208.085	1510.5
210.615	1483.5
213.144	1497.5
215.673	1506
218.201	1502.5
220.728	1529
223.253	1527
225.778	1521
228.303	1510.5
230.826	1516
233.348	1533.5
235.87	1526.5
238.391	1564
240.91	1568
243.43	1566.5
245.949	1554
248.465	1566
250.983	1568.5
253.498	1572
256.013	1557.5
258.526	1565
261.039	1580.5
263.552	1553.5
266.063	1541.5
268.573	1578.5
271.084	1573
273.592	1580.5
276.1	1564.5
278.607	1572
281.113	1566.5
283.619	1588.5
286.124	1585.5
288.627	1626
291.13	1625
293.632	1621
296.133	1615
298.634	1631.5
301.133	1621.5
303.63	1637
306.128	1628.5
308.625	1639
311.122	1645.5
313.617	1629.5
316.111	1597.5
318.604	1649.5
321.098	1629.5
323.588	1609
326.08	1605
328.569	1582.5
331.059	1580.5
333.548	1575.5
336.035	1550
338.521	1565.5
341.008	1561.5
343.492	1542.5
345.977	1561
348.46	1552.5
350.942	1557
353.425	1577
355.905	1565
358.385	1545.5
360.864	1529.5
363.342	1544.5
365.819	1564.5
368.296	1536.5
370.771	1548.5
373.246	1541.5
375.72	1554.5
378.194	1545.5
380.666	1544.5
383.138	1560
385.609	1517.5
388.079	1550.5
390.548	1548
393.016	1542
395.483	1565.5
397.95	1561
400.416	1531
402.88	1569
405.345	1565
407.807	1586.5
410.27	1615.5
412.731	1586
415.193	1607
417.652	1592
420.112	1627
422.569	1575
425.028	1626
427.484	1627
429.939	1639
432.394	1647.5
434.849	1611
437.302	1628
439.754	1636
442.205	1663.5
444.656	1649
447.106	1649.5
449.555	1614.5
452.003	1651
454.45	1639.5
456.897	1644.5
459.343	1651
461.788	1643
464.232	1627.5
466.676	1642.5
469.119	1630.5
471.559	1639
474.001	1663.5
476.441	1658
478.879	1632
481.318	1634
483.756	1667
486.192	1667.5
488.629	1686.5
491.063	1666
493.498	1677.5
495.931	1689
498.365	1697.5
500.796	1678.5
503.226	1704
505.657	1700.5
508.086	1669.5
510.515	1683
512.942	1695
515.369	1678
517.796	1670
520.221	1702.5
522.645	1682.5
525.069	1685
527.492	1686.5
529.914	1687
532.335	1689
534.756	1678.5
537.175	1663.5
539.593	1655
542.011	1658.5
544.429	1683
546.845	1685
549.261	1669
551.675	1671.5
554.089	1681.5
556.503	1668.5
558.914	1685
561.326	1651.5
563.736	1671
566.147	1665
568.555	1664.5
570.964	1676
573.371	1677.5
575.777	1669.5
578.184	1673.5
580.588	1662
582.992	1688.5
585.395	1715.5
587.799	1691
590.201	1695
592.601	1687.5
595.001	1687.5
597.401	1689
599.799	1686.5
602.197	1703
604.594	1699
606.99	1733
609.386	1715
611.78	1730
614.174	1741.5
616.566	1737
618.958	1743.5
621.35	1725.5
623.741	1755
626.13	1743.5
628.519	1737.5
630.908	1771.5
633.295	1769.5
635.682	1795
638.067	1757.5
640.453	1770.5
642.836	1771.5
645.219	1755.5
647.602	1805.5
649.984	1783
652.364	1752
654.745	1761
657.124	1809.5
659.503	1756.5
661.88	1783
664.257	1793
666.635	1759.5
669.01	1763.5
671.384	1751
673.758	1768.5
676.131	1764.5
678.502	1743
680.874	1762
683.245	1746.5
685.615	1776
687.984	1745
690.353	1724.5
692.719	1741.5
695.086	1750.5
697.453	1751
699.817	1734
702.182	1734
704.545	1760.5
706.908	1762.5
709.27	1736
711.632	1733
713.991	1744
716.352	1721
718.71	1740.5
721.068	1757
723.426	1767.5
725.782	1759
728.138	1747.5
730.492	1755
732.846	1786
735.201	1758
737.553	1757.5
739.905	1743.5
742.256	1758
744.606	1767.5
746.956	1780.5
749.303	1771.5
751.651	1711
753.999	1760.5
756.345	1734.5
758.691	1769.5
761.035	1743
763.379	1725.5
765.723	1739
768.064	1741
770.407	1748.5
772.748	1739.5
775.088	1757
777.427	1747.5
779.765	1750
782.104	1753
784.44	1753
786.776	1784
789.113	1733.5
791.447	1751.5
793.78	1751.5
796.113	1760
798.445	1753
800.778	1761.5
803.109	1724.5
805.439	1745
807.768	1754.5
810.096	1739
812.424	1787
814.751	1764
817.078	1784
819.402	1776.5
821.727	1801.5
824.051	1806.5
826.374	1809.5
828.697	1794
831.018	1804.5
833.339	1802.5
835.659	1811.5
837.978	1782.5
840.297	1796
842.614	1812
844.932	1782
847.247	1818.5
849.562	1811
851.878	1809.5
854.191	1812.5
856.504	1804.5
858.817	1836.5
861.129	1821
863.439	1800
865.749	1798
868.058	1799
870.367	1777
872.676	1780.5
874.983	1786
877.289	1783
879.593	1768.5
881.898	1763
884.202	1773.5
886.506	1728.5
888.808	1775
891.11	1769.5
893.41	1756.5
895.711	1726
898.011	1744
900.309	1729.5
902.607	1727.5
904.904	1744
907.201	1721.5
909.496	1703
911.791	1726
914.085	1729
916.379	1738
918.671	1748.5
920.963	1759
923.255	1708
925.545	1709
927.834	1720.5
930.123	1733
932.411	1738.5
934.698	1728.5
936.985	1694.5
939.271	1726
941.556	1678
943.84	1732
946.124	1709.5
948.407	1747
950.689	1713.5
952.971	1729.5
955.25	1725.5
957.531	1716
959.81	1750
962.088	1718
964.366	1746
966.643	1726
968.919	1731.5
971.195	1742.75
973.469	1732.5
975.743	1715
978.016	1724.5
980.288	1744.5
982.56	1751.5
984.831	1740.5
987.101	1707
989.37	1741
991.638	1735.5
993.907	1731
996.174	1727
998.44	1787
1000.71	1806
1002.97	1743
1005.24	1749
1007.5	1748.5
1009.76	1717
1012.02	1713.5
1014.28	1726
1016.54	1730
1018.8	1725
1021.06	1712.5
1023.32	1760
1025.58	1762.5
1027.84	1729.5
1030.09	1759
1032.35	1719
1034.6	1725.5
1036.86	1724
1039.11	1718.5
1041.36	1734.5
1043.61	1742
1045.86	1750
1048.11	1738
1050.36	1736
1052.61	1744.5
1054.86	1738
1057.11	1740.5
1059.35	1738
1061.6	1748.5
1063.84	1737
1066.09	1754
1068.33	1715.5
1070.57	1717.5
1072.82	1750
1075.06	1742
1077.3	1705
1079.54	1724.5
1081.78	1719
1084.02	1705
1086.25	1695
1088.49	1712
1090.73	1696
1092.96	1726
1095.2	1676
1097.43	1694.5
1099.66	1692
1101.9	1685.5
1104.13	1681.5
1106.36	1677
1108.59	1683.5
1110.82	1683.5
1113.05	1684
1115.28	1680
1117.51	1664.5
1119.73	1684
1121.96	1684
1124.18	1689
1126.41	1675.5
1128.63	1681.5
1130.85	1694
1133.08	1676
1135.3	1680
1137.52	1685
1139.74	1706
1141.96	1716
1144.18	1707.5
1146.4	1719.5
1148.61	1714.5
1150.83	1730.5
1153.05	1751
1155.26	1772
1157.48	1758
1159.69	1724.5
1161.9	1766
1164.11	1761
1166.33	1784
1168.54	1790.5
1170.75	1773.5
1172.96	1798
1175.17	1783
1177.37	1783.5
1179.58	1741
1181.79	1751
1183.99	1726
1186.2	1726.5
1188.4	1730
1190.61	1734
1192.81	1698
1195.01	1729
1197.21	1729.82
1199.42	1743.11
1201.61	1710.11
1203.81	1701.92
1206.01	1720.86
1208.21	1718.44
1210.41	1734.89
1212.61	1730.41
1214.8	1702.77
1217	1733.59
1219.19	1717.45
1221.38	1700.91
1223.58	1701.91
1225.77	1704.1
1227.96	1712.57
1230.15	1710.09
1232.34	1720.68
1234.53	1734.43
1236.72	1728.89
1238.91	1726.5
1241.1	1727.65
1243.28	1728.42
1245.47	1729.6
1247.65	1733.36
1249.84	1741.26
1252.02	1737.58
1254.21	1745
1256.39	1739.72
1258.57	1760.97
1260.75	1763.32
1262.93	1767.29
1265.11	1776.99
1267.29	1760.29
1269.47	1774.83
1271.65	1781.82
1273.82	1781.06
1276	1777.95
1278.17	1747.04
1280.35	1768.53
1282.52	1767.04
1284.69	1767.4
1286.87	1792.81
1289.04	1786.44
1291.21	1804.13
1293.38	1807.67
1295.55	1788.71
1297.72	1787.95
1299.89	1796.64
1302.06	1794.23
1304.22	1793.1
1306.39	1790.72
1308.43	1767
1310.6	1791
1312.78	1776
1314.96	1769
1317.13	1772.5
1319.3	1769.5
1321.47	1756
1323.65	1722
1325.82	1735
1327.99	1700.5
1330.16	1722
1332.32	1748
1334.49	1750
1336.66	1736
1338.83	1702.5
1340.99	1741
1343.16	1700.5
1345.32	1720.5
1347.49	1730
1349.65	1704
1351.81	1667
1353.98	1715
1356.14	1697.5
1358.3	1680.5
1360.46	1652.5
1362.62	1658
1364.78	1670.5
1366.93	1654
1369.09	1639.5
1371.25	1660
1373.4	1677
1375.56	1652
1377.71	1637
1379.87	1652.5
1382.02	1638
1384.17	1616.5
1386.32	1657
1388.47	1622.5
1390.63	1629
1392.77	1633
1394.92	1619.5
1397.07	1625.5
1399.22	1643
1401.37	1621
1403.51	1615.5
1405.66	1619
1407.8	1629.5
1409.95	1627
1412.09	1628.5
1414.23	1626.5
1416.38	1652
1418.52	1597
1420.66	1632.5
1422.8	1639
1424.94	1607.5
1427.08	1654
1429.21	1625
1431.35	1627.5
1433.49	1667
1435.63	1645
1437.76	1656
1439.89	1646
1442.03	1648.5
1444.16	1638
1446.3	1663
1448.43	1648.5
1450.56	1649.5
1452.69	1639
1454.82	1620.5
1456.95	1633.5
1459.08	1646
1461.2	1602
1463.33	1612.5
1465.46	1631
1467.58	1588
1469.71	1614
1471.83	1614.5
1473.96	1627
1476.08	1616.5
1478.2	1617.5
1480.33	1658
1482.45	1648
1484.57	1629
1486.69	1623
1488.81	1638
1490.93	1616
1493.04	1612.5
1495.16	1631.5
1497.28	1637.5
1499.39	1620
1501.51	1639
1503.62	1616
1505.74	1665
1507.85	1632
1509.96	1626
1512.07	1634.5
1514.19	1635
1516.3	1660.5
1518.41	1669
1520.52	1646
1522.62	1675.5
1524.73	1659
1526.84	1665.5
1528.95	1683
1531.05	1665
1533.16	1681.5
1535.26	1677.5
1537.37	1672.5
1539.47	1639
1541.57	1628.5
1543.67	1667
1545.78	1672.5
1547.88	1656.5
1549.98	1680.5
1552.07	1668.5
1554.17	1635
1556.27	1660
1558.37	1680
1560.47	1663.5
1562.56	1657.5
1564.66	1664.5
1566.75	1643
1568.85	1656.5
1570.94	1689
1573.03	1678.5
1575.12	1671
1577.21	1656
1579.31	1669
1581.4	1708
1583.49	1690.5
1585.57	1680.5
1587.66	1692
1589.75	1663.5
1591.84	1690.5
1593.92	1683
1596.01	1701
1598.09	1707
1600.18	1660
1602.26	1659
1604.34	1641
1606.43	1595
1608.51	1566
1610.59	1557
1612.67	1551.5
1614.75	1517
1616.83	1498.5
1618.91	1481.5
1620.98	1443
1623.06	1413.5
1625.14	1417
1627.21	1407
1629.29	1357.5
1631.36	1355.5
1633.43	1301.5
1635.51	1336.5
1637.58	1318
1639.65	1278
1641.72	1272
1643.79	1294
1645.86	1249
1647.93	1238
1650	1239.5
1652.07	1208
1654.14	1219
1656.2	1178.5
1658.27	1179.5
1660.34	1157.5
1662.4	1169
1664.46	1143.5
1666.53	1121
1668.59	1129
1670.65	1105
1672.71	1103
1674.77	1101
1676.83	1097
1678.89	1079.5
1680.95	1077
1683.01	1050
1685.07	1078
1687.13	1060
1689.18	1052
1691.24	1065
1693.29	1052
1695.35	1047.5
1697.4	1041
1699.45	1025
1701.51	1037
1703.56	1027
1705.61	1026.5
1707.66	1011.5
1709.71	1013
1711.76	999
1713.81	1018.5
1715.86	1005
1717.9	1005.5
1719.95	996
1722	974
1724.04	993
1726.09	981
1728.13	964
1730.17	967
1732.22	968
1734.26	952
1736.3	949.5
1738.34	944.5
1740.38	960.5
1742.42	949
1744.46	950.5
1746.5	931.5
1748.54	936
1750.57	926
1752.61	936
1754.65	941
1756.68	929
1758.72	926
1760.75	909
1762.78	905
1764.82	922
1766.85	884.5
1768.88	899.5
1770.91	892
1772.94	911.5
1774.97	875
1777	899
1779.03	888
1781.06	870
1783.08	876.5
1785.11	872
1787.14	867.5
1789.16	868.5
1791.18	876
1793.21	863.5
1795.23	844.5
1797.26	866
1799.28	866.5
1801.3	869.5
1803.32	848
1805.34	846
1807.36	859
1809.38	820
1811.4	829.5
1813.41	836
1815.43	821.5
1817.45	825
1819.46	830
1821.48	818
1823.49	817.5
1825.51	808.5
1827.52	804.5
1829.53	834
1831.54	814
1833.56	794
1835.57	807.5
1837.58	810.5
1839.59	812
1841.59	809
1843.6	802
1845.61	802
1847.62	781
1849.62	804
1851.63	782
1853.64	780.5
1855.64	789.5
1857.64	771
1859.65	784.5
1861.65	759
1863.65	765.5
1865.65	755
1867.65	763
1869.65	761
1871.65	758
1873.65	753
1875.65	756.5
1877.65	760
1879.65	741
1881.64	753
1883.64	776.5
1885.63	732
1887.63	756
1889.62	748
1891.62	746
1893.61	730
1895.6	727
1897.59	718.5
1899.58	729.5
1901.57	725
1903.56	724.5
1905.55	726
1907.54	712
1909.53	739.5
1911.52	723.5
1913.5	713
1915.49	720
1917.48	715
1919.46	726
1921.44	700
1923.43	697
1925.41	701
1927.39	697.5
1929.38	695
1931.36	711.5
1933.34	704.5
1935.32	688
1937.3	702
1939.28	699.5
1941.25	675
1943.23	700
1945.21	699.5
1947.18	705
1949.16	690
1951.13	682
1953.11	683
1955.08	673
1957.06	678.5
1959.03	673.5
1961	656.5
1962.97	689.5
1964.94	679
1966.91	662.5
1968.88	668
1970.85	674
1972.82	660
1974.79	663
1976.76	659
1978.72	662
1980.69	637
1982.65	657
1984.62	651
1986.58	645.5
1988.55	651
1990.51	647
1992.47	654
1994.43	642
1996.39	649
1998.36	635
2000.31	642.5
2002.27	641
2004.23	647.5
2006.19	644
2008.15	620
2010.11	649
2012.06	617
2014.02	638
2015.97	624.5
2017.93	626
2019.88	633
2021.83	626.5
2023.79	618.5
2025.74	629
2027.69	628
2029.64	625.5
2031.59	620
2033.54	621.5
2035.49	620.5
2037.44	625.5
2039.39	615
2041.34	623
2043.28	603
2045.23	603
2047.17	619
2049.12	601.5
2051.06	605
2053.01	593.5
2054.95	611.5
2056.89	588
2058.84	593.5
2060.78	594.5
2062.72	601.5
2064.66	597
2066.6	588
2068.54	589.5
2070.48	597
2072.41	595
2074.35	586.5
2076.29	590
2078.22	578.5
2080.16	574
2082.09	578.5
2084.03	569
2085.96	570
2087.9	590.5
2089.83	579
2091.76	584
2093.69	569
2095.62	583
2097.55	595.5
2099.48	570.5
2101.41	589
2103.34	597.5
2105.27	602
2107.19	591.5
2109.12	607
2111.05	614
2112.97	596
2114.9	626
2116.82	633.5
2118.75	652
2120.67	651
2122.59	694
2124.51	696
2126.43	692
2128.36	693.5
2130.28	707
2132.2	718
2134.11	743.5
2136.03	734
2137.95	735.5
2139.87	748
2141.78	733.5
2143.7	731
2145.62	741.044
2147.53	760.414
2149.45	741.849
2151.36	716.441
2153.27	709.894
2155.19	741.748
2157.1	725.202
2159.01	708.863
2160.92	736.053
2162.83	710.814
2164.74	697.206
2166.65	696.933
2168.56	695.27
2170.47	684.179
2172.37	665.468
2174.28	665.993
2176.19	662.255
2178.09	647.716
2180	632.174
2181.9	624.063
2183.81	618.845
2185.71	593.319
2187.61	583.35
2189.51	560.003
2191.42	546.402
2193.32	539.565
2195.22	537.948
2197.12	519.889
2199.02	520.372
2200.92	509.854
2202.81	502.63
2204.71	508.604
2206.61	499.188
2208.5	494.844
2210.4	497.657
2212.3	485.29
2214.19	500.157
2216.08	489.552
2217.98	483.895
2219.87	486.431
2221.76	487.911
2223.65	481.191
2225.55	483.583
2227.44	484.87
2229.33	480.61
2231.22	480.924
2233.11	484.449
2234.99	479.764
2236.88	486.505
2238.77	472.801
2240.66	494.129
2242.06	495
2243.96	504.5
2245.85	492.5
2247.75	504.5
2249.64	490.5
2251.54	505
2253.43	493
2255.32	475.5
2257.21	482.5
2259.1	467.5
2260.99	450
2262.89	467
2264.77	468
2266.66	458
2268.55	452
2270.44	469
2272.33	460
2274.21	463
2276.1	454
2277.98	444
2279.87	456.5
2281.75	450
2283.64	442.5
2285.52	446
2287.4	445
2289.29	446.5
2291.17	449
2293.05	433
2294.93	451.5
2296.81	437
2298.69	435.5
2300.57	438.5
2302.44	425
2304.32	441.5
2306.2	434.5
2308.08	423
2309.95	421
2311.83	442.5
2313.7	417.5
2315.58	422
2317.45	421.5
2319.32	429
2321.2	419.5
2323.07	415.5
2324.94	421.5
2326.81	410.5
2328.68	420.5
2330.55	426
2332.42	419.5
2334.29	388
2336.16	413
2338.02	399
2339.89	414
2341.76	408.5
2343.62	408.5
2345.49	413
2347.35	413
2349.22	409
2351.08	420
2352.94	418
2354.81	407
2356.67	407
2358.53	412
2360.39	396
2362.25	414.5
2364.11	405
2365.97	395.5
2367.83	402.5
2369.69	384
2371.55	404
2373.4	412.5
2375.26	380.5
2377.11	393.5
2378.97	413.5
2380.83	375
2382.68	379.5
2384.53	391.5
2386.39	393
2388.24	388.5
2390.09	384.5
2391.94	398
2393.79	391.5
2395.64	379.5
2397.49	376
2399.34	389
2401.19	378
2403.04	378.5
2404.89	380
2406.74	374
2408.58	379
2410.43	382.5
2412.27	373
2414.12	363.5
2415.96	387.5
2417.81	363
2419.65	368.5
2421.49	373.5
2423.34	386.5
2425.18	370.5
2427.02	359.5
2428.86	378.5
2430.7	366
2432.54	367.5
2434.38	356
2436.22	357.5
2438.05	366.5
2439.89	371
2441.73	358.5
2443.56	373
2445.4	357.5
2447.24	363
2449.07	371
2450.9	367
2452.74	358.5
2454.57	365
2456.4	361.5
2458.23	372
2460.07	348.5
2461.9	354
2463.73	360
2465.56	357
2467.39	360.5
2469.21	343
2471.04	345.5
2472.87	352
2474.7	351.5
2476.52	345
2478.35	353.5
2480.17	335.5
2482	346
2483.82	349
2485.65	355.5
2487.47	345.5
2489.29	348
2491.12	334.5
2492.94	343
2494.76	334
2496.58	342.5
2498.4	347
2500.22	348
2502.04	350.5
2503.86	339.5
2505.67	329.5
2507.49	338
2509.31	336.5
2511.12	338.5
2512.94	340
2514.76	330
2516.57	334
2518.38	324.5
2520.2	340
2522.01	323
2523.82	336.5
2525.64	327
2527.45	329
2529.26	318.5
2531.07	319
2532.88	327.5
2534.69	313
2536.5	328
2538.31	317
2540.11	323.5
2541.92	315
2543.73	320
2545.53	318.5
2547.34	326.5
2549.14	319.5
2550.95	317.5
2552.75	315
2554.56	335
2556.36	312.5
2558.16	302.5
2559.96	319
2561.76	319
2563.57	301.5
2565.37	318
2567.17	294
2568.96	309.5
2570.76	303.5
2572.56	312.5
2574.36	301.5
2576.16	294.5
2577.95	301.5
2579.75	297.5
2581.54	308.5
2583.34	305.5
2585.13	301
2586.93	305.5
2588.72	311
2590.51	296
2592.31	298.5
2594.1	304
2595.89	292
2597.68	287.5
2599.47	296
2601.26	291.5
2603.05	311.5
2604.84	301.5
2606.63	293.5
2608.42	297.5
2610.2	284.5
2611.99	297.5
2613.78	284.5
2615.56	280.5
2617.35	276
2619.13	279
2620.91	287
2622.7	298.5
2624.48	291
2626.26	291.5
2628.04	278
2629.83	286
2631.61	276.5
2633.39	285.5
2635.17	275
2636.95	282
2638.73	266
2640.5	271
2642.28	282
2644.06	271
2645.84	264.5
2647.61	277.5
2649.39	270.5
2651.16	268
2652.94	268
2654.71	268
2656.49	267.5
2658.26	262
2660.03	274
2661.8	271.5
2663.57	278.5
2665.35	281
2667.12	266.5
2668.89	272
2670.66	270
2672.42	268
2674.19	260.5
2675.96	269.5
2677.73	269.5
2679.49	254.5
2681.26	270
2683.03	269
2684.79	261.5
2686.56	263.5
2688.32	255
2690.09	253.5
2691.85	262
2693.61	269.5
2695.37	256.5
2697.14	265
2698.9	265
2700.66	264.5
2702.42	253
2704.18	260.5
2705.94	255
2707.7	256
2709.45	252.5
2711.21	246.5
2712.97	243
2714.72	255.5
2716.48	246
2718.24	252.5
2719.99	250.5
2721.75	247
2723.5	250
2725.25	259
2727.01	247.5
2728.76	242.5
2730.51	245.5
2732.26	249
2734.01	253.5
2735.76	253.5
2737.51	237
2739.26	253
2741.01	247
2742.76	226
2744.51	244
2746.26	240
2748	247
2749.75	239
2751.5	239
2753.24	242.5
2754.99	238.5
2756.73	231
2758.47	238
2760.22	231.5
2761.96	242
2763.7	233
2765.44	237.5
2767.19	233
2768.93	234.5
2770.67	234
2772.41	221
2774.15	230.5
2775.89	228
2777.62	233
2779.36	222
2781.1	225.5
2782.84	224
2784.57	227
2786.31	226
2788.04	219.5
2789.78	220.5
2791.51	225.5
2793.24	216.5
2794.98	214
2796.71	217
2798.44	230
2800.18	219
2801.91	227.5
2803.64	221.25
2805.37	220.5
2807.1	224.5
2808.83	212.5
2810.55	222.5
2812.28	224.5
2814.01	222
2815.74	222.5
2817.46	226
2819.19	214.5
2820.92	222.5
2822.64	210
2824.37	218.5
2826.09	215
2827.81	228
2829.54	216
2831.26	216.5
2832.98	218.5
2834.71	224
2836.43	219
2838.15	212
2839.87	222
2841.59	223
2843.31	233.5
2845.02	229.5
2846.74	242
2848.46	231.5
2850.18	242
2851.9	231
2853.61	239.5
2855.33	243
2857.04	237.5
2858.76	234.5
2860.47	226.5
2862.19	235.5
2863.9	233
2865.61	239
2867.32	236
2869.04	234.5
2870.75	236.5
2872.46	230
2874.17	235
2875.88	234
2877.59	230.5
2879.3	233
2881	230.5
2882.71	233
2884.42	229.5
2886.13	228.5
2887.83	229.5
2889.54	229
2891.24	232
2892.95	227
2894.65	237.5
2896.36	231
2898.06	225.5
2899.76	226
2901.47	235
2903.17	233
2904.87	228
2906.57	240.5
2908.27	235.5
2909.97	231
2911.67	235.5
2913.37	230
2915.07	230.5
2916.77	234
2918.47	242
2920.16	237
2921.86	234
2923.55	241.5
2925.25	238.5
2926.94	228
2928.64	237
2930.33	243
2932.03	235.5
2933.72	234.5
2935.41	239.5
2937.11	243
2938.8	226
2940.49	231
2942.18	239.5
2943.87	235
2945.56	230
2947.25	219.5
2948.94	212.5
2950.63	216
2952.31	218
2954	209
2955.69	211
2957.37	208
2959.06	210
2960.75	195.5
2962.43	202
2964.11	196
2965.8	213
2967.48	196
2969.16	197.5
2970.85	199
2972.53	196
2974.21	193
2975.89	197
2977.57	196.5
2979.25	191
2980.93	192
2982.61	181
2984.29	182
2985.97	184
2987.65	182.5
2989.32	179
2991	172.5
2992.68	184.5
2994.35	177.5
2996.03	169
2997.7	175
2999.38	167