File: muestras/ogompa/nsno_10.txt
#Acq. time (s)=	5
#Accumulations=	5
#Range (cm-¹)=	100...3000
#Windows=	3
#Autofocus=	Off
#AutoExposure=	Off
#Spike filter=	Multiple accum.
#Delay time (s)=	0
#Binning=	1
#Readout mode=	Signal
#DeNoise=	Off
#ICS correction=	Off
#Dark correction=	Off
#Inst. Process=	Off
#Instrument=	LabRAM HR Evol
#Detector=	Syncerity OE
#Objective=	x100_VIS_LWD
#Grating=	600 (500nm)
#ND Filter=	100%
#Laser=	633nm_Edge
#Hole=	100.021
#Range=	Visible
#Project=	Omar
#Sample=	chi
#Site=	f
#Title=	nsno
#Remark=
#Date=	12.09.2023 17:13
#Acquired=	12.09.2023 17:13:30
101.026	3665.5
103.592	3560.5
106.158	3488
108.723	3430.5
111.289	3387
113.852	3329
116.415	3270.5
118.976	3199
121.537	3170
124.097	3114.5
126.656	3088.5
129.215	3018.5
131.772	3017.5
134.327	2937.5
136.883	2914.5
139.438	2839
141.992	2807
144.545	2725
147.096	2680
149.648	2636.5
152.199	2564.5
154.747	2507.5
157.296	2479.5
159.843	2472.5
162.391	2474
164.937	2410
167.482	2403.5
170.025	2383.5
172.569	2328.5
175.111	2339.5
177.654	2313
180.194	2311
182.733	2324
185.273	2265.5
187.811	2274
190.348	2303
192.884	2242.5
195.419	2302
197.955	2291.5
200.489	2325
203.022	2331
205.554	2345
208.085	2346
210.615	2341.5
213.144	2349.5
215.673	2316
218.201	2325
220.728	2335
223.253	2338.5
225.778	2343
228.303	2371
230.826	2365
233.348	2367.5
235.87	2369.5
238.391	2377
240.91	2393.5
243.43	2389
245.949	2428
248.465	2378.5
250.983	2428
253.498	2433.5
256.013	2434
258.526	2426
261.039	2460.5
263.552	2429
266.063	2429.5
268.573	2421.5
271.084	2416.5
273.592	2455.5
276.1	2444.5
278.607	2416.5
281.113	2459
283.619	2506
286.124	2520
288.627	2512
291.13	2510.5
293.632	2563.5
296.133	2582
298.634	2542.5
301.133	2518.5
303.63	2568.5
306.128	2535
308.625	2532.5
311.122	2496
313.617	2508.5
316.111	2468
318.604	2425.5
321.098	2458
323.588	2454
326.08	2448.5
328.569	2416
331.059	2427
333.548	2375.5
336.035	2382
338.521	2357
341.008	2369.5
343.492	2377
345.977	2372.5
348.46	2363.5
350.942	2355.5
353.425	2375.5
355.905	2389
358.385	2379.5
360.864	2368
363.342	2392.5
365.819	2391.5
368.296	2418
370.771	2391
373.246	2371.5
375.72	2408.5
378.194	2385
380.666	2403.5
383.138	2400.5
385.609	2351
388.079	2356
390.548	2381
393.016	2358
395.483	2367
397.95	2372
400.416	2371
402.88	2357.5
405.345	2360
407.807	2395.5
410.27	2415
412.731	2414
415.193	2427.5
417.652	2434.5
420.112	2416
422.569	2453
425.028	2461
427.484	2447
429.939	2459
432.394	2465
434.849	2452
437.302	2415.5
439.754	2475
442.205	2499.5
444.656	2476
447.106	2467
449.555	2474.5
452.003	2502.5
454.45	2463.5
456.897	2451.5
459.343	2490.5
461.788	2445.5
464.232	2476
466.676	2412
469.119	2484
471.559	2483.5
474.001	2445.5
476.441	2485
478.879	2464
481.318	2502
483.756	2507
486.192	2473
488.629	2521.5
491.063	2498
493.498	2540
495.931	2532
498.365	2523
500.796	2586
503.226	2540.5
505.657	2542
508.086	2581.5
510.515	2570.5
512.942	2572
515.369	2561
517.796	2597.5
520.221	2563
522.645	2578
525.069	2595.5
527.492	2574.5
529.914	2590.5
532.335	2625.5
534.756	2588.5
537.175	2590.5
539.593	2617
542.011	2576
544.429	2593.5
546.845	2605.5
549.261	2572.5
551.675	2589.5
554.089	2627
556.503	2604.5
558.914	2591
561.326	2614
563.736	2655.5
566.147	2631.5
568.555	2632
570.964	2651.5
573.371	2628
575.777	2627
578.184	2646.5
580.588	2670
582.992	2659.5
585.395	2645.5
587.799	2638
590.201	2623.5
592.601	2638
595.001	2668
597.401	2668
599.799	2660
602.197	2674
604.594	2697.5
606.99	2650
609.386	2693
611.78	2746
614.174	2718.5
616.566	2758
618.958	2766
621.35	2761
623.741	2738.5
626.13	2792.5
628.519	2800.5
630.908	2817
633.295	2844
635.682	2794
638.067	2796.5
640.453	2805
642.836	2809
645.219	2819
647.602	2821
649.984	2800
652.364	2782
654.745	2822.5
657.124	2753
659.503	2759
661.88	2729
664.257	2732.5
666.635	2701.5
669.01	2731.5
671.384	2727.5
673.758	2706.5
676.131	2713
678.502	2672.5
680.874	2712.5
683.245	2695
685.615	2702
687.984	2678
690.353	2713.5
692.719	2720
695.086	2686.5
697.453	2711
699.817	2699.5
702.182	2687.5
704.545	2701.5
706.908	2667
709.27	2684.5
711.632	2690
713.991	2692.5
716.352	2707
718.71	2700.5
721.068	2696
723.426	2713
725.782	2654.5
728.138	2680.5
730.492	2696.5
732.846	2675.5
735.201	2693.5
737.553	2676
739.905	2685
742.256	2710
744.606	2686.5
746.956	2699
749.303	2716
751.651	2696.5
753.999	2715.5
756.345	2669.5
758.691	2722.5
761.035	2673
763.379	2674
765.723	2701.5
768.064	2728
770.407	2728
772.748	2695
775.088	2684
777.427	2722.5
779.765	2719
782.104	2736
784.44	2731
786.776	2702
789.113	2722
791.447	2712
793.78	2703
796.113	2710.5
798.445	2738.5
800.778	2696.5
803.109	2767.5
805.439	2763
807.768	2744.5
810.096	2773
812.424	2760
814.751	2797.5
817.078	2806
819.402	2799
821.727	2800.5
824.051	2823.5
826.374	2850.5
828.697	2839.5
831.018	2795
833.339	2800
835.659	2828
837.978	2839
840.297	2851
842.614	2846
844.932	2839
847.247	2846
849.562	2840
851.878	2864
854.191	2874.5
856.504	2869.5
858.817	2885.5
861.129	2867
863.439	2855
865.749	2839
868.058	2841
870.367	2845.5
872.676	2851.5
874.983	2789
877.289	2799
879.593	2800
881.898	2760
884.202	2764.5
886.506	2785.5
888.808	2752
891.11	2736
893.41	2752.5
895.711	2744
898.011	2759.5
900.309	2735
902.607	2743.5
904.904	2716
907.201	2708.5
909.496	2717
911.791	2704
914.085	2704.5
916.379	2702.5
918.671	2716
920.963	2692
923.255	2727
925.545	2714.5
927.834	2728
930.123	2719.5
932.411	2748
934.698	2751
936.985	2752
939.271	2751
941.556	2755
943.84	2767
946.124	2753.5
948.407	2750.5
950.689	2777
952.971	2776
955.25	2749
957.531	2789
959.81	2812
962.088	2802.5
964.366	2828
966.643	2787.5
968.919	2779
971.195	2807.25
973.469	2815.5
975.743	2794
978.016	2786
980.288	2828.5
982.56	2860.5
984.831	2845.5
987.101	2856.5
989.37	2868.5
991.638	2795.5
993.907	2857
996.174	2894.5
998.44	2933.5
1000.71	2937.5
1002.97	2867
1005.24	2806.5
1007.5	2797.5
1009.76	2804.5
1012.02	2811
1014.28	2766.5
1016.54	2824.5
1018.8	2800.5
1021.06	2807
1023.32	2825.5
1025.58	2843.5
1027.84	2829
1030.09	2835
1032.35	2855.5
1034.6	2846.5
1036.86	2817
1039.11	2842.5
1041.36	2856
1043.61	2893.5
1045.86	2897.5
1048.11	2877
1050.36	2885.5
1052.61	2887
1054.86	2873.5
1057.11	2914
1059.35	2907
1061.6	2904.5
1063.84	2862
1066.09	2925.5
1068.33	2914
1070.57	2883
1072.82	2912
1075.06	2929.5
1077.3	2936.5
1079.54	2890
1081.78	2897
1084.02	2876
1086.25	2876
1088.49	2886
1090.73	2874.5
1092.96	2854
1095.2	2853.5
1097.43	2856.5
1099.66	2874.5
1101.9	2863.5
1104.13	2867.5
1106.36	2889
1108.59	2870
1110.82	2845
1113.05	2900.5
1115.28	2910
1117.51	2911.5
1119.73	2893
1121.96	2915
1124.18	2922
1126.41	2886.5
1128.63	2914.5
1130.85	2921.5
1133.08	2937.5
1135.3	2920
1137.52	2981
1139.74	2964.5
1141.96	2971.5
1144.18	2972
1146.4	3027.5
1148.61	3067
1150.83	3057.5
1153.05	3058
1155.26	3117.5
1157.48	3124.5
1159.69	3120
1161.9	3146
1164.11	3168
1166.33	3198
1168.54	3223.5
1170.75	3178
1172.96	3186
1175.17	3207.5
1177.37	3190.5
1179.58	3127
1181.79	3170
1183.99	3143
1186.2	3116
1188.4	3122
1190.61	3119.5
1192.81	3113
1195.01	3112
1197.21	3089.75
1199.42	3101
1201.61	3102.9
1203.81	3082.16
1206.01	3113.58
1208.21	3113.23
1210.41	3120.52
1212.61	3098.74
1214.8	3116.41
1217	3091.37
1219.19	3098.93
1221.38	3092.39
1223.58	3087.01
1225.77	3097.78
1227.96	3099.26
1230.15	3090.99
1232.34	3102.77
1234.53	3098.33
1236.72	3089.54
1238.91	3108.75
1241.1	3100.18
1243.28	3115
1245.47	3121.66
1247.65	3108.73
1249.84	3154.14
1252.02	3106.02
1254.21	3153.81
1256.39	3157.21
1258.57	3173.67
1260.75	3180.99
1262.93	3210.57
1265.11	3197.43
1267.29	3221.89
1269.47	3230.78
1271.65	3226.98
1273.82	3205.4
1276	3250.83
1278.17	3243.16
1280.35	3251.52
1282.52	3247.84
1284.69	3250.3
1286.87	3242.03
1289.04	3292.03
1291.21	3272.34
1293.38	3255.19
1295.55	3264.39
1297.72	3292.56
1299.89	3246.63
1302.06	3228.69
1304.22	3231.45
1306.39	3257.15
1308.43	3238.5
1310.6	3220.5
1312.78	3235
1314.96	3232.5
1317.13	3232
1319.3	3187
1321.47	3220
1323.65	3240
1325.82	3242
1327.99	3215
1330.16	3256.5
1332.32	3235.5
1334.49	3225
1336.66	3191
1338.83	3183.5
1340.99	3199
1343.16	3166
1345.32	3192.5
1347.49	3183
1349.65	3136
1351.81	3063.5
1353.98	3105
1356.14	3098
1358.3	3103
1360.46	3112.5
1362.62	3072.5
1364.78	3078
1366.93	3096.5
1369.09	3118
1371.25	3110
1373.4	3060
1375.56	3017
1377.71	3039
1379.87	3032.5
1382.02	3053
1384.17	3003
1386.32	3009
1388.47	2985.5
1390.63	2979
1392.77	3029
1394.92	3006.5
1397.07	3031.5
1399.22	3084.5
1401.37	3052.5
1403.51	3034.5
1405.66	3057
1407.8	3082
1409.95	3085
1412.09	3108.5
1414.23	3141.5
1416.38	3130.5
1418.52	3135
1420.66	3100.5
1422.8	3124.5
1424.94	3101.5
1427.08	3160
1429.21	3115
1431.35	3171.5
1433.49	3198
1435.63	3186.5
1437.76	3221
1439.89	3240
1442.03	3258
1444.16	3254
1446.3	3254.5
1448.43	3331.5
1450.56	3346
1452.69	3352.5
1454.82	3311.5
1456.95	3363
1459.08	3334
1461.2	3361
1463.33	3348
1465.46	3360.5
1467.58	3402
1469.71	3389.5
1471.83	3437
1473.96	3444.5
1476.08	3419.5
1478.2	3454
1480.33	3397
1482.45	3436
1484.57	3452.5
1486.69	3443
1488.81	3408.5
1490.93	3375
1493.04	3406.5
1495.16	3370.5
1497.28	3391
1499.39	3370
1501.51	3383.5
1503.62	3364
1505.74	3266.5
1507.85	3341.5
1509.96	3330
1512.07	3335.5
1514.19	3304.5
1516.3	3394
1518.41	3341.5
1520.52	3336.5
1522.62	3329.5
1524.73	3368.5
1526.84	3351
1528.95	3371.5
1531.05	3356
1533.16	3355.5
1535.26	3364
1537.37	3323
1539.47	3366.5
1541.57	3417.5
1543.67	3402.5
1545.78	3405.5
1547.88	3421.5
1549.98	3337
1552.07	3414.5
1554.17	3426.5
1556.27	3416
1558.37	3427.5
1560.47	3385.5
1562.56	3413
1564.66	3384
1566.75	3397
1568.85	3420
1570.94	3398
1573.03	3371.5
1575.12	3409
1577.21	3392
1579.31	3323
1581.4	3358
1583.49	3378
1585.57	3352
1587.66	3344
1589.75	3360
1591.84	3346
1593.92	3380.5
1596.01	3384
1598.09	3344
1600.18	3289
1602.26	3283
1604.34	3266.5
1606.43	3218.5
1608.51	3157.5
1610.59	3106
1612.67	3089.5
1614.75	3044.5
1616.83	2991
1618.91	2922
1620.98	2854.5
1623.06	2817.5
1625.14	2796
1627.21	2776
1629.29	2730.5
1631.36	2692
1633.43	2654
1635.51	2594.5
1637.58	2576
1639.65	2573
1641.72	2497.5
1643.79	2476
1645.86	2460
1647.93	2392
1650	2448
1652.07	2377.5
1654.14	2356
1656.2	2337.5
1658.27	2299.5
1660.34	2296
1662.4	2219.5
1664.46	2264
1666.53	2208
1668.59	2211.5
1670.65	2183
1672.71	2196
1674.77	2202.5
1676.83	2170.5
1678.89	2176.5
1680.95	2139.5
1683.01	2114
1685.07	2137
1687.13	2094.5
1689.18	2061
1691.24	2080
1693.29	2071.5
1695.35	2059.5
1697.4	2041
1699.45	2054.5
1701.51	2044.5
1703.56	1992.5
1705.61	2009
1707.66	2010
1709.71	1975.5
1711.76	1980.5
1713.81	1987
1715.86	1977.5
1717.9	1947.5
1719.95	1954
1722	1935.5
1724.04	1933
1726.09	1900.5
1728.13	1941
1730.17	1902.5
1732.22	1919.5
1734.26	1937
1736.3	1875.5
1738.34	1899
1740.38	1875.5
1742.42	1902.5
1744.46	1851.5
1746.5	1856.5
1748.54	1840
1750.57	1857
1752.61	1818.5
1754.65	1847.5
1756.68	1827
1758.72	1819.5
1760.75	1810
1762.78	1814.5
1764.82	1816
1766.85	1791.5
1768.88	1809.5
1770.91	1748.5
1772.94	1770.5
1774.97	1755.5
1777	1744.5
1779.03	1756
1781.06	1750.5
1783.08	1747
1785.11	1744
1787.14	1740.5
1789.16	1711.5
1791.18	1711.5
1793.21	1688
1795.23	1720
1797.26	1689
1799.28	1679.5
1801.3	1719.5
1803.32	1690
1805.34	1709
1807.36	1670.5
1809.38	1698
1811.4	1622.5
1813.41	1682
1815.43	1688.5
1817.45	1674
1819.46	1655.5
1821.48	1664
1823.49	1649.5
1825.51	1620.5
1827.52	1604
1829.53	1587
1831.54	1631.5
1833.56	1589
1835.57	1629
1837.58	1615
1839.59	1624
1841.59	1594
1843.6	1589
1845.61	1568
1847.62	1575
1849.62	1565.5
1851.63	1556.5
1853.64	1539
1855.64	1557
1857.64	1543
1859.65	1559
1861.65	1566
1863.65	1531.5
1865.65	1551
1867.65	1533.5
1869.65	1541.5
1871.65	1528.5
1873.65	1518.5
1875.65	1542.5
1877.65	1522.5
1879.65	1536.5
1881.64	1513.5
1883.64	1524.5
1885.63	1508.5
1887.63	1491.5
1889.62	1502.5
1891.62	1529.5
1893.61	1546
1895.6	1491
1897.59	1468
1899.58	1490
1901.57	1498.5
1903.56	1488.5
1905.55	1511.5
1907.54	1499
1909.53	1481
1911.52	1492.5
1913.5	1484.5
1915.49	1463
1917.48	1451
1919.46	1506.5
1921.44	1457.5
1923.43	1487.5
1925.41	1458
1927.39	1451
1929.38	1449
1931.36	1447.5
1933.34	1466
1935.32	1460.5
1937.3	1444.5
1939.28	1444
1941.25	1448.5
1943.23	1467.5
1945.21	1408
1947.18	1426
1949.16	1432
1951.13	1436
1953.11	1437.5
1955.08	1393
1957.06	1393
1959.03	1419.5
1961	1434
1962.97	1411
1964.94	1388.5
1966.91	1398
1968.88	1412.5
1970.85	1419.5
1972.82	1394
1974.79	1385
1976.76	1398.5
1978.72	1402.5
1980.69	1394.5
1982.65	1393
1984.62	1371
1986.58	1368
1988.55	1359
1990.51	1348
1992.47	1390
1994.43	1341
1996.39	1363.5
1998.36	1354
2000.31	1354
2002.27	1356
2004.23	1386
2006.19	1379
2008.15	1332.5
2010.11	1338
2012.06	1343.5
2014.02	1346
2015.97	1361
2017.93	1361
2019.88	1339.5
2021.83	1311
2023.79	1340.5
2025.74	1306
2027.69	1343
2029.64	1311
2031.59	1327
2033.54	1297.5
2035.49	1314
2037.44	1321.5
2039.39	1315.5
2041.34	1311
2043.28	1291
2045.23	1307.5
2047.17	1306
2049.12	1292.5
2051.06	1282.5
2053.01	1281.5
2054.95	1284.5
2056.89	1273
2058.84	1271
2060.78	1253
2062.72	1277.5
2064.66	1279.5
2066.6	1263.5
2068.54	1253.5
2070.48	1270.5
2072.41	1270.5
2074.35	1277.5
2076.29	1286.5
2078.22	1262.5
2080.16	1240
2082.09	1242.5
2084.03	1260.5
2085.96	1253
2087.9	1235.5
2089.83	1254.5
2091.76	1234.5
2093.69	1246.5
2095.62	1275.5
2097.55	1257.5
2099.48	1244.5
2101.41	1277.5
2103.34	1314
2105.27	1303.5
2107.19	1296
2109.12	1367
2111.05	1385.5
2112.97	1430.5
2114.9	1475.5
2116.82	1531.5
2118.75	1595
2120.67	1671
2122.59	1719
2124.51	1782
2126.43	1795.5
2128.36	1872
2130.28	1865
2132.2	1835
2134.11	1794
2136.03	1688.5
2137.95	1640
2139.87	1553
2141.78	1476.5
2143.7	1451.5
2145.62	1368.27
2147.53	1314.18
2149.45	1306.85
2151.36	1278.3
2153.27	1249.11
2155.19	1234.95
2157.1	1215.96
2159.01	1217.8
2160.92	1207.93
2162.83	1196.55
2164.74	1183.19
2166.65	1155.94
2168.56	1155.09
2170.47	1117.4
2172.37	1143.62
2174.28	1109.66
2176.19	1131.65
2178.09	1125.54
2180	1118.53
2181.9	1124.45
2183.81	1105.31
2185.71	1105.71
2187.61	1093.92
2189.51	1097.44
2191.42	1084.85
2193.32	1088.04
2195.22	1095.95
2197.12	1086.5
2199.02	1081.95
2200.92	1082.79
2202.81	1081.09
2204.71	1077.9
2206.61	1079.61
2208.5	1066.8
2210.4	1062.13
2212.3	1074.63
2214.19	1074.9
2216.08	1059.53
2217.98	1056.03
2219.87	1051.24
2221.76	1056.68
2223.65	1063.54
2225.55	1056.65
2227.44	1060.17
2229.33	1049.93
2231.22	1057
2233.11	1054.16
2234.99	1053.02
2236.88	1055.04
2238.77	1046.13
2240.66	1049.97
2242.06	1052
2243.96	1073.5
2245.85	1050
2247.75	1037.5
2249.64	1053
2251.54	1048.5
2253.43	1037
2255.32	1039
2257.21	1016
2259.1	1019.5
2260.99	1020
2262.89	1008
2264.77	1017
2266.66	1007.5
2268.55	989
2270.44	994.5
2272.33	994
2274.21	986.5
2276.1	997
2277.98	1003.5
2279.87	997.5
2281.75	978
2283.64	977
2285.52	993
2287.4	982
2289.29	993.5
2291.17	982
2293.05	963
2294.93	966
2296.81	966.5
2298.69	973
2300.57	951
2302.44	954
2304.32	959
2306.2	957
2308.08	963
2309.95	960.5
2311.83	934
2313.7	950
2315.58	933
2317.45	945
2319.32	938.5
2321.2	959
2323.07	948
2324.94	945.5
2326.81	920
2328.68	939
2330.55	950
2332.42	930
2334.29	917
2336.16	932
2338.02	944
2339.89	900
2341.76	919.5
2343.62	910
2345.49	921.5
2347.35	913.5
2349.22	924.5
2351.08	924
2352.94	910
2354.81	908.5
2356.67	898.5
2358.53	912.5
2360.39	912.5
2362.25	910
2364.11	906.5
2365.97	921
2367.83	912
2369.69	912
2371.55	889
2373.4	901.5
2375.26	885.5
2377.11	902
2378.97	910.5
2380.83	890
2382.68	877.5
2384.53	872
2386.39	888
2388.24	889.5
2390.09	877.5
2391.94	875
2393.79	885
2395.64	864
2397.49	887.5
2399.34	855
2401.19	870.5
2403.04	881
2404.89	871
2406.74	860
2408.58	876
2410.43	879.5
2412.27	870.5
2414.12	866.5
2415.96	858.5
2417.81	846
2419.65	856.5
2421.49	875.5
2423.34	866
2425.18	856
2427.02	854.5
2428.86	849.5
2430.7	853
2432.54	840
2434.38	840.5
2436.22	829.5
2438.05	858.5
2439.89	858
2441.73	824
2443.56	851.5
2445.4	827.5
2447.24	846.5
2449.07	833
2450.9	809.5
2452.74	836
2454.57	833.5
2456.4	838
2458.23	833
2460.07	827
2461.9	822
2463.73	818.5
2465.56	845
2467.39	798
2469.21	819.5
2471.04	815.5
2472.87	810.5
2474.7	813
2476.52	837
2478.35	803
2480.17	811.5
2482	811.5
2483.82	807
2485.65	799.5
2487.47	789
2489.29	808
2491.12	795
2492.94	800.5
2494.76	806
2496.58	812
2498.4	795.5
2500.22	778.5
2502.04	791.5
2503.86	795
2505.67	780.5
2507.49	800.5
2509.31	785
2511.12	794
2512.94	792.5
2514.76	802.5
2516.57	795.5
2518.38	779
2520.2	765
2522.01	785.5
2523.82	764
2525.64	777.5
2527.45	787
2529.26	775
2531.07	777.5
2532.88	776
2534.69	765.5
2536.5	769.5
2538.31	751
2540.11	768.5
2541.92	754
2543.73	763.5
2545.53	743
2547.34	746
2549.14	745.5
2550.95	753.5
2552.75	745
2554.56	763
2556.36	757.5
2558.16	745.5
2559.96	728
2561.76	733
2563.57	731
2565.37	765.5
2567.17	756
2568.96	720
2570.76	734
2572.56	729
2574.36	739.5
2576.16	748
2577.95	738.5
2579.75	745
2581.54	746
2583.34	731
2585.13	738.5
2586.93	722
2588.72	730.5
2590.51	708.5
2592.31	717
2594.1	735
2595.89	718
2597.68	702.5
2599.47	728
2601.26	724.5
2603.05	688
2604.84	714
2606.63	702.5
2608.42	715
2610.2	705
2611.99	713
2613.78	710.5
2615.56	705.5
2617.35	700
2619.13	678
2620.91	700.5
2622.7	692.5
2624.48	717
2626.26	700.5
2628.04	681
2629.83	689.5
2631.61	696
2633.39	675
2635.17	689
2636.95	688
2638.73	681
2640.5	684
2642.28	673
2644.06	679.5
2645.84	675.5
2647.61	670
2649.39	678.5
2651.16	667
2652.94	692.5
2654.71	667
2656.49	657.5
2658.26	671
2660.03	664
2661.8	670
2663.57	680.5
2665.35	653
2667.12	670
2668.89	645.5
2670.66	682
2672.42	669.5
2674.19	663
2675.96	650.5
2677.73	655
2679.49	653.5
2681.26	666
2683.03	659
2684.79	650
2686.56	661.5
2688.32	648
2690.09	647
2691.85	634
2693.61	641
2695.37	644.5
2697.14	638
2698.9	648.5
2700.66	642.5
2702.42	642
2704.18	651
2705.94	650.5
2707.7	637.5
2709.45	631
2711.21	630
2712.97	627
2714.72	631.5
2716.48	615
2718.24	637.5
2719.99	618
2721.75	625.5
2723.5	639.5
2725.25	623
2727.01	633.5
2728.76	628
2730.51	624
2732.26	630.5
2734.01	623
2735.76	615
2737.51	621.5
2739.26	611
2741.01	606
2742.76	611.5
2744.51	600.5
2746.26	594
2748	583
2749.75	601.5
2751.5	611
2753.24	606
2754.99	597
2756.73	566
2758.47	599.5
2760.22	596
2761.96	592
2763.7	589
2765.44	603.5
2767.19	609.5
2768.93	601
2770.67	593.5
2772.41	576
2774.15	594
2775.89	577
2777.62	582
2779.36	571.5
2781.1	597
2782.84	575
2784.57	580.5
2786.31	587.5
2788.04	580
2789.78	571
2791.51	567.5
2793.24	572
2794.98	571
2796.71	555
2798.44	571.5
2800.18	561
2801.91	575
2803.64	568
2805.37	563
2807.1	569.5
2808.83	565.5
2810.55	574
2812.28	563
2814.01	562.5
2815.74	567.5
2817.46	556
2819.19	568
2820.92	546.5
2822.64	563.5
2824.37	564
2826.09	555
2827.81	555
2829.54	553
2831.26	572
2832.98	553
2834.71	571
2836.43	571.5
2838.15	555.5
2839.87	552.5
2841.59	563.5
2843.31	560
2845.02	586.5
2846.74	587
2848.46	578
2850.18	597
2851.9	580
2853.61	581.5
2855.33	564.5
2857.04	576.5
2858.76	582
2860.47	574.5
2862.19	589.5
2863.9	576.5
2865.61	597.5
2867.32	592
2869.04	557
2870.75	595.5
2872.46	584
2874.17	583
2875.88	583.5
2877.59	582
2879.3	588.5
2881	563.5
2882.71	580
2884.42	585
2886.13	570.5
2887.83	588
2889.54	578.5
2891.24	582
2892.95	584.5
2894.65	582
2896.36	601
2898.06	599
2899.76	601
2901.47	600
2903.17	604
2904.87	603
2906.57	614
2908.27	617
2909.97	624
2911.67	609
2913.37	617
2915.07	629
2916.77	601.5
2918.47	597
2920.16	608.5
2921.86	613.5
2923.55	598
2925.25	600
2926.94	610.5
2928.64	611.5
2930.33	612.5
2932.03	612.5
2933.72	613.5
2935.41	589
2937.11	588
2938.8	607
2940.49	588.5
2942.18	571
2943.87	593
2945.56	569
2947.25	553
2948.94	543
2950.63	543.5
2952.31	534.5
2954	531.5
2955.69	521
2957.37	509
2959.06	517
2960.75	524.5
2962.43	512
2964.11	496
2965.8	484
2967.48	493
2969.16	501
2970.85	513.5
2972.53	513
2974.21	492
2975.89	494
2977.57	477
2979.25	497
2980.93	483.5
2982.61	478
2984.29	473.5
2985.97	478.5
2987.65	468
2989.32	457.5
2991	473.5
2992.68	454
2994.35	453
2996.03	446
2997.7	438.5
2999.38	450.5