File: muestras/ogompa/nsno_03.txt
#Acq. time (s)=	5
#Accumulations=	5
#Range (cm-¹)=	100...3000
#Windows=	3
#Autofocus=	Off
#AutoExposure=	Off
#Spike filter=	Multiple accum.
#Delay time (s)=	0
#Binning=	1
#Readout mode=	Signal
#DeNoise=	Off
#ICS correction=	Off
#Dark correction=	Off
#Inst. Process=	Off
#Instrument=	LabRAM HR Evol
#Detector=	Syncerity OE
#Objective=	x100_VIS_LWD
#Grating=	600 (500nm)
#ND Filter=	100%
#Laser=	633nm_Edge
#Hole=	100.021
#Range=	Visible
#Project=	Omar
#Sample=	chi
#Site=	f
#Title=	nsno
#Remark=
#Date=	12.09.2023 16:50
#Acquired=	12.09.2023 16:50:42
101.026	4425
103.592	4371.5
106.158	4301
108.723	4220
111.289	4166
113.852	4112.5
116.415	4036
118.976	3987.5
121.537	3976
124.097	3907
126.656	3835.5
129.215	3808
131.772	3767
134.327	3723.5
136.883	3688.5
139.438	3573.5
141.992	3598.5
144.545	3531
147.096	3458.5
149.648	3462.5
152.199	3382.5
154.747	3316
157.296	3327.5
159.843	3308.5
162.391	3196.5
164.937	3209.5
167.482	3198.5
170.025	3147
172.569	3152
175.111	3071
177.654	3048.5
180.194	3052.5
182.733	3055
185.273	3032.5
187.811	3043
190.348	3070
192.884	3052.5
195.419	3097
197.955	3079
200.489	3108
203.022	3131
205.554	3149
208.085	3084.5
210.615	3121.5
213.144	3102.5
215.673	3103.5
218.201	3106
220.728	3101.5
223.253	3094
225.778	3086
228.303	3103.5
230.826	3116.5
233.348	3140
235.87	3162
238.391	3133.5
240.91	3169
243.43	3172.5
245.949	3207.5
248.465	3180.5
250.983	3245.5
253.498	3234.5
256.013	3222
258.526	3249.5
261.039	3210
263.552	3226.5
266.063	3198.5
268.573	3166.5
271.084	3237.5
273.592	3180.5
276.1	3218
278.607	3187
281.113	3258.5
283.619	3267
286.124	3257
288.627	3256.5
291.13	3286
293.632	3270
296.133	3323
298.634	3316
301.133	3362
303.63	3344
306.128	3338.5
308.625	3367
311.122	3332.5
313.617	3327
316.111	3302
318.604	3315.5
321.098	3304
323.588	3233
326.08	3262.5
328.569	3238
331.059	3256.5
333.548	3218.5
336.035	3170
338.521	3190
341.008	3187
343.492	3136
345.977	3192
348.46	3215.5
350.942	3180
353.425	3148.5
355.905	3193
358.385	3188
360.864	3187.5
363.342	3215
365.819	3161
368.296	3204.5
370.771	3182.5
373.246	3170.5
375.72	3180.5
378.194	3184.5
380.666	3160
383.138	3194
385.609	3129.5
388.079	3146.5
390.548	3132.5
393.016	3158.5
395.483	3167.5
397.95	3132
400.416	3134.5
402.88	3182
405.345	3175.5
407.807	3217
410.27	3189
412.731	3196
415.193	3210.5
417.652	3258
420.112	3246.5
422.569	3263.5
425.028	3252.5
427.484	3309.5
429.939	3309
432.394	3284.5
434.849	3292.5
437.302	3310
439.754	3310
442.205	3293
444.656	3287.5
447.106	3265
449.555	3247
452.003	3329.5
454.45	3280
456.897	3239.5
459.343	3286
461.788	3260
464.232	3256.5
466.676	3320.5
469.119	3254.5
471.559	3315.5
474.001	3274.5
476.441	3291
478.879	3311
481.318	3336.5
483.756	3323.5
486.192	3324
488.629	3321
491.063	3394
493.498	3323.5
495.931	3351
498.365	3383.5
500.796	3354.5
503.226	3371.5
505.657	3377
508.086	3386.5
510.515	3375
512.942	3354.5
515.369	3403
517.796	3353.5
520.221	3389.5
522.645	3353.5
525.069	3417.5
527.492	3374
529.914	3375
532.335	3404
534.756	3381
537.175	3365.5
539.593	3328.5
542.011	3330
544.429	3358
546.845	3342.5
549.261	3371
551.675	3380.5
554.089	3351.5
556.503	3388.5
558.914	3361.5
561.326	3384.5
563.736	3388
566.147	3386
568.555	3368.5
570.964	3397.5
573.371	3428.5
575.777	3386
578.184	3399
580.588	3428
582.992	3389
585.395	3394.5
587.799	3386.5
590.201	3370.5
592.601	3447.5
595.001	3443
597.401	3406.5
599.799	3419
602.197	3423.5
604.594	3430.5
606.99	3441.5
609.386	3444
611.78	3486.5
614.174	3457.5
616.566	3450
618.958	3484.5
621.35	3519.5
623.741	3469
626.13	3509.5
628.519	3517.5
630.908	3558.5
633.295	3575
635.682	3561
638.067	3562.5
640.453	3551.5
642.836	3585
645.219	3582
647.602	3571
649.984	3580
652.364	3522.5
654.745	3542.5
657.124	3533
659.503	3504
661.88	3550.5
664.257	3528.5
666.635	3535.5
669.01	3504.5
671.384	3480
673.758	3485.5
676.131	3441
678.502	3486
680.874	3476.5
683.245	3476.5
685.615	3488.5
687.984	3464
690.353	3467
692.719	3484
695.086	3446.5
697.453	3370.5
699.817	3399
702.182	3427.5
704.545	3427
706.908	3439.5
709.27	3428
711.632	3412
713.991	3430.5
716.352	3450
718.71	3487.5
721.068	3446.5
723.426	3474
725.782	3399
728.138	3487
730.492	3435.5
732.846	3459.5
735.201	3494.5
737.553	3427
739.905	3472
742.256	3413.5
744.606	3465.5
746.956	3408.5
749.303	3450.5
751.651	3483.5
753.999	3470
756.345	3424.5
758.691	3449
761.035	3405
763.379	3433
765.723	3416
768.064	3420.5
770.407	3446
772.748	3414
775.088	3424
777.427	3414
779.765	3413
782.104	3442
784.44	3427.5
786.776	3415.5
789.113	3421
791.447	3401.5
793.78	3430.5
796.113	3438.5
798.445	3434
800.778	3438
803.109	3458.5
805.439	3470.5
807.768	3450
810.096	3476
812.424	3420.5
814.751	3433.5
817.078	3422
819.402	3494.5
821.727	3468
824.051	3498
826.374	3486.5
828.697	3483
831.018	3488.5
833.339	3517.5
835.659	3536
837.978	3520
840.297	3524
842.614	3525.5
844.932	3516
847.247	3516
849.562	3517
851.878	3528
854.191	3584.5
856.504	3567
858.817	3579.5
861.129	3520.5
863.439	3567.5
865.749	3551
868.058	3533
870.367	3505.5
872.676	3515
874.983	3448
877.289	3482
879.593	3425
881.898	3420.5
884.202	3436
886.506	3441.5
888.808	3409
891.11	3441
893.41	3433
895.711	3405
898.011	3395.5
900.309	3413
902.607	3363
904.904	3387.5
907.201	3410
909.496	3340.5
911.791	3372
914.085	3363
916.379	3375.5
918.671	3342.5
920.963	3378
923.255	3334
925.545	3346
927.834	3321.5
930.123	3375
932.411	3358.5
934.698	3360.5
936.985	3359.5
939.271	3366.5
941.556	3358
943.84	3319.5
946.124	3367.5
948.407	3369.5
950.689	3411.5
952.971	3395
955.25	3400
957.531	3395.5
959.81	3396
962.088	3397.5
964.366	3427
966.643	3407
968.919	3412
971.195	3400
973.469	3446
975.743	3399.5
978.016	3378.5
980.288	3383
982.56	3379.5
984.831	3384.5
987.101	3370
989.37	3392.5
991.638	3427
993.907	3427
996.174	3457.5
998.44	3506
1000.71	3531.5
1002.97	3444.5
1005.24	3388
1007.5	3359.5
1009.76	3367
1012.02	3368.5
1014.28	3383
1016.54	3334
1018.8	3365.5
1021.06	3329.5
1023.32	3395.5
1025.58	3371.5
1027.84	3397.5
1030.09	3382.5
1032.35	3374.5
1034.6	3386.5
1036.86	3370.5
1039.11	3373
1041.36	3366.5
1043.61	3405.5
1045.86	3409
1048.11	3455.5
1050.36	3397.5
1052.61	3398.5
1054.86	3415
1057.11	3408.5
1059.35	3426
1061.6	3380.5
1063.84	3414.5
1066.09	3409
1068.33	3388
1070.57	3424
1072.82	3413
1075.06	3409.5
1077.3	3434.5
1079.54	3421.5
1081.78	3419
1084.02	3369
1086.25	3345.5
1088.49	3336.5
1090.73	3343.5
1092.96	3367.5
1095.2	3351.5
1097.43	3321
1099.66	3318
1101.9	3367
1104.13	3310.5
1106.36	3292
1108.59	3288.5
1110.82	3313
1113.05	3373.5
1115.28	3331
1117.51	3352
1119.73	3315.5
1121.96	3320
1124.18	3352.5
1126.41	3345.5
1128.63	3348
1130.85	3336.5
1133.08	3364.5
1135.3	3378
1137.52	3306.5
1139.74	3367.5
1141.96	3385.5
1144.18	3423.5
1146.4	3362.5
1148.61	3428
1150.83	3423.5
1153.05	3448.5
1155.26	3505
1157.48	3527.5
1159.69	3531
1161.9	3528.5
1164.11	3529.5
1166.33	3563
1168.54	3596
1170.75	3559.5
1172.96	3574
1175.17	3564.5
1177.37	3523
1179.58	3540.5
1181.79	3497.5
1183.99	3477
1186.2	3485
1188.4	3473
1190.61	3470
1192.81	3485
1195.01	3471
1197.21	3479.61
1199.42	3449.79
1201.61	3411.87
1203.81	3402.31
1206.01	3435.51
1208.21	3411.54
1210.41	3401.82
1212.61	3355.16
1214.8	3351.2
1217	3329.71
1219.19	3339.45
1221.38	3309.75
1223.58	3269.52
1225.77	3272.66
1227.96	3278.86
1230.15	3245.41
1232.34	3283.96
1234.53	3242.55
1236.72	3230.16
1238.91	3265.45
1241.1	3198.46
1243.28	3212.76
1245.47	3196.84
1247.65	3215.4
1249.84	3212.14
1252.02	3188.3
1254.21	3176.58
1256.39	3196
1258.57	3192.04
1260.75	3182.86
1262.93	3167.66
1265.11	3169.54
1267.29	3156.06
1269.47	3169.45
1271.65	3159.13
1273.82	3134.98
1276	3135.51
1278.17	3118.91
1280.35	3114.42
1282.52	3097.29
1284.69	3097.05
1286.87	3062.53
1289.04	3086.99
1291.21	3061.6
1293.38	3042.3
1295.55	3076.57
1297.72	3047
1299.89	3043.85
1302.06	2989.93
1304.22	2974.96
1306.39	2950.19
1308.43	2951.5
1310.6	2973.5
1312.78	2990.5
1314.96	2957.5
1317.13	2936.5
1319.3	2979.5
1321.47	2945.5
1323.65	2917.5
1325.82	2920
1327.99	2918
1330.16	2921.5
1332.32	2950
1334.49	2890.5
1336.66	2909
1338.83	2900
1340.99	2895.5
1343.16	2839
1345.32	2880.5
1347.49	2823.5
1349.65	2812.5
1351.81	2806.5
1353.98	2842.5
1356.14	2822.5
1358.3	2824.5
1360.46	2771
1362.62	2786
1364.78	2811.5
1366.93	2773
1369.09	2764.5
1371.25	2774
1373.4	2741.5
1375.56	2734
1377.71	2775.5
1379.87	2752
1382.02	2742.5
1384.17	2755.5
1386.32	2738.5
1388.47	2770
1390.63	2727
1392.77	2703
1394.92	2724
1397.07	2703.5
1399.22	2738
1401.37	2713
1403.51	2720.5
1405.66	2712
1407.8	2721
1409.95	2726.5
1412.09	2686
1414.23	2691
1416.38	2700
1418.52	2698.5
1420.66	2701
1422.8	2720
1424.94	2749.5
1427.08	2735
1429.21	2721
1431.35	2710.5
1433.49	2749.5
1435.63	2756
1437.76	2767.5
1439.89	2728.5
1442.03	2762
1444.16	2767.5
1446.3	2768.5
1448.43	2760
1450.56	2733
1452.69	2783
1454.82	2757
1456.95	2770.5
1459.08	2772.5
1461.2	2775
1463.33	2787
1465.46	2763
1467.58	2762
1469.71	2772.5
1471.83	2805
1473.96	2763
1476.08	2759
1478.2	2778.5
1480.33	2807
1482.45	2766.5
1484.57	2714
1486.69	2740.5
1488.81	2718.5
1490.93	2686.5
1493.04	2706.5
1495.16	2699.5
1497.28	2680.5
1499.39	2715
1501.51	2671
1503.62	2657
1505.74	2647.5
1507.85	2655
1509.96	2699
1512.07	2641
1514.19	2649
1516.3	2652.5
1518.41	2648.5
1520.52	2648
1522.62	2672
1524.73	2676
1526.84	2640
1528.95	2674.5
1531.05	2651
1533.16	2665.5
1535.26	2647
1537.37	2637.5
1539.47	2648.5
1541.57	2641
1543.67	2652.5
1545.78	2643
1547.88	2608.5
1549.98	2635.5
1552.07	2626
1554.17	2645.5
1556.27	2640.5
1558.37	2617
1560.47	2645
1562.56	2628
1564.66	2628
1566.75	2643
1568.85	2597
1570.94	2607
1573.03	2628
1575.12	2624
1577.21	2577
1579.31	2627
1581.4	2592
1583.49	2596.5
1585.57	2584
1587.66	2626
1589.75	2628
1591.84	2611
1593.92	2600.5
1596.01	2612.5
1598.09	2587.5
1600.18	2536
1602.26	2512.5
1604.34	2502.5
1606.43	2456
1608.51	2420.5
1610.59	2378
1612.67	2346
1614.75	2345.5
1616.83	2280
1618.91	2271.5
1620.98	2264
1623.06	2172.5
1625.14	2185
1627.21	2155.5
1629.29	2159
1631.36	2117.5
1633.43	2090
1635.51	2045
1637.58	2014
1639.65	2016.5
1641.72	1988.5
1643.79	1953
1645.86	1940
1647.93	1904.5
1650	1895
1652.07	1907
1654.14	1866.5
1656.2	1858.5
1658.27	1836.5
1660.34	1792
1662.4	1809.5
1664.46	1786
1666.53	1756
1668.59	1776.5
1670.65	1747
1672.71	1726.5
1674.77	1698
1676.83	1691
1678.89	1698
1680.95	1665
1683.01	1706
1685.07	1671
1687.13	1644
1689.18	1655.5
1691.24	1657
1693.29	1623
1695.35	1622.5
1697.4	1605.5
1699.45	1594
1701.51	1616
1703.56	1594.5
1705.61	1578.5
1707.66	1596.5
1709.71	1561
1711.76	1566.5
1713.81	1569.5
1715.86	1572
1717.9	1547.5
1719.95	1502
1722	1538
1724.04	1523.5
1726.09	1515
1728.13	1507
1730.17	1505
1732.22	1491.5
1734.26	1492
1736.3	1502
1738.34	1477
1740.38	1479
1742.42	1471.5
1744.46	1457.5
1746.5	1455.5
1748.54	1430
1750.57	1444.5
1752.61	1433.5
1754.65	1429.5
1756.68	1437
1758.72	1432
1760.75	1424.5
1762.78	1398.5
1764.82	1415
1766.85	1415.5
1768.88	1382
1770.91	1336
1772.94	1368.5
1774.97	1364
1777	1369
1779.03	1359.5
1781.06	1363.5
1783.08	1358.5
1785.11	1345
1787.14	1332
1789.16	1353.5
1791.18	1339.5
1793.21	1313
1795.23	1316.5
1797.26	1306
1799.28	1305.5
1801.3	1289.5
1803.32	1308.5
1805.34	1309
1807.36	1293
1809.38	1287
1811.4	1292
1813.41	1278.5
1815.43	1275
1817.45	1262.5
1819.46	1278
1821.48	1268.5
1823.49	1265
1825.51	1253.5
1827.52	1258.5
1829.53	1251
1831.54	1262.5
1833.56	1244
1835.57	1237
1837.58	1232.5
1839.59	1218
1841.59	1204.5
1843.6	1218
1845.61	1215.5
1847.62	1184
1849.62	1192.5
1851.63	1213
1853.64	1175.5
1855.64	1190
1857.64	1155
1859.65	1180
1861.65	1207
1863.65	1165
1865.65	1152
1867.65	1173
1869.65	1192
1871.65	1159.5
1873.65	1171
1875.65	1149
1877.65	1166
1879.65	1145.5
1881.64	1145
1883.64	1149.5
1885.63	1142.5
1887.63	1140.5
1889.62	1110
1891.62	1129.5
1893.61	1123
1895.6	1129.5
1897.59	1118
1899.58	1108
1901.57	1126
1903.56	1131
1905.55	1110.5
1907.54	1100.5
1909.53	1107.5
1911.52	1106.5
1913.5	1104.5
1915.49	1081
1917.48	1075.5
1919.46	1084
1921.44	1094
1923.43	1063
1925.41	1084.5
1927.39	1086
1929.38	1092
1931.36	1075.5
1933.34	1073
1935.32	1064
1937.3	1069.5
1939.28	1056.5
1941.25	1063
1943.23	1067
1945.21	1084
1947.18	1033.5
1949.16	1059.5
1951.13	1044
1953.11	1053.5
1955.08	1036
1957.06	1040.5
1959.03	1040
1961	1048.5
1962.97	1042
1964.94	980
1966.91	1022.5
1968.88	1009
1970.85	1036.5
1972.82	1012
1974.79	993
1976.76	1009
1978.72	1002
1980.69	998.5
1982.65	995.5
1984.62	1020.5
1986.58	999.5
1988.55	996
1990.51	988
1992.47	974.5
1994.43	975
1996.39	979
1998.36	988
2000.31	974.5
2002.27	960
2004.23	991.5
2006.19	979
2008.15	970.5
2010.11	965
2012.06	970.5
2014.02	960.5
2015.97	958.5
2017.93	978
2019.88	954
2021.83	961
2023.79	950.5
2025.74	942
2027.69	937.5
2029.64	937.5
2031.59	949
2033.54	919.5
2035.49	928.5
2037.44	905
2039.39	932.5
2041.34	936.5
2043.28	921
2045.23	937.5
2047.17	917
2049.12	901.5
2051.06	918.5
2053.01	913
2054.95	918
2056.89	921.5
2058.84	899
2060.78	879.5
2062.72	913.5
2064.66	897.5
2066.6	894
2068.54	890
2070.48	878.5
2072.41	878.5
2074.35	868
2076.29	883.5
2078.22	880
2080.16	852
2082.09	871.5
2084.03	884
2085.96	867
2087.9	869
2089.83	871.5
2091.76	870.5
2093.69	854.5
2095.62	869
2097.55	868
2099.48	853.5
2101.41	865.5
2103.34	865
2105.27	859.5
2107.19	856.5
2109.12	877.5
2111.05	881.5
2112.97	881
2114.9	882.5
2116.82	885
2118.75	928
2120.67	923.5
2122.59	902.5
2124.51	926
2126.43	932
2128.36	951.5
2130.28	942.5
2132.2	932
2134.11	926
2136.03	890.5
2137.95	892.5
2139.87	890
2141.78	883.5
2143.7	872.5
2145.62	846.583
2147.53	846.491
2149.45	807.22
2151.36	798.383
2153.27	809.559
2155.19	808.928
2157.1	798.959
2159.01	782.926
2160.92	770.245
2162.83	773.215
2164.74	763.014
2166.65	761.831
2168.56	764.846
2170.47	753.469
2172.37	742.483
2174.28	740.409
2176.19	745.17
2178.09	727.53
2180	733.385
2181.9	725.429
2183.81	723.149
2185.71	726.933
2187.61	714.286
2189.51	703.587
2191.42	712.115
2193.32	710.505
2195.22	711.799
2197.12	690.332
2199.02	688.38
2200.92	691.002
2202.81	692.073
2204.71	692.274
2206.61	693.051
2208.5	693.296
2210.4	691.902
2212.3	667.798
2214.19	673.63
2216.08	684.595
2217.98	677.375
2219.87	668.758
2221.76	668.161
2223.65	656.309
2225.55	657.892
2227.44	650.303
2229.33	650.861
2231.22	653.438
2233.11	645.451
2234.99	647.381
2236.88	655.736
2238.77	649.153
2240.66	644.268
2242.06	644.5
2243.96	649
2245.85	661
2247.75	652.5
2249.64	669.5
2251.54	645
2253.43	653
2255.32	641
2257.21	618
2259.1	635
2260.99	622.5
2262.89	612.5
2264.77	623
2266.66	614
2268.55	601
2270.44	611
2272.33	593
2274.21	605.5
2276.1	595
2277.98	608.5
2279.87	592.5
2281.75	604.5
2283.64	581
2285.52	593.5
2287.4	589
2289.29	587
2291.17	591
2293.05	582.5
2294.93	587
2296.81	584
2298.69	586.5
2300.57	585.5
2302.44	566.5
2304.32	574.5
2306.2	586.5
2308.08	586.5
2309.95	579
2311.83	562
2313.7	576
2315.58	556
2317.45	571.5
2319.32	573.5
2321.2	557
2323.07	573
2324.94	555.5
2326.81	559
2328.68	561.5
2330.55	571
2332.42	554
2334.29	558.5
2336.16	560.5
2338.02	554.5
2339.89	565
2341.76	541
2343.62	543.5
2345.49	554.5
2347.35	540.5
2349.22	551.5
2351.08	547.5
2352.94	556.5
2354.81	549
2356.67	539
2358.53	547.5
2360.39	545
2362.25	545
2364.11	527
2365.97	546
2367.83	534.5
2369.69	532
2371.55	518
2373.4	540
2375.26	545.5
2377.11	540.5
2378.97	539.5
2380.83	531
2382.68	538.5
2384.53	508
2386.39	510.5
2388.24	514
2390.09	517.5
2391.94	528
2393.79	534.5
2395.64	514
2397.49	506.5
2399.34	509
2401.19	523.5
2403.04	485.5
2404.89	496.5
2406.74	527
2408.58	520.5
2410.43	512
2412.27	512
2414.12	511
2415.96	515.5
2417.81	492
2419.65	509
2421.49	497.5
2423.34	487
2425.18	506
2427.02	495
2428.86	488
2430.7	494
2432.54	489.5
2434.38	490
2436.22	499
2438.05	494
2439.89	487
2441.73	492
2443.56	469
2445.4	480.5
2447.24	483
2449.07	477
2450.9	485.5
2452.74	494.5
2454.57	486.5
2456.4	477
2458.23	491.5
2460.07	485.5
2461.9	469.5
2463.73	478.5
2465.56	476
2467.39	480.5
2469.21	481.5
2471.04	474.5
2472.87	454.5
2474.7	474.5
2476.52	459
2478.35	471
2480.17	463
2482	477
2483.82	467
2485.65	457
2487.47	463
2489.29	467.5
2491.12	453
2492.94	465
2494.76	448
2496.58	469
2498.4	457
2500.22	455.5
2502.04	448
2503.86	435
2505.67	458
2507.49	440.5
2509.31	455
2511.12	444
2512.94	444.5
2514.76	433
2516.57	458
2518.38	455
2520.2	452
2522.01	437
2523.82	430
2525.64	437.5
2527.45	428
2529.26	439
2531.07	427.5
2532.88	432
2534.69	430
2536.5	424
2538.31	430
2540.11	408
2541.92	417
2543.73	425
2545.53	415
2547.34	430
2549.14	405.5
2550.95	420.5
2552.75	427
2554.56	429.5
2556.36	419
2558.16	423.5
2559.96	416.5
2561.76	418.5
2563.57	413.5
2565.37	416.5
2567.17	423
2568.96	415
2570.76	422.5
2572.56	413.5
2574.36	397
2576.16	409
2577.95	413.5
2579.75	392
2581.54	408.5
2583.34	407
2585.13	406.5
2586.93	396.5
2588.72	393
2590.51	399
2592.31	403.5
2594.1	396
2595.89	404
2597.68	401.5
2599.47	410
2601.26	408
2603.05	393
2604.84	398.5
2606.63	389
2608.42	392.5
2610.2	379.5
2611.99	398.5
2613.78	384
2615.56	389
2617.35	400
2619.13	389
2620.91	394
2622.7	381
2624.48	384.5
2626.26	390
2628.04	398.5
2629.83	377
2631.61	381
2633.39	369
2635.17	360.5
2636.95	370.5
2638.73	376
2640.5	368
2642.28	354.5
2644.06	378.5
2645.84	367.5
2647.61	358
2649.39	382
2651.16	368
2652.94	361
2654.71	364
2656.49	350
2658.26	366
2660.03	363
2661.8	365.5
2663.57	364.5
2665.35	354.5
2667.12	362
2668.89	356
2670.66	350
2672.42	361
2674.19	350.5
2675.96	361
2677.73	365
2679.49	354.5
2681.26	359.5
2683.03	357
2684.79	351
2686.56	351
2688.32	359
2690.09	342
2691.85	350.5
2693.61	347
2695.37	343.5
2697.14	342
2698.9	344
2700.66	348.5
2702.42	341
2704.18	337
2705.94	353
2707.7	358
2709.45	348
2711.21	351
2712.97	334
2714.72	320.5
2716.48	345.5
2718.24	350
2719.99	334.5
2721.75	337.5
2723.5	334
2725.25	336.5
2727.01	333.5
2728.76	334.5
2730.51	324.5
2732.26	325.5
2734.01	330.5
2735.76	341
2737.51	334.5
2739.26	315
2741.01	334
2742.76	324
2744.51	323
2746.26	330.5
2748	323
2749.75	313
2751.5	327
2753.24	324.5
2754.99	309.5
2756.73	307
2758.47	315.5
2760.22	305
2761.96	323
2763.7	312.5
2765.44	310
2767.19	315
2768.93	313
2770.67	314
2772.41	312
2774.15	304.5
2775.89	297
2777.62	306
2779.36	310
2781.1	302
2782.84	308
2784.57	307.5
2786.31	309
2788.04	293
2789.78	292
2791.51	291.5
2793.24	299.5
2794.98	305
2796.71	287.5
2798.44	301.5
2800.18	295.5
2801.91	288.5
2803.64	298.5
2805.37	290.5
2807.1	292.5
2808.83	290
2810.55	293.5
2812.28	292
2814.01	292.5
2815.74	292
2817.46	293
2819.19	285
2820.92	293.5
2822.64	292
2824.37	286.5
2826.09	291
2827.81	292.5
2829.54	294
2831.26	282
2832.98	287
2834.71	289.5
2836.43	289
2838.15	288
2839.87	284
2841.59	283
2843.31	284
2845.02	291.5
2846.74	282
2848.46	296
2850.18	284.5
2851.9	304
2853.61	296.5
2855.33	284.5
2857.04	292.5
2858.76	273
2860.47	298.5
2862.19	299.5
2863.9	297
2865.61	287.5
2867.32	284
2869.04	293
2870.75	283
2872.46	297
2874.17	287.5
2875.88	299
2877.59	290
2879.3	281
2881	296
2882.71	288
2884.42	287.5
2886.13	287.5
2887.83	293
2889.54	275
2891.24	289.5
2892.95	293
2894.65	284
2896.36	289
2898.06	284
2899.76	289.5
2901.47	290.5
2903.17	275
2904.87	291.5
2906.57	282.5
2908.27	278.5
2909.97	289
2911.67	290.5
2913.37	296.5
2915.07	289
2916.77	294.5
2918.47	279.5
2920.16	290
2921.86	292.5
2923.55	296.5
2925.25	290
2926.94	292.5
2928.64	287.5
2930.33	295
2932.03	299
2933.72	297.5
2935.41	296.5
2937.11	292
2938.8	289
2940.49	283.5
2942.18	288
2943.87	286
2945.56	282
2947.25	272.5
2948.94	276
2950.63	277
2952.31	271
2954	261.5
2955.69	273
2957.37	259
2959.06	258.5
2960.75	262.5
2962.43	252.5
2964.11	259.5
2965.8	253.5
2967.48	257
2969.16	254.5
2970.85	252
2972.53	255
2974.21	243
2975.89	258
2977.57	244
2979.25	242.5
2980.93	244
2982.61	232.5
2984.29	245.5
2985.97	232.5
2987.65	230.5
2989.32	229
2991	245.5
2992.68	225.5
2994.35	231
2996.03	227
2997.7	224.5
2999.38	228