File: muestras/ogompa/nsno_18.txt
#Acq. time (s)=	5
#Accumulations=	5
#Range (cm-¹)=	100...3000
#Windows=	3
#Autofocus=	Off
#AutoExposure=	Off
#Spike filter=	Multiple accum.
#Delay time (s)=	0
#Binning=	1
#Readout mode=	Signal
#DeNoise=	Off
#ICS correction=	Off
#Dark correction=	Off
#Inst. Process=	Off
#Instrument=	LabRAM HR Evol
#Detector=	Syncerity OE
#Objective=	x100_VIS_LWD
#Grating=	600 (500nm)
#ND Filter=	100%
#Laser=	633nm_Edge
#Hole=	100.021
#Range=	Visible
#Project=	Omar
#Sample=	chi
#Site=	f
#Title=	nsno
#Remark=
#Date=	12.09.2023 17:43
#Acquired=	12.09.2023 17:43:38
101.026	4425.5
103.592	4436
106.158	4334
108.723	4244.5
111.289	4256
113.852	4087
116.415	4055.5
118.976	3990
121.537	3972.5
124.097	3951
126.656	3907
129.215	3845.5
131.772	3785
134.327	3714
136.883	3707
139.438	3635.5
141.992	3597.5
144.545	3564
147.096	3445.5
149.648	3445.5
152.199	3385
154.747	3381
157.296	3294.5
159.843	3260
162.391	3222
164.937	3220
167.482	3234.5
170.025	3178
172.569	3134
175.111	3116
177.654	3142.5
180.194	3127
182.733	3102.5
185.273	3139
187.811	3126
190.348	3124
192.884	3144
195.419	3121.5
197.955	3123
200.489	3152.5
203.022	3130.5
205.554	3111
208.085	3163.5
210.615	3181
213.144	3207.5
215.673	3170
218.201	3188
220.728	3205
223.253	3191
225.778	3167.5
228.303	3189
230.826	3224
233.348	3248
235.87	3256.5
238.391	3241
240.91	3228
243.43	3236
245.949	3244
248.465	3288
250.983	3237.5
253.498	3297
256.013	3257
258.526	3301.5
261.039	3268
263.552	3229.5
266.063	3275.5
268.573	3298.5
271.084	3220
273.592	3258.5
276.1	3287.5
278.607	3271
281.113	3288.5
283.619	3286.5
286.124	3322.5
288.627	3316
291.13	3338
293.632	3338
296.133	3375
298.634	3387
301.133	3364
303.63	3385.5
306.128	3378
308.625	3380
311.122	3359.5
313.617	3398
316.111	3373.5
318.604	3305
321.098	3345
323.588	3311.5
326.08	3314
328.569	3275.5
331.059	3298.5
333.548	3254.5
336.035	3272
338.521	3264.5
341.008	3193
343.492	3239.5
345.977	3311
348.46	3243
350.942	3259
353.425	3253.5
355.905	3276.5
358.385	3247.5
360.864	3250
363.342	3253
365.819	3249.5
368.296	3298.5
370.771	3238
373.246	3220
375.72	3236.5
378.194	3253.5
380.666	3249
383.138	3209.5
385.609	3214.5
388.079	3238
390.548	3254.5
393.016	3216
395.483	3248.5
397.95	3244
400.416	3257.5
402.88	3244.5
405.345	3305
407.807	3302
410.27	3326
412.731	3326.5
415.193	3342
417.652	3367.5
420.112	3403
422.569	3351.5
425.028	3418.5
427.484	3391
429.939	3411.5
432.394	3454
434.849	3443
437.302	3457
439.754	3446
442.205	3461
444.656	3425.5
447.106	3419
449.555	3414
452.003	3376
454.45	3379
456.897	3401.5
459.343	3416
461.788	3408
464.232	3372.5
466.676	3412
469.119	3449
471.559	3418
474.001	3396.5
476.441	3466
478.879	3448.5
481.318	3423.5
483.756	3421
486.192	3419.5
488.629	3448
491.063	3465.5
493.498	3453.5
495.931	3464
498.365	3441
500.796	3466.5
503.226	3502
505.657	3485.5
508.086	3487.5
510.515	3447.5
512.942	3503.5
515.369	3477
517.796	3530
520.221	3508
522.645	3472
525.069	3509.5
527.492	3464.5
529.914	3470
532.335	3482
534.756	3485.5
537.175	3443
539.593	3478.5
542.011	3490
544.429	3448.5
546.845	3482.5
549.261	3474.5
551.675	3495.5
554.089	3459
556.503	3450.5
558.914	3478.5
561.326	3436
563.736	3492.5
566.147	3525
568.555	3483.5
570.964	3492.5
573.371	3479
575.777	3510
578.184	3491
580.588	3440
582.992	3512.5
585.395	3513.5
587.799	3530
590.201	3507.5
592.601	3532
595.001	3496
597.401	3525.5
599.799	3549
602.197	3517.5
604.594	3552.5
606.99	3534.5
609.386	3539
611.78	3579.5
614.174	3596
616.566	3599
618.958	3601.5
621.35	3578.5
623.741	3625
626.13	3601.5
628.519	3644
630.908	3638
633.295	3649
635.682	3683.5
638.067	3657.5
640.453	3693.5
642.836	3697
645.219	3655.5
647.602	3677
649.984	3648
652.364	3663.5
654.745	3673.5
657.124	3712
659.503	3655
661.88	3620.5
664.257	3697.5
666.635	3614.5
669.01	3651.5
671.384	3667
673.758	3632
676.131	3650.5
678.502	3665.5
680.874	3640
683.245	3616
685.615	3620
687.984	3598.5
690.353	3626
692.719	3593.5
695.086	3566.5
697.453	3599
699.817	3549
702.182	3578.5
704.545	3621
706.908	3599.5
709.27	3605.5
711.632	3582
713.991	3601.5
716.352	3604.5
718.71	3642.5
721.068	3602.5
723.426	3591.5
725.782	3593
728.138	3654
730.492	3624.5
732.846	3653
735.201	3659.5
737.553	3612
739.905	3628
742.256	3628
744.606	3642
746.956	3626
749.303	3643.5
751.651	3614.5
753.999	3657.5
756.345	3570
758.691	3623
761.035	3620.5
763.379	3619
765.723	3612
768.064	3590
770.407	3622.5
772.748	3599
775.088	3565.5
777.427	3625.5
779.765	3607
782.104	3583
784.44	3598
786.776	3582
789.113	3629.5
791.447	3605
793.78	3603
796.113	3661.5
798.445	3601.5
800.778	3644
803.109	3616.5
805.439	3676
807.768	3635.5
810.096	3669.5
812.424	3640
814.751	3695.5
817.078	3673
819.402	3708.5
821.727	3702
824.051	3668.5
826.374	3703.5
828.697	3684.5
831.018	3761.5
833.339	3706.5
835.659	3685.5
837.978	3700.5
840.297	3745
842.614	3755.5
844.932	3727.5
847.247	3679.5
849.562	3701.5
851.878	3700.5
854.191	3714
856.504	3714.5
858.817	3738
861.129	3755
863.439	3720
865.749	3728
868.058	3706.5
870.367	3656.5
872.676	3687
874.983	3652
877.289	3666
879.593	3681
881.898	3691.5
884.202	3669
886.506	3620.5
888.808	3653.5
891.11	3630
893.41	3603
895.711	3611.5
898.011	3600
900.309	3563.5
902.607	3594
904.904	3531.5
907.201	3573
909.496	3566
911.791	3595
914.085	3542
916.379	3549.5
918.671	3524
920.963	3565
923.255	3553.5
925.545	3568.5
927.834	3562.5
930.123	3541
932.411	3553.5
934.698	3615.5
936.985	3573.5
939.271	3598.5
941.556	3551
943.84	3571
946.124	3593
948.407	3590
950.689	3568
952.971	3610.5
955.25	3576
957.531	3562
959.81	3586
962.088	3638
964.366	3623
966.643	3599
968.919	3614
971.195	3600
973.469	3599
975.743	3658
978.016	3548.5
980.288	3570.5
982.56	3620
984.831	3604
987.101	3595.5
989.37	3628.5
991.638	3605.5
993.907	3609
996.174	3678.5
998.44	3765
1000.71	3756.5
1002.97	3671.5
1005.24	3626
1007.5	3604
1009.76	3546.5
1012.02	3568
1014.28	3609
1016.54	3615.5
1018.8	3571
1021.06	3539.5
1023.32	3569.5
1025.58	3596.5
1027.84	3606
1030.09	3589
1032.35	3606
1034.6	3590.5
1036.86	3595
1039.11	3601
1041.36	3539
1043.61	3600
1045.86	3609.5
1048.11	3581
1050.36	3639.5
1052.61	3652
1054.86	3630
1057.11	3638.5
1059.35	3619.5
1061.6	3661
1063.84	3634
1066.09	3620.5
1068.33	3616
1070.57	3616
1072.82	3616
1075.06	3629
1077.3	3604.5
1079.54	3561.5
1081.78	3608.5
1084.02	3619.5
1086.25	3562
1088.49	3602
1090.73	3602
1092.96	3601
1095.2	3627.5
1097.43	3610.5
1099.66	3627.5
1101.9	3630.5
1104.13	3578.5
1106.36	3581.5
1108.59	3619.5
1110.82	3584
1113.05	3553.5
1115.28	3588.5
1117.51	3562
1119.73	3549.5
1121.96	3587
1124.18	3581
1126.41	3583.5
1128.63	3625.5
1130.85	3592
1133.08	3587.5
1135.3	3600
1137.52	3664.5
1139.74	3560.5
1141.96	3647
1144.18	3631
1146.4	3635.5
1148.61	3650.5
1150.83	3664.5
1153.05	3700.5
1155.26	3737.5
1157.48	3760
1159.69	3798.5
1161.9	3799.5
1164.11	3813.5
1166.33	3858.5
1168.54	3869
1170.75	3867.5
1172.96	3856
1175.17	3844
1177.37	3842
1179.58	3817.5
1181.79	3808.5
1183.99	3750
1186.2	3779
1188.4	3751
1190.61	3771.5
1192.81	3711
1195.01	3732.5
1197.21	3739.78
1199.42	3742.49
1201.61	3739.19
1203.81	3748.99
1206.01	3709.34
1208.21	3706.63
1210.41	3703.29
1212.61	3700.86
1214.8	3731.59
1217	3687.66
1219.19	3658.7
1221.38	3701.75
1223.58	3699.55
1225.77	3675.96
1227.96	3715.87
1230.15	3688.73
1232.34	3702.97
1234.53	3711.42
1236.72	3711.7
1238.91	3674.99
1241.1	3707.94
1243.28	3715.83
1245.47	3699.64
1247.65	3712.16
1249.84	3757.3
1252.02	3744.9
1254.21	3749.38
1256.39	3752.88
1258.57	3748.41
1260.75	3771.62
1262.93	3776.63
1265.11	3781.27
1267.29	3785.01
1269.47	3803.04
1271.65	3788.58
1273.82	3807.84
1276	3793.69
1278.17	3791.19
1280.35	3775.35
1282.52	3798.36
1284.69	3810.63
1286.87	3846.7
1289.04	3835.51
1291.21	3827.62
1293.38	3817.71
1295.55	3798.27
1297.72	3815.5
1299.89	3789.91
1302.06	3774.03
1304.22	3768.23
1306.39	3776.71
1308.43	3799.5
1310.6	3804
1312.78	3721
1314.96	3730
1317.13	3744.5
1319.3	3717
1321.47	3752.5
1323.65	3720.5
1325.82	3737
1327.99	3729
1330.16	3695
1332.32	3697
1334.49	3730.5
1336.66	3702.5
1338.83	3619
1340.99	3677
1343.16	3684.5
1345.32	3680
1347.49	3673
1349.65	3665
1351.81	3682.5
1353.98	3655
1356.14	3675
1358.3	3626
1360.46	3648.5
1362.62	3660.5
1364.78	3605
1366.93	3635.5
1369.09	3616
1371.25	3567
1373.4	3589
1375.56	3597
1377.71	3570
1379.87	3601
1382.02	3560.5
1384.17	3586
1386.32	3549
1388.47	3551
1390.63	3527.5
1392.77	3489
1394.92	3484
1397.07	3489
1399.22	3515.5
1401.37	3491.5
1403.51	3480
1405.66	3504.5
1407.8	3514
1409.95	3450.5
1412.09	3448.5
1414.23	3470.5
1416.38	3460.5
1418.52	3480
1420.66	3425
1422.8	3442
1424.94	3454.5
1427.08	3424.5
1429.21	3461
1431.35	3454
1433.49	3422
1435.63	3448
1437.76	3450
1439.89	3486
1442.03	3474.5
1444.16	3464
1446.3	3455.5
1448.43	3510
1450.56	3442.5
1452.69	3454.5
1454.82	3436
1456.95	3479.5
1459.08	3469
1461.2	3454.5
1463.33	3469.5
1465.46	3521
1467.58	3454.5
1469.71	3458.5
1471.83	3468
1473.96	3457
1476.08	3446
1478.2	3492
1480.33	3493
1482.45	3469
1484.57	3547
1486.69	3472
1488.81	3502.5
1490.93	3499.5
1493.04	3554.5
1495.16	3535.5
1497.28	3489
1499.39	3545
1501.51	3559
1503.62	3562.5
1505.74	3581
1507.85	3549.5
1509.96	3572
1512.07	3582.5
1514.19	3638
1516.3	3589
1518.41	3657
1520.52	3637
1522.62	3668.5
1524.73	3650.5
1526.84	3639.5
1528.95	3666.5
1531.05	3641
1533.16	3606.5
1535.26	3606.5
1537.37	3609.5
1539.47	3573.5
1541.57	3606.5
1543.67	3575
1545.78	3623.5
1547.88	3626
1549.98	3618.5
1552.07	3623.5
1554.17	3659.5
1556.27	3636
1558.37	3648.5
1560.47	3639
1562.56	3670.5
1564.66	3655.5
1566.75	3605.5
1568.85	3621.5
1570.94	3644
1573.03	3588
1575.12	3627
1577.21	3612
1579.31	3597
1581.4	3618.5
1583.49	3630.5
1585.57	3589
1587.66	3628.5
1589.75	3637.5
1591.84	3624
1593.92	3617
1596.01	3629.5
1598.09	3571.5
1600.18	3590.5
1602.26	3539.5
1604.34	3490
1606.43	3442.5
1608.51	3478
1610.59	3389
1612.67	3281
1614.75	3250
1616.83	3286.5
1618.91	3224
1620.98	3157
1623.06	3099.5
1625.14	3060
1627.21	3031
1629.29	2993
1631.36	2954.5
1633.43	2940.5
1635.51	2870
1637.58	2817
1639.65	2818.5
1641.72	2769.5
1643.79	2761.5
1645.86	2619.5
1647.93	2664.5
1650	2599.5
1652.07	2584.5
1654.14	2544
1656.2	2515.5
1658.27	2495.5
1660.34	2466
1662.4	2425.5
1664.46	2439
1666.53	2436
1668.59	2395
1670.65	2347
1672.71	2334.5
1674.77	2334
1676.83	2297
1678.89	2317
1680.95	2280
1683.01	2299.5
1685.07	2288
1687.13	2219
1689.18	2237
1691.24	2201.5
1693.29	2223
1695.35	2229
1697.4	2186.5
1699.45	2170.5
1701.51	2209.5
1703.56	2159.5
1705.61	2164
1707.66	2110.5
1709.71	2120.5
1711.76	2111
1713.81	2099.5
1715.86	2089
1717.9	2109.5
1719.95	2060
1722	2084.5
1724.04	2047
1726.09	2071.5
1728.13	2024.5
1730.17	2053.5
1732.22	2018.5
1734.26	2013
1736.3	2022.5
1738.34	1998.5
1740.38	2035.5
1742.42	1998
1744.46	1959
1746.5	1968.5
1748.54	1942.5
1750.57	1963.5
1752.61	1928
1754.65	1926
1756.68	1925.5
1758.72	1909
1760.75	1926
1762.78	1891.5
1764.82	1905
1766.85	1881
1768.88	1873
1770.91	1881
1772.94	1863.5
1774.97	1850.5
1777	1857
1779.03	1830.5
1781.06	1828.5
1783.08	1846
1785.11	1822.5
1787.14	1821
1789.16	1825.5
1791.18	1777
1793.21	1806.5
1795.23	1821
1797.26	1786.5
1799.28	1758.5
1801.3	1766
1803.32	1788.5
1805.34	1760
1807.36	1719.5
1809.38	1726.5
1811.4	1732
1813.41	1716.5
1815.43	1722
1817.45	1725
1819.46	1710.5
1821.48	1725
1823.49	1719
1825.51	1693.5
1827.52	1709
1829.53	1703
1831.54	1687
1833.56	1680
1835.57	1659
1837.58	1676.5
1839.59	1636
1841.59	1646.5
1843.6	1634.5
1845.61	1651
1847.62	1635
1849.62	1621
1851.63	1642.5
1853.64	1608.5
1855.64	1613.5
1857.64	1610
1859.65	1626
1861.65	1614
1863.65	1594.5
1865.65	1573
1867.65	1573
1869.65	1569
1871.65	1565.5
1873.65	1555
1875.65	1573
1877.65	1550.5
1879.65	1543
1881.64	1553.5
1883.64	1538.5
1885.63	1570
1887.63	1543
1889.62	1563.5
1891.62	1529.5
1893.61	1514
1895.6	1504.5
1897.59	1537.5
1899.58	1497.5
1901.57	1488
1903.56	1525.5
1905.55	1526.5
1907.54	1514
1909.53	1487.5
1911.52	1511
1913.5	1485
1915.49	1500.5
1917.48	1494.5
1919.46	1489
1921.44	1449.5
1923.43	1484.5
1925.41	1464.5
1927.39	1473
1929.38	1467.5
1931.36	1451.5
1933.34	1455.5
1935.32	1459
1937.3	1454
1939.28	1440.5
1941.25	1464.5
1943.23	1453.5
1945.21	1438
1947.18	1442.5
1949.16	1463
1951.13	1426.5
1953.11	1431.5
1955.08	1399
1957.06	1414.5
1959.03	1416.5
1961	1417
1962.97	1388.5
1964.94	1391
1966.91	1399.5
1968.88	1395.5
1970.85	1397
1972.82	1367
1974.79	1367.5
1976.76	1366.5
1978.72	1391
1980.69	1370.5
1982.65	1370
1984.62	1369
1986.58	1360.5
1988.55	1355
1990.51	1331.5
1992.47	1352.5
1994.43	1342.5
1996.39	1364
1998.36	1327.5
2000.31	1345
2002.27	1333.5
2004.23	1342.5
2006.19	1317.5
2008.15	1343
2010.11	1314.5
2012.06	1330.5
2014.02	1311
2015.97	1279
2017.93	1313
2019.88	1326
2021.83	1307
2023.79	1312
2025.74	1302
2027.69	1296.5
2029.64	1295.5
2031.59	1290.5
2033.54	1292.5
2035.49	1276
2037.44	1279.5
2039.39	1284
2041.34	1281.5
2043.28	1270.5
2045.23	1287.5
2047.17	1258
2049.12	1283
2051.06	1266
2053.01	1276
2054.95	1259
2056.89	1234
2058.84	1236
2060.78	1234.5
2062.72	1257.5
2064.66	1230.5
2066.6	1228
2068.54	1235
2070.48	1234.5
2072.41	1232
2074.35	1198.5
2076.29	1223.5
2078.22	1235.5
2080.16	1198.5
2082.09	1245.5
2084.03	1233.5
2085.96	1210.5
2087.9	1234.5
2089.83	1227.5
2091.76	1211.5
2093.69	1201
2095.62	1207
2097.55	1236.5
2099.48	1212.5
2101.41	1219
2103.34	1240.5
2105.27	1239
2107.19	1240
2109.12	1257.5
2111.05	1257.5
2112.97	1269
2114.9	1321.5
2116.82	1330
2118.75	1400.5
2120.67	1405
2122.59	1433
2124.51	1464
2126.43	1473
2128.36	1472
2130.28	1490.5
2132.2	1440.5
2134.11	1460.5
2136.03	1456.5
2137.95	1400.5
2139.87	1379.5
2141.78	1366
2143.7	1366.5
2145.62	1338.62
2147.53	1337.22
2149.45	1309.13
2151.36	1293.95
2153.27	1275.76
2155.19	1265.4
2157.1	1275.74
2159.01	1243.03
2160.92	1221.02
2162.83	1221.91
2164.74	1196.78
2166.65	1167.54
2168.56	1172.11
2170.47	1176.3
2172.37	1164.76
2174.28	1138.37
2176.19	1140.03
2178.09	1131.57
2180	1100.62
2181.9	1102.95
2183.81	1100.88
2185.71	1093.83
2187.61	1074.63
2189.51	1058.38
2191.42	1072.83
2193.32	1042.82
2195.22	1030
2197.12	1045.49
2199.02	1036.17
2200.92	1037.46
2202.81	1039.45
2204.71	1018.64
2206.61	1024.68
2208.5	1018.89
2210.4	1036.68
2212.3	1017.38
2214.19	1021.32
2216.08	1017.22
2217.98	1003.18
2219.87	1012.9
2221.76	1002.81
2223.65	995.566
2225.55	1002.71
2227.44	1005.82
2229.33	989.361
2231.22	1001.99
2233.11	999.331
2234.99	983.223
2236.88	983.954
2238.77	978.682
2240.66	993.452
2242.06	1010.5
2243.96	1011.5
2245.85	1009.5
2247.75	993.5
2249.64	976.5
2251.54	1005.5
2253.43	984
2255.32	982
2257.21	967.5
2259.1	945.5
2260.99	953
2262.89	955.5
2264.77	934
2266.66	920
2268.55	942
2270.44	922
2272.33	906
2274.21	917
2276.1	909
2277.98	904.5
2279.87	926.5
2281.75	918
2283.64	914.5
2285.52	898
2287.4	893.5
2289.29	887.5
2291.17	912.5
2293.05	898
2294.93	893.5
2296.81	881
2298.69	900.5
2300.57	891.5
2302.44	881
2304.32	887.5
2306.2	888.5
2308.08	867.5
2309.95	881.5
2311.83	863
2313.7	882
2315.58	857.5
2317.45	873.5
2319.32	853.5
2321.2	868.5
2323.07	864.5
2324.94	857.5
2326.81	840
2328.68	874
2330.55	844.5
2332.42	849
2334.29	850.5
2336.16	840.5
2338.02	826
2339.89	853.5
2341.76	844.5
2343.62	822.5
2345.49	838.5
2347.35	827.5
2349.22	847.5
2351.08	841.5
2352.94	845.5
2354.81	811.5
2356.67	814
2358.53	830
2360.39	834
2362.25	834
2364.11	823
2365.97	822
2367.83	826.5
2369.69	825
2371.55	808
2373.4	822.5
2375.26	810.5
2377.11	823.5
2378.97	778.5
2380.83	799.5
2382.68	785.5
2384.53	804
2386.39	797.5
2388.24	798
2390.09	788
2391.94	786.5
2393.79	777
2395.64	786.5
2397.49	780
2399.34	793.5
2401.19	794.5
2403.04	788
2404.89	777
2406.74	774
2408.58	773
2410.43	766
2412.27	750
2414.12	759
2415.96	781
2417.81	756.5
2419.65	766
2421.49	760.5
2423.34	766.5
2425.18	747.5
2427.02	757
2428.86	760.5
2430.7	743
2432.54	758.5
2434.38	767
2436.22	740
2438.05	746.5
2439.89	732.5
2441.73	737
2443.56	738
2445.4	748.5
2447.24	737.5
2449.07	727.5
2450.9	750
2452.74	750
2454.57	732.5
2456.4	733
2458.23	720
2460.07	720.5
2461.9	724
2463.73	705
2465.56	715.5
2467.39	696.5
2469.21	717
2471.04	724.5
2472.87	703
2474.7	706
2476.52	709
2478.35	728.5
2480.17	704
2482	728
2483.82	707
2485.65	719
2487.47	730
2489.29	708.5
2491.12	688.5
2492.94	715.5
2494.76	692
2496.58	706
2498.4	698.5
2500.22	674
2502.04	697
2503.86	688
2505.67	677
2507.49	678
2509.31	683.5
2511.12	673.5
2512.94	687
2514.76	679.5
2516.57	670
2518.38	684
2520.2	677
2522.01	666
2523.82	664.5
2525.64	655.5
2527.45	660.5
2529.26	658
2531.07	665.5
2532.88	659.5
2534.69	651
2536.5	666
2538.31	639.5
2540.11	667.5
2541.92	650
2543.73	644
2545.53	672
2547.34	650
2549.14	639
2550.95	656
2552.75	641
2554.56	648.5
2556.36	629
2558.16	645.5
2559.96	628
2561.76	618.5
2563.57	617
2565.37	616
2567.17	634.5
2568.96	631.5
2570.76	641.5
2572.56	630.5
2574.36	604.5
2576.16	609
2577.95	622
2579.75	621
2581.54	621
2583.34	630
2585.13	606
2586.93	603.5
2588.72	598
2590.51	618
2592.31	616
2594.1	598
2595.89	601
2597.68	601.5
2599.47	594.5
2601.26	616
2603.05	591.5
2604.84	601
2606.63	601.5
2608.42	602
2610.2	608
2611.99	604
2613.78	599.5
2615.56	599
2617.35	600.5
2619.13	584
2620.91	594
2622.7	587
2624.48	581
2626.26	577
2628.04	583
2629.83	564
2631.61	564.5
2633.39	568
2635.17	561
2636.95	564
2638.73	575.5
2640.5	560
2642.28	582
2644.06	562.5
2645.84	570
2647.61	574
2649.39	562.5
2651.16	563.5
2652.94	551.5
2654.71	531
2656.49	567
2658.26	541.5
2660.03	557.5
2661.8	535
2663.57	548.5
2665.35	549.5
2667.12	537.5
2668.89	547
2670.66	554.5
2672.42	543
2674.19	546.5
2675.96	539.5
2677.73	558
2679.49	538
2681.26	535.5
2683.03	541
2684.79	530
2686.56	540
2688.32	539.5
2690.09	542.5
2691.85	537
2693.61	534.5
2695.37	540.5
2697.14	515
2698.9	523.5
2700.66	514
2702.42	519
2704.18	538.5
2705.94	518
2707.7	506
2709.45	517
2711.21	529
2712.97	526
2714.72	537.5
2716.48	508
2718.24	524.5
2719.99	526
2721.75	495
2723.5	531
2725.25	517.5
2727.01	502
2728.76	509.5
2730.51	508.5
2732.26	503
2734.01	509
2735.76	499
2737.51	513
2739.26	499.5
2741.01	511.5
2742.76	503
2744.51	510
2746.26	494
2748	493
2749.75	495
2751.5	499
2753.24	482
2754.99	497
2756.73	492
2758.47	493
2760.22	476
2761.96	487
2763.7	495
2765.44	478.5
2767.19	481.5
2768.93	476
2770.67	488
2772.41	467
2774.15	460
2775.89	476
2777.62	476
2779.36	478.5
2781.1	459
2782.84	459
2784.57	477
2786.31	464
2788.04	455.5
2789.78	487
2791.51	455.5
2793.24	459.5
2794.98	453.5
2796.71	468.5
2798.44	457.5
2800.18	455
2801.91	454
2803.64	451
2805.37	454
2807.1	457
2808.83	461
2810.55	452
2812.28	456
2814.01	443
2815.74	449.5
2817.46	458.5
2819.19	444.5
2820.92	441.5
2822.64	425
2824.37	433.5
2826.09	447
2827.81	434
2829.54	451
2831.26	440.5
2832.98	443.5
2834.71	457.5
2836.43	448
2838.15	438
2839.87	460.5
2841.59	444
2843.31	440.5
2845.02	448.5
2846.74	453
2848.46	467.5
2850.18	472.5
2851.9	464.5
2853.61	467
2855.33	446.5
2857.04	454
2858.76	457
2860.47	467
2862.19	455.5
2863.9	455
2865.61	460
2867.32	460.5
2869.04	452
2870.75	455.5
2872.46	453.5
2874.17	463
2875.88	453
2877.59	460
2879.3	442
2881	468
2882.71	466.5
2884.42	457.5
2886.13	458.5
2887.83	456
2889.54	434
2891.24	464.5
2892.95	448.5
2894.65	456
2896.36	450.5
2898.06	455
2899.76	449
2901.47	478.5
2903.17	450
2904.87	451
2906.57	446
2908.27	453
2909.97	473
2911.67	463
2913.37	452
2915.07	475.5
2916.77	475.5
2918.47	480.5
2920.16	463.5
2921.86	472
2923.55	470
2925.25	474
2926.94	461
2928.64	453
2930.33	472.5
2932.03	463.5
2933.72	475.5
2935.41	476.5
2937.11	470
2938.8	458
2940.49	465.5
2942.18	469.5
2943.87	472
2945.56	450
2947.25	450.5
2948.94	431
2950.63	444
2952.31	426.5
2954	420.5
2955.69	400.5
2957.37	412
2959.06	427
2960.75	412.5
2962.43	418.5
2964.11	414
2965.8	403
2967.48	399
2969.16	392
2970.85	392
2972.53	402
2974.21	411
2975.89	374
2977.57	387
2979.25	380
2980.93	393.5
2982.61	385
2984.29	383
2985.97	379.5
2987.65	369
2989.32	364.5
2991	363
2992.68	361
2994.35	368
2996.03	359
2997.7	345.5
2999.38	359.5