File: muestras/ogompa/nsno_08.txt
#Acq. time (s)=	5
#Accumulations=	5
#Range (cm-¹)=	100...3000
#Windows=	3
#Autofocus=	Off
#AutoExposure=	Off
#Spike filter=	Multiple accum.
#Delay time (s)=	0
#Binning=	1
#Readout mode=	Signal
#DeNoise=	Off
#ICS correction=	Off
#Dark correction=	Off
#Inst. Process=	Off
#Instrument=	LabRAM HR Evol
#Detector=	Syncerity OE
#Objective=	x100_VIS_LWD
#Grating=	600 (500nm)
#ND Filter=	100%
#Laser=	633nm_Edge
#Hole=	100.021
#Range=	Visible
#Project=	Omar
#Sample=	chi
#Site=	f
#Title=	nsno
#Remark=
#Date=	12.09.2023 17:06
#Acquired=	12.09.2023 17:06:44
101.026	5431
103.592	5358
106.158	5252.5
108.723	5241.5
111.289	5102.5
113.852	5034.5
116.415	4975
118.976	4903
121.537	4846
124.097	4817
126.656	4782
129.215	4785
131.772	4695
134.327	4660
136.883	4591
139.438	4546.5
141.992	4488.5
144.545	4379.5
147.096	4363
149.648	4255.5
152.199	4267.5
154.747	4181
157.296	4105.5
159.843	4109.5
162.391	4065.5
164.937	4037
167.482	3984
170.025	3991
172.569	3939.5
175.111	3967.5
177.654	3922
180.194	3914.5
182.733	3914
185.273	3880
187.811	3829
190.348	3887
192.884	3918.5
195.419	3942
197.955	3904.5
200.489	3937.5
203.022	3951
205.554	3947
208.085	3946
210.615	3966
213.144	3977.5
215.673	4011
218.201	3947
220.728	4009
223.253	3957.5
225.778	4015
228.303	4021.5
230.826	3985.5
233.348	3995.5
235.87	4005
238.391	3964.5
240.91	4053
243.43	4040.5
245.949	4045
248.465	4018
250.983	4080.5
253.498	4052
256.013	4079
258.526	4055.5
261.039	4046.5
263.552	4025.5
266.063	4021
268.573	4052.5
271.084	4080
273.592	4070
276.1	4026.5
278.607	4039
281.113	4075
283.619	4069.5
286.124	4097.5
288.627	4120.5
291.13	4176
293.632	4180
296.133	4222.5
298.634	4233
301.133	4232
303.63	4239.5
306.128	4200
308.625	4263
311.122	4259
313.617	4185.5
316.111	4212
318.604	4207.5
321.098	4187.5
323.588	4148.5
326.08	4131.5
328.569	4107.5
331.059	4078.5
333.548	4099.5
336.035	4072.5
338.521	4035.5
341.008	4052
343.492	4031.5
345.977	4090
348.46	4063.5
350.942	4071.5
353.425	4090.5
355.905	4102
358.385	4080.5
360.864	4094
363.342	4125
365.819	4050
368.296	4100
370.771	4067.5
373.246	4070
375.72	4078.5
378.194	4094.5
380.666	4046
383.138	4042
385.609	4039.5
388.079	4047
390.548	4027
393.016	4074.5
395.483	4022
397.95	4039.5
400.416	4070.5
402.88	4081.5
405.345	4109.5
407.807	4146
410.27	4176.5
412.731	4143.5
415.193	4192
417.652	4191
420.112	4241
422.569	4212.5
425.028	4222.5
427.484	4298
429.939	4248.5
432.394	4290
434.849	4308
437.302	4298
439.754	4336
442.205	4328
444.656	4265
447.106	4267.5
449.555	4271
452.003	4265.5
454.45	4283.5
456.897	4259.5
459.343	4223
461.788	4244
464.232	4243.5
466.676	4223.5
469.119	4280
471.559	4276
474.001	4236
476.441	4274.5
478.879	4238
481.318	4308
483.756	4302
486.192	4270
488.629	4321.5
491.063	4350.5
493.498	4307.5
495.931	4357
498.365	4344.5
500.796	4336
503.226	4330.5
505.657	4361
508.086	4386.5
510.515	4395.5
512.942	4361.5
515.369	4310.5
517.796	4359.5
520.221	4318
522.645	4378
525.069	4354
527.492	4348.5
529.914	4357
532.335	4322.5
534.756	4337
537.175	4325
539.593	4301.5
542.011	4269.5
544.429	4314.5
546.845	4292.5
549.261	4305.5
551.675	4361
554.089	4317
556.503	4308.5
558.914	4342.5
561.326	4353
563.736	4357
566.147	4336
568.555	4371.5
570.964	4306
573.371	4358.5
575.777	4330.5
578.184	4362.5
580.588	4370
582.992	4349.5
585.395	4346
587.799	4357.5
590.201	4365.5
592.601	4341.5
595.001	4356
597.401	4411.5
599.799	4372
602.197	4376.5
604.594	4387.5
606.99	4417
609.386	4434
611.78	4372.5
614.174	4475
616.566	4444.5
618.958	4442
621.35	4454.5
623.741	4493
626.13	4489.5
628.519	4530
630.908	4538.5
633.295	4534.5
635.682	4574
638.067	4583.5
640.453	4567
642.836	4563
645.219	4567.5
647.602	4630.5
649.984	4627.5
652.364	4602.5
654.745	4563.5
657.124	4539.5
659.503	4566
661.88	4540
664.257	4548
666.635	4554.5
669.01	4517
671.384	4508
673.758	4522
676.131	4471.5
678.502	4505
680.874	4428
683.245	4432.5
685.615	4435.5
687.984	4469
690.353	4415.5
692.719	4397.5
695.086	4403
697.453	4403.5
699.817	4450
702.182	4449
704.545	4408
706.908	4431.5
709.27	4421.5
711.632	4399.5
713.991	4413.5
716.352	4394
718.71	4437
721.068	4404
723.426	4433
725.782	4465
728.138	4480
730.492	4502.5
732.846	4425.5
735.201	4491.5
737.553	4422
739.905	4431.5
742.256	4422
744.606	4490
746.956	4482.5
749.303	4455
751.651	4430.5
753.999	4483.5
756.345	4426
758.691	4459.5
761.035	4454
763.379	4368
765.723	4418
768.064	4405
770.407	4422
772.748	4403.5
775.088	4437.5
777.427	4337.5
779.765	4444.5
782.104	4432.5
784.44	4414.5
786.776	4465.5
789.113	4408
791.447	4398
793.78	4406.5
796.113	4418.5
798.445	4398.5
800.778	4453
803.109	4475.5
805.439	4428
807.768	4476
810.096	4479.5
812.424	4481
814.751	4502.5
817.078	4525.5
819.402	4457.5
821.727	4507.5
824.051	4478
826.374	4476
828.697	4495.5
831.018	4547
833.339	4494
835.659	4559
837.978	4537.5
840.297	4475.5
842.614	4509.5
844.932	4509.5
847.247	4538.5
849.562	4551
851.878	4559
854.191	4553.5
856.504	4569
858.817	4559
861.129	4531.5
863.439	4537
865.749	4551
868.058	4475.5
870.367	4500.5
872.676	4487
874.983	4437.5
877.289	4428.5
879.593	4430.5
881.898	4395.5
884.202	4428.5
886.506	4384.5
888.808	4373.5
891.11	4383.5
893.41	4407.5
895.711	4390
898.011	4354
900.309	4325
902.607	4350
904.904	4339.5
907.201	4343
909.496	4353
911.791	4335
914.085	4338
916.379	4337
918.671	4339
920.963	4388.5
923.255	4310
925.545	4299.5
927.834	4328.5
930.123	4337.5
932.411	4397.5
934.698	4374.5
936.985	4315
939.271	4363.5
941.556	4289
943.84	4385.5
946.124	4325
948.407	4343.5
950.689	4374.5
952.971	4358.5
955.25	4393
957.531	4368
959.81	4395.5
962.088	4372
964.366	4368.5
966.643	4373.5
968.919	4362.5
971.195	4383.75
973.469	4379
975.743	4408.5
978.016	4386
980.288	4360.5
982.56	4339
984.831	4376
987.101	4338.5
989.37	4345
991.638	4390
993.907	4367
996.174	4336
998.44	4433.5
1000.71	4393.5
1002.97	4366
1005.24	4345.5
1007.5	4287
1009.76	4291
1012.02	4330.5
1014.28	4324
1016.54	4320
1018.8	4316
1021.06	4295.5
1023.32	4312.5
1025.58	4328.5
1027.84	4327.5
1030.09	4332
1032.35	4318.5
1034.6	4335
1036.86	4310.5
1039.11	4288
1041.36	4362.5
1043.61	4360
1045.86	4338.5
1048.11	4374.5
1050.36	4350
1052.61	4357
1054.86	4370.5
1057.11	4390
1059.35	4373.5
1061.6	4377
1063.84	4340.5
1066.09	4350
1068.33	4354
1070.57	4378
1072.82	4339
1075.06	4345
1077.3	4336.5
1079.54	4355
1081.78	4341
1084.02	4343
1086.25	4297
1088.49	4290.5
1090.73	4320.5
1092.96	4314.5
1095.2	4326.5
1097.43	4297
1099.66	4297.5
1101.9	4308.5
1104.13	4303
1106.36	4332.5
1108.59	4273
1110.82	4304.5
1113.05	4307
1115.28	4305.5
1117.51	4285.5
1119.73	4296
1121.96	4328
1124.18	4287.5
1126.41	4323.5
1128.63	4265.5
1130.85	4330.5
1133.08	4344.5
1135.3	4323
1137.52	4326.5
1139.74	4328.5
1141.96	4357
1144.18	4365
1146.4	4381
1148.61	4409.5
1150.83	4434.5
1153.05	4410.5
1155.26	4469.5
1157.48	4484
1159.69	4492.5
1161.9	4533
1164.11	4548
1166.33	4549.5
1168.54	4587.5
1170.75	4582.5
1172.96	4566
1175.17	4619
1177.37	4533
1179.58	4544.5
1181.79	4492
1183.99	4480
1186.2	4454.5
1188.4	4456.5
1190.61	4413.5
1192.81	4381
1195.01	4415.5
1197.21	4425.34
1199.42	4365.58
1201.61	4368.66
1203.81	4335.99
1206.01	4392.06
1208.21	4360.61
1210.41	4373.47
1212.61	4388.94
1214.8	4328.99
1217	4332.91
1219.19	4306.49
1221.38	4282.43
1223.58	4279.91
1225.77	4262.39
1227.96	4236.02
1230.15	4256.8
1232.34	4246.08
1234.53	4224.59
1236.72	4206.25
1238.91	4227.34
1241.1	4211.03
1243.28	4226.82
1245.47	4195.86
1247.65	4222.96
1249.84	4225.8
1252.02	4232
1254.21	4214.76
1256.39	4206.98
1258.57	4207.01
1260.75	4195.12
1262.93	4199.42
1265.11	4181.59
1267.29	4176.16
1269.47	4211.85
1271.65	4178.39
1273.82	4177.09
1276	4222.66
1278.17	4198.04
1280.35	4186.19
1282.52	4201.93
1284.69	4192.75
1286.87	4198.17
1289.04	4152.58
1291.21	4160.84
1293.38	4160.45
1295.55	4171.56
1297.72	4141.87
1299.89	4139.56
1302.06	4084.74
1304.22	4036.33
1306.39	4089.15
1308.43	4035
1310.6	4072
1312.78	4066
1314.96	4043.5
1317.13	4027.5
1319.3	4037.5
1321.47	3981.5
1323.65	4000
1325.82	4046.5
1327.99	3969
1330.16	3951.5
1332.32	3977
1334.49	3974
1336.66	3971
1338.83	3938.5
1340.99	3918
1343.16	3899
1345.32	3923.5
1347.49	3879
1349.65	3959.5
1351.81	3927.5
1353.98	3906.5
1356.14	3871.5
1358.3	3888
1360.46	3879.5
1362.62	3906
1364.78	3867
1366.93	3830.5
1369.09	3873
1371.25	3860
1373.4	3830
1375.56	3845
1377.71	3821.5
1379.87	3865
1382.02	3829
1384.17	3840.5
1386.32	3834.5
1388.47	3835.5
1390.63	3792.5
1392.77	3795
1394.92	3776
1397.07	3750
1399.22	3789
1401.37	3781
1403.51	3818.5
1405.66	3824
1407.8	3831.5
1409.95	3802
1412.09	3800
1414.23	3818.5
1416.38	3793.5
1418.52	3817
1420.66	3792.5
1422.8	3788.5
1424.94	3827
1427.08	3773
1429.21	3817
1431.35	3789.5
1433.49	3813.5
1435.63	3754
1437.76	3846.5
1439.89	3822.5
1442.03	3829.5
1444.16	3810
1446.3	3838
1448.43	3852
1450.56	3806.5
1452.69	3806.5
1454.82	3787
1456.95	3821
1459.08	3814
1461.2	3820.5
1463.33	3835
1465.46	3804.5
1467.58	3845
1469.71	3798
1471.83	3900
1473.96	3799
1476.08	3837
1478.2	3860.5
1480.33	3861
1482.45	3870.5
1484.57	3855
1486.69	3864.5
1488.81	3944.5
1490.93	3924
1493.04	3906
1495.16	3934.5
1497.28	3967
1499.39	3913.5
1501.51	3934.5
1503.62	3889
1505.74	3893
1507.85	3918
1509.96	3877
1512.07	3930.5
1514.19	3891
1516.3	3853
1518.41	3876
1520.52	3860
1522.62	3884.5
1524.73	3849
1526.84	3829.5
1528.95	3833
1531.05	3828
1533.16	3858.5
1535.26	3839
1537.37	3784.5
1539.47	3855.5
1541.57	3742
1543.67	3830.5
1545.78	3788
1547.88	3771
1549.98	3764.5
1552.07	3788
1554.17	3775
1556.27	3801.5
1558.37	3833
1560.47	3761
1562.56	3775
1564.66	3785.5
1566.75	3786.5
1568.85	3774.5
1570.94	3823
1573.03	3789
1575.12	3798.5
1577.21	3805
1579.31	3787
1581.4	3789.5
1583.49	3819
1585.57	3763
1587.66	3790.5
1589.75	3799
1591.84	3765
1593.92	3769
1596.01	3744
1598.09	3757
1600.18	3732.5
1602.26	3737
1604.34	3644.5
1606.43	3632.5
1608.51	3621
1610.59	3532
1612.67	3508
1614.75	3445.5
1616.83	3407.5
1618.91	3388.5
1620.98	3308.5
1623.06	3261
1625.14	3254
1627.21	3222.5
1629.29	3168.5
1631.36	3147
1633.43	3091
1635.51	3044
1637.58	3003.5
1639.65	2988
1641.72	2962.5
1643.79	2924
1645.86	2898.5
1647.93	2862
1650	2843.5
1652.07	2783
1654.14	2799
1656.2	2761
1658.27	2724
1660.34	2695.5
1662.4	2694
1664.46	2666.5
1666.53	2631.5
1668.59	2629.5
1670.65	2600
1672.71	2581
1674.77	2570.5
1676.83	2483
1678.89	2546
1680.95	2508
1683.01	2498
1685.07	2499.5
1687.13	2481.5
1689.18	2481.5
1691.24	2440.5
1693.29	2410.5
1695.35	2432.5
1697.4	2427.5
1699.45	2408.5
1701.51	2390.5
1703.56	2382.5
1705.61	2360.5
1707.66	2372
1709.71	2385
1711.76	2335.5
1713.81	2337
1715.86	2316.5
1717.9	2288
1719.95	2280.5
1722	2313.5
1724.04	2322.5
1726.09	2282
1728.13	2265
1730.17	2283
1732.22	2283.5
1734.26	2249
1736.3	2239.5
1738.34	2227
1740.38	2274.5
1742.42	2242.5
1744.46	2209
1746.5	2187.5
1748.54	2194
1750.57	2197.5
1752.61	2172
1754.65	2200
1756.68	2132
1758.72	2143.5
1760.75	2122
1762.78	2127.5
1764.82	2138.5
1766.85	2125
1768.88	2136
1770.91	2093
1772.94	2093
1774.97	2120
1777	2057.5
1779.03	2087
1781.06	2054
1783.08	2050
1785.11	2019
1787.14	2055.5
1789.16	2018
1791.18	2034
1793.21	2020
1795.23	2026
1797.26	2025.5
1799.28	1999.5
1801.3	2008.5
1803.32	1978.5
1805.34	1957
1807.36	1993
1809.38	1958
1811.4	1946.5
1813.41	1952.5
1815.43	1955
1817.45	1963
1819.46	1965
1821.48	1946
1823.49	1925.5
1825.51	1921
1827.52	1934.5
1829.53	1911.5
1831.54	1893.5
1833.56	1881
1835.57	1916
1837.58	1899.5
1839.59	1853
1841.59	1840.5
1843.6	1869.5
1845.61	1829.5
1847.62	1837
1849.62	1853.5
1851.63	1814.5
1853.64	1799.5
1855.64	1815
1857.64	1829
1859.65	1814
1861.65	1784
1863.65	1799
1865.65	1788.5
1867.65	1776.5
1869.65	1770
1871.65	1801.5
1873.65	1767
1875.65	1756
1877.65	1766
1879.65	1767.5
1881.64	1750
1883.64	1772.5
1885.63	1774.5
1887.63	1735
1889.62	1710
1891.62	1732.5
1893.61	1725
1895.6	1732.5
1897.59	1719
1899.58	1726
1901.57	1701.5
1903.56	1711.5
1905.55	1731.5
1907.54	1701
1909.53	1750
1911.52	1697.5
1913.5	1680.5
1915.49	1692
1917.48	1681
1919.46	1705
1921.44	1626
1923.43	1679.5
1925.41	1665
1927.39	1681.5
1929.38	1634
1931.36	1671
1933.34	1691.5
1935.32	1671
1937.3	1661
1939.28	1626
1941.25	1630.5
1943.23	1630.5
1945.21	1650
1947.18	1633
1949.16	1610
1951.13	1622
1953.11	1634.5
1955.08	1625.5
1957.06	1602
1959.03	1611.5
1961	1600.5
1962.97	1579
1964.94	1557
1966.91	1578.5
1968.88	1552.5
1970.85	1578
1972.82	1571
1974.79	1574.5
1976.76	1547.5
1978.72	1576.5
1980.69	1557
1982.65	1561.5
1984.62	1554
1986.58	1532.5
1988.55	1540
1990.51	1568
1992.47	1535.5
1994.43	1521
1996.39	1506.5
1998.36	1534
2000.31	1530.5
2002.27	1504
2004.23	1490
2006.19	1521.5
2008.15	1487.5
2010.11	1488
2012.06	1489
2014.02	1497
2015.97	1487.5
2017.93	1492
2019.88	1496
2021.83	1469.5
2023.79	1482
2025.74	1481.5
2027.69	1468.5
2029.64	1480
2031.59	1479
2033.54	1444
2035.49	1432
2037.44	1420
2039.39	1417
2041.34	1446
2043.28	1422
2045.23	1445
2047.17	1423.5
2049.12	1417
2051.06	1427.5
2053.01	1422
2054.95	1439
2056.89	1401.5
2058.84	1388.5
2060.78	1399.5
2062.72	1389.5
2064.66	1388.5
2066.6	1430.5
2068.54	1377
2070.48	1382.5
2072.41	1375
2074.35	1373.5
2076.29	1386.5
2078.22	1382.5
2080.16	1391.5
2082.09	1344.5
2084.03	1361.5
2085.96	1340.5
2087.9	1356
2089.83	1359
2091.76	1351
2093.69	1367
2095.62	1347.5
2097.55	1368
2099.48	1342.5
2101.41	1369.5
2103.34	1357.5
2105.27	1379
2107.19	1364
2109.12	1380.5
2111.05	1393
2112.97	1401
2114.9	1403
2116.82	1475
2118.75	1474
2120.67	1490.5
2122.59	1526.5
2124.51	1538
2126.43	1579.5
2128.36	1556.5
2130.28	1573.5
2132.2	1597
2134.11	1576.5
2136.03	1592
2137.95	1546.5
2139.87	1544.5
2141.78	1521.5
2143.7	1494.5
2145.62	1478.61
2147.53	1477.43
2149.45	1453.22
2151.36	1428.76
2153.27	1423.68
2155.19	1385.77
2157.1	1398.88
2159.01	1378.54
2160.92	1356.91
2162.83	1342.58
2164.74	1326.94
2166.65	1327.63
2168.56	1316.15
2170.47	1285.9
2172.37	1292.2
2174.28	1240.63
2176.19	1266.22
2178.09	1249.51
2180	1230.26
2181.9	1222.56
2183.81	1216.63
2185.71	1208.91
2187.61	1210.62
2189.51	1178.21
2191.42	1182.22
2193.32	1175.75
2195.22	1166.17
2197.12	1163.19
2199.02	1162.81
2200.92	1152.26
2202.81	1140.18
2204.71	1138.55
2206.61	1124.9
2208.5	1138.02
2210.4	1143.14
2212.3	1123.12
2214.19	1128.01
2216.08	1121.21
2217.98	1105.19
2219.87	1101.78
2221.76	1090.5
2223.65	1109.93
2225.55	1101
2227.44	1093.94
2229.33	1085.06
2231.22	1107.09
2233.11	1100.42
2234.99	1101.68
2236.88	1114.47
2238.77	1124.01
2240.66	1129.22
2242.06	1171
2243.96	1147
2245.85	1144
2247.75	1156
2249.64	1158.5
2251.54	1163
2253.43	1118.5
2255.32	1110.5
2257.21	1083.5
2259.1	1074
2260.99	1061.5
2262.89	1046.5
2264.77	1056.5
2266.66	1059
2268.55	1045
2270.44	1027
2272.33	1035.5
2274.21	1016
2276.1	998
2277.98	1012.5
2279.87	989
2281.75	1013.5
2283.64	1022.5
2285.52	990
2287.4	988
2289.29	996
2291.17	1002
2293.05	974.5
2294.93	998
2296.81	984
2298.69	985
2300.57	969
2302.44	977
2304.32	952
2306.2	971
2308.08	977
2309.95	970
2311.83	962
2313.7	953.5
2315.58	949.5
2317.45	961
2319.32	946.5
2321.2	949.5
2323.07	950
2324.94	943.5
2326.81	936
2328.68	937.5
2330.55	929.5
2332.42	941
2334.29	954.5
2336.16	964
2338.02	925
2339.89	940.5
2341.76	926.5
2343.62	913
2345.49	923.5
2347.35	899
2349.22	924.5
2351.08	910
2352.94	913.5
2354.81	915
2356.67	906
2358.53	900
2360.39	912
2362.25	931
2364.11	920
2365.97	900
2367.83	916
2369.69	911
2371.55	904
2373.4	876
2375.26	905
2377.11	901.5
2378.97	898
2380.83	891
2382.68	904.5
2384.53	882
2386.39	904
2388.24	876
2390.09	876.5
2391.94	890
2393.79	882
2395.64	855
2397.49	865
2399.34	853
2401.19	899
2403.04	867
2404.89	891.5
2406.74	866.5
2408.58	875
2410.43	851.5
2412.27	856
2414.12	851.5
2415.96	842
2417.81	850
2419.65	832
2421.49	867.5
2423.34	861
2425.18	853.5
2427.02	826.5
2428.86	849
2430.7	845
2432.54	844
2434.38	824
2436.22	819.5
2438.05	841.5
2439.89	847.5
2441.73	824.5
2443.56	856.5
2445.4	832.5
2447.24	817.5
2449.07	826.5
2450.9	821
2452.74	821
2454.57	803
2456.4	815.5
2458.23	837
2460.07	800
2461.9	823
2463.73	797
2465.56	809.5
2467.39	811.5
2469.21	816
2471.04	808
2472.87	817
2474.7	788.5
2476.52	800.5
2478.35	794
2480.17	805.5
2482	811
2483.82	815.5
2485.65	776
2487.47	808
2489.29	771
2491.12	787.5
2492.94	780.5
2494.76	791
2496.58	785
2498.4	789
2500.22	771
2502.04	777
2503.86	776
2505.67	770.5
2507.49	783.5
2509.31	765
2511.12	772.5
2512.94	788.5
2514.76	766
2516.57	745
2518.38	763
2520.2	784
2522.01	744
2523.82	755
2525.64	742
2527.45	745.5
2529.26	765.5
2531.07	754
2532.88	748.5
2534.69	765.5
2536.5	743
2538.31	737
2540.11	756
2541.92	754.5
2543.73	736
2545.53	745.5
2547.34	732
2549.14	741.5
2550.95	732
2552.75	741
2554.56	723
2556.36	706
2558.16	712
2559.96	735
2561.76	721
2563.57	728.5
2565.37	750.5
2567.17	728
2568.96	721
2570.76	714
2572.56	730
2574.36	711
2576.16	725
2577.95	706.5
2579.75	723
2581.54	711
2583.34	717
2585.13	695
2586.93	699
2588.72	695
2590.51	681
2592.31	695
2594.1	692
2595.89	698
2597.68	667
2599.47	696.5
2601.26	686
2603.05	687
2604.84	692.5
2606.63	683.5
2608.42	694
2610.2	689
2611.99	681.5
2613.78	683.5
2615.56	679
2617.35	658
2619.13	676.5
2620.91	667
2622.7	678
2624.48	678.5
2626.26	666
2628.04	671
2629.83	643.5
2631.61	664
2633.39	668.5
2635.17	652.5
2636.95	659
2638.73	664
2640.5	642
2642.28	643
2644.06	644.5
2645.84	644
2647.61	659
2649.39	657
2651.16	624.5
2652.94	643.5
2654.71	638
2656.49	633
2658.26	645
2660.03	645
2661.8	640
2663.57	637
2665.35	635
2667.12	627
2668.89	639.5
2670.66	617
2672.42	602
2674.19	641
2675.96	629
2677.73	624
2679.49	626
2681.26	633
2683.03	625
2684.79	626.5
2686.56	616
2688.32	616
2690.09	626
2691.85	613.5
2693.61	618
2695.37	615
2697.14	597.5
2698.9	620.5
2700.66	607.5
2702.42	603
2704.18	594
2705.94	614
2707.7	611.5
2709.45	598.5
2711.21	606.5
2712.97	587.5
2714.72	600
2716.48	601
2718.24	617
2719.99	607
2721.75	587
2723.5	599.5
2725.25	586.5
2727.01	580
2728.76	588
2730.51	585.5
2732.26	584
2734.01	577
2735.76	575
2737.51	590
2739.26	587
2741.01	587.5
2742.76	596.5
2744.51	587
2746.26	571.5
2748	573
2749.75	574.5
2751.5	589.5
2753.24	589
2754.99	581
2756.73	566
2758.47	576
2760.22	563
2761.96	572
2763.7	561.5
2765.44	572
2767.19	565
2768.93	545
2770.67	571.5
2772.41	560
2774.15	552.5
2775.89	568.5
2777.62	564.5
2779.36	540.5
2781.1	547
2782.84	550.5
2784.57	544
2786.31	546
2788.04	529
2789.78	561
2791.51	538
2793.24	542.5
2794.98	560.5
2796.71	549.5
2798.44	527
2800.18	541
2801.91	539
2803.64	540.25
2805.37	525
2807.1	534
2808.83	515
2810.55	536.5
2812.28	524.5
2814.01	533
2815.74	533.5
2817.46	542
2819.19	533
2820.92	509.5
2822.64	518.5
2824.37	508.5
2826.09	528
2827.81	508
2829.54	507.5
2831.26	533
2832.98	515
2834.71	520
2836.43	525.5
2838.15	537.5
2839.87	520
2841.59	519
2843.31	523
2845.02	520
2846.74	510
2848.46	530.5
2850.18	522
2851.9	544.5
2853.61	516.5
2855.33	522.5
2857.04	524.5
2858.76	528
2860.47	528.5
2862.19	520
2863.9	514
2865.61	521.5
2867.32	518
2869.04	522.5
2870.75	519.5
2872.46	535
2874.17	520
2875.88	527
2877.59	536
2879.3	506.5
2881	519.5
2882.71	509
2884.42	503
2886.13	527
2887.83	531
2889.54	527.5
2891.24	526
2892.95	533.5
2894.65	521.5
2896.36	520
2898.06	531
2899.76	510.5
2901.47	531
2903.17	523.5
2904.87	524
2906.57	517.5
2908.27	536.5
2909.97	523.5
2911.67	523
2913.37	520
2915.07	525.5
2916.77	526
2918.47	529.5
2920.16	525.5
2921.86	528
2923.55	551.5
2925.25	545.5
2926.94	553.5
2928.64	550
2930.33	547.5
2932.03	541
2933.72	558.5
2935.41	539
2937.11	550
2938.8	557
2940.49	548
2942.18	546
2943.87	553
2945.56	526
2947.25	529.5
2948.94	526.5
2950.63	516.5
2952.31	504
2954	509
2955.69	492
2957.37	493
2959.06	492.5
2960.75	484
2962.43	488
2964.11	476
2965.8	494
2967.48	491
2969.16	491
2970.85	481.5
2972.53	477
2974.21	472
2975.89	473
2977.57	483
2979.25	458.5
2980.93	461
2982.61	454.5
2984.29	458
2985.97	455
2987.65	452.5
2989.32	444
2991	445
2992.68	447.5
2994.35	446
2996.03	434
2997.7	430
2999.38	441.5