File: muestras/ogompa/nsno_07.txt
#Acq. time (s)=	5
#Accumulations=	5
#Range (cm-¹)=	100...3000
#Windows=	3
#Autofocus=	Off
#AutoExposure=	Off
#Spike filter=	Multiple accum.
#Delay time (s)=	0
#Binning=	1
#Readout mode=	Signal
#DeNoise=	Off
#ICS correction=	Off
#Dark correction=	Off
#Inst. Process=	Off
#Instrument=	LabRAM HR Evol
#Detector=	Syncerity OE
#Objective=	x100_VIS_LWD
#Grating=	600 (500nm)
#ND Filter=	100%
#Laser=	633nm_Edge
#Hole=	100.021
#Range=	Visible
#Project=	Omar
#Sample=	chi
#Site=	f
#Title=	nsno
#Remark=
#Date=	12.09.2023 17:03
#Acquired=	12.09.2023 17:03:16
101.026	2963.5
103.592	2910
106.158	2828.5
108.723	2776
111.289	2740
113.852	2689.5
116.415	2684.5
118.976	2641.5
121.537	2618.5
124.097	2564.5
126.656	2528
129.215	2528
131.772	2466
134.327	2433
136.883	2402.5
139.438	2390
141.992	2338
144.545	2287.5
147.096	2279
149.648	2241.5
152.199	2223
154.747	2200.5
157.296	2138.5
159.843	2135
162.391	2143
164.937	2092
167.482	2044.5
170.025	2048.5
172.569	2009.5
175.111	2019
177.654	2016.5
180.194	2012
182.733	1980
185.273	2011.5
187.811	1979
190.348	1962.5
192.884	1975.5
195.419	1973.5
197.955	1989
200.489	1982.5
203.022	2033.5
205.554	1999.5
208.085	2027.5
210.615	2041.5
213.144	2032
215.673	2034.5
218.201	2034.5
220.728	2013.5
223.253	2061.5
225.778	2036
228.303	2046
230.826	2033.5
233.348	2037.5
235.87	2034.5
238.391	2048.5
240.91	2070.5
243.43	2079.5
245.949	2108
248.465	2072
250.983	2126
253.498	2099.5
256.013	2111.5
258.526	2101
261.039	2108
263.552	2117
266.063	2130.5
268.573	2107.5
271.084	2138.5
273.592	2112
276.1	2111
278.607	2112.5
281.113	2137.5
283.619	2153.5
286.124	2127
288.627	2166
291.13	2154
293.632	2183.5
296.133	2169
298.634	2217
301.133	2206
303.63	2201.5
306.128	2215
308.625	2206
311.122	2185.5
313.617	2168
316.111	2184.5
318.604	2171
321.098	2172
323.588	2153
326.08	2153.5
328.569	2143
331.059	2119
333.548	2102
336.035	2109
338.521	2091.5
341.008	2101
343.492	2064
345.977	2096
348.46	2060.5
350.942	2110.5
353.425	2097.5
355.905	2102
358.385	2129
360.864	2107.5
363.342	2118
365.819	2139
368.296	2094.5
370.771	2074
373.246	2083
375.72	2076
378.194	2077
380.666	2094
383.138	2093
385.609	2089.5
388.079	2071
390.548	2071.5
393.016	2107
395.483	2053.5
397.95	2071.5
400.416	2068.5
402.88	2056.5
405.345	2094.5
407.807	2111
410.27	2113
412.731	2119
415.193	2135.5
417.652	2134
420.112	2160.5
422.569	2129
425.028	2151
427.484	2153
429.939	2134.5
432.394	2176
434.849	2163.5
437.302	2172
439.754	2178
442.205	2159.5
444.656	2163.5
447.106	2148
449.555	2156
452.003	2146
454.45	2163.5
456.897	2170.5
459.343	2149
461.788	2129
464.232	2158.5
466.676	2138.5
469.119	2138.5
471.559	2178.5
474.001	2173
476.441	2201.5
478.879	2171
481.318	2165
483.756	2199
486.192	2211.5
488.629	2210.5
491.063	2194.5
493.498	2239
495.931	2223
498.365	2248
500.796	2249
503.226	2225.5
505.657	2221.5
508.086	2228
510.515	2268.5
512.942	2257.5
515.369	2242
517.796	2268.5
520.221	2261.5
522.645	2246
525.069	2274
527.492	2267.5
529.914	2272.5
532.335	2270.5
534.756	2246.5
537.175	2297
539.593	2228.5
542.011	2247.5
544.429	2259
546.845	2268
549.261	2313
551.675	2277
554.089	2265.5
556.503	2287.5
558.914	2294
561.326	2269
563.736	2331.5
566.147	2277.5
568.555	2266
570.964	2306
573.371	2304.5
575.777	2297.5
578.184	2300.5
580.588	2272
582.992	2293.5
585.395	2326
587.799	2304
590.201	2310.5
592.601	2313
595.001	2280
597.401	2316
599.799	2338
602.197	2298
604.594	2337.5
606.99	2336.5
609.386	2344.5
611.78	2355
614.174	2313
616.566	2345.5
618.958	2349
621.35	2385
623.741	2345
626.13	2374.5
628.519	2393
630.908	2351
633.295	2400
635.682	2415.5
638.067	2422
640.453	2437
642.836	2426.5
645.219	2403
647.602	2379
649.984	2383.5
652.364	2401.5
654.745	2383
657.124	2393
659.503	2361.5
661.88	2340
664.257	2350
666.635	2361.5
669.01	2327.5
671.384	2338
673.758	2332
676.131	2353.5
678.502	2335
680.874	2333.5
683.245	2325
685.615	2276.5
687.984	2308.5
690.353	2340
692.719	2325.5
695.086	2307
697.453	2286
699.817	2265.5
702.182	2310
704.545	2319.5
706.908	2286.5
709.27	2298.5
711.632	2287
713.991	2297.5
716.352	2304.5
718.71	2331.5
721.068	2329
723.426	2304.5
725.782	2294
728.138	2291
730.492	2320.5
732.846	2283
735.201	2340
737.553	2332.5
739.905	2296
742.256	2325.5
744.606	2329.5
746.956	2322.5
749.303	2281
751.651	2298
753.999	2294
756.345	2303
758.691	2290
761.035	2325
763.379	2303.5
765.723	2265.5
768.064	2289
770.407	2254.5
772.748	2302
775.088	2312.5
777.427	2281.5
779.765	2315.5
782.104	2313
784.44	2310
786.776	2277.5
789.113	2305.5
791.447	2296.5
793.78	2278.5
796.113	2295
798.445	2298
800.778	2327.5
803.109	2327
805.439	2343
807.768	2330.5
810.096	2344
812.424	2353.5
814.751	2380.5
817.078	2399
819.402	2369
821.727	2396.5
824.051	2368.5
826.374	2348.5
828.697	2370.5
831.018	2369
833.339	2378.5
835.659	2398.5
837.978	2377
840.297	2411.5
842.614	2385
844.932	2425
847.247	2379.5
849.562	2407
851.878	2392.5
854.191	2372.5
856.504	2421.5
858.817	2436.5
861.129	2421
863.439	2410.5
865.749	2396.5
868.058	2378
870.367	2401.5
872.676	2349
874.983	2353.5
877.289	2363
879.593	2347
881.898	2326.5
884.202	2342.5
886.506	2332
888.808	2305
891.11	2338
893.41	2326
895.711	2298
898.011	2294.5
900.309	2302.5
902.607	2272.5
904.904	2290
907.201	2285.5
909.496	2244.5
911.791	2260
914.085	2255
916.379	2259
918.671	2253.5
920.963	2254.5
923.255	2294
925.545	2286
927.834	2250
930.123	2241.5
932.411	2284.5
934.698	2252
936.985	2273
939.271	2304.5
941.556	2275
943.84	2296.5
946.124	2282.5
948.407	2298.5
950.689	2290
952.971	2313.5
955.25	2301
957.531	2278.5
959.81	2336.5
962.088	2305
964.366	2343
966.643	2306
968.919	2313
971.195	2319.5
973.469	2289
975.743	2303.5
978.016	2302
980.288	2302.5
982.56	2335.5
984.831	2317
987.101	2287
989.37	2302
991.638	2302
993.907	2290.5
996.174	2360.5
998.44	2376
1000.71	2433
1002.97	2338
1005.24	2292.5
1007.5	2298.5
1009.76	2283.5
1012.02	2256
1014.28	2294.5
1016.54	2296.5
1018.8	2310
1021.06	2331
1023.32	2291.5
1025.58	2322
1027.84	2323.5
1030.09	2325
1032.35	2314.5
1034.6	2278.5
1036.86	2333
1039.11	2323.5
1041.36	2344
1043.61	2338
1045.86	2343
1048.11	2334.5
1050.36	2332.5
1052.61	2324
1054.86	2355.5
1057.11	2349.5
1059.35	2330
1061.6	2332
1063.84	2317.5
1066.09	2325
1068.33	2317
1070.57	2328
1072.82	2337.5
1075.06	2338
1077.3	2335
1079.54	2299.5
1081.78	2338
1084.02	2278
1086.25	2315
1088.49	2325
1090.73	2299
1092.96	2328
1095.2	2299
1097.43	2280
1099.66	2265
1101.9	2304
1104.13	2314.5
1106.36	2328
1108.59	2293.5
1110.82	2282
1113.05	2309
1115.28	2326
1117.51	2291
1119.73	2259.5
1121.96	2288
1124.18	2280.5
1126.41	2313
1128.63	2273.5
1130.85	2314.5
1133.08	2321
1135.3	2306
1137.52	2302.5
1139.74	2362.5
1141.96	2324
1144.18	2376
1146.4	2362.5
1148.61	2372
1150.83	2372
1153.05	2367
1155.26	2392
1157.48	2409
1159.69	2412
1161.9	2449.5
1164.11	2455.5
1166.33	2466.5
1168.54	2466.5
1170.75	2448.5
1172.96	2470.5
1175.17	2464.5
1177.37	2468
1179.58	2427
1181.79	2437
1183.99	2400.5
1186.2	2412
1188.4	2392.5
1190.61	2403.5
1192.81	2407.5
1195.01	2390
1197.21	2396.13
1199.42	2403.79
1201.61	2415.68
1203.81	2384.37
1206.01	2415.39
1208.21	2379.35
1210.41	2418.2
1212.61	2392.31
1214.8	2367.3
1217	2383.65
1219.19	2354.57
1221.38	2406.44
1223.58	2365.42
1225.77	2354.82
1227.96	2407.31
1230.15	2407.05
1232.34	2391.39
1234.53	2405.72
1236.72	2396.43
1238.91	2415.7
1241.1	2411.96
1243.28	2423.01
1245.47	2423.54
1247.65	2444.22
1249.84	2444.18
1252.02	2426.13
1254.21	2449.3
1256.39	2450.52
1258.57	2479.26
1260.75	2450.9
1262.93	2482.76
1265.11	2470.63
1267.29	2486.84
1269.47	2512.17
1271.65	2510.31
1273.82	2484.47
1276	2485.65
1278.17	2486.49
1280.35	2493.4
1282.52	2501.94
1284.69	2503.89
1286.87	2492.17
1289.04	2513.06
1291.21	2524.61
1293.38	2522.47
1295.55	2489.1
1297.72	2507.13
1299.89	2487.62
1302.06	2520.28
1304.22	2503
1306.39	2495.21
1308.43	2503
1310.6	2507
1312.78	2500.5
1314.96	2492
1317.13	2478
1319.3	2491.5
1321.47	2496.5
1323.65	2489.5
1325.82	2483.5
1327.99	2456.5
1330.16	2477
1332.32	2452
1334.49	2472
1336.66	2471
1338.83	2443
1340.99	2418
1343.16	2418
1345.32	2431
1347.49	2398.5
1349.65	2392.5
1351.81	2394.5
1353.98	2391.5
1356.14	2385
1358.3	2375
1360.46	2354
1362.62	2387
1364.78	2332
1366.93	2354.5
1369.09	2323.5
1371.25	2353
1373.4	2356.5
1375.56	2299
1377.71	2326
1379.87	2313
1382.02	2324.5
1384.17	2293
1386.32	2299
1388.47	2325.5
1390.63	2322
1392.77	2290.5
1394.92	2318
1397.07	2333.5
1399.22	2285
1401.37	2327
1403.51	2296.5
1405.66	2340
1407.8	2297
1409.95	2314
1412.09	2342.5
1414.23	2324
1416.38	2322
1418.52	2337
1420.66	2354
1422.8	2368.5
1424.94	2343
1427.08	2348
1429.21	2381.5
1431.35	2360
1433.49	2400.5
1435.63	2377
1437.76	2361
1439.89	2374
1442.03	2414.5
1444.16	2429.5
1446.3	2413.5
1448.43	2404.5
1450.56	2406.5
1452.69	2397.5
1454.82	2412.5
1456.95	2411
1459.08	2429.5
1461.2	2418
1463.33	2434.5
1465.46	2423
1467.58	2442.5
1469.71	2457.5
1471.83	2427
1473.96	2454.5
1476.08	2483.5
1478.2	2491.5
1480.33	2493
1482.45	2488.5
1484.57	2472.5
1486.69	2467.5
1488.81	2453
1490.93	2453
1493.04	2445.5
1495.16	2430
1497.28	2443
1499.39	2384.5
1501.51	2403
1503.62	2430
1505.74	2423
1507.85	2395
1509.96	2387.5
1512.07	2360
1514.19	2372
1516.3	2357.5
1518.41	2336.5
1520.52	2372.5
1522.62	2387
1524.73	2347
1526.84	2351
1528.95	2395
1531.05	2363.5
1533.16	2350.5
1535.26	2374.5
1537.37	2377
1539.47	2377.5
1541.57	2345
1543.67	2358.5
1545.78	2352
1547.88	2360
1549.98	2366
1552.07	2372.5
1554.17	2342.5
1556.27	2364.5
1558.37	2394
1560.47	2330.5
1562.56	2365
1564.66	2341
1566.75	2384
1568.85	2380.5
1570.94	2361
1573.03	2349
1575.12	2312
1577.21	2332
1579.31	2338.5
1581.4	2329
1583.49	2338.5
1585.57	2329
1587.66	2343.5
1589.75	2349
1591.84	2358.5
1593.92	2331
1596.01	2360
1598.09	2363.5
1600.18	2332
1602.26	2279.5
1604.34	2281.5
1606.43	2205.5
1608.51	2168
1610.59	2144.5
1612.67	2114
1614.75	2096
1616.83	2079
1618.91	2046
1620.98	2059
1623.06	1992.5
1625.14	1990
1627.21	1919.5
1629.29	1934
1631.36	1926
1633.43	1901.5
1635.51	1848.5
1637.58	1845
1639.65	1828.5
1641.72	1789.5
1643.79	1810
1645.86	1767
1647.93	1725
1650	1756.5
1652.07	1727.5
1654.14	1703.5
1656.2	1706
1658.27	1698
1660.34	1680.5
1662.4	1639.5
1664.46	1652
1666.53	1612
1668.59	1604.5
1670.65	1608
1672.71	1614
1674.77	1594
1676.83	1570
1678.89	1581
1680.95	1582.5
1683.01	1541
1685.07	1575
1687.13	1552
1689.18	1552
1691.24	1526.5
1693.29	1502
1695.35	1513.5
1697.4	1490.5
1699.45	1461.5
1701.51	1508.5
1703.56	1494
1705.61	1510
1707.66	1480
1709.71	1465
1711.76	1487.5
1713.81	1468.5
1715.86	1481
1717.9	1438
1719.95	1443.5
1722	1423.5
1724.04	1437.5
1726.09	1429.5
1728.13	1424.5
1730.17	1422
1732.22	1411.5
1734.26	1403.5
1736.3	1395
1738.34	1426.5
1740.38	1385.5
1742.42	1393
1744.46	1422
1746.5	1398.5
1748.54	1360
1750.57	1346
1752.61	1370
1754.65	1365.5
1756.68	1327.5
1758.72	1380
1760.75	1364
1762.78	1330
1764.82	1330.5
1766.85	1330
1768.88	1347
1770.91	1322
1772.94	1311
1774.97	1311
1777	1323.5
1779.03	1326
1781.06	1307.5
1783.08	1287.5
1785.11	1290.5
1787.14	1296
1789.16	1299
1791.18	1262
1793.21	1265
1795.23	1283.5
1797.26	1255
1799.28	1260
1801.3	1274.5
1803.32	1249.5
1805.34	1256
1807.36	1263.5
1809.38	1275
1811.4	1267
1813.41	1244.5
1815.43	1246
1817.45	1245.5
1819.46	1224
1821.48	1241.5
1823.49	1233.5
1825.51	1236
1827.52	1224.5
1829.53	1207.5
1831.54	1189.5
1833.56	1202
1835.57	1201
1837.58	1214.5
1839.59	1211.5
1841.59	1182
1843.6	1201
1845.61	1179
1847.62	1175.5
1849.62	1190
1851.63	1173.5
1853.64	1165
1855.64	1159
1857.64	1153
1859.65	1178
1861.65	1171
1863.65	1144.5
1865.65	1145
1867.65	1150.5
1869.65	1148.5
1871.65	1134.5
1873.65	1153
1875.65	1141
1877.65	1105.5
1879.65	1147.5
1881.64	1136
1883.64	1117.5
1885.63	1125
1887.63	1113
1889.62	1130
1891.62	1130
1893.61	1101.5
1895.6	1124
1897.59	1102
1899.58	1109
1901.57	1125.5
1903.56	1123
1905.55	1103.5
1907.54	1104
1909.53	1090
1911.52	1110.5
1913.5	1091.5
1915.49	1083
1917.48	1089.5
1919.46	1080
1921.44	1084
1923.43	1065
1925.41	1087
1927.39	1078
1929.38	1079.5
1931.36	1070.5
1933.34	1081
1935.32	1073
1937.3	1049
1939.28	1057
1941.25	1067.5
1943.23	1084.5
1945.21	1082
1947.18	1062.5
1949.16	1031.5
1951.13	1044
1953.11	1048.5
1955.08	1052.5
1957.06	1048
1959.03	1058
1961	1040
1962.97	1058
1964.94	1031.5
1966.91	1021
1968.88	1009.5
1970.85	1023
1972.82	1013.5
1974.79	1033.5
1976.76	1019.5
1978.72	992
1980.69	1006
1982.65	1024.5
1984.62	1013
1986.58	1037.5
1988.55	1007
1990.51	1026
1992.47	995
1994.43	1015
1996.39	999.5
1998.36	1018
2000.31	994.5
2002.27	1002.5
2004.23	985.5
2006.19	988
2008.15	979.5
2010.11	966.5
2012.06	988
2014.02	985
2015.97	976.5
2017.93	974.5
2019.88	948
2021.83	972.5
2023.79	991.5
2025.74	956
2027.69	942
2029.64	971.5
2031.59	979
2033.54	956
2035.49	965.5
2037.44	939
2039.39	960.5
2041.34	949.5
2043.28	943
2045.23	933
2047.17	928.5
2049.12	941
2051.06	935
2053.01	920
2054.95	946.5
2056.89	920.5
2058.84	929
2060.78	927.5
2062.72	935.5
2064.66	926
2066.6	921.5
2068.54	912.5
2070.48	929.5
2072.41	936.5
2074.35	899
2076.29	901
2078.22	895
2080.16	922.5
2082.09	891.5
2084.03	900.5
2085.96	910
2087.9	912
2089.83	913.5
2091.76	900.5
2093.69	905
2095.62	913.5
2097.55	910.5
2099.48	905
2101.41	894
2103.34	909
2105.27	887.5
2107.19	916
2109.12	918.5
2111.05	930
2112.97	947.5
2114.9	959.5
2116.82	981
2118.75	980.5
2120.67	994.5
2122.59	1022.5
2124.51	1033.5
2126.43	1050
2128.36	1060
2130.28	1033
2132.2	1055
2134.11	1034
2136.03	1021.5
2137.95	988.5
2139.87	952.5
2141.78	935
2143.7	934.5
2145.62	910.095
2147.53	920.926
2149.45	906.889
2151.36	894.256
2153.27	875.719
2155.19	870.228
2157.1	885.497
2159.01	874.873
2160.92	850.401
2162.83	844.043
2164.74	867.215
2166.65	857.953
2168.56	836.629
2170.47	826.62
2172.37	819.574
2174.28	827.257
2176.19	829.517
2178.09	823.337
2180	812.683
2181.9	810.442
2183.81	800.362
2185.71	795.45
2187.61	798.097
2189.51	796.262
2191.42	793.802
2193.32	795.37
2195.22	792.067
2197.12	783.25
2199.02	794.079
2200.92	788.493
2202.81	776.449
2204.71	774.682
2206.61	781.689
2208.5	775.588
2210.4	779.305
2212.3	780.405
2214.19	781.09
2216.08	791.875
2217.98	772.175
2219.87	776.319
2221.76	784.416
2223.65	777.396
2225.55	766.802
2227.44	770.993
2229.33	770.47
2231.22	780.809
2233.11	781.098
2234.99	786.18
2236.88	758.383
2238.77	784.576
2240.66	792.34
2242.06	789.5
2243.96	791.5
2245.85	792.5
2247.75	798
2249.64	804.5
2251.54	779.5
2253.43	788.5
2255.32	768.5
2257.21	772.5
2259.1	755.5
2260.99	752
2262.89	740.5
2264.77	760
2266.66	734
2268.55	759.5
2270.44	752
2272.33	739.5
2274.21	739
2276.1	749.5
2277.98	714.5
2279.87	715
2281.75	734
2283.64	725
2285.52	715
2287.4	711
2289.29	693
2291.17	726.5
2293.05	718
2294.93	710.5
2296.81	705.5
2298.69	712.5
2300.57	705
2302.44	698
2304.32	699.5
2306.2	688
2308.08	701.5
2309.95	696.5
2311.83	700.5
2313.7	711.5
2315.58	676
2317.45	700.5
2319.32	688.5
2321.2	676.5
2323.07	696
2324.94	685
2326.81	689
2328.68	688
2330.55	680
2332.42	679
2334.29	680.5
2336.16	667
2338.02	669
2339.89	672
2341.76	678
2343.62	656.5
2345.49	655
2347.35	671
2349.22	667
2351.08	677.5
2352.94	664.5
2354.81	668.5
2356.67	656
2358.53	676.5
2360.39	674
2362.25	645
2364.11	657
2365.97	673
2367.83	663.5
2369.69	666
2371.55	670
2373.4	660.5
2375.26	655.5
2377.11	662
2378.97	644.5
2380.83	643.5
2382.68	651.5
2384.53	628
2386.39	622
2388.24	637
2390.09	626
2391.94	626.5
2393.79	644.5
2395.64	639
2397.49	621
2399.34	639
2401.19	631
2403.04	621
2404.89	635
2406.74	611
2408.58	632.5
2410.43	632.5
2412.27	634.5
2414.12	623
2415.96	618
2417.81	642.5
2419.65	611.5
2421.49	624.5
2423.34	605.5
2425.18	602
2427.02	610.5
2428.86	621
2430.7	602.5
2432.54	616
2434.38	617.5
2436.22	612
2438.05	620
2439.89	622.5
2441.73	607.5
2443.56	608.5
2445.4	606
2447.24	591
2449.07	604.5
2450.9	599
2452.74	598.5
2454.57	598
2456.4	594.5
2458.23	597
2460.07	595
2461.9	593
2463.73	601.5
2465.56	582
2467.39	598.5
2469.21	606.5
2471.04	585.5
2472.87	592.5
2474.7	573
2476.52	600.5
2478.35	576.5
2480.17	573
2482	580.5
2483.82	579.5
2485.65	594.5
2487.47	564
2489.29	579
2491.12	576.5
2492.94	568.5
2494.76	572.5
2496.58	566.5
2498.4	576
2500.22	580.5
2502.04	592
2503.86	560
2505.67	560
2507.49	561.5
2509.31	562
2511.12	569
2512.94	558.5
2514.76	558
2516.57	553
2518.38	550.5
2520.2	552
2522.01	539
2523.82	552
2525.64	551.5
2527.45	539.5
2529.26	550.5
2531.07	560.5
2532.88	542
2534.69	550
2536.5	546.5
2538.31	548.5
2540.11	552
2541.92	549
2543.73	529.5
2545.53	545.5
2547.34	537.5
2549.14	534.5
2550.95	540.5
2552.75	550.5
2554.56	529
2556.36	518
2558.16	534
2559.96	527
2561.76	525
2563.57	526
2565.37	535.5
2567.17	530.5
2568.96	527
2570.76	534
2572.56	532.5
2574.36	504
2576.16	521
2577.95	518
2579.75	522.5
2581.54	514.5
2583.34	520
2585.13	502.5
2586.93	516
2588.72	502
2590.51	503
2592.31	505
2594.1	484.5
2595.89	503
2597.68	513.5
2599.47	514
2601.26	502.5
2603.05	501.5
2604.84	519.5
2606.63	501
2608.42	499
2610.2	500.5
2611.99	499.5
2613.78	492.5
2615.56	500
2617.35	498
2619.13	504.5
2620.91	492.5
2622.7	494
2624.48	487.5
2626.26	496
2628.04	497.5
2629.83	497.5
2631.61	485.5
2633.39	485.5
2635.17	494
2636.95	477.5
2638.73	488.5
2640.5	480
2642.28	471
2644.06	473
2645.84	465
2647.61	477
2649.39	476.5
2651.16	476.5
2652.94	475.5
2654.71	458
2656.49	478.5
2658.26	474
2660.03	463.5
2661.8	473.5
2663.57	465
2665.35	473
2667.12	460
2668.89	466
2670.66	473.5
2672.42	468.5
2674.19	448
2675.96	466
2677.73	462.5
2679.49	458
2681.26	458.5
2683.03	450
2684.79	462
2686.56	461.5
2688.32	462
2690.09	458.5
2691.85	457
2693.61	446
2695.37	471
2697.14	435.5
2698.9	453.5
2700.66	444
2702.42	449
2704.18	455
2705.94	447.5
2707.7	448
2709.45	442
2711.21	442
2712.97	437
2714.72	442.5
2716.48	441
2718.24	452
2719.99	442
2721.75	445
2723.5	443.5
2725.25	450
2727.01	440.5
2728.76	432
2730.51	436
2732.26	433
2734.01	436.5
2735.76	428
2737.51	434
2739.26	428.5
2741.01	428
2742.76	437.5
2744.51	427.5
2746.26	419.5
2748	428
2749.75	434
2751.5	421.5
2753.24	418.5
2754.99	416.5
2756.73	416
2758.47	418
2760.22	425.5
2761.96	424
2763.7	413.5
2765.44	404
2767.19	431.5
2768.93	413
2770.67	402.5
2772.41	425.5
2774.15	416.5
2775.89	405
2777.62	414
2779.36	407
2781.1	403
2782.84	417
2784.57	402.5
2786.31	399.5
2788.04	403.5
2789.78	418.5
2791.51	401.5
2793.24	393.5
2794.98	402.5
2796.71	403.5
2798.44	387.5
2800.18	387
2801.91	405
2803.64	399
2805.37	406
2807.1	400.5
2808.83	393
2810.55	403
2812.28	398
2814.01	386
2815.74	388.5
2817.46	390.5
2819.19	395.5
2820.92	381
2822.64	389.5
2824.37	384
2826.09	375.5
2827.81	378
2829.54	388.5
2831.26	384.5
2832.98	383
2834.71	381
2836.43	378
2838.15	388
2839.87	377
2841.59	380.5
2843.31	381.5
2845.02	385
2846.74	395
2848.46	387
2850.18	378
2851.9	390.5
2853.61	386
2855.33	381.5
2857.04	378
2858.76	381
2860.47	387
2862.19	390.5
2863.9	384.5
2865.61	381
2867.32	389
2869.04	383.5
2870.75	390.5
2872.46	387.5
2874.17	382
2875.88	392
2877.59	381
2879.3	387.5
2881	368
2882.71	386.5
2884.42	387
2886.13	383
2887.83	387
2889.54	380.5
2891.24	379
2892.95	382.5
2894.65	387
2896.36	373
2898.06	385
2899.76	389
2901.47	401
2903.17	383
2904.87	382
2906.57	376.5
2908.27	386
2909.97	391.5
2911.67	403.5
2913.37	383.5
2915.07	385
2916.77	386.5
2918.47	378.5
2920.16	401.5
2921.86	395
2923.55	388
2925.25	407
2926.94	393.5
2928.64	402
2930.33	408.5
2932.03	408
2933.72	404
2935.41	415
2937.11	410
2938.8	415
2940.49	397.5
2942.18	410
2943.87	400.5
2945.56	397
2947.25	391.5
2948.94	385
2950.63	375
2952.31	368.5
2954	364
2955.69	353
2957.37	354
2959.06	354
2960.75	354.5
2962.43	370.5
2964.11	357
2965.8	351
2967.48	355.5
2969.16	353
2970.85	347
2972.53	341.5
2974.21	348
2975.89	343.5
2977.57	341.5
2979.25	330.5
2980.93	341.5
2982.61	345
2984.29	331
2985.97	343.5
2987.65	324
2989.32	322.5
2991	327
2992.68	311.5
2994.35	326
2996.03	324.5
2997.7	315.5
2999.38	310