File: muestras/ogompa/nsno_04.txt
#Acq. time (s)=	5
#Accumulations=	5
#Range (cm-¹)=	100...3000
#Windows=	3
#Autofocus=	Off
#AutoExposure=	Off
#Spike filter=	Multiple accum.
#Delay time (s)=	0
#Binning=	1
#Readout mode=	Signal
#DeNoise=	Off
#ICS correction=	Off
#Dark correction=	Off
#Inst. Process=	Off
#Instrument=	LabRAM HR Evol
#Detector=	Syncerity OE
#Objective=	x100_VIS_LWD
#Grating=	600 (500nm)
#ND Filter=	100%
#Laser=	633nm_Edge
#Hole=	100.021
#Range=	Visible
#Project=	Omar
#Sample=	chi
#Site=	f
#Title=	nsno
#Remark=
#Date=	12.09.2023 16:53
#Acquired=	12.09.2023 16:53:15
101.026	15260.5
103.592	14936
106.158	14858.5
108.723	14764.5
111.289	14526.5
113.852	14388.5
116.415	14201
118.976	14134.5
121.537	14079
124.097	13985
126.656	13827
129.215	13708
131.772	13628
134.327	13563
136.883	13375
139.438	13300.5
141.992	13286.5
144.545	13071.5
147.096	13055
149.648	12903.5
152.199	12827.5
154.747	12723
157.296	12644.5
159.843	12629.5
162.391	12566
164.937	12477
167.482	12358.5
170.025	12306.5
172.569	12206
175.111	12225
177.654	12084
180.194	11946
182.733	12009
185.273	11919.5
187.811	11911
190.348	11950
192.884	12036
195.419	12087
197.955	12111.5
200.489	12162.5
203.022	12152.5
205.554	12111.5
208.085	12199
210.615	12186
213.144	12185.5
215.673	12180.5
218.201	12138
220.728	12229
223.253	12097.5
225.778	12152.5
228.303	12168
230.826	12228
233.348	12243
235.87	12317
238.391	12359.5
240.91	12428.5
243.43	12443.5
245.949	12538.5
248.465	12505.5
250.983	12540.5
253.498	12553.5
256.013	12575.5
258.526	12544.5
261.039	12468
263.552	12492
266.063	12502
268.573	12463
271.084	12393
273.592	12319
276.1	12256.5
278.607	12417.5
281.113	12372
283.619	12488
286.124	12510.5
288.627	12491.5
291.13	12699
293.632	12663
296.133	12744
298.634	12775
301.133	12787.5
303.63	12961
306.128	12917.5
308.625	12885.5
311.122	12960.5
313.617	13016.5
316.111	12995.5
318.604	12980
321.098	12910.5
323.588	12821.5
326.08	12847.5
328.569	12778
331.059	12709
333.548	12740.5
336.035	12656.5
338.521	12601.5
341.008	12683.5
343.492	12763.5
345.977	12747
348.46	12807
350.942	12802
353.425	12789
355.905	12874
358.385	12929
360.864	12811.5
363.342	12874.5
365.819	12939
368.296	12867
370.771	12933.5
373.246	12887
375.72	12842.5
378.194	12799.5
380.666	12839.5
383.138	12812.5
385.609	12822
388.079	12846
390.548	12810
393.016	12734.5
395.483	12793.5
397.95	12741.5
400.416	12703.5
402.88	12819
405.345	12829
407.807	12990
410.27	12983.5
412.731	13118.5
415.193	13153.5
417.652	13173
420.112	13221
422.569	13217.5
425.028	13324.5
427.484	13286
429.939	13394.5
432.394	13529
434.849	13470
437.302	13513
439.754	13547.5
442.205	13511.5
444.656	13441
447.106	13514.5
449.555	13460
452.003	13437
454.45	13473.5
456.897	13393.5
459.343	13302.5
461.788	13264.5
464.232	13336.5
466.676	13267
469.119	13359.5
471.559	13356.5
474.001	13310
476.441	13344.5
478.879	13291.5
481.318	13259
483.756	13368.5
486.192	13332.5
488.629	13498
491.063	13413
493.498	13422.5
495.931	13408.5
498.365	13481
500.796	13453.5
503.226	13520.5
505.657	13488.5
508.086	13551.5
510.515	13520
512.942	13468
515.369	13470
517.796	13486
520.221	13417.5
522.645	13454.5
525.069	13451.5
527.492	13407.5
529.914	13405.5
532.335	13321.5
534.756	13347.5
537.175	13312
539.593	13304
542.011	13282.5
544.429	13245
546.845	13297.5
549.261	13257
551.675	13263
554.089	13250.5
556.503	13217
558.914	13261
561.326	13260.5
563.736	13340.5
566.147	13281.5
568.555	13278
570.964	13320.5
573.371	13260.5
575.777	13284.5
578.184	13246.5
580.588	13339
582.992	13291.5
585.395	13347
587.799	13365.5
590.201	13313
592.601	13359.5
595.001	13379.5
597.401	13367.5
599.799	13403.5
602.197	13391
604.594	13438.5
606.99	13516.5
609.386	13448.5
611.78	13509.5
614.174	13605.5
616.566	13551
618.958	13636
621.35	13661
623.741	13636
626.13	13672.5
628.519	13703
630.908	13818
633.295	13788
635.682	13890
638.067	13921.5
640.453	13906
642.836	13941
645.219	13944
647.602	14002.5
649.984	13950.5
652.364	13964
654.745	13918.5
657.124	13999.5
659.503	13930
661.88	13860
664.257	13863
666.635	13776.5
669.01	13765.5
671.384	13826
673.758	13825
676.131	13737
678.502	13687.5
680.874	13652
683.245	13643.5
685.615	13729
687.984	13635
690.353	13672.5
692.719	13616.5
695.086	13585
697.453	13482.5
699.817	13640.5
702.182	13559.5
704.545	13527.5
706.908	13540.5
709.27	13586.5
711.632	13560
713.991	13549
716.352	13593.5
718.71	13618.5
721.068	13564
723.426	13587.5
725.782	13643
728.138	13618
730.492	13567.5
732.846	13612.5
735.201	13603
737.553	13572.5
739.905	13608
742.256	13622.5
744.606	13589
746.956	13504.5
749.303	13556.5
751.651	13519.5
753.999	13584.5
756.345	13517.5
758.691	13555
761.035	13534
763.379	13577
765.723	13426.5
768.064	13474.5
770.407	13447
772.748	13388.5
775.088	13367
777.427	13352.5
779.765	13396.5
782.104	13430.5
784.44	13314
786.776	13465.5
789.113	13264.5
791.447	13301
793.78	13321
796.113	13329
798.445	13316.5
800.778	13352.5
803.109	13344
805.439	13386.5
807.768	13347.5
810.096	13352.5
812.424	13334.5
814.751	13481.5
817.078	13410
819.402	13424
821.727	13498
824.051	13472.5
826.374	13406
828.697	13414
831.018	13470
833.339	13464
835.659	13476
837.978	13492
840.297	13477.5
842.614	13565.5
844.932	13561
847.247	13547
849.562	13482
851.878	13570
854.191	13573.5
856.504	13513
858.817	13609
861.129	13547
863.439	13596
865.749	13526
868.058	13581.5
870.367	13470.5
872.676	13495.5
874.983	13490.5
877.289	13409
879.593	13399
881.898	13448
884.202	13379
886.506	13279.5
888.808	13217.5
891.11	13312
893.41	13231
895.711	13152.5
898.011	13177
900.309	13208
902.607	13172
904.904	13155.5
907.201	13083
909.496	13022
911.791	13016.5
914.085	13067.5
916.379	13104
918.671	13027.5
920.963	13040.5
923.255	13037
925.545	12948.5
927.834	12946.5
930.123	12971
932.411	12943.5
934.698	13044.5
936.985	12987
939.271	12947
941.556	13001.5
943.84	13006.5
946.124	13045.5
948.407	13039
950.689	13049
952.971	13025.5
955.25	13035
957.531	13074.5
959.81	13090.5
962.088	13092
964.366	13084
966.643	13083.5
968.919	13088.5
971.195	13053
973.469	13075
975.743	13050
978.016	13035.5
980.288	13080
982.56	13089.5
984.831	13035
987.101	12974
989.37	12974.5
991.638	13023
993.907	13037.5
996.174	13074
998.44	13056
1000.71	13059
1002.97	13005
1005.24	12946
1007.5	12941
1009.76	12941
1012.02	12931
1014.28	12986.5
1016.54	12973.5
1018.8	12946
1021.06	12992.5
1023.32	12936
1025.58	12987
1027.84	12987.5
1030.09	12985
1032.35	13103
1034.6	13059.5
1036.86	13075.5
1039.11	13094
1041.36	13033.5
1043.61	13152
1045.86	13110
1048.11	13091.5
1050.36	13115
1052.61	13179
1054.86	13159
1057.11	13182.5
1059.35	13154
1061.6	13279
1063.84	13249
1066.09	13195
1068.33	13191.5
1070.57	13224
1072.82	13221
1075.06	13244
1077.3	13203
1079.54	13249
1081.78	13195
1084.02	13157.5
1086.25	13191
1088.49	13186
1090.73	13198.5
1092.96	13154.5
1095.2	13151.5
1097.43	13092
1099.66	13168
1101.9	13120.5
1104.13	13088
1106.36	13074
1108.59	13122
1110.82	13162.5
1113.05	13170
1115.28	13081
1117.51	13075
1119.73	13118.5
1121.96	13121.5
1124.18	13211.5
1126.41	13182.5
1128.63	13189.5
1130.85	13129.5
1133.08	13289
1135.3	13347
1137.52	13330.5
1139.74	13465.5
1141.96	13474.5
1144.18	13497.5
1146.4	13584
1148.61	13772
1150.83	13754
1153.05	13755.5
1155.26	13868.5
1157.48	13939.5
1159.69	13941
1161.9	14057.5
1164.11	14071.5
1166.33	14057.5
1168.54	14168
1170.75	14203.5
1172.96	14216.5
1175.17	14169
1177.37	14187.5
1179.58	14197.5
1181.79	14235
1183.99	14187
1186.2	14055
1188.4	14195
1190.61	14106
1192.81	14137.5
1195.01	14141.5
1197.21	14141.5
1199.42	13975.5
1201.61	13878
1203.81	13829.3
1206.01	13705.7
1208.21	13712.3
1210.41	13583
1212.61	13482
1214.8	13410.1
1217	13297.4
1219.19	13289.1
1221.38	13174
1223.58	13060.9
1225.77	13023.1
1227.96	12911.8
1230.15	12907.7
1232.34	12906.1
1234.53	12814.3
1236.72	12797.9
1238.91	12683.7
1241.1	12566.4
1243.28	12553.6
1245.47	12457.2
1247.65	12438.1
1249.84	12372
1252.02	12301.6
1254.21	12257.2
1256.39	12267.4
1258.57	12107.1
1260.75	12092.7
1262.93	12087.5
1265.11	12012.2
1267.29	11936.8
1269.47	11893.3
1271.65	11860.4
1273.82	11737
1276	11739.3
1278.17	11614.7
1280.35	11562.7
1282.52	11534.6
1284.69	11445.4
1286.87	11419.6
1289.04	11335.6
1291.21	11249.1
1293.38	11198.4
1295.55	11155.7
1297.72	11053.1
1299.89	10922.3
1302.06	10867.4
1304.22	10725.1
1306.39	10660.3
1308.43	10693
1310.6	10691.5
1312.78	10693.5
1314.96	10568.5
1317.13	10568.5
1319.3	10571.5
1321.47	10627
1323.65	10602.5
1325.82	10567
1327.99	10619.5
1330.16	10604
1332.32	10595.5
1334.49	10573
1336.66	10534
1338.83	10506.5
1340.99	10618.5
1343.16	10526.5
1345.32	10468.5
1347.49	10396
1349.65	10435
1351.81	10422.5
1353.98	10427.5
1356.14	10445.5
1358.3	10366.5
1360.46	10291
1362.62	10341.5
1364.78	10256
1366.93	10326
1369.09	10282.5
1371.25	10095
1373.4	10164
1375.56	10155
1377.71	10115
1379.87	10082.5
1382.02	10085.5
1384.17	9997.5
1386.32	9976.5
1388.47	9929.5
1390.63	9878.5
1392.77	9777
1394.92	9770
1397.07	9803.5
1399.22	9788.5
1401.37	9705
1403.51	9686
1405.66	9706.5
1407.8	9577
1409.95	9605.5
1412.09	9508.5
1414.23	9524.5
1416.38	9470
1418.52	9428.5
1420.66	9461
1422.8	9354
1424.94	9387
1427.08	9350
1429.21	9318
1431.35	9330
1433.49	9321
1435.63	9307.5
1437.76	9272.5
1439.89	9295
1442.03	9328.5
1444.16	9228
1446.3	9227
1448.43	9234
1450.56	9174.5
1452.69	9194.5
1454.82	9158.5
1456.95	9191.5
1459.08	9116
1461.2	9174.5
1463.33	9100
1465.46	9084
1467.58	9095
1469.71	9142.5
1471.83	9125
1473.96	8979
1476.08	9089
1478.2	9080
1480.33	9159
1482.45	9101.5
1484.57	9197.5
1486.69	9149.5
1488.81	9123.5
1490.93	9157
1493.04	9160
1495.16	9202.5
1497.28	9310
1499.39	9244.5
1501.51	9230
1503.62	9259
1505.74	9302
1507.85	9247
1509.96	9304.5
1512.07	9253.5
1514.19	9309.5
1516.3	9297
1518.41	9315.5
1520.52	9307
1522.62	9350
1524.73	9342.5
1526.84	9345
1528.95	9248.5
1531.05	9329
1533.16	9338.5
1535.26	9272.5
1537.37	9344
1539.47	9313.5
1541.57	9293.5
1543.67	9288.5
1545.78	9342.5
1547.88	9283
1549.98	9306
1552.07	9276
1554.17	9362
1556.27	9297.5
1558.37	9316.5
1560.47	9343
1562.56	9261.5
1564.66	9224
1566.75	9325
1568.85	9315.5
1570.94	9332.5
1573.03	9195
1575.12	9307.5
1577.21	9304
1579.31	9282.5
1581.4	9257.5
1583.49	9242
1585.57	9207.5
1587.66	9273
1589.75	9196
1591.84	9087
1593.92	9015
1596.01	9071
1598.09	8950.5
1600.18	8917
1602.26	8921.5
1604.34	8749.5
1606.43	8656
1608.51	8599.5
1610.59	8461.5
1612.67	8336
1614.75	8197
1616.83	8145.5
1618.91	7998
1620.98	7901.5
1623.06	7780.5
1625.14	7688
1627.21	7609
1629.29	7448.5
1631.36	7333.5
1633.43	7199.5
1635.51	7055.5
1637.58	6983
1639.65	6906
1641.72	6720
1643.79	6581.5
1645.86	6555
1647.93	6363.5
1650	6336.5
1652.07	6296.5
1654.14	6203
1656.2	6111
1658.27	6028
1660.34	5913.5
1662.4	5872.5
1664.46	5828
1666.53	5753.5
1668.59	5662
1670.65	5630
1672.71	5608
1674.77	5510
1676.83	5448
1678.89	5434
1680.95	5380
1683.01	5399
1685.07	5338.5
1687.13	5251
1689.18	5188.5
1691.24	5241.5
1693.29	5154
1695.35	5143
1697.4	5100
1699.45	5077
1701.51	5006
1703.56	5048.5
1705.61	4969
1707.66	4970
1709.71	4933.5
1711.76	4884.5
1713.81	4862
1715.86	4871
1717.9	4857
1719.95	4742.5
1722	4751
1724.04	4799
1726.09	4748.5
1728.13	4706.5
1730.17	4673
1732.22	4679.5
1734.26	4636
1736.3	4618.5
1738.34	4637
1740.38	4601
1742.42	4593
1744.46	4553
1746.5	4544.5
1748.54	4499.5
1750.57	4469.5
1752.61	4464.5
1754.65	4511.5
1756.68	4454
1758.72	4386
1760.75	4394
1762.78	4379
1764.82	4345
1766.85	4359.5
1768.88	4329.5
1770.91	4294
1772.94	4285
1774.97	4301
1777	4290.5
1779.03	4223
1781.06	4272.5
1783.08	4227.5
1785.11	4228
1787.14	4184
1789.16	4211
1791.18	4170.5
1793.21	4123.5
1795.23	4102
1797.26	4098
1799.28	4102
1801.3	4071.5
1803.32	4065
1805.34	4039.5
1807.36	4068.5
1809.38	4038
1811.4	3959.5
1813.41	4027
1815.43	3970
1817.45	4022.5
1819.46	3931.5
1821.48	3944.5
1823.49	3903
1825.51	3898.5
1827.52	3874.5
1829.53	3854.5
1831.54	3874
1833.56	3768.5
1835.57	3844
1837.58	3829.5
1839.59	3784.5
1841.59	3774
1843.6	3734.5
1845.61	3768
1847.62	3725
1849.62	3688.5
1851.63	3685.5
1853.64	3709
1855.64	3642
1857.64	3664.5
1859.65	3640
1861.65	3603.5
1863.65	3620
1865.65	3596.5
1867.65	3558
1869.65	3560
1871.65	3540
1873.65	3568.5
1875.65	3544.5
1877.65	3531
1879.65	3515.5
1881.64	3482.5
1883.64	3495.5
1885.63	3464.5
1887.63	3485.5
1889.62	3451.5
1891.62	3460.5
1893.61	3422.5
1895.6	3392
1897.59	3440.5
1899.58	3396
1901.57	3409
1903.56	3409.5
1905.55	3427.5
1907.54	3387.5
1909.53	3351
1911.52	3350
1913.5	3357
1915.49	3349
1917.48	3350.5
1919.46	3321
1921.44	3325
1923.43	3319
1925.41	3310.5
1927.39	3300
1929.38	3306
1931.36	3272.5
1933.34	3252
1935.32	3249
1937.3	3267.5
1939.28	3236.5
1941.25	3244.5
1943.23	3271
1945.21	3242
1947.18	3177
1949.16	3165
1951.13	3124
1953.11	3172
1955.08	3105
1957.06	3144.5
1959.03	3138.5
1961	3120.5
1962.97	3139
1964.94	3106.5
1966.91	3078.5
1968.88	3094.5
1970.85	3094.5
1972.82	3058.5
1974.79	3089
1976.76	3030.5
1978.72	3024
1980.69	3037.5
1982.65	3018
1984.62	3005
1986.58	3025
1988.55	3002.5
1990.51	2988.5
1992.47	2957.5
1994.43	2946
1996.39	2940.5
1998.36	2912
2000.31	2941.5
2002.27	2903
2004.23	2935
2006.19	2874
2008.15	2910
2010.11	2900.5
2012.06	2879.5
2014.02	2875.5
2015.97	2907
2017.93	2844.5
2019.88	2837.5
2021.83	2870.5
2023.79	2868.5
2025.74	2829
2027.69	2819.5
2029.64	2859
2031.59	2824.5
2033.54	2771.5
2035.49	2807.5
2037.44	2790.5
2039.39	2769
2041.34	2791.5
2043.28	2758.5
2045.23	2760
2047.17	2763.5
2049.12	2733.5
2051.06	2740
2053.01	2749.5
2054.95	2712.5
2056.89	2671.5
2058.84	2683
2060.78	2676.5
2062.72	2668.5
2064.66	2672
2066.6	2645.5
2068.54	2662
2070.48	2672
2072.41	2660.5
2074.35	2614
2076.29	2643
2078.22	2602
2080.16	2597
2082.09	2600.5
2084.03	2598.5
2085.96	2566
2087.9	2570
2089.83	2579.5
2091.76	2585.5
2093.69	2554
2095.62	2575
2097.55	2543.5
2099.48	2554.5
2101.41	2546.5
2103.34	2566
2105.27	2538.5
2107.19	2536.5
2109.12	2564.5
2111.05	2578.5
2112.97	2522
2114.9	2540
2116.82	2572
2118.75	2585.5
2120.67	2607.5
2122.59	2577
2124.51	2597.5
2126.43	2626.5
2128.36	2637.5
2130.28	2629
2132.2	2635.5
2134.11	2647.5
2136.03	2652.5
2137.95	2656
2139.87	2654
2141.78	2650
2143.7	2637
2145.62	2659.86
2147.53	2669.68
2149.45	2620.65
2151.36	2622.39
2153.27	2631.51
2155.19	2607.74
2157.1	2568.03
2159.01	2551.28
2160.92	2510.52
2162.83	2503.67
2164.74	2467.05
2166.65	2469.4
2168.56	2422.78
2170.47	2368.55
2172.37	2360.24
2174.28	2289.06
2176.19	2279.75
2178.09	2238.27
2180	2202.06
2181.9	2156.79
2183.81	2135.85
2185.71	2057.63
2187.61	2049.24
2189.51	2028.75
2191.42	2021.74
2193.32	2025.17
2195.22	1986.55
2197.12	1963.24
2199.02	1939.78
2200.92	1926.16
2202.81	1928.85
2204.71	1921.46
2206.61	1885.53
2208.5	1894.29
2210.4	1870.02
2212.3	1868.64
2214.19	1861.38
2216.08	1848.78
2217.98	1832.69
2219.87	1827.6
2221.76	1807.25
2223.65	1829.65
2225.55	1800.77
2227.44	1785.51
2229.33	1779.51
2231.22	1769.98
2233.11	1751.96
2234.99	1748.02
2236.88	1730.61
2238.77	1744.17
2240.66	1725.97
2242.06	1712.5
2243.96	1752
2245.85	1791
2247.75	1767
2249.64	1760
2251.54	1699
2253.43	1699.5
2255.32	1683
2257.21	1670
2259.1	1629.5
2260.99	1663
2262.89	1633.5
2264.77	1627.5
2266.66	1606
2268.55	1615.5
2270.44	1612.5
2272.33	1623
2274.21	1579.5
2276.1	1587.5
2277.98	1594.5
2279.87	1607
2281.75	1565
2283.64	1567.5
2285.52	1591
2287.4	1557
2289.29	1565.5
2291.17	1573.5
2293.05	1552
2294.93	1529.5
2296.81	1566
2298.69	1525
2300.57	1525
2302.44	1540.5
2304.32	1512.5
2306.2	1542.5
2308.08	1541.5
2309.95	1514
2311.83	1516.5
2313.7	1521.5
2315.58	1530.5
2317.45	1496.5
2319.32	1512.5
2321.2	1477
2323.07	1488
2324.94	1500.5
2326.81	1469.5
2328.68	1470.5
2330.55	1475.5
2332.42	1478
2334.29	1488.5
2336.16	1457
2338.02	1466.5
2339.89	1458.5
2341.76	1452.5
2343.62	1475
2345.49	1443.5
2347.35	1472
2349.22	1445.5
2351.08	1451.5
2352.94	1438.5
2354.81	1448.5
2356.67	1451.5
2358.53	1455
2360.39	1424
2362.25	1443.5
2364.11	1422
2365.97	1431.5
2367.83	1416.5
2369.69	1431
2371.55	1436
2373.4	1402
2375.26	1404
2377.11	1436
2378.97	1433.5
2380.83	1403
2382.68	1383.5
2384.53	1396
2386.39	1362
2388.24	1387
2390.09	1387
2391.94	1375
2393.79	1407
2395.64	1364
2397.49	1376
2399.34	1374
2401.19	1378
2403.04	1339
2404.89	1368
2406.74	1355
2408.58	1346
2410.43	1348
2412.27	1372.5
2414.12	1342
2415.96	1339
2417.81	1333
2419.65	1309.5
2421.49	1319.5
2423.34	1351.5
2425.18	1328
2427.02	1323.5
2428.86	1334.5
2430.7	1306
2432.54	1323
2434.38	1317.5
2436.22	1304
2438.05	1321.5
2439.89	1309
2441.73	1296
2443.56	1283
2445.4	1293
2447.24	1303.5
2449.07	1309
2450.9	1286
2452.74	1266
2454.57	1308
2456.4	1294.5
2458.23	1283.5
2460.07	1281
2461.9	1275
2463.73	1254
2465.56	1270.5
2467.39	1265.5
2469.21	1304
2471.04	1266
2472.87	1265.5
2474.7	1247.5
2476.52	1256.5
2478.35	1267.5
2480.17	1254
2482	1250.5
2483.82	1256
2485.65	1237
2487.47	1235
2489.29	1252
2491.12	1244.5
2492.94	1214.5
2494.76	1243
2496.58	1216.5
2498.4	1212
2500.22	1228.5
2502.04	1239.5
2503.86	1232
2505.67	1220
2507.49	1217
2509.31	1213.5
2511.12	1203.5
2512.94	1211
2514.76	1190
2516.57	1194.5
2518.38	1194
2520.2	1203.5
2522.01	1196
2523.82	1182
2525.64	1198.5
2527.45	1184.5
2529.26	1144
2531.07	1175
2532.88	1206
2534.69	1168.5
2536.5	1179.5
2538.31	1165
2540.11	1163.5
2541.92	1174
2543.73	1165
2545.53	1153
2547.34	1152.5
2549.14	1138.5
2550.95	1141.5
2552.75	1138
2554.56	1136
2556.36	1153.5
2558.16	1129
2559.96	1139
2561.76	1159
2563.57	1132
2565.37	1145
2567.17	1124.5
2568.96	1120.5
2570.76	1137.5
2572.56	1116
2574.36	1112
2576.16	1127
2577.95	1113
2579.75	1105.5
2581.54	1104
2583.34	1106.5
2585.13	1131
2586.93	1114
2588.72	1081.5
2590.51	1086
2592.31	1086
2594.1	1073
2595.89	1093
2597.68	1087
2599.47	1106.5
2601.26	1106
2603.05	1098
2604.84	1096
2606.63	1071
2608.42	1067
2610.2	1083.5
2611.99	1044
2613.78	1055
2615.56	1084
2617.35	1060
2619.13	1053
2620.91	1059.5
2622.7	1074
2624.48	1070.5
2626.26	1054
2628.04	1045
2629.83	1050.5
2631.61	1041.5
2633.39	1028.5
2635.17	1050.5
2636.95	1040
2638.73	1024
2640.5	1029
2642.28	1019
2644.06	994
2645.84	1001
2647.61	1000
2649.39	1011
2651.16	996
2652.94	1021.5
2654.71	986.5
2656.49	1004
2658.26	1026
2660.03	1007.5
2661.8	991
2663.57	1002
2665.35	966
2667.12	989
2668.89	974
2670.66	1006
2672.42	1011.5
2674.19	987.5
2675.96	1000
2677.73	995
2679.49	980
2681.26	982
2683.03	988
2684.79	975.5
2686.56	972.5
2688.32	984
2690.09	957.5
2691.85	950
2693.61	979
2695.37	974
2697.14	968
2698.9	964
2700.66	940.5
2702.42	955.5
2704.18	955.5
2705.94	953.5
2707.7	955
2709.45	954.5
2711.21	933
2712.97	912
2714.72	922
2716.48	951.5
2718.24	946.5
2719.99	957
2721.75	928
2723.5	928
2725.25	933
2727.01	937
2728.76	926
2730.51	904.5
2732.26	921.5
2734.01	912.5
2735.76	908.5
2737.51	923
2739.26	907.5
2741.01	908.5
2742.76	886
2744.51	900.5
2746.26	888.5
2748	905
2749.75	886.5
2751.5	879
2753.24	894
2754.99	868
2756.73	877.5
2758.47	877.5
2760.22	878
2761.96	880
2763.7	870.5
2765.44	861.5
2767.19	872.5
2768.93	857.5
2770.67	867
2772.41	853
2774.15	861
2775.89	848.5
2777.62	844.5
2779.36	852
2781.1	856
2782.84	858.5
2784.57	823
2786.31	848
2788.04	839
2789.78	842.5
2791.51	843
2793.24	830.5
2794.98	856.5
2796.71	830.5
2798.44	833
2800.18	822
2801.91	812.5
2803.64	822
2805.37	827
2807.1	832.5
2808.83	804
2810.55	815
2812.28	829
2814.01	806
2815.74	812.5
2817.46	811
2819.19	810
2820.92	811.5
2822.64	806
2824.37	803.5
2826.09	805
2827.81	798
2829.54	785.5
2831.26	808.5
2832.98	789.5
2834.71	803
2836.43	800
2838.15	788
2839.87	798.5
2841.59	802
2843.31	797.5
2845.02	812
2846.74	802
2848.46	805
2850.18	803
2851.9	811
2853.61	803.5
2855.33	804
2857.04	790
2858.76	815
2860.47	794.5
2862.19	788.5
2863.9	790.5
2865.61	802.5
2867.32	786
2869.04	787
2870.75	779
2872.46	807.5
2874.17	801
2875.88	785
2877.59	784
2879.3	788
2881	795
2882.71	783.5
2884.42	795
2886.13	779
2887.83	780
2889.54	762.5
2891.24	769.5
2892.95	766.5
2894.65	783.5
2896.36	787.5
2898.06	763
2899.76	790
2901.47	766.5
2903.17	783
2904.87	778.5
2906.57	783
2908.27	774
2909.97	789.5
2911.67	768
2913.37	784.5
2915.07	766
2916.77	759.5
2918.47	764
2920.16	764.5
2921.86	772.5
2923.55	786
2925.25	782
2926.94	770
2928.64	780
2930.33	801.5
2932.03	792.5
2933.72	803.5
2935.41	792
2937.11	769
2938.8	783.5
2940.49	775
2942.18	753.5
2943.87	757
2945.56	746
2947.25	764
2948.94	753.5
2950.63	737
2952.31	736
2954	721
2955.69	699
2957.37	711
2959.06	698
2960.75	691
2962.43	707
2964.11	697
2965.8	687
2967.48	699.5
2969.16	680
2970.85	690
2972.53	679
2974.21	675.5
2975.89	686
2977.57	679
2979.25	657
2980.93	666.5
2982.61	654
2984.29	640.5
2985.97	661.5
2987.65	647
2989.32	641
2991	630
2992.68	634
2994.35	637
2996.03	626
2997.7	626.5
2999.38	622