File: muestras/ogompa/nsno_17.txt
#Acq. time (s)=	5
#Accumulations=	5
#Range (cm-¹)=	100...3000
#Windows=	3
#Autofocus=	Off
#AutoExposure=	Off
#Spike filter=	Multiple accum.
#Delay time (s)=	0
#Binning=	1
#Readout mode=	Signal
#DeNoise=	Off
#ICS correction=	Off
#Dark correction=	Off
#Inst. Process=	Off
#Instrument=	LabRAM HR Evol
#Detector=	Syncerity OE
#Objective=	x100_VIS_LWD
#Grating=	600 (500nm)
#ND Filter=	100%
#Laser=	633nm_Edge
#Hole=	100.021
#Range=	Visible
#Project=	Omar
#Sample=	chi
#Site=	f
#Title=	nsno
#Remark=
#Date=	12.09.2023 17:40
#Acquired=	12.09.2023 17:40:53
101.026	4098.5
103.592	4031.5
106.158	3992.5
108.723	3887
111.289	3829
113.852	3752
116.415	3717.5
118.976	3691
121.537	3607.5
124.097	3616.5
126.656	3591
129.215	3542.5
131.772	3513
134.327	3450
136.883	3380
139.438	3343
141.992	3298.5
144.545	3208.5
147.096	3217.5
149.648	3142
152.199	3133.5
154.747	3080.5
157.296	3067
159.843	3024
162.391	2996.5
164.937	2967
167.482	2948
170.025	2887
172.569	2919
175.111	2876
177.654	2870.5
180.194	2852
182.733	2854.5
185.273	2835
187.811	2793.5
190.348	2840.5
192.884	2895
195.419	2880.5
197.955	2852
200.489	2887.5
203.022	2915.5
205.554	2875
208.085	2872
210.615	2933
213.144	2955
215.673	2964.5
218.201	2888
220.728	2939
223.253	2926
225.778	2996
228.303	2933
230.826	2986
233.348	2995.5
235.87	2976
238.391	3010
240.91	3028.5
243.43	3060
245.949	3052
248.465	3023
250.983	3051.5
253.498	3073
256.013	3067.5
258.526	3092.5
261.039	3025
263.552	3030.5
266.063	3075
268.573	3047.5
271.084	3058
273.592	3034
276.1	3080.5
278.607	3047
281.113	3079.5
283.619	3108.5
286.124	3118.5
288.627	3139
291.13	3096
293.632	3171.5
296.133	3160.5
298.634	3159
301.133	3153.5
303.63	3143.5
306.128	3135.5
308.625	3128
311.122	3133
313.617	3121
316.111	3145.5
318.604	3096.5
321.098	3043
323.588	3056
326.08	3059.5
328.569	3049.5
331.059	3019.5
333.548	3097.5
336.035	3060
338.521	3002
341.008	2978.5
343.492	3010.5
345.977	3023.5
348.46	3002.5
350.942	2982.5
353.425	3036.5
355.905	3051.5
358.385	3006
360.864	3012
363.342	2989.5
365.819	2997
368.296	3027
370.771	3000
373.246	3004
375.72	3015.5
378.194	3000
380.666	3012
383.138	2988.5
385.609	2980
388.079	2998.5
390.548	2964.5
393.016	2973
395.483	2970.5
397.95	3005.5
400.416	2962
402.88	3012.5
405.345	3050
407.807	3008
410.27	3077
412.731	3043.5
415.193	3116
417.652	3120
420.112	3088.5
422.569	3127.5
425.028	3136.5
427.484	3085.5
429.939	3121.5
432.394	3162.5
434.849	3186.5
437.302	3129
439.754	3171
442.205	3156.5
444.656	3161
447.106	3136.5
449.555	3154
452.003	3156.5
454.45	3153
456.897	3134.5
459.343	3124.5
461.788	3121
464.232	3126
466.676	3152
469.119	3106
471.559	3165.5
474.001	3104
476.441	3141
478.879	3156
481.318	3168.5
483.756	3165
486.192	3164.5
488.629	3172
491.063	3204
493.498	3205.5
495.931	3193
498.365	3225.5
500.796	3214
503.226	3234
505.657	3216.5
508.086	3233.5
510.515	3216
512.942	3215
515.369	3225.5
517.796	3249
520.221	3243
522.645	3225
525.069	3220
527.492	3184
529.914	3157
532.335	3229
534.756	3156.5
537.175	3184
539.593	3214.5
542.011	3194.5
544.429	3195.5
546.845	3199
549.261	3175
551.675	3181.5
554.089	3246.5
556.503	3208
558.914	3212.5
561.326	3192.5
563.736	3208
566.147	3210.5
568.555	3229
570.964	3218.5
573.371	3219
575.777	3260.5
578.184	3220
580.588	3198
582.992	3224
585.395	3186.5
587.799	3218.5
590.201	3232
592.601	3260
595.001	3256.5
597.401	3263.5
599.799	3299.5
602.197	3259.5
604.594	3251.5
606.99	3318
609.386	3308
611.78	3320
614.174	3317.5
616.566	3325
618.958	3379
621.35	3353.5
623.741	3374.5
626.13	3357
628.519	3357.5
630.908	3394.5
633.295	3434.5
635.682	3454
638.067	3414.5
640.453	3452
642.836	3432.5
645.219	3483.5
647.602	3475.5
649.984	3438.5
652.364	3429
654.745	3400
657.124	3425.5
659.503	3399
661.88	3415
664.257	3394
666.635	3373
669.01	3360
671.384	3379
673.758	3420.5
676.131	3338
678.502	3406.5
680.874	3349
683.245	3390
685.615	3394
687.984	3401
690.353	3349.5
692.719	3381.5
695.086	3351.5
697.453	3378
699.817	3347
702.182	3322.5
704.545	3350
706.908	3350
709.27	3322
711.632	3374
713.991	3357.5
716.352	3351
718.71	3382.5
721.068	3398
723.426	3368
725.782	3303
728.138	3364.5
730.492	3392
732.846	3331.5
735.201	3355
737.553	3342.5
739.905	3375.5
742.256	3367
744.606	3356
746.956	3356.5
749.303	3414.5
751.651	3420.5
753.999	3330
756.345	3322
758.691	3331
761.035	3386.5
763.379	3367
765.723	3350.5
768.064	3353.5
770.407	3355
772.748	3332
775.088	3312
777.427	3348.5
779.765	3359
782.104	3350
784.44	3313.5
786.776	3381
789.113	3385
791.447	3322
793.78	3384
796.113	3326
798.445	3352
800.778	3353.5
803.109	3337
805.439	3371
807.768	3415
810.096	3411
812.424	3402
814.751	3429.5
817.078	3431.5
819.402	3478
821.727	3455.5
824.051	3440
826.374	3479
828.697	3397.5
831.018	3430
833.339	3454.5
835.659	3473.5
837.978	3452
840.297	3508.5
842.614	3518
844.932	3514.5
847.247	3510
849.562	3513
851.878	3497
854.191	3483
856.504	3499
858.817	3501
861.129	3494.5
863.439	3528
865.749	3490.5
868.058	3475.5
870.367	3468
872.676	3484.5
874.983	3424
877.289	3450
879.593	3416
881.898	3409
884.202	3437.5
886.506	3393
888.808	3433
891.11	3382
893.41	3357.5
895.711	3374.5
898.011	3348
900.309	3367
902.607	3371
904.904	3328
907.201	3335
909.496	3331
911.791	3353
914.085	3303.5
916.379	3360.5
918.671	3306.5
920.963	3357.5
923.255	3340.5
925.545	3353.5
927.834	3362
930.123	3339.5
932.411	3351.5
934.698	3343
936.985	3363.5
939.271	3322.5
941.556	3333
943.84	3362
946.124	3342
948.407	3391
950.689	3347
952.971	3389.5
955.25	3396
957.531	3356
959.81	3368
962.088	3394
964.366	3377
966.643	3392
968.919	3390.5
971.195	3413
973.469	3374
975.743	3418.5
978.016	3384
980.288	3350.5
982.56	3416.5
984.831	3439
987.101	3397.5
989.37	3447.5
991.638	3365.5
993.907	3411
996.174	3479
998.44	3539.5
1000.71	3553.5
1002.97	3470.5
1005.24	3412.5
1007.5	3407
1009.76	3373
1012.02	3427.5
1014.28	3414
1016.54	3414
1018.8	3378
1021.06	3376
1023.32	3406
1025.58	3373
1027.84	3417
1030.09	3409
1032.35	3396
1034.6	3361
1036.86	3422
1039.11	3416.5
1041.36	3393
1043.61	3412
1045.86	3411.5
1048.11	3470
1050.36	3378
1052.61	3418
1054.86	3391
1057.11	3393
1059.35	3392
1061.6	3426.5
1063.84	3387
1066.09	3425
1068.33	3409.5
1070.57	3418
1072.82	3403
1075.06	3435.5
1077.3	3411
1079.54	3416
1081.78	3411
1084.02	3364
1086.25	3409
1088.49	3367
1090.73	3399
1092.96	3375
1095.2	3375.5
1097.43	3403.5
1099.66	3385
1101.9	3455
1104.13	3398
1106.36	3391.5
1108.59	3424
1110.82	3397.5
1113.05	3430.5
1115.28	3485.5
1117.51	3465.5
1119.73	3413.5
1121.96	3401
1124.18	3419
1126.41	3382
1128.63	3372
1130.85	3465.5
1133.08	3434
1135.3	3515
1137.52	3462
1139.74	3465.5
1141.96	3453
1144.18	3502
1146.4	3461.5
1148.61	3523
1150.83	3526
1153.05	3531
1155.26	3566.5
1157.48	3617
1159.69	3619
1161.9	3582
1164.11	3574.5
1166.33	3585.5
1168.54	3620
1170.75	3612
1172.96	3620.5
1175.17	3613
1177.37	3627
1179.58	3589
1181.79	3597.5
1183.99	3615
1186.2	3597.5
1188.4	3614.5
1190.61	3588
1192.81	3610
1195.01	3519
1197.21	3555.55
1199.42	3541.67
1201.61	3558.37
1203.81	3595.99
1206.01	3553.46
1208.21	3509.6
1210.41	3513.54
1212.61	3547.2
1214.8	3462.06
1217	3499.82
1219.19	3511.09
1221.38	3473.39
1223.58	3470.77
1225.77	3482.34
1227.96	3493.49
1230.15	3525.44
1232.34	3454.19
1234.53	3490.02
1236.72	3473.89
1238.91	3486.14
1241.1	3479.16
1243.28	3511.43
1245.47	3490.15
1247.65	3559.47
1249.84	3581.95
1252.02	3600.44
1254.21	3610.92
1256.39	3603.12
1258.57	3552.84
1260.75	3554.11
1262.93	3582.92
1265.11	3575.13
1267.29	3572.88
1269.47	3584.13
1271.65	3585.8
1273.82	3580.48
1276	3584.3
1278.17	3625.13
1280.35	3673.67
1282.52	3713.81
1284.69	3663.58
1286.87	3634.39
1289.04	3582.31
1291.21	3572.22
1293.38	3520.26
1295.55	3520
1297.72	3525.93
1299.89	3510.31
1302.06	3477.06
1304.22	3515.82
1306.39	3508.77
1308.43	3505.5
1310.6	3553.5
1312.78	3497
1314.96	3520.5
1317.13	3532
1319.3	3521
1321.47	3554
1323.65	3507
1325.82	3508.5
1327.99	3537
1330.16	3561
1332.32	3587
1334.49	3571
1336.66	3579
1338.83	3552
1340.99	3539.5
1343.16	3549
1345.32	3490
1347.49	3547.5
1349.65	3571
1351.81	3506
1353.98	3495
1356.14	3479
1358.3	3461
1360.46	3445
1362.62	3458
1364.78	3402.5
1366.93	3362.5
1369.09	3406
1371.25	3384
1373.4	3332
1375.56	3311.5
1377.71	3296
1379.87	3281
1382.02	3274.5
1384.17	3250
1386.32	3224
1388.47	3245
1390.63	3206.5
1392.77	3201.5
1394.92	3198.5
1397.07	3171.5
1399.22	3199
1401.37	3235.5
1403.51	3217
1405.66	3214.5
1407.8	3243
1409.95	3245
1412.09	3268.5
1414.23	3243.5
1416.38	3250
1418.52	3260.5
1420.66	3226.5
1422.8	3198.5
1424.94	3248.5
1427.08	3230
1429.21	3223
1431.35	3210.5
1433.49	3216.5
1435.63	3184.5
1437.76	3186.5
1439.89	3234
1442.03	3226.5
1444.16	3274
1446.3	3273
1448.43	3297
1450.56	3315
1452.69	3327
1454.82	3263.5
1456.95	3259
1459.08	3200
1461.2	3246.5
1463.33	3246.5
1465.46	3206
1467.58	3176.5
1469.71	3232
1471.83	3221.5
1473.96	3269
1476.08	3286.5
1478.2	3248.5
1480.33	3250.5
1482.45	3252
1484.57	3248
1486.69	3284
1488.81	3254.5
1490.93	3257.5
1493.04	3242.5
1495.16	3256
1497.28	3217.5
1499.39	3235.5
1501.51	3250
1503.62	3293
1505.74	3227
1507.85	3281.5
1509.96	3285
1512.07	3295
1514.19	3308.5
1516.3	3354
1518.41	3379
1520.52	3399
1522.62	3407
1524.73	3434
1526.84	3391.5
1528.95	3441.5
1531.05	3445.5
1533.16	3452.5
1535.26	3489
1537.37	3464
1539.47	3457.5
1541.57	3440
1543.67	3427.5
1545.78	3399
1547.88	3426.5
1549.98	3396
1552.07	3373
1554.17	3410.5
1556.27	3353
1558.37	3383
1560.47	3363
1562.56	3399
1564.66	3416
1566.75	3435
1568.85	3536.5
1570.94	3498
1573.03	3500.5
1575.12	3582.5
1577.21	3532
1579.31	3518
1581.4	3558
1583.49	3630
1585.57	3623
1587.66	3793.5
1589.75	3802
1591.84	3882.5
1593.92	3918
1596.01	3794.5
1598.09	3747.5
1600.18	3682.5
1602.26	3559
1604.34	3386
1606.43	3306
1608.51	3235.5
1610.59	3133.5
1612.67	3039
1614.75	2972.5
1616.83	2899.5
1618.91	2918.5
1620.98	2845
1623.06	2765.5
1625.14	2709.5
1627.21	2681
1629.29	2630
1631.36	2590
1633.43	2591
1635.51	2550
1637.58	2521.5
1639.65	2443.5
1641.72	2417
1643.79	2392
1645.86	2325
1647.93	2297.5
1650	2317
1652.07	2266
1654.14	2250.5
1656.2	2232.5
1658.27	2214.5
1660.34	2168
1662.4	2125
1664.46	2120
1666.53	2126.5
1668.59	2113
1670.65	2057
1672.71	2034
1674.77	2054
1676.83	2056
1678.89	2018
1680.95	2018.5
1683.01	2008
1685.07	1985
1687.13	2009
1689.18	1951.5
1691.24	1938
1693.29	1946
1695.35	1948
1697.4	1912.5
1699.45	1910.5
1701.51	1918
1703.56	1884
1705.61	1874
1707.66	1905
1709.71	1834
1711.76	1825
1713.81	1840
1715.86	1861
1717.9	1836
1719.95	1794.5
1722	1761.5
1724.04	1790
1726.09	1795.5
1728.13	1805.5
1730.17	1776
1732.22	1759.5
1734.26	1760
1736.3	1759
1738.34	1763
1740.38	1751
1742.42	1739.5
1744.46	1743
1746.5	1737.5
1748.54	1736
1750.57	1725
1752.61	1723
1754.65	1721
1756.68	1726.5
1758.72	1668.5
1760.75	1703.5
1762.78	1680
1764.82	1679.5
1766.85	1650.5
1768.88	1654.5
1770.91	1638
1772.94	1623
1774.97	1634
1777	1598.5
1779.03	1600
1781.06	1565
1783.08	1557
1785.11	1588.5
1787.14	1573
1789.16	1550
1791.18	1548.5
1793.21	1533
1795.23	1520
1797.26	1533
1799.28	1490
1801.3	1548.5
1803.32	1507
1805.34	1523
1807.36	1518.5
1809.38	1496.5
1811.4	1490
1813.41	1502
1815.43	1500.5
1817.45	1474
1819.46	1490
1821.48	1492
1823.49	1459
1825.51	1451
1827.52	1439.5
1829.53	1439
1831.54	1424.5
1833.56	1461
1835.57	1411
1837.58	1434
1839.59	1436
1841.59	1426.5
1843.6	1398
1845.61	1382
1847.62	1392
1849.62	1370
1851.63	1388
1853.64	1398
1855.64	1385.5
1857.64	1398
1859.65	1377
1861.65	1357.5
1863.65	1379
1865.65	1355.5
1867.65	1338
1869.65	1385
1871.65	1351
1873.65	1337
1875.65	1316.5
1877.65	1323
1879.65	1340
1881.64	1314
1883.64	1322
1885.63	1325
1887.63	1330
1889.62	1312.5
1891.62	1332.5
1893.61	1313
1895.6	1309
1897.59	1298
1899.58	1295
1901.57	1294
1903.56	1303
1905.55	1290
1907.54	1277
1909.53	1283
1911.52	1279.5
1913.5	1283
1915.49	1287
1917.48	1264
1919.46	1292
1921.44	1267
1923.43	1260
1925.41	1271
1927.39	1248
1929.38	1260.5
1931.36	1271.5
1933.34	1253.5
1935.32	1233.5
1937.3	1225
1939.28	1243.5
1941.25	1258
1943.23	1250
1945.21	1255
1947.18	1210
1949.16	1221
1951.13	1220
1953.11	1246
1955.08	1224
1957.06	1215.5
1959.03	1219.5
1961	1235
1962.97	1199
1964.94	1181.5
1966.91	1204
1968.88	1180
1970.85	1202.5
1972.82	1191.5
1974.79	1195
1976.76	1179
1978.72	1163
1980.69	1169.5
1982.65	1171
1984.62	1161
1986.58	1154
1988.55	1168
1990.51	1150
1992.47	1157
1994.43	1141
1996.39	1148
1998.36	1153.5
2000.31	1155.5
2002.27	1166.5
2004.23	1138
2006.19	1126
2008.15	1139.5
2010.11	1146.5
2012.06	1129.5
2014.02	1127
2015.97	1149
2017.93	1114
2019.88	1121
2021.83	1089
2023.79	1093
2025.74	1109
2027.69	1093
2029.64	1069
2031.59	1084
2033.54	1092.5
2035.49	1070.5
2037.44	1096.5
2039.39	1100
2041.34	1093.5
2043.28	1086
2045.23	1073
2047.17	1095.5
2049.12	1062
2051.06	1094
2053.01	1061.5
2054.95	1062
2056.89	1060.5
2058.84	1079.5
2060.78	1047
2062.72	1042
2064.66	1037
2066.6	1046.5
2068.54	1087
2070.48	1027
2072.41	1041
2074.35	1051.5
2076.29	1067.5
2078.22	1062
2080.16	1032
2082.09	1016
2084.03	1051
2085.96	1027
2087.9	1012
2089.83	1028
2091.76	1052
2093.69	1021
2095.62	1026.5
2097.55	1034
2099.48	1047
2101.41	1021.5
2103.34	1037
2105.27	1039
2107.19	1032.5
2109.12	1065.5
2111.05	1073
2112.97	1083
2114.9	1095
2116.82	1113.5
2118.75	1158.5
2120.67	1148
2122.59	1174.5
2124.51	1168.5
2126.43	1166.5
2128.36	1190.5
2130.28	1162.5
2132.2	1179
2134.11	1185
2136.03	1192
2137.95	1142
2139.87	1131
2141.78	1128
2143.7	1131.5
2145.62	1120.27
2147.53	1085.92
2149.45	1076.49
2151.36	1053.14
2153.27	1060.06
2155.19	1032.71
2157.1	1029.28
2159.01	1009.93
2160.92	1001.32
2162.83	981.238
2164.74	983.735
2166.65	972.696
2168.56	955.725
2170.47	943.519
2172.37	929.799
2174.28	920.015
2176.19	929.974
2178.09	929.865
2180	909.471
2181.9	890.773
2183.81	910
2185.71	906.114
2187.61	894.506
2189.51	900.551
2191.42	897.343
2193.32	894.829
2195.22	885.085
2197.12	890.703
2199.02	884.783
2200.92	863.789
2202.81	885.134
2204.71	868.187
2206.61	876.184
2208.5	880.278
2210.4	870.752
2212.3	871.59
2214.19	875.694
2216.08	867.858
2217.98	866.669
2219.87	854.355
2221.76	854.961
2223.65	862.134
2225.55	852.591
2227.44	862.046
2229.33	840.477
2231.22	839.292
2233.11	846.568
2234.99	848.568
2236.88	853.489
2238.77	845.903
2240.66	850.514
2242.06	851.5
2243.96	861
2245.85	881
2247.75	838
2249.64	851
2251.54	844.5
2253.43	853
2255.32	834.5
2257.21	820.5
2259.1	797
2260.99	805
2262.89	799.5
2264.77	804.5
2266.66	809
2268.55	808
2270.44	802
2272.33	789
2274.21	801.5
2276.1	790
2277.98	798.5
2279.87	777
2281.75	788
2283.64	776
2285.52	790
2287.4	784
2289.29	765
2291.17	768
2293.05	760
2294.93	767
2296.81	791
2298.69	763
2300.57	766
2302.44	746
2304.32	758
2306.2	744
2308.08	743
2309.95	741
2311.83	737.5
2313.7	763
2315.58	738
2317.45	756
2319.32	740
2321.2	760
2323.07	737.5
2324.94	746.5
2326.81	734.5
2328.68	737.5
2330.55	732.5
2332.42	725
2334.29	732.5
2336.16	737
2338.02	720
2339.89	731.5
2341.76	725
2343.62	714
2345.49	730
2347.35	722.5
2349.22	723.5
2351.08	710.5
2352.94	723.5
2354.81	711.5
2356.67	725
2358.53	722
2360.39	716.5
2362.25	714
2364.11	705.5
2365.97	706
2367.83	717.5
2369.69	717
2371.55	715
2373.4	709.5
2375.26	706.5
2377.11	695.5
2378.97	693
2380.83	682.5
2382.68	704.5
2384.53	696
2386.39	690
2388.24	683
2390.09	713.5
2391.94	691
2393.79	688.5
2395.64	698.5
2397.49	677.5
2399.34	675.5
2401.19	695.5
2403.04	665
2404.89	673
2406.74	676
2408.58	669
2410.43	686
2412.27	669
2414.12	677
2415.96	671
2417.81	678.5
2419.65	666
2421.49	656
2423.34	670.5
2425.18	671
2427.02	671.5
2428.86	654
2430.7	663.5
2432.54	650
2434.38	644.5
2436.22	649.5
2438.05	667.5
2439.89	661
2441.73	638
2443.56	644.5
2445.4	642
2447.24	624
2449.07	635
2450.9	629
2452.74	616.5
2454.57	640
2456.4	642.5
2458.23	631.5
2460.07	638.5
2461.9	630.5
2463.73	635.5
2465.56	638
2467.39	629
2469.21	624.5
2471.04	628
2472.87	634.5
2474.7	624.5
2476.52	628
2478.35	629.5
2480.17	626
2482	617
2483.82	602
2485.65	638
2487.47	624.5
2489.29	629
2491.12	593
2492.94	605
2494.76	614
2496.58	599
2498.4	616.5
2500.22	603
2502.04	593.5
2503.86	593.5
2505.67	595
2507.49	582
2509.31	587
2511.12	583
2512.94	608.5
2514.76	600
2516.57	612
2518.38	571.5
2520.2	576
2522.01	581.5
2523.82	576
2525.64	598
2527.45	590
2529.26	592
2531.07	588.5
2532.88	577.5
2534.69	574
2536.5	553
2538.31	579.5
2540.11	563.5
2541.92	585
2543.73	568.5
2545.53	574
2547.34	562
2549.14	566
2550.95	555
2552.75	556
2554.56	575.5
2556.36	571
2558.16	570
2559.96	548
2561.76	540
2563.57	557
2565.37	552.5
2567.17	566
2568.96	561.5
2570.76	557
2572.56	567
2574.36	548
2576.16	540.5
2577.95	539.5
2579.75	551
2581.54	536
2583.34	546
2585.13	548
2586.93	532
2588.72	538.5
2590.51	533
2592.31	536
2594.1	531.5
2595.89	532
2597.68	543
2599.47	543.5
2601.26	544
2603.05	517
2604.84	518
2606.63	522
2608.42	525
2610.2	516
2611.99	530
2613.78	523.5
2615.56	527
2617.35	517
2619.13	513
2620.91	511
2622.7	527.5
2624.48	520
2626.26	518
2628.04	514
2629.83	508.5
2631.61	500
2633.39	509
2635.17	505
2636.95	493.5
2638.73	514
2640.5	504.5
2642.28	494.5
2644.06	492.5
2645.84	495
2647.61	493
2649.39	494
2651.16	499.5
2652.94	496
2654.71	508
2656.49	494
2658.26	479
2660.03	484
2661.8	471
2663.57	485.5
2665.35	475.5
2667.12	481.5
2668.89	484
2670.66	505.5
2672.42	473
2674.19	473
2675.96	482.5
2677.73	491
2679.49	475
2681.26	486
2683.03	467
2684.79	471.5
2686.56	486.5
2688.32	474
2690.09	481
2691.85	475
2693.61	465
2695.37	473
2697.14	484.5
2698.9	457
2700.66	467.5
2702.42	484.5
2704.18	441
2705.94	479
2707.7	459
2709.45	470.5
2711.21	466.5
2712.97	469
2714.72	445
2716.48	467
2718.24	452
2719.99	458
2721.75	454
2723.5	459.5
2725.25	462.5
2727.01	442
2728.76	457.5
2730.51	450
2732.26	459
2734.01	455
2735.76	462
2737.51	435.5
2739.26	431
2741.01	432
2742.76	437.5
2744.51	435.5
2746.26	430.5
2748	430
2749.75	450
2751.5	434
2753.24	414.5
2754.99	436.5
2756.73	433
2758.47	427
2760.22	417.5
2761.96	414
2763.7	428
2765.44	417
2767.19	429.5
2768.93	412
2770.67	417.5
2772.41	430
2774.15	414
2775.89	421.5
2777.62	414
2779.36	411
2781.1	409
2782.84	411.5
2784.57	422.5
2786.31	418
2788.04	405
2789.78	410
2791.51	405
2793.24	405
2794.98	408
2796.71	404
2798.44	410
2800.18	415
2801.91	403
2803.64	401.5
2805.37	404
2807.1	404.5
2808.83	418.5
2810.55	404.5
2812.28	403.5
2814.01	401.5
2815.74	411.5
2817.46	392.5
2819.19	385
2820.92	398
2822.64	387
2824.37	393.5
2826.09	399
2827.81	394
2829.54	393
2831.26	397
2832.98	394
2834.71	388
2836.43	394.5
2838.15	394
2839.87	392
2841.59	411.5
2843.31	396
2845.02	397
2846.74	406
2848.46	409.5
2850.18	406.5
2851.9	407
2853.61	413
2855.33	419.5
2857.04	413.5
2858.76	416
2860.47	410
2862.19	397
2863.9	406
2865.61	399
2867.32	415
2869.04	416
2870.75	403
2872.46	401.5
2874.17	409.5
2875.88	408.5
2877.59	407
2879.3	401.5
2881	400.5
2882.71	395
2884.42	401.5
2886.13	409
2887.83	415.5
2889.54	401
2891.24	391.5
2892.95	400.5
2894.65	409
2896.36	408
2898.06	406.5
2899.76	413.5
2901.47	403
2903.17	424.5
2904.87	397
2906.57	411.5
2908.27	422.5
2909.97	410.5
2911.67	416
2913.37	417.5
2915.07	406.5
2916.77	407
2918.47	414
2920.16	406.5
2921.86	419
2923.55	406.5
2925.25	415.5
2926.94	419
2928.64	413
2930.33	418.5
2932.03	415.5
2933.72	422
2935.41	416
2937.11	422
2938.8	416.5
2940.49	426
2942.18	415.5
2943.87	400.5
2945.56	398
2947.25	387.5
2948.94	388.5
2950.63	393.5
2952.31	388
2954	389.5
2955.69	372.5
2957.37	378.5
2959.06	367.5
2960.75	366
2962.43	356.5
2964.11	359
2965.8	362
2967.48	358.5
2969.16	349.5
2970.85	367
2972.53	350.5
2974.21	341.5
2975.89	350.5
2977.57	343.5
2979.25	353.5
2980.93	340.5
2982.61	334
2984.29	329
2985.97	338.5
2987.65	324
2989.32	338.5
2991	325
2992.68	311
2994.35	326
2996.03	311
2997.7	322.5
2999.38	312