File: muestras/manzana/mz_08.txt
#Acq. time (s)=	15
#Accumulations=	4
#Range (cm-¹)=	50...4000
#Windows=	3
#Autofocus=	Off
#AutoExposure=	Off
#Spike filter=	Multiple accum.
#Delay time (s)=	0
#Binning=	1
#Readout mode=	Signal
#DeNoise=	Off
#ICS correction=	Off
#Dark correction=	Off
#Inst. Process=	Off
#Instrument=	LabRAM HR Evol
#Detector=	Syncerity OE
#Objective=	x100_VIS
#Grating=	600 (500nm)
#ND Filter=	5%
#Laser=	532nm_Edge
#Hole=	100.021
#Range=	Visible
#Project=	Omar
#Sample=	120523
#Site=	ap
#Title=	mz
#Remark=	5 laser intensity
#Date=	12.05.2023 16:56
#Acquired=	12.05.2023 16:56:50
51.0297	26
54.7185	35.8496
58.406	50.3659
62.0919	92.2156
65.7765	144.065
69.4595	207.248
73.1412	293.764
76.8214	365.614
80.5001	404.797
84.1774	463.313
87.8532	485.83
91.5276	470.346
95.2006	479.529
98.8721	476.045
102.54	487.895
106.209	505.744
109.876	502.927
113.542	495.444
117.204	491.293
120.867	502.476
124.526	478.993
128.186	482.842
131.845	493.358
135.5	495.875
139.155	499.058
142.807	494.907
146.46	512.757
150.11	493.94
153.757	508.456
157.406	524.973
161.051	519.489
164.697	500.005
168.339	515.188
171.98	503.704
175.619	474.887
179.259	495.404
182.895	493.92
186.53	494.436
190.164	493.619
193.796	488.802
197.427	499.985
201.059	495.168
204.686	487.018
208.313	503.534
211.938	485.384
215.562	477.9
219.184	493.083
222.803	494.266
226.422	472.782
230.04	488.632
233.657	480.481
237.272	478.998
240.886	460.847
244.497	480.03
248.108	490.547
251.717	488.396
255.325	489.579
258.93	469.429
262.535	465.945
266.137	473.795
269.74	478.978
273.341	491.494
276.939	473.344
280.537	478.527
284.132	483.043
287.728	469.559
291.32	473.409
294.911	473.925
298.502	477.775
302.09	483.624
305.677	481.474
309.264	489.99
312.848	495.84
316.43	479.023
320.011	489.539
323.593	484.722
327.171	485.905
330.748	482.421
334.323	495.604
337.897	486.787
341.47	492.637
345.041	494.487
348.611	490.336
352.18	500.852
355.747	478.035
359.312	496.552
362.877	489.068
366.44	490.251
369.999	488.101
373.56	504.617
377.119	490.467
380.676	497.65
384.23	496.166
387.785	483.349
391.338	511.198
394.888	515.715
398.439	504.898
401.988	508.747
405.534	503.93
409.081	507.78
412.624	510.963
416.167	510.812
419.708	502.662
423.249	517.178
426.786	505.695
430.323	514.878
433.86	502.061
437.393	505.91
440.926	503.093
444.458	516.276
447.988	512.792
451.516	495.975
455.043	529.158
458.568	515.008
462.092	519.524
465.615	516.041
469.138	519.224
472.658	508.407
476.177	510.256
479.694	525.439
483.21	517.955
486.723	519.138
490.236	544.988
493.748	529.504
497.258	508.687
500.768	515.87
504.276	521.72
507.78	533.569
511.285	526.086
514.789	517.269
518.289	545.118
521.791	540.968
525.29	537.484
528.787	538.001
532.284	533.184
535.778	534.367
539.272	529.549
542.763	544.732
546.255	531.249
549.743	548.432
553.232	531.615
556.718	534.131
560.203	517.98
563.688	546.497
567.169	554.346
570.65	524.196
574.129	544.712
577.609	546.562
581.085	533.078
584.56	538.261
588.034	544.111
591.506	539.961
594.978	520.477
598.447	552.993
601.916	541.509
605.383	550.026
608.849	559.209
612.313	535.725
615.776	565.575
619.238	550.758
622.699	575.94
626.156	564.457
629.614	572.973
633.071	560.156
636.526	565.339
639.978	572.522
643.431	559.705
646.88	548.221
650.33	560.738
653.779	555.92
657.224	547.77
660.67	564.953
664.113	546.136
667.556	547.986
670.997	577.835
674.435	559.018
677.875	556.201
681.311	560.051
684.746	576.567
688.182	567.083
691.614	555.6
695.045	551.449
698.475	564.632
701.904	567.149
705.333	583.665
708.759	574.181
712.183	559.364
715.606	575.214
719.028	571.73
722.449	574.913
725.868	555.429
729.286	566.612
732.703	571.129
736.117	578.978
739.531	564.828
742.944	577.344
746.355	564.527
749.766	559.71
753.173	574.893
756.581	563.409
759.987	583.259
763.39	570.442
766.794	579.625
770.195	564.141
773.596	583.991
776.994	572.507
780.393	579.023
783.788	576.206
787.185	568.723
790.578	567.906
793.971	569.089
797.362	556.272
800.751	582.121
804.138	574.637
807.527	568.487
810.912	589.003
814.296	596.853
817.679	586.036
821.06	591.219
824.441	597.735
827.822	583.585
831.199	606.101
834.576	599.284
837.951	600.467
841.323	590.317
844.695	594.166
848.066	604.683
851.436	607.866
854.805	599.715
858.173	597.565
861.539	607.414
864.902	627.931
868.266	615.114
871.628	603.63
874.987	613.48
878.347	599.329
881.704	610.512
885.061	583.695
888.418	588.878
891.771	594.728
895.122	578.577
898.475	573.76
901.824	600.943
905.174	604.793
908.52	601.309
911.866	603.159
915.212	576.342
918.555	582.858
921.896	594.708
925.237	583.224
928.576	582.407
931.914	598.257
935.253	600.773
938.588	601.289
941.922	603.806
945.255	592.322
948.587	618.172
951.917	624.688
955.244	602.537
958.572	610.387
961.899	635.57
965.225	595.42
968.549	621.936
971.872	613.786
975.192	616.302
978.512	596.818
981.831	610.668
985.148	606.517
988.464	583.7
991.778	610.217
995.092	602.066
998.404	619.916
1001.72	629.766
1005.02	629.615
1008.33	649.465
1011.64	640.648
1014.95	629.831
1018.25	629.014
1021.55	627.53
1024.85	625.38
1028.16	627.229
1031.46	627.079
1034.75	628.928
1038.05	616.111
1041.34	607.961
1044.64	628.477
1047.93	623.66
1051.22	628.843
1054.51	648.693
1057.8	641.209
1061.09	625.059
1064.38	636.908
1067.66	663.425
1070.95	641.941
1074.23	646.457
1077.51	640.307
1080.79	637.49
1084.07	610.006
1087.35	626.523
1090.62	664.372
1093.9	629.555
1097.17	631.405
1100.44	626.588
1103.71	643.104
1106.99	636.954
1110.25	620.137
1113.52	642.653
1116.79	632.503
1120.05	631.019
1123.31	658.202
1126.58	652.718
1129.84	656.568
1133.1	645.751
1136.36	657.6
1139.61	645.45
1142.87	667.3
1146.12	670.482
1149.38	688.332
1152.63	754.848
1155.88	760.031
1159.13	774.548
1162.38	754.397
1165.63	696.247
1168.87	687.43
1172.12	648.613
1175.36	673.129
1178.6	652.979
1181.84	682.162
1185.08	683.345
1188.32	685.861
1191.56	692.377
1194.79	663.56
1198.03	662.743
1201.26	655.926
1204.49	680.443
1207.72	648.959
1210.95	656.142
1214.18	665.991
1217.41	645.841
1220.64	633.024
1223.86	649.54
1227.08	647.39
1230.3	632.573
1233.53	645.089
1236.75	629.605
1239.96	635.455
1243.18	657.305
1246.4	643.821
1249.61	605.004
1252.82	646.187
1256.04	640.037
1259.25	642.553
1262.46	681.736
1265.67	661.585
1268.87	649.435
1272.08	645.285
1275.28	651.134
1278.49	648.317
1281.69	644.834
1284.89	671.35
1288.09	659.199
1291.29	664.382
1294.49	646.232
1297.68	662.082
1300.88	680.598
1304.07	656.448
1307.26	636.964
1310.46	646.147
1313.65	669.33
1316.84	661.846
1320.02	670.362
1323.21	654.212
1326.39	662.062
1329.58	666.578
1332.76	656.428
1335.94	670.277
1339.12	652.127
1342.3	656.643
1345.48	678.493
1348.65	655.009
1351.83	662.192
1355	651.375
1358.18	668.558
1361.35	651.074
1364.52	660.924
1367.69	656.107
1370.86	653.956
1374.02	645.139
1377.19	662.322
1380.35	658.839
1383.52	640.022
1386.68	645.871
1389.84	659.721
1393	656.904
1396.16	675.42
1399.31	651.936
1402.47	663.119
1405.63	674.969
1408.78	664.819
1411.93	680.002
1415.08	663.851
1418.23	654.368
1421.38	657.551
1424.53	675.4
1427.68	651.916
1430.82	679.766
1433.96	680.949
1437.11	654.799
1440.25	661.315
1443.39	666.498
1446.53	668.348
1449.67	700.197
1452.8	667.38
1455.94	697.23
1459.07	658.413
1462.21	672.262
1465.34	688.112
1468.47	671.295
1471.6	670.478
1474.72	654.994
1477.85	674.177
1480.98	670.693
1484.1	651.876
1487.23	677.726
1490.35	665.576
1493.47	662.092
1496.59	669.942
1499.71	667.791
1502.83	697.641
1505.94	700.824
1509.06	700.007
1512.17	710.523
1515.29	769.706
1518.4	798.889
1521.51	846.072
1524.62	869.255
1527.72	871.771
1530.83	854.287
1533.94	820.804
1537.04	757.987
1540.15	731.17
1543.25	715.019
1546.35	700.202
1549.45	700.052
1552.55	669.902
1555.65	685.751
1558.74	680.268
1561.84	683.451
1564.93	662.633
1568.02	681.15
1571.12	688.333
1574.2	676.849
1577.3	676.032
1580.38	672.548
1583.47	664.398
1586.56	668.914
1589.64	668.764
1592.72	666.613
1595.81	675.13
1598.89	684.313
1601.97	684.162
1605.05	670.012
1608.12	672.718
1611.2	675.287
1614.27	666.519
1617.35	685.926
1620.42	676.891
1623.5	674.242
1626.57	673.304
1629.63	673.359
1632.7	668.838
1635.77	670.169
1638.84	659.931
1641.9	686.057
1644.97	669.896
1648.03	670.412
1651.09	669.054
1654.15	669.598
1657.21	675.186
1660.27	659.721
1663.32	665.425
1666.38	670.977
1669.43	683.796
1672.49	679.156
1675.54	675.388
1678.59	671.053
1681.64	668.058
1684.69	673.085
1687.73	675.747
1690.78	658.495
1693.83	671.884
1696.87	670.027
1699.91	675.697
1702.96	669.404
1706	671.343
1709.04	663.948
1712.07	683.153
1715.11	667.463
1718.15	655.498
1721.18	666.708
1724.21	650.993
1727.25	656.964
1730.28	640.411
1733.31	650.84
1736.34	647.242
1739.37	646.47
1742.39	645.87
1745.42	659.01
1748.45	648.304
1751.47	649.087
1754.49	636.344
1757.51	661.047
1759.25	658.354
1762.28	636.932
1765.31	648.842
1768.34	660.086
1771.37	663.33
1774.4	648.574
1777.43	643.151
1780.46	654.395
1783.48	658.973
1786.51	651.55
1789.53	636.794
1792.55	649.371
1795.57	647.282
1798.59	640.526
1801.61	659.769
1804.63	673.013
1807.64	669.591
1810.66	655.501
1813.67	656.078
1816.68	657.989
1819.7	641.9
1822.71	651.144
1825.72	657.721
1828.72	670.965
1831.73	653.542
1834.74	658.786
1837.74	658.697
1840.75	649.274
1843.75	651.184
1846.75	655.095
1849.75	672.339
1852.75	650.916
1855.75	646.16
1858.75	663.404
1861.74	649.981
1864.74	663.892
1867.73	639.802
1870.72	669.713
1873.71	650.29
1876.7	662.201
1879.69	660.112
1882.68	661.355
1885.67	655.933
1888.66	643.843
1891.64	643.754
1894.62	661.664
1897.61	650.242
1900.59	657.486
1903.57	649.396
1906.55	661.974
1909.53	647.217
1912.5	670.461
1915.48	638.372
1918.46	655.616
1921.43	637.526
1924.4	661.437
1927.37	673.348
1930.34	675.258
1933.31	656.502
1936.28	665.079
1939.25	644.99
1942.22	658.234
1945.18	656.145
1948.14	652.055
1951.11	654.632
1954.07	661.21
1957.03	649.787
1959.99	652.364
1962.95	650.275
1965.91	665.519
1968.86	659.429
1971.82	664.007
1974.77	657.917
1977.73	649.828
1980.68	661.738
1983.63	636.316
1986.58	646.893
1989.53	649.47
1992.47	652.714
1995.42	635.958
1998.37	661.869
2001.31	626.446
2004.25	647.69
2007.2	654.934
2010.14	662.178
2013.08	656.755
2016.02	653.332
2018.96	651.243
2021.89	659.82
2024.83	659.731
2027.76	648.974
2030.7	642.885
2033.63	656.129
2036.56	658.04
2039.49	657.95
2042.42	648.527
2045.35	633.105
2048.28	628.349
2051.2	657.593
2054.13	655.503
2057.05	632.747
2059.97	638.658
2062.9	645.902
2065.82	632.479
2068.74	645.723
2071.65	646.967
2074.57	638.877
2077.49	634.788
2080.4	642.032
2083.32	623.942
2086.23	645.853
2089.15	611.764
2092.05	651.674
2094.97	634.251
2097.87	642.829
2100.78	648.073
2103.69	632.65
2106.6	617.227
2109.5	625.138
2112.4	630.382
2115.31	656.959
2118.21	618.87
2121.11	626.78
2124.01	621.357
2126.91	634.601
2129.8	652.512
2132.7	634.422
2135.59	609
2138.49	631.577
2141.38	644.821
2144.27	640.065
2147.16	613.975
2150.05	625.219
2152.94	623.13
2155.83	627.707
2158.72	621.618
2161.6	640.862
2164.49	633.439
2167.37	618.683
2170.26	639.26
2173.14	627.171
2176.02	616.415
2178.9	628.325
2181.77	627.569
2184.65	636.146
2187.53	649.39
2190.4	627.968
2193.28	620.545
2196.15	611.122
2199.02	626.366
2201.89	620.277
2204.76	618.187
2207.63	621.431
2210.5	601.342
2213.37	601.252
2216.23	619.163
2219.1	600.407
2221.96	612.318
2224.82	604.228
2227.69	602.805
2230.55	592.716
2233.41	615.96
2236.26	607.204
2239.12	613.781
2241.98	613.025
2244.83	608.269
2247.69	576.846
2250.54	582.757
2253.39	599.334
2256.24	605.911
2259.09	598.489
2261.94	602.399
2264.79	590.976
2267.64	586.22
2270.49	586.798
2273.33	591.375
2276.18	598.619
2279.02	583.863
2281.86	593.773
2284.7	621.017
2287.54	601.595
2290.38	600.172
2293.22	598.082
2296.05	599.993
2298.89	589.237
2301.72	591.814
2304.56	597.725
2307.39	593.635
2310.22	593.546
2313.05	588.123
2315.88	584.034
2318.71	583.944
2321.54	585.855
2324.36	596.432
2327.19	607.009
2330.01	592.92
2332.84	599.497
2335.66	586.741
2338.48	588.652
2341.3	568.562
2344.12	571.806
2346.94	613.05
2349.76	596.294
2352.57	598.871
2355.39	584.782
2358.2	590.026
2361.02	591.27
2363.83	576.514
2366.64	573.091
2369.45	571.668
2372.26	586.246
2375.07	572.156
2377.87	574.733
2380.68	565.977
2383.49	565.888
2386.29	567.799
2389.09	559.043
2391.9	574.286
2394.7	570.864
2397.5	566.774
2400.29	576.685
2403.09	581.262
2405.89	580.506
2408.69	567.083
2411.48	552.327
2414.28	574.238
2417.07	566.148
2419.86	558.059
2422.65	579.97
2425.44	581.214
2428.23	560.458
2431.02	577.035
2433.81	593.612
2436.59	564.189
2439.38	550.767
2442.16	586.677
2444.94	585.921
2447.73	570.498
2450.51	559.742
2453.29	566.986
2456.07	550.897
2458.84	588.807
2461.62	588.718
2464.4	594.629
2467.17	565.872
2469.95	586.45
2472.72	575.694
2475.49	578.271
2478.26	574.848
2481.03	575.425
2483.8	568.669
2486.57	575.913
2489.34	582.491
2492.1	575.734
2494.87	580.978
2497.63	598.222
2500.39	594.8
2503.16	572.71
2505.92	586.621
2508.68	568.531
2511.44	568.442
2514.19	566.353
2516.95	574.263
2519.71	582.174
2522.46	567.418
2525.22	570.662
2527.97	568.572
2530.72	578.483
2533.47	567.06
2536.22	557.637
2538.97	564.881
2541.72	559.458
2544.47	560.702
2547.21	553.28
2549.96	565.857
2552.7	551.101
2555.45	582.345
2558.19	563.589
2560.93	571.499
2563.67	551.41
2566.41	555.32
2569.15	559.898
2571.89	559.142
2574.62	568.386
2577.36	551.63
2580.09	571.54
2582.83	571.451
2585.56	581.361
2588.29	558.605
2591.02	553.182
2593.75	573.76
2596.48	575.004
2599.21	562.914
2601.93	569.492
2604.66	580.069
2607.39	587.979
2610.11	568.557
2612.83	575.801
2615.55	577.711
2618.27	572.288
2620.99	582.199
2623.71	571.443
2626.43	578.687
2629.15	575.931
2631.86	569.175
2634.58	581.085
2637.29	570.329
2640.01	562.24
2642.72	569.484
2645.43	540.728
2648.14	579.972
2650.85	565.216
2653.56	572.459
2656.26	562.37
2658.97	560.947
2661.68	595.525
2664.38	542.102
2667.09	567.346
2669.79	570.59
2672.49	575.167
2675.19	577.744
2677.89	562.321
2680.59	572.232
2683.29	573.476
2685.98	568.053
2688.68	577.964
2691.37	567.874
2694.07	573.118
2696.76	567.696
2699.45	560.94
2702.14	569.517
2704.83	576.094
2707.52	565.338
2710.21	555.249
2712.9	558.492
2715.58	571.736
2718.27	550.314
2720.95	562.891
2723.64	570.802
2726.32	573.379
2729	565.289
2731.68	569.867
2734.36	537.111
2737.04	553.688
2739.72	572.265
2742.39	546.176
2745.07	576.753
2747.74	574.664
2750.42	569.241
2753.09	564.485
2755.76	555.062
2758.43	576.973
2761.1	582.883
2763.77	572.794
2766.44	570.038
2769.11	535.282
2771.78	547.859
2774.44	564.436
2777.11	549.68
2779.77	565.591
2782.43	564.835
2785.09	569.412
2787.76	566.656
2790.41	582.566
2793.07	574.477
2795.73	576.388
2798.39	555.631
2801.04	575.542
2803.7	572.119
2806.35	568.03
2809.01	567.274
2811.66	573.851
2814.31	560.428
2816.96	573.006
2819.61	579.583
2822.26	567.493
2824.91	561.404
2827.55	570.648
2830.2	575.225
2832.84	577.802
2835.49	570.38
2838.13	567.624
2840.77	574.868
2843.41	586.112
2846.05	578.022
2848.69	577.933
2851.33	583.177
2853.97	573.754
2856.6	580.331
2859.24	593.575
2861.87	588.152
2864.51	599.396
2867.14	600.64
2869.77	582.551
2872.4	600.461
2875.03	613.705
2877.66	620.949
2880.29	610.193
2882.92	604.104
2885.54	626.681
2888.17	619.258
2890.79	630.502
2893.42	632.413
2896.04	622.99
2898.66	639.567
2901.28	641.478
2903.9	627.388
2906.52	625.966
2909.14	623.876
2911.76	625.12
2914.37	635.031
2916.99	646.941
2919.6	642.185
2922.21	640.763
2924.83	644.673
2927.44	649.25
2930.05	633.828
2932.66	649.738
2935.27	652.982
2937.88	652.226
2940.48	658.137
2943.09	658.714
2945.69	643.958
2948.3	647.202
2950.9	655.112
2953.5	656.356
2956.1	647.6
2958.7	645.511
2961.3	636.088
2963.9	621.999
2966.5	620.576
2969.1	615.82
2971.69	609.064
2974.29	607.641
2976.88	620.218
2979.48	624.129
2982.07	596.04
2984.66	605.284
2987.25	609.194
2989.84	603.105
2992.43	595.015
2995.02	591.593
2997.6	594.837
3000.19	584.081
3002.77	589.324
3005.36	587.235
3007.94	580.479
3010.53	555.056
3013.11	574.3
3015.69	568.877
3018.27	570.788
3020.85	576.032
3023.42	574.609
3026	555.186
3028.58	571.097
3031.15	575.674
3033.73	557.585
3036.3	580.829
3038.87	571.406
3041.44	577.983
3044.01	587.227
3046.58	579.805
3047.87	575.76