File: muestras/manzana/mz_10.txt
#Acq. time (s)=	15
#Accumulations=	4
#Range (cm-¹)=	50...4000
#Windows=	3
#Autofocus=	Off
#AutoExposure=	Off
#Spike filter=	Multiple accum.
#Delay time (s)=	0
#Binning=	1
#Readout mode=	Signal
#DeNoise=	Off
#ICS correction=	Off
#Dark correction=	Off
#Inst. Process=	Off
#Instrument=	LabRAM HR Evol
#Detector=	Syncerity OE
#Objective=	x100_VIS
#Grating=	600 (500nm)
#ND Filter=	5%
#Laser=	532nm_Edge
#Hole=	100.021
#Range=	Visible
#Project=	Omar
#Sample=	120523
#Site=	ap
#Title=	mz
#Remark=	5 laser intensity
#Date=	12.05.2023 16:56
#Acquired=	12.05.2023 16:56:50
51.0297	26
54.7185	35.8496
58.406	50.3659
62.0919	92.2156
65.7765	144.065
69.4595	207.248
73.1412	293.764
76.8214	365.614
80.5001	404.797
84.1774	463.313
87.8532	485.83
91.5276	470.346
95.2006	479.529
98.8721	476.045
102.54	487.895
106.209	505.744
109.876	502.927
113.542	495.444
117.204	491.293
120.867	502.476
124.526	478.993
128.186	482.842
131.845	493.358
135.5	495.875
139.155	499.058
142.807	494.907
146.46	512.757
150.11	493.94
153.757	508.456
157.406	524.973
161.051	519.489
164.697	500.005
168.339	515.188
171.98	503.704
175.619	474.887
179.259	495.404
182.895	493.92
186.53	494.436
190.164	493.619
193.796	488.802
197.427	499.985
201.059	495.168
204.686	487.018
208.313	503.534
211.938	485.384
215.562	477.9
219.184	493.083
222.803	494.266
226.422	472.782
230.04	488.632
233.657	480.481
237.272	478.998
240.886	460.847
244.497	480.03
248.108	490.547
251.717	488.396
255.325	489.579
258.93	469.429
262.535	465.945
266.137	473.795
269.74	478.978
273.341	491.494
276.939	473.344
280.537	478.527
284.132	483.043
287.728	469.559
291.32	473.409
294.911	473.925
298.502	477.775
302.09	483.624
305.677	481.474
309.264	489.99
312.848	495.84
316.43	479.023
320.011	489.539
323.593	484.722
327.171	485.905
330.748	482.421
334.323	495.604
337.897	486.787
341.47	492.637
345.041	494.487
348.611	490.336
352.18	500.852
355.747	478.035
359.312	496.552
362.877	489.068
366.44	490.251
369.999	488.101
373.56	504.617
377.119	490.467
380.676	497.65
384.23	496.166
387.785	483.349
391.338	511.198
394.888	515.715
398.439	504.898
401.988	508.747
405.534	503.93
409.081	507.78
412.624	510.963
416.167	510.812
419.708	502.662
423.249	517.178
426.786	505.695
430.323	514.878
433.86	502.061
437.393	505.91
440.926	503.093
444.458	516.276
447.988	512.792
451.516	495.975
455.043	529.158
458.568	515.008
462.092	519.524
465.615	516.041
469.138	519.224
472.658	508.407
476.177	510.256
479.694	525.439
483.21	517.955
486.723	519.138
490.236	544.988
493.748	529.504
497.258	508.687
500.768	515.87
504.276	521.72
507.78	533.569
511.285	526.086
514.789	517.269
518.289	545.118
521.791	540.968
525.29	537.484
528.787	538.001
532.284	533.184
535.778	534.367
539.272	529.549
542.763	544.732
546.255	531.249
549.743	548.432
553.232	531.615
556.718	534.131
560.203	517.98
563.688	546.497
567.169	554.346
570.65	524.196
574.129	544.712
577.609	546.562
581.085	533.078
584.56	538.261
588.034	544.111
591.506	539.961
594.978	520.477
598.447	552.993
601.916	541.509
605.383	550.026
608.849	559.209
612.313	535.725
615.776	565.575
619.238	550.758
622.699	575.94
626.156	564.457
629.614	572.973
633.071	560.156
636.526	565.339
639.978	572.522
643.431	559.705
646.88	548.221
650.33	560.738
653.779	555.92
657.224	547.77
660.67	564.953
664.113	546.136
667.556	547.986
670.997	577.835
674.435	559.018
677.875	556.201
681.311	560.051
684.746	576.567
688.182	567.083
691.614	555.6
695.045	551.449
698.475	564.632
701.904	567.149
705.333	583.665
708.759	574.181
712.183	559.364
715.606	575.214
719.028	571.73
722.449	574.913
725.868	555.429
729.286	566.612
732.703	571.129
736.117	578.978
739.531	564.828
742.944	577.344
746.355	564.527
749.766	559.71
753.173	574.893
756.581	563.409
759.987	583.259
763.39	570.442
766.794	579.625
770.195	564.141
773.596	583.991
776.994	572.507
780.393	579.023
783.788	576.206
787.185	568.723
790.578	567.906
793.971	569.089
797.362	556.272
800.751	582.121
804.138	574.637
807.527	568.487
810.912	589.003
814.296	596.853
817.679	586.036
821.06	591.219
824.441	597.735
827.822	583.585
831.199	606.101
834.576	599.284
837.951	600.467
841.323	590.317
844.695	594.166
848.066	604.683
851.436	607.866
854.805	599.715
858.173	597.565
861.539	607.414
864.902	627.931
868.266	615.114
871.628	603.63
874.987	613.48
878.347	599.329
881.704	610.512
885.061	583.695
888.418	588.878
891.771	594.728
895.122	578.577
898.475	573.76
901.824	600.943
905.174	604.793
908.52	601.309
911.866	603.159
915.212	576.342
918.555	582.858
921.896	594.708
925.237	583.224
928.576	582.407
931.914	598.257
935.253	600.773
938.588	601.289
941.922	603.806
945.255	592.322
948.587	618.172
951.917	624.688
955.244	602.537
958.572	610.387
961.899	635.57
965.225	595.42
968.549	621.936
971.872	613.786
975.192	616.302
978.512	596.818
981.831	610.668
985.148	606.517
988.464	583.7
991.778	610.217
995.092	602.066
998.404	619.916
1001.72	629.766
1005.02	629.615
1008.33	649.465
1011.64	640.648
1014.95	629.831
1018.25	629.014
1021.55	627.53
1024.85	625.38
1028.16	627.229
1031.46	627.079
1034.75	628.928
1038.05	616.111
1041.34	607.961
1044.64	628.477
1047.93	623.66
1051.22	628.843
1054.51	648.693
1057.8	641.209
1061.09	625.059
1064.38	636.908
1067.66	663.425
1070.95	641.941
1074.23	646.457
1077.51	640.307
1080.79	637.49
1084.07	610.006
1087.35	626.523
1090.62	664.372
1093.9	629.555
1097.17	631.405
1100.44	626.588
1103.71	643.104
1106.99	636.954
1110.25	620.137
1113.52	642.653
1116.79	632.503
1120.05	631.019
1123.31	658.202
1126.58	652.718
1129.84	656.568
1133.1	645.751
1136.36	657.6
1139.61	645.45
1142.87	667.3
1146.12	670.482
1149.38	688.332
1152.63	754.848
1155.88	760.031
1159.13	774.548
1162.38	754.397
1165.63	696.247
1168.87	687.43
1172.12	648.613
1175.36	673.129
1178.6	652.979
1181.84	682.162
1185.08	683.345
1188.32	685.861
1191.56	692.377
1194.79	663.56
1198.03	662.743
1201.26	655.926
1204.49	680.443
1207.72	648.959
1210.95	656.142
1214.18	665.991
1217.41	645.841
1220.64	633.024
1223.86	649.54
1227.08	647.39
1230.3	632.573
1233.53	645.089
1236.75	629.605
1239.96	635.455
1243.18	657.305
1246.4	643.821
1249.61	605.004
1252.82	646.187
1256.04	640.037
1259.25	642.553
1262.46	681.736
1265.67	661.585
1268.87	649.435
1272.08	645.285
1275.28	651.134
1278.49	648.317
1281.69	644.834
1284.89	671.35
1288.09	659.199
1291.29	664.382
1294.49	646.232
1297.68	662.082
1300.88	680.598
1304.07	656.448
1307.26	636.964
1310.46	646.147
1313.65	669.33
1316.84	661.846
1320.02	670.362
1323.21	654.212
1326.39	662.062
1329.58	666.578
1332.76	656.428
1335.94	670.277
1339.12	652.127
1342.3	656.643
1345.48	678.493
1348.65	655.009
1351.83	662.192
1355	651.375
1358.18	668.558
1361.35	651.074
1364.52	660.924
1367.69	656.107
1370.86	653.956
1374.02	645.139
1377.19	662.322
1380.35	658.839
1383.52	640.022
1386.68	645.871
1389.84	659.721
1393	656.904
1396.16	675.42
1399.31	651.936
1402.47	663.119
1405.63	674.969
1408.78	664.819
1411.93	680.002
1415.08	663.851
1418.23	654.368
1421.38	657.551
1424.53	675.4
1427.68	651.916
1430.82	679.766
1433.96	680.949
1437.11	654.799
1440.25	661.315
1443.39	666.498
1446.53	668.348
1449.67	700.197
1452.8	667.38
1455.94	697.23
1459.07	658.413
1462.21	672.262
1465.34	688.112
1468.47	671.295
1471.6	670.478
1474.72	654.994
1477.85	674.177
1480.98	670.693
1484.1	651.876
1487.23	677.726
1490.35	665.576
1493.47	662.092
1496.59	669.942
1499.71	667.791
1502.83	697.641
1505.94	700.824
1509.06	700.007
1512.17	710.523
1515.29	769.706
1518.4	798.889
1521.51	846.072
1524.62	869.255
1527.72	871.771
1530.83	854.287
1533.94	820.804
1537.04	757.987
1540.15	731.17
1543.25	715.019
1546.35	700.202
1549.45	700.052
1552.55	669.902
1555.65	685.751
1558.74	680.268
1561.84	683.451
1564.93	662.633
1568.02	681.15
1571.12	688.333
1574.2	676.849
1577.3	676.032
1580.38	672.548
1583.47	664.398
1586.56	668.914
1589.64	668.764
1592.72	666.613
1595.81	675.13
1598.89	684.313
1601.97	684.162
1605.05	670.012
1608.12	672.718
1611.2	675.287
1614.27	666.519
1617.35	685.926
1620.42	676.891
1623.5	674.242
1626.57	673.304
1629.63	673.359
1632.7	668.838
1635.77	670.169
1638.84	659.931
1641.9	686.057
1644.97	669.896
1648.03	670.412
1651.09	669.054
1654.15	669.598
1657.21	675.186
1660.27	659.721
1663.32	665.425
1666.38	670.977
1669.43	683.796
1672.49	679.156
1675.54	675.388
1678.59	671.053
1681.64	668.058
1684.69	673.085
1687.73	675.747
1690.78	658.495
1693.83	671.884
1696.87	670.027
1699.91	675.697
1702.96	669.404
1706	671.343
1709.04	663.948
1712.07	683.153
1715.11	667.463
1718.15	655.498
1721.18	666.708
1724.21	650.993
1727.25	656.964
1730.28	640.411
1733.31	650.84
1736.34	647.242
1739.37	646.47
1742.39	645.87
1745.42	659.01
1748.45	648.304
1751.47	649.087
1754.49	636.344
1757.51	661.047
1759.25	658.354
1762.28	636.932
1765.31	648.842
1768.34	660.086
1771.37	663.33
1774.4	648.574
1777.43	643.151
1780.46	654.395
1783.48	658.973
1786.51	651.55
1789.53	636.794
1792.55	649.371
1795.57	647.282
1798.59	640.526
1801.61	659.769
1804.63	673.013
1807.64	669.591
1810.66	655.501
1813.67	656.129
1816.68	658.089
1819.7	642.05
1822.71	651.344
1825.72	657.971
1828.72	671.265
1831.73	653.892
1834.74	659.186
1837.74	659.147
1840.75	649.774
1843.75	651.735
1846.75	655.695
1849.75	672.989
1852.75	651.617
1855.75	646.911
1858.75	664.205
1861.74	650.832
1864.74	664.792
1867.73	640.753
1870.72	670.714
1873.71	651.341
1876.7	663.302
1879.69	661.262
1882.68	662.556
1885.67	657.184
1888.66	645.144
1891.64	645.105
1894.62	663.066
1897.61	651.693
1900.59	658.987
1903.57	650.947
1906.55	663.575
1909.53	648.869
1912.5	672.163
1915.48	640.123
1918.46	657.417
1921.43	639.378
1924.4	663.339
1927.37	675.299
1930.34	677.26
1933.31	658.554
1936.28	667.181
1939.25	647.142
1942.22	660.436
1945.18	658.396
1948.14	654.357
1951.11	656.984
1954.07	663.611
1957.03	652.239
1959.99	654.866
1962.95	652.827
1965.91	668.121
1968.86	662.081
1971.82	666.709
1974.77	660.669
1977.73	652.63
1980.68	664.59
1983.63	639.218
1986.58	649.845
1989.53	652.472
1992.47	655.766
1995.42	639.06
1998.37	665.021
2001.31	629.648
2004.25	650.942
2007.2	658.236
2010.14	665.53
2013.08	660.157
2016.02	656.785
2018.96	654.745
2021.89	663.373
2024.83	663.333
2027.76	652.627
2030.7	646.588
2033.63	659.882
2036.56	661.842
2039.49	661.803
2042.42	652.43
2045.35	637.058
2048.28	632.352
2051.2	661.646
2054.13	659.606
2057.05	636.9
2059.97	642.861
2062.9	650.155
2065.82	636.782
2068.74	650.076
2071.65	651.37
2074.57	643.331
2077.49	639.291
2080.4	646.585
2083.32	628.546
2086.23	650.507
2089.15	616.467
2092.05	656.428
2094.97	639.055
2097.87	647.682
2100.78	652.976
2103.69	637.604
2106.6	622.231
2109.5	630.192
2112.4	635.486
2115.31	662.113
2118.21	624.073
2121.11	632.034
2124.01	626.661
2126.91	639.955
2129.8	657.916
2132.7	639.877
2135.59	614.504
2138.49	637.131
2141.38	650.425
2144.27	645.719
2147.16	619.68
2150.05	630.974
2152.94	628.934
2155.83	633.562
2158.72	627.522
2161.6	646.816
2164.49	639.443
2167.37	624.737
2170.26	645.365
2173.14	633.325
2176.02	622.619
2178.9	634.58
2181.77	633.874
2184.65	642.501
2187.53	655.795
2190.4	634.422
2193.28	627.05
2196.15	617.677
2199.02	632.971
2201.89	626.932
2204.76	624.892
2207.63	628.186
2210.5	608.147
2213.37	608.108
2216.23	626.068
2219.1	607.362
2221.96	619.323
2224.82	611.283
2227.69	609.911
2230.55	599.871
2233.41	623.165
2236.26	614.459
2239.12	621.087
2241.98	620.381
2244.83	615.674
2247.69	584.302
2250.54	590.262
2253.39	606.89
2256.24	613.517
2259.09	606.144
2261.94	610.105
2264.79	598.732
2267.64	594.026
2270.49	594.654
2273.33	599.281
2276.18	606.575
2279.02	591.869
2281.86	601.829
2284.7	629.123
2287.54	609.751
2290.38	608.378
2293.22	606.339
2296.05	608.299
2298.89	597.593
2301.72	600.22
2304.56	606.181
2307.39	602.142
2310.22	602.102
2313.05	596.73
2315.88	592.69
2318.71	592.651
2321.54	594.612
2324.36	605.239
2327.19	615.866
2330.01	601.827
2332.84	608.454
2335.66	595.748
2338.48	597.709
2341.3	577.669
2344.12	580.963
2346.94	622.257
2349.76	605.551
2352.57	608.178
2355.39	594.139
2358.2	599.433
2361.02	600.727
2363.83	586.021
2366.64	582.648
2369.45	581.276
2372.26	595.903
2375.07	581.864
2377.87	584.491
2380.68	575.785
2383.49	575.745
2386.29	577.706
2389.09	569
2391.9	584.294
2394.7	580.921
2397.5	576.882
2400.29	586.843
2403.09	591.47
2405.89	590.764
2408.69	577.391
2411.48	562.685
2414.28	584.646
2417.07	576.606
2419.86	568.567
2422.65	590.528
2425.44	591.821
2428.23	571.115
2431.02	587.743
2433.81	604.37
2436.59	574.997
2439.38	561.625
2442.16	597.585
2444.94	596.879
2447.73	581.507
2450.51	570.8
2453.29	578.094
2456.07	562.055
2458.84	600.016
2461.62	599.976
2464.4	605.937
2467.17	577.231
2469.95	597.858
2472.72	587.152
2475.49	589.78
2478.26	586.407
2481.03	587.034
2483.8	580.328
2486.57	587.622
2489.34	594.249
2492.1	587.543
2494.87	592.837
2497.63	610.131
2500.39	606.759
2503.16	584.719
2505.92	598.68
2508.68	580.64
2511.44	580.601
2514.19	578.562
2516.95	586.522
2519.71	594.483
2522.46	579.777
2525.22	583.071
2527.97	581.031
2530.72	590.992
2533.47	579.619
2536.22	570.247
2538.97	577.541
2541.72	572.168
2544.47	573.462
2547.21	566.089
2549.96	578.716
2552.7	564.01
2555.45	595.305
2558.19	576.598
2560.93	584.559
2563.67	564.52
2566.41	568.48
2569.15	573.108
2571.89	572.402
2574.62	581.696
2577.36	564.99
2580.09	584.95
2582.83	584.911
2585.56	594.871
2588.29	572.165
2591.02	566.793
2593.75	587.42
2596.48	588.714
2599.21	576.674
2601.93	583.302
2604.66	593.929
2607.39	601.89
2610.11	582.517
2612.83	589.811
2615.55	591.772
2618.27	586.399
2620.99	596.36
2623.71	585.654
2626.43	592.948
2629.15	590.242
2631.86	583.535
2634.58	595.496
2637.29	584.79
2640.01	576.751
2642.72	584.045
2645.43	555.339
2648.14	594.633
2650.85	579.927
2653.56	587.22
2656.26	577.181
2658.97	575.808
2661.68	610.436
2664.38	557.063
2667.09	582.357
2669.79	585.651
2672.49	590.278
2675.19	592.906
2677.89	577.533
2680.59	587.493
2683.29	588.787
2685.98	583.415
2688.68	593.375
2691.37	583.336
2694.07	588.63
2696.76	583.257
2699.45	576.551
2702.14	585.179
2704.83	591.806
2707.52	581.1
2710.21	571.06
2712.9	574.354
2715.58	587.648
2718.27	566.276
2720.95	578.903
2723.64	586.864
2726.32	589.491
2729	581.452
2731.68	586.079
2734.36	553.373
2737.04	570
2739.72	588.627
2742.39	562.588
2745.07	593.215
2747.74	591.176
2750.42	585.803
2753.09	581.097
2755.76	571.724
2758.43	593.685
2761.1	599.646
2763.77	589.606
2766.44	586.9
2769.11	552.194
2771.78	564.822
2774.44	581.449
2777.11	566.743
2779.77	582.703
2782.43	581.997
2785.09	586.625
2787.76	583.919
2790.41	599.879
2793.07	591.84
2795.73	593.801
2798.39	573.095
2801.04	593.055
2803.7	589.682
2806.35	585.643
2809.01	584.937
2811.66	591.564
2814.31	578.192
2816.96	590.819
2819.61	597.446
2822.26	585.407
2824.91	579.367
2827.55	588.661
2830.2	593.289
2832.84	595.916
2835.49	588.543
2838.13	585.837
2840.77	593.131
2843.41	604.425
2846.05	596.386
2848.69	596.346
2851.33	601.641
2853.97	592.268
2856.6	598.895
2859.24	612.189
2861.87	606.816
2864.51	618.11
2867.14	619.404
2869.77	601.365
2872.4	619.326
2875.03	632.62
2877.66	639.914
2880.29	629.207
2882.92	623.168
2885.54	645.795
2888.17	638.423
2890.79	649.717
2893.42	651.677
2896.04	642.305
2898.66	658.932
2901.28	660.892
2903.9	646.853
2906.52	645.48
2909.14	643.441
2911.76	644.735
2914.37	654.696
2916.99	666.656
2919.6	661.737
2922.21	660.555
2924.83	664.531
2927.44	668.949
2930.05	654.949
2932.66	669.584
2935.27	673.741
2937.88	672.2
2940.48	678.181
2943.09	681.452
2945.69	667.438
2948.3	672.017
2950.9	676.704
2953.5	673.19
2956.1	666.364
2958.7	664.278
2961.3	652.729
2963.9	646.83
2966.5	640.772
2969.1	633.413
2971.69	637.099
2974.29	624.282
2976.88	635.372
2979.48	645.292
2982.07	623.15
2984.66	627.396
2987.25	621.436
2989.84	617.129
2992.43	613.332
2995.02	609.699
2997.6	620.704
3000.19	610.438
3002.77	608.764
3005.36	602.151
3007.94	601.919
3010.53	600.591
3013.11	614.749
3015.69	598.618
3018.27	592.414
3020.85	593.447
3023.42	596.843
3026	590.754
3028.58	602.814
3031.15	606.726
3033.73	578.867
3036.3	597.027
3038.87	593.374
3041.44	611.416
3044.01	614.629
3046.58	609.973
3048.04	593.268
3050.62	619.256
3053.2	625.243
3055.77	605.897
3058.35	609.885
3060.93	601.206
3063.51	615.86
3066.08	620.514
3068.66	616.502
3071.23	602.489
3073.8	617.144
3076.37	617.798
3078.94	641.119
3081.51	627.106
3084.08	631.094
3086.65	635.081
3089.22	645.069
3091.78	639.056
3094.35	639.044
3096.91	629.031
3099.48	631.019
3102.04	639.007
3104.6	654.994
3107.16	663.648
3109.72	656.302
3112.28	652.29
3114.84	654.944
3117.4	674.932
3119.96	658.253
3122.51	674.24
3125.07	686.894
3127.62	656.215
3130.18	670.203
3132.73	661.524
3135.28	683.511
3137.83	691.499
3140.38	700.153
3142.93	694.807
3145.47	692.795
3148.02	701.449
3150.57	722.77
3153.11	723.424
3155.66	712.745
3158.2	692.732
3160.74	723.387
3163.28	727.374
3165.83	744.028
3168.37	723.349
3170.91	742.67
3173.44	741.324
3175.98	753.312
3178.52	750.633
3181.05	760.62
3183.59	760.608
3186.12	759.929
3188.66	750.583
3191.19	755.237
3193.72	774.558
3196.25	763.879
3198.78	772.533
3201.31	759.854
3203.84	770.508
3206.36	773.829
3208.89	785.817
3211.41	773.804
3213.94	791.125
3216.46	775.779
3218.99	771.767
3221.51	777.088
3224.03	775.075
3226.55	769.063
3229.07	793.717
3231.59	769.038
3234.1	785.025
3236.62	780.346
3239.13	786.334
3241.65	774.321
3244.16	782.309
3246.68	762.297
3249.19	783.617
3251.7	778.938
3254.21	779.592
3256.72	775.58
3259.23	794.234
3261.74	789.555
3264.25	779.543
3266.75	796.863
3269.26	784.184
3271.76	783.505
3274.27	773.493
3276.77	771.48
3279.27	773.468
3281.77	800.122
3284.27	769.443
3286.77	768.764
3289.27	768.085
3291.77	788.072
3294.27	789.393
3296.76	806.047
3299.26	793.368
3301.75	800.689
3304.24	794.01
3306.74	795.997
3309.23	781.318
3311.72	793.973
3314.21	766.627
3316.7	798.614
3319.19	799.935
3321.68	785.256
3324.16	799.91
3326.65	802.565
3329.13	801.885
3331.62	793.206
3334.1	798.527
3336.58	799.848
3339.07	783.836
3341.55	794.49
3344.03	801.144
3346.51	809.798
3348.99	787.786
3351.46	799.107
3353.94	807.094
3356.42	804.415
3358.89	790.403
3361.36	781.057
3363.84	780.378
3366.31	788.365
3368.78	820.353
3371.25	802.34
3373.72	809.661
3376.19	779.649
3378.66	804.97
3381.13	797.624
3383.59	800.945
3386.06	821.599
3388.52	780.253
3390.99	774.907
3393.45	810.895
3395.91	810.882
3398.38	783.537
3400.84	812.191
3403.3	806.178
3405.76	810.833
3408.21	808.82
3410.67	812.808
3413.13	802.795
3415.58	822.116
3418.04	822.77
3420.49	807.425
3422.95	820.745
3425.4	821.4
3427.85	804.721
3430.3	800.041
3432.75	812.029
3435.2	804.683
3437.65	816.004
3440.1	823.325
3442.54	807.979
3444.99	815.3
3447.43	789.954
3449.88	812.608
3452.32	813.929
3454.76	805.917
3457.21	818.571
3459.65	789.892
3462.09	784.546
3464.53	793.2
3466.96	790.521
3469.4	808.509
3471.84	788.496
3474.27	773.15
3476.71	795.805
3479.14	787.126
3481.58	776.446
3484.01	771.767
3486.44	776.422
3488.87	777.076
3491.3	757.73
3493.73	759.718
3496.16	750.372
3498.59	756.359
3501.01	743.013
3503.44	734.334
3505.87	720.322
3508.29	712.976
3510.71	720.964
3513.14	692.284
3515.56	706.272
3517.98	709.593
3520.4	711.58
3522.82	701.568
3525.24	674.889
3527.66	688.21
3530.07	679.531
3532.49	700.852
3534.9	679.506
3537.32	671.493
3539.73	677.481
3542.15	652.802
3544.56	653.456
3546.97	662.777
3549.38	646.764
3551.79	645.419
3554.2	658.073
3556.61	644.06
3559.02	648.715
3561.42	639.369
3563.83	646.69
3566.23	640.01
3568.64	644.665
3571.04	621.986
3573.44	641.973
3575.84	628.627
3578.25	637.281
3580.65	618.602
3583.04	624.59
3585.44	621.911
3587.84	607.232
3590.24	619.219
3592.63	617.873
3595.03	621.194
3597.42	613.849
3599.82	606.503
3602.21	616.49
3604.6	599.811
3606.99	605.132
3609.38	585.786
3611.77	602.44
3614.16	576.428
3616.55	573.749
3618.94	603.736
3621.32	592.391
3623.71	586.378
3626.09	583.699
3628.48	589.687
3630.86	580.341
3633.24	561.662
3635.63	579.649
3638.01	583.637
3640.39	563.624
3642.77	555.612
3645.15	571.599
3647.52	570.254
3649.9	543.574
3652.28	571.562
3654.65	554.216
3657.03	551.537
3659.4	549.525
3661.77	537.512
3664.14	544.833
3666.52	544.154
3668.89	552.808
3671.25	534.796
3673.62	526.783
3675.99	541.438
3678.36	530.092
3680.73	520.746
3683.09	516.067
3685.46	506.054
3687.82	511.375
3690.19	521.363
3692.55	504.684
3694.91	511.338
3697.27	487.992
3699.63	503.313
3701.99	509.3
3704.35	510.621
3706.71	514.609
3709.06	513.93
3711.42	511.251
3713.78	494.571
3716.13	505.892
3718.48	516.547
3720.84	511.201
3723.19	509.855
3725.54	516.509
3727.89	498.497
3730.24	529.151
3732.59	507.138
3734.94	512.459
3737.29	523.114
3739.64	533.768
3741.98	526.422
3744.33	524.41
3746.67	533.73
3749.02	515.051
3751.36	539.039
3753.7	542.36
3756.04	523.681
3758.38	541.668
3760.72	512.322
3763.06	544.31
3765.4	532.297
3767.74	550.285
3770.08	546.273
3772.41	539.593
3774.75	552.248
3777.08	550.235
3779.41	538.889
3781.75	543.544
3784.08	549.531
3786.41	544.852
3788.74	560.839
3791.07	545.494
3793.4	534.815
3795.73	550.802
3798.06	546.79
3800.38	560.111
3802.71	552.765
3805.03	548.752
3807.36	548.74
3809.68	552.061
3812.01	557.382
3814.33	556.036
3816.65	559.357
3818.97	552.678
3821.29	575.332
3823.61	559.319
3825.93	557.974
3828.24	580.628
3830.56	568.615
3832.88	563.27
3835.19	585.257
3837.51	581.911
3839.82	587.899
3842.13	583.886
3844.45	592.541
3846.76	577.195
3849.07	587.182
3851.38	579.837
3853.69	609.824
3856	599.145
3858.3	605.133
3860.61	580.453
3862.92	606.441
3865.22	595.762
3867.53	607.083
3869.83	607.07
3872.13	623.058
3874.43	614.379
3876.74	621.033
3879.04	631.02
3881.34	631.008
3883.64	634.329
3885.93	621.65
3888.23	643.637
3890.53	646.291
3892.83	648.279
3895.12	666.267
3897.41	664.921
3899.71	658.908
3902	650.896
3904.29	658.883
3906.59	660.204
3908.88	690.192
3911.17	668.179
3913.46	681.5
3915.75	684.154
3918.03	698.142
3920.32	697.463
3922.61	701.45
3924.89	700.771
3927.18	697.425
3929.46	694.746
3931.74	708.734
3934.03	723.388
3936.31	714.709
3938.59	733.363
3940.87	720.017
3943.15	726.005
3945.43	750.659
3947.71	719.313
3949.98	725.968
3952.26	732.622
3954.54	721.943
3956.81	729.263
3959.09	732.584
3961.36	755.239
3963.63	755.893
3965.9	747.214
3968.18	737.201
3970.45	754.522
3972.72	772.51
3974.99	761.831
3977.25	767.151
3979.52	773.139
3981.79	781.127
3984.05	769.781
3986.32	789.102
3988.58	789.756
3990.85	785.743
3993.11	793.064
3995.37	791.052
3997.64	831.039
3999.9	810.36