File: muestras/manzana/mz_19.txt
#Acq. time (s)=	20
#Accumulations=	8
#Range (cm-¹)=	50...4000
#Windows=	3
#Autofocus=	Off
#AutoExposure=	Off
#Spike filter=	Multiple accum.
#Delay time (s)=	0
#Binning=	1
#Readout mode=	Signal
#DeNoise=	Off
#ICS correction=	Off
#Dark correction=	Off
#Inst. Process=	Off
#Instrument=	LabRAM HR Evol
#Detector=	Syncerity OE
#Objective=	x100_VIS
#Grating=	600 (500nm)
#ND Filter=	5%
#Laser=	532nm_Edge
#Hole=	100.021
#Range=	Visible
#Project=	Omar
#Sample=	120523
#Site=	ap
#Title=	mz
#Remark=	5 laser intensity
#Date=	12.05.2023 17:01
#Acquired=	12.05.2023 17:01:16
51.0297	26.5714
54.7185	34.6951
58.406	52.8187
62.0919	110.085
65.7765	178.78
69.4595	257.761
73.1412	363.885
76.8214	442.294
80.5001	496.132
84.1774	563.684
87.8532	578.379
91.5276	601.36
95.2006	585.483
98.8721	593.321
102.54	600.588
106.209	608.711
109.876	612.549
113.542	615.244
117.204	616.225
120.867	605.492
124.526	602.472
128.186	602.596
131.845	600.72
135.5	616.843
139.155	613.253
142.807	609.091
146.46	619.5
150.11	619.624
153.757	630.89
157.406	609.585
161.051	622.566
164.697	611.832
168.339	625.099
171.98	619.222
175.619	613.632
179.259	613.184
182.895	620.45
186.53	620.288
190.164	610.126
193.796	616.25
197.427	615.231
201.059	603.069
204.686	601.764
208.313	610.459
211.938	602.582
215.562	600.42
219.184	592.83
222.803	591.239
226.422	580.505
230.04	587.2
233.657	597.324
237.272	582.305
240.886	589.857
244.497	591.409
248.108	590.676
251.717	578.228
255.325	595.494
258.93	585.618
262.535	578.599
266.137	580.151
269.74	589.703
273.341	583.541
276.939	581.95
280.537	574.36
284.132	578.769
287.728	565.178
291.32	584.159
294.911	572.283
298.502	578.121
302.09	566.816
305.677	576.368
309.264	588.777
312.848	598.329
316.43	591.882
320.011	578.005
323.593	600.129
327.171	591.395
330.748	581.805
334.323	595.928
337.897	588.338
341.47	587.604
345.041	597.442
348.611	593.566
352.18	567.689
355.747	586.956
359.312	587.365
362.877	582.632
366.44	585.041
369.999	597.736
373.56	595.86
377.119	599.698
380.676	600.964
384.23	602.23
387.785	609.211
391.338	605.049
394.888	593.173
398.439	601.868
401.988	610.563
405.534	601.829
409.081	605.382
412.624	613.791
416.167	612.772
419.708	623.752
423.249	606.162
426.786	616
430.323	599.838
433.86	600.818
437.393	600.942
440.926	601.066
444.458	608.046
447.988	606.17
451.516	626.865
455.043	616.132
458.568	619.112
462.092	622.664
465.615	620.217
469.138	631.483
472.658	624.75
476.177	611.445
479.694	613.283
483.21	619.692
486.723	624.387
490.236	620.796
493.748	623.491
497.258	631.615
500.768	618.024
504.276	639.005
507.78	625.414
511.285	619.538
514.789	631.376
518.289	639.5
521.791	641.337
525.29	660.604
528.787	636.442
532.284	641.137
535.778	631.832
539.272	624.527
542.763	629.793
546.255	648.203
549.743	638.041
553.232	643.021
556.718	632.574
560.203	639.554
563.688	624.535
567.169	642.373
570.65	626.497
574.129	638.049
577.609	637.03
581.085	642.01
584.56	643.848
588.034	642.829
591.506	655.238
594.978	643.076
598.447	644.914
601.916	652.181
605.383	641.447
608.849	652.999
612.313	658.552
615.776	658.104
619.238	667.37
622.699	664.065
626.156	669.903
629.614	694.884
633.071	672.151
636.526	670.274
639.978	654.112
643.431	655.093
646.88	666.931
650.33	662.197
653.779	656.607
657.224	661.016
660.67	649.425
664.113	677.549
667.556	650.244
670.997	662.367
674.435	661.92
677.875	661.472
681.311	675.596
684.746	658.005
688.182	657.843
691.614	655.395
695.045	658.09
698.475	673.357
701.904	664.623
705.333	668.175
708.759	670.299
712.183	676.137
715.606	668.832
719.028	665.813
722.449	662.222
725.868	671.488
729.286	666.183
732.703	668.307
736.117	669.002
739.531	661.983
742.944	659.821
746.355	659.944
749.766	663.211
753.173	656.477
756.581	686.029
759.987	665.582
763.39	682.277
766.794	672.686
770.195	673.953
773.596	662.648
776.994	674.485
780.393	671.466
783.788	665.304
787.185	675.428
790.578	657.551
793.971	676.247
797.362	676.084
800.751	678.208
804.138	675.76
807.527	675.884
810.912	675.722
814.296	690.131
817.679	684.826
821.06	694.378
824.441	703.645
827.822	698.626
831.199	704.178
834.576	696.873
837.951	708.425
841.323	708.834
844.695	695.529
848.066	706.51
851.436	694.92
854.805	708.186
858.173	711.738
861.539	692.148
864.902	721.7
868.266	712.109
871.628	714.233
874.987	696.071
878.347	700.48
881.704	705.461
885.061	696.727
888.418	681.994
891.771	676.974
895.122	685.384
898.475	688.65
901.824	678.202
905.174	678.897
908.52	681.307
911.866	680.573
915.212	686.983
918.555	691.106
921.896	683.516
925.237	692.782
928.576	683.477
931.914	692.172
935.253	689.439
938.588	697.562
941.922	690.257
945.255	706.095
948.587	705.647
951.917	700.343
955.244	692.18
958.572	712.304
961.899	697.856
965.225	696.837
968.549	708.961
971.872	690.798
975.192	712.636
978.512	703.903
981.831	718.884
985.148	707.007
988.464	721.131
991.778	701.826
995.092	703.664
998.404	711.216
1001.72	711.34
1005.02	746.32
1008.33	727.873
1011.64	723.139
1014.95	714.691
1018.25	717.386
1021.55	709.51
1024.85	701.634
1028.16	714.043
1031.46	719.309
1034.75	711.433
1038.05	712.128
1041.34	716.823
1044.64	723.518
1047.93	713.07
1051.22	731.765
1054.51	738.461
1057.8	740.87
1061.09	730.708
1064.38	727.403
1067.66	742.098
1070.95	732.507
1074.23	742.631
1077.51	726.469
1080.79	732.021
1084.07	735.002
1087.35	742.554
1090.62	731.82
1093.9	738.801
1097.17	728.639
1100.44	735.334
1103.71	732.886
1106.99	730.724
1110.25	721.705
1113.52	712.4
1116.79	718.238
1120.05	734.362
1123.31	740.485
1126.58	738.894
1129.84	748.161
1133.1	721.427
1136.36	740.123
1139.61	736.818
1142.87	745.513
1146.12	749.636
1149.38	762.331
1152.63	805.312
1155.88	829.721
1159.13	825.845
1162.38	799.683
1165.63	754.092
1168.87	760.216
1172.12	745.482
1175.36	739.606
1178.6	750.872
1181.84	743.853
1185.08	757.405
1188.32	769.529
1191.56	752.224
1194.79	752.062
1198.03	743.9
1201.26	737.166
1204.49	761.576
1207.72	739.128
1210.95	752.966
1214.18	755.089
1217.41	735.213
1220.64	741.908
1223.86	725.175
1227.08	739.584
1230.3	720.565
1233.53	733.545
1236.75	712.812
1239.96	728.078
1243.18	714.202
1246.4	726.326
1249.61	737.306
1252.82	747.144
1256.04	740.697
1259.25	747.106
1262.46	738.658
1265.67	755.068
1268.87	746.62
1272.08	743.886
1275.28	740.867
1278.49	749.848
1281.69	746.828
1284.89	746.381
1288.09	740.361
1291.29	738.914
1294.49	729.037
1297.68	740.589
1300.88	751.284
1304.07	759.408
1307.26	746.103
1310.46	744.512
1313.65	754.35
1316.84	758.474
1320.02	758.598
1323.21	744.15
1326.39	760.845
1329.58	766.683
1332.76	750.521
1335.94	749.216
1339.12	750.482
1342.3	745.463
1345.48	743.872
1348.65	753.424
1351.83	764.977
1355	745.1
1358.18	754.081
1361.35	747.919
1364.52	755.185
1367.69	758.166
1370.86	727.147
1374.02	768.128
1377.19	737.394
1380.35	751.518
1383.52	740.499
1386.68	735.765
1389.84	743.032
1393	742.87
1396.16	752.707
1399.31	736.831
1402.47	755.526
1405.63	747.078
1408.78	750.916
1411.93	746.183
1415.08	742.878
1418.23	755.573
1421.38	753.696
1424.53	756.963
1427.68	758.801
1430.82	760.067
1433.96	775.334
1437.11	768.6
1440.25	758.152
1443.39	772.847
1446.53	757.828
1449.67	774.809
1452.8	782.933
1455.94	765.913
1459.07	774.037
1462.21	753.303
1465.34	782.856
1468.47	758.694
1471.6	753.96
1474.72	766.369
1477.85	750.207
1480.98	742.902
1484.1	766.74
1487.23	752.007
1490.35	739.845
1493.47	753.397
1496.59	773.235
1499.71	755.358
1502.83	761.482
1505.94	768.748
1509.06	782.301
1512.17	810.424
1515.29	836.548
1518.4	850.672
1521.51	877.938
1524.62	888.347
1527.72	907.614
1530.83	883.737
1533.94	866.433
1537.04	806.842
1540.15	802.108
1543.25	808.803
1546.35	786.641
1549.45	791.908
1552.55	776.031
1555.65	773.584
1558.74	775.136
1561.84	765.259
1564.93	774.24
1568.02	774.935
1571.12	754.773
1574.2	775.754
1577.3	754.449
1580.38	763.144
1583.47	769.839
1586.56	748.82
1589.64	761.801
1592.72	761.638
1595.81	762.619
1598.89	765.6
1601.97	768.867
1605.05	770.133
1608.12	772.676
1611.2	761.465
1614.27	771.515
1617.35	756.71
1620.42	747.77
1623.5	761.088
1626.57	765.244
1629.63	768.975
1632.7	757.276
1635.77	743.145
1638.84	761.845
1641.9	757.727
1644.97	763.118
1648.03	756.201
1651.09	760.167
1654.15	770.742
1657.21	765.89
1660.27	755.449
1663.32	765.577
1666.38	758.667
1669.43	762.54
1672.49	768.165
1675.54	761.583
1678.59	759.744
1681.64	768.174
1684.69	765.502
1687.73	757.556
1690.78	758.865
1693.83	758.756
1696.87	751.063
1699.91	753.04
1702.96	751.927
1706	751.607
1709.04	744.423
1712.07	752.246
1715.11	750.581
1718.15	746.869
1721.18	743.921
1724.21	751.214
1727.25	742.108
1730.28	745.412
1733.31	738.171
1736.34	737.018
1739.37	725.479
1742.39	741.185
1745.42	732.218
1748.45	737.335
1751.47	739.451
1754.49	722.946
1757.51	738.359
1759.25	736.144
1762.28	745.26
1765.31	731.804
1768.34	750.634
1771.37	726.892
1774.4	742.865
1777.43	743.98
1780.46	743.953
1783.48	735.354
1786.51	744.184
1789.53	738.156
1792.55	721.272
1795.57	738.102
1798.59	741.789
1801.61	750.047
1804.63	751.163
1807.64	753.135
1810.66	751.965
1813.67	742.28
1816.68	764.881
1819.7	744.91
1822.71	745.511
1825.72	725.826
1828.72	723.855
1831.73	741.028
1834.74	731.628
1837.74	737.372
1840.75	743.973
1843.75	730.288
1846.75	724.317
1849.75	740.061
1852.75	747.233
1855.75	736.406
1858.75	722.149
1861.74	732.179
1864.74	725.351
1867.73	739.951
1870.72	747.981
1873.71	736.01
1876.7	742.325
1879.69	736.64
1882.68	730.956
1885.67	737.842
1888.66	741.586
1891.64	742.472
1894.62	736.502
1897.61	738.817
1900.59	733.417
1903.57	730.018
1906.55	734.905
1909.53	739.22
1912.5	743.249
1915.48	749.279
1918.46	749.594
1921.43	746.766
1924.4	740.224
1927.37	743.396
1930.34	738.568
1933.31	739.169
1936.28	756.341
1939.25	758.085
1942.22	755.829
1945.18	749.858
1948.14	743.887
1951.11	747.345
1954.07	736.517
1957.03	745.69
1959.99	736.862
1962.95	720.891
1965.91	739.778
1968.86	740.95
1971.82	727.265
1974.77	739.866
1977.73	742.752
1980.68	751.924
1983.63	723.668
1986.58	736.84
1989.53	736.584
1992.47	740.614
1995.42	735.214
1998.37	743.529
2001.31	736.987
2004.25	733.588
2007.2	720.475
2010.14	737.647
2013.08	738.533
2016.02	739.42
2018.96	734.878
2021.89	736.907
2024.83	726.651
2027.76	739.252
2030.7	727.281
2033.63	717.882
2036.56	732.768
2039.49	734.512
2042.42	743.97
2045.35	737.713
2048.28	714.886
2051.2	732.629
2054.13	734.373
2057.05	735.545
2059.97	733.003
2062.9	725.318
2065.82	734.49
2068.74	735.663
2071.65	743.121
2074.57	735.721
2077.49	737.179
2080.4	730.923
2083.32	730.667
2086.23	729.839
2089.15	716.154
2092.05	724.183
2094.97	714.784
2097.87	727.385
2100.78	725.414
2103.69	720.015
2106.6	727.473
2109.5	722.074
2112.4	717.817
2115.31	716.418
2118.21	715.59
2121.11	702.191
2124.01	721.078
2126.91	722.821
2129.8	714.565
2132.7	727.166
2135.59	721.767
2138.49	722.939
2141.38	718.968
2144.27	712.998
2147.16	717.027
2150.05	723.913
2152.94	717.943
2155.83	722.544
2158.72	714.287
2161.6	718.602
2164.49	725.489
2167.37	722.661
2170.26	719.262
2173.14	706.148
2176.02	711.035
2178.9	720.207
2181.77	723.951
2184.65	728.266
2187.53	716.295
2190.4	712.039
2193.28	720.354
2196.15	709.526
2199.02	718.127
2201.89	707.585
2204.76	717.9
2207.63	719.358
2210.5	706.53
2213.37	702.274
2216.23	700.303
2219.1	692.333
2221.96	688.648
2224.82	700.677
2227.69	680.706
2230.55	696.45
2233.41	692.765
2236.26	686.794
2239.12	679.681
2241.98	685.71
2244.83	692.883
2247.69	679.483
2250.54	683.227
2253.39	670.113
2256.24	684.714
2259.09	676.458
2261.94	674.202
2264.79	672.231
2267.64	672.546
2270.49	673.433
2273.33	674.319
2276.18	687.491
2279.02	675.806
2281.86	672.407
2284.7	679.008
2287.54	681.323
2290.38	669.924
2293.22	678.525
2296.05	681.411
2298.89	686.869
2301.72	678.613
2304.56	685.214
2307.39	685.243
2310.22	686.129
2313.05	680.444
2315.88	691.617
2318.71	692.217
2321.54	682.247
2324.36	695.705
2327.19	672.306
2330.01	691.478
2332.84	684.079
2335.66	670.394
2338.48	678.709
2341.3	672.452
2344.12	674.196
2346.94	691.654
2349.76	674.255
2352.57	674.57
2355.39	672.028
2358.2	664.914
2361.02	656.944
2363.83	674.402
2366.64	662.431
2369.45	666.175
2372.26	667.061
2375.07	655.662
2377.87	669.12
2380.68	669.721
2383.49	668.321
2386.29	669.208
2389.09	648.952
2391.9	653.838
2394.7	652.153
2397.5	661.897
2400.29	661.355
2403.09	649.67
2405.89	653.699
2408.69	662.871
2411.48	663.472
2414.28	665.502
2417.07	658.388
2419.86	658.989
2422.65	653.875
2425.44	663.048
2428.23	660.791
2431.02	660.249
2433.81	667.707
2436.59	655.165
2439.38	660.337
2442.16	659.795
2444.94	672.967
2447.73	665.283
2450.51	659.026
2453.29	663.627
2456.07	667.085
2458.84	681.4
2461.62	672.572
2464.4	663.459
2467.17	660.345
2469.95	673.232
2472.72	665.547
2475.49	665.862
2478.26	663.32
2481.03	663.921
2483.8	669.093
2486.57	677.979
2489.34	669.152
2492.1	664.61
2494.87	669.496
2497.63	674.668
2500.39	679.841
2503.16	662.727
2505.92	664.471
2508.68	669.643
2511.44	662.815
2514.19	666.559
2516.95	666.017
2519.71	659.475
2522.46	669.218
2525.22	648.676
2527.97	653.563
2530.72	655.878
2533.47	654.479
2536.22	669.079
2538.97	658.252
2541.72	669.424
2544.47	668.882
2547.21	669.483
2549.96	664.083
2552.7	656.399
2555.45	657.571
2558.19	668.172
2560.93	649.629
2563.67	659.087
2566.41	662.26
2569.15	653.718
2571.89	666.89
2574.62	641.491
2577.36	659.234
2580.09	648.121
2582.83	647.864
2585.56	663.894
2588.29	669.066
2591.02	648.81
2593.75	658.553
2596.48	670.868
2599.21	662.326
2601.93	659.213
2604.66	654.099
2607.39	669.272
2610.11	662.729
2612.83	677.902
2615.55	673.931
2618.27	676.532
2620.99	666.561
2623.71	670.591
2626.43	665.763
2629.15	674.078
2631.86	656.679
2634.58	664.708
2637.29	662.452
2640.01	669.91
2642.72	675.653
2645.43	667.683
2648.14	675.141
2650.85	669.456
2653.56	660.628
2656.26	664.943
2658.97	660.401
2661.68	662.716
2664.38	662.174
2667.09	664.489
2669.79	661.947
2672.49	663.405
2675.19	667.434
2677.89	669.749
2680.59	661.207
2683.29	662.665
2685.98	668.98
2688.68	675.295
2691.37	679.61
2694.07	673.068
2696.76	664.526
2699.45	657.413
2702.14	662.585
2704.83	655.472
2707.52	664.644
2710.21	656.387
2712.9	647.845
2715.58	669.303
2718.27	661.333
2720.95	658.505
2723.64	645.963
2726.32	675.135
2729	653.45
2731.68	648.908
2734.36	658.652
2737.04	676.11
2739.72	670.425
2742.39	655.883
2745.07	659.341
2747.74	661.656
2750.42	673.971
2753.09	660
2755.76	678.601
2758.43	661.202
2761.1	651.231
2763.77	670.689
2766.44	668.147
2769.11	671.033
2771.78	668.777
2774.44	663.092
2777.11	663.979
2779.77	659.722
2782.43	662.037
2785.09	659.21
2787.76	655.239
2790.41	679.84
2793.07	666.441
2795.73	659.899
2798.39	671.357
2801.04	665.672
2803.7	660.272
2806.35	674.302
2809.01	666.331
2811.66	668.646
2814.31	664.104
2816.96	660.133
2819.61	661.02
2822.26	670.764
2824.91	687.936
2827.55	669.108
2830.2	675.709
2832.84	668.595
2835.49	673.196
2838.13	680.654
2840.77	681.255
2843.41	679.284
2846.05	685.028
2848.69	685.343
2851.33	691.944
2853.97	686.259
2856.6	693.145
2859.24	702.603
2861.87	697.49
2864.51	697.519
2867.14	704.406
2869.77	711.292
2872.4	713.893
2875.03	719.637
2877.66	712.237
2880.29	719.124
2882.92	744.582
2885.54	745.754
2888.17	733.498
2890.79	744.956
2893.42	760.699
2896.04	747.872
2898.66	768.187
2901.28	764.216
2903.9	760.817
2906.52	771.703
2909.14	760.875
2911.76	766.048
2914.37	765.22
2916.99	748.392
2919.6	787.16
2922.21	769.451
2924.83	763.17
2927.44	781.262
2930.05	772.151
2932.66	778.909
2935.27	798.325
2937.88	777.463
2940.48	782.93
2943.09	789.106
2945.69	781.393
2948.3	786.22
2950.9	771.872
2953.5	781.813
2956.1	770.301
2958.7	758.932
2961.3	753.007
2963.9	742.561
2966.5	736.619
2969.1	731.426
2971.69	726.134
2974.29	740.135
2976.88	727.806
2979.48	734.892
2982.07	724.184
2984.66	732.141
2987.25	723.157
2989.84	721.597
2992.43	713.009
2995.02	702.045
2997.6	696.015
3000.19	707.079
3002.77	695.611
3005.36	695.726
3007.94	690.948
3010.53	694.371
3013.11	686.992
3015.69	672.616
3018.27	692.03
3020.85	692.389
3023.42	687.479
3026	691.108
3028.58	685.693
3031.15	695.01
3033.73	695.465
3036.3	700.742
3038.87	691.935
3041.44	688.152
3044.01	701.919
3046.58	700.995
3048.04	688.099
3050.62	703.818
3053.2	708.109
3055.77	711.542
3058.35	715.547
3060.93	698.124
3063.51	712.986
3066.08	697.277
3068.66	719.853
3071.23	713.858
3073.8	721.863
3076.37	710.725
3078.94	714.445
3081.51	720.164
3084.08	729.883
3086.65	721.603
3089.22	734.465
3091.78	740.47
3094.35	744.189
3096.91	745.052
3099.48	735.342
3102.04	739.062
3104.6	740.781
3107.16	735.072
3109.72	752.22
3112.28	759.082
3114.84	771.373
3117.4	751.663
3119.96	777.097
3122.51	773.102
3125.07	775.964
3127.62	785.684
3130.18	777.117
3132.73	790.551
3135.28	799.984
3137.83	802.275
3140.38	809.709
3142.93	817.142
3145.47	819.433
3148.02	818.01
3150.57	829.729
3153.11	830.306
3155.66	825.739
3158.2	846.887
3160.74	841.178
3163.28	840.04
3165.83	853.188
3168.37	846.622
3170.91	862.627
3173.44	858.06
3175.98	874.351
3178.52	864.07
3181.05	868.361
3183.59	878.938
3186.12	886.371
3188.66	874.948
3191.19	890.381
3193.72	877.815
3196.25	898.106
3198.78	892.968
3201.31	886.116
3203.84	894.121
3206.36	890.126
3208.89	897.274
3211.41	894.707
3213.94	905.284
3216.46	906.432
3218.99	913.865
3221.51	890.442
3224.03	878.161
3226.55	909.595
3229.07	900.457
3231.59	888.462
3234.1	906.181
3236.62	885.615
3239.13	921.049
3241.65	910.768
3244.16	904.773
3246.68	895.921
3249.19	902.783
3251.7	898.217
3254.21	919.936
3256.72	917.655
3259.23	918.803
3261.74	905.094
3264.25	915.385
3266.75	915.104
3269.26	901.681
3271.76	893.686
3274.27	917.119
3276.77	932.267
3279.27	925.987
3281.77	910.277
3284.27	902.854
3286.77	911.716
3289.27	922.007
3291.77	912.298
3294.27	902.588
3296.76	910.022
3299.26	914.027
3301.75	923.461
3304.24	923.751
3306.74	927.756
3309.23	915.761
3311.72	919.195
3314.21	917.2
3316.7	929.491
3319.19	915.496
3321.68	924.358
3324.16	908.078
3326.65	937.797
3329.13	912.373
3331.62	946.378
3334.1	914.383
3336.58	924.388
3339.07	927.822
3341.55	933.541
3344.03	924.975
3346.51	921.266
3348.99	917.271
3351.46	908.419
3353.94	924.995
3356.42	934.143
3358.89	923.862
3361.36	936.153
3363.84	925.016
3366.31	926.163
3368.78	936.454
3371.25	915.888
3373.72	935.036
3376.19	941.898
3378.66	931.331
3381.13	922.479
3383.59	918.199
3386.06	928.204
3388.52	919.923
3390.99	924.785
3393.45	932.79
3395.91	917.367
3398.38	934.8
3400.84	933.377
3403.3	925.953
3405.76	931.673
3408.21	939.392
3410.67	918.54
3413.13	925.116
3415.58	933.407
3418.04	939.412
3420.49	933.132
3422.95	947.708
3425.4	939.427
3427.85	949.718
3430.3	950.866
3432.75	942.014
3435.2	952.019
3437.65	936.596
3440.1	936.886
3442.54	953.463
3444.99	930.039
3447.43	943.187
3449.88	925.478
3452.32	937.197
3454.76	932.917
3457.21	934.35
3459.65	930.927
3462.09	927.217
3464.53	907.223
3466.96	914.37
3469.4	894.661
3471.84	914.095
3474.27	911.528
3476.71	886.676
3479.14	888.681
3481.58	887.258
3484.01	883.263
3486.44	883.268
3488.87	884.987
3491.3	868.421
3493.73	856.712
3496.16	864.431
3498.59	842.722
3501.01	845.87
3503.44	836.16
3505.87	837.023
3508.29	829.599
3510.71	811.033
3513.14	816.466
3515.56	818.757
3517.98	803.619
3520.4	802.767
3522.82	799.915
3525.24	773.063
3527.66	765.64
3530.07	778.216
3532.49	768.507
3534.9	755.083
3537.32	760.231
3539.73	765.665
3542.15	758.527
3544.56	747.389
3546.97	725.68
3549.38	740.256
3551.79	723.976
3554.2	722.552
3556.61	728.843
3559.02	728.848
3561.42	726.853
3563.83	709.715
3566.23	713.435
3568.64	702.297
3571.04	706.016
3573.44	691.45
3575.84	706.026
3578.25	685.46
3580.65	695.465
3583.04	677.756
3585.44	683.761
3587.84	664.909
3590.24	692.628
3592.63	673.49
3595.03	681.209
3597.42	680.929
3599.82	668.077
3602.21	668.939
3604.6	660.087
3606.99	665.235
3609.38	663.526
3611.77	660.673
3614.16	651.536
3616.55	647.255
3618.94	654.689
3621.32	647.265
3623.71	640.984
3626.09	627.275
3628.48	644.995
3630.86	626.999
3633.24	636.147
3635.63	631.295
3638.01	619.872
3640.39	611.877
3642.77	614.168
3645.15	603.316
3647.52	596.749
3649.9	605.326
3652.28	592.474
3654.65	598.193
3657.03	582.198
3659.4	580.489
3661.77	573.637
3664.14	587.07
3666.52	555.647
3668.89	560.795
3671.25	552.8
3673.62	555.376
3675.99	560.81
3678.36	541.386
3680.73	539.677
3683.09	535.682
3685.46	539.116
3687.82	523.406
3690.19	531.983
3692.55	533.131
3694.91	519.707
3697.27	529.141
3699.63	515.717
3701.99	523.437
3704.35	534.013
3706.71	521.447
3709.06	524.88
3711.42	517.457
3713.78	511.748
3716.13	508.61
3718.48	510.615
3720.84	532.334
3723.19	515.482
3725.54	513.487
3727.89	522.064
3730.24	525.212
3732.59	496.931
3734.94	532.365
3737.29	515.798
3739.64	523.232
3741.98	510.951
3744.33	503.242
3746.67	519.818
3749.02	513.823
3751.36	515.828
3753.7	533.262
3756.04	515.553
3758.38	527.844
3760.72	521.563
3763.06	509.568
3765.4	521.573
3767.74	510.15
3770.08	503.583
3772.41	528.445
3774.75	523.308
3777.08	519.313
3779.41	508.746
3781.75	517.037
3784.08	518.185
3786.41	529.904
3788.74	525.338
3791.07	513.914
3793.4	519.062
3795.73	517.353
3798.06	521.644
3800.38	517.077
3802.71	514.511
3805.03	514.802
3807.36	512.521
3809.68	512.526
3812.01	506.531
3814.33	511.108
3816.65	513.113
3818.97	517.975
3821.29	523.98
3823.61	502.842
3825.93	515.419
3828.24	519.995
3830.56	508.857
3832.88	511.148
3835.19	514.01
3837.51	514.015
3839.82	512.306
3842.13	513.74
3844.45	522.602
3846.76	509.464
3849.07	508.898
3851.38	520.331
3853.69	512.622
3856	519.199
3858.3	515.204
3860.61	509.209
3862.92	507.785
3865.22	509.79
3867.53	520.367
3869.83	534.943
3872.13	520.091
3874.43	523.81
3876.74	524.101
3879.04	520.392
3881.34	530.683
3883.64	524.688
3885.93	530.407
3888.23	518.412
3890.53	539.56
3892.83	532.422
3895.12	534.713
3897.41	536.718
3899.71	555.866
3902	541.014
3904.29	532.447
3906.59	541.595
3908.88	548.743
3911.17	559.034
3913.46	564.182
3915.75	552.473
3918.03	540.478
3920.32	545.626
3922.61	556.202
3924.89	553.636
3927.18	558.212
3929.46	561.646
3931.74	560.222
3934.03	566.227
3936.31	560.518
3938.59	566.809
3940.87	549.957
3943.15	556.533
3945.43	561.967
3947.71	564.543
3949.98	562.548
3952.26	566.554
3954.54	567.13
3956.81	568.849
3959.09	575.997
3961.36	575.145
3963.63	558.579
3965.9	567.727
3968.18	565.16
3970.45	562.594
3972.72	566.885
3974.99	556.89
3977.25	566.609
3979.52	574.043
3981.79	567.476
3984.05	568.91
3986.32	573.201
3988.58	573.492
3990.85	576.068
3993.11	580.359
3995.37	567.221
3997.64	577.797
3999.9	591.803