File: muestras/manzana/mz_13.txt
#Acq. time (s)=	20
#Accumulations=	8
#Range (cm-¹)=	50...4000
#Windows=	3
#Autofocus=	Off
#AutoExposure=	Off
#Spike filter=	Multiple accum.
#Delay time (s)=	0
#Binning=	1
#Readout mode=	Signal
#DeNoise=	Off
#ICS correction=	Off
#Dark correction=	Off
#Inst. Process=	Off
#Instrument=	LabRAM HR Evol
#Detector=	Syncerity OE
#Objective=	x100_VIS
#Grating=	600 (500nm)
#ND Filter=	5%
#Laser=	532nm_Edge
#Hole=	100.021
#Range=	Visible
#Project=	Omar
#Sample=	120523
#Site=	ap
#Title=	mz
#Remark=	5 laser intensity
#Date=	12.05.2023 17:01
#Acquired=	12.05.2023 17:01:16
51.0297	26.5714
54.7185	34.7545
58.406	52.9376
62.0919	110.264
65.7765	179.018
69.4595	258.058
73.1412	364.241
76.8214	442.71
80.5001	496.608
84.1774	564.219
87.8532	578.974
91.5276	602.014
95.2006	586.197
98.8721	594.095
102.54	601.421
106.209	609.604
109.876	613.501
113.542	616.256
117.204	617.296
120.867	606.622
124.526	603.662
128.186	603.845
131.845	602.028
135.5	618.211
139.155	614.68
142.807	610.578
146.46	621.046
150.11	621.229
153.757	632.555
157.406	611.31
161.051	624.35
164.697	613.676
168.339	627.002
171.98	621.185
175.619	615.654
179.259	615.266
182.895	622.592
186.53	622.489
190.164	612.386
193.796	618.57
197.427	617.61
201.059	605.507
204.686	604.262
208.313	613.016
211.938	605.199
215.562	603.097
219.184	595.566
222.803	594.034
226.422	583.36
230.04	590.115
233.657	600.298
237.272	585.338
240.886	592.95
244.497	594.562
248.108	593.888
251.717	581.499
255.325	598.825
258.93	589.008
262.535	582.048
266.137	583.66
269.74	593.272
273.341	587.169
276.939	585.638
280.537	578.107
284.132	582.576
287.728	569.044
291.32	588.085
294.911	576.268
298.502	582.165
302.09	570.92
305.677	580.531
309.264	593
312.848	602.612
316.43	596.224
320.011	582.407
323.593	604.59
327.171	595.916
330.748	586.385
334.323	600.568
337.897	593.036
341.47	592.362
345.041	602.26
348.611	598.443
352.18	572.626
355.747	591.952
359.312	592.421
362.877	587.747
366.44	590.216
369.999	602.97
373.56	601.153
377.119	605.051
380.676	606.377
384.23	607.703
387.785	614.743
391.338	610.64
394.888	598.823
398.439	607.578
401.988	616.332
405.534	607.658
409.081	611.27
412.624	619.739
416.167	618.779
419.708	629.819
423.249	612.288
426.786	622.185
430.323	606.083
433.86	607.123
437.393	607.306
440.926	607.489
444.458	614.53
447.988	612.713
451.516	633.467
455.043	622.793
458.568	625.833
462.092	629.445
465.615	627.057
469.138	638.383
472.658	631.709
476.177	618.463
479.694	620.361
483.21	626.829
486.723	631.584
490.236	628.053
493.748	630.807
497.258	638.99
500.768	625.459
504.276	646.499
507.78	632.968
511.285	627.151
514.789	639.049
518.289	647.232
521.791	649.129
525.29	668.455
528.787	644.352
532.284	649.107
535.778	639.862
539.272	632.616
542.763	637.942
546.255	656.411
549.743	646.308
553.232	651.349
556.718	640.96
560.203	648
563.688	633.041
567.169	650.938
570.65	635.121
574.129	646.733
577.609	645.773
581.085	650.813
584.56	652.711
588.034	651.751
591.506	664.22
594.978	652.117
598.447	654.015
601.916	661.341
605.383	650.666
608.849	662.278
612.313	667.89
615.776	667.502
619.238	676.828
622.699	673.582
626.156	679.479
629.614	704.52
633.071	681.846
636.526	680.029
639.978	663.926
643.431	664.966
646.88	676.864
650.33	672.19
653.779	666.659
657.224	671.127
660.67	659.596
664.113	687.779
667.556	660.534
670.997	672.717
674.435	672.328
677.875	671.94
681.311	686.123
684.746	668.592
688.182	668.489
691.614	666.101
695.045	668.856
698.475	684.182
701.904	675.508
705.333	679.119
708.759	681.302
712.183	687.2
715.606	679.954
719.028	676.995
722.449	673.463
725.868	682.789
729.286	677.544
732.703	679.727
736.117	680.482
739.531	673.522
742.944	671.419
746.355	671.602
749.766	674.928
753.173	668.254
756.581	697.866
759.987	677.477
763.39	694.232
766.794	684.701
770.195	686.027
773.596	674.781
776.994	686.679
780.393	683.719
783.788	677.616
787.185	687.799
790.578	669.983
793.971	688.737
797.362	688.634
800.751	690.818
804.138	688.429
807.527	688.612
810.912	688.51
814.296	702.979
817.679	697.733
821.06	707.345
824.441	716.671
827.822	711.711
831.199	717.323
834.576	710.077
837.951	721.689
841.323	722.158
844.695	708.912
848.066	719.952
851.436	708.421
854.805	721.747
858.173	725.359
861.539	705.828
864.902	735.439
868.266	725.908
871.628	728.091
874.987	709.989
878.347	714.458
881.704	719.498
885.061	710.824
888.418	696.15
891.771	691.19
895.122	699.659
898.475	702.985
901.824	692.596
905.174	693.351
908.52	695.82
911.866	695.146
915.212	701.615
918.555	705.798
921.896	698.266
925.237	707.592
928.576	698.347
931.914	707.101
935.253	704.427
938.588	712.61
941.922	705.365
945.255	721.262
948.587	720.874
951.917	715.629
955.244	707.526
958.572	727.709
961.899	713.321
965.225	712.361
968.549	724.544
971.872	706.441
975.192	728.339
978.512	719.665
981.831	734.705
985.148	722.888
988.464	737.071
991.778	717.826
995.092	719.723
998.404	727.335
1001.72	727.518
1005.02	762.558
1008.33	744.17
1011.64	739.496
1014.95	731.108
1018.25	733.862
1021.55	726.045
1024.85	718.228
1028.16	730.697
1031.46	736.023
1034.75	728.206
1038.05	728.961
1041.34	733.715
1044.64	740.47
1047.93	730.081
1051.22	748.836
1054.51	755.59
1057.8	758.059
1061.09	747.957
1064.38	744.711
1067.66	759.466
1070.95	749.935
1074.23	760.118
1077.51	744.015
1080.79	749.627
1084.07	752.667
1087.35	760.279
1090.62	749.605
1093.9	756.645
1097.17	746.542
1100.44	753.297
1103.71	750.908
1106.99	748.806
1110.25	739.846
1113.52	730.601
1116.79	736.498
1120.05	752.681
1123.31	758.864
1126.58	757.333
1129.84	766.659
1133.1	739.985
1136.36	758.739
1139.61	755.494
1142.87	764.249
1146.12	768.432
1149.38	781.186
1152.63	824.226
1155.88	848.695
1159.13	844.878
1162.38	818.776
1165.63	773.244
1168.87	779.428
1172.12	764.754
1175.36	758.937
1178.6	770.263
1181.84	763.303
1185.08	776.914
1188.32	789.098
1191.56	771.852
1194.79	771.749
1198.03	763.647
1201.26	756.973
1204.49	781.442
1207.72	759.053
1210.95	772.951
1214.18	775.134
1217.41	755.317
1220.64	762.072
1223.86	745.398
1227.08	759.866
1230.3	740.907
1233.53	753.947
1236.75	733.273
1239.96	748.599
1243.18	734.782
1246.4	746.965
1249.61	758.005
1252.82	767.903
1256.04	761.514
1259.25	767.983
1262.46	759.595
1265.67	776.064
1268.87	767.675
1272.08	765.001
1275.28	762.041
1278.49	771.082
1281.69	768.122
1284.89	767.734
1288.09	761.774
1291.29	760.385
1294.49	750.569
1297.68	762.18
1300.88	772.935
1304.07	781.118
1307.26	767.872
1310.46	766.341
1313.65	776.239
1316.84	780.422
1320.02	780.605
1323.21	766.216
1326.39	782.971
1329.58	788.868
1332.76	772.766
1335.94	771.52
1339.12	772.846
1342.3	767.886
1345.48	766.355
1348.65	775.967
1351.83	787.579
1355	767.762
1358.18	776.802
1361.35	770.699
1364.52	778.025
1367.69	781.066
1370.86	750.106
1374.02	791.146
1377.19	760.472
1380.35	774.655
1383.52	763.695
1386.68	759.021
1389.84	766.347
1393	766.245
1396.16	776.142
1399.31	760.325
1402.47	779.08
1405.63	770.691
1408.78	774.589
1411.93	769.915
1415.08	766.669
1418.23	779.424
1421.38	777.607
1424.53	780.933
1427.68	782.83
1430.82	784.156
1433.96	799.482
1437.11	792.808
1440.25	782.42
1443.39	797.174
1446.53	782.215
1449.67	799.255
1452.8	807.438
1455.94	790.478
1459.07	798.661
1462.21	777.987
1465.34	807.599
1468.47	783.496
1471.6	778.822
1474.72	791.291
1477.85	775.188
1480.98	767.943
1484.1	791.84
1487.23	777.166
1490.35	765.064
1493.47	778.675
1496.59	798.573
1499.71	780.756
1502.83	786.939
1505.94	794.265
1509.06	807.877
1512.17	836.06
1515.29	862.243
1518.4	876.426
1521.51	903.752
1524.62	914.221
1527.72	933.547
1530.83	909.73
1533.94	892.484
1537.04	832.953
1540.15	828.279
1543.25	835.034
1546.35	812.931
1549.45	818.257
1552.55	802.44
1555.65	800.052
1558.74	801.663
1561.84	791.846
1564.93	800.887
1568.02	801.641
1571.12	781.539
1574.2	802.579
1577.3	781.333
1580.38	790.088
1583.47	796.842
1586.56	775.883
1589.64	788.923
1592.72	788.82
1595.81	789.861
1598.89	792.901
1601.97	796.227
1605.05	797.553
1608.12	800.593
1611.2	789.348
1614.27	800.674
1617.35	785.142
1620.42	775.897
1623.5	790.937
1626.57	797.406
1629.63	801.589
1632.7	786.629
1635.77	771.67
1638.84	793.853
1641.9	789.179
1644.97	796.79
1648.03	783.259
1651.09	790.585
1654.15	807.34
1657.21	801.523
1660.27	791.991
1663.32	799.032
1666.38	797.501
1669.43	804.255
1672.49	802.724
1675.54	799.764
1678.59	791.376
1681.64	805.559
1684.69	796.599
1687.73	798.782
1690.78	799.251
1693.83	800.863
1696.87	795.046
1699.91	810.372
1702.96	787.983
1706	800.738
1709.04	784.635
1712.07	799.104
1715.11	787.573
1718.15	783.756
1721.18	796.225
1724.21	790.694
1727.25	786.02
1730.28	780.774
1733.31	797.529
1736.34	774.283
1739.37	774.181
1742.39	768.935
1745.42	793.404
1748.45	789.301
1751.47	794.913
1754.49	769.096
1757.51	781.279
1759.25	767.31
1762.28	783.207
1765.31	819.105
1768.34	805.003
1771.37	798.9
1774.4	746.798
1777.43	794.695
1780.46	774.593
1783.48	790.491
1786.51	780.388
1789.53	790.286
1792.55	778.183
1795.57	784.081
1798.59	791.979
1801.61	779.876
1804.63	757.774
1807.64	807.671
1810.66	807.569
1813.67	805.466
1816.68	791.364
1819.7	801.262
1822.71	807.159
1825.72	773.057
1828.72	764.955
1831.73	816.852
1834.74	802.75
1837.74	800.647
1840.75	780.545
1843.75	782.443
1846.75	764.34
1849.75	800.238
1852.75	772.135
1855.75	788.033
1858.75	781.93
1861.74	797.828
1864.74	769.726
1867.73	787.623
1870.72	781.521
1873.71	747.418
1876.7	787.316
1879.69	777.214
1882.68	773.111
1885.67	781.009
1888.66	756.906
1891.64	794.804
1894.62	752.702
1897.61	784.599
1900.59	812.497
1903.57	776.394
1906.55	766.292
1909.53	774.19
1912.5	762.087
1915.48	799.985
1918.46	789.882
1921.43	775.78
1924.4	757.678
1927.37	789.575
1930.34	761.473
1933.31	801.37
1936.28	795.268
1939.25	793.166
1942.22	795.063
1945.18	788.961
1948.14	748.858
1951.11	774.756
1954.07	768.654
1957.03	774.551
1959.99	780.449
1962.95	744.346
1965.91	788.244
1968.86	762.142
1971.82	780.039
1974.77	761.937
1977.73	789.834
1980.68	779.732
1983.63	777.63
1986.58	769.527
1989.53	749.425
1992.47	783.322
1995.42	779.22
1998.37	795.118
2001.31	783.015
2004.25	770.913
2007.2	778.81
2010.14	780.708
2013.08	760.606
2016.02	790.503
2018.96	764.401
2021.89	762.298
2024.83	748.196
2027.76	748.094
2030.7	773.991
2033.63	759.889
2036.56	787.786
2039.49	819.684
2042.42	781.582
2045.35	755.479
2048.28	751.377
2051.2	765.274
2054.13	763.172
2057.05	755.07
2059.97	782.967
2062.9	752.865
2065.82	750.762
2068.74	786.66
2071.65	774.558
2074.57	766.455
2077.49	776.353
2080.4	758.25
2083.32	776.148
2086.23	748.046
2089.15	773.943
2092.05	757.841
2094.97	769.738
2097.87	771.636
2100.78	739.534
2103.69	717.431
2106.6	765.329
2109.5	743.226
2112.4	737.124
2115.31	761.021
2118.21	750.919
2121.11	744.817
2124.01	736.714
2126.91	762.612
2129.8	752.51
2132.7	744.407
2135.59	758.305
2138.49	752.202
2141.38	750.1
2144.27	761.997
2147.16	753.895
2150.05	751.793
2152.94	757.69
2155.83	759.588
2158.72	751.485
2161.6	767.383
2164.49	737.281
2167.37	755.178
2170.26	763.076
2173.14	728.973
2176.02	716.871
2178.9	754.769
2181.77	732.666
2184.65	764.564
2187.53	724.461
2190.4	732.359
2193.28	740.257
2196.15	742.154
2199.02	750.052
2201.89	725.949
2204.76	753.847
2207.63	725.745
2210.5	775.642
2213.37	755.54
2216.23	747.437
2219.1	753.335
2221.96	707.233
2224.82	709.13
2227.69	739.028
2230.55	734.925
2233.41	746.823
2236.26	696.721
2239.12	712.618
2241.98	706.516
2244.83	732.413
2247.69	718.311
2250.54	702.209
2253.39	702.106
2256.24	712.004
2259.09	729.901
2261.94	709.799
2264.79	695.697
2267.64	713.594
2270.49	735.492
2273.33	677.389
2276.18	701.287
2279.02	695.185
2281.86	687.082
2284.7	682.98
2287.54	696.877
2290.38	686.775
2293.22	704.673
2296.05	678.57
2298.89	704.468
2301.72	706.365
2304.56	728.263
2307.39	720.161
2310.22	706.058
2313.05	707.956
2315.88	743.853
2318.71	727.751
2321.54	697.649
2324.36	727.546
2327.19	725.444
2330.01	729.341
2332.84	709.239
2335.66	709.137
2338.48	673.034
2341.3	708.932
2344.12	662.829
2346.94	702.727
2349.76	744.625
2352.57	676.522
2355.39	702.42
2358.2	654.317
2361.02	678.215
2363.83	706.113
2366.64	690.01
2369.45	675.908
2372.26	669.805
2375.07	711.703
2377.87	649.601
2380.68	701.498
2383.49	663.396
2386.29	699.293
2389.09	655.191
2391.9	677.089
2394.7	686.986
2397.5	666.884
2400.29	690.781
2403.09	670.679
2405.89	642.576
2408.69	678.474
2411.48	676.372
2414.28	714.269
2417.07	664.167
2419.86	686.065
2422.65	691.962
2425.44	649.86
2428.23	667.757
2431.02	691.655
2433.81	675.552
2436.59	705.45
2439.38	669.348
2442.16	665.245
2444.94	659.143
2447.73	689.04
2450.51	674.938
2453.29	702.836
2456.07	666.733
2458.84	688.631
2461.62	694.528
2464.4	648.426
2467.17	684.324
2469.95	674.221
2472.72	678.119
2475.49	704.016
2478.26	665.914
2481.03	697.812
2483.8	705.709
2486.57	677.607
2489.34	643.504
2492.1	653.402
2494.87	665.3
2497.63	677.197
2500.39	663.095
2503.16	688.992
2505.92	720.89
2508.68	658.788
2511.44	662.685
2514.19	688.583
2516.95	674.48
2519.71	654.378
2522.46	674.276
2525.22	642.173
2527.97	674.071
2530.72	693.968
2533.47	685.866
2536.22	675.764
2538.97	679.661
2541.72	689.559
2544.47	685.456
2547.21	667.354
2549.96	675.252
2552.7	687.149
2555.45	649.047
2558.19	666.944
2560.93	652.842
2563.67	688.74
2566.41	656.637
2569.15	676.535
2571.89	678.432
2574.62	668.33
2577.36	680.228
2580.09	656.125
2582.83	650.023
2585.56	685.92
2588.29	667.818
2591.02	643.716
2593.75	653.613
2596.48	671.511
2599.21	681.408
2601.93	683.306
2604.66	667.204
2607.39	679.101
2610.11	676.999
2612.83	692.896
2615.55	684.794
2618.27	690.692
2620.99	660.589
2623.71	682.487
2626.43	690.384
2629.15	686.282
2631.86	672.18
2634.58	662.077
2637.29	689.975
2640.01	661.872
2642.72	697.77
2645.43	685.668
2648.14	687.565
2650.85	669.463
2653.56	671.36
2656.26	641.258
2658.97	669.156
2661.68	643.053
2664.38	674.951
2667.09	670.848
2669.79	674.746
2672.49	692.643
2675.19	660.541
2677.89	656.439
2680.59	678.336
2683.29	686.234
2685.98	686.131
2688.68	666.029
2691.37	705.927
2694.07	675.824
2696.76	633.722
2699.45	653.619
2702.14	641.517
2704.83	645.415
2707.52	673.312
2710.21	675.21
2712.9	673.107
2715.58	661.005
2718.27	662.903
2720.95	664.8
2723.64	678.698
2726.32	694.595
2729	680.493
2731.68	674.391
2734.36	634.288
2737.04	660.186
2739.72	678.083
2742.39	667.981
2745.07	643.879
2747.74	659.776
2750.42	655.674
2753.09	639.571
2755.76	671.469
2758.43	643.367
2761.1	673.264
2763.77	671.162
2766.44	667.059
2769.11	664.957
2771.78	662.855
2774.44	674.752
2777.11	642.65
2779.77	682.547
2782.43	652.445
2785.09	670.343
2787.76	646.24
2790.41	680.138
2793.07	640.035
2795.73	673.933
2798.39	683.831
2801.04	667.728
2803.7	687.626
2806.35	669.523
2809.01	707.421
2811.66	659.319
2814.31	641.216
2816.96	657.114
2819.61	639.011
2822.26	632.909
2824.91	666.807
2827.55	700.704
2830.2	670.602
2832.84	642.499
2835.49	702.397
2838.13	666.295
2840.77	670.192
2843.41	700.09
2846.05	693.987
2848.69	679.885
2851.33	701.783
2853.97	663.68
2856.6	667.578
2859.24	719.475
2861.87	685.373
2864.51	709.271
2867.14	719.168
2869.77	731.066
2872.4	706.963
2875.03	706.861
2877.66	744.759
2880.29	710.656
2882.92	734.554
2885.54	746.451
2888.17	740.349
2890.79	748.247
2893.42	738.144
2896.04	774.042
2898.66	727.939
2901.28	733.837
2903.9	781.734
2906.52	741.632
2909.14	769.53
2911.76	767.427
2914.37	747.325
2916.99	735.223
2919.6	783.12
2922.21	747.018
2924.83	746.915
2927.44	770.813
2930.05	750.711
2932.66	788.608
2935.27	788.506
2937.88	772.403
2940.48	776.301
2943.09	810.198
2945.69	772.096
2948.3	757.994
2950.9	717.891
2953.5	779.789
2956.1	773.686
2958.7	743.584
2961.3	731.482
2963.9	709.379
2966.5	719.277
2969.1	713.174
2971.69	755.072
2974.29	692.97
2976.88	714.867
2979.48	728.765
2982.07	692.662
2984.66	714.56
2987.25	714.458
2989.84	708.355
2992.43	724.253
2995.02	690.15
2997.6	708.048
3000.19	699.946
3002.77	681.843
3005.36	695.741
3007.94	693.638
3010.53	651.536
3013.11	717.434
3015.69	693.331
3018.27	679.229
3020.85	693.126
3023.42	647.024
3026	672.922
3028.58	672.819
3031.15	642.717
3033.73	680.614
3036.3	672.512
3038.87	682.41
3041.44	656.307
3044.01	676.205
3046.58	680.102
3047.87	682.051