File: muestras/manzana/mz_14.txt
#Acq. time (s)=	20
#Accumulations=	8
#Range (cm-¹)=	50...4000
#Windows=	3
#Autofocus=	Off
#AutoExposure=	Off
#Spike filter=	Multiple accum.
#Delay time (s)=	0
#Binning=	1
#Readout mode=	Signal
#DeNoise=	Off
#ICS correction=	Off
#Dark correction=	Off
#Inst. Process=	Off
#Instrument=	LabRAM HR Evol
#Detector=	Syncerity OE
#Objective=	x100_VIS
#Grating=	600 (500nm)
#ND Filter=	5%
#Laser=	532nm_Edge
#Hole=	100.021
#Range=	Visible
#Project=	Omar
#Sample=	120523
#Site=	ap
#Title=	mz
#Remark=	5 laser intensity
#Date=	12.05.2023 17:01
#Acquired=	12.05.2023 17:01:16
51.0297	26.5714
54.7185	34.6951
58.406	52.8187
62.0919	110.085
65.7765	178.78
69.4595	257.761
73.1412	363.885
76.8214	442.294
80.5001	496.132
84.1774	563.684
87.8532	578.379
91.5276	601.36
95.2006	585.483
98.8721	593.321
102.54	600.588
106.209	608.711
109.876	612.549
113.542	615.244
117.204	616.225
120.867	605.492
124.526	602.472
128.186	602.596
131.845	600.72
135.5	616.843
139.155	613.253
142.807	609.091
146.46	619.5
150.11	619.624
153.757	630.89
157.406	609.585
161.051	622.566
164.697	611.832
168.339	625.099
171.98	619.222
175.619	613.632
179.259	613.184
182.895	620.45
186.53	620.288
190.164	610.126
193.796	616.25
197.427	615.231
201.059	603.069
204.686	601.764
208.313	610.459
211.938	602.582
215.562	600.42
219.184	592.83
222.803	591.239
226.422	580.505
230.04	587.2
233.657	597.324
237.272	582.305
240.886	589.857
244.497	591.409
248.108	590.676
251.717	578.228
255.325	595.494
258.93	585.618
262.535	578.599
266.137	580.151
269.74	589.703
273.341	583.541
276.939	581.95
280.537	574.36
284.132	578.769
287.728	565.178
291.32	584.159
294.911	572.283
298.502	578.121
302.09	566.816
305.677	576.368
309.264	588.777
312.848	598.329
316.43	591.882
320.011	578.005
323.593	600.129
327.171	591.395
330.748	581.805
334.323	595.928
337.897	588.338
341.47	587.604
345.041	597.442
348.611	593.566
352.18	567.689
355.747	586.956
359.312	587.365
362.877	582.632
366.44	585.041
369.999	597.736
373.56	595.86
377.119	599.698
380.676	600.964
384.23	602.23
387.785	609.211
391.338	605.049
394.888	593.173
398.439	601.868
401.988	610.563
405.534	601.829
409.081	605.382
412.624	613.791
416.167	612.772
419.708	623.752
423.249	606.162
426.786	616
430.323	599.838
433.86	600.818
437.393	600.942
440.926	601.066
444.458	608.046
447.988	606.17
451.516	626.865
455.043	616.132
458.568	619.112
462.092	622.664
465.615	620.217
469.138	631.483
472.658	624.75
476.177	611.445
479.694	613.283
483.21	619.692
486.723	624.387
490.236	620.796
493.748	623.491
497.258	631.615
500.768	618.024
504.276	639.005
507.78	625.414
511.285	619.538
514.789	631.376
518.289	639.5
521.791	641.337
525.29	660.604
528.787	636.442
532.284	641.137
535.778	631.832
539.272	624.527
542.763	629.793
546.255	648.203
549.743	638.041
553.232	643.021
556.718	632.574
560.203	639.554
563.688	624.535
567.169	642.373
570.65	626.497
574.129	638.049
577.609	637.03
581.085	642.01
584.56	643.848
588.034	642.829
591.506	655.238
594.978	643.076
598.447	644.914
601.916	652.181
605.383	641.447
608.849	652.999
612.313	658.552
615.776	658.104
619.238	667.37
622.699	664.065
626.156	669.903
629.614	694.884
633.071	672.151
636.526	670.274
639.978	654.112
643.431	655.093
646.88	666.931
650.33	662.197
653.779	656.607
657.224	661.016
660.67	649.425
664.113	677.549
667.556	650.244
670.997	662.367
674.435	661.92
677.875	661.472
681.311	675.596
684.746	658.005
688.182	657.843
691.614	655.395
695.045	658.09
698.475	673.357
701.904	664.623
705.333	668.175
708.759	670.299
712.183	676.137
715.606	668.832
719.028	665.813
722.449	662.222
725.868	671.488
729.286	666.183
732.703	668.307
736.117	669.002
739.531	661.983
742.944	659.821
746.355	659.944
749.766	663.211
753.173	656.477
756.581	686.029
759.987	665.582
763.39	682.277
766.794	672.686
770.195	673.953
773.596	662.648
776.994	674.485
780.393	671.466
783.788	665.304
787.185	675.428
790.578	657.551
793.971	676.247
797.362	676.084
800.751	678.208
804.138	675.76
807.527	675.884
810.912	675.722
814.296	690.131
817.679	684.826
821.06	694.378
824.441	703.645
827.822	698.626
831.199	704.178
834.576	696.873
837.951	708.425
841.323	708.834
844.695	695.529
848.066	706.51
851.436	694.92
854.805	708.186
858.173	711.738
861.539	692.148
864.902	721.7
868.266	712.109
871.628	714.233
874.987	696.071
878.347	700.48
881.704	705.461
885.061	696.727
888.418	681.994
891.771	676.974
895.122	685.384
898.475	688.65
901.824	678.202
905.174	678.897
908.52	681.307
911.866	680.573
915.212	686.983
918.555	691.106
921.896	683.516
925.237	692.782
928.576	683.477
931.914	692.172
935.253	689.439
938.588	697.562
941.922	690.257
945.255	706.095
948.587	705.647
951.917	700.343
955.244	692.18
958.572	712.304
961.899	697.856
965.225	696.837
968.549	708.961
971.872	690.798
975.192	712.636
978.512	703.903
981.831	718.884
985.148	707.007
988.464	721.131
991.778	701.826
995.092	703.664
998.404	711.216
1001.72	711.34
1005.02	746.32
1008.33	727.873
1011.64	723.139
1014.95	714.691
1018.25	717.386
1021.55	709.51
1024.85	701.634
1028.16	714.043
1031.46	719.309
1034.75	711.433
1038.05	712.128
1041.34	716.823
1044.64	723.518
1047.93	713.07
1051.22	731.765
1054.51	738.461
1057.8	740.87
1061.09	730.708
1064.38	727.403
1067.66	742.098
1070.95	732.507
1074.23	742.631
1077.51	726.469
1080.79	732.021
1084.07	735.002
1087.35	742.554
1090.62	731.82
1093.9	738.801
1097.17	728.639
1100.44	735.334
1103.71	732.886
1106.99	730.724
1110.25	721.705
1113.52	712.4
1116.79	718.238
1120.05	734.362
1123.31	740.485
1126.58	738.894
1129.84	748.161
1133.1	721.427
1136.36	740.123
1139.61	736.818
1142.87	745.513
1146.12	749.636
1149.38	762.331
1152.63	805.312
1155.88	829.721
1159.13	825.845
1162.38	799.683
1165.63	754.092
1168.87	760.216
1172.12	745.482
1175.36	739.606
1178.6	750.872
1181.84	743.853
1185.08	757.405
1188.32	769.529
1191.56	752.224
1194.79	752.062
1198.03	743.9
1201.26	737.166
1204.49	761.576
1207.72	739.128
1210.95	752.966
1214.18	755.089
1217.41	735.213
1220.64	741.908
1223.86	725.175
1227.08	739.584
1230.3	720.565
1233.53	733.545
1236.75	712.812
1239.96	728.078
1243.18	714.202
1246.4	726.326
1249.61	737.306
1252.82	747.144
1256.04	740.697
1259.25	747.106
1262.46	738.658
1265.67	755.068
1268.87	746.62
1272.08	743.886
1275.28	740.867
1278.49	749.848
1281.69	746.828
1284.89	746.381
1288.09	740.361
1291.29	738.914
1294.49	729.037
1297.68	740.589
1300.88	751.284
1304.07	759.408
1307.26	746.103
1310.46	744.512
1313.65	754.35
1316.84	758.474
1320.02	758.598
1323.21	744.15
1326.39	760.845
1329.58	766.683
1332.76	750.521
1335.94	749.216
1339.12	750.482
1342.3	745.463
1345.48	743.872
1348.65	753.424
1351.83	764.977
1355	745.1
1358.18	754.081
1361.35	747.919
1364.52	755.185
1367.69	758.166
1370.86	727.147
1374.02	768.128
1377.19	737.394
1380.35	751.518
1383.52	740.499
1386.68	735.765
1389.84	743.032
1393	742.87
1396.16	752.707
1399.31	736.831
1402.47	755.526
1405.63	747.078
1408.78	750.916
1411.93	746.183
1415.08	742.878
1418.23	755.573
1421.38	753.696
1424.53	756.963
1427.68	758.801
1430.82	760.067
1433.96	775.334
1437.11	768.6
1440.25	758.152
1443.39	772.847
1446.53	757.828
1449.67	774.809
1452.8	782.933
1455.94	765.913
1459.07	774.037
1462.21	753.303
1465.34	782.856
1468.47	758.694
1471.6	753.96
1474.72	766.369
1477.85	750.207
1480.98	742.902
1484.1	766.74
1487.23	752.007
1490.35	739.845
1493.47	753.397
1496.59	773.235
1499.71	755.358
1502.83	761.482
1505.94	768.748
1509.06	782.301
1512.17	810.424
1515.29	836.548
1518.4	850.672
1521.51	877.938
1524.62	888.347
1527.72	907.614
1530.83	883.737
1533.94	866.433
1537.04	806.842
1540.15	802.108
1543.25	808.803
1546.35	786.641
1549.45	791.908
1552.55	776.031
1555.65	773.584
1558.74	775.136
1561.84	765.259
1564.93	774.24
1568.02	774.935
1571.12	754.773
1574.2	775.754
1577.3	754.449
1580.38	763.144
1583.47	769.839
1586.56	748.82
1589.64	761.801
1592.72	761.638
1595.81	762.619
1598.89	765.6
1601.97	768.867
1605.05	770.133
1608.12	773.052
1611.2	761.722
1614.27	772.926
1617.35	757.648
1620.42	748.175
1623.5	762.601
1626.57	767.836
1629.63	771.967
1632.7	758.138
1635.77	743.386
1638.84	764.316
1641.9	760.31
1644.97	766.232
1648.03	756.229
1651.09	762.021
1654.15	776.97
1657.21	770.818
1660.27	758.912
1663.32	770.111
1666.38	763.714
1669.43	769.593
1672.49	773.578
1675.54	768.449
1678.59	762.853
1681.64	770.638
1684.69	765.12
1687.73	765.033
1690.78	768.524
1693.83	766.341
1696.87	759.093
1699.91	762.765
1702.96	756.706
1706	752.295
1709.04	753.439
1712.07	753.427
1715.11	755.218
1718.15	748.527
1721.18	751.47
1724.21	756.666
1727.25	745.931
1730.28	753.038
1733.31	745.291
1736.34	753.669
1739.37	739.732
1742.39	748.854
1745.42	739.288
1748.45	739.852
1751.47	745.45
1754.49	736.758
1757.51	747.433
1759.25	742.074
1762.28	740.691
1765.31	735.309
1768.34	767.26
1771.37	718.544
1774.4	744.495
1777.43	748.446
1780.46	740.397
1783.48	729.681
1786.51	758.299
1789.53	745.583
1792.55	722.867
1795.57	738.151
1798.59	766.102
1801.61	740.053
1804.63	750.004
1807.64	776.622
1810.66	756.573
1813.67	774.524
1816.68	764.475
1819.7	747.092
1822.71	753.71
1825.72	728.994
1828.72	722.278
1831.73	743.563
1834.74	720.18
1837.74	740.798
1840.75	748.749
1843.75	744.033
1846.75	731.317
1849.75	735.268
1852.75	762.553
1855.75	757.17
1858.75	729.121
1861.74	739.072
1864.74	732.356
1867.73	739.641
1870.72	757.591
1873.71	741.542
1876.7	762.827
1879.69	732.778
1882.68	739.395
1885.67	752.68
1888.66	750.63
1891.64	741.915
1894.62	742.532
1897.61	737.817
1900.59	753.101
1903.57	744.385
1906.55	745.669
1909.53	732.954
1912.5	738.238
1915.48	750.855
1918.46	756.806
1921.43	722.757
1924.4	754.042
1927.37	753.992
1930.34	744.61
1933.31	742.561
1936.28	758.512
1939.25	778.463
1942.22	759.747
1945.18	761.698
1948.14	728.316
1951.11	727.6
1954.07	737.551
1957.03	756.835
1959.99	722.786
1962.95	723.404
1965.91	754.688
1968.86	750.639
1971.82	732.59
1974.77	739.874
1977.73	753.158
1980.68	755.776
1983.63	716.394
1986.58	749.678
1989.53	740.962
1992.47	734.246
1995.42	735.531
1998.37	742.148
2001.31	744.099
2004.25	740.717
2007.2	718.668
2010.14	753.285
2013.08	739.236
2016.02	745.187
2018.96	733.138
2021.89	741.089
2024.83	713.04
2027.76	732.991
2030.7	716.275
2033.63	711.559
2036.56	730.844
2039.49	741.461
2042.42	738.079
2045.35	741.363
2048.28	715.314
2051.2	733.265
2054.13	734.549
2057.05	733.834
2059.97	736.451
2062.9	738.402
2065.82	733.686
2068.74	750.971
2071.65	732.922
2074.57	744.872
2077.49	734.823
2080.4	740.774
2083.32	731.392
2086.23	729.343
2089.15	721.96
2092.05	723.911
2094.97	703.862
2097.87	737.813
2100.78	717.098
2103.69	701.049
2106.6	714.999
2109.5	717.617
2112.4	712.901
2115.31	741.519
2118.21	715.47
2121.11	706.087
2124.01	726.038
2126.91	725.323
2129.8	721.94
2132.7	727.891
2135.59	718.509
2138.49	724.46
2141.38	712.411
2144.27	701.695
2147.16	718.312
2150.05	721.597
2152.94	726.214
2155.83	718.832
2158.72	718.116
2161.6	720.067
2164.49	708.685
2167.37	718.636
2170.26	723.253
2173.14	695.871
2176.02	707.822
2178.9	711.106
2181.77	725.057
2184.65	741.008
2187.53	704.292
2190.4	706.91
2193.28	725.527
2196.15	710.812
2199.02	717.429
2201.89	698.047
2204.76	713.331
2207.63	710.615
2210.5	721.9
2213.37	705.184
2216.23	690.468
2219.1	679.086
2221.96	679.037
2224.82	696.321
2227.69	670.272
2230.55	703.556
2233.41	706.174
2236.26	684.791
2239.12	684.742
2241.98	678.027
2244.83	693.311
2247.69	685.262
2250.54	677.213
2253.39	661.83
2256.24	689.781
2259.09	665.065
2261.94	671.016
2264.79	664.967
2267.64	665.585
2270.49	675.536
2273.33	672.154
2276.18	681.438
2279.02	661.389
2281.86	678.006
2284.7	664.624
2287.54	681.908
2290.38	669.859
2293.22	673.143
2296.05	675.761
2298.89	673.712
2301.72	670.996
2304.56	678.947
2307.39	674.898
2310.22	672.182
2313.05	682.133
2315.88	692.751
2318.71	702.702
2321.54	670.653
2324.36	681.937
2327.19	659.221
2330.01	687.839
2332.84	684.456
2335.66	665.741
2338.48	670.358
2341.3	666.976
2344.12	656.927
2346.94	690.878
2349.76	670.162
2352.57	662.113
2355.39	659.397
2358.2	648.015
2361.02	636.632
2363.83	673.25
2366.64	653.868
2369.45	666.485
2372.26	654.436
2375.07	655.054
2377.87	653.005
2380.68	670.289
2383.49	652.907
2386.29	658.857
2389.09	632.142
2391.9	654.093
2394.7	644.71
2397.5	655.328
2400.29	645.279
2403.09	657.23
2405.89	643.847
2408.69	652.465
2411.48	652.416
2414.28	659.033
2417.07	644.984
2419.86	655.602
2422.65	658.22
2425.44	652.837
2428.23	654.788
2431.02	652.739
2433.81	662.69
2436.59	651.308
2439.38	651.925
2442.16	657.209
2444.94	653.16
2447.73	644.445
2450.51	647.729
2453.29	650.346
2456.07	643.631
2458.84	668.915
2461.62	668.199
2464.4	650.817
2467.17	650.768
2469.95	669.385
2472.72	655.336
2475.49	661.287
2478.26	652.572
2481.03	645.856
2483.8	661.14
2486.57	674.424
2489.34	651.042
2492.1	656.326
2494.87	646.277
2497.63	654.895
2500.39	664.179
2503.16	649.463
2505.92	656.748
2508.68	646.698
2511.44	649.983
2514.19	648.6
2516.95	667.885
2519.71	653.169
2522.46	655.12
2525.22	633.071
2527.97	633.688
2530.72	637.639
2533.47	638.924
2536.22	650.208
2538.97	632.825
2541.72	660.11
2544.47	661.394
2547.21	666.012
2549.96	649.962
2552.7	647.913
2555.45	643.864
2558.19	653.149
2560.93	639.766
2563.67	657.717
2566.41	642.335
2569.15	644.952
2571.89	653.57
2574.62	616.188
2577.36	646.138
2580.09	636.756
2582.83	638.04
2585.56	643.325
2588.29	647.276
2591.02	617.893
2593.75	627.844
2596.48	655.128
2599.21	643.079
2601.93	648.364
2604.66	657.648
2607.39	656.265
2610.11	652.216
2612.83	674.167
2615.55	656.785
2618.27	680.069
2620.99	644.687
2623.71	654.638
2626.43	663.922
2629.15	653.206
2631.86	640.49
2634.58	657.108
2637.29	637.059
2640.01	647.677
2642.72	678.294
2645.43	640.912
2648.14	670.196
2650.85	658.147
2653.56	636.098
2656.26	638.049
2658.97	648.666
2661.68	641.284
2664.38	637.902
2667.09	654.519
2669.79	650.47
2672.49	656.421
2675.19	653.705
2677.89	644.323
2680.59	654.274
2683.29	656.225
2685.98	664.842
2688.68	666.127
2691.37	670.744
2694.07	658.695
2696.76	651.313
2699.45	647.264
2702.14	629.215
2704.83	644.499
2707.52	654.45
2710.21	639.734
2712.9	634.352
2715.58	653.636
2718.27	654.254
2720.95	640.871
2723.64	630.822
2726.32	662.773
2729	635.391
2731.68	627.342
2734.36	631.293
2737.04	651.91
2739.72	661.861
2742.39	646.479
2745.07	641.096
2747.74	634.381
2750.42	660.998
2753.09	632.949
2755.76	666.9
2758.43	634.184
2761.1	638.802
2763.77	658.753
2766.44	654.037
2769.11	666.655
2771.78	656.606
2774.44	645.223
2777.11	632.508
2779.77	637.125
2782.43	645.076
2785.09	645.694
2787.76	622.978
2790.41	659.595
2793.07	631.546
2795.73	637.497
2798.39	657.448
2801.04	639.399
2803.7	652.017
2806.35	656.634
2809.01	640.585
2811.66	640.536
2814.31	626.487
2816.96	643.771
2819.61	632.389
2822.26	639.673
2824.91	666.291
2827.55	645.575
2830.2	650.859
2832.84	641.477
2835.49	649.428
2838.13	662.046
2840.77	659.33
2843.41	664.614
2846.05	663.898
2848.69	658.516
2851.33	664.467
2853.97	666.418
2856.6	659.035
2859.24	674.986
2861.87	674.271
2864.51	670.222
2867.14	690.839
2869.77	694.79
2872.4	702.074
2875.03	685.359
2877.66	697.976
2880.29	682.594
2882.92	717.211
2885.54	731.162
2888.17	711.113
2890.79	727.064
2893.42	737.015
2896.04	730.966
2898.66	737.584
2901.28	723.535
2903.9	734.152
2906.52	752.77
2909.14	750.054
2911.76	741.338
2914.37	742.623
2916.99	713.24
2919.6	763.858
2922.21	745.809
2924.83	735.093
2927.44	743.044
2930.05	740.995
2932.66	758.946
2935.27	773.563
2937.88	747.514
2940.48	759.465
2943.09	758.083
2945.69	756.7
2948.3	766.651
2950.9	739.269
2953.5	755.887
2956.1	767.171
2958.7	721.122
2961.3	724.406
2963.9	711.69
2966.5	719.641
2969.1	695.592
2971.69	680.21
2974.29	717.494
2976.88	700.778
2979.48	721.396
2982.07	689.347
2984.66	701.298
2987.25	705.915
2989.84	703.866
2992.43	689.151
2995.02	683.768
2997.6	681.052
3000.19	689.003
3002.77	660.954
3005.36	662.239
3007.94	668.856
3010.53	652.807
3013.11	664.758
3015.69	666.709
3018.27	667.993
3020.85	678.611
3023.42	660.562
3026	658.513
3028.58	649.13
3031.15	661.081
3033.73	659.699
3036.3	676.983
3038.87	670.934
3041.44	655.552
3044.01	662.169
3046.58	660.12
3047.87	678.762