File: muestras/manzana/mz_15.txt
#Acq. time (s)=	20
#Accumulations=	8
#Range (cm-¹)=	50...4000
#Windows=	3
#Autofocus=	Off
#AutoExposure=	Off
#Spike filter=	Multiple accum.
#Delay time (s)=	0
#Binning=	1
#Readout mode=	Signal
#DeNoise=	Off
#ICS correction=	Off
#Dark correction=	Off
#Inst. Process=	Off
#Instrument=	LabRAM HR Evol
#Detector=	Syncerity OE
#Objective=	x100_VIS
#Grating=	600 (500nm)
#ND Filter=	5%
#Laser=	532nm_Edge
#Hole=	100.021
#Range=	Visible
#Project=	Omar
#Sample=	120523
#Site=	ap
#Title=	mz
#Remark=	5 laser intensity
#Date=	12.05.2023 17:01
#Acquired=	12.05.2023 17:01:16
51.0297	26.5714
54.7185	34.6951
58.406	52.8187
62.0919	110.085
65.7765	178.78
69.4595	257.761
73.1412	363.885
76.8214	442.294
80.5001	496.132
84.1774	563.684
87.8532	578.379
91.5276	601.36
95.2006	585.483
98.8721	593.321
102.54	600.588
106.209	608.711
109.876	612.549
113.542	615.244
117.204	616.225
120.867	605.492
124.526	602.472
128.186	602.596
131.845	600.72
135.5	616.843
139.155	613.253
142.807	609.091
146.46	619.5
150.11	619.624
153.757	630.89
157.406	609.585
161.051	622.566
164.697	611.832
168.339	625.099
171.98	619.222
175.619	613.632
179.259	613.184
182.895	620.45
186.53	620.288
190.164	610.126
193.796	616.25
197.427	615.231
201.059	603.069
204.686	601.764
208.313	610.459
211.938	602.582
215.562	600.42
219.184	592.83
222.803	591.239
226.422	580.505
230.04	587.2
233.657	597.324
237.272	582.305
240.886	589.857
244.497	591.409
248.108	590.676
251.717	578.228
255.325	595.494
258.93	585.618
262.535	578.599
266.137	580.151
269.74	589.703
273.341	583.541
276.939	581.95
280.537	574.36
284.132	578.769
287.728	565.178
291.32	584.159
294.911	572.283
298.502	578.121
302.09	566.816
305.677	576.368
309.264	588.777
312.848	598.329
316.43	591.882
320.011	578.005
323.593	600.129
327.171	591.395
330.748	581.805
334.323	595.928
337.897	588.338
341.47	587.604
345.041	597.442
348.611	593.566
352.18	567.689
355.747	586.956
359.312	587.365
362.877	582.632
366.44	585.041
369.999	597.736
373.56	595.86
377.119	599.698
380.676	600.964
384.23	602.23
387.785	609.211
391.338	605.049
394.888	593.173
398.439	601.868
401.988	610.563
405.534	601.829
409.081	605.382
412.624	613.791
416.167	612.772
419.708	623.752
423.249	606.162
426.786	616
430.323	599.838
433.86	600.818
437.393	600.942
440.926	601.066
444.458	608.046
447.988	606.17
451.516	626.865
455.043	616.132
458.568	619.112
462.092	622.664
465.615	620.217
469.138	631.483
472.658	624.75
476.177	611.445
479.694	613.283
483.21	619.692
486.723	624.387
490.236	620.796
493.748	623.491
497.258	631.615
500.768	618.024
504.276	639.005
507.78	625.414
511.285	619.538
514.789	631.376
518.289	639.5
521.791	641.337
525.29	660.604
528.787	636.442
532.284	641.137
535.778	631.832
539.272	624.527
542.763	629.793
546.255	648.203
549.743	638.041
553.232	643.021
556.718	632.574
560.203	639.554
563.688	624.535
567.169	642.373
570.65	626.497
574.129	638.049
577.609	637.03
581.085	642.01
584.56	643.848
588.034	642.829
591.506	655.238
594.978	643.076
598.447	644.914
601.916	652.181
605.383	641.447
608.849	652.999
612.313	658.552
615.776	658.104
619.238	667.37
622.699	664.065
626.156	669.903
629.614	694.884
633.071	672.151
636.526	670.274
639.978	654.112
643.431	655.093
646.88	666.931
650.33	662.197
653.779	656.607
657.224	661.016
660.67	649.425
664.113	677.549
667.556	650.244
670.997	662.367
674.435	661.92
677.875	661.472
681.311	675.596
684.746	658.005
688.182	657.843
691.614	655.395
695.045	658.09
698.475	673.357
701.904	664.623
705.333	668.175
708.759	670.299
712.183	676.137
715.606	668.832
719.028	665.813
722.449	662.222
725.868	671.488
729.286	666.183
732.703	668.307
736.117	669.002
739.531	661.983
742.944	659.821
746.355	659.944
749.766	663.211
753.173	656.477
756.581	686.029
759.987	665.582
763.39	682.277
766.794	672.686
770.195	673.953
773.596	662.648
776.994	674.485
780.393	671.466
783.788	665.304
787.185	675.428
790.578	657.551
793.971	676.247
797.362	676.084
800.751	678.208
804.138	675.76
807.527	675.884
810.912	675.722
814.296	690.131
817.679	684.826
821.06	694.378
824.441	703.645
827.822	698.626
831.199	704.178
834.576	696.873
837.951	708.425
841.323	708.834
844.695	695.529
848.066	706.51
851.436	694.92
854.805	708.186
858.173	711.738
861.539	692.148
864.902	721.7
868.266	712.109
871.628	714.233
874.987	696.071
878.347	700.48
881.704	705.461
885.061	696.727
888.418	681.994
891.771	676.974
895.122	685.384
898.475	688.65
901.824	678.202
905.174	678.897
908.52	681.307
911.866	680.573
915.212	686.983
918.555	691.106
921.896	683.516
925.237	692.782
928.576	683.477
931.914	692.172
935.253	689.439
938.588	697.562
941.922	690.257
945.255	706.095
948.587	705.647
951.917	700.343
955.244	692.18
958.572	712.304
961.899	697.856
965.225	696.837
968.549	708.961
971.872	690.798
975.192	712.636
978.512	703.903
981.831	718.884
985.148	707.007
988.464	721.131
991.778	701.826
995.092	703.664
998.404	711.216
1001.72	711.34
1005.02	746.32
1008.33	727.873
1011.64	723.139
1014.95	714.691
1018.25	717.386
1021.55	709.51
1024.85	701.634
1028.16	714.043
1031.46	719.309
1034.75	711.433
1038.05	712.128
1041.34	716.823
1044.64	723.518
1047.93	713.07
1051.22	731.765
1054.51	738.461
1057.8	740.87
1061.09	730.708
1064.38	727.403
1067.66	742.098
1070.95	732.507
1074.23	742.631
1077.51	726.469
1080.79	732.021
1084.07	735.002
1087.35	742.554
1090.62	731.82
1093.9	738.801
1097.17	728.639
1100.44	735.334
1103.71	732.886
1106.99	730.724
1110.25	721.705
1113.52	712.4
1116.79	718.238
1120.05	734.362
1123.31	740.485
1126.58	738.894
1129.84	748.161
1133.1	721.427
1136.36	740.123
1139.61	736.818
1142.87	745.513
1146.12	749.636
1149.38	762.331
1152.63	805.312
1155.88	829.721
1159.13	825.845
1162.38	799.683
1165.63	754.092
1168.87	760.216
1172.12	745.482
1175.36	739.606
1178.6	750.872
1181.84	743.853
1185.08	757.405
1188.32	769.529
1191.56	752.224
1194.79	752.062
1198.03	743.9
1201.26	737.166
1204.49	761.576
1207.72	739.128
1210.95	752.966
1214.18	755.089
1217.41	735.213
1220.64	741.908
1223.86	725.175
1227.08	739.584
1230.3	720.565
1233.53	733.545
1236.75	712.812
1239.96	728.078
1243.18	714.202
1246.4	726.326
1249.61	737.306
1252.82	747.144
1256.04	740.697
1259.25	747.106
1262.46	738.658
1265.67	755.068
1268.87	746.62
1272.08	743.886
1275.28	740.867
1278.49	749.848
1281.69	746.828
1284.89	746.381
1288.09	740.361
1291.29	738.914
1294.49	729.037
1297.68	740.589
1300.88	751.284
1304.07	759.408
1307.26	746.103
1310.46	744.512
1313.65	754.35
1316.84	758.474
1320.02	758.598
1323.21	744.15
1326.39	760.845
1329.58	766.683
1332.76	750.521
1335.94	749.216
1339.12	750.482
1342.3	745.463
1345.48	743.872
1348.65	753.424
1351.83	764.977
1355	745.1
1358.18	754.081
1361.35	747.919
1364.52	755.185
1367.69	758.166
1370.86	727.147
1374.02	768.128
1377.19	737.394
1380.35	751.518
1383.52	740.499
1386.68	735.765
1389.84	743.032
1393	742.87
1396.16	752.707
1399.31	736.831
1402.47	755.526
1405.63	747.078
1408.78	750.916
1411.93	746.183
1415.08	742.878
1418.23	755.573
1421.38	753.696
1424.53	756.963
1427.68	758.801
1430.82	760.067
1433.96	775.334
1437.11	768.6
1440.25	758.152
1443.39	772.847
1446.53	757.828
1449.67	774.809
1452.8	782.933
1455.94	765.913
1459.07	774.037
1462.21	753.303
1465.34	782.856
1468.47	758.694
1471.6	753.96
1474.72	766.369
1477.85	750.207
1480.98	742.902
1484.1	766.74
1487.23	752.007
1490.35	739.845
1493.47	753.397
1496.59	773.235
1499.71	755.358
1502.83	761.482
1505.94	768.748
1509.06	782.301
1512.17	810.424
1515.29	836.548
1518.4	850.672
1521.51	877.938
1524.62	888.347
1527.72	907.614
1530.83	883.737
1533.94	866.433
1537.04	806.842
1540.15	802.108
1543.25	808.803
1546.35	786.641
1549.45	791.908
1552.55	776.031
1555.65	773.584
1558.74	775.136
1561.84	765.259
1564.93	774.24
1568.02	774.935
1571.12	754.773
1574.2	775.754
1577.3	754.449
1580.38	763.144
1583.47	769.839
1586.56	748.82
1589.64	761.801
1592.72	761.638
1595.81	762.619
1598.89	765.6
1601.97	768.867
1605.05	770.133
1608.12	772.779
1611.2	761.568
1614.27	771.82
1617.35	756.881
1620.42	747.852
1623.5	761.619
1626.57	765.657
1629.63	769.538
1632.7	757.405
1635.77	743.037
1638.84	762.742
1641.9	757.813
1644.97	763.893
1648.03	755.382
1651.09	760.465
1654.15	771.737
1657.21	767.111
1660.27	756.31
1663.32	767.076
1666.38	760.098
1669.43	762.392
1672.49	768.816
1675.54	761.929
1678.59	759.358
1681.64	767.423
1684.69	765.702
1687.73	758.448
1690.78	759.21
1693.83	761.854
1696.87	753.194
1699.91	751.924
1702.96	752.221
1706	750.804
1709.04	746.863
1712.07	752.778
1715.11	750.752
1718.15	745.734
1721.18	745.86
1724.21	750.937
1727.25	743.488
1730.28	745.879
1733.31	739.145
1736.34	740.588
1739.37	726.329
1742.39	740.57
1745.42	731.98
1748.45	740.417
1751.47	740.894
1754.49	723.852
1757.51	737.015
1759.25	734.941
1762.28	747.238
1765.31	732.868
1768.34	755.498
1771.37	727.128
1774.4	744.425
1777.43	743.055
1780.46	743.018
1783.48	735.648
1786.51	745.612
1789.53	736.575
1792.55	723.872
1795.57	738.168
1798.59	746.132
1801.61	749.095
1804.63	748.725
1807.64	757.022
1810.66	749.985
1813.67	746.615
1816.68	766.579
1819.7	741.876
1822.71	745.172
1825.72	722.136
1828.72	720.432
1831.73	739.729
1834.74	726.359
1837.74	737.656
1840.75	741.286
1843.75	734.916
1846.75	722.546
1849.75	739.176
1852.75	746.806
1855.75	735.77
1858.75	721.4
1861.74	732.363
1864.74	726.326
1867.73	738.956
1870.72	747.586
1873.71	732.216
1876.7	742.18
1879.69	733.81
1882.68	729.773
1885.67	736.403
1888.66	746.034
1891.64	744.997
1894.62	736.627
1897.61	738.257
1900.59	736.22
1903.57	727.184
1906.55	733.814
1909.53	739.444
1912.5	738.741
1915.48	748.371
1918.46	747.334
1921.43	742.964
1924.4	739.927
1927.37	742.557
1930.34	736.854
1933.31	734.484
1936.28	754.114
1939.25	755.411
1942.22	754.708
1945.18	747.004
1948.14	737.635
1951.11	742.598
1954.07	732.561
1957.03	743.858
1959.99	733.155
1962.95	716.451
1965.91	739.415
1968.86	741.045
1971.82	725.008
1974.77	737.305
1977.73	737.602
1980.68	749.898
1983.63	717.862
1986.58	739.158
1989.53	732.789
1992.47	739.085
1995.42	733.715
1998.37	736.345
2001.31	734.642
2004.25	729.939
2007.2	718.236
2010.14	735.532
2013.08	736.829
2016.02	735.792
2018.96	730.422
2021.89	730.719
2024.83	721.349
2027.76	730.979
2030.7	720.609
2033.63	709.239
2036.56	728.536
2039.49	731.5
2042.42	737.796
2045.35	732.426
2048.28	706.723
2051.2	729.686
2054.13	730.316
2057.05	734.28
2059.97	724.243
2062.9	718.54
2065.82	728.837
2068.74	728.467
2071.65	738.097
2074.57	731.727
2077.49	728.357
2080.4	728.654
2083.32	724.95
2086.23	724.247
2089.15	709.21
2092.05	718.174
2094.97	708.471
2097.87	725.767
2100.78	717.397
2103.69	709.361
2106.6	718.324
2109.5	717.621
2112.4	711.917
2115.31	707.214
2118.21	708.178
2121.11	693.474
2124.01	718.104
2126.91	718.068
2129.8	709.698
2132.7	720.661
2135.59	715.958
2138.49	718.921
2141.38	711.885
2144.27	704.515
2147.16	710.811
2150.05	719.441
2152.94	715.405
2155.83	715.702
2158.72	710.665
2161.6	711.295
2164.49	718.925
2167.37	713.555
2170.26	713.852
2173.14	698.815
2176.02	703.445
2178.9	710.075
2181.77	718.039
2184.65	720.002
2187.53	708.299
2190.4	704.596
2193.28	713.226
2196.15	704.856
2199.02	710.486
2201.89	701.449
2204.76	710.412
2207.63	709.709
2210.5	698.006
2213.37	692.969
2216.23	692.599
2219.1	683.896
2221.96	680.526
2224.82	692.823
2227.69	671.786
2230.55	686.75
2233.41	687.38
2236.26	678.676
2239.12	672.973
2241.98	675.936
2244.83	681.9
2247.69	673.197
2250.54	673.827
2253.39	658.123
2256.24	673.753
2259.09	665.383
2261.94	668.68
2264.79	663.977
2267.64	663.274
2270.49	664.57
2273.33	660.867
2276.18	677.83
2279.02	666.127
2281.86	662.424
2284.7	669.387
2287.54	668.017
2290.38	664.314
2293.22	668.944
2296.05	670.574
2298.89	673.871
2301.72	668.834
2304.56	674.798
2307.39	673.428
2310.22	673.058
2313.05	669.688
2315.88	683.318
2318.71	683.948
2321.54	667.911
2324.36	683.541
2327.19	661.171
2330.01	675.801
2332.84	671.765
2335.66	657.395
2338.48	665.358
2341.3	657.655
2344.12	659.952
2346.94	680.915
2349.76	663.212
2352.57	660.842
2355.39	660.139
2358.2	654.102
2361.02	645.065
2363.83	658.362
2366.64	646.992
2369.45	656.622
2372.26	652.919
2375.07	645.882
2377.87	658.512
2380.68	658.476
2383.49	653.439
2386.29	656.403
2389.09	636.366
2391.9	644.996
2394.7	640.293
2397.5	647.923
2400.29	650.219
2403.09	640.516
2405.89	639.813
2408.69	647.776
2411.48	652.406
2414.28	651.036
2417.07	646
2419.86	646.63
2422.65	643.26
2425.44	653.223
2428.23	649.853
2431.02	648.15
2433.81	654.78
2436.59	642.077
2439.38	646.04
2442.16	642.004
2444.94	658.634
2447.73	649.93
2450.51	645.227
2453.29	648.19
2456.07	656.82
2458.84	663.784
2461.62	658.747
2464.4	648.044
2467.17	644.007
2469.95	660.637
2472.72	651.601
2475.49	649.231
2478.26	649.194
2481.03	646.824
2483.8	655.121
2486.57	663.084
2489.34	653.381
2492.1	650.011
2494.87	652.641
2497.63	659.938
2500.39	663.235
2503.16	647.198
2505.92	650.495
2508.68	652.791
2511.44	648.755
2514.19	652.052
2516.95	652.015
2519.71	644.978
2522.46	655.275
2525.22	631.572
2527.97	636.535
2530.72	640.499
2533.47	636.795
2536.22	652.759
2538.97	641.389
2541.72	655.352
2544.47	657.649
2547.21	657.279
2549.96	646.909
2552.7	643.539
2555.45	640.836
2558.19	653.466
2560.93	634.429
2563.67	645.726
2566.41	643.689
2569.15	636.986
2571.89	647.949
2574.62	621.246
2577.36	643.209
2580.09	632.506
2582.83	631.803
2585.56	646.433
2588.29	651.396
2591.02	628.36
2593.75	638.323
2596.48	653.953
2599.21	644.917
2601.93	638.547
2604.66	637.51
2607.39	650.807
2610.11	648.437
2612.83	662.067
2615.55	661.03
2618.27	661.66
2620.99	649.624
2623.71	652.254
2626.43	649.55
2629.15	652.18
2631.86	638.81
2634.58	643.44
2637.29	644.071
2640.01	650.701
2642.72	659.997
2645.43	648.627
2648.14	653.924
2650.85	650.888
2653.56	640.518
2656.26	647.481
2658.97	643.111
2661.68	644.074
2664.38	642.038
2667.09	647.001
2669.79	644.965
2672.49	644.928
2675.19	651.225
2677.89	648.188
2680.59	644.151
2683.29	642.115
2685.98	649.078
2688.68	659.042
2691.37	664.338
2694.07	653.635
2696.76	644.932
2699.45	639.562
2702.14	639.859
2704.83	635.489
2707.52	648.785
2710.21	636.749
2712.9	631.045
2715.58	648.009
2718.27	637.639
2720.95	638.269
2723.64	625.899
2726.32	657.196
2729	631.826
2731.68	626.122
2734.36	642.752
2737.04	655.383
2739.72	651.013
2742.39	632.643
2745.07	639.273
2747.74	637.236
2750.42	654.199
2753.09	636.496
2755.76	657.793
2758.43	645.423
2761.1	631.72
2763.77	650.35
2766.44	648.98
2769.11	653.61
2771.78	646.573
2774.44	642.203
2777.11	639.833
2779.77	639.13
2782.43	640.76
2785.09	635.057
2787.76	632.687
2790.41	659.984
2793.07	643.614
2795.73	638.577
2798.39	651.874
2801.04	643.17
2803.7	642.467
2806.35	652.764
2809.01	643.727
2811.66	645.691
2814.31	635.321
2816.96	637.284
2819.61	639.581
2822.26	646.544
2824.91	665.174
2827.55	646.471
2830.2	650.768
2832.84	645.064
2835.49	648.361
2838.13	655.658
2840.77	658.621
2843.41	657.251
2846.05	663.215
2848.69	657.845
2851.33	667.141
2853.97	664.105
2856.6	667.068
2859.24	680.698
2861.87	674.995
2864.51	672.292
2867.14	677.922
2869.77	688.552
2872.4	688.515
2875.03	694.145
2877.66	685.442
2880.29	692.072
2882.92	720.369
2885.54	723.999
2888.17	708.962
2890.79	719.259
2893.42	736.889
2896.04	730.519
2898.66	743.149
2901.28	738.446
2903.9	737.742
2906.52	746.706
2909.14	737.669
2911.76	740.966
2914.37	740.929
2916.99	722.893
2919.6	763.189
2922.21	740.486
2924.83	741.45
2927.44	755.746
2930.05	738.043
2932.66	751.34
2935.27	773.303
2937.88	747.6
2940.48	749.897
2943.09	757.527
2945.69	755.157
2948.3	758.12
2950.9	747.417
2953.5	758.047
2956.1	747.677
2958.7	731.974
2961.3	721.27
2963.9	716.567
2966.5	708.53
2969.1	699.494
2971.69	695.124
2974.29	721.421
2976.88	696.051
2979.48	704.681
2982.07	689.644
2984.66	704.607
2987.25	703.571
2989.84	703.868
2992.43	684.831
2995.02	675.794
2997.6	672.424
3000.19	685.721
3002.77	664.684
3005.36	653.648
3007.94	659.611
3010.53	656.908
3013.11	663.205
3015.69	659.168
3018.27	662.798
3020.85	682.762
3023.42	654.058
3026	653.022
3028.58	644.985
3031.15	672.948
3033.73	661.912
3036.3	667.875
3038.87	665.505
3041.44	651.135
3044.01	669.099
3046.58	659.729
3047.87	677.71