File: muestras/manzana/mz_25.txt
#Acq. time (s)=	15
#Accumulations=	4
#Range (cm-¹)=	50...4000
#Windows=	3
#Autofocus=	Off
#AutoExposure=	Off
#Spike filter=	Multiple accum.
#Delay time (s)=	0
#Binning=	1
#Readout mode=	Signal
#DeNoise=	Off
#ICS correction=	Off
#Dark correction=	Off
#Inst. Process=	Off
#Instrument=	LabRAM HR Evol
#Detector=	Syncerity OE
#Objective=	x100_VIS
#Grating=	600 (500nm)
#ND Filter=	5%
#Laser=	532nm_Edge
#Hole=	100.021
#Range=	Visible
#Project=	Omar
#Sample=	120523
#Site=	ap
#Title=	mz
#Remark=	5 laser intensity
#Date=	12.05.2023 17:17
#Acquired=	12.05.2023 17:17:49
51.0297	17.3333
54.7185	28.473
58.406	35.6128
62.0919	62.0858
65.7765	95.2255
69.4595	141.699
73.1412	210.838
76.8214	269.978
80.5001	307.118
84.1774	360.924
87.8532	414.73
91.5276	414.537
95.2006	397.677
98.8721	419.483
102.54	405.289
106.209	441.762
109.876	437.569
113.542	432.042
117.204	464.515
120.867	436.988
124.526	446.128
128.186	449.267
131.845	441.074
135.5	455.547
139.155	450.02
142.807	465.826
146.46	468.966
150.11	458.106
153.757	461.245
157.406	450.385
161.051	466.191
164.697	469.331
168.339	471.138
171.98	476.277
175.619	465.417
179.259	467.223
182.895	471.03
186.53	484.836
190.164	483.976
193.796	496.449
197.427	495.589
201.059	489.395
204.686	485.868
208.313	478.341
211.938	484.147
215.562	503.287
219.184	485.76
222.803	476.233
226.422	482.706
230.04	488.513
233.657	480.986
237.272	485.459
240.886	501.932
244.497	495.072
248.108	505.545
251.717	499.351
255.325	499.824
258.93	509.63
262.535	502.104
266.137	501.91
269.74	508.383
273.341	518.189
276.939	492.662
280.537	508.469
284.132	490.942
287.728	506.748
291.32	501.888
294.911	511.028
298.502	513.501
302.09	527.307
305.677	516.447
309.264	520.92
312.848	530.06
316.43	543.866
320.011	525.672
323.593	537.479
327.171	542.618
330.748	521.091
334.323	542.231
337.897	538.038
341.47	560.511
345.041	534.984
348.611	503.457
352.18	527.93
355.747	529.736
359.312	530.876
362.877	564.016
366.44	536.489
369.999	561.628
373.56	537.435
377.119	558.574
380.676	547.047
384.23	550.187
387.785	555.327
391.338	580.467
394.888	555.606
398.439	557.413
401.988	559.219
405.534	566.359
409.081	558.165
412.624	569.972
416.167	555.778
419.708	559.584
423.249	572.057
426.786	545.197
430.323	551.67
433.86	564.143
437.393	560.616
440.926	565.089
444.458	571.562
447.988	568.035
451.516	579.842
455.043	572.982
458.568	582.788
462.092	583.261
465.615	588.401
469.138	600.207
472.658	588.68
476.177	598.486
479.694	601.626
483.21	593.433
486.723	603.239
490.236	591.045
493.748	594.852
497.258	616.658
500.768	588.465
504.276	598.938
507.78	610.077
511.285	597.217
514.789	605.023
518.289	609.496
521.791	608.636
525.29	621.776
528.787	618.916
532.284	606.055
535.778	622.528
539.272	637.001
542.763	625.474
546.255	619.281
549.743	619.087
553.232	642.227
556.718	628.033
560.203	633.84
563.688	635.646
567.169	615.452
570.65	640.592
574.129	622.399
577.609	620.205
581.085	634.678
584.56	643.818
588.034	641.624
591.506	610.097
594.978	625.904
598.447	633.043
601.916	625.516
605.383	649.323
608.849	629.129
612.313	634.269
615.776	656.075
619.238	646.548
622.699	651.021
626.156	658.828
629.614	640.634
633.071	669.107
636.526	652.247
639.978	663.386
643.431	673.859
646.88	672.333
650.33	674.806
653.779	678.612
657.224	683.085
660.67	664.891
664.113	680.698
667.556	679.171
670.997	668.977
674.435	678.784
677.875	659.257
681.311	665.063
684.746	664.203
688.182	667.343
691.614	673.816
695.045	671.622
698.475	666.762
701.904	670.568
705.333	677.041
708.759	688.181
712.183	669.32
715.606	684.46
719.028	700.267
722.449	688.073
725.868	685.213
729.286	677.686
732.703	679.492
736.117	678.632
739.531	670.438
742.944	698.911
746.355	694.051
749.766	699.857
753.173	687.664
756.581	706.137
759.987	679.943
763.39	677.75
766.794	684.889
770.195	687.362
773.596	681.169
776.994	678.308
780.393	681.448
783.788	681.255
787.185	671.728
790.578	710.867
793.971	678.007
797.362	694.48
800.751	692.953
804.138	702.093
807.527	714.566
810.912	687.706
814.296	710.179
817.679	700.652
821.06	699.791
824.441	716.265
827.822	716.738
831.199	703.211
834.576	707.017
837.951	708.823
841.323	715.963
844.695	713.103
848.066	722.242
851.436	714.716
854.805	722.522
858.173	758.995
861.539	711.468
864.902	722.608
868.266	711.747
871.628	702.887
874.987	720.694
878.347	717.167
881.704	718.306
885.061	720.779
888.418	707.252
891.771	712.392
895.122	718.199
898.475	716.672
901.824	733.145
905.174	720.284
908.52	712.757
911.866	723.897
915.212	699.703
918.555	737.51
921.896	731.983
925.237	718.456
928.576	706.262
931.914	710.069
935.253	732.542
938.588	745.681
941.922	716.821
945.255	730.628
948.587	738.434
951.917	736.24
955.244	728.047
958.572	740.52
961.899	728.993
965.225	736.133
968.549	721.272
971.872	734.412
975.192	735.552
978.512	744.691
981.831	736.498
985.148	749.638
988.464	725.444
991.778	737.917
995.092	728.39
998.404	760.196
1001.72	734.003
1005.02	745.809
1008.33	749.616
1011.64	738.755
1014.95	737.228
1018.25	736.368
1021.55	743.508
1024.85	743.314
1028.16	761.787
1031.46	735.594
1034.75	750.733
1038.05	738.54
1041.34	745.679
1044.64	742.819
1047.93	745.292
1051.22	769.765
1054.51	779.571
1057.8	772.045
1061.09	773.184
1064.38	762.324
1067.66	770.13
1070.95	775.937
1074.23	766.41
1077.51	775.55
1080.79	780.023
1084.07	766.496
1087.35	781.635
1090.62	780.775
1093.9	755.248
1097.17	781.721
1100.44	762.861
1103.71	774.667
1106.99	763.14
1110.25	776.28
1113.52	760.086
1116.79	786.56
1120.05	743.699
1123.31	766.172
1126.58	762.645
1129.84	772.452
1133.1	760.925
1136.36	796.064
1139.61	767.871
1142.87	755.011
1146.12	763.484
1149.38	792.623
1152.63	775.763
1155.88	784.236
1159.13	794.042
1162.38	784.516
1165.63	766.989
1168.87	780.128
1172.12	769.935
1175.36	809.074
1178.6	814.214
1181.84	790.02
1185.08	797.16
1188.32	797.633
1191.56	798.773
1194.79	799.913
1198.03	815.719
1201.26	817.525
1204.49	799.332
1207.72	779.138
1210.95	829.611
1214.18	818.751
1217.41	799.224
1220.64	803.03
1223.86	787.503
1227.08	802.643
1230.3	800.45
1233.53	810.256
1236.75	794.729
1239.96	779.202
1243.18	807.675
1246.4	798.148
1249.61	807.954
1252.82	798.428
1256.04	800.901
1259.25	817.374
1262.46	817.847
1265.67	803.653
1268.87	802.126
1272.08	809.933
1275.28	797.072
1278.49	796.212
1281.69	796.018
1284.89	799.158
1288.09	826.631
1291.29	835.437
1294.49	816.577
1297.68	829.05
1300.88	816.19
1304.07	824.663
1307.26	837.803
1310.46	816.276
1313.65	814.749
1316.84	817.888
1320.02	827.028
1323.21	832.168
1326.39	825.974
1329.58	857.114
1332.76	826.254
1335.94	846.06
1339.12	837.867
1342.3	808.34
1345.48	830.813
1348.65	838.619
1351.83	820.425
1355	833.565
1358.18	822.705
1361.35	830.511
1364.52	828.318
1367.69	840.791
1370.86	820.597
1374.02	835.737
1377.19	846.21
1380.35	855.35
1383.52	833.156
1386.68	848.296
1389.84	851.435
1393	829.908
1396.16	833.715
1399.31	853.521
1402.47	837.328
1405.63	819.801
1408.78	846.94
1411.93	862.747
1415.08	849.22
1418.23	837.693
1421.38	846.833
1424.53	863.972
1427.68	847.112
1430.82	876.252
1433.96	854.725
1437.11	860.531
1440.25	853.671
1443.39	858.81
1446.53	866.617
1449.67	868.423
1452.8	858.896
1455.94	878.703
1459.07	856.509
1462.21	852.982
1465.34	851.455
1468.47	869.928
1471.6	851.068
1474.72	862.874
1477.85	857.347
1480.98	843.154
1484.1	852.294
1487.23	854.1
1490.35	854.573
1493.47	851.713
1496.59	829.519
1499.71	850.659
1502.83	873.798
1505.94	868.938
1509.06	871.411
1512.17	864.551
1515.29	857.024
1518.4	870.83
1521.51	885.303
1524.62	905.776
1527.72	909.583
1530.83	894.056
1533.94	869.196
1537.04	879.669
1540.15	886.808
1543.25	879.948
1546.35	883.088
1549.45	894.894
1552.55	884.701
1555.65	892.507
1558.74	892.313
1561.84	878.786
1564.93	890.593
1568.02	885.066
1571.12	923.539
1574.2	879.345
1577.3	887.152
1580.38	892.291
1583.47	882.764
1586.56	896.571
1589.64	883.044
1592.72	888.85
1595.81	907.323
1598.89	893.796
1601.97	888.269
1605.05	880.742
1608.12	873.096
1611.2	884.024
1614.27	879.133
1617.35	859.371
1620.42	872.749
1623.5	874.343
1626.57	882.167
1629.63	887.397
1632.7	876.777
1635.77	876.473
1638.84	876.716
1641.9	893.096
1644.97	883.217
1648.03	888.349
1651.09	891.794
1654.15	888.605
1657.21	888.809
1660.27	898.768
1663.32	899.984
1666.38	885.121
1669.43	908.937
1672.49	902.999
1675.54	889.431
1678.59	901.026
1681.64	909.414
1684.69	910.427
1687.73	907.451
1690.78	912.346
1693.83	909.793
1696.87	907.991
1699.91	896.129
1702.96	906.384
1706	904.68
1709.04	899.874
1712.07	900.118
1715.11	886.021
1718.15	879.801
1721.18	897.657
1724.21	895.688
1727.25	895.395
1730.28	899.287
1733.31	891.177
1736.34	901.645
1739.37	897.003
1742.39	897.363
1745.42	873.318
1748.45	895.69
1751.47	888.499
1754.49	900.419
1757.51	903.179
1759.25	885.803
1762.28	888.459
1765.31	882.448
1768.34	903.77
1771.37	879.093
1774.4	897.082
1777.43	909.071
1780.46	889.06
1783.48	902.382
1786.51	895.037
1789.53	891.026
1792.55	916.349
1795.57	905.004
1798.59	908.327
1801.61	910.316
1804.63	931.638
1807.64	903.627
1810.66	905.616
1813.67	904.272
1816.68	904.927
1819.7	905.583
1822.71	900.239
1825.72	899.561
1828.72	894.883
1831.73	898.206
1834.74	920.195
1837.74	907.517
1840.75	914.172
1843.75	932.161
1846.75	900.15
1849.75	914.139
1852.75	890.795
1855.75	910.784
1858.75	911.44
1861.74	897.429
1864.74	895.418
1867.73	904.073
1870.72	899.396
1873.71	899.385
1876.7	906.707
1879.69	901.363
1882.68	896.685
1885.67	895.341
1888.66	892.663
1891.64	903.318
1894.62	899.974
1897.61	913.296
1900.59	915.285
1903.57	913.941
1906.55	915.263
1909.53	917.919
1912.5	927.908
1915.48	905.897
1918.46	899.219
1921.43	917.875
1924.4	907.197
1927.37	918.52
1930.34	906.509
1933.31	907.164
1936.28	911.82
1939.25	911.809
1942.22	918.465
1945.18	889.12
1948.14	921.109
1951.11	908.431
1954.07	933.754
1957.03	895.743
1959.99	923.732
1962.95	919.054
1965.91	905.71
1968.86	895.699
1971.82	925.021
1974.77	917.677
1977.73	897.666
1980.68	916.321
1983.63	921.644
1986.58	926.966
1989.53	914.288
1992.47	889.611
1995.42	896.266
1998.37	886.922
2001.31	921.578
2004.25	899.567
2007.2	905.555
2010.14	920.211
2013.08	926.2
2016.02	926.189
2018.96	914.178
2021.89	896.834
2024.83	932.823
2027.76	897.478
2030.7	914.134
2033.63	912.79
2036.56	924.112
2039.49	934.768
2042.42	915.423
2045.35	915.412
2048.28	913.401
2051.2	909.39
2054.13	915.379
2057.05	912.035
2059.97	883.357
2062.9	924.679
2065.82	910.668
2068.74	908.657
2071.65	926.646
2074.57	917.969
2077.49	914.624
2080.4	907.947
2083.32	894.602
2086.23	913.258
2089.15	909.914
2092.05	913.903
2094.97	898.558
2097.87	908.547
2100.78	903.87
2103.69	886.525
2106.6	899.848
2109.5	905.836
2112.4	873.826
2115.31	899.148
2118.21	897.137
2121.11	875.126
2124.01	893.115
2126.91	886.437
2129.8	893.093
2132.7	881.082
2135.59	898.404
2138.49	899.726
2141.38	901.049
2144.27	889.704
2147.16	898.36
2150.05	901.682
2152.94	893.671
2155.83	884.994
2158.72	893.649
2161.6	884.971
2164.49	898.96
2167.37	904.283
2170.26	894.272
2173.14	910.261
2176.02	920.25
2178.9	916.239
2181.77	899.561
2184.65	905.55
2187.53	906.872
2190.4	890.861
2193.28	889.517
2196.15	908.839
2199.02	897.495
2201.89	910.817
2204.76	893.473
2207.63	876.128
2210.5	910.784
2213.37	886.773
2216.23	894.095
2219.1	888.751
2221.96	871.407
2224.82	863.396
2227.69	874.718
2230.55	866.04
2233.41	860.696
2236.26	870.685
2239.12	868.007
2241.98	852.663
2244.83	871.319
2247.69	859.974
2250.54	851.963
2253.39	848.619
2256.24	854.608
2259.09	850.597
2261.94	867.919
2264.79	853.241
2267.64	867.897
2270.49	869.886
2273.33	865.208
2276.18	858.531
2279.02	863.186
2281.86	860.509
2284.7	863.831
2287.54	868.487
2290.38	855.809
2293.22	856.465
2296.05	822.454
2298.89	857.776
2301.72	863.098
2304.56	864.421
2307.39	874.41
2310.22	868.398
2313.05	879.054
2315.88	862.376
2318.71	869.699
2321.54	869.021
2324.36	885.677
2327.19	877.666
2330.01	855.655
2332.84	863.644
2335.66	878.966
2338.48	886.288
2341.3	886.277
2344.12	858.933
2346.94	884.922
2349.76	871.578
2352.57	855.567
2355.39	861.556
2358.2	858.878
2361.02	854.2
2363.83	864.856
2366.64	865.511
2369.45	843.5
2372.26	873.489
2375.07	842.812
2377.87	870.134
2380.68	842.123
2383.49	841.445
2386.29	854.101
2389.09	850.09
2391.9	841.412
2394.7	858.068
2397.5	841.39
2400.29	815.379
2403.09	827.368
2405.89	862.024
2408.69	842.013
2411.48	850.669
2414.28	832.657
2417.07	847.98
2419.86	845.302
2422.65	858.624
2425.44	829.28
2428.23	854.602
2431.02	863.925
2433.81	831.247
2436.59	858.569
2439.38	847.225
2442.16	849.881
2444.94	847.203
2447.73	851.192
2450.51	845.181
2453.29	859.17
2456.07	833.159
2458.84	861.815
2461.62	869.137
2464.4	860.459
2467.17	851.115
2469.95	879.104
2472.72	876.426
2475.49	868.415
2478.26	879.071
2481.03	877.726
2483.8	866.382
2486.57	879.038
2489.34	862.36
2492.1	858.349
2494.87	845.671
2497.63	880.327
2500.39	856.983
2503.16	860.305
2505.92	861.627
2508.68	863.616
2511.44	864.272
2514.19	882.927
2516.95	854.25
2519.71	866.906
2522.46	867.561
2525.22	839.55
2527.97	848.872
2530.72	868.861
2533.47	827.517
2536.22	858.173
2538.97	860.828
2541.72	827.484
2544.47	858.14
2547.21	843.462
2549.96	847.451
2552.7	840.107
2555.45	867.429
2558.19	862.085
2560.93	858.74
2563.67	855.396
2566.41	853.385
2569.15	866.04
2571.89	848.696
2574.62	851.352
2577.36	836.674
2580.09	837.33
2582.83	871.985
2585.56	877.308
2588.29	862.63
2591.02	883.286
2593.75	857.941
2596.48	875.93
2599.21	869.919
2601.93	858.575
2604.66	871.231
2607.39	871.886
2610.11	876.542
2612.83	880.531
2615.55	873.186
2618.27	863.842
2620.99	870.498
2623.71	882.487
2626.43	887.809
2629.15	875.131
2631.86	873.787
2634.58	879.109
2637.29	867.098
2640.01	880.421
2642.72	885.743
2645.43	887.065
2648.14	878.388
2650.85	893.043
2653.56	884.366
2656.26	905.688
2658.97	892.344
2661.68	880.999
2664.38	882.321
2667.09	852.977
2669.79	866.299
2672.49	880.288
2675.19	868.277
2677.89	870.933
2680.59	856.255
2683.29	864.244
2685.98	872.233
2688.68	873.556
2691.37	871.545
2694.07	880.2
2696.76	885.523
2699.45	886.845
2702.14	878.834
2704.83	876.156
2707.52	853.479
2710.21	855.468
2712.9	865.456
2715.58	884.112
2718.27	865.434
2720.95	855.423
2723.64	889.412
2726.32	868.068
2729	872.724
2731.68	872.046
2734.36	876.035
2737.04	872.024
2739.72	868.013
2742.39	878.002
2745.07	875.324
2747.74	885.313
2750.42	868.636
2753.09	892.625
2755.76	907.947
2758.43	899.269
2761.1	891.925
2763.77	882.58
2766.44	903.903
2769.11	873.225
2771.78	901.881
2774.44	891.203
2777.11	894.525
2779.77	885.848
2782.43	899.837
2785.09	866.492
2787.76	895.148
2790.41	883.804
2793.07	907.126
2795.73	879.115
2798.39	887.104
2801.04	881.76
2803.7	869.082
2806.35	902.404
2809.01	892.393
2811.66	894.382
2814.31	895.038
2816.96	885.027
2819.61	908.349
2822.26	913.005
2824.91	902.994
2827.55	899.649
2830.2	895.638
2832.84	889.627
2835.49	894.283
2838.13	908.272
2840.77	902.928
2843.41	892.25
2846.05	874.906
2848.69	902.895
2851.33	920.883
2853.97	911.539
2856.6	922.195
2859.24	880.184
2861.87	896.173
2864.51	922.162
2867.14	902.151
2869.77	914.14
2872.4	912.129
2875.03	903.451
2877.66	917.44
2880.29	898.096
2882.92	920.751
2885.54	928.74
2888.17	924.063
2890.79	922.052
2893.42	930.041
2896.04	945.363
2898.66	930.019
2901.28	927.341
2903.9	932.663
2906.52	934.652
2909.14	942.641
2911.76	942.63
2914.37	946.619
2916.99	935.275
2919.6	937.93
2922.21	942.586
2924.83	919.908
2927.44	913.897
2930.05	921.886
2932.66	950.542
2935.27	936.531
2937.88	963.187
2940.48	936.509
2943.09	947.165
2945.69	952.487
2948.3	925.809
2950.9	950.465
2953.5	962.454
2956.1	931.109
2958.7	943.098
2961.3	916.421
2963.9	919.743
2966.5	921.732
2969.1	923.721
2971.69	924.377
2974.29	914.366
2976.88	937.021
2979.48	943.677
2982.07	900.333
2984.66	918.322
2987.25	892.977
2989.84	914.299
2992.43	902.289
2995.02	898.278
2997.6	909.6
3000.19	901.589
3002.77	885.578
3005.36	901.567
3007.94	897.556
3010.53	900.211
3013.11	902.2
3015.69	910.856
3018.27	896.845
3020.85	913.501
3023.42	924.823
3026	908.145
3028.58	907.468
3031.15	896.123
3033.73	904.112
3036.3	890.768
3038.87	905.424
3041.44	912.746
3044.01	904.068
3046.58	914.724
3047.87	896.052