File: muestras/manzana/mz_29.txt
#Acq. time (s)=	15
#Accumulations=	4
#Range (cm-¹)=	50...4000
#Windows=	3
#Autofocus=	Off
#AutoExposure=	Off
#Spike filter=	Multiple accum.
#Delay time (s)=	0
#Binning=	1
#Readout mode=	Signal
#DeNoise=	Off
#ICS correction=	Off
#Dark correction=	Off
#Inst. Process=	Off
#Instrument=	LabRAM HR Evol
#Detector=	Syncerity OE
#Objective=	x100_VIS
#Grating=	600 (500nm)
#ND Filter=	5%
#Laser=	532nm_Edge
#Hole=	100.021
#Range=	Visible
#Project=	Omar
#Sample=	120523
#Site=	ap
#Title=	mz
#Remark=	5 laser intensity
#Date=	12.05.2023 17:23
#Acquired=	12.05.2023 17:23:54
51.0297	20
54.7185	29.4889
58.406	34.9778
62.0919	70.4668
65.7765	104.622
69.4595	146.778
73.1412	246.267
76.8214	295.756
80.5001	345.245
84.1774	406.067
87.8532	456.223
91.5276	449.045
95.2006	442.534
98.8721	444.689
102.54	466.845
106.209	485.667
109.876	469.156
113.542	498.645
117.204	498.134
120.867	497.623
124.526	489.112
128.186	482.601
131.845	480.09
135.5	504.245
139.155	489.734
142.807	498.556
146.46	528.712
150.11	512.868
153.757	531.69
157.406	534.512
161.051	521.334
164.697	508.157
168.339	505.646
171.98	506.468
175.619	518.623
179.259	534.779
182.895	522.935
186.53	524.424
190.164	531.912
193.796	522.068
197.427	547.557
201.059	535.046
204.686	526.535
208.313	522.69
211.938	536.179
215.562	537.002
219.184	541.824
222.803	532.646
226.422	549.468
230.04	548.957
233.657	531.779
237.272	553.935
240.886	549.424
244.497	540.246
248.108	553.735
251.717	557.891
255.325	552.046
258.93	548.202
262.535	562.358
266.137	553.847
269.74	553.335
273.341	566.158
276.939	544.98
280.537	563.802
284.132	563.291
287.728	550.113
291.32	568.269
294.911	562.425
298.502	565.247
302.09	563.402
305.677	567.558
309.264	579.714
312.848	585.869
316.43	581.358
320.011	556.847
323.593	565.669
327.171	579.158
330.748	585.314
334.323	570.136
337.897	574.292
341.47	577.114
345.041	579.936
348.611	583.425
352.18	583.581
355.747	587.07
359.312	561.892
362.877	588.048
366.44	584.87
369.999	605.025
373.56	597.181
377.119	595.336
380.676	596.159
384.23	616.314
387.785	611.137
391.338	615.959
394.888	594.115
398.439	607.603
401.988	616.426
405.534	602.581
409.081	610.737
412.624	612.226
416.167	611.715
419.708	615.87
423.249	604.026
426.786	622.182
430.323	585.67
433.86	615.159
437.393	611.315
440.926	590.804
444.458	637.626
447.988	630.448
451.516	609.937
455.043	621.426
458.568	627.582
462.092	633.071
465.615	635.893
469.138	632.049
472.658	625.538
476.177	652.36
479.694	647.182
483.21	630.671
486.723	659.493
490.236	642.982
493.748	629.138
497.258	651.96
500.768	646.116
504.276	656.938
507.78	639.76
511.285	650.582
514.789	636.738
518.289	646.227
521.791	656.382
525.29	657.871
528.787	671.36
532.284	679.516
535.778	673.005
539.272	664.494
542.763	661.316
546.255	688.138
549.743	692.294
553.232	668.449
556.718	668.605
560.203	678.761
563.688	658.25
567.169	673.738
570.65	661.894
574.129	688.05
577.609	692.205
581.085	690.361
584.56	691.183
588.034	682.005
591.506	684.161
594.978	658.983
598.447	674.472
601.916	678.628
605.383	671.45
608.849	688.939
612.313	735.761
615.776	703.917
619.238	696.739
622.699	708.228
626.156	715.717
629.614	717.872
633.071	719.361
636.526	718.184
639.978	732.339
643.431	716.495
646.88	723.984
650.33	720.806
653.779	686.962
657.224	727.784
660.67	745.939
664.113	723.428
667.556	718.917
670.997	723.74
674.435	711.228
677.875	717.384
681.311	716.873
684.746	736.362
688.182	719.851
691.614	728.006
695.045	725.495
698.475	719.651
701.904	727.806
705.333	719.962
708.759	738.784
712.183	723.607
715.606	753.096
719.028	733.251
722.449	744.74
725.868	734.229
729.286	757.718
732.703	749.874
736.117	728.696
739.531	738.185
742.944	745.674
746.355	747.829
749.766	731.318
753.173	744.14
756.581	752.296
759.987	744.452
763.39	755.94
766.794	747.429
770.195	732.252
773.596	726.407
776.994	751.23
780.393	769.385
783.788	760.207
787.185	776.363
790.578	725.852
793.971	739.341
797.362	758.83
800.751	751.652
804.138	765.141
807.527	758.63
810.912	762.119
814.296	763.608
817.679	791.097
821.06	767.919
824.441	775.408
827.822	790.897
831.199	769.052
834.576	797.875
837.951	763.363
841.323	770.852
844.695	791.675
848.066	778.497
851.436	792.653
854.805	789.475
858.173	806.964
861.539	794.453
864.902	792.608
868.266	784.097
871.628	789.586
874.987	799.742
878.347	801.897
881.704	793.386
885.061	776.208
888.418	798.364
891.771	792.52
895.122	778.675
898.475	783.497
901.824	802.986
905.174	789.809
908.52	787.964
911.866	814.12
915.212	798.942
918.555	811.098
921.896	809.92
925.237	805.409
928.576	801.564
931.914	821.72
935.253	815.876
938.588	821.365
941.922	802.187
945.255	803.676
948.587	806.498
951.917	806.654
955.244	840.143
958.572	834.965
961.899	819.12
965.225	823.943
968.549	826.765
971.872	828.254
975.192	832.409
978.512	827.898
981.831	821.387
985.148	805.543
988.464	816.365
991.778	835.854
995.092	808.676
998.404	841.499
1001.72	819.654
1005.02	836.476
1008.33	837.299
1011.64	831.454
1014.95	832.943
1018.25	837.765
1021.55	857.921
1024.85	833.41
1028.16	840.232
1031.46	846.388
1034.75	843.21
1038.05	846.699
1041.34	844.188
1044.64	851.01
1047.93	833.832
1051.22	838.655
1054.51	840.81
1057.8	868.966
1061.09	862.455
1064.38	874.61
1067.66	868.099
1070.95	875.588
1074.23	885.744
1077.51	873.899
1080.79	862.055
1084.07	884.211
1087.35	863.033
1090.62	879.188
1093.9	866.011
1097.17	876.166
1100.44	878.322
1103.71	859.144
1106.99	881.966
1110.25	856.122
1113.52	866.278
1116.79	870.433
1120.05	889.922
1123.31	858.078
1126.58	872.9
1129.84	860.389
1133.1	865.878
1136.36	894.7
1139.61	866.189
1142.87	891.678
1146.12	892.5
1149.38	891.989
1152.63	920.811
1155.88	917.634
1159.13	909.789
1162.38	897.278
1165.63	908.1
1168.87	892.256
1172.12	901.745
1175.36	907.901
1178.6	909.389
1181.84	911.545
1185.08	936.367
1188.32	927.856
1191.56	935.345
1194.79	919.501
1198.03	952.99
1201.26	920.479
1204.49	905.301
1207.72	911.456
1210.95	927.612
1214.18	937.768
1217.41	931.923
1220.64	924.079
1223.86	913.568
1227.08	939.723
1230.3	899.212
1233.53	912.701
1236.75	888.19
1239.96	907.012
1243.18	919.168
1246.4	922.657
1249.61	925.479
1252.82	928.968
1256.04	927.124
1259.25	913.946
1262.46	931.435
1265.67	956.257
1268.87	932.413
1272.08	943.902
1275.28	951.39
1278.49	975.546
1281.69	935.035
1284.89	963.857
1288.09	939.013
1291.29	948.835
1294.49	939.657
1297.68	953.813
1300.88	963.302
1304.07	979.458
1307.26	958.946
1310.46	957.102
1313.65	962.591
1316.84	963.413
1320.02	978.235
1323.21	960.391
1326.39	969.213
1329.58	966.702
1332.76	956.858
1335.94	977.013
1339.12	958.502
1342.3	967.991
1345.48	1075.48
1348.65	988.969
1351.83	979.125
1355	965.28
1358.18	972.102
1361.35	980.925
1364.52	959.747
1367.69	962.569
1370.86	1010.72
1374.02	962.214
1377.19	969.703
1380.35	974.525
1383.52	979.347
1386.68	982.836
1389.84	980.992
1393	1002.48
1396.16	989.97
1399.31	972.125
1402.47	991.614
1405.63	975.103
1408.78	995.925
1411.93	1000.75
1415.08	1031.57
1418.23	1003.73
1421.38	1017.88
1424.53	1012.04
1427.68	984.859
1430.82	1033.68
1433.96	1013.84
1437.11	1010.66
1440.25	1038.15
1443.39	1026.97
1446.53	1023.79
1449.67	1019.28
1452.8	1033.44
1455.94	1020.26
1459.07	1027.08
1462.21	1003.9
1465.34	1031.39
1468.47	1021.55
1471.6	1003.7
1474.72	1033.86
1477.85	1004.01
1480.98	995.504
1484.1	1024.33
1487.23	1008.48
1490.35	1007.3
1493.47	1027.46
1496.59	1024.28
1499.71	1033.1
1502.83	1031.26
1505.94	1008.75
1509.06	1036.24
1512.17	1059.73
1515.29	1048.55
1518.4	1058.7
1521.51	1104.86
1524.62	1095.02
1527.72	1065.84
1530.83	1072.66
1533.94	1082.82
1537.04	1085.64
1540.15	1063.79
1543.25	1078.62
1546.35	1058.1
1549.45	1073.59
1552.55	1049.75
1555.65	1054.57
1558.74	1071.39
1561.84	1076.88
1564.93	1067.7
1568.02	1054.53
1571.12	1064.02
1574.2	1067.5
1577.3	1078.99
1580.38	1061.15
1583.47	1066.64
1586.56	1054.79
1589.64	1070.28
1592.72	1083.77
1595.81	1083.26
1598.89	1043.42
1601.97	1074.91
1605.05	1044.39
1608.12	1052.38
1611.2	1040.63
1614.27	1051.95
1617.35	1033.39
1620.42	1058.93
1623.5	1052.01
1626.57	1083.17
1629.63	1060.21
1632.7	1072.52
1635.77	1057
1638.84	1076.48
1641.9	1061.15
1644.97	1041.72
1648.03	1041.14
1651.09	1057.26
1654.15	1078.72
1657.21	1058.51
1660.27	1084.66
1663.32	1081.29
1666.38	1069.28
1669.43	1078.89
1672.49	1076.74
1675.54	1057.7
1678.59	1070.36
1681.64	1096.8
1684.69	1091.2
1687.73	1081.13
1690.78	1072.61
1693.83	1076.08
1696.87	1071.05
1699.91	1065.02
1702.96	1070.03
1706	1052.06
1709.04	1047.01
1712.07	1065.51
1715.11	1048.93
1718.15	1067.84
1721.18	1053.21
1724.21	1037.28
1727.25	1047.69
1730.28	1041.24
1733.31	1035.33
1736.34	1025.18
1739.37	1021.98
1742.39	1043.78
1745.42	1027.57
1748.45	1028.66
1751.47	1025.13
1754.49	1040.09
1757.51	1037.89
1759.25	1028.54
1762.28	1028.11
1765.31	1049.67
1768.34	1035.23
1771.37	1039.46
1774.4	1026.36
1777.43	1041.25
1780.46	1062.15
1783.48	1065.71
1786.51	1063.27
1789.53	1045.5
1792.55	1065.73
1795.57	1041.96
1798.59	1037.52
1801.61	1042.42
1804.63	1054.65
1807.64	1052.88
1810.66	1039.11
1813.67	1053.34
1816.68	1057.57
1819.7	1035.8
1822.71	1046.02
1825.72	1054.92
1828.72	1046.48
1831.73	1046.05
1834.74	1056.27
1837.74	1041.17
1840.75	1050.07
1843.75	1038.96
1846.75	1044.52
1849.75	1039.42
1852.75	1042.98
1855.75	1031.21
1858.75	1056.77
1861.74	1041.67
1864.74	1050.57
1867.73	1061.46
1870.72	1038.36
1873.71	1035.25
1876.7	1018.15
1879.69	1051.71
1882.68	1042.61
1885.67	1040.17
1888.66	1059.07
1891.64	1051.3
1894.62	1037.53
1897.61	1034.42
1900.59	1056.65
1903.57	1042.21
1906.55	1042.44
1909.53	1060
1912.5	1050.23
1915.48	1067.8
1918.46	1054.03
1921.43	1050.25
1924.4	1065.15
1927.37	1048.71
1930.34	1062.28
1933.31	1083.17
1936.28	1054.73
1939.25	1078.3
1942.22	1046.53
1945.18	1050.75
1948.14	1064.32
1951.11	1052.55
1954.07	1060.78
1957.03	1059
1959.99	1073.23
1962.95	1044.13
1965.91	1067.03
1968.86	1045.92
1971.82	1051.48
1974.77	1069.05
1977.73	1074.61
1980.68	1048.84
1983.63	1036.4
1986.58	1070.63
1989.53	1045.53
1992.47	1039.09
1995.42	1010.65
1998.37	1040.88
2001.31	1055.11
2004.25	1038.67
2007.2	1048.23
2010.14	1035.13
2013.08	1044.03
2016.02	1051.59
2018.96	1039.15
2021.89	1039.38
2024.83	1046.94
2027.76	1060.51
2030.7	1036.07
2033.63	1049.63
2036.56	1036.53
2039.49	1022.09
2042.42	1044.32
2045.35	1031.88
2048.28	1044.78
2051.2	1050.34
2054.13	1037.9
2057.05	1056.13
2059.97	1051.69
2062.9	1036.59
2065.82	1056.82
2068.74	1058.38
2071.65	1022.61
2074.57	1038.84
2077.49	1051.73
2080.4	1042.63
2083.32	1033.53
2086.23	1023.76
2089.15	1025.32
2092.05	1041.55
2094.97	1043.78
2097.87	1030.01
2100.78	1035.57
2103.69	1026.46
2106.6	1036.03
2109.5	1019.59
2112.4	1005.15
2115.31	1030.71
2118.21	1024.28
2121.11	1033.17
2124.01	1006.07
2126.91	1020.96
2129.8	1007.86
2132.7	1018.76
2135.59	1014.99
2138.49	1032.55
2141.38	1020.11
2144.27	1037.01
2147.16	1025.9
2150.05	1016.8
2152.94	1044.36
2155.83	1017.92
2158.72	1010.82
2161.6	1023.71
2164.49	1019.28
2167.37	1026.84
2170.26	1043.07
2173.14	1052.63
2176.02	1015.53
2178.9	1034.42
2181.77	1017.99
2184.65	1008.88
2187.53	1028.44
2190.4	1017.34
2193.28	1011.57
2196.15	1025.8
2199.02	1010.69
2201.89	1021.59
2204.76	1018.49
2207.63	1019.38
2210.5	1017.61
2213.37	1014.51
2216.23	1014.74
2219.1	994.299
2221.96	999.861
2224.82	1014.09
2227.69	995.653
2230.55	1013.88
2233.41	1000.78
2236.26	980.34
2239.12	987.236
2241.98	998.799
2244.83	975.028
2247.69	973.257
2250.54	973.486
2253.39	970.382
2256.24	969.945
2259.09	992.84
2261.94	979.736
2264.79	960.632
2267.64	983.528
2270.49	963.091
2273.33	967.986
2276.18	953.549
2279.02	987.111
2281.86	992.674
2284.7	988.903
2287.54	952.466
2290.38	983.362
2293.22	986.257
2296.05	972.487
2298.89	964.049
2301.72	972.945
2304.56	964.508
2307.39	979.403
2310.22	968.966
2313.05	982.528
2315.88	994.758
2318.71	972.32
2321.54	974.549
2324.36	976.112
2327.19	996.341
2330.01	991.237
2332.84	998.799
2335.66	1002.36
2338.48	975.924
2341.3	987.487
2344.12	972.383
2346.94	979.279
2349.76	979.508
2352.57	980.404
2355.39	973.299
2358.2	985.529
2361.02	985.758
2363.83	967.987
2366.64	972.216
2369.45	976.445
2372.26	977.341
2375.07	985.57
2377.87	949.8
2380.68	963.362
2383.49	948.925
2386.29	961.821
2389.09	958.05
2391.9	954.279
2394.7	950.508
2397.5	961.404
2400.29	946.967
2403.09	948.529
2405.89	940.758
2408.69	960.321
2411.48	959.217
2414.28	952.779
2417.07	944.342
2419.86	957.238
2422.65	957.467
2425.44	950.363
2428.23	972.592
2431.02	959.488
2433.81	944.383
2436.59	958.613
2439.38	966.842
2442.16	967.738
2444.94	959.967
2447.73	978.196
2450.51	972.425
2453.29	977.988
2456.07	983.55
2458.84	969.113
2461.62	977.342
2464.4	986.238
2467.17	968.467
2469.95	973.363
2472.72	957.592
2475.49	960.488
2478.26	982.051
2481.03	981.613
2483.8	991.176
2486.57	948.738
2489.34	960.967
2492.1	989.196
2494.87	976.092
2497.63	960.322
2500.39	994.551
2503.16	960.78
2505.92	971.009
2508.68	984.572
2511.44	996.134
2514.19	961.697
2516.95	932.593
2519.71	954.155
2522.46	971.718
2525.22	964.613
2527.97	972.176
2530.72	943.738
2533.47	959.301
2536.22	965.53
2538.97	951.759
2541.72	963.322
2544.47	936.884
2547.21	956.447
2549.96	950.009
2552.7	932.239
2555.45	936.468
2558.19	951.364
2560.93	956.26
2563.67	953.822
2566.41	946.051
2569.15	930.947
2571.89	959.843
2574.62	964.739
2577.36	958.968
2580.09	969.197
2582.83	946.093
2585.56	950.322
2588.29	973.218
2591.02	962.114
2593.75	936.343
2596.48	965.239
2599.21	967.468
2601.93	977.697
2604.66	958.593
2607.39	964.156
2610.11	985.718
2612.83	976.614
2615.55	982.843
2618.27	987.739
2620.99	988.635
2623.71	967.531
2626.43	977.093
2629.15	978.656
2631.86	996.885
2634.58	983.781
2637.29	965.343
2640.01	936.239
2642.72	977.135
2645.43	962.031
2648.14	966.927
2650.85	974.489
2653.56	977.385
2656.26	964.948
2658.97	969.844
2661.68	995.406
2664.38	960.302
2667.09	955.198
2669.79	968.76
2672.49	969.656
2675.19	981.219
2677.89	968.115
2680.59	979.011
2683.29	961.906
2685.98	994.802
2688.68	958.365
2691.37	965.261
2694.07	944.156
2696.76	950.386
2699.45	960.615
2702.14	942.177
2704.83	969.073
2707.52	946.636
2710.21	969.532
2712.9	963.094
2715.58	950.657
2718.27	956.219
2720.95	976.448
2723.64	974.011
2726.32	983.573
2729	977.803
2731.68	971.365
2734.36	959.594
2737.04	972.49
2739.72	984.719
2742.39	981.615
2745.07	971.844
2747.74	1006.07
2750.42	977.636
2753.09	967.865
2755.76	979.428
2758.43	982.324
2761.1	1001.22
2763.77	974.782
2766.44	959.678
2769.11	989.24
2771.78	988.136
2774.44	991.699
2777.11	1001.26
2779.77	996.824
2782.43	987.053
2785.09	991.949
2787.76	972.845
2790.41	978.407
2793.07	1014.64
2795.73	1000.87
2798.39	991.762
2801.04	973.991
2803.7	986.22
2806.35	976.449
2809.01	966.012
2811.66	976.241
2814.31	967.137
2816.96	974.033
2819.61	991.595
2822.26	979.158
2824.91	987.387
2827.55	990.283
2830.2	976.512
2832.84	984.074
2835.49	990.97
2838.13	989.199
2840.77	1002.1
2843.41	981.658
2846.05	1009.89
2848.69	1000.12
2851.33	961.012
2853.97	956.574
2856.6	988.804
2859.24	1007.7
2861.87	986.595
2864.51	1023.49
2867.14	975.054
2869.77	1001.28
2872.4	979.512
2875.03	1002.41
2877.66	987.971
2880.29	1000.2
2882.92	1001.1
2885.54	1024.66
2888.17	1004.22
2890.79	1007.78
2893.42	1027.35
2896.04	1022.24
2898.66	1016.47
2901.28	1005.37
2903.9	1007.6
2906.52	1003.16
2909.14	1018.05
2911.76	996.283
2914.37	1013.18
2916.99	1017.41
2919.6	1003.64
2922.21	1019.2
2924.83	1000.76
2927.44	1020.33
2930.05	1026.55
2932.66	995.45
2935.27	1024.35
2937.88	1004.58
2940.48	1014.14
2943.09	1020.37
2945.69	1023.93
2948.3	987.492
2950.9	1012.39
2953.5	991.284
2956.1	1027.51
2958.7	993.742
2961.3	995.305
2963.9	990.867
2966.5	985.763
2969.1	1003.99
2971.69	982.888
2974.29	969.117
2976.88	981.346
2979.48	1001.58
2982.07	994.471
2984.66	977.367
2987.25	989.596
2989.84	997.826
2992.43	981.388
2995.02	994.951
2997.6	993.846
3000.19	1006.74
3002.77	965.638
3005.36	968.534
3007.94	966.097
3010.53	981.659
3013.11	951.888
3015.69	974.117
3018.27	977.013
3020.85	954.576
3023.42	976.138
3026	974.368
3028.58	977.93
3031.15	981.493
3033.73	974.388
3036.3	985.284
3038.87	939.514
3041.44	979.076
3044.01	965.305
3046.58	955.534
3047.87	987.316