File: muestras/manzana/mz_21.txt
#Acq. time (s)=	15
#Accumulations=	4
#Range (cm-¹)=	50...4000
#Windows=	3
#Autofocus=	Off
#AutoExposure=	Off
#Spike filter=	Multiple accum.
#Delay time (s)=	0
#Binning=	1
#Readout mode=	Signal
#DeNoise=	Off
#ICS correction=	Off
#Dark correction=	Off
#Inst. Process=	Off
#Instrument=	LabRAM HR Evol
#Detector=	Syncerity OE
#Objective=	x100_VIS
#Grating=	600 (500nm)
#ND Filter=	5%
#Laser=	532nm_Edge
#Hole=	100.021
#Range=	Visible
#Project=	Omar
#Sample=	120523
#Site=	ap
#Title=	mz
#Remark=	5 laser intensity
#Date=	12.05.2023 17:13
#Acquired=	12.05.2023 17:13:03
51.0297	20.6667
54.7185	31.7971
58.406	39.5943
62.0919	60.7248
65.7765	112.522
69.4595	153.652
73.1412	235.45
76.8214	280.58
80.5001	327.044
84.1774	369.508
87.8532	388.638
91.5276	413.769
95.2006	410.899
98.8721	413.363
102.54	407.827
106.209	421.624
109.876	436.088
113.542	425.218
117.204	439.015
120.867	443.479
124.526	439.276
128.186	439.74
131.845	434.871
135.5	446.001
139.155	452.465
142.807	452.929
146.46	446.059
150.11	446.523
153.757	460.987
157.406	458.784
161.051	443.248
164.697	462.378
168.339	452.842
171.98	463.973
175.619	461.103
179.259	456.233
182.895	464.697
186.53	467.828
190.164	475.625
193.796	484.755
197.427	451.886
201.059	468.35
204.686	478.147
208.313	476.611
211.938	476.408
215.562	474.205
219.184	468.669
222.803	475.133
226.422	463.596
230.04	467.394
233.657	473.857
237.272	474.988
240.886	484.118
244.497	476.582
248.108	478.379
251.717	480.843
255.325	472.64
258.93	481.104
262.535	473.568
266.137	487.365
269.74	485.162
273.341	486.959
276.939	476.756
280.537	474.554
284.132	493.017
287.728	484.815
291.32	471.945
294.911	485.076
298.502	498.206
302.09	486.67
305.677	501.134
309.264	499.597
312.848	492.061
316.43	489.192
320.011	497.656
323.593	489.453
327.171	497.916
330.748	504.38
334.323	484.844
337.897	499.975
341.47	484.438
345.041	499.569
348.611	502.699
352.18	499.83
355.747	498.294
359.312	492.757
362.877	514.555
366.44	491.018
369.999	508.149
373.56	509.946
377.119	507.743
380.676	507.54
384.23	504.671
387.785	496.468
391.338	495.598
394.888	518.062
398.439	505.859
401.988	502.323
405.534	514.787
409.081	491.918
412.624	502.381
416.167	512.845
419.708	513.976
423.249	521.773
426.786	508.237
430.323	518.034
433.86	503.164
437.393	518.295
440.926	505.425
444.458	514.556
447.988	512.353
451.516	518.15
455.043	524.614
458.568	531.078
462.092	527.541
465.615	515.339
469.138	518.469
472.658	540.266
476.177	522.063
479.694	536.527
483.21	528.991
486.723	519.455
490.236	541.919
493.748	522.382
497.258	535.513
500.768	525.31
504.276	520.44
507.78	528.904
511.285	539.368
514.789	529.832
518.289	530.296
521.791	528.093
525.29	546.557
528.787	531.687
532.284	526.818
535.778	547.281
539.272	539.079
542.763	527.542
546.255	540.006
549.743	554.47
553.232	550.934
556.718	550.064
560.203	547.862
563.688	554.325
567.169	544.789
570.65	548.586
574.129	536.383
577.609	542.847
581.085	553.311
584.56	556.442
588.034	552.905
591.506	546.036
594.978	553.833
598.447	556.297
601.916	533.427
605.383	538.558
608.849	551.688
612.313	534.152
615.776	570.616
619.238	553.746
622.699	545.544
626.156	554.007
629.614	561.804
633.071	572.935
636.526	574.732
639.978	573.863
643.431	571.66
646.88	560.123
650.33	571.254
653.779	570.384
657.224	560.182
660.67	573.312
664.113	576.443
667.556	577.573
670.997	568.703
674.435	569.167
677.875	574.298
681.311	559.428
684.746	559.225
688.182	576.356
691.614	563.486
695.045	581.284
698.475	585.747
701.904	561.545
705.333	568.675
708.759	569.139
712.183	567.603
715.606	588.733
719.028	590.53
722.449	590.327
725.868	586.125
729.286	571.255
732.703	592.385
736.117	590.849
739.531	587.98
742.944	587.777
746.355	592.241
749.766	576.705
753.173	591.168
756.581	585.632
759.987	576.096
763.39	591.893
766.794	595.024
770.195	580.154
773.596	578.618
776.994	585.748
780.393	601.546
783.788	584.676
787.185	594.473
790.578	592.27
793.971	569.401
797.362	598.531
800.751	600.995
804.138	604.792
807.527	602.589
810.912	605.053
814.296	596.184
817.679	577.314
821.06	601.778
824.441	598.908
827.822	601.372
831.199	615.169
834.576	610.967
837.951	602.097
841.323	611.228
844.695	599.025
848.066	605.488
851.436	625.952
854.805	608.416
858.173	621.547
861.539	614.677
864.902	637.808
868.266	624.938
871.628	632.735
874.987	633.199
878.347	623.663
881.704	628.127
885.061	613.257
888.418	601.054
891.771	620.185
895.122	611.315
898.475	607.779
901.824	617.576
905.174	614.04
908.52	608.504
911.866	614.968
915.212	616.765
918.555	623.895
921.896	615.026
925.237	620.823
928.576	625.953
931.914	621.75
935.253	623.548
938.588	626.011
941.922	615.809
945.255	634.272
948.587	645.403
951.917	631.867
955.244	637.664
958.572	659.461
961.899	669.925
965.225	673.722
968.549	665.519
971.872	639.316
975.192	647.113
978.512	640.911
981.831	630.041
985.148	638.505
988.464	666.302
991.778	646.099
995.092	658.563
998.404	671.027
1001.72	713.491
1005.02	740.621
1008.33	739.085
1011.64	734.882
1014.95	702.012
1018.25	675.81
1021.55	682.94
1024.85	672.737
1028.16	646.534
1031.46	648.331
1034.75	646.795
1038.05	649.259
1041.34	649.723
1044.64	653.52
1047.93	649.984
1051.22	637.114
1054.51	634.245
1057.8	644.709
1061.09	650.506
1064.38	647.636
1067.66	645.434
1070.95	651.897
1074.23	651.028
1077.51	652.825
1080.79	646.622
1084.07	639.086
1087.35	662.883
1090.62	650.013
1093.9	665.144
1097.17	642.274
1100.44	638.738
1103.71	651.202
1106.99	660.333
1110.25	647.463
1113.52	641.927
1116.79	667.057
1120.05	675.521
1123.31	650.652
1126.58	668.449
1129.84	679.579
1133.1	684.043
1136.36	695.174
1139.61	704.971
1142.87	732.768
1146.12	772.565
1149.38	789.029
1152.63	878.826
1155.88	988.623
1159.13	1025.75
1162.38	957.551
1165.63	820.681
1168.87	764.478
1172.12	726.276
1175.36	736.739
1178.6	740.536
1181.84	733
1185.08	774.797
1188.32	773.928
1191.56	785.725
1194.79	769.522
1198.03	737.986
1201.26	728.45
1204.49	730.247
1207.72	694.044
1210.95	710.508
1214.18	737.638
1217.41	714.769
1220.64	691.233
1223.86	665.697
1227.08	643.494
1230.3	667.291
1233.53	677.088
1236.75	657.552
1239.96	660.682
1243.18	639.146
1246.4	646.277
1249.61	641.407
1252.82	687.871
1256.04	662.335
1259.25	662.798
1262.46	674.596
1265.67	665.726
1268.87	680.19
1272.08	669.987
1275.28	658.451
1278.49	663.581
1281.69	678.712
1284.89	679.842
1288.09	664.64
1291.29	678.77
1294.49	672.567
1297.68	679.031
1300.88	672.161
1304.07	679.959
1307.26	665.756
1310.46	668.886
1313.65	679.35
1316.84	667.147
1320.02	674.278
1323.21	676.075
1326.39	661.205
1329.58	671.669
1332.76	659.466
1335.94	657.263
1339.12	656.394
1342.3	658.858
1345.48	658.655
1348.65	662.452
1351.83	666.916
1355	679.38
1358.18	659.177
1361.35	658.307
1364.52	646.771
1367.69	658.568
1370.86	661.699
1374.02	644.829
1377.19	646.626
1380.35	639.757
1383.52	668.887
1386.68	664.018
1389.84	643.148
1393	663.612
1396.16	649.409
1399.31	644.54
1402.47	666.337
1405.63	647.467
1408.78	673.931
1411.93	657.062
1415.08	690.859
1418.23	667.989
1421.38	658.453
1424.53	666.25
1427.68	676.047
1430.82	677.178
1433.96	677.642
1437.11	689.439
1440.25	665.236
1443.39	713.7
1446.53	703.497
1449.67	697.961
1452.8	691.758
1455.94	696.222
1459.07	690.685
1462.21	685.149
1465.34	672.946
1468.47	670.077
1471.6	687.874
1474.72	685.004
1477.85	679.468
1480.98	682.599
1484.1	701.729
1487.23	688.86
1490.35	703.324
1493.47	709.121
1496.59	706.918
1499.71	710.715
1502.83	741.845
1505.94	756.976
1509.06	789.44
1512.17	828.57
1515.29	909.701
1518.4	1004.83
1521.51	1089.3
1524.62	1153.76
1527.72	1156.22
1530.83	1101.35
1533.94	993.15
1537.04	878.947
1540.15	822.745
1543.25	764.542
1546.35	762.339
1549.45	738.136
1552.55	725.266
1555.65	694.397
1558.74	692.861
1561.84	677.325
1564.93	686.455
1568.02	674.252
1571.12	678.049
1574.2	664.513
1577.3	691.644
1580.38	687.441
1583.47	673.238
1586.56	659.035
1589.64	658.832
1592.72	677.963
1595.81	674.426
1598.89	659.557
1601.97	672.688
1605.05	674.485
1608.12	664.504
1611.2	666.647
1614.27	647.473
1617.35	644.417
1620.42	638.177
1623.5	656.214
1626.57	656.472
1629.63	663.63
1632.7	644.426
1635.77	651.528
1638.84	651.843
1641.9	652.523
1644.97	648.356
1648.03	649.187
1651.09	656.751
1654.15	640.685
1657.21	648.614
1660.27	663.065
1663.32	651.063
1666.38	659.662
1669.43	651.195
1672.49	640.298
1675.54	652.781
1678.59	663.854
1681.64	651.686
1684.69	646.069
1687.73	648.879
1690.78	659.422
1693.83	661.193
1696.87	650.535
1699.91	654.299
1702.96	629.681
1706	638.924
1709.04	630.135
1712.07	648.267
1715.11	643.93
1718.15	634.696
1721.18	644.435
1724.21	633.826
1727.25	633.535
1730.28	641.948
1733.31	636.852
1736.34	640.871
1739.37	639.671
1742.39	643.37
1745.42	622.699
1748.45	634.902
1751.47	636.485
1754.49	624.027
1757.51	625.868
1759.25	637.716
1762.28	616.924
1765.31	625.466
1768.34	632.008
1771.37	627.216
1774.4	627.758
1777.43	631.633
1780.46	654.175
1783.48	626.05
1786.51	635.258
1789.53	623.133
1792.55	641.008
1795.57	638.883
1798.59	635.425
1801.61	619.3
1804.63	613.842
1807.64	624.384
1810.66	630.259
1813.67	641.467
1816.68	634.009
1819.7	639.217
1822.71	636.426
1825.72	620.968
1828.72	634.843
1831.73	647.384
1834.74	611.926
1837.74	615.135
1840.75	619.676
1843.75	629.551
1846.75	629.426
1849.75	635.968
1852.75	616.51
1855.75	615.718
1858.75	620.927
1861.74	616.135
1864.74	626.677
1867.73	629.219
1870.72	619.76
1873.71	622.969
1876.7	632.844
1879.69	610.052
1882.68	633.261
1885.67	629.136
1888.66	628.344
1891.64	630.219
1894.62	626.094
1897.61	619.303
1900.59	632.511
1903.57	623.72
1906.55	652.928
1909.53	610.136
1912.5	626.012
1915.48	608.553
1918.46	629.095
1921.43	616.97
1924.4	628.845
1927.37	638.054
1930.34	623.929
1933.31	621.137
1936.28	640.346
1939.25	630.887
1942.22	612.762
1945.18	624.637
1948.14	617.846
1951.11	615.721
1954.07	618.929
1957.03	616.804
1959.99	610.679
1962.95	607.888
1965.91	597.096
1968.86	618.305
1971.82	629.513
1974.77	622.055
1977.73	636.597
1980.68	622.472
1983.63	627.68
1986.58	619.555
1989.53	621.43
1992.47	615.305
1995.42	608.514
1998.37	608.389
2001.31	612.93
2004.25	606.806
2007.2	623.347
2010.14	627.889
2013.08	599.097
2016.02	617.639
2018.96	616.181
2021.89	605.389
2024.83	619.264
2027.76	614.473
2030.7	626.348
2033.63	616.223
2036.56	599.431
2039.49	613.306
2042.42	607.848
2045.35	622.39
2048.28	608.932
2051.2	624.14
2054.13	612.682
2057.05	605.89
2059.97	604.432
2062.9	610.307
2065.82	614.182
2068.74	608.057
2071.65	607.266
2074.57	597.141
2077.49	611.682
2080.4	614.891
2083.32	604.099
2086.23	600.641
2089.15	604.516
2092.05	598.391
2094.97	594.266
2097.87	590.808
2100.78	593.35
2103.69	605.225
2106.6	619.767
2109.5	600.308
2112.4	588.183
2115.31	598.725
2118.21	595.267
2121.11	590.475
2124.01	597.684
2126.91	588.892
2129.8	581.434
2132.7	607.309
2135.59	587.184
2138.49	595.726
2141.38	585.601
2144.27	590.809
2147.16	590.684
2150.05	593.893
2152.94	581.101
2155.83	578.31
2158.72	590.851
2161.6	591.393
2164.49	594.602
2167.37	599.81
2170.26	599.018
2173.14	584.893
2176.02	614.102
2178.9	597.31
2181.77	585.852
2184.65	583.727
2187.53	577.602
2190.4	601.477
2193.28	596.019
2196.15	582.561
2199.02	593.102
2201.89	601.644
2204.76	588.186
2207.63	580.061
2210.5	581.269
2213.37	579.144
2216.23	559.02
2219.1	571.561
2221.96	572.103
2224.82	575.978
2227.69	575.853
2230.55	555.062
2233.41	565.603
2236.26	560.812
2239.12	564.02
2241.98	566.562
2244.83	547.77
2247.69	557.645
2250.54	559.52
2253.39	557.396
2256.24	571.937
2259.09	542.479
2261.94	557.687
2264.79	556.229
2267.64	562.771
2270.49	555.313
2273.33	546.521
2276.18	555.063
2279.02	554.271
2281.86	548.813
2284.7	556.688
2287.54	563.23
2290.38	565.105
2293.22	543.647
2296.05	562.855
2298.89	556.73
2301.72	570.605
2304.56	563.814
2307.39	570.355
2310.22	559.564
2313.05	551.439
2315.88	560.647
2318.71	561.856
2321.54	565.064
2324.36	561.606
2327.19	572.814
2330.01	568.689
2332.84	557.898
2335.66	562.439
2338.48	568.315
2341.3	555.523
2344.12	549.398
2346.94	555.273
2349.76	546.481
2352.57	555.69
2355.39	548.898
2358.2	537.44
2361.02	539.982
2363.83	559.19
2366.64	542.399
2369.45	554.274
2372.26	560.815
2375.07	531.357
2377.87	522.566
2380.68	529.774
2383.49	522.982
2386.29	537.524
2389.09	516.066
2391.9	531.941
2394.7	519.816
2397.5	525.691
2400.29	532.233
2403.09	532.775
2405.89	535.983
2408.69	521.858
2411.48	511.066
2414.28	532.275
2417.07	517.483
2419.86	540.692
2422.65	530.567
2425.44	528.442
2428.23	531.65
2431.02	539.525
2433.81	520.067
2436.59	524.609
2439.38	554.484
2442.16	532.359
2444.94	543.567
2447.73	518.776
2450.51	529.984
2453.29	541.193
2456.07	535.734
2458.84	528.276
2461.62	539.485
2464.4	540.026
2467.17	527.901
2469.95	539.776
2472.72	530.985
2475.49	534.86
2478.26	533.402
2481.03	529.277
2483.8	527.819
2486.57	527.027
2489.34	531.569
2492.1	537.444
2494.87	515.319
2497.63	532.527
2500.39	531.069
2503.16	538.277
2505.92	533.486
2508.68	525.361
2511.44	534.569
2514.19	535.111
2516.95	518.319
2519.71	519.528
2522.46	530.07
2525.22	515.278
2527.97	534.486
2530.72	534.361
2533.47	508.903
2536.22	516.112
2538.97	549.987
2541.72	515.195
2544.47	505.07
2547.21	509.612
2549.96	527.487
2552.7	503.362
2555.45	521.237
2558.19	527.112
2560.93	514.321
2563.67	514.862
2566.41	524.737
2569.15	509.279
2571.89	539.154
2574.62	512.363
2577.36	516.904
2580.09	525.446
2582.83	527.321
2585.56	523.196
2588.29	535.738
2591.02	530.28
2593.75	535.488
2596.48	520.697
2599.21	519.905
2601.93	514.447
2604.66	501.655
2607.39	524.197
2610.11	520.739
2612.83	511.947
2615.55	523.156
2618.27	526.364
2620.99	516.906
2623.71	528.781
2626.43	518.656
2629.15	503.864
2631.86	509.739
2634.58	532.281
2637.29	517.489
2640.01	532.031
2642.72	527.24
2645.43	520.448
2648.14	516.323
2650.85	517.532
2653.56	522.073
2656.26	527.948
2658.97	531.157
2661.68	521.699
2664.38	518.907
2667.09	521.449
2669.79	521.324
2672.49	520.532
2675.19	531.741
2677.89	527.616
2680.59	526.824
2683.29	518.699
2685.98	539.241
2688.68	517.116
2691.37	528.991
2694.07	516.199
2696.76	523.408
2699.45	501.283
2702.14	509.825
2704.83	519.033
2707.52	528.908
2710.21	511.45
2712.9	499.325
2715.58	499.867
2718.27	519.742
2720.95	521.617
2723.64	513.492
2726.32	512.7
2729	516.575
2731.68	510.451
2734.36	516.992
2737.04	495.534
2739.72	518.742
2742.39	506.617
2745.07	495.826
2747.74	506.368
2750.42	514.243
2753.09	504.118
2755.76	526.66
2758.43	506.535
2761.1	505.743
2763.77	510.951
2766.44	489.493
2769.11	510.035
2771.78	518.577
2774.44	485.118
2777.11	501.66
2779.77	506.869
2782.43	504.744
2785.09	481.285
2787.76	491.16
2790.41	495.036
2793.07	497.577
2795.73	506.119
2798.39	497.327
2801.04	519.203
2803.7	513.078
2806.35	504.286
2809.01	501.494
2811.66	498.703
2814.31	499.245
2816.96	507.12
2819.61	499.661
2822.26	500.87
2824.91	508.745
2827.55	484.62
2830.2	497.828
2832.84	499.703
2835.49	504.245
2838.13	497.454
2840.77	491.329
2843.41	501.87
2846.05	490.412
2848.69	506.287
2851.33	489.496
2853.97	518.037
2856.6	503.912
2859.24	483.788
2861.87	499.663
2864.51	500.204
2867.14	496.079
2869.77	507.288
2872.4	509.163
2875.03	496.371
2877.66	495.58
2880.29	506.121
2882.92	493.997
2885.54	503.205
2888.17	501.747
2890.79	512.289
2893.42	510.164
2896.04	499.372
2898.66	490.58
2901.28	501.789
2903.9	496.331
2906.52	496.872
2909.14	516.081
2911.76	510.622
2914.37	495.831
2916.99	485.706
2919.6	491.581
2922.21	488.789
2924.83	496.664
2927.44	497.206
2930.05	492.415
2932.66	506.29
2935.27	480.831
2937.88	496.04
2940.48	490.582
2943.09	487.123
2945.69	498.998
2948.3	490.874
2950.9	488.082
2953.5	493.957
2956.1	505.832
2958.7	472.374
2961.3	510.916
2963.9	504.124
2966.5	479.999
2969.1	485.207
2971.69	480.416
2974.29	495.624
2976.88	477.499
2979.48	474.708
2982.07	487.25
2984.66	477.125
2987.25	472.333
2989.84	475.541
2992.43	482.083
2995.02	477.958
2997.6	469.833
3000.19	479.708
3002.77	478.25
3005.36	466.125
3007.94	462
3010.53	469.875
3013.11	473.084
3015.69	474.959
3018.27	482.167
3020.85	466.709
3023.42	474.584
3026	469.126
3028.58	477.668
3031.15	476.876
3033.73	472.751
3036.3	477.293
3038.87	489.168
3041.44	480.376
3044.01	480.251
3046.58	466.126
3047.87	474.731