File: muestras/manzana/mz_26.txt
#Acq. time (s)=	15
#Accumulations=	4
#Range (cm-¹)=	50...4000
#Windows=	3
#Autofocus=	Off
#AutoExposure=	Off
#Spike filter=	Multiple accum.
#Delay time (s)=	0
#Binning=	1
#Readout mode=	Signal
#DeNoise=	Off
#ICS correction=	Off
#Dark correction=	Off
#Inst. Process=	Off
#Instrument=	LabRAM HR Evol
#Detector=	Syncerity OE
#Objective=	x100_VIS
#Grating=	600 (500nm)
#ND Filter=	5%
#Laser=	532nm_Edge
#Hole=	100.021
#Range=	Visible
#Project=	Omar
#Sample=	120523
#Site=	ap
#Title=	mz
#Remark=	5 laser intensity
#Date=	12.05.2023 17:17
#Acquired=	12.05.2023 17:17:49
51.0297	17.3333
54.7185	28.473
58.406	35.6128
62.0919	62.0858
65.7765	95.2255
69.4595	141.699
73.1412	210.838
76.8214	269.978
80.5001	307.118
84.1774	360.924
87.8532	414.73
91.5276	414.537
95.2006	397.677
98.8721	419.483
102.54	405.289
106.209	441.762
109.876	437.569
113.542	432.042
117.204	464.515
120.867	436.988
124.526	446.128
128.186	449.267
131.845	441.074
135.5	455.547
139.155	450.02
142.807	465.826
146.46	468.966
150.11	458.106
153.757	461.245
157.406	450.385
161.051	466.191
164.697	469.331
168.339	471.138
171.98	476.277
175.619	465.417
179.259	467.223
182.895	471.03
186.53	484.836
190.164	483.976
193.796	496.449
197.427	495.589
201.059	489.395
204.686	485.868
208.313	478.341
211.938	484.147
215.562	503.287
219.184	485.76
222.803	476.233
226.422	482.706
230.04	488.513
233.657	480.986
237.272	485.459
240.886	501.932
244.497	495.072
248.108	505.545
251.717	499.351
255.325	499.824
258.93	509.63
262.535	502.104
266.137	501.91
269.74	508.383
273.341	518.189
276.939	492.662
280.537	508.469
284.132	490.942
287.728	506.748
291.32	501.888
294.911	511.028
298.502	513.501
302.09	527.307
305.677	516.447
309.264	520.92
312.848	530.06
316.43	543.866
320.011	525.672
323.593	537.479
327.171	542.618
330.748	521.091
334.323	542.231
337.897	538.038
341.47	560.511
345.041	534.984
348.611	503.457
352.18	527.93
355.747	529.736
359.312	530.876
362.877	564.016
366.44	536.489
369.999	561.628
373.56	537.435
377.119	558.574
380.676	547.047
384.23	550.187
387.785	555.327
391.338	580.467
394.888	555.606
398.439	557.413
401.988	559.219
405.534	566.359
409.081	558.165
412.624	569.972
416.167	555.778
419.708	559.584
423.249	572.057
426.786	545.197
430.323	551.67
433.86	564.143
437.393	560.616
440.926	565.089
444.458	571.562
447.988	568.035
451.516	579.842
455.043	572.982
458.568	582.788
462.092	583.261
465.615	588.401
469.138	600.207
472.658	588.68
476.177	598.486
479.694	601.626
483.21	593.433
486.723	603.239
490.236	591.045
493.748	594.852
497.258	616.658
500.768	588.465
504.276	598.938
507.78	610.077
511.285	597.217
514.789	605.023
518.289	609.496
521.791	608.636
525.29	621.776
528.787	618.916
532.284	606.055
535.778	622.528
539.272	637.001
542.763	625.474
546.255	619.281
549.743	619.087
553.232	642.227
556.718	628.033
560.203	633.84
563.688	635.646
567.169	615.452
570.65	640.592
574.129	622.399
577.609	620.205
581.085	634.678
584.56	643.818
588.034	641.624
591.506	610.097
594.978	625.904
598.447	633.043
601.916	625.516
605.383	649.323
608.849	629.129
612.313	634.269
615.776	656.075
619.238	646.548
622.699	651.021
626.156	658.828
629.614	640.634
633.071	669.107
636.526	652.247
639.978	663.386
643.431	673.859
646.88	672.333
650.33	674.806
653.779	678.612
657.224	683.085
660.67	664.891
664.113	680.698
667.556	679.171
670.997	668.977
674.435	678.784
677.875	659.257
681.311	665.063
684.746	664.203
688.182	667.343
691.614	673.816
695.045	671.622
698.475	666.762
701.904	670.568
705.333	677.041
708.759	688.181
712.183	669.32
715.606	684.46
719.028	700.267
722.449	688.073
725.868	685.213
729.286	677.686
732.703	679.492
736.117	678.632
739.531	670.438
742.944	698.911
746.355	694.051
749.766	699.857
753.173	687.664
756.581	706.137
759.987	679.943
763.39	677.75
766.794	684.889
770.195	687.362
773.596	681.169
776.994	678.308
780.393	681.448
783.788	681.255
787.185	671.728
790.578	710.867
793.971	678.007
797.362	694.48
800.751	692.953
804.138	702.093
807.527	714.566
810.912	687.706
814.296	710.179
817.679	700.652
821.06	699.791
824.441	716.265
827.822	716.738
831.199	703.211
834.576	707.017
837.951	708.823
841.323	715.963
844.695	713.103
848.066	722.242
851.436	714.716
854.805	722.522
858.173	758.995
861.539	711.468
864.902	722.608
868.266	711.747
871.628	702.887
874.987	720.694
878.347	717.167
881.704	718.306
885.061	720.779
888.418	707.252
891.771	712.392
895.122	718.199
898.475	716.672
901.824	733.145
905.174	720.284
908.52	712.757
911.866	723.897
915.212	699.703
918.555	737.51
921.896	731.983
925.237	718.456
928.576	706.262
931.914	710.069
935.253	732.542
938.588	745.681
941.922	716.821
945.255	730.628
948.587	738.434
951.917	736.24
955.244	728.047
958.572	740.52
961.899	728.993
965.225	736.133
968.549	721.272
971.872	734.412
975.192	735.552
978.512	744.691
981.831	736.498
985.148	749.638
988.464	725.444
991.778	737.917
995.092	728.39
998.404	760.196
1001.72	734.003
1005.02	745.809
1008.33	749.616
1011.64	738.755
1014.95	737.228
1018.25	736.368
1021.55	743.508
1024.85	743.314
1028.16	761.787
1031.46	735.594
1034.75	750.733
1038.05	738.54
1041.34	745.679
1044.64	742.819
1047.93	745.292
1051.22	769.765
1054.51	779.571
1057.8	772.045
1061.09	773.184
1064.38	762.324
1067.66	770.13
1070.95	775.937
1074.23	766.41
1077.51	775.55
1080.79	780.023
1084.07	766.496
1087.35	781.635
1090.62	780.775
1093.9	755.248
1097.17	781.721
1100.44	762.861
1103.71	774.667
1106.99	763.14
1110.25	776.28
1113.52	760.086
1116.79	786.56
1120.05	743.699
1123.31	766.172
1126.58	762.645
1129.84	772.452
1133.1	760.925
1136.36	796.064
1139.61	767.871
1142.87	755.011
1146.12	763.484
1149.38	792.623
1152.63	775.763
1155.88	784.236
1159.13	794.042
1162.38	784.516
1165.63	766.989
1168.87	780.128
1172.12	769.935
1175.36	809.074
1178.6	814.214
1181.84	790.02
1185.08	797.16
1188.32	797.633
1191.56	798.773
1194.79	799.913
1198.03	815.719
1201.26	817.525
1204.49	799.332
1207.72	779.138
1210.95	829.611
1214.18	818.751
1217.41	799.224
1220.64	803.03
1223.86	787.503
1227.08	802.643
1230.3	800.45
1233.53	810.256
1236.75	794.729
1239.96	779.202
1243.18	807.675
1246.4	798.148
1249.61	807.954
1252.82	798.428
1256.04	800.901
1259.25	817.374
1262.46	817.847
1265.67	803.653
1268.87	802.126
1272.08	809.933
1275.28	797.072
1278.49	796.212
1281.69	796.018
1284.89	799.158
1288.09	826.631
1291.29	835.437
1294.49	816.577
1297.68	829.05
1300.88	816.19
1304.07	824.663
1307.26	837.803
1310.46	816.276
1313.65	814.749
1316.84	817.888
1320.02	827.028
1323.21	832.168
1326.39	825.974
1329.58	857.114
1332.76	826.254
1335.94	846.06
1339.12	837.867
1342.3	808.34
1345.48	830.813
1348.65	838.619
1351.83	820.425
1355	833.565
1358.18	822.705
1361.35	830.511
1364.52	828.318
1367.69	840.791
1370.86	820.597
1374.02	835.737
1377.19	846.21
1380.35	855.35
1383.52	833.156
1386.68	848.296
1389.84	851.435
1393	829.908
1396.16	833.715
1399.31	853.521
1402.47	837.328
1405.63	819.801
1408.78	846.94
1411.93	862.747
1415.08	849.22
1418.23	837.693
1421.38	846.833
1424.53	863.972
1427.68	847.112
1430.82	876.252
1433.96	854.725
1437.11	860.531
1440.25	853.671
1443.39	858.81
1446.53	866.617
1449.67	868.423
1452.8	858.896
1455.94	878.703
1459.07	856.509
1462.21	852.982
1465.34	851.455
1468.47	869.928
1471.6	851.068
1474.72	862.874
1477.85	857.347
1480.98	843.154
1484.1	852.294
1487.23	854.1
1490.35	854.573
1493.47	851.713
1496.59	829.519
1499.71	850.659
1502.83	873.798
1505.94	868.938
1509.06	871.411
1512.17	864.551
1515.29	857.024
1518.4	870.83
1521.51	885.303
1524.62	905.776
1527.72	909.583
1530.83	894.056
1533.94	869.196
1537.04	879.669
1540.15	886.808
1543.25	879.948
1546.35	883.088
1549.45	894.894
1552.55	884.701
1555.65	892.507
1558.74	892.313
1561.84	878.786
1564.93	890.593
1568.02	885.066
1571.12	923.539
1574.2	879.345
1577.3	887.152
1580.38	892.291
1583.47	882.764
1586.56	896.571
1589.64	883.044
1592.72	888.85
1595.81	907.323
1598.89	893.796
1601.97	888.269
1605.05	880.742
1608.12	873.096
1611.2	884.024
1614.27	879.133
1617.35	859.371
1620.42	872.749
1623.5	874.343
1626.57	882.167
1629.63	887.397
1632.7	876.777
1635.77	876.473
1638.84	876.716
1641.9	893.096
1644.97	883.217
1648.03	888.349
1651.09	891.794
1654.15	888.605
1657.21	888.809
1660.27	898.768
1663.32	899.984
1666.38	885.121
1669.43	908.937
1672.49	902.999
1675.54	889.431
1678.59	901.026
1681.64	909.414
1684.69	910.427
1687.73	907.451
1690.78	912.346
1693.83	909.793
1696.87	907.991
1699.91	896.129
1702.96	906.384
1706	904.68
1709.04	899.874
1712.07	900.118
1715.11	886.021
1718.15	879.801
1721.18	897.657
1724.21	895.688
1727.25	895.395
1730.28	899.287
1733.31	891.177
1736.34	901.645
1739.37	897.003
1742.39	897.363
1745.42	873.318
1748.45	895.69
1751.47	888.499
1754.49	900.419
1757.51	903.179
1759.25	885.803
1762.28	888.459
1765.31	882.448
1768.34	903.77
1771.37	879.093
1774.4	897.082
1777.43	909.071
1780.46	889.06
1783.48	902.382
1786.51	895.037
1789.53	891.026
1792.55	916.349
1795.57	905.004
1798.59	908.327
1801.61	910.316
1804.63	931.638
1807.64	903.627
1810.66	905.616
1813.67	904.358
1816.68	905.1
1819.7	905.841
1822.71	900.583
1825.72	899.992
1828.72	895.4
1831.73	898.809
1834.74	920.884
1837.74	908.292
1840.75	915.034
1843.75	933.109
1846.75	901.184
1849.75	915.259
1852.75	892.001
1855.75	912.076
1858.75	912.818
1861.74	898.893
1864.74	896.968
1867.73	905.71
1870.72	901.118
1873.71	901.193
1876.7	908.602
1879.69	903.344
1882.68	898.752
1885.67	897.494
1888.66	894.902
1891.64	905.644
1894.62	902.386
1897.61	915.794
1900.59	917.869
1903.57	916.611
1906.55	918.02
1909.53	920.761
1912.5	930.837
1915.48	908.912
1918.46	902.32
1921.43	921.062
1924.4	910.47
1927.37	921.879
1930.34	909.954
1933.31	910.696
1936.28	915.438
1939.25	915.513
1942.22	922.254
1945.18	892.996
1948.14	925.071
1951.11	912.48
1954.07	937.888
1957.03	899.963
1959.99	928.038
1962.95	923.447
1965.91	910.189
1968.86	900.264
1971.82	929.672
1974.77	922.414
1977.73	902.489
1980.68	921.231
1983.63	926.639
1986.58	932.048
1989.53	919.456
1992.47	894.865
1995.42	901.606
1998.37	892.348
2001.31	927.09
2004.25	905.165
2007.2	911.24
2010.14	925.982
2013.08	932.057
2016.02	932.132
2018.96	920.207
2021.89	902.949
2024.83	939.024
2027.76	903.766
2030.7	920.508
2033.63	919.25
2036.56	930.658
2039.49	941.4
2042.42	922.142
2045.35	922.217
2048.28	920.292
2051.2	916.367
2054.13	922.442
2057.05	919.184
2059.97	890.592
2062.9	932.001
2065.82	918.076
2068.74	916.151
2071.65	934.226
2074.57	925.635
2077.49	922.376
2080.4	915.785
2083.32	902.527
2086.23	921.268
2089.15	918.01
2092.05	922.085
2094.97	906.827
2097.87	916.902
2100.78	912.311
2103.69	895.052
2106.6	908.461
2109.5	914.536
2112.4	882.611
2115.31	908.019
2118.21	906.095
2121.11	884.17
2124.01	902.245
2126.91	895.653
2129.8	902.395
2132.7	890.47
2135.59	907.879
2138.49	909.287
2141.38	910.695
2144.27	899.437
2147.16	908.179
2150.05	911.588
2152.94	903.663
2155.83	895.071
2158.72	903.813
2161.6	895.221
2164.49	909.296
2167.37	914.705
2170.26	904.78
2173.14	920.855
2176.02	930.93
2178.9	927.005
2181.77	910.414
2184.65	916.489
2187.53	917.897
2190.4	901.972
2193.28	900.714
2196.15	920.123
2199.02	908.865
2201.89	922.273
2204.76	905.015
2207.63	887.756
2210.5	922.498
2213.37	898.573
2216.23	905.982
2219.1	900.724
2221.96	883.465
2224.82	875.541
2227.69	886.949
2230.55	878.357
2233.41	873.099
2236.26	883.174
2239.12	880.583
2241.98	865.325
2244.83	884.066
2247.69	872.808
2250.54	864.883
2253.39	861.625
2256.24	867.7
2259.09	863.775
2261.94	881.184
2264.79	866.592
2267.64	881.334
2270.49	883.409
2273.33	878.818
2276.18	872.226
2279.02	876.968
2281.86	874.376
2284.7	877.785
2287.54	882.526
2290.38	869.935
2293.22	870.677
2296.05	836.752
2298.89	872.16
2301.72	877.569
2304.56	878.977
2307.39	889.052
2310.22	883.127
2313.05	893.869
2315.88	877.278
2318.71	884.686
2321.54	884.094
2324.36	900.836
2327.19	892.911
2330.01	870.986
2332.84	879.062
2335.66	894.47
2338.48	901.878
2341.3	901.954
2344.12	874.695
2346.94	900.771
2349.76	887.512
2352.57	871.587
2355.39	877.662
2358.2	875.071
2361.02	870.479
2363.83	881.221
2366.64	881.963
2369.45	860.038
2372.26	890.113
2375.07	859.522
2377.87	886.93
2380.68	859.005
2383.49	858.414
2386.29	871.155
2389.09	867.231
2391.9	858.639
2394.7	875.381
2397.5	858.789
2400.29	832.864
2403.09	844.939
2405.89	879.681
2408.69	859.756
2411.48	868.498
2414.28	850.573
2417.07	865.982
2419.86	863.39
2422.65	876.799
2425.44	847.54
2428.23	872.949
2431.02	882.357
2433.81	849.766
2436.59	877.174
2439.38	865.916
2442.16	868.658
2444.94	866.066
2447.73	870.141
2450.51	864.216
2453.29	878.292
2456.07	852.367
2458.84	881.108
2461.62	888.517
2464.4	879.925
2467.17	870.667
2469.95	898.742
2472.72	896.151
2475.49	888.226
2478.26	898.968
2481.03	897.709
2483.8	886.451
2486.57	899.193
2489.34	882.601
2492.1	878.676
2494.87	866.085
2497.63	900.827
2500.39	877.568
2503.16	880.977
2505.92	882.385
2508.68	884.461
2511.44	885.202
2514.19	903.944
2516.95	875.352
2519.71	888.094
2522.46	888.836
2525.22	860.911
2527.97	870.32
2530.72	890.395
2533.47	849.137
2536.22	879.878
2538.97	882.62
2541.72	849.362
2544.47	880.104
2547.21	865.512
2549.96	869.587
2552.7	862.329
2555.45	889.737
2558.19	884.479
2560.93	881.221
2563.67	877.963
2566.41	876.038
2569.15	888.78
2571.89	871.521
2574.62	874.263
2577.36	859.672
2580.09	860.414
2582.83	895.155
2585.56	900.564
2588.29	885.972
2591.02	906.714
2593.75	881.456
2596.48	899.531
2599.21	893.606
2601.93	882.348
2604.66	895.089
2607.39	895.831
2610.11	900.573
2612.83	904.648
2615.55	897.39
2618.27	888.132
2620.99	894.874
2623.71	906.949
2626.43	912.357
2629.15	899.766
2631.86	898.507
2634.58	903.916
2637.29	891.991
2640.01	905.399
2642.72	910.808
2645.43	912.216
2648.14	903.625
2650.85	918.366
2653.56	909.775
2656.26	931.183
2658.97	917.925
2661.68	906.667
2664.38	908.075
2667.09	878.817
2669.79	892.226
2672.49	906.301
2675.19	894.376
2677.89	897.118
2680.59	882.526
2683.29	890.601
2685.98	898.676
2688.68	900.085
2691.37	898.16
2694.07	906.902
2696.76	912.31
2699.45	913.719
2702.14	905.794
2704.83	903.202
2707.52	880.611
2710.21	882.686
2712.9	892.761
2715.58	911.503
2718.27	892.911
2720.95	882.986
2723.64	917.061
2726.32	895.803
2729	900.545
2731.68	899.953
2734.36	904.028
2737.04	900.104
2739.72	896.179
2742.39	906.254
2745.07	903.662
2747.74	913.737
2750.42	897.146
2753.09	921.221
2755.76	936.629
2758.43	928.038
2761.1	920.78
2763.77	911.521
2766.44	932.93
2769.11	902.338
2771.78	931.08
2774.44	920.488
2777.11	923.897
2779.77	915.305
2782.43	929.38
2785.09	896.122
2787.76	924.864
2790.41	913.606
2793.07	937.014
2795.73	909.089
2798.39	917.164
2801.04	911.906
2803.7	899.315
2806.35	932.723
2809.01	922.798
2811.66	924.873
2814.31	925.615
2816.96	915.69
2819.61	939.099
2822.26	943.841
2824.91	933.916
2827.55	930.657
2830.2	926.733
2832.84	920.808
2835.49	925.549
2838.13	939.624
2840.77	934.366
2843.41	923.775
2846.05	906.517
2848.69	934.592
2851.33	952.667
2853.97	943.409
2856.6	954.15
2859.24	912.225
2861.87	928.301
2864.51	954.376
2867.14	934.451
2869.77	946.526
2872.4	944.601
2875.03	936.009
2877.66	950.085
2880.29	930.826
2882.92	953.568
2885.54	961.643
2888.17	957.052
2890.79	955.127
2893.42	963.202
2896.04	978.61
2898.66	963.352
2901.28	960.761
2903.9	966.169
2906.52	968.244
2909.14	976.319
2911.76	976.394
2914.37	980.47
2916.99	969.211
2919.6	971.641
2922.21	975.31
2924.83	954.593
2927.44	948.065
2930.05	956.212
2932.66	982.887
2935.27	968.941
2937.88	990.567
2940.48	970.879
2943.09	977.812
2945.69	981.169
2948.3	961.85
2950.9	976.498
2953.5	989.438
2956.1	962.377
2958.7	972.396
2961.3	952.302
2963.9	952.345
2966.5	946.053
2969.1	949.867
2971.69	955.429
2974.29	944.134
2976.88	961.972
2979.48	959.954
2982.07	945.909
2984.66	941.235
2987.25	943.936
2989.84	947.319
2992.43	941.87
2995.02	936.314
2997.6	943.516
3000.19	941.849
3002.77	920.45
3005.36	934.18
3007.94	942.223
3010.53	938.593
3013.11	935.841
3015.69	933.405
3018.27	938.837
3020.85	923.809
3023.42	929.689
3026	948.697
3028.58	938.244
3031.15	936.451
3033.73	939.411
3036.3	940.138
3038.87	921.526
3041.44	942.473
3044.01	933.586
3046.58	913.284
3048.04	918.75
3050.62	935.318
3053.2	953.887
3055.77	943.789
3058.35	914.357
3060.93	954.926
3063.51	927.494
3066.08	920.063
3068.66	901.298
3071.23	940.533
3073.8	941.102
3076.37	937.67
3078.94	930.905
3081.51	930.14
3084.08	918.709
3086.65	939.277
3089.22	929.179
3091.78	937.081
3094.35	928.983
3096.91	916.885
3099.48	910.12
3102.04	954.689
3104.6	929.924
3107.16	925.826
3109.72	950.394
3112.28	944.963
3114.84	924.198
3117.4	944.766
3119.96	926.002
3122.51	944.57
3125.07	928.472
3127.62	932.374
3130.18	942.942
3132.73	958.844
3135.28	942.079
3137.83	955.315
3140.38	945.883
3142.93	924.452
3145.47	950.353
3148.02	944.255
3150.57	939.49
3153.11	952.059
3155.66	950.628
3158.2	951.863
3160.74	931.098
3163.28	958.333
3165.83	944.235
3168.37	958.803
3170.91	944.039
3173.44	944.607
3175.98	968.509
3178.52	969.078
3181.05	956.313
3183.59	961.548
3186.12	946.116
3188.66	953.352
3191.19	965.92
3193.72	951.822
3196.25	953.724
3198.78	930.959
3201.31	943.528
3203.84	947.429
3206.36	949.998
3208.89	931.9
3211.41	927.135
3213.94	957.704
3216.46	953.605
3218.99	932.841
3221.51	925.409
3224.03	936.644
3226.55	937.88
3229.07	935.115
3231.59	927.017
3234.1	936.252
3236.62	938.154
3239.13	912.722
3241.65	931.291
3244.16	942.526
3246.68	927.094
3249.19	911.663
3251.7	921.565
3254.21	926.8
3256.72	972.035
3259.23	939.27
3261.74	941.172
3264.25	937.741
3266.75	918.309
3269.26	930.878
3271.76	939.446
3274.27	912.015
3276.77	944.583
3279.27	932.485
3281.77	925.054
3284.27	939.622
3286.77	941.524
3289.27	924.759
3291.77	934.661
3294.27	960.563
3296.76	942.465
3299.26	936.367
3301.75	950.268
3304.24	941.504
3306.74	936.739
3309.23	937.974
3311.72	935.209
3314.21	942.444
3316.7	928.346
3319.19	940.915
3321.68	934.15
3324.16	936.719
3326.65	915.954
3329.13	925.856
3331.62	930.424
3334.1	953.659
3336.58	933.561
3339.07	936.13
3341.55	901.365
3344.03	935.933
3346.51	926.502
3348.99	905.07
3351.46	936.306
3353.94	908.874
3356.42	917.443
3358.89	934.678
3361.36	921.246
3363.84	919.815
3366.31	899.05
3368.78	933.619
3371.25	892.854
3373.72	910.756
3376.19	931.991
3378.66	913.893
3381.13	898.461
3383.59	910.363
3386.06	927.598
3388.52	910.167
3390.99	896.069
3393.45	895.304
3395.91	911.872
3398.38	883.774
3400.84	921.676
3403.3	914.245
3405.76	898.813
3408.21	900.048
3410.67	897.95
3413.13	903.852
3415.58	941.754
3418.04	898.989
3420.49	895.558
3422.95	901.459
3425.4	908.695
3427.85	915.93
3430.3	926.498
3432.75	913.734
3435.2	905.635
3437.65	898.204
3440.1	910.772
3442.54	904.008
3444.99	921.909
3447.43	894.478
3449.88	907.047
3452.32	930.282
3454.76	904.184
3457.21	921.419
3459.65	907.987
3462.09	926.556
3464.53	885.791
3466.96	905.026
3469.4	883.595
3471.84	892.163
3474.27	906.065
3476.71	919.3
3479.14	899.869
3481.58	911.104
3484.01	907.672
3486.44	884.908
3488.87	896.81
3491.3	875.378
3493.73	893.28
3496.16	877.182
3498.59	880.417
3501.01	880.985
3503.44	852.887
3505.87	868.789
3508.29	854.691
3510.71	869.926
3513.14	867.161
3515.56	857.063
3517.98	834.298
3520.4	838.2
3522.82	853.435
3525.24	824.004
3527.66	838.573
3530.07	843.808
3532.49	835.043
3534.9	849.611
3537.32	834.18
3539.73	823.415
3542.15	837.984
3544.56	828.552
3546.97	819.787
3549.38	829.689
3551.79	821.591
3554.2	834.16
3556.61	830.061
3559.02	808.63
3561.42	851.199
3563.83	825.1
3566.23	817.669
3568.64	816.237
3571.04	808.806
3573.44	808.708
3575.84	801.276
3578.25	829.845
3580.65	825.08
3583.04	830.315
3585.44	810.884
3587.84	791.452
3590.24	830.687
3592.63	843.923
3595.03	805.158
3597.42	830.393
3599.82	820.295
3602.21	834.863
3604.6	808.099
3606.99	803.334
3609.38	821.236
3611.77	827.804
3614.16	823.706
3616.55	837.608
3618.94	811.51
3621.32	805.412
3623.71	798.647
3626.09	802.549
3628.48	819.784
3630.86	808.352
3633.24	794.254
3635.63	806.823
3638.01	804.058
3640.39	777.293
3642.77	779.862
3645.15	784.43
3647.52	775.665
3649.9	788.234
3652.28	794.136
3654.65	780.038
3657.03	775.939
3659.4	762.508
3661.77	777.743
3664.14	779.645
3666.52	774.214
3668.89	768.782
3671.25	764.017
3673.62	763.919
3675.99	771.821
3678.36	741.723
3680.73	748.958
3683.09	752.86
3685.46	764.095
3687.82	736.664
3690.19	757.232
3692.55	755.134
3694.91	709.702
3697.27	744.271
3699.63	733.506
3701.99	740.075
3704.35	755.977
3706.71	737.212
3709.06	744.447
3711.42	742.349
3713.78	748.917
3716.13	762.819
3718.48	735.388
3720.84	729.956
3723.19	738.525
3725.54	739.093
3727.89	760.995
3730.24	727.564
3732.59	741.465
3734.94	742.701
3737.29	752.603
3739.64	727.838
3741.98	751.073
3744.33	731.641
3746.67	754.877
3749.02	746.112
3751.36	732.014
3753.7	736.582
3756.04	747.817
3758.38	726.386
3760.72	754.954
3763.06	748.19
3765.4	736.758
3767.74	739.993
3770.08	743.229
3772.41	764.464
3774.75	740.366
3777.08	728.267
3779.41	733.503
3781.75	748.738
3784.08	727.306
3786.41	725.208
3788.74	735.777
3791.07	723.679
3793.4	729.58
3795.73	715.482
3798.06	716.717
3800.38	735.953
3802.71	714.521
3805.03	707.756
3807.36	710.325
3809.68	706.227
3812.01	700.795
3814.33	699.364
3816.65	693.932
3818.97	689.834
3821.29	705.069
3823.61	684.971
3825.93	696.206
3828.24	688.775
3830.56	684.01
3832.88	699.245
3835.19	697.814
3837.51	696.382
3839.82	693.617
3842.13	696.853
3844.45	703.421
3846.76	681.99
3849.07	701.892
3851.38	696.46
3853.69	717.029
3856	677.597
3858.3	680.166
3860.61	695.401
3862.92	686.636
3865.22	689.205
3867.53	682.44
3869.83	683.675
3872.13	690.243
3874.43	678.145
3876.74	700.714
3879.04	697.949
3881.34	687.851
3883.64	665.753
3885.93	700.321
3888.23	679.556
3890.53	675.458
3892.83	675.36
3895.12	673.929
3897.41	683.831
3899.71	689.732
3902	691.634
3904.29	698.203
3906.59	687.438
3908.88	697.34
3911.17	691.908
3913.46	691.144
3915.75	671.712
3918.03	682.947
3920.32	653.516
3922.61	692.084
3924.89	679.986
3927.18	667.221
3929.46	667.123
3931.74	667.025
3934.03	681.594
3936.31	663.495
3938.59	659.397
3940.87	665.966
3943.15	671.868
3945.43	668.436
3947.71	657.671
3949.98	656.24
3952.26	648.808
3954.54	669.377
3956.81	687.279
3959.09	653.847
3961.36	641.083
3963.63	665.651
3965.9	644.886
3968.18	648.121
3970.45	659.357
3972.72	641.258
3974.99	634.494
3977.25	652.395
3979.52	653.631
3981.79	658.866
3984.05	652.101
3986.32	636.003
3988.58	649.238
3990.85	658.473
3993.11	646.375
3995.37	646.944
3997.64	639.512
3999.9	631.414