File: muestras/manzana/mz_22.txt
#Acq. time (s)=	15
#Accumulations=	4
#Range (cm-¹)=	50...4000
#Windows=	3
#Autofocus=	Off
#AutoExposure=	Off
#Spike filter=	Multiple accum.
#Delay time (s)=	0
#Binning=	1
#Readout mode=	Signal
#DeNoise=	Off
#ICS correction=	Off
#Dark correction=	Off
#Inst. Process=	Off
#Instrument=	LabRAM HR Evol
#Detector=	Syncerity OE
#Objective=	x100_VIS
#Grating=	600 (500nm)
#ND Filter=	5%
#Laser=	532nm_Edge
#Hole=	100.021
#Range=	Visible
#Project=	Omar
#Sample=	120523
#Site=	ap
#Title=	mz
#Remark=	5 laser intensity
#Date=	12.05.2023 17:13
#Acquired=	12.05.2023 17:13:03
51.0297	20.6667
54.7185	31.7971
58.406	39.5943
62.0919	60.7248
65.7765	112.522
69.4595	153.652
73.1412	235.45
76.8214	280.58
80.5001	327.044
84.1774	369.508
87.8532	388.638
91.5276	413.769
95.2006	410.899
98.8721	413.363
102.54	407.827
106.209	421.624
109.876	436.088
113.542	425.218
117.204	439.015
120.867	443.479
124.526	439.276
128.186	439.74
131.845	434.871
135.5	446.001
139.155	452.465
142.807	452.929
146.46	446.059
150.11	446.523
153.757	460.987
157.406	458.784
161.051	443.248
164.697	462.378
168.339	452.842
171.98	463.973
175.619	461.103
179.259	456.233
182.895	464.697
186.53	467.828
190.164	475.625
193.796	484.755
197.427	451.886
201.059	468.35
204.686	478.147
208.313	476.611
211.938	476.408
215.562	474.205
219.184	468.669
222.803	475.133
226.422	463.596
230.04	467.394
233.657	473.857
237.272	474.988
240.886	484.118
244.497	476.582
248.108	478.379
251.717	480.843
255.325	472.64
258.93	481.104
262.535	473.568
266.137	487.365
269.74	485.162
273.341	486.959
276.939	476.756
280.537	474.554
284.132	493.017
287.728	484.815
291.32	471.945
294.911	485.076
298.502	498.206
302.09	486.67
305.677	501.134
309.264	499.597
312.848	492.061
316.43	489.192
320.011	497.656
323.593	489.453
327.171	497.916
330.748	504.38
334.323	484.844
337.897	499.975
341.47	484.438
345.041	499.569
348.611	502.699
352.18	499.83
355.747	498.294
359.312	492.757
362.877	514.555
366.44	491.018
369.999	508.149
373.56	509.946
377.119	507.743
380.676	507.54
384.23	504.671
387.785	496.468
391.338	495.598
394.888	518.062
398.439	505.859
401.988	502.323
405.534	514.787
409.081	491.918
412.624	502.381
416.167	512.845
419.708	513.976
423.249	521.773
426.786	508.237
430.323	518.034
433.86	503.164
437.393	518.295
440.926	505.425
444.458	514.556
447.988	512.353
451.516	518.15
455.043	524.614
458.568	531.078
462.092	527.541
465.615	515.339
469.138	518.469
472.658	540.266
476.177	522.063
479.694	536.527
483.21	528.991
486.723	519.455
490.236	541.919
493.748	522.382
497.258	535.513
500.768	525.31
504.276	520.44
507.78	528.904
511.285	539.368
514.789	529.832
518.289	530.296
521.791	528.093
525.29	546.557
528.787	531.687
532.284	526.818
535.778	547.281
539.272	539.079
542.763	527.542
546.255	540.006
549.743	554.47
553.232	550.934
556.718	550.064
560.203	547.862
563.688	554.325
567.169	544.789
570.65	548.586
574.129	536.383
577.609	542.847
581.085	553.311
584.56	556.442
588.034	552.905
591.506	546.036
594.978	553.833
598.447	556.297
601.916	533.427
605.383	538.558
608.849	551.688
612.313	534.152
615.776	570.616
619.238	553.746
622.699	545.544
626.156	554.007
629.614	561.804
633.071	572.935
636.526	574.732
639.978	573.863
643.431	571.66
646.88	560.123
650.33	571.254
653.779	570.384
657.224	560.182
660.67	573.312
664.113	576.443
667.556	577.573
670.997	568.703
674.435	569.167
677.875	574.298
681.311	559.428
684.746	559.225
688.182	576.356
691.614	563.486
695.045	581.284
698.475	585.747
701.904	561.545
705.333	568.675
708.759	569.139
712.183	567.603
715.606	588.733
719.028	590.53
722.449	590.327
725.868	586.125
729.286	571.255
732.703	592.385
736.117	590.849
739.531	587.98
742.944	587.777
746.355	592.241
749.766	576.705
753.173	591.168
756.581	585.632
759.987	576.096
763.39	591.893
766.794	595.024
770.195	580.154
773.596	578.618
776.994	585.748
780.393	601.546
783.788	584.676
787.185	594.473
790.578	592.27
793.971	569.401
797.362	598.531
800.751	600.995
804.138	604.792
807.527	602.589
810.912	605.053
814.296	596.184
817.679	577.314
821.06	601.778
824.441	598.908
827.822	601.372
831.199	615.169
834.576	610.967
837.951	602.097
841.323	611.228
844.695	599.025
848.066	605.488
851.436	625.952
854.805	608.416
858.173	621.547
861.539	614.677
864.902	637.808
868.266	624.938
871.628	632.735
874.987	633.199
878.347	623.663
881.704	628.127
885.061	613.257
888.418	601.054
891.771	620.185
895.122	611.315
898.475	607.779
901.824	617.576
905.174	614.04
908.52	608.504
911.866	614.968
915.212	616.765
918.555	623.895
921.896	615.026
925.237	620.823
928.576	625.953
931.914	621.75
935.253	623.548
938.588	626.011
941.922	615.809
945.255	634.272
948.587	645.403
951.917	631.867
955.244	637.664
958.572	659.461
961.899	669.925
965.225	673.722
968.549	665.519
971.872	639.316
975.192	647.113
978.512	640.911
981.831	630.041
985.148	638.505
988.464	666.302
991.778	646.099
995.092	658.563
998.404	671.027
1001.72	713.491
1005.02	740.621
1008.33	739.085
1011.64	734.882
1014.95	702.012
1018.25	675.81
1021.55	682.94
1024.85	672.737
1028.16	646.534
1031.46	648.331
1034.75	646.795
1038.05	649.259
1041.34	649.723
1044.64	653.52
1047.93	649.984
1051.22	637.114
1054.51	634.245
1057.8	644.709
1061.09	650.506
1064.38	647.636
1067.66	645.434
1070.95	651.897
1074.23	651.028
1077.51	652.825
1080.79	646.622
1084.07	639.086
1087.35	662.883
1090.62	650.013
1093.9	665.144
1097.17	642.274
1100.44	638.738
1103.71	651.202
1106.99	660.333
1110.25	647.463
1113.52	641.927
1116.79	667.057
1120.05	675.521
1123.31	650.652
1126.58	668.449
1129.84	679.579
1133.1	684.043
1136.36	695.174
1139.61	704.971
1142.87	732.768
1146.12	772.565
1149.38	789.029
1152.63	878.826
1155.88	988.623
1159.13	1025.75
1162.38	957.551
1165.63	820.681
1168.87	764.478
1172.12	726.276
1175.36	736.739
1178.6	740.536
1181.84	733
1185.08	774.797
1188.32	773.928
1191.56	785.725
1194.79	769.522
1198.03	737.986
1201.26	728.45
1204.49	730.247
1207.72	694.044
1210.95	710.508
1214.18	737.638
1217.41	714.769
1220.64	691.233
1223.86	665.697
1227.08	643.494
1230.3	667.291
1233.53	677.088
1236.75	657.552
1239.96	660.682
1243.18	639.146
1246.4	646.277
1249.61	641.407
1252.82	687.871
1256.04	662.335
1259.25	662.798
1262.46	674.596
1265.67	665.726
1268.87	680.19
1272.08	669.987
1275.28	658.451
1278.49	663.581
1281.69	678.712
1284.89	679.842
1288.09	664.64
1291.29	678.77
1294.49	672.567
1297.68	679.031
1300.88	672.161
1304.07	679.959
1307.26	665.756
1310.46	668.886
1313.65	679.35
1316.84	667.147
1320.02	674.278
1323.21	676.075
1326.39	661.205
1329.58	671.669
1332.76	659.466
1335.94	657.263
1339.12	656.394
1342.3	658.858
1345.48	658.655
1348.65	662.452
1351.83	666.916
1355	679.38
1358.18	659.177
1361.35	658.307
1364.52	646.771
1367.69	658.568
1370.86	661.699
1374.02	644.829
1377.19	646.626
1380.35	639.757
1383.52	668.887
1386.68	664.018
1389.84	643.148
1393	663.612
1396.16	649.409
1399.31	644.54
1402.47	666.337
1405.63	647.467
1408.78	673.931
1411.93	657.062
1415.08	690.859
1418.23	667.989
1421.38	658.453
1424.53	666.25
1427.68	676.047
1430.82	677.178
1433.96	677.642
1437.11	689.439
1440.25	665.236
1443.39	713.7
1446.53	703.497
1449.67	697.961
1452.8	691.758
1455.94	696.222
1459.07	690.685
1462.21	685.149
1465.34	672.946
1468.47	670.077
1471.6	687.874
1474.72	685.004
1477.85	679.468
1480.98	682.599
1484.1	701.729
1487.23	688.86
1490.35	703.324
1493.47	709.121
1496.59	706.918
1499.71	710.715
1502.83	741.845
1505.94	756.976
1509.06	789.44
1512.17	828.57
1515.29	909.701
1518.4	1004.83
1521.51	1089.3
1524.62	1153.76
1527.72	1156.22
1530.83	1101.35
1533.94	993.15
1537.04	878.947
1540.15	822.745
1543.25	764.542
1546.35	762.339
1549.45	738.136
1552.55	725.266
1555.65	694.397
1558.74	692.861
1561.84	677.325
1564.93	686.455
1568.02	674.252
1571.12	678.049
1574.2	664.513
1577.3	691.644
1580.38	687.441
1583.47	673.238
1586.56	659.035
1589.64	658.832
1592.72	677.963
1595.81	674.426
1598.89	659.557
1601.97	672.688
1605.05	674.485
1608.12	664.504
1611.2	666.647
1614.27	647.473
1617.35	644.417
1620.42	638.177
1623.5	656.214
1626.57	656.472
1629.63	663.63
1632.7	644.426
1635.77	651.528
1638.84	651.843
1641.9	652.523
1644.97	648.356
1648.03	649.187
1651.09	656.751
1654.15	640.685
1657.21	648.614
1660.27	663.065
1663.32	651.063
1666.38	659.662
1669.43	651.195
1672.49	640.298
1675.54	652.781
1678.59	663.854
1681.64	651.686
1684.69	646.069
1687.73	648.879
1690.78	659.422
1693.83	661.193
1696.87	650.535
1699.91	654.299
1702.96	629.681
1706	638.924
1709.04	630.135
1712.07	648.267
1715.11	643.93
1718.15	634.696
1721.18	644.435
1724.21	633.826
1727.25	633.535
1730.28	641.948
1733.31	636.852
1736.34	640.871
1739.37	639.671
1742.39	643.37
1745.42	622.699
1748.45	634.902
1751.47	636.485
1754.49	624.027
1757.51	625.868
1759.25	637.716
1762.28	616.924
1765.31	625.466
1768.34	632.008
1771.37	627.216
1774.4	627.758
1777.43	631.633
1780.46	654.175
1783.48	626.05
1786.51	635.258
1789.53	623.133
1792.55	641.008
1795.57	638.883
1798.59	635.425
1801.61	619.3
1804.63	613.842
1807.64	624.384
1810.66	630.259
1813.67	641.506
1816.68	634.087
1819.7	639.334
1822.71	636.581
1825.72	621.162
1828.72	635.076
1831.73	647.657
1834.74	612.237
1837.74	615.485
1840.75	620.065
1843.75	629.979
1846.75	629.893
1849.75	636.474
1852.75	617.054
1855.75	616.302
1858.75	621.549
1861.74	616.796
1864.74	627.377
1867.73	629.958
1870.72	620.538
1873.71	623.786
1876.7	633.7
1879.69	610.947
1882.68	634.194
1885.67	630.108
1888.66	629.355
1891.64	631.269
1894.62	627.183
1897.61	620.431
1900.59	633.678
1903.57	624.925
1906.55	654.172
1909.53	611.42
1912.5	627.334
1915.48	609.914
1918.46	630.495
1921.43	618.409
1924.4	630.323
1927.37	639.57
1930.34	625.484
1933.31	622.732
1936.28	641.979
1939.25	632.56
1942.22	614.473
1945.18	626.387
1948.14	619.635
1951.11	617.549
1954.07	620.796
1957.03	618.71
1959.99	612.624
1962.95	609.871
1965.91	599.119
1968.86	620.366
1971.82	631.613
1974.77	624.194
1977.73	638.774
1980.68	624.688
1983.63	629.936
1986.58	621.85
1989.53	623.764
1992.47	617.678
1995.42	610.925
1998.37	610.839
2001.31	615.419
2004.25	609.333
2007.2	625.914
2010.14	630.495
2013.08	601.742
2016.02	620.323
2018.96	618.903
2021.89	608.151
2024.83	622.065
2027.76	617.312
2030.7	629.226
2033.63	619.14
2036.56	602.387
2039.49	616.301
2042.42	610.882
2045.35	625.462
2048.28	612.043
2051.2	627.29
2054.13	615.871
2057.05	609.118
2059.97	607.699
2062.9	613.613
2065.82	617.527
2068.74	611.441
2071.65	610.688
2074.57	600.602
2077.49	615.183
2080.4	618.43
2083.32	607.677
2086.23	604.258
2089.15	608.172
2092.05	602.086
2094.97	598
2097.87	594.58
2100.78	597.161
2103.69	609.075
2106.6	623.656
2109.5	604.236
2112.4	592.15
2115.31	602.731
2118.21	599.312
2121.11	594.559
2124.01	601.806
2126.91	593.053
2129.8	585.634
2132.7	611.548
2135.59	591.462
2138.49	600.043
2141.38	589.957
2144.27	595.204
2147.16	595.118
2150.05	598.365
2152.94	585.612
2155.83	582.86
2158.72	595.44
2161.6	596.021
2164.49	599.268
2167.37	604.516
2170.26	603.763
2173.14	589.677
2176.02	618.924
2178.9	602.172
2181.77	590.752
2184.65	588.666
2187.53	582.58
2190.4	606.494
2193.28	601.075
2196.15	587.655
2199.02	598.236
2201.89	606.817
2204.76	593.397
2207.63	585.311
2210.5	586.558
2213.37	584.472
2216.23	564.386
2219.1	576.967
2221.96	577.548
2224.82	581.462
2227.69	581.376
2230.55	560.623
2233.41	571.204
2236.26	566.451
2239.12	569.698
2241.98	572.279
2244.83	553.526
2247.69	563.44
2250.54	565.354
2253.39	563.268
2256.24	577.849
2259.09	548.429
2261.94	563.677
2264.79	562.257
2267.64	568.838
2270.49	561.418
2273.33	552.666
2276.18	561.246
2279.02	560.494
2281.86	555.074
2284.7	562.988
2287.54	569.569
2290.38	571.483
2293.22	550.063
2296.05	569.311
2298.89	563.225
2301.72	577.139
2304.56	570.386
2307.39	576.967
2310.22	566.214
2313.05	558.128
2315.88	567.375
2318.71	568.623
2321.54	571.87
2324.36	568.45
2327.19	579.698
2330.01	575.612
2332.84	564.859
2335.66	569.44
2338.48	575.354
2341.3	562.601
2344.12	556.515
2346.94	562.429
2349.76	553.676
2352.57	562.924
2355.39	556.171
2358.2	544.751
2361.02	547.332
2363.83	566.579
2366.64	549.827
2369.45	561.741
2372.26	568.321
2375.07	538.902
2377.87	530.149
2380.68	537.396
2383.49	530.644
2386.29	545.224
2389.09	523.805
2391.9	539.719
2394.7	527.633
2397.5	533.547
2400.29	540.128
2403.09	540.708
2405.89	543.956
2408.69	529.87
2411.48	519.117
2414.28	540.364
2417.07	525.611
2419.86	548.859
2422.65	538.773
2425.44	536.687
2428.23	539.934
2431.02	547.848
2433.81	528.429
2436.59	533.009
2439.38	562.923
2442.16	540.837
2444.94	552.084
2447.73	527.332
2450.51	538.579
2453.29	549.826
2456.07	544.407
2458.84	536.988
2461.62	548.235
2464.4	548.815
2467.17	536.729
2469.95	548.643
2472.72	539.891
2475.49	543.805
2478.26	542.385
2481.03	538.299
2483.8	536.88
2486.57	536.127
2489.34	540.708
2492.1	546.622
2494.87	524.536
2497.63	541.783
2500.39	540.364
2503.16	547.611
2505.92	542.858
2508.68	534.772
2511.44	544.02
2514.19	544.6
2516.95	527.848
2519.71	529.095
2522.46	539.675
2525.22	524.923
2527.97	544.17
2530.72	544.084
2533.47	518.665
2536.22	525.912
2538.97	559.826
2541.72	525.073
2544.47	514.987
2547.21	519.568
2549.96	537.482
2552.7	513.396
2555.45	531.31
2558.19	537.224
2560.93	524.471
2563.67	525.052
2566.41	534.966
2569.15	519.546
2571.89	549.46
2574.62	522.708
2577.36	527.288
2580.09	535.869
2582.83	537.783
2585.56	533.697
2588.29	546.277
2591.02	540.858
2593.75	546.105
2596.48	531.353
2599.21	530.6
2601.93	525.181
2604.66	512.428
2607.39	535.008
2610.11	531.589
2612.83	522.836
2615.55	534.084
2618.27	537.331
2620.99	527.912
2623.71	539.826
2626.43	529.74
2629.15	514.987
2631.86	520.901
2634.58	543.481
2637.29	528.729
2640.01	543.309
2642.72	538.557
2645.43	531.804
2648.14	527.718
2650.85	528.965
2653.56	533.546
2656.26	539.46
2658.97	542.707
2661.68	533.288
2664.38	530.535
2667.09	533.116
2669.79	533.03
2672.49	532.277
2675.19	543.524
2677.89	539.438
2680.59	538.686
2683.29	530.6
2685.98	551.18
2688.68	529.094
2691.37	541.008
2694.07	528.255
2696.76	535.503
2699.45	513.417
2702.14	521.997
2704.83	531.245
2707.52	541.159
2710.21	523.739
2712.9	511.653
2715.58	512.234
2718.27	532.148
2720.95	534.062
2723.64	525.976
2726.32	525.223
2729	529.137
2731.68	523.051
2734.36	529.632
2737.04	508.212
2739.72	531.46
2742.39	519.373
2745.07	508.621
2747.74	519.201
2750.42	527.115
2753.09	517.029
2755.76	539.61
2758.43	519.524
2761.1	518.771
2763.77	524.019
2766.44	502.599
2769.11	523.18
2771.78	531.76
2774.44	498.341
2777.11	514.922
2779.77	520.169
2782.43	518.083
2785.09	494.664
2787.76	504.578
2790.41	508.492
2793.07	511.072
2795.73	519.653
2798.39	510.9
2801.04	532.814
2803.7	526.728
2806.35	517.975
2809.01	515.223
2811.66	512.47
2814.31	513.051
2816.96	520.965
2819.61	513.545
2822.26	514.793
2824.91	522.706
2827.55	498.62
2830.2	511.868
2832.84	513.782
2835.49	518.362
2838.13	511.61
2840.77	505.524
2843.41	516.104
2846.05	504.685
2848.69	520.599
2851.33	503.846
2853.97	532.427
2856.6	518.341
2859.24	498.255
2861.87	514.169
2864.51	514.749
2867.14	510.663
2869.77	521.911
2872.4	523.825
2875.03	511.072
2877.66	510.319
2880.29	520.9
2882.92	508.814
2885.54	518.061
2888.17	516.642
2890.79	527.222
2893.42	525.136
2896.04	514.384
2898.66	505.631
2901.28	516.878
2903.9	511.459
2906.52	512.039
2909.14	531.287
2911.76	525.867
2914.37	511.115
2916.99	501.029
2919.6	506.922
2922.21	504.263
2924.83	511.565
2927.44	512.358
2930.05	506.934
2932.66	521.3
2935.27	498.827
2937.88	511.14
2940.48	506.743
2943.09	502.868
2945.69	514.553
2948.3	508.322
2950.9	507.589
2953.5	508.958
2956.1	515.716
2958.7	493.057
2961.3	517.927
2963.9	514.027
2966.5	494.845
2969.1	500.856
2971.69	500.428
2974.29	499.438
2976.88	493.429
2979.48	491.502
2982.07	488.741
2984.66	498.068
2987.25	490.093
2989.84	490.286
2992.43	493.82
2995.02	497.798
2997.6	489.319
3000.19	504.282
3002.77	487.235
3005.36	486.83
3007.94	486.641
3010.53	497.105
3013.11	485.719
3015.69	494.537
3018.27	505.777
3020.85	490.228
3023.42	496.618
3026	501.332
3028.58	490.244
3031.15	482.363
3033.73	481.154
3036.3	497.297
3038.87	491.291
3041.44	489.002
3044.01	498.644
3046.58	501.791
3048.04	494.158
3050.62	492.809
3053.2	497.461
3055.77	476.113
3058.35	508.765
3060.93	488.083
3063.51	487.402
3066.08	485.387
3068.66	492.039
3071.23	478.024
3073.8	503.342
3076.37	480.661
3078.94	473.313
3081.51	467.298
3084.08	487.283
3086.65	484.601
3089.22	475.253
3091.78	485.905
3094.35	483.89
3096.91	475.209
3099.48	480.527
3102.04	501.846
3104.6	495.164
3107.16	494.483
3109.72	481.801
3112.28	497.12
3114.84	494.438
3117.4	491.757
3119.96	493.075
3122.51	486.394
3125.07	480.379
3127.62	468.364
3130.18	485.016
3132.73	491.667
3135.28	489.653
3137.83	478.971
3140.38	484.956
3142.93	498.275
3145.47	482.927
3148.02	486.245
3150.57	495.564
3153.11	495.549
3155.66	494.201
3158.2	481.519
3160.74	478.171
3163.28	475.489
3165.83	487.474
3168.37	492.126
3170.91	500.778
3173.44	486.097
3175.98	508.082
3178.52	482.734
3181.05	482.719
3183.59	489.37
3186.12	500.689
3188.66	493.341
3191.19	484.659
3193.72	483.978
3196.25	471.296
3198.78	487.281
3201.31	503.933
3203.84	480.585
3206.36	491.904
3208.89	477.889
3211.41	502.54
3213.94	489.192
3216.46	477.177
3218.99	484.496
3221.51	484.481
3224.03	485.133
3226.55	489.118
3229.07	475.77
3231.59	488.422
3234.1	479.074
3236.62	486.392
3239.13	480.377
3241.65	473.029
3244.16	469.014
3246.68	480.333
3249.19	478.984
3251.7	478.303
3254.21	481.621
3256.72	482.273
3259.23	465.592
3261.74	461.577
3264.25	455.562
3266.75	476.214
3269.26	478.199
3271.76	474.851
3274.27	468.836
3276.77	468.821
3279.27	479.473
3281.77	477.458
3284.27	473.443
3286.77	480.095
3289.27	478.747
3291.77	487.399
3294.27	472.051
3296.76	475.369
3299.26	482.021
3301.75	476.673
3304.24	473.991
3306.74	492.643
3309.23	471.961
3311.72	482.613
3314.21	475.265
3316.7	477.25
3319.19	483.902
3321.68	478.554
3324.16	475.872
3326.65	473.191
3329.13	487.176
3331.62	471.161
3334.1	483.813
3336.58	478.465
3339.07	466.45
3341.55	477.768
3344.03	465.087
3346.51	455.739
3348.99	457.724
3351.46	467.709
3353.94	471.027
3356.42	464.346
3358.89	462.331
3361.36	474.316
3363.84	477.635
3366.31	463.62
3368.78	441.605
3371.25	454.924
3373.72	475.575
3376.19	456.227
3378.66	456.879
3381.13	460.197
3383.59	456.849
3386.06	450.834
3388.52	471.486
3390.99	466.805
3393.45	453.457
3395.91	443.442
3398.38	465.427
3400.84	460.745
3403.3	451.397
3405.76	464.049
3408.21	450.701
3410.67	462.019
3413.13	460.671
3415.58	455.99
3418.04	460.641
3420.49	463.96
3422.95	465.945
3425.4	467.264
3427.85	447.915
3430.3	458.567
3432.75	447.219
3435.2	469.871
3437.65	442.523
3440.1	457.174
3442.54	467.826
3444.99	459.145
3447.43	463.797
3449.88	447.115
3452.32	439.767
3454.76	457.752
3457.21	458.404
3459.65	455.722
3462.09	456.374
3464.53	450.359
3466.96	446.344
3469.4	440.996
3471.84	459.648
3474.27	462.3
3476.71	466.285
3479.14	456.937
3481.58	456.255
3484.01	444.24
3486.44	462.892
3488.87	446.877
3491.3	435.529
3493.73	450.181
3496.16	450.166
3498.59	455.485
3501.01	434.137
3503.44	440.788
3505.87	442.773
3508.29	422.759
3510.71	445.41
3513.14	436.062
3515.56	432.714
3517.98	439.366
3520.4	423.351
3522.82	414.67
3525.24	418.655
3527.66	409.973
3530.07	408.625
3532.49	417.943
3534.9	413.262
3537.32	409.914
3539.73	385.899
3542.15	423.217
3544.56	410.536
3546.97	427.854
3549.38	407.173
3551.79	399.825
3554.2	415.143
3556.61	413.128
3559.02	401.78
3561.42	417.765
3563.83	399.084
3566.23	407.736
3568.64	420.387
3571.04	411.039
3573.44	419.691
3575.84	392.343
3578.25	418.328
3580.65	416.98
3583.04	384.965
3585.44	398.95
3587.84	409.602
3590.24	402.254
3592.63	397.572
3595.03	404.224
3597.42	411.543
3599.82	398.861
3602.21	396.18
3604.6	394.165
3606.99	400.15
3609.38	413.468
3611.77	404.787
3614.16	404.105
3616.55	398.757
3618.94	412.742
3621.32	406.061
3623.71	378.713
3626.09	395.364
3628.48	409.35
3630.86	406.668
3633.24	403.987
3635.63	399.972
3638.01	386.623
3640.39	383.275
3642.77	400.594
3645.15	382.579
3647.52	382.564
3649.9	377.883
3652.28	385.201
3654.65	386.52
3657.03	371.838
3659.4	389.823
3661.77	376.475
3664.14	381.793
3666.52	364.445
3668.89	367.764
3671.25	379.082
3673.62	367.067
3675.99	389.719
3678.36	366.371
3680.73	370.356
3683.09	369.675
3685.46	360.993
3687.82	352.312
3690.19	366.297
3692.55	363.615
3694.91	342.267
3697.27	366.252
3699.63	352.237
3701.99	375.556
3704.35	357.541
3706.71	356.193
3709.06	369.511
3711.42	359.496
3713.78	362.815
3716.13	364.133
3718.48	365.452
3720.84	371.437
3723.19	354.089
3725.54	358.741
3727.89	362.059
3730.24	356.711
3732.59	381.363
3734.94	375.348
3737.29	358
3739.64	359.318
3741.98	347.303
3744.33	368.622
3746.67	346.607
3749.02	357.926
3751.36	358.577
3753.7	379.896
3756.04	366.548
3758.38	362.533
3760.72	360.518
3763.06	373.17
3765.4	371.822
3767.74	364.473
3770.08	349.792
3772.41	368.444
3774.75	365.762
3777.08	359.081
3779.41	375.733
3781.75	347.718
3784.08	365.703
3786.41	356.355
3788.74	374.34
3791.07	348.992
3793.4	357.643
3795.73	362.962
3798.06	352.28
3800.38	352.932
3802.71	364.251
3805.03	344.236
3807.36	364.221
3809.68	349.54
3812.01	342.191
3814.33	351.51
3816.65	350.828
3818.97	357.48
3821.29	340.799
3823.61	330.784
3825.93	339.436
3828.24	350.754
3830.56	342.739
3832.88	356.058
3835.19	351.376
3837.51	349.361
3839.82	346.68
3842.13	348.665
3844.45	345.983
3846.76	339.302
3849.07	333.287
3851.38	352.606
3853.69	358.591
3856	337.909
3858.3	347.894
3860.61	333.213
3862.92	350.531
3865.22	345.183
3867.53	332.502
3869.83	327.82
3872.13	341.805
3874.43	352.457
3876.74	348.442
3879.04	340.427
3881.34	337.746
3883.64	340.398
3885.93	358.383
3888.23	340.368
3890.53	344.353
3892.83	341.005
3895.12	343.657
3897.41	339.642
3899.71	349.627
3902	341.612
3904.29	330.931
3906.59	342.916
3908.88	357.568
3911.17	335.553
3913.46	347.538
3915.75	352.856
3918.03	355.508
3920.32	344.827
3922.61	341.479
3924.89	351.464
3927.18	351.449
3929.46	348.101
3931.74	352.086
3934.03	351.404
3936.31	348.056
3938.59	343.375
3940.87	344.693
3943.15	334.678
3945.43	343.997
3947.71	337.982
3949.98	331.967
3952.26	335.952
3954.54	337.271
3956.81	330.589
3959.09	345.241
3961.36	339.893
3963.63	324.545
3965.9	339.863
3968.18	329.182
3970.45	323.167
3972.72	327.819
3974.99	333.137
3977.25	329.789
3979.52	335.107
3981.79	335.093
3984.05	333.078
3986.32	319.063
3988.58	316.381
3990.85	333.033
3993.11	329.018
3995.37	330.337
3997.64	325.655
3999.9	320.974