File: muestras/manzana/mz_36.txt
#Acq. time (s)=	15
#Accumulations=	4
#Range (cm-¹)=	50...4000
#Windows=	3
#Autofocus=	Off
#AutoExposure=	Off
#Spike filter=	Multiple accum.
#Delay time (s)=	0
#Binning=	1
#Readout mode=	Signal
#DeNoise=	Off
#ICS correction=	Off
#Dark correction=	Off
#Inst. Process=	Off
#Instrument=	LabRAM HR Evol
#Detector=	Syncerity OE
#Objective=	x100_VIS
#Grating=	600 (500nm)
#ND Filter=	5%
#Laser=	532nm_Edge
#Hole=	100.021
#Range=	Visible
#Project=	Omar
#Sample=	120523
#Site=	ap
#Title=	mz
#Remark=	5 laser intensity
#Date=	12.05.2023 17:33
#Acquired=	12.05.2023 17:33:01
51.0297	-486
54.7185	-486
58.406	-486
62.0919	-486
65.7765	-486
69.4595	-486
73.1412	-486
76.8214	-486
80.5001	-486
84.1774	-486
87.8532	-486
91.5276	-486
95.2006	-486
98.8721	-486
102.54	-486
106.209	-486
109.876	-486
113.542	-486
117.204	-486
120.867	-486
124.526	-486
128.186	-486
131.845	-486
135.5	-486
139.155	-486
142.807	-486
146.46	-486
150.11	-486
153.757	-486
157.406	-486
161.051	-486
164.697	-486
168.339	-486
171.98	-486
175.619	-486
179.259	-486
182.895	-486
186.53	-486
190.164	-486
193.796	-486
197.427	-486
201.059	-486
204.686	-486
208.313	-486
211.938	-486
215.562	-486
219.184	-486
222.803	-486
226.422	-486
230.04	-486
233.657	-486
237.272	-486
240.886	-486
244.497	-486
248.108	-486
251.717	-486
255.325	-486
258.93	-486
262.535	-486
266.137	-486
269.74	-486
273.341	-486
276.939	-486
280.537	-486
284.132	-486
287.728	-486
291.32	-486
294.911	-486
298.502	-486
302.09	-486
305.677	-486
309.264	-486
312.848	-486
316.43	-486
320.011	-486
323.593	-486
327.171	-486
330.748	-486
334.323	-486
337.897	-486
341.47	-486
345.041	-486
348.611	-486
352.18	-486
355.747	-486
359.312	-486
362.877	-486
366.44	-486
369.999	-486
373.56	-486
377.119	-486
380.676	-486
384.23	-486
387.785	-486
391.338	-486
394.888	-486
398.439	-486
401.988	-486
405.534	-486
409.081	-486
412.624	-486
416.167	-486
419.708	-486
423.249	-486
426.786	-486
430.323	-486
433.86	-486
437.393	-486
440.926	-486
444.458	-486
447.988	-486
451.516	-486
455.043	-486
458.568	-486
462.092	-486
465.615	-486
469.138	-486
472.658	-486
476.177	-486
479.694	-486
483.21	-486
486.723	-486
490.236	-486
493.748	-486
497.258	-486
500.768	-486
504.276	-486
507.78	-486
511.285	-486
514.789	-486
518.289	-486
521.791	-486
525.29	-486
528.787	-486
532.284	-486
535.778	-486
539.272	-486
542.763	-486
546.255	-486
549.743	-486
553.232	-486
556.718	-486
560.203	-486
563.688	-486
567.169	-486
570.65	-486
574.129	-486
577.609	-486
581.085	-486
584.56	-486
588.034	-486
591.506	-486
594.978	-486
598.447	-486
601.916	-486
605.383	-486
608.849	-486
612.313	-486
615.776	-486
619.238	-486
622.699	-486
626.156	-486
629.614	-486
633.071	-486
636.526	-486
639.978	-486
643.431	-486
646.88	-486
650.33	-486
653.779	-486
657.224	-486
660.67	-486
664.113	-486
667.556	-486
670.997	-486
674.435	-486
677.875	-486
681.311	-486
684.746	-486
688.182	-486
691.614	-486
695.045	-486
698.475	-486
701.904	-486
705.333	-486
708.759	-486
712.183	-486
715.606	-486
719.028	-486
722.449	-486
725.868	-486
729.286	-486
732.703	-486
736.117	-486
739.531	-486
742.944	-486
746.355	-486
749.766	-486
753.173	-486
756.581	-486
759.987	-486
763.39	-486
766.794	-486
770.195	-486
773.596	-486
776.994	-486
780.393	-486
783.788	-486
787.185	-486
790.578	-486
793.971	-486
797.362	-486
800.751	-486
804.138	-486
807.527	-486
810.912	-486
814.296	-486
817.679	-486
821.06	-486
824.441	-486
827.822	-486
831.199	-486
834.576	-486
837.951	-486
841.323	-486
844.695	-486
848.066	-486
851.436	-486
854.805	-486
858.173	-486
861.539	-486
864.902	-486
868.266	-486
871.628	-486
874.987	-486
878.347	-486
881.704	-486
885.061	-486
888.418	-486
891.771	-486
895.122	-486
898.475	-486
901.824	-486
905.174	-486
908.52	-486
911.866	-486
915.212	-486
918.555	-486
921.896	-486
925.237	-486
928.576	-486
931.914	-486
935.253	-486
938.588	-486
941.922	-486
945.255	-486
948.587	-486
951.917	-486
955.244	-486
958.572	-486
961.899	-486
965.225	-486
968.549	-486
971.872	-486
975.192	-486
978.512	-486
981.831	-486
985.148	-486
988.464	-486
991.778	-486
995.092	-486
998.404	-486
1001.72	-486
1005.02	-486
1008.33	-486
1011.64	-486
1014.95	-486
1018.25	-486
1021.55	-486
1024.85	-486
1028.16	-486
1031.46	-486
1034.75	-486
1038.05	-486
1041.34	-486
1044.64	-486
1047.93	-486
1051.22	-486
1054.51	-486
1057.8	-486
1061.09	-486
1064.38	-486
1067.66	-486
1070.95	-486
1074.23	-486
1077.51	-486
1080.79	-486
1084.07	-486
1087.35	-486
1090.62	-486
1093.9	-486
1097.17	-486
1100.44	-486
1103.71	-486
1106.99	-486
1110.25	-486
1113.52	-486
1116.79	-486
1120.05	-486
1123.31	-486
1126.58	-486
1129.84	-486
1133.1	-486
1136.36	-486
1139.61	-486
1142.87	-486
1146.12	-486
1149.38	-486
1152.63	-486
1155.88	-486
1159.13	-486
1162.38	-486
1165.63	-486
1168.87	-486
1172.12	-486
1175.36	-486
1178.6	-486
1181.84	-486
1185.08	-486
1188.32	-486
1191.56	-486
1194.79	-486
1198.03	-486
1201.26	-486
1204.49	-486
1207.72	-486
1210.95	-486
1214.18	-486
1217.41	-486
1220.64	-486
1223.86	-486
1227.08	-486
1230.3	-486
1233.53	-486
1236.75	-486
1239.96	-486
1243.18	-486
1246.4	-486
1249.61	-486
1252.82	-486
1256.04	-486
1259.25	-486
1262.46	-486
1265.67	-486
1268.87	-486
1272.08	-486
1275.28	-486
1278.49	-486
1281.69	-486
1284.89	-486
1288.09	-486
1291.29	-486
1294.49	-486
1297.68	-486
1300.88	-486
1304.07	-486
1307.26	-486
1310.46	-486
1313.65	-486
1316.84	-486
1320.02	-486
1323.21	-486
1326.39	-486
1329.58	-486
1332.76	-486
1335.94	-486
1339.12	-486
1342.3	-486
1345.48	-486
1348.65	-486
1351.83	-486
1355	-486
1358.18	-486
1361.35	-486
1364.52	-486
1367.69	-486
1370.86	-486
1374.02	-486
1377.19	-486
1380.35	-486
1383.52	-486
1386.68	-486
1389.84	-486
1393	-486
1396.16	-486
1399.31	-486
1402.47	-486
1405.63	-486
1408.78	-486
1411.93	-486
1415.08	-486
1418.23	-486
1421.38	-486
1424.53	-486
1427.68	-486
1430.82	-486
1433.96	-486
1437.11	-486
1440.25	-486
1443.39	-486
1446.53	-486
1449.67	-486
1452.8	-486
1455.94	-486
1459.07	-486
1462.21	-486
1465.34	-486
1468.47	-486
1471.6	-486
1474.72	-486
1477.85	-486
1480.98	-486
1484.1	-486
1487.23	-486
1490.35	-486
1493.47	-486
1496.59	-486
1499.71	-486
1502.83	-486
1505.94	-486
1509.06	-486
1512.17	-486
1515.29	-486
1518.4	-486
1521.51	-486
1524.62	-486
1527.72	-486
1530.83	-486
1533.94	-486
1537.04	-486
1540.15	-486
1543.25	-486
1546.35	-486
1549.45	-486
1552.55	-486
1555.65	-486
1558.74	-486
1561.84	-486
1564.93	-486
1568.02	-486
1571.12	-486
1574.2	-486
1577.3	-486
1580.38	-486
1583.47	-486
1586.56	-486
1589.64	-486
1592.72	-486
1595.81	-486
1598.89	-486
1601.97	-486
1605.05	-486
1608.12	-486
1611.2	-486
1614.27	-486
1617.35	-486
1620.42	-486
1623.5	-486
1626.57	-486
1629.63	-486
1632.7	-486
1635.77	-486
1638.84	-486
1641.9	-486
1644.97	-486
1648.03	-486
1651.09	-486
1654.15	-486
1657.21	-486
1660.27	-486
1663.32	-486
1666.38	-486
1669.43	-486
1672.49	-486
1675.54	-486
1678.59	-486
1681.64	-486
1684.69	-486
1687.73	-486
1690.78	-486
1693.83	-486
1696.87	-486
1699.91	-486
1702.96	-486
1706	-486
1709.04	-486
1712.07	-486
1715.11	-486
1718.15	-486
1721.18	-486
1724.21	-486
1727.25	-486
1730.28	-486
1733.31	-486
1736.34	-486
1739.37	-486
1742.39	-486
1745.42	-486
1748.45	-486
1751.47	-486
1754.49	-486
1757.51	-486
1759.25	-486
1762.28	-486
1765.31	-486
1768.34	-486
1771.37	-486
1774.4	-486
1777.43	-486
1780.46	-486
1783.48	-486
1786.51	-486
1789.53	-486
1792.55	-486
1795.57	-486
1798.59	-486
1801.61	-486
1804.63	-486
1807.64	-486
1810.66	-486
1813.67	-486
1816.68	-486
1819.7	-486
1822.71	-486
1825.72	-486
1828.72	-486
1831.73	-486
1834.74	-486
1837.74	-486
1840.75	-486
1843.75	-486
1846.75	-486
1849.75	-486
1852.75	-486
1855.75	-486
1858.75	-486
1861.74	-486
1864.74	-486
1867.73	-486
1870.72	-486
1873.71	-486
1876.7	-486
1879.69	-486
1882.68	-486
1885.67	-486
1888.66	-486
1891.64	-486
1894.62	-486
1897.61	-486
1900.59	-486
1903.57	-486
1906.55	-486
1909.53	-486
1912.5	-486
1915.48	-486
1918.46	-486
1921.43	-486
1924.4	-486
1927.37	-486
1930.34	-486
1933.31	-486
1936.28	-486
1939.25	-486
1942.22	-486
1945.18	-486
1948.14	-486
1951.11	-486
1954.07	-486
1957.03	-486
1959.99	-486
1962.95	-486
1965.91	-486
1968.86	-486
1971.82	-486
1974.77	-486
1977.73	-486
1980.68	-486
1983.63	-486
1986.58	-486
1989.53	-486
1992.47	-486
1995.42	-486
1998.37	-486
2001.31	-486
2004.25	-486
2007.2	-486
2010.14	-486
2013.08	-486
2016.02	-486
2018.96	-486
2021.89	-486
2024.83	-486
2027.76	-486
2030.7	-486
2033.63	-486
2036.56	-486
2039.49	-486
2042.42	-486
2045.35	-486
2048.28	-486
2051.2	-486
2054.13	-486
2057.05	-486
2059.97	-486
2062.9	-486
2065.82	-486
2068.74	-486
2071.65	-486
2074.57	-486
2077.49	-486
2080.4	-486
2083.32	-486
2086.23	-486
2089.15	-486
2092.05	-486
2094.97	-486
2097.87	-486
2100.78	-486
2103.69	-486
2106.6	-486
2109.5	-486
2112.4	-486
2115.31	-486
2118.21	-486
2121.11	-486
2124.01	-486
2126.91	-486
2129.8	-486
2132.7	-486
2135.59	-486
2138.49	-486
2141.38	-486
2144.27	-486
2147.16	-486
2150.05	-486
2152.94	-486
2155.83	-486
2158.72	-486
2161.6	-486
2164.49	-486
2167.37	-486
2170.26	-486
2173.14	-486
2176.02	-486
2178.9	-486
2181.77	-486
2184.65	-486
2187.53	-486
2190.4	-486
2193.28	-486
2196.15	-486
2199.02	-486
2201.89	-486
2204.76	-486
2207.63	-486
2210.5	-486
2213.37	-486
2216.23	-486
2219.1	-486
2221.96	-486
2224.82	-486
2227.69	-486
2230.55	-486
2233.41	-486
2236.26	-486
2239.12	-486
2241.98	-486
2244.83	-486
2247.69	-486
2250.54	-486
2253.39	-486
2256.24	-486
2259.09	-486
2261.94	-486
2264.79	-486
2267.64	-486
2270.49	-486
2273.33	-486
2276.18	-486
2279.02	-486
2281.86	-486
2284.7	-486
2287.54	-486
2290.38	-486
2293.22	-486
2296.05	-486
2298.89	-486
2301.72	-486
2304.56	-486
2307.39	-486
2310.22	-486
2313.05	-486
2315.88	-486
2318.71	-486
2321.54	-486
2324.36	-486
2327.19	-486
2330.01	-486
2332.84	-486
2335.66	-486
2338.48	-486
2341.3	-486
2344.12	-486
2346.94	-486
2349.76	-486
2352.57	-486
2355.39	-486
2358.2	-486
2361.02	-486
2363.83	-486
2366.64	-486
2369.45	-486
2372.26	-486
2375.07	-486
2377.87	-486
2380.68	-486
2383.49	-486
2386.29	-486
2389.09	-486
2391.9	-486
2394.7	-486
2397.5	-486
2400.29	-486
2403.09	-486
2405.89	-486
2408.69	-486
2411.48	-486
2414.28	-486
2417.07	-486
2419.86	-486
2422.65	-486
2425.44	-486
2428.23	-486
2431.02	-486
2433.81	-486
2436.59	-486
2439.38	-486
2442.16	-486
2444.94	-486
2447.73	-486
2450.51	-486
2453.29	-486
2456.07	-486
2458.84	-486
2461.62	-486
2464.4	-486
2467.17	-486
2469.95	-486
2472.72	-486
2475.49	-486
2478.26	-486
2481.03	-486
2483.8	-486
2486.57	-486
2489.34	-486
2492.1	-486
2494.87	-486
2497.63	-486
2500.39	-486
2503.16	-486
2505.92	-486
2508.68	-486
2511.44	-486
2514.19	-486
2516.95	-486
2519.71	-486
2522.46	-486
2525.22	-486
2527.97	-486
2530.72	-486
2533.47	-486
2536.22	-486
2538.97	-486
2541.72	-486
2544.47	-486
2547.21	-486
2549.96	-486
2552.7	-486
2555.45	-486
2558.19	-486
2560.93	-486
2563.67	-486
2566.41	-486
2569.15	-486
2571.89	-486
2574.62	-486
2577.36	-486
2580.09	-486
2582.83	-486
2585.56	-486
2588.29	-486
2591.02	-486
2593.75	-486
2596.48	-486
2599.21	-486
2601.93	-486
2604.66	-486
2607.39	-486
2610.11	-486
2612.83	-486
2615.55	-486
2618.27	-486
2620.99	-486
2623.71	-486
2626.43	-486
2629.15	-486
2631.86	-486
2634.58	-486
2637.29	-486
2640.01	-486
2642.72	-486
2645.43	-486
2648.14	-486
2650.85	-486
2653.56	-486
2656.26	-486
2658.97	-486
2661.68	-486
2664.38	-486
2667.09	-486
2669.79	-486
2672.49	-486
2675.19	-486
2677.89	-486
2680.59	-486
2683.29	-486
2685.98	-486
2688.68	-486
2691.37	-486
2694.07	-486
2696.76	-486
2699.45	-486
2702.14	-486
2704.83	-486
2707.52	-486
2710.21	-486
2712.9	-486
2715.58	-486
2718.27	-486
2720.95	-486
2723.64	-486
2726.32	-486
2729	-486
2731.68	-486
2734.36	-486
2737.04	-486
2739.72	-486
2742.39	-486
2745.07	-486
2747.74	-486
2750.42	-486
2753.09	-486
2755.76	-486
2758.43	-486
2761.1	-486
2763.77	-486
2766.44	-486
2769.11	-486
2771.78	-486
2774.44	-486
2777.11	-486
2779.77	-486
2782.43	-486
2785.09	-486
2787.76	-486
2790.41	-486
2793.07	-486
2795.73	-486
2798.39	-486
2801.04	-486
2803.7	-486
2806.35	-486
2809.01	-486
2811.66	-486
2814.31	-486
2816.96	-486
2819.61	-486
2822.26	-486
2824.91	-486
2827.55	-486
2830.2	-486
2832.84	-486
2835.49	-486
2838.13	-486
2840.77	-486
2843.41	-486
2846.05	-486
2848.69	-486
2851.33	-486
2853.97	-486
2856.6	-486
2859.24	-486
2861.87	-486
2864.51	-486
2867.14	-486
2869.77	-486
2872.4	-486
2875.03	-486
2877.66	-486
2880.29	-486
2882.92	-486
2885.54	-486
2888.17	-486
2890.79	-486
2893.42	-486
2896.04	-486
2898.66	-486
2901.28	-486
2903.9	-486
2906.52	-486
2909.14	-486
2911.76	-486
2914.37	-486
2916.99	-486
2919.6	-486
2922.21	-486
2924.83	-486
2927.44	-486
2930.05	-486
2932.66	-486
2935.27	-486
2937.88	-486
2940.48	-486
2943.09	-486
2945.69	-486
2948.3	-486
2950.9	-486
2953.5	-486
2956.1	-486
2958.7	-486
2961.3	-486
2963.9	-486
2966.5	-486
2969.1	-486
2971.69	-486
2974.29	-486
2976.88	-486
2979.48	-486
2982.07	-486
2984.66	-486
2987.25	-486
2989.84	-486
2992.43	-486
2995.02	-486
2997.6	-486
3000.19	-486
3002.77	-486
3005.36	-486
3007.94	-486
3010.53	-486
3013.11	-486
3015.69	-486
3018.27	-486
3020.85	-486
3023.42	-486
3026	-486
3028.58	-486
3031.15	-486
3033.73	-486
3036.3	-486
3038.87	-486
3041.44	-486
3044.01	-486
3046.58	-486
3048.04	-486
3050.62	-486
3053.2	-486
3055.77	-486
3058.35	-486
3060.93	-486
3063.51	-486
3066.08	-486
3068.66	-486
3071.23	-486
3073.8	-486
3076.37	-486
3078.94	-486
3081.51	-486
3084.08	-486
3086.65	-486
3089.22	-486
3091.78	-486
3094.35	-486
3096.91	-486
3099.48	-486
3102.04	-486
3104.6	-486
3107.16	-486
3109.72	-486
3112.28	-486
3114.84	-486
3117.4	-486
3119.96	-486
3122.51	-486
3125.07	-486
3127.62	-486
3130.18	-486
3132.73	-486
3135.28	-486
3137.83	-486
3140.38	-486
3142.93	-486
3145.47	-486
3148.02	-486
3150.57	-486
3153.11	-486
3155.66	-486
3158.2	-486
3160.74	-486
3163.28	-486
3165.83	-486
3168.37	-486
3170.91	-486
3173.44	-486
3175.98	-486
3178.52	-486
3181.05	-486
3183.59	-486
3186.12	-486
3188.66	-486
3191.19	-486
3193.72	-486
3196.25	-486
3198.78	-486
3201.31	-486
3203.84	-486
3206.36	-486
3208.89	-486
3211.41	-486
3213.94	-486
3216.46	-486
3218.99	-486
3221.51	-486
3224.03	-486
3226.55	-486
3229.07	-486
3231.59	-486
3234.1	-486
3236.62	-486
3239.13	-486
3241.65	-486
3244.16	-486
3246.68	-486
3249.19	-486
3251.7	-486
3254.21	-486
3256.72	-486
3259.23	-486
3261.74	-486
3264.25	-486
3266.75	-486
3269.26	-486
3271.76	-486
3274.27	-486
3276.77	-486
3279.27	-486
3281.77	-486
3284.27	-486
3286.77	-486
3289.27	-486
3291.77	-486
3294.27	-486
3296.76	-486
3299.26	-486
3301.75	-486
3304.24	-486
3306.74	-486
3309.23	-486
3311.72	-486
3314.21	-486
3316.7	-486
3319.19	-486
3321.68	-486
3324.16	-486
3326.65	-486
3329.13	-486
3331.62	-486
3334.1	-486
3336.58	-486
3339.07	-486
3341.55	-486
3344.03	-486
3346.51	-486
3348.99	-486
3351.46	-486
3353.94	-486
3356.42	-486
3358.89	-486
3361.36	-486
3363.84	-486
3366.31	-486
3368.78	-486
3371.25	-486
3373.72	-486
3376.19	-486
3378.66	-486
3381.13	-486
3383.59	-486
3386.06	-486
3388.52	-486
3390.99	-486
3393.45	-486
3395.91	-486
3398.38	-486
3400.84	-486
3403.3	-486
3405.76	-486
3408.21	-486
3410.67	-486
3413.13	-486
3415.58	-486
3418.04	-486
3420.49	-486
3422.95	-486
3425.4	-486
3427.85	-486
3430.3	-486
3432.75	-486
3435.2	-486
3437.65	-486
3440.1	-486
3442.54	-486
3444.99	-486
3447.43	-486
3449.88	-486
3452.32	-486
3454.76	-486
3457.21	-486
3459.65	-486
3462.09	-486
3464.53	-486
3466.96	-486
3469.4	-486
3471.84	-486
3474.27	-486
3476.71	-486
3479.14	-486
3481.58	-486
3484.01	-486
3486.44	-486
3488.87	-486
3491.3	-486
3493.73	-486
3496.16	-486
3498.59	-486
3501.01	-486
3503.44	-486
3505.87	-486
3508.29	-486
3510.71	-486
3513.14	-486
3515.56	-486
3517.98	-486
3520.4	-486
3522.82	-486
3525.24	-486
3527.66	-486
3530.07	-486
3532.49	-486
3534.9	-486
3537.32	-486
3539.73	-486
3542.15	-486
3544.56	-486
3546.97	-486
3549.38	-486
3551.79	-486
3554.2	-486
3556.61	-486
3559.02	-486
3561.42	-486
3563.83	-486
3566.23	-486
3568.64	-486
3571.04	-486
3573.44	-486
3575.84	-486
3578.25	-486
3580.65	-486
3583.04	-486
3585.44	-486
3587.84	-486
3590.24	-486
3592.63	-486
3595.03	-486
3597.42	-486
3599.82	-486
3602.21	-486
3604.6	-486
3606.99	-486
3609.38	-486
3611.77	-486
3614.16	-486
3616.55	-486
3618.94	-486
3621.32	-486
3623.71	-486
3626.09	-486
3628.48	-486
3630.86	-486
3633.24	-486
3635.63	-486
3638.01	-486
3640.39	-486
3642.77	-486
3645.15	-486
3647.52	-486
3649.9	-486
3652.28	-486
3654.65	-486
3657.03	-486
3659.4	-486
3661.77	-486
3664.14	-486
3666.52	-486
3668.89	-486
3671.25	-486
3673.62	-486
3675.99	-486
3678.36	-486
3680.73	-486
3683.09	-486
3685.46	-486
3687.82	-486
3690.19	-486
3692.55	-486
3694.91	-486
3697.27	-486
3699.63	-486
3701.99	-486
3704.35	-486
3706.71	-486
3709.06	-486
3711.42	-486
3713.78	-486
3716.13	-486
3718.48	-486
3720.84	-486
3723.19	-486
3725.54	-486
3727.89	-486
3730.24	-486
3732.59	-486
3734.94	-486
3737.29	-486
3739.64	-486
3741.98	-486
3744.33	-486
3746.67	-486
3749.02	-486
3751.36	-486
3753.7	-486
3756.04	-486
3758.38	-486
3760.72	-486
3763.06	-486
3765.4	-486
3767.74	-486
3770.08	-486
3772.41	-486
3774.75	-486
3777.08	-486
3779.41	-486
3781.75	-486
3784.08	-486
3786.41	-486
3788.74	-486
3791.07	-486
3793.4	-486
3795.73	-486
3798.06	-486
3800.38	-486
3802.71	-486
3805.03	-486
3807.36	-486
3809.68	-486
3812.01	-486
3814.33	-486
3816.65	-486
3818.97	-486
3821.29	-486
3823.61	-486
3825.93	-486
3828.24	-486
3830.56	-486
3832.88	-486
3835.19	-486
3837.51	-486
3839.82	-486
3842.13	-486
3844.45	-486
3846.76	-486
3849.07	-486
3851.38	-486
3853.69	-486
3856	-486
3858.3	-486
3860.61	-486
3862.92	-486
3865.22	-486
3867.53	-486
3869.83	-486
3872.13	-486
3874.43	-486
3876.74	-486
3879.04	-486
3881.34	-486
3883.64	-486
3885.93	-486
3888.23	-486
3890.53	-486
3892.83	-486
3895.12	-486
3897.41	-486
3899.71	-486
3902	-486
3904.29	-486
3906.59	-486
3908.88	-486
3911.17	-486
3913.46	-486
3915.75	-486
3918.03	-486
3920.32	-486
3922.61	-486
3924.89	-486
3927.18	-486
3929.46	-486
3931.74	-486
3934.03	-486
3936.31	-486
3938.59	-486
3940.87	-486
3943.15	-486
3945.43	-486
3947.71	-486
3949.98	-486
3952.26	-486
3954.54	-486
3956.81	-486
3959.09	-486
3961.36	-486
3963.63	-486
3965.9	-486
3968.18	-486
3970.45	-486
3972.72	-486
3974.99	-486
3977.25	-486
3979.52	-486
3981.79	-486
3984.05	-486
3986.32	-486
3988.58	-486
3990.85	-486
3993.11	-486
3995.37	-486
3997.64	-486
3999.9	-486