File: muestras/manzana/mz_34.txt
#Acq. time (s)=	15
#Accumulations=	4
#Range (cm-¹)=	50...4000
#Windows=	3
#Autofocus=	Off
#AutoExposure=	Off
#Spike filter=	Multiple accum.
#Delay time (s)=	0
#Binning=	1
#Readout mode=	Signal
#DeNoise=	Off
#ICS correction=	Off
#Dark correction=	Off
#Inst. Process=	Off
#Instrument=	LabRAM HR Evol
#Detector=	Syncerity OE
#Objective=	x100_VIS
#Grating=	600 (500nm)
#ND Filter=	5%
#Laser=	532nm_Edge
#Hole=	100.021
#Range=	Visible
#Project=	Omar
#Sample=	120523
#Site=	ap
#Title=	mz
#Remark=	5 laser intensity
#Date=	12.05.2023 17:28
#Acquired=	12.05.2023 17:28:58
51.0297	18.6667
54.7185	32.5642
58.406	33.1283
62.0919	59.0258
65.7765	87.59
69.4595	121.488
73.1412	164.052
76.8214	193.949
80.5001	216.513
84.1774	249.744
87.8532	260.975
91.5276	259.539
95.2006	263.437
98.8721	277.334
102.54	279.232
106.209	294.463
109.876	297.027
113.542	286.258
117.204	292.822
120.867	292.053
124.526	297.283
128.186	282.514
131.845	285.745
135.5	305.643
139.155	300.873
142.807	296.104
146.46	296.002
150.11	314.566
153.757	303.13
157.406	303.028
161.051	305.592
164.697	312.823
168.339	299.387
171.98	319.951
175.619	304.515
179.259	315.079
182.895	318.977
186.53	314.208
190.164	314.105
193.796	298.669
197.427	313.9
201.059	314.464
204.686	318.362
208.313	314.926
211.938	315.49
215.562	305.388
219.184	314.619
222.803	323.183
226.422	322.414
230.04	312.978
233.657	318.875
237.272	314.106
240.886	328.67
244.497	314.568
248.108	312.465
251.717	341.029
255.325	327.594
258.93	326.158
262.535	313.389
266.137	334.619
269.74	321.85
273.341	341.081
276.939	334.312
280.537	326.209
284.132	319.44
287.728	326.671
291.32	326.569
294.911	327.133
298.502	331.03
302.09	329.594
305.677	318.825
309.264	322.056
312.848	336.62
316.43	335.184
320.011	337.082
323.593	330.313
327.171	341.544
330.748	333.441
334.323	329.339
337.897	329.903
341.47	333.8
345.041	329.698
348.611	343.595
352.18	351.493
355.747	348.724
359.312	351.954
362.877	327.185
366.44	323.083
369.999	340.98
373.56	344.878
377.119	333.442
380.676	338.006
384.23	341.237
387.785	345.801
391.338	345.699
394.888	352.263
398.439	347.494
401.988	338.725
405.534	328.622
409.081	344.52
412.624	352.417
416.167	335.648
419.708	346.879
423.249	351.443
426.786	344.007
430.323	346.571
433.86	357.135
437.393	339.033
440.926	345.597
444.458	338.161
447.988	344.725
451.516	339.956
455.043	342.52
458.568	353.085
462.092	343.649
465.615	346.213
469.138	370.11
472.658	354.008
476.177	351.239
479.694	357.803
483.21	347.034
486.723	348.265
490.236	360.162
493.748	367.393
497.258	353.957
500.768	361.188
504.276	376.419
507.78	350.983
511.285	356.881
514.789	348.778
518.289	354.676
521.791	360.573
525.29	369.137
528.787	365.035
532.284	360.932
535.778	370.83
539.272	360.061
542.763	367.291
546.255	353.856
549.743	371.753
553.232	361.651
556.718	374.215
560.203	372.779
563.688	367.343
567.169	364.574
570.65	371.805
574.129	374.369
577.609	372.933
581.085	367.497
584.56	359.395
588.034	375.959
591.506	380.523
594.978	351.087
598.447	364.318
601.916	366.216
605.383	381.446
608.849	398.011
612.313	364.575
615.776	372.472
619.238	374.37
622.699	359.601
626.156	383.498
629.614	373.396
633.071	371.293
636.526	384.524
639.978	385.755
643.431	378.319
646.88	384.883
650.33	384.781
653.779	382.012
657.224	381.242
660.67	377.807
664.113	396.371
667.556	379.602
670.997	381.499
674.435	370.73
677.875	380.627
681.311	375.192
684.746	385.089
688.182	388.987
691.614	379.551
695.045	389.448
698.475	367.346
701.904	404.577
705.333	399.807
708.759	381.038
712.183	394.936
715.606	367.5
719.028	395.397
722.449	381.295
725.868	389.192
729.286	391.09
732.703	371.654
736.117	384.218
739.531	390.782
742.944	384.013
746.355	387.911
749.766	394.475
753.173	389.706
756.581	385.603
759.987	394.167
763.39	390.065
766.794	404.629
770.195	393.86
773.596	395.758
776.994	391.655
780.393	394.219
783.788	388.117
787.185	378.014
790.578	386.578
793.971	381.809
797.362	382.373
800.751	393.604
804.138	392.835
807.527	402.066
810.912	385.297
814.296	396.528
817.679	383.758
821.06	392.989
824.441	397.553
827.822	399.451
831.199	404.015
834.576	399.913
837.951	392.477
841.323	409.041
844.695	394.938
848.066	394.836
851.436	387.4
854.805	407.298
858.173	400.528
861.539	385.093
864.902	404.323
868.266	394.888
871.628	396.785
874.987	388.016
878.347	409.247
881.704	397.811
885.061	402.375
888.418	390.939
891.771	382.837
895.122	392.734
898.475	392.632
901.824	385.196
905.174	387.093
908.52	393.658
911.866	384.889
915.212	399.453
918.555	397.35
921.896	386.581
925.237	394.479
928.576	395.043
931.914	396.94
935.253	404.171
938.588	399.402
941.922	419.966
945.255	390.53
948.587	399.761
951.917	398.325
955.244	396.889
958.572	397.454
961.899	410.684
965.225	389.249
968.549	395.146
971.872	397.71
975.192	401.608
978.512	388.839
981.831	404.736
985.148	399.967
988.464	388.531
991.778	404.429
995.092	403.659
998.404	388.89
1001.72	402.788
1005.02	399.352
1008.33	393.916
1011.64	407.147
1014.95	391.044
1018.25	407.609
1021.55	395.506
1024.85	416.07
1028.16	405.968
1031.46	391.199
1034.75	384.43
1038.05	394.327
1041.34	402.224
1044.64	384.789
1047.93	401.353
1051.22	391.25
1054.51	395.815
1057.8	400.379
1061.09	396.943
1064.38	390.174
1067.66	414.071
1070.95	386.635
1074.23	407.2
1077.51	405.764
1080.79	398.328
1084.07	397.559
1087.35	398.123
1090.62	408.687
1093.9	407.251
1097.17	392.482
1100.44	389.046
1103.71	402.944
1106.99	404.841
1110.25	392.739
1113.52	398.636
1116.79	403.2
1120.05	395.765
1123.31	408.995
1126.58	393.56
1129.84	391.457
1133.1	398.688
1136.36	389.252
1139.61	391.15
1142.87	408.38
1146.12	390.278
1149.38	402.175
1152.63	404.74
1155.88	421.304
1159.13	423.868
1162.38	398.432
1165.63	406.996
1168.87	396.894
1172.12	408.791
1175.36	391.355
1178.6	391.253
1181.84	399.151
1185.08	394.381
1188.32	402.279
1191.56	404.176
1194.79	406.741
1198.03	391.305
1201.26	395.869
1204.49	395.766
1207.72	388.997
1210.95	404.228
1214.18	386.126
1217.41	417.356
1220.64	394.587
1223.86	395.818
1227.08	405.716
1230.3	360.946
1233.53	398.844
1236.75	408.741
1239.96	385.306
1243.18	401.87
1246.4	392.434
1249.61	397.665
1252.82	397.562
1256.04	404.793
1259.25	383.357
1262.46	400.588
1265.67	396.486
1268.87	398.383
1272.08	402.947
1275.28	392.845
1278.49	399.409
1281.69	399.306
1284.89	403.871
1288.09	404.768
1291.29	402.332
1294.49	426.23
1297.68	394.127
1300.88	404.691
1304.07	404.589
1307.26	398.486
1310.46	409.717
1313.65	389.615
1316.84	399.512
1320.02	393.41
1323.21	404.641
1326.39	399.872
1329.58	398.436
1332.76	415
1335.94	400.897
1339.12	398.795
1342.3	412.692
1345.48	389.923
1348.65	410.487
1351.83	396.385
1355	407.616
1358.18	396.18
1361.35	390.077
1364.52	408.642
1367.69	393.206
1370.86	383.103
1374.02	408.334
1377.19	387.565
1380.35	402.796
1383.52	409.36
1386.68	403.257
1389.84	389.155
1393	385.052
1396.16	388.283
1399.31	398.181
1402.47	420.745
1405.63	411.976
1408.78	403.873
1411.93	394.437
1415.08	415.002
1418.23	422.232
1421.38	405.463
1424.53	408.027
1427.68	423.925
1430.82	391.156
1433.96	422.387
1437.11	411.618
1440.25	408.848
1443.39	410.746
1446.53	399.977
1449.67	400.541
1452.8	423.772
1455.94	399.003
1459.07	400.9
1462.21	406.131
1465.34	402.028
1468.47	395.926
1471.6	392.49
1474.72	397.054
1477.85	394.952
1480.98	393.516
1484.1	391.413
1487.23	404.644
1490.35	405.875
1493.47	407.773
1496.59	402.337
1499.71	407.568
1502.83	408.132
1505.94	400.029
1509.06	419.927
1512.17	402.491
1515.29	404.388
1518.4	430.953
1521.51	426.183
1524.62	423.414
1527.72	435.312
1530.83	423.209
1533.94	417.773
1537.04	412.338
1540.15	410.235
1543.25	405.466
1546.35	421.363
1549.45	398.594
1552.55	409.825
1555.65	410.389
1558.74	417.62
1561.84	405.518
1564.93	407.415
1568.02	409.979
1571.12	408.543
1574.2	403.108
1577.3	402.339
1580.38	401.569
1583.47	415.467
1586.56	386.698
1589.64	405.929
1592.72	408.493
1595.81	417.724
1598.89	395.621
1601.97	399.519
1605.05	396.083
1608.12	408.987
1611.2	405.59
1614.27	392.274
1617.35	393.891
1620.42	400.81
1623.5	390.123
1626.57	399.602
1629.63	398.348
1632.7	398.679
1635.77	391.35
1638.84	395.452
1641.9	390.952
1644.97	407.634
1648.03	389.44
1651.09	386.627
1654.15	393.028
1657.21	401.679
1660.27	406.448
1663.32	407.834
1666.38	394.329
1669.43	416.13
1672.49	397.933
1675.54	398.555
1678.59	401.177
1681.64	395.834
1684.69	399.376
1687.73	408.392
1690.78	394.787
1693.83	396.915
1696.87	399.821
1699.91	405.62
1702.96	402.148
1706	396.962
1709.04	399.355
1712.07	407.934
1715.11	397.218
1718.15	386.396
1721.18	395.368
1724.21	401.851
1727.25	386.713
1730.28	390.607
1733.31	377.624
1736.34	393.922
1739.37	407.928
1742.39	395.253
1745.42	391.848
1748.45	389.612
1751.47	389.182
1754.49	382.328
1757.51	393.088
1759.25	361.559
1762.28	368.153
1765.31	385.414
1768.34	392.008
1771.37	392.602
1774.4	391.196
1777.43	390.456
1780.46	393.05
1783.48	379.644
1786.51	382.238
1789.53	394.832
1792.55	382.759
1795.57	392.02
1798.59	393.947
1801.61	395.874
1804.63	373.135
1807.64	395.062
1810.66	384.989
1813.67	388.276
1816.68	386.229
1819.7	371.515
1822.71	384.802
1825.72	390.755
1828.72	394.708
1831.73	401.327
1834.74	373.947
1837.74	386.567
1840.75	393.853
1843.75	397.139
1846.75	392.426
1849.75	383.712
1852.75	396.332
1855.75	381.618
1858.75	384.238
1861.74	380.191
1864.74	398.144
1867.73	376.764
1870.72	384.717
1873.71	377.336
1876.7	388.623
1879.69	392.576
1882.68	377.862
1885.67	388.482
1888.66	388.435
1891.64	397.055
1894.62	369.674
1897.61	380.961
1900.59	372.914
1903.57	385.533
1906.55	371.486
1909.53	396.106
1912.5	394.726
1915.48	380.679
1918.46	389.965
1921.43	380.585
1924.4	378.538
1927.37	367.824
1930.34	382.444
1933.31	377.73
1936.28	397.017
1939.25	377.636
1942.22	385.589
1945.18	382.876
1948.14	384.829
1951.11	386.782
1954.07	388.068
1957.03	374.021
1959.99	389.974
1962.95	383.927
1965.91	383.214
1968.86	373.167
1971.82	359.786
1974.77	381.739
1977.73	385.026
1980.68	375.645
1983.63	379.598
1986.58	378.218
1989.53	370.838
1992.47	376.791
1995.42	382.077
1998.37	375.364
2001.31	365.983
2004.25	374.603
2007.2	358.556
2010.14	386.509
2013.08	373.129
2016.02	377.748
2018.96	369.701
2021.89	362.321
2024.83	372.941
2027.76	375.561
2030.7	375.514
2033.63	365.467
2036.56	372.086
2039.49	362.706
2042.42	382.659
2045.35	365.279
2048.28	371.232
2051.2	367.851
2054.13	383.138
2057.05	382.424
2059.97	372.377
2062.9	380.997
2065.82	381.617
2068.74	370.903
2071.65	377.523
2074.57	372.142
2077.49	378.095
2080.4	382.048
2083.32	360.668
2086.23	373.288
2089.15	359.908
2092.05	366.527
2094.97	359.814
2097.87	363.767
2100.78	357.053
2103.69	353.673
2106.6	357.626
2109.5	378.245
2112.4	360.198
2115.31	358.151
2118.21	363.438
2121.11	349.391
2124.01	369.344
2126.91	342.63
2129.8	368.583
2132.7	359.203
2135.59	350.489
2138.49	369.109
2141.38	345.062
2144.27	347.682
2147.16	361.635
2150.05	343.588
2152.94	358.874
2155.83	351.494
2158.72	363.447
2161.6	349.4
2164.49	356.02
2167.37	363.973
2170.26	363.926
2173.14	366.545
2176.02	357.832
2178.9	355.785
2181.77	359.738
2184.65	357.024
2187.53	362.311
2190.4	355.597
2193.28	354.883
2196.15	344.17
2199.02	344.123
2201.89	353.409
2204.76	361.362
2207.63	340.648
2210.5	343.935
2213.37	339.221
2216.23	348.508
2219.1	333.794
2221.96	355.747
2224.82	335.033
2227.69	348.32
2230.55	348.939
2233.41	350.226
2236.26	358.845
2239.12	338.798
2241.98	337.418
2244.83	334.704
2247.69	343.324
2250.54	338.611
2253.39	320.564
2256.24	331.183
2259.09	347.136
2261.94	325.089
2264.79	331.042
2267.64	336.329
2270.49	332.282
2273.33	337.568
2276.18	351.521
2279.02	332.807
2281.86	335.427
2284.7	338.047
2287.54	326
2290.38	330.62
2293.22	317.239
2296.05	338.526
2298.89	337.812
2301.72	328.432
2304.56	337.051
2307.39	321.671
2310.22	338.291
2313.05	327.577
2315.88	336.863
2318.71	317.483
2321.54	326.77
2324.36	332.723
2327.19	328.009
2330.01	327.962
2332.84	330.582
2335.66	317.201
2338.48	324.488
2341.3	319.107
2344.12	316.394
2346.94	333.013
2349.76	338.967
2352.57	321.586
2355.39	318.206
2358.2	328.159
2361.02	316.779
2363.83	338.732
2366.64	326.018
2369.45	317.971
2372.26	336.591
2375.07	318.544
2377.87	323.83
2380.68	317.117
2383.49	325.07
2386.29	318.356
2389.09	301.642
2391.9	328.262
2394.7	321.548
2397.5	314.835
2400.29	320.121
2403.09	302.074
2405.89	318.694
2408.69	321.98
2411.48	319.267
2414.28	319.886
2417.07	319.839
2419.86	322.459
2422.65	323.745
2425.44	303.032
2428.23	311.651
2431.02	305.604
2433.81	324.891
2436.59	327.51
2439.38	322.13
2442.16	315.417
2444.94	315.37
2447.73	326.656
2450.51	327.942
2453.29	321.895
2456.07	318.515
2458.84	318.468
2461.62	319.088
2464.4	314.374
2467.17	318.994
2469.95	318.28
2472.72	329.567
2475.49	320.186
2478.26	322.139
2481.03	315.426
2483.8	319.379
2486.57	326.665
2489.34	305.951
2492.1	310.571
2494.87	313.191
2497.63	309.144
2500.39	329.763
2503.16	319.717
2505.92	318.336
2508.68	304.956
2511.44	322.242
2514.19	307.529
2516.95	310.815
2519.71	316.768
2522.46	318.054
2525.22	310.007
2527.97	299.96
2530.72	302.58
2533.47	307.2
2536.22	307.153
2538.97	310.439
2541.72	302.392
2544.47	307.679
2547.21	317.632
2549.96	313.585
2552.7	298.871
2555.45	318.824
2558.19	312.777
2560.93	312.73
2563.67	307.35
2566.41	305.303
2569.15	301.923
2571.89	319.876
2574.62	316.495
2577.36	308.448
2580.09	301.068
2582.83	301.021
2585.56	314.307
2588.29	294.26
2591.02	303.547
2593.75	312.167
2596.48	303.453
2599.21	306.073
2601.93	310.692
2604.66	305.979
2607.39	298.598
2610.11	307.218
2612.83	307.171
2615.55	313.124
2618.27	305.077
2620.99	299.697
2623.71	308.983
2626.43	303.603
2629.15	311.556
2631.86	316.842
2634.58	318.129
2637.29	297.415
2640.01	311.368
2642.72	297.988
2645.43	310.607
2648.14	304.56
2650.85	289.847
2653.56	309.8
2656.26	310.42
2658.97	303.706
2661.68	292.326
2664.38	300.945
2667.09	310.232
2669.79	309.518
2672.49	302.804
2675.19	304.757
2677.89	304.044
2680.59	294.663
2683.29	298.616
2685.98	304.569
2688.68	298.523
2691.37	299.142
2694.07	305.762
2696.76	295.715
2699.45	303.668
2702.14	308.954
2704.83	297.574
2707.52	302.194
2710.21	296.147
2712.9	294.766
2715.58	308.053
2718.27	309.339
2720.95	295.292
2723.64	285.245
2726.32	295.865
2729	305.818
2731.68	295.771
2734.36	297.724
2737.04	313.01
2739.72	302.297
2742.39	289.583
2745.07	298.869
2747.74	294.156
2750.42	303.442
2753.09	298.062
2755.76	296.682
2758.43	301.301
2761.1	294.588
2763.77	295.207
2766.44	297.827
2769.11	287.78
2771.78	287.066
2774.44	310.353
2777.11	288.306
2779.77	296.926
2782.43	292.879
2785.09	308.165
2787.76	294.785
2790.41	293.404
2793.07	289.357
2795.73	303.977
2798.39	296.597
2801.04	300.55
2803.7	293.169
2806.35	289.122
2809.01	291.076
2811.66	297.029
2814.31	278.315
2816.96	292.268
2819.61	287.554
2822.26	284.841
2824.91	291.46
2827.55	290.08
2830.2	292.033
2832.84	291.986
2835.49	295.939
2838.13	289.892
2840.77	291.845
2843.41	288.465
2846.05	268.418
2848.69	287.038
2851.33	278.991
2853.97	289.61
2856.6	287.563
2859.24	288.183
2861.87	291.469
2864.51	305.422
2867.14	297.376
2869.77	297.329
2872.4	272.615
2875.03	297.901
2877.66	278.521
2880.29	301.807
2882.92	299.76
2885.54	288.38
2888.17	280.333
2890.79	288.953
2893.42	284.239
2896.04	286.859
2898.66	288.812
2901.28	292.098
2903.9	289.385
2906.52	286.004
2909.14	293.957
2911.76	299.244
2914.37	289.863
2916.99	293.816
2919.6	280.426
2922.21	281.851
2924.83	273.032
2927.44	283.419
2930.05	289.119
2932.66	282.879
2935.27	289.29
2937.88	280.233
2940.48	271.861
2943.09	280.327
2945.69	279.02
2948.3	288.355
2950.9	282.982
2953.5	266.159
2956.1	276.476
2958.7	276.61
2961.3	277.601
2963.9	281.925
2966.5	277.223
2969.1	280.217
2971.69	278.693
2974.29	279.405
2976.88	276.197
2979.48	277.05
2982.07	271.821
2984.66	277.2
2987.25	277.417
2989.84	271.635
2992.43	277.871
2995.02	275.459
2997.6	266.867
3000.19	273.457
3002.77	277.099
3005.36	262.957
3007.94	269.606
3010.53	260.641
3013.11	267.133
3015.69	265.686
3018.27	275.191
3020.85	262.431
3023.42	266.588
3026	271.78
3028.58	273.917
3031.15	275.472
3033.73	268.439
3036.3	268.504
3038.87	264.354
3041.44	273.06
3044.01	269.403
3046.58	264.308
3048.04	266.748
3050.62	268.068
3053.2	288.056
3055.77	247.376
3058.35	262.03
3060.93	265.351
3063.51	266.671
3066.08	274.658
3068.66	268.646
3071.23	251.966
3073.8	245.953
3076.37	252.607
3078.94	267.928
3081.51	252.582
3084.08	264.569
3086.65	260.556
3089.22	264.543
3091.78	263.864
3094.35	259.184
3096.91	266.505
3099.48	253.826
3102.04	262.479
3104.6	265.133
3107.16	261.12
3109.72	273.774
3112.28	281.095
3114.84	265.749
3117.4	260.403
3119.96	257.723
3122.51	267.044
3125.07	260.364
3127.62	273.018
3130.18	257.005
3132.73	264.993
3135.28	256.313
3137.83	263.634
3140.38	264.288
3142.93	246.942
3145.47	260.262
3148.02	246.249
3150.57	258.903
3153.11	258.89
3155.66	262.211
3158.2	257.531
3160.74	255.519
3163.28	262.839
3165.83	250.16
3168.37	256.814
3170.91	256.134
3173.44	261.455
3175.98	262.775
3178.52	256.096
3181.05	265.416
3183.59	256.07
3186.12	256.724
3188.66	241.378
3191.19	262.699
3193.72	262.686
3196.25	260.006
3198.78	263.327
3201.31	256.647
3203.84	259.968
3206.36	259.955
3208.89	245.942
3211.41	259.93
3213.94	248.584
3216.46	254.571
3218.99	244.558
3221.51	253.212
3224.03	241.199
3226.55	246.52
3229.07	253.174
3231.59	255.161
3234.1	255.815
3236.62	250.468
3239.13	250.456
3241.65	253.776
3244.16	245.097
3246.68	257.084
3249.19	251.738
3251.7	245.725
3254.21	237.712
3256.72	249.7
3259.23	235.02
3261.74	241.007
3264.25	243.661
3266.75	250.315
3269.26	234.969
3271.76	230.956
3274.27	257.61
3276.77	241.597
3279.27	248.918
3281.77	239.572
3284.27	242.226
3286.77	244.879
3289.27	243.533
3291.77	244.854
3294.27	234.841
3296.76	246.162
3299.26	246.816
3301.75	233.469
3304.24	242.123
3306.74	238.111
3309.23	237.431
3311.72	236.085
3314.21	248.739
3316.7	250.726
3319.19	247.38
3321.68	234.7
3324.16	240.021
3326.65	241.342
3329.13	237.329
3331.62	243.983
3334.1	248.637
3336.58	243.29
3339.07	240.611
3341.55	239.265
3344.03	243.252
3346.51	239.239
3348.99	239.893
3351.46	238.547
3353.94	231.201
3356.42	233.188
3358.89	239.175
3361.36	237.163
3363.84	234.483
3366.31	232.47
3368.78	231.124
3371.25	240.445
3373.72	223.099
3376.19	240.419
3378.66	229.74
3381.13	243.06
3383.59	227.714
3386.06	243.701
3388.52	239.689
3390.99	225.009
3393.45	214.996
3395.91	234.317
3398.38	232.971
3400.84	213.625
3403.3	226.945
3405.76	226.932
3408.21	218.92
3410.67	230.24
3413.13	220.227
3415.58	225.548
3418.04	234.202
3420.49	232.856
3422.95	228.176
3425.4	234.83
3427.85	228.817
3430.3	228.138
3432.75	242.792
3435.2	227.446
3437.65	226.1
3440.1	220.087
3442.54	226.741
3444.99	234.728
3447.43	234.715
3449.88	233.369
3452.32	238.69
3454.76	223.343
3457.21	231.331
3459.65	233.985
3462.09	227.305
3464.53	227.959
3466.96	225.946
3469.4	237.933
3471.84	225.921
3474.27	210.575
3476.71	229.895
3479.14	229.216
3481.58	221.869
3484.01	212.523
3486.44	226.511
3488.87	243.831
3491.3	224.485
3493.73	219.139
3496.16	223.126
3498.59	217.113
3501.01	223.101
3503.44	217.088
3505.87	219.742
3508.29	217.729
3510.71	215.716
3513.14	216.37
3515.56	210.357
3517.98	201.011
3520.4	206.332
3522.82	216.985
3525.24	212.306
3527.66	217.627
3530.07	208.28
3532.49	218.934
3534.9	216.255
3537.32	212.909
3539.73	204.229
3542.15	211.55
3544.56	216.204
3546.97	194.191
3549.38	217.512
3551.79	202.165
3554.2	200.819
3556.61	192.14
3559.02	208.794
3561.42	202.781
3563.83	204.101
3566.23	211.422
3568.64	205.409
3571.04	198.73
3573.44	206.717
3575.84	206.038
3578.25	204.691
3580.65	203.345
3583.04	209.333
3585.44	201.986
3587.84	203.307
3590.24	200.628
3592.63	202.615
3595.03	203.935
3597.42	206.589
3599.82	207.91
3602.21	207.897
3604.6	211.217
3606.99	203.871
3609.38	207.859
3611.77	211.179
3614.16	203.833
3616.55	197.82
3618.94	201.807
3621.32	205.128
3623.71	198.449
3626.09	206.436
3628.48	204.423
3630.86	205.744
3633.24	201.064
3635.63	203.718
3638.01	213.039
3640.39	202.359
3642.77	199.013
3645.15	205.667
3647.52	190.321
3649.9	202.308
3652.28	198.962
3654.65	190.949
3657.03	198.936
3659.4	206.257
3661.77	199.577
3664.14	196.231
3666.52	196.218
3668.89	190.206
3671.25	202.193
3673.62	193.513
3675.99	190.167
3678.36	196.821
3680.73	201.475
3683.09	192.796
3685.46	184.783
3687.82	195.437
3690.19	198.091
3692.55	181.411
3694.91	197.398
3697.27	196.719
3699.63	190.039
3701.99	197.36
3704.35	190.681
3706.71	191.334
3709.06	183.322
3711.42	191.976
3713.78	181.296
3716.13	194.617
3718.48	177.937
3720.84	192.591
3723.19	196.578
3725.54	190.565
3727.89	190.553
3730.24	188.54
3732.59	185.86
3734.94	197.848
3737.29	197.168
3739.64	199.155
3741.98	193.809
3744.33	200.463
3746.67	191.784
3749.02	180.438
3751.36	198.425
3753.7	193.079
3756.04	183.066
3758.38	196.386
3760.72	189.707
3763.06	184.361
3765.4	192.348
3767.74	179.002
3770.08	194.989
3772.41	185.643
3774.75	188.297
3777.08	185.618
3779.41	190.938
3781.75	195.592
3784.08	196.913
3786.41	184.9
3788.74	194.887
3791.07	185.541
3793.4	190.195
3795.73	187.515
3798.06	187.502
3800.38	188.156
3802.71	188.81
3805.03	189.464
3807.36	182.118
3809.68	190.772
3812.01	189.426
3814.33	176.746
3816.65	192.067
3818.97	186.054
3821.29	190.708
3823.61	188.695
3825.93	180.016
3828.24	182.003
3830.56	173.324
3832.88	187.977
3835.19	186.631
3837.51	189.285
3839.82	193.272
3842.13	187.926
3844.45	185.247
3846.76	195.234
3849.07	175.221
3851.38	189.208
3853.69	184.529
3856	185.183
3858.3	191.837
3860.61	189.824
3862.92	187.145
3865.22	185.132
3867.53	193.119
3869.83	191.106
3872.13	191.093
3874.43	187.747
3876.74	195.068
3879.04	193.055
3881.34	194.376
3883.64	189.029
3885.93	190.35
3888.23	189.004
3890.53	189.658
3892.83	199.645
3895.12	183.632
3897.41	191.619
3899.71	184.94
3902	191.594
3904.29	196.914
3906.59	196.235
3908.88	187.555
3911.17	189.543
3913.46	186.863
3915.75	195.517
3918.03	188.171
3920.32	188.158
3922.61	181.479
3924.89	194.799
3927.18	198.787
3929.46	190.774
3931.74	196.761
3934.03	200.082
3936.31	187.402
3938.59	195.389
3940.87	199.377
3943.15	194.697
3945.43	200.018
3947.71	196.671
3949.98	190.659
3952.26	191.979
3954.54	189.3
3956.81	193.287
3959.09	194.608
3961.36	189.928
3963.63	201.915
3965.9	203.236
3968.18	203.223
3970.45	198.544
3972.72	197.198
3974.99	186.518
3977.25	191.172
3979.52	209.826
3981.79	193.813
3984.05	199.8
3986.32	197.787
3988.58	192.441
3990.85	207.095
3993.11	195.749
3995.37	199.07
3997.64	202.39
3999.9	203.711