File: muestras/manzana/mz_31.txt
#Acq. time (s)=	15
#Accumulations=	4
#Range (cm-¹)=	50...4000
#Windows=	3
#Autofocus=	Off
#AutoExposure=	Off
#Spike filter=	Multiple accum.
#Delay time (s)=	0
#Binning=	1
#Readout mode=	Signal
#DeNoise=	Off
#ICS correction=	Off
#Dark correction=	Off
#Inst. Process=	Off
#Instrument=	LabRAM HR Evol
#Detector=	Syncerity OE
#Objective=	x100_VIS
#Grating=	600 (500nm)
#ND Filter=	5%
#Laser=	532nm_Edge
#Hole=	100.021
#Range=	Visible
#Project=	Omar
#Sample=	120523
#Site=	ap
#Title=	mz
#Remark=	5 laser intensity
#Date=	12.05.2023 17:23
#Acquired=	12.05.2023 17:23:54
51.0297	20
54.7185	29.4889
58.406	34.9778
62.0919	70.4668
65.7765	104.622
69.4595	146.778
73.1412	246.267
76.8214	295.756
80.5001	345.245
84.1774	406.067
87.8532	456.223
91.5276	449.045
95.2006	442.534
98.8721	444.689
102.54	466.845
106.209	485.667
109.876	469.156
113.542	498.645
117.204	498.134
120.867	497.623
124.526	489.112
128.186	482.601
131.845	480.09
135.5	504.245
139.155	489.734
142.807	498.556
146.46	528.712
150.11	512.868
153.757	531.69
157.406	534.512
161.051	521.334
164.697	508.157
168.339	505.646
171.98	506.468
175.619	518.623
179.259	534.779
182.895	522.935
186.53	524.424
190.164	531.912
193.796	522.068
197.427	547.557
201.059	535.046
204.686	526.535
208.313	522.69
211.938	536.179
215.562	537.002
219.184	541.824
222.803	532.646
226.422	549.468
230.04	548.957
233.657	531.779
237.272	553.935
240.886	549.424
244.497	540.246
248.108	553.735
251.717	557.891
255.325	552.046
258.93	548.202
262.535	562.358
266.137	553.847
269.74	553.335
273.341	566.158
276.939	544.98
280.537	563.802
284.132	563.291
287.728	550.113
291.32	568.269
294.911	562.425
298.502	565.247
302.09	563.402
305.677	567.558
309.264	579.714
312.848	585.869
316.43	581.358
320.011	556.847
323.593	565.669
327.171	579.158
330.748	585.314
334.323	570.136
337.897	574.292
341.47	577.114
345.041	579.936
348.611	583.425
352.18	583.581
355.747	587.07
359.312	561.892
362.877	588.048
366.44	584.87
369.999	605.025
373.56	597.181
377.119	595.336
380.676	596.159
384.23	616.314
387.785	611.137
391.338	615.959
394.888	594.115
398.439	607.603
401.988	616.426
405.534	602.581
409.081	610.737
412.624	612.226
416.167	611.715
419.708	615.87
423.249	604.026
426.786	622.182
430.323	585.67
433.86	615.159
437.393	611.315
440.926	590.804
444.458	637.626
447.988	630.448
451.516	609.937
455.043	621.426
458.568	627.582
462.092	633.071
465.615	635.893
469.138	632.049
472.658	625.538
476.177	652.36
479.694	647.182
483.21	630.671
486.723	659.493
490.236	642.982
493.748	629.138
497.258	651.96
500.768	646.116
504.276	656.938
507.78	639.76
511.285	650.582
514.789	636.738
518.289	646.227
521.791	656.382
525.29	657.871
528.787	671.36
532.284	679.516
535.778	673.005
539.272	664.494
542.763	661.316
546.255	688.138
549.743	692.294
553.232	668.449
556.718	668.605
560.203	678.761
563.688	658.25
567.169	673.738
570.65	661.894
574.129	688.05
577.609	692.205
581.085	690.361
584.56	691.183
588.034	682.005
591.506	684.161
594.978	658.983
598.447	674.472
601.916	678.628
605.383	671.45
608.849	688.939
612.313	735.761
615.776	703.917
619.238	696.739
622.699	708.228
626.156	715.717
629.614	717.872
633.071	719.361
636.526	718.184
639.978	732.339
643.431	716.495
646.88	723.984
650.33	720.806
653.779	686.962
657.224	727.784
660.67	745.939
664.113	723.428
667.556	718.917
670.997	723.74
674.435	711.228
677.875	717.384
681.311	716.873
684.746	736.362
688.182	719.851
691.614	728.006
695.045	725.495
698.475	719.651
701.904	727.806
705.333	719.962
708.759	738.784
712.183	723.607
715.606	753.096
719.028	733.251
722.449	744.74
725.868	734.229
729.286	757.718
732.703	749.874
736.117	728.696
739.531	738.185
742.944	745.674
746.355	747.829
749.766	731.318
753.173	744.14
756.581	752.296
759.987	744.452
763.39	755.94
766.794	747.429
770.195	732.252
773.596	726.407
776.994	751.23
780.393	769.385
783.788	760.207
787.185	776.363
790.578	725.852
793.971	739.341
797.362	758.83
800.751	751.652
804.138	765.141
807.527	758.63
810.912	762.119
814.296	763.608
817.679	791.097
821.06	767.919
824.441	775.408
827.822	790.897
831.199	769.052
834.576	797.875
837.951	763.363
841.323	770.852
844.695	791.675
848.066	778.497
851.436	792.653
854.805	789.475
858.173	806.964
861.539	794.453
864.902	792.608
868.266	784.097
871.628	789.586
874.987	799.742
878.347	801.897
881.704	793.386
885.061	776.208
888.418	798.364
891.771	792.52
895.122	778.675
898.475	783.497
901.824	802.986
905.174	789.809
908.52	787.964
911.866	814.12
915.212	798.942
918.555	811.098
921.896	809.92
925.237	805.409
928.576	801.564
931.914	821.72
935.253	815.876
938.588	821.365
941.922	802.187
945.255	803.676
948.587	806.498
951.917	806.654
955.244	840.143
958.572	834.965
961.899	819.12
965.225	823.943
968.549	826.765
971.872	828.254
975.192	832.409
978.512	827.898
981.831	821.387
985.148	805.543
988.464	816.365
991.778	835.854
995.092	808.676
998.404	841.499
1001.72	819.654
1005.02	836.476
1008.33	837.299
1011.64	831.454
1014.95	832.943
1018.25	837.765
1021.55	857.921
1024.85	833.41
1028.16	840.232
1031.46	846.388
1034.75	843.21
1038.05	846.699
1041.34	844.188
1044.64	851.01
1047.93	833.832
1051.22	838.655
1054.51	840.81
1057.8	868.966
1061.09	862.455
1064.38	874.61
1067.66	868.099
1070.95	875.588
1074.23	885.744
1077.51	873.899
1080.79	862.055
1084.07	884.211
1087.35	863.033
1090.62	879.188
1093.9	866.011
1097.17	876.166
1100.44	878.322
1103.71	859.144
1106.99	881.966
1110.25	856.122
1113.52	866.278
1116.79	870.433
1120.05	889.922
1123.31	858.078
1126.58	872.9
1129.84	860.389
1133.1	865.878
1136.36	894.7
1139.61	866.189
1142.87	891.678
1146.12	892.5
1149.38	891.989
1152.63	920.811
1155.88	917.634
1159.13	909.789
1162.38	897.278
1165.63	908.1
1168.87	892.256
1172.12	901.745
1175.36	907.901
1178.6	909.389
1181.84	911.545
1185.08	936.367
1188.32	927.856
1191.56	935.345
1194.79	919.501
1198.03	952.99
1201.26	920.479
1204.49	905.301
1207.72	911.456
1210.95	927.612
1214.18	937.768
1217.41	931.923
1220.64	924.079
1223.86	913.568
1227.08	939.723
1230.3	899.212
1233.53	912.701
1236.75	888.19
1239.96	907.012
1243.18	919.168
1246.4	922.657
1249.61	925.479
1252.82	928.968
1256.04	927.124
1259.25	913.946
1262.46	931.435
1265.67	956.257
1268.87	932.413
1272.08	943.902
1275.28	951.39
1278.49	975.546
1281.69	935.035
1284.89	963.857
1288.09	939.013
1291.29	948.835
1294.49	939.657
1297.68	953.813
1300.88	963.302
1304.07	979.458
1307.26	958.946
1310.46	957.102
1313.65	962.591
1316.84	963.413
1320.02	978.235
1323.21	960.391
1326.39	969.213
1329.58	966.702
1332.76	956.858
1335.94	977.013
1339.12	958.502
1342.3	967.991
1345.48	1075.48
1348.65	988.969
1351.83	979.125
1355	965.28
1358.18	972.102
1361.35	980.925
1364.52	959.747
1367.69	962.569
1370.86	1010.72
1374.02	962.214
1377.19	969.703
1380.35	974.525
1383.52	979.347
1386.68	982.836
1389.84	980.992
1393	1002.48
1396.16	989.97
1399.31	972.125
1402.47	991.614
1405.63	975.103
1408.78	995.925
1411.93	1000.75
1415.08	1031.57
1418.23	1003.73
1421.38	1017.88
1424.53	1012.04
1427.68	984.859
1430.82	1033.68
1433.96	1013.84
1437.11	1010.66
1440.25	1038.15
1443.39	1026.97
1446.53	1023.79
1449.67	1019.28
1452.8	1033.44
1455.94	1020.26
1459.07	1027.08
1462.21	1003.9
1465.34	1031.39
1468.47	1021.55
1471.6	1003.7
1474.72	1033.86
1477.85	1004.01
1480.98	995.504
1484.1	1024.33
1487.23	1008.48
1490.35	1007.3
1493.47	1027.46
1496.59	1024.28
1499.71	1033.1
1502.83	1031.26
1505.94	1008.75
1509.06	1036.24
1512.17	1059.73
1515.29	1048.55
1518.4	1058.7
1521.51	1104.86
1524.62	1095.02
1527.72	1065.84
1530.83	1072.66
1533.94	1082.82
1537.04	1085.64
1540.15	1063.79
1543.25	1078.62
1546.35	1058.1
1549.45	1073.59
1552.55	1049.75
1555.65	1054.57
1558.74	1071.39
1561.84	1076.88
1564.93	1067.7
1568.02	1054.53
1571.12	1064.02
1574.2	1067.5
1577.3	1078.99
1580.38	1061.15
1583.47	1066.64
1586.56	1054.79
1589.64	1070.28
1592.72	1083.77
1595.81	1083.26
1598.89	1043.42
1601.97	1074.91
1605.05	1044.39
1608.12	1052.38
1611.2	1040.63
1614.27	1051.95
1617.35	1033.39
1620.42	1058.93
1623.5	1052.01
1626.57	1083.17
1629.63	1060.21
1632.7	1072.52
1635.77	1057
1638.84	1076.48
1641.9	1061.15
1644.97	1041.72
1648.03	1041.14
1651.09	1057.26
1654.15	1078.72
1657.21	1058.51
1660.27	1084.66
1663.32	1081.29
1666.38	1069.28
1669.43	1078.89
1672.49	1076.74
1675.54	1057.7
1678.59	1070.36
1681.64	1096.8
1684.69	1091.2
1687.73	1081.13
1690.78	1072.61
1693.83	1076.08
1696.87	1071.05
1699.91	1065.02
1702.96	1070.03
1706	1052.06
1709.04	1047.01
1712.07	1065.51
1715.11	1048.93
1718.15	1067.84
1721.18	1053.21
1724.21	1037.28
1727.25	1047.69
1730.28	1041.24
1733.31	1035.33
1736.34	1025.18
1739.37	1021.98
1742.39	1043.78
1745.42	1027.57
1748.45	1028.66
1751.47	1025.13
1754.49	1040.09
1757.51	1037.89
1759.25	1028.54
1762.28	1028.11
1765.31	1049.67
1768.34	1035.23
1771.37	1039.46
1774.4	1026.36
1777.43	1041.25
1780.46	1062.15
1783.48	1065.71
1786.51	1063.27
1789.53	1045.5
1792.55	1065.73
1795.57	1041.96
1798.59	1037.52
1801.61	1042.42
1804.63	1054.65
1807.64	1052.88
1810.66	1039.11
1813.67	1052.87
1816.68	1056.64
1819.7	1034.41
1822.71	1044.18
1825.72	1052.61
1828.72	1043.71
1831.73	1042.81
1834.74	1052.58
1837.74	1037.01
1840.75	1045.45
1843.75	1033.88
1846.75	1038.98
1849.75	1033.41
1852.75	1036.51
1855.75	1024.28
1858.75	1049.38
1861.74	1033.82
1864.74	1042.25
1867.73	1052.68
1870.72	1029.12
1873.71	1025.55
1876.7	1007.98
1879.69	1041.08
1882.68	1031.52
1885.67	1028.62
1888.66	1047.05
1891.64	1038.82
1894.62	1024.59
1897.61	1021.02
1900.59	1042.79
1903.57	1027.89
1906.55	1027.65
1909.53	1044.76
1912.5	1034.52
1915.48	1051.62
1918.46	1037.39
1921.43	1033.16
1924.4	1047.59
1927.37	1030.69
1930.34	1043.79
1933.31	1064.23
1936.28	1035.33
1939.25	1058.43
1942.22	1026.19
1945.18	1029.96
1948.14	1043.06
1951.11	1030.83
1954.07	1038.6
1957.03	1036.36
1959.99	1050.13
1962.95	1020.56
1965.91	1043
1968.86	1021.43
1971.82	1026.53
1974.77	1043.63
1977.73	1048.73
1980.68	1022.5
1983.63	1009.6
1986.58	1043.37
1989.53	1017.8
1992.47	1010.9
1995.42	982.001
1998.37	1011.77
2001.31	1025.54
2004.25	1008.64
2007.2	1017.74
2010.14	1004.17
2013.08	1012.6
2016.02	1019.7
2018.96	1006.8
2021.89	1006.57
2024.83	1013.67
2027.76	1026.77
2030.7	1001.87
2033.63	1014.97
2036.56	1001.41
2039.49	986.508
2042.42	1008.27
2045.35	995.375
2048.28	1007.81
2051.2	1012.91
2054.13	1000.01
2057.05	1017.78
2059.97	1012.88
2062.9	997.311
2065.82	1017.08
2068.74	1018.18
2071.65	981.946
2074.57	997.713
2077.49	1010.15
2080.4	1000.58
2083.32	991.014
2086.23	980.781
2089.15	981.881
2092.05	997.649
2094.97	999.416
2097.87	985.183
2100.78	990.283
2103.69	980.717
2106.6	989.818
2109.5	972.918
2112.4	958.018
2115.31	983.119
2118.21	976.219
2121.11	984.653
2124.01	957.087
2126.91	971.52
2129.8	957.954
2132.7	968.388
2135.59	964.155
2138.49	981.255
2141.38	968.356
2144.27	984.79
2147.16	973.223
2150.05	963.657
2152.94	990.758
2155.83	963.858
2158.72	956.292
2161.6	968.726
2164.49	963.826
2167.37	970.926
2170.26	986.694
2173.14	995.794
2176.02	958.228
2178.9	976.661
2181.77	959.762
2184.65	950.196
2187.53	969.296
2190.4	957.73
2193.28	951.497
2196.15	965.264
2199.02	949.698
2201.89	960.132
2204.76	956.565
2207.63	956.999
2210.5	954.766
2213.37	951.2
2216.23	950.967
2219.1	930.068
2221.96	935.168
2224.82	948.935
2227.69	930.035
2230.55	947.802
2233.41	934.236
2236.26	913.337
2239.12	919.77
2241.98	930.871
2244.83	906.638
2247.69	904.405
2250.54	904.172
2253.39	900.606
2256.24	899.706
2259.09	922.14
2261.94	908.574
2264.79	889.008
2267.64	911.441
2270.49	890.542
2273.33	894.976
2276.18	880.076
2279.02	913.176
2281.86	918.277
2284.7	914.044
2287.54	877.144
2290.38	907.578
2293.22	910.012
2296.05	895.779
2298.89	886.879
2301.72	895.313
2304.56	886.414
2307.39	900.847
2310.22	889.948
2313.05	903.048
2315.88	914.815
2318.71	891.916
2321.54	893.683
2324.36	894.783
2327.19	914.55
2330.01	908.984
2332.84	916.085
2335.66	919.185
2338.48	892.285
2341.3	903.386
2344.12	887.82
2346.94	894.253
2349.76	894.021
2352.57	894.454
2355.39	886.888
2358.2	898.655
2361.02	898.422
2363.83	880.189
2366.64	883.956
2369.45	887.724
2372.26	888.157
2375.07	895.924
2377.87	859.691
2380.68	872.792
2383.49	857.892
2386.29	870.326
2389.09	866.093
2391.9	861.86
2394.7	857.627
2397.5	868.061
2400.29	853.161
2403.09	854.262
2405.89	846.029
2408.69	865.13
2411.48	863.563
2414.28	856.664
2417.07	847.764
2419.86	860.198
2422.65	859.965
2425.44	852.399
2428.23	874.166
2431.02	860.6
2433.81	845.033
2436.59	858.8
2439.38	866.568
2442.16	867.001
2444.94	858.768
2447.73	876.536
2450.51	870.303
2453.29	875.403
2456.07	880.503
2458.84	865.604
2461.62	873.371
2464.4	881.805
2467.17	863.572
2469.95	868.006
2472.72	851.773
2475.49	854.206
2478.26	875.307
2481.03	874.407
2483.8	883.508
2486.57	840.608
2489.34	852.375
2492.1	880.142
2494.87	866.576
2497.63	850.343
2500.39	884.11
2503.16	849.877
2505.92	859.644
2508.68	872.745
2511.44	883.845
2514.19	848.946
2516.95	819.38
2519.71	840.48
2522.46	857.58
2525.22	850.014
2527.97	857.115
2530.72	828.215
2533.47	843.315
2536.22	849.083
2538.97	834.85
2541.72	845.95
2544.47	819.051
2547.21	838.151
2549.96	831.251
2552.7	813.018
2555.45	816.786
2558.19	831.219
2560.93	835.653
2563.67	832.754
2566.41	824.521
2569.15	808.954
2571.89	837.388
2574.62	841.822
2577.36	835.589
2580.09	845.356
2582.83	821.79
2585.56	825.557
2588.29	847.991
2591.02	836.424
2593.75	810.192
2596.48	838.625
2599.21	840.392
2601.93	850.159
2604.66	830.593
2607.39	835.694
2610.11	856.794
2612.83	847.228
2615.55	852.995
2618.27	857.429
2620.99	857.863
2623.71	836.296
2626.43	845.397
2629.15	846.497
2631.86	864.264
2634.58	850.698
2637.29	831.798
2640.01	802.232
2642.72	842.666
2645.43	827.1
2648.14	831.534
2650.85	838.634
2653.56	841.068
2656.26	828.168
2658.97	832.602
2661.68	857.702
2664.38	822.136
2667.09	816.57
2669.79	829.67
2672.49	830.104
2675.19	841.204
2677.89	827.638
2680.59	838.072
2683.29	820.506
2685.98	852.94
2688.68	816.04
2691.37	822.474
2694.07	800.907
2696.76	806.675
2699.45	816.442
2702.14	797.542
2704.83	823.976
2707.52	801.076
2710.21	823.51
2712.9	816.61
2715.58	803.711
2718.27	808.811
2720.95	828.578
2723.64	825.679
2726.32	834.779
2729	828.546
2731.68	821.647
2734.36	809.414
2737.04	821.848
2739.72	833.615
2742.39	830.048
2745.07	819.816
2747.74	853.583
2750.42	824.683
2753.09	814.45
2755.76	825.551
2758.43	827.984
2761.1	846.418
2763.77	819.519
2766.44	803.952
2769.11	833.053
2771.78	831.487
2774.44	834.587
2777.11	843.687
2779.77	838.788
2782.43	828.555
2785.09	832.989
2787.76	813.422
2790.41	818.523
2793.07	854.29
2795.73	840.057
2798.39	830.491
2801.04	812.258
2803.7	824.025
2806.35	813.792
2809.01	802.893
2811.66	812.66
2814.31	803.093
2816.96	809.527
2819.61	826.628
2822.26	813.728
2824.91	821.495
2827.55	823.929
2830.2	809.696
2832.84	816.796
2835.49	823.23
2838.13	820.997
2840.77	833.431
2843.41	812.531
2846.05	840.298
2848.69	830.066
2851.33	790.499
2853.97	785.6
2856.6	817.367
2859.24	835.801
2861.87	814.234
2864.51	850.668
2867.14	801.769
2869.77	827.536
2872.4	805.303
2875.03	827.737
2877.66	812.837
2880.29	824.604
2882.92	825.038
2885.54	848.138
2888.17	827.239
2890.79	830.339
2893.42	849.44
2896.04	843.873
2898.66	837.64
2901.28	826.074
2903.9	827.841
2906.52	822.942
2909.14	837.375
2911.76	815.143
2914.37	831.576
2916.99	835.343
2919.6	819.776
2922.21	832.61
2924.83	812.109
2927.44	827.537
2930.05	830.362
2932.66	801.13
2935.27	821.657
2937.88	804.198
2940.48	810.371
2943.09	812.446
2945.69	809.89
2948.3	780.237
2950.9	796.272
2953.5	780.392
2956.1	805.997
2958.7	779.253
2961.3	782.132
2963.9	772.322
2966.5	769.609
2969.1	776.232
2971.69	751.415
2974.29	747.7
2976.88	756.039
2979.48	770.072
2982.07	759.286
2984.66	748.951
2987.25	766.939
2989.84	758.765
2992.43	742.569
2995.02	756.065
2997.6	749.773
3000.19	756.18
3002.77	735.378
3005.36	734.123
3007.94	723.057
3010.53	726.653
3013.11	714.41
3015.69	724.984
3018.27	725.533
3020.85	727.301
3023.42	726.289
3026	722.368
3028.58	730.814
3031.15	735.13
3033.73	715.298
3036.3	729.138
3038.87	717.153
3041.44	728.218
3044.01	723.044
3046.58	703.053
3048.04	714.634
3050.62	727.464
3053.2	715.627
3055.77	706.457
3058.35	713.954
3060.93	721.451
3063.51	715.614
3066.08	722.444
3068.66	719.941
3071.23	710.104
3073.8	702.267
3076.37	723.764
3078.94	711.927
3081.51	713.424
3084.08	719.587
3086.65	707.75
3089.22	727.914
3091.78	718.743
3094.35	718.907
3096.91	697.07
3099.48	706.567
3102.04	708.73
3104.6	722.893
3107.16	714.39
3109.72	707.886
3112.28	713.383
3114.84	700.213
3117.4	708.376
3119.96	709.206
3122.51	707.37
3125.07	714.866
3127.62	716.363
3130.18	709.859
3132.73	704.023
3135.28	712.186
3137.83	717.683
3140.38	715.179
3142.93	693.343
3145.47	724.173
3148.02	723.669
3150.57	700.499
3153.11	711.329
3155.66	734.159
3158.2	713.656
3160.74	702.486
3163.28	724.649
3165.83	715.479
3168.37	722.975
3170.91	709.805
3173.44	723.302
3175.98	726.799
3178.52	728.962
3181.05	711.125
3183.59	706.622
3186.12	701.452
3188.66	716.282
3191.19	718.445
3193.72	711.275
3196.25	728.772
3198.78	698.935
3201.31	711.098
3203.84	689.262
3206.36	687.425
3208.89	698.921
3211.41	713.751
3213.94	711.248
3216.46	708.745
3218.99	704.241
3221.51	693.071
3224.03	709.901
3226.55	701.398
3229.07	692.228
3231.59	688.391
3234.1	717.221
3236.62	697.384
3239.13	682.881
3241.65	695.044
3244.16	684.541
3246.68	680.704
3249.19	699.534
3251.7	685.031
3254.21	709.861
3256.72	697.357
3259.23	687.521
3261.74	695.017
3264.25	705.18
3266.75	688.01
3269.26	676.174
3271.76	695.67
3274.27	687.834
3276.77	685.33
3279.27	688.16
3281.77	696.99
3284.27	696.487
3286.77	679.317
3289.27	704.813
3291.77	692.31
3294.27	679.807
3296.76	695.303
3299.26	674.133
3301.75	704.963
3304.24	699.793
3306.74	683.956
3309.23	698.786
3311.72	692.283
3314.21	683.78
3316.7	677.276
3319.19	692.106
3321.68	674.936
3324.16	673.099
3326.65	677.263
3329.13	690.759
3331.62	669.589
3334.1	676.419
3336.58	672.583
3339.07	692.746
3341.55	668.909
3344.03	671.739
3346.51	671.902
3348.99	688.732
3351.46	679.562
3353.94	682.392
3356.42	687.222
3358.89	671.385
3361.36	668.215
3363.84	687.712
3366.31	671.209
3368.78	653.372
3371.25	654.202
3373.72	663.032
3376.19	658.529
3378.66	662.692
3381.13	648.855
3383.59	653.685
3386.06	651.848
3388.52	648.678
3390.99	644.175
3393.45	662.338
3395.91	650.502
3398.38	658.665
3400.84	656.161
3403.3	667.658
3405.76	651.821
3408.21	662.651
3410.67	640.148
3413.13	644.978
3415.58	638.474
3418.04	658.638
3420.49	658.801
3422.95	653.631
3425.4	647.794
3427.85	645.291
3430.3	640.121
3432.75	655.618
3435.2	649.781
3437.65	639.277
3440.1	652.774
3442.54	652.271
3444.99	644.434
3447.43	663.264
3449.88	651.427
3452.32	640.257
3454.76	657.754
3457.21	646.584
3459.65	652.08
3462.09	662.244
3464.53	643.074
3466.96	635.237
3469.4	636.067
3471.84	643.563
3474.27	636.393
3476.71	637.223
3479.14	610.053
3481.58	645.55
3484.01	632.38
3486.44	628.543
3488.87	646.04
3491.3	619.536
3493.73	639.033
3496.16	627.863
3498.59	638.693
3501.01	622.19
3503.44	629.02
3505.87	600.516
3508.29	614.013
3510.71	614.176
3513.14	598.339
3515.56	603.169
3517.98	602.666
3520.4	576.829
3522.82	588.326
3525.24	597.823
3527.66	588.652
3530.07	582.816
3532.49	583.646
3534.9	591.809
3537.32	598.639
3539.73	572.135
3542.15	578.966
3544.56	599.796
3546.97	575.959
3549.38	585.455
3551.79	576.952
3554.2	603.782
3556.61	573.279
3559.02	576.109
3561.42	573.605
3563.83	569.768
3566.23	569.265
3568.64	583.428
3571.04	579.592
3573.44	565.088
3575.84	571.918
3578.25	578.082
3580.65	572.245
3583.04	566.408
3585.44	569.905
3587.84	591.401
3590.24	572.898
3592.63	581.061
3595.03	549.891
3597.42	566.055
3599.82	556.218
3602.21	563.714
3604.6	571.211
3606.99	572.041
3609.38	588.204
3611.77	569.034
3614.16	570.531
3616.55	552.027
3618.94	558.191
3621.32	567.687
3623.71	558.517
3626.09	564.014
3628.48	552.177
3630.86	561.674
3633.24	560.504
3635.63	552.667
3638.01	542.164
3640.39	546.994
3642.77	544.49
3645.15	537.987
3647.52	558.817
3649.9	534.98
3652.28	541.143
3654.65	551.307
3657.03	548.803
3659.4	550.3
3661.77	545.13
3664.14	535.96
3666.52	532.123
3668.89	535.62
3671.25	545.116
3673.62	519.946
3675.99	525.443
3678.36	531.606
3680.73	521.103
3683.09	535.933
3685.46	516.096
3687.82	516.26
3690.19	513.089
3692.55	494.586
3694.91	527.416
3697.27	496.246
3699.63	512.409
3701.99	497.239
3704.35	510.069
3706.71	499.566
3709.06	507.062
3711.42	499.226
3713.78	503.389
3716.13	492.886
3718.48	491.049
3720.84	503.879
3723.19	508.042
3725.54	494.872
3727.89	489.035
3730.24	497.865
3732.59	491.362
3734.94	504.192
3737.29	493.689
3739.64	487.852
3741.98	510.015
3744.33	498.178
3746.67	500.342
3749.02	503.172
3751.36	505.335
3753.7	493.498
3756.04	514.328
3758.38	506.492
3760.72	485.988
3763.06	498.818
3765.4	480.315
3767.74	501.145
3770.08	485.975
3772.41	496.805
3774.75	482.968
3777.08	502.465
3779.41	491.294
3781.75	490.791
3784.08	496.288
3786.41	503.118
3788.74	475.948
3791.07	482.111
3793.4	490.274
3795.73	479.771
3798.06	471.934
3800.38	494.764
3802.71	488.261
3805.03	475.757
3807.36	467.254
3809.68	480.084
3812.01	466.247
3814.33	472.41
3816.65	479.24
3818.97	453.404
3821.29	456.234
3823.61	462.397
3825.93	461.894
3828.24	439.39
3830.56	450.887
3832.88	459.717
3835.19	447.213
3837.51	452.043
3839.82	452.207
3842.13	442.37
3844.45	443.867
3846.76	461.363
3849.07	437.526
3851.38	427.69
3853.69	430.52
3856	454.016
3858.3	440.846
3860.61	436.343
3862.92	443.84
3865.22	441.336
3867.53	447.499
3869.83	433.663
3872.13	442.493
3874.43	427.989
3876.74	433.486
3879.04	418.983
3881.34	442.479
3883.64	432.642
3885.93	446.806
3888.23	428.969
3890.53	437.132
3892.83	448.629
3895.12	436.126
3897.41	452.956
3899.71	429.119
3902	435.282
3904.29	432.779
3906.59	438.942
3908.88	451.105
3911.17	441.935
3913.46	421.432
3915.75	434.262
3918.03	428.425
3920.32	429.922
3922.61	420.085
3924.89	440.248
3927.18	450.412
3929.46	433.242
3931.74	433.405
3934.03	416.235
3936.31	428.398
3938.59	432.561
3940.87	414.058
3943.15	434.221
3945.43	425.718
3947.71	414.548
3949.98	416.045
3952.26	422.208
3954.54	401.704
3956.81	405.201
3959.09	408.031
3961.36	414.861
3963.63	417.024
3965.9	399.188
3968.18	409.351
3970.45	410.847
3972.72	382.344
3974.99	394.507
3977.25	401.337
3979.52	390.167
3981.79	387.664
3984.05	385.827
3986.32	384.657
3988.58	389.487
3990.85	397.65
3993.11	385.147
3995.37	381.977
3997.64	381.474
3999.9	378.304