File: muestras/manzana/mz_33.txt
#Acq. time (s)=	15
#Accumulations=	4
#Range (cm-¹)=	50...4000
#Windows=	3
#Autofocus=	Off
#AutoExposure=	Off
#Spike filter=	Multiple accum.
#Delay time (s)=	0
#Binning=	1
#Readout mode=	Signal
#DeNoise=	Off
#ICS correction=	Off
#Dark correction=	Off
#Inst. Process=	Off
#Instrument=	LabRAM HR Evol
#Detector=	Syncerity OE
#Objective=	x100_VIS
#Grating=	600 (500nm)
#ND Filter=	5%
#Laser=	532nm_Edge
#Hole=	100.021
#Range=	Visible
#Project=	Omar
#Sample=	120523
#Site=	ap
#Title=	mz
#Remark=	5 laser intensity
#Date=	12.05.2023 17:28
#Acquired=	12.05.2023 17:28:58
51.0297	18.6667
54.7185	32.5642
58.406	33.1283
62.0919	59.0258
65.7765	87.59
69.4595	121.488
73.1412	164.052
76.8214	193.949
80.5001	216.513
84.1774	249.744
87.8532	260.975
91.5276	259.539
95.2006	263.437
98.8721	277.334
102.54	279.232
106.209	294.463
109.876	297.027
113.542	286.258
117.204	292.822
120.867	292.053
124.526	297.283
128.186	282.514
131.845	285.745
135.5	305.643
139.155	300.873
142.807	296.104
146.46	296.002
150.11	314.566
153.757	303.13
157.406	303.028
161.051	305.592
164.697	312.823
168.339	299.387
171.98	319.951
175.619	304.515
179.259	315.079
182.895	318.977
186.53	314.208
190.164	314.105
193.796	298.669
197.427	313.9
201.059	314.464
204.686	318.362
208.313	314.926
211.938	315.49
215.562	305.388
219.184	314.619
222.803	323.183
226.422	322.414
230.04	312.978
233.657	318.875
237.272	314.106
240.886	328.67
244.497	314.568
248.108	312.465
251.717	341.029
255.325	327.594
258.93	326.158
262.535	313.389
266.137	334.619
269.74	321.85
273.341	341.081
276.939	334.312
280.537	326.209
284.132	319.44
287.728	326.671
291.32	326.569
294.911	327.133
298.502	331.03
302.09	329.594
305.677	318.825
309.264	322.056
312.848	336.62
316.43	335.184
320.011	337.082
323.593	330.313
327.171	341.544
330.748	333.441
334.323	329.339
337.897	329.903
341.47	333.8
345.041	329.698
348.611	343.595
352.18	351.493
355.747	348.724
359.312	351.954
362.877	327.185
366.44	323.083
369.999	340.98
373.56	344.878
377.119	333.442
380.676	338.006
384.23	341.237
387.785	345.801
391.338	345.699
394.888	352.263
398.439	347.494
401.988	338.725
405.534	328.622
409.081	344.52
412.624	352.417
416.167	335.648
419.708	346.879
423.249	351.443
426.786	344.007
430.323	346.571
433.86	357.135
437.393	339.033
440.926	345.597
444.458	338.161
447.988	344.725
451.516	339.956
455.043	342.52
458.568	353.085
462.092	343.649
465.615	346.213
469.138	370.11
472.658	354.008
476.177	351.239
479.694	357.803
483.21	347.034
486.723	348.265
490.236	360.162
493.748	367.393
497.258	353.957
500.768	361.188
504.276	376.419
507.78	350.983
511.285	356.881
514.789	348.778
518.289	354.676
521.791	360.573
525.29	369.137
528.787	365.035
532.284	360.932
535.778	370.83
539.272	360.061
542.763	367.291
546.255	353.856
549.743	371.753
553.232	361.651
556.718	374.215
560.203	372.779
563.688	367.343
567.169	364.574
570.65	371.805
574.129	374.369
577.609	372.933
581.085	367.497
584.56	359.395
588.034	375.959
591.506	380.523
594.978	351.087
598.447	364.318
601.916	366.216
605.383	381.446
608.849	398.011
612.313	364.575
615.776	372.472
619.238	374.37
622.699	359.601
626.156	383.498
629.614	373.396
633.071	371.293
636.526	384.524
639.978	385.755
643.431	378.319
646.88	384.883
650.33	384.781
653.779	382.012
657.224	381.242
660.67	377.807
664.113	396.371
667.556	379.602
670.997	381.499
674.435	370.73
677.875	380.627
681.311	375.192
684.746	385.089
688.182	388.987
691.614	379.551
695.045	389.448
698.475	367.346
701.904	404.577
705.333	399.807
708.759	381.038
712.183	394.936
715.606	367.5
719.028	395.397
722.449	381.295
725.868	389.192
729.286	391.09
732.703	371.654
736.117	384.218
739.531	390.782
742.944	384.013
746.355	387.911
749.766	394.475
753.173	389.706
756.581	385.603
759.987	394.167
763.39	390.065
766.794	404.629
770.195	393.86
773.596	395.758
776.994	391.655
780.393	394.219
783.788	388.117
787.185	378.014
790.578	386.578
793.971	381.809
797.362	382.373
800.751	393.604
804.138	392.835
807.527	402.066
810.912	385.297
814.296	396.528
817.679	383.758
821.06	392.989
824.441	397.553
827.822	399.451
831.199	404.015
834.576	399.913
837.951	392.477
841.323	409.041
844.695	394.938
848.066	394.836
851.436	387.4
854.805	407.298
858.173	400.528
861.539	385.093
864.902	404.323
868.266	394.888
871.628	396.785
874.987	388.016
878.347	409.247
881.704	397.811
885.061	402.375
888.418	390.939
891.771	382.837
895.122	392.734
898.475	392.632
901.824	385.196
905.174	387.093
908.52	393.658
911.866	384.889
915.212	399.453
918.555	397.35
921.896	386.581
925.237	394.479
928.576	395.043
931.914	396.94
935.253	404.171
938.588	399.402
941.922	419.966
945.255	390.53
948.587	399.761
951.917	398.325
955.244	396.889
958.572	397.454
961.899	410.684
965.225	389.249
968.549	395.146
971.872	397.71
975.192	401.608
978.512	388.839
981.831	404.736
985.148	399.967
988.464	388.531
991.778	404.429
995.092	403.659
998.404	388.89
1001.72	402.788
1005.02	399.352
1008.33	393.916
1011.64	407.147
1014.95	391.044
1018.25	407.609
1021.55	395.506
1024.85	416.07
1028.16	405.968
1031.46	391.199
1034.75	384.43
1038.05	394.327
1041.34	402.224
1044.64	384.789
1047.93	401.353
1051.22	391.25
1054.51	395.815
1057.8	400.379
1061.09	396.943
1064.38	390.174
1067.66	414.071
1070.95	386.635
1074.23	407.2
1077.51	405.764
1080.79	398.328
1084.07	397.559
1087.35	398.123
1090.62	408.687
1093.9	407.251
1097.17	392.482
1100.44	389.046
1103.71	402.944
1106.99	404.841
1110.25	392.739
1113.52	398.636
1116.79	403.2
1120.05	395.765
1123.31	408.995
1126.58	393.56
1129.84	391.457
1133.1	398.688
1136.36	389.252
1139.61	391.15
1142.87	408.38
1146.12	390.278
1149.38	402.175
1152.63	404.74
1155.88	421.304
1159.13	423.868
1162.38	398.432
1165.63	406.996
1168.87	396.894
1172.12	408.791
1175.36	391.355
1178.6	391.253
1181.84	399.151
1185.08	394.381
1188.32	402.279
1191.56	404.176
1194.79	406.741
1198.03	391.305
1201.26	395.869
1204.49	395.766
1207.72	388.997
1210.95	404.228
1214.18	386.126
1217.41	417.356
1220.64	394.587
1223.86	395.818
1227.08	405.716
1230.3	360.946
1233.53	398.844
1236.75	408.741
1239.96	385.306
1243.18	401.87
1246.4	392.434
1249.61	397.665
1252.82	397.562
1256.04	404.793
1259.25	383.357
1262.46	400.588
1265.67	396.486
1268.87	398.383
1272.08	402.947
1275.28	392.845
1278.49	399.409
1281.69	399.306
1284.89	403.871
1288.09	404.768
1291.29	402.332
1294.49	426.23
1297.68	394.127
1300.88	404.691
1304.07	404.589
1307.26	398.486
1310.46	409.717
1313.65	389.615
1316.84	399.512
1320.02	393.41
1323.21	404.641
1326.39	399.872
1329.58	398.436
1332.76	415
1335.94	400.897
1339.12	398.795
1342.3	412.692
1345.48	389.923
1348.65	410.487
1351.83	396.385
1355	407.616
1358.18	396.18
1361.35	390.077
1364.52	408.642
1367.69	393.206
1370.86	383.103
1374.02	408.334
1377.19	387.565
1380.35	402.796
1383.52	409.36
1386.68	403.257
1389.84	389.155
1393	385.052
1396.16	388.283
1399.31	398.181
1402.47	420.745
1405.63	411.976
1408.78	403.873
1411.93	394.437
1415.08	415.002
1418.23	422.232
1421.38	405.463
1424.53	408.027
1427.68	423.925
1430.82	391.156
1433.96	422.387
1437.11	411.618
1440.25	408.848
1443.39	410.746
1446.53	399.977
1449.67	400.541
1452.8	423.772
1455.94	399.003
1459.07	400.9
1462.21	406.131
1465.34	402.028
1468.47	395.926
1471.6	392.49
1474.72	397.054
1477.85	394.952
1480.98	393.516
1484.1	391.413
1487.23	404.644
1490.35	405.875
1493.47	407.773
1496.59	402.337
1499.71	407.568
1502.83	408.132
1505.94	400.029
1509.06	419.927
1512.17	402.491
1515.29	404.388
1518.4	430.953
1521.51	426.183
1524.62	423.414
1527.72	435.312
1530.83	423.209
1533.94	417.773
1537.04	412.338
1540.15	410.235
1543.25	405.466
1546.35	421.363
1549.45	398.594
1552.55	409.825
1555.65	410.389
1558.74	417.62
1561.84	405.518
1564.93	407.415
1568.02	409.979
1571.12	408.543
1574.2	403.108
1577.3	402.339
1580.38	401.569
1583.47	415.467
1586.56	386.698
1589.64	405.929
1592.72	408.493
1595.81	417.724
1598.89	395.621
1601.97	399.519
1605.05	396.083
1608.12	408.987
1611.2	405.59
1614.27	392.274
1617.35	393.891
1620.42	400.81
1623.5	390.123
1626.57	399.602
1629.63	398.348
1632.7	398.679
1635.77	391.35
1638.84	395.452
1641.9	390.952
1644.97	407.634
1648.03	389.44
1651.09	386.627
1654.15	393.028
1657.21	401.679
1660.27	406.448
1663.32	407.834
1666.38	394.329
1669.43	416.13
1672.49	397.933
1675.54	398.555
1678.59	401.177
1681.64	395.834
1684.69	399.376
1687.73	408.392
1690.78	394.787
1693.83	396.915
1696.87	399.821
1699.91	405.62
1702.96	402.148
1706	396.962
1709.04	399.355
1712.07	407.934
1715.11	397.218
1718.15	386.396
1721.18	395.368
1724.21	401.851
1727.25	386.713
1730.28	390.607
1733.31	377.624
1736.34	393.922
1739.37	407.928
1742.39	395.253
1745.42	391.848
1748.45	389.612
1751.47	389.182
1754.49	382.328
1757.51	393.088
1759.25	361.559
1762.28	368.153
1765.31	385.414
1768.34	392.008
1771.37	392.602
1774.4	391.196
1777.43	390.456
1780.46	393.05
1783.48	379.644
1786.51	382.238
1789.53	394.832
1792.55	382.759
1795.57	392.02
1798.59	393.947
1801.61	395.874
1804.63	373.135
1807.64	395.062
1810.66	384.989
1813.67	388.25
1816.68	386.177
1819.7	371.438
1822.71	384.698
1825.72	390.626
1828.72	394.553
1831.73	401.147
1834.74	373.741
1837.74	386.335
1840.75	393.595
1843.75	396.856
1846.75	392.117
1849.75	383.377
1852.75	395.971
1855.75	381.232
1858.75	383.826
1861.74	379.753
1864.74	397.68
1867.73	376.274
1870.72	384.201
1873.71	376.795
1876.7	388.056
1879.69	391.983
1882.68	377.244
1885.67	387.838
1888.66	387.765
1891.64	396.359
1894.62	368.953
1897.61	380.213
1900.59	372.141
1903.57	384.734
1906.55	370.662
1909.53	395.256
1912.5	393.85
1915.48	379.777
1918.46	389.037
1921.43	379.631
1924.4	377.559
1927.37	366.819
1930.34	381.413
1933.31	376.674
1936.28	395.934
1939.25	376.528
1942.22	384.455
1945.18	381.716
1948.14	383.643
1951.11	385.571
1954.07	386.831
1957.03	372.758
1959.99	388.686
1962.95	382.613
1965.91	381.874
1968.86	371.801
1971.82	358.395
1974.77	380.322
1977.73	383.583
1980.68	374.177
1983.63	378.104
1986.58	376.698
1989.53	369.292
1992.47	375.219
1995.42	380.479
1998.37	373.74
2001.31	364.334
2004.25	372.928
2007.2	356.855
2010.14	384.782
2013.08	371.376
2016.02	375.97
2018.96	367.898
2021.89	360.491
2024.83	371.085
2027.76	373.679
2030.7	373.607
2033.63	363.534
2036.56	370.128
2039.49	360.722
2042.42	380.649
2045.35	363.243
2048.28	369.17
2051.2	365.764
2054.13	381.025
2057.05	380.285
2059.97	370.213
2062.9	378.806
2065.82	379.4
2068.74	368.661
2071.65	375.255
2074.57	369.849
2077.49	375.776
2080.4	379.703
2083.32	358.297
2086.23	370.891
2089.15	357.485
2092.05	364.079
2094.97	357.34
2097.87	361.267
2100.78	354.527
2103.69	351.121
2106.6	355.049
2109.5	375.643
2112.4	357.57
2115.31	355.497
2118.21	360.758
2121.11	346.685
2124.01	366.612
2126.91	339.873
2129.8	365.8
2132.7	356.394
2135.59	347.655
2138.49	366.249
2141.38	342.176
2144.27	344.77
2147.16	358.697
2150.05	340.624
2152.94	355.885
2155.83	348.479
2158.72	360.406
2161.6	346.333
2164.49	352.927
2167.37	360.854
2170.26	360.782
2173.14	363.376
2176.02	354.636
2178.9	352.564
2181.77	356.491
2184.65	353.751
2187.53	359.012
2190.4	352.273
2193.28	351.533
2196.15	340.794
2199.02	340.721
2201.89	349.982
2204.76	357.909
2207.63	337.169
2210.5	340.43
2213.37	335.691
2216.23	344.951
2219.1	330.212
2221.96	352.139
2224.82	331.4
2227.69	344.66
2230.55	345.254
2233.41	346.515
2236.26	355.109
2239.12	335.036
2241.98	333.63
2244.83	330.89
2247.69	339.484
2250.54	334.745
2253.39	316.672
2256.24	327.266
2259.09	343.193
2261.94	321.121
2264.79	327.048
2267.64	332.309
2270.49	328.236
2273.33	333.496
2276.18	347.424
2279.02	328.684
2281.86	331.278
2284.7	333.872
2287.54	321.799
2290.38	326.393
2293.22	312.987
2296.05	334.248
2298.89	333.508
2301.72	324.102
2304.56	332.696
2307.39	317.29
2310.22	333.884
2313.05	323.145
2315.88	332.405
2318.71	312.999
2321.54	322.26
2324.36	328.187
2327.19	323.448
2330.01	323.375
2332.84	325.969
2335.66	312.563
2338.48	319.823
2341.3	314.417
2344.12	311.678
2346.94	328.272
2349.76	334.199
2352.57	316.793
2355.39	313.387
2358.2	323.314
2361.02	311.908
2363.83	333.835
2366.64	321.096
2369.45	313.023
2372.26	331.617
2375.07	313.544
2377.87	318.805
2380.68	312.066
2383.49	319.993
2386.29	313.253
2389.09	296.514
2391.9	323.108
2394.7	316.369
2397.5	309.629
2400.29	314.89
2403.09	296.817
2405.89	313.411
2408.69	316.672
2411.48	313.932
2414.28	314.526
2417.07	314.453
2419.86	317.047
2422.65	318.308
2425.44	297.568
2428.23	306.162
2431.02	300.09
2433.81	319.35
2436.59	321.944
2439.38	316.538
2442.16	309.799
2444.94	309.726
2447.73	320.987
2450.51	322.247
2453.29	316.174
2456.07	312.768
2458.84	312.696
2461.62	313.289
2464.4	308.55
2467.17	313.144
2469.95	312.405
2472.72	323.665
2475.49	314.259
2478.26	316.186
2481.03	309.447
2483.8	313.374
2486.57	320.635
2489.34	299.895
2492.1	304.489
2494.87	307.083
2497.63	303.01
2500.39	323.604
2503.16	313.532
2505.92	312.126
2508.68	298.72
2511.44	315.98
2514.19	301.241
2516.95	304.501
2519.71	310.429
2522.46	311.689
2525.22	303.616
2527.97	293.544
2530.72	296.138
2533.47	300.732
2536.22	300.659
2538.97	303.919
2541.72	295.847
2544.47	301.107
2547.21	311.035
2549.96	306.962
2552.7	292.222
2555.45	312.15
2558.19	306.077
2560.93	306.004
2563.67	300.598
2566.41	298.525
2569.15	295.119
2571.89	313.047
2574.62	309.64
2577.36	301.568
2580.09	294.162
2582.83	294.089
2585.56	307.349
2588.29	287.277
2591.02	296.537
2593.75	305.131
2596.48	296.392
2599.21	298.986
2601.93	303.58
2604.66	298.84
2607.39	291.434
2610.11	300.028
2612.83	299.955
2615.55	305.883
2618.27	297.81
2620.99	292.404
2623.71	301.664
2626.43	296.258
2629.15	304.186
2631.86	309.446
2634.58	310.707
2637.29	289.967
2640.01	303.895
2642.72	290.489
2645.43	303.083
2648.14	297.01
2650.85	282.27
2653.56	302.198
2656.26	302.792
2658.97	296.052
2661.68	284.646
2664.38	293.24
2667.09	302.501
2669.79	301.761
2672.49	295.022
2675.19	296.949
2677.89	296.21
2680.59	286.804
2683.29	290.731
2685.98	296.658
2688.68	290.585
2691.37	291.179
2694.07	297.773
2696.76	287.7
2699.45	295.628
2702.14	300.888
2704.83	289.482
2707.52	294.076
2710.21	288.003
2712.9	286.597
2715.58	299.858
2718.27	301.119
2720.95	287.046
2723.64	276.973
2726.32	287.567
2729	297.494
2731.68	287.422
2734.36	289.349
2737.04	304.609
2739.72	293.87
2742.39	281.131
2745.07	290.391
2747.74	285.652
2750.42	294.912
2753.09	289.506
2755.76	288.1
2758.43	292.694
2761.1	285.955
2763.77	286.549
2766.44	289.143
2769.11	279.07
2771.78	278.33
2774.44	301.591
2777.11	279.518
2779.77	288.112
2782.43	284.039
2785.09	299.3
2787.76	285.894
2790.41	284.488
2793.07	280.415
2795.73	295.009
2798.39	287.603
2801.04	291.53
2803.7	284.124
2806.35	280.051
2809.01	281.979
2811.66	287.906
2814.31	269.167
2816.96	283.094
2819.61	278.354
2822.26	275.615
2824.91	282.209
2827.55	280.803
2830.2	282.73
2832.84	282.657
2835.49	286.585
2838.13	280.512
2840.77	282.439
2843.41	279.033
2846.05	258.96
2848.69	277.554
2851.33	269.482
2853.97	280.075
2856.6	278.003
2859.24	278.597
2861.87	281.857
2864.51	295.784
2867.14	287.712
2869.77	287.639
2872.4	262.9
2875.03	288.16
2877.66	268.754
2880.29	292.015
2882.92	289.942
2885.54	278.536
2888.17	270.463
2890.79	279.057
2893.42	274.318
2896.04	276.912
2898.66	278.839
2901.28	282.099
2903.9	279.36
2906.52	275.954
2909.14	283.881
2911.76	289.142
2914.37	279.736
2916.99	283.663
2919.6	270.257
2922.21	271.518
2924.83	262.111
2927.44	273.372
2930.05	279.299
2932.66	272.56
2935.27	280.487
2937.88	270.414
2940.48	263.008
2943.09	269.602
2945.69	269.53
2948.3	282.79
2950.9	272.717
2953.5	251.311
2956.1	267.239
2958.7	266.499
2961.3	274.426
2963.9	270.354
2966.5	266.281
2969.1	270.208
2971.69	268.802
2974.29	270.063
2976.88	262.657
2979.48	265.251
2982.07	258.511
2984.66	273.772
2987.25	269.032
2989.84	259.626
2992.43	274.887
2995.02	260.814
2997.6	262.075
3000.19	263.335
3002.77	264.596
3005.36	249.857
3007.94	269.117
3010.53	249.044
3013.11	256.972
3015.69	260.899
3018.27	262.159
3020.85	266.087
3023.42	254.681
3026	250.608
3028.58	264.535
3031.15	255.129
3033.73	241.056
3036.3	251.65
3038.87	265.578
3041.44	248.171
3044.01	246.099
3046.58	256.693
3047.87	253.323