File: muestras/suculenta_dedo/inside_pr_02.txt
#Acq. time (s)=	10
#Accumulations=	1
#Range (cm-¹)=	200...3000
#Windows=	3
#Autofocus=	Off
#AutoExposure=	Off
#Spike filter=	Off
#Delay time (s)=	0
#Binning=	1
#Readout mode=	Signal
#DeNoise=	Off
#ICS correction=	Off
#Dark correction=	Off
#Inst. Process=	Off
#Instrument=	LabRAM HR Evol
#Detector=	Syncerity OE
#Objective=	x100_VIS
#Grating=	600 (500nm)
#ND Filter=	0.01%
#Laser=	633nm_Edge
#Hole=	30.0125
#Range=	Visible
#Project=	Omar
#Sample=	03-07-23
#Site=	fings
#Title=	inside_pr
#Remark=
#Date=	03.07.2023 14:57
#Acquired=	03.07.2023 14:57:05
201.713	42
204.247	40
206.778	40
209.311	34
211.84	32
214.371	32
216.899	36
219.428	38
221.955	30
224.482	32
227.007	32
229.531	28
232.055	36
234.579	32
237.1	34
239.621	22
242.141	32
244.661	34
247.179	26
249.698	30
252.215	30
254.731	32
257.246	36
259.761	34
262.273	38
264.786	32
267.298	34
269.809	32
272.319	36
274.828	34
277.336	32
279.844	36
282.351	46
284.855	36
287.361	36
289.866	32
292.368	26
294.871	40
297.372	26
299.873	34
302.372	32
304.872	32
307.37	28
309.866	44
312.364	36
314.859	36
317.353	36
319.848	32
322.341	38
324.833	38
327.324	42
329.814	44
332.304	42
334.792	44
337.28	42
339.767	34
342.254	38
344.739	34
347.224	38
349.708	42
352.191	40
354.673	40
357.155	42
359.634	36
362.114	40
364.593	30
367.07	46
369.548	40
372.024	36
374.499	32
376.974	34
379.447	38
381.92	42
384.392	50
386.864	38
389.333	44
391.802	48
394.272	46
396.739	38
399.206	50
401.673	40
404.138	44
406.602	42
409.066	42
411.528	48
413.99	44
416.451	40
418.911	48
421.371	42
423.83	40
426.288	42
428.745	50
431.201	44
433.657	46
436.111	50
438.565	44
441.017	42
443.469	52
445.921	52
448.37	52
450.821	48
453.27	46
455.717	48
458.165	44
460.61	46
463.056	48
465.5	54
467.945	50
470.387	52
472.829	46
475.271	48
477.711	58
480.15	50
482.589	50
485.027	50
487.465	56
489.901	52
492.337	54
494.771	56
497.205	54
499.638	54
502.07	52
504.502	48
506.933	50
509.363	52
511.792	56
514.219	60
516.647	60
519.073	52
521.5	54
523.924	52
526.348	46
528.772	56
531.194	50
533.616	44
536.036	58
538.457	46
540.875	58
543.294	56
545.712	52
548.128	54
550.545	64
552.959	64
555.373	60
557.788	60
560.2	56
562.612	58
565.023	60
567.433	48
569.843	48
572.251	66
574.659	56
577.066	62
579.472	58
581.878	52
584.283	60
586.687	52
589.09	64
591.493	64
593.893	72
596.294	64
598.694	68
601.093	74
603.491	68
605.889	60
608.285	70
610.682	76
613.076	68
615.471	72
617.864	76
620.256	64
622.648	74
625.039	66
627.429	68
629.819	64
632.208	78
634.595	90
636.982	72
639.369	74
641.755	88
644.139	80
646.523	74
648.906	70
651.288	74
653.67	80
656.051	96
658.429	82
660.808	78
663.187	82
665.565	82
667.942	88
670.317	72
672.692	86
675.067	80
677.44	84
679.813	86
682.184	84
684.556	92
686.926	98
689.296	90
691.664	88
694.033	86
696.4	82
698.766	88
701.133	88
703.497	84
705.861	102
708.224	88
710.586	96
712.949	88
715.31	84
717.67	90
720.029	90
722.388	84
724.746	92
727.103	96
729.458	108
731.814	110
734.168	98
736.523	100
738.876	96
741.227	108
743.579	102
745.931	116
748.28	118
750.629	104
752.977	112
755.325	116
757.672	124
760.018	118
762.363	112
764.708	108
767.052	118
769.394	118
771.737	112
774.078	134
776.419	124
778.758	134
781.097	120
783.435	112
785.773	114
788.11	128
790.446	128
792.781	134
795.115	140
797.449	118
799.782	136
802.115	126
804.446	124
806.777	132
809.106	132
811.435	134
813.764	144
816.091	160
818.418	140
820.743	144
823.069	152
825.393	130
827.717	146
830.039	146
832.362	144
834.683	142
837.003	156
839.324	168
841.643	166
843.961	168
846.278	148
848.594	166
850.91	180
853.227	172
855.541	178
857.855	174
860.168	178
862.48	160
864.79	182
867.101	180
869.411	168
871.721	180
874.029	178
876.336	180
878.643	180
880.95	190
883.254	178
885.559	178
887.862	178
890.166	188
892.467	194
894.77	188
897.07	182
899.371	188
901.669	194
903.968	204
906.266	202
908.563	198
910.859	196
913.154	230
915.449	208
917.742	212
920.036	214
922.329	226
924.621	218
926.911	248
929.201	224
931.49	216
933.779	214
936.068	218
938.355	244
940.64	242
942.926	234
945.212	236
947.495	240
949.779	254
952.062	242
954.344	236
956.625	242
958.905	256
961.184	268
963.464	262
965.742	272
968.02	274
970.296	288
972.572	284
974.847	276
977.121	288
979.396	278
981.669	282
983.941	278
986.212	308
988.483	282
990.753	304
993.022	280
995.29	282
997.558	294
999.825	310
1002.09	322
1004.36	306
1006.62	294
1008.89	328
1011.15	316
1013.41	340
1015.67	348
1017.93	320
1020.19	330
1022.45	318
1024.71	344
1026.97	344
1029.23	338
1031.49	348
1033.74	334
1036	342
1038.25	374
1040.5	368
1042.76	354
1045.01	362
1047.26	358
1049.51	364
1051.76	382
1054.01	380
1056.26	384
1058.51	382
1060.75	384
1063	370
1065.25	388
1067.49	382
1069.73	400
1071.98	422
1074.22	440
1076.46	438
1078.7	422
1080.94	390
1083.18	440
1085.42	416
1087.66	412
1089.9	408
1092.14	402
1094.37	440
1096.61	424
1098.84	444
1101.08	422
1103.31	412
1105.54	432
1107.77	428
1110	454
1112.23	462
1114.46	442
1116.69	442
1118.92	414
1121.15	460
1123.37	456
1125.6	450
1127.83	448
1130.05	482
1132.27	474
1134.5	492
1136.72	460
1138.94	452
1141.16	466
1143.38	486
1145.6	486
1147.82	484
1150.04	482
1152.26	484
1154.47	514
1156.69	484
1158.9	528
1161.12	504
1163.33	498
1165.54	488
1167.76	508
1169.97	500
1172.18	520
1174.39	520
1176.6	502
1178.81	516
1181.02	516
1183.22	466
1185.43	518
1187.63	506
1189.84	508
1192.04	504
1194.25	500
1196.45	512
1198.65	500
1200.85	512
1203.05	506
1205.25	520
1207.45	504
1209.65	510
1211.85	510
1214.05	496
1216.24	502
1218.44	478
1220.64	498
1222.83	474
1225.02	484
1227.22	490
1229.41	466
1231.6	470
1233.79	484
1235.98	468
1238.17	466
1240.36	484
1242.55	492
1244.73	482
1246.92	476
1249.11	462
1251.29	450
1253.48	474
1255.66	458
1257.84	442
1260.03	458
1262.21	440
1264.39	448
1266.57	436
1268.75	440
1270.93	452
1273.11	428
1275.28	444
1277.46	422
1279.64	418
1281.81	428
1283.98	410.109
1286.16	431.847
1288.33	429.855
1290.5	453.779
1292.68	419.061
1294.85	419.183
1297.02	414.368
1299.19	404.47
1301.36	414.765
1303.53	411.736
1305.69	385.085
1307.86	383.069
1310.03	391.611
1312.19	389.611
1314.36	387.655
1316.52	371.823
1318.68	396.223
1320.85	366.989
1323.01	361.593
1325.17	358.12
1327.33	373.819
1329.49	344.628
1331.65	354.679
1333.81	357.639
1335.97	353.843
1338.12	359.828
1340.28	337.003
1342.44	348.766
1344.59	330.167
1346.75	339.366
1348.9	349.186
1351.05	342.856
1353.2	324.902
1355.36	314.752
1357.51	337.699
1359.66	317.42
1361.81	324.281
1363.96	307.425
1366.1	335.777
1368.25	321.316
1370.4	308.396
1372.54	305.016
1374.69	308.347
1376.83	294.287
1378.98	310.214
1381.12	309.125
1383.26	298.608
1385.41	301.7
1387.55	285.75
1389.69	302.796
1391.83	279.446
1393.02	278
1395.17	290
1397.32	288
1399.47	276
1401.62	272
1403.77	274
1405.91	248
1408.06	278
1410.2	276
1412.35	278
1414.49	276
1416.63	254
1418.78	266
1420.92	266
1423.06	258
1425.2	268
1427.34	258
1429.48	228
1431.61	238
1433.75	250
1435.89	250
1438.02	236
1440.16	258
1442.3	246
1444.43	252
1446.56	234
1448.7	262
1450.83	238
1452.96	248
1455.09	240
1457.22	228
1459.35	232
1461.48	248
1463.61	222
1465.73	240
1467.86	240
1469.98	246
1472.11	234
1474.24	224
1476.36	224
1478.48	224
1480.6	206
1482.73	216
1484.85	222
1486.97	222
1489.09	208
1491.21	200
1493.33	224
1495.44	206
1497.56	202
1499.68	222
1501.79	208
1503.91	200
1506.02	214
1508.14	206
1510.25	202
1512.36	202
1514.48	212
1516.59	198
1518.7	186
1520.81	190
1522.92	188
1525.02	200
1527.13	192
1529.24	208
1531.35	198
1533.45	188
1535.56	172
1537.66	190
1539.77	180
1541.87	176
1543.97	170
1546.08	198
1548.18	188
1550.28	186
1552.38	176
1554.48	188
1556.57	174
1558.67	186
1560.77	200
1562.87	174
1564.96	186
1567.06	180
1569.15	174
1571.25	170
1573.34	182
1575.43	162
1577.53	172
1579.62	178
1581.71	172
1583.8	164
1585.89	172
1587.98	170
1590.06	174
1592.15	172
1594.24	170
1596.33	176
1598.41	176
1600.5	170
1602.58	154
1604.66	170
1606.75	152
1608.83	164
1610.91	174
1612.99	162
1615.07	166
1617.15	168
1619.23	162
1621.31	170
1623.39	142
1625.46	176
1627.54	150
1629.62	154
1631.69	148
1633.77	164
1635.84	158
1637.91	144
1639.99	140
1642.06	178
1644.13	158
1646.2	162
1648.27	148
1650.34	148
1652.41	154
1654.47	158
1656.54	164
1658.61	174
1660.67	148
1662.74	148
1664.81	154
1666.87	152
1668.93	144
1671	152
1673.06	138
1675.12	150
1677.18	138
1679.24	132
1681.3	142
1683.36	142
1685.42	154
1687.47	146
1689.53	152
1691.59	134
1693.64	144
1695.7	160
1697.75	146
1699.81	138
1701.86	140
1703.91	142
1705.97	132
1708.02	150
1710.07	148
1712.12	130
1714.17	130
1716.22	136
1718.26	156
1720.31	158
1722.36	146
1724.4	142
1726.45	150
1728.49	144
1730.54	124
1732.58	144
1734.63	134
1736.67	134
1738.71	142
1740.75	142
1742.79	136
1744.83	142
1746.87	128
1748.91	136
1750.95	140
1752.98	160
1755.02	128
1757.06	130
1759.09	134
1761.13	136
1763.16	136
1765.19	144
1767.23	136
1769.26	144
1771.29	134
1773.32	148
1775.35	134
1777.38	136
1779.41	142
1781.44	136
1783.47	152
1785.49	134
1787.52	146
1789.55	144
1791.57	158
1793.6	144
1795.62	136
1797.64	134
1799.67	150
1801.69	134
1803.71	136
1805.73	136
1807.75	152
1809.77	132
1811.79	140
1813.81	132
1815.83	132
1817.84	150
1819.86	140
1821.88	124
1823.89	140
1825.91	134
1827.92	130
1829.93	130
1831.95	150
1833.96	132
1835.97	138
1837.98	136
1839.99	122
1842	142
1844.01	142
1846.02	126
1848.03	128
1850.03	136
1852.04	142
1854.05	134
1856.05	116
1858.06	136
1860.06	118
1862.06	134
1864.07	146
1866.07	132
1868.07	144
1870.07	116
1872.07	130
1874.07	134
1876.07	134
1878.07	134
1880.07	136
1882.07	114
1884.06	142
1886.06	120
1888.05	126
1890.05	136
1892.04	146
1894.04	132
1896.03	138
1898.02	122
1900.01	140
1902	130
1903.99	142
1905.98	136
1907.97	126
1909.96	120
1911.95	142
1913.94	132
1915.93	128
1917.91	136
1919.9	128
1921.88	124
1923.87	124
1925.85	138
1927.83	130
1929.82	136
1931.8	144
1933.78	130
1935.76	140
1937.74	124
1939.72	118
1941.7	136
1943.68	134
1945.65	134
1947.63	116
1949.61	136
1951.58	132
1953.56	126
1955.53	138
1957.51	132
1959.48	130
1961.45	118
1963.43	134
1965.4	126
1967.37	136
1969.34	136
1971.31	152
1973.28	118
1975.25	134
1977.22	126
1979.18	130
1981.15	126
1983.12	134
1985.08	128
1987.05	132
1989.01	138
1990.97	140
1992.94	120
1994.9	122
1996.86	140
1998.82	128
2000.78	120
2002.74	128
2004.7	122
2006.66	124
2008.62	134
2010.58	132
2012.54	138
2014.49	138
2016.45	118
2018.4	134
2020.36	140
2022.31	118
2024.27	140
2026.22	136
2028.17	122
2030.12	128
2032.07	124
2034.03	136
2035.98	114
2037.93	128
2039.87	128
2041.82	128
2043.77	126
2045.72	130
2047.66	122
2049.61	132
2051.55	128
2053.5	132
2055.44	134
2057.39	134
2059.33	120
2061.27	122
2063.21	134
2065.15	120
2067.09	130
2069.03	126
2070.97	116
2072.91	138
2074.85	142
2076.79	136
2078.73	130
2080.66	130
2082.6	124
2084.53	136
2086.47	128
2088.4	132
2090.33	128
2092.27	118
2094.2	124
2096.13	116
2098.06	142
2099.99	122
2101.92	130
2103.85	130
2105.78	130
2107.71	102
2109.64	120
2111.56	128
2113.49	124
2115.41	130
2117.34	132
2119.26	120
2121.19	130
2123.11	128
2125.03	114
2126.96	126
2128.88	126
2130.8	124
2132.72	128
2134.64	114
2136.56	126
2138.48	122
2140.4	126
2142.31	112
2144.23	134
2146.15	130
2148.06	140
2149.98	136
2151.89	136
2153.81	120
2155.72	126
2157.63	128
2159.55	128
2161.46	134
2163.37	118
2165.28	134
2167.19	126
2169.1	112
2171.01	114
2172.91	134
2174.82	132
2176.73	112
2178.64	128
2180.54	146
2182.45	126
2184.35	116
2186.26	110
2188.16	124
2190.06	130
2191.96	126
2193.87	128
2195.77	124
2197.67	122
2199.57	118
2201.47	124
2203.37	114
2205.27	124
2207.16	122
2209.06	122
2210.96	132
2212.85	122
2214.75	118
2216.64	118
2218.54	136
2220.43	122
2222.33	128
2224.22	137.618
2226.11	119.951
2228	126.191
2229.89	125.993
2231.78	135.218
2233.67	122.852
2235.56	118.15
2237.45	119.838
2239.34	125.94
2241.23	127.917
2243.11	128.606
2245	125.383
2246.89	132.47
2248.77	121.013
2250.66	125.567
2252.54	122.125
2254.42	128.451
2256.31	121.745
2258.19	119.637
2260.07	123.156
2261.95	123.534
2263.83	122.84
2265.71	122.927
2267.59	116.626
2269.47	122.458
2271.35	111.495
2273.23	125.18
2275.1	122.561
2276.98	116.078
2278.86	116.42
2280.73	114.933
2282.61	117.124
2284.48	121.739
2286.36	117.825
2288.23	117.234
2290.1	119.323
2291.98	114.994
2293.85	116.889
2295.72	117.746
2297.59	121.676
2299.46	118.636
2301.33	117.692
2303.2	122.302
2305.06	117.907
2306.93	119.198
2308.8	119.751
2310.67	114.037
2312.53	116.915
2314.4	112.017
2316.26	116.01
2317.62	118
2319.5	114
2321.37	130
2323.24	124
2325.12	112
2326.99	112
2328.86	120
2330.73	116
2332.6	132
2334.47	120
2336.34	118
2338.2	118
2340.07	106
2341.94	114
2343.81	112
2345.67	114
2347.54	124
2349.4	112
2351.27	120
2353.13	110
2354.99	116
2356.86	116
2358.72	112
2360.58	116
2362.44	98
2364.3	116
2366.16	118
2368.02	114
2369.88	100
2371.74	112
2373.6	108
2375.45	110
2377.31	110
2379.17	118
2381.02	114
2382.88	118
2384.73	112
2386.58	124
2388.44	122
2390.29	118
2392.14	106
2393.99	112
2395.85	116
2397.7	108
2399.55	98
2401.4	116
2403.25	114
2405.09	114
2406.94	98
2408.79	104
2410.63	110
2412.48	122
2414.33	118
2416.17	112
2418.02	110
2419.86	104
2421.7	114
2423.55	104
2425.39	92
2427.23	96
2429.07	98
2430.91	104
2432.75	112
2434.59	104
2436.43	108
2438.27	106
2440.11	106
2441.95	106
2443.78	108
2445.62	104
2447.46	100
2449.29	104
2451.13	90
2452.96	100
2454.79	112
2456.63	92
2458.46	124
2460.29	94
2462.12	98
2463.95	102
2465.78	92
2467.61	98
2469.44	106
2471.27	94
2473.1	108
2474.93	102
2476.76	90
2478.58	94
2480.41	92
2482.23	98
2484.06	96
2485.88	94
2487.71	94
2489.53	94
2491.35	96
2493.18	102
2495	108
2496.82	98
2498.64	92
2500.46	86
2502.28	98
2504.1	94
2505.92	100
2507.74	84
2509.55	96
2511.37	90
2513.19	90
2515	100
2516.82	98
2518.63	106
2520.45	102
2522.26	96
2524.07	90
2525.89	90
2527.7	96
2529.51	82
2531.32	90
2533.13	92
2534.94	94
2536.75	90
2538.56	90
2540.37	96
2542.18	86
2543.98	78
2545.79	98
2547.6	94
2549.4	80
2551.21	92
2553.01	94
2554.82	82
2556.62	86
2558.42	90
2560.23	94
2562.03	86
2563.83	86
2565.63	86
2567.43	88
2569.23	82
2571.03	84
2572.83	86
2574.63	78
2576.43	88
2578.22	78
2580.02	70
2581.82	80
2583.61	84
2585.41	88
2587.2	86
2589	80
2590.79	70
2592.58	80
2594.38	84
2596.17	92
2597.96	80
2599.75	76
2601.54	90
2603.33	80
2605.12	86
2606.91	82
2608.7	82
2610.49	80
2612.27	86
2614.06	84
2615.85	84
2617.63	78
2619.42	72
2621.2	72
2622.99	74
2624.77	74
2626.55	80
2628.34	80
2630.12	68
2631.9	72
2633.68	68
2635.46	82
2637.24	78
2639.02	78
2640.8	78
2642.58	80
2644.36	76
2646.14	72
2647.91	72
2649.69	72
2651.46	74
2653.24	80
2655.01	80
2656.79	68
2658.56	68
2660.34	74
2662.11	72
2663.88	72
2665.65	76
2667.42	72
2669.2	76
2670.96	74
2672.73	74
2674.5	68
2676.27	72
2678.04	68
2679.81	70
2681.58	64
2683.34	76
2685.11	76
2686.87	72
2688.64	66
2690.4	64
2692.17	76
2693.93	66
2695.69	74
2697.46	62
2699.22	66
2700.98	60
2702.74	66
2704.5	76
2706.26	62
2708.02	72
2709.78	74
2711.54	64
2713.3	62
2715.05	64
2716.81	64
2718.57	72
2720.32	60
2722.08	62
2723.83	66
2725.59	54
2727.34	58
2729.09	64
2730.85	62
2732.6	62
2734.35	56
2736.1	74
2737.85	62
2739.6	64
2741.35	64
2743.1	62
2744.85	58
2746.6	66
2748.35	66
2750.09	60
2751.84	58
2753.59	60
2755.33	56
2757.08	64
2758.82	56
2760.57	54
2762.31	58
2764.05	60
2765.79	58
2767.54	60
2769.28	56
2771.02	56
2772.76	56
2774.5	58
2776.24	60
2777.98	52
2779.72	70
2781.46	64
2783.19	52
2784.93	62
2786.67	62
2788.4	62
2790.14	70
2791.87	48
2793.61	56
2795.34	60
2797.07	60
2798.81	56
2800.54	54
2802.27	56
2804	54
2805.74	56
2807.47	54
2809.2	52
2810.93	54
2812.65	50
2814.38	58
2816.11	62
2817.84	58
2819.56	54
2821.29	58
2823.02	54
2824.74	58
2826.47	52
2828.19	56
2829.92	44
2831.64	58
2833.36	54
2835.09	56
2836.81	54
2838.53	46
2840.25	66
2841.97	48
2843.69	54
2845.41	48
2847.13	56
2848.85	60
2850.57	48
2852.28	56
2854	50
2855.72	46
2857.43	46
2859.15	54
2860.86	58
2862.58	50
2864.29	50
2866.01	50
2867.72	50
2869.43	58
2871.14	56
2872.86	56
2874.57	50
2876.28	42
2877.99	42
2879.7	48
2881.41	50
2883.11	52
2884.82	50
2886.53	54
2888.24	50
2889.94	38
2891.65	38
2893.36	60
2895.06	46
2896.77	50
2898.47	52
2900.17	44
2901.88	44
2903.58	46
2905.28	40
2906.98	56
2908.69	44
2910.39	48
2912.09	60
2913.79	40
2915.49	48
2917.19	54
2918.88	46
2920.58	48
2922.28	40
2923.98	48
2925.67	46
2927.37	40
2929.06	46
2930.76	48
2932.45	40
2934.15	40
2935.84	38
2937.53	48
2939.23	46
2940.92	48
2942.61	50
2944.3	36
2945.99	48
2947.68	42
2949.37	44
2951.06	38
2952.75	42
2954.44	40
2956.12	52
2957.81	46
2959.5	48
2961.18	48
2962.87	48
2964.56	48
2966.24	52
2967.92	50
2969.61	42
2971.29	42
2972.97	44
2974.66	42
2976.34	40
2978.02	40
2979.7	48
2981.38	44
2983.06	36
2984.74	38
2986.42	46
2988.1	44
2989.78	38
2991.45	44
2993.13	46
2994.81	44
2996.48	42
2998.16	30
2999.83	44