File: muestras/suculenta_dedo/inside_pr_13.txt
#Acq. time (s)=	10
#Accumulations=	1
#Range (cm-¹)=	200...3000
#Windows=	3
#Autofocus=	Off
#AutoExposure=	Off
#Spike filter=	Off
#Delay time (s)=	0
#Binning=	1
#Readout mode=	Signal
#DeNoise=	Off
#ICS correction=	Off
#Dark correction=	Off
#Inst. Process=	Off
#Instrument=	LabRAM HR Evol
#Detector=	Syncerity OE
#Objective=	x100_VIS
#Grating=	600 (500nm)
#ND Filter=	1%
#Laser=	633nm_Edge
#Hole=	30.0125
#Range=	Visible
#Project=	Omar
#Sample=	03-07-23
#Site=	fings
#Title=	inside_pr
#Remark=
#Date=	03.07.2023 15:10
#Acquired=	03.07.2023 15:10:08
201.713	54
204.247	52
206.778	50
209.311	52
211.84	48
214.371	54
216.899	48
219.428	54
221.955	54
224.482	48
227.007	48
229.531	56
232.055	58
234.579	44
237.1	56
239.621	50
242.141	44
244.661	38
247.179	52
249.698	50
252.215	64
254.731	56
257.246	52
259.761	54
262.273	66
264.786	42
267.298	50
269.809	58
272.319	54
274.828	58
277.336	62
279.844	54
282.351	58
284.855	64
287.361	58
289.866	60
292.368	58
294.871	64
297.372	54
299.873	54
302.372	54
304.872	60
307.37	56
309.866	64
312.364	54
314.859	66
317.353	66
319.848	62
322.341	64
324.833	72
327.324	60
329.814	58
332.304	82
334.792	70
337.28	70
339.767	70
342.254	64
344.739	64
347.224	70
349.708	66
352.191	70
354.673	68
357.155	68
359.634	74
362.114	78
364.593	70
367.07	72
369.548	60
372.024	84
374.499	78
376.974	74
379.447	70
381.92	68
384.392	86
386.864	78
389.333	78
391.802	72
394.272	70
396.739	76
399.206	82
401.673	84
404.138	78
406.602	76
409.066	82
411.528	88
413.99	86
416.451	76
418.911	90
421.371	84
423.83	88
426.288	88
428.745	92
431.201	104
433.657	90
436.111	100
438.565	96
441.017	90
443.469	90
445.921	90
448.37	94
450.821	92
453.27	98
455.717	96
458.165	96
460.61	100
463.056	102
465.5	110
467.945	98
470.387	106
472.829	90
475.271	104
477.711	102
480.15	96
482.589	104
485.027	96
487.465	104
489.901	104
492.337	104
494.771	110
497.205	124
499.638	102
502.07	116
504.502	122
506.933	114
509.363	200
511.792	176
514.219	2330
516.647	168
519.073	122
521.5	108
523.924	120
526.348	102
528.772	128
531.194	120
533.616	114
536.036	114
538.457	112
540.875	134
543.294	104
545.712	116
548.128	134
550.545	120
552.959	130
555.373	136
557.788	124
560.2	118
562.612	130
565.023	132
567.433	146
569.843	134
572.251	144
574.659	154
577.066	146
579.472	142
581.878	136
584.283	152
586.687	152
589.09	150
591.493	144
593.893	132
596.294	140
598.694	152
601.093	152
603.491	164
605.889	172
608.285	144
610.682	156
613.076	160
615.471	156
617.864	162
620.256	156
622.648	148
625.039	162
627.429	144
629.819	172
632.208	184
634.595	170
636.982	184
639.369	190
641.755	178
644.139	198
646.523	190
648.906	184
651.288	182
653.67	174
656.051	196
658.429	194
660.808	188
663.187	200
665.565	200
667.942	198
670.317	202
672.692	188
675.067	202
677.44	218
679.813	218
682.184	196
684.556	218
686.926	210
689.296	206
691.664	214
694.033	222
696.4	206
698.766	216
701.133	216
703.497	224
705.861	202
708.224	228
710.586	238
712.949	248
715.31	246
717.67	250
720.029	228
722.388	246
724.746	266
727.103	248
729.458	256
731.814	262
734.168	256
736.523	264
738.876	286
741.227	286
743.579	272
745.931	268
748.28	276
750.629	286
752.977	286
755.325	278
757.672	314
760.018	300
762.363	306
764.708	296
767.052	300
769.394	300
771.737	318
774.078	316
776.419	340
778.758	322
781.097	316
783.435	324
785.773	326
788.11	344
790.446	350
792.781	344
795.115	348
797.449	344
799.782	350
802.115	360
804.446	370
806.777	398
809.106	384
811.435	372
813.764	376
816.091	396
818.418	414
820.743	416
823.069	402
825.393	422
827.717	420
830.039	426
832.362	424
834.683	434
837.003	426
839.324	462
841.643	450
843.961	468
846.278	454
848.594	478
850.91	482
853.227	484
855.541	452
857.855	492
860.168	504
862.48	504
864.79	526
867.101	544
869.411	482
871.721	514
874.029	510
876.336	514
878.643	546
880.95	552
883.254	546
885.559	558
887.862	550
890.166	568
892.467	564
894.77	564
897.07	588
899.371	600
901.669	568
903.968	584
906.266	598
908.563	622
910.859	620
913.154	636
915.449	630
917.742	662
920.036	660
922.329	640
924.621	648
926.911	652
929.201	706
931.49	690
933.779	698
936.068	720
938.355	720
940.64	718
942.926	732
945.212	744
947.495	742
949.779	770
952.062	748
954.344	760
956.625	798
958.905	748
961.184	782
963.464	818
965.742	812
968.02	822
970.296	810
972.572	874
974.847	818
977.121	812
979.396	848
981.669	862
983.941	866
986.212	864
988.483	894
990.753	862
993.022	904
995.29	892
997.558	898
999.825	922
1002.09	918
1004.36	942
1006.62	956
1008.89	1004
1011.15	988
1013.41	956
1015.67	1016
1017.93	992
1020.19	1042
1022.45	1010
1024.71	1034
1026.97	1046
1029.23	1056
1031.49	1080
1033.74	1080
1036	1100
1038.25	1126
1040.5	1106
1042.76	1118
1045.01	1158
1047.26	1156
1049.51	1172
1051.76	1136
1054.01	1180
1056.26	1218
1058.51	1192
1060.75	1236
1063	1230
1065.25	1250
1067.49	1246
1069.73	1270
1071.98	1290
1074.22	1286
1076.46	1312
1078.7	1288
1080.94	1300
1083.18	1298
1085.42	1308
1087.66	1292
1089.9	1364
1092.14	1346
1094.37	1330
1096.61	1340
1098.84	1396
1101.08	1352
1103.31	1372
1105.54	1376
1107.77	1402
1110	1426
1112.23	1446
1114.46	1466
1116.69	1444
1118.92	1440
1121.15	1428
1123.37	1448
1125.6	1486
1127.83	1440
1130.05	1478
1132.27	1524
1134.5	1522
1136.72	1504
1138.94	1534
1141.16	1490
1143.38	1540
1145.6	1548
1147.82	1512
1150.04	1592
1152.26	1572
1154.47	1508
1156.69	1540
1158.9	1546
1161.12	1570
1163.33	1566
1165.54	1556
1167.76	1548
1169.97	1602
1172.18	1574
1174.39	1616
1176.6	1588
1178.81	1578
1181.02	1570
1183.22	1578
1185.43	1576
1187.63	1608
1189.84	1562
1192.04	1574
1194.25	1602
1196.45	1552
1198.65	1550
1200.85	1592
1203.05	1608
1205.25	1466
1207.45	1554
1209.65	1560
1211.85	1526
1214.05	1546
1216.24	1558
1218.44	1540
1220.64	1530
1222.83	1522
1225.02	1470
1227.22	1478
1229.41	1474
1231.6	1434
1233.79	1500
1235.98	1476
1238.17	1426
1240.36	1454
1242.55	1460
1244.73	1446
1246.92	1418
1249.11	1428
1251.29	1372
1253.48	1442
1255.66	1406
1257.84	1374
1260.03	1406
1262.21	1364
1264.39	1374
1266.57	1364
1268.75	1332
1270.93	1338
1273.11	1306
1275.28	1348
1277.46	1330
1279.64	1278
1281.81	1304
1283.98	1299.97
1286.16	1251.05
1288.33	1241.45
1290.5	1263.42
1292.68	1282.04
1294.85	1261.62
1297.02	1234.9
1299.19	1248.14
1301.36	1187.14
1303.53	1161.73
1305.69	1201.23
1307.86	1152.82
1310.03	1165.48
1312.19	1181.39
1314.36	1186.81
1316.52	1133.34
1318.68	1125.65
1320.85	1124.91
1323.01	1108.42
1325.17	1075.98
1327.33	1086.41
1329.49	1096.13
1331.65	1077.79
1333.81	1027.87
1335.97	1044.81
1338.12	1019.82
1340.28	1048.94
1342.44	1033.66
1344.59	1003.56
1346.75	1007.5
1348.9	1010.1
1351.05	998.766
1353.2	975.393
1355.36	971.651
1357.51	931.824
1359.66	951.21
1361.81	959.697
1363.96	926.334
1366.1	932.042
1368.25	951.061
1370.4	958.1
1372.54	945.64
1374.69	910.186
1376.83	867.359
1378.98	892.338
1381.12	901.601
1383.26	884.624
1385.41	864.771
1387.55	863.177
1389.69	841.233
1391.83	852.654
1393.02	846
1395.17	870
1397.32	852
1399.47	834
1401.62	814
1403.77	790
1405.91	806
1408.06	814
1410.2	754
1412.35	802
1414.49	772
1416.63	802
1418.78	808
1420.92	746
1423.06	752
1425.2	744
1427.34	758
1429.48	744
1431.61	716
1433.75	750
1435.89	756
1438.02	732
1440.16	720
1442.3	718
1444.43	716
1446.56	684
1448.7	720
1450.83	690
1452.96	690
1455.09	708
1457.22	692
1459.35	700
1461.48	688
1463.61	692
1465.73	650
1467.86	686
1469.98	632
1472.11	698
1474.24	658
1476.36	650
1478.48	676
1480.6	648
1482.73	676
1484.85	650
1486.97	634
1489.09	664
1491.21	626
1493.33	624
1495.44	608
1497.56	618
1499.68	628
1501.79	608
1503.91	606
1506.02	626
1508.14	572
1510.25	596
1512.36	588
1514.48	576
1516.59	586
1518.7	574
1520.81	590
1522.92	578
1525.02	588
1527.13	552
1529.24	584
1531.35	592
1533.45	556
1535.56	554
1537.66	574
1539.77	534
1541.87	554
1543.97	556
1546.08	562
1548.18	524
1550.28	550
1552.38	514
1554.48	528
1556.57	514
1558.67	512
1560.77	542
1562.87	514
1564.96	520
1567.06	540
1569.15	504
1571.25	516
1573.34	518
1575.43	538
1577.53	492
1579.62	514
1581.71	486
1583.8	490
1585.89	514
1587.98	500
1590.06	500
1592.15	506
1594.24	480
1596.33	492
1598.41	496
1600.5	492
1602.58	494
1604.66	462
1606.75	490
1608.83	500
1610.91	474
1612.99	484
1615.07	474
1617.15	488
1619.23	474
1621.31	478
1623.39	480
1625.46	462
1627.54	478
1629.62	474
1631.69	462
1633.77	450
1635.84	480
1637.91	458
1639.99	468
1642.06	460
1644.13	450
1646.2	454
1648.27	474
1650.34	452
1652.41	480
1654.47	462
1656.54	442
1658.61	450
1660.67	466
1662.74	446
1664.81	464
1666.87	430
1668.93	428
1671	428
1673.06	444
1675.12	454
1677.18	452
1679.24	436
1681.3	452
1683.36	444
1685.42	414
1687.47	426
1689.53	434
1691.59	432
1693.64	424
1695.7	412
1697.75	420
1699.81	436
1701.86	444
1703.91	436
1705.97	412
1708.02	444
1710.07	398
1712.12	418
1714.17	412
1716.22	430
1718.26	420
1720.31	398
1722.36	420
1724.4	414
1726.45	408
1728.49	384
1730.54	410
1732.58	424
1734.63	392
1736.67	418
1738.71	428
1740.75	426
1742.79	412
1744.83	412
1746.87	412
1748.91	434
1750.95	406
1752.98	410
1755.02	404
1757.06	412
1759.09	404
1761.13	380
1763.16	388
1765.19	394
1767.23	416
1769.26	400
1771.29	384
1773.32	414
1775.35	410
1777.38	378
1779.41	402
1781.44	402
1783.47	396
1785.49	406
1787.52	420
1789.55	398
1791.57	410
1793.6	386
1795.62	416
1797.64	404
1799.67	416
1801.69	382
1803.71	390
1805.73	402
1807.75	376
1809.77	390
1811.79	376
1813.81	390
1815.83	388
1817.84	386
1819.86	406
1821.88	410
1823.89	416
1825.91	392
1827.92	400
1829.93	390
1831.95	376
1833.96	396
1835.97	382
1837.98	400
1839.99	394
1842	404
1844.01	410
1846.02	410
1848.03	400
1850.03	378
1852.04	370
1854.05	410
1856.05	382
1858.06	400
1860.06	380
1862.06	364
1864.07	394
1866.07	388
1868.07	372
1870.07	378
1872.07	392
1874.07	382
1876.07	386
1878.07	366
1880.07	378
1882.07	386
1884.06	382
1886.06	394
1888.05	408
1890.05	376
1892.04	378
1894.04	376
1896.03	374
1898.02	402
1900.01	398
1902	388
1903.99	388
1905.98	386
1907.97	386
1909.96	368
1911.95	396
1913.94	396
1915.93	360
1917.91	394
1919.9	392
1921.88	376
1923.87	384
1925.85	374
1927.83	388
1929.82	376
1931.8	370
1933.78	364
1935.76	364
1937.74	410
1939.72	388
1941.7	376
1943.68	382
1945.65	368
1947.63	354
1949.61	378
1951.58	372
1953.56	392
1955.53	380
1957.51	370
1959.48	358
1961.45	382
1963.43	382
1965.4	364
1967.37	382
1969.34	370
1971.31	380
1973.28	346
1975.25	362
1977.22	388
1979.18	370
1981.15	382
1983.12	368
1985.08	400
1987.05	362
1989.01	364
1990.97	366
1992.94	364
1994.9	372
1996.86	382
1998.82	370
2000.78	352
2002.74	386
2004.7	368
2006.66	360
2008.62	364
2010.58	368
2012.54	376
2014.49	368
2016.45	354
2018.4	382
2020.36	368
2022.31	388
2024.27	398
2026.22	362
2028.17	368
2030.12	356
2032.07	368
2034.03	364
2035.98	348
2037.93	360
2039.87	360
2041.82	354
2043.77	336
2045.72	360
2047.66	354
2049.61	374
2051.55	352
2053.5	362
2055.44	362
2057.39	356
2059.33	336
2061.27	362
2063.21	364
2065.15	358
2067.09	358
2069.03	384
2070.97	360
2072.91	366
2074.85	350
2076.79	366
2078.73	360
2080.66	370
2082.6	350
2084.53	358
2086.47	372
2088.4	372
2090.33	354
2092.27	346
2094.2	356
2096.13	364
2098.06	344
2099.99	344
2101.92	384
2103.85	370
2105.78	356
2107.71	380
2109.64	362
2111.56	342
2113.49	354
2115.41	376
2117.34	380
2119.26	366
2121.19	354
2123.11	370
2125.03	348
2126.96	362
2128.88	388
2130.8	352
2132.72	316
2134.64	338
2136.56	352
2138.48	364
2140.4	368
2142.31	356
2144.23	370
2146.15	368
2148.06	344
2149.98	354
2151.89	352
2153.81	348
2155.72	358
2157.63	372
2159.55	370
2161.46	354
2163.37	360
2165.28	374
2167.19	332
2169.1	368
2171.01	354
2172.91	356
2174.82	356
2176.73	334
2178.64	358
2180.54	314
2182.45	366
2184.35	354
2186.26	366
2188.16	354
2190.06	346
2191.96	334
2193.87	338
2195.77	338
2197.67	336
2199.57	350
2201.47	342
2203.37	334
2205.27	334
2207.16	340
2209.06	324
2210.96	348
2212.85	320
2214.75	338
2216.64	356
2218.54	338
2220.43	340
2222.33	350
2224.22	339.545
2226.11	333.519
2228	353.184
2229.89	337.794
2231.78	358.865
2233.67	351.473
2235.56	331.865
2237.45	353.828
2239.34	328.681
2241.23	334.564
2243.11	323.608
2245	333.538
2246.89	354.265
2248.77	332.027
2250.66	332.606
2252.54	344.049
2254.42	348.965
2256.31	342.411
2258.19	341.041
2260.07	329.253
2261.95	328.14
2263.83	347.12
2265.71	334.102
2267.59	327.924
2269.47	323.637
2271.35	332.989
2273.23	325.247
2275.1	318.933
2276.98	324.122
2278.86	335.48
2280.73	315.697
2282.61	324.703
2284.48	319.423
2286.36	319.59
2288.23	339.546
2290.1	319.12
2291.98	322.89
2293.85	313.209
2295.72	327.813
2297.59	320.45
2299.46	311.637
2301.33	313.104
2303.2	311.537
2305.06	308.069
2306.93	337.098
2308.8	318.04
2310.67	310.18
2312.53	327.765
2314.4	319.379
2316.26	312.019
2317.62	314
2319.5	308
2321.37	314
2323.24	308
2325.12	326
2326.99	294
2328.86	290
2330.73	302
2332.6	306
2334.47	322
2336.34	318
2338.2	316
2340.07	316
2341.94	290
2343.81	300
2345.67	290
2347.54	308
2349.4	302
2351.27	316
2353.13	306
2354.99	314
2356.86	314
2358.72	282
2360.58	318
2362.44	308
2364.3	296
2366.16	294
2368.02	276
2369.88	288
2371.74	286
2373.6	294
2375.45	296
2377.31	308
2379.17	278
2381.02	272
2382.88	288
2384.73	278
2386.58	290
2388.44	292
2390.29	284
2392.14	314
2393.99	274
2395.85	276
2397.7	278
2399.55	288
2401.4	294
2403.25	274
2405.09	274
2406.94	302
2408.79	270
2410.63	284
2412.48	276
2414.33	246
2416.17	282
2418.02	260
2419.86	294
2421.7	260
2423.55	280
2425.39	276
2427.23	288
2429.07	274
2430.91	284
2432.75	270
2434.59	266
2436.43	286
2438.27	258
2440.11	254
2441.95	264
2443.78	270
2445.62	258
2447.46	280
2449.29	270
2451.13	268
2452.96	236
2454.79	278
2456.63	262
2458.46	240
2460.29	274
2462.12	262
2463.95	244
2465.78	256
2467.61	244
2469.44	252
2471.27	268
2473.1	254
2474.93	266
2476.76	232
2478.58	250
2480.41	252
2482.23	256
2484.06	242
2485.88	248
2487.71	246
2489.53	242
2491.35	242
2493.18	236
2495	238
2496.82	244
2498.64	252
2500.46	228
2502.28	224
2504.1	250
2505.92	228
2507.74	214
2509.55	228
2511.37	216
2513.19	212
2515	236
2516.82	234
2518.63	232
2520.45	214
2522.26	214
2524.07	236
2525.89	248
2527.7	228
2529.51	228
2531.32	212
2533.13	224
2534.94	226
2536.75	230
2538.56	214
2540.37	222
2542.18	214
2543.98	190
2545.79	222
2547.6	204
2549.4	224
2551.21	192
2553.01	206
2554.82	212
2556.62	230
2558.42	210
2560.23	194
2562.03	198
2563.83	198
2565.63	192
2567.43	204
2569.23	214
2571.03	196
2572.83	210
2574.63	204
2576.43	196
2578.22	210
2580.02	202
2581.82	196
2583.61	190
2585.41	194
2587.2	216
2589	194
2590.79	200
2592.58	198
2594.38	180
2596.17	176
2597.96	194
2599.75	196
2601.54	176
2603.33	192
2605.12	198
2606.91	186
2608.7	184
2610.49	190
2612.27	202
2614.06	184
2615.85	184
2617.63	176
2619.42	190
2621.2	180
2622.99	178
2624.77	172
2626.55	176
2628.34	174
2630.12	166
2631.9	190
2633.68	182
2635.46	188
2637.24	182
2639.02	186
2640.8	178
2642.58	168
2644.36	176
2646.14	170
2647.91	158
2649.69	164
2651.46	170
2653.24	184
2655.01	154
2656.79	174
2658.56	174
2660.34	162
2662.11	174
2663.88	172
2665.65	164
2667.42	170
2669.2	166
2670.96	164
2672.73	160
2674.5	164
2676.27	174
2678.04	172
2679.81	164
2681.58	178
2683.34	146
2685.11	164
2686.87	150
2688.64	150
2690.4	148
2692.17	150
2693.93	148
2695.69	154
2697.46	144
2699.22	158
2700.98	146
2702.74	166
2704.5	150
2706.26	152
2708.02	144
2709.78	152
2711.54	150
2713.3	146
2715.05	136
2716.81	152
2718.57	150
2720.32	136
2722.08	144
2723.83	148
2725.59	146
2727.34	152
2729.09	142
2730.85	160
2732.6	142
2734.35	120
2736.1	134
2737.85	136
2739.6	126
2741.35	134
2743.1	132
2744.85	124
2746.6	144
2748.35	132
2750.09	126
2751.84	140
2753.59	136
2755.33	136
2757.08	144
2758.82	138
2760.57	134
2762.31	132
2764.05	118
2765.79	120
2767.54	126
2769.28	130
2771.02	120
2772.76	140
2774.5	132
2776.24	132
2777.98	138
2779.72	126
2781.46	124
2783.19	118
2784.93	128
2786.67	136
2788.4	120
2790.14	132
2791.87	116
2793.61	124
2795.34	140
2797.07	118
2798.81	122
2800.54	132
2802.27	112
2804	104
2805.74	116
2807.47	122
2809.2	114
2810.93	108
2812.65	118
2814.38	140
2816.11	110
2817.84	126
2819.56	124
2821.29	100
2823.02	120
2824.74	116
2826.47	106
2828.19	106
2829.92	120
2831.64	104
2833.36	102
2835.09	108
2836.81	118
2838.53	116
2840.25	108
2841.97	114
2843.69	102
2845.41	94
2847.13	94
2848.85	108
2850.57	108
2852.28	106
2854	96
2855.72	98
2857.43	102
2859.15	98
2860.86	108
2862.58	110
2864.29	92
2866.01	112
2867.72	104
2869.43	104
2871.14	98
2872.86	102
2874.57	90
2876.28	108
2877.99	100
2879.7	86
2881.41	92
2883.11	96
2884.82	102
2886.53	90
2888.24	92
2889.94	86
2891.65	100
2893.36	94
2895.06	88
2896.77	86
2898.47	88
2900.17	84
2901.88	76
2903.58	86
2905.28	94
2906.98	88
2908.69	80
2910.39	94
2912.09	96
2913.79	90
2915.49	84
2917.19	82
2918.88	94
2920.58	96
2922.28	80
2923.98	68
2925.67	94
2927.37	100
2929.06	82
2930.76	96
2932.45	78
2934.15	82
2935.84	76
2937.53	94
2939.23	74
2940.92	92
2942.61	90
2944.3	98
2945.99	82
2947.68	86
2949.37	80
2951.06	76
2952.75	80
2954.44	70
2956.12	82
2957.81	88
2959.5	82
2961.18	92
2962.87	78
2964.56	78
2966.24	82
2967.92	82
2969.61	80
2971.29	76
2972.97	74
2974.66	76
2976.34	76
2978.02	74
2979.7	76
2981.38	72
2983.06	86
2984.74	84
2986.42	72
2988.1	72
2989.78	78
2991.45	86
2993.13	76
2994.81	68
2996.48	66
2998.16	72
2999.83	86