File: muestras/suculenta_dedo/inside_pr_15.txt
#Acq. time (s)=	10
#Accumulations=	1
#Range (cm-¹)=	200...3000
#Windows=	3
#Autofocus=	Off
#AutoExposure=	Off
#Spike filter=	Off
#Delay time (s)=	0
#Binning=	1
#Readout mode=	Signal
#DeNoise=	Off
#ICS correction=	Off
#Dark correction=	Off
#Inst. Process=	Off
#Instrument=	LabRAM HR Evol
#Detector=	Syncerity OE
#Objective=	x100_VIS
#Grating=	600 (500nm)
#ND Filter=	1%
#Laser=	633nm_Edge
#Hole=	30.0125
#Range=	Visible
#Project=	Omar
#Sample=	03-07-23
#Site=	fings
#Title=	inside_pr
#Remark=
#Date=	03.07.2023 15:11
#Acquired=	03.07.2023 15:11:57
201.713	48
204.247	54
206.778	50
209.311	54
211.84	50
214.371	62
216.899	52
219.428	66
221.955	48
224.482	44
227.007	52
229.531	50
232.055	46
234.579	52
237.1	56
239.621	52
242.141	60
244.661	52
247.179	56
249.698	64
252.215	54
254.731	58
257.246	66
259.761	60
262.273	60
264.786	62
267.298	58
269.809	52
272.319	56
274.828	66
277.336	52
279.844	56
282.351	72
284.855	52
287.361	50
289.866	58
292.368	54
294.871	56
297.372	64
299.873	58
302.372	60
304.872	62
307.37	64
309.866	68
312.364	66
314.859	58
317.353	70
319.848	60
322.341	58
324.833	62
327.324	60
329.814	60
332.304	60
334.792	64
337.28	66
339.767	66
342.254	58
344.739	80
347.224	70
349.708	64
352.191	64
354.673	66
357.155	68
359.634	64
362.114	82
364.593	74
367.07	70
369.548	78
372.024	64
374.499	72
376.974	74
379.447	80
381.92	74
384.392	86
386.864	76
389.333	74
391.802	76
394.272	82
396.739	70
399.206	70
401.673	86
404.138	86
406.602	80
409.066	74
411.528	64
413.99	80
416.451	94
418.911	88
421.371	84
423.83	92
426.288	78
428.745	84
431.201	86
433.657	94
436.111	84
438.565	88
441.017	98
443.469	82
445.921	96
448.37	102
450.821	92
453.27	84
455.717	90
458.165	96
460.61	98
463.056	94
465.5	104
467.945	104
470.387	104
472.829	108
475.271	104
477.711	100
480.15	86
482.589	116
485.027	98
487.465	110
489.901	102
492.337	112
494.771	96
497.205	110
499.638	112
502.07	110
504.502	102
506.933	118
509.363	98
511.792	110
514.219	110
516.647	116
519.073	112
521.5	110
523.924	122
526.348	110
528.772	116
531.194	110
533.616	122
536.036	132
538.457	118
540.875	122
543.294	110
545.712	134
548.128	102
550.545	112
552.959	118
555.373	124
557.788	132
560.2	128
562.612	130
565.023	120
567.433	122
569.843	126
572.251	134
574.659	124
577.066	142
579.472	150
581.878	146
584.283	138
586.687	136
589.09	146
591.493	152
593.893	150
596.294	142
598.694	154
601.093	140
603.491	140
605.889	158
608.285	152
610.682	138
613.076	162
615.471	156
617.864	152
620.256	156
622.648	158
625.039	158
627.429	158
629.819	164
632.208	174
634.595	156
636.982	170
639.369	160
641.755	172
644.139	176
646.523	166
648.906	194
651.288	172
653.67	186
656.051	180
658.429	184
660.808	182
663.187	190
665.565	198
667.942	180
670.317	194
672.692	208
675.067	182
677.44	184
679.813	190
682.184	198
684.556	210
686.926	194
689.296	202
691.664	194
694.033	200
696.4	216
698.766	212
701.133	212
703.497	218
705.861	244
708.224	246
710.586	218
712.949	224
715.31	230
717.67	238
720.029	218
722.388	244
724.746	254
727.103	250
729.458	244
731.814	236
734.168	266
736.523	246
738.876	252
741.227	252
743.579	248
745.931	266
748.28	256
750.629	252
752.977	290
755.325	286
757.672	280
760.018	282
762.363	270
764.708	300
767.052	294
769.394	284
771.737	330
774.078	996
776.419	1262
778.758	306
781.097	320
783.435	310
785.773	304
788.11	312
790.446	334
792.781	332
795.115	312
797.449	336
799.782	368
802.115	338
804.446	358
806.777	354
809.106	364
811.435	376
813.764	380
816.091	338
818.418	374
820.743	374
823.069	384
825.393	398
827.717	400
830.039	394
832.362	420
834.683	420
837.003	426
839.324	436
841.643	430
843.961	414
846.278	430
848.594	462
850.91	448
853.227	458
855.541	436
857.855	434
860.168	472
862.48	446
864.79	476
867.101	482
869.411	526
871.721	492
874.029	486
876.336	506
878.643	502
880.95	508
883.254	526
885.559	526
887.862	524
890.166	530
892.467	548
894.77	516
897.07	548
899.371	526
901.669	546
903.968	550
906.266	554
908.563	552
910.859	584
913.154	602
915.449	594
917.742	588
920.036	602
922.329	600
924.621	598
926.911	618
929.201	618
931.49	634
933.779	634
936.068	614
938.355	636
940.64	682
942.926	706
945.212	678
947.495	650
949.779	710
952.062	700
954.344	696
956.625	712
958.905	720
961.184	734
963.464	706
965.742	758
968.02	736
970.296	754
972.572	768
974.847	748
977.121	792
979.396	784
981.669	754
983.941	806
986.212	776
988.483	814
990.753	806
993.022	846
995.29	846
997.558	850
999.825	860
1002.09	834
1004.36	876
1006.62	870
1008.89	892
1011.15	938
1013.41	918
1015.67	890
1017.93	938
1020.19	890
1022.45	944
1024.71	942
1026.97	980
1029.23	988
1031.49	988
1033.74	1004
1036	1020
1038.25	998
1040.5	1012
1042.76	1030
1045.01	1056
1047.26	1046
1049.51	1042
1051.76	1070
1054.01	1064
1056.26	1090
1058.51	1126
1060.75	1124
1063	1122
1065.25	1118
1067.49	1132
1069.73	1184
1071.98	1160
1074.22	1190
1076.46	1188
1078.7	1162
1080.94	1206
1083.18	1224
1085.42	1202
1087.66	1222
1089.9	1300
1092.14	1208
1094.37	1212
1096.61	1248
1098.84	1234
1101.08	1280
1103.31	1272
1105.54	1268
1107.77	1266
1110	1280
1112.23	1316
1114.46	1302
1116.69	1330
1118.92	1350
1121.15	1356
1123.37	1332
1125.6	1354
1127.83	1312
1130.05	1376
1132.27	1350
1134.5	1400
1136.72	1376
1138.94	1416
1141.16	1408
1143.38	1438
1145.6	1406
1147.82	1468
1150.04	1436
1152.26	1472
1154.47	1458
1156.69	1442
1158.9	1398
1161.12	1442
1163.33	1482
1165.54	1474
1167.76	1476
1169.97	1456
1172.18	1490
1174.39	1438
1176.6	1430
1178.81	1444
1181.02	1406
1183.22	1458
1185.43	1416
1187.63	1446
1189.84	1446
1192.04	1468
1194.25	1438
1196.45	1398
1198.65	1426
1200.85	1438
1203.05	1436
1205.25	1390
1207.45	1434
1209.65	1430
1211.85	1368
1214.05	1422
1216.24	1328
1218.44	1390
1220.64	1392
1222.83	1334
1225.02	1378
1227.22	1318
1229.41	1362
1231.6	1346
1233.79	1330
1235.98	1330
1238.17	1340
1240.36	1304
1242.55	1270
1244.73	1356
1246.92	1278
1249.11	1290
1251.29	1334
1253.48	1324
1255.66	1280
1257.84	1250
1260.03	1254
1262.21	1258
1264.39	1256
1266.57	1260
1268.75	1226
1270.93	1206
1273.11	1224
1275.28	1212
1277.46	1204
1279.64	1148
1281.81	1192
1283.98	1125.99
1286.16	1138.87
1288.33	1165.96
1290.5	1132.68
1292.68	1108.5
1294.85	1106.27
1297.02	1125.93
1299.19	1068.08
1301.36	1074.09
1303.53	1053.3
1305.69	1049.97
1307.86	1057.86
1310.03	1047.8
1312.19	1033.92
1314.36	1030.6
1316.52	992.814
1318.68	988.357
1320.85	996.079
1323.01	978.82
1325.17	980.071
1327.33	964.779
1329.49	950.32
1331.65	961.31
1333.81	939.977
1335.97	952.541
1338.12	932.958
1340.28	905.311
1342.44	886.68
1344.59	888.554
1346.75	901.618
1348.9	864.924
1351.05	865.063
1353.2	862.972
1355.36	862.607
1357.51	860.248
1359.66	843.87
1361.81	823.216
1363.96	816.639
1366.1	827.489
1368.25	801.313
1370.4	814.966
1372.54	793.479
1374.69	773.184
1376.83	772.784
1378.98	771.513
1381.12	772.058
1383.26	718.249
1385.41	720.347
1387.55	767.454
1389.69	741.394
1391.83	708.602
1393.02	716
1395.17	704
1397.32	718
1399.47	704
1401.62	710
1403.77	704
1405.91	688
1408.06	674
1410.2	664
1412.35	678
1414.49	678
1416.63	670
1418.78	646
1420.92	678
1423.06	628
1425.2	626
1427.34	618
1429.48	666
1431.61	644
1433.75	622
1435.89	632
1438.02	592
1440.16	632
1442.3	622
1444.43	600
1446.56	594
1448.7	598
1450.83	628
1452.96	600
1455.09	566
1457.22	592
1459.35	594
1461.48	606
1463.61	572
1465.73	584
1467.86	586
1469.98	556
1472.11	572
1474.24	606
1476.36	568
1478.48	560
1480.6	568
1482.73	548
1484.85	584
1486.97	538
1489.09	518
1491.21	532
1493.33	554
1495.44	540
1497.56	542
1499.68	554
1501.79	514
1503.91	534
1506.02	518
1508.14	498
1510.25	516
1512.36	462
1514.48	514
1516.59	510
1518.7	510
1520.81	500
1522.92	522
1525.02	506
1527.13	492
1529.24	502
1531.35	484
1533.45	492
1535.56	466
1537.66	464
1539.77	472
1541.87	452
1543.97	460
1546.08	472
1548.18	442
1550.28	456
1552.38	430
1554.48	474
1556.57	454
1558.67	442
1560.77	432
1562.87	432
1564.96	438
1567.06	440
1569.15	436
1571.25	446
1573.34	446
1575.43	440
1577.53	442
1579.62	424
1581.71	444
1583.8	420
1585.89	390
1587.98	402
1590.06	442
1592.15	414
1594.24	410
1596.33	432
1598.41	436
1600.5	390
1602.58	442
1604.66	404
1606.75	406
1608.83	414
1610.91	398
1612.99	416
1615.07	418
1617.15	410
1619.23	418
1621.31	400
1623.39	424
1625.46	414
1627.54	390
1629.62	404
1631.69	400
1633.77	386
1635.84	422
1637.91	390
1639.99	406
1642.06	384
1644.13	400
1646.2	388
1648.27	370
1650.34	406
1652.41	388
1654.47	400
1656.54	384
1658.61	402
1660.67	390
1662.74	384
1664.81	362
1666.87	378
1668.93	382
1671	378
1673.06	374
1675.12	358
1677.18	374
1679.24	358
1681.3	358
1683.36	360
1685.42	382
1687.47	374
1689.53	380
1691.59	342
1693.64	358
1695.7	372
1697.75	364
1699.81	392
1701.86	356
1703.91	344
1705.97	378
1708.02	376
1710.07	374
1712.12	358
1714.17	376
1716.22	366
1718.26	358
1720.31	366
1722.36	354
1724.4	350
1726.45	362
1728.49	370
1730.54	374
1732.58	336
1734.63	356
1736.67	342
1738.71	360
1740.75	350
1742.79	358
1744.83	354
1746.87	352
1748.91	388
1750.95	364
1752.98	332
1755.02	368
1757.06	348
1759.09	358
1761.13	340
1763.16	344
1765.19	368
1767.23	354
1769.26	358
1771.29	352
1773.32	340
1775.35	322
1777.38	354
1779.41	356
1781.44	330
1783.47	330
1785.49	326
1787.52	338
1789.55	348
1791.57	346
1793.6	352
1795.62	368
1797.64	330
1799.67	340
1801.69	338
1803.71	330
1805.73	358
1807.75	348
1809.77	342
1811.79	348
1813.81	364
1815.83	338
1817.84	340
1819.86	348
1821.88	324
1823.89	378
1825.91	328
1827.92	336
1829.93	336
1831.95	318
1833.96	334
1835.97	314
1837.98	334
1839.99	340
1842	330
1844.01	342
1846.02	332
1848.03	322
1850.03	338
1852.04	338
1854.05	316
1856.05	316
1858.06	332
1860.06	320
1862.06	314
1864.07	348
1866.07	338
1868.07	338
1870.07	310
1872.07	350
1874.07	332
1876.07	330
1878.07	326
1880.07	326
1882.07	334
1884.06	336
1886.06	338
1888.05	330
1890.05	332
1892.04	326
1894.04	316
1896.03	326
1898.02	328
1900.01	318
1902	338
1903.99	316
1905.98	328
1907.97	326
1909.96	326
1911.95	328
1913.94	316
1915.93	306
1917.91	352
1919.9	294
1921.88	310
1923.87	324
1925.85	328
1927.83	330
1929.82	308
1931.8	326
1933.78	308
1935.76	328
1937.74	316
1939.72	312
1941.7	306
1943.68	328
1945.65	334
1947.63	314
1949.61	330
1951.58	314
1953.56	308
1955.53	320
1957.51	318
1959.48	336
1961.45	326
1963.43	290
1965.4	320
1967.37	302
1969.34	332
1971.31	312
1973.28	312
1975.25	344
1977.22	310
1979.18	338
1981.15	338
1983.12	312
1985.08	328
1987.05	322
1989.01	344
1990.97	314
1992.94	300
1994.9	318
1996.86	308
1998.82	322
2000.78	316
2002.74	316
2004.7	320
2006.66	316
2008.62	318
2010.58	320
2012.54	304
2014.49	328
2016.45	308
2018.4	326
2020.36	296
2022.31	300
2024.27	298
2026.22	310
2028.17	322
2030.12	302
2032.07	320
2034.03	314
2035.98	304
2037.93	326
2039.87	290
2041.82	280
2043.77	314
2045.72	316
2047.66	286
2049.61	322
2051.55	306
2053.5	304
2055.44	294
2057.39	304
2059.33	316
2061.27	294
2063.21	320
2065.15	308
2067.09	308
2069.03	304
2070.97	324
2072.91	292
2074.85	322
2076.79	310
2078.73	292
2080.66	316
2082.6	282
2084.53	314
2086.47	306
2088.4	310
2090.33	306
2092.27	318
2094.2	288
2096.13	312
2098.06	280
2099.99	308
2101.92	308
2103.85	300
2105.78	298
2107.71	320
2109.64	322
2111.56	312
2113.49	296
2115.41	328
2117.34	310
2119.26	298
2121.19	298
2123.11	292
2125.03	316
2126.96	312
2128.88	304
2130.8	324
2132.72	294
2134.64	318
2136.56	310
2138.48	322
2140.4	302
2142.31	304
2144.23	276
2146.15	300
2148.06	298
2149.98	310
2151.89	310
2153.81	292
2155.72	320
2157.63	302
2159.55	310
2161.46	300
2163.37	290
2165.28	286
2167.19	312
2169.1	290
2171.01	336
2172.91	294
2174.82	294
2176.73	322
2178.64	288
2180.54	274
2182.45	306
2184.35	284
2186.26	288
2188.16	296
2190.06	296
2191.96	272
2193.87	302
2195.77	292
2197.67	290
2199.57	282
2201.47	302
2203.37	294
2205.27	298
2207.16	288
2209.06	294
2210.96	316
2212.85	288
2214.75	304
2216.64	312
2218.54	282
2220.43	292
2222.33	286
2224.22	292.069
2226.11	270.085
2228	291.841
2229.89	285.214
2231.78	294.943
2233.67	294.988
2235.56	308.123
2237.45	290.921
2239.34	263.43
2241.23	288.131
2243.11	298.985
2245	281.385
2246.89	264.715
2248.77	287.518
2250.66	303.848
2252.54	297.763
2254.42	297.875
2256.31	291.304
2258.19	300.234
2260.07	292.972
2261.95	299.571
2263.83	292.99
2265.71	283.361
2267.59	290.532
2269.47	295.697
2271.35	296.252
2273.23	302.237
2275.1	304.281
2276.98	306.964
2278.86	289.83
2280.73	291.37
2282.61	303.052
2284.48	290.703
2286.36	277.23
2288.23	296.099
2290.1	297.377
2291.98	292.98
2293.85	292.671
2295.72	291.082
2297.59	304.756
2299.46	299.567
2301.33	309.514
2303.2	299.55
2305.06	293.368
2306.93	300.554
2308.8	285.72
2310.67	297.049
2312.53	291.91
2314.4	293.47
2316.26	293.474
2317.62	280
2319.5	304
2321.37	292
2323.24	294
2325.12	278
2326.99	296
2328.86	302
2330.73	284
2332.6	320
2334.47	304
2336.34	276
2338.2	276
2340.07	298
2341.94	282
2343.81	306
2345.67	288
2347.54	282
2349.4	298
2351.27	292
2353.13	274
2354.99	266
2356.86	300
2358.72	278
2360.58	274
2362.44	280
2364.3	282
2366.16	300
2368.02	286
2369.88	268
2371.74	272
2373.6	288
2375.45	282
2377.31	282
2379.17	296
2381.02	266
2382.88	286
2384.73	268
2386.58	274
2388.44	270
2390.29	278
2392.14	268
2393.99	282
2395.85	268
2397.7	266
2399.55	278
2401.4	270
2403.25	276
2405.09	258
2406.94	270
2408.79	270
2410.63	254
2412.48	262
2414.33	242
2416.17	250
2418.02	258
2419.86	244
2421.7	244
2423.55	246
2425.39	252
2427.23	268
2429.07	260
2430.91	246
2432.75	246
2434.59	254
2436.43	254
2438.27	258
2440.11	226
2441.95	246
2443.78	228
2445.62	246
2447.46	258
2449.29	226
2451.13	252
2452.96	248
2454.79	238
2456.63	244
2458.46	242
2460.29	244
2462.12	254
2463.95	250
2465.78	232
2467.61	250
2469.44	240
2471.27	240
2473.1	222
2474.93	220
2476.76	224
2478.58	226
2480.41	226
2482.23	228
2484.06	250
2485.88	250
2487.71	238
2489.53	232
2491.35	242
2493.18	216
2495	228
2496.82	216
2498.64	230
2500.46	224
2502.28	204
2504.1	212
2505.92	228
2507.74	208
2509.55	196
2511.37	204
2513.19	210
2515	224
2516.82	200
2518.63	202
2520.45	212
2522.26	226
2524.07	206
2525.89	200
2527.7	220
2529.51	204
2531.32	230
2533.13	214
2534.94	220
2536.75	214
2538.56	210
2540.37	206
2542.18	188
2543.98	198
2545.79	200
2547.6	212
2549.4	184
2551.21	192
2553.01	212
2554.82	204
2556.62	198
2558.42	192
2560.23	194
2562.03	214
2563.83	202
2565.63	198
2567.43	176
2569.23	200
2571.03	202
2572.83	190
2574.63	186
2576.43	182
2578.22	210
2580.02	188
2581.82	194
2583.61	192
2585.41	188
2587.2	182
2589	170
2590.79	194
2592.58	178
2594.38	194
2596.17	194
2597.96	186
2599.75	186
2601.54	178
2603.33	170
2605.12	198
2606.91	186
2608.7	182
2610.49	162
2612.27	186
2614.06	180
2615.85	170
2617.63	192
2619.42	178
2621.2	190
2622.99	182
2624.77	178
2626.55	168
2628.34	180
2630.12	176
2631.9	176
2633.68	156
2635.46	180
2637.24	178
2639.02	172
2640.8	162
2642.58	150
2644.36	178
2646.14	162
2647.91	170
2649.69	168
2651.46	164
2653.24	174
2655.01	156
2656.79	158
2658.56	148
2660.34	156
2662.11	170
2663.88	158
2665.65	152
2667.42	164
2669.2	156
2670.96	146
2672.73	154
2674.5	154
2676.27	172
2678.04	154
2679.81	158
2681.58	158
2683.34	156
2685.11	162
2686.87	164
2688.64	148
2690.4	142
2692.17	138
2693.93	146
2695.69	152
2697.46	162
2699.22	144
2700.98	148
2702.74	136
2704.5	142
2706.26	142
2708.02	144
2709.78	154
2711.54	160
2713.3	126
2715.05	140
2716.81	152
2718.57	146
2720.32	134
2722.08	148
2723.83	138
2725.59	120
2727.34	132
2729.09	136
2730.85	132
2732.6	130
2734.35	120
2736.1	138
2737.85	126
2739.6	126
2741.35	142
2743.1	132
2744.85	126
2746.6	116
2748.35	136
2750.09	124
2751.84	124
2753.59	126
2755.33	118
2757.08	122
2758.82	128
2760.57	126
2762.31	116
2764.05	126
2765.79	128
2767.54	130
2769.28	120
2771.02	122
2772.76	116
2774.5	112
2776.24	126
2777.98	122
2779.72	108
2781.46	126
2783.19	122
2784.93	118
2786.67	110
2788.4	106
2790.14	110
2791.87	114
2793.61	110
2795.34	108
2797.07	94
2798.81	108
2800.54	122
2802.27	112
2804	104
2805.74	108
2807.47	102
2809.2	106
2810.93	106
2812.65	106
2814.38	114
2816.11	98
2817.84	110
2819.56	106
2821.29	106
2823.02	106
2824.74	110
2826.47	108
2828.19	96
2829.92	96
2831.64	94
2833.36	94
2835.09	96
2836.81	100
2838.53	108
2840.25	98
2841.97	96
2843.69	96
2845.41	94
2847.13	96
2848.85	100
2850.57	92
2852.28	88
2854	102
2855.72	88
2857.43	96
2859.15	100
2860.86	100
2862.58	92
2864.29	94
2866.01	84
2867.72	92
2869.43	86
2871.14	96
2872.86	84
2874.57	86
2876.28	90
2877.99	96
2879.7	92
2881.41	86
2883.11	88
2884.82	86
2886.53	72
2888.24	76
2889.94	86
2891.65	88
2893.36	86
2895.06	88
2896.77	90
2898.47	86
2900.17	104
2901.88	92
2903.58	88
2905.28	84
2906.98	92
2908.69	84
2910.39	80
2912.09	88
2913.79	84
2915.49	88
2917.19	94
2918.88	70
2920.58	82
2922.28	74
2923.98	90
2925.67	82
2927.37	76
2929.06	88
2930.76	66
2932.45	76
2934.15	86
2935.84	80
2937.53	74
2939.23	84
2940.92	82
2942.61	92
2944.3	78
2945.99	64
2947.68	84
2949.37	80
2951.06	70
2952.75	86
2954.44	68
2956.12	78
2957.81	74
2959.5	70
2961.18	92
2962.87	84
2964.56	74
2966.24	76
2967.92	70
2969.61	74
2971.29	74
2972.97	72
2974.66	70
2976.34	70
2978.02	70
2979.7	80
2981.38	80
2983.06	70
2984.74	86
2986.42	78
2988.1	82
2989.78	74
2991.45	76
2993.13	68
2994.81	72
2996.48	74
2998.16	68
2999.83	74