File: muestras/suculenta_dedo/inside_pr_12.txt
#Acq. time (s)=	10
#Accumulations=	1
#Range (cm-¹)=	200...3000
#Windows=	3
#Autofocus=	Off
#AutoExposure=	Off
#Spike filter=	Off
#Delay time (s)=	0
#Binning=	1
#Readout mode=	Signal
#DeNoise=	Off
#ICS correction=	Off
#Dark correction=	Off
#Inst. Process=	Off
#Instrument=	LabRAM HR Evol
#Detector=	Syncerity OE
#Objective=	x100_VIS
#Grating=	600 (500nm)
#ND Filter=	1%
#Laser=	633nm_Edge
#Hole=	30.0125
#Range=	Visible
#Project=	Omar
#Sample=	03-07-23
#Site=	fings
#Title=	inside_pr
#Remark=
#Date=	03.07.2023 15:09
#Acquired=	03.07.2023 15:09:10
201.713	58
204.247	44
206.778	56
209.311	56
211.84	48
214.371	54
216.899	58
219.428	56
221.955	58
224.482	56
227.007	54
229.531	62
232.055	66
234.579	64
237.1	62
239.621	70
242.141	58
244.661	66
247.179	60
249.698	70
252.215	66
254.731	58
257.246	60
259.761	66
262.273	68
264.786	74
267.298	66
269.809	64
272.319	60
274.828	64
277.336	60
279.844	72
282.351	64
284.855	72
287.361	70
289.866	56
292.368	64
294.871	64
297.372	72
299.873	72
302.372	68
304.872	74
307.37	72
309.866	82
312.364	82
314.859	68
317.353	68
319.848	66
322.341	74
324.833	72
327.324	78
329.814	76
332.304	80
334.792	80
337.28	72
339.767	82
342.254	74
344.739	74
347.224	82
349.708	70
352.191	82
354.673	76
357.155	82
359.634	82
362.114	92
364.593	86
367.07	88
369.548	74
372.024	86
374.499	88
376.974	90
379.447	90
381.92	92
384.392	102
386.864	92
389.333	98
391.802	96
394.272	84
396.739	84
399.206	92
401.673	88
404.138	98
406.602	106
409.066	98
411.528	98
413.99	98
416.451	94
418.911	106
421.371	108
423.83	100
426.288	92
428.745	102
431.201	108
433.657	112
436.111	110
438.565	112
441.017	134
443.469	108
445.921	102
448.37	106
450.821	124
453.27	114
455.717	118
458.165	102
460.61	102
463.056	112
465.5	110
467.945	104
470.387	122
472.829	124
475.271	112
477.711	124
480.15	114
482.589	134
485.027	130
487.465	124
489.901	138
492.337	120
494.771	128
497.205	132
499.638	144
502.07	144
504.502	124
506.933	146
509.363	152
511.792	144
514.219	132
516.647	130
519.073	144
521.5	136
523.924	146
526.348	138
528.772	144
531.194	154
533.616	138
536.036	134
538.457	156
540.875	136
543.294	142
545.712	158
548.128	142
550.545	158
552.959	158
555.373	158
557.788	154
560.2	166
562.612	150
565.023	162
567.433	146
569.843	168
572.251	170
574.659	164
577.066	176
579.472	160
581.878	186
584.283	184
586.687	170
589.09	190
591.493	176
593.893	164
596.294	172
598.694	190
601.093	184
603.491	174
605.889	182
608.285	176
610.682	190
613.076	204
615.471	180
617.864	184
620.256	186
622.648	196
625.039	206
627.429	196
629.819	200
632.208	214
634.595	218
636.982	210
639.369	218
641.755	212
644.139	204
646.523	210
648.906	230
651.288	234
653.67	224
656.051	226
658.429	226
660.808	232
663.187	222
665.565	244
667.942	256
670.317	254
672.692	260
675.067	248
677.44	246
679.813	260
682.184	262
684.556	250
686.926	274
689.296	248
691.664	264
694.033	256
696.4	286
698.766	274
701.133	280
703.497	286
705.861	288
708.224	280
710.586	298
712.949	290
715.31	296
717.67	308
720.029	306
722.388	284
724.746	292
727.103	304
729.458	290
731.814	328
734.168	330
736.523	344
738.876	342
741.227	324
743.579	328
745.931	366
748.28	334
750.629	360
752.977	360
755.325	370
757.672	364
760.018	352
762.363	356
764.708	362
767.052	402
769.394	368
771.737	378
774.078	390
776.419	384
778.758	396
781.097	416
783.435	430
785.773	424
788.11	392
790.446	428
792.781	440
795.115	422
797.449	488
799.782	464
802.115	444
804.446	448
806.777	442
809.106	456
811.435	468
813.764	474
816.091	476
818.418	480
820.743	504
823.069	494
825.393	520
827.717	492
830.039	512
832.362	536
834.683	514
837.003	538
839.324	536
841.643	520
843.961	582
846.278	550
848.594	606
850.91	586
853.227	588
855.541	590
857.855	612
860.168	618
862.48	630
864.79	606
867.101	654
869.411	610
871.721	662
874.029	678
876.336	666
878.643	636
880.95	664
883.254	676
885.559	674
887.862	696
890.166	694
892.467	726
894.77	704
897.07	734
899.371	714
901.669	728
903.968	740
906.266	734
908.563	748
910.859	800
913.154	782
915.449	776
917.742	778
920.036	792
922.329	784
924.621	820
926.911	828
929.201	864
931.49	820
933.779	866
936.068	860
938.355	838
940.64	868
942.926	862
945.212	922
947.495	872
949.779	934
952.062	942
954.344	906
956.625	964
958.905	964
961.184	1016
963.464	980
965.742	982
968.02	992
970.296	1048
972.572	1026
974.847	1030
977.121	1044
979.396	1032
981.669	1068
983.941	1104
986.212	1096
988.483	1072
990.753	1138
993.022	1128
995.29	1102
997.558	1146
999.825	1130
1002.09	1150
1004.36	1178
1006.62	1206
1008.89	1208
1011.15	1194
1013.41	1244
1015.67	1238
1017.93	1260
1020.19	1248
1022.45	1240
1024.71	1328
1026.97	1312
1029.23	1292
1031.49	1324
1033.74	1360
1036	1384
1038.25	1388
1040.5	1384
1042.76	1436
1045.01	1412
1047.26	1500
1049.51	1490
1051.76	1460
1054.01	1470
1056.26	1456
1058.51	1546
1060.75	1550
1063	1496
1065.25	1540
1067.49	1552
1069.73	1578
1071.98	1566
1074.22	1570
1076.46	1624
1078.7	1576
1080.94	1614
1083.18	1622
1085.42	1660
1087.66	1676
1089.9	1626
1092.14	1696
1094.37	1686
1096.61	1692
1098.84	1690
1101.08	1706
1103.31	1654
1105.54	1720
1107.77	1752
1110	1716
1112.23	1804
1114.46	1764
1116.69	1790
1118.92	1770
1121.15	1762
1123.37	1800
1125.6	1784
1127.83	1798
1130.05	1840
1132.27	1886
1134.5	1820
1136.72	1830
1138.94	1904
1141.16	1874
1143.38	1884
1145.6	1896
1147.82	1884
1150.04	2004
1152.26	1880
1154.47	1876
1156.69	1962
1158.9	2000
1161.12	2000
1163.33	1948
1165.54	1960
1167.76	1998
1169.97	1966
1172.18	1952
1174.39	1934
1176.6	1992
1178.81	1956
1181.02	1974
1183.22	2024
1185.43	1956
1187.63	2014
1189.84	1980
1192.04	2002
1194.25	1954
1196.45	1940
1198.65	1918
1200.85	1970
1203.05	2006
1205.25	1984
1207.45	1954
1209.65	1906
1211.85	1892
1214.05	1906
1216.24	1890
1218.44	1868
1220.64	1896
1222.83	1892
1225.02	1870
1227.22	1856
1229.41	1824
1231.6	1780
1233.79	1760
1235.98	1826
1238.17	1752
1240.36	1792
1242.55	1750
1244.73	1716
1246.92	1778
1249.11	1770
1251.29	1754
1253.48	1704
1255.66	1736
1257.84	1692
1260.03	1724
1262.21	1690
1264.39	1714
1266.57	1644
1268.75	1680
1270.93	1660
1273.11	1642
1275.28	1652
1277.46	1644
1279.64	1646
1281.81	1588
1283.98	1571.94
1286.16	1572.59
1288.33	1559.89
1290.5	2364.62
1292.68	1552.27
1294.85	1490.39
1297.02	1510.29
1299.19	1528.27
1301.36	1543.32
1303.53	1458.05
1305.69	1445.17
1307.86	1474.85
1310.03	1438.52
1312.19	1436.05
1314.36	1398.39
1316.52	1373.56
1318.68	1401.86
1320.85	1385.42
1323.01	1376.92
1325.17	1329.19
1327.33	1331.33
1329.49	1341.79
1331.65	1346.16
1333.81	1298.71
1335.97	1302.91
1338.12	1271.9
1340.28	1273.51
1342.44	1273.86
1344.59	1227.48
1346.75	1277.87
1348.9	1228.68
1351.05	1202.18
1353.2	1194.78
1355.36	1210.5
1357.51	1211.43
1359.66	1197.16
1361.81	1169.06
1363.96	1130.47
1366.1	1150.35
1368.25	1112.06
1370.4	1111.46
1372.54	1125.9
1374.69	1136.42
1376.83	1100.53
1378.98	1092.03
1381.12	1057.81
1383.26	1110.72
1385.41	1100.56
1387.55	1079.57
1389.69	1050.97
1391.83	1040.61
1393.02	1014
1395.17	1038
1397.32	1040
1399.47	1020
1401.62	996
1403.77	1014
1405.91	1006
1408.06	978
1410.2	950
1412.35	948
1414.49	940
1416.63	952
1418.78	934
1420.92	958
1423.06	952
1425.2	938
1427.34	946
1429.48	938
1431.61	968
1433.75	908
1435.89	936
1438.02	872
1440.16	880
1442.3	868
1444.43	882
1446.56	866
1448.7	870
1450.83	860
1452.96	860
1455.09	900
1457.22	840
1459.35	842
1461.48	822
1463.61	882
1465.73	842
1467.86	840
1469.98	804
1472.11	802
1474.24	822
1476.36	798
1478.48	792
1480.6	826
1482.73	802
1484.85	756
1486.97	794
1489.09	792
1491.21	774
1493.33	772
1495.44	792
1497.56	756
1499.68	746
1501.79	728
1503.91	770
1506.02	726
1508.14	752
1510.25	752
1512.36	754
1514.48	750
1516.59	718
1518.7	724
1520.81	736
1522.92	714
1525.02	724
1527.13	724
1529.24	684
1531.35	710
1533.45	684
1535.56	706
1537.66	692
1539.77	678
1541.87	678
1543.97	676
1546.08	652
1548.18	654
1550.28	670
1552.38	672
1554.48	638
1556.57	628
1558.67	634
1560.77	670
1562.87	662
1564.96	650
1567.06	650
1569.15	608
1571.25	630
1573.34	634
1575.43	638
1577.53	620
1579.62	618
1581.71	608
1583.8	598
1585.89	642
1587.98	628
1590.06	620
1592.15	584
1594.24	616
1596.33	614
1598.41	622
1600.5	618
1602.58	612
1604.66	620
1606.75	586
1608.83	608
1610.91	590
1612.99	598
1615.07	580
1617.15	552
1619.23	572
1621.31	580
1623.39	586
1625.46	588
1627.54	598
1629.62	596
1631.69	568
1633.77	550
1635.84	586
1637.91	594
1639.99	616
1642.06	582
1644.13	556
1646.2	574
1648.27	562
1650.34	558
1652.41	558
1654.47	538
1656.54	550
1658.61	560
1660.67	540
1662.74	566
1664.81	572
1666.87	534
1668.93	570
1671	566
1673.06	510
1675.12	548
1677.18	546
1679.24	526
1681.3	540
1683.36	530
1685.42	530
1687.47	520
1689.53	542
1691.59	510
1693.64	514
1695.7	520
1697.75	504
1699.81	524
1701.86	508
1703.91	514
1705.97	544
1708.02	536
1710.07	522
1712.12	536
1714.17	528
1716.22	548
1718.26	498
1720.31	494
1722.36	514
1724.4	512
1726.45	506
1728.49	508
1730.54	508
1732.58	498
1734.63	516
1736.67	512
1738.71	506
1740.75	502
1742.79	500
1744.83	536
1746.87	496
1748.91	478
1750.95	510
1752.98	528
1755.02	496
1757.06	486
1759.09	506
1761.13	482
1763.16	518
1765.19	520
1767.23	492
1769.26	484
1771.29	488
1773.32	484
1775.35	512
1777.38	504
1779.41	500
1781.44	518
1783.47	494
1785.49	516
1787.52	474
1789.55	498
1791.57	504
1793.6	502
1795.62	490
1797.64	504
1799.67	482
1801.69	484
1803.71	496
1805.73	514
1807.75	494
1809.77	516
1811.79	496
1813.81	502
1815.83	510
1817.84	500
1819.86	500
1821.88	474
1823.89	486
1825.91	504
1827.92	490
1829.93	472
1831.95	462
1833.96	498
1835.97	494
1837.98	496
1839.99	480
1842	482
1844.01	442
1846.02	496
1848.03	478
1850.03	498
1852.04	466
1854.05	494
1856.05	482
1858.06	454
1860.06	480
1862.06	464
1864.07	482
1866.07	482
1868.07	460
1870.07	470
1872.07	464
1874.07	462
1876.07	476
1878.07	476
1880.07	492
1882.07	478
1884.06	464
1886.06	476
1888.05	454
1890.05	504
1892.04	506
1894.04	490
1896.03	468
1898.02	454
1900.01	470
1902	462
1903.99	478
1905.98	496
1907.97	480
1909.96	486
1911.95	462
1913.94	482
1915.93	474
1917.91	464
1919.9	492
1921.88	462
1923.87	468
1925.85	468
1927.83	458
1929.82	488
1931.8	460
1933.78	474
1935.76	506
1937.74	500
1939.72	478
1941.7	480
1943.68	482
1945.65	504
1947.63	488
1949.61	458
1951.58	466
1953.56	498
1955.53	480
1957.51	472
1959.48	456
1961.45	456
1963.43	442
1965.4	454
1967.37	470
1969.34	438
1971.31	480
1973.28	480
1975.25	486
1977.22	470
1979.18	434
1981.15	446
1983.12	466
1985.08	430
1987.05	442
1989.01	470
1990.97	442
1992.94	438
1994.9	462
1996.86	442
1998.82	442
2000.78	444
2002.74	462
2004.7	470
2006.66	442
2008.62	450
2010.58	456
2012.54	472
2014.49	448
2016.45	440
2018.4	442
2020.36	452
2022.31	462
2024.27	478
2026.22	408
2028.17	463
2030.12	448
2032.07	454
2034.03	462
2035.98	444
2037.93	466
2039.87	428
2041.82	478
2043.77	448
2045.72	448
2047.66	416
2049.61	452
2051.55	428
2053.5	424
2055.44	462
2057.39	448
2059.33	440
2061.27	466
2063.21	432
2065.15	434
2067.09	434
2069.03	454
2070.97	448
2072.91	450
2074.85	442
2076.79	472
2078.73	448
2080.66	450
2082.6	458
2084.53	442
2086.47	474
2088.4	452
2090.33	454
2092.27	418
2094.2	452
2096.13	462
2098.06	456
2099.99	454
2101.92	440
2103.85	438
2105.78	460
2107.71	426
2109.64	458
2111.56	444
2113.49	466
2115.41	452
2117.34	440
2119.26	440
2121.19	476
2123.11	426
2125.03	408
2126.96	444
2128.88	428
2130.8	478
2132.72	450
2134.64	408
2136.56	422
2138.48	442
2140.4	454
2142.31	442
2144.23	456
2146.15	428
2148.06	428
2149.98	440
2151.89	450
2153.81	456
2155.72	446
2157.63	432
2159.55	414
2161.46	424
2163.37	452
2165.28	424
2167.19	448
2169.1	440
2171.01	436
2172.91	448
2174.82	432
2176.73	458
2178.64	436
2180.54	442
2182.45	466
2184.35	424
2186.26	444
2188.16	432
2190.06	420
2191.96	426
2193.87	408
2195.77	426
2197.67	452
2199.57	418
2201.47	460
2203.37	418
2205.27	422
2207.16	396
2209.06	428
2210.96	444
2212.85	420
2214.75	450
2216.64	440
2218.54	452
2220.43	430
2222.33	422
2224.22	429.73
2226.11	431.851
2228	430.383
2229.89	456.707
2231.78	422.87
2233.67	412.86
2235.56	431.74
2237.45	419.223
2239.34	417.33
2241.23	428.969
2243.11	439.592
2245	441.954
2246.89	426.885
2248.77	432.22
2250.66	436.387
2252.54	442.601
2254.42	422.673
2256.31	441.46
2258.19	427.162
2260.07	423.31
2261.95	417.521
2263.83	404.18
2265.71	418.652
2267.59	416.138
2269.47	417.631
2271.35	426.702
2273.23	427.55
2275.1	426.504
2276.98	414.204
2278.86	412.1
2280.73	429.134
2282.61	416.496
2284.48	415.34
2286.36	411.31
2288.23	406.284
2290.1	406.583
2291.98	404.087
2293.85	423.038
2295.72	399.636
2297.59	419.396
2299.46	415.001
2301.33	397.804
2303.2	407.84
2305.06	404.358
2306.93	404.248
2308.8	406.949
2310.67	388.537
2312.53	400.73
2314.4	411.165
2316.26	417.175
2317.62	418
2319.5	406
2321.37	396
2323.24	386
2325.12	408
2326.99	402
2328.86	400
2330.73	404
2332.6	406
2334.47	392
2336.34	396
2338.2	388
2340.07	392
2341.94	398
2343.81	410
2345.67	412
2347.54	400
2349.4	396
2351.27	384
2353.13	402
2354.99	396
2356.86	406
2358.72	388
2360.58	362
2362.44	400
2364.3	368
2366.16	396
2368.02	380
2369.88	372
2371.74	380
2373.6	368
2375.45	374
2377.31	378
2379.17	408
2381.02	370
2382.88	392
2384.73	388
2386.58	378
2388.44	374
2390.29	360
2392.14	372
2393.99	362
2395.85	368
2397.7	360
2399.55	350
2401.4	354
2403.25	372
2405.09	372
2406.94	368
2408.79	372
2410.63	354
2412.48	346
2414.33	362
2416.17	358
2418.02	372
2419.86	368
2421.7	352
2423.55	340
2425.39	354
2427.23	358
2429.07	362
2430.91	356
2432.75	334
2434.59	364
2436.43	350
2438.27	346
2440.11	336
2441.95	360
2443.78	336
2445.62	366
2447.46	334
2449.29	338
2451.13	334
2452.96	346
2454.79	336
2456.63	344
2458.46	336
2460.29	348
2462.12	322
2463.95	314
2465.78	338
2467.61	342
2469.44	336
2471.27	328
2473.1	322
2474.93	298
2476.76	326
2478.58	326
2480.41	340
2482.23	312
2484.06	318
2485.88	310
2487.71	314
2489.53	298
2491.35	310
2493.18	300
2495	322
2496.82	312
2498.64	318
2500.46	296
2502.28	312
2504.1	280
2505.92	324
2507.74	304
2509.55	306
2511.37	302
2513.19	312
2515	308
2516.82	286
2518.63	292
2520.45	304
2522.26	300
2524.07	302
2525.89	280
2527.7	290
2529.51	278
2531.32	300
2533.13	288
2534.94	280
2536.75	310
2538.56	322
2540.37	266
2542.18	286
2543.98	288
2545.79	268
2547.6	262
2549.4	272
2551.21	274
2553.01	288
2554.82	278
2556.62	274
2558.42	252
2560.23	282
2562.03	276
2563.83	266
2565.63	276
2567.43	276
2569.23	272
2571.03	264
2572.83	252
2574.63	264
2576.43	270
2578.22	264
2580.02	270
2581.82	270
2583.61	272
2585.41	264
2587.2	272
2589	256
2590.79	254
2592.58	240
2594.38	256
2596.17	246
2597.96	264
2599.75	252
2601.54	238
2603.33	258
2605.12	248
2606.91	248
2608.7	240
2610.49	250
2612.27	262
2614.06	236
2615.85	234
2617.63	248
2619.42	228
2621.2	232
2622.99	244
2624.77	228
2626.55	224
2628.34	242
2630.12	226
2631.9	252
2633.68	208
2635.46	248
2637.24	236
2639.02	224
2640.8	230
2642.58	220
2644.36	226
2646.14	232
2647.91	216
2649.69	210
2651.46	222
2653.24	222
2655.01	234
2656.79	216
2658.56	224
2660.34	214
2662.11	218
2663.88	210
2665.65	208
2667.42	212
2669.2	194
2670.96	4294
2672.73	236
2674.5	228
2676.27	222
2678.04	222
2679.81	198
2681.58	210
2683.34	230
2685.11	200
2686.87	214
2688.64	182
2690.4	212
2692.17	198
2693.93	190
2695.69	194
2697.46	190
2699.22	208
2700.98	208
2702.74	180
2704.5	212
2706.26	192
2708.02	190
2709.78	196
2711.54	200
2713.3	188
2715.05	184
2716.81	186
2718.57	200
2720.32	178
2722.08	198
2723.83	192
2725.59	172
2727.34	184
2729.09	184
2730.85	176
2732.6	198
2734.35	176
2736.1	186
2737.85	180
2739.6	172
2741.35	176
2743.1	172
2744.85	174
2746.6	166
2748.35	178
2750.09	166
2751.84	164
2753.59	176
2755.33	174
2757.08	162
2758.82	180
2760.57	176
2762.31	172
2764.05	154
2765.79	164
2767.54	178
2769.28	164
2771.02	160
2772.76	160
2774.5	158
2776.24	166
2777.98	158
2779.72	170
2781.46	152
2783.19	170
2784.93	160
2786.67	158
2788.4	168
2790.14	152
2791.87	148
2793.61	168
2795.34	152
2797.07	160
2798.81	148
2800.54	142
2802.27	156
2804	144
2805.74	156
2807.47	158
2809.2	142
2810.93	150
2812.65	136
2814.38	154
2816.11	148
2817.84	132
2819.56	140
2821.29	136
2823.02	152
2824.74	138
2826.47	146
2828.19	152
2829.92	146
2831.64	144
2833.36	142
2835.09	136
2836.81	130
2838.53	150
2840.25	150
2841.97	126
2843.69	142
2845.41	134
2847.13	128
2848.85	140
2850.57	134
2852.28	140
2854	134
2855.72	124
2857.43	110
2859.15	124
2860.86	122
2862.58	118
2864.29	122
2866.01	118
2867.72	122
2869.43	132
2871.14	118
2872.86	112
2874.57	124
2876.28	116
2877.99	132
2879.7	124
2881.41	110
2883.11	120
2884.82	110
2886.53	126
2888.24	118
2889.94	114
2891.65	126
2893.36	120
2895.06	112
2896.77	110
2898.47	124
2900.17	112
2901.88	128
2903.58	110
2905.28	106
2906.98	110
2908.69	108
2910.39	110
2912.09	104
2913.79	112
2915.49	112
2917.19	116
2918.88	104
2920.58	104
2922.28	116
2923.98	122
2925.67	116
2927.37	114
2929.06	100
2930.76	96
2932.45	104
2934.15	102
2935.84	104
2937.53	100
2939.23	120
2940.92	108
2942.61	98
2944.3	110
2945.99	92
2947.68	98
2949.37	100
2951.06	106
2952.75	98
2954.44	110
2956.12	96
2957.81	110
2959.5	104
2961.18	104
2962.87	110
2964.56	102
2966.24	106
2967.92	120
2969.61	106
2971.29	96
2972.97	88
2974.66	104
2976.34	100
2978.02	102
2979.7	94
2981.38	94
2983.06	108
2984.74	104
2986.42	86
2988.1	84
2989.78	92
2991.45	84
2993.13	98
2994.81	94
2996.48	88
2998.16	100
2999.83	86