File: muestras/suculenta_dedo/inside_pr_11.txt
#Acq. time (s)=	10
#Accumulations=	1
#Range (cm-¹)=	200...3000
#Windows=	3
#Autofocus=	Off
#AutoExposure=	Off
#Spike filter=	Off
#Delay time (s)=	0
#Binning=	1
#Readout mode=	Signal
#DeNoise=	Off
#ICS correction=	Off
#Dark correction=	Off
#Inst. Process=	Off
#Instrument=	LabRAM HR Evol
#Detector=	Syncerity OE
#Objective=	x100_VIS
#Grating=	600 (500nm)
#ND Filter=	1%
#Laser=	633nm_Edge
#Hole=	30.0125
#Range=	Visible
#Project=	Omar
#Sample=	03-07-23
#Site=	fings
#Title=	inside_pr
#Remark=
#Date=	03.07.2023 15:08
#Acquired=	03.07.2023 15:08:13
201.713	56
204.247	60
206.778	64
209.311	64
211.84	46
214.371	60
216.899	70
219.428	72
221.955	62
224.482	62
227.007	62
229.531	72
232.055	72
234.579	76
237.1	76
239.621	68
242.141	68
244.661	74
247.179	78
249.698	80
252.215	74
254.731	80
257.246	84
259.761	70
262.273	72
264.786	86
267.298	74
269.809	76
272.319	68
274.828	76
277.336	78
279.844	72
282.351	78
284.855	76
287.361	78
289.866	76
292.368	80
294.871	80
297.372	76
299.873	70
302.372	70
304.872	88
307.37	88
309.866	78
312.364	96
314.859	84
317.353	90
319.848	84
322.341	90
324.833	92
327.324	100
329.814	94
332.304	88
334.792	98
337.28	90
339.767	90
342.254	94
344.739	102
347.224	102
349.708	104
352.191	102
354.673	98
357.155	102
359.634	100
362.114	100
364.593	110
367.07	120
369.548	104
372.024	112
374.499	92
376.974	112
379.447	104
381.92	118
384.392	114
386.864	112
389.333	114
391.802	114
394.272	120
396.739	112
399.206	116
401.673	118
404.138	126
406.602	124
409.066	124
411.528	118
413.99	132
416.451	128
418.911	114
421.371	116
423.83	128
426.288	132
428.745	138
431.201	140
433.657	130
436.111	132
438.565	142
441.017	140
443.469	152
445.921	140
448.37	150
450.821	142
453.27	142
455.717	148
458.165	148
460.61	152
463.056	138
465.5	168
467.945	144
470.387	146
472.829	156
475.271	148
477.711	166
480.15	170
482.589	156
485.027	156
487.465	176
489.901	172
492.337	148
494.771	160
497.205	172
499.638	184
502.07	160
504.502	160
506.933	184
509.363	174
511.792	168
514.219	174
516.647	200
519.073	168
521.5	196
523.924	178
526.348	182
528.772	180
531.194	188
533.616	190
536.036	190
538.457	202
540.875	188
543.294	202
545.712	202
548.128	190
550.545	178
552.959	206
555.373	198
557.788	200
560.2	210
562.612	214
565.023	198
567.433	212
569.843	232
572.251	202
574.659	228
577.066	210
579.472	214
581.878	210
584.283	226
586.687	228
589.09	216
591.493	220
593.893	242
596.294	236
598.694	224
601.093	240
603.491	246
605.889	252
608.285	252
610.682	242
613.076	248
615.471	236
617.864	260
620.256	272
622.648	264
625.039	280
627.429	278
629.819	266
632.208	274
634.595	268
636.982	276
639.369	296
641.755	290
644.139	302
646.523	300
648.906	288
651.288	312
653.67	292
656.051	300
658.429	314
660.808	328
663.187	308
665.565	308
667.942	314
670.317	314
672.692	322
675.067	312
677.44	314
679.813	312
682.184	340
684.556	336
686.926	334
689.296	338
691.664	352
694.033	350
696.4	344
698.766	380
701.133	396
703.497	362
705.861	410
708.224	374
710.586	388
712.949	406
715.31	384
717.67	398
720.029	410
722.388	420
724.746	428
727.103	416
729.458	422
731.814	450
734.168	424
736.523	436
738.876	444
741.227	454
743.579	454
745.931	464
748.28	484
750.629	482
752.977	498
755.325	480
757.672	498
760.018	476
762.363	502
764.708	526
767.052	522
769.394	498
771.737	544
774.078	534
776.419	526
778.758	562
781.097	524
783.435	584
785.773	566
788.11	568
790.446	570
792.781	588
795.115	616
797.449	606
799.782	586
802.115	594
804.446	630
806.777	654
809.106	632
811.435	638
813.764	608
816.091	690
818.418	680
820.743	682
823.069	722
825.393	710
827.717	712
830.039	712
832.362	702
834.683	738
837.003	756
839.324	754
841.643	754
843.961	736
846.278	784
848.594	818
850.91	804
853.227	794
855.541	810
857.855	808
860.168	814
862.48	852
864.79	840
867.101	846
869.411	888
871.721	910
874.029	912
876.336	926
878.643	902
880.95	910
883.254	928
885.559	960
887.862	954
890.166	950
892.467	964
894.77	962
897.07	1028
899.371	988
901.669	1006
903.968	1030
906.266	1036
908.563	1002
910.859	1066
913.154	1052
915.449	1114
917.742	1108
920.036	1094
922.329	1070
924.621	1148
926.911	1154
929.201	1154
931.49	1132
933.779	1196
936.068	1194
938.355	1222
940.64	1206
942.926	1282
945.212	1234
947.495	1234
949.779	1304
952.062	1310
954.344	1308
956.625	1330
958.905	1322
961.184	1370
963.464	1366
965.742	1384
968.02	1396
970.296	1406
972.572	1420
974.847	1458
977.121	1452
979.396	1508
981.669	1466
983.941	1496
986.212	1526
988.483	1530
990.753	1506
993.022	1568
995.29	1614
997.558	1586
999.825	1638
1002.09	1566
1004.36	1634
1006.62	1660
1008.89	1644
1011.15	1742
1013.41	1706
1015.67	1722
1017.93	1718
1020.19	1770
1022.45	1808
1024.71	1764
1026.97	1806
1029.23	1842
1031.49	1790
1033.74	1848
1036	1852
1038.25	1944
1040.5	1938
1042.76	1944
1045.01	1938
1047.26	2062
1049.51	2038
1051.76	1952
1054.01	2108
1056.26	2096
1058.51	2028
1060.75	2104
1063	2096
1065.25	2148
1067.49	2176
1069.73	2122
1071.98	2212
1074.22	2158
1076.46	2206
1078.7	2264
1080.94	2234
1083.18	2288
1085.42	2288
1087.66	2310
1089.9	2284
1092.14	2344
1094.37	2346
1096.61	2322
1098.84	2348
1101.08	2354
1103.31	2456
1105.54	2402
1107.77	2360
1110	2402
1112.23	2494
1114.46	2438
1116.69	2396
1118.92	2480
1121.15	2506
1123.37	2484
1125.6	2564
1127.83	2460
1130.05	2520
1132.27	2566
1134.5	2534
1136.72	2568
1138.94	2522
1141.16	2606
1143.38	2620
1145.6	2620
1147.82	2634
1150.04	2652
1152.26	2598
1154.47	2638
1156.69	2658
1158.9	2690
1161.12	2658
1163.33	2734
1165.54	2692
1167.76	2756
1169.97	2718
1172.18	2730
1174.39	2686
1176.6	2704
1178.81	2712
1181.02	2694
1183.22	2686
1185.43	2642
1187.63	2766
1189.84	2598
1192.04	2640
1194.25	2632
1196.45	2592
1198.65	2636
1200.85	2612
1203.05	2588
1205.25	2586
1207.45	2588
1209.65	2652
1211.85	2580
1214.05	2624
1216.24	2622
1218.44	2508
1220.64	2498
1222.83	2514
1225.02	2572
1227.22	2506
1229.41	2442
1231.6	2436
1233.79	2482
1235.98	2492
1238.17	2448
1240.36	2488
1242.55	2404
1244.73	2438
1246.92	2408
1249.11	2368
1251.29	2394
1253.48	2368
1255.66	2348
1257.84	2326
1260.03	2288
1262.21	2240
1264.39	2270
1266.57	2228
1268.75	2226
1270.93	2174
1273.11	2278
1275.28	2230
1277.46	2154
1279.64	2220
1281.81	2148
1283.98	2108.96
1286.16	2191.56
1288.33	2086.3
1290.5	2088.8
1292.68	2042.22
1294.85	2012.05
1297.02	1991.88
1299.19	2023.75
1301.36	1987.35
1303.53	1989.58
1305.69	1932.41
1307.86	1931.48
1310.03	1875.72
1312.19	1887.15
1314.36	1871.17
1316.52	1816.63
1318.68	1814.35
1320.85	1794.86
1323.01	1752.32
1325.17	1765.12
1327.33	1712.35
1329.49	1710.36
1331.65	1665.49
1333.81	1647.04
1335.97	1626.09
1338.12	1640.09
1340.28	1587.01
1342.44	1571.1
1344.59	1566.79
1346.75	1523.77
1348.9	1537.03
1351.05	1517.06
1353.2	1515.59
1355.36	1500.24
1357.51	1460.72
1359.66	1397.77
1361.81	1428.34
1363.96	1408.57
1366.1	1418.35
1368.25	1384.25
1370.4	1364.77
1372.54	1351.6
1374.69	1329.05
1376.83	1361.75
1378.98	1334.44
1381.12	1325.05
1383.26	1273.88
1385.41	1264.53
1387.55	1266.85
1389.69	1212.01
1391.83	1211.42
1393.02	1196
1395.17	1184
1397.32	1202
1399.47	1228
1401.62	1146
1403.77	1188
1405.91	1204
1408.06	1164
1410.2	1130
1412.35	1158
1414.49	1190
1416.63	1144
1418.78	1122
1420.92	1086
1423.06	1098
1425.2	1132
1427.34	1100
1429.48	1108
1431.61	1124
1433.75	1084
1435.89	1070
1438.02	1042
1440.16	1068
1442.3	1032
1444.43	1046
1446.56	1024
1448.7	1006
1450.83	1022
1452.96	998
1455.09	984
1457.22	1056
1459.35	984
1461.48	992
1463.61	982
1465.73	950
1467.86	990
1469.98	972
1472.11	990
1474.24	974
1476.36	964
1478.48	940
1480.6	934
1482.73	920
1484.85	874
1486.97	928
1489.09	934
1491.21	926
1493.33	890
1495.44	916
1497.56	928
1499.68	912
1501.79	872
1503.91	892
1506.02	894
1508.14	892
1510.25	848
1512.36	852
1514.48	842
1516.59	844
1518.7	872
1520.81	878
1522.92	854
1525.02	828
1527.13	834
1529.24	830
1531.35	818
1533.45	814
1535.56	810
1537.66	796
1539.77	776
1541.87	810
1543.97	800
1546.08	810
1548.18	778
1550.28	756
1552.38	790
1554.48	768
1556.57	756
1558.67	760
1560.77	778
1562.87	746
1564.96	768
1567.06	784
1569.15	774
1571.25	738
1573.34	736
1575.43	738
1577.53	768
1579.62	752
1581.71	750
1583.8	760
1585.89	732
1587.98	706
1590.06	716
1592.15	720
1594.24	734
1596.33	700
1598.41	724
1600.5	746
1602.58	684
1604.66	682
1606.75	720
1608.83	692
1610.91	722
1612.99	704
1615.07	712
1617.15	694
1619.23	684
1621.31	710
1623.39	690
1625.46	682
1627.54	690
1629.62	690
1631.69	690
1633.77	648
1635.84	686
1637.91	688
1639.99	672
1642.06	650
1644.13	676
1646.2	624
1648.27	656
1650.34	656
1652.41	676
1654.47	644
1656.54	684
1658.61	642
1660.67	658
1662.74	630
1664.81	662
1666.87	670
1668.93	656
1671	634
1673.06	644
1675.12	604
1677.18	652
1679.24	626
1681.3	646
1683.36	614
1685.42	632
1687.47	634
1689.53	628
1691.59	612
1693.64	618
1695.7	656
1697.75	602
1699.81	594
1701.86	646
1703.91	604
1705.97	598
1708.02	584
1710.07	600
1712.12	610
1714.17	584
1716.22	610
1718.26	596
1720.31	608
1722.36	602
1724.4	558
1726.45	588
1728.49	586
1730.54	612
1732.58	608
1734.63	610
1736.67	566
1738.71	590
1740.75	610
1742.79	600
1744.83	600
1746.87	560
1748.91	568
1750.95	578
1752.98	572
1755.02	544
1757.06	568
1759.09	600
1761.13	564
1763.16	584
1765.19	572
1767.23	570
1769.26	588
1771.29	554
1773.32	574
1775.35	592
1777.38	584
1779.41	562
1781.44	576
1783.47	580
1785.49	586
1787.52	548
1789.55	556
1791.57	586
1793.6	552
1795.62	550
1797.64	556
1799.67	586
1801.69	552
1803.71	584
1805.73	588
1807.75	568
1809.77	596
1811.79	542
1813.81	554
1815.83	580
1817.84	556
1819.86	572
1821.88	538
1823.89	528
1825.91	540
1827.92	604
1829.93	562
1831.95	584
1833.96	552
1835.97	558
1837.98	556
1839.99	554
1842	524
1844.01	562
1846.02	548
1848.03	542
1850.03	562
1852.04	554
1854.05	562
1856.05	518
1858.06	558
1860.06	542
1862.06	558
1864.07	556
1866.07	558
1868.07	540
1870.07	522
1872.07	528
1874.07	574
1876.07	508
1878.07	544
1880.07	540
1882.07	544
1884.06	538
1886.06	556
1888.05	550
1890.05	536
1892.04	528
1894.04	522
1896.03	540
1898.02	530
1900.01	546
1902	536
1903.99	534
1905.98	540
1907.97	532
1909.96	538
1911.95	524
1913.94	524
1915.93	548
1917.91	540
1919.9	534
1921.88	528
1923.87	540
1925.85	546
1927.83	510
1929.82	550
1931.8	506
1933.78	536
1935.76	568
1937.74	526
1939.72	518
1941.7	544
1943.68	524
1945.65	536
1947.63	554
1949.61	538
1951.58	526
1953.56	526
1955.53	500
1957.51	552
1959.48	514
1961.45	564
1963.43	526
1965.4	496
1967.37	552
1969.34	532
1971.31	526
1973.28	536
1975.25	522
1977.22	512
1979.18	490
1981.15	518
1983.12	508
1985.08	498
1987.05	538
1989.01	516
1990.97	528
1992.94	520
1994.9	526
1996.86	524
1998.82	526
2000.78	484
2002.74	520
2004.7	528
2006.66	530
2008.62	520
2010.58	520
2012.54	552
2014.49	536
2016.45	550
2018.4	522
2020.36	490
2022.31	520
2024.27	498
2026.22	540
2028.17	502
2030.12	502
2032.07	482
2034.03	502
2035.98	496
2037.93	498
2039.87	510
2041.82	476
2043.77	516
2045.72	510
2047.66	518
2049.61	478
2051.55	502
2053.5	544
2055.44	544
2057.39	508
2059.33	492
2061.27	510
2063.21	512
2065.15	518
2067.09	514
2069.03	512
2070.97	514
2072.91	500
2074.85	502
2076.79	526
2078.73	514
2080.66	482
2082.6	522
2084.53	526
2086.47	510
2088.4	498
2090.33	474
2092.27	502
2094.2	498
2096.13	520
2098.06	512
2099.99	498
2101.92	510
2103.85	492
2105.78	506
2107.71	508
2109.64	484
2111.56	494
2113.49	532
2115.41	500
2117.34	500
2119.26	506
2121.19	484
2123.11	482
2125.03	492
2126.96	492
2128.88	508
2130.8	506
2132.72	498
2134.64	498
2136.56	526
2138.48	496
2140.4	520
2142.31	500
2144.23	488
2146.15	514
2148.06	496
2149.98	502
2151.89	520
2153.81	488
2155.72	490
2157.63	500
2159.55	496
2161.46	500
2163.37	482
2165.28	502
2167.19	474
2169.1	488
2171.01	476
2172.91	510
2174.82	488
2176.73	468
2178.64	498
2180.54	510
2182.45	512
2184.35	516
2186.26	506
2188.16	502
2190.06	476
2191.96	490
2193.87	478
2195.77	496
2197.67	474
2199.57	488
2201.47	458
2203.37	496
2205.27	512
2207.16	488
2209.06	490
2210.96	482
2212.85	490
2214.75	490
2216.64	476
2218.54	482
2220.43	488
2222.33	484
2224.22	489.373
2226.11	488.229
2228	489.455
2229.89	488.48
2231.78	483.267
2233.67	493.5
2235.56	476.623
2237.45	498.14
2239.34	473.829
2241.23	480.265
2243.11	474.782
2245	468.313
2246.89	473.745
2248.77	465.831
2250.66	480.138
2252.54	470.061
2254.42	451.223
2256.31	460.971
2258.19	464.959
2260.07	472.669
2261.95	471.814
2263.83	469.32
2265.71	456.998
2267.59	440.458
2269.47	487.739
2271.35	461.068
2273.23	471.247
2275.1	461.521
2276.98	460.892
2278.86	467.16
2280.73	461.825
2282.61	455.431
2284.48	444.39
2286.36	449.865
2288.23	440.412
2290.1	449.753
2291.98	455.973
2293.85	446.807
2295.72	428.264
2297.59	440.666
2299.46	450.244
2301.33	435.697
2303.2	436.722
2305.06	423.838
2306.93	429.04
2308.8	430.038
2310.67	430.947
2312.53	447.17
2314.4	424.268
2316.26	424.236
2317.62	410
2319.5	428
2321.37	422
2323.24	442
2325.12	414
2326.99	428
2328.86	416
2330.73	414
2332.6	410
2334.47	424
2336.34	434
2338.2	432
2340.07	422
2341.94	436
2343.81	418
2345.67	412
2347.54	420
2349.4	426
2351.27	424
2353.13	422
2354.99	434
2356.86	428
2358.72	406
2360.58	408
2362.44	420
2364.3	412
2366.16	418
2368.02	424
2369.88	406
2371.74	406
2373.6	394
2375.45	432
2377.31	410
2379.17	432
2381.02	404
2382.88	402
2384.73	418
2386.58	388
2388.44	390
2390.29	400
2392.14	402
2393.99	406
2395.85	388
2397.7	370
2399.55	392
2401.4	396
2403.25	388
2405.09	382
2406.94	406
2408.79	390
2410.63	368
2412.48	374
2414.33	374
2416.17	384
2418.02	386
2419.86	408
2421.7	388
2423.55	368
2425.39	386
2427.23	388
2429.07	392
2430.91	364
2432.75	388
2434.59	384
2436.43	364
2438.27	400
2440.11	368
2441.95	364
2443.78	356
2445.62	356
2447.46	374
2449.29	368
2451.13	372
2452.96	370
2454.79	368
2456.63	332
2458.46	352
2460.29	368
2462.12	344
2463.95	346
2465.78	350
2467.61	358
2469.44	366
2471.27	356
2473.1	334
2474.93	348
2476.76	334
2478.58	342
2480.41	336
2482.23	340
2484.06	342
2485.88	354
2487.71	340
2489.53	352
2491.35	328
2493.18	316
2495	348
2496.82	330
2498.64	350
2500.46	314
2502.28	336
2504.1	308
2505.92	316
2507.74	306
2509.55	326
2511.37	318
2513.19	332
2515	304
2516.82	324
2518.63	326
2520.45	314
2522.26	306
2524.07	314
2525.89	296
2527.7	310
2529.51	324
2531.32	324
2533.13	298
2534.94	284
2536.75	324
2538.56	290
2540.37	312
2542.18	300
2543.98	282
2545.79	300
2547.6	310
2549.4	308
2551.21	320
2553.01	304
2554.82	290
2556.62	288
2558.42	298
2560.23	292
2562.03	298
2563.83	280
2565.63	310
2567.43	286
2569.23	294
2571.03	288
2572.83	270
2574.63	302
2576.43	274
2578.22	288
2580.02	284
2581.82	282
2583.61	280
2585.41	298
2587.2	290
2589	266
2590.79	270
2592.58	274
2594.38	266
2596.17	282
2597.96	264
2599.75	276
2601.54	276
2603.33	268
2605.12	250
2606.91	256
2608.7	276
2610.49	274
2612.27	256
2614.06	244
2615.85	248
2617.63	248
2619.42	256
2621.2	258
2622.99	280
2624.77	256
2626.55	268
2628.34	246
2630.12	260
2631.9	260
2633.68	246
2635.46	256
2637.24	254
2639.02	252
2640.8	262
2642.58	238
2644.36	230
2646.14	254
2647.91	250
2649.69	240
2651.46	236
2653.24	252
2655.01	242
2656.79	234
2658.56	220
2660.34	244
2662.11	244
2663.88	220
2665.65	248
2667.42	216
2669.2	234
2670.96	244
2672.73	246
2674.5	230
2676.27	258
2678.04	226
2679.81	240
2681.58	224
2683.34	218
2685.11	228
2686.87	238
2688.64	222
2690.4	228
2692.17	218
2693.93	224
2695.69	218
2697.46	228
2699.22	226
2700.98	230
2702.74	210
2704.5	228
2706.26	238
2708.02	198
2709.78	236
2711.54	224
2713.3	212
2715.05	216
2716.81	196
2718.57	208
2720.32	210
2722.08	206
2723.83	214
2725.59	204
2727.34	196
2729.09	208
2730.85	204
2732.6	192
2734.35	188
2736.1	204
2737.85	194
2739.6	200
2741.35	176
2743.1	198
2744.85	186
2746.6	188
2748.35	186
2750.09	200
2751.84	184
2753.59	188
2755.33	184
2757.08	176
2758.82	176
2760.57	178
2762.31	186
2764.05	178
2765.79	174
2767.54	188
2769.28	178
2771.02	188
2772.76	180
2774.5	178
2776.24	164
2777.98	172
2779.72	170
2781.46	172
2783.19	188
2784.93	170
2786.67	178
2788.4	180
2790.14	182
2791.87	166
2793.61	170
2795.34	190
2797.07	164
2798.81	168
2800.54	178
2802.27	168
2804	160
2805.74	174
2807.47	164
2809.2	162
2810.93	148
2812.65	156
2814.38	170
2816.11	156
2817.84	152
2819.56	164
2821.29	158
2823.02	168
2824.74	148
2826.47	156
2828.19	150
2829.92	146
2831.64	156
2833.36	146
2835.09	164
2836.81	156
2838.53	146
2840.25	164
2841.97	134
2843.69	152
2845.41	150
2847.13	166
2848.85	138
2850.57	142
2852.28	150
2854	138
2855.72	144
2857.43	138
2859.15	138
2860.86	134
2862.58	134
2864.29	148
2866.01	144
2867.72	156
2869.43	132
2871.14	132
2872.86	146
2874.57	134
2876.28	134
2877.99	138
2879.7	140
2881.41	126
2883.11	124
2884.82	136
2886.53	126
2888.24	134
2889.94	138
2891.65	126
2893.36	122
2895.06	122
2896.77	124
2898.47	126
2900.17	140
2901.88	126
2903.58	124
2905.28	118
2906.98	136
2908.69	132
2910.39	118
2912.09	110
2913.79	128
2915.49	126
2917.19	120
2918.88	122
2920.58	118
2922.28	114
2923.98	108
2925.67	120
2927.37	114
2929.06	118
2930.76	116
2932.45	134
2934.15	122
2935.84	122
2937.53	114
2939.23	124
2940.92	122
2942.61	116
2944.3	116
2945.99	104
2947.68	110
2949.37	122
2951.06	98
2952.75	118
2954.44	114
2956.12	112
2957.81	110
2959.5	112
2961.18	100
2962.87	102
2964.56	118
2966.24	122
2967.92	114
2969.61	112
2971.29	116
2972.97	114
2974.66	102
2976.34	100
2978.02	112
2979.7	118
2981.38	110
2983.06	108
2984.74	104
2986.42	108
2988.1	108
2989.78	104
2991.45	110
2993.13	90
2994.81	98
2996.48	112
2998.16	108
2999.83	108