File: muestras/suculenta_dedo/inside_pr_17.txt
#Acq. time (s)=	10
#Accumulations=	1
#Range (cm-¹)=	200...3000
#Windows=	3
#Autofocus=	Off
#AutoExposure=	Off
#Spike filter=	Off
#Delay time (s)=	0
#Binning=	1
#Readout mode=	Signal
#DeNoise=	Off
#ICS correction=	Off
#Dark correction=	Off
#Inst. Process=	Off
#Instrument=	LabRAM HR Evol
#Detector=	Syncerity OE
#Objective=	x100_VIS
#Grating=	600 (500nm)
#ND Filter=	1%
#Laser=	633nm_Edge
#Hole=	30.0125
#Range=	Visible
#Project=	Omar
#Sample=	03-07-23
#Site=	fings
#Title=	inside_pr
#Remark=
#Date=	03.07.2023 15:13
#Acquired=	03.07.2023 15:13:44
201.713	38
204.247	36
206.778	42
209.311	46
211.84	48
214.371	40
216.899	38
219.428	42
221.955	34
224.482	38
227.007	42
229.531	46
232.055	40
234.579	40
237.1	40
239.621	40
242.141	38
244.661	42
247.179	44
249.698	46
252.215	32
254.731	46
257.246	42
259.761	38
262.273	42
264.786	44
267.298	36
269.809	36
272.319	44
274.828	46
277.336	46
279.844	38
282.351	38
284.855	50
287.361	54
289.866	42
292.368	44
294.871	48
297.372	50
299.873	50
302.372	46
304.872	44
307.37	44
309.866	50
312.364	54
314.859	54
317.353	48
319.848	54
322.341	62
324.833	54
327.324	54
329.814	50
332.304	44
334.792	60
337.28	54
339.767	54
342.254	56
344.739	48
347.224	58
349.708	52
352.191	54
354.673	58
357.155	56
359.634	56
362.114	48
364.593	58
367.07	62
369.548	54
372.024	62
374.499	52
376.974	50
379.447	54
381.92	52
384.392	62
386.864	62
389.333	58
391.802	54
394.272	62
396.739	66
399.206	54
401.673	68
404.138	54
406.602	52
409.066	58
411.528	66
413.99	66
416.451	68
418.911	76
421.371	64
423.83	62
426.288	60
428.745	70
431.201	66
433.657	64
436.111	72
438.565	70
441.017	66
443.469	72
445.921	64
448.37	72
450.821	66
453.27	66
455.717	62
458.165	72
460.61	66
463.056	70
465.5	62
467.945	84
470.387	70
472.829	80
475.271	74
477.711	76
480.15	74
482.589	74
485.027	74
487.465	76
489.901	84
492.337	78
494.771	82
497.205	84
499.638	90
502.07	80
504.502	78
506.933	76
509.363	84
511.792	86
514.219	70
516.647	76
519.073	74
521.5	78
523.924	76
526.348	82
528.772	80
531.194	80
533.616	80
536.036	96
538.457	88
540.875	90
543.294	88
545.712	96
548.128	84
550.545	96
552.959	84
555.373	92
557.788	90
560.2	92
562.612	94
565.023	88
567.433	90
569.843	86
572.251	108
574.659	96
577.066	92
579.472	96
581.878	108
584.283	96
586.687	110
589.09	106
591.493	104
593.893	114
596.294	110
598.694	114
601.093	110
603.491	102
605.889	106
608.285	110
610.682	112
613.076	124
615.471	102
617.864	112
620.256	124
622.648	122
625.039	112
627.429	128
629.819	114
632.208	122
634.595	122
636.982	118
639.369	142
641.755	132
644.139	138
646.523	106
648.906	130
651.288	140
653.67	130
656.051	130
658.429	126
660.808	144
663.187	128
665.565	140
667.942	156
670.317	132
672.692	152
675.067	134
677.44	158
679.813	152
682.184	142
684.556	146
686.926	148
689.296	156
691.664	160
694.033	148
696.4	136
698.766	152
701.133	172
703.497	184
705.861	160
708.224	172
710.586	172
712.949	174
715.31	174
717.67	172
720.029	176
722.388	194
724.746	186
727.103	182
729.458	176
731.814	188
734.168	184
736.523	170
738.876	170
741.227	190
743.579	176
745.931	198
748.28	196
750.629	202
752.977	184
755.325	200
757.672	198
760.018	196
762.363	208
764.708	200
767.052	202
769.394	214
771.737	208
774.078	214
776.419	228
778.758	234
781.097	218
783.435	226
785.773	226
788.11	234
790.446	258
792.781	246
795.115	234
797.449	236
799.782	240
802.115	252
804.446	264
806.777	266
809.106	274
811.435	258
813.764	262
816.091	262
818.418	282
820.743	252
823.069	278
825.393	280
827.717	278
830.039	294
832.362	278
834.683	282
837.003	288
839.324	294
841.643	300
843.961	312
846.278	320
848.594	298
850.91	306
853.227	320
855.541	298
857.855	328
860.168	324
862.48	342
864.79	338
867.101	346
869.411	370
871.721	350
874.029	370
876.336	360
878.643	368
880.95	388
883.254	360
885.559	370
887.862	400
890.166	396
892.467	382
894.77	382
897.07	404
899.371	412
901.669	408
903.968	398
906.266	406
908.563	386
910.859	428
913.154	434
915.449	432
917.742	422
920.036	434
922.329	450
924.621	452
926.911	462
929.201	454
931.49	466
933.779	442
936.068	454
938.355	462
940.64	476
942.926	486
945.212	494
947.495	478
949.779	498
952.062	474
954.344	518
956.625	500
958.905	542
961.184	548
963.464	540
965.742	548
968.02	510
970.296	576
972.572	570
974.847	542
977.121	552
979.396	562
981.669	594
983.941	604
986.212	570
988.483	590
990.753	596
993.022	604
995.29	614
997.558	628
999.825	632
1002.09	624
1004.36	638
1006.62	620
1008.89	650
1011.15	672
1013.41	648
1015.67	674
1017.93	660
1020.19	674
1022.45	670
1024.71	706
1026.97	718
1029.23	710
1031.49	734
1033.74	712
1036	714
1038.25	736
1040.5	760
1042.76	746
1045.01	734
1047.26	792
1049.51	792
1051.76	790
1054.01	794
1056.26	798
1058.51	788
1060.75	838
1063	810
1065.25	820
1067.49	884
1069.73	868
1071.98	844
1074.22	866
1076.46	858
1078.7	910
1080.94	880
1083.18	890
1085.42	882
1087.66	912
1089.9	908
1092.14	906
1094.37	916
1096.61	934
1098.84	890
1101.08	872
1103.31	924
1105.54	972
1107.77	984
1110	926
1112.23	978
1114.46	948
1116.69	974
1118.92	978
1121.15	980
1123.37	990
1125.6	982
1127.83	1024
1130.05	1016
1132.27	1054
1134.5	1016
1136.72	1052
1138.94	1020
1141.16	1058
1143.38	1078
1145.6	1068
1147.82	1028
1150.04	1098
1152.26	1098
1154.47	1072
1156.69	1070
1158.9	1094
1161.12	1070
1163.33	1046
1165.54	1096
1167.76	1084
1169.97	1082
1172.18	1094
1174.39	1100
1176.6	1090
1178.81	1100
1181.02	1100
1183.22	1086
1185.43	1094
1187.63	1104
1189.84	1076
1192.04	1066
1194.25	1082
1196.45	1062
1198.65	1078
1200.85	1080
1203.05	1062
1205.25	1096
1207.45	1054
1209.65	1042
1211.85	1034
1214.05	1036
1216.24	1040
1218.44	1058
1220.64	1060
1222.83	1024
1225.02	1014
1227.22	1034
1229.41	1010
1231.6	1002
1233.79	1034
1235.98	1010
1238.17	1022
1240.36	994
1242.55	976
1244.73	946
1246.92	978
1249.11	962
1251.29	1002
1253.48	958
1255.66	952
1257.84	954
1260.03	940
1262.21	928
1264.39	970
1266.57	928
1268.75	938
1270.93	944
1273.11	922
1275.28	896
1277.46	940
1279.64	898
1281.81	910
1283.98	912.255
1286.16	875.73
1288.33	845.824
1290.5	865.681
1292.68	878.439
1294.85	853.187
1297.02	847.771
1299.19	849.15
1301.36	840.135
1303.53	847.279
1305.69	854.795
1307.86	841.436
1310.03	803.961
1312.19	808.148
1314.36	789.799
1316.52	817.152
1318.68	790.844
1320.85	765.776
1323.01	796.986
1325.17	754.37
1327.33	773.502
1329.49	761.547
1331.65	753.664
1333.81	752.125
1335.97	738.999
1338.12	731.116
1340.28	724.802
1342.44	731.401
1344.59	723.234
1346.75	702.026
1348.9	713.488
1351.05	709.736
1353.2	705.36
1355.36	679.53
1357.51	684.201
1359.66	662.728
1361.81	695.529
1363.96	644.027
1366.1	643.511
1368.25	659.511
1370.4	662.597
1372.54	658.229
1374.69	646.027
1376.83	630.008
1378.98	639.569
1381.12	641.204
1383.26	626.687
1385.41	599.788
1387.55	610.585
1389.69	619.031
1391.83	606.876
1393.02	620
1395.17	602
1397.32	616
1399.47	602
1401.62	576
1403.77	576
1405.91	574
1408.06	570
1410.2	586
1412.35	576
1414.49	602
1416.63	554
1418.78	546
1420.92	536
1423.06	532
1425.2	526
1427.34	550
1429.48	546
1431.61	520
1433.75	516
1435.89	540
1438.02	530
1440.16	536
1442.3	520
1444.43	508
1446.56	512
1448.7	516
1450.83	506
1452.96	504
1455.09	484
1457.22	518
1459.35	486
1461.48	494
1463.61	456
1465.73	490
1467.86	472
1469.98	488
1472.11	492
1474.24	458
1476.36	476
1478.48	490
1480.6	464
1482.73	454
1484.85	444
1486.97	452
1489.09	444
1491.21	436
1493.33	428
1495.44	446
1497.56	440
1499.68	412
1501.79	426
1503.91	456
1506.02	442
1508.14	432
1510.25	432
1512.36	430
1514.48	418
1516.59	410
1518.7	400
1520.81	396
1522.92	402
1525.02	426
1527.13	390
1529.24	414
1531.35	384
1533.45	410
1535.56	374
1537.66	406
1539.77	394
1541.87	372
1543.97	382
1546.08	388
1548.18	380
1550.28	390
1552.38	352
1554.48	366
1556.57	388
1558.67	350
1560.77	380
1562.87	376
1564.96	376
1567.06	368
1569.15	350
1571.25	352
1573.34	356
1575.43	378
1577.53	374
1579.62	356
1581.71	366
1583.8	354
1585.89	364
1587.98	370
1590.06	354
1592.15	382
1594.24	360
1596.33	354
1598.41	342
1600.5	356
1602.58	332
1604.66	354
1606.75	346
1608.83	370
1610.91	326
1612.99	370
1615.07	330
1617.15	350
1619.23	340
1621.31	340
1623.39	342
1625.46	344
1627.54	356
1629.62	342
1631.69	356
1633.77	328
1635.84	342
1637.91	308
1639.99	332
1642.06	328
1644.13	336
1646.2	330
1648.27	320
1650.34	326
1652.41	324
1654.47	326
1656.54	328
1658.61	310
1660.67	306
1662.74	320
1664.81	332
1666.87	336
1668.93	322
1671	342
1673.06	298
1675.12	322
1677.18	312
1679.24	318
1681.3	316
1683.36	318
1685.42	286
1687.47	322
1689.53	292
1691.59	314
1693.64	290
1695.7	302
1697.75	298
1699.81	286
1701.86	296
1703.91	290
1705.97	302
1708.02	286
1710.07	304
1712.12	288
1714.17	296
1716.22	294
1718.26	292
1720.31	308
1722.36	278
1724.4	302
1726.45	302
1728.49	298
1730.54	286
1732.58	284
1734.63	274
1736.67	304
1738.71	294
1740.75	290
1742.79	290
1744.83	306
1746.87	296
1748.91	292
1750.95	290
1752.98	300
1755.02	298
1757.06	294
1759.09	288
1761.13	290
1763.16	278
1765.19	298
1767.23	280
1769.26	296
1771.29	280
1773.32	282
1775.35	298
1777.38	300
1779.41	294
1781.44	280
1783.47	274
1785.49	292
1787.52	272
1789.55	300
1791.57	280
1793.6	286
1795.62	270
1797.64	276
1799.67	288
1801.69	286
1803.71	284
1805.73	292
1807.75	278
1809.77	270
1811.79	288
1813.81	288
1815.83	266
1817.84	272
1819.86	296
1821.88	292
1823.89	268
1825.91	282
1827.92	282
1829.93	296
1831.95	276
1833.96	282
1835.97	298
1837.98	272
1839.99	278
1842	254
1844.01	266
1846.02	288
1848.03	296
1850.03	276
1852.04	282
1854.05	284
1856.05	280
1858.06	258
1860.06	278
1862.06	274
1864.07	266
1866.07	266
1868.07	268
1870.07	250
1872.07	248
1874.07	262
1876.07	276
1878.07	286
1880.07	278
1882.07	272
1884.06	276
1886.06	254
1888.05	282
1890.05	264
1892.04	278
1894.04	304
1896.03	278
1898.02	272
1900.01	270
1902	266
1903.99	270
1905.98	290
1907.97	260
1909.96	276
1911.95	266
1913.94	294
1915.93	292
1917.91	280
1919.9	294
1921.88	276
1923.87	264
1925.85	290
1927.83	260
1929.82	264
1931.8	254
1933.78	278
1935.76	270
1937.74	302
1939.72	266
1941.7	282
1943.68	264
1945.65	282
1947.63	274
1949.61	276
1951.58	272
1953.56	280
1955.53	274
1957.51	272
1959.48	264
1961.45	276
1963.43	248
1965.4	260
1967.37	282
1969.34	266
1971.31	274
1973.28	260
1975.25	262
1977.22	284
1979.18	272
1981.15	256
1983.12	276
1985.08	278
1987.05	286
1989.01	270
1990.97	254
1992.94	252
1994.9	256
1996.86	262
1998.82	278
2000.78	292
2002.74	280
2004.7	252
2006.66	272
2008.62	268
2010.58	250
2012.54	272
2014.49	274
2016.45	266
2018.4	262
2020.36	260
2022.31	252
2024.27	268
2026.22	252
2028.17	257
2030.12	262
2032.07	258
2034.03	254
2035.98	262
2037.93	260
2039.87	274
2041.82	256
2043.77	272
2045.72	270
2047.66	264
2049.61	250
2051.55	274
2053.5	274
2055.44	264
2057.39	246
2059.33	258
2061.27	290
2063.21	262
2065.15	266
2067.09	262
2069.03	272
2070.97	254
2072.91	268
2074.85	252
2076.79	238
2078.73	256
2080.66	280
2082.6	254
2084.53	260
2086.47	244
2088.4	260
2090.33	248
2092.27	256
2094.2	248
2096.13	250
2098.06	246
2099.99	262
2101.92	256
2103.85	260
2105.78	256
2107.71	252
2109.64	254
2111.56	266
2113.49	250
2115.41	246
2117.34	264
2119.26	266
2121.19	272
2123.11	252
2125.03	260
2126.96	254
2128.88	242
2130.8	252
2132.72	266
2134.64	252
2136.56	262
2138.48	260
2140.4	252
2142.31	236
2144.23	250
2146.15	266
2148.06	262
2149.98	240
2151.89	256
2153.81	254
2155.72	244
2157.63	246
2159.55	232
2161.46	246
2163.37	260
2165.28	246
2167.19	250
2169.1	242
2171.01	270
2172.91	254
2174.82	264
2176.73	276
2178.64	230
2180.54	254
2182.45	232
2184.35	264
2186.26	238
2188.16	218
2190.06	254
2191.96	246
2193.87	234
2195.77	248
2197.67	234
2199.57	244
2201.47	224
2203.37	256
2205.27	246
2207.16	254
2209.06	228
2210.96	244
2212.85	228
2214.75	234
2216.64	254
2218.54	246
2220.43	230
2222.33	238
2224.22	259.746
2226.11	247.014
2228	241.21
2229.89	236.947
2231.78	253.27
2233.67	247.609
2235.56	241.234
2237.45	250.472
2239.34	241.3
2241.23	249.625
2243.11	230.408
2245	256.33
2246.89	255.715
2248.77	236.618
2250.66	245.768
2252.54	241.795
2254.42	243.602
2256.31	245.842
2258.19	249.903
2260.07	255.762
2261.95	247.081
2263.83	252.63
2265.71	248.608
2267.59	245.818
2269.47	254.403
2271.35	243.694
2273.23	247.037
2275.1	243.842
2276.98	256.537
2278.86	250.98
2280.73	247.809
2282.61	244.072
2284.48	257.456
2286.36	239.355
2288.23	255.093
2290.1	250.573
2291.98	266.121
2293.85	242.493
2295.72	250.004
2297.59	252.988
2299.46	258.554
2301.33	249.491
2303.2	251.693
2305.06	253.525
2306.93	229.628
2308.8	240.224
2310.67	256.18
2312.53	246.36
2314.4	256.326
2316.26	257.93
2317.62	260
2319.5	234
2321.37	250
2323.24	248
2325.12	232
2326.99	232
2328.86	252
2330.73	254
2332.6	268
2334.47	236
2336.34	258
2338.2	244
2340.07	264
2341.94	250
2343.81	250
2345.67	250
2347.54	238
2349.4	232
2351.27	244
2353.13	232
2354.99	234
2356.86	230
2358.72	242
2360.58	226
2362.44	234
2364.3	236
2366.16	236
2368.02	242
2369.88	246
2371.74	252
2373.6	250
2375.45	240
2377.31	248
2379.17	244
2381.02	214
2382.88	234
2384.73	210
2386.58	222
2388.44	210
2390.29	226
2392.14	240
2393.99	218
2395.85	214
2397.7	222
2399.55	238
2401.4	234
2403.25	228
2405.09	216
2406.94	220
2408.79	222
2410.63	236
2412.48	226
2414.33	228
2416.17	226
2418.02	224
2419.86	206
2421.7	234
2423.55	214
2425.39	210
2427.23	228
2429.07	212
2430.91	216
2432.75	222
2434.59	204
2436.43	220
2438.27	214
2440.11	212
2441.95	220
2443.78	212
2445.62	208
2447.46	214
2449.29	218
2451.13	208
2452.96	200
2454.79	210
2456.63	218
2458.46	208
2460.29	206
2462.12	226
2463.95	196
2465.78	208
2467.61	182
2469.44	210
2471.27	210
2473.1	204
2474.93	190
2476.76	186
2478.58	200
2480.41	192
2482.23	198
2484.06	186
2485.88	196
2487.71	168
2489.53	190
2491.35	214
2493.18	198
2495	192
2496.82	208
2498.64	206
2500.46	184
2502.28	188
2504.1	196
2505.92	188
2507.74	182
2509.55	184
2511.37	204
2513.19	174
2515	178
2516.82	192
2518.63	196
2520.45	176
2522.26	166
2524.07	182
2525.89	178
2527.7	178
2529.51	178
2531.32	176
2533.13	190
2534.94	160
2536.75	170
2538.56	178
2540.37	152
2542.18	178
2543.98	166
2545.79	162
2547.6	154
2549.4	160
2551.21	154
2553.01	174
2554.82	170
2556.62	174
2558.42	158
2560.23	160
2562.03	166
2563.83	152
2565.63	170
2567.43	172
2569.23	158
2571.03	152
2572.83	172
2574.63	168
2576.43	156
2578.22	142
2580.02	160
2581.82	142
2583.61	168
2585.41	172
2587.2	150
2589	148
2590.79	160
2592.58	142
2594.38	154
2596.17	160
2597.96	148
2599.75	150
2601.54	160
2603.33	142
2605.12	150
2606.91	150
2608.7	148
2610.49	154
2612.27	144
2614.06	158
2615.85	138
2617.63	166
2619.42	146
2621.2	144
2622.99	130
2624.77	146
2626.55	134
2628.34	146
2630.12	144
2631.9	138
2633.68	134
2635.46	130
2637.24	130
2639.02	130
2640.8	138
2642.58	138
2644.36	134
2646.14	136
2647.91	146
2649.69	148
2651.46	146
2653.24	140
2655.01	128
2656.79	124
2658.56	138
2660.34	144
2662.11	142
2663.88	136
2665.65	122
2667.42	142
2669.2	138
2670.96	134
2672.73	124
2674.5	128
2676.27	118
2678.04	118
2679.81	128
2681.58	146
2683.34	122
2685.11	120
2686.87	120
2688.64	126
2690.4	118
2692.17	128
2693.93	132
2695.69	120
2697.46	136
2699.22	126
2700.98	136
2702.74	126
2704.5	126
2706.26	122
2708.02	114
2709.78	126
2711.54	134
2713.3	114
2715.05	116
2716.81	122
2718.57	122
2720.32	116
2722.08	104
2723.83	120
2725.59	114
2727.34	108
2729.09	106
2730.85	104
2732.6	110
2734.35	114
2736.1	108
2737.85	100
2739.6	118
2741.35	102
2743.1	104
2744.85	108
2746.6	276
2748.35	864
2750.09	112
2751.84	112
2753.59	112
2755.33	114
2757.08	110
2758.82	108
2760.57	108
2762.31	102
2764.05	110
2765.79	114
2767.54	100
2769.28	100
2771.02	96
2772.76	100
2774.5	92
2776.24	110
2777.98	104
2779.72	104
2781.46	96
2783.19	104
2784.93	100
2786.67	96
2788.4	98
2790.14	88
2791.87	100
2793.61	96
2795.34	104
2797.07	88
2798.81	84
2800.54	100
2802.27	82
2804	90
2805.74	102
2807.47	90
2809.2	98
2810.93	90
2812.65	92
2814.38	104
2816.11	94
2817.84	84
2819.56	96
2821.29	84
2823.02	78
2824.74	96
2826.47	84
2828.19	100
2829.92	78
2831.64	84
2833.36	92
2835.09	98
2836.81	92
2838.53	90
2840.25	84
2841.97	74
2843.69	88
2845.41	88
2847.13	84
2848.85	74
2850.57	80
2852.28	76
2854	88
2855.72	78
2857.43	84
2859.15	74
2860.86	78
2862.58	80
2864.29	86
2866.01	76
2867.72	76
2869.43	72
2871.14	86
2872.86	76
2874.57	84
2876.28	74
2877.99	76
2879.7	78
2881.41	72
2883.11	76
2884.82	74
2886.53	80
2888.24	80
2889.94	74
2891.65	80
2893.36	76
2895.06	68
2896.77	78
2898.47	64
2900.17	74
2901.88	72
2903.58	78
2905.28	62
2906.98	80
2908.69	72
2910.39	60
2912.09	68
2913.79	72
2915.49	66
2917.19	68
2918.88	66
2920.58	80
2922.28	78
2923.98	70
2925.67	76
2927.37	74
2929.06	60
2930.76	60
2932.45	72
2934.15	66
2935.84	60
2937.53	74
2939.23	60
2940.92	66
2942.61	74
2944.3	68
2945.99	70
2947.68	72
2949.37	62
2951.06	64
2952.75	66
2954.44	60
2956.12	66
2957.81	78
2959.5	66
2961.18	56
2962.87	64
2964.56	66
2966.24	76
2967.92	68
2969.61	62
2971.29	72
2972.97	58
2974.66	72
2976.34	62
2978.02	66
2979.7	68
2981.38	62
2983.06	58
2984.74	66
2986.42	64
2988.1	62
2989.78	68
2991.45	66
2993.13	70
2994.81	66
2996.48	62
2998.16	56
2999.83	64