File: muestras/suculenta_dedo/inside_pr_14.txt
#Acq. time (s)=	10
#Accumulations=	1
#Range (cm-¹)=	200...3000
#Windows=	3
#Autofocus=	Off
#AutoExposure=	Off
#Spike filter=	Off
#Delay time (s)=	0
#Binning=	1
#Readout mode=	Signal
#DeNoise=	Off
#ICS correction=	Off
#Dark correction=	Off
#Inst. Process=	Off
#Instrument=	LabRAM HR Evol
#Detector=	Syncerity OE
#Objective=	x100_VIS
#Grating=	600 (500nm)
#ND Filter=	1%
#Laser=	633nm_Edge
#Hole=	30.0125
#Range=	Visible
#Project=	Omar
#Sample=	03-07-23
#Site=	fings
#Title=	inside_pr
#Remark=
#Date=	03.07.2023 15:11
#Acquired=	03.07.2023 15:11:03
201.713	44
204.247	46
206.778	38
209.311	44
211.84	52
214.371	50
216.899	44
219.428	44
221.955	46
224.482	48
227.007	50
229.531	46
232.055	46
234.579	50
237.1	50
239.621	40
242.141	46
244.661	38
247.179	46
249.698	44
252.215	46
254.731	46
257.246	46
259.761	44
262.273	52
264.786	44
267.298	40
269.809	58
272.319	54
274.828	48
277.336	54
279.844	54
282.351	54
284.855	48
287.361	48
289.866	52
292.368	56
294.871	56
297.372	50
299.873	56
302.372	52
304.872	54
307.37	60
309.866	52
312.364	70
314.859	58
317.353	58
319.848	52
322.341	62
324.833	62
327.324	54
329.814	58
332.304	56
334.792	66
337.28	50
339.767	54
342.254	54
344.739	60
347.224	80
349.708	58
352.191	68
354.673	64
357.155	56
359.634	64
362.114	74
364.593	66
367.07	66
369.548	66
372.024	78
374.499	64
376.974	66
379.447	62
381.92	76
384.392	66
386.864	76
389.333	78
391.802	66
394.272	76
396.739	70
399.206	68
401.673	74
404.138	60
406.602	74
409.066	74
411.528	82
413.99	70
416.451	68
418.911	80
421.371	70
423.83	88
426.288	92
428.745	86
431.201	80
433.657	88
436.111	96
438.565	104
441.017	88
443.469	86
445.921	74
448.37	80
450.821	76
453.27	108
455.717	76
458.165	88
460.61	84
463.056	80
465.5	88
467.945	96
470.387	82
472.829	94
475.271	86
477.711	94
480.15	90
482.589	84
485.027	96
487.465	84
489.901	100
492.337	106
494.771	102
497.205	98
499.638	88
502.07	96
504.502	106
506.933	108
509.363	104
511.792	96
514.219	96
516.647	106
519.073	102
521.5	114
523.924	112
526.348	110
528.772	116
531.194	110
533.616	96
536.036	108
538.457	116
540.875	110
543.294	104
545.712	120
548.128	114
550.545	108
552.959	112
555.373	110
557.788	102
560.2	120
562.612	112
565.023	114
567.433	120
569.843	130
572.251	124
574.659	122
577.066	124
579.472	116
581.878	120
584.283	126
586.687	132
589.09	136
591.493	140
593.893	136
596.294	118
598.694	140
601.093	130
603.491	130
605.889	128
608.285	136
610.682	146
613.076	140
615.471	146
617.864	146
620.256	154
622.648	140
625.039	162
627.429	158
629.819	152
632.208	146
634.595	150
636.982	166
639.369	158
641.755	154
644.139	154
646.523	160
648.906	160
651.288	164
653.67	174
656.051	180
658.429	172
660.808	180
663.187	190
665.565	164
667.942	168
670.317	172
672.692	160
675.067	184
677.44	188
679.813	168
682.184	176
684.556	202
686.926	192
689.296	184
691.664	192
694.033	204
696.4	214
698.766	184
701.133	210
703.497	204
705.861	204
708.224	230
710.586	214
712.949	220
715.31	224
717.67	212
720.029	236
722.388	226
724.746	230
727.103	242
729.458	244
731.814	240
734.168	230
736.523	250
738.876	256
741.227	238
743.579	252
745.931	254
748.28	252
750.629	270
752.977	254
755.325	260
757.672	254
760.018	282
762.363	268
764.708	268
767.052	262
769.394	272
771.737	288
774.078	288
776.419	284
778.758	304
781.097	290
783.435	296
785.773	296
788.11	290
790.446	308
792.781	328
795.115	308
797.449	310
799.782	334
802.115	328
804.446	296
806.777	346
809.106	332
811.435	350
813.764	354
816.091	352
818.418	378
820.743	364
823.069	356
825.393	384
827.717	356
830.039	398
832.362	378
834.683	386
837.003	406
839.324	394
841.643	396
843.961	400
846.278	392
848.594	420
850.91	428
853.227	416
855.541	416
857.855	404
860.168	466
862.48	440
864.79	446
867.101	436
869.411	460
871.721	460
874.029	456
876.336	486
878.643	508
880.95	476
883.254	490
885.559	466
887.862	484
890.166	486
892.467	516
894.77	508
897.07	494
899.371	504
901.669	508
903.968	526
906.266	524
908.563	520
910.859	562
913.154	554
915.449	560
917.742	566
920.036	568
922.329	574
924.621	574
926.911	586
929.201	588
931.49	606
933.779	610
936.068	600
938.355	614
940.64	644
942.926	642
945.212	642
947.495	656
949.779	664
952.062	666
954.344	634
956.625	700
958.905	676
961.184	694
963.464	690
965.742	730
968.02	688
970.296	724
972.572	704
974.847	762
977.121	756
979.396	762
981.669	728
983.941	780
986.212	762
988.483	800
990.753	804
993.022	794
995.29	822
997.558	794
999.825	796
1002.09	848
1004.36	812
1006.62	822
1008.89	854
1011.15	812
1013.41	884
1015.67	844
1017.93	908
1020.19	898
1022.45	894
1024.71	926
1026.97	916
1029.23	952
1031.49	928
1033.74	952
1036	982
1038.25	964
1040.5	1014
1042.76	986
1045.01	1010
1047.26	1052
1049.51	1024
1051.76	1042
1054.01	1072
1056.26	1034
1058.51	1066
1060.75	1028
1063	1052
1065.25	1104
1067.49	1098
1069.73	1100
1071.98	1130
1074.22	1158
1076.46	1130
1078.7	1154
1080.94	1124
1083.18	1104
1085.42	1152
1087.66	1194
1089.9	1166
1092.14	1182
1094.37	1194
1096.61	1228
1098.84	1224
1101.08	1194
1103.31	1176
1105.54	1252
1107.77	1226
1110	1236
1112.23	1220
1114.46	1294
1116.69	1286
1118.92	1232
1121.15	1230
1123.37	1294
1125.6	1306
1127.83	1280
1130.05	1338
1132.27	1340
1134.5	1342
1136.72	1294
1138.94	1338
1141.16	1348
1143.38	1376
1145.6	1376
1147.82	1342
1150.04	1390
1152.26	1410
1154.47	1394
1156.69	1388
1158.9	1364
1161.12	1372
1163.33	1368
1165.54	1422
1167.76	1434
1169.97	1396
1172.18	1440
1174.39	1350
1176.6	1398
1178.81	1376
1181.02	1472
1183.22	1386
1185.43	1394
1187.63	1406
1189.84	1418
1192.04	1350
1194.25	1386
1196.45	1376
1198.65	1392
1200.85	1338
1203.05	1426
1205.25	1370
1207.45	1386
1209.65	1368
1211.85	1338
1214.05	1342
1216.24	1288
1218.44	1314
1220.64	1290
1222.83	1330
1225.02	1278
1227.22	1290
1229.41	1334
1231.6	1270
1233.79	1290
1235.98	1316
1238.17	1290
1240.36	1270
1242.55	1268
1244.73	1298
1246.92	1228
1249.11	1284
1251.29	1238
1253.48	1214
1255.66	1262
1257.84	1258
1260.03	1242
1262.21	1200
1264.39	1170
1266.57	1230
1268.75	1176
1270.93	1166
1273.11	1204
1275.28	1174
1277.46	1158
1279.64	1132
1281.81	1108
1283.98	1094.36
1286.16	1102.79
1288.33	1099.05
1290.5	1082.06
1292.68	1108.37
1294.85	1058.26
1297.02	1068.19
1299.19	1052.91
1301.36	1029.27
1303.53	1070.03
1305.69	1072.61
1307.86	1063.15
1310.03	1045.16
1312.19	1022.22
1314.36	996.69
1316.52	1009.63
1318.68	998.362
1320.85	984.919
1323.01	985.144
1325.17	1057.58
1327.33	1184.07
1329.49	948.833
1331.65	939.87
1333.81	948.029
1335.97	935.74
1338.12	943.041
1340.28	914.705
1342.44	902.958
1344.59	892.399
1346.75	884.897
1348.9	880.108
1351.05	839.882
1353.2	856.838
1355.36	877.739
1357.51	849.28
1359.66	857.139
1361.81	836.491
1363.96	803.765
1366.1	812.032
1368.25	806.668
1370.4	789.577
1372.54	808.765
1374.69	788.336
1376.83	774.855
1378.98	778.279
1381.12	765.409
1383.26	751.133
1385.41	738.841
1387.55	753.897
1389.69	757.852
1391.83	744.147
1393.02	732
1395.17	746
1397.32	732
1399.47	736
1401.62	720
1403.77	694
1405.91	730
1408.06	676
1410.2	710
1412.35	710
1414.49	714
1416.63	730
1418.78	670
1420.92	648
1423.06	660
1425.2	656
1427.34	654
1429.48	670
1431.61	656
1433.75	660
1435.89	656
1438.02	648
1440.16	632
1442.3	608
1444.43	652
1446.56	626
1448.7	618
1450.83	652
1452.96	592
1455.09	608
1457.22	594
1459.35	594
1461.48	598
1463.61	610
1465.73	582
1467.86	616
1469.98	582
1472.11	584
1474.24	582
1476.36	596
1478.48	546
1480.6	578
1482.73	568
1484.85	542
1486.97	542
1489.09	602
1491.21	548
1493.33	534
1495.44	502
1497.56	558
1499.68	564
1501.79	526
1503.91	536
1506.02	536
1508.14	524
1510.25	514
1512.36	538
1514.48	486
1516.59	514
1518.7	514
1520.81	534
1522.92	494
1525.02	518
1527.13	486
1529.24	488
1531.35	508
1533.45	502
1535.56	474
1537.66	494
1539.77	474
1541.87	478
1543.97	496
1546.08	462
1548.18	454
1550.28	472
1552.38	470
1554.48	476
1556.57	468
1558.67	448
1560.77	428
1562.87	488
1564.96	450
1567.06	456
1569.15	466
1571.25	464
1573.34	466
1575.43	430
1577.53	442
1579.62	452
1581.71	448
1583.8	456
1585.89	456
1587.98	420
1590.06	446
1592.15	424
1594.24	428
1596.33	416
1598.41	424
1600.5	428
1602.58	404
1604.66	412
1606.75	402
1608.83	440
1610.91	402
1612.99	438
1615.07	452
1617.15	422
1619.23	428
1621.31	394
1623.39	410
1625.46	376
1627.54	382
1629.62	396
1631.69	398
1633.77	402
1635.84	406
1637.91	394
1639.99	418
1642.06	404
1644.13	418
1646.2	408
1648.27	398
1650.34	410
1652.41	374
1654.47	398
1656.54	374
1658.61	382
1660.67	426
1662.74	380
1664.81	382
1666.87	366
1668.93	368
1671	394
1673.06	404
1675.12	390
1677.18	384
1679.24	376
1681.3	376
1683.36	360
1685.42	362
1687.47	368
1689.53	374
1691.59	362
1693.64	360
1695.7	390
1697.75	348
1699.81	358
1701.86	356
1703.91	368
1705.97	360
1708.02	392
1710.07	368
1712.12	392
1714.17	328
1716.22	344
1718.26	346
1720.31	362
1722.36	334
1724.4	372
1726.45	354
1728.49	354
1730.54	364
1732.58	336
1734.63	362
1736.67	370
1738.71	348
1740.75	354
1742.79	356
1744.83	362
1746.87	332
1748.91	344
1750.95	350
1752.98	356
1755.02	348
1757.06	354
1759.09	336
1761.13	340
1763.16	352
1765.19	336
1767.23	364
1769.26	350
1771.29	368
1773.32	330
1775.35	362
1777.38	336
1779.41	360
1781.44	364
1783.47	358
1785.49	352
1787.52	348
1789.55	334
1791.57	346
1793.6	338
1795.62	322
1797.64	384
1799.67	3282
1801.69	364
1803.71	318
1805.73	332
1807.75	342
1809.77	346
1811.79	350
1813.81	322
1815.83	336
1817.84	322
1819.86	338
1821.88	334
1823.89	348
1825.91	332
1827.92	334
1829.93	362
1831.95	344
1833.96	342
1835.97	332
1837.98	322
1839.99	320
1842	348
1844.01	338
1846.02	330
1848.03	310
1850.03	336
1852.04	332
1854.05	316
1856.05	348
1858.06	354
1860.06	344
1862.06	330
1864.07	336
1866.07	318
1868.07	342
1870.07	328
1872.07	330
1874.07	348
1876.07	318
1878.07	336
1880.07	330
1882.07	330
1884.06	340
1886.06	326
1888.05	330
1890.05	346
1892.04	342
1894.04	336
1896.03	326
1898.02	314
1900.01	348
1902	316
1903.99	332
1905.98	330
1907.97	308
1909.96	334
1911.95	342
1913.94	336
1915.93	310
1917.91	316
1919.9	350
1921.88	334
1923.87	326
1925.85	322
1927.83	356
1929.82	322
1931.8	318
1933.78	334
1935.76	304
1937.74	316
1939.72	324
1941.7	320
1943.68	340
1945.65	362
1947.63	338
1949.61	334
1951.58	332
1953.56	340
1955.53	288
1957.51	316
1959.48	326
1961.45	326
1963.43	318
1965.4	314
1967.37	330
1969.34	340
1971.31	336
1973.28	336
1975.25	312
1977.22	326
1979.18	308
1981.15	320
1983.12	326
1985.08	328
1987.05	320
1989.01	308
1990.97	306
1992.94	316
1994.9	320
1996.86	310
1998.82	314
2000.78	308
2002.74	324
2004.7	316
2006.66	308
2008.62	330
2010.58	306
2012.54	320
2014.49	324
2016.45	312
2018.4	332
2020.36	322
2022.31	304
2024.27	314
2026.22	336
2028.17	306
2030.12	294
2032.07	306
2034.03	312
2035.98	322
2037.93	318
2039.87	316
2041.82	312
2043.77	304
2045.72	318
2047.66	304
2049.61	302
2051.55	290
2053.5	314
2055.44	336
2057.39	304
2059.33	316
2061.27	316
2063.21	298
2065.15	308
2067.09	328
2069.03	320
2070.97	296
2072.91	310
2074.85	300
2076.79	306
2078.73	294
2080.66	328
2082.6	316
2084.53	320
2086.47	304
2088.4	298
2090.33	324
2092.27	304
2094.2	302
2096.13	296
2098.06	304
2099.99	310
2101.92	304
2103.85	314
2105.78	324
2107.71	294
2109.64	302
2111.56	316
2113.49	304
2115.41	306
2117.34	292
2119.26	318
2121.19	302
2123.11	324
2125.03	308
2126.96	318
2128.88	310
2130.8	310
2132.72	292
2134.64	300
2136.56	302
2138.48	322
2140.4	304
2142.31	324
2144.23	284
2146.15	302
2148.06	322
2149.98	290
2151.89	326
2153.81	302
2155.72	320
2157.63	296
2159.55	306
2161.46	314
2163.37	316
2165.28	316
2167.19	302
2169.1	296
2171.01	298
2172.91	312
2174.82	328
2176.73	292
2178.64	278
2180.54	274
2182.45	322
2184.35	280
2186.26	286
2188.16	284
2190.06	298
2191.96	290
2193.87	286
2195.77	320
2197.67	314
2199.57	302
2201.47	302
2203.37	298
2205.27	294
2207.16	316
2209.06	280
2210.96	280
2212.85	302
2214.75	298
2216.64	290
2218.54	284
2220.43	296
2222.33	286
2224.22	304.248
2226.11	281.099
2228	304.345
2229.89	283.677
2231.78	285.218
2233.67	295.674
2235.56	288.964
2237.45	297.838
2239.34	293.27
2241.23	298.122
2243.11	282.045
2245	310.637
2246.89	284.605
2248.77	312.368
2250.66	296.103
2252.54	279.093
2254.42	303.536
2256.31	302.195
2258.19	290.572
2260.07	299.074
2261.95	307.246
2263.83	289.31
2265.71	304.061
2267.59	315.346
2269.47	298.735
2271.35	297.696
2273.23	309.53
2275.1	294.583
2276.98	303.833
2278.86	289.19
2280.73	288.306
2282.61	306.144
2284.48	303.941
2286.36	300.21
2288.23	302.128
2290.1	304.246
2291.98	298.842
2293.85	295.845
2295.72	297.369
2297.59	306.284
2299.46	296.189
2301.33	299.955
2303.2	300.878
2305.06	296.5
2306.93	307.628
2308.8	296.938
2310.67	293.742
2312.53	304.775
2314.4	292.55
2316.26	297.773
2317.62	304
2319.5	304
2321.37	292
2323.24	292
2325.12	296
2326.99	302
2328.86	298
2330.73	304
2332.6	296
2334.47	294
2336.34	288
2338.2	304
2340.07	286
2341.94	302
2343.81	286
2345.67	282
2347.54	302
2349.4	304
2351.27	288
2353.13	292
2354.99	270
2356.86	274
2358.72	280
2360.58	284
2362.44	278
2364.3	306
2366.16	296
2368.02	290
2369.88	266
2371.74	280
2373.6	302
2375.45	280
2377.31	288
2379.17	274
2381.02	288
2382.88	282
2384.73	272
2386.58	266
2388.44	282
2390.29	272
2392.14	290
2393.99	278
2395.85	270
2397.7	264
2399.55	268
2401.4	266
2403.25	270
2405.09	254
2406.94	266
2408.79	276
2410.63	278
2412.48	274
2414.33	268
2416.17	268
2418.02	266
2419.86	276
2421.7	276
2423.55	266
2425.39	252
2427.23	246
2429.07	254
2430.91	246
2432.75	268
2434.59	258
2436.43	254
2438.27	256
2440.11	268
2441.95	240
2443.78	276
2445.62	250
2447.46	256
2449.29	238
2451.13	238
2452.96	258
2454.79	252
2456.63	254
2458.46	246
2460.29	258
2462.12	244
2463.95	246
2465.78	252
2467.61	252
2469.44	250
2471.27	240
2473.1	246
2474.93	224
2476.76	260
2478.58	232
2480.41	252
2482.23	222
2484.06	222
2485.88	236
2487.71	242
2489.53	238
2491.35	228
2493.18	226
2495	226
2496.82	232
2498.64	234
2500.46	234
2502.28	214
2504.1	212
2505.92	208
2507.74	230
2509.55	210
2511.37	214
2513.19	232
2515	224
2516.82	208
2518.63	212
2520.45	214
2522.26	218
2524.07	228
2525.89	206
2527.7	218
2529.51	196
2531.32	208
2533.13	218
2534.94	214
2536.75	206
2538.56	224
2540.37	208
2542.18	198
2543.98	196
2545.79	200
2547.6	216
2549.4	210
2551.21	208
2553.01	196
2554.82	198
2556.62	202
2558.42	204
2560.23	204
2562.03	180
2563.83	208
2565.63	186
2567.43	204
2569.23	196
2571.03	202
2572.83	202
2574.63	210
2576.43	204
2578.22	192
2580.02	180
2581.82	208
2583.61	198
2585.41	180
2587.2	184
2589	190
2590.79	192
2592.58	188
2594.38	180
2596.17	172
2597.96	188
2599.75	170
2601.54	192
2603.33	192
2605.12	162
2606.91	166
2608.7	184
2610.49	184
2612.27	186
2614.06	188
2615.85	186
2617.63	176
2619.42	174
2621.2	174
2622.99	190
2624.77	170
2626.55	172
2628.34	190
2630.12	170
2631.9	186
2633.68	182
2635.46	174
2637.24	174
2639.02	178
2640.8	178
2642.58	162
2644.36	174
2646.14	174
2647.91	172
2649.69	172
2651.46	166
2653.24	162
2655.01	148
2656.79	168
2658.56	162
2660.34	170
2662.11	158
2663.88	134
2665.65	178
2667.42	156
2669.2	160
2670.96	174
2672.73	174
2674.5	162
2676.27	162
2678.04	158
2679.81	166
2681.58	158
2683.34	160
2685.11	160
2686.87	160
2688.64	138
2690.4	158
2692.17	150
2693.93	160
2695.69	148
2697.46	156
2699.22	146
2700.98	142
2702.74	146
2704.5	148
2706.26	150
2708.02	142
2709.78	134
2711.54	160
2713.3	142
2715.05	152
2716.81	152
2718.57	136
2720.32	128
2722.08	142
2723.83	140
2725.59	140
2727.34	128
2729.09	138
2730.85	150
2732.6	134
2734.35	144
2736.1	140
2737.85	142
2739.6	136
2741.35	144
2743.1	128
2744.85	138
2746.6	128
2748.35	130
2750.09	132
2751.84	120
2753.59	130
2755.33	126
2757.08	124
2758.82	142
2760.57	118
2762.31	132
2764.05	128
2765.79	120
2767.54	130
2769.28	126
2771.02	130
2772.76	134
2774.5	120
2776.24	124
2777.98	124
2779.72	120
2781.46	120
2783.19	106
2784.93	114
2786.67	128
2788.4	126
2790.14	128
2791.87	114
2793.61	114
2795.34	114
2797.07	122
2798.81	118
2800.54	116
2802.27	106
2804	116
2805.74	118
2807.47	116
2809.2	116
2810.93	122
2812.65	110
2814.38	122
2816.11	108
2817.84	96
2819.56	100
2821.29	108
2823.02	112
2824.74	104
2826.47	102
2828.19	110
2829.92	104
2831.64	108
2833.36	114
2835.09	106
2836.81	98
2838.53	102
2840.25	106
2841.97	106
2843.69	108
2845.41	92
2847.13	106
2848.85	100
2850.57	104
2852.28	90
2854	110
2855.72	102
2857.43	100
2859.15	92
2860.86	98
2862.58	88
2864.29	102
2866.01	102
2867.72	100
2869.43	98
2871.14	98
2872.86	106
2874.57	94
2876.28	98
2877.99	90
2879.7	94
2881.41	92
2883.11	96
2884.82	84
2886.53	92
2888.24	82
2889.94	96
2891.65	76
2893.36	100
2895.06	102
2896.77	90
2898.47	88
2900.17	76
2901.88	106
2903.58	84
2905.28	90
2906.98	88
2908.69	84
2910.39	84
2912.09	86
2913.79	88
2915.49	90
2917.19	90
2918.88	90
2920.58	86
2922.28	82
2923.98	90
2925.67	88
2927.37	82
2929.06	86
2930.76	88
2932.45	74
2934.15	84
2935.84	86
2937.53	80
2939.23	88
2940.92	82
2942.61	76
2944.3	90
2945.99	84
2947.68	76
2949.37	88
2951.06	88
2952.75	82
2954.44	82
2956.12	78
2957.81	72
2959.5	80
2961.18	92
2962.87	78
2964.56	88
2966.24	88
2967.92	82
2969.61	68
2971.29	72
2972.97	76
2974.66	78
2976.34	88
2978.02	78
2979.7	76
2981.38	70
2983.06	66
2984.74	78
2986.42	78
2988.1	82
2989.78	70
2991.45	78
2993.13	80
2994.81	74
2996.48	76
2998.16	74
2999.83	74