File: muestras/suculenta_dedo/inside_pr_16.txt
#Acq. time (s)=	10
#Accumulations=	1
#Range (cm-¹)=	200...3000
#Windows=	3
#Autofocus=	Off
#AutoExposure=	Off
#Spike filter=	Off
#Delay time (s)=	0
#Binning=	1
#Readout mode=	Signal
#DeNoise=	Off
#ICS correction=	Off
#Dark correction=	Off
#Inst. Process=	Off
#Instrument=	LabRAM HR Evol
#Detector=	Syncerity OE
#Objective=	x100_VIS
#Grating=	600 (500nm)
#ND Filter=	1%
#Laser=	633nm_Edge
#Hole=	30.0125
#Range=	Visible
#Project=	Omar
#Sample=	03-07-23
#Site=	fings
#Title=	inside_pr
#Remark=
#Date=	03.07.2023 15:12
#Acquired=	03.07.2023 15:12:50
201.713	38
204.247	42
206.778	50
209.311	36
211.84	44
214.371	48
216.899	46
219.428	46
221.955	46
224.482	44
227.007	50
229.531	46
232.055	56
234.579	42
237.1	38
239.621	44
242.141	48
244.661	50
247.179	44
249.698	42
252.215	46
254.731	48
257.246	48
259.761	40
262.273	50
264.786	48
267.298	52
269.809	66
272.319	48
274.828	48
277.336	54
279.844	56
282.351	60
284.855	40
287.361	48
289.866	50
292.368	52
294.871	50
297.372	52
299.873	48
302.372	54
304.872	56
307.37	56
309.866	46
312.364	48
314.859	58
317.353	56
319.848	56
322.341	50
324.833	52
327.324	54
329.814	66
332.304	52
334.792	58
337.28	56
339.767	54
342.254	50
344.739	50
347.224	60
349.708	62
352.191	60
354.673	46
357.155	58
359.634	56
362.114	62
364.593	56
367.07	68
369.548	60
372.024	60
374.499	50
376.974	68
379.447	66
381.92	72
384.392	68
386.864	60
389.333	68
391.802	68
394.272	68
396.739	70
399.206	60
401.673	68
404.138	62
406.602	64
409.066	62
411.528	56
413.99	60
416.451	66
418.911	84
421.371	72
423.83	64
426.288	74
428.745	84
431.201	70
433.657	80
436.111	78
438.565	78
441.017	64
443.469	86
445.921	84
448.37	82
450.821	82
453.27	84
455.717	64
458.165	84
460.61	86
463.056	84
465.5	88
467.945	94
470.387	84
472.829	92
475.271	94
477.711	80
480.15	84
482.589	88
485.027	80
487.465	90
489.901	78
492.337	88
494.771	86
497.205	90
499.638	94
502.07	90
504.502	78
506.933	90
509.363	90
511.792	108
514.219	92
516.647	96
519.073	90
521.5	86
523.924	96
526.348	92
528.772	96
531.194	100
533.616	96
536.036	98
538.457	100
540.875	106
543.294	98
545.712	110
548.128	110
550.545	96
552.959	90
555.373	104
557.788	114
560.2	110
562.612	106
565.023	104
567.433	104
569.843	112
572.251	100
574.659	114
577.066	124
579.472	120
581.878	114
584.283	110
586.687	126
589.09	110
591.493	130
593.893	114
596.294	118
598.694	124
601.093	130
603.491	116
605.889	122
608.285	136
610.682	130
613.076	124
615.471	124
617.864	128
620.256	130
622.648	128
625.039	124
627.429	130
629.819	136
632.208	142
634.595	140
636.982	150
639.369	150
641.755	154
644.139	144
646.523	134
648.906	140
651.288	140
653.67	150
656.051	160
658.429	150
660.808	148
663.187	152
665.565	152
667.942	164
670.317	158
672.692	156
675.067	162
677.44	156
679.813	174
682.184	164
684.556	174
686.926	176
689.296	172
691.664	166
694.033	182
696.4	182
698.766	174
701.133	174
703.497	168
705.861	180
708.224	188
710.586	174
712.949	180
715.31	196
717.67	192
720.029	198
722.388	210
724.746	202
727.103	208
729.458	212
731.814	220
734.168	218
736.523	212
738.876	200
741.227	244
743.579	206
745.931	236
748.28	216
750.629	212
752.977	240
755.325	252
757.672	216
760.018	240
762.363	228
764.708	230
767.052	254
769.394	252
771.737	220
774.078	268
776.419	262
778.758	256
781.097	252
783.435	274
785.773	266
788.11	264
790.446	268
792.781	274
795.115	280
797.449	270
799.782	278
802.115	298
804.446	286
806.777	314
809.106	286
811.435	302
813.764	302
816.091	314
818.418	312
820.743	334
823.069	306
825.393	326
827.717	322
830.039	336
832.362	314
834.683	348
837.003	352
839.324	336
841.643	368
843.961	340
846.278	346
848.594	360
850.91	356
853.227	362
855.541	370
857.855	368
860.168	382
862.48	404
864.79	378
867.101	408
869.411	372
871.721	370
874.029	416
876.336	394
878.643	408
880.95	402
883.254	412
885.559	422
887.862	450
890.166	420
892.467	420
894.77	430
897.07	468
899.371	496
901.669	454
903.968	458
906.266	488
908.563	466
910.859	470
913.154	460
915.449	488
917.742	482
920.036	510
922.329	496
924.621	532
926.911	548
929.201	506
931.49	520
933.779	550
936.068	518
938.355	530
940.64	544
942.926	556
945.212	542
947.495	574
949.779	556
952.062	588
954.344	580
956.625	586
958.905	580
961.184	612
963.464	602
965.742	616
968.02	606
970.296	658
972.572	634
974.847	646
977.121	658
979.396	646
981.669	652
983.941	682
986.212	684
988.483	668
990.753	702
993.022	694
995.29	714
997.558	710
999.825	738
1002.09	740
1004.36	728
1006.62	740
1008.89	744
1011.15	746
1013.41	744
1015.67	774
1017.93	762
1020.19	812
1022.45	796
1024.71	826
1026.97	810
1029.23	806
1031.49	774
1033.74	792
1036	830
1038.25	846
1040.5	860
1042.76	842
1045.01	878
1047.26	848
1049.51	864
1051.76	880
1054.01	914
1056.26	944
1058.51	914
1060.75	972
1063	926
1065.25	936
1067.49	940
1069.73	1010
1071.98	982
1074.22	986
1076.46	970
1078.7	992
1080.94	998
1083.18	1028
1085.42	1034
1087.66	1036
1089.9	1030
1092.14	1028
1094.37	1042
1096.61	1056
1098.84	1060
1101.08	1066
1103.31	1026
1105.54	1052
1107.77	1058
1110	1070
1112.23	1086
1114.46	1058
1116.69	1126
1118.92	1128
1121.15	1112
1123.37	1076
1125.6	1148
1127.83	1128
1130.05	1138
1132.27	1168
1134.5	1186
1136.72	1170
1138.94	1176
1141.16	1154
1143.38	1204
1145.6	1194
1147.82	1194
1150.04	1202
1152.26	1224
1154.47	1216
1156.69	1236
1158.9	1246
1161.12	1194
1163.33	1208
1165.54	1256
1167.76	1216
1169.97	1242
1172.18	1272
1174.39	1254
1176.6	1244
1178.81	1240
1181.02	1200
1183.22	1242
1185.43	1228
1187.63	1214
1189.84	1202
1192.04	1220
1194.25	1238
1196.45	1228
1198.65	1206
1200.85	1174
1203.05	1236
1205.25	1196
1207.45	1160
1209.65	1184
1211.85	1178
1214.05	1164
1216.24	1206
1218.44	1174
1220.64	1164
1222.83	1174
1225.02	1124
1227.22	1132
1229.41	1142
1231.6	1118
1233.79	1088
1235.98	1138
1238.17	1144
1240.36	1130
1242.55	1102
1244.73	1090
1246.92	1060
1249.11	1128
1251.29	1068
1253.48	1052
1255.66	1078
1257.84	1078
1260.03	1072
1262.21	1110
1264.39	1066
1266.57	986
1268.75	1078
1270.93	1072
1273.11	1012
1275.28	1052
1277.46	1044
1279.64	1026
1281.81	998
1283.98	1014.66
1286.16	1002.84
1288.33	979.729
1290.5	1024.73
1292.68	990.986
1294.85	966.908
1297.02	973.128
1299.19	961.397
1301.36	955.792
1303.53	938.067
1305.69	903.838
1307.86	952.768
1310.03	913.402
1312.19	938.784
1314.36	931.693
1316.52	927.649
1318.68	897.706
1320.85	889.34
1323.01	882.382
1325.17	890.659
1327.33	930.842
1329.49	891.838
1331.65	871.43
1333.81	849.92
1335.97	855.841
1338.12	827.479
1340.28	852.724
1342.44	809.709
1344.59	840.978
1346.75	822.275
1348.9	847.879
1351.05	822.337
1353.2	810.342
1355.36	808.164
1357.51	820.919
1359.66	794.647
1361.81	757.62
1363.96	787.446
1366.1	784.574
1368.25	779.797
1370.4	763.747
1372.54	785.686
1374.69	746.799
1376.83	770.635
1378.98	756.756
1381.12	737.913
1383.26	766.455
1385.41	770.6
1387.55	725.054
1389.69	731.921
1391.83	737.827
1393.02	692
1395.17	714
1397.32	704
1399.47	714
1401.62	736
1403.77	682
1405.91	680
1408.06	680
1410.2	740
1412.35	664
1414.49	660
1416.63	666
1418.78	630
1420.92	656
1423.06	658
1425.2	654
1427.34	648
1429.48	622
1431.61	612
1433.75	618
1435.89	636
1438.02	616
1440.16	614
1442.3	614
1444.43	598
1446.56	616
1448.7	606
1450.83	620
1452.96	580
1455.09	588
1457.22	606
1459.35	588
1461.48	564
1463.61	594
1465.73	594
1467.86	558
1469.98	544
1472.11	580
1474.24	572
1476.36	582
1478.48	560
1480.6	534
1482.73	560
1484.85	558
1486.97	520
1489.09	574
1491.21	528
1493.33	536
1495.44	522
1497.56	506
1499.68	522
1501.79	518
1503.91	528
1506.02	508
1508.14	490
1510.25	534
1512.36	536
1514.48	530
1516.59	516
1518.7	498
1520.81	484
1522.92	506
1525.02	466
1527.13	488
1529.24	468
1531.35	466
1533.45	488
1535.56	464
1537.66	462
1539.77	492
1541.87	478
1543.97	480
1546.08	432
1548.18	450
1550.28	476
1552.38	428
1554.48	432
1556.57	452
1558.67	450
1560.77	462
1562.87	472
1564.96	432
1567.06	456
1569.15	422
1571.25	444
1573.34	428
1575.43	448
1577.53	414
1579.62	428
1581.71	424
1583.8	438
1585.89	436
1587.98	400
1590.06	420
1592.15	422
1594.24	426
1596.33	434
1598.41	418
1600.5	432
1602.58	432
1604.66	406
1606.75	420
1608.83	398
1610.91	422
1612.99	400
1615.07	416
1617.15	392
1619.23	388
1621.31	416
1623.39	394
1625.46	420
1627.54	390
1629.62	386
1631.69	388
1633.77	408
1635.84	402
1637.91	382
1639.99	390
1642.06	384
1644.13	392
1646.2	394
1648.27	398
1650.34	392
1652.41	384
1654.47	390
1656.54	362
1658.61	358
1660.67	364
1662.74	380
1664.81	386
1666.87	388
1668.93	370
1671	372
1673.06	368
1675.12	374
1677.18	370
1679.24	366
1681.3	388
1683.36	374
1685.42	372
1687.47	356
1689.53	368
1691.59	370
1693.64	366
1695.7	364
1697.75	360
1699.81	354
1701.86	372
1703.91	328
1705.97	356
1708.02	330
1710.07	354
1712.12	370
1714.17	352
1716.22	368
1718.26	364
1720.31	338
1722.36	366
1724.4	354
1726.45	344
1728.49	334
1730.54	344
1732.58	348
1734.63	340
1736.67	344
1738.71	342
1740.75	354
1742.79	340
1744.83	342
1746.87	348
1748.91	336
1750.95	356
1752.98	336
1755.02	334
1757.06	332
1759.09	338
1761.13	326
1763.16	348
1765.19	344
1767.23	338
1769.26	336
1771.29	360
1773.32	350
1775.35	330
1777.38	338
1779.41	352
1781.44	330
1783.47	324
1785.49	344
1787.52	342
1789.55	346
1791.57	336
1793.6	350
1795.62	326
1797.64	354
1799.67	336
1801.69	328
1803.71	326
1805.73	340
1807.75	340
1809.77	352
1811.79	342
1813.81	360
1815.83	342
1817.84	338
1819.86	342
1821.88	330
1823.89	310
1825.91	344
1827.92	328
1829.93	326
1831.95	332
1833.96	318
1835.97	334
1837.98	318
1839.99	306
1842	332
1844.01	342
1846.02	316
1848.03	326
1850.03	344
1852.04	358
1854.05	358
1856.05	318
1858.06	338
1860.06	328
1862.06	328
1864.07	310
1866.07	338
1868.07	340
1870.07	330
1872.07	326
1874.07	330
1876.07	302
1878.07	318
1880.07	330
1882.07	328
1884.06	324
1886.06	328
1888.05	308
1890.05	320
1892.04	322
1894.04	334
1896.03	324
1898.02	318
1900.01	318
1902	320
1903.99	314
1905.98	318
1907.97	336
1909.96	306
1911.95	330
1913.94	312
1915.93	312
1917.91	334
1919.9	326
1921.88	322
1923.87	334
1925.85	322
1927.83	322
1929.82	314
1931.8	328
1933.78	332
1935.76	314
1937.74	332
1939.72	312
1941.7	314
1943.68	300
1945.65	328
1947.63	314
1949.61	346
1951.58	314
1953.56	316
1955.53	316
1957.51	310
1959.48	326
1961.45	326
1963.43	306
1965.4	298
1967.37	314
1969.34	328
1971.31	318
1973.28	298
1975.25	318
1977.22	324
1979.18	328
1981.15	312
1983.12	312
1985.08	308
1987.05	316
1989.01	320
1990.97	302
1992.94	304
1994.9	312
1996.86	306
1998.82	320
2000.78	312
2002.74	334
2004.7	314
2006.66	340
2008.62	322
2010.58	294
2012.54	324
2014.49	324
2016.45	314
2018.4	302
2020.36	290
2022.31	294
2024.27	292
2026.22	300
2028.17	321
2030.12	298
2032.07	298
2034.03	294
2035.98	302
2037.93	316
2039.87	346
2041.82	304
2043.77	316
2045.72	298
2047.66	296
2049.61	298
2051.55	312
2053.5	310
2055.44	308
2057.39	308
2059.33	282
2061.27	298
2063.21	298
2065.15	290
2067.09	306
2069.03	310
2070.97	300
2072.91	282
2074.85	312
2076.79	306
2078.73	294
2080.66	300
2082.6	308
2084.53	302
2086.47	300
2088.4	310
2090.33	294
2092.27	302
2094.2	300
2096.13	308
2098.06	312
2099.99	304
2101.92	294
2103.85	308
2105.78	314
2107.71	292
2109.64	314
2111.56	288
2113.49	308
2115.41	304
2117.34	314
2119.26	298
2121.19	298
2123.11	300
2125.03	300
2126.96	304
2128.88	284
2130.8	296
2132.72	300
2134.64	316
2136.56	306
2138.48	322
2140.4	296
2142.31	282
2144.23	302
2146.15	318
2148.06	318
2149.98	308
2151.89	312
2153.81	296
2155.72	310
2157.63	294
2159.55	302
2161.46	288
2163.37	286
2165.28	290
2167.19	284
2169.1	284
2171.01	282
2172.91	294
2174.82	280
2176.73	282
2178.64	294
2180.54	288
2182.45	314
2184.35	286
2186.26	296
2188.16	308
2190.06	292
2191.96	308
2193.87	298
2195.77	302
2197.67	288
2199.57	282
2201.47	292
2203.37	304
2205.27	288
2207.16	296
2209.06	274
2210.96	310
2212.85	282
2214.75	274
2216.64	308
2218.54	282
2220.43	284
2222.33	284
2224.22	269.799
2226.11	279.431
2228	303.921
2229.89	285.893
2231.78	287.167
2233.67	302.09
2235.56	289.958
2237.45	272.905
2239.34	263.6
2241.23	278.8
2243.11	281.68
2245	270.876
2246.89	286.215
2248.77	279.389
2250.66	274.433
2252.54	271.524
2254.42	281.028
2256.31	293.89
2258.19	270.025
2260.07	288.399
2261.95	272.944
2263.83	271.53
2265.71	278.017
2267.59	280.328
2269.47	274.801
2271.35	276.105
2273.23	290.76
2275.1	262.275
2276.98	279.618
2278.86	268.77
2280.73	274.467
2282.61	271.824
2284.48	269.687
2286.36	271.365
2288.23	260.071
2290.1	285.807
2291.98	278.918
2293.85	254.501
2295.72	252.551
2297.59	260.56
2299.46	261.023
2301.33	259.764
2303.2	265.313
2305.06	270.162
2306.93	259.274
2308.8	260.624
2310.67	257.177
2312.53	261.705
2314.4	262.4
2316.26	246.375
2317.62	256
2319.5	252
2321.37	268
2323.24	274
2325.12	268
2326.99	266
2328.86	250
2330.73	268
2332.6	264
2334.47	258
2336.34	258
2338.2	254
2340.07	254
2341.94	258
2343.81	258
2345.67	256
2347.54	244
2349.4	254
2351.27	232
2353.13	248
2354.99	264
2356.86	242
2358.72	234
2360.58	228
2362.44	246
2364.3	252
2366.16	242
2368.02	250
2369.88	230
2371.74	220
2373.6	222
2375.45	252
2377.31	244
2379.17	264
2381.02	218
2382.88	252
2384.73	266
2386.58	234
2388.44	234
2390.29	234
2392.14	238
2393.99	222
2395.85	246
2397.7	238
2399.55	238
2401.4	252
2403.25	232
2405.09	238
2406.94	242
2408.79	228
2410.63	226
2412.48	240
2414.33	232
2416.17	244
2418.02	226
2419.86	230
2421.7	226
2423.55	226
2425.39	232
2427.23	242
2429.07	238
2430.91	232
2432.75	216
2434.59	238
2436.43	218
2438.27	208
2440.11	226
2441.95	240
2443.78	220
2445.62	200
2447.46	224
2449.29	226
2451.13	212
2452.96	224
2454.79	216
2456.63	198
2458.46	208
2460.29	228
2462.12	200
2463.95	214
2465.78	222
2467.61	226
2469.44	200
2471.27	210
2473.1	206
2474.93	192
2476.76	218
2478.58	190
2480.41	198
2482.23	200
2484.06	206
2485.88	192
2487.71	198
2489.53	222
2491.35	202
2493.18	210
2495	192
2496.82	192
2498.64	176
2500.46	208
2502.28	194
2504.1	192
2505.92	202
2507.74	190
2509.55	200
2511.37	180
2513.19	190
2515	212
2516.82	204
2518.63	188
2520.45	190
2522.26	188
2524.07	172
2525.89	182
2527.7	176
2529.51	180
2531.32	178
2533.13	184
2534.94	180
2536.75	172
2538.56	174
2540.37	178
2542.18	182
2543.98	166
2545.79	178
2547.6	174
2549.4	190
2551.21	182
2553.01	182
2554.82	196
2556.62	182
2558.42	170
2560.23	174
2562.03	170
2563.83	158
2565.63	182
2567.43	152
2569.23	166
2571.03	164
2572.83	168
2574.63	158
2576.43	174
2578.22	160
2580.02	156
2581.82	156
2583.61	146
2585.41	172
2587.2	142
2589	176
2590.79	150
2592.58	170
2594.38	160
2596.17	152
2597.96	170
2599.75	150
2601.54	166
2603.33	164
2605.12	154
2606.91	158
2608.7	150
2610.49	142
2612.27	154
2614.06	128
2615.85	168
2617.63	144
2619.42	146
2621.2	148
2622.99	160
2624.77	138
2626.55	156
2628.34	142
2630.12	148
2631.9	142
2633.68	148
2635.46	148
2637.24	152
2639.02	142
2640.8	132
2642.58	142
2644.36	134
2646.14	146
2647.91	142
2649.69	150
2651.46	138
2653.24	146
2655.01	144
2656.79	134
2658.56	142
2660.34	134
2662.11	128
2663.88	136
2665.65	140
2667.42	138
2669.2	124
2670.96	148
2672.73	138
2674.5	140
2676.27	130
2678.04	130
2679.81	136
2681.58	144
2683.34	144
2685.11	130
2686.87	146
2688.64	134
2690.4	134
2692.17	118
2693.93	130
2695.69	136
2697.46	122
2699.22	138
2700.98	126
2702.74	122
2704.5	120
2706.26	112
2708.02	128
2709.78	122
2711.54	120
2713.3	116
2715.05	126
2716.81	110
2718.57	120
2720.32	126
2722.08	122
2723.83	124
2725.59	116
2727.34	120
2729.09	114
2730.85	114
2732.6	116
2734.35	126
2736.1	118
2737.85	112
2739.6	122
2741.35	118
2743.1	118
2744.85	110
2746.6	116
2748.35	120
2750.09	106
2751.84	102
2753.59	118
2755.33	114
2757.08	106
2758.82	110
2760.57	104
2762.31	116
2764.05	108
2765.79	112
2767.54	120
2769.28	98
2771.02	98
2772.76	112
2774.5	102
2776.24	104
2777.98	108
2779.72	104
2781.46	100
2783.19	104
2784.93	104
2786.67	92
2788.4	102
2790.14	100
2791.87	96
2793.61	104
2795.34	88
2797.07	102
2798.81	92
2800.54	104
2802.27	100
2804	102
2805.74	106
2807.47	102
2809.2	102
2810.93	100
2812.65	98
2814.38	94
2816.11	90
2817.84	102
2819.56	92
2821.29	90
2823.02	98
2824.74	92
2826.47	82
2828.19	82
2829.92	88
2831.64	88
2833.36	94
2835.09	86
2836.81	78
2838.53	86
2840.25	94
2841.97	74
2843.69	84
2845.41	90
2847.13	92
2848.85	84
2850.57	90
2852.28	86
2854	78
2855.72	86
2857.43	86
2859.15	96
2860.86	74
2862.58	70
2864.29	84
2866.01	80
2867.72	86
2869.43	78
2871.14	78
2872.86	88
2874.57	80
2876.28	76
2877.99	70
2879.7	76
2881.41	92
2883.11	80
2884.82	80
2886.53	78
2888.24	82
2889.94	76
2891.65	90
2893.36	74
2895.06	78
2896.77	70
2898.47	88
2900.17	76
2901.88	76
2903.58	72
2905.28	76
2906.98	58
2908.69	84
2910.39	66
2912.09	74
2913.79	84
2915.49	84
2917.19	78
2918.88	64
2920.58	68
2922.28	76
2923.98	74
2925.67	74
2927.37	80
2929.06	76
2930.76	72
2932.45	68
2934.15	72
2935.84	74
2937.53	76
2939.23	76
2940.92	74
2942.61	66
2944.3	70
2945.99	80
2947.68	76
2949.37	62
2951.06	76
2952.75	66
2954.44	56
2956.12	78
2957.81	64
2959.5	64
2961.18	62
2962.87	72
2964.56	74
2966.24	74
2967.92	74
2969.61	68
2971.29	60
2972.97	64
2974.66	56
2976.34	66
2978.02	66
2979.7	68
2981.38	70
2983.06	70
2984.74	62
2986.42	58
2988.1	70
2989.78	66
2991.45	70
2993.13	68
2994.81	62
2996.48	56
2998.16	62
2999.83	60