File: muestras/suculenta_dedo/inside_pr_01.txt
#Acq. time (s)=	10
#Accumulations=	1
#Range (cm-¹)=	200...3000
#Windows=	3
#Autofocus=	Off
#AutoExposure=	Off
#Spike filter=	Off
#Delay time (s)=	0
#Binning=	1
#Readout mode=	Signal
#DeNoise=	Off
#ICS correction=	Off
#Dark correction=	Off
#Inst. Process=	Off
#Instrument=	LabRAM HR Evol
#Detector=	Syncerity OE
#Objective=	x100_VIS
#Grating=	600 (500nm)
#ND Filter=	0.01%
#Laser=	633nm_Edge
#Hole=	30.0125
#Range=	Visible
#Project=	Omar
#Sample=	03-07-23
#Site=	fings
#Title=	inside_pr
#Remark=
#Date=	03.07.2023 14:55
#Acquired=	03.07.2023 14:55:05
201.713	24
204.247	32
206.778	28
209.311	38
211.84	24
214.371	24
216.899	30
219.428	38
221.955	30
224.482	36
227.007	28
229.531	30
232.055	32
234.579	38
237.1	38
239.621	30
242.141	32
244.661	40
247.179	26
249.698	44
252.215	36
254.731	32
257.246	36
259.761	36
262.273	42
264.786	36
267.298	30
269.809	32
272.319	30
274.828	30
277.336	38
279.844	40
282.351	30
284.855	26
287.361	38
289.866	30
292.368	34
294.871	34
297.372	30
299.873	36
302.372	30
304.872	36
307.37	26
309.866	42
312.364	32
314.859	40
317.353	34
319.848	32
322.341	36
324.833	40
327.324	24
329.814	34
332.304	38
334.792	36
337.28	36
339.767	30
342.254	32
344.739	32
347.224	48
349.708	38
352.191	40
354.673	32
357.155	32
359.634	34
362.114	34
364.593	30
367.07	40
369.548	36
372.024	36
374.499	42
376.974	30
379.447	40
381.92	38
384.392	36
386.864	28
389.333	42
391.802	40
394.272	40
396.739	36
399.206	48
401.673	34
404.138	34
406.602	42
409.066	34
411.528	44
413.99	40
416.451	42
418.911	36
421.371	34
423.83	38
426.288	42
428.745	40
431.201	36
433.657	36
436.111	38
438.565	46
441.017	48
443.469	36
445.921	38
448.37	38
450.821	44
453.27	48
455.717	46
458.165	42
460.61	38
463.056	38
465.5	48
467.945	36
470.387	36
472.829	40
475.271	44
477.711	34
480.15	38
482.589	34
485.027	44
487.465	44
489.901	42
492.337	46
494.771	40
497.205	40
499.638	44
502.07	40
504.502	44
506.933	42
509.363	40
511.792	44
514.219	52
516.647	42
519.073	44
521.5	42
523.924	46
526.348	36
528.772	50
531.194	46
533.616	46
536.036	48
538.457	48
540.875	52
543.294	60
545.712	48
548.128	58
550.545	52
552.959	40
555.373	52
557.788	48
560.2	42
562.612	48
565.023	54
567.433	48
569.843	50
572.251	48
574.659	40
577.066	52
579.472	50
581.878	46
584.283	54
586.687	50
589.09	48
591.493	46
593.893	50
596.294	60
598.694	60
601.093	50
603.491	54
605.889	56
608.285	48
610.682	50
613.076	48
615.471	58
617.864	58
620.256	58
622.648	54
625.039	60
627.429	52
629.819	60
632.208	54
634.595	56
636.982	56
639.369	60
641.755	48
644.139	58
646.523	52
648.906	68
651.288	62
653.67	70
656.051	72
658.429	50
660.808	64
663.187	64
665.565	58
667.942	68
670.317	62
672.692	60
675.067	66
677.44	58
679.813	70
682.184	72
684.556	72
686.926	66
689.296	62
691.664	80
694.033	72
696.4	62
698.766	60
701.133	70
703.497	82
705.861	82
708.224	74
710.586	74
712.949	78
715.31	80
717.67	82
720.029	84
722.388	76
724.746	76
727.103	78
729.458	70
731.814	78
734.168	90
736.523	94
738.876	72
741.227	84
743.579	80
745.931	84
748.28	94
750.629	82
752.977	84
755.325	88
757.672	84
760.018	88
762.363	88
764.708	94
767.052	88
769.394	92
771.737	98
774.078	88
776.419	84
778.758	92
781.097	102
783.435	94
785.773	84
788.11	90
790.446	110
792.781	94
795.115	110
797.449	94
799.782	102
802.115	96
804.446	100
806.777	104
809.106	106
811.435	112
813.764	104
816.091	114
818.418	108
820.743	106
823.069	108
825.393	110
827.717	118
830.039	114
832.362	108
834.683	110
837.003	118
839.324	114
841.643	128
843.961	120
846.278	116
848.594	120
850.91	110
853.227	130
855.541	114
857.855	126
860.168	126
862.48	132
864.79	140
867.101	130
869.411	122
871.721	148
874.029	132
876.336	138
878.643	140
880.95	144
883.254	138
885.559	132
887.862	158
890.166	126
892.467	152
894.77	140
897.07	146
899.371	144
901.669	130
903.968	160
906.266	150
908.563	160
910.859	162
913.154	160
915.449	168
917.742	164
920.036	148
922.329	154
924.621	158
926.911	160
929.201	160
931.49	166
933.779	168
936.068	166
938.355	162
940.64	174
942.926	172
945.212	180
947.495	166
949.779	190
952.062	176
954.344	182
956.625	196
958.905	182
961.184	194
963.464	214
965.742	188
968.02	200
970.296	182
972.572	188
974.847	214
977.121	194
979.396	196
981.669	194
983.941	198
986.212	214
988.483	222
990.753	208
993.022	198
995.29	210
997.558	202
999.825	222
1002.09	222
1004.36	236
1006.62	228
1008.89	214
1011.15	240
1013.41	222
1015.67	234
1017.93	236
1020.19	242
1022.45	230
1024.71	244
1026.97	236
1029.23	236
1031.49	240
1033.74	258
1036	260
1038.25	260
1040.5	248
1042.76	258
1045.01	272
1047.26	268
1049.51	268
1051.76	262
1054.01	282
1056.26	292
1058.51	286
1060.75	282
1063	296
1065.25	276
1067.49	304
1069.73	290
1071.98	280
1074.22	302
1076.46	264
1078.7	284
1080.94	296
1083.18	288
1085.42	304
1087.66	284
1089.9	298
1092.14	302
1094.37	304
1096.61	316
1098.84	310
1101.08	320
1103.31	292
1105.54	310
1107.77	322
1110	324
1112.23	298
1114.46	302
1116.69	334
1118.92	328
1121.15	370
1123.37	320
1125.6	314
1127.83	324
1130.05	340
1132.27	346
1134.5	352
1136.72	346
1138.94	356
1141.16	336
1143.38	344
1145.6	348
1147.82	350
1150.04	356
1152.26	366
1154.47	350
1156.69	364
1158.9	356
1161.12	336
1163.33	388
1165.54	356
1167.76	366
1169.97	368
1172.18	386
1174.39	346
1176.6	356
1178.81	362
1181.02	368
1183.22	356
1185.43	374
1187.63	374
1189.84	380
1192.04	360
1194.25	354
1196.45	360
1198.65	344
1200.85	354
1203.05	352
1205.25	354
1207.45	342
1209.65	352
1211.85	348
1214.05	328
1216.24	384
1218.44	330
1220.64	342
1222.83	338
1225.02	348
1227.22	338
1229.41	342
1231.6	374
1233.79	346
1235.98	358
1238.17	342
1240.36	328
1242.55	334
1244.73	330
1246.92	326
1249.11	320
1251.29	318
1253.48	326
1255.66	324
1257.84	324
1260.03	320
1262.21	318
1264.39	296
1266.57	334
1268.75	304
1270.93	310
1273.11	306
1275.28	304
1277.46	300
1279.64	290
1281.81	300
1283.98	327.857
1286.16	309.309
1288.33	273.892
1290.5	279.833
1292.68	305.226
1294.85	270.466
1297.02	274.245
1299.19	280.227
1301.36	266.415
1303.53	292.359
1305.69	279.101
1307.86	262.695
1310.03	264.039
1312.19	258.748
1314.36	258.076
1316.52	266.407
1318.68	259.414
1320.85	250.218
1323.01	255.559
1325.17	253.151
1327.33	259.391
1329.49	251.483
1331.65	243.097
1333.81	240.18
1335.97	249.642
1338.12	228.133
1340.28	231.334
1342.44	235.383
1344.59	235.269
1346.75	231.355
1348.9	228.098
1351.05	223.039
1353.2	216.456
1355.36	223.705
1357.51	211.941
1359.66	220.684
1361.81	224.147
1363.96	218.136
1366.1	226.447
1368.25	206.965
1370.4	201.937
1372.54	203.312
1374.69	199.613
1376.83	205.439
1378.98	206.601
1381.12	194.596
1383.26	199.883
1385.41	214.935
1387.55	218.564
1389.69	184.739
1391.83	176.799
1393.02	198
1395.17	198
1397.32	176
1399.47	180
1401.62	200
1403.77	206
1405.91	186
1408.06	186
1410.2	184
1412.35	186
1414.49	184
1416.63	164
1418.78	172
1420.92	166
1423.06	166
1425.2	174
1427.34	170
1429.48	156
1431.61	174
1433.75	166
1435.89	162
1438.02	180
1440.16	164
1442.3	168
1444.43	170
1446.56	170
1448.7	166
1450.83	172
1452.96	154
1455.09	152
1457.22	144
1459.35	144
1461.48	152
1463.61	148
1465.73	158
1467.86	154
1469.98	160
1472.11	148
1474.24	160
1476.36	152
1478.48	126
1480.6	156
1482.73	150
1484.85	140
1486.97	130
1489.09	146
1491.21	154
1493.33	154
1495.44	144
1497.56	136
1499.68	130
1501.79	144
1503.91	124
1506.02	142
1508.14	134
1510.25	130
1512.36	132
1514.48	138
1516.59	134
1518.7	140
1520.81	130
1522.92	136
1525.02	128
1527.13	130
1529.24	134
1531.35	126
1533.45	108
1535.56	128
1537.66	136
1539.77	128
1541.87	138
1543.97	120
1546.08	124
1548.18	128
1550.28	132
1552.38	128
1554.48	130
1556.57	120
1558.67	130
1560.77	116
1562.87	120
1564.96	124
1567.06	118
1569.15	108
1571.25	116
1573.34	112
1575.43	126
1577.53	124
1579.62	114
1581.71	122
1583.8	116
1585.89	104
1587.98	118
1590.06	126
1592.15	116
1594.24	116
1596.33	134
1598.41	114
1600.5	102
1602.58	110
1604.66	116
1606.75	130
1608.83	118
1610.91	110
1612.99	104
1615.07	108
1617.15	116
1619.23	112
1621.31	106
1623.39	118
1625.46	106
1627.54	110
1629.62	118
1631.69	104
1633.77	96
1635.84	108
1637.91	116
1639.99	90
1642.06	108
1644.13	114
1646.2	118
1648.27	114
1650.34	102
1652.41	108
1654.47	110
1656.54	110
1658.61	116
1660.67	100
1662.74	98
1664.81	106
1666.87	108
1668.93	116
1671	110
1673.06	102
1675.12	92
1677.18	96
1679.24	108
1681.3	108
1683.36	90
1685.42	96
1687.47	104
1689.53	108
1691.59	88
1693.64	102
1695.7	94
1697.75	102
1699.81	106
1701.86	114
1703.91	100
1705.97	90
1708.02	88
1710.07	104
1712.12	100
1714.17	110
1716.22	114
1718.26	102
1720.31	100
1722.36	100
1724.4	100
1726.45	104
1728.49	114
1730.54	86
1732.58	92
1734.63	96
1736.67	102
1738.71	96
1740.75	86
1742.79	112
1744.83	88
1746.87	92
1748.91	100
1750.95	100
1752.98	94
1755.02	94
1757.06	88
1759.09	98
1761.13	94
1763.16	106
1765.19	106
1767.23	100
1769.26	104
1771.29	86
1773.32	86
1775.35	98
1777.38	106
1779.41	96
1781.44	102
1783.47	88
1785.49	102
1787.52	100
1789.55	92
1791.57	94
1793.6	102
1795.62	106
1797.64	88
1799.67	104
1801.69	98
1803.71	96
1805.73	92
1807.75	94
1809.77	98
1811.79	106
1813.81	90
1815.83	104
1817.84	94
1819.86	96
1821.88	90
1823.89	98
1825.91	88
1827.92	108
1829.93	106
1831.95	98
1833.96	96
1835.97	94
1837.98	108
1839.99	80
1842	98
1844.01	88
1846.02	96
1848.03	94
1850.03	82
1852.04	96
1854.05	94
1856.05	106
1858.06	92
1860.06	90
1862.06	102
1864.07	92
1866.07	94
1868.07	110
1870.07	104
1872.07	88
1874.07	98
1876.07	86
1878.07	86
1880.07	96
1882.07	104
1884.06	94
1886.06	102
1888.05	94
1890.05	102
1892.04	94
1894.04	98
1896.03	98
1898.02	94
1900.01	88
1902	94
1903.99	100
1905.98	82
1907.97	96
1909.96	90
1911.95	100
1913.94	100
1915.93	92
1917.91	94
1919.9	106
1921.88	96
1923.87	96
1925.85	88
1927.83	96
1929.82	92
1931.8	102
1933.78	92
1935.76	100
1937.74	92
1939.72	84
1941.7	98
1943.68	94
1945.65	92
1947.63	92
1949.61	96
1951.58	84
1953.56	92
1955.53	100
1957.51	94
1959.48	92
1961.45	90
1963.43	92
1965.4	90
1967.37	90
1969.34	104
1971.31	90
1973.28	92
1975.25	90
1977.22	92
1979.18	96
1981.15	92
1983.12	96
1985.08	92
1987.05	94
1989.01	90
1990.97	88
1992.94	84
1994.9	96
1996.86	92
1998.82	88
2000.78	102
2002.74	86
2004.7	90
2006.66	80
2008.62	88
2010.58	82
2012.54	96
2014.49	96
2016.45	92
2018.4	94
2020.36	88
2022.31	82
2024.27	98
2026.22	90
2028.17	81
2030.12	86
2032.07	94
2034.03	82
2035.98	100
2037.93	96
2039.87	86
2041.82	102
2043.77	76
2045.72	82
2047.66	90
2049.61	100
2051.55	92
2053.5	84
2055.44	78
2057.39	92
2059.33	88
2061.27	96
2063.21	90
2065.15	90
2067.09	82
2069.03	96
2070.97	88
2072.91	90
2074.85	98
2076.79	90
2078.73	86
2080.66	86
2082.6	98
2084.53	96
2086.47	100
2088.4	82
2090.33	92
2092.27	96
2094.2	92
2096.13	88
2098.06	102
2099.99	80
2101.92	86
2103.85	96
2105.78	86
2107.71	98
2109.64	74
2111.56	82
2113.49	90
2115.41	92
2117.34	86
2119.26	86
2121.19	92
2123.11	90
2125.03	100
2126.96	92
2128.88	86
2130.8	96
2132.72	98
2134.64	92
2136.56	96
2138.48	82
2140.4	86
2142.31	88
2144.23	90
2146.15	88
2148.06	90
2149.98	90
2151.89	84
2153.81	78
2155.72	100
2157.63	92
2159.55	92
2161.46	84
2163.37	100
2165.28	96
2167.19	74
2169.1	92
2171.01	88
2172.91	94
2174.82	88
2176.73	90
2178.64	92
2180.54	90
2182.45	90
2184.35	80
2186.26	92
2188.16	92
2190.06	86
2191.96	82
2193.87	100
2195.77	88
2197.67	98
2199.57	88
2201.47	94
2203.37	98
2205.27	104
2207.16	82
2209.06	98
2210.96	96
2212.85	88
2214.75	90
2216.64	82
2218.54	94
2220.43	80
2222.33	88
2224.22	92.06
2226.11	95.9211
2228	84.0401
2229.89	71.4899
2231.78	95.05
2233.67	86.5256
2235.56	87.3442
2237.45	104.922
2239.34	93.3199
2241.23	99.2109
2243.11	102.581
2245	96.3309
2246.89	80.34
2248.77	90.7256
2250.66	91.0024
2252.54	89.3247
2254.42	92.7295
2256.31	100.625
2258.19	89.8874
2260.07	99.3094
2261.95	83.8343
2263.83	88.4901
2265.71	82.0815
2267.59	91.622
2269.47	91.4135
2271.35	89.88
2273.23	93.3267
2275.1	94.6428
2276.98	96.7827
2278.86	90.81
2280.73	86.313
2282.61	90.1456
2284.48	92.2073
2286.36	95.1198
2288.23	95.4901
2290.1	95.7332
2291.98	86.5845
2293.85	92.5204
2295.72	94.2183
2297.59	93.154
2299.46	91.6038
2301.33	94.1761
2303.2	92.1917
2305.06	95.2059
2306.93	89.914
2308.8	93.2498
2310.67	95.4431
2312.53	88.63
2314.4	86.9443
2316.26	92.5281
2317.62	92
2319.5	98
2321.37	98
2323.24	90
2325.12	92
2326.99	92
2328.86	86
2330.73	86
2332.6	88
2334.47	80
2336.34	100
2338.2	86
2340.07	94
2341.94	98
2343.81	96
2345.67	88
2347.54	96
2349.4	86
2351.27	88
2353.13	90
2354.99	92
2356.86	82
2358.72	84
2360.58	92
2362.44	94
2364.3	84
2366.16	88
2368.02	100
2369.88	74
2371.74	88
2373.6	90
2375.45	74
2377.31	80
2379.17	86
2381.02	84
2382.88	98
2384.73	86
2386.58	86
2388.44	92
2390.29	84
2392.14	90
2393.99	82
2395.85	88
2397.7	82
2399.55	80
2401.4	92
2403.25	84
2405.09	88
2406.94	96
2408.79	70
2410.63	86
2412.48	86
2414.33	80
2416.17	82
2418.02	86
2419.86	90
2421.7	82
2423.55	86
2425.39	90
2427.23	80
2429.07	76
2430.91	86
2432.75	84
2434.59	74
2436.43	86
2438.27	78
2440.11	96
2441.95	72
2443.78	80
2445.62	86
2447.46	86
2449.29	90
2451.13	88
2452.96	74
2454.79	82
2456.63	80
2458.46	80
2460.29	86
2462.12	82
2463.95	80
2465.78	84
2467.61	72
2469.44	88
2471.27	86
2473.1	82
2474.93	84
2476.76	84
2478.58	72
2480.41	80
2482.23	78
2484.06	74
2485.88	76
2487.71	78
2489.53	78
2491.35	70
2493.18	78
2495	78
2496.82	68
2498.64	74
2500.46	72
2502.28	84
2504.1	84
2505.92	80
2507.74	74
2509.55	80
2511.37	82
2513.19	84
2515	78
2516.82	70
2518.63	72
2520.45	70
2522.26	72
2524.07	68
2525.89	74
2527.7	80
2529.51	72
2531.32	58
2533.13	68
2534.94	84
2536.75	70
2538.56	82
2540.37	64
2542.18	64
2543.98	72
2545.79	80
2547.6	70
2549.4	60
2551.21	68
2553.01	68
2554.82	84
2556.62	66
2558.42	64
2560.23	76
2562.03	70
2563.83	70
2565.63	62
2567.43	68
2569.23	72
2571.03	74
2572.83	72
2574.63	74
2576.43	70
2578.22	62
2580.02	64
2581.82	72
2583.61	64
2585.41	58
2587.2	66
2589	70
2590.79	70
2592.58	68
2594.38	64
2596.17	66
2597.96	68
2599.75	72
2601.54	64
2603.33	60
2605.12	64
2606.91	68
2608.7	72
2610.49	62
2612.27	64
2614.06	82
2615.85	74
2617.63	72
2619.42	66
2621.2	60
2622.99	58
2624.77	62
2626.55	62
2628.34	58
2630.12	62
2631.9	66
2633.68	68
2635.46	52
2637.24	64
2639.02	74
2640.8	60
2642.58	70
2644.36	52
2646.14	60
2647.91	54
2649.69	68
2651.46	60
2653.24	62
2655.01	68
2656.79	60
2658.56	64
2660.34	54
2662.11	58
2663.88	56
2665.65	56
2667.42	58
2669.2	60
2670.96	64
2672.73	58
2674.5	68
2676.27	54
2678.04	66
2679.81	66
2681.58	58
2683.34	66
2685.11	56
2686.87	60
2688.64	62
2690.4	62
2692.17	58
2693.93	62
2695.69	52
2697.46	58
2699.22	52
2700.98	54
2702.74	56
2704.5	56
2706.26	68
2708.02	66
2709.78	54
2711.54	62
2713.3	64
2715.05	54
2716.81	48
2718.57	62
2720.32	60
2722.08	54
2723.83	62
2725.59	50
2727.34	54
2729.09	58
2730.85	56
2732.6	58
2734.35	56
2736.1	54
2737.85	52
2739.6	52
2741.35	56
2743.1	56
2744.85	54
2746.6	56
2748.35	52
2750.09	46
2751.84	58
2753.59	50
2755.33	52
2757.08	52
2758.82	64
2760.57	60
2762.31	60
2764.05	50
2765.79	46
2767.54	50
2769.28	48
2771.02	58
2772.76	58
2774.5	58
2776.24	50
2777.98	50
2779.72	52
2781.46	44
2783.19	48
2784.93	44
2786.67	52
2788.4	50
2790.14	54
2791.87	54
2793.61	48
2795.34	62
2797.07	56
2798.81	48
2800.54	54
2802.27	56
2804	48
2805.74	46
2807.47	48
2809.2	54
2810.93	44
2812.65	44
2814.38	50
2816.11	56
2817.84	50
2819.56	48
2821.29	44
2823.02	54
2824.74	46
2826.47	54
2828.19	54
2829.92	42
2831.64	46
2833.36	44
2835.09	52
2836.81	40
2838.53	52
2840.25	46
2841.97	52
2843.69	42
2845.41	42
2847.13	44
2848.85	48
2850.57	46
2852.28	50
2854	48
2855.72	54
2857.43	44
2859.15	48
2860.86	40
2862.58	42
2864.29	48
2866.01	36
2867.72	50
2869.43	42
2871.14	46
2872.86	38
2874.57	46
2876.28	36
2877.99	46
2879.7	44
2881.41	40
2883.11	48
2884.82	42
2886.53	44
2888.24	42
2889.94	46
2891.65	46
2893.36	38
2895.06	36
2896.77	44
2898.47	46
2900.17	42
2901.88	50
2903.58	42
2905.28	54
2906.98	42
2908.69	42
2910.39	50
2912.09	38
2913.79	42
2915.49	40
2917.19	46
2918.88	40
2920.58	42
2922.28	42
2923.98	38
2925.67	48
2927.37	44
2929.06	40
2930.76	46
2932.45	40
2934.15	46
2935.84	48
2937.53	44
2939.23	46
2940.92	36
2942.61	42
2944.3	40
2945.99	40
2947.68	46
2949.37	48
2951.06	46
2952.75	38
2954.44	40
2956.12	42
2957.81	42
2959.5	38
2961.18	36
2962.87	36
2964.56	30
2966.24	36
2967.92	42
2969.61	26
2971.29	38
2972.97	38
2974.66	42
2976.34	36
2978.02	34
2979.7	40
2981.38	38
2983.06	44
2984.74	44
2986.42	46
2988.1	38
2989.78	42
2991.45	38
2993.13	36
2994.81	42
2996.48	38
2998.16	36
2999.83	36