File: muestras/suculenta_dedo/inside_pr_04.txt
#Acq. time (s)=	10
#Accumulations=	1
#Range (cm-¹)=	200...3000
#Windows=	3
#Autofocus=	Off
#AutoExposure=	Off
#Spike filter=	Off
#Delay time (s)=	0
#Binning=	1
#Readout mode=	Signal
#DeNoise=	Off
#ICS correction=	Off
#Dark correction=	Off
#Inst. Process=	Off
#Instrument=	LabRAM HR Evol
#Detector=	Syncerity OE
#Objective=	x100_VIS
#Grating=	600 (500nm)
#ND Filter=	1%
#Laser=	633nm_Edge
#Hole=	30.0125
#Range=	Visible
#Project=	Omar
#Sample=	03-07-23
#Site=	fings
#Title=	inside_pr
#Remark=
#Date=	03.07.2023 15:00
#Acquired=	03.07.2023 15:00:37
201.713	64
204.247	72
206.778	76
209.311	70
211.84	66
214.371	74
216.899	70
219.428	82
221.955	78
224.482	68
227.007	80
229.531	74
232.055	76
234.579	80
237.1	68
239.621	70
242.141	72
244.661	72
247.179	82
249.698	84
252.215	74
254.731	76
257.246	78
259.761	78
262.273	88
264.786	82
267.298	88
269.809	88
272.319	94
274.828	96
277.336	78
279.844	86
282.351	102
284.855	94
287.361	100
289.866	88
292.368	90
294.871	106
297.372	106
299.873	104
302.372	88
304.872	108
307.37	106
309.866	104
312.364	102
314.859	106
317.353	102
319.848	110
322.341	104
324.833	108
327.324	116
329.814	116
332.304	100
334.792	124
337.28	130
339.767	116
342.254	130
344.739	120
347.224	112
349.708	124
352.191	116
354.673	120
357.155	142
359.634	138
362.114	128
364.593	124
367.07	138
369.548	124
372.024	130
374.499	126
376.974	150
379.447	136
381.92	138
384.392	144
386.864	144
389.333	144
391.802	136
394.272	132
396.739	156
399.206	146
401.673	154
404.138	142
406.602	168
409.066	166
411.528	158
413.99	170
416.451	170
418.911	166
421.371	170
423.83	174
426.288	168
428.745	166
431.201	176
433.657	176
436.111	172
438.565	182
441.017	178
443.469	176
445.921	194
448.37	188
450.821	178
453.27	188
455.717	192
458.165	190
460.61	192
463.056	194
465.5	216
467.945	204
470.387	200
472.829	198
475.271	214
477.711	214
480.15	226
482.589	218
485.027	216
487.465	216
489.901	236
492.337	220
494.771	228
497.205	216
499.638	218
502.07	224
504.502	228
506.933	250
509.363	234
511.792	242
514.219	232
516.647	244
519.073	240
521.5	242
523.924	250
526.348	244
528.772	246
531.194	260
533.616	246
536.036	254
538.457	266
540.875	254
543.294	258
545.712	266
548.128	268
550.545	288
552.959	268
555.373	286
557.788	290
560.2	280
562.612	286
565.023	286
567.433	286
569.843	302
572.251	288
574.659	316
577.066	306
579.472	300
581.878	300
584.283	326
586.687	312
589.09	338
591.493	322
593.893	330
596.294	324
598.694	312
601.093	330
603.491	340
605.889	334
608.285	350
610.682	372
613.076	346
615.471	384
617.864	370
620.256	384
622.648	352
625.039	372
627.429	372
629.819	392
632.208	390
634.595	414
636.982	406
639.369	426
641.755	400
644.139	422
646.523	412
648.906	422
651.288	404
653.67	410
656.051	448
658.429	450
660.808	434
663.187	450
665.565	456
667.942	450
670.317	470
672.692	488
675.067	462
677.44	480
679.813	492
682.184	530
684.556	486
686.926	500
689.296	540
691.664	514
694.033	526
696.4	524
698.766	514
701.133	526
703.497	564
705.861	552
708.224	568
710.586	564
712.949	542
715.31	580
717.67	580
720.029	568
722.388	594
724.746	636
727.103	628
729.458	606
731.814	648
734.168	634
736.523	656
738.876	682
741.227	672
743.579	698
745.931	676
748.28	672
750.629	694
752.977	660
755.325	750
757.672	754
760.018	758
762.363	756
764.708	760
767.052	722
769.394	764
771.737	784
774.078	808
776.419	784
778.758	820
781.097	780
783.435	790
785.773	830
788.11	824
790.446	844
792.781	848
795.115	884
797.449	862
799.782	898
802.115	914
804.446	888
806.777	928
809.106	880
811.435	944
813.764	970
816.091	978
818.418	996
820.743	1020
823.069	1014
825.393	1012
827.717	1054
830.039	1038
832.362	1028
834.683	1140
837.003	1112
839.324	1066
841.643	1140
843.961	1122
846.278	1106
848.594	1166
850.91	1184
853.227	1228
855.541	1220
857.855	1208
860.168	1208
862.48	1218
864.79	1264
867.101	1254
869.411	1306
871.721	1294
874.029	1328
876.336	1326
878.643	1374
880.95	1322
883.254	1368
885.559	1396
887.862	1378
890.166	1392
892.467	1434
894.77	1440
897.07	1436
899.371	1516
901.669	1458
903.968	1460
906.266	1564
908.563	1514
910.859	1538
913.154	1582
915.449	1596
917.742	1558
920.036	1614
922.329	1674
924.621	1640
926.911	1662
929.201	1682
931.49	1762
933.779	1716
936.068	1794
938.355	1776
940.64	1770
942.926	1818
945.212	1794
947.495	1840
949.779	1906
952.062	1884
954.344	1886
956.625	1922
958.905	1934
961.184	1938
963.464	2020
965.742	1996
968.02	2114
970.296	2088
972.572	2082
974.847	2056
977.121	2074
979.396	2112
981.669	2168
983.941	2222
986.212	2262
988.483	2266
990.753	2222
993.022	2306
995.29	2320
997.558	2324
999.825	2372
1002.09	2412
1004.36	2438
1006.62	2458
1008.89	2404
1011.15	2504
1013.41	2504
1015.67	2536
1017.93	2506
1020.19	2564
1022.45	2628
1024.71	2632
1026.97	2698
1029.23	2678
1031.49	2768
1033.74	2768
1036	2876
1038.25	2832
1040.5	2920
1042.76	2970
1045.01	2936
1047.26	3032
1049.51	2930
1051.76	3034
1054.01	2940
1056.26	3076
1058.51	3086
1060.75	3072
1063	3146
1065.25	3208
1067.49	3164
1069.73	3266
1071.98	3262
1074.22	3234
1076.46	3278
1078.7	3356
1080.94	3262
1083.18	3300
1085.42	3384
1087.66	3348
1089.9	3326
1092.14	3454
1094.37	3472
1096.61	3476
1098.84	3452
1101.08	3522
1103.31	3478
1105.54	3578
1107.77	3642
1110	3560
1112.23	3666
1114.46	3692
1116.69	3654
1118.92	3712
1121.15	3682
1123.37	3746
1125.6	3744
1127.83	3774
1130.05	3832
1132.27	3766
1134.5	3872
1136.72	3926
1138.94	3876
1141.16	3878
1143.38	3926
1145.6	3950
1147.82	3948
1150.04	3954
1152.26	4000
1154.47	4086
1156.69	4074
1158.9	4122
1161.12	4040
1163.33	4110
1165.54	4074
1167.76	4128
1169.97	4158
1172.18	4126
1174.39	4142
1176.6	4128
1178.81	4202
1181.02	4154
1183.22	4146
1185.43	4180
1187.63	4124
1189.84	4200
1192.04	4078
1194.25	4124
1196.45	4118
1198.65	4102
1200.85	4032
1203.05	4016
1205.25	4006
1207.45	4032
1209.65	4030
1211.85	4002
1214.05	3998
1216.24	3906
1218.44	3918
1220.64	3972
1222.83	3816
1225.02	3880
1227.22	3852
1229.41	3856
1231.6	3772
1233.79	3800
1235.98	3876
1238.17	3848
1240.36	3768
1242.55	3736
1244.73	3722
1246.92	3706
1249.11	3730
1251.29	3688
1253.48	3708
1255.66	3658
1257.84	3626
1260.03	3580
1262.21	3590
1264.39	3540
1266.57	3568
1268.75	3544
1270.93	3504
1273.11	3478
1275.28	3530
1277.46	3416
1279.64	3396
1281.81	3386
1283.98	3339.67
1286.16	3355.11
1288.33	3325.65
1290.5	3309.48
1292.68	3238.45
1294.85	3216.3
1297.02	3178.87
1299.19	3219.93
1301.36	3228.01
1303.53	3106.54
1305.69	3100.34
1307.86	3085.07
1310.03	3013.46
1312.19	2977.16
1314.36	2956.02
1316.52	2963.56
1318.68	2955.88
1320.85	2901.5
1323.01	2864.32
1325.17	2875.44
1327.33	2825.29
1329.49	2800.45
1331.65	2772.11
1333.81	2712.93
1335.97	2727.76
1338.12	2665.11
1340.28	2661.62
1342.44	2670.01
1344.59	2582.47
1346.75	2582.6
1348.9	2527.44
1351.05	2566.17
1353.2	2535.08
1355.36	2505.95
1357.51	2445.48
1359.66	2422.69
1361.81	2422.08
1363.96	2397.6
1366.1	2416.25
1368.25	2347.28
1370.4	2346.67
1372.54	2278.35
1374.69	2332.23
1376.83	2276.06
1378.98	2254.08
1381.12	2235.51
1383.26	2195.43
1385.41	2165.4
1387.55	2196.35
1389.69	2175.29
1391.83	2110.03
1393.02	2158
1395.17	2136
1397.32	2160
1399.47	2076
1401.62	2052
1403.77	2090
1405.91	2030
1408.06	2056
1410.2	2026
1412.35	1942
1414.49	2014
1416.63	1984
1418.78	1946
1420.92	1892
1423.06	1980
1425.2	1892
1427.34	1858
1429.48	1848
1431.61	1834
1433.75	1878
1435.89	1850
1438.02	1806
1440.16	1798
1442.3	1812
1444.43	1822
1446.56	1786
1448.7	1718
1450.83	1812
1452.96	1744
1455.09	1778
1457.22	1756
1459.35	1724
1461.48	1686
1463.61	1700
1465.73	1684
1467.86	1670
1469.98	1706
1472.11	1694
1474.24	1640
1476.36	1674
1478.48	1628
1480.6	1618
1482.73	1612
1484.85	1598
1486.97	1652
1489.09	1600
1491.21	1518
1493.33	1552
1495.44	1572
1497.56	1572
1499.68	1540
1501.79	1572
1503.91	1494
1506.02	1538
1508.14	1484
1510.25	1478
1512.36	1508
1514.48	1498
1516.59	1534
1518.7	1486
1520.81	1480
1522.92	1440
1525.02	1446
1527.13	1396
1529.24	1408
1531.35	1384
1533.45	1418
1535.56	1390
1537.66	1380
1539.77	1348
1541.87	1366
1543.97	1344
1546.08	1372
1548.18	1372
1550.28	1372
1552.38	1322
1554.48	1346
1556.57	1378
1558.67	1296
1560.77	1328
1562.87	1316
1564.96	1292
1567.06	1260
1569.15	1304
1571.25	1260
1573.34	1296
1575.43	1334
1577.53	1258
1579.62	1222
1581.71	1234
1583.8	1240
1585.89	1198
1587.98	1244
1590.06	1250
1592.15	1254
1594.24	1256
1596.33	1212
1598.41	1228
1600.5	1218
1602.58	1152
1604.66	1184
1606.75	1188
1608.83	1216
1610.91	1158
1612.99	1208
1615.07	1160
1617.15	1214
1619.23	1148
1621.31	1168
1623.39	1134
1625.46	1156
1627.54	1186
1629.62	1124
1631.69	1134
1633.77	1162
1635.84	1164
1637.91	1160
1639.99	1142
1642.06	1132
1644.13	1116
1646.2	1150
1648.27	1104
1650.34	1142
1652.41	1098
1654.47	1080
1656.54	1118
1658.61	1092
1660.67	1078
1662.74	1138
1664.81	1058
1666.87	1090
1668.93	1094
1671	1100
1673.06	1078
1675.12	1076
1677.18	1048
1679.24	1116
1681.3	1066
1683.36	1080
1685.42	1094
1687.47	1048
1689.53	1072
1691.59	1014
1693.64	1080
1695.7	1056
1697.75	1040
1699.81	1016
1701.86	1032
1703.91	1014
1705.97	1054
1708.02	1020
1710.07	1006
1712.12	1018
1714.17	992
1716.22	1036
1718.26	990
1720.31	1012
1722.36	1002
1724.4	1030
1726.45	968
1728.49	1002
1730.54	1004
1732.58	994
1734.63	982
1736.67	1018
1738.71	994
1740.75	1028
1742.79	978
1744.83	1016
1746.87	1022
1748.91	994
1750.95	1020
1752.98	1020
1755.02	1010
1757.06	986
1759.09	1012
1761.13	976
1763.16	996
1765.19	990
1767.23	1018
1769.26	972
1771.29	1026
1773.32	964
1775.35	1000
1777.38	964
1779.41	974
1781.44	954
1783.47	978
1785.49	952
1787.52	990
1789.55	966
1791.57	958
1793.6	986
1795.62	952
1797.64	972
1799.67	1002
1801.69	962
1803.71	954
1805.73	958
1807.75	978
1809.77	954
1811.79	958
1813.81	940
1815.83	948
1817.84	938
1819.86	984
1821.88	972
1823.89	928
1825.91	974
1827.92	946
1829.93	972
1831.95	968
1833.96	960
1835.97	926
1837.98	944
1839.99	944
1842	950
1844.01	936
1846.02	908
1848.03	952
1850.03	928
1852.04	934
1854.05	956
1856.05	906
1858.06	934
1860.06	908
1862.06	978
1864.07	968
1866.07	912
1868.07	928
1870.07	932
1872.07	932
1874.07	904
1876.07	926
1878.07	948
1880.07	962
1882.07	938
1884.06	932
1886.06	938
1888.05	910
1890.05	938
1892.04	920
1894.04	942
1896.03	916
1898.02	936
1900.01	916
1902	886
1903.99	926
1905.98	918
1907.97	946
1909.96	908
1911.95	954
1913.94	926
1915.93	936
1917.91	916
1919.9	932
1921.88	902
1923.87	936
1925.85	896
1927.83	930
1929.82	918
1931.8	938
1933.78	920
1935.76	908
1937.74	924
1939.72	868
1941.7	912
1943.68	928
1945.65	912
1947.63	890
1949.61	972
1951.58	910
1953.56	880
1955.53	926
1957.51	916
1959.48	916
1961.45	936
1963.43	868
1965.4	878
1967.37	892
1969.34	870
1971.31	858
1973.28	876
1975.25	864
1977.22	900
1979.18	860
1981.15	890
1983.12	884
1985.08	848
1987.05	876
1989.01	890
1990.97	862
1992.94	836
1994.9	856
1996.86	862
1998.82	882
2000.78	876
2002.74	912
2004.7	888
2006.66	876
2008.62	888
2010.58	888
2012.54	864
2014.49	882
2016.45	878
2018.4	830
2020.36	890
2022.31	866
2024.27	888
2026.22	884
2028.17	877
2030.12	874
2032.07	890
2034.03	904
2035.98	886
2037.93	864
2039.87	892
2041.82	872
2043.77	870
2045.72	880
2047.66	890
2049.61	882
2051.55	896
2053.5	906
2055.44	874
2057.39	868
2059.33	862
2061.27	878
2063.21	830
2065.15	858
2067.09	866
2069.03	880
2070.97	852
2072.91	876
2074.85	870
2076.79	882
2078.73	838
2080.66	870
2082.6	854
2084.53	820
2086.47	866
2088.4	866
2090.33	884
2092.27	832
2094.2	868
2096.13	860
2098.06	860
2099.99	876
2101.92	892
2103.85	880
2105.78	844
2107.71	874
2109.64	884
2111.56	894
2113.49	842
2115.41	856
2117.34	864
2119.26	854
2121.19	858
2123.11	866
2125.03	822
2126.96	870
2128.88	860
2130.8	850
2132.72	854
2134.64	848
2136.56	878
2138.48	884
2140.4	892
2142.31	854
2144.23	832
2146.15	860
2148.06	828
2149.98	814
2151.89	874
2153.81	838
2155.72	834
2157.63	866
2159.55	828
2161.46	818
2163.37	828
2165.28	838
2167.19	820
2169.1	854
2171.01	830
2172.91	832
2174.82	816
2176.73	808
2178.64	830
2180.54	828
2182.45	828
2184.35	818
2186.26	838
2188.16	842
2190.06	834
2191.96	814
2193.87	810
2195.77	836
2197.67	856
2199.57	852
2201.47	820
2203.37	796
2205.27	820
2207.16	788
2209.06	820
2210.96	786
2212.85	778
2214.75	800
2216.64	836
2218.54	832
2220.43	834
2222.33	798
2224.22	803.552
2226.11	824.469
2228	827.367
2229.89	795.86
2231.78	874.558
2233.67	1227.65
2235.56	1633.45
2237.45	805.844
2239.34	798.48
2241.23	784.148
2243.11	802.947
2245	817.859
2246.89	816.525
2248.77	806.413
2250.66	827.84
2252.54	808.224
2254.42	807.522
2256.31	780.652
2258.19	828.725
2260.07	809.174
2261.95	777.913
2263.83	809.21
2265.71	800.752
2267.59	792.716
2269.47	813.27
2271.35	780.595
2273.23	786.347
2275.1	770.246
2276.98	776.485
2278.86	793.64
2280.73	786.466
2282.61	800.933
2284.48	795.07
2286.36	792.025
2288.23	783.035
2290.1	788.52
2291.98	785.776
2293.85	790.123
2295.72	783.177
2297.59	788.77
2299.46	783.555
2301.33	775.126
2303.2	756.323
2305.06	751.789
2306.93	767.756
2308.8	763.35
2310.67	763.59
2312.53	760.24
2314.4	776.42
2316.26	742.495
2317.62	766
2319.5	752
2321.37	732
2323.24	726
2325.12	730
2326.99	774
2328.86	718
2330.73	764
2332.6	750
2334.47	746
2336.34	744
2338.2	744
2340.07	752
2341.94	740
2343.81	708
2345.67	712
2347.54	746
2349.4	712
2351.27	722
2353.13	726
2354.99	752
2356.86	712
2358.72	716
2360.58	726
2362.44	744
2364.3	742
2366.16	722
2368.02	736
2369.88	690
2371.74	712
2373.6	730
2375.45	712
2377.31	742
2379.17	700
2381.02	692
2382.88	686
2384.73	714
2386.58	676
2388.44	682
2390.29	704
2392.14	722
2393.99	694
2395.85	652
2397.7	694
2399.55	712
2401.4	676
2403.25	678
2405.09	682
2406.94	686
2408.79	682
2410.63	680
2412.48	694
2414.33	666
2416.17	662
2418.02	672
2419.86	666
2421.7	642
2423.55	658
2425.39	648
2427.23	650
2429.07	654
2430.91	636
2432.75	644
2434.59	642
2436.43	630
2438.27	626
2440.11	640
2441.95	596
2443.78	650
2445.62	596
2447.46	608
2449.29	626
2451.13	600
2452.96	622
2454.79	606
2456.63	582
2458.46	648
2460.29	632
2462.12	616
2463.95	644
2465.78	590
2467.61	600
2469.44	608
2471.27	594
2473.1	606
2474.93	594
2476.76	598
2478.58	598
2480.41	616
2482.23	594
2484.06	576
2485.88	578
2487.71	576
2489.53	566
2491.35	566
2493.18	574
2495	546
2496.82	570
2498.64	574
2500.46	548
2502.28	546
2504.1	560
2505.92	550
2507.74	526
2509.55	546
2511.37	598
2513.19	544
2515	520
2516.82	554
2518.63	548
2520.45	528
2522.26	522
2524.07	534
2525.89	504
2527.7	528
2529.51	524
2531.32	544
2533.13	494
2534.94	526
2536.75	510
2538.56	488
2540.37	502
2542.18	506
2543.98	522
2545.79	534
2547.6	494
2549.4	498
2551.21	482
2553.01	520
2554.82	520
2556.62	492
2558.42	470
2560.23	496
2562.03	488
2563.83	482
2565.63	502
2567.43	492
2569.23	496
2571.03	490
2572.83	448
2574.63	460
2576.43	496
2578.22	462
2580.02	500
2581.82	480
2583.61	446
2585.41	478
2587.2	486
2589	440
2590.79	460
2592.58	444
2594.38	464
2596.17	440
2597.96	454
2599.75	446
2601.54	448
2603.33	440
2605.12	440
2606.91	456
2608.7	440
2610.49	424
2612.27	444
2614.06	424
2615.85	416
2617.63	406
2619.42	422
2621.2	448
2622.99	424
2624.77	422
2626.55	424
2628.34	404
2630.12	430
2631.9	400
2633.68	412
2635.46	404
2637.24	410
2639.02	384
2640.8	400
2642.58	398
2644.36	382
2646.14	386
2647.91	400
2649.69	370
2651.46	388
2653.24	368
2655.01	368
2656.79	358
2658.56	354
2660.34	388
2662.11	388
2663.88	382
2665.65	376
2667.42	352
2669.2	398
2670.96	372
2672.73	394
2674.5	398
2676.27	380
2678.04	394
2679.81	370
2681.58	358
2683.34	360
2685.11	406
2686.87	358
2688.64	368
2690.4	350
2692.17	382
2693.93	356
2695.69	358
2697.46	362
2699.22	342
2700.98	338
2702.74	342
2704.5	356
2706.26	334
2708.02	338
2709.78	328
2711.54	346
2713.3	340
2715.05	342
2716.81	332
2718.57	320
2720.32	316
2722.08	316
2723.83	324
2725.59	308
2727.34	320
2729.09	318
2730.85	304
2732.6	306
2734.35	314
2736.1	326
2737.85	300
2739.6	302
2741.35	320
2743.1	308
2744.85	308
2746.6	298
2748.35	302
2750.09	320
2751.84	302
2753.59	286
2755.33	288
2757.08	280
2758.82	286
2760.57	282
2762.31	280
2764.05	288
2765.79	270
2767.54	296
2769.28	296
2771.02	280
2772.76	284
2774.5	266
2776.24	276
2777.98	280
2779.72	284
2781.46	264
2783.19	276
2784.93	270
2786.67	276
2788.4	248
2790.14	262
2791.87	274
2793.61	264
2795.34	256
2797.07	252
2798.81	238
2800.54	252
2802.27	256
2804	266
2805.74	242
2807.47	266
2809.2	234
2810.93	254
2812.65	236
2814.38	244
2816.11	262
2817.84	230
2819.56	236
2821.29	258
2823.02	250
2824.74	226
2826.47	234
2828.19	240
2829.92	230
2831.64	230
2833.36	206
2835.09	226
2836.81	236
2838.53	222
2840.25	238
2841.97	216
2843.69	206
2845.41	216
2847.13	224
2848.85	208
2850.57	222
2852.28	222
2854	214
2855.72	222
2857.43	206
2859.15	210
2860.86	218
2862.58	194
2864.29	218
2866.01	204
2867.72	210
2869.43	200
2871.14	214
2872.86	222
2874.57	208
2876.28	190
2877.99	202
2879.7	188
2881.41	206
2883.11	184
2884.82	192
2886.53	196
2888.24	198
2889.94	178
2891.65	190
2893.36	196
2895.06	184
2896.77	182
2898.47	200
2900.17	196
2901.88	184
2903.58	198
2905.28	192
2906.98	194
2908.69	184
2910.39	184
2912.09	188
2913.79	182
2915.49	186
2917.19	182
2918.88	158
2920.58	168
2922.28	160
2923.98	174
2925.67	170
2927.37	178
2929.06	186
2930.76	182
2932.45	196
2934.15	164
2935.84	158
2937.53	182
2939.23	180
2940.92	166
2942.61	174
2944.3	172
2945.99	180
2947.68	166
2949.37	168
2951.06	174
2952.75	170
2954.44	158
2956.12	156
2957.81	162
2959.5	182
2961.18	174
2962.87	162
2964.56	144
2966.24	146
2967.92	164
2969.61	156
2971.29	160
2972.97	152
2974.66	158
2976.34	150
2978.02	146
2979.7	142
2981.38	154
2983.06	158
2984.74	156
2986.42	150
2988.1	150
2989.78	146
2991.45	146
2993.13	142
2994.81	152
2996.48	140
2998.16	154
2999.83	152