File: muestras/suculenta_dedo/inside_pr_06.txt
#Acq. time (s)=	10
#Accumulations=	1
#Range (cm-¹)=	200...3000
#Windows=	3
#Autofocus=	Off
#AutoExposure=	Off
#Spike filter=	Off
#Delay time (s)=	0
#Binning=	1
#Readout mode=	Signal
#DeNoise=	Off
#ICS correction=	Off
#Dark correction=	Off
#Inst. Process=	Off
#Instrument=	LabRAM HR Evol
#Detector=	Syncerity OE
#Objective=	x100_VIS
#Grating=	600 (500nm)
#ND Filter=	1%
#Laser=	633nm_Edge
#Hole=	30.0125
#Range=	Visible
#Project=	Omar
#Sample=	03-07-23
#Site=	fings
#Title=	inside_pr
#Remark=
#Date=	03.07.2023 15:03
#Acquired=	03.07.2023 15:03:12
201.713	84
204.247	72
206.778	72
209.311	72
211.84	80
214.371	76
216.899	80
219.428	78
221.955	88
224.482	90
227.007	80
229.531	70
232.055	78
234.579	94
237.1	78
239.621	86
242.141	100
244.661	88
247.179	86
249.698	86
252.215	90
254.731	80
257.246	96
259.761	84
262.273	100
264.786	94
267.298	92
269.809	102
272.319	110
274.828	98
277.336	118
279.844	108
282.351	122
284.855	110
287.361	118
289.866	102
292.368	116
294.871	110
297.372	124
299.873	130
302.372	120
304.872	122
307.37	128
309.866	122
312.364	126
314.859	126
317.353	120
319.848	120
322.341	140
324.833	138
327.324	126
329.814	124
332.304	138
334.792	122
337.28	138
339.767	136
342.254	144
344.739	148
347.224	144
349.708	136
352.191	142
354.673	160
357.155	146
359.634	158
362.114	174
364.593	162
367.07	164
369.548	156
372.024	156
374.499	160
376.974	162
379.447	154
381.92	178
384.392	180
386.864	188
389.333	176
391.802	170
394.272	166
396.739	170
399.206	192
401.673	180
404.138	206
406.602	194
409.066	184
411.528	204
413.99	216
416.451	196
418.911	196
421.371	196
423.83	204
426.288	212
428.745	224
431.201	216
433.657	226
436.111	212
438.565	214
441.017	224
443.469	204
445.921	236
448.37	230
450.821	240
453.27	250
455.717	250
458.165	246
460.61	244
463.056	250
465.5	238
467.945	250
470.387	264
472.829	248
475.271	268
477.711	240
480.15	264
482.589	280
485.027	276
487.465	280
489.901	276
492.337	264
494.771	274
497.205	276
499.638	262
502.07	292
504.502	290
506.933	306
509.363	326
511.792	308
514.219	282
516.647	316
519.073	320
521.5	314
523.924	322
526.348	306
528.772	310
531.194	320
533.616	338
536.036	344
538.457	342
540.875	332
543.294	348
545.712	348
548.128	348
550.545	354
552.959	348
555.373	362
557.788	360
560.2	358
562.612	354
565.023	366
567.433	376
569.843	382
572.251	358
574.659	386
577.066	412
579.472	406
581.878	412
584.283	398
586.687	418
589.09	432
591.493	422
593.893	418
596.294	438
598.694	462
601.093	456
603.491	458
605.889	426
608.285	480
610.682	436
613.076	468
615.471	488
617.864	480
620.256	502
622.648	488
625.039	524
627.429	492
629.819	500
632.208	512
634.595	528
636.982	516
639.369	518
641.755	548
644.139	540
646.523	552
648.906	566
651.288	564
653.67	576
656.051	578
658.429	594
660.808	586
663.187	612
665.565	594
667.942	614
670.317	636
672.692	646
675.067	646
677.44	646
679.813	680
682.184	664
684.556	664
686.926	660
689.296	682
691.664	700
694.033	692
696.4	744
698.766	696
701.133	722
703.497	746
705.861	746
708.224	754
710.586	764
712.949	796
715.31	804
717.67	766
720.029	792
722.388	846
724.746	844
727.103	820
729.458	828
731.814	846
734.168	886
736.523	874
738.876	864
741.227	910
743.579	920
745.931	924
748.28	906
750.629	948
752.977	942
755.325	960
757.672	972
760.018	1024
762.363	958
764.708	972
767.052	1010
769.394	1032
771.737	1066
774.078	1054
776.419	1076
778.758	1084
781.097	1062
783.435	1094
785.773	1120
788.11	1118
790.446	1174
792.781	1192
795.115	1152
797.449	1190
799.782	1206
802.115	1256
804.446	1214
806.777	1222
809.106	1254
811.435	1292
813.764	1348
816.091	1276
818.418	1264
820.743	1328
823.069	1392
825.393	1388
827.717	1402
830.039	1376
832.362	1420
834.683	1426
837.003	1464
839.324	1512
841.643	1584
843.961	1532
846.278	1584
848.594	1578
850.91	1598
853.227	1640
855.541	1658
857.855	1694
860.168	1674
862.48	1706
864.79	1726
867.101	1736
869.411	1716
871.721	1800
874.029	1776
876.336	1748
878.643	1860
880.95	1846
883.254	1870
885.559	1924
887.862	1912
890.166	1918
892.467	1962
894.77	1960
897.07	2026
899.371	1986
901.669	2052
903.968	2108
906.266	2118
908.563	2044
910.859	2096
913.154	2136
915.449	2164
917.742	2156
920.036	2174
922.329	2230
924.621	2276
926.911	2228
929.201	2280
931.49	2320
933.779	2410
936.068	2410
938.355	2444
940.64	2462
942.926	2478
945.212	2476
947.495	2508
949.779	2554
952.062	2622
954.344	2630
956.625	2700
958.905	2702
961.184	2700
963.464	2700
965.742	2750
968.02	2776
970.296	2788
972.572	2860
974.847	2896
977.121	2918
979.396	2958
981.669	3026
983.941	3022
986.212	3070
988.483	3084
990.753	3102
993.022	3082
995.29	3144
997.558	3188
999.825	3266
1002.09	3198
1004.36	3270
1006.62	3274
1008.89	3360
1011.15	3456
1013.41	3470
1015.67	3390
1017.93	3552
1020.19	3488
1022.45	3630
1024.71	3686
1026.97	3658
1029.23	3618
1031.49	3742
1033.74	3686
1036	3862
1038.25	3858
1040.5	3858
1042.76	3982
1045.01	3986
1047.26	4094
1049.51	4058
1051.76	4122
1054.01	4122
1056.26	4184
1058.51	4192
1060.75	4208
1063	4344
1065.25	4300
1067.49	4360
1069.73	4420
1071.98	4408
1074.22	4476
1076.46	4430
1078.7	4534
1080.94	4564
1083.18	4556
1085.42	4686
1087.66	4674
1089.9	4720
1092.14	4700
1094.37	4670
1096.61	4828
1098.84	4772
1101.08	4862
1103.31	4866
1105.54	4948
1107.77	4964
1110	4876
1112.23	4996
1114.46	5050
1116.69	5038
1118.92	5018
1121.15	5042
1123.37	5160
1125.6	5198
1127.83	5172
1130.05	5138
1132.27	5254
1134.5	5344
1136.72	5280
1138.94	5372
1141.16	5292
1143.38	5388
1145.6	5386
1147.82	5336
1150.04	5472
1152.26	5444
1154.47	5490
1156.69	5530
1158.9	5564
1161.12	5578
1163.33	5558
1165.54	5606
1167.76	5620
1169.97	5580
1172.18	5514
1174.39	5554
1176.6	5504
1178.81	5666
1181.02	5630
1183.22	5576
1185.43	5552
1187.63	5536
1189.84	5500
1192.04	5492
1194.25	5540
1196.45	5416
1198.65	5452
1200.85	5366
1203.05	5420
1205.25	5532
1207.45	5496
1209.65	5378
1211.85	5342
1214.05	5376
1216.24	5266
1218.44	5342
1220.64	5328
1222.83	5284
1225.02	5256
1227.22	5208
1229.41	5186
1231.6	5146
1233.79	5096
1235.98	5132
1238.17	5066
1240.36	5126
1242.55	5002
1244.73	4996
1246.92	4918
1249.11	4954
1251.29	4960
1253.48	4888
1255.66	4854
1257.84	4792
1260.03	4910
1262.21	4810
1264.39	4746
1266.57	4746
1268.75	4666
1270.93	4588
1273.11	4668
1275.28	4582
1277.46	4552
1279.64	4528
1281.81	4464
1283.98	4457.94
1286.16	4403.52
1288.33	4359.6
1290.5	4325.26
1292.68	4241.82
1294.85	4168.02
1297.02	4087.72
1299.19	4164.13
1301.36	3992.87
1303.53	3961.26
1305.69	3978.8
1307.86	3913.47
1310.03	3850.47
1312.19	3754.22
1314.36	3726.68
1316.52	3700.92
1318.68	3683.2
1320.85	3551.37
1323.01	3600.38
1325.17	3507.21
1327.33	3478.26
1329.49	3434.85
1331.65	3379.5
1333.81	3314.8
1335.97	3305.64
1338.12	3218.78
1340.28	3209.83
1342.44	3211.31
1344.59	3161.87
1346.75	3062.03
1348.9	3034.21
1351.05	3026.84
1353.2	2919.01
1355.36	2947.53
1357.51	2883.4
1359.66	2895.15
1361.81	2873.16
1363.96	2784.38
1366.1	2758.11
1368.25	2729.59
1370.4	2692.59
1372.54	2658.56
1374.69	2659.83
1376.83	2541.68
1378.98	2571.46
1381.12	2545.41
1383.26	2510.62
1385.41	2484.34
1387.55	2416.28
1389.69	2377.26
1391.83	2385.33
1393.02	2278
1395.17	2454
1397.32	2248
1399.47	2264
1401.62	2246
1403.77	2282
1405.91	2260
1408.06	2286
1410.2	2216
1412.35	2218
1414.49	2182
1416.63	2144
1418.78	2134
1420.92	2120
1423.06	2108
1425.2	2054
1427.34	2084
1429.48	2036
1431.61	2032
1433.75	2052
1435.89	2002
1438.02	2034
1440.16	1970
1442.3	1954
1444.43	1970
1446.56	1930
1448.7	1898
1450.83	1928
1452.96	1898
1455.09	1914
1457.22	1928
1459.35	1900
1461.48	1882
1463.61	1832
1465.73	1858
1467.86	1814
1469.98	1828
1472.11	1786
1474.24	1820
1476.36	1802
1478.48	1810
1480.6	1798
1482.73	1822
1484.85	1734
1486.97	1730
1489.09	1756
1491.21	1730
1493.33	1742
1495.44	1696
1497.56	1730
1499.68	1658
1501.79	1648
1503.91	1666
1506.02	1656
1508.14	1638
1510.25	1652
1512.36	1620
1514.48	1604
1516.59	1586
1518.7	1578
1520.81	1578
1522.92	1578
1525.02	1574
1527.13	1552
1529.24	1520
1531.35	1482
1533.45	1482
1535.56	1538
1537.66	1490
1539.77	1496
1541.87	1514
1543.97	1414
1546.08	1508
1548.18	1476
1550.28	1444
1552.38	1444
1554.48	1440
1556.57	1420
1558.67	1432
1560.77	1416
1562.87	1428
1564.96	1410
1567.06	1384
1569.15	1400
1571.25	1388
1573.34	1404
1575.43	1386
1577.53	1374
1579.62	1354
1581.71	1392
1583.8	1358
1585.89	1348
1587.98	1326
1590.06	1310
1592.15	1284
1594.24	1328
1596.33	1328
1598.41	1400
1600.5	1304
1602.58	1302
1604.66	1330
1606.75	1332
1608.83	1274
1610.91	1330
1612.99	1286
1615.07	1314
1617.15	1328
1619.23	1252
1621.31	1266
1623.39	1260
1625.46	1260
1627.54	1260
1629.62	1254
1631.69	1220
1633.77	1278
1635.84	1210
1637.91	1262
1639.99	1236
1642.06	1228
1644.13	1212
1646.2	1268
1648.27	1196
1650.34	1256
1652.41	1210
1654.47	1210
1656.54	1212
1658.61	1200
1660.67	1220
1662.74	1206
1664.81	1168
1666.87	1216
1668.93	1150
1671	1136
1673.06	1170
1675.12	1162
1677.18	1148
1679.24	1158
1681.3	1116
1683.36	1150
1685.42	1170
1687.47	1134
1689.53	1134
1691.59	1124
1693.64	1134
1695.7	1092
1697.75	1170
1699.81	1146
1701.86	1150
1703.91	1134
1705.97	1140
1708.02	1130
1710.07	1112
1712.12	1114
1714.17	1128
1716.22	1156
1718.26	1084
1720.31	1126
1722.36	1104
1724.4	1114
1726.45	1104
1728.49	1108
1730.54	1084
1732.58	1074
1734.63	1094
1736.67	1064
1738.71	1052
1740.75	1078
1742.79	1068
1744.83	1080
1746.87	1076
1748.91	1084
1750.95	1050
1752.98	1078
1755.02	1054
1757.06	1064
1759.09	1076
1761.13	1084
1763.16	1068
1765.19	1066
1767.23	1078
1769.26	1026
1771.29	1080
1773.32	1068
1775.35	1090
1777.38	1072
1779.41	1074
1781.44	1040
1783.47	1070
1785.49	1080
1787.52	1074
1789.55	1056
1791.57	1070
1793.6	1028
1795.62	1028
1797.64	1072
1799.67	1070
1801.69	1038
1803.71	1078
1805.73	1028
1807.75	1066
1809.77	1042
1811.79	1034
1813.81	1066
1815.83	1032
1817.84	1050
1819.86	1054
1821.88	1042
1823.89	1060
1825.91	1058
1827.92	1058
1829.93	1022
1831.95	1048
1833.96	1006
1835.97	1072
1837.98	1014
1839.99	1006
1842	1030
1844.01	1054
1846.02	1054
1848.03	1028
1850.03	1028
1852.04	1010
1854.05	1032
1856.05	998
1858.06	1020
1860.06	986
1862.06	1054
1864.07	1044
1866.07	1018
1868.07	1010
1870.07	1014
1872.07	1022
1874.07	1014
1876.07	1026
1878.07	1028
1880.07	1032
1882.07	976
1884.06	1032
1886.06	1032
1888.05	1022
1890.05	1006
1892.04	1028
1894.04	996
1896.03	1008
1898.02	988
1900.01	992
1902	1008
1903.99	1050
1905.98	1050
1907.97	1008
1909.96	1022
1911.95	1038
1913.94	1046
1915.93	1022
1917.91	1024
1919.9	1004
1921.88	1026
1923.87	1034
1925.85	986
1927.83	1000
1929.82	1000
1931.8	982
1933.78	974
1935.76	974
1937.74	988
1939.72	1008
1941.7	1022
1943.68	992
1945.65	1036
1947.63	1028
1949.61	986
1951.58	986
1953.56	1080
1955.53	1004
1957.51	1050
1959.48	982
1961.45	990
1963.43	954
1965.4	974
1967.37	1032
1969.34	966
1971.31	952
1973.28	978
1975.25	962
1977.22	942
1979.18	990
1981.15	920
1983.12	1028
1985.08	962
1987.05	992
1989.01	1006
1990.97	976
1992.94	984
1994.9	974
1996.86	944
1998.82	1006
2000.78	976
2002.74	1026
2004.7	998
2006.66	992
2008.62	954
2010.58	978
2012.54	1012
2014.49	996
2016.45	994
2018.4	982
2020.36	1010
2022.31	952
2024.27	980
2026.22	988
2028.17	990
2030.12	986
2032.07	994
2034.03	966
2035.98	988
2037.93	964
2039.87	968
2041.82	960
2043.77	958
2045.72	984
2047.66	984
2049.61	952
2051.55	988
2053.5	966
2055.44	934
2057.39	994
2059.33	966
2061.27	964
2063.21	974
2065.15	972
2067.09	980
2069.03	972
2070.97	990
2072.91	948
2074.85	972
2076.79	966
2078.73	964
2080.66	952
2082.6	986
2084.53	980
2086.47	970
2088.4	988
2090.33	962
2092.27	970
2094.2	946
2096.13	966
2098.06	938
2099.99	966
2101.92	996
2103.85	1000
2105.78	942
2107.71	980
2109.64	984
2111.56	966
2113.49	976
2115.41	970
2117.34	936
2119.26	962
2121.19	950
2123.11	1004
2125.03	966
2126.96	944
2128.88	960
2130.8	946
2132.72	976
2134.64	938
2136.56	944
2138.48	954
2140.4	962
2142.31	978
2144.23	984
2146.15	966
2148.06	942
2149.98	982
2151.89	958
2153.81	966
2155.72	940
2157.63	920
2159.55	976
2161.46	940
2163.37	932
2165.28	966
2167.19	954
2169.1	932
2171.01	982
2172.91	968
2174.82	948
2176.73	952
2178.64	948
2180.54	970
2182.45	908
2184.35	946
2186.26	930
2188.16	948
2190.06	952
2191.96	940
2193.87	956
2195.77	944
2197.67	910
2199.57	950
2201.47	934
2203.37	930
2205.27	976
2207.16	912
2209.06	912
2210.96	934
2212.85	898
2214.75	908
2216.64	892
2218.54	894
2220.43	928
2222.33	920
2224.22	918.978
2226.11	876.302
2228	915.521
2229.89	934.693
2231.78	915.702
2233.67	913.559
2235.56	925.767
2237.45	916.152
2239.34	924.869
2241.23	937.33
2243.11	909
2245	894.978
2246.89	902.735
2248.77	893.832
2250.66	886.062
2252.54	917.81
2254.42	899.114
2256.31	877.32
2258.19	894.815
2260.07	903.058
2261.95	885.84
2263.83	877.47
2265.71	878.762
2267.59	882.924
2269.47	888.277
2271.35	875.457
2273.23	863.98
2275.1	876.848
2276.98	861.959
2278.86	869.771
2280.73	880.847
2282.61	868.982
2284.48	853.994
2286.36	846.11
2288.23	853.379
2290.1	858.9
2291.98	844.216
2293.85	848.145
2295.72	852.403
2297.59	842.702
2299.46	842.159
2301.33	834.651
2303.2	858.128
2305.06	828.588
2306.93	833.054
2308.8	825.143
2310.67	841.352
2312.53	823.861
2314.4	825.474
2316.26	823.045
2317.62	816
2319.5	830
2321.37	808
2323.24	850
2325.12	810
2326.99	818
2328.86	808
2330.73	804
2332.6	834
2334.47	798
2336.34	802
2338.2	800
2340.07	792
2341.94	852
2343.81	824
2345.67	776
2347.54	792
2349.4	782
2351.27	800
2353.13	810
2354.99	806
2356.86	788
2358.72	800
2360.58	822
2362.44	778
2364.3	802
2366.16	780
2368.02	816
2369.88	762
2371.74	778
2373.6	782
2375.45	762
2377.31	770
2379.17	808
2381.02	754
2382.88	780
2384.73	752
2386.58	772
2388.44	786
2390.29	718
2392.14	768
2393.99	748
2395.85	724
2397.7	760
2399.55	708
2401.4	756
2403.25	752
2405.09	780
2406.94	768
2408.79	742
2410.63	708
2412.48	742
2414.33	734
2416.17	734
2418.02	704
2419.86	748
2421.7	732
2423.55	698
2425.39	684
2427.23	730
2429.07	688
2430.91	716
2432.75	728
2434.59	740
2436.43	700
2438.27	700
2440.11	706
2441.95	662
2443.78	664
2445.62	718
2447.46	676
2449.29	688
2451.13	666
2452.96	682
2454.79	686
2456.63	682
2458.46	678
2460.29	688
2462.12	694
2463.95	646
2465.78	640
2467.61	658
2469.44	662
2471.27	648
2473.1	644
2474.93	642
2476.76	672
2478.58	662
2480.41	632
2482.23	614
2484.06	618
2485.88	668
2487.71	624
2489.53	602
2491.35	608
2493.18	628
2495	636
2496.82	646
2498.64	622
2500.46	634
2502.28	624
2504.1	612
2505.92	584
2507.74	594
2509.55	600
2511.37	576
2513.19	600
2515	582
2516.82	622
2518.63	584
2520.45	578
2522.26	588
2524.07	596
2525.89	560
2527.7	580
2529.51	562
2531.32	576
2533.13	568
2534.94	542
2536.75	560
2538.56	556
2540.37	552
2542.18	536
2543.98	580
2545.79	560
2547.6	556
2549.4	546
2551.21	536
2553.01	552
2554.82	558
2556.62	542
2558.42	558
2560.23	546
2562.03	544
2563.83	518
2565.63	522
2567.43	532
2569.23	540
2571.03	518
2572.83	524
2574.63	520
2576.43	532
2578.22	486
2580.02	500
2581.82	512
2583.61	506
2585.41	524
2587.2	478
2589	510
2590.79	496
2592.58	508
2594.38	488
2596.17	496
2597.96	516
2599.75	488
2601.54	498
2603.33	500
2605.12	490
2606.91	464
2608.7	478
2610.49	476
2612.27	478
2614.06	484
2615.85	480
2617.63	478
2619.42	450
2621.2	436
2622.99	438
2624.77	472
2626.55	478
2628.34	466
2630.12	454
2631.9	434
2633.68	472
2635.46	464
2637.24	430
2639.02	458
2640.8	428
2642.58	444
2644.36	460
2646.14	434
2647.91	444
2649.69	440
2651.46	440
2653.24	448
2655.01	442
2656.79	418
2658.56	422
2660.34	396
2662.11	404
2663.88	412
2665.65	420
2667.42	424
2669.2	396
2670.96	398
2672.73	412
2674.5	418
2676.27	396
2678.04	418
2679.81	386
2681.58	410
2683.34	390
2685.11	400
2686.87	390
2688.64	402
2690.4	382
2692.17	420
2693.93	386
2695.69	382
2697.46	376
2699.22	374
2700.98	380
2702.74	370
2704.5	372
2706.26	386
2708.02	390
2709.78	370
2711.54	364
2713.3	372
2715.05	366
2716.81	356
2718.57	360
2720.32	328
2722.08	384
2723.83	354
2725.59	354
2727.34	366
2729.09	358
2730.85	314
2732.6	344
2734.35	342
2736.1	326
2737.85	326
2739.6	338
2741.35	348
2743.1	316
2744.85	340
2746.6	352
2748.35	326
2750.09	320
2751.84	320
2753.59	324
2755.33	304
2757.08	332
2758.82	326
2760.57	316
2762.31	310
2764.05	332
2765.79	318
2767.54	330
2769.28	320
2771.02	306
2772.76	298
2774.5	304
2776.24	292
2777.98	300
2779.72	308
2781.46	286
2783.19	294
2784.93	280
2786.67	298
2788.4	276
2790.14	282
2791.87	294
2793.61	284
2795.34	288
2797.07	260
2798.81	284
2800.54	244
2802.27	272
2804	272
2805.74	276
2807.47	276
2809.2	282
2810.93	282
2812.65	272
2814.38	258
2816.11	254
2817.84	264
2819.56	268
2821.29	272
2823.02	292
2824.74	264
2826.47	268
2828.19	250
2829.92	264
2831.64	244
2833.36	252
2835.09	270
2836.81	246
2838.53	250
2840.25	242
2841.97	220
2843.69	230
2845.41	242
2847.13	244
2848.85	258
2850.57	248
2852.28	234
2854	240
2855.72	238
2857.43	242
2859.15	230
2860.86	228
2862.58	220
2864.29	204
2866.01	214
2867.72	204
2869.43	234
2871.14	224
2872.86	230
2874.57	222
2876.28	224
2877.99	204
2879.7	210
2881.41	218
2883.11	208
2884.82	212
2886.53	216
2888.24	216
2889.94	202
2891.65	202
2893.36	200
2895.06	210
2896.77	206
2898.47	200
2900.17	224
2901.88	200
2903.58	204
2905.28	210
2906.98	212
2908.69	190
2910.39	216
2912.09	196
2913.79	188
2915.49	190
2917.19	184
2918.88	186
2920.58	190
2922.28	196
2923.98	188
2925.67	182
2927.37	194
2929.06	216
2930.76	194
2932.45	194
2934.15	182
2935.84	190
2937.53	180
2939.23	206
2940.92	184
2942.61	188
2944.3	174
2945.99	188
2947.68	198
2949.37	184
2951.06	178
2952.75	178
2954.44	182
2956.12	170
2957.81	170
2959.5	166
2961.18	162
2962.87	184
2964.56	176
2966.24	172
2967.92	158
2969.61	168
2971.29	176
2972.97	172
2974.66	174
2976.34	160
2978.02	162
2979.7	158
2981.38	164
2983.06	156
2984.74	174
2986.42	162
2988.1	152
2989.78	168
2991.45	158
2993.13	192
2994.81	164
2996.48	160
2998.16	162
2999.83	156