File: muestras/suculenta_dedo/inside_pr_09.txt
#Acq. time (s)=	10
#Accumulations=	1
#Range (cm-¹)=	200...3000
#Windows=	3
#Autofocus=	Off
#AutoExposure=	Off
#Spike filter=	Off
#Delay time (s)=	0
#Binning=	1
#Readout mode=	Signal
#DeNoise=	Off
#ICS correction=	Off
#Dark correction=	Off
#Inst. Process=	Off
#Instrument=	LabRAM HR Evol
#Detector=	Syncerity OE
#Objective=	x100_VIS
#Grating=	600 (500nm)
#ND Filter=	1%
#Laser=	633nm_Edge
#Hole=	30.0125
#Range=	Visible
#Project=	Omar
#Sample=	03-07-23
#Site=	fings
#Title=	inside_pr
#Remark=
#Date=	03.07.2023 15:07
#Acquired=	03.07.2023 15:07:05
201.713	66
204.247	60
206.778	78
209.311	62
211.84	66
214.371	62
216.899	70
219.428	64
221.955	66
224.482	74
227.007	72
229.531	70
232.055	66
234.579	70
237.1	74
239.621	64
242.141	76
244.661	70
247.179	74
249.698	76
252.215	88
254.731	78
257.246	72
259.761	82
262.273	70
264.786	80
267.298	86
269.809	92
272.319	74
274.828	78
277.336	88
279.844	88
282.351	84
284.855	82
287.361	78
289.866	96
292.368	92
294.871	84
297.372	98
299.873	94
302.372	90
304.872	96
307.37	92
309.866	96
312.364	102
314.859	108
317.353	92
319.848	110
322.341	88
324.833	108
327.324	104
329.814	108
332.304	106
334.792	112
337.28	114
339.767	112
342.254	122
344.739	106
347.224	122
349.708	116
352.191	108
354.673	118
357.155	110
359.634	124
362.114	110
364.593	108
367.07	120
369.548	126
372.024	118
374.499	114
376.974	128
379.447	112
381.92	120
384.392	128
386.864	120
389.333	130
391.802	136
394.272	124
396.739	138
399.206	118
401.673	146
404.138	136
406.602	142
409.066	154
411.528	142
413.99	156
416.451	138
418.911	154
421.371	152
423.83	130
426.288	162
428.745	178
431.201	160
433.657	158
436.111	160
438.565	178
441.017	178
443.469	154
445.921	162
448.37	162
450.821	164
453.27	180
455.717	164
458.165	178
460.61	164
463.056	176
465.5	158
467.945	176
470.387	164
472.829	180
475.271	190
477.711	186
480.15	180
482.589	200
485.027	192
487.465	196
489.901	206
492.337	220
494.771	178
497.205	202
499.638	200
502.07	212
504.502	208
506.933	208
509.363	204
511.792	212
514.219	216
516.647	210
519.073	212
521.5	216
523.924	232
526.348	212
528.772	234
531.194	226
533.616	246
536.036	234
538.457	232
540.875	228
543.294	244
545.712	226
548.128	244
550.545	240
552.959	244
555.373	238
557.788	248
560.2	270
562.612	250
565.023	250
567.433	262
569.843	244
572.251	260
574.659	278
577.066	276
579.472	282
581.878	258
584.283	278
586.687	276
589.09	292
591.493	292
593.893	296
596.294	292
598.694	294
601.093	292
603.491	308
605.889	298
608.285	298
610.682	296
613.076	334
615.471	322
617.864	332
620.256	320
622.648	338
625.039	320
627.429	320
629.819	348
632.208	352
634.595	348
636.982	360
639.369	336
641.755	342
644.139	376
646.523	352
648.906	388
651.288	390
653.67	402
656.051	394
658.429	394
660.808	396
663.187	408
665.565	406
667.942	418
670.317	396
672.692	424
675.067	418
677.44	394
679.813	440
682.184	416
684.556	454
686.926	426
689.296	454
691.664	444
694.033	474
696.4	440
698.766	456
701.133	472
703.497	484
705.861	478
708.224	484
710.586	486
712.949	502
715.31	498
717.67	512
720.029	522
722.388	524
724.746	544
727.103	538
729.458	514
731.814	564
734.168	594
736.523	574
738.876	588
741.227	598
743.579	578
745.931	568
748.28	602
750.629	626
752.977	626
755.325	652
757.672	652
760.018	642
762.363	634
764.708	658
767.052	614
769.394	686
771.737	650
774.078	696
776.419	678
778.758	698
781.097	690
783.435	728
785.773	746
788.11	746
790.446	732
792.781	778
795.115	752
797.449	786
799.782	800
802.115	780
804.446	812
806.777	802
809.106	844
811.435	850
813.764	864
816.091	882
818.418	866
820.743	870
823.069	864
825.393	902
827.717	930
830.039	922
832.362	916
834.683	936
837.003	968
839.324	956
841.643	992
843.961	1022
846.278	1006
848.594	1048
850.91	1054
853.227	1094
855.541	1082
857.855	1106
860.168	1110
862.48	1132
864.79	1094
867.101	1110
869.411	1150
871.721	1150
874.029	1222
876.336	1160
878.643	1206
880.95	1248
883.254	1266
885.559	1258
887.862	1238
890.166	1244
892.467	1266
894.77	1296
897.07	1326
899.371	1336
901.669	1342
903.968	1346
906.266	1384
908.563	1374
910.859	1412
913.154	1396
915.449	1406
917.742	1478
920.036	1482
922.329	1478
924.621	1514
926.911	1520
929.201	1560
931.49	1540
933.779	1556
936.068	1580
938.355	1588
940.64	1612
942.926	1598
945.212	1622
947.495	1706
949.779	1700
952.062	1710
954.344	1726
956.625	1728
958.905	1732
961.184	1792
963.464	1818
965.742	1842
968.02	1822
970.296	1806
972.572	1886
974.847	1876
977.121	1888
979.396	1902
981.669	1960
983.941	1972
986.212	1990
988.483	2040
990.753	2030
993.022	2058
995.29	2054
997.558	2166
999.825	2170
1002.09	2120
1004.36	2170
1006.62	2222
1008.89	2196
1011.15	2272
1013.41	2292
1015.67	2246
1017.93	2300
1020.19	2358
1022.45	2350
1024.71	2414
1026.97	2424
1029.23	2452
1031.49	2458
1033.74	2484
1036	2582
1038.25	2622
1040.5	2560
1042.76	2610
1045.01	2632
1047.26	2644
1049.51	2694
1051.76	2730
1054.01	2772
1056.26	2752
1058.51	2846
1060.75	2820
1063	2848
1065.25	2876
1067.49	2896
1069.73	2908
1071.98	2970
1074.22	2878
1076.46	2992
1078.7	2994
1080.94	3016
1083.18	3002
1085.42	3090
1087.66	3080
1089.9	3114
1092.14	3126
1094.37	3096
1096.61	3212
1098.84	3256
1101.08	3198
1103.31	3194
1105.54	3260
1107.77	3266
1110	3306
1112.23	3256
1114.46	3312
1116.69	3322
1118.92	3424
1121.15	3378
1123.37	3362
1125.6	3478
1127.83	3458
1130.05	3490
1132.27	3510
1134.5	3450
1136.72	3500
1138.94	3568
1141.16	3518
1143.38	3564
1145.6	3630
1147.82	3626
1150.04	3648
1152.26	3624
1154.47	3566
1156.69	3638
1158.9	3628
1161.12	3656
1163.33	3714
1165.54	3666
1167.76	3700
1169.97	3702
1172.18	3726
1174.39	3796
1176.6	3608
1178.81	3694
1181.02	3714
1183.22	3700
1185.43	3686
1187.63	3630
1189.84	3662
1192.04	3710
1194.25	3668
1196.45	3616
1198.65	3584
1200.85	3610
1203.05	3626
1205.25	3594
1207.45	3568
1209.65	3552
1211.85	3530
1214.05	3554
1216.24	3560
1218.44	3514
1220.64	3466
1222.83	3428
1225.02	3488
1227.22	3450
1229.41	3380
1231.6	3406
1233.79	3458
1235.98	3398
1238.17	3352
1240.36	3334
1242.55	3364
1244.73	3274
1246.92	3284
1249.11	3242
1251.29	3304
1253.48	3242
1255.66	3218
1257.84	3236
1260.03	3186
1262.21	3206
1264.39	3056
1266.57	3134
1268.75	3094
1270.93	3092
1273.11	3116
1275.28	3060
1277.46	3064
1279.64	2970
1281.81	3042
1283.98	2898.06
1286.16	2936.88
1288.33	2881.3
1290.5	2855.35
1292.68	2886.9
1294.85	2878.94
1297.02	2801.34
1299.19	2785.1
1301.36	2815.77
1303.53	2725
1305.69	2719.89
1307.86	2716.43
1310.03	2687.66
1312.19	2621.58
1314.36	2609.59
1316.52	2607.16
1318.68	2577.77
1320.85	2531.61
1323.01	2494.42
1325.17	2495.69
1327.33	2499.88
1329.49	2477.22
1331.65	2437.53
1333.81	2416.6
1335.97	2396.28
1338.12	2383.23
1340.28	2337.68
1342.44	2335.42
1344.59	2288.22
1346.75	2251.77
1348.9	2261.3
1351.05	2257.38
1353.2	2253.78
1355.36	2181.59
1357.51	2169.24
1359.66	2174.18
1361.81	2103.3
1363.96	2097.92
1366.1	2084.61
1368.25	2093.83
1370.4	2088.89
1372.54	2043.62
1374.69	1999.77
1376.83	2065.89
1378.98	2014.25
1381.12	1993.16
1383.26	1964.27
1385.41	1958.18
1387.55	1941.85
1389.69	1966.21
1391.83	1871.91
1393.02	1888
1395.17	1894
1397.32	1886
1399.47	1882
1401.62	1818
1403.77	1808
1405.91	1772
1408.06	1806
1410.2	1786
1412.35	1806
1414.49	1740
1416.63	1758
1418.78	1734
1420.92	1726
1423.06	1712
1425.2	1742
1427.34	1680
1429.48	1650
1431.61	1694
1433.75	1644
1435.89	1618
1438.02	1652
1440.16	1632
1442.3	1616
1444.43	1616
1446.56	1600
1448.7	1598
1450.83	1588
1452.96	1590
1455.09	1582
1457.22	1560
1459.35	1572
1461.48	1524
1463.61	1562
1465.73	1488
1467.86	1562
1469.98	1524
1472.11	1516
1474.24	1476
1476.36	1504
1478.48	1460
1480.6	1490
1482.73	1478
1484.85	1452
1486.97	1476
1489.09	1446
1491.21	1436
1493.33	1390
1495.44	1366
1497.56	1410
1499.68	1454
1501.79	1380
1503.91	1350
1506.02	1376
1508.14	1346
1510.25	1392
1512.36	1352
1514.48	1314
1516.59	1344
1518.7	1326
1520.81	1276
1522.92	1272
1525.02	1312
1527.13	1308
1529.24	1308
1531.35	1294
1533.45	1218
1535.56	1304
1537.66	1248
1539.77	1226
1541.87	1230
1543.97	1218
1546.08	1206
1548.18	1202
1550.28	1210
1552.38	1178
1554.48	1198
1556.57	1214
1558.67	1178
1560.77	1196
1562.87	1190
1564.96	1202
1567.06	1182
1569.15	1162
1571.25	1132
1573.34	1128
1575.43	1146
1577.53	1110
1579.62	1136
1581.71	1122
1583.8	1148
1585.89	1082
1587.98	1156
1590.06	1166
1592.15	1084
1594.24	1170
1596.33	1150
1598.41	1100
1600.5	1120
1602.58	1102
1604.66	1094
1606.75	1100
1608.83	1122
1610.91	1090
1612.99	1112
1615.07	1066
1617.15	1084
1619.23	1054
1621.31	1038
1623.39	1050
1625.46	1072
1627.54	1042
1629.62	1066
1631.69	1036
1633.77	1060
1635.84	1076
1637.91	1042
1639.99	1062
1642.06	1076
1644.13	998
1646.2	1046
1648.27	1046
1650.34	1080
1652.41	1050
1654.47	1012
1656.54	1054
1658.61	992
1660.67	990
1662.74	976
1664.81	998
1666.87	988
1668.93	990
1671	996
1673.06	996
1675.12	1016
1677.18	972
1679.24	958
1681.3	976
1683.36	990
1685.42	970
1687.47	970
1689.53	954
1691.59	968
1693.64	968
1695.7	968
1697.75	948
1699.81	952
1701.86	972
1703.91	960
1705.97	932
1708.02	964
1710.07	960
1712.12	922
1714.17	900
1716.22	944
1718.26	932
1720.31	952
1722.36	912
1724.4	944
1726.45	940
1728.49	912
1730.54	944
1732.58	916
1734.63	924
1736.67	936
1738.71	934
1740.75	934
1742.79	938
1744.83	894
1746.87	922
1748.91	910
1750.95	900
1752.98	912
1755.02	920
1757.06	884
1759.09	914
1761.13	918
1763.16	922
1765.19	926
1767.23	912
1769.26	910
1771.29	920
1773.32	890
1775.35	880
1777.38	908
1779.41	956
1781.44	900
1783.47	854
1785.49	892
1787.52	898
1789.55	888
1791.57	918
1793.6	874
1795.62	884
1797.64	878
1799.67	878
1801.69	854
1803.71	892
1805.73	848
1807.75	892
1809.77	872
1811.79	888
1813.81	862
1815.83	876
1817.84	860
1819.86	870
1821.88	916
1823.89	864
1825.91	882
1827.92	896
1829.93	900
1831.95	886
1833.96	884
1835.97	862
1837.98	850
1839.99	878
1842	860
1844.01	840
1846.02	864
1848.03	858
1850.03	834
1852.04	844
1854.05	872
1856.05	852
1858.06	856
1860.06	862
1862.06	848
1864.07	842
1866.07	858
1868.07	882
1870.07	874
1872.07	856
1874.07	878
1876.07	840
1878.07	870
1880.07	838
1882.07	876
1884.06	824
1886.06	820
1888.05	856
1890.05	840
1892.04	844
1894.04	876
1896.03	830
1898.02	880
1900.01	844
1902	856
1903.99	832
1905.98	854
1907.97	840
1909.96	846
1911.95	842
1913.94	878
1915.93	828
1917.91	840
1919.9	866
1921.88	828
1923.87	834
1925.85	814
1927.83	844
1929.82	862
1931.8	842
1933.78	862
1935.76	844
1937.74	866
1939.72	800
1941.7	850
1943.68	830
1945.65	836
1947.63	822
1949.61	824
1951.58	826
1953.56	844
1955.53	896
1957.51	828
1959.48	800
1961.45	814
1963.43	790
1965.4	810
1967.37	826
1969.34	826
1971.31	822
1973.28	864
1975.25	810
1977.22	804
1979.18	824
1981.15	852
1983.12	818
1985.08	838
1987.05	820
1989.01	818
1990.97	836
1992.94	828
1994.9	798
1996.86	826
1998.82	842
2000.78	794
2002.74	824
2004.7	798
2006.66	818
2008.62	838
2010.58	800
2012.54	838
2014.49	800
2016.45	784
2018.4	798
2020.36	830
2022.31	826
2024.27	830
2026.22	820
2028.17	830
2030.12	806
2032.07	814
2034.03	848
2035.98	836
2037.93	794
2039.87	804
2041.82	778
2043.77	810
2045.72	830
2047.66	798
2049.61	818
2051.55	830
2053.5	824
2055.44	818
2057.39	814
2059.33	802
2061.27	794
2063.21	800
2065.15	800
2067.09	810
2069.03	798
2070.97	822
2072.91	828
2074.85	798
2076.79	814
2078.73	802
2080.66	816
2082.6	820
2084.53	802
2086.47	792
2088.4	856
2090.33	1034
2092.27	828
2094.2	784
2096.13	778
2098.06	812
2099.99	798
2101.92	790
2103.85	790
2105.78	828
2107.71	750
2109.64	784
2111.56	798
2113.49	786
2115.41	820
2117.34	800
2119.26	808
2121.19	798
2123.11	790
2125.03	826
2126.96	824
2128.88	792
2130.8	818
2132.72	806
2134.64	832
2136.56	804
2138.48	818
2140.4	818
2142.31	816
2144.23	784
2146.15	800
2148.06	806
2149.98	798
2151.89	838
2153.81	800
2155.72	782
2157.63	808
2159.55	800
2161.46	756
2163.37	796
2165.28	778
2167.19	788
2169.1	800
2171.01	794
2172.91	776
2174.82	798
2176.73	760
2178.64	780
2180.54	744
2182.45	816
2184.35	806
2186.26	766
2188.16	780
2190.06	754
2191.96	802
2193.87	756
2195.77	806
2197.67	768
2199.57	782
2201.47	784
2203.37	774
2205.27	774
2207.16	782
2209.06	776
2210.96	758
2212.85	772
2214.75	778
2216.64	800
2218.54	770
2220.43	756
2222.33	798
2224.22	778.285
2226.11	793.307
2228	737.959
2229.89	737.02
2231.78	764.473
2233.67	767.885
2235.56	764.409
2237.45	818.579
2239.34	725.75
2241.23	756.701
2243.11	751.463
2245	739.831
2246.89	772.78
2248.77	746.069
2250.66	764.914
2252.54	769.369
2254.42	742.724
2256.31	730.646
2258.19	735.275
2260.07	736.525
2261.95	750.551
2263.83	728.53
2265.71	723.81
2267.59	754.154
2269.47	730.452
2271.35	737.025
2273.23	727.69
2275.1	722.485
2276.98	707.782
2278.86	713.889
2280.73	696.585
2282.61	709.579
2284.48	701.969
2286.36	706.295
2288.23	704.556
2290.1	704.614
2291.98	696.675
2293.85	696.143
2295.72	698.004
2297.59	682.362
2299.46	664.21
2301.33	676.493
2303.2	689.255
2305.06	685.794
2306.93	682.806
2308.8	690.801
2310.67	687.93
2312.53	654.65
2314.4	662.824
2316.26	674.878
2317.62	690
2319.5	650
2321.37	678
2323.24	666
2325.12	668
2326.99	612
2328.86	642
2330.73	644
2332.6	646
2334.47	640
2336.34	660
2338.2	676
2340.07	670
2341.94	680
2343.81	662
2345.67	626
2347.54	670
2349.4	660
2351.27	638
2353.13	646
2354.99	630
2356.86	634
2358.72	654
2360.58	612
2362.44	638
2364.3	614
2366.16	600
2368.02	640
2369.88	626
2371.74	636
2373.6	638
2375.45	648
2377.31	624
2379.17	618
2381.02	628
2382.88	618
2384.73	660
2386.58	614
2388.44	630
2390.29	632
2392.14	670
2393.99	620
2395.85	622
2397.7	606
2399.55	624
2401.4	580
2403.25	590
2405.09	618
2406.94	608
2408.79	578
2410.63	612
2412.48	584
2414.33	582
2416.17	564
2418.02	600
2419.86	596
2421.7	566
2423.55	602
2425.39	554
2427.23	600
2429.07	576
2430.91	598
2432.75	590
2434.59	562
2436.43	600
2438.27	572
2440.11	576
2441.95	534
2443.78	562
2445.62	560
2447.46	566
2449.29	578
2451.13	536
2452.96	534
2454.79	554
2456.63	536
2458.46	568
2460.29	554
2462.12	544
2463.95	532
2465.78	532
2467.61	546
2469.44	554
2471.27	542
2473.1	568
2474.93	526
2476.76	548
2478.58	552
2480.41	524
2482.23	506
2484.06	500
2485.88	508
2487.71	518
2489.53	524
2491.35	502
2493.18	514
2495	510
2496.82	512
2498.64	500
2500.46	506
2502.28	510
2504.1	510
2505.92	500
2507.74	520
2509.55	500
2511.37	514
2513.19	508
2515	498
2516.82	492
2518.63	478
2520.45	490
2522.26	504
2524.07	482
2525.89	472
2527.7	482
2529.51	480
2531.32	474
2533.13	476
2534.94	456
2536.75	474
2538.56	464
2540.37	454
2542.18	436
2543.98	446
2545.79	456
2547.6	472
2549.4	464
2551.21	458
2553.01	452
2554.82	454
2556.62	464
2558.42	442
2560.23	430
2562.03	436
2563.83	448
2565.63	444
2567.43	452
2569.23	436
2571.03	454
2572.83	430
2574.63	428
2576.43	424
2578.22	438
2580.02	412
2581.82	424
2583.61	432
2585.41	424
2587.2	416
2589	412
2590.79	420
2592.58	410
2594.38	418
2596.17	400
2597.96	406
2599.75	390
2601.54	396
2603.33	406
2605.12	386
2606.91	398
2608.7	382
2610.49	408
2612.27	382
2614.06	394
2615.85	398
2617.63	386
2619.42	382
2621.2	382
2622.99	372
2624.77	386
2626.55	384
2628.34	392
2630.12	372
2631.9	374
2633.68	380
2635.46	360
2637.24	362
2639.02	368
2640.8	390
2642.58	376
2644.36	352
2646.14	368
2647.91	368
2649.69	362
2651.46	360
2653.24	362
2655.01	346
2656.79	370
2658.56	360
2660.34	328
2662.11	352
2663.88	398
2665.65	364
2667.42	360
2669.2	356
2670.96	366
2672.73	326
2674.5	350
2676.27	344
2678.04	350
2679.81	358
2681.58	354
2683.34	322
2685.11	320
2686.87	346
2688.64	344
2690.4	366
2692.17	322
2693.93	326
2695.69	332
2697.46	318
2699.22	346
2700.98	332
2702.74	324
2704.5	312
2706.26	316
2708.02	342
2709.78	324
2711.54	310
2713.3	306
2715.05	308
2716.81	316
2718.57	314
2720.32	306
2722.08	300
2723.83	312
2725.59	302
2727.34	318
2729.09	296
2730.85	288
2732.6	324
2734.35	290
2736.1	270
2737.85	288
2739.6	282
2741.35	274
2743.1	270
2744.85	276
2746.6	260
2748.35	278
2750.09	306
2751.84	276
2753.59	272
2755.33	284
2757.08	270
2758.82	280
2760.57	270
2762.31	260
2764.05	274
2765.79	268
2767.54	260
2769.28	286
2771.02	272
2772.76	258
2774.5	258
2776.24	274
2777.98	272
2779.72	256
2781.46	250
2783.19	272
2784.93	272
2786.67	276
2788.4	258
2790.14	250
2791.87	244
2793.61	262
2795.34	230
2797.07	240
2798.81	252
2800.54	228
2802.27	236
2804	246
2805.74	236
2807.47	224
2809.2	240
2810.93	226
2812.65	228
2814.38	216
2816.11	240
2817.84	216
2819.56	224
2821.29	224
2823.02	220
2824.74	232
2826.47	220
2828.19	232
2829.92	212
2831.64	226
2833.36	242
2835.09	230
2836.81	234
2838.53	210
2840.25	226
2841.97	222
2843.69	220
2845.41	226
2847.13	212
2848.85	214
2850.57	214
2852.28	214
2854	206
2855.72	218
2857.43	210
2859.15	200
2860.86	202
2862.58	208
2864.29	200
2866.01	204
2867.72	210
2869.43	202
2871.14	202
2872.86	210
2874.57	206
2876.28	200
2877.99	196
2879.7	170
2881.41	198
2883.11	186
2884.82	208
2886.53	192
2888.24	198
2889.94	188
2891.65	186
2893.36	192
2895.06	180
2896.77	182
2898.47	198
2900.17	188
2901.88	196
2903.58	178
2905.28	162
2906.98	188
2908.69	184
2910.39	174
2912.09	176
2913.79	174
2915.49	184
2917.19	186
2918.88	170
2920.58	176
2922.28	170
2923.98	186
2925.67	178
2927.37	166
2929.06	190
2930.76	178
2932.45	164
2934.15	170
2935.84	158
2937.53	156
2939.23	178
2940.92	170
2942.61	170
2944.3	180
2945.99	166
2947.68	172
2949.37	158
2951.06	162
2952.75	170
2954.44	170
2956.12	162
2957.81	160
2959.5	164
2961.18	160
2962.87	166
2964.56	160
2966.24	162
2967.92	166
2969.61	156
2971.29	154
2972.97	144
2974.66	144
2976.34	156
2978.02	142
2979.7	162
2981.38	158
2983.06	146
2984.74	150
2986.42	142
2988.1	168
2989.78	152
2991.45	152
2993.13	152
2994.81	154
2996.48	130
2998.16	156
2999.83	156