File: muestras/suculenta_dedo/inside_pr_03.txt
#Acq. time (s)=	10
#Accumulations=	1
#Range (cm-¹)=	200...3000
#Windows=	3
#Autofocus=	Off
#AutoExposure=	Off
#Spike filter=	Off
#Delay time (s)=	0
#Binning=	1
#Readout mode=	Signal
#DeNoise=	Off
#ICS correction=	Off
#Dark correction=	Off
#Inst. Process=	Off
#Instrument=	LabRAM HR Evol
#Detector=	Syncerity OE
#Objective=	x100_VIS
#Grating=	600 (500nm)
#ND Filter=	1%
#Laser=	633nm_Edge
#Hole=	30.0125
#Range=	Visible
#Project=	Omar
#Sample=	03-07-23
#Site=	fings
#Title=	inside_pr
#Remark=
#Date=	03.07.2023 14:59
#Acquired=	03.07.2023 14:59:43
201.713	108
204.247	104
206.778	112
209.311	114
211.84	106
214.371	118
216.899	106
219.428	114
221.955	106
224.482	106
227.007	108
229.531	122
232.055	120
234.579	122
237.1	124
239.621	140
242.141	142
244.661	132
247.179	124
249.698	134
252.215	132
254.731	142
257.246	130
259.761	140
262.273	140
264.786	146
267.298	130
269.809	148
272.319	134
274.828	158
277.336	152
279.844	152
282.351	146
284.855	152
287.361	154
289.866	166
292.368	172
294.871	166
297.372	170
299.873	190
302.372	178
304.872	182
307.37	180
309.866	182
312.364	178
314.859	182
317.353	182
319.848	192
322.341	206
324.833	190
327.324	194
329.814	202
332.304	188
334.792	218
337.28	198
339.767	198
342.254	202
344.739	220
347.224	252
349.708	208
352.191	208
354.673	244
357.155	242
359.634	226
362.114	212
364.593	232
367.07	238
369.548	244
372.024	248
374.499	244
376.974	244
379.447	262
381.92	240
384.392	262
386.864	244
389.333	266
391.802	272
394.272	264
396.739	260
399.206	292
401.673	280
404.138	268
406.602	286
409.066	286
411.528	282
413.99	306
416.451	316
418.911	304
421.371	300
423.83	318
426.288	318
428.745	336
431.201	324
433.657	314
436.111	316
438.565	342
441.017	330
443.469	380
445.921	358
448.37	352
450.821	364
453.27	356
455.717	376
458.165	366
460.61	368
463.056	376
465.5	392
467.945	380
470.387	356
472.829	396
475.271	384
477.711	408
480.15	398
482.589	404
485.027	398
487.465	414
489.901	428
492.337	434
494.771	444
497.205	420
499.638	440
502.07	448
504.502	470
506.933	442
509.363	460
511.792	438
514.219	472
516.647	480
519.073	452
521.5	490
523.924	490
526.348	500
528.772	506
531.194	488
533.616	498
536.036	488
538.457	500
540.875	532
543.294	520
545.712	518
548.128	520
550.545	528
552.959	556
555.373	556
557.788	552
560.2	538
562.612	574
565.023	540
567.433	570
569.843	564
572.251	566
574.659	594
577.066	618
579.472	606
581.878	614
584.283	628
586.687	630
589.09	644
591.493	634
593.893	640
596.294	648
598.694	676
601.093	644
603.491	676
605.889	710
608.285	650
610.682	718
613.076	714
615.471	704
617.864	722
620.256	738
622.648	734
625.039	768
627.429	800
629.819	808
632.208	808
634.595	776
636.982	804
639.369	824
641.755	870
644.139	850
646.523	844
648.906	876
651.288	868
653.67	872
656.051	878
658.429	868
660.808	900
663.187	926
665.565	920
667.942	944
670.317	916
672.692	962
675.067	988
677.44	970
679.813	996
682.184	994
684.556	990
686.926	1026
689.296	1038
691.664	1046
694.033	1038
696.4	1056
698.766	1054
701.133	1102
703.497	1060
705.861	1104
708.224	1132
710.586	1150
712.949	1168
715.31	1170
717.67	1194
720.029	1192
722.388	1212
724.746	1240
727.103	1240
729.458	1252
731.814	1248
734.168	1316
736.523	1292
738.876	1342
741.227	1338
743.579	1352
745.931	1376
748.28	1376
750.629	1394
752.977	1336
755.325	1452
757.672	1442
760.018	1496
762.363	1506
764.708	1548
767.052	1504
769.394	1574
771.737	1522
774.078	1588
776.419	1584
778.758	1614
781.097	1628
783.435	1598
785.773	1750
788.11	1662
790.446	1666
792.781	1740
795.115	1770
797.449	1786
799.782	1848
802.115	1818
804.446	1864
806.777	1896
809.106	1890
811.435	1930
813.764	1954
816.091	1958
818.418	1948
820.743	1980
823.069	2054
825.393	2074
827.717	2098
830.039	2126
832.362	2190
834.683	2224
837.003	2244
839.324	2144
841.643	2232
843.961	2294
846.278	2316
848.594	2404
850.91	2422
853.227	2410
855.541	2424
857.855	2474
860.168	2498
862.48	2522
864.79	2518
867.101	2616
869.411	2676
871.721	2672
874.029	2624
876.336	2736
878.643	2748
880.95	2778
883.254	2796
885.559	2794
887.862	2784
890.166	2830
892.467	2924
894.77	2914
897.07	2912
899.371	2948
901.669	2958
903.968	3080
906.266	3034
908.563	3104
910.859	3154
913.154	3130
915.449	3202
917.742	3252
920.036	3306
922.329	3278
924.621	3294
926.911	3330
929.201	3420
931.49	3398
933.779	3462
936.068	3546
938.355	3484
940.64	3740
942.926	3684
945.212	3618
947.495	3844
949.779	3838
952.062	3854
954.344	3884
956.625	4010
958.905	4016
961.184	4024
963.464	4046
965.742	4140
968.02	4116
970.296	4164
972.572	4196
974.847	4330
977.121	4356
979.396	4302
981.669	4398
983.941	4382
986.212	4514
988.483	4590
990.753	4572
993.022	4664
995.29	4640
997.558	4676
999.825	4688
1002.09	4890
1004.36	4850
1006.62	4898
1008.89	4994
1011.15	4976
1013.41	5160
1015.67	5106
1017.93	5150
1020.19	5230
1022.45	5196
1024.71	5350
1026.97	5446
1029.23	5444
1031.49	5572
1033.74	5562
1036	5614
1038.25	5684
1040.5	5734
1042.76	5846
1045.01	5974
1047.26	6036
1049.51	6058
1051.76	6122
1054.01	6160
1056.26	6158
1058.51	6274
1060.75	6292
1063	6344
1065.25	6450
1067.49	6384
1069.73	6436
1071.98	6496
1074.22	6636
1076.46	6694
1078.7	6710
1080.94	6792
1083.18	6828
1085.42	6886
1087.66	6794
1089.9	6914
1092.14	6972
1094.37	6900
1096.61	7038
1098.84	7120
1101.08	7202
1103.31	7166
1105.54	7212
1107.77	7188
1110	7334
1112.23	7434
1114.46	7416
1116.69	7426
1118.92	7426
1121.15	7564
1123.37	7682
1125.6	7528
1127.83	7694
1130.05	7642
1132.27	7732
1134.5	7738
1136.72	7790
1138.94	7962
1141.16	7934
1143.38	8038
1145.6	7946
1147.82	8078
1150.04	8176
1152.26	8110
1154.47	8066
1156.69	8150
1158.9	8252
1161.12	8146
1163.33	8308
1165.54	8416
1167.76	8428
1169.97	8318
1172.18	8170
1174.39	8314
1176.6	8470
1178.81	8370
1181.02	8302
1183.22	8440
1185.43	8370
1187.63	8280
1189.84	8338
1192.04	8298
1194.25	8324
1196.45	8326
1198.65	8320
1200.85	8312
1203.05	8334
1205.25	8350
1207.45	8248
1209.65	8168
1211.85	8056
1214.05	8038
1216.24	8044
1218.44	8040
1220.64	7926
1222.83	8034
1225.02	7928
1227.22	7846
1229.41	7928
1231.6	7788
1233.79	7708
1235.98	7720
1238.17	7796
1240.36	7804
1242.55	7724
1244.73	7712
1246.92	7598
1249.11	7486
1251.29	7524
1253.48	7526
1255.66	7478
1257.84	7352
1260.03	7446
1262.21	7404
1264.39	7296
1266.57	7338
1268.75	7310
1270.93	7114
1273.11	7190
1275.28	7048
1277.46	7010
1279.64	6942
1281.81	6882
1283.98	6857.99
1286.16	6844.63
1288.33	6712.76
1290.5	6649.8
1292.68	6435.71
1294.85	6456.09
1297.02	6247.15
1299.19	6176.02
1301.36	6125.77
1303.53	6063.32
1305.69	5978.43
1307.86	5784.54
1310.03	5740.55
1312.19	5684.63
1314.36	5656.55
1316.52	5503.89
1318.68	5540.6
1320.85	5332.1
1323.01	5323.1
1325.17	5170.27
1327.33	5113.04
1329.49	5017.26
1331.65	4902.72
1333.81	4860.22
1335.97	4802.06
1338.12	4737.75
1340.28	4666.5
1342.44	4610.07
1344.59	4479.88
1346.75	4451.41
1348.9	4322.59
1351.05	4293.45
1353.2	4248.15
1355.36	4139.06
1357.51	4064.8
1359.66	4051.61
1361.81	3997.13
1363.96	3929.87
1366.1	3843.59
1368.25	3809.08
1370.4	3763.29
1372.54	3605.21
1374.69	3642.69
1376.83	3517.3
1378.98	3432.05
1381.12	3402.52
1383.26	3341.03
1385.41	3237.98
1387.55	3221.44
1389.69	3223.03
1391.83	3151.07
1393.02	3158
1395.17	3142
1397.32	3032
1399.47	3076
1401.62	2960
1403.77	3030
1405.91	2984
1408.06	2966
1410.2	2958
1412.35	2982
1414.49	2874
1416.63	2832
1418.78	2862
1420.92	2830
1423.06	2818
1425.2	2824
1427.34	2700
1429.48	2792
1431.61	2698
1433.75	2648
1435.89	2674
1438.02	2646
1440.16	2658
1442.3	2594
1444.43	2600
1446.56	2588
1448.7	2650
1450.83	2574
1452.96	2556
1455.09	2488
1457.22	2514
1459.35	2424
1461.48	2458
1463.61	2460
1465.73	2478
1467.86	2460
1469.98	2454
1472.11	2422
1474.24	2386
1476.36	2388
1478.48	2262
1480.6	2334
1482.73	2318
1484.85	2304
1486.97	2302
1489.09	2268
1491.21	2334
1493.33	2226
1495.44	2274
1497.56	2252
1499.68	2208
1501.79	2232
1503.91	2176
1506.02	2188
1508.14	2252
1510.25	2172
1512.36	2100
1514.48	2104
1516.59	2146
1518.7	2100
1520.81	2086
1522.92	2082
1525.02	2054
1527.13	2034
1529.24	2032
1531.35	2062
1533.45	2030
1535.56	1996
1537.66	2004
1539.77	1966
1541.87	1976
1543.97	1940
1546.08	1938
1548.18	1904
1550.28	1912
1552.38	1862
1554.48	1874
1556.57	1838
1558.67	1886
1560.77	1892
1562.87	1906
1564.96	1830
1567.06	1828
1569.15	1836
1571.25	1808
1573.34	1790
1575.43	1780
1577.53	1794
1579.62	1852
1581.71	1790
1583.8	1806
1585.89	1766
1587.98	1748
1590.06	1746
1592.15	1710
1594.24	1760
1596.33	1766
1598.41	1776
1600.5	1686
1602.58	1704
1604.66	1692
1606.75	1730
1608.83	1716
1610.91	1708
1612.99	1720
1615.07	1702
1617.15	1694
1619.23	1672
1621.31	1676
1623.39	1644
1625.46	1642
1627.54	1668
1629.62	1636
1631.69	1648
1633.77	1654
1635.84	1630
1637.91	1600
1639.99	1642
1642.06	1604
1644.13	1582
1646.2	1570
1648.27	1594
1650.34	1584
1652.41	1620
1654.47	1572
1656.54	1538
1658.61	1560
1660.67	1542
1662.74	1484
1664.81	1570
1666.87	1504
1668.93	1538
1671	1514
1673.06	1536
1675.12	1548
1677.18	1532
1679.24	1546
1681.3	1452
1683.36	1544
1685.42	1470
1687.47	1514
1689.53	1486
1691.59	1476
1693.64	1434
1695.7	1470
1697.75	1508
1699.81	1434
1701.86	1416
1703.91	1492
1705.97	1450
1708.02	1454
1710.07	1438
1712.12	1420
1714.17	1448
1716.22	1464
1718.26	1422
1720.31	1438
1722.36	1406
1724.4	1448
1726.45	1414
1728.49	1406
1730.54	1440
1732.58	1400
1734.63	1414
1736.67	1402
1738.71	1430
1740.75	1408
1742.79	1376
1744.83	1396
1746.87	1390
1748.91	1426
1750.95	1404
1752.98	1394
1755.02	1366
1757.06	1370
1759.09	1398
1761.13	1362
1763.16	1382
1765.19	1414
1767.23	1380
1769.26	1412
1771.29	1396
1773.32	1358
1775.35	1366
1777.38	1360
1779.41	1396
1781.44	1336
1783.47	1368
1785.49	1368
1787.52	1396
1789.55	1404
1791.57	1368
1793.6	1374
1795.62	1356
1797.64	1386
1799.67	1408
1801.69	1328
1803.71	1390
1805.73	1356
1807.75	1360
1809.77	1342
1811.79	1364
1813.81	1268
1815.83	1346
1817.84	1374
1819.86	1388
1821.88	1390
1823.89	1330
1825.91	1310
1827.92	1356
1829.93	1272
1831.95	1316
1833.96	1328
1835.97	1318
1837.98	1348
1839.99	1352
1842	1326
1844.01	1380
1846.02	1312
1848.03	1362
1850.03	1300
1852.04	1300
1854.05	1362
1856.05	1314
1858.06	1300
1860.06	1300
1862.06	1310
1864.07	1298
1866.07	1326
1868.07	1318
1870.07	1336
1872.07	1296
1874.07	1336
1876.07	1292
1878.07	1326
1880.07	1310
1882.07	1288
1884.06	1308
1886.06	1318
1888.05	1308
1890.05	1354
1892.04	1272
1894.04	1318
1896.03	1346
1898.02	1280
1900.01	1274
1902	1296
1903.99	1294
1905.98	1296
1907.97	1286
1909.96	1316
1911.95	1314
1913.94	1316
1915.93	1290
1917.91	1292
1919.9	1304
1921.88	1306
1923.87	1312
1925.85	1298
1927.83	1302
1929.82	1330
1931.8	1292
1933.78	1348
1935.76	1318
1937.74	1298
1939.72	1284
1941.7	1284
1943.68	1300
1945.65	1250
1947.63	1290
1949.61	1284
1951.58	1270
1953.56	1280
1955.53	1242
1957.51	1284
1959.48	1230
1961.45	1308
1963.43	1280
1965.4	1268
1967.37	1288
1969.34	1212
1971.31	1224
1973.28	1260
1975.25	1262
1977.22	1260
1979.18	1282
1981.15	1282
1983.12	1266
1985.08	1264
1987.05	1210
1989.01	1230
1990.97	1230
1992.94	1268
1994.9	1216
1996.86	1274
1998.82	1278
2000.78	1228
2002.74	1224
2004.7	1218
2006.66	1276
2008.62	1246
2010.58	1214
2012.54	1238
2014.49	1256
2016.45	1276
2018.4	1228
2020.36	1206
2022.31	1226
2024.27	1292
2026.22	1248
2028.17	1234
2030.12	1242
2032.07	1192
2034.03	1252
2035.98	1190
2037.93	1248
2039.87	1212
2041.82	1294
2043.77	1202
2045.72	1260
2047.66	1212
2049.61	1286
2051.55	1208
2053.5	1190
2055.44	1252
2057.39	1222
2059.33	1204
2061.27	1242
2063.21	1214
2065.15	1250
2067.09	1260
2069.03	1276
2070.97	1172
2072.91	1216
2074.85	1210
2076.79	1190
2078.73	1254
2080.66	1220
2082.6	1226
2084.53	1216
2086.47	1260
2088.4	1194
2090.33	1212
2092.27	1198
2094.2	1290
2096.13	1244
2098.06	1194
2099.99	1272
2101.92	1218
2103.85	1252
2105.78	1230
2107.71	1196
2109.64	1182
2111.56	1202
2113.49	1208
2115.41	1246
2117.34	1232
2119.26	1278
2121.19	1218
2123.11	1218
2125.03	1218
2126.96	1214
2128.88	1196
2130.8	1196
2132.72	1250
2134.64	1226
2136.56	1200
2138.48	1200
2140.4	1168
2142.31	1204
2144.23	1208
2146.15	1228
2148.06	1238
2149.98	1188
2151.89	1224
2153.81	1204
2155.72	1214
2157.63	1204
2159.55	1162
2161.46	1204
2163.37	1192
2165.28	1198
2167.19	1194
2169.1	1184
2171.01	1160
2172.91	1210
2174.82	1216
2176.73	1148
2178.64	1188
2180.54	1188
2182.45	1166
2184.35	1188
2186.26	1140
2188.16	1180
2190.06	1198
2191.96	1188
2193.87	1166
2195.77	1182
2197.67	1194
2199.57	1152
2201.47	1204
2203.37	1150
2205.27	1146
2207.16	1132
2209.06	1120
2210.96	1206
2212.85	1182
2214.75	1142
2216.64	1164
2218.54	1114
2220.43	1142
2222.33	1110
2224.22	1154.35
2226.11	1131.62
2228	1112.82
2229.89	1117.01
2231.78	1123.23
2233.67	1111.85
2235.56	1079.44
2237.45	1111.41
2239.34	1114.28
2241.23	1095.37
2243.11	1112.35
2245	1104.43
2246.89	1107.21
2248.77	1118.53
2250.66	1095.32
2252.54	1058.45
2254.42	1062.04
2256.31	1066.88
2258.19	1095.15
2260.07	1067.29
2261.95	1059.43
2263.83	1047.46
2265.71	1039.98
2267.59	1052.01
2269.47	1045.48
2271.35	1021.8
2273.23	1015.7
2275.1	1030.59
2276.98	996.441
2278.86	995.219
2280.73	1009.48
2282.61	1028.24
2284.48	974.31
2286.36	974.126
2288.23	962.332
2290.1	976.384
2291.98	963.432
2293.85	957.24
2295.72	944.109
2297.59	945.364
2299.46	937.003
2301.33	954.062
2303.2	943.525
2305.06	920.892
2306.93	932.098
2308.8	902.349
2310.67	921.734
2312.53	875.115
2314.4	900.32
2316.26	888.036
2317.62	900
2319.5	912
2321.37	878
2323.24	880
2325.12	876
2326.99	874
2328.86	856
2330.73	884
2332.6	904
2334.47	878
2336.34	860
2338.2	900
2340.07	878
2341.94	900
2343.81	864
2345.67	888
2347.54	848
2349.4	864
2351.27	890
2353.13	856
2354.99	850
2356.86	850
2358.72	836
2360.58	840
2362.44	852
2364.3	806
2366.16	854
2368.02	858
2369.88	824
2371.74	832
2373.6	808
2375.45	818
2377.31	834
2379.17	850
2381.02	862
2382.88	790
2384.73	838
2386.58	792
2388.44	848
2390.29	820
2392.14	800
2393.99	798
2395.85	782
2397.7	808
2399.55	782
2401.4	814
2403.25	784
2405.09	764
2406.94	768
2408.79	768
2410.63	776
2412.48	774
2414.33	804
2416.17	798
2418.02	786
2419.86	754
2421.7	772
2423.55	742
2425.39	768
2427.23	768
2429.07	774
2430.91	782
2432.75	762
2434.59	748
2436.43	746
2438.27	756
2440.11	708
2441.95	720
2443.78	750
2445.62	728
2447.46	752
2449.29	740
2451.13	730
2452.96	712
2454.79	722
2456.63	716
2458.46	696
2460.29	722
2462.12	710
2463.95	712
2465.78	692
2467.61	712
2469.44	690
2471.27	692
2473.1	702
2474.93	650
2476.76	690
2478.58	694
2480.41	672
2482.23	630
2484.06	674
2485.88	688
2487.71	672
2489.53	640
2491.35	664
2493.18	672
2495	668
2496.82	662
2498.64	650
2500.46	656
2502.28	628
2504.1	652
2505.92	650
2507.74	632
2509.55	624
2511.37	664
2513.19	628
2515	616
2516.82	642
2518.63	594
2520.45	600
2522.26	616
2524.07	598
2525.89	632
2527.7	574
2529.51	602
2531.32	600
2533.13	570
2534.94	596
2536.75	602
2538.56	586
2540.37	604
2542.18	590
2543.98	566
2545.79	564
2547.6	568
2549.4	596
2551.21	602
2553.01	576
2554.82	570
2556.62	578
2558.42	534
2560.23	572
2562.03	562
2563.83	558
2565.63	534
2567.43	538
2569.23	546
2571.03	538
2572.83	538
2574.63	534
2576.43	534
2578.22	554
2580.02	560
2581.82	538
2583.61	526
2585.41	526
2587.2	514
2589	510
2590.79	530
2592.58	542
2594.38	504
2596.17	528
2597.96	482
2599.75	518
2601.54	500
2603.33	496
2605.12	498
2606.91	516
2608.7	506
2610.49	496
2612.27	506
2614.06	494
2615.85	490
2617.63	462
2619.42	476
2621.2	480
2622.99	472
2624.77	484
2626.55	510
2628.34	458
2630.12	468
2631.9	474
2633.68	470
2635.46	480
2637.24	472
2639.02	468
2640.8	498
2642.58	478
2644.36	466
2646.14	452
2647.91	446
2649.69	464
2651.46	422
2653.24	448
2655.01	440
2656.79	446
2658.56	420
2660.34	398
2662.11	440
2663.88	428
2665.65	434
2667.42	450
2669.2	440
2670.96	400
2672.73	436
2674.5	422
2676.27	428
2678.04	406
2679.81	420
2681.58	420
2683.34	396
2685.11	396
2686.87	414
2688.64	408
2690.4	408
2692.17	420
2693.93	388
2695.69	420
2697.46	388
2699.22	390
2700.98	370
2702.74	390
2704.5	386
2706.26	376
2708.02	374
2709.78	388
2711.54	382
2713.3	372
2715.05	362
2716.81	380
2718.57	362
2720.32	386
2722.08	370
2723.83	388
2725.59	376
2727.34	350
2729.09	344
2730.85	366
2732.6	354
2734.35	352
2736.1	358
2737.85	350
2739.6	360
2741.35	344
2743.1	326
2744.85	328
2746.6	330
2748.35	340
2750.09	336
2751.84	294
2753.59	316
2755.33	324
2757.08	330
2758.82	312
2760.57	300
2762.31	310
2764.05	326
2765.79	326
2767.54	330
2769.28	318
2771.02	304
2772.76	314
2774.5	308
2776.24	300
2777.98	312
2779.72	290
2781.46	334
2783.19	320
2784.93	306
2786.67	292
2788.4	288
2790.14	304
2791.87	288
2793.61	284
2795.34	298
2797.07	282
2798.81	294
2800.54	290
2802.27	290
2804	282
2805.74	278
2807.47	282
2809.2	288
2810.93	272
2812.65	284
2814.38	268
2816.11	284
2817.84	274
2819.56	288
2821.29	260
2823.02	282
2824.74	264
2826.47	230
2828.19	252
2829.92	248
2831.64	264
2833.36	252
2835.09	270
2836.81	246
2838.53	230
2840.25	252
2841.97	230
2843.69	230
2845.41	236
2847.13	240
2848.85	232
2850.57	234
2852.28	222
2854	224
2855.72	234
2857.43	244
2859.15	224
2860.86	234
2862.58	224
2864.29	230
2866.01	228
2867.72	228
2869.43	232
2871.14	236
2872.86	212
2874.57	206
2876.28	210
2877.99	218
2879.7	200
2881.41	222
2883.11	208
2884.82	208
2886.53	222
2888.24	208
2889.94	204
2891.65	228
2893.36	194
2895.06	202
2896.77	214
2898.47	184
2900.17	210
2901.88	198
2903.58	214
2905.28	204
2906.98	180
2908.69	212
2910.39	206
2912.09	204
2913.79	188
2915.49	192
2917.19	186
2918.88	196
2920.58	184
2922.28	206
2923.98	178
2925.67	204
2927.37	206
2929.06	182
2930.76	172
2932.45	176
2934.15	180
2935.84	176
2937.53	168
2939.23	158
2940.92	182
2942.61	180
2944.3	186
2945.99	172
2947.68	168
2949.37	168
2951.06	170
2952.75	162
2954.44	184
2956.12	160
2957.81	182
2959.5	174
2961.18	182
2962.87	174
2964.56	142
2966.24	158
2967.92	158
2969.61	168
2971.29	166
2972.97	162
2974.66	152
2976.34	142
2978.02	154
2979.7	160
2981.38	176
2983.06	172
2984.74	174
2986.42	170
2988.1	150
2989.78	148
2991.45	164
2993.13	160
2994.81	170
2996.48	142
2998.16	142
2999.83	160