File: muestras/suculenta_dedo/inside_pr_08.txt
#Acq. time (s)=	10
#Accumulations=	1
#Range (cm-¹)=	200...3000
#Windows=	3
#Autofocus=	Off
#AutoExposure=	Off
#Spike filter=	Off
#Delay time (s)=	0
#Binning=	1
#Readout mode=	Signal
#DeNoise=	Off
#ICS correction=	Off
#Dark correction=	Off
#Inst. Process=	Off
#Instrument=	LabRAM HR Evol
#Detector=	Syncerity OE
#Objective=	x100_VIS
#Grating=	600 (500nm)
#ND Filter=	1%
#Laser=	633nm_Edge
#Hole=	30.0125
#Range=	Visible
#Project=	Omar
#Sample=	03-07-23
#Site=	fings
#Title=	inside_pr
#Remark=
#Date=	03.07.2023 15:05
#Acquired=	03.07.2023 15:05:46
201.713	62
204.247	68
206.778	64
209.311	68
211.84	64
214.371	68
216.899	70
219.428	66
221.955	74
224.482	60
227.007	62
229.531	70
232.055	76
234.579	66
237.1	70
239.621	84
242.141	84
244.661	70
247.179	76
249.698	80
252.215	80
254.731	70
257.246	80
259.761	80
262.273	72
264.786	82
267.298	84
269.809	78
272.319	86
274.828	78
277.336	94
279.844	74
282.351	80
284.855	94
287.361	92
289.866	90
292.368	80
294.871	80
297.372	84
299.873	90
302.372	98
304.872	80
307.37	98
309.866	96
312.364	94
314.859	90
317.353	100
319.848	104
322.341	102
324.833	98
327.324	104
329.814	110
332.304	108
334.792	108
337.28	120
339.767	118
342.254	112
344.739	102
347.224	116
349.708	110
352.191	112
354.673	122
357.155	114
359.634	106
362.114	108
364.593	120
367.07	134
369.548	120
372.024	116
374.499	120
376.974	104
379.447	122
381.92	122
384.392	120
386.864	138
389.333	124
391.802	132
394.272	146
396.739	132
399.206	138
401.673	150
404.138	144
406.602	128
409.066	144
411.528	136
413.99	140
416.451	156
418.911	150
421.371	152
423.83	142
426.288	164
428.745	158
431.201	166
433.657	152
436.111	158
438.565	150
441.017	168
443.469	186
445.921	152
448.37	164
450.821	170
453.27	174
455.717	152
458.165	176
460.61	170
463.056	170
465.5	178
467.945	200
470.387	190
472.829	188
475.271	186
477.711	198
480.15	188
482.589	194
485.027	216
487.465	192
489.901	194
492.337	216
494.771	186
497.205	210
499.638	210
502.07	214
504.502	230
506.933	210
509.363	222
511.792	230
514.219	220
516.647	218
519.073	218
521.5	242
523.924	220
526.348	244
528.772	222
531.194	228
533.616	254
536.036	234
538.457	248
540.875	234
543.294	236
545.712	248
548.128	242
550.545	244
552.959	252
555.373	256
557.788	242
560.2	258
562.612	242
565.023	252
567.433	266
569.843	272
572.251	262
574.659	294
577.066	270
579.472	276
581.878	286
584.283	270
586.687	302
589.09	300
591.493	284
593.893	298
596.294	294
598.694	314
601.093	306
603.491	304
605.889	316
608.285	320
610.682	324
613.076	346
615.471	326
617.864	314
620.256	342
622.648	346
625.039	334
627.429	348
629.819	360
632.208	348
634.595	370
636.982	356
639.369	382
641.755	392
644.139	384
646.523	370
648.906	370
651.288	416
653.67	384
656.051	392
658.429	412
660.808	414
663.187	430
665.565	386
667.942	422
670.317	428
672.692	426
675.067	434
677.44	450
679.813	418
682.184	490
684.556	464
686.926	458
689.296	468
691.664	480
694.033	460
696.4	492
698.766	486
701.133	496
703.497	488
705.861	514
708.224	506
710.586	528
712.949	506
715.31	528
717.67	522
720.029	534
722.388	552
724.746	558
727.103	552
729.458	598
731.814	584
734.168	564
736.523	588
738.876	590
741.227	604
743.579	580
745.931	622
748.28	600
750.629	622
752.977	660
755.325	634
757.672	646
760.018	624
762.363	668
764.708	704
767.052	690
769.394	678
771.737	696
774.078	744
776.419	706
778.758	740
781.097	748
783.435	760
785.773	748
788.11	768
790.446	792
792.781	764
795.115	764
797.449	798
799.782	856
802.115	828
804.446	852
806.777	864
809.106	864
811.435	882
813.764	890
816.091	880
818.418	880
820.743	896
823.069	952
825.393	946
827.717	940
830.039	948
832.362	998
834.683	986
837.003	1002
839.324	1002
841.643	1044
843.961	1080
846.278	1056
848.594	1064
850.91	1064
853.227	1090
855.541	1114
857.855	1132
860.168	1144
862.48	1146
864.79	1212
867.101	1160
869.411	1196
871.721	1204
874.029	1236
876.336	1206
878.643	1190
880.95	1218
883.254	1260
885.559	1304
887.862	1294
890.166	1270
892.467	1288
894.77	1364
897.07	1350
899.371	1358
901.669	1366
903.968	1396
906.266	1408
908.563	1456
910.859	1434
913.154	1440
915.449	1526
917.742	1482
920.036	1442
922.329	1526
924.621	1516
926.911	1544
929.201	1550
931.49	1580
933.779	1576
936.068	1602
938.355	1644
940.64	1672
942.926	1672
945.212	1686
947.495	1742
949.779	1690
952.062	1724
954.344	1780
956.625	1786
958.905	1824
961.184	1804
963.464	1860
965.742	1842
968.02	1924
970.296	1924
972.572	1942
974.847	1958
977.121	2016
979.396	1980
981.669	2022
983.941	2060
986.212	2044
988.483	2090
990.753	2130
993.022	2104
995.29	2160
997.558	2208
999.825	2126
1002.09	2180
1004.36	2204
1006.62	2268
1008.89	2258
1011.15	2238
1013.41	2354
1015.67	2398
1017.93	2344
1020.19	2394
1022.45	2438
1024.71	2434
1026.97	2544
1029.23	2484
1031.49	2552
1033.74	2630
1036	2602
1038.25	2648
1040.5	2640
1042.76	2712
1045.01	2724
1047.26	2792
1049.51	2818
1051.76	2790
1054.01	2826
1056.26	2874
1058.51	2910
1060.75	2862
1063	2936
1065.25	2926
1067.49	2980
1069.73	2986
1071.98	3076
1074.22	3040
1076.46	3076
1078.7	3070
1080.94	3062
1083.18	3120
1085.42	3148
1087.66	3128
1089.9	3160
1092.14	3218
1094.37	3258
1096.61	3220
1098.84	3214
1101.08	3268
1103.31	3414
1105.54	3290
1107.77	3362
1110	3352
1112.23	3466
1114.46	3402
1116.69	3404
1118.92	3382
1121.15	3484
1123.37	3486
1125.6	3566
1127.83	3586
1130.05	3594
1132.27	3588
1134.5	3580
1136.72	3624
1138.94	3680
1141.16	3650
1143.38	3630
1145.6	3630
1147.82	3708
1150.04	3646
1152.26	3716
1154.47	3750
1156.69	3774
1158.9	3732
1161.12	3692
1163.33	3722
1165.54	3804
1167.76	3858
1169.97	3774
1172.18	3758
1174.39	3844
1176.6	3840
1178.81	3832
1181.02	3796
1183.22	3720
1185.43	3782
1187.63	3858
1189.84	3764
1192.04	3776
1194.25	3746
1196.45	3730
1198.65	3738
1200.85	3730
1203.05	3686
1205.25	3674
1207.45	3678
1209.65	3702
1211.85	3684
1214.05	3672
1216.24	3672
1218.44	3622
1220.64	3652
1222.83	3594
1225.02	3562
1227.22	3588
1229.41	3510
1231.6	3540
1233.79	3438
1235.98	3454
1238.17	3472
1240.36	3500
1242.55	3458
1244.73	3504
1246.92	3390
1249.11	3354
1251.29	3340
1253.48	3334
1255.66	3302
1257.84	3284
1260.03	3248
1262.21	3346
1264.39	3196
1266.57	3282
1268.75	3214
1270.93	3210
1273.11	3160
1275.28	3122
1277.46	3076
1279.64	3092
1281.81	3118
1283.98	3089.81
1286.16	3000.26
1288.33	2947.6
1290.5	2965.55
1292.68	2923.33
1294.85	2926.09
1297.02	2902.03
1299.19	2835.8
1301.36	2796.28
1303.53	2749.65
1305.69	2748.62
1307.86	2661.24
1310.03	2712.7
1312.19	2588.37
1314.36	2614.71
1316.52	2585.76
1318.68	2487.49
1320.85	2492.28
1323.01	2453.51
1325.17	2462.94
1327.33	2438.46
1329.49	2431.27
1331.65	2404.35
1333.81	2355.1
1335.97	2288.35
1338.12	2304.51
1340.28	2249.05
1342.44	2230.57
1344.59	2200.13
1346.75	2174.38
1348.9	2156.3
1351.05	2106.83
1353.2	2125.52
1355.36	2056.11
1357.51	2061.83
1359.66	2002.62
1361.81	1986.5
1363.96	1958.27
1366.1	1982.89
1368.25	1921.26
1370.4	1885.21
1372.54	1903.59
1374.69	1893.33
1376.83	1828.69
1378.98	1837.88
1381.12	1800.44
1383.26	1798.26
1385.41	1771.64
1387.55	1776.15
1389.69	1743.03
1391.83	1719.42
1393.02	1728
1395.17	1660
1397.32	1674
1399.47	1700
1401.62	1588
1403.77	1672
1405.91	1580
1408.06	1642
1410.2	1592
1412.35	1560
1414.49	1574
1416.63	1524
1418.78	1524
1420.92	1600
1423.06	1514
1425.2	1518
1427.34	1488
1429.48	1436
1431.61	1502
1433.75	1480
1435.89	1474
1438.02	1480
1440.16	1448
1442.3	1454
1444.43	1446
1446.56	1446
1448.7	1426
1450.83	1426
1452.96	1382
1455.09	1360
1457.22	1396
1459.35	1404
1461.48	1378
1463.61	1374
1465.73	1340
1467.86	1284
1469.98	1360
1472.11	1306
1474.24	1270
1476.36	1332
1478.48	1326
1480.6	1360
1482.73	1270
1484.85	1268
1486.97	1266
1489.09	1264
1491.21	1260
1493.33	1224
1495.44	1250
1497.56	1238
1499.68	1230
1501.79	1214
1503.91	1202
1506.02	1166
1508.14	1222
1510.25	1222
1512.36	1192
1514.48	1214
1516.59	1178
1518.7	1156
1520.81	1172
1522.92	1150
1525.02	1114
1527.13	1148
1529.24	1126
1531.35	1122
1533.45	1152
1535.56	1116
1537.66	1086
1539.77	1106
1541.87	1078
1543.97	1044
1546.08	1088
1548.18	1086
1550.28	1050
1552.38	1086
1554.48	1056
1556.57	1052
1558.67	1068
1560.77	1030
1562.87	1052
1564.96	1052
1567.06	1046
1569.15	986
1571.25	986
1573.34	1040
1575.43	1030
1577.53	996
1579.62	1022
1581.71	1014
1583.8	1004
1585.89	1018
1587.98	982
1590.06	1034
1592.15	1008
1594.24	964
1596.33	994
1598.41	1016
1600.5	980
1602.58	1000
1604.66	948
1606.75	1002
1608.83	968
1610.91	990
1612.99	970
1615.07	934
1617.15	968
1619.23	942
1621.31	928
1623.39	942
1625.46	960
1627.54	938
1629.62	920
1631.69	950
1633.77	926
1635.84	902
1637.91	904
1639.99	866
1642.06	918
1644.13	920
1646.2	944
1648.27	934
1650.34	882
1652.41	922
1654.47	906
1656.54	878
1658.61	890
1660.67	906
1662.74	922
1664.81	870
1666.87	866
1668.93	886
1671	854
1673.06	858
1675.12	890
1677.18	838
1679.24	858
1681.3	862
1683.36	884
1685.42	860
1687.47	834
1689.53	876
1691.59	886
1693.64	850
1695.7	858
1697.75	822
1699.81	836
1701.86	838
1703.91	828
1705.97	808
1708.02	794
1710.07	840
1712.12	848
1714.17	806
1716.22	818
1718.26	818
1720.31	816
1722.36	784
1724.4	780
1726.45	834
1728.49	810
1730.54	834
1732.58	808
1734.63	796
1736.67	810
1738.71	826
1740.75	772
1742.79	768
1744.83	806
1746.87	796
1748.91	804
1750.95	770
1752.98	806
1755.02	796
1757.06	802
1759.09	820
1761.13	822
1763.16	782
1765.19	814
1767.23	810
1769.26	798
1771.29	762
1773.32	800
1775.35	820
1777.38	814
1779.41	786
1781.44	788
1783.47	776
1785.49	806
1787.52	826
1789.55	802
1791.57	784
1793.6	794
1795.62	790
1797.64	766
1799.67	806
1801.69	784
1803.71	768
1805.73	790
1807.75	774
1809.77	790
1811.79	748
1813.81	808
1815.83	782
1817.84	772
1819.86	782
1821.88	736
1823.89	770
1825.91	762
1827.92	770
1829.93	750
1831.95	746
1833.96	758
1835.97	768
1837.98	778
1839.99	762
1842	756
1844.01	778
1846.02	760
1848.03	776
1850.03	754
1852.04	760
1854.05	760
1856.05	786
1858.06	758
1860.06	774
1862.06	740
1864.07	762
1866.07	782
1868.07	732
1870.07	788
1872.07	752
1874.07	766
1876.07	754
1878.07	762
1880.07	744
1882.07	770
1884.06	716
1886.06	754
1888.05	764
1890.05	748
1892.04	782
1894.04	704
1896.03	752
1898.02	748
1900.01	756
1902	744
1903.99	770
1905.98	748
1907.97	728
1909.96	724
1911.95	744
1913.94	744
1915.93	750
1917.91	724
1919.9	750
1921.88	738
1923.87	752
1925.85	736
1927.83	756
1929.82	748
1931.8	732
1933.78	726
1935.76	706
1937.74	742
1939.72	744
1941.7	746
1943.68	740
1945.65	704
1947.63	740
1949.61	732
1951.58	748
1953.56	768
1955.53	720
1957.51	772
1959.48	722
1961.45	736
1963.43	740
1965.4	708
1967.37	724
1969.34	732
1971.31	714
1973.28	722
1975.25	742
1977.22	724
1979.18	712
1981.15	718
1983.12	724
1985.08	716
1987.05	742
1989.01	694
1990.97	754
1992.94	722
1994.9	746
1996.86	744
1998.82	692
2000.78	734
2002.74	736
2004.7	722
2006.66	704
2008.62	754
2010.58	714
2012.54	724
2014.49	720
2016.45	706
2018.4	708
2020.36	734
2022.31	710
2024.27	714
2026.22	714
2028.17	712
2030.12	722
2032.07	710
2034.03	694
2035.98	742
2037.93	704
2039.87	694
2041.82	716
2043.77	712
2045.72	716
2047.66	688
2049.61	718
2051.55	718
2053.5	706
2055.44	734
2057.39	714
2059.33	716
2061.27	698
2063.21	678
2065.15	698
2067.09	712
2069.03	730
2070.97	692
2072.91	696
2074.85	714
2076.79	708
2078.73	700
2080.66	714
2082.6	706
2084.53	726
2086.47	680
2088.4	736
2090.33	698
2092.27	700
2094.2	694
2096.13	684
2098.06	684
2099.99	690
2101.92	704
2103.85	708
2105.78	716
2107.71	684
2109.64	728
2111.56	690
2113.49	728
2115.41	708
2117.34	696
2119.26	700
2121.19	722
2123.11	700
2125.03	712
2126.96	708
2128.88	706
2130.8	692
2132.72	702
2134.64	712
2136.56	716
2138.48	708
2140.4	716
2142.31	698
2144.23	696
2146.15	718
2148.06	708
2149.98	718
2151.89	700
2153.81	666
2155.72	690
2157.63	724
2159.55	686
2161.46	658
2163.37	716
2165.28	704
2167.19	670
2169.1	696
2171.01	694
2172.91	686
2174.82	710
2176.73	656
2178.64	698
2180.54	716
2182.45	710
2184.35	688
2186.26	700
2188.16	674
2190.06	672
2191.96	678
2193.87	674
2195.77	658
2197.67	648
2199.57	696
2201.47	666
2203.37	690
2205.27	664
2207.16	688
2209.06	688
2210.96	696
2212.85	698
2214.75	660
2216.64	680
2218.54	672
2220.43	698
2222.33	668
2224.22	666.089
2226.11	675.08
2228	665.089
2229.89	638.949
2231.78	683.537
2233.67	693.865
2235.56	672.91
2237.45	691.559
2239.34	685.859
2241.23	674.987
2243.11	658.129
2245	663.258
2246.89	658.58
2248.77	671.573
2250.66	667.134
2252.54	674.49
2254.42	697.089
2256.31	665.607
2258.19	669.363
2260.07	661.851
2261.95	667.439
2263.83	661.3
2265.71	681.379
2267.59	671.14
2269.47	682.429
2271.35	672.495
2273.23	680.673
2275.1	666.205
2276.98	653.818
2278.86	634.54
2280.73	639.995
2282.61	653.487
2284.48	656.938
2286.36	665.945
2288.23	658.199
2290.1	659.633
2291.98	651.394
2293.85	642.346
2295.72	631.046
2297.59	664.608
2299.46	660.568
2301.33	657.338
2303.2	653.892
2305.06	633
2306.93	641.732
2308.8	640.44
2310.67	653.862
2312.53	637.08
2314.4	643.502
2316.26	657.873
2317.62	622
2319.5	630
2321.37	656
2323.24	664
2325.12	634
2326.99	642
2328.86	658
2330.73	624
2332.6	686
2334.47	628
2336.34	642
2338.2	650
2340.07	622
2341.94	594
2343.81	644
2345.67	632
2347.54	636
2349.4	626
2351.27	634
2353.13	600
2354.99	644
2356.86	606
2358.72	622
2360.58	632
2362.44	608
2364.3	624
2366.16	598
2368.02	640
2369.88	606
2371.74	606
2373.6	602
2375.45	614
2377.31	614
2379.17	574
2381.02	630
2382.88	594
2384.73	586
2386.58	580
2388.44	592
2390.29	600
2392.14	574
2393.99	582
2395.85	580
2397.7	576
2399.55	592
2401.4	588
2403.25	600
2405.09	598
2406.94	618
2408.79	592
2410.63	572
2412.48	544
2414.33	558
2416.17	550
2418.02	568
2419.86	568
2421.7	556
2423.55	570
2425.39	578
2427.23	550
2429.07	576
2430.91	560
2432.75	546
2434.59	566
2436.43	590
2438.27	558
2440.11	552
2441.95	564
2443.78	560
2445.62	556
2447.46	546
2449.29	556
2451.13	516
2452.96	544
2454.79	538
2456.63	520
2458.46	512
2460.29	512
2462.12	540
2463.95	542
2465.78	508
2467.61	506
2469.44	528
2471.27	512
2473.1	512
2474.93	496
2476.76	512
2478.58	520
2480.41	504
2482.23	496
2484.06	500
2485.88	538
2487.71	482
2489.53	480
2491.35	516
2493.18	498
2495	518
2496.82	518
2498.64	492
2500.46	484
2502.28	482
2504.1	470
2505.92	488
2507.74	470
2509.55	472
2511.37	454
2513.19	460
2515	492
2516.82	456
2518.63	454
2520.45	470
2522.26	448
2524.07	454
2525.89	458
2527.7	452
2529.51	470
2531.32	436
2533.13	444
2534.94	446
2536.75	428
2538.56	436
2540.37	454
2542.18	456
2543.98	422
2545.79	430
2547.6	476
2549.4	436
2551.21	430
2553.01	430
2554.82	436
2556.62	462
2558.42	428
2560.23	418
2562.03	424
2563.83	410
2565.63	420
2567.43	400
2569.23	426
2571.03	438
2572.83	414
2574.63	396
2576.43	382
2578.22	430
2580.02	388
2581.82	408
2583.61	402
2585.41	406
2587.2	424
2589	398
2590.79	392
2592.58	416
2594.38	370
2596.17	404
2597.96	376
2599.75	378
2601.54	394
2603.33	404
2605.12	368
2606.91	372
2608.7	382
2610.49	394
2612.27	394
2614.06	370
2615.85	374
2617.63	392
2619.42	370
2621.2	380
2622.99	340
2624.77	356
2626.55	364
2628.34	394
2630.12	354
2631.9	362
2633.68	370
2635.46	350
2637.24	376
2639.02	342
2640.8	348
2642.58	356
2644.36	364
2646.14	352
2647.91	358
2649.69	368
2651.46	346
2653.24	346
2655.01	342
2656.79	356
2658.56	334
2660.34	344
2662.11	338
2663.88	338
2665.65	334
2667.42	310
2669.2	326
2670.96	330
2672.73	312
2674.5	342
2676.27	324
2678.04	336
2679.81	314
2681.58	340
2683.34	334
2685.11	326
2686.87	322
2688.64	308
2690.4	304
2692.17	306
2693.93	312
2695.69	328
2697.46	308
2699.22	308
2700.98	320
2702.74	302
2704.5	302
2706.26	284
2708.02	290
2709.78	288
2711.54	316
2713.3	286
2715.05	292
2716.81	288
2718.57	302
2720.32	296
2722.08	300
2723.83	278
2725.59	312
2727.34	310
2729.09	274
2730.85	304
2732.6	282
2734.35	264
2736.1	280
2737.85	278
2739.6	272
2741.35	268
2743.1	282
2744.85	268
2746.6	266
2748.35	268
2750.09	254
2751.84	282
2753.59	272
2755.33	244
2757.08	254
2758.82	246
2760.57	242
2762.31	256
2764.05	246
2765.79	266
2767.54	260
2769.28	250
2771.02	238
2772.76	240
2774.5	250
2776.24	238
2777.98	250
2779.72	232
2781.46	276
2783.19	246
2784.93	246
2786.67	236
2788.4	222
2790.14	228
2791.87	248
2793.61	236
2795.34	230
2797.07	234
2798.81	230
2800.54	224
2802.27	236
2804	222
2805.74	228
2807.47	218
2809.2	230
2810.93	226
2812.65	232
2814.38	220
2816.11	212
2817.84	214
2819.56	230
2821.29	212
2823.02	204
2824.74	198
2826.47	200
2828.19	202
2829.92	212
2831.64	198
2833.36	204
2835.09	204
2836.81	210
2838.53	198
2840.25	210
2841.97	200
2843.69	202
2845.41	224
2847.13	188
2848.85	190
2850.57	180
2852.28	178
2854	210
2855.72	200
2857.43	194
2859.15	204
2860.86	192
2862.58	188
2864.29	178
2866.01	196
2867.72	192
2869.43	192
2871.14	190
2872.86	184
2874.57	174
2876.28	206
2877.99	190
2879.7	168
2881.41	182
2883.11	180
2884.82	186
2886.53	174
2888.24	188
2889.94	170
2891.65	170
2893.36	174
2895.06	178
2896.77	176
2898.47	172
2900.17	174
2901.88	164
2903.58	174
2905.28	156
2906.98	170
2908.69	162
2910.39	166
2912.09	182
2913.79	178
2915.49	178
2917.19	166
2918.88	182
2920.58	154
2922.28	162
2923.98	168
2925.67	156
2927.37	156
2929.06	154
2930.76	156
2932.45	150
2934.15	154
2935.84	144
2937.53	164
2939.23	146
2940.92	138
2942.61	156
2944.3	152
2945.99	144
2947.68	154
2949.37	148
2951.06	140
2952.75	160
2954.44	148
2956.12	142
2957.81	164
2959.5	158
2961.18	138
2962.87	144
2964.56	144
2966.24	150
2967.92	142
2969.61	134
2971.29	136
2972.97	144
2974.66	128
2976.34	156
2978.02	134
2979.7	142
2981.38	136
2983.06	140
2984.74	144
2986.42	142
2988.1	136
2989.78	142
2991.45	146
2993.13	148
2994.81	118
2996.48	136
2998.16	152
2999.83	136