File: muestras/suculenta_dedo/inside_pr_07.txt
#Acq. time (s)=	10
#Accumulations=	1
#Range (cm-¹)=	200...3000
#Windows=	3
#Autofocus=	Off
#AutoExposure=	Off
#Spike filter=	Off
#Delay time (s)=	0
#Binning=	1
#Readout mode=	Signal
#DeNoise=	Off
#ICS correction=	Off
#Dark correction=	Off
#Inst. Process=	Off
#Instrument=	LabRAM HR Evol
#Detector=	Syncerity OE
#Objective=	x100_VIS
#Grating=	600 (500nm)
#ND Filter=	1%
#Laser=	633nm_Edge
#Hole=	30.0125
#Range=	Visible
#Project=	Omar
#Sample=	03-07-23
#Site=	fings
#Title=	inside_pr
#Remark=
#Date=	03.07.2023 15:04
#Acquired=	03.07.2023 15:04:50
201.713	70
204.247	78
206.778	76
209.311	62
211.84	72
214.371	58
216.899	70
219.428	98
221.955	76
224.482	70
227.007	70
229.531	72
232.055	72
234.579	76
237.1	72
239.621	78
242.141	76
244.661	86
247.179	90
249.698	88
252.215	84
254.731	80
257.246	96
259.761	84
262.273	88
264.786	94
267.298	88
269.809	98
272.319	96
274.828	100
277.336	96
279.844	94
282.351	100
284.855	94
287.361	90
289.866	98
292.368	100
294.871	94
297.372	104
299.873	108
302.372	110
304.872	110
307.37	108
309.866	98
312.364	100
314.859	102
317.353	118
319.848	116
322.341	108
324.833	118
327.324	116
329.814	118
332.304	114
334.792	112
337.28	132
339.767	134
342.254	138
344.739	126
347.224	134
349.708	136
352.191	118
354.673	136
357.155	118
359.634	136
362.114	142
364.593	146
367.07	138
369.548	132
372.024	144
374.499	144
376.974	148
379.447	160
381.92	144
384.392	158
386.864	142
389.333	140
391.802	180
394.272	166
396.739	174
399.206	162
401.673	162
404.138	164
406.602	172
409.066	174
411.528	164
413.99	162
416.451	176
418.911	184
421.371	178
423.83	188
426.288	184
428.745	186
431.201	196
433.657	202
436.111	202
438.565	190
441.017	192
443.469	204
445.921	166
448.37	186
450.821	202
453.27	192
455.717	210
458.165	196
460.61	216
463.056	188
465.5	220
467.945	234
470.387	220
472.829	214
475.271	216
477.711	240
480.15	234
482.589	242
485.027	228
487.465	238
489.901	242
492.337	258
494.771	240
497.205	254
499.638	248
502.07	270
504.502	268
506.933	242
509.363	248
511.792	284
514.219	274
516.647	278
519.073	282
521.5	266
523.924	264
526.348	274
528.772	290
531.194	288
533.616	274
536.036	270
538.457	304
540.875	294
543.294	292
545.712	304
548.128	300
550.545	290
552.959	306
555.373	302
557.788	308
560.2	302
562.612	314
565.023	326
567.433	314
569.843	340
572.251	326
574.659	318
577.066	348
579.472	344
581.878	334
584.283	342
586.687	348
589.09	356
591.493	368
593.893	348
596.294	348
598.694	382
601.093	388
603.491	400
605.889	394
608.285	388
610.682	392
613.076	402
615.471	390
617.864	418
620.256	428
622.648	384
625.039	442
627.429	406
629.819	436
632.208	410
634.595	452
636.982	444
639.369	448
641.755	466
644.139	460
646.523	464
648.906	486
651.288	474
653.67	486
656.051	508
658.429	498
660.808	494
663.187	536
665.565	480
667.942	520
670.317	520
672.692	508
675.067	526
677.44	530
679.813	530
682.184	566
684.556	558
686.926	572
689.296	590
691.664	596
694.033	600
696.4	558
698.766	590
701.133	612
703.497	600
705.861	654
708.224	642
710.586	658
712.949	666
715.31	662
717.67	678
720.029	672
722.388	680
724.746	738
727.103	680
729.458	740
731.814	732
734.168	698
736.523	710
738.876	750
741.227	726
743.579	726
745.931	748
748.28	774
750.629	780
752.977	808
755.325	800
757.672	816
760.018	848
762.363	824
764.708	840
767.052	856
769.394	858
771.737	874
774.078	900
776.419	880
778.758	894
781.097	908
783.435	928
785.773	922
788.11	940
790.446	944
792.781	948
795.115	972
797.449	1030
799.782	998
802.115	1008
804.446	1024
806.777	1006
809.106	1048
811.435	1064
813.764	1116
816.091	1084
818.418	1088
820.743	1136
823.069	1132
825.393	1168
827.717	1140
830.039	1182
832.362	1132
834.683	1228
837.003	1218
839.324	1262
841.643	1256
843.961	1304
846.278	1316
848.594	1296
850.91	1292
853.227	1378
855.541	1404
857.855	1386
860.168	1416
862.48	1362
864.79	1458
867.101	1460
869.411	1442
871.721	1504
874.029	1494
876.336	1540
878.643	1504
880.95	1536
883.254	1580
885.559	1596
887.862	1612
890.166	1638
892.467	1650
894.77	1608
897.07	1702
899.371	1640
901.669	1684
903.968	1726
906.266	1744
908.563	1720
910.859	1762
913.154	1802
915.449	1796
917.742	1790
920.036	1848
922.329	1898
924.621	1934
926.911	1910
929.201	1888
931.49	1942
933.779	1960
936.068	2016
938.355	1998
940.64	2018
942.926	2086
945.212	2152
947.495	2154
949.779	2134
952.062	2168
954.344	2194
956.625	2190
958.905	2240
961.184	2274
963.464	2230
965.742	2258
968.02	2308
970.296	2384
972.572	2446
974.847	2454
977.121	2462
979.396	2506
981.669	2524
983.941	2528
986.212	2538
988.483	2528
990.753	2602
993.022	2626
995.29	2672
997.558	2710
999.825	2742
1002.09	2716
1004.36	2734
1006.62	2724
1008.89	2858
1011.15	2814
1013.41	2820
1015.67	2924
1017.93	2956
1020.19	2964
1022.45	2978
1024.71	3034
1026.97	3104
1029.23	3080
1031.49	3068
1033.74	3110
1036	3162
1038.25	3240
1040.5	3266
1042.76	3358
1045.01	3248
1047.26	3382
1049.51	3418
1051.76	3470
1054.01	3462
1056.26	3554
1058.51	3560
1060.75	3574
1063	3634
1065.25	3600
1067.49	3606
1069.73	3742
1071.98	3658
1074.22	3770
1076.46	3774
1078.7	3840
1080.94	3832
1083.18	3848
1085.42	3892
1087.66	3872
1089.9	3888
1092.14	4032
1094.37	4042
1096.61	3954
1098.84	4076
1101.08	4098
1103.31	4046
1105.54	4054
1107.77	4074
1110	4124
1112.23	4148
1114.46	4164
1116.69	4194
1118.92	4248
1121.15	4202
1123.37	4324
1125.6	4326
1127.83	4282
1130.05	4424
1132.27	4370
1134.5	4508
1136.72	4498
1138.94	4412
1141.16	4474
1143.38	4456
1145.6	4558
1147.82	4580
1150.04	4580
1152.26	4616
1154.47	4600
1156.69	4602
1158.9	4630
1161.12	4662
1163.33	4712
1165.54	4670
1167.76	4722
1169.97	4688
1172.18	4740
1174.39	4750
1176.6	4738
1178.81	4708
1181.02	4664
1183.22	4766
1185.43	4684
1187.63	4670
1189.84	4644
1192.04	4658
1194.25	4656
1196.45	4668
1198.65	4636
1200.85	4556
1203.05	4546
1205.25	4574
1207.45	4546
1209.65	4554
1211.85	4504
1214.05	4524
1216.24	4488
1218.44	4432
1220.64	4410
1222.83	4364
1225.02	4442
1227.22	4422
1229.41	4276
1231.6	4366
1233.79	4346
1235.98	4324
1238.17	4256
1240.36	4326
1242.55	4308
1244.73	4254
1246.92	4242
1249.11	4212
1251.29	4150
1253.48	4050
1255.66	4090
1257.84	4050
1260.03	4054
1262.21	4018
1264.39	3936
1266.57	3980
1268.75	3966
1270.93	3920
1273.11	3908
1275.28	3942
1277.46	3818
1279.64	3760
1281.81	3786
1283.98	3814.94
1286.16	3749.99
1288.33	3673.36
1290.5	3672.39
1292.68	3617.66
1294.85	3525.06
1297.02	3543.23
1299.19	3495.25
1301.36	3418.91
1303.53	3428.44
1305.69	3323.86
1307.86	3325.13
1310.03	3246.67
1312.19	3199.65
1314.36	3223.79
1316.52	3134.26
1318.68	3069.38
1320.85	3019.08
1323.01	3053.05
1325.17	3055.8
1327.33	2958.38
1329.49	2948.62
1331.65	2929.98
1333.81	2835.07
1335.97	2822.35
1338.12	2789.54
1340.28	2737.6
1342.44	2738.2
1344.59	2689.96
1346.75	2663.76
1348.9	2614.21
1351.05	2547.5
1353.2	2570.62
1355.36	2560.15
1357.51	2518.95
1359.66	2433.1
1361.81	2443.69
1363.96	2375.28
1366.1	2364.48
1368.25	2294.65
1370.4	2340.45
1372.54	2291.42
1374.69	2266.3
1376.83	2239.53
1378.98	2219.69
1381.12	2206.36
1383.26	2158.43
1385.41	2120.5
1387.55	2097.13
1389.69	2062.57
1391.83	2030.38
1393.02	2028
1395.17	2024
1397.32	2020
1399.47	2006
1401.62	2004
1403.77	1962
1405.91	1950
1408.06	1938
1410.2	1912
1412.35	1886
1414.49	1874
1416.63	1898
1418.78	1886
1420.92	1844
1423.06	1872
1425.2	1806
1427.34	1834
1429.48	1764
1431.61	1782
1433.75	1740
1435.89	1718
1438.02	1772
1440.16	1724
1442.3	1740
1444.43	1688
1446.56	1694
1448.7	1728
1450.83	1676
1452.96	1696
1455.09	1702
1457.22	1688
1459.35	1610
1461.48	1614
1463.61	1634
1465.73	1610
1467.86	1618
1469.98	1602
1472.11	1618
1474.24	1586
1476.36	1624
1478.48	1520
1480.6	1516
1482.73	1544
1484.85	1560
1486.97	1552
1489.09	1502
1491.21	1516
1493.33	1476
1495.44	1472
1497.56	1462
1499.68	1464
1501.79	1424
1503.91	1478
1506.02	1444
1508.14	1412
1510.25	1454
1512.36	1418
1514.48	1372
1516.59	1370
1518.7	1398
1520.81	1364
1522.92	1354
1525.02	1390
1527.13	1392
1529.24	1360
1531.35	1364
1533.45	1332
1535.56	1284
1537.66	1338
1539.77	1306
1541.87	1306
1543.97	1274
1546.08	1278
1548.18	1298
1550.28	1314
1552.38	1274
1554.48	1284
1556.57	1266
1558.67	1224
1560.77	1262
1562.87	1246
1564.96	1258
1567.06	1210
1569.15	1208
1571.25	1190
1573.34	1202
1575.43	1184
1577.53	1198
1579.62	1170
1581.71	1164
1583.8	1202
1585.89	1140
1587.98	1200
1590.06	1180
1592.15	1170
1594.24	1220
1596.33	1152
1598.41	1176
1600.5	1144
1602.58	1208
1604.66	1158
1606.75	1168
1608.83	1172
1610.91	1138
1612.99	1134
1615.07	1122
1617.15	1114
1619.23	1104
1621.31	1026
1623.39	1136
1625.46	1126
1627.54	1090
1629.62	1082
1631.69	1126
1633.77	1108
1635.84	1104
1637.91	1072
1639.99	1094
1642.06	1082
1644.13	1098
1646.2	1108
1648.27	1066
1650.34	1072
1652.41	1074
1654.47	1068
1656.54	1040
1658.61	1028
1660.67	1054
1662.74	1050
1664.81	1014
1666.87	1072
1668.93	1050
1671	1018
1673.06	992
1675.12	1044
1677.18	1018
1679.24	1016
1681.3	978
1683.36	994
1685.42	1004
1687.47	1004
1689.53	974
1691.59	992
1693.64	998
1695.7	996
1697.75	978
1699.81	984
1701.86	992
1703.91	1016
1705.97	980
1708.02	930
1710.07	962
1712.12	950
1714.17	984
1716.22	942
1718.26	942
1720.31	894
1722.36	974
1724.4	976
1726.45	916
1728.49	944
1730.54	948
1732.58	914
1734.63	902
1736.67	948
1738.71	932
1740.75	908
1742.79	922
1744.83	910
1746.87	968
1748.91	928
1750.95	934
1752.98	916
1755.02	910
1757.06	904
1759.09	936
1761.13	914
1763.16	902
1765.19	930
1767.23	968
1769.26	946
1771.29	914
1773.32	906
1775.35	896
1777.38	918
1779.41	954
1781.44	946
1783.47	922
1785.49	934
1787.52	948
1789.55	878
1791.57	926
1793.6	914
1795.62	884
1797.64	916
1799.67	928
1801.69	912
1803.71	902
1805.73	938
1807.75	938
1809.77	916
1811.79	896
1813.81	914
1815.83	912
1817.84	908
1819.86	906
1821.88	924
1823.89	920
1825.91	876
1827.92	858
1829.93	936
1831.95	872
1833.96	880
1835.97	902
1837.98	896
1839.99	888
1842	882
1844.01	886
1846.02	880
1848.03	886
1850.03	890
1852.04	890
1854.05	864
1856.05	878
1858.06	846
1860.06	886
1862.06	904
1864.07	904
1866.07	894
1868.07	866
1870.07	860
1872.07	866
1874.07	892
1876.07	882
1878.07	856
1880.07	842
1882.07	858
1884.06	868
1886.06	840
1888.05	880
1890.05	870
1892.04	898
1894.04	880
1896.03	904
1898.02	864
1900.01	878
1902	874
1903.99	870
1905.98	836
1907.97	902
1909.96	858
1911.95	878
1913.94	868
1915.93	846
1917.91	894
1919.9	900
1921.88	884
1923.87	870
1925.85	842
1927.83	880
1929.82	878
1931.8	858
1933.78	846
1935.76	866
1937.74	828
1939.72	862
1941.7	860
1943.68	844
1945.65	842
1947.63	900
1949.61	864
1951.58	880
1953.56	864
1955.53	840
1957.51	852
1959.48	828
1961.45	862
1963.43	876
1965.4	852
1967.37	872
1969.34	838
1971.31	858
1973.28	836
1975.25	854
1977.22	884
1979.18	842
1981.15	870
1983.12	862
1985.08	834
1987.05	834
1989.01	860
1990.97	868
1992.94	854
1994.9	832
1996.86	810
1998.82	836
2000.78	782
2002.74	872
2004.7	868
2006.66	866
2008.62	844
2010.58	834
2012.54	830
2014.49	844
2016.45	880
2018.4	846
2020.36	842
2022.31	818
2024.27	848
2026.22	800
2028.17	839
2030.12	848
2032.07	846
2034.03	846
2035.98	822
2037.93	812
2039.87	834
2041.82	794
2043.77	870
2045.72	844
2047.66	810
2049.61	802
2051.55	854
2053.5	838
2055.44	842
2057.39	840
2059.33	834
2061.27	806
2063.21	830
2065.15	808
2067.09	822
2069.03	812
2070.97	822
2072.91	820
2074.85	810
2076.79	878
2078.73	816
2080.66	846
2082.6	840
2084.53	838
2086.47	832
2088.4	832
2090.33	826
2092.27	806
2094.2	814
2096.13	814
2098.06	804
2099.99	824
2101.92	820
2103.85	810
2105.78	810
2107.71	828
2109.64	820
2111.56	836
2113.49	824
2115.41	824
2117.34	826
2119.26	804
2121.19	814
2123.11	850
2125.03	822
2126.96	808
2128.88	824
2130.8	842
2132.72	826
2134.64	824
2136.56	806
2138.48	818
2140.4	794
2142.31	826
2144.23	804
2146.15	834
2148.06	798
2149.98	830
2151.89	786
2153.81	794
2155.72	822
2157.63	828
2159.55	826
2161.46	824
2163.37	800
2165.28	770
2167.19	786
2169.1	772
2171.01	808
2172.91	814
2174.82	816
2176.73	818
2178.64	796
2180.54	800
2182.45	836
2184.35	754
2186.26	806
2188.16	802
2190.06	800
2191.96	794
2193.87	816
2195.77	782
2197.67	772
2199.57	794
2201.47	792
2203.37	794
2205.27	808
2207.16	798
2209.06	776
2210.96	810
2212.85	792
2214.75	754
2216.64	804
2218.54	808
2220.43	776
2222.33	798
2224.22	784.866
2226.11	785.924
2228	783.774
2229.89	789.157
2231.78	784.555
2233.67	804.56
2235.56	772.193
2237.45	784.837
2239.34	797.69
2241.23	750.348
2243.11	787.513
2245	765.054
2246.89	812.225
2248.77	774.374
2250.66	784.248
2252.54	771.819
2254.42	754.172
2256.31	772.309
2258.19	776.881
2260.07	756.894
2261.95	777.163
2263.83	776.06
2265.71	765.6
2267.59	774.674
2269.47	767.817
2271.35	762.511
2273.23	765.64
2275.1	738.191
2276.98	753.472
2278.86	733.91
2280.73	768.93
2282.61	740.981
2284.48	761.758
2286.36	741.79
2288.23	748.485
2290.1	748.49
2291.98	721.889
2293.85	737.299
2295.72	730.686
2297.59	732.776
2299.46	714.397
2301.33	742.382
2303.2	719.903
2305.06	705.333
2306.93	711.66
2308.8	729.186
2310.67	703.014
2312.53	726.1
2314.4	713.606
2316.26	697.549
2317.62	700
2319.5	700
2321.37	706
2323.24	730
2325.12	674
2326.99	726
2328.86	686
2330.73	714
2332.6	694
2334.47	692
2336.34	672
2338.2	678
2340.07	688
2341.94	704
2343.81	692
2345.67	700
2347.54	680
2349.4	650
2351.27	654
2353.13	692
2354.99	690
2356.86	658
2358.72	668
2360.58	686
2362.44	690
2364.3	688
2366.16	718
2368.02	682
2369.88	662
2371.74	676
2373.6	664
2375.45	662
2377.31	658
2379.17	676
2381.02	670
2382.88	646
2384.73	684
2386.58	644
2388.44	664
2390.29	640
2392.14	642
2393.99	664
2395.85	654
2397.7	646
2399.55	650
2401.4	652
2403.25	640
2405.09	640
2406.94	610
2408.79	640
2410.63	636
2412.48	618
2414.33	620
2416.17	656
2418.02	622
2419.86	602
2421.7	572
2423.55	618
2425.39	610
2427.23	610
2429.07	628
2430.91	606
2432.75	626
2434.59	580
2436.43	592
2438.27	602
2440.11	612
2441.95	596
2443.78	602
2445.62	574
2447.46	572
2449.29	612
2451.13	592
2452.96	588
2454.79	586
2456.63	570
2458.46	584
2460.29	602
2462.12	570
2463.95	568
2465.78	576
2467.61	550
2469.44	572
2471.27	594
2473.1	570
2474.93	544
2476.76	560
2478.58	550
2480.41	570
2482.23	550
2484.06	562
2485.88	574
2487.71	552
2489.53	532
2491.35	524
2493.18	534
2495	548
2496.82	504
2498.64	550
2500.46	530
2502.28	528
2504.1	544
2505.92	474
2507.74	534
2509.55	506
2511.37	530
2513.19	514
2515	538
2516.82	526
2518.63	510
2520.45	506
2522.26	510
2524.07	484
2525.89	478
2527.7	502
2529.51	504
2531.32	520
2533.13	514
2534.94	472
2536.75	488
2538.56	494
2540.37	454
2542.18	478
2543.98	512
2545.79	486
2547.6	476
2549.4	496
2551.21	496
2553.01	484
2554.82	444
2556.62	482
2558.42	486
2560.23	472
2562.03	474
2563.83	460
2565.63	466
2567.43	464
2569.23	456
2571.03	466
2572.83	444
2574.63	452
2576.43	450
2578.22	456
2580.02	446
2581.82	438
2583.61	432
2585.41	452
2587.2	470
2589	442
2590.79	452
2592.58	442
2594.38	430
2596.17	412
2597.96	448
2599.75	434
2601.54	440
2603.33	418
2605.12	432
2606.91	416
2608.7	412
2610.49	436
2612.27	416
2614.06	424
2615.85	408
2617.63	406
2619.42	400
2621.2	386
2622.99	442
2624.77	392
2626.55	392
2628.34	396
2630.12	396
2631.9	392
2633.68	368
2635.46	384
2637.24	366
2639.02	410
2640.8	394
2642.58	372
2644.36	384
2646.14	378
2647.91	382
2649.69	384
2651.46	380
2653.24	400
2655.01	362
2656.79	362
2658.56	358
2660.34	368
2662.11	360
2663.88	364
2665.65	366
2667.42	354
2669.2	378
2670.96	370
2672.73	344
2674.5	362
2676.27	352
2678.04	360
2679.81	368
2681.58	374
2683.34	370
2685.11	338
2686.87	348
2688.64	350
2690.4	344
2692.17	334
2693.93	312
2695.69	350
2697.46	334
2699.22	342
2700.98	318
2702.74	324
2704.5	330
2706.26	350
2708.02	322
2709.78	328
2711.54	324
2713.3	364
2715.05	330
2716.81	334
2718.57	338
2720.32	324
2722.08	342
2723.83	320
2725.59	306
2727.34	314
2729.09	308
2730.85	294
2732.6	298
2734.35	290
2736.1	320
2737.85	308
2739.6	298
2741.35	296
2743.1	302
2744.85	306
2746.6	296
2748.35	266
2750.09	296
2751.84	292
2753.59	280
2755.33	282
2757.08	300
2758.82	286
2760.57	282
2762.31	274
2764.05	272
2765.79	282
2767.54	276
2769.28	282
2771.02	282
2772.76	266
2774.5	272
2776.24	260
2777.98	262
2779.72	276
2781.46	260
2783.19	252
2784.93	262
2786.67	256
2788.4	278
2790.14	248
2791.87	258
2793.61	246
2795.34	260
2797.07	246
2798.81	250
2800.54	248
2802.27	250
2804	248
2805.74	258
2807.47	230
2809.2	250
2810.93	222
2812.65	244
2814.38	234
2816.11	242
2817.84	234
2819.56	230
2821.29	240
2823.02	234
2824.74	244
2826.47	218
2828.19	226
2829.92	228
2831.64	226
2833.36	220
2835.09	232
2836.81	230
2838.53	224
2840.25	202
2841.97	224
2843.69	216
2845.41	222
2847.13	204
2848.85	232
2850.57	210
2852.28	214
2854	212
2855.72	232
2857.43	210
2859.15	212
2860.86	214
2862.58	222
2864.29	204
2866.01	210
2867.72	202
2869.43	214
2871.14	204
2872.86	198
2874.57	192
2876.28	198
2877.99	196
2879.7	192
2881.41	192
2883.11	182
2884.82	196
2886.53	178
2888.24	194
2889.94	184
2891.65	186
2893.36	206
2895.06	178
2896.77	200
2898.47	192
2900.17	180
2901.88	192
2903.58	194
2905.28	182
2906.98	184
2908.69	168
2910.39	196
2912.09	172
2913.79	192
2915.49	188
2917.19	178
2918.88	170
2920.58	180
2922.28	194
2923.98	170
2925.67	168
2927.37	176
2929.06	178
2930.76	170
2932.45	156
2934.15	168
2935.84	176
2937.53	148
2939.23	154
2940.92	174
2942.61	168
2944.3	164
2945.99	174
2947.68	156
2949.37	166
2951.06	184
2952.75	156
2954.44	156
2956.12	170
2957.81	166
2959.5	176
2961.18	162
2962.87	170
2964.56	178
2966.24	156
2967.92	162
2969.61	170
2971.29	140
2972.97	152
2974.66	156
2976.34	142
2978.02	152
2979.7	140
2981.38	166
2983.06	154
2984.74	160
2986.42	146
2988.1	140
2989.78	148
2991.45	134
2993.13	154
2994.81	138
2996.48	152
2998.16	146
2999.83	130