File: muestras/suculenta_dedo/inside_pr_05.txt
#Acq. time (s)=	10
#Accumulations=	1
#Range (cm-¹)=	200...3000
#Windows=	3
#Autofocus=	Off
#AutoExposure=	Off
#Spike filter=	Off
#Delay time (s)=	0
#Binning=	1
#Readout mode=	Signal
#DeNoise=	Off
#ICS correction=	Off
#Dark correction=	Off
#Inst. Process=	Off
#Instrument=	LabRAM HR Evol
#Detector=	Syncerity OE
#Objective=	x100_VIS
#Grating=	600 (500nm)
#ND Filter=	1%
#Laser=	633nm_Edge
#Hole=	30.0125
#Range=	Visible
#Project=	Omar
#Sample=	03-07-23
#Site=	fings
#Title=	inside_pr
#Remark=
#Date=	03.07.2023 15:01
#Acquired=	03.07.2023 15:01:31
201.713	82
204.247	78
206.778	74
209.311	76
211.84	76
214.371	64
216.899	76
219.428	72
221.955	76
224.482	78
227.007	72
229.531	76
232.055	66
234.579	74
237.1	80
239.621	74
242.141	82
244.661	82
247.179	74
249.698	70
252.215	78
254.731	78
257.246	78
259.761	72
262.273	78
264.786	88
267.298	88
269.809	82
272.319	74
274.828	92
277.336	84
279.844	84
282.351	96
284.855	92
287.361	94
289.866	94
292.368	100
294.871	90
297.372	98
299.873	92
302.372	88
304.872	94
307.37	96
309.866	88
312.364	90
314.859	88
317.353	100
319.848	106
322.341	102
324.833	96
327.324	98
329.814	96
332.304	96
334.792	96
337.28	100
339.767	100
342.254	110
344.739	106
347.224	116
349.708	104
352.191	114
354.673	116
357.155	114
359.634	110
362.114	118
364.593	126
367.07	128
369.548	130
372.024	134
374.499	130
376.974	120
379.447	124
381.92	122
384.392	98
386.864	126
389.333	132
391.802	134
394.272	120
396.739	140
399.206	136
401.673	130
404.138	156
406.602	148
409.066	152
411.528	148
413.99	144
416.451	162
418.911	142
421.371	146
423.83	156
426.288	174
428.745	142
431.201	152
433.657	160
436.111	154
438.565	172
441.017	164
443.469	154
445.921	168
448.37	188
450.821	176
453.27	170
455.717	162
458.165	172
460.61	182
463.056	188
465.5	186
467.945	210
470.387	172
472.829	184
475.271	166
477.711	168
480.15	190
482.589	204
485.027	196
487.465	176
489.901	224
492.337	198
494.771	212
497.205	204
499.638	204
502.07	218
504.502	202
506.933	202
509.363	218
511.792	202
514.219	216
516.647	222
519.073	232
521.5	222
523.924	224
526.348	232
528.772	236
531.194	230
533.616	234
536.036	236
538.457	234
540.875	240
543.294	242
545.712	242
548.128	246
550.545	230
552.959	260
555.373	260
557.788	246
560.2	252
562.612	264
565.023	262
567.433	258
569.843	270
572.251	272
574.659	284
577.066	286
579.472	300
581.878	288
584.283	280
586.687	282
589.09	292
591.493	300
593.893	300
596.294	294
598.694	314
601.093	314
603.491	312
605.889	302
608.285	300
610.682	310
613.076	324
615.471	336
617.864	324
620.256	330
622.648	342
625.039	338
627.429	336
629.819	360
632.208	352
634.595	366
636.982	376
639.369	354
641.755	382
644.139	388
646.523	394
648.906	362
651.288	362
653.67	400
656.051	374
658.429	400
660.808	404
663.187	402
665.565	446
667.942	418
670.317	410
672.692	432
675.067	418
677.44	424
679.813	414
682.184	454
684.556	422
686.926	468
689.296	454
691.664	466
694.033	436
696.4	444
698.766	464
701.133	476
703.497	476
705.861	486
708.224	504
710.586	496
712.949	498
715.31	502
717.67	520
720.029	528
722.388	530
724.746	534
727.103	538
729.458	534
731.814	566
734.168	582
736.523	566
738.876	600
741.227	638
743.579	568
745.931	606
748.28	612
750.629	606
752.977	610
755.325	624
757.672	602
760.018	642
762.363	646
764.708	660
767.052	652
769.394	646
771.737	680
774.078	636
776.419	680
778.758	694
781.097	674
783.435	708
785.773	698
788.11	740
790.446	736
792.781	764
795.115	756
797.449	770
799.782	758
802.115	760
804.446	778
806.777	792
809.106	808
811.435	850
813.764	840
816.091	874
818.418	830
820.743	860
823.069	868
825.393	910
827.717	882
830.039	910
832.362	926
834.683	934
837.003	946
839.324	948
841.643	994
843.961	978
846.278	992
848.594	1044
850.91	1016
853.227	1046
855.541	1044
857.855	1080
860.168	1036
862.48	1060
864.79	1108
867.101	1106
869.411	1144
871.721	1168
874.029	1144
876.336	1162
878.643	1158
880.95	1164
883.254	1164
885.559	1218
887.862	1188
890.166	1248
892.467	1244
894.77	1278
897.07	1274
899.371	1332
901.669	1318
903.968	1314
906.266	1354
908.563	1336
910.859	1344
913.154	1366
915.449	1366
917.742	1398
920.036	1414
922.329	1432
924.621	1430
926.911	1460
929.201	1436
931.49	1474
933.779	1502
936.068	1554
938.355	1508
940.64	1568
942.926	1578
945.212	1642
947.495	1600
949.779	1608
952.062	1602
954.344	1656
956.625	1714
958.905	1710
961.184	1722
963.464	1740
965.742	1792
968.02	1750
970.296	1842
972.572	1794
974.847	1778
977.121	1804
979.396	1860
981.669	1908
983.941	1982
986.212	1930
988.483	1950
990.753	1944
993.022	2054
995.29	2010
997.558	2060
999.825	2046
1002.09	2104
1004.36	2078
1006.62	2132
1008.89	2140
1011.15	2140
1013.41	2194
1015.67	2200
1017.93	2294
1020.19	2224
1022.45	2286
1024.71	2284
1026.97	2310
1029.23	2396
1031.49	2394
1033.74	2346
1036	2472
1038.25	2460
1040.5	2510
1042.76	2500
1045.01	2492
1047.26	2588
1049.51	2566
1051.76	2610
1054.01	2714
1056.26	2702
1058.51	2702
1060.75	2664
1063	2726
1065.25	2788
1067.49	2758
1069.73	2742
1071.98	2782
1074.22	2880
1076.46	2884
1078.7	2882
1080.94	2914
1083.18	2896
1085.42	2954
1087.66	2900
1089.9	3010
1092.14	2964
1094.37	3030
1096.61	3054
1098.84	3060
1101.08	3150
1103.31	3042
1105.54	3096
1107.77	3142
1110	3140
1112.23	3178
1114.46	3186
1116.69	3204
1118.92	3246
1121.15	3232
1123.37	3298
1125.6	3308
1127.83	3356
1130.05	3374
1132.27	3330
1134.5	3328
1136.72	3342
1138.94	3432
1141.16	3478
1143.38	3394
1145.6	3450
1147.82	3462
1150.04	3488
1152.26	3614
1154.47	3516
1156.69	3512
1158.9	3646
1161.12	3600
1163.33	3602
1165.54	3624
1167.76	3604
1169.97	3544
1172.18	3544
1174.39	3582
1176.6	3666
1178.81	3636
1181.02	3556
1183.22	3586
1185.43	3624
1187.63	3562
1189.84	3608
1192.04	3540
1194.25	3554
1196.45	3546
1198.65	3546
1200.85	3590
1203.05	3536
1205.25	3534
1207.45	3532
1209.65	3542
1211.85	3520
1214.05	3536
1216.24	3478
1218.44	3448
1220.64	3408
1222.83	3406
1225.02	3406
1227.22	3334
1229.41	3322
1231.6	3374
1233.79	3374
1235.98	3418
1238.17	3338
1240.36	3326
1242.55	3290
1244.73	3222
1246.92	3370
1249.11	3160
1251.29	3138
1253.48	3254
1255.66	3154
1257.84	3192
1260.03	3116
1262.21	3080
1264.39	3114
1266.57	3154
1268.75	3048
1270.93	3074
1273.11	3090
1275.28	3062
1277.46	3004
1279.64	3050
1281.81	3050
1283.98	2873.18
1286.16	2881.31
1288.33	2928.46
1290.5	2925.06
1292.68	2876.65
1294.85	2902.65
1297.02	2860.93
1299.19	2809.92
1301.36	2825.88
1303.53	2778.15
1305.69	2777.67
1307.86	2711.14
1310.03	2693.02
1312.19	2663.82
1314.36	2679.15
1316.52	2648.85
1318.68	2621.99
1320.85	2629.93
1323.01	2506.57
1325.17	2585.96
1327.33	2558.65
1329.49	2532.06
1331.65	2503.62
1333.81	2467.74
1335.97	2448.52
1338.12	2415.55
1340.28	2389.72
1342.44	2410.36
1344.59	2394.17
1346.75	2302.28
1348.9	2346.19
1351.05	2319.77
1353.2	2290.35
1355.36	2299.12
1357.51	2300.89
1359.66	2230.15
1361.81	2251.97
1363.96	2219.23
1366.1	2173.93
1368.25	2157.79
1370.4	2116.65
1372.54	2195.93
1374.69	2110.71
1376.83	2149.91
1378.98	2065.65
1381.12	2088.45
1383.26	2039.3
1385.41	2073.74
1387.55	1988.97
1389.69	1994.93
1391.83	1976.37
1393.02	1934
1395.17	1950
1397.32	1918
1399.47	1900
1401.62	1888
1403.77	1902
1405.91	1878
1408.06	1848
1410.2	1846
1412.35	1830
1414.49	1812
1416.63	1804
1418.78	1858
1420.92	1790
1423.06	1792
1425.2	1800
1427.34	1730
1429.48	1800
1431.61	1670
1433.75	1714
1435.89	1678
1438.02	1674
1440.16	1670
1442.3	1674
1444.43	1676
1446.56	1674
1448.7	1670
1450.83	1652
1452.96	1622
1455.09	1626
1457.22	1604
1459.35	1648
1461.48	1566
1463.61	1524
1465.73	1556
1467.86	1542
1469.98	1542
1472.11	1524
1474.24	1514
1476.36	1518
1478.48	1534
1480.6	1506
1482.73	1498
1484.85	1518
1486.97	1526
1489.09	1430
1491.21	1448
1493.33	1452
1495.44	1464
1497.56	1430
1499.68	1412
1501.79	1476
1503.91	1406
1506.02	1410
1508.14	1444
1510.25	1434
1512.36	1348
1514.48	1364
1516.59	1348
1518.7	1354
1520.81	1344
1522.92	1344
1525.02	1384
1527.13	1296
1529.24	1280
1531.35	1322
1533.45	1268
1535.56	1276
1537.66	1344
1539.77	1266
1541.87	1258
1543.97	1258
1546.08	1212
1548.18	1268
1550.28	1246
1552.38	1232
1554.48	1218
1556.57	1230
1558.67	1224
1560.77	1206
1562.87	1188
1564.96	1218
1567.06	1238
1569.15	1196
1571.25	1216
1573.34	1142
1575.43	1150
1577.53	1198
1579.62	1130
1581.71	1152
1583.8	1150
1585.89	1144
1587.98	1154
1590.06	1104
1592.15	1100
1594.24	1148
1596.33	1128
1598.41	1124
1600.5	1104
1602.58	1112
1604.66	1136
1606.75	1170
1608.83	1108
1610.91	1112
1612.99	1088
1615.07	1094
1617.15	1106
1619.23	1068
1621.31	1064
1623.39	1042
1625.46	1080
1627.54	1084
1629.62	1106
1631.69	1056
1633.77	1092
1635.84	1030
1637.91	1066
1639.99	1076
1642.06	1038
1644.13	1052
1646.2	1062
1648.27	988
1650.34	1014
1652.41	1064
1654.47	1014
1656.54	1034
1658.61	1020
1660.67	1016
1662.74	1034
1664.81	998
1666.87	1008
1668.93	1010
1671	1012
1673.06	1006
1675.12	990
1677.18	974
1679.24	988
1681.3	1000
1683.36	986
1685.42	994
1687.47	980
1689.53	976
1691.59	1030
1693.64	948
1695.7	946
1697.75	988
1699.81	926
1701.86	1008
1703.91	974
1705.97	954
1708.02	952
1710.07	950
1712.12	986
1714.17	916
1716.22	948
1718.26	924
1720.31	934
1722.36	918
1724.4	926
1726.45	952
1728.49	950
1730.54	932
1732.58	934
1734.63	952
1736.67	924
1738.71	942
1740.75	942
1742.79	934
1744.83	938
1746.87	928
1748.91	918
1750.95	898
1752.98	872
1755.02	950
1757.06	920
1759.09	924
1761.13	902
1763.16	900
1765.19	914
1767.23	918
1769.26	928
1771.29	932
1773.32	930
1775.35	938
1777.38	946
1779.41	932
1781.44	918
1783.47	918
1785.49	904
1787.52	934
1789.55	908
1791.57	920
1793.6	858
1795.62	904
1797.64	926
1799.67	894
1801.69	904
1803.71	890
1805.73	894
1807.75	914
1809.77	922
1811.79	906
1813.81	918
1815.83	872
1817.84	876
1819.86	912
1821.88	908
1823.89	868
1825.91	910
1827.92	864
1829.93	872
1831.95	920
1833.96	892
1835.97	910
1837.98	904
1839.99	888
1842	858
1844.01	852
1846.02	886
1848.03	868
1850.03	858
1852.04	882
1854.05	866
1856.05	894
1858.06	856
1860.06	858
1862.06	858
1864.07	832
1866.07	882
1868.07	890
1870.07	890
1872.07	884
1874.07	856
1876.07	876
1878.07	872
1880.07	882
1882.07	840
1884.06	864
1886.06	844
1888.05	864
1890.05	900
1892.04	886
1894.04	886
1896.03	900
1898.02	858
1900.01	890
1902	890
1903.99	858
1905.98	856
1907.97	872
1909.96	862
1911.95	888
1913.94	850
1915.93	888
1917.91	862
1919.9	854
1921.88	852
1923.87	888
1925.85	866
1927.83	872
1929.82	854
1931.8	868
1933.78	868
1935.76	872
1937.74	842
1939.72	872
1941.7	860
1943.68	868
1945.65	864
1947.63	874
1949.61	836
1951.58	856
1953.56	844
1955.53	856
1957.51	886
1959.48	844
1961.45	812
1963.43	860
1965.4	852
1967.37	848
1969.34	870
1971.31	858
1973.28	858
1975.25	868
1977.22	800
1979.18	854
1981.15	876
1983.12	852
1985.08	818
1987.05	862
1989.01	846
1990.97	850
1992.94	838
1994.9	844
1996.86	810
1998.82	794
2000.78	816
2002.74	846
2004.7	854
2006.66	844
2008.62	840
2010.58	810
2012.54	862
2014.49	840
2016.45	850
2018.4	836
2020.36	878
2022.31	796
2024.27	816
2026.22	840
2028.17	840
2030.12	838
2032.07	870
2034.03	836
2035.98	846
2037.93	812
2039.87	810
2041.82	828
2043.77	808
2045.72	820
2047.66	844
2049.61	814
2051.55	820
2053.5	836
2055.44	808
2057.39	816
2059.33	802
2061.27	842
2063.21	824
2065.15	800
2067.09	826
2069.03	814
2070.97	844
2072.91	826
2074.85	822
2076.79	838
2078.73	810
2080.66	798
2082.6	812
2084.53	804
2086.47	800
2088.4	804
2090.33	802
2092.27	820
2094.2	816
2096.13	818
2098.06	822
2099.99	798
2101.92	796
2103.85	826
2105.78	788
2107.71	818
2109.64	818
2111.56	794
2113.49	796
2115.41	808
2117.34	842
2119.26	814
2121.19	838
2123.11	814
2125.03	836
2126.96	796
2128.88	792
2130.8	860
2132.72	798
2134.64	800
2136.56	826
2138.48	842
2140.4	798
2142.31	800
2144.23	814
2146.15	786
2148.06	788
2149.98	822
2151.89	796
2153.81	800
2155.72	794
2157.63	820
2159.55	812
2161.46	816
2163.37	808
2165.28	806
2167.19	780
2169.1	814
2171.01	838
2172.91	824
2174.82	792
2176.73	780
2178.64	788
2180.54	824
2182.45	778
2184.35	822
2186.26	786
2188.16	814
2190.06	796
2191.96	746
2193.87	766
2195.77	814
2197.67	784
2199.57	802
2201.47	782
2203.37	768
2205.27	766
2207.16	778
2209.06	778
2210.96	774
2212.85	804
2214.75	766
2216.64	774
2218.54	774
2220.43	794
2222.33	790
2224.22	777.603
2226.11	822.74
2228	770.539
2229.89	758.766
2231.78	763.695
2233.67	766.787
2235.56	777.72
2237.45	773.333
2239.34	767.97
2241.23	795.424
2243.11	782.655
2245	781.202
2246.89	786.495
2248.77	768.317
2250.66	771.391
2252.54	781.75
2254.42	775.629
2256.31	784.696
2258.19	751.969
2260.07	776.741
2261.95	789.184
2263.83	793.46
2265.71	763.99
2267.59	756.972
2269.47	781.802
2271.35	780.373
2273.23	757.557
2275.1	771.925
2276.98	774.61
2278.86	775.89
2280.73	773.702
2282.61	763.697
2284.48	739.868
2286.36	764.306
2288.23	748.469
2290.1	760.204
2291.98	757.589
2293.85	742.625
2295.72	735.855
2297.59	753.7
2299.46	761.021
2301.33	745.65
2303.2	761.492
2305.06	763.642
2306.93	753.876
2308.8	742.45
2310.67	751.097
2312.53	737.32
2314.4	746.885
2316.26	731.508
2317.62	730
2319.5	746
2321.37	712
2323.24	720
2325.12	742
2326.99	730
2328.86	756
2330.73	718
2332.6	742
2334.47	718
2336.34	722
2338.2	728
2340.07	740
2341.94	726
2343.81	742
2345.67	722
2347.54	728
2349.4	726
2351.27	672
2353.13	708
2354.99	710
2356.86	710
2358.72	700
2360.58	692
2362.44	722
2364.3	706
2366.16	708
2368.02	688
2369.88	682
2371.74	674
2373.6	700
2375.45	686
2377.31	672
2379.17	678
2381.02	658
2382.88	690
2384.73	680
2386.58	686
2388.44	674
2390.29	668
2392.14	690
2393.99	682
2395.85	650
2397.7	678
2399.55	664
2401.4	708
2403.25	688
2405.09	672
2406.94	670
2408.79	668
2410.63	640
2412.48	644
2414.33	652
2416.17	686
2418.02	670
2419.86	632
2421.7	624
2423.55	630
2425.39	636
2427.23	634
2429.07	650
2430.91	612
2432.75	616
2434.59	610
2436.43	638
2438.27	636
2440.11	640
2441.95	648
2443.78	604
2445.62	616
2447.46	606
2449.29	592
2451.13	614
2452.96	604
2454.79	612
2456.63	644
2458.46	630
2460.29	582
2462.12	616
2463.95	582
2465.78	558
2467.61	604
2469.44	646
2471.27	562
2473.1	588
2474.93	580
2476.76	594
2478.58	572
2480.41	552
2482.23	590
2484.06	550
2485.88	556
2487.71	552
2489.53	572
2491.35	548
2493.18	570
2495	544
2496.82	542
2498.64	538
2500.46	572
2502.28	534
2504.1	556
2505.92	526
2507.74	560
2509.55	526
2511.37	550
2513.19	542
2515	526
2516.82	518
2518.63	512
2520.45	530
2522.26	562
2524.07	500
2525.89	512
2527.7	484
2529.51	482
2531.32	502
2533.13	486
2534.94	500
2536.75	502
2538.56	488
2540.37	484
2542.18	498
2543.98	494
2545.79	490
2547.6	488
2549.4	498
2551.21	472
2553.01	468
2554.82	494
2556.62	470
2558.42	484
2560.23	482
2562.03	470
2563.83	468
2565.63	490
2567.43	446
2569.23	476
2571.03	460
2572.83	460
2574.63	478
2576.43	452
2578.22	458
2580.02	438
2581.82	476
2583.61	450
2585.41	446
2587.2	450
2589	428
2590.79	432
2592.58	430
2594.38	430
2596.17	446
2597.96	416
2599.75	438
2601.54	430
2603.33	418
2605.12	426
2606.91	428
2608.7	430
2610.49	422
2612.27	424
2614.06	408
2615.85	418
2617.63	424
2619.42	398
2621.2	426
2622.99	416
2624.77	422
2626.55	416
2628.34	416
2630.12	406
2631.9	420
2633.68	408
2635.46	404
2637.24	408
2639.02	414
2640.8	378
2642.58	404
2644.36	396
2646.14	386
2647.91	406
2649.69	396
2651.46	378
2653.24	412
2655.01	372
2656.79	382
2658.56	400
2660.34	364
2662.11	358
2663.88	368
2665.65	366
2667.42	364
2669.2	354
2670.96	358
2672.73	376
2674.5	358
2676.27	368
2678.04	368
2679.81	364
2681.58	332
2683.34	346
2685.11	344
2686.87	346
2688.64	374
2690.4	354
2692.17	344
2693.93	338
2695.69	346
2697.46	314
2699.22	354
2700.98	316
2702.74	322
2704.5	330
2706.26	350
2708.02	348
2709.78	342
2711.54	324
2713.3	328
2715.05	344
2716.81	326
2718.57	338
2720.32	338
2722.08	316
2723.83	328
2725.59	320
2727.34	308
2729.09	310
2730.85	312
2732.6	320
2734.35	306
2736.1	312
2737.85	290
2739.6	316
2741.35	310
2743.1	310
2744.85	302
2746.6	288
2748.35	300
2750.09	300
2751.84	294
2753.59	308
2755.33	276
2757.08	290
2758.82	288
2760.57	282
2762.31	278
2764.05	286
2765.79	274
2767.54	264
2769.28	280
2771.02	256
2772.76	272
2774.5	264
2776.24	292
2777.98	282
2779.72	276
2781.46	260
2783.19	260
2784.93	252
2786.67	260
2788.4	258
2790.14	250
2791.87	256
2793.61	252
2795.34	248
2797.07	234
2798.81	258
2800.54	254
2802.27	252
2804	248
2805.74	240
2807.47	230
2809.2	246
2810.93	250
2812.65	254
2814.38	246
2816.11	228
2817.84	240
2819.56	240
2821.29	228
2823.02	232
2824.74	224
2826.47	250
2828.19	230
2829.92	202
2831.64	214
2833.36	230
2835.09	206
2836.81	238
2838.53	244
2840.25	226
2841.97	238
2843.69	210
2845.41	228
2847.13	200
2848.85	194
2850.57	198
2852.28	212
2854	210
2855.72	192
2857.43	206
2859.15	204
2860.86	192
2862.58	220
2864.29	204
2866.01	178
2867.72	202
2869.43	190
2871.14	192
2872.86	202
2874.57	206
2876.28	188
2877.99	212
2879.7	188
2881.41	188
2883.11	210
2884.82	184
2886.53	198
2888.24	188
2889.94	186
2891.65	200
2893.36	164
2895.06	178
2896.77	186
2898.47	188
2900.17	186
2901.88	200
2903.58	178
2905.28	198
2906.98	172
2908.69	180
2910.39	176
2912.09	188
2913.79	180
2915.49	162
2917.19	176
2918.88	186
2920.58	160
2922.28	168
2923.98	178
2925.67	166
2927.37	178
2929.06	162
2930.76	168
2932.45	162
2934.15	170
2935.84	166
2937.53	162
2939.23	160
2940.92	158
2942.61	156
2944.3	158
2945.99	164
2947.68	166
2949.37	164
2951.06	168
2952.75	156
2954.44	164
2956.12	156
2957.81	156
2959.5	168
2961.18	156
2962.87	162
2964.56	136
2966.24	156
2967.92	150
2969.61	158
2971.29	160
2972.97	144
2974.66	146
2976.34	148
2978.02	140
2979.7	152
2981.38	136
2983.06	146
2984.74	152
2986.42	134
2988.1	142
2989.78	150
2991.45	142
2993.13	144
2994.81	144
2996.48	144
2998.16	160
2999.83	148