File: muestras/LIG/fproof_11.txt
#Acq. time (s)=	10
#Accumulations=	2
#Range (cm-¹)=	100...2000
#Windows=	2
#Autofocus=	Off
#AutoExposure=	Off
#Spike filter=	Multiple accum.
#Delay time (s)=	0
#Binning=	1
#Readout mode=	Signal
#DeNoise=	Off
#ICS correction=	Off
#Dark correction=	Off
#Inst. Process=	Off
#Instrument=	LabRAM HR Evol
#Detector=	Syncerity OE
#Objective=	x100_VIS_LWD
#Grating=	600 (500nm)
#ND Filter=	25%
#Laser=	633nm_Edge
#Hole=	100.021
#Range=	Visible
#Project=	LIG
#Sample=	proof
#Site=
#Title=	fproof
#Remark=
#Date=	07.03.2023 12:56
#Acquired=	07.03.2023 12:56:07
101.054	38
103.621	46
106.187	40
108.753	38
111.317	38
113.881	38
116.443	40
119.005	42
121.566	38
124.126	42
126.685	38
129.243	36
131.801	32
134.357	42
136.911	34
139.466	42
142.021	42
144.574	46
147.126	34
149.676	36
152.227	32
154.777	38
157.325	36
159.873	30
162.419	38
164.966	42
167.51	34
170.055	38
172.598	38
175.141	38
177.682	40
180.222	44
182.763	38
185.302	44
187.839	40
190.378	38
192.914	38
195.449	34
197.983	38
200.517	32
203.05	34
205.582	42
208.113	36
210.643	36
213.173	40
215.701	40
218.229	38
220.756	40
223.282	38
225.808	42
228.331	38
230.855	42
233.378	42
235.9	28
238.419	38
240.94	42
243.46	44
245.977	36
248.495	42
251.011	38
253.527	36
256.041	36
258.556	38
261.068	36
263.58	30
266.092	42
268.603	48
271.112	32
273.622	36
276.129	38
278.636	26
281.142	38
283.647	42
286.152	36
288.655	40
291.158	32
293.66	36
296.161	36
298.661	34
301.161	34
303.66	38
306.158	38
308.655	36
311.151	32
313.645	40
316.14	38
318.634	42
321.125	30
323.618	40
326.109	34
328.598	38
331.088	34
333.576	42
336.064	32
338.55	38
341.037	40
343.521	34
346.005	38
348.489	38
350.971	34
353.453	40
355.935	46
358.414	40
360.893	44
363.371	38
365.848	36
368.325	38
370.801	38
373.275	40
375.75	38
378.223	38
380.695	40
383.167	36
385.638	42
388.108	40
390.577	40
393.044	36
395.512	36
397.979	44
400.445	36
402.909	34
405.374	38
407.836	34
410.299	40
412.762	42
415.221	42
417.681	38
420.141	38
422.598	32
425.057	34
427.513	40
429.968	34
432.424	38
434.878	36
437.33	42
439.783	40
442.234	42
444.685	42
447.136	42
449.585	40
452.033	34
454.48	44
456.927	34
459.372	38
461.817	38
464.261	42
466.705	38
469.147	40
471.589	42
474.029	36
476.47	46
478.909	38
481.347	44
483.785	40
486.221	36
488.657	42
491.093	42
493.527	44
495.96	40
498.393	38
500.824	36
503.256	34
505.686	36
508.115	38
510.543	36
512.972	40
515.399	34
517.825	34
520.25	38
522.674	40
525.097	40
527.52	38
529.942	32
532.364	32
534.784	36
537.204	38
539.623	38
542.041	38
544.458	34
546.874	38
549.289	42
551.705	40
554.118	40
556.531	40
558.944	40
561.355	40
563.766	34
566.175	36
568.585	36
570.992	40
573.401	44
575.807	44
578.212	38
580.618	38
583.022	36
585.425	40
587.827	38
590.229	38
592.631	42
595.031	42
597.43	42
599.829	34
602.226	38
604.623	40
607.02	34
609.415	40
611.808	38
614.202	40
616.596	38
618.988	40
621.38	38
623.769	46
626.159	46
628.549	34
630.936	40
633.324	38
635.71	36
638.096	30
640.481	32
642.866	42
645.248	34
647.632	38
650.013	38
652.394	32
654.773	38
657.154	34
659.532	38
661.91	38
664.286	42
666.663	44
669.038	38
671.412	36
673.786	36
676.159	34
678.532	40
680.903	42
683.274	38
685.644	42
688.014	46
690.382	34
692.749	42
695.116	38
697.482	32
699.846	30
702.211	44
704.574	34
706.938	38
709.299	36
711.661	42
714.021	36
716.381	42
718.739	38
721.097	44
723.455	34
725.811	42
728.167	42
730.521	42
732.877	44
735.23	40
737.582	38
739.934	46
742.285	38
744.635	46
746.985	42
749.334	40
751.682	32
754.028	38
756.374	50
758.72	48
761.065	42
763.408	28
765.752	36
768.095	42
770.436	30
772.777	38
775.116	44
777.456	46
779.794	40
782.133	34
784.469	34
786.806	34
789.141	38
791.476	34
793.809	40
796.143	32
798.476	42
800.807	40
803.138	36
805.468	36
807.797	36
810.125	44
812.453	38
814.78	38
817.106	42
819.432	34
821.757	40
824.081	34
826.403	36
828.726	40
831.048	34
833.368	44
835.688	38
838.008	36
840.326	42
842.644	40
844.96	40
847.277	38
849.592	34
851.906	32
854.221	38
856.534	40
858.846	40
861.159	38
863.469	38
865.779	40
868.088	40
870.396	36
872.704	38
875.011	40
877.318	36
879.623	36
881.928	36
884.232	32
886.536	42
888.838	40
891.139	40
893.44	40
895.741	40
898.039	36
900.339	38
902.637	42
904.933	42
907.231	32
909.526	34
911.821	40
914.115	36
916.408	34
918.701	38
920.993	38
923.283	38
925.575	42
927.864	44
930.153	32
932.441	34
934.728	40
937.014	42
939.3	42
941.585	44
943.87	40
946.154	36
948.437	42
950.719	40
953	38
955.28	36
957.56	32
959.84	40
962.117	36
964.395	38
966.673	42
968.948	40
971.224	44
973.498	38
975.773	34
978.045	46
980.317	42
982.59	36
984.86	36
987.13	38
989.399	38
991.669	34
993.937	42
996.204	42
998.47	44
1000.74	36
1003	40
1005.26	36
1007.53	40
1009.79	36
1012.05	44
1014.31	44
1016.57	46
1018.83	36
1021.09	38
1023.35	40
1025.61	46
1027.87	44
1030.12	40
1032.38	44
1034.63	36
1036.88	38
1039.14	46
1041.39	38
1043.64	44
1045.89	40
1048.14	38
1050.39	42
1052.64	38
1054.89	44
1057.14	38
1059.38	44
1061.63	42
1063.87	42
1066.12	32
1068.36	42
1070.6	32
1072.85	36
1075.09	46
1077.33	38
1079.57	38
1081.81	42
1084.05	36
1086.28	48
1088.52	40
1090.76	40
1092.99	40
1095.23	38
1097.46	46
1099.69	40
1101.93	46
1104.16	36
1106.39	40
1108.62	44
1110.85	48
1113.08	40
1115.31	52
1117.53	38
1119.76	50
1121.99	52
1124.21	52
1126.44	42
1128.66	48
1130.88	50
1133.11	54
1135.33	52
1137.55	44
1139.77	46
1141.99	46
1144.21	52
1146.43	48
1148.64	48
1150.86	44
1153.08	52
1155.29	50
1157.51	48
1159.72	46
1161.93	50
1164.14	44
1166.36	50
1168.57	48
1170.78	46
1172.99	50
1175.2	44
1177.4	46
1179.61	48
1181.82	40
1184.02	52
1186.23	46
1188.43	50
1190.64	50
1192.84	54
1195.04	54
1197.24	52
1199.45	50.01
1201.64	46.1694
1203.84	40.4684
1206.04	53.663
1208.24	45.7873
1210.44	50.5994
1212.64	46.5
1214.83	55.4514
1217.03	53.19
1219.22	53.7084
1221.41	47.0146
1223.61	53.1
1225.8	48.7782
1227.99	56.1403
1230.18	55.0836
1232.37	51.9455
1234.56	53.3
1236.75	58.2916
1238.94	55.2476
1241.13	55.4466
1243.31	55.8535
1245.5	58.8757
1247.68	60.3052
1249.87	58.606
1252.05	58.5427
1254.24	58.7685
1256.42	63.97
1258.6	65.0571
1260.78	66.398
1262.96	61.5389
1265.14	66
1267.32	65.8039
1269.5	71.6447
1271.67	69.33
1273.85	72.9806
1276.03	77.9772
1278.2	75.45
1280.38	81.96
1282.55	84.0361
1284.72	86.8572
1286.9	89.6741
1289.07	88.5078
1291.24	89.7407
1293.41	90.3576
1295.58	100.46
1297.75	102.19
1299.92	113.83
1302.09	124.199
1304.25	125.323
1306.42	126.615
1308.44	130
1310.61	130
1312.79	136
1314.97	144
1317.14	144
1319.31	134
1321.48	154
1323.66	136
1325.83	158
1328	152
1330.17	158
1332.34	154
1334.5	138
1336.67	160
1338.84	154
1341	140
1343.17	138
1345.33	132
1347.5	132
1349.66	128
1351.83	112
1353.99	112
1356.15	106
1358.31	96
1360.47	112
1362.63	102
1364.79	96
1366.94	96
1369.1	92
1371.26	90
1373.41	82
1375.57	74
1377.72	82
1379.88	74
1382.03	82
1384.18	70
1386.33	68
1388.48	70
1390.64	66
1392.79	68
1394.93	70
1397.08	62
1399.23	54
1401.38	66
1403.52	64
1405.67	60
1407.81	60
1409.96	54
1412.1	56
1414.24	62
1416.39	60
1418.53	62
1420.67	64
1422.81	62
1424.95	54
1427.09	52
1429.23	56
1431.36	56
1433.5	56
1435.64	52
1437.77	48
1439.91	52
1442.04	54
1444.17	56
1446.31	58
1448.44	50
1450.57	46
1452.7	54
1454.83	50
1456.96	54
1459.09	52
1461.22	52
1463.34	54
1465.47	62
1467.6	54
1469.72	50
1471.85	54
1473.97	50
1476.09	56
1478.22	56
1480.34	52
1482.46	54
1484.58	48
1486.7	50
1488.82	48
1490.94	58
1493.06	56
1495.17	54
1497.29	54
1499.41	56
1501.52	52
1503.64	54
1505.75	52
1507.86	60
1509.98	56
1512.09	54
1514.2	58
1516.31	58
1518.42	60
1520.53	62
1522.64	52
1524.74	58
1526.85	62
1528.96	62
1531.07	56
1533.17	60
1535.27	60
1537.38	58
1539.48	58
1541.58	62
1543.69	58
1545.79	62
1547.89	64
1549.99	60
1552.09	64
1554.19	78
1556.28	70
1558.38	68
1560.48	78
1562.57	84
1564.67	78
1566.76	72
1568.86	80
1570.95	84
1573.05	88
1575.14	94
1577.23	92
1579.32	100
1581.41	88
1583.5	98
1585.59	110
1587.68	100
1589.76	116
1591.85	106
1593.94	100
1596.02	110
1598.11	108
1600.19	94
1602.27	104
1604.36	102
1606.44	106
1608.52	100
1610.6	110
1612.68	100
1614.76	94
1616.84	96
1618.92	102
1621	90
1623.07	90
1625.15	84
1627.23	90
1629.3	90
1631.38	76
1633.45	84
1635.52	72
1637.59	78
1639.67	64
1641.74	64
1643.81	66
1645.88	58
1647.95	54
1650.02	58
1652.08	56
1654.15	52
1656.22	48
1658.28	48
1660.35	52
1662.41	54
1664.48	42
1666.54	44
1668.6	44
1670.67	46
1672.73	40
1674.79	44
1676.85	44
1678.91	34
1680.97	44
1683.03	42
1685.08	40
1687.14	40
1689.2	42
1691.25	40
1693.31	44
1695.36	36
1697.42	40
1699.47	40
1701.52	38
1703.57	40
1705.63	36
1707.68	38
1709.72	38
1711.77	38
1713.82	40
1715.87	36
1717.92	44
1719.97	36
1722.01	46
1724.06	34
1726.1	32
1728.15	32
1730.19	40
1732.23	44
1734.27	42
1736.32	34
1738.36	44
1740.4	38
1742.44	30
1744.48	46
1746.51	38
1748.55	38
1750.59	42
1752.63	40
1754.66	40
1756.7	34
1758.73	44
1760.77	44
1762.8	42
1764.83	44
1766.86	34
1768.9	44
1770.93	44
1772.96	38
1774.99	36
1777.02	40
1779.04	42
1781.07	32
1783.1	38
1785.13	46
1787.15	40
1789.18	36
1791.2	40
1793.23	38
1795.25	42
1797.27	36
1799.29	36
1801.31	40
1803.34	42
1805.36	32
1807.38	36
1809.39	40
1811.41	30
1813.43	38
1815.45	30
1817.46	36
1819.48	40
1821.49	38
1823.51	40
1825.52	40
1827.54	38
1829.55	40
1831.56	36
1833.57	38
1835.58	38
1837.59	32
1839.6	38
1841.61	38
1843.62	30
1845.63	38
1847.64	32
1849.64	36
1851.65	32
1853.65	36
1855.66	38
1857.66	38
1859.66	42
1861.67	38
1863.67	28
1865.67	34
1867.67	34
1869.67	38
1871.67	36
1873.67	32
1875.67	36
1877.67	42
1879.66	36
1881.66	36
1883.66	40
1885.65	32
1887.65	38
1889.64	36
1891.63	32
1893.63	36
1895.62	36
1897.61	36
1899.6	40
1901.59	32
1903.58	32
1905.57	30
1907.56	36
1909.55	38
1911.53	38
1913.52	40
1915.51	38
1917.49	36
1919.48	32
1921.46	38
1923.45	38
1925.43	40
1927.41	38
1929.39	34
1931.37	40
1933.36	34
1935.33	38
1937.31	36
1939.29	26
1941.27	34
1943.25	42
1945.23	30
1947.2	28
1949.18	42
1951.15	38
1953.13	36
1955.1	38
1957.08	30
1959.05	34
1961.02	42
1962.99	40
1964.96	32
1966.93	42
1968.9	40
1970.87	28
1972.84	30
1974.81	36
1976.77	36
1978.74	36
1980.71	32
1982.67	34
1984.64	42
1986.6	36
1988.57	32
1990.53	34
1992.49	34
1994.45	30
1996.41	38
1998.37	32
1999.35	36