File: muestras/LIG/fproof_02.txt
#Acq. time (s)=	20
#Accumulations=	1
#Range (cm-¹)=	100...2000
#Windows=	2
#Autofocus=	Off
#AutoExposure=	Off
#Spike filter=	Off
#Delay time (s)=	0
#Binning=	1
#Readout mode=	Signal
#DeNoise=	Off
#ICS correction=	Off
#Dark correction=	Off
#Inst. Process=	Off
#Instrument=	LabRAM HR Evol
#Detector=	Syncerity OE
#Objective=	x100_VIS_LWD
#Grating=	600 (500nm)
#ND Filter=	100%
#Laser=	633nm_Edge
#Hole=	39.9962
#Range=	Visible
#Project=	LIG
#Sample=	proof
#Site=
#Title=	fproof
#Remark=
#Date=	07.03.2023 12:19
#Acquired=	07.03.2023 12:19:28
101.054	274
103.621	280
106.187	280
108.753	276
111.317	272
113.881	268
116.443	290
119.005	282
121.566	270
124.126	278
126.685	294
129.243	280
131.801	302
134.357	274
136.911	306
139.466	296
142.021	286
144.574	310
147.126	282
149.676	264
152.227	286
154.777	298
157.325	310
159.873	306
162.419	286
164.966	288
167.51	294
170.055	294
172.598	290
175.141	288
177.682	272
180.222	290
182.763	284
185.302	280
187.839	282
190.378	290
192.914	290
195.449	300
197.983	300
200.517	314
203.05	302
205.582	310
208.113	290
210.643	298
213.173	300
215.701	284
218.229	302
220.756	298
223.282	316
225.808	298
228.331	320
230.855	300
233.378	310
235.9	300
238.419	328
240.94	320
243.46	316
245.977	306
248.495	310
251.011	328
253.527	320
256.041	322
258.556	308
261.068	304
263.58	318
266.092	284
268.603	316
271.112	292
273.622	318
276.129	304
278.636	326
281.142	310
283.647	324
286.152	320
288.655	302
291.158	308
293.66	312
296.161	330
298.661	310
301.161	298
303.66	318
306.158	340
308.655	318
311.151	332
313.645	334
316.14	320
318.634	322
321.125	312
323.618	308
326.109	318
328.598	340
331.088	336
333.576	314
336.064	340
338.55	342
341.037	328
343.521	324
346.005	342
348.489	326
350.971	322
353.453	322
355.935	328
358.414	362
360.893	322
363.371	326
365.848	320
368.325	342
370.801	338
373.275	344
375.75	326
378.223	328
380.695	320
383.167	338
385.638	320
388.108	342
390.577	314
393.044	346
395.512	356
397.979	346
400.445	352
402.909	326
405.374	332
407.836	358
410.299	344
412.762	326
415.221	334
417.681	368
420.141	350
422.598	358
425.057	338
427.513	360
429.968	350
432.424	364
434.878	336
437.33	364
439.783	352
442.234	358
444.685	350
447.136	342
449.585	352
452.033	354
454.48	340
456.927	350
459.372	334
461.817	364
464.261	364
466.705	364
469.147	362
471.589	382
474.029	352
476.47	356
478.909	362
481.347	376
483.785	350
486.221	342
488.657	362
491.093	362
493.527	386
495.96	362
498.393	370
500.824	344
503.256	370
505.686	358
508.115	366
510.543	356
512.972	366
515.399	344
517.825	352
520.25	364
522.674	370
525.097	354
527.52	362
529.942	382
532.364	362
534.784	374
537.204	372
539.623	348
542.041	344
544.458	352
546.874	366
549.289	372
551.705	366
554.118	370
556.531	364
558.944	368
561.355	348
563.766	368
566.175	372
568.585	370
570.992	354
573.401	372
575.807	366
578.212	362
580.618	346
583.022	364
585.425	374
587.827	354
590.229	390
592.631	356
595.031	364
597.43	380
599.829	344
602.226	368
604.623	364
607.02	370
609.415	382
611.808	342
614.202	360
616.596	368
618.988	370
621.38	376
623.769	386
626.159	382
628.549	384
630.936	380
633.324	356
635.71	378
638.096	372
640.481	366
642.866	378
645.248	398
647.632	374
650.013	382
652.394	358
654.773	366
657.154	388
659.532	368
661.91	370
664.286	392
666.663	364
669.038	390
671.412	384
673.786	388
676.159	394
678.532	372
680.903	382
683.274	382
685.644	376
688.014	390
690.382	358
692.749	384
695.116	390
697.482	364
699.846	380
702.211	366
704.574	394
706.938	368
709.299	364
711.661	360
714.021	362
716.381	382
718.739	400
721.097	388
723.455	392
725.811	382
728.167	376
730.521	354
732.877	388
735.23	396
737.582	378
739.934	402
742.285	362
744.635	388
746.985	380
749.334	390
751.682	394
754.028	414
756.374	378
758.72	380
761.065	370
763.408	374
765.752	372
768.095	394
770.436	386
772.777	406
775.116	372
777.456	398
779.794	400
782.133	370
784.469	396
786.806	376
789.141	382
791.476	372
793.809	404
796.143	380
798.476	370
800.807	388
803.138	406
805.468	402
807.797	378
810.125	372
812.453	374
814.78	372
817.106	412
819.432	388
821.757	400
824.081	400
826.403	376
828.726	378
831.048	392
833.368	392
835.688	390
838.008	378
840.326	406
842.644	372
844.96	378
847.277	406
849.592	398
851.906	402
854.221	372
856.534	374
858.846	370
861.159	388
863.469	378
865.779	402
868.088	396
870.396	410
872.704	408
875.011	402
877.318	388
879.623	384
881.928	384
884.232	370
886.536	390
888.838	386
891.139	392
893.44	382
895.741	396
898.039	376
900.339	406
902.637	396
904.933	372
907.231	390
909.526	390
911.821	380
914.115	390
916.408	376
918.701	390
920.993	390
923.283	400
925.575	372
927.864	376
930.153	362
932.441	380
934.728	372
937.014	376
939.3	374
941.585	396
943.87	388
946.154	388
948.437	370
950.719	382
953	380
955.28	362
957.56	396
959.84	372
962.117	380
964.395	382
966.673	400
968.948	398
971.224	388
973.498	394
975.773	426
978.045	378
980.317	388
982.59	408
984.86	378
987.13	400
989.399	390
991.669	394
993.937	384
996.204	374
998.47	402
1000.74	382
1003	368
1005.26	394
1007.53	394
1009.79	406
1012.05	400
1014.31	394
1016.57	384
1018.83	386
1021.09	388
1023.35	388
1025.61	384
1027.87	390
1030.12	404
1032.38	402
1034.63	362
1036.88	384
1039.14	374
1041.39	408
1043.64	406
1045.89	396
1048.14	398
1050.39	394
1052.64	376
1054.89	396
1057.14	396
1059.38	426
1061.63	372
1063.87	398
1066.12	412
1068.36	398
1070.6	410
1072.85	396
1075.09	394
1077.33	396
1079.57	420
1081.81	396
1084.05	394
1086.28	394
1088.52	412
1090.76	364
1092.99	408
1095.23	400
1097.46	402
1099.69	382
1101.93	384
1104.16	404
1106.39	384
1108.62	384
1110.85	378
1113.08	412
1115.31	380
1117.53	384
1119.76	378
1121.99	402
1124.21	380
1126.44	406
1128.66	388
1130.88	386
1133.11	404
1135.33	376
1137.55	402
1139.77	404
1141.99	400
1144.21	388
1146.43	392
1148.64	398
1150.86	408
1153.08	406
1155.29	416
1157.51	400
1159.72	412
1161.93	384
1164.14	388
1166.36	412
1168.57	392
1170.78	404
1172.99	384
1175.2	384
1177.4	426
1179.61	408
1181.82	384
1184.02	382
1186.23	412
1188.43	400
1190.64	398
1192.84	406
1195.04	388
1197.24	420
1199.45	381.74
1201.64	386.339
1203.84	382.023
1206.04	367.491
1208.24	415.243
1210.44	420.726
1212.64	389.282
1214.83	366.973
1217.03	383.81
1219.22	388.808
1221.41	384.561
1223.61	375.196
1225.8	367.483
1227.99	377.433
1230.18	363.224
1232.37	368.331
1234.56	358.45
1236.75	370.258
1238.94	360.577
1241.13	364.168
1243.31	363.787
1245.5	377.837
1247.68	362.285
1249.87	338.703
1252.05	361.925
1254.24	368.98
1256.42	356.112
1258.6	350.301
1260.78	358.508
1262.96	354.466
1265.14	367.749
1267.32	353.49
1269.5	365.525
1271.67	353.879
1273.85	359.448
1276.03	357.869
1278.2	349.954
1280.38	361.485
1282.55	359.062
1284.72	356.424
1286.9	342.446
1289.07	354.316
1291.24	351.837
1293.41	352.657
1295.58	358.83
1297.75	355.314
1299.92	382.287
1302.09	362.829
1304.25	340.349
1306.42	367.498
1308.44	354
1310.61	344
1312.79	332
1314.97	358
1317.14	370
1319.31	362
1321.48	358
1323.66	352
1325.83	358
1328	364
1330.17	356
1332.34	342
1334.5	352
1336.67	356
1338.84	362
1341	342
1343.17	340
1345.33	318
1347.5	340
1349.66	348
1351.83	332
1353.99	344
1356.15	318
1358.31	346
1360.47	336
1362.63	326
1364.79	328
1366.94	326
1369.1	346
1371.26	356
1373.41	330
1375.57	332
1377.72	314
1379.88	314
1382.03	352
1384.18	316
1386.33	326
1388.48	330
1390.64	342
1392.79	328
1394.93	332
1397.08	332
1399.23	334
1401.38	336
1403.52	324
1405.67	324
1407.81	336
1409.96	332
1412.1	338
1414.24	332
1416.39	320
1418.53	340
1420.67	332
1422.81	326
1424.95	326
1427.09	334
1429.23	306
1431.36	330
1433.5	318
1435.64	326
1437.77	342
1439.91	320
1442.04	336
1444.17	316
1446.31	332
1448.44	320
1450.57	336
1452.7	320
1454.83	354
1456.96	330
1459.09	338
1461.22	336
1463.34	318
1465.47	324
1467.6	332
1469.72	326
1471.85	330
1473.97	316
1476.09	336
1478.22	368
1480.34	330
1482.46	324
1484.58	334
1486.7	320
1488.82	316
1490.94	326
1493.06	322
1495.17	332
1497.29	328
1499.41	336
1501.52	342
1503.64	332
1505.75	322
1507.86	322
1509.98	338
1512.09	320
1514.2	318
1516.31	326
1518.42	334
1520.53	318
1522.64	320
1524.74	328
1526.85	324
1528.96	320
1531.07	318
1533.17	350
1535.27	320
1537.38	326
1539.48	324
1541.58	312
1543.69	332
1545.79	324
1547.89	322
1549.99	320
1552.09	322
1554.19	310
1556.28	316
1558.38	334
1560.48	338
1562.57	334
1564.67	326
1566.76	334
1568.86	336
1570.95	296
1573.05	340
1575.14	322
1577.23	328
1579.32	314
1581.41	330
1583.5	332
1585.59	328
1587.68	326
1589.76	308
1591.85	322
1593.94	316
1596.02	328
1598.11	334
1600.19	316
1602.27	302
1604.36	352
1606.44	316
1608.52	330
1610.6	334
1612.68	320
1614.76	326
1616.84	304
1618.92	326
1621	300
1623.07	312
1625.15	324
1627.23	318
1629.3	296
1631.38	338
1633.45	298
1635.52	296
1637.59	316
1639.67	328
1641.74	296
1643.81	306
1645.88	308
1647.95	316
1650.02	328
1652.08	316
1654.15	326
1656.22	356
1658.28	300
1660.35	314
1662.41	322
1664.48	326
1666.54	336
1668.6	298
1670.67	306
1672.73	296
1674.79	306
1676.85	310
1678.91	298
1680.97	318
1683.03	294
1685.08	294
1687.14	318
1689.2	302
1691.25	290
1693.31	314
1695.36	302
1697.42	280
1699.47	296
1701.52	296
1703.57	278
1705.63	288
1707.68	308
1709.72	298
1711.77	286
1713.82	270
1715.87	308
1717.92	296
1719.97	290
1722.01	308
1724.06	312
1726.1	312
1728.15	298
1730.19	298
1732.23	324
1734.27	292
1736.32	306
1738.36	314
1740.4	290
1742.44	306
1744.48	290
1746.51	314
1748.55	280
1750.59	292
1752.63	308
1754.66	300
1756.7	288
1758.73	290
1760.77	284
1762.8	270
1764.83	310
1766.86	276
1768.9	290
1770.93	304
1772.96	290
1774.99	298
1777.02	274
1779.04	292
1781.07	278
1783.1	296
1785.13	296
1787.15	284
1789.18	294
1791.2	284
1793.23	276
1795.25	288
1797.27	292
1799.29	272
1801.31	286
1803.34	298
1805.36	282
1807.38	290
1809.39	286
1811.41	288
1813.43	278
1815.45	284
1817.46	290
1819.48	288
1821.49	312
1823.51	286
1825.52	292
1827.54	278
1829.55	284
1831.56	266
1833.57	286
1835.58	288
1837.59	274
1839.6	282
1841.61	272
1843.62	254
1845.63	270
1847.64	286
1849.64	266
1851.65	280
1853.65	294
1855.66	254
1857.66	284
1859.66	278
1861.67	282
1863.67	264
1865.67	270
1867.67	284
1869.67	278
1871.67	278
1873.67	274
1875.67	274
1877.67	266
1879.66	264
1881.66	296
1883.66	258
1885.65	272
1887.65	268
1889.64	264
1891.63	276
1893.63	260
1895.62	270
1897.61	258
1899.6	262
1901.59	288
1903.58	256
1905.57	282
1907.56	278
1909.55	268
1911.53	262
1913.52	266
1915.51	262
1917.49	258
1919.48	268
1921.46	248
1923.45	266
1925.43	284
1927.41	254
1929.39	282
1931.37	274
1933.36	268
1935.33	264
1937.31	268
1939.29	260
1941.27	280
1943.25	264
1945.23	272
1947.2	256
1949.18	256
1951.15	256
1953.13	267
1955.1	258
1957.08	262
1959.05	262
1961.02	254
1962.99	264
1964.96	270
1966.93	248
1968.9	246
1970.87	252
1972.84	230
1974.81	246
1976.77	244
1978.74	256
1980.71	258
1982.67	254
1984.64	248
1986.6	252
1988.57	248
1990.53	248
1992.49	246
1994.45	248
1996.41	246
1998.37	250
1999.35	252