File: muestras/LIG/fproof_03.txt
#Acq. time (s)=	20
#Accumulations=	1
#Range (cm-¹)=	100...2000
#Windows=	2
#Autofocus=	Off
#AutoExposure=	Off
#Spike filter=	Off
#Delay time (s)=	0
#Binning=	1
#Readout mode=	Signal
#DeNoise=	Off
#ICS correction=	Off
#Dark correction=	Off
#Inst. Process=	Off
#Instrument=	LabRAM HR Evol
#Detector=	Syncerity OE
#Objective=	x100_VIS_LWD
#Grating=	600 (500nm)
#ND Filter=	50%
#Laser=	633nm_Edge
#Hole=	100.021
#Range=	Visible
#Project=	LIG
#Sample=	proof
#Site=
#Title=	fproof
#Remark=
#Date=	07.03.2023 12:20
#Acquired=	07.03.2023 12:20:42
101.054	2482
103.621	2444
106.187	2494
108.753	2484
111.317	2516
113.881	2486
116.443	2486
119.005	2504
121.566	2488
124.126	2462
126.685	2564
129.243	2530
131.801	2558
134.357	2540
136.911	2550
139.466	2568
142.021	2584
144.574	2548
147.126	2562
149.676	2586
152.227	2664
154.777	2582
157.325	2612
159.873	2634
162.419	2598
164.966	2662
167.51	2598
170.055	2602
172.598	2684
175.141	2652
177.682	2688
180.222	2656
182.763	2716
185.302	2690
187.839	2648
190.378	2626
192.914	2630
195.449	2712
197.983	2654
200.517	2714
203.05	2750
205.582	2792
208.113	2846
210.643	2768
213.173	2766
215.701	2750
218.229	2750
220.756	2780
223.282	2804
225.808	2844
228.331	2800
230.855	2814
233.378	2886
235.9	2928
238.419	2930
240.94	2890
243.46	2896
245.977	2998
248.495	2874
251.011	2860
253.527	2936
256.041	2896
258.556	2924
261.068	2894
263.58	2896
266.092	2882
268.603	2910
271.112	2950
273.622	2956
276.129	2912
278.636	2902
281.142	2964
283.647	2890
286.152	2946
288.655	2930
291.158	2938
293.66	3032
296.161	2970
298.661	3024
301.161	2992
303.66	3022
306.158	2952
308.655	3018
311.151	3080
313.645	3040
316.14	2996
318.634	3100
321.125	3014
323.618	3040
326.109	3086
328.598	3024
331.088	3130
333.576	3112
336.064	3078
338.55	3094
341.037	3058
343.521	3100
346.005	3108
348.489	3124
350.971	3142
353.453	3060
355.935	3156
358.414	3182
360.893	3138
363.371	3144
365.848	3114
368.325	3180
370.801	3082
373.275	3152
375.75	3160
378.223	3216
380.695	3170
383.167	3116
385.638	3142
388.108	3174
390.577	3120
393.044	3162
395.512	3116
397.979	3180
400.445	3196
402.909	3178
405.374	3210
407.836	3242
410.299	3278
412.762	3300
415.221	3234
417.681	3288
420.141	3298
422.598	3278
425.057	3340
427.513	3382
429.968	3356
432.424	3386
434.878	3328
437.33	3352
439.783	3362
442.234	3460
444.685	3452
447.136	3322
449.585	3350
452.033	3324
454.48	3314
456.927	3344
459.372	3384
461.817	3326
464.261	3360
466.705	3442
469.147	3306
471.589	3400
474.029	3316
476.47	3332
478.909	3430
481.347	3382
483.785	3394
486.221	3482
488.657	3420
491.093	3458
493.527	3406
495.96	3388
498.393	3382
500.824	3438
503.256	3490
505.686	3442
508.115	3398
510.543	3454
512.972	3436
515.399	3466
517.825	3428
520.25	3384
522.674	3474
525.097	3428
527.52	3406
529.942	3418
532.364	3446
534.784	3462
537.204	3330
539.623	3464
542.041	3428
544.458	3428
546.874	3418
549.289	3412
551.705	3438
554.118	3482
556.531	3392
558.944	3474
561.355	3456
563.766	3384
566.175	3426
568.585	3466
570.992	3432
573.401	3398
575.807	3428
578.212	3476
580.618	3490
583.022	3430
585.425	3516
587.827	3414
590.229	3466
592.631	3540
595.031	3456
597.43	3470
599.829	3530
602.226	3458
604.623	3548
607.02	3482
609.415	3466
611.808	3480
614.202	3494
616.596	3494
618.988	3576
621.38	3468
623.769	3528
626.159	3592
628.549	3570
630.936	3528
633.324	3604
635.71	3554
638.096	3630
640.481	3628
642.866	3612
645.248	3598
647.632	3706
650.013	3590
652.394	3660
654.773	3612
657.154	3626
659.532	3620
661.91	3644
664.286	3660
666.663	3650
669.038	3642
671.412	3592
673.786	3570
676.159	3558
678.532	3602
680.903	3588
683.274	3632
685.644	3616
688.014	3604
690.382	3590
692.749	3588
695.116	3676
697.482	3650
699.846	3566
702.211	3598
704.574	3598
706.938	3616
709.299	3628
711.661	3600
714.021	3586
716.381	3570
718.739	3624
721.097	3628
723.455	3646
725.811	3656
728.167	3608
730.521	3724
732.877	3640
735.23	3770
737.582	3662
739.934	3662
742.285	3628
744.635	3718
746.985	3672
749.334	3634
751.682	3692
754.028	3692
756.374	3662
758.72	3646
761.065	3710
763.408	3624
765.752	3616
768.095	3656
770.436	3610
772.777	3658
775.116	3612
777.456	3678
779.794	3636
782.133	3628
784.469	3694
786.806	3632
789.141	3626
791.476	3600
793.809	3732
796.143	3650
798.476	3668
800.807	3588
803.138	3670
805.468	3646
807.797	3652
810.125	3708
812.453	3650
814.78	3640
817.106	3674
819.432	3690
821.757	3762
824.081	3682
826.403	3724
828.726	3726
831.048	3720
833.368	3692
835.688	3746
838.008	3708
840.326	3762
842.644	3722
844.96	3746
847.277	3760
849.592	3700
851.906	3766
854.221	3696
856.534	3778
858.846	3790
861.159	3728
863.469	3858
865.779	3744
868.088	3780
870.396	3842
872.704	3694
875.011	3800
877.318	3706
879.623	3802
881.928	3774
884.232	3780
886.536	3702
888.838	3780
891.139	3730
893.44	3740
895.741	3720
898.039	3706
900.339	3686
902.637	3788
904.933	3718
907.231	3728
909.526	3700
911.821	3660
914.115	3762
916.408	3752
918.701	3746
920.993	3632
923.283	3762
925.575	3656
927.864	3650
930.153	3712
932.441	3764
934.728	3756
937.014	3694
939.3	3798
941.585	3708
943.87	3782
946.154	3812
948.437	3698
950.719	3724
953	3720
955.28	3766
957.56	3744
959.84	3746
962.117	3702
964.395	3788
966.673	3752
968.948	3814
971.224	3828
973.498	3764
975.773	3736
978.045	3806
980.317	3750
982.59	3724
984.86	3760
987.13	3742
989.399	3784
991.669	3786
993.937	3772
996.204	3768
998.47	3766
1000.74	3838
1003	3778
1005.26	3760
1007.53	3724
1009.79	3768
1012.05	3742
1014.31	3864
1016.57	3838
1018.83	3772
1021.09	3830
1023.35	3744
1025.61	3794
1027.87	3858
1030.12	3722
1032.38	3832
1034.63	3826
1036.88	3844
1039.14	3782
1041.39	3862
1043.64	3820
1045.89	3810
1048.14	3814
1050.39	3816
1052.64	3870
1054.89	3822
1057.14	3904
1059.38	3934
1061.63	3892
1063.87	3838
1066.12	3858
1068.36	3954
1070.6	3840
1072.85	3900
1075.09	3920
1077.33	3854
1079.57	3788
1081.81	3838
1084.05	3880
1086.28	3852
1088.52	3808
1090.76	3848
1092.99	3780
1095.23	3812
1097.46	3866
1099.69	3836
1101.93	3816
1104.16	3824
1106.39	3788
1108.62	3796
1110.85	3830
1113.08	3868
1115.31	3860
1117.53	3960
1119.76	3784
1121.99	3830
1124.21	3818
1126.44	3744
1128.66	3736
1130.88	3734
1133.11	3746
1135.33	3806
1137.55	3892
1139.77	3836
1141.99	3806
1144.21	3816
1146.43	3790
1148.64	3874
1150.86	3928
1153.08	3818
1155.29	3850
1157.51	3916
1159.72	3846
1161.93	3844
1164.14	3864
1166.36	3860
1168.57	3870
1170.78	3906
1172.99	3824
1175.2	3820
1177.4	3916
1179.61	3890
1181.82	3908
1184.02	3814
1186.23	3834
1188.43	3876
1190.64	3796
1192.84	3818
1195.04	3820
1197.24	3858
1199.45	3849.86
1201.64	3832.36
1203.84	3877.49
1206.04	3850.85
1208.24	3826.95
1210.44	3750.92
1212.64	3795.27
1214.83	3810.26
1217.03	3850.1
1219.22	3811.25
1221.41	3874.69
1223.61	3809.08
1225.8	3819.53
1227.99	3833.36
1230.18	3815.04
1232.37	3842.31
1234.56	3776.63
1236.75	3759.86
1238.94	3846.01
1241.13	3808.22
1243.31	3776.33
1245.5	3789.92
1247.68	3800.12
1249.87	3791.03
1252.05	3840.32
1254.24	3856.9
1256.42	3869.46
1258.6	3836.67
1260.78	3840.69
1262.96	3821.47
1265.14	3891.62
1267.32	3871.81
1269.5	3889.66
1271.67	3871.13
1273.85	3873.93
1276.03	3895.26
1278.2	3891.27
1280.38	3933.62
1282.55	3923.43
1284.72	4000.4
1286.9	3921.87
1289.07	3932.66
1291.24	3904.14
1293.41	3921.84
1295.58	3939.69
1297.75	3991.77
1299.92	3937.96
1302.09	3983.93
1304.25	3952.16
1306.42	3989.91
1308.44	4066
1310.61	3996
1312.79	4010
1314.97	4062
1317.14	4076
1319.31	4022
1321.48	4064
1323.66	3964
1325.83	3992
1328	3970
1330.17	4060
1332.34	4072
1334.5	4048
1336.67	3962
1338.84	4018
1341	3924
1343.17	3974
1345.33	3940
1347.5	3964
1349.66	3928
1351.83	3890
1353.99	3922
1356.15	3896
1358.31	3730
1360.47	3830
1362.63	3888
1364.79	3868
1366.94	3812
1369.1	3936
1371.26	3946
1373.41	3848
1375.57	3864
1377.72	3890
1379.88	3900
1382.03	3780
1384.18	3898
1386.33	3800
1388.48	3746
1390.64	3842
1392.79	3758
1394.93	3816
1397.08	3754
1399.23	3798
1401.38	3882
1403.52	3842
1405.67	3862
1407.81	3802
1409.96	3778
1412.1	3748
1414.24	3806
1416.39	3782
1418.53	3794
1420.67	3834
1422.81	3868
1424.95	3682
1427.09	3734
1429.23	3748
1431.36	3738
1433.5	3778
1435.64	3806
1437.77	3852
1439.91	3730
1442.04	3784
1444.17	3792
1446.31	3800
1448.44	3792
1450.57	3810
1452.7	3746
1454.83	3754
1456.96	3778
1459.09	3800
1461.22	3746
1463.34	3780
1465.47	3818
1467.6	3826
1469.72	3810
1471.85	3884
1473.97	3720
1476.09	3826
1478.22	3744
1480.34	3830
1482.46	3768
1484.58	3820
1486.7	3704
1488.82	3804
1490.94	3750
1493.06	3798
1495.17	3736
1497.29	3718
1499.41	3784
1501.52	3776
1503.64	3742
1505.75	3740
1507.86	3758
1509.98	3762
1512.09	3750
1514.2	3778
1516.31	3780
1518.42	3752
1520.53	3726
1522.64	3716
1524.74	3718
1526.85	3760
1528.96	3716
1531.07	3724
1533.17	3712
1535.27	3686
1537.38	3790
1539.48	3684
1541.58	3704
1543.69	3686
1545.79	3724
1547.89	3660
1549.99	3702
1552.09	3656
1554.19	3742
1556.28	3698
1558.38	3686
1560.48	3730
1562.57	3690
1564.67	3780
1566.76	3736
1568.86	3694
1570.95	3772
1573.05	3778
1575.14	3810
1577.23	3794
1579.32	3742
1581.41	3764
1583.5	3732
1585.59	3734
1587.68	3790
1589.76	3760
1591.85	3734
1593.94	3762
1596.02	3716
1598.11	3750
1600.19	3820
1602.27	3824
1604.36	3698
1606.44	3724
1608.52	3732
1610.6	3750
1612.68	3678
1614.76	3756
1616.84	3650
1618.92	3754
1621	3712
1623.07	3654
1625.15	3714
1627.23	3638
1629.3	3700
1631.38	3712
1633.45	3692
1635.52	3692
1637.59	3700
1639.67	3730
1641.74	3690
1643.81	3644
1645.88	3710
1647.95	3608
1650.02	3558
1652.08	3672
1654.15	3550
1656.22	3642
1658.28	3592
1660.35	3686
1662.41	3660
1664.48	3552
1666.54	3660
1668.6	3604
1670.67	3584
1672.73	3582
1674.79	3612
1676.85	3558
1678.91	3554
1680.97	3590
1683.03	3526
1685.08	3532
1687.14	3578
1689.2	3502
1691.25	3512
1693.31	3516
1695.36	3560
1697.42	3506
1699.47	3458
1701.52	3518
1703.57	3484
1705.63	3500
1707.68	3498
1709.72	3550
1711.77	3410
1713.82	3480
1715.87	3488
1717.92	3426
1719.97	3446
1722.01	3490
1724.06	3500
1726.1	3410
1728.15	3502
1730.19	3384
1732.23	3418
1734.27	3398
1736.32	3452
1738.36	3404
1740.4	3456
1742.44	3452
1744.48	3464
1746.51	3404
1748.55	3380
1750.59	3368
1752.63	3478
1754.66	3418
1756.7	3426
1758.73	3396
1760.77	3356
1762.8	3390
1764.83	3348
1766.86	3414
1768.9	3454
1770.93	3408
1772.96	3358
1774.99	3364
1777.02	3370
1779.04	3392
1781.07	3404
1783.1	3334
1785.13	3422
1787.15	3354
1789.18	3320
1791.2	3336
1793.23	3444
1795.25	3374
1797.27	3314
1799.29	3356
1801.31	3484
1803.34	3272
1805.36	3404
1807.38	3304
1809.39	3322
1811.41	3382
1813.43	3314
1815.45	3262
1817.46	3316
1819.48	3352
1821.49	3254
1823.51	3350
1825.52	3292
1827.54	3234
1829.55	3222
1831.56	3246
1833.57	3294
1835.58	3288
1837.59	3288
1839.6	3228
1841.61	3284
1843.62	3322
1845.63	3272
1847.64	3262
1849.64	3210
1851.65	3238
1853.65	3146
1855.66	3274
1857.66	3206
1859.66	3204
1861.67	3178
1863.67	3258
1865.67	3104
1867.67	3194
1869.67	3214
1871.67	3166
1873.67	3136
1875.67	3152
1877.67	3102
1879.66	3080
1881.66	3100
1883.66	3120
1885.65	3128
1887.65	3182
1889.64	3146
1891.63	3102
1893.63	3056
1895.62	3112
1897.61	3070
1899.6	3072
1901.59	3106
1903.58	3088
1905.57	3076
1907.56	3050
1909.55	3090
1911.53	3114
1913.52	3102
1915.51	3076
1917.49	3032
1919.48	3098
1921.46	3114
1923.45	3080
1925.43	3072
1927.41	3072
1929.39	3036
1931.37	3078
1933.36	3048
1935.33	3044
1937.31	3006
1939.29	3024
1941.27	2948
1943.25	3114
1945.23	2980
1947.2	3040
1949.18	2990
1951.15	3044
1953.13	3043
1955.1	3042
1957.08	2944
1959.05	2990
1961.02	2960
1962.99	2970
1964.96	2972
1966.93	2946
1968.9	2932
1970.87	2898
1972.84	2966
1974.81	2892
1976.77	2906
1978.74	2874
1980.71	2938
1982.67	2882
1984.64	2940
1986.6	2902
1988.57	2950
1990.53	2914
1992.49	2864
1994.45	2880
1996.41	2856
1998.37	2898
1999.35	2946