File: muestras/LIG/fproof_24.txt
#Acq. time (s)=	10
#Accumulations=	2
#Range (cm-¹)=	100...2000
#Windows=	2
#Autofocus=	Off
#AutoExposure=	Off
#Spike filter=	Multiple accum.
#Delay time (s)=	0
#Binning=	1
#Readout mode=	Signal
#DeNoise=	Off
#ICS correction=	Off
#Dark correction=	Off
#Inst. Process=	Off
#Instrument=	LabRAM HR Evol
#Detector=	Syncerity OE
#Objective=	x100_VIS_LWD
#Grating=	600 (500nm)
#ND Filter=	25%
#Laser=	633nm_Edge
#Hole=	100.021
#Range=	Visible
#Project=	LIG
#Sample=	proof
#Site=
#Title=	fproof
#Remark=
#Date=	07.03.2023 13:29
#Acquired=	07.03.2023 13:29:30
101.054	68
103.621	66
106.187	78
108.753	66
111.317	64
113.881	58
116.443	62
119.005	70
121.566	60
124.126	62
126.685	62
129.243	62
131.801	58
134.357	62
136.911	50
139.466	60
142.021	62
144.574	54
147.126	60
149.676	50
152.227	60
154.777	50
157.325	52
159.873	46
162.419	50
164.966	52
167.51	54
170.055	50
172.598	48
175.141	58
177.682	50
180.222	64
182.763	52
185.302	48
187.839	62
190.378	60
192.914	56
195.449	54
197.983	64
200.517	56
203.05	60
205.582	60
208.113	62
210.643	58
213.173	68
215.701	54
218.229	60
220.756	60
223.282	64
225.808	56
228.331	58
230.855	54
233.378	56
235.9	66
238.419	56
240.94	56
243.46	54
245.977	58
248.495	60
251.011	60
253.527	62
256.041	58
258.556	54
261.068	62
263.58	54
266.092	54
268.603	58
271.112	54
273.622	50
276.129	52
278.636	60
281.142	52
283.647	54
286.152	54
288.655	50
291.158	54
293.66	58
296.161	46
298.661	48
301.161	60
303.66	52
306.158	58
308.655	50
311.151	50
313.645	54
316.14	56
318.634	50
321.125	46
323.618	46
326.109	48
328.598	52
331.088	54
333.576	56
336.064	48
338.55	48
341.037	52
343.521	54
346.005	46
348.489	60
350.971	50
353.453	44
355.935	42
358.414	54
360.893	46
363.371	60
365.848	54
368.325	50
370.801	50
373.275	50
375.75	42
378.223	48
380.695	56
383.167	44
385.638	54
388.108	46
390.577	52
393.044	44
395.512	48
397.979	50
400.445	42
402.909	44
405.374	42
407.836	56
410.299	54
412.762	42
415.221	50
417.681	46
420.141	50
422.598	50
425.057	52
427.513	52
429.968	52
432.424	46
434.878	56
437.33	52
439.783	54
442.234	54
444.685	46
447.136	52
449.585	50
452.033	48
454.48	42
456.927	56
459.372	54
461.817	46
464.261	44
466.705	52
469.147	48
471.589	56
474.029	54
476.47	48
478.909	50
481.347	50
483.785	46
486.221	50
488.657	52
491.093	52
493.527	50
495.96	52
498.393	50
500.824	40
503.256	50
505.686	46
508.115	50
510.543	50
512.972	40
515.399	46
517.825	44
520.25	46
522.674	40
525.097	50
527.52	48
529.942	50
532.364	50
534.784	48
537.204	50
539.623	32
542.041	44
544.458	46
546.874	42
549.289	42
551.705	48
554.118	44
556.531	48
558.944	50
561.355	44
563.766	48
566.175	44
568.585	46
570.992	48
573.401	42
575.807	42
578.212	44
580.618	48
583.022	46
585.425	40
587.827	46
590.229	42
592.631	46
595.031	42
597.43	46
599.829	48
602.226	48
604.623	42
607.02	48
609.415	50
611.808	48
614.202	54
616.596	40
618.988	46
621.38	42
623.769	56
626.159	52
628.549	48
630.936	48
633.324	50
635.71	44
638.096	44
640.481	48
642.866	50
645.248	54
647.632	50
650.013	50
652.394	50
654.773	44
657.154	48
659.532	50
661.91	42
664.286	46
666.663	46
669.038	48
671.412	42
673.786	42
676.159	50
678.532	42
680.903	40
683.274	44
685.644	44
688.014	46
690.382	50
692.749	46
695.116	40
697.482	48
699.846	48
702.211	40
704.574	44
706.938	44
709.299	50
711.661	52
714.021	42
716.381	50
718.739	44
721.097	52
723.455	54
725.811	44
728.167	48
730.521	52
732.877	46
735.23	54
737.582	48
739.934	52
742.285	48
744.635	40
746.985	52
749.334	44
751.682	42
754.028	42
756.374	42
758.72	42
761.065	52
763.408	48
765.752	44
768.095	48
770.436	44
772.777	50
775.116	52
777.456	50
779.794	56
782.133	52
784.469	44
786.806	44
789.141	48
791.476	44
793.809	52
796.143	56
798.476	44
800.807	48
803.138	48
805.468	48
807.797	52
810.125	50
812.453	52
814.78	42
817.106	52
819.432	54
821.757	44
824.081	46
826.403	44
828.726	48
831.048	48
833.368	46
835.688	50
838.008	44
840.326	48
842.644	50
844.96	50
847.277	50
849.592	50
851.906	52
854.221	48
856.534	52
858.846	48
861.159	50
863.469	54
865.779	52
868.088	46
870.396	56
872.704	44
875.011	46
877.318	48
879.623	52
881.928	46
884.232	46
886.536	56
888.838	44
891.139	46
893.44	42
895.741	40
898.039	48
900.339	44
902.637	48
904.933	44
907.231	52
909.526	54
911.821	46
914.115	52
916.408	48
918.701	46
920.993	44
923.283	46
925.575	54
927.864	52
930.153	46
932.441	50
934.728	46
937.014	50
939.3	46
941.585	48
943.87	48
946.154	44
948.437	52
950.719	52
953	48
955.28	52
957.56	50
959.84	56
962.117	48
964.395	50
966.673	52
968.948	40
971.224	42
973.498	42
975.773	52
978.045	52
980.317	50
982.59	48
984.86	48
987.13	48
989.399	52
991.669	40
993.937	48
996.204	50
998.47	50
1000.74	44
1003	52
1005.26	50
1007.53	50
1009.79	60
1012.05	52
1014.31	52
1016.57	48
1018.83	52
1021.09	48
1023.35	56
1025.61	52
1027.87	54
1030.12	48
1032.38	56
1034.63	52
1036.88	54
1039.14	56
1041.39	48
1043.64	52
1045.89	56
1048.14	60
1050.39	58
1052.64	56
1054.89	60
1057.14	52
1059.38	54
1061.63	56
1063.87	52
1066.12	62
1068.36	58
1070.6	60
1072.85	62
1075.09	62
1077.33	62
1079.57	54
1081.81	62
1084.05	66
1086.28	56
1088.52	52
1090.76	62
1092.99	62
1095.23	62
1097.46	58
1099.69	66
1101.93	60
1104.16	60
1106.39	62
1108.62	68
1110.85	60
1113.08	74
1115.31	68
1117.53	68
1119.76	68
1121.99	66
1124.21	76
1126.44	72
1128.66	72
1130.88	74
1133.11	72
1135.33	74
1137.55	70
1139.77	74
1141.99	76
1144.21	72
1146.43	70
1148.64	76
1150.86	72
1153.08	78
1155.29	68
1157.51	74
1159.72	70
1161.93	72
1164.14	72
1166.36	78
1168.57	78
1170.78	76
1172.99	72
1175.2	72
1177.4	82
1179.61	82
1181.82	74
1184.02	60
1186.23	82
1188.43	76
1190.64	82
1192.84	82
1195.04	82
1197.24	86
1199.45	80
1201.64	80.1223
1203.84	82.1984
1206.04	72.597
1208.24	94.9518
1210.44	84.9297
1212.64	82.8463
1214.83	75.0921
1217.03	82.3998
1219.22	83.9022
1221.41	83.8554
1223.61	80.5
1225.8	85.7245
1227.99	85.4403
1230.18	96.8036
1232.37	94.44
1234.56	96
1236.75	96.4107
1238.94	98.1152
1241.13	104.367
1243.31	98.6265
1245.5	107.674
1247.68	113.576
1249.87	111.021
1252.05	115.546
1254.24	123.573
1256.42	118.673
1258.6	122.02
1260.78	131.326
1262.96	130.458
1265.14	142.808
1267.32	152.49
1269.5	155.978
1271.67	163.3
1273.85	165.64
1276.03	168.852
1278.2	193.904
1280.38	192.745
1282.55	204.087
1284.72	226.788
1286.9	243.952
1289.07	247.185
1291.24	272.641
1293.41	282.285
1295.58	297.83
1297.75	327.381
1299.92	352.602
1302.09	385.524
1304.25	394.569
1306.42	429.159
1308.44	432
1310.61	492
1312.79	522
1314.97	526
1317.14	538
1319.31	542
1321.48	564
1323.66	542
1325.83	568
1328	570
1330.17	548
1332.34	528
1334.5	504
1336.67	484
1338.84	462
1341	444
1343.17	390
1345.33	360
1347.5	358
1349.66	312
1351.83	290
1353.99	284
1356.15	270
1358.31	258
1360.47	230
1362.63	228
1364.79	214
1366.94	196
1369.1	188
1371.26	178
1373.41	164
1375.57	162
1377.72	154
1379.88	158
1382.03	140
1384.18	142
1386.33	138
1388.48	132
1390.64	116
1392.79	114
1394.93	120
1397.08	122
1399.23	122
1401.38	106
1403.52	108
1405.67	104
1407.81	104
1409.96	106
1412.1	104
1414.24	96
1416.39	92
1418.53	94
1420.67	96
1422.81	98
1424.95	90
1427.09	94
1429.23	90
1431.36	94
1433.5	96
1435.64	88
1437.77	88
1439.91	88
1442.04	90
1444.17	92
1446.31	88
1448.44	80
1450.57	98
1452.7	86
1454.83	86
1456.96	90
1459.09	96
1461.22	80
1463.34	92
1465.47	80
1467.6	86
1469.72	84
1471.85	96
1473.97	80
1476.09	88
1478.22	84
1480.34	88
1482.46	80
1484.58	84
1486.7	86
1488.82	84
1490.94	88
1493.06	88
1495.17	96
1497.29	92
1499.41	92
1501.52	84
1503.64	86
1505.75	94
1507.86	96
1509.98	96
1512.09	86
1514.2	94
1516.31	94
1518.42	100
1520.53	98
1522.64	96
1524.74	108
1526.85	96
1528.96	110
1531.07	106
1533.17	108
1535.27	124
1537.38	128
1539.48	122
1541.58	120
1543.69	134
1545.79	146
1547.89	152
1549.99	152
1552.09	158
1554.19	174
1556.28	180
1558.38	176
1560.48	200
1562.57	204
1564.67	238
1566.76	240
1568.86	238
1570.95	260
1573.05	270
1575.14	272
1577.23	282
1579.32	282
1581.41	292
1583.5	292
1585.59	298
1587.68	290
1589.76	276
1591.85	276
1593.94	282
1596.02	282
1598.11	250
1600.19	266
1602.27	260
1604.36	260
1606.44	258
1608.52	256
1610.6	244
1612.68	250
1614.76	232
1616.84	230
1618.92	218
1621	194
1623.07	190
1625.15	170
1627.23	158
1629.3	158
1631.38	142
1633.45	134
1635.52	124
1637.59	114
1639.67	112
1641.74	102
1643.81	102
1645.88	94
1647.95	88
1650.02	86
1652.08	84
1654.15	72
1656.22	66
1658.28	68
1660.35	72
1662.41	62
1664.48	68
1666.54	64
1668.6	60
1670.67	62
1672.73	62
1674.79	68
1676.85	58
1678.91	54
1680.97	62
1683.03	54
1685.08	52
1687.14	54
1689.2	54
1691.25	52
1693.31	52
1695.36	56
1697.42	58
1699.47	58
1701.52	50
1703.57	52
1705.63	58
1707.68	54
1709.72	58
1711.77	56
1713.82	50
1715.87	52
1717.92	50
1719.97	56
1722.01	58
1724.06	58
1726.1	58
1728.15	52
1730.19	52
1732.23	50
1734.27	52
1736.32	48
1738.36	54
1740.4	56
1742.44	52
1744.48	52
1746.51	48
1748.55	54
1750.59	52
1752.63	56
1754.66	50
1756.7	52
1758.73	48
1760.77	50
1762.8	48
1764.83	44
1766.86	56
1768.9	50
1770.93	50
1772.96	60
1774.99	56
1777.02	46
1779.04	54
1781.07	48
1783.1	46
1785.13	48
1787.15	56
1789.18	52
1791.2	54
1793.23	46
1795.25	58
1797.27	42
1799.29	48
1801.31	50
1803.34	52
1805.36	52
1807.38	46
1809.39	50
1811.41	56
1813.43	52
1815.45	48
1817.46	50
1819.48	42
1821.49	48
1823.51	42
1825.52	50
1827.54	50
1829.55	48
1831.56	46
1833.57	48
1835.58	46
1837.59	48
1839.6	48
1841.61	52
1843.62	48
1845.63	44
1847.64	48
1849.64	44
1851.65	50
1853.65	44
1855.66	56
1857.66	48
1859.66	56
1861.67	40
1863.67	50
1865.67	50
1867.67	54
1869.67	46
1871.67	52
1873.67	44
1875.67	48
1877.67	40
1879.66	44
1881.66	56
1883.66	50
1885.65	46
1887.65	48
1889.64	48
1891.63	44
1893.63	44
1895.62	46
1897.61	48
1899.6	46
1901.59	50
1903.58	38
1905.57	38
1907.56	50
1909.55	44
1911.53	46
1913.52	46
1915.51	44
1917.49	46
1919.48	46
1921.46	44
1923.45	42
1925.43	48
1927.41	50
1929.39	50
1931.37	46
1933.36	50
1935.33	44
1937.31	46
1939.29	42
1941.27	50
1943.25	48
1945.23	48
1947.2	46
1949.18	48
1951.15	42
1953.13	46
1955.1	48
1957.08	42
1959.05	52
1961.02	44
1962.99	44
1964.96	50
1966.93	44
1968.9	46
1970.87	46
1972.84	42
1974.81	48
1976.77	38
1978.74	46
1980.71	46
1982.67	48
1984.64	48
1986.6	48
1988.57	48
1990.53	46
1992.49	46
1994.45	48
1996.41	42
1998.37	42
1999.35	40