File: muestras/LIG/fproof_18.txt
#Acq. time (s)=	10
#Accumulations=	2
#Range (cm-¹)=	100...2000
#Windows=	2
#Autofocus=	Off
#AutoExposure=	Off
#Spike filter=	Multiple accum.
#Delay time (s)=	0
#Binning=	1
#Readout mode=	Signal
#DeNoise=	Off
#ICS correction=	Off
#Dark correction=	Off
#Inst. Process=	Off
#Instrument=	LabRAM HR Evol
#Detector=	Syncerity OE
#Objective=	x100_VIS_LWD
#Grating=	600 (500nm)
#ND Filter=	25%
#Laser=	633nm_Edge
#Hole=	100.021
#Range=	Visible
#Project=	LIG
#Sample=	proof
#Site=
#Title=	fproof
#Remark=
#Date=	07.03.2023 13:14
#Acquired=	07.03.2023 13:14:05
101.054	38
103.621	46
106.187	38
108.753	40
111.317	40
113.881	36
116.443	32
119.005	40
121.566	36
124.126	28
126.685	36
129.243	38
131.801	38
134.357	36
136.911	40
139.466	44
142.021	32
144.574	34
147.126	34
149.676	38
152.227	34
154.777	32
157.325	36
159.873	40
162.419	32
164.966	42
167.51	36
170.055	38
172.598	40
175.141	36
177.682	42
180.222	34
182.763	34
185.302	34
187.839	40
190.378	32
192.914	34
195.449	36
197.983	42
200.517	38
203.05	42
205.582	38
208.113	46
210.643	40
213.173	42
215.701	48
218.229	40
220.756	36
223.282	42
225.808	42
228.331	38
230.855	40
233.378	42
235.9	38
238.419	38
240.94	36
243.46	42
245.977	34
248.495	40
251.011	32
253.527	40
256.041	38
258.556	32
261.068	30
263.58	40
266.092	40
268.603	46
271.112	38
273.622	36
276.129	40
278.636	40
281.142	48
283.647	36
286.152	38
288.655	38
291.158	42
293.66	36
296.161	38
298.661	38
301.161	36
303.66	36
306.158	38
308.655	40
311.151	30
313.645	34
316.14	38
318.634	42
321.125	38
323.618	36
326.109	34
328.598	34
331.088	44
333.576	38
336.064	42
338.55	34
341.037	34
343.521	40
346.005	40
348.489	34
350.971	40
353.453	36
355.935	44
358.414	40
360.893	36
363.371	34
365.848	40
368.325	34
370.801	42
373.275	36
375.75	42
378.223	38
380.695	42
383.167	40
385.638	38
388.108	46
390.577	34
393.044	40
395.512	40
397.979	36
400.445	32
402.909	36
405.374	36
407.836	38
410.299	40
412.762	30
415.221	42
417.681	38
420.141	40
422.598	42
425.057	38
427.513	42
429.968	36
432.424	36
434.878	36
437.33	42
439.783	36
442.234	36
444.685	38
447.136	36
449.585	38
452.033	40
454.48	38
456.927	42
459.372	42
461.817	42
464.261	40
466.705	34
469.147	36
471.589	40
474.029	38
476.47	48
478.909	34
481.347	36
483.785	32
486.221	38
488.657	32
491.093	36
493.527	38
495.96	36
498.393	40
500.824	38
503.256	40
505.686	34
508.115	32
510.543	28
512.972	38
515.399	42
517.825	36
520.25	36
522.674	34
525.097	40
527.52	40
529.942	34
532.364	38
534.784	42
537.204	38
539.623	38
542.041	36
544.458	38
546.874	40
549.289	42
551.705	44
554.118	40
556.531	34
558.944	38
561.355	36
563.766	40
566.175	40
568.585	46
570.992	42
573.401	36
575.807	32
578.212	38
580.618	38
583.022	36
585.425	40
587.827	40
590.229	42
592.631	38
595.031	40
597.43	44
599.829	34
602.226	38
604.623	32
607.02	40
609.415	38
611.808	40
614.202	38
616.596	32
618.988	42
621.38	40
623.769	42
626.159	44
628.549	38
630.936	40
633.324	46
635.71	40
638.096	42
640.481	38
642.866	42
645.248	36
647.632	38
650.013	34
652.394	40
654.773	36
657.154	38
659.532	34
661.91	40
664.286	38
666.663	44
669.038	40
671.412	38
673.786	28
676.159	38
678.532	36
680.903	44
683.274	34
685.644	44
688.014	36
690.382	34
692.749	36
695.116	38
697.482	36
699.846	38
702.211	40
704.574	42
706.938	38
709.299	32
711.661	38
714.021	44
716.381	42
718.739	38
721.097	38
723.455	44
725.811	44
728.167	32
730.521	38
732.877	42
735.23	38
737.582	34
739.934	40
742.285	44
744.635	38
746.985	36
749.334	30
751.682	38
754.028	38
756.374	38
758.72	28
761.065	42
763.408	36
765.752	34
768.095	36
770.436	40
772.777	38
775.116	40
777.456	40
779.794	38
782.133	40
784.469	38
786.806	36
789.141	40
791.476	38
793.809	42
796.143	40
798.476	34
800.807	38
803.138	36
805.468	38
807.797	38
810.125	38
812.453	38
814.78	40
817.106	42
819.432	34
821.757	40
824.081	38
826.403	34
828.726	40
831.048	38
833.368	40
835.688	42
838.008	42
840.326	46
842.644	40
844.96	36
847.277	40
849.592	42
851.906	34
854.221	36
856.534	42
858.846	38
861.159	44
863.469	42
865.779	36
868.088	42
870.396	36
872.704	42
875.011	42
877.318	40
879.623	40
881.928	40
884.232	36
886.536	32
888.838	36
891.139	34
893.44	38
895.741	32
898.039	38
900.339	40
902.637	44
904.933	32
907.231	42
909.526	34
911.821	42
914.115	32
916.408	34
918.701	40
920.993	40
923.283	36
925.575	38
927.864	34
930.153	42
932.441	40
934.728	40
937.014	28
939.3	38
941.585	40
943.87	38
946.154	38
948.437	44
950.719	36
953	42
955.28	38
957.56	34
959.84	34
962.117	44
964.395	34
966.673	42
968.948	36
971.224	40
973.498	40
975.773	32
978.045	38
980.317	40
982.59	40
984.86	42
987.13	40
989.399	34
991.669	42
993.937	34
996.204	36
998.47	46
1000.74	40
1003	46
1005.26	36
1007.53	36
1009.79	40
1012.05	42
1014.31	34
1016.57	30
1018.83	32
1021.09	42
1023.35	32
1025.61	40
1027.87	38
1030.12	34
1032.38	44
1034.63	36
1036.88	44
1039.14	46
1041.39	36
1043.64	40
1045.89	38
1048.14	42
1050.39	38
1052.64	34
1054.89	36
1057.14	38
1059.38	40
1061.63	42
1063.87	40
1066.12	40
1068.36	46
1070.6	40
1072.85	44
1075.09	42
1077.33	40
1079.57	44
1081.81	38
1084.05	40
1086.28	40
1088.52	48
1090.76	42
1092.99	44
1095.23	38
1097.46	48
1099.69	50
1101.93	36
1104.16	40
1106.39	38
1108.62	38
1110.85	44
1113.08	44
1115.31	42
1117.53	42
1119.76	50
1121.99	46
1124.21	42
1126.44	48
1128.66	48
1130.88	50
1133.11	50
1135.33	46
1137.55	46
1139.77	52
1141.99	50
1144.21	50
1146.43	50
1148.64	44
1150.86	52
1153.08	56
1155.29	50
1157.51	44
1159.72	46
1161.93	52
1164.14	50
1166.36	56
1168.57	42
1170.78	50
1172.99	46
1175.2	56
1177.4	44
1179.61	48
1181.82	54
1184.02	48
1186.23	48
1188.43	48
1190.64	48
1192.84	46
1195.04	46
1197.24	50
1199.45	52.01
1201.64	48.0611
1203.84	50.3232
1206.04	50.0049
1208.24	50.17
1210.44	59.521
1212.64	51.3269
1214.83	55.0007
1217.03	53.9901
1219.22	54.6658
1221.41	54.7908
1223.61	56.6346
1225.8	50.0063
1227.99	54.53
1230.18	54.3041
1232.37	55.0441
1234.56	58.2184
1236.75	55.6839
1238.94	59.27
1241.13	56.3383
1243.31	63.4878
1245.5	62.8743
1247.68	55.6352
1249.87	57.0227
1252.05	61.0409
1254.24	63.03
1256.42	61.7117
1258.6	65.7615
1260.78	62.7959
1262.96	70.1193
1265.14	64.8219
1267.32	67.3481
1269.5	67.6933
1271.67	69.8678
1273.85	73.6602
1276.03	71.7243
1278.2	74.7925
1280.38	77.9245
1282.55	83.3405
1284.72	84.5715
1286.9	81.8796
1289.07	91.4
1291.24	85.2907
1293.41	97.3999
1295.58	102.968
1297.75	101.287
1299.92	111.059
1302.09	114.199
1304.25	120.888
1306.42	122.15
1308.44	118
1310.61	122
1312.79	144
1314.97	126
1317.14	140
1319.31	162
1321.48	168
1323.66	174
1325.83	156
1328	170
1330.17	182
1332.34	180
1334.5	168
1336.67	164
1338.84	164
1341	162
1343.17	160
1345.33	164
1347.5	156
1349.66	146
1351.83	130
1353.99	136
1356.15	120
1358.31	120
1360.47	118
1362.63	98
1364.79	106
1366.94	100
1369.1	96
1371.26	94
1373.41	90
1375.57	94
1377.72	80
1379.88	78
1382.03	80
1384.18	84
1386.33	70
1388.48	74
1390.64	76
1392.79	72
1394.93	72
1397.08	68
1399.23	60
1401.38	64
1403.52	66
1405.67	72
1407.81	64
1409.96	64
1412.1	58
1414.24	64
1416.39	54
1418.53	64
1420.67	56
1422.81	58
1424.95	60
1427.09	58
1429.23	60
1431.36	52
1433.5	62
1435.64	52
1437.77	52
1439.91	48
1442.04	48
1444.17	58
1446.31	52
1448.44	56
1450.57	56
1452.7	50
1454.83	58
1456.96	56
1459.09	48
1461.22	56
1463.34	60
1465.47	50
1467.6	42
1469.72	50
1471.85	48
1473.97	58
1476.09	56
1478.22	56
1480.34	58
1482.46	50
1484.58	52
1486.7	58
1488.82	64
1490.94	58
1493.06	58
1495.17	56
1497.29	52
1499.41	50
1501.52	56
1503.64	52
1505.75	56
1507.86	52
1509.98	56
1512.09	52
1514.2	60
1516.31	58
1518.42	50
1520.53	50
1522.64	58
1524.74	54
1526.85	60
1528.96	58
1531.07	52
1533.17	66
1535.27	60
1537.38	64
1539.48	60
1541.58	72
1543.69	60
1545.79	72
1547.89	66
1549.99	74
1552.09	70
1554.19	74
1556.28	74
1558.38	62
1560.48	78
1562.57	88
1564.67	72
1566.76	88
1568.86	74
1570.95	92
1573.05	98
1575.14	100
1577.23	100
1579.32	106
1581.41	114
1583.5	116
1585.59	122
1587.68	112
1589.76	118
1591.85	118
1593.94	124
1596.02	122
1598.11	120
1600.19	130
1602.27	112
1604.36	126
1606.44	128
1608.52	116
1610.6	112
1612.68	124
1614.76	124
1616.84	120
1618.92	116
1621	118
1623.07	104
1625.15	94
1627.23	92
1629.3	82
1631.38	96
1633.45	90
1635.52	78
1637.59	74
1639.67	76
1641.74	70
1643.81	66
1645.88	72
1647.95	60
1650.02	56
1652.08	56
1654.15	52
1656.22	50
1658.28	48
1660.35	46
1662.41	46
1664.48	44
1666.54	46
1668.6	44
1670.67	48
1672.73	42
1674.79	44
1676.85	36
1678.91	50
1680.97	40
1683.03	36
1685.08	32
1687.14	36
1689.2	44
1691.25	42
1693.31	44
1695.36	42
1697.42	42
1699.47	38
1701.52	36
1703.57	32
1705.63	38
1707.68	46
1709.72	36
1711.77	38
1713.82	32
1715.87	38
1717.92	40
1719.97	42
1722.01	44
1724.06	36
1726.1	46
1728.15	38
1730.19	36
1732.23	42
1734.27	36
1736.32	44
1738.36	44
1740.4	48
1742.44	38
1744.48	36
1746.51	38
1748.55	44
1750.59	40
1752.63	42
1754.66	38
1756.7	38
1758.73	38
1760.77	46
1762.8	42
1764.83	40
1766.86	42
1768.9	42
1770.93	40
1772.96	40
1774.99	38
1777.02	40
1779.04	38
1781.07	40
1783.1	36
1785.13	36
1787.15	32
1789.18	34
1791.2	42
1793.23	38
1795.25	44
1797.27	38
1799.29	36
1801.31	40
1803.34	36
1805.36	36
1807.38	34
1809.39	38
1811.41	36
1813.43	36
1815.45	36
1817.46	36
1819.48	36
1821.49	34
1823.51	40
1825.52	32
1827.54	42
1829.55	36
1831.56	40
1833.57	36
1835.58	36
1837.59	46
1839.6	34
1841.61	42
1843.62	38
1845.63	34
1847.64	40
1849.64	38
1851.65	32
1853.65	40
1855.66	42
1857.66	30
1859.66	40
1861.67	34
1863.67	36
1865.67	36
1867.67	36
1869.67	50
1871.67	34
1873.67	38
1875.67	40
1877.67	34
1879.66	36
1881.66	40
1883.66	36
1885.65	36
1887.65	38
1889.64	34
1891.63	34
1893.63	44
1895.62	40
1897.61	38
1899.6	40
1901.59	38
1903.58	36
1905.57	32
1907.56	38
1909.55	40
1911.53	34
1913.52	42
1915.51	36
1917.49	44
1919.48	34
1921.46	36
1923.45	38
1925.43	34
1927.41	38
1929.39	34
1931.37	34
1933.36	34
1935.33	32
1937.31	36
1939.29	42
1941.27	34
1943.25	38
1945.23	38
1947.2	32
1949.18	38
1951.15	42
1953.13	37
1955.1	36
1957.08	38
1959.05	32
1961.02	34
1962.99	38
1964.96	38
1966.93	34
1968.9	32
1970.87	36
1972.84	40
1974.81	38
1976.77	36
1978.74	36
1980.71	36
1982.67	34
1984.64	28
1986.6	40
1988.57	38
1990.53	36
1992.49	38
1994.45	38
1996.41	34
1998.37	36
1999.35	34