File: muestras/LIG/fproof_07.txt
#Acq. time (s)=	10
#Accumulations=	2
#Range (cm-¹)=	100...2000
#Windows=	2
#Autofocus=	Off
#AutoExposure=	Off
#Spike filter=	Multiple accum.
#Delay time (s)=	0
#Binning=	1
#Readout mode=	Signal
#DeNoise=	Off
#ICS correction=	Off
#Dark correction=	Off
#Inst. Process=	Off
#Instrument=	LabRAM HR Evol
#Detector=	Syncerity OE
#Objective=	x100_VIS_LWD
#Grating=	600 (500nm)
#ND Filter=	5%
#Laser=	633nm_Edge
#Hole=	100.021
#Range=	Visible
#Project=	LIG
#Sample=	proof
#Site=
#Title=	fproof
#Remark=
#Date=	07.03.2023 12:37
#Acquired=	07.03.2023 12:37:42
101.054	30
103.621	30
106.187	34
108.753	38
111.317	34
113.881	26
116.443	32
119.005	36
121.566	32
124.126	32
126.685	32
129.243	36
131.801	28
134.357	30
136.911	32
139.466	34
142.021	32
144.574	26
147.126	32
149.676	28
152.227	28
154.777	28
157.325	28
159.873	28
162.419	26
164.966	32
167.51	32
170.055	30
172.598	30
175.141	30
177.682	30
180.222	34
182.763	32
185.302	26
187.839	28
190.378	26
192.914	32
195.449	32
197.983	34
200.517	34
203.05	28
205.582	34
208.113	28
210.643	32
213.173	36
215.701	32
218.229	34
220.756	32
223.282	28
225.808	26
228.331	38
230.855	32
233.378	30
235.9	40
238.419	30
240.94	30
243.46	30
245.977	28
248.495	24
251.011	28
253.527	32
256.041	32
258.556	32
261.068	32
263.58	32
266.092	32
268.603	32
271.112	30
273.622	32
276.129	22
278.636	32
281.142	36
283.647	28
286.152	32
288.655	30
291.158	32
293.66	38
296.161	26
298.661	32
301.161	36
303.66	34
306.158	32
308.655	32
311.151	30
313.645	30
316.14	34
318.634	30
321.125	32
323.618	26
326.109	36
328.598	26
331.088	28
333.576	28
336.064	38
338.55	30
341.037	34
343.521	32
346.005	30
348.489	26
350.971	30
353.453	32
355.935	30
358.414	26
360.893	28
363.371	30
365.848	28
368.325	34
370.801	34
373.275	28
375.75	30
378.223	34
380.695	28
383.167	32
385.638	36
388.108	34
390.577	34
393.044	32
395.512	30
397.979	30
400.445	34
402.909	32
405.374	36
407.836	32
410.299	30
412.762	30
415.221	32
417.681	34
420.141	34
422.598	28
425.057	32
427.513	34
429.968	34
432.424	34
434.878	30
437.33	36
439.783	40
442.234	32
444.685	34
447.136	36
449.585	32
452.033	34
454.48	32
456.927	32
459.372	32
461.817	30
464.261	36
466.705	34
469.147	32
471.589	32
474.029	28
476.47	32
478.909	32
481.347	30
483.785	28
486.221	30
488.657	30
491.093	28
493.527	30
495.96	28
498.393	22
500.824	22
503.256	36
505.686	34
508.115	28
510.543	32
512.972	26
515.399	28
517.825	34
520.25	32
522.674	30
525.097	34
527.52	32
529.942	22
532.364	32
534.784	34
537.204	30
539.623	32
542.041	34
544.458	30
546.874	32
549.289	32
551.705	36
554.118	30
556.531	32
558.944	28
561.355	32
563.766	28
566.175	38
568.585	30
570.992	36
573.401	24
575.807	28
578.212	30
580.618	32
583.022	32
585.425	32
587.827	36
590.229	26
592.631	24
595.031	34
597.43	42
599.829	36
602.226	32
604.623	36
607.02	32
609.415	38
611.808	26
614.202	32
616.596	30
618.988	32
621.38	28
623.769	38
626.159	32
628.549	34
630.936	28
633.324	26
635.71	36
638.096	36
640.481	28
642.866	30
645.248	30
647.632	26
650.013	38
652.394	26
654.773	30
657.154	30
659.532	30
661.91	32
664.286	24
666.663	30
669.038	30
671.412	28
673.786	34
676.159	22
678.532	36
680.903	26
683.274	30
685.644	34
688.014	40
690.382	30
692.749	26
695.116	30
697.482	34
699.846	32
702.211	34
704.574	32
706.938	34
709.299	28
711.661	30
714.021	40
716.381	40
718.739	30
721.097	34
723.455	32
725.811	34
728.167	34
730.521	28
732.877	34
735.23	30
737.582	24
739.934	34
742.285	38
744.635	34
746.985	38
749.334	32
751.682	34
754.028	32
756.374	38
758.72	28
761.065	34
763.408	34
765.752	40
768.095	36
770.436	32
772.777	34
775.116	36
777.456	34
779.794	34
782.133	36
784.469	34
786.806	32
789.141	32
791.476	34
793.809	36
796.143	30
798.476	38
800.807	36
803.138	34
805.468	28
807.797	32
810.125	36
812.453	38
814.78	32
817.106	38
819.432	24
821.757	34
824.081	28
826.403	26
828.726	38
831.048	30
833.368	28
835.688	32
838.008	34
840.326	26
842.644	32
844.96	36
847.277	40
849.592	34
851.906	36
854.221	30
856.534	26
858.846	32
861.159	36
863.469	38
865.779	32
868.088	24
870.396	34
872.704	32
875.011	34
877.318	34
879.623	36
881.928	34
884.232	38
886.536	34
888.838	30
891.139	32
893.44	42
895.741	30
898.039	36
900.339	36
902.637	36
904.933	38
907.231	30
909.526	34
911.821	28
914.115	38
916.408	30
918.701	26
920.993	34
923.283	34
925.575	32
927.864	38
930.153	32
932.441	30
934.728	30
937.014	36
939.3	28
941.585	30
943.87	30
946.154	32
948.437	30
950.719	28
953	26
955.28	34
957.56	34
959.84	32
962.117	32
964.395	34
966.673	26
968.948	32
971.224	38
973.498	36
975.773	28
978.045	28
980.317	34
982.59	36
984.86	32
987.13	32
989.399	32
991.669	30
993.937	38
996.204	34
998.47	32
1000.74	28
1003	32
1005.26	30
1007.53	36
1009.79	34
1012.05	30
1014.31	34
1016.57	36
1018.83	34
1021.09	34
1023.35	28
1025.61	34
1027.87	32
1030.12	30
1032.38	32
1034.63	42
1036.88	34
1039.14	24
1041.39	34
1043.64	34
1045.89	32
1048.14	36
1050.39	30
1052.64	28
1054.89	28
1057.14	28
1059.38	28
1061.63	34
1063.87	32
1066.12	30
1068.36	34
1070.6	32
1072.85	32
1075.09	34
1077.33	28
1079.57	32
1081.81	32
1084.05	34
1086.28	36
1088.52	32
1090.76	36
1092.99	32
1095.23	30
1097.46	42
1099.69	38
1101.93	32
1104.16	32
1106.39	36
1108.62	34
1110.85	36
1113.08	42
1115.31	34
1117.53	36
1119.76	34
1121.99	38
1124.21	36
1126.44	34
1128.66	36
1130.88	32
1133.11	34
1135.33	40
1137.55	34
1139.77	40
1141.99	40
1144.21	36
1146.43	34
1148.64	36
1150.86	36
1153.08	40
1155.29	32
1157.51	38
1159.72	28
1161.93	42
1164.14	36
1166.36	32
1168.57	42
1170.78	46
1172.99	44
1175.2	40
1177.4	42
1179.61	34
1181.82	42
1184.02	40
1186.23	40
1188.43	34
1190.64	36
1192.84	36
1195.04	38
1197.24	36
1199.45	32.02
1201.64	36.1111
1203.84	37.8926
1206.04	36.1589
1208.24	39.6174
1210.44	40.2406
1212.64	46.25
1214.83	36.7407
1217.03	33.47
1219.22	36.0261
1221.41	37.0146
1223.61	41.3173
1225.8	40.53
1227.99	41.6134
1230.18	43.4139
1232.37	37.0227
1234.56	39.35
1236.75	41.3677
1238.94	40.012
1241.13	45.3517
1243.31	38.4622
1245.5	38.2193
1247.68	40.0412
1249.87	40.6027
1252.05	42.2136
1254.24	42.02
1256.42	43.7117
1258.6	43.0571
1260.78	48.658
1262.96	46.83
1265.14	46
1267.32	51.2942
1269.5	47.0306
1271.67	46.1582
1273.85	50.3398
1276.03	47.8086
1278.2	51.9538
1280.38	56.5886
1282.55	53.9305
1284.72	57.4747
1286.9	61.2341
1289.07	64.6
1291.24	67.1207
1293.41	67.4376
1295.58	70.048
1297.75	70.333
1299.92	76.4594
1302.09	77.8489
1304.25	80.1017
1306.42	83.4038
1308.44	100
1310.61	82
1312.79	94
1314.97	94
1317.14	114
1319.31	106
1321.48	110
1323.66	118
1325.83	130
1328	116
1330.17	122
1332.34	132
1334.5	128
1336.67	120
1338.84	116
1341	114
1343.17	110
1345.33	114
1347.5	114
1349.66	90
1351.83	96
1353.99	96
1356.15	92
1358.31	78
1360.47	82
1362.63	76
1364.79	76
1366.94	58
1369.1	68
1371.26	76
1373.41	62
1375.57	52
1377.72	56
1379.88	60
1382.03	54
1384.18	46
1386.33	52
1388.48	56
1390.64	56
1392.79	40
1394.93	50
1397.08	50
1399.23	46
1401.38	44
1403.52	42
1405.67	38
1407.81	38
1409.96	48
1412.1	46
1414.24	42
1416.39	44
1418.53	38
1420.67	48
1422.81	48
1424.95	42
1427.09	38
1429.23	44
1431.36	42
1433.5	34
1435.64	40
1437.77	38
1439.91	38
1442.04	44
1444.17	46
1446.31	36
1448.44	46
1450.57	36
1452.7	40
1454.83	38
1456.96	38
1459.09	28
1461.22	42
1463.34	40
1465.47	40
1467.6	38
1469.72	36
1471.85	40
1473.97	50
1476.09	36
1478.22	38
1480.34	44
1482.46	40
1484.58	38
1486.7	42
1488.82	40
1490.94	36
1493.06	42
1495.17	42
1497.29	46
1499.41	34
1501.52	40
1503.64	36
1505.75	40
1507.86	44
1509.98	36
1512.09	46
1514.2	40
1516.31	42
1518.42	38
1520.53	48
1522.64	44
1524.74	46
1526.85	46
1528.96	46
1531.07	48
1533.17	44
1535.27	48
1537.38	50
1539.48	46
1541.58	54
1543.69	50
1545.79	48
1547.89	42
1549.99	50
1552.09	48
1554.19	52
1556.28	50
1558.38	58
1560.48	62
1562.57	64
1564.67	62
1566.76	70
1568.86	64
1570.95	68
1573.05	68
1575.14	64
1577.23	72
1579.32	68
1581.41	80
1583.5	74
1585.59	86
1587.68	86
1589.76	82
1591.85	88
1593.94	80
1596.02	76
1598.11	78
1600.19	78
1602.27	76
1604.36	82
1606.44	76
1608.52	74
1610.6	72
1612.68	80
1614.76	64
1616.84	80
1618.92	74
1621	66
1623.07	74
1625.15	70
1627.23	70
1629.3	56
1631.38	68
1633.45	70
1635.52	54
1637.59	48
1639.67	56
1641.74	56
1643.81	48
1645.88	52
1647.95	40
1650.02	46
1652.08	40
1654.15	46
1656.22	40
1658.28	36
1660.35	40
1662.41	32
1664.48	34
1666.54	32
1668.6	36
1670.67	32
1672.73	40
1674.79	34
1676.85	40
1678.91	28
1680.97	36
1683.03	34
1685.08	32
1687.14	34
1689.2	36
1691.25	38
1693.31	36
1695.36	34
1697.42	34
1699.47	34
1701.52	34
1703.57	36
1705.63	34
1707.68	26
1709.72	26
1711.77	34
1713.82	26
1715.87	28
1717.92	26
1719.97	30
1722.01	40
1724.06	36
1726.1	40
1728.15	36
1730.19	32
1732.23	30
1734.27	32
1736.32	32
1738.36	30
1740.4	26
1742.44	30
1744.48	32
1746.51	34
1748.55	34
1750.59	32
1752.63	36
1754.66	24
1756.7	32
1758.73	36
1760.77	32
1762.8	38
1764.83	32
1766.86	28
1768.9	32
1770.93	26
1772.96	40
1774.99	32
1777.02	34
1779.04	34
1781.07	38
1783.1	32
1785.13	30
1787.15	32
1789.18	28
1791.2	36
1793.23	28
1795.25	32
1797.27	34
1799.29	30
1801.31	32
1803.34	36
1805.36	38
1807.38	30
1809.39	26
1811.41	34
1813.43	30
1815.45	36
1817.46	32
1819.48	32
1821.49	30
1823.51	32
1825.52	30
1827.54	36
1829.55	26
1831.56	36
1833.57	34
1835.58	28
1837.59	28
1839.6	22
1841.61	30
1843.62	34
1845.63	30
1847.64	34
1849.64	30
1851.65	36
1853.65	36
1855.66	36
1857.66	34
1859.66	34
1861.67	36
1863.67	36
1865.67	30
1867.67	30
1869.67	26
1871.67	32
1873.67	32
1875.67	32
1877.67	30
1879.66	30
1881.66	34
1883.66	26
1885.65	24
1887.65	36
1889.64	40
1891.63	30
1893.63	26
1895.62	34
1897.61	30
1899.6	30
1901.59	30
1903.58	28
1905.57	34
1907.56	32
1909.55	32
1911.53	32
1913.52	28
1915.51	30
1917.49	36
1919.48	28
1921.46	26
1923.45	38
1925.43	34
1927.41	32
1929.39	30
1931.37	30
1933.36	30
1935.33	36
1937.31	32
1939.29	26
1941.27	30
1943.25	36
1945.23	36
1947.2	32
1949.18	22
1951.15	26
1953.13	30
1955.1	30
1957.08	32
1959.05	30
1961.02	28
1962.99	32
1964.96	28
1966.93	36
1968.9	32
1970.87	34
1972.84	30
1974.81	32
1976.77	30
1978.74	36
1980.71	30
1982.67	30
1984.64	32
1986.6	24
1988.57	34
1990.53	32
1992.49	32
1994.45	34
1996.41	32
1998.37	30
1999.35	26