File: muestras/LIG/fproof_05.txt
#Acq. time (s)=	10
#Accumulations=	2
#Range (cm-¹)=	100...2000
#Windows=	2
#Autofocus=	Off
#AutoExposure=	Off
#Spike filter=	Multiple accum.
#Delay time (s)=	0
#Binning=	1
#Readout mode=	Signal
#DeNoise=	Off
#ICS correction=	Off
#Dark correction=	Off
#Inst. Process=	Off
#Instrument=	LabRAM HR Evol
#Detector=	Syncerity OE
#Objective=	x100_VIS_LWD
#Grating=	600 (500nm)
#ND Filter=	50%
#Laser=	633nm_Edge
#Hole=	100.021
#Range=	Visible
#Project=	LIG
#Sample=	proof
#Site=
#Title=	fproof
#Remark=
#Date=	07.03.2023 12:25
#Acquired=	07.03.2023 12:25:03
101.054	44
103.621	48
106.187	48
108.753	46
111.317	42
113.881	46
116.443	44
119.005	48
121.566	44
124.126	46
126.685	52
129.243	46
131.801	48
134.357	42
136.911	44
139.466	44
142.021	40
144.574	44
147.126	42
149.676	38
152.227	40
154.777	40
157.325	40
159.873	36
162.419	42
164.966	42
167.51	40
170.055	52
172.598	42
175.141	50
177.682	50
180.222	40
182.763	38
185.302	38
187.839	48
190.378	46
192.914	50
195.449	40
197.983	46
200.517	44
203.05	44
205.582	46
208.113	48
210.643	50
213.173	48
215.701	50
218.229	52
220.756	46
223.282	40
225.808	44
228.331	40
230.855	38
233.378	46
235.9	42
238.419	42
240.94	38
243.46	50
245.977	44
248.495	40
251.011	42
253.527	48
256.041	44
258.556	40
261.068	50
263.58	44
266.092	42
268.603	50
271.112	46
273.622	42
276.129	48
278.636	44
281.142	42
283.647	46
286.152	40
288.655	48
291.158	44
293.66	40
296.161	52
298.661	42
301.161	38
303.66	40
306.158	40
308.655	50
311.151	36
313.645	42
316.14	40
318.634	36
321.125	36
323.618	38
326.109	34
328.598	42
331.088	46
333.576	46
336.064	42
338.55	44
341.037	46
343.521	42
346.005	46
348.489	42
350.971	40
353.453	40
355.935	50
358.414	44
360.893	44
363.371	42
365.848	42
368.325	40
370.801	38
373.275	46
375.75	42
378.223	48
380.695	34
383.167	30
385.638	36
388.108	46
390.577	48
393.044	44
395.512	42
397.979	42
400.445	48
402.909	42
405.374	48
407.836	42
410.299	46
412.762	48
415.221	44
417.681	46
420.141	42
422.598	38
425.057	44
427.513	40
429.968	42
432.424	40
434.878	36
437.33	34
439.783	48
442.234	44
444.685	44
447.136	46
449.585	46
452.033	46
454.48	44
456.927	48
459.372	38
461.817	42
464.261	40
466.705	42
469.147	44
471.589	42
474.029	44
476.47	42
478.909	48
481.347	44
483.785	40
486.221	44
488.657	42
491.093	40
493.527	40
495.96	40
498.393	50
500.824	42
503.256	36
505.686	40
508.115	48
510.543	40
512.972	40
515.399	44
517.825	40
520.25	48
522.674	48
525.097	42
527.52	38
529.942	52
532.364	32
534.784	40
537.204	44
539.623	38
542.041	42
544.458	42
546.874	34
549.289	40
551.705	46
554.118	44
556.531	42
558.944	46
561.355	46
563.766	44
566.175	46
568.585	44
570.992	40
573.401	44
575.807	48
578.212	46
580.618	44
583.022	36
585.425	46
587.827	48
590.229	44
592.631	44
595.031	40
597.43	44
599.829	40
602.226	44
604.623	38
607.02	38
609.415	46
611.808	44
614.202	48
616.596	42
618.988	40
621.38	38
623.769	44
626.159	42
628.549	42
630.936	42
633.324	42
635.71	40
638.096	46
640.481	50
642.866	44
645.248	42
647.632	44
650.013	46
652.394	44
654.773	40
657.154	40
659.532	38
661.91	42
664.286	44
666.663	46
669.038	46
671.412	40
673.786	44
676.159	46
678.532	48
680.903	44
683.274	42
685.644	40
688.014	42
690.382	38
692.749	44
695.116	40
697.482	48
699.846	44
702.211	44
704.574	46
706.938	36
709.299	38
711.661	44
714.021	40
716.381	38
718.739	44
721.097	46
723.455	44
725.811	42
728.167	46
730.521	44
732.877	42
735.23	46
737.582	38
739.934	34
742.285	44
744.635	46
746.985	42
749.334	40
751.682	40
754.028	40
756.374	46
758.72	38
761.065	46
763.408	48
765.752	46
768.095	36
770.436	46
772.777	46
775.116	40
777.456	42
779.794	44
782.133	52
784.469	48
786.806	38
789.141	44
791.476	50
793.809	40
796.143	40
798.476	40
800.807	44
803.138	42
805.468	46
807.797	42
810.125	38
812.453	42
814.78	42
817.106	42
819.432	48
821.757	42
824.081	44
826.403	42
828.726	42
831.048	44
833.368	44
835.688	44
838.008	50
840.326	42
842.644	42
844.96	44
847.277	44
849.592	42
851.906	42
854.221	56
856.534	46
858.846	42
861.159	40
863.469	46
865.779	50
868.088	42
870.396	46
872.704	48
875.011	40
877.318	42
879.623	36
881.928	34
884.232	38
886.536	36
888.838	42
891.139	36
893.44	44
895.741	42
898.039	42
900.339	44
902.637	36
904.933	30
907.231	40
909.526	38
911.821	40
914.115	44
916.408	40
918.701	46
920.993	44
923.283	40
925.575	44
927.864	46
930.153	48
932.441	46
934.728	38
937.014	42
939.3	50
941.585	44
943.87	36
946.154	48
948.437	36
950.719	40
953	40
955.28	36
957.56	44
959.84	40
962.117	44
964.395	38
966.673	40
968.948	42
971.224	40
973.498	46
975.773	42
978.045	40
980.317	50
982.59	32
984.86	50
987.13	42
989.399	40
991.669	44
993.937	52
996.204	42
998.47	42
1000.74	44
1003	40
1005.26	40
1007.53	48
1009.79	40
1012.05	44
1014.31	42
1016.57	40
1018.83	48
1021.09	46
1023.35	44
1025.61	48
1027.87	44
1030.12	44
1032.38	50
1034.63	46
1036.88	46
1039.14	52
1041.39	44
1043.64	44
1045.89	42
1048.14	44
1050.39	48
1052.64	42
1054.89	40
1057.14	40
1059.38	44
1061.63	50
1063.87	50
1066.12	42
1068.36	34
1070.6	44
1072.85	48
1075.09	50
1077.33	46
1079.57	44
1081.81	46
1084.05	44
1086.28	42
1088.52	44
1090.76	54
1092.99	44
1095.23	50
1097.46	44
1099.69	52
1101.93	50
1104.16	40
1106.39	44
1108.62	46
1110.85	44
1113.08	38
1115.31	46
1117.53	48
1119.76	54
1121.99	46
1124.21	48
1126.44	52
1128.66	38
1130.88	52
1133.11	54
1135.33	48
1137.55	52
1139.77	50
1141.99	48
1144.21	48
1146.43	52
1148.64	52
1150.86	44
1153.08	56
1155.29	50
1157.51	48
1159.72	54
1161.93	52
1164.14	56
1166.36	58
1168.57	54
1170.78	50
1172.99	52
1175.2	50
1177.4	56
1179.61	54
1181.82	58
1184.02	58
1186.23	54
1188.43	46
1190.64	58
1192.84	48
1195.04	58
1197.24	52
1199.45	46.04
1201.64	57.8528
1203.84	48.45
1206.04	50.1589
1208.24	61.7873
1210.44	57.4903
1212.64	55.8463
1214.83	54.0942
1217.03	55.52
1219.22	52.9903
1221.41	58.9854
1223.61	51.1173
1225.8	59.8045
1227.99	57.5931
1230.18	58.0141
1232.37	58.6314
1234.56	57.9921
1236.75	63.1823
1238.94	64.3276
1241.13	56.6766
1243.31	62.1787
1245.5	57.8936
1247.68	60.5692
1249.87	60.4187
1252.05	67.6927
1254.24	60.7685
1256.42	60.03
1258.6	66.7529
1260.78	64.4561
1262.96	63.9096
1265.14	66.0362
1267.32	65.9019
1269.5	70.3074
1271.67	72.1022
1273.85	75.0798
1276.03	72.3915
1278.2	76.2151
1280.38	80.3127
1282.55	80.8778
1284.72	77.5322
1286.9	88.9082
1289.07	93.1078
1291.24	92.0629
1293.41	96.2424
1295.58	96.162
1297.75	100.092
1299.92	104.191
1302.09	104.997
1304.25	105.861
1306.42	119.121
1308.44	112
1310.61	120
1312.79	148
1314.97	132
1317.14	134
1319.31	136
1321.48	142
1323.66	144
1325.83	152
1328	134
1330.17	148
1332.34	150
1334.5	146
1336.67	144
1338.84	130
1341	130
1343.17	124
1345.33	124
1347.5	130
1349.66	108
1351.83	108
1353.99	102
1356.15	110
1358.31	104
1360.47	88
1362.63	90
1364.79	100
1366.94	92
1369.1	84
1371.26	86
1373.41	88
1375.57	84
1377.72	76
1379.88	76
1382.03	68
1384.18	74
1386.33	74
1388.48	80
1390.64	70
1392.79	68
1394.93	68
1397.08	72
1399.23	64
1401.38	70
1403.52	62
1405.67	72
1407.81	68
1409.96	62
1412.1	70
1414.24	64
1416.39	60
1418.53	64
1420.67	60
1422.81	64
1424.95	64
1427.09	60
1429.23	64
1431.36	62
1433.5	56
1435.64	58
1437.77	54
1439.91	60
1442.04	62
1444.17	64
1446.31	62
1448.44	50
1450.57	54
1452.7	64
1454.83	58
1456.96	58
1459.09	52
1461.22	54
1463.34	64
1465.47	56
1467.6	56
1469.72	54
1471.85	62
1473.97	58
1476.09	60
1478.22	54
1480.34	58
1482.46	54
1484.58	58
1486.7	60
1488.82	58
1490.94	58
1493.06	56
1495.17	60
1497.29	64
1499.41	66
1501.52	54
1503.64	58
1505.75	64
1507.86	56
1509.98	56
1512.09	52
1514.2	58
1516.31	58
1518.42	58
1520.53	56
1522.64	60
1524.74	70
1526.85	58
1528.96	66
1531.07	64
1533.17	62
1535.27	58
1537.38	64
1539.48	56
1541.58	72
1543.69	64
1545.79	68
1547.89	70
1549.99	70
1552.09	72
1554.19	74
1556.28	70
1558.38	82
1560.48	80
1562.57	82
1564.67	88
1566.76	78
1568.86	84
1570.95	80
1573.05	94
1575.14	96
1577.23	88
1579.32	96
1581.41	92
1583.5	102
1585.59	100
1587.68	102
1589.76	106
1591.85	100
1593.94	108
1596.02	104
1598.11	94
1600.19	96
1602.27	104
1604.36	106
1606.44	96
1608.52	96
1610.6	98
1612.68	104
1614.76	86
1616.84	94
1618.92	102
1621	94
1623.07	76
1625.15	88
1627.23	76
1629.3	74
1631.38	70
1633.45	68
1635.52	74
1637.59	68
1639.67	58
1641.74	60
1643.81	58
1645.88	54
1647.95	56
1650.02	52
1652.08	54
1654.15	56
1656.22	58
1658.28	56
1660.35	44
1662.41	58
1664.48	56
1666.54	40
1668.6	48
1670.67	46
1672.73	46
1674.79	42
1676.85	50
1678.91	44
1680.97	48
1683.03	42
1685.08	42
1687.14	40
1689.2	44
1691.25	46
1693.31	44
1695.36	46
1697.42	48
1699.47	48
1701.52	50
1703.57	42
1705.63	38
1707.68	40
1709.72	40
1711.77	44
1713.82	46
1715.87	44
1717.92	48
1719.97	46
1722.01	44
1724.06	40
1726.1	46
1728.15	50
1730.19	34
1732.23	42
1734.27	50
1736.32	48
1738.36	46
1740.4	42
1742.44	40
1744.48	42
1746.51	42
1748.55	38
1750.59	42
1752.63	40
1754.66	40
1756.7	42
1758.73	38
1760.77	42
1762.8	48
1764.83	46
1766.86	38
1768.9	44
1770.93	40
1772.96	40
1774.99	40
1777.02	46
1779.04	38
1781.07	44
1783.1	52
1785.13	46
1787.15	42
1789.18	42
1791.2	42
1793.23	48
1795.25	36
1797.27	46
1799.29	36
1801.31	42
1803.34	44
1805.36	42
1807.38	36
1809.39	40
1811.41	38
1813.43	42
1815.45	44
1817.46	46
1819.48	44
1821.49	50
1823.51	44
1825.52	34
1827.54	38
1829.55	34
1831.56	34
1833.57	36
1835.58	38
1837.59	48
1839.6	40
1841.61	36
1843.62	38
1845.63	40
1847.64	40
1849.64	46
1851.65	42
1853.65	32
1855.66	38
1857.66	32
1859.66	40
1861.67	40
1863.67	38
1865.67	38
1867.67	48
1869.67	40
1871.67	38
1873.67	38
1875.67	44
1877.67	40
1879.66	40
1881.66	42
1883.66	38
1885.65	40
1887.65	44
1889.64	42
1891.63	34
1893.63	34
1895.62	40
1897.61	46
1899.6	40
1901.59	40
1903.58	36
1905.57	42
1907.56	42
1909.55	40
1911.53	42
1913.52	38
1915.51	40
1917.49	48
1919.48	32
1921.46	38
1923.45	40
1925.43	46
1927.41	42
1929.39	38
1931.37	44
1933.36	40
1935.33	34
1937.31	44
1939.29	34
1941.27	34
1943.25	40
1945.23	40
1947.2	44
1949.18	38
1951.15	40
1953.13	42
1955.1	40
1957.08	42
1959.05	42
1961.02	40
1962.99	38
1964.96	42
1966.93	38
1968.9	40
1970.87	38
1972.84	42
1974.81	34
1976.77	42
1978.74	36
1980.71	38
1982.67	42
1984.64	40
1986.6	42
1988.57	38
1990.53	40
1992.49	34
1994.45	30
1996.41	36
1998.37	34
1999.35	42