File: muestras/LIG/fproof_15.txt
#Acq. time (s)=	10
#Accumulations=	2
#Range (cm-¹)=	100...2000
#Windows=	2
#Autofocus=	Off
#AutoExposure=	Off
#Spike filter=	Multiple accum.
#Delay time (s)=	0
#Binning=	1
#Readout mode=	Signal
#DeNoise=	Off
#ICS correction=	Off
#Dark correction=	Off
#Inst. Process=	Off
#Instrument=	LabRAM HR Evol
#Detector=	Syncerity OE
#Objective=	x100_VIS_LWD
#Grating=	600 (500nm)
#ND Filter=	25%
#Laser=	633nm_Edge
#Hole=	100.021
#Range=	Visible
#Project=	LIG
#Sample=	proof
#Site=
#Title=	fproof
#Remark=
#Date=	07.03.2023 13:08
#Acquired=	07.03.2023 13:08:12
101.054	42
103.621	40
106.187	42
108.753	40
111.317	40
113.881	42
116.443	46
119.005	46
121.566	48
124.126	40
126.685	40
129.243	34
131.801	36
134.357	40
136.911	38
139.466	42
142.021	44
144.574	32
147.126	38
149.676	44
152.227	46
154.777	38
157.325	26
159.873	38
162.419	32
164.966	40
167.51	38
170.055	44
172.598	38
175.141	34
177.682	40
180.222	34
182.763	40
185.302	36
187.839	38
190.378	40
192.914	36
195.449	40
197.983	40
200.517	46
203.05	34
205.582	28
208.113	36
210.643	36
213.173	44
215.701	34
218.229	46
220.756	38
223.282	42
225.808	36
228.331	40
230.855	40
233.378	36
235.9	40
238.419	38
240.94	46
243.46	46
245.977	36
248.495	38
251.011	38
253.527	32
256.041	46
258.556	46
261.068	40
263.58	42
266.092	40
268.603	44
271.112	34
273.622	42
276.129	40
278.636	38
281.142	42
283.647	42
286.152	38
288.655	24
291.158	48
293.66	38
296.161	30
298.661	40
301.161	40
303.66	42
306.158	38
308.655	34
311.151	42
313.645	40
316.14	38
318.634	42
321.125	40
323.618	38
326.109	42
328.598	38
331.088	42
333.576	38
336.064	42
338.55	42
341.037	42
343.521	42
346.005	34
348.489	36
350.971	38
353.453	40
355.935	54
358.414	38
360.893	40
363.371	40
365.848	44
368.325	42
370.801	34
373.275	38
375.75	38
378.223	42
380.695	42
383.167	38
385.638	42
388.108	36
390.577	40
393.044	42
395.512	40
397.979	38
400.445	48
402.909	42
405.374	44
407.836	34
410.299	32
412.762	36
415.221	40
417.681	40
420.141	40
422.598	40
425.057	42
427.513	36
429.968	36
432.424	40
434.878	40
437.33	42
439.783	34
442.234	38
444.685	34
447.136	38
449.585	38
452.033	46
454.48	42
456.927	40
459.372	36
461.817	40
464.261	42
466.705	42
469.147	32
471.589	38
474.029	38
476.47	44
478.909	38
481.347	40
483.785	34
486.221	40
488.657	40
491.093	48
493.527	36
495.96	32
498.393	36
500.824	36
503.256	38
505.686	44
508.115	38
510.543	32
512.972	42
515.399	36
517.825	38
520.25	40
522.674	40
525.097	34
527.52	36
529.942	42
532.364	38
534.784	38
537.204	40
539.623	44
542.041	38
544.458	34
546.874	46
549.289	42
551.705	38
554.118	40
556.531	50
558.944	44
561.355	34
563.766	40
566.175	42
568.585	40
570.992	42
573.401	32
575.807	38
578.212	38
580.618	38
583.022	40
585.425	36
587.827	44
590.229	34
592.631	44
595.031	32
597.43	36
599.829	40
602.226	38
604.623	38
607.02	42
609.415	36
611.808	42
614.202	38
616.596	40
618.988	34
621.38	42
623.769	42
626.159	40
628.549	44
630.936	40
633.324	44
635.71	38
638.096	40
640.481	42
642.866	40
645.248	36
647.632	40
650.013	40
652.394	42
654.773	38
657.154	38
659.532	38
661.91	42
664.286	46
666.663	38
669.038	44
671.412	42
673.786	36
676.159	44
678.532	40
680.903	42
683.274	46
685.644	34
688.014	34
690.382	32
692.749	38
695.116	42
697.482	38
699.846	36
702.211	36
704.574	44
706.938	40
709.299	40
711.661	34
714.021	44
716.381	44
718.739	48
721.097	42
723.455	44
725.811	36
728.167	36
730.521	44
732.877	42
735.23	44
737.582	38
739.934	36
742.285	42
744.635	42
746.985	36
749.334	40
751.682	40
754.028	38
756.374	38
758.72	36
761.065	40
763.408	46
765.752	44
768.095	40
770.436	44
772.777	44
775.116	48
777.456	32
779.794	34
782.133	42
784.469	40
786.806	44
789.141	44
791.476	44
793.809	44
796.143	42
798.476	42
800.807	40
803.138	48
805.468	46
807.797	40
810.125	40
812.453	36
814.78	42
817.106	42
819.432	42
821.757	44
824.081	38
826.403	46
828.726	44
831.048	38
833.368	40
835.688	36
838.008	38
840.326	40
842.644	44
844.96	40
847.277	40
849.592	36
851.906	44
854.221	46
856.534	42
858.846	44
861.159	36
863.469	42
865.779	40
868.088	36
870.396	34
872.704	44
875.011	42
877.318	32
879.623	30
881.928	38
884.232	38
886.536	34
888.838	40
891.139	38
893.44	42
895.741	34
898.039	46
900.339	40
902.637	48
904.933	42
907.231	42
909.526	36
911.821	44
914.115	48
916.408	42
918.701	40
920.993	40
923.283	36
925.575	46
927.864	38
930.153	42
932.441	32
934.728	46
937.014	42
939.3	38
941.585	40
943.87	40
946.154	40
948.437	44
950.719	38
953	40
955.28	42
957.56	40
959.84	46
962.117	36
964.395	42
966.673	36
968.948	36
971.224	40
973.498	44
975.773	38
978.045	42
980.317	44
982.59	36
984.86	42
987.13	34
989.399	38
991.669	42
993.937	44
996.204	42
998.47	40
1000.74	42
1003	44
1005.26	42
1007.53	40
1009.79	42
1012.05	42
1014.31	44
1016.57	48
1018.83	42
1021.09	44
1023.35	42
1025.61	40
1027.87	44
1030.12	38
1032.38	42
1034.63	36
1036.88	42
1039.14	40
1041.39	40
1043.64	42
1045.89	42
1048.14	42
1050.39	42
1052.64	42
1054.89	46
1057.14	44
1059.38	46
1061.63	46
1063.87	48
1066.12	44
1068.36	44
1070.6	52
1072.85	40
1075.09	42
1077.33	42
1079.57	46
1081.81	42
1084.05	46
1086.28	48
1088.52	34
1090.76	42
1092.99	34
1095.23	46
1097.46	38
1099.69	40
1101.93	46
1104.16	44
1106.39	42
1108.62	48
1110.85	52
1113.08	46
1115.31	44
1117.53	48
1119.76	50
1121.99	46
1124.21	44
1126.44	44
1128.66	44
1130.88	48
1133.11	54
1135.33	40
1137.55	50
1139.77	50
1141.99	48
1144.21	38
1146.43	54
1148.64	50
1150.86	46
1153.08	44
1155.29	48
1157.51	46
1159.72	52
1161.93	48
1164.14	46
1166.36	50
1168.57	46
1170.78	48
1172.99	50
1175.2	40
1177.4	52
1179.61	46
1181.82	54
1184.02	44
1186.23	44
1188.43	48
1190.64	52
1192.84	52
1195.04	46
1197.24	56
1199.45	46.04
1201.64	50.0611
1203.84	51.9111
1206.04	44.2311
1208.24	51.7309
1210.44	42.1203
1212.64	49.6731
1214.83	53.3886
1217.03	50.86
1219.22	45.48
1221.41	54.9231
1223.61	51.4712
1225.8	56.57
1227.99	52.9369
1230.18	50.6123
1232.37	51.2473
1234.56	53.0461
1236.75	51.4254
1238.94	60.2124
1241.13	53.1649
1243.31	53.2722
1245.5	61.8872
1247.68	53.8552
1249.87	56
1252.05	58.8163
1254.24	60.2215
1256.42	60.835
1258.6	58
1260.78	59.0661
1262.96	64.7396
1265.14	63.6481
1267.32	65.5442
1269.5	71.5841
1271.67	68.4256
1273.85	69.4898
1276.03	72.9728
1278.2	76.9925
1280.38	68.51
1282.55	74.8344
1284.72	75.6275
1286.9	74.2055
1289.07	83.2807
1291.24	86.1136
1293.41	94.2374
1295.58	92.64
1297.75	94.8967
1299.92	105.659
1302.09	104.517
1304.25	106.475
1306.42	122.361
1308.44	132
1310.61	136
1312.79	140
1314.97	154
1317.14	146
1319.31	160
1321.48	166
1323.66	172
1325.83	182
1328	162
1330.17	166
1332.34	174
1334.5	180
1336.67	162
1338.84	170
1341	154
1343.17	154
1345.33	144
1347.5	140
1349.66	138
1351.83	136
1353.99	116
1356.15	122
1358.31	108
1360.47	98
1362.63	102
1364.79	92
1366.94	90
1369.1	84
1371.26	92
1373.41	88
1375.57	72
1377.72	84
1379.88	80
1382.03	80
1384.18	70
1386.33	72
1388.48	76
1390.64	70
1392.79	68
1394.93	56
1397.08	58
1399.23	66
1401.38	66
1403.52	64
1405.67	68
1407.81	54
1409.96	68
1412.1	58
1414.24	62
1416.39	52
1418.53	58
1420.67	60
1422.81	58
1424.95	46
1427.09	54
1429.23	52
1431.36	52
1433.5	60
1435.64	58
1437.77	50
1439.91	50
1442.04	54
1444.17	54
1446.31	48
1448.44	54
1450.57	48
1452.7	50
1454.83	50
1456.96	48
1459.09	50
1461.22	50
1463.34	60
1465.47	58
1467.6	42
1469.72	56
1471.85	44
1473.97	52
1476.09	52
1478.22	50
1480.34	54
1482.46	44
1484.58	56
1486.7	56
1488.82	54
1490.94	52
1493.06	58
1495.17	64
1497.29	60
1499.41	54
1501.52	54
1503.64	54
1505.75	54
1507.86	56
1509.98	54
1512.09	46
1514.2	54
1516.31	56
1518.42	52
1520.53	48
1522.64	56
1524.74	50
1526.85	58
1528.96	58
1531.07	62
1533.17	56
1535.27	60
1537.38	62
1539.48	62
1541.58	60
1543.69	68
1545.79	62
1547.89	72
1549.99	72
1552.09	68
1554.19	70
1556.28	72
1558.38	80
1560.48	82
1562.57	94
1564.67	96
1566.76	102
1568.86	104
1570.95	94
1573.05	102
1575.14	100
1577.23	118
1579.32	120
1581.41	126
1583.5	136
1585.59	130
1587.68	122
1589.76	138
1591.85	132
1593.94	130
1596.02	132
1598.11	130
1600.19	124
1602.27	120
1604.36	122
1606.44	116
1608.52	124
1610.6	116
1612.68	126
1614.76	118
1616.84	122
1618.92	104
1621	110
1623.07	102
1625.15	110
1627.23	106
1629.3	88
1631.38	78
1633.45	82
1635.52	74
1637.59	82
1639.67	68
1641.74	66
1643.81	62
1645.88	58
1647.95	62
1650.02	50
1652.08	50
1654.15	54
1656.22	54
1658.28	56
1660.35	44
1662.41	54
1664.48	58
1666.54	52
1668.6	44
1670.67	52
1672.73	48
1674.79	52
1676.85	44
1678.91	50
1680.97	50
1683.03	46
1685.08	40
1687.14	48
1689.2	38
1691.25	40
1693.31	44
1695.36	44
1697.42	50
1699.47	40
1701.52	40
1703.57	38
1705.63	42
1707.68	38
1709.72	42
1711.77	38
1713.82	40
1715.87	42
1717.92	46
1719.97	38
1722.01	44
1724.06	40
1726.1	42
1728.15	38
1730.19	46
1732.23	38
1734.27	36
1736.32	48
1738.36	38
1740.4	52
1742.44	46
1744.48	36
1746.51	40
1748.55	44
1750.59	40
1752.63	40
1754.66	42
1756.7	38
1758.73	46
1760.77	46
1762.8	48
1764.83	34
1766.86	36
1768.9	38
1770.93	40
1772.96	42
1774.99	42
1777.02	40
1779.04	42
1781.07	38
1783.1	38
1785.13	38
1787.15	42
1789.18	40
1791.2	44
1793.23	42
1795.25	36
1797.27	44
1799.29	42
1801.31	38
1803.34	40
1805.36	38
1807.38	46
1809.39	44
1811.41	46
1813.43	40
1815.45	44
1817.46	42
1819.48	42
1821.49	44
1823.51	38
1825.52	40
1827.54	40
1829.55	36
1831.56	48
1833.57	44
1835.58	34
1837.59	46
1839.6	46
1841.61	36
1843.62	46
1845.63	44
1847.64	40
1849.64	44
1851.65	42
1853.65	34
1855.66	40
1857.66	40
1859.66	44
1861.67	46
1863.67	40
1865.67	42
1867.67	28
1869.67	38
1871.67	34
1873.67	36
1875.67	36
1877.67	38
1879.66	34
1881.66	48
1883.66	38
1885.65	36
1887.65	36
1889.64	40
1891.63	40
1893.63	44
1895.62	42
1897.61	36
1899.6	40
1901.59	38
1903.58	40
1905.57	34
1907.56	46
1909.55	42
1911.53	38
1913.52	40
1915.51	34
1917.49	42
1919.48	42
1921.46	40
1923.45	46
1925.43	40
1927.41	40
1929.39	36
1931.37	38
1933.36	38
1935.33	38
1937.31	44
1939.29	36
1941.27	38
1943.25	38
1945.23	42
1947.2	38
1949.18	42
1951.15	40
1953.13	40
1955.1	38
1957.08	46
1959.05	32
1961.02	32
1962.99	38
1964.96	40
1966.93	36
1968.9	30
1970.87	36
1972.84	34
1974.81	36
1976.77	46
1978.74	38
1980.71	42
1982.67	40
1984.64	38
1986.6	36
1988.57	44
1990.53	46
1992.49	36
1994.45	42
1996.41	40
1998.37	36
1999.35	42