File: muestras/LIG/fproof_19.txt
#Acq. time (s)=	10
#Accumulations=	2
#Range (cm-¹)=	100...2000
#Windows=	2
#Autofocus=	Off
#AutoExposure=	Off
#Spike filter=	Multiple accum.
#Delay time (s)=	0
#Binning=	1
#Readout mode=	Signal
#DeNoise=	Off
#ICS correction=	Off
#Dark correction=	Off
#Inst. Process=	Off
#Instrument=	LabRAM HR Evol
#Detector=	Syncerity OE
#Objective=	x100_VIS_LWD
#Grating=	600 (500nm)
#ND Filter=	25%
#Laser=	633nm_Edge
#Hole=	100.021
#Range=	Visible
#Project=	LIG
#Sample=	proof
#Site=
#Title=	fproof
#Remark=
#Date=	07.03.2023 13:16
#Acquired=	07.03.2023 13:16:35
101.054	66
103.621	66
106.187	64
108.753	64
111.317	52
113.881	60
116.443	58
119.005	64
121.566	62
124.126	62
126.685	60
129.243	56
131.801	52
134.357	58
136.911	56
139.466	52
142.021	56
144.574	60
147.126	50
149.676	58
152.227	46
154.777	48
157.325	52
159.873	50
162.419	58
164.966	58
167.51	56
170.055	56
172.598	54
175.141	54
177.682	52
180.222	52
182.763	60
185.302	64
187.839	62
190.378	50
192.914	50
195.449	46
197.983	52
200.517	54
203.05	54
205.582	56
208.113	44
210.643	54
213.173	56
215.701	62
218.229	58
220.756	62
223.282	58
225.808	62
228.331	58
230.855	60
233.378	60
235.9	52
238.419	54
240.94	58
243.46	56
245.977	50
248.495	60
251.011	52
253.527	58
256.041	56
258.556	62
261.068	56
263.58	62
266.092	54
268.603	50
271.112	54
273.622	48
276.129	56
278.636	52
281.142	56
283.647	56
286.152	56
288.655	60
291.158	60
293.66	52
296.161	50
298.661	48
301.161	62
303.66	54
306.158	50
308.655	56
311.151	60
313.645	58
316.14	56
318.634	60
321.125	56
323.618	52
326.109	54
328.598	54
331.088	50
333.576	56
336.064	60
338.55	56
341.037	56
343.521	52
346.005	56
348.489	58
350.971	56
353.453	50
355.935	68
358.414	58
360.893	54
363.371	54
365.848	54
368.325	56
370.801	54
373.275	60
375.75	64
378.223	48
380.695	52
383.167	52
385.638	54
388.108	56
390.577	48
393.044	52
395.512	44
397.979	50
400.445	52
402.909	50
405.374	48
407.836	60
410.299	58
412.762	50
415.221	50
417.681	46
420.141	60
422.598	54
425.057	56
427.513	54
429.968	54
432.424	52
434.878	46
437.33	46
439.783	58
442.234	52
444.685	56
447.136	52
449.585	54
452.033	54
454.48	56
456.927	48
459.372	50
461.817	52
464.261	52
466.705	54
469.147	52
471.589	52
474.029	58
476.47	58
478.909	50
481.347	50
483.785	48
486.221	54
488.657	50
491.093	56
493.527	50
495.96	48
498.393	48
500.824	54
503.256	52
505.686	50
508.115	54
510.543	46
512.972	46
515.399	48
517.825	60
520.25	44
522.674	54
525.097	50
527.52	52
529.942	54
532.364	48
534.784	52
537.204	52
539.623	48
542.041	48
544.458	48
546.874	44
549.289	42
551.705	56
554.118	38
556.531	52
558.944	52
561.355	44
563.766	56
566.175	56
568.585	50
570.992	54
573.401	44
575.807	56
578.212	52
580.618	54
583.022	58
585.425	62
587.827	44
590.229	64
592.631	58
595.031	52
597.43	58
599.829	54
602.226	52
604.623	48
607.02	54
609.415	58
611.808	52
614.202	44
616.596	56
618.988	54
621.38	54
623.769	50
626.159	48
628.549	46
630.936	58
633.324	48
635.71	62
638.096	56
640.481	52
642.866	50
645.248	54
647.632	52
650.013	54
652.394	52
654.773	58
657.154	56
659.532	60
661.91	58
664.286	56
666.663	52
669.038	54
671.412	48
673.786	46
676.159	60
678.532	52
680.903	56
683.274	50
685.644	56
688.014	52
690.382	42
692.749	54
695.116	50
697.482	48
699.846	48
702.211	52
704.574	50
706.938	46
709.299	52
711.661	56
714.021	52
716.381	58
718.739	56
721.097	48
723.455	54
725.811	50
728.167	48
730.521	56
732.877	56
735.23	60
737.582	48
739.934	54
742.285	50
744.635	50
746.985	50
749.334	48
751.682	60
754.028	46
756.374	50
758.72	50
761.065	54
763.408	54
765.752	56
768.095	50
770.436	44
772.777	54
775.116	56
777.456	54
779.794	58
782.133	58
784.469	56
786.806	50
789.141	56
791.476	54
793.809	58
796.143	58
798.476	48
800.807	56
803.138	50
805.468	52
807.797	62
810.125	50
812.453	52
814.78	62
817.106	52
819.432	50
821.757	52
824.081	48
826.403	56
828.726	52
831.048	58
833.368	54
835.688	66
838.008	56
840.326	50
842.644	54
844.96	50
847.277	48
849.592	52
851.906	46
854.221	60
856.534	50
858.846	52
861.159	56
863.469	50
865.779	64
868.088	56
870.396	58
872.704	54
875.011	48
877.318	50
879.623	56
881.928	54
884.232	58
886.536	54
888.838	48
891.139	50
893.44	56
895.741	52
898.039	50
900.339	58
902.637	60
904.933	56
907.231	50
909.526	54
911.821	56
914.115	52
916.408	54
918.701	54
920.993	58
923.283	58
925.575	58
927.864	52
930.153	60
932.441	48
934.728	62
937.014	56
939.3	62
941.585	62
943.87	48
946.154	56
948.437	54
950.719	60
953	52
955.28	58
957.56	58
959.84	62
962.117	60
964.395	56
966.673	56
968.948	64
971.224	54
973.498	58
975.773	54
978.045	54
980.317	62
982.59	56
984.86	54
987.13	50
989.399	60
991.669	50
993.937	58
996.204	50
998.47	50
1000.74	58
1003	60
1005.26	54
1007.53	56
1009.79	64
1012.05	58
1014.31	56
1016.57	58
1018.83	56
1021.09	58
1023.35	56
1025.61	50
1027.87	56
1030.12	64
1032.38	64
1034.63	64
1036.88	50
1039.14	60
1041.39	60
1043.64	56
1045.89	54
1048.14	54
1050.39	58
1052.64	62
1054.89	64
1057.14	64
1059.38	62
1061.63	56
1063.87	58
1066.12	64
1068.36	72
1070.6	62
1072.85	64
1075.09	70
1077.33	60
1079.57	74
1081.81	62
1084.05	62
1086.28	64
1088.52	70
1090.76	66
1092.99	64
1095.23	62
1097.46	66
1099.69	64
1101.93	66
1104.16	74
1106.39	78
1108.62	72
1110.85	70
1113.08	80
1115.31	76
1117.53	72
1119.76	72
1121.99	64
1124.21	70
1126.44	74
1128.66	76
1130.88	76
1133.11	80
1135.33	78
1137.55	76
1139.77	88
1141.99	88
1144.21	88
1146.43	78
1148.64	82
1150.86	86
1153.08	74
1155.29	84
1157.51	82
1159.72	86
1161.93	86
1164.14	84
1166.36	86
1168.57	92
1170.78	88
1172.99	82
1175.2	86
1177.4	76
1179.61	76
1181.82	96
1184.02	86
1186.23	94
1188.43	86
1190.64	82
1192.84	92
1195.04	86
1197.24	90
1199.45	86.06
1201.64	92.0083
1203.84	84.3774
1206.04	93.716
1208.24	96.2835
1210.44	78.2203
1212.64	95.3269
1214.83	87.2579
1217.03	93.0199
1219.22	94.1458
1221.41	94.6254
1223.61	86.3154
1225.8	104.765
1227.99	99.0662
1230.18	105.75
1232.37	97.4232
1234.56	100.912
1236.75	101.927
1238.94	102.811
1241.13	105.577
1243.31	116.38
1245.5	114.082
1247.68	116.931
1249.87	115.999
1252.05	112.456
1254.24	116.183
1256.42	121.768
1258.6	129.876
1260.78	136.8
1262.96	127.331
1265.14	134.899
1267.32	147.294
1269.5	143.48
1271.67	145.02
1273.85	164.11
1276.03	167.118
1278.2	169.096
1280.38	172.111
1282.55	185.756
1284.72	200.263
1286.9	196.958
1289.07	201.15
1291.24	223.842
1293.41	242.545
1295.58	243.438
1297.75	269.814
1299.92	275.25
1302.09	291.849
1304.25	310.64
1306.42	315.73
1308.44	344
1310.61	348
1312.79	388
1314.97	408
1317.14	412
1319.31	446
1321.48	454
1323.66	466
1325.83	474
1328	480
1330.17	496
1332.34	486
1334.5	474
1336.67	448
1338.84	460
1341	444
1343.17	424
1345.33	372
1347.5	376
1349.66	336
1351.83	338
1353.99	314
1356.15	304
1358.31	282
1360.47	270
1362.63	246
1364.79	242
1366.94	220
1369.1	208
1371.26	214
1373.41	188
1375.57	192
1377.72	172
1379.88	166
1382.03	168
1384.18	144
1386.33	168
1388.48	152
1390.64	142
1392.79	150
1394.93	144
1397.08	136
1399.23	128
1401.38	130
1403.52	130
1405.67	118
1407.81	122
1409.96	120
1412.1	104
1414.24	120
1416.39	124
1418.53	112
1420.67	118
1422.81	118
1424.95	104
1427.09	110
1429.23	102
1431.36	112
1433.5	96
1435.64	96
1437.77	94
1439.91	102
1442.04	94
1444.17	92
1446.31	96
1448.44	106
1450.57	94
1452.7	98
1454.83	90
1456.96	96
1459.09	102
1461.22	98
1463.34	102
1465.47	106
1467.6	94
1469.72	104
1471.85	102
1473.97	92
1476.09	104
1478.22	104
1480.34	100
1482.46	104
1484.58	106
1486.7	104
1488.82	102
1490.94	98
1493.06	96
1495.17	102
1497.29	112
1499.41	108
1501.52	98
1503.64	98
1505.75	104
1507.86	92
1509.98	98
1512.09	114
1514.2	100
1516.31	104
1518.42	104
1520.53	102
1522.64	116
1524.74	116
1526.85	110
1528.96	108
1531.07	126
1533.17	132
1535.27	130
1537.38	126
1539.48	130
1541.58	132
1543.69	136
1545.79	142
1547.89	158
1549.99	158
1552.09	162
1554.19	170
1556.28	180
1558.38	184
1560.48	190
1562.57	204
1564.67	212
1566.76	220
1568.86	232
1570.95	256
1573.05	272
1575.14	262
1577.23	294
1579.32	296
1581.41	296
1583.5	308
1585.59	296
1587.68	320
1589.76	300
1591.85	310
1593.94	294
1596.02	296
1598.11	312
1600.19	298
1602.27	300
1604.36	298
1606.44	302
1608.52	302
1610.6	282
1612.68	278
1614.76	280
1616.84	272
1618.92	274
1621	252
1623.07	246
1625.15	222
1627.23	216
1629.3	200
1631.38	178
1633.45	168
1635.52	164
1637.59	146
1639.67	136
1641.74	124
1643.81	122
1645.88	106
1647.95	106
1650.02	90
1652.08	102
1654.15	82
1656.22	90
1658.28	82
1660.35	78
1662.41	72
1664.48	80
1666.54	72
1668.6	74
1670.67	72
1672.73	62
1674.79	70
1676.85	76
1678.91	74
1680.97	66
1683.03	64
1685.08	70
1687.14	68
1689.2	70
1691.25	74
1693.31	64
1695.36	60
1697.42	60
1699.47	60
1701.52	68
1703.57	56
1705.63	62
1707.68	64
1709.72	58
1711.77	60
1713.82	56
1715.87	62
1717.92	64
1719.97	60
1722.01	60
1724.06	60
1726.1	48
1728.15	62
1730.19	66
1732.23	56
1734.27	66
1736.32	54
1738.36	58
1740.4	58
1742.44	64
1744.48	54
1746.51	60
1748.55	64
1750.59	56
1752.63	58
1754.66	54
1756.7	58
1758.73	58
1760.77	58
1762.8	56
1764.83	58
1766.86	54
1768.9	52
1770.93	54
1772.96	62
1774.99	58
1777.02	60
1779.04	50
1781.07	50
1783.1	60
1785.13	58
1787.15	58
1789.18	58
1791.2	58
1793.23	60
1795.25	60
1797.27	56
1799.29	54
1801.31	54
1803.34	48
1805.36	60
1807.38	56
1809.39	66
1811.41	58
1813.43	56
1815.45	58
1817.46	60
1819.48	52
1821.49	56
1823.51	52
1825.52	52
1827.54	50
1829.55	58
1831.56	56
1833.57	62
1835.58	50
1837.59	48
1839.6	52
1841.61	52
1843.62	50
1845.63	54
1847.64	60
1849.64	44
1851.65	56
1853.65	50
1855.66	46
1857.66	50
1859.66	54
1861.67	52
1863.67	56
1865.67	54
1867.67	56
1869.67	48
1871.67	54
1873.67	52
1875.67	52
1877.67	56
1879.66	62
1881.66	60
1883.66	52
1885.65	48
1887.65	54
1889.64	58
1891.63	48
1893.63	58
1895.62	56
1897.61	50
1899.6	48
1901.59	48
1903.58	52
1905.57	56
1907.56	56
1909.55	48
1911.53	54
1913.52	54
1915.51	50
1917.49	46
1919.48	48
1921.46	56
1923.45	56
1925.43	48
1927.41	50
1929.39	54
1931.37	44
1933.36	50
1935.33	46
1937.31	50
1939.29	50
1941.27	50
1943.25	54
1945.23	50
1947.2	56
1949.18	54
1951.15	46
1953.13	53
1955.1	54
1957.08	54
1959.05	52
1961.02	46
1962.99	44
1964.96	58
1966.93	50
1968.9	48
1970.87	48
1972.84	48
1974.81	50
1976.77	46
1978.74	48
1980.71	48
1982.67	54
1984.64	52
1986.6	50
1988.57	54
1990.53	46
1992.49	50
1994.45	56
1996.41	48
1998.37	46
1999.35	54