File: muestras/LIG/fproof_08.txt
#Acq. time (s)=	10
#Accumulations=	2
#Range (cm-¹)=	100...2000
#Windows=	2
#Autofocus=	Off
#AutoExposure=	Off
#Spike filter=	Multiple accum.
#Delay time (s)=	0
#Binning=	1
#Readout mode=	Signal
#DeNoise=	Off
#ICS correction=	Off
#Dark correction=	Off
#Inst. Process=	Off
#Instrument=	LabRAM HR Evol
#Detector=	Syncerity OE
#Objective=	x100_VIS_LWD
#Grating=	600 (500nm)
#ND Filter=	50%
#Laser=	633nm_Edge
#Hole=	100.021
#Range=	Visible
#Project=	LIG
#Sample=	proof
#Site=
#Title=	fproof
#Remark=
#Date=	07.03.2023 12:41
#Acquired=	07.03.2023 12:41:40
101.054	124
103.621	124
106.187	124
108.753	124
111.317	122
113.881	108
116.443	116
119.005	120
121.566	116
124.126	126
126.685	114
129.243	118
131.801	112
134.357	110
136.911	116
139.466	124
142.021	112
144.574	114
147.126	114
149.676	112
152.227	114
154.777	114
157.325	106
159.873	118
162.419	116
164.966	120
167.51	118
170.055	130
172.598	112
175.141	120
177.682	116
180.222	124
182.763	106
185.302	112
187.839	124
190.378	118
192.914	116
195.449	108
197.983	126
200.517	108
203.05	114
205.582	118
208.113	110
210.643	126
213.173	102
215.701	118
218.229	116
220.756	120
223.282	134
225.808	118
228.331	132
230.855	112
233.378	130
235.9	112
238.419	118
240.94	108
243.46	114
245.977	114
248.495	106
251.011	112
253.527	110
256.041	114
258.556	124
261.068	120
263.58	128
266.092	128
268.603	116
271.112	110
273.622	110
276.129	122
278.636	124
281.142	116
283.647	112
286.152	116
288.655	110
291.158	108
293.66	110
296.161	114
298.661	116
301.161	126
303.66	116
306.158	102
308.655	120
311.151	116
313.645	128
316.14	126
318.634	104
321.125	106
323.618	112
326.109	116
328.598	120
331.088	108
333.576	112
336.064	104
338.55	100
341.037	112
343.521	124
346.005	128
348.489	136
350.971	122
353.453	110
355.935	120
358.414	120
360.893	126
363.371	106
365.848	106
368.325	112
370.801	122
373.275	104
375.75	118
378.223	110
380.695	122
383.167	122
385.638	106
388.108	110
390.577	118
393.044	112
395.512	122
397.979	116
400.445	118
402.909	112
405.374	116
407.836	124
410.299	112
412.762	118
415.221	110
417.681	126
420.141	112
422.598	112
425.057	112
427.513	122
429.968	116
432.424	120
434.878	122
437.33	120
439.783	130
442.234	114
444.685	120
447.136	124
449.585	138
452.033	124
454.48	118
456.927	114
459.372	120
461.817	122
464.261	112
466.705	110
469.147	110
471.589	120
474.029	122
476.47	114
478.909	108
481.347	116
483.785	116
486.221	106
488.657	122
491.093	114
493.527	114
495.96	104
498.393	102
500.824	106
503.256	110
505.686	110
508.115	118
510.543	120
512.972	116
515.399	104
517.825	110
520.25	110
522.674	120
525.097	118
527.52	106
529.942	116
532.364	106
534.784	114
537.204	118
539.623	96
542.041	108
544.458	108
546.874	110
549.289	118
551.705	98
554.118	124
556.531	100
558.944	104
561.355	114
563.766	128
566.175	100
568.585	114
570.992	122
573.401	126
575.807	108
578.212	112
580.618	102
583.022	114
585.425	108
587.827	116
590.229	124
592.631	114
595.031	116
597.43	102
599.829	120
602.226	102
604.623	118
607.02	108
609.415	102
611.808	116
614.202	110
616.596	128
618.988	116
621.38	122
623.769	120
626.159	108
628.549	114
630.936	110
633.324	114
635.71	114
638.096	120
640.481	122
642.866	120
645.248	122
647.632	116
650.013	120
652.394	114
654.773	118
657.154	112
659.532	120
661.91	120
664.286	100
666.663	106
669.038	112
671.412	114
673.786	116
676.159	110
678.532	110
680.903	128
683.274	126
685.644	100
688.014	112
690.382	118
692.749	108
695.116	112
697.482	116
699.846	128
702.211	116
704.574	120
706.938	126
709.299	122
711.661	114
714.021	118
716.381	120
718.739	128
721.097	120
723.455	120
725.811	122
728.167	126
730.521	120
732.877	122
735.23	106
737.582	112
739.934	126
742.285	120
744.635	120
746.985	114
749.334	120
751.682	124
754.028	118
756.374	118
758.72	108
761.065	128
763.408	126
765.752	120
768.095	106
770.436	116
772.777	138
775.116	120
777.456	134
779.794	114
782.133	124
784.469	118
786.806	132
789.141	118
791.476	114
793.809	124
796.143	120
798.476	120
800.807	132
803.138	118
805.468	122
807.797	110
810.125	114
812.453	126
814.78	124
817.106	124
819.432	118
821.757	114
824.081	124
826.403	124
828.726	122
831.048	110
833.368	114
835.688	130
838.008	116
840.326	120
842.644	108
844.96	104
847.277	118
849.592	128
851.906	112
854.221	122
856.534	140
858.846	116
861.159	128
863.469	122
865.779	116
868.088	126
870.396	118
872.704	128
875.011	122
877.318	104
879.623	128
881.928	122
884.232	120
886.536	110
888.838	120
891.139	110
893.44	128
895.741	102
898.039	102
900.339	104
902.637	118
904.933	118
907.231	112
909.526	104
911.821	128
914.115	122
916.408	114
918.701	122
920.993	134
923.283	134
925.575	108
927.864	114
930.153	134
932.441	118
934.728	112
937.014	114
939.3	114
941.585	124
943.87	136
946.154	118
948.437	116
950.719	110
953	114
955.28	114
957.56	118
959.84	132
962.117	136
964.395	134
966.673	138
968.948	114
971.224	120
973.498	104
975.773	124
978.045	120
980.317	122
982.59	124
984.86	138
987.13	138
989.399	116
991.669	114
993.937	130
996.204	116
998.47	114
1000.74	136
1003	122
1005.26	128
1007.53	132
1009.79	128
1012.05	132
1014.31	136
1016.57	132
1018.83	128
1021.09	122
1023.35	128
1025.61	122
1027.87	130
1030.12	130
1032.38	122
1034.63	134
1036.88	152
1039.14	126
1041.39	136
1043.64	122
1045.89	132
1048.14	136
1050.39	134
1052.64	144
1054.89	136
1057.14	132
1059.38	138
1061.63	146
1063.87	140
1066.12	136
1068.36	134
1070.6	156
1072.85	134
1075.09	146
1077.33	144
1079.57	160
1081.81	154
1084.05	144
1086.28	144
1088.52	140
1090.76	150
1092.99	152
1095.23	150
1097.46	146
1099.69	146
1101.93	154
1104.16	150
1106.39	150
1108.62	150
1110.85	156
1113.08	144
1115.31	152
1117.53	148
1119.76	136
1121.99	166
1124.21	164
1126.44	154
1128.66	150
1130.88	150
1133.11	168
1135.33	158
1137.55	172
1139.77	158
1141.99	172
1144.21	168
1146.43	168
1148.64	168
1150.86	184
1153.08	160
1155.29	170
1157.51	174
1159.72	180
1161.93	186
1164.14	174
1166.36	162
1168.57	174
1170.78	172
1172.99	166
1175.2	182
1177.4	196
1179.61	178
1181.82	172
1184.02	182
1186.23	176
1188.43	174
1190.64	182
1192.84	180
1195.04	204
1197.24	192
1199.45	204.34
1201.64	192.164
1203.84	181.904
1206.04	204.815
1208.24	193.976
1210.44	188.723
1212.64	199.186
1214.83	194.441
1217.03	204.35
1219.22	223.17
1221.41	209.432
1223.61	226.652
1225.8	222.456
1227.99	219.533
1230.18	227.638
1232.37	242.29
1234.56	227.532
1236.75	234.64
1238.94	252.982
1241.13	240.111
1243.31	255.094
1245.5	262.723
1247.68	262.585
1249.87	278.125
1252.05	281.897
1254.24	279.767
1256.42	282.497
1258.6	286.996
1260.78	288.734
1262.96	293.24
1265.14	315.335
1267.32	309
1269.5	325.543
1271.67	330.932
1273.85	328.212
1276.03	333.146
1278.2	337.589
1280.38	361.758
1282.55	346.376
1284.72	350.766
1286.9	361.552
1289.07	364.123
1291.24	378.395
1293.41	375.872
1295.58	386.244
1297.75	392.512
1299.92	419.219
1302.09	410.903
1304.25	408
1306.42	417.973
1308.44	412
1310.61	418
1312.79	428
1314.97	424
1317.14	406
1319.31	400
1321.48	422
1323.66	410
1325.83	406
1328	406
1330.17	418
1332.34	398
1334.5	420
1336.67	420
1338.84	398
1341	418
1343.17	426
1345.33	384
1347.5	430
1349.66	396
1351.83	404
1353.99	390
1356.15	388
1358.31	396
1360.47	402
1362.63	386
1364.79	364
1366.94	388
1369.1	404
1371.26	356
1373.41	374
1375.57	392
1377.72	356
1379.88	340
1382.03	388
1384.18	374
1386.33	356
1388.48	340
1390.64	344
1392.79	358
1394.93	318
1397.08	350
1399.23	328
1401.38	358
1403.52	326
1405.67	332
1407.81	310
1409.96	310
1412.1	316
1414.24	326
1416.39	316
1418.53	304
1420.67	308
1422.81	322
1424.95	306
1427.09	306
1429.23	298
1431.36	298
1433.5	304
1435.64	308
1437.77	316
1439.91	296
1442.04	304
1444.17	300
1446.31	268
1448.44	296
1450.57	292
1452.7	290
1454.83	298
1456.96	296
1459.09	278
1461.22	298
1463.34	268
1465.47	278
1467.6	288
1469.72	292
1471.85	296
1473.97	304
1476.09	290
1478.22	292
1480.34	290
1482.46	300
1484.58	294
1486.7	280
1488.82	296
1490.94	286
1493.06	296
1495.17	282
1497.29	290
1499.41	276
1501.52	284
1503.64	280
1505.75	292
1507.86	306
1509.98	292
1512.09	298
1514.2	276
1516.31	298
1518.42	318
1520.53	290
1522.64	292
1524.74	314
1526.85	306
1528.96	302
1531.07	298
1533.17	342
1535.27	292
1537.38	320
1539.48	312
1541.58	306
1543.69	318
1545.79	298
1547.89	314
1549.99	332
1552.09	320
1554.19	324
1556.28	344
1558.38	346
1560.48	352
1562.57	344
1564.67	354
1566.76	356
1568.86	362
1570.95	350
1573.05	352
1575.14	344
1577.23	374
1579.32	366
1581.41	380
1583.5	378
1585.59	366
1587.68	350
1589.76	378
1591.85	346
1593.94	354
1596.02	338
1598.11	352
1600.19	338
1602.27	314
1604.36	320
1606.44	324
1608.52	306
1610.6	300
1612.68	310
1614.76	292
1616.84	290
1618.92	260
1621	266
1623.07	280
1625.15	246
1627.23	246
1629.3	236
1631.38	242
1633.45	238
1635.52	222
1637.59	220
1639.67	218
1641.74	222
1643.81	202
1645.88	206
1647.95	204
1650.02	200
1652.08	214
1654.15	196
1656.22	186
1658.28	184
1660.35	182
1662.41	192
1664.48	190
1666.54	160
1668.6	166
1670.67	166
1672.73	180
1674.79	162
1676.85	158
1678.91	164
1680.97	178
1683.03	174
1685.08	172
1687.14	166
1689.2	160
1691.25	152
1693.31	150
1695.36	156
1697.42	150
1699.47	142
1701.52	154
1703.57	146
1705.63	152
1707.68	152
1709.72	148
1711.77	152
1713.82	142
1715.87	144
1717.92	152
1719.97	148
1722.01	156
1724.06	134
1726.1	146
1728.15	142
1730.19	148
1732.23	138
1734.27	144
1736.32	138
1738.36	136
1740.4	144
1742.44	130
1744.48	142
1746.51	130
1748.55	142
1750.59	138
1752.63	138
1754.66	134
1756.7	124
1758.73	134
1760.77	132
1762.8	136
1764.83	132
1766.86	132
1768.9	142
1770.93	138
1772.96	146
1774.99	138
1777.02	144
1779.04	136
1781.07	128
1783.1	128
1785.13	132
1787.15	128
1789.18	144
1791.2	136
1793.23	130
1795.25	128
1797.27	138
1799.29	130
1801.31	136
1803.34	136
1805.36	132
1807.38	128
1809.39	138
1811.41	120
1813.43	128
1815.45	132
1817.46	132
1819.48	134
1821.49	126
1823.51	130
1825.52	130
1827.54	130
1829.55	126
1831.56	124
1833.57	122
1835.58	122
1837.59	128
1839.6	122
1841.61	126
1843.62	136
1845.63	126
1847.64	102
1849.64	122
1851.65	120
1853.65	128
1855.66	126
1857.66	122
1859.66	120
1861.67	130
1863.67	134
1865.67	120
1867.67	122
1869.67	124
1871.67	120
1873.67	132
1875.67	132
1877.67	118
1879.66	120
1881.66	128
1883.66	132
1885.65	122
1887.65	130
1889.64	112
1891.63	130
1893.63	106
1895.62	118
1897.61	126
1899.6	116
1901.59	114
1903.58	128
1905.57	120
1907.56	134
1909.55	130
1911.53	126
1913.52	134
1915.51	122
1917.49	128
1919.48	116
1921.46	118
1923.45	120
1925.43	116
1927.41	118
1929.39	118
1931.37	124
1933.36	128
1935.33	110
1937.31	126
1939.29	114
1941.27	116
1943.25	128
1945.23	122
1947.2	132
1949.18	124
1951.15	116
1953.13	116
1955.1	118
1957.08	114
1959.05	120
1961.02	128
1962.99	122
1964.96	110
1966.93	120
1968.9	120
1970.87	116
1972.84	114
1974.81	126
1976.77	122
1978.74	118
1980.71	106
1982.67	120
1984.64	108
1986.6	120
1988.57	126
1990.53	110
1992.49	114
1994.45	112
1996.41	116
1998.37	112
1999.35	116