File: muestras/LIG/fproof_12.txt
#Acq. time (s)=	10
#Accumulations=	2
#Range (cm-¹)=	100...2000
#Windows=	2
#Autofocus=	Off
#AutoExposure=	Off
#Spike filter=	Multiple accum.
#Delay time (s)=	0
#Binning=	1
#Readout mode=	Signal
#DeNoise=	Off
#ICS correction=	Off
#Dark correction=	Off
#Inst. Process=	Off
#Instrument=	LabRAM HR Evol
#Detector=	Syncerity OE
#Objective=	x100_VIS_LWD
#Grating=	600 (500nm)
#ND Filter=	25%
#Laser=	633nm_Edge
#Hole=	100.021
#Range=	Visible
#Project=	LIG
#Sample=	proof
#Site=
#Title=	fproof
#Remark=
#Date=	07.03.2023 12:59
#Acquired=	07.03.2023 12:59:30
101.054	42
103.621	48
106.187	40
108.753	42
111.317	40
113.881	48
116.443	42
119.005	42
121.566	42
124.126	42
126.685	46
129.243	40
131.801	40
134.357	46
136.911	42
139.466	38
142.021	36
144.574	40
147.126	40
149.676	38
152.227	38
154.777	48
157.325	38
159.873	32
162.419	32
164.966	38
167.51	38
170.055	42
172.598	42
175.141	40
177.682	36
180.222	44
182.763	42
185.302	34
187.839	44
190.378	42
192.914	34
195.449	40
197.983	38
200.517	48
203.05	40
205.582	36
208.113	38
210.643	42
213.173	40
215.701	40
218.229	38
220.756	36
223.282	36
225.808	44
228.331	38
230.855	42
233.378	40
235.9	42
238.419	36
240.94	44
243.46	40
245.977	32
248.495	42
251.011	42
253.527	42
256.041	40
258.556	36
261.068	40
263.58	36
266.092	38
268.603	36
271.112	40
273.622	38
276.129	40
278.636	44
281.142	38
283.647	42
286.152	44
288.655	42
291.158	38
293.66	38
296.161	40
298.661	42
301.161	38
303.66	40
306.158	40
308.655	46
311.151	44
313.645	40
316.14	34
318.634	40
321.125	42
323.618	38
326.109	40
328.598	40
331.088	34
333.576	36
336.064	40
338.55	44
341.037	38
343.521	34
346.005	36
348.489	38
350.971	38
353.453	44
355.935	46
358.414	30
360.893	38
363.371	40
365.848	44
368.325	38
370.801	36
373.275	38
375.75	34
378.223	34
380.695	38
383.167	44
385.638	44
388.108	36
390.577	42
393.044	44
395.512	48
397.979	40
400.445	48
402.909	30
405.374	42
407.836	40
410.299	36
412.762	36
415.221	44
417.681	40
420.141	42
422.598	42
425.057	34
427.513	38
429.968	40
432.424	46
434.878	36
437.33	42
439.783	34
442.234	36
444.685	42
447.136	34
449.585	38
452.033	42
454.48	38
456.927	40
459.372	44
461.817	36
464.261	28
466.705	40
469.147	34
471.589	38
474.029	40
476.47	40
478.909	38
481.347	38
483.785	38
486.221	48
488.657	44
491.093	38
493.527	44
495.96	42
498.393	40
500.824	42
503.256	34
505.686	36
508.115	40
510.543	36
512.972	36
515.399	38
517.825	40
520.25	34
522.674	40
525.097	42
527.52	38
529.942	36
532.364	40
534.784	40
537.204	32
539.623	34
542.041	38
544.458	42
546.874	34
549.289	40
551.705	34
554.118	34
556.531	36
558.944	34
561.355	46
563.766	42
566.175	38
568.585	34
570.992	40
573.401	38
575.807	34
578.212	42
580.618	44
583.022	42
585.425	44
587.827	38
590.229	40
592.631	40
595.031	46
597.43	42
599.829	42
602.226	36
604.623	40
607.02	40
609.415	40
611.808	32
614.202	38
616.596	38
618.988	44
621.38	42
623.769	42
626.159	36
628.549	50
630.936	44
633.324	40
635.71	40
638.096	44
640.481	34
642.866	36
645.248	40
647.632	42
650.013	40
652.394	38
654.773	46
657.154	38
659.532	38
661.91	38
664.286	44
666.663	46
669.038	40
671.412	40
673.786	40
676.159	40
678.532	40
680.903	40
683.274	44
685.644	40
688.014	36
690.382	40
692.749	38
695.116	34
697.482	36
699.846	46
702.211	36
704.574	38
706.938	38
709.299	30
711.661	40
714.021	38
716.381	40
718.739	38
721.097	42
723.455	38
725.811	42
728.167	40
730.521	38
732.877	40
735.23	42
737.582	46
739.934	30
742.285	46
744.635	38
746.985	42
749.334	46
751.682	46
754.028	40
756.374	42
758.72	40
761.065	34
763.408	46
765.752	48
768.095	32
770.436	32
772.777	36
775.116	42
777.456	40
779.794	34
782.133	36
784.469	36
786.806	40
789.141	46
791.476	44
793.809	38
796.143	34
798.476	44
800.807	38
803.138	38
805.468	42
807.797	36
810.125	40
812.453	40
814.78	42
817.106	44
819.432	38
821.757	44
824.081	40
826.403	42
828.726	38
831.048	36
833.368	38
835.688	42
838.008	46
840.326	38
842.644	42
844.96	36
847.277	40
849.592	44
851.906	46
854.221	42
856.534	44
858.846	46
861.159	34
863.469	44
865.779	46
868.088	42
870.396	40
872.704	40
875.011	44
877.318	40
879.623	36
881.928	42
884.232	40
886.536	42
888.838	36
891.139	40
893.44	38
895.741	42
898.039	34
900.339	38
902.637	36
904.933	46
907.231	38
909.526	40
911.821	34
914.115	42
916.408	36
918.701	38
920.993	40
923.283	48
925.575	32
927.864	38
930.153	40
932.441	42
934.728	38
937.014	42
939.3	34
941.585	34
943.87	38
946.154	38
948.437	40
950.719	38
953	40
955.28	40
957.56	44
959.84	46
962.117	44
964.395	46
966.673	44
968.948	38
971.224	40
973.498	44
975.773	42
978.045	36
980.317	44
982.59	40
984.86	48
987.13	48
989.399	40
991.669	40
993.937	32
996.204	40
998.47	38
1000.74	40
1003	40
1005.26	38
1007.53	44
1009.79	52
1012.05	46
1014.31	42
1016.57	36
1018.83	40
1021.09	34
1023.35	44
1025.61	42
1027.87	44
1030.12	38
1032.38	34
1034.63	36
1036.88	40
1039.14	44
1041.39	42
1043.64	44
1045.89	46
1048.14	42
1050.39	42
1052.64	38
1054.89	42
1057.14	44
1059.38	38
1061.63	52
1063.87	50
1066.12	50
1068.36	42
1070.6	46
1072.85	48
1075.09	44
1077.33	42
1079.57	48
1081.81	42
1084.05	42
1086.28	48
1088.52	48
1090.76	42
1092.99	44
1095.23	46
1097.46	44
1099.69	48
1101.93	46
1104.16	46
1106.39	48
1108.62	46
1110.85	46
1113.08	56
1115.31	44
1117.53	46
1119.76	44
1121.99	52
1124.21	48
1126.44	56
1128.66	52
1130.88	42
1133.11	48
1135.33	52
1137.55	50
1139.77	54
1141.99	50
1144.21	52
1146.43	54
1148.64	50
1150.86	50
1153.08	44
1155.29	52
1157.51	56
1159.72	60
1161.93	52
1164.14	54
1166.36	48
1168.57	54
1170.78	60
1172.99	50
1175.2	50
1177.4	54
1179.61	48
1181.82	50
1184.02	60
1186.23	58
1188.43	56
1190.64	54
1192.84	56
1195.04	60
1197.24	56
1199.45	54.04
1201.64	52.1334
1203.84	58.0195
1206.04	59.6821
1208.24	51.9009
1210.44	59.7594
1212.64	48.2694
1214.83	54.29
1217.03	57.82
1219.22	62.8639
1221.41	50.0708
1223.61	62.1846
1225.8	55.4763
1227.99	57.47
1230.18	63.4159
1232.37	64.8955
1234.56	57.4421
1236.75	51.0184
1238.94	59.6724
1241.13	62.4034
1243.31	63.3044
1245.5	63.5307
1247.68	66.7892
1249.87	65.07
1252.05	69.4573
1254.24	57.8185
1256.42	67.4233
1258.6	65.7286
1260.78	75.0182
1262.96	71.17
1265.14	71.6076
1267.32	76.0539
1269.5	81.502
1271.67	77.8778
1273.85	86.8608
1276.03	84.7814
1278.2	84.4425
1280.38	84.2727
1282.55	91.77
1284.72	88.0028
1286.9	88.1914
1289.07	89.577
1291.24	97.8036
1293.41	96.975
1295.58	111.868
1297.75	107.767
1299.92	113.25
1302.09	118.831
1304.25	125.719
1306.42	119.385
1308.44	134
1310.61	134
1312.79	132
1314.97	142
1317.14	140
1319.31	132
1321.48	148
1323.66	148
1325.83	148
1328	140
1330.17	150
1332.34	158
1334.5	136
1336.67	142
1338.84	132
1341	146
1343.17	132
1345.33	138
1347.5	130
1349.66	134
1351.83	134
1353.99	118
1356.15	108
1358.31	106
1360.47	108
1362.63	108
1364.79	108
1366.94	104
1369.1	106
1371.26	98
1373.41	92
1375.57	88
1377.72	88
1379.88	82
1382.03	88
1384.18	88
1386.33	90
1388.48	80
1390.64	76
1392.79	72
1394.93	78
1397.08	76
1399.23	64
1401.38	74
1403.52	78
1405.67	72
1407.81	58
1409.96	78
1412.1	60
1414.24	72
1416.39	70
1418.53	64
1420.67	78
1422.81	64
1424.95	56
1427.09	68
1429.23	62
1431.36	60
1433.5	58
1435.64	62
1437.77	64
1439.91	54
1442.04	64
1444.17	66
1446.31	56
1448.44	64
1450.57	68
1452.7	56
1454.83	58
1456.96	66
1459.09	62
1461.22	68
1463.34	66
1465.47	62
1467.6	60
1469.72	60
1471.85	56
1473.97	60
1476.09	58
1478.22	48
1480.34	60
1482.46	66
1484.58	62
1486.7	58
1488.82	60
1490.94	62
1493.06	62
1495.17	62
1497.29	68
1499.41	62
1501.52	64
1503.64	62
1505.75	64
1507.86	66
1509.98	60
1512.09	52
1514.2	58
1516.31	70
1518.42	68
1520.53	60
1522.64	66
1524.74	68
1526.85	64
1528.96	64
1531.07	62
1533.17	68
1535.27	60
1537.38	62
1539.48	74
1541.58	64
1543.69	64
1545.79	76
1547.89	66
1549.99	70
1552.09	76
1554.19	84
1556.28	82
1558.38	84
1560.48	80
1562.57	84
1564.67	92
1566.76	86
1568.86	88
1570.95	100
1573.05	90
1575.14	96
1577.23	100
1579.32	100
1581.41	108
1583.5	118
1585.59	110
1587.68	110
1589.76	114
1591.85	102
1593.94	112
1596.02	114
1598.11	114
1600.19	124
1602.27	120
1604.36	116
1606.44	114
1608.52	116
1610.6	116
1612.68	104
1614.76	108
1616.84	102
1618.92	104
1621	102
1623.07	96
1625.15	108
1627.23	102
1629.3	88
1631.38	80
1633.45	76
1635.52	84
1637.59	76
1639.67	76
1641.74	68
1643.81	72
1645.88	62
1647.95	64
1650.02	62
1652.08	68
1654.15	52
1656.22	58
1658.28	58
1660.35	56
1662.41	54
1664.48	52
1666.54	54
1668.6	50
1670.67	48
1672.73	50
1674.79	40
1676.85	44
1678.91	52
1680.97	44
1683.03	44
1685.08	42
1687.14	40
1689.2	42
1691.25	46
1693.31	44
1695.36	42
1697.42	42
1699.47	40
1701.52	50
1703.57	36
1705.63	46
1707.68	46
1709.72	38
1711.77	38
1713.82	46
1715.87	42
1717.92	36
1719.97	46
1722.01	46
1724.06	44
1726.1	42
1728.15	42
1730.19	38
1732.23	36
1734.27	38
1736.32	44
1738.36	38
1740.4	34
1742.44	44
1744.48	42
1746.51	38
1748.55	34
1750.59	38
1752.63	40
1754.66	42
1756.7	42
1758.73	42
1760.77	40
1762.8	32
1764.83	34
1766.86	38
1768.9	36
1770.93	34
1772.96	44
1774.99	42
1777.02	44
1779.04	46
1781.07	36
1783.1	42
1785.13	42
1787.15	38
1789.18	42
1791.2	46
1793.23	36
1795.25	34
1797.27	40
1799.29	42
1801.31	38
1803.34	44
1805.36	42
1807.38	34
1809.39	30
1811.41	36
1813.43	34
1815.45	42
1817.46	38
1819.48	38
1821.49	38
1823.51	38
1825.52	36
1827.54	36
1829.55	36
1831.56	36
1833.57	36
1835.58	38
1837.59	40
1839.6	38
1841.61	40
1843.62	40
1845.63	40
1847.64	36
1849.64	34
1851.65	42
1853.65	38
1855.66	38
1857.66	42
1859.66	42
1861.67	38
1863.67	38
1865.67	40
1867.67	34
1869.67	42
1871.67	42
1873.67	42
1875.67	42
1877.67	30
1879.66	34
1881.66	42
1883.66	34
1885.65	36
1887.65	42
1889.64	38
1891.63	36
1893.63	40
1895.62	38
1897.61	40
1899.6	34
1901.59	36
1903.58	36
1905.57	34
1907.56	30
1909.55	38
1911.53	40
1913.52	40
1915.51	40
1917.49	40
1919.48	40
1921.46	40
1923.45	42
1925.43	34
1927.41	36
1929.39	36
1931.37	30
1933.36	36
1935.33	36
1937.31	36
1939.29	36
1941.27	34
1943.25	42
1945.23	38
1947.2	36
1949.18	32
1951.15	40
1953.13	35
1955.1	44
1957.08	42
1959.05	34
1961.02	38
1962.99	42
1964.96	48
1966.93	30
1968.9	36
1970.87	36
1972.84	38
1974.81	32
1976.77	38
1978.74	36
1980.71	36
1982.67	30
1984.64	36
1986.6	38
1988.57	34
1990.53	38
1992.49	34
1994.45	40
1996.41	38
1998.37	40
1999.35	38