File: muestras/LIG/fproof_27.txt
#Acq. time (s)=	10
#Accumulations=	2
#Range (cm-¹)=	100...2000
#Windows=	2
#Autofocus=	Off
#AutoExposure=	Off
#Spike filter=	Multiple accum.
#Delay time (s)=	0
#Binning=	1
#Readout mode=	Signal
#DeNoise=	Off
#ICS correction=	Off
#Dark correction=	Off
#Inst. Process=	Off
#Instrument=	LabRAM HR Evol
#Detector=	Syncerity OE
#Objective=	x100_VIS_LWD
#Grating=	600 (500nm)
#ND Filter=	25%
#Laser=	633nm_Edge
#Hole=	100.021
#Range=	Visible
#Project=	LIG
#Sample=	proof
#Site=
#Title=	fproof
#Remark=
#Date=	07.03.2023 13:38
#Acquired=	07.03.2023 13:38:14
101.054	70
103.621	76
106.187	70
108.753	66
111.317	68
113.881	68
116.443	70
119.005	70
121.566	72
124.126	70
126.685	68
129.243	70
131.801	70
134.357	72
136.911	70
139.466	68
142.021	64
144.574	56
147.126	64
149.676	72
152.227	66
154.777	70
157.325	68
159.873	62
162.419	62
164.966	76
167.51	64
170.055	68
172.598	66
175.141	64
177.682	64
180.222	56
182.763	72
185.302	62
187.839	66
190.378	66
192.914	70
195.449	70
197.983	74
200.517	62
203.05	68
205.582	56
208.113	62
210.643	76
213.173	60
215.701	68
218.229	66
220.756	70
223.282	80
225.808	60
228.331	70
230.855	60
233.378	56
235.9	70
238.419	64
240.94	70
243.46	68
245.977	68
248.495	70
251.011	72
253.527	70
256.041	64
258.556	64
261.068	60
263.58	68
266.092	62
268.603	60
271.112	68
273.622	68
276.129	66
278.636	66
281.142	64
283.647	64
286.152	64
288.655	60
291.158	70
293.66	72
296.161	62
298.661	60
301.161	58
303.66	72
306.158	76
308.655	68
311.151	56
313.645	82
316.14	72
318.634	68
321.125	72
323.618	78
326.109	68
328.598	74
331.088	72
333.576	70
336.064	68
338.55	72
341.037	76
343.521	66
346.005	70
348.489	72
350.971	68
353.453	58
355.935	72
358.414	68
360.893	66
363.371	70
365.848	70
368.325	66
370.801	70
373.275	58
375.75	64
378.223	62
380.695	78
383.167	60
385.638	68
388.108	72
390.577	62
393.044	70
395.512	60
397.979	66
400.445	76
402.909	84
405.374	64
407.836	68
410.299	68
412.762	70
415.221	70
417.681	76
420.141	76
422.598	74
425.057	80
427.513	76
429.968	72
432.424	74
434.878	64
437.33	68
439.783	72
442.234	80
444.685	74
447.136	76
449.585	64
452.033	76
454.48	82
456.927	74
459.372	70
461.817	70
464.261	76
466.705	70
469.147	68
471.589	74
474.029	70
476.47	64
478.909	68
481.347	78
483.785	68
486.221	64
488.657	70
491.093	80
493.527	72
495.96	66
498.393	66
500.824	74
503.256	66
505.686	62
508.115	70
510.543	72
512.972	70
515.399	76
517.825	76
520.25	64
522.674	70
525.097	78
527.52	70
529.942	64
532.364	66
534.784	72
537.204	64
539.623	76
542.041	72
544.458	64
546.874	66
549.289	72
551.705	68
554.118	70
556.531	72
558.944	62
561.355	72
563.766	64
566.175	72
568.585	70
570.992	70
573.401	64
575.807	66
578.212	66
580.618	60
583.022	80
585.425	70
587.827	70
590.229	66
592.631	72
595.031	70
597.43	80
599.829	74
602.226	78
604.623	78
607.02	76
609.415	76
611.808	78
614.202	80
616.596	80
618.988	68
621.38	72
623.769	74
626.159	80
628.549	78
630.936	60
633.324	78
635.71	74
638.096	68
640.481	76
642.866	66
645.248	72
647.632	78
650.013	74
652.394	70
654.773	70
657.154	70
659.532	74
661.91	78
664.286	74
666.663	66
669.038	72
671.412	74
673.786	74
676.159	68
678.532	70
680.903	70
683.274	70
685.644	74
688.014	76
690.382	62
692.749	74
695.116	76
697.482	72
699.846	78
702.211	78
704.574	74
706.938	68
709.299	76
711.661	74
714.021	84
716.381	88
718.739	78
721.097	68
723.455	72
725.811	84
728.167	80
730.521	68
732.877	84
735.23	74
737.582	76
739.934	74
742.285	80
744.635	74
746.985	78
749.334	76
751.682	82
754.028	66
756.374	76
758.72	78
761.065	82
763.408	76
765.752	80
768.095	64
770.436	70
772.777	70
775.116	72
777.456	70
779.794	78
782.133	68
784.469	74
786.806	68
789.141	66
791.476	74
793.809	72
796.143	74
798.476	80
800.807	80
803.138	74
805.468	78
807.797	78
810.125	70
812.453	78
814.78	78
817.106	76
819.432	78
821.757	82
824.081	70
826.403	74
828.726	74
831.048	78
833.368	76
835.688	80
838.008	78
840.326	74
842.644	70
844.96	76
847.277	66
849.592	72
851.906	72
854.221	72
856.534	78
858.846	84
861.159	86
863.469	66
865.779	80
868.088	76
870.396	66
872.704	64
875.011	64
877.318	70
879.623	80
881.928	80
884.232	64
886.536	70
888.838	72
891.139	86
893.44	82
895.741	74
898.039	72
900.339	72
902.637	72
904.933	78
907.231	76
909.526	78
911.821	78
914.115	70
916.408	78
918.701	78
920.993	74
923.283	76
925.575	74
927.864	76
930.153	70
932.441	72
934.728	70
937.014	74
939.3	84
941.585	76
943.87	76
946.154	84
948.437	74
950.719	74
953	74
955.28	72
957.56	70
959.84	86
962.117	70
964.395	72
966.673	74
968.948	84
971.224	80
973.498	68
975.773	84
978.045	84
980.317	78
982.59	78
984.86	72
987.13	76
989.399	80
991.669	84
993.937	74
996.204	76
998.47	78
1000.74	80
1003	74
1005.26	84
1007.53	82
1009.79	80
1012.05	74
1014.31	74
1016.57	80
1018.83	78
1021.09	86
1023.35	84
1025.61	88
1027.87	84
1030.12	82
1032.38	84
1034.63	78
1036.88	82
1039.14	86
1041.39	88
1043.64	72
1045.89	78
1048.14	88
1050.39	86
1052.64	78
1054.89	90
1057.14	70
1059.38	84
1061.63	88
1063.87	92
1066.12	74
1068.36	98
1070.6	88
1072.85	86
1075.09	80
1077.33	98
1079.57	90
1081.81	86
1084.05	90
1086.28	84
1088.52	88
1090.76	92
1092.99	86
1095.23	98
1097.46	86
1099.69	92
1101.93	74
1104.16	82
1106.39	88
1108.62	82
1110.85	86
1113.08	90
1115.31	88
1117.53	88
1119.76	88
1121.99	88
1124.21	92
1126.44	102
1128.66	94
1130.88	100
1133.11	92
1135.33	88
1137.55	102
1139.77	96
1141.99	102
1144.21	94
1146.43	102
1148.64	98
1150.86	104
1153.08	98
1155.29	104
1157.51	104
1159.72	104
1161.93	106
1164.14	104
1166.36	104
1168.57	114
1170.78	102
1172.99	114
1175.2	108
1177.4	96
1179.61	104
1181.82	100
1184.02	110
1186.23	110
1188.43	96
1190.64	100
1192.84	104
1195.04	116
1197.24	112
1199.45	111.97
1201.64	106.169
1203.84	106.054
1206.04	105.507
1208.24	105.36
1210.44	107.05
1212.64	116.673
1214.83	121.514
1217.03	113.71
1219.22	115.428
1221.41	125.498
1223.61	114.467
1225.8	110.41
1227.99	121.356
1230.18	126.876
1232.37	114.385
1234.56	125.384
1236.75	120.891
1238.94	124.92
1241.13	126.677
1243.31	130.398
1245.5	127.837
1247.68	122.96
1249.87	130.511
1252.05	128.018
1254.24	134.684
1256.42	137.538
1258.6	139.82
1260.78	135.062
1262.96	139.349
1265.14	138.727
1267.32	146.26
1269.5	147.801
1271.67	155.32
1273.85	152.122
1276.03	156.613
1278.2	148.316
1280.38	151.957
1282.55	154.415
1284.72	164.419
1286.9	156.461
1289.07	162.777
1291.24	171.615
1293.41	182.48
1295.58	167.442
1297.75	173.234
1299.92	182.316
1302.09	176.453
1304.25	182.888
1306.42	167.252
1308.44	198
1310.61	210
1312.79	192
1314.97	190
1317.14	178
1319.31	198
1321.48	200
1323.66	204
1325.83	186
1328	206
1330.17	202
1332.34	200
1334.5	198
1336.67	180
1338.84	200
1341	180
1343.17	194
1345.33	198
1347.5	182
1349.66	186
1351.83	180
1353.99	172
1356.15	174
1358.31	174
1360.47	190
1362.63	154
1364.79	174
1366.94	164
1369.1	164
1371.26	160
1373.41	158
1375.57	162
1377.72	156
1379.88	166
1382.03	150
1384.18	162
1386.33	168
1388.48	142
1390.64	164
1392.79	144
1394.93	146
1397.08	152
1399.23	144
1401.38	128
1403.52	140
1405.67	140
1407.81	144
1409.96	140
1412.1	136
1414.24	138
1416.39	142
1418.53	134
1420.67	136
1422.81	136
1424.95	132
1427.09	120
1429.23	136
1431.36	130
1433.5	124
1435.64	124
1437.77	118
1439.91	134
1442.04	116
1444.17	118
1446.31	130
1448.44	138
1450.57	126
1452.7	126
1454.83	118
1456.96	116
1459.09	116
1461.22	122
1463.34	128
1465.47	120
1467.6	134
1469.72	126
1471.85	120
1473.97	118
1476.09	114
1478.22	120
1480.34	118
1482.46	132
1484.58	112
1486.7	126
1488.82	108
1490.94	130
1493.06	124
1495.17	114
1497.29	130
1499.41	128
1501.52	116
1503.64	124
1505.75	122
1507.86	124
1509.98	128
1512.09	128
1514.2	120
1516.31	128
1518.42	124
1520.53	124
1522.64	118
1524.74	138
1526.85	132
1528.96	126
1531.07	130
1533.17	128
1535.27	116
1537.38	118
1539.48	126
1541.58	134
1543.69	128
1545.79	136
1547.89	120
1549.99	134
1552.09	128
1554.19	122
1556.28	128
1558.38	144
1560.48	138
1562.57	148
1564.67	144
1566.76	138
1568.86	140
1570.95	146
1573.05	152
1575.14	136
1577.23	152
1579.32	152
1581.41	164
1583.5	154
1585.59	156
1587.68	168
1589.76	154
1591.85	168
1593.94	174
1596.02	154
1598.11	164
1600.19	166
1602.27	158
1604.36	168
1606.44	164
1608.52	156
1610.6	148
1612.68	146
1614.76	150
1616.84	144
1618.92	138
1621	148
1623.07	148
1625.15	136
1627.23	136
1629.3	128
1631.38	136
1633.45	116
1635.52	120
1637.59	120
1639.67	116
1641.74	106
1643.81	110
1645.88	110
1647.95	94
1650.02	98
1652.08	92
1654.15	98
1656.22	92
1658.28	94
1660.35	92
1662.41	86
1664.48	84
1666.54	82
1668.6	84
1670.67	84
1672.73	86
1674.79	80
1676.85	86
1678.91	88
1680.97	90
1683.03	86
1685.08	90
1687.14	84
1689.2	78
1691.25	80
1693.31	66
1695.36	74
1697.42	74
1699.47	76
1701.52	72
1703.57	76
1705.63	86
1707.68	68
1709.72	74
1711.77	74
1713.82	80
1715.87	66
1717.92	70
1719.97	78
1722.01	72
1724.06	76
1726.1	70
1728.15	64
1730.19	72
1732.23	82
1734.27	74
1736.32	72
1738.36	74
1740.4	76
1742.44	68
1744.48	74
1746.51	80
1748.55	66
1750.59	82
1752.63	62
1754.66	76
1756.7	64
1758.73	74
1760.77	62
1762.8	82
1764.83	72
1766.86	78
1768.9	66
1770.93	74
1772.96	62
1774.99	70
1777.02	74
1779.04	74
1781.07	68
1783.1	76
1785.13	72
1787.15	72
1789.18	82
1791.2	70
1793.23	68
1795.25	70
1797.27	68
1799.29	76
1801.31	62
1803.34	76
1805.36	66
1807.38	66
1809.39	64
1811.41	70
1813.43	70
1815.45	70
1817.46	68
1819.48	72
1821.49	62
1823.51	68
1825.52	72
1827.54	82
1829.55	64
1831.56	66
1833.57	68
1835.58	78
1837.59	72
1839.6	74
1841.61	66
1843.62	72
1845.63	70
1847.64	60
1849.64	70
1851.65	70
1853.65	62
1855.66	68
1857.66	60
1859.66	70
1861.67	68
1863.67	72
1865.67	66
1867.67	66
1869.67	68
1871.67	66
1873.67	68
1875.67	72
1877.67	72
1879.66	64
1881.66	66
1883.66	66
1885.65	68
1887.65	68
1889.64	64
1891.63	64
1893.63	68
1895.62	68
1897.61	66
1899.6	66
1901.59	72
1903.58	62
1905.57	72
1907.56	72
1909.55	70
1911.53	62
1913.52	70
1915.51	54
1917.49	68
1919.48	66
1921.46	66
1923.45	66
1925.43	64
1927.41	66
1929.39	72
1931.37	74
1933.36	70
1935.33	58
1937.31	68
1939.29	64
1941.27	60
1943.25	70
1945.23	58
1947.2	54
1949.18	64
1951.15	76
1953.13	59
1955.1	70
1957.08	68
1959.05	66
1961.02	64
1962.99	64
1964.96	64
1966.93	62
1968.9	66
1970.87	66
1972.84	60
1974.81	60
1976.77	64
1978.74	74
1980.71	62
1982.67	68
1984.64	64
1986.6	58
1988.57	60
1990.53	68
1992.49	64
1994.45	60
1996.41	64
1998.37	66
1999.35	64