File: muestras/LIG/fproof_10.txt
#Acq. time (s)=	10
#Accumulations=	2
#Range (cm-¹)=	100...2000
#Windows=	2
#Autofocus=	Off
#AutoExposure=	Off
#Spike filter=	Multiple accum.
#Delay time (s)=	0
#Binning=	1
#Readout mode=	Signal
#DeNoise=	Off
#ICS correction=	Off
#Dark correction=	Off
#Inst. Process=	Off
#Instrument=	LabRAM HR Evol
#Detector=	Syncerity OE
#Objective=	x100_VIS_LWD
#Grating=	600 (500nm)
#ND Filter=	25%
#Laser=	633nm_Edge
#Hole=	100.021
#Range=	Visible
#Project=	LIG
#Sample=	proof
#Site=
#Title=	fproof
#Remark=
#Date=	07.03.2023 12:47
#Acquired=	07.03.2023 12:47:05
101.054	34
103.621	44
106.187	40
108.753	38
111.317	42
113.881	40
116.443	38
119.005	32
121.566	42
124.126	40
126.685	38
129.243	40
131.801	44
134.357	42
136.911	46
139.466	38
142.021	36
144.574	38
147.126	42
149.676	36
152.227	38
154.777	36
157.325	40
159.873	40
162.419	40
164.966	40
167.51	36
170.055	32
172.598	36
175.141	32
177.682	38
180.222	42
182.763	32
185.302	36
187.839	38
190.378	38
192.914	40
195.449	36
197.983	32
200.517	40
203.05	38
205.582	36
208.113	42
210.643	36
213.173	40
215.701	36
218.229	40
220.756	44
223.282	38
225.808	42
228.331	38
230.855	34
233.378	34
235.9	34
238.419	32
240.94	36
243.46	40
245.977	40
248.495	34
251.011	36
253.527	34
256.041	30
258.556	32
261.068	40
263.58	32
266.092	38
268.603	42
271.112	30
273.622	34
276.129	36
278.636	38
281.142	36
283.647	32
286.152	42
288.655	34
291.158	34
293.66	36
296.161	42
298.661	34
301.161	30
303.66	34
306.158	32
308.655	36
311.151	36
313.645	40
316.14	38
318.634	28
321.125	42
323.618	38
326.109	30
328.598	38
331.088	38
333.576	28
336.064	34
338.55	36
341.037	38
343.521	32
346.005	42
348.489	36
350.971	34
353.453	36
355.935	46
358.414	36
360.893	36
363.371	32
365.848	40
368.325	38
370.801	32
373.275	34
375.75	38
378.223	32
380.695	32
383.167	36
385.638	34
388.108	42
390.577	30
393.044	36
395.512	42
397.979	34
400.445	34
402.909	36
405.374	26
407.836	34
410.299	34
412.762	38
415.221	30
417.681	30
420.141	32
422.598	38
425.057	34
427.513	34
429.968	32
432.424	32
434.878	36
437.33	34
439.783	30
442.234	36
444.685	34
447.136	40
449.585	30
452.033	32
454.48	36
456.927	36
459.372	42
461.817	32
464.261	40
466.705	32
469.147	40
471.589	36
474.029	32
476.47	36
478.909	30
481.347	36
483.785	38
486.221	34
488.657	38
491.093	42
493.527	42
495.96	30
498.393	34
500.824	32
503.256	36
505.686	36
508.115	32
510.543	34
512.972	28
515.399	34
517.825	30
520.25	30
522.674	34
525.097	32
527.52	28
529.942	34
532.364	30
534.784	38
537.204	36
539.623	34
542.041	32
544.458	36
546.874	34
549.289	34
551.705	32
554.118	28
556.531	36
558.944	32
561.355	38
563.766	36
566.175	36
568.585	30
570.992	36
573.401	42
575.807	34
578.212	34
580.618	34
583.022	36
585.425	36
587.827	40
590.229	36
592.631	36
595.031	38
597.43	34
599.829	36
602.226	38
604.623	34
607.02	34
609.415	32
611.808	34
614.202	34
616.596	36
618.988	42
621.38	34
623.769	36
626.159	34
628.549	32
630.936	38
633.324	32
635.71	34
638.096	34
640.481	32
642.866	36
645.248	42
647.632	32
650.013	36
652.394	38
654.773	32
657.154	32
659.532	34
661.91	34
664.286	30
666.663	32
669.038	40
671.412	34
673.786	38
676.159	34
678.532	36
680.903	36
683.274	36
685.644	34
688.014	42
690.382	40
692.749	38
695.116	36
697.482	34
699.846	38
702.211	40
704.574	38
706.938	38
709.299	32
711.661	30
714.021	40
716.381	36
718.739	36
721.097	40
723.455	30
725.811	40
728.167	36
730.521	40
732.877	32
735.23	30
737.582	30
739.934	36
742.285	34
744.635	36
746.985	38
749.334	38
751.682	38
754.028	36
756.374	40
758.72	40
761.065	36
763.408	42
765.752	32
768.095	36
770.436	32
772.777	32
775.116	42
777.456	32
779.794	30
782.133	34
784.469	34
786.806	42
789.141	34
791.476	38
793.809	30
796.143	34
798.476	36
800.807	34
803.138	44
805.468	42
807.797	38
810.125	42
812.453	36
814.78	32
817.106	38
819.432	38
821.757	38
824.081	38
826.403	30
828.726	40
831.048	36
833.368	34
835.688	36
838.008	34
840.326	36
842.644	40
844.96	38
847.277	36
849.592	38
851.906	30
854.221	36
856.534	34
858.846	36
861.159	40
863.469	40
865.779	34
868.088	36
870.396	30
872.704	48
875.011	40
877.318	38
879.623	40
881.928	34
884.232	42
886.536	40
888.838	32
891.139	32
893.44	38
895.741	32
898.039	40
900.339	36
902.637	34
904.933	42
907.231	42
909.526	34
911.821	30
914.115	32
916.408	34
918.701	42
920.993	36
923.283	36
925.575	24
927.864	34
930.153	36
932.441	34
934.728	32
937.014	40
939.3	32
941.585	36
943.87	36
946.154	40
948.437	40
950.719	38
953	38
955.28	40
957.56	32
959.84	30
962.117	38
964.395	36
966.673	38
968.948	36
971.224	38
973.498	34
975.773	30
978.045	36
980.317	40
982.59	36
984.86	28
987.13	36
989.399	34
991.669	38
993.937	34
996.204	36
998.47	38
1000.74	34
1003	38
1005.26	38
1007.53	32
1009.79	38
1012.05	36
1014.31	40
1016.57	44
1018.83	38
1021.09	36
1023.35	34
1025.61	36
1027.87	38
1030.12	36
1032.38	38
1034.63	30
1036.88	42
1039.14	38
1041.39	36
1043.64	38
1045.89	44
1048.14	38
1050.39	36
1052.64	36
1054.89	40
1057.14	34
1059.38	34
1061.63	36
1063.87	28
1066.12	34
1068.36	38
1070.6	40
1072.85	36
1075.09	40
1077.33	42
1079.57	42
1081.81	46
1084.05	38
1086.28	36
1088.52	40
1090.76	40
1092.99	44
1095.23	42
1097.46	48
1099.69	38
1101.93	44
1104.16	42
1106.39	42
1108.62	42
1110.85	46
1113.08	48
1115.31	42
1117.53	46
1119.76	38
1121.99	42
1124.21	42
1126.44	42
1128.66	40
1130.88	42
1133.11	48
1135.33	46
1137.55	44
1139.77	44
1141.99	40
1144.21	40
1146.43	40
1148.64	42
1150.86	36
1153.08	40
1155.29	42
1157.51	44
1159.72	46
1161.93	44
1164.14	42
1166.36	40
1168.57	38
1170.78	42
1172.99	48
1175.2	44
1177.4	42
1179.61	38
1181.82	52
1184.02	46
1186.23	36
1188.43	38
1190.64	50
1192.84	50
1195.04	42
1197.24	48
1199.45	49.98
1201.64	36.2306
1203.84	55.6411
1206.04	42.207
1208.24	47.5747
1210.44	42.2713
1212.64	44.891
1214.83	50
1217.03	41.3499
1219.22	47.4319
1221.41	40.5423
1223.61	48.4346
1225.8	38.6918
1227.99	53.0928
1230.18	46.8741
1232.37	43.3959
1234.56	50.9618
1236.75	44.1277
1238.94	52.2124
1241.13	48.7983
1243.31	48.7278
1245.5	47.8372
1247.68	49.11
1249.87	50.6987
1252.05	53.4082
1254.24	51.6757
1256.42	52
1258.6	51.9643
1260.78	53.1939
1262.96	56.1014
1265.14	61.2238
1267.32	61.9461
1269.5	60.8053
1271.67	62.1022
1273.85	72.0496
1276.03	62.5601
1278.2	63.7387
1280.38	67.3682
1282.55	80.295
1284.72	77.4719
1286.9	85.4686
1289.07	76.7193
1291.24	88.6586
1293.41	100.7
1295.58	90.572
1297.75	101.434
1299.92	109.028
1302.09	106.276
1304.25	117.285
1306.42	129.447
1308.44	130
1310.61	138
1312.79	140
1314.97	152
1317.14	156
1319.31	152
1321.48	160
1323.66	174
1325.83	166
1328	178
1330.17	180
1332.34	182
1334.5	168
1336.67	172
1338.84	172
1341	170
1343.17	150
1345.33	156
1347.5	144
1349.66	140
1351.83	130
1353.99	120
1356.15	122
1358.31	104
1360.47	98
1362.63	110
1364.79	104
1366.94	90
1369.1	76
1371.26	80
1373.41	78
1375.57	86
1377.72	64
1379.88	72
1382.03	70
1384.18	76
1386.33	56
1388.48	62
1390.64	62
1392.79	72
1394.93	64
1397.08	60
1399.23	58
1401.38	56
1403.52	64
1405.67	54
1407.81	58
1409.96	58
1412.1	58
1414.24	46
1416.39	62
1418.53	48
1420.67	52
1422.81	52
1424.95	50
1427.09	52
1429.23	48
1431.36	48
1433.5	52
1435.64	54
1437.77	52
1439.91	44
1442.04	48
1444.17	44
1446.31	44
1448.44	46
1450.57	52
1452.7	54
1454.83	48
1456.96	48
1459.09	44
1461.22	44
1463.34	50
1465.47	52
1467.6	48
1469.72	44
1471.85	46
1473.97	48
1476.09	52
1478.22	48
1480.34	56
1482.46	42
1484.58	42
1486.7	48
1488.82	48
1490.94	48
1493.06	50
1495.17	52
1497.29	48
1499.41	52
1501.52	50
1503.64	48
1505.75	54
1507.86	56
1509.98	56
1512.09	50
1514.2	48
1516.31	50
1518.42	58
1520.53	50
1522.64	58
1524.74	56
1526.85	56
1528.96	56
1531.07	56
1533.17	52
1535.27	52
1537.38	62
1539.48	52
1541.58	62
1543.69	66
1545.79	66
1547.89	64
1549.99	68
1552.09	60
1554.19	76
1556.28	64
1558.38	80
1560.48	76
1562.57	84
1564.67	90
1566.76	90
1568.86	92
1570.95	98
1573.05	120
1575.14	120
1577.23	112
1579.32	116
1581.41	124
1583.5	126
1585.59	128
1587.68	116
1589.76	136
1591.85	130
1593.94	126
1596.02	134
1598.11	112
1600.19	122
1602.27	126
1604.36	114
1606.44	120
1608.52	114
1610.6	116
1612.68	116
1614.76	116
1616.84	116
1618.92	106
1621	102
1623.07	100
1625.15	92
1627.23	90
1629.3	86
1631.38	72
1633.45	82
1635.52	70
1637.59	70
1639.67	66
1641.74	62
1643.81	58
1645.88	54
1647.95	46
1650.02	52
1652.08	50
1654.15	48
1656.22	44
1658.28	44
1660.35	50
1662.41	46
1664.48	44
1666.54	40
1668.6	38
1670.67	40
1672.73	38
1674.79	46
1676.85	44
1678.91	40
1680.97	46
1683.03	44
1685.08	38
1687.14	36
1689.2	40
1691.25	36
1693.31	42
1695.36	36
1697.42	42
1699.47	40
1701.52	34
1703.57	36
1705.63	40
1707.68	38
1709.72	40
1711.77	38
1713.82	38
1715.87	36
1717.92	40
1719.97	42
1722.01	44
1724.06	38
1726.1	36
1728.15	40
1730.19	38
1732.23	38
1734.27	38
1736.32	40
1738.36	42
1740.4	38
1742.44	40
1744.48	34
1746.51	36
1748.55	38
1750.59	38
1752.63	42
1754.66	36
1756.7	38
1758.73	34
1760.77	36
1762.8	36
1764.83	38
1766.86	36
1768.9	36
1770.93	36
1772.96	40
1774.99	28
1777.02	36
1779.04	36
1781.07	44
1783.1	36
1785.13	36
1787.15	34
1789.18	36
1791.2	34
1793.23	32
1795.25	38
1797.27	36
1799.29	38
1801.31	34
1803.34	34
1805.36	34
1807.38	38
1809.39	26
1811.41	26
1813.43	34
1815.45	30
1817.46	40
1819.48	34
1821.49	34
1823.51	36
1825.52	36
1827.54	32
1829.55	44
1831.56	36
1833.57	36
1835.58	40
1837.59	38
1839.6	36
1841.61	40
1843.62	36
1845.63	38
1847.64	40
1849.64	36
1851.65	34
1853.65	40
1855.66	30
1857.66	30
1859.66	38
1861.67	30
1863.67	38
1865.67	38
1867.67	36
1869.67	30
1871.67	28
1873.67	38
1875.67	40
1877.67	38
1879.66	36
1881.66	32
1883.66	38
1885.65	36
1887.65	40
1889.64	36
1891.63	32
1893.63	36
1895.62	36
1897.61	40
1899.6	34
1901.59	30
1903.58	38
1905.57	30
1907.56	32
1909.55	28
1911.53	38
1913.52	32
1915.51	34
1917.49	30
1919.48	38
1921.46	34
1923.45	36
1925.43	28
1927.41	40
1929.39	30
1931.37	40
1933.36	40
1935.33	28
1937.31	32
1939.29	40
1941.27	34
1943.25	36
1945.23	32
1947.2	36
1949.18	28
1951.15	34
1953.13	35
1955.1	32
1957.08	34
1959.05	38
1961.02	36
1962.99	36
1964.96	34
1966.93	42
1968.9	28
1970.87	28
1972.84	30
1974.81	32
1976.77	28
1978.74	26
1980.71	30
1982.67	32
1984.64	32
1986.6	38
1988.57	34
1990.53	36
1992.49	32
1994.45	36
1996.41	32
1998.37	28
1999.35	32