File: muestras/LIG/fproof_23.txt
#Acq. time (s)=	10
#Accumulations=	2
#Range (cm-¹)=	100...2000
#Windows=	2
#Autofocus=	Off
#AutoExposure=	Off
#Spike filter=	Multiple accum.
#Delay time (s)=	0
#Binning=	1
#Readout mode=	Signal
#DeNoise=	Off
#ICS correction=	Off
#Dark correction=	Off
#Inst. Process=	Off
#Instrument=	LabRAM HR Evol
#Detector=	Syncerity OE
#Objective=	x100_VIS_LWD
#Grating=	600 (500nm)
#ND Filter=	25%
#Laser=	633nm_Edge
#Hole=	100.021
#Range=	Visible
#Project=	LIG
#Sample=	proof
#Site=
#Title=	fproof
#Remark=
#Date=	07.03.2023 13:26
#Acquired=	07.03.2023 13:26:39
101.054	56
103.621	52
106.187	44
108.753	46
111.317	46
113.881	46
116.443	46
119.005	48
121.566	44
124.126	50
126.685	46
129.243	42
131.801	40
134.357	38
136.911	44
139.466	38
142.021	38
144.574	30
147.126	48
149.676	48
152.227	42
154.777	46
157.325	40
159.873	36
162.419	42
164.966	44
167.51	38
170.055	38
172.598	40
175.141	34
177.682	44
180.222	40
182.763	38
185.302	44
187.839	48
190.378	46
192.914	38
195.449	44
197.983	44
200.517	42
203.05	40
205.582	52
208.113	36
210.643	36
213.173	46
215.701	50
218.229	40
220.756	44
223.282	48
225.808	40
228.331	36
230.855	50
233.378	42
235.9	48
238.419	44
240.94	42
243.46	40
245.977	48
248.495	40
251.011	42
253.527	36
256.041	42
258.556	40
261.068	40
263.58	40
266.092	44
268.603	42
271.112	42
273.622	40
276.129	40
278.636	38
281.142	38
283.647	42
286.152	46
288.655	44
291.158	44
293.66	40
296.161	38
298.661	40
301.161	42
303.66	40
306.158	38
308.655	32
311.151	42
313.645	44
316.14	38
318.634	44
321.125	44
323.618	44
326.109	42
328.598	32
331.088	40
333.576	40
336.064	44
338.55	46
341.037	34
343.521	40
346.005	38
348.489	36
350.971	46
353.453	48
355.935	48
358.414	42
360.893	46
363.371	40
365.848	42
368.325	48
370.801	48
373.275	44
375.75	40
378.223	40
380.695	46
383.167	38
385.638	38
388.108	46
390.577	42
393.044	42
395.512	40
397.979	40
400.445	46
402.909	46
405.374	44
407.836	40
410.299	48
412.762	44
415.221	46
417.681	42
420.141	36
422.598	40
425.057	38
427.513	42
429.968	40
432.424	46
434.878	34
437.33	38
439.783	44
442.234	42
444.685	50
447.136	34
449.585	46
452.033	42
454.48	36
456.927	42
459.372	42
461.817	42
464.261	46
466.705	36
469.147	38
471.589	36
474.029	44
476.47	40
478.909	40
481.347	36
483.785	32
486.221	40
488.657	40
491.093	38
493.527	44
495.96	40
498.393	44
500.824	36
503.256	38
505.686	40
508.115	36
510.543	38
512.972	40
515.399	40
517.825	36
520.25	42
522.674	36
525.097	40
527.52	42
529.942	42
532.364	40
534.784	40
537.204	36
539.623	38
542.041	44
544.458	50
546.874	32
549.289	34
551.705	38
554.118	40
556.531	40
558.944	42
561.355	40
563.766	34
566.175	34
568.585	42
570.992	38
573.401	40
575.807	34
578.212	42
580.618	34
583.022	46
585.425	44
587.827	40
590.229	44
592.631	44
595.031	46
597.43	40
599.829	42
602.226	42
604.623	40
607.02	42
609.415	38
611.808	38
614.202	40
616.596	40
618.988	46
621.38	44
623.769	38
626.159	40
628.549	44
630.936	38
633.324	40
635.71	38
638.096	40
640.481	38
642.866	36
645.248	36
647.632	38
650.013	42
652.394	44
654.773	40
657.154	28
659.532	42
661.91	44
664.286	42
666.663	36
669.038	46
671.412	42
673.786	40
676.159	44
678.532	34
680.903	42
683.274	44
685.644	40
688.014	48
690.382	38
692.749	36
695.116	42
697.482	42
699.846	44
702.211	36
704.574	40
706.938	38
709.299	42
711.661	42
714.021	42
716.381	44
718.739	48
721.097	38
723.455	40
725.811	30
728.167	38
730.521	40
732.877	34
735.23	36
737.582	36
739.934	44
742.285	50
744.635	40
746.985	46
749.334	40
751.682	46
754.028	36
756.374	38
758.72	44
761.065	38
763.408	38
765.752	42
768.095	40
770.436	44
772.777	34
775.116	38
777.456	36
779.794	46
782.133	48
784.469	40
786.806	36
789.141	38
791.476	32
793.809	42
796.143	40
798.476	44
800.807	50
803.138	48
805.468	40
807.797	42
810.125	40
812.453	42
814.78	48
817.106	44
819.432	44
821.757	40
824.081	40
826.403	34
828.726	42
831.048	38
833.368	40
835.688	46
838.008	42
840.326	42
842.644	40
844.96	36
847.277	44
849.592	48
851.906	40
854.221	36
856.534	46
858.846	46
861.159	38
863.469	46
865.779	42
868.088	46
870.396	44
872.704	34
875.011	36
877.318	36
879.623	42
881.928	30
884.232	40
886.536	44
888.838	34
891.139	34
893.44	40
895.741	34
898.039	40
900.339	38
902.637	42
904.933	46
907.231	38
909.526	42
911.821	36
914.115	40
916.408	38
918.701	44
920.993	42
923.283	40
925.575	40
927.864	40
930.153	36
932.441	44
934.728	42
937.014	34
939.3	46
941.585	40
943.87	44
946.154	40
948.437	42
950.719	34
953	44
955.28	42
957.56	48
959.84	42
962.117	34
964.395	36
966.673	44
968.948	40
971.224	34
973.498	42
975.773	46
978.045	38
980.317	42
982.59	42
984.86	42
987.13	40
989.399	40
991.669	46
993.937	44
996.204	46
998.47	42
1000.74	42
1003	50
1005.26	48
1007.53	48
1009.79	42
1012.05	38
1014.31	44
1016.57	48
1018.83	48
1021.09	42
1023.35	40
1025.61	48
1027.87	38
1030.12	44
1032.38	34
1034.63	48
1036.88	42
1039.14	48
1041.39	42
1043.64	46
1045.89	46
1048.14	48
1050.39	40
1052.64	48
1054.89	44
1057.14	44
1059.38	46
1061.63	48
1063.87	50
1066.12	50
1068.36	40
1070.6	54
1072.85	50
1075.09	46
1077.33	50
1079.57	40
1081.81	50
1084.05	44
1086.28	48
1088.52	44
1090.76	48
1092.99	46
1095.23	52
1097.46	44
1099.69	56
1101.93	48
1104.16	46
1106.39	44
1108.62	50
1110.85	58
1113.08	50
1115.31	58
1117.53	58
1119.76	58
1121.99	56
1124.21	58
1126.44	56
1128.66	60
1130.88	64
1133.11	54
1135.33	52
1137.55	58
1139.77	60
1141.99	62
1144.21	64
1146.43	60
1148.64	62
1150.86	66
1153.08	60
1155.29	54
1157.51	64
1159.72	58
1161.93	62
1164.14	68
1166.36	56
1168.57	62
1170.78	60
1172.99	62
1175.2	62
1177.4	60
1179.61	60
1181.82	56
1184.02	68
1186.23	64
1188.43	58
1190.64	64
1192.84	60
1195.04	64
1197.24	60
1199.45	69.96
1201.64	60.0723
1203.84	58.5226
1206.04	62.4911
1208.24	57.53
1210.44	64.5381
1212.64	61.0769
1214.83	59.2228
1217.03	64.2701
1219.22	64.4897
1221.41	64.9939
1223.61	67.35
1225.8	68.9927
1227.99	74.1434
1230.18	67.988
1232.37	73.8027
1234.56	76.9197
1236.75	78.1277
1238.94	77.098
1241.13	73.4537
1243.31	79.7665
1245.5	78.9872
1247.68	78.5096
1249.87	78.694
1252.05	82.0937
1254.24	88.2855
1256.42	89.5383
1258.6	92.1443
1260.78	87.0457
1262.96	95.3925
1265.14	101.567
1267.32	107.446
1269.5	104.744
1271.67	105.406
1273.85	115.299
1276.03	119.111
1278.2	122.877
1280.38	130.86
1282.55	144.247
1284.72	140.274
1286.9	147.596
1289.07	167.181
1291.24	167.437
1293.41	180.463
1295.58	195.258
1297.75	205.81
1299.92	230.581
1302.09	241.388
1304.25	261.683
1306.42	290.268
1308.44	288
1310.61	312
1312.79	328
1314.97	356
1317.14	362
1319.31	366
1321.48	398
1323.66	412
1325.83	410
1328	414
1330.17	386
1332.34	404
1334.5	390
1336.67	378
1338.84	370
1341	368
1343.17	358
1345.33	338
1347.5	294
1349.66	296
1351.83	262
1353.99	246
1356.15	238
1358.31	210
1360.47	224
1362.63	190
1364.79	170
1366.94	186
1369.1	178
1371.26	158
1373.41	148
1375.57	140
1377.72	130
1379.88	116
1382.03	126
1384.18	110
1386.33	118
1388.48	114
1390.64	102
1392.79	104
1394.93	102
1397.08	106
1399.23	98
1401.38	90
1403.52	92
1405.67	94
1407.81	96
1409.96	88
1412.1	86
1414.24	86
1416.39	76
1418.53	80
1420.67	74
1422.81	72
1424.95	80
1427.09	82
1429.23	72
1431.36	78
1433.5	76
1435.64	76
1437.77	74
1439.91	76
1442.04	70
1444.17	72
1446.31	68
1448.44	74
1450.57	70
1452.7	82
1454.83	72
1456.96	64
1459.09	76
1461.22	64
1463.34	68
1465.47	68
1467.6	70
1469.72	64
1471.85	72
1473.97	70
1476.09	66
1478.22	60
1480.34	74
1482.46	64
1484.58	66
1486.7	62
1488.82	68
1490.94	70
1493.06	66
1495.17	74
1497.29	66
1499.41	74
1501.52	64
1503.64	74
1505.75	70
1507.86	74
1509.98	80
1512.09	72
1514.2	66
1516.31	70
1518.42	66
1520.53	70
1522.64	78
1524.74	80
1526.85	80
1528.96	76
1531.07	88
1533.17	76
1535.27	84
1537.38	92
1539.48	94
1541.58	94
1543.69	90
1545.79	108
1547.89	96
1549.99	112
1552.09	112
1554.19	122
1556.28	110
1558.38	126
1560.48	142
1562.57	140
1564.67	158
1566.76	168
1568.86	170
1570.95	162
1573.05	174
1575.14	200
1577.23	180
1579.32	204
1581.41	198
1583.5	206
1585.59	216
1587.68	244
1589.76	216
1591.85	230
1593.94	232
1596.02	238
1598.11	226
1600.19	214
1602.27	210
1604.36	230
1606.44	198
1608.52	220
1610.6	218
1612.68	212
1614.76	210
1616.84	212
1618.92	200
1621	196
1623.07	188
1625.15	188
1627.23	164
1629.3	142
1631.38	138
1633.45	130
1635.52	112
1637.59	120
1639.67	104
1641.74	98
1643.81	94
1645.88	90
1647.95	76
1650.02	76
1652.08	70
1654.15	54
1656.22	64
1658.28	60
1660.35	64
1662.41	60
1664.48	54
1666.54	54
1668.6	50
1670.67	50
1672.73	50
1674.79	46
1676.85	58
1678.91	44
1680.97	54
1683.03	44
1685.08	56
1687.14	50
1689.2	50
1691.25	50
1693.31	50
1695.36	54
1697.42	52
1699.47	44
1701.52	46
1703.57	50
1705.63	44
1707.68	50
1709.72	50
1711.77	42
1713.82	50
1715.87	40
1717.92	40
1719.97	44
1722.01	34
1724.06	38
1726.1	46
1728.15	52
1730.19	42
1732.23	44
1734.27	46
1736.32	44
1738.36	38
1740.4	44
1742.44	46
1744.48	40
1746.51	44
1748.55	46
1750.59	44
1752.63	46
1754.66	44
1756.7	50
1758.73	40
1760.77	36
1762.8	42
1764.83	44
1766.86	46
1768.9	48
1770.93	46
1772.96	42
1774.99	38
1777.02	40
1779.04	46
1781.07	40
1783.1	46
1785.13	44
1787.15	42
1789.18	40
1791.2	40
1793.23	44
1795.25	52
1797.27	44
1799.29	42
1801.31	38
1803.34	42
1805.36	44
1807.38	40
1809.39	40
1811.41	40
1813.43	42
1815.45	48
1817.46	44
1819.48	48
1821.49	46
1823.51	40
1825.52	46
1827.54	34
1829.55	42
1831.56	42
1833.57	42
1835.58	40
1837.59	42
1839.6	38
1841.61	40
1843.62	44
1845.63	38
1847.64	42
1849.64	34
1851.65	42
1853.65	38
1855.66	46
1857.66	42
1859.66	40
1861.67	36
1863.67	30
1865.67	40
1867.67	44
1869.67	44
1871.67	36
1873.67	42
1875.67	46
1877.67	44
1879.66	38
1881.66	40
1883.66	42
1885.65	36
1887.65	44
1889.64	38
1891.63	36
1893.63	46
1895.62	48
1897.61	44
1899.6	48
1901.59	44
1903.58	46
1905.57	46
1907.56	38
1909.55	40
1911.53	36
1913.52	42
1915.51	36
1917.49	38
1919.48	36
1921.46	40
1923.45	40
1925.43	40
1927.41	38
1929.39	38
1931.37	48
1933.36	46
1935.33	40
1937.31	36
1939.29	46
1941.27	44
1943.25	40
1945.23	42
1947.2	44
1949.18	34
1951.15	38
1953.13	44
1955.1	40
1957.08	42
1959.05	36
1961.02	46
1962.99	34
1964.96	38
1966.93	38
1968.9	42
1970.87	40
1972.84	46
1974.81	42
1976.77	44
1978.74	42
1980.71	42
1982.67	40
1984.64	42
1986.6	36
1988.57	30
1990.53	36
1992.49	38
1994.45	36
1996.41	34
1998.37	42
1999.35	44