File: muestras/LIG/fproof_13.txt
#Acq. time (s)=	10
#Accumulations=	2
#Range (cm-¹)=	100...2000
#Windows=	2
#Autofocus=	Off
#AutoExposure=	Off
#Spike filter=	Multiple accum.
#Delay time (s)=	0
#Binning=	1
#Readout mode=	Signal
#DeNoise=	Off
#ICS correction=	Off
#Dark correction=	Off
#Inst. Process=	Off
#Instrument=	LabRAM HR Evol
#Detector=	Syncerity OE
#Objective=	x100_VIS_LWD
#Grating=	600 (500nm)
#ND Filter=	25%
#Laser=	633nm_Edge
#Hole=	100.021
#Range=	Visible
#Project=	LIG
#Sample=	proof
#Site=
#Title=	fproof
#Remark=
#Date=	07.03.2023 13:03
#Acquired=	07.03.2023 13:03:05
101.054	72
103.621	70
106.187	76
108.753	78
111.317	64
113.881	64
116.443	66
119.005	74
121.566	82
124.126	62
126.685	64
129.243	74
131.801	72
134.357	70
136.911	68
139.466	58
142.021	68
144.574	76
147.126	66
149.676	70
152.227	62
154.777	74
157.325	68
159.873	68
162.419	64
164.966	64
167.51	72
170.055	60
172.598	78
175.141	70
177.682	68
180.222	70
182.763	72
185.302	66
187.839	60
190.378	64
192.914	72
195.449	64
197.983	66
200.517	66
203.05	74
205.582	82
208.113	68
210.643	70
213.173	70
215.701	62
218.229	66
220.756	76
223.282	76
225.808	72
228.331	74
230.855	68
233.378	76
235.9	72
238.419	74
240.94	76
243.46	78
245.977	72
248.495	78
251.011	74
253.527	66
256.041	68
258.556	60
261.068	76
263.58	72
266.092	68
268.603	70
271.112	72
273.622	84
276.129	62
278.636	70
281.142	72
283.647	66
286.152	78
288.655	70
291.158	70
293.66	70
296.161	66
298.661	70
301.161	76
303.66	78
306.158	74
308.655	70
311.151	74
313.645	80
316.14	76
318.634	74
321.125	74
323.618	66
326.109	76
328.598	76
331.088	70
333.576	78
336.064	76
338.55	70
341.037	74
343.521	76
346.005	72
348.489	64
350.971	70
353.453	66
355.935	68
358.414	74
360.893	76
363.371	76
365.848	58
368.325	74
370.801	70
373.275	76
375.75	68
378.223	80
380.695	66
383.167	76
385.638	72
388.108	78
390.577	68
393.044	80
395.512	64
397.979	76
400.445	74
402.909	74
405.374	74
407.836	76
410.299	80
412.762	78
415.221	76
417.681	78
420.141	72
422.598	70
425.057	66
427.513	76
429.968	66
432.424	74
434.878	70
437.33	86
439.783	64
442.234	74
444.685	76
447.136	74
449.585	66
452.033	72
454.48	80
456.927	74
459.372	74
461.817	72
464.261	76
466.705	74
469.147	74
471.589	66
474.029	76
476.47	76
478.909	66
481.347	78
483.785	80
486.221	68
488.657	66
491.093	90
493.527	66
495.96	72
498.393	78
500.824	68
503.256	74
505.686	68
508.115	70
510.543	76
512.972	70
515.399	74
517.825	72
520.25	70
522.674	78
525.097	74
527.52	66
529.942	72
532.364	62
534.784	78
537.204	70
539.623	76
542.041	64
544.458	74
546.874	68
549.289	74
551.705	80
554.118	72
556.531	76
558.944	72
561.355	76
563.766	76
566.175	78
568.585	82
570.992	76
573.401	78
575.807	70
578.212	80
580.618	76
583.022	76
585.425	72
587.827	84
590.229	80
592.631	62
595.031	70
597.43	70
599.829	84
602.226	76
604.623	78
607.02	70
609.415	74
611.808	64
614.202	76
616.596	78
618.988	74
621.38	68
623.769	84
626.159	74
628.549	72
630.936	78
633.324	88
635.71	74
638.096	80
640.481	76
642.866	64
645.248	78
647.632	80
650.013	76
652.394	76
654.773	78
657.154	78
659.532	84
661.91	74
664.286	72
666.663	82
669.038	74
671.412	74
673.786	82
676.159	78
678.532	80
680.903	68
683.274	72
685.644	70
688.014	66
690.382	68
692.749	76
695.116	72
697.482	82
699.846	76
702.211	68
704.574	72
706.938	78
709.299	74
711.661	82
714.021	78
716.381	86
718.739	84
721.097	82
723.455	90
725.811	86
728.167	62
730.521	68
732.877	70
735.23	72
737.582	80
739.934	74
742.285	76
744.635	76
746.985	68
749.334	78
751.682	76
754.028	72
756.374	64
758.72	74
761.065	78
763.408	72
765.752	84
768.095	72
770.436	70
772.777	84
775.116	78
777.456	70
779.794	76
782.133	72
784.469	72
786.806	72
789.141	72
791.476	72
793.809	74
796.143	64
798.476	82
800.807	62
803.138	82
805.468	78
807.797	76
810.125	64
812.453	70
814.78	86
817.106	76
819.432	74
821.757	74
824.081	70
826.403	76
828.726	80
831.048	70
833.368	76
835.688	84
838.008	80
840.326	74
842.644	76
844.96	76
847.277	76
849.592	82
851.906	80
854.221	74
856.534	86
858.846	74
861.159	80
863.469	72
865.779	80
868.088	80
870.396	82
872.704	84
875.011	82
877.318	76
879.623	78
881.928	66
884.232	80
886.536	80
888.838	78
891.139	84
893.44	76
895.741	74
898.039	72
900.339	76
902.637	80
904.933	74
907.231	82
909.526	78
911.821	62
914.115	74
916.408	70
918.701	76
920.993	72
923.283	72
925.575	80
927.864	72
930.153	62
932.441	74
934.728	74
937.014	68
939.3	62
941.585	80
943.87	68
946.154	84
948.437	68
950.719	72
953	68
955.28	72
957.56	64
959.84	62
962.117	66
964.395	64
966.673	70
968.948	94
971.224	70
973.498	78
975.773	70
978.045	76
980.317	78
982.59	78
984.86	78
987.13	74
989.399	72
991.669	78
993.937	72
996.204	72
998.47	80
1000.74	66
1003	76
1005.26	72
1007.53	74
1009.79	88
1012.05	62
1014.31	74
1016.57	80
1018.83	80
1021.09	72
1023.35	72
1025.61	78
1027.87	70
1030.12	70
1032.38	76
1034.63	78
1036.88	82
1039.14	76
1041.39	74
1043.64	72
1045.89	82
1048.14	82
1050.39	80
1052.64	78
1054.89	76
1057.14	78
1059.38	80
1061.63	80
1063.87	82
1066.12	70
1068.36	80
1070.6	78
1072.85	82
1075.09	80
1077.33	74
1079.57	72
1081.81	82
1084.05	78
1086.28	72
1088.52	90
1090.76	76
1092.99	74
1095.23	76
1097.46	80
1099.69	76
1101.93	70
1104.16	78
1106.39	78
1108.62	78
1110.85	94
1113.08	78
1115.31	68
1117.53	76
1119.76	82
1121.99	76
1124.21	88
1126.44	80
1128.66	88
1130.88	82
1133.11	80
1135.33	82
1137.55	90
1139.77	82
1141.99	86
1144.21	78
1146.43	80
1148.64	82
1150.86	80
1153.08	72
1155.29	78
1157.51	78
1159.72	98
1161.93	86
1164.14	90
1166.36	86
1168.57	80
1170.78	78
1172.99	76
1175.2	78
1177.4	74
1179.61	78
1181.82	76
1184.02	88
1186.23	84
1188.43	88
1190.64	72
1192.84	76
1195.04	92
1197.24	84
1199.45	96.05
1201.64	84.4111
1203.84	86.5389
1206.04	89.194
1208.24	92.2553
1210.44	93.05
1212.64	95.8784
1214.83	80.8949
1217.03	92.7298
1219.22	85.2103
1221.41	99.28
1223.61	96.0807
1225.8	92.8937
1227.99	98.1169
1230.18	96.3264
1232.37	84.1059
1234.56	100.043
1236.75	94.5384
1238.94	103.322
1241.13	96.9017
1243.31	98.8231
1245.5	96.3307
1247.68	94.274
1249.87	101.3
1252.05	101.715
1254.24	107.839
1256.42	106.197
1258.6	98.1672
1260.78	109.602
1262.96	107.02
1265.14	109.644
1267.32	114.554
1269.5	108.606
1271.67	110.485
1273.85	119.942
1276.03	117.273
1278.2	126.989
1280.38	130.865
1282.55	124.269
1284.72	137.605
1286.9	141.142
1289.07	134.196
1291.24	140.697
1293.41	146.005
1295.58	149.31
1297.75	153.142
1299.92	159.85
1302.09	164.145
1304.25	176.902
1306.42	179.272
1308.44	168
1310.61	188
1312.79	194
1314.97	204
1317.14	218
1319.31	214
1321.48	238
1323.66	236
1325.83	234
1328	218
1330.17	240
1332.34	228
1334.5	244
1336.67	232
1338.84	220
1341	232
1343.17	208
1345.33	214
1347.5	188
1349.66	182
1351.83	190
1353.99	190
1356.15	166
1358.31	158
1360.47	162
1362.63	158
1364.79	158
1366.94	152
1369.1	144
1371.26	152
1373.41	134
1375.57	134
1377.72	134
1379.88	132
1382.03	128
1384.18	130
1386.33	116
1388.48	114
1390.64	118
1392.79	122
1394.93	118
1397.08	120
1399.23	110
1401.38	114
1403.52	114
1405.67	110
1407.81	110
1409.96	96
1412.1	98
1414.24	108
1416.39	112
1418.53	100
1420.67	106
1422.81	110
1424.95	98
1427.09	108
1429.23	110
1431.36	108
1433.5	108
1435.64	98
1437.77	106
1439.91	114
1442.04	104
1444.17	100
1446.31	106
1448.44	106
1450.57	98
1452.7	98
1454.83	96
1456.96	100
1459.09	100
1461.22	100
1463.34	104
1465.47	106
1467.6	92
1469.72	94
1471.85	110
1473.97	96
1476.09	98
1478.22	98
1480.34	94
1482.46	108
1484.58	104
1486.7	104
1488.82	98
1490.94	98
1493.06	98
1495.17	98
1497.29	98
1499.41	96
1501.52	106
1503.64	104
1505.75	96
1507.86	110
1509.98	108
1512.09	102
1514.2	102
1516.31	96
1518.42	102
1520.53	102
1522.64	90
1524.74	108
1526.85	104
1528.96	104
1531.07	122
1533.17	104
1535.27	104
1537.38	106
1539.48	106
1541.58	104
1543.69	108
1545.79	118
1547.89	110
1549.99	122
1552.09	124
1554.19	118
1556.28	108
1558.38	136
1560.48	122
1562.57	140
1564.67	138
1566.76	150
1568.86	168
1570.95	152
1573.05	166
1575.14	156
1577.23	182
1579.32	166
1581.41	190
1583.5	178
1585.59	174
1587.68	178
1589.76	196
1591.85	170
1593.94	184
1596.02	174
1598.11	174
1600.19	164
1602.27	180
1604.36	160
1606.44	174
1608.52	164
1610.6	174
1612.68	170
1614.76	172
1616.84	152
1618.92	158
1621	162
1623.07	156
1625.15	160
1627.23	142
1629.3	136
1631.38	142
1633.45	134
1635.52	102
1637.59	112
1639.67	110
1641.74	110
1643.81	110
1645.88	102
1647.95	98
1650.02	92
1652.08	96
1654.15	90
1656.22	92
1658.28	86
1660.35	96
1662.41	92
1664.48	88
1666.54	96
1668.6	90
1670.67	94
1672.73	92
1674.79	92
1676.85	88
1678.91	90
1680.97	84
1683.03	86
1685.08	76
1687.14	88
1689.2	86
1691.25	90
1693.31	90
1695.36	80
1697.42	78
1699.47	86
1701.52	86
1703.57	80
1705.63	90
1707.68	78
1709.72	74
1711.77	90
1713.82	88
1715.87	78
1717.92	82
1719.97	78
1722.01	82
1724.06	90
1726.1	78
1728.15	78
1730.19	76
1732.23	80
1734.27	74
1736.32	80
1738.36	76
1740.4	76
1742.44	68
1744.48	78
1746.51	80
1748.55	70
1750.59	78
1752.63	68
1754.66	80
1756.7	68
1758.73	64
1760.77	74
1762.8	78
1764.83	74
1766.86	70
1768.9	76
1770.93	66
1772.96	70
1774.99	70
1777.02	76
1779.04	80
1781.07	78
1783.1	78
1785.13	74
1787.15	72
1789.18	76
1791.2	82
1793.23	76
1795.25	80
1797.27	68
1799.29	78
1801.31	70
1803.34	80
1805.36	68
1807.38	70
1809.39	74
1811.41	78
1813.43	66
1815.45	76
1817.46	66
1819.48	70
1821.49	78
1823.51	80
1825.52	74
1827.54	74
1829.55	70
1831.56	74
1833.57	80
1835.58	80
1837.59	70
1839.6	68
1841.61	66
1843.62	68
1845.63	64
1847.64	68
1849.64	76
1851.65	78
1853.65	70
1855.66	84
1857.66	68
1859.66	64
1861.67	74
1863.67	70
1865.67	82
1867.67	74
1869.67	74
1871.67	70
1873.67	78
1875.67	76
1877.67	76
1879.66	64
1881.66	68
1883.66	74
1885.65	74
1887.65	70
1889.64	70
1891.63	70
1893.63	72
1895.62	60
1897.61	70
1899.6	66
1901.59	66
1903.58	68
1905.57	70
1907.56	64
1909.55	68
1911.53	76
1913.52	74
1915.51	62
1917.49	62
1919.48	66
1921.46	64
1923.45	60
1925.43	70
1927.41	70
1929.39	74
1931.37	76
1933.36	66
1935.33	62
1937.31	72
1939.29	74
1941.27	68
1943.25	68
1945.23	68
1947.2	68
1949.18	62
1951.15	58
1953.13	66
1955.1	74
1957.08	62
1959.05	72
1961.02	74
1962.99	70
1964.96	64
1966.93	70
1968.9	66
1970.87	64
1972.84	62
1974.81	66
1976.77	70
1978.74	62
1980.71	74
1982.67	60
1984.64	70
1986.6	72
1988.57	66
1990.53	70
1992.49	66
1994.45	64
1996.41	72
1998.37	58
1999.35	60