File: muestras/LIG/fproof_01.txt
#Acq. time (s)=	10
#Accumulations=	1
#Range (cm-¹)=	100...2000
#Windows=	2
#Autofocus=	Off
#AutoExposure=	Off
#Spike filter=	Off
#Delay time (s)=	0
#Binning=	1
#Readout mode=	Signal
#DeNoise=	Off
#ICS correction=	Off
#Dark correction=	Off
#Inst. Process=	Off
#Instrument=	LabRAM HR Evol
#Detector=	Syncerity OE
#Objective=	x100_VIS_LWD
#Grating=	600 (500nm)
#ND Filter=	100%
#Laser=	633nm_Edge
#Hole=	39.9962
#Range=	Visible
#Project=	LIG
#Sample=	proof
#Site=
#Title=	fproof
#Remark=
#Date=	07.03.2023 12:17
#Acquired=	07.03.2023 12:17:46
101.054	98
103.621	98
106.187	104
108.753	104
111.317	92
113.881	94
116.443	88
119.005	116
121.566	88
124.126	96
126.685	84
129.243	96
131.801	100
134.357	100
136.911	92
139.466	90
142.021	90
144.574	104
147.126	92
149.676	88
152.227	98
154.777	112
157.325	102
159.873	98
162.419	104
164.966	94
167.51	92
170.055	104
172.598	90
175.141	98
177.682	100
180.222	90
182.763	100
185.302	92
187.839	112
190.378	94
192.914	114
195.449	102
197.983	88
200.517	102
203.05	96
205.582	96
208.113	112
210.643	108
213.173	106
215.701	104
218.229	96
220.756	116
223.282	92
225.808	100
228.331	116
230.855	94
233.378	110
235.9	100
238.419	116
240.94	108
243.46	110
245.977	112
248.495	104
251.011	104
253.527	96
256.041	108
258.556	108
261.068	108
263.58	104
266.092	110
268.603	122
271.112	112
273.622	108
276.129	114
278.636	126
281.142	102
283.647	112
286.152	104
288.655	120
291.158	112
293.66	124
296.161	106
298.661	110
301.161	110
303.66	102
306.158	110
308.655	116
311.151	106
313.645	126
316.14	104
318.634	102
321.125	124
323.618	114
326.109	112
328.598	110
331.088	110
333.576	120
336.064	112
338.55	112
341.037	112
343.521	112
346.005	108
348.489	112
350.971	106
353.453	100
355.935	114
358.414	122
360.893	116
363.371	120
365.848	116
368.325	100
370.801	128
373.275	112
375.75	116
378.223	130
380.695	120
383.167	116
385.638	118
388.108	96
390.577	118
393.044	106
395.512	118
397.979	116
400.445	128
402.909	114
405.374	108
407.836	108
410.299	116
412.762	116
415.221	100
417.681	120
420.141	112
422.598	118
425.057	116
427.513	110
429.968	124
432.424	126
434.878	116
437.33	106
439.783	110
442.234	110
444.685	118
447.136	130
449.585	116
452.033	120
454.48	120
456.927	112
459.372	120
461.817	116
464.261	122
466.705	130
469.147	118
471.589	124
474.029	118
476.47	120
478.909	116
481.347	120
483.785	114
486.221	116
488.657	122
491.093	122
493.527	136
495.96	118
498.393	116
500.824	130
503.256	116
505.686	128
508.115	122
510.543	126
512.972	128
515.399	126
517.825	118
520.25	118
522.674	128
525.097	128
527.52	118
529.942	116
532.364	106
534.784	110
537.204	118
539.623	128
542.041	114
544.458	120
546.874	136
549.289	130
551.705	124
554.118	128
556.531	120
558.944	126
561.355	124
563.766	112
566.175	136
568.585	118
570.992	134
573.401	126
575.807	126
578.212	126
580.618	120
583.022	114
585.425	116
587.827	134
590.229	130
592.631	118
595.031	108
597.43	128
599.829	126
602.226	128
604.623	140
607.02	126
609.415	120
611.808	132
614.202	130
616.596	126
618.988	136
621.38	128
623.769	136
626.159	118
628.549	146
630.936	120
633.324	126
635.71	124
638.096	132
640.481	132
642.866	128
645.248	132
647.632	138
650.013	120
652.394	130
654.773	126
657.154	124
659.532	126
661.91	132
664.286	136
666.663	130
669.038	120
671.412	130
673.786	126
676.159	132
678.532	134
680.903	138
683.274	122
685.644	124
688.014	132
690.382	134
692.749	110
695.116	126
697.482	130
699.846	138
702.211	136
704.574	140
706.938	114
709.299	122
711.661	124
714.021	124
716.381	132
718.739	132
721.097	140
723.455	138
725.811	122
728.167	142
730.521	126
732.877	130
735.23	124
737.582	128
739.934	122
742.285	124
744.635	122
746.985	128
749.334	128
751.682	140
754.028	128
756.374	146
758.72	136
761.065	134
763.408	122
765.752	136
768.095	136
770.436	132
772.777	128
775.116	134
777.456	134
779.794	122
782.133	130
784.469	136
786.806	128
789.141	136
791.476	126
793.809	120
796.143	132
798.476	128
800.807	134
803.138	138
805.468	130
807.797	132
810.125	130
812.453	144
814.78	144
817.106	124
819.432	134
821.757	132
824.081	132
826.403	128
828.726	128
831.048	132
833.368	128
835.688	140
838.008	138
840.326	124
842.644	130
844.96	130
847.277	132
849.592	140
851.906	138
854.221	138
856.534	138
858.846	136
861.159	148
863.469	136
865.779	130
868.088	140
870.396	130
872.704	118
875.011	140
877.318	132
879.623	128
881.928	128
884.232	132
886.536	140
888.838	134
891.139	122
893.44	136
895.741	120
898.039	134
900.339	132
902.637	130
904.933	130
907.231	130
909.526	148
911.821	150
914.115	124
916.408	126
918.701	146
920.993	130
923.283	142
925.575	144
927.864	146
930.153	138
932.441	132
934.728	132
937.014	118
939.3	126
941.585	118
943.87	136
946.154	140
948.437	138
950.719	144
953	134
955.28	146
957.56	134
959.84	140
962.117	132
964.395	122
966.673	142
968.948	124
971.224	132
973.498	142
975.773	134
978.045	138
980.317	152
982.59	132
984.86	146
987.13	142
989.399	130
991.669	144
993.937	146
996.204	138
998.47	132
1000.74	144
1003	138
1005.26	138
1007.53	146
1009.79	132
1012.05	132
1014.31	128
1016.57	132
1018.83	140
1021.09	146
1023.35	128
1025.61	148
1027.87	124
1030.12	136
1032.38	134
1034.63	126
1036.88	150
1039.14	116
1041.39	150
1043.64	138
1045.89	132
1048.14	138
1050.39	144
1052.64	140
1054.89	132
1057.14	144
1059.38	136
1061.63	118
1063.87	142
1066.12	144
1068.36	130
1070.6	128
1072.85	138
1075.09	144
1077.33	134
1079.57	142
1081.81	144
1084.05	138
1086.28	142
1088.52	138
1090.76	134
1092.99	136
1095.23	146
1097.46	150
1099.69	152
1101.93	148
1104.16	138
1106.39	128
1108.62	144
1110.85	134
1113.08	130
1115.31	132
1117.53	146
1119.76	142
1121.99	142
1124.21	138
1126.44	148
1128.66	132
1130.88	148
1133.11	140
1135.33	134
1137.55	154
1139.77	134
1141.99	146
1144.21	136
1146.43	132
1148.64	140
1150.86	122
1153.08	144
1155.29	140
1157.51	134
1159.72	150
1161.93	142
1164.14	142
1166.36	136
1168.57	152
1170.78	142
1172.99	132
1175.2	136
1177.4	152
1179.61	144
1181.82	152
1184.02	144
1186.23	154
1188.43	152
1190.64	158
1192.84	150
1195.04	144
1197.24	136
1199.45	133.89
1201.64	148.6
1203.84	134.941
1206.04	119.263
1208.24	140.402
1210.44	137.29
1212.64	137.359
1214.83	145.557
1217.03	129.76
1219.22	138.08
1221.41	136.641
1223.61	139.665
1225.8	134.839
1227.99	128.454
1230.18	134.614
1232.37	125.405
1234.56	128.554
1236.75	136.635
1238.94	123.25
1241.13	124.385
1243.31	130.478
1245.5	127.05
1247.68	127.939
1249.87	120.057
1252.05	137.323
1254.24	133.637
1256.42	120.235
1258.6	121.293
1260.78	121.676
1262.96	117.622
1265.14	123.854
1267.32	116.098
1269.5	130.044
1271.67	120.862
1273.85	117.179
1276.03	130.29
1278.2	116.361
1280.38	122.128
1282.55	123.371
1284.72	117.642
1286.9	128.998
1289.07	118.246
1291.24	122.978
1293.41	125.285
1295.58	129.684
1297.75	124.703
1299.92	108.494
1302.09	126.791
1304.25	123.245
1306.42	134.703
1308.44	140
1310.61	122
1312.79	118
1314.97	124
1317.14	118
1319.31	126
1321.48	122
1323.66	116
1325.83	118
1328	130
1330.17	120
1332.34	112
1334.5	122
1336.67	116
1338.84	126
1341	126
1343.17	118
1345.33	102
1347.5	110
1349.66	108
1351.83	116
1353.99	100
1356.15	114
1358.31	102
1360.47	106
1362.63	106
1364.79	104
1366.94	108
1369.1	104
1371.26	96
1373.41	100
1375.57	96
1377.72	112
1379.88	110
1382.03	102
1384.18	106
1386.33	114
1388.48	110
1390.64	104
1392.79	124
1394.93	116
1397.08	106
1399.23	102
1401.38	104
1403.52	108
1405.67	98
1407.81	116
1409.96	112
1412.1	112
1414.24	112
1416.39	104
1418.53	108
1420.67	114
1422.81	104
1424.95	106
1427.09	108
1429.23	102
1431.36	106
1433.5	98
1435.64	102
1437.77	114
1439.91	98
1442.04	116
1444.17	122
1446.31	108
1448.44	112
1450.57	96
1452.7	104
1454.83	104
1456.96	106
1459.09	96
1461.22	112
1463.34	106
1465.47	106
1467.6	114
1469.72	102
1471.85	106
1473.97	116
1476.09	100
1478.22	112
1480.34	102
1482.46	112
1484.58	104
1486.7	120
1488.82	102
1490.94	108
1493.06	118
1495.17	110
1497.29	108
1499.41	114
1501.52	100
1503.64	94
1505.75	98
1507.86	114
1509.98	98
1512.09	102
1514.2	96
1516.31	120
1518.42	104
1520.53	104
1522.64	116
1524.74	102
1526.85	110
1528.96	94
1531.07	92
1533.17	114
1535.27	124
1537.38	108
1539.48	116
1541.58	110
1543.69	102
1545.79	110
1547.89	120
1549.99	102
1552.09	112
1554.19	122
1556.28	118
1558.38	106
1560.48	118
1562.57	106
1564.67	112
1566.76	98
1568.86	110
1570.95	116
1573.05	104
1575.14	124
1577.23	110
1579.32	116
1581.41	106
1583.5	110
1585.59	110
1587.68	118
1589.76	118
1591.85	94
1593.94	114
1596.02	104
1598.11	106
1600.19	114
1602.27	106
1604.36	118
1606.44	108
1608.52	110
1610.6	112
1612.68	118
1614.76	104
1616.84	116
1618.92	110
1621	104
1623.07	104
1625.15	100
1627.23	106
1629.3	102
1631.38	110
1633.45	104
1635.52	112
1637.59	102
1639.67	96
1641.74	110
1643.81	116
1645.88	102
1647.95	112
1650.02	98
1652.08	108
1654.15	108
1656.22	112
1658.28	90
1660.35	100
1662.41	120
1664.48	102
1666.54	106
1668.6	96
1670.67	102
1672.73	98
1674.79	98
1676.85	84
1678.91	110
1680.97	106
1683.03	98
1685.08	106
1687.14	110
1689.2	102
1691.25	104
1693.31	90
1695.36	96
1697.42	102
1699.47	92
1701.52	96
1703.57	104
1705.63	102
1707.68	86
1709.72	106
1711.77	94
1713.82	100
1715.87	98
1717.92	86
1719.97	92
1722.01	100
1724.06	84
1726.1	102
1728.15	104
1730.19	96
1732.23	96
1734.27	94
1736.32	94
1738.36	96
1740.4	96
1742.44	102
1744.48	112
1746.51	102
1748.55	100
1750.59	92
1752.63	104
1754.66	100
1756.7	92
1758.73	94
1760.77	94
1762.8	102
1764.83	102
1766.86	90
1768.9	102
1770.93	100
1772.96	102
1774.99	90
1777.02	100
1779.04	104
1781.07	94
1783.1	98
1785.13	98
1787.15	104
1789.18	90
1791.2	98
1793.23	98
1795.25	104
1797.27	100
1799.29	100
1801.31	110
1803.34	102
1805.36	100
1807.38	94
1809.39	94
1811.41	108
1813.43	98
1815.45	100
1817.46	96
1819.48	106
1821.49	84
1823.51	94
1825.52	92
1827.54	92
1829.55	88
1831.56	96
1833.57	104
1835.58	94
1837.59	86
1839.6	100
1841.61	78
1843.62	96
1845.63	98
1847.64	104
1849.64	88
1851.65	86
1853.65	98
1855.66	90
1857.66	100
1859.66	88
1861.67	88
1863.67	92
1865.67	106
1867.67	82
1869.67	96
1871.67	96
1873.67	90
1875.67	106
1877.67	86
1879.66	88
1881.66	80
1883.66	84
1885.65	98
1887.65	84
1889.64	96
1891.63	82
1893.63	82
1895.62	90
1897.61	88
1899.6	96
1901.59	88
1903.58	86
1905.57	100
1907.56	86
1909.55	94
1911.53	98
1913.52	96
1915.51	94
1917.49	98
1919.48	96
1921.46	88
1923.45	86
1925.43	86
1927.41	98
1929.39	76
1931.37	92
1933.36	96
1935.33	92
1937.31	92
1939.29	80
1941.27	88
1943.25	88
1945.23	88
1947.2	106
1949.18	96
1951.15	100
1953.13	91
1955.1	86
1957.08	94
1959.05	92
1961.02	96
1962.99	82
1964.96	92
1966.93	88
1968.9	82
1970.87	88
1972.84	80
1974.81	88
1976.77	86
1978.74	96
1980.71	80
1982.67	96
1984.64	90
1986.6	80
1988.57	82
1990.53	94
1992.49	80
1994.45	90
1996.41	94
1998.37	82
1999.35	100