File: muestras/LIG/fproof_16.txt
#Acq. time (s)=	10
#Accumulations=	2
#Range (cm-¹)=	100...2000
#Windows=	2
#Autofocus=	Off
#AutoExposure=	Off
#Spike filter=	Multiple accum.
#Delay time (s)=	0
#Binning=	1
#Readout mode=	Signal
#DeNoise=	Off
#ICS correction=	Off
#Dark correction=	Off
#Inst. Process=	Off
#Instrument=	LabRAM HR Evol
#Detector=	Syncerity OE
#Objective=	x100_VIS_LWD
#Grating=	600 (500nm)
#ND Filter=	25%
#Laser=	633nm_Edge
#Hole=	100.021
#Range=	Visible
#Project=	LIG
#Sample=	proof
#Site=
#Title=	fproof
#Remark=
#Date=	07.03.2023 13:10
#Acquired=	07.03.2023 13:10:18
101.054	98
103.621	96
106.187	94
108.753	88
111.317	104
113.881	102
116.443	90
119.005	92
121.566	76
124.126	82
126.685	92
129.243	86
131.801	92
134.357	82
136.911	84
139.466	94
142.021	80
144.574	82
147.126	94
149.676	82
152.227	74
154.777	88
157.325	82
159.873	78
162.419	78
164.966	88
167.51	76
170.055	86
172.598	84
175.141	70
177.682	70
180.222	82
182.763	76
185.302	92
187.839	74
190.378	80
192.914	78
195.449	82
197.983	88
200.517	94
203.05	80
205.582	86
208.113	84
210.643	86
213.173	92
215.701	80
218.229	76
220.756	86
223.282	88
225.808	86
228.331	88
230.855	86
233.378	80
235.9	84
238.419	90
240.94	86
243.46	88
245.977	88
248.495	78
251.011	86
253.527	84
256.041	82
258.556	82
261.068	74
263.58	90
266.092	84
268.603	88
271.112	78
273.622	80
276.129	78
278.636	86
281.142	84
283.647	78
286.152	90
288.655	84
291.158	84
293.66	82
296.161	74
298.661	72
301.161	82
303.66	84
306.158	80
308.655	86
311.151	82
313.645	86
316.14	82
318.634	76
321.125	88
323.618	80
326.109	90
328.598	86
331.088	88
333.576	76
336.064	78
338.55	74
341.037	80
343.521	86
346.005	74
348.489	88
350.971	82
353.453	72
355.935	80
358.414	86
360.893	82
363.371	78
365.848	74
368.325	84
370.801	78
373.275	88
375.75	80
378.223	86
380.695	84
383.167	88
385.638	82
388.108	78
390.577	84
393.044	86
395.512	84
397.979	84
400.445	80
402.909	80
405.374	80
407.836	76
410.299	88
412.762	84
415.221	82
417.681	76
420.141	66
422.598	78
425.057	78
427.513	86
429.968	74
432.424	72
434.878	88
437.33	80
439.783	80
442.234	74
444.685	82
447.136	74
449.585	88
452.033	78
454.48	84
456.927	80
459.372	80
461.817	76
464.261	80
466.705	78
469.147	80
471.589	80
474.029	74
476.47	78
478.909	68
481.347	78
483.785	88
486.221	76
488.657	92
491.093	88
493.527	80
495.96	84
498.393	84
500.824	82
503.256	78
505.686	90
508.115	84
510.543	80
512.972	76
515.399	74
517.825	86
520.25	76
522.674	76
525.097	80
527.52	80
529.942	84
532.364	74
534.784	72
537.204	76
539.623	78
542.041	78
544.458	76
546.874	74
549.289	82
551.705	76
554.118	70
556.531	72
558.944	76
561.355	80
563.766	78
566.175	74
568.585	72
570.992	82
573.401	76
575.807	74
578.212	76
580.618	80
583.022	76
585.425	70
587.827	78
590.229	78
592.631	70
595.031	76
597.43	76
599.829	74
602.226	72
604.623	86
607.02	94
609.415	82
611.808	68
614.202	84
616.596	84
618.988	88
621.38	78
623.769	78
626.159	78
628.549	86
630.936	84
633.324	86
635.71	84
638.096	78
640.481	86
642.866	88
645.248	72
647.632	80
650.013	74
652.394	82
654.773	86
657.154	80
659.532	84
661.91	86
664.286	80
666.663	82
669.038	80
671.412	76
673.786	82
676.159	74
678.532	74
680.903	78
683.274	80
685.644	74
688.014	86
690.382	76
692.749	82
695.116	78
697.482	76
699.846	82
702.211	80
704.574	82
706.938	80
709.299	82
711.661	74
714.021	78
716.381	86
718.739	86
721.097	78
723.455	74
725.811	84
728.167	84
730.521	72
732.877	82
735.23	70
737.582	82
739.934	78
742.285	80
744.635	76
746.985	80
749.334	80
751.682	78
754.028	80
756.374	86
758.72	70
761.065	80
763.408	84
765.752	86
768.095	76
770.436	80
772.777	80
775.116	82
777.456	82
779.794	84
782.133	86
784.469	78
786.806	78
789.141	86
791.476	88
793.809	86
796.143	80
798.476	78
800.807	84
803.138	82
805.468	88
807.797	80
810.125	76
812.453	82
814.78	80
817.106	80
819.432	74
821.757	84
824.081	78
826.403	78
828.726	70
831.048	82
833.368	82
835.688	82
838.008	90
840.326	88
842.644	84
844.96	84
847.277	84
849.592	70
851.906	88
854.221	80
856.534	82
858.846	88
861.159	84
863.469	84
865.779	90
868.088	88
870.396	80
872.704	82
875.011	84
877.318	88
879.623	78
881.928	82
884.232	84
886.536	86
888.838	80
891.139	72
893.44	78
895.741	86
898.039	78
900.339	70
902.637	86
904.933	90
907.231	82
909.526	80
911.821	82
914.115	88
916.408	80
918.701	78
920.993	76
923.283	90
925.575	84
927.864	76
930.153	82
932.441	88
934.728	82
937.014	86
939.3	74
941.585	88
943.87	88
946.154	82
948.437	84
950.719	78
953	80
955.28	86
957.56	86
959.84	86
962.117	80
964.395	82
966.673	82
968.948	74
971.224	76
973.498	94
975.773	80
978.045	86
980.317	92
982.59	78
984.86	90
987.13	88
989.399	84
991.669	86
993.937	90
996.204	84
998.47	78
1000.74	96
1003	88
1005.26	80
1007.53	98
1009.79	88
1012.05	76
1014.31	82
1016.57	90
1018.83	80
1021.09	84
1023.35	82
1025.61	92
1027.87	88
1030.12	90
1032.38	84
1034.63	90
1036.88	82
1039.14	88
1041.39	86
1043.64	88
1045.89	104
1048.14	94
1050.39	88
1052.64	92
1054.89	90
1057.14	90
1059.38	92
1061.63	92
1063.87	92
1066.12	96
1068.36	92
1070.6	100
1072.85	100
1075.09	94
1077.33	94
1079.57	102
1081.81	98
1084.05	96
1086.28	94
1088.52	92
1090.76	100
1092.99	92
1095.23	90
1097.46	108
1099.69	104
1101.93	92
1104.16	96
1106.39	102
1108.62	100
1110.85	94
1113.08	112
1115.31	112
1117.53	108
1119.76	110
1121.99	108
1124.21	114
1126.44	104
1128.66	106
1130.88	112
1133.11	106
1135.33	112
1137.55	114
1139.77	110
1141.99	104
1144.21	120
1146.43	118
1148.64	124
1150.86	112
1153.08	112
1155.29	122
1157.51	108
1159.72	122
1161.93	114
1164.14	104
1166.36	112
1168.57	122
1170.78	116
1172.99	112
1175.2	118
1177.4	112
1179.61	124
1181.82	122
1184.02	122
1186.23	120
1188.43	134
1190.64	118
1192.84	126
1195.04	108
1197.24	124
1199.45	124.05
1201.64	116.4
1203.84	116.829
1206.04	131.066
1208.24	123.858
1210.44	115.409
1212.64	108.154
1214.83	126.549
1217.03	128
1219.22	132.62
1221.41	133.979
1223.61	138.248
1225.8	126.404
1227.99	138.41
1230.18	131.434
1232.37	138.507
1234.56	150.666
1236.75	144.471
1238.94	139.138
1241.13	150.733
1243.31	149.13
1245.5	146.608
1247.68	157.035
1249.87	155.161
1252.05	169.299
1254.24	162.366
1256.42	170.877
1258.6	166.02
1260.78	176.298
1262.96	183.539
1265.14	187.653
1267.32	198.402
1269.5	191.398
1271.67	197.786
1273.85	198.463
1276.03	217.273
1278.2	225.311
1280.38	237.492
1282.55	242.801
1284.72	263.117
1286.9	269.796
1289.07	272.67
1291.24	296.266
1293.41	307.9
1295.58	317.164
1297.75	343.289
1299.92	363.13
1302.09	377.033
1304.25	384.493
1306.42	438.279
1308.44	464
1310.61	480
1312.79	478
1314.97	518
1317.14	560
1319.31	588
1321.48	574
1323.66	600
1325.83	618
1328	590
1330.17	580
1332.34	600
1334.5	560
1336.67	564
1338.84	500
1341	500
1343.17	476
1345.33	438
1347.5	428
1349.66	380
1351.83	360
1353.99	338
1356.15	316
1358.31	314
1360.47	296
1362.63	280
1364.79	282
1366.94	248
1369.1	240
1371.26	242
1373.41	226
1375.57	220
1377.72	218
1379.88	208
1382.03	200
1384.18	186
1386.33	194
1388.48	166
1390.64	186
1392.79	176
1394.93	182
1397.08	170
1399.23	156
1401.38	160
1403.52	162
1405.67	146
1407.81	150
1409.96	156
1412.1	158
1414.24	150
1416.39	142
1418.53	158
1420.67	142
1422.81	134
1424.95	142
1427.09	140
1429.23	144
1431.36	130
1433.5	142
1435.64	148
1437.77	134
1439.91	134
1442.04	136
1444.17	142
1446.31	142
1448.44	136
1450.57	128
1452.7	136
1454.83	142
1456.96	132
1459.09	138
1461.22	130
1463.34	130
1465.47	130
1467.6	134
1469.72	136
1471.85	126
1473.97	142
1476.09	120
1478.22	138
1480.34	120
1482.46	128
1484.58	134
1486.7	142
1488.82	128
1490.94	130
1493.06	144
1495.17	126
1497.29	138
1499.41	140
1501.52	130
1503.64	140
1505.75	142
1507.86	152
1509.98	142
1512.09	130
1514.2	152
1516.31	138
1518.42	146
1520.53	144
1522.64	146
1524.74	148
1526.85	158
1528.96	160
1531.07	162
1533.17	158
1535.27	164
1537.38	164
1539.48	172
1541.58	176
1543.69	182
1545.79	190
1547.89	196
1549.99	204
1552.09	202
1554.19	228
1556.28	246
1558.38	240
1560.48	266
1562.57	268
1564.67	288
1566.76	318
1568.86	330
1570.95	330
1573.05	348
1575.14	340
1577.23	368
1579.32	378
1581.41	380
1583.5	390
1585.59	374
1587.68	388
1589.76	378
1591.85	362
1593.94	364
1596.02	350
1598.11	350
1600.19	324
1602.27	332
1604.36	320
1606.44	360
1608.52	322
1610.6	334
1612.68	306
1614.76	326
1616.84	306
1618.92	282
1621	276
1623.07	254
1625.15	238
1627.23	220
1629.3	206
1631.38	196
1633.45	172
1635.52	154
1637.59	152
1639.67	158
1641.74	148
1643.81	144
1645.88	128
1647.95	118
1650.02	110
1652.08	128
1654.15	116
1656.22	110
1658.28	104
1660.35	94
1662.41	110
1664.48	98
1666.54	102
1668.6	106
1670.67	88
1672.73	100
1674.79	96
1676.85	100
1678.91	102
1680.97	86
1683.03	88
1685.08	86
1687.14	92
1689.2	84
1691.25	88
1693.31	86
1695.36	86
1697.42	94
1699.47	82
1701.52	102
1703.57	78
1705.63	90
1707.68	80
1709.72	80
1711.77	72
1713.82	84
1715.87	86
1717.92	82
1719.97	84
1722.01	94
1724.06	80
1726.1	88
1728.15	76
1730.19	74
1732.23	84
1734.27	68
1736.32	78
1738.36	80
1740.4	80
1742.44	78
1744.48	80
1746.51	72
1748.55	90
1750.59	74
1752.63	78
1754.66	74
1756.7	74
1758.73	72
1760.77	74
1762.8	80
1764.83	84
1766.86	88
1768.9	78
1770.93	74
1772.96	78
1774.99	80
1777.02	82
1779.04	66
1781.07	88
1783.1	86
1785.13	78
1787.15	76
1789.18	90
1791.2	80
1793.23	72
1795.25	76
1797.27	78
1799.29	80
1801.31	74
1803.34	82
1805.36	92
1807.38	74
1809.39	74
1811.41	80
1813.43	82
1815.45	68
1817.46	76
1819.48	72
1821.49	70
1823.51	74
1825.52	80
1827.54	84
1829.55	72
1831.56	78
1833.57	70
1835.58	74
1837.59	80
1839.6	78
1841.61	80
1843.62	74
1845.63	76
1847.64	78
1849.64	64
1851.65	66
1853.65	64
1855.66	80
1857.66	72
1859.66	78
1861.67	78
1863.67	80
1865.67	74
1867.67	70
1869.67	74
1871.67	80
1873.67	68
1875.67	78
1877.67	66
1879.66	70
1881.66	66
1883.66	76
1885.65	72
1887.65	64
1889.64	76
1891.63	68
1893.63	74
1895.62	80
1897.61	74
1899.6	70
1901.59	66
1903.58	70
1905.57	66
1907.56	70
1909.55	78
1911.53	72
1913.52	76
1915.51	70
1917.49	66
1919.48	80
1921.46	64
1923.45	72
1925.43	70
1927.41	74
1929.39	70
1931.37	68
1933.36	70
1935.33	68
1937.31	72
1939.29	70
1941.27	74
1943.25	66
1945.23	76
1947.2	68
1949.18	68
1951.15	68
1953.13	67
1955.1	72
1957.08	76
1959.05	70
1961.02	66
1962.99	68
1964.96	70
1966.93	64
1968.9	68
1970.87	58
1972.84	70
1974.81	64
1976.77	62
1978.74	56
1980.71	68
1982.67	64
1984.64	66
1986.6	64
1988.57	66
1990.53	70
1992.49	64
1994.45	62
1996.41	64
1998.37	68
1999.35	74