File: muestras/LIG/fproof_20.txt
#Acq. time (s)=	10
#Accumulations=	2
#Range (cm-¹)=	100...2000
#Windows=	2
#Autofocus=	Off
#AutoExposure=	Off
#Spike filter=	Multiple accum.
#Delay time (s)=	0
#Binning=	1
#Readout mode=	Signal
#DeNoise=	Off
#ICS correction=	Off
#Dark correction=	Off
#Inst. Process=	Off
#Instrument=	LabRAM HR Evol
#Detector=	Syncerity OE
#Objective=	x100_VIS_LWD
#Grating=	600 (500nm)
#ND Filter=	25%
#Laser=	633nm_Edge
#Hole=	100.021
#Range=	Visible
#Project=	LIG
#Sample=	proof
#Site=
#Title=	fproof
#Remark=
#Date=	07.03.2023 13:18
#Acquired=	07.03.2023 13:18:46
101.054	350
103.621	326
106.187	330
108.753	348
111.317	352
113.881	366
116.443	330
119.005	366
121.566	356
124.126	370
126.685	360
129.243	366
131.801	364
134.357	368
136.911	368
139.466	364
142.021	344
144.574	354
147.126	370
149.676	350
152.227	364
154.777	360
157.325	386
159.873	362
162.419	374
164.966	356
167.51	370
170.055	358
172.598	378
175.141	354
177.682	366
180.222	380
182.763	372
185.302	366
187.839	384
190.378	388
192.914	384
195.449	374
197.983	390
200.517	394
203.05	386
205.582	374
208.113	380
210.643	380
213.173	384
215.701	410
218.229	388
220.756	390
223.282	370
225.808	388
228.331	384
230.855	386
233.378	368
235.9	374
238.419	392
240.94	402
243.46	418
245.977	394
248.495	404
251.011	418
253.527	396
256.041	406
258.556	394
261.068	432
263.58	388
266.092	408
268.603	416
271.112	418
273.622	414
276.129	422
278.636	400
281.142	398
283.647	394
286.152	394
288.655	416
291.158	402
293.66	422
296.161	428
298.661	406
301.161	424
303.66	410
306.158	436
308.655	438
311.151	432
313.645	430
316.14	436
318.634	438
321.125	404
323.618	418
326.109	446
328.598	442
331.088	432
333.576	430
336.064	438
338.55	438
341.037	430
343.521	458
346.005	438
348.489	440
350.971	450
353.453	414
355.935	452
358.414	458
360.893	448
363.371	400
365.848	450
368.325	456
370.801	440
373.275	426
375.75	434
378.223	440
380.695	430
383.167	412
385.638	420
388.108	424
390.577	418
393.044	418
395.512	448
397.979	468
400.445	454
402.909	424
405.374	436
407.836	438
410.299	452
412.762	440
415.221	456
417.681	436
420.141	466
422.598	440
425.057	448
427.513	472
429.968	462
432.424	456
434.878	470
437.33	466
439.783	470
442.234	478
444.685	476
447.136	462
449.585	464
452.033	448
454.48	462
456.927	476
459.372	470
461.817	458
464.261	454
466.705	470
469.147	458
471.589	466
474.029	462
476.47	488
478.909	476
481.347	478
483.785	450
486.221	444
488.657	442
491.093	466
493.527	470
495.96	472
498.393	474
500.824	472
503.256	478
505.686	460
508.115	448
510.543	460
512.972	496
515.399	488
517.825	474
520.25	460
522.674	470
525.097	488
527.52	470
529.942	474
532.364	478
534.784	482
537.204	454
539.623	472
542.041	466
544.458	458
546.874	464
549.289	482
551.705	470
554.118	452
556.531	470
558.944	444
561.355	476
563.766	472
566.175	490
568.585	452
570.992	468
573.401	474
575.807	470
578.212	454
580.618	462
583.022	492
585.425	472
587.827	478
590.229	462
592.631	480
595.031	462
597.43	468
599.829	484
602.226	464
604.623	486
607.02	466
609.415	490
611.808	466
614.202	468
616.596	488
618.988	482
621.38	472
623.769	492
626.159	506
628.549	486
630.936	492
633.324	468
635.71	466
638.096	496
640.481	484
642.866	458
645.248	494
647.632	498
650.013	488
652.394	484
654.773	512
657.154	460
659.532	498
661.91	494
664.286	470
666.663	502
669.038	486
671.412	494
673.786	436
676.159	500
678.532	480
680.903	476
683.274	482
685.644	506
688.014	480
690.382	494
692.749	496
695.116	506
697.482	502
699.846	506
702.211	488
704.574	492
706.938	490
709.299	512
711.661	508
714.021	510
716.381	462
718.739	508
721.097	494
723.455	484
725.811	510
728.167	494
730.521	514
732.877	520
735.23	492
737.582	496
739.934	490
742.285	496
744.635	500
746.985	502
749.334	496
751.682	498
754.028	506
756.374	478
758.72	480
761.065	496
763.408	506
765.752	492
768.095	498
770.436	478
772.777	448
775.116	490
777.456	510
779.794	488
782.133	506
784.469	488
786.806	496
789.141	482
791.476	474
793.809	486
796.143	480
798.476	502
800.807	464
803.138	504
805.468	496
807.797	502
810.125	496
812.453	496
814.78	484
817.106	512
819.432	512
821.757	490
824.081	490
826.403	474
828.726	480
831.048	496
833.368	486
835.688	476
838.008	478
840.326	500
842.644	502
844.96	514
847.277	508
849.592	482
851.906	492
854.221	492
856.534	508
858.846	494
861.159	504
863.469	510
865.779	488
868.088	520
870.396	500
872.704	480
875.011	484
877.318	508
879.623	504
881.928	502
884.232	498
886.536	486
888.838	462
891.139	506
893.44	496
895.741	500
898.039	480
900.339	488
902.637	482
904.933	508
907.231	500
909.526	472
911.821	478
914.115	474
916.408	488
918.701	496
920.993	498
923.283	510
925.575	498
927.864	492
930.153	498
932.441	502
934.728	508
937.014	480
939.3	496
941.585	482
943.87	486
946.154	496
948.437	484
950.719	492
953	524
955.28	494
957.56	496
959.84	504
962.117	506
964.395	518
966.673	506
968.948	496
971.224	492
973.498	494
975.773	478
978.045	496
980.317	492
982.59	496
984.86	502
987.13	500
989.399	520
991.669	496
993.937	502
996.204	498
998.47	498
1000.74	490
1003	492
1005.26	498
1007.53	522
1009.79	526
1012.05	504
1014.31	506
1016.57	504
1018.83	484
1021.09	468
1023.35	490
1025.61	524
1027.87	506
1030.12	474
1032.38	502
1034.63	506
1036.88	506
1039.14	508
1041.39	528
1043.64	510
1045.89	520
1048.14	516
1050.39	498
1052.64	512
1054.89	502
1057.14	498
1059.38	508
1061.63	512
1063.87	500
1066.12	512
1068.36	502
1070.6	500
1072.85	516
1075.09	484
1077.33	528
1079.57	494
1081.81	502
1084.05	492
1086.28	498
1088.52	504
1090.76	512
1092.99	484
1095.23	522
1097.46	492
1099.69	500
1101.93	524
1104.16	492
1106.39	506
1108.62	496
1110.85	512
1113.08	518
1115.31	494
1117.53	506
1119.76	524
1121.99	502
1124.21	488
1126.44	514
1128.66	512
1130.88	466
1133.11	494
1135.33	504
1137.55	530
1139.77	506
1141.99	498
1144.21	504
1146.43	494
1148.64	524
1150.86	526
1153.08	528
1155.29	518
1157.51	540
1159.72	522
1161.93	500
1164.14	518
1166.36	516
1168.57	506
1170.78	526
1172.99	512
1175.2	530
1177.4	522
1179.61	494
1181.82	500
1184.02	498
1186.23	506
1188.43	506
1190.64	496
1192.84	504
1195.04	524
1197.24	500
1199.45	497.97
1201.64	497.767
1203.84	508.286
1206.04	513.721
1208.24	506.057
1210.44	502.989
1212.64	477.302
1214.83	519.293
1217.03	500.27
1219.22	491.21
1221.41	501.292
1223.61	519.998
1225.8	497.487
1227.99	495.694
1230.18	507.803
1232.37	485.641
1234.56	507.392
1236.75	506.051
1238.94	497.364
1241.13	504.807
1243.31	502.535
1245.5	498.251
1247.68	511.698
1249.87	510.835
1252.05	504.574
1254.24	499.917
1256.42	512.447
1258.6	501.44
1260.78	513.332
1262.96	515.23
1265.14	504.019
1267.32	519.579
1269.5	513.809
1271.67	518.66
1273.85	531.539
1276.03	522.021
1278.2	512.658
1280.38	522.388
1282.55	521.777
1284.72	546.603
1286.9	532.56
1289.07	537.019
1291.24	527.98
1293.41	535.663
1295.58	524.648
1297.75	545.771
1299.92	562.092
1302.09	540.207
1304.25	530.35
1306.42	566.706
1308.44	546
1310.61	552
1312.79	550
1314.97	590
1317.14	588
1319.31	554
1321.48	550
1323.66	558
1325.83	546
1328	568
1330.17	570
1332.34	560
1334.5	576
1336.67	546
1338.84	568
1341	584
1343.17	562
1345.33	546
1347.5	542
1349.66	556
1351.83	534
1353.99	568
1356.15	528
1358.31	506
1360.47	546
1362.63	510
1364.79	556
1366.94	532
1369.1	540
1371.26	500
1373.41	544
1375.57	534
1377.72	532
1379.88	524
1382.03	516
1384.18	526
1386.33	516
1388.48	510
1390.64	524
1392.79	512
1394.93	510
1397.08	500
1399.23	526
1401.38	512
1403.52	532
1405.67	506
1407.81	504
1409.96	470
1412.1	488
1414.24	486
1416.39	510
1418.53	510
1420.67	506
1422.81	506
1424.95	502
1427.09	492
1429.23	490
1431.36	488
1433.5	510
1435.64	488
1437.77	508
1439.91	494
1442.04	490
1444.17	512
1446.31	504
1448.44	482
1450.57	508
1452.7	478
1454.83	484
1456.96	482
1459.09	472
1461.22	504
1463.34	480
1465.47	520
1467.6	482
1469.72	502
1471.85	496
1473.97	478
1476.09	508
1478.22	482
1480.34	470
1482.46	482
1484.58	498
1486.7	502
1488.82	488
1490.94	478
1493.06	504
1495.17	474
1497.29	494
1499.41	510
1501.52	494
1503.64	478
1505.75	518
1507.86	502
1509.98	482
1512.09	496
1514.2	488
1516.31	474
1518.42	502
1520.53	486
1522.64	474
1524.74	474
1526.85	470
1528.96	504
1531.07	466
1533.17	468
1535.27	458
1537.38	494
1539.48	472
1541.58	484
1543.69	470
1545.79	470
1547.89	482
1549.99	492
1552.09	484
1554.19	504
1556.28	496
1558.38	488
1560.48	478
1562.57	476
1564.67	492
1566.76	502
1568.86	510
1570.95	496
1573.05	490
1575.14	504
1577.23	486
1579.32	530
1581.41	496
1583.5	500
1585.59	494
1587.68	506
1589.76	514
1591.85	516
1593.94	512
1596.02	492
1598.11	510
1600.19	506
1602.27	492
1604.36	518
1606.44	502
1608.52	486
1610.6	492
1612.68	528
1614.76	478
1616.84	484
1618.92	482
1621	506
1623.07	498
1625.15	476
1627.23	476
1629.3	480
1631.38	504
1633.45	472
1635.52	462
1637.59	450
1639.67	468
1641.74	480
1643.81	470
1645.88	476
1647.95	472
1650.02	470
1652.08	456
1654.15	464
1656.22	426
1658.28	452
1660.35	454
1662.41	440
1664.48	432
1666.54	428
1668.6	438
1670.67	468
1672.73	430
1674.79	440
1676.85	464
1678.91	454
1680.97	436
1683.03	432
1685.08	424
1687.14	434
1689.2	422
1691.25	442
1693.31	454
1695.36	444
1697.42	440
1699.47	420
1701.52	402
1703.57	414
1705.63	422
1707.68	426
1709.72	414
1711.77	442
1713.82	428
1715.87	426
1717.92	446
1719.97	430
1722.01	434
1724.06	424
1726.1	438
1728.15	416
1730.19	402
1732.23	406
1734.27	420
1736.32	424
1738.36	410
1740.4	424
1742.44	410
1744.48	404
1746.51	436
1748.55	402
1750.59	390
1752.63	408
1754.66	400
1756.7	386
1758.73	412
1760.77	426
1762.8	442
1764.83	402
1766.86	424
1768.9	398
1770.93	402
1772.96	396
1774.99	416
1777.02	394
1779.04	402
1781.07	410
1783.1	402
1785.13	412
1787.15	392
1789.18	412
1791.2	400
1793.23	394
1795.25	386
1797.27	414
1799.29	400
1801.31	398
1803.34	406
1805.36	412
1807.38	408
1809.39	378
1811.41	388
1813.43	400
1815.45	416
1817.46	402
1819.48	404
1821.49	398
1823.51	394
1825.52	394
1827.54	398
1829.55	408
1831.56	398
1833.57	380
1835.58	378
1837.59	388
1839.6	384
1841.61	364
1843.62	398
1845.63	384
1847.64	394
1849.64	382
1851.65	366
1853.65	372
1855.66	388
1857.66	378
1859.66	366
1861.67	370
1863.67	392
1865.67	376
1867.67	388
1869.67	378
1871.67	394
1873.67	370
1875.67	370
1877.67	382
1879.66	364
1881.66	372
1883.66	370
1885.65	364
1887.65	360
1889.64	358
1891.63	374
1893.63	386
1895.62	372
1897.61	378
1899.6	360
1901.59	348
1903.58	368
1905.57	370
1907.56	364
1909.55	340
1911.53	368
1913.52	368
1915.51	354
1917.49	372
1919.48	358
1921.46	378
1923.45	338
1925.43	374
1927.41	366
1929.39	362
1931.37	356
1933.36	354
1935.33	362
1937.31	376
1939.29	382
1941.27	350
1943.25	364
1945.23	352
1947.2	352
1949.18	352
1951.15	352
1953.13	367
1955.1	332
1957.08	354
1959.05	364
1961.02	360
1962.99	346
1964.96	356
1966.93	350
1968.9	362
1970.87	354
1972.84	352
1974.81	352
1976.77	348
1978.74	344
1980.71	358
1982.67	344
1984.64	338
1986.6	352
1988.57	348
1990.53	336
1992.49	342
1994.45	338
1996.41	328
1998.37	344
1999.35	342