File: muestras/LIG/fproof_14.txt
#Acq. time (s)=	10
#Accumulations=	2
#Range (cm-¹)=	100...2000
#Windows=	2
#Autofocus=	Off
#AutoExposure=	Off
#Spike filter=	Multiple accum.
#Delay time (s)=	0
#Binning=	1
#Readout mode=	Signal
#DeNoise=	Off
#ICS correction=	Off
#Dark correction=	Off
#Inst. Process=	Off
#Instrument=	LabRAM HR Evol
#Detector=	Syncerity OE
#Objective=	x100_VIS_LWD
#Grating=	600 (500nm)
#ND Filter=	25%
#Laser=	633nm_Edge
#Hole=	100.021
#Range=	Visible
#Project=	LIG
#Sample=	proof
#Site=
#Title=	fproof
#Remark=
#Date=	07.03.2023 13:05
#Acquired=	07.03.2023 13:05:43
101.054	36
103.621	44
106.187	38
108.753	44
111.317	36
113.881	42
116.443	42
119.005	36
121.566	36
124.126	36
126.685	40
129.243	34
131.801	32
134.357	36
136.911	34
139.466	42
142.021	36
144.574	36
147.126	30
149.676	30
152.227	32
154.777	32
157.325	28
159.873	32
162.419	32
164.966	34
167.51	32
170.055	32
172.598	34
175.141	30
177.682	36
180.222	40
182.763	42
185.302	34
187.839	42
190.378	30
192.914	28
195.449	32
197.983	34
200.517	36
203.05	32
205.582	30
208.113	32
210.643	36
213.173	34
215.701	38
218.229	38
220.756	36
223.282	38
225.808	38
228.331	32
230.855	44
233.378	30
235.9	38
238.419	42
240.94	36
243.46	28
245.977	34
248.495	38
251.011	38
253.527	32
256.041	40
258.556	32
261.068	32
263.58	32
266.092	28
268.603	32
271.112	34
273.622	32
276.129	38
278.636	32
281.142	28
283.647	34
286.152	32
288.655	32
291.158	32
293.66	30
296.161	38
298.661	36
301.161	36
303.66	32
306.158	36
308.655	40
311.151	28
313.645	38
316.14	32
318.634	38
321.125	36
323.618	38
326.109	34
328.598	30
331.088	36
333.576	34
336.064	28
338.55	32
341.037	36
343.521	36
346.005	38
348.489	28
350.971	40
353.453	32
355.935	40
358.414	36
360.893	36
363.371	28
365.848	32
368.325	34
370.801	32
373.275	30
375.75	36
378.223	36
380.695	40
383.167	36
385.638	34
388.108	32
390.577	36
393.044	36
395.512	38
397.979	38
400.445	38
402.909	40
405.374	36
407.836	34
410.299	36
412.762	42
415.221	36
417.681	32
420.141	32
422.598	34
425.057	32
427.513	38
429.968	28
432.424	38
434.878	30
437.33	38
439.783	30
442.234	34
444.685	32
447.136	38
449.585	32
452.033	32
454.48	42
456.927	34
459.372	42
461.817	38
464.261	34
466.705	36
469.147	36
471.589	38
474.029	36
476.47	40
478.909	30
481.347	34
483.785	36
486.221	38
488.657	32
491.093	32
493.527	42
495.96	36
498.393	26
500.824	36
503.256	36
505.686	36
508.115	36
510.543	32
512.972	36
515.399	36
517.825	34
520.25	36
522.674	36
525.097	30
527.52	44
529.942	36
532.364	38
534.784	40
537.204	34
539.623	30
542.041	36
544.458	38
546.874	40
549.289	34
551.705	30
554.118	34
556.531	34
558.944	40
561.355	36
563.766	28
566.175	40
568.585	34
570.992	28
573.401	36
575.807	42
578.212	34
580.618	36
583.022	32
585.425	34
587.827	36
590.229	36
592.631	38
595.031	34
597.43	40
599.829	36
602.226	32
604.623	36
607.02	28
609.415	34
611.808	32
614.202	36
616.596	32
618.988	34
621.38	32
623.769	36
626.159	32
628.549	30
630.936	32
633.324	38
635.71	38
638.096	34
640.481	32
642.866	38
645.248	34
647.632	38
650.013	34
652.394	42
654.773	30
657.154	40
659.532	32
661.91	34
664.286	38
666.663	30
669.038	34
671.412	38
673.786	34
676.159	32
678.532	30
680.903	42
683.274	36
685.644	38
688.014	42
690.382	38
692.749	30
695.116	38
697.482	34
699.846	42
702.211	30
704.574	30
706.938	30
709.299	32
711.661	36
714.021	36
716.381	36
718.739	36
721.097	30
723.455	34
725.811	32
728.167	38
730.521	30
732.877	34
735.23	38
737.582	32
739.934	32
742.285	38
744.635	36
746.985	36
749.334	38
751.682	36
754.028	36
756.374	38
758.72	32
761.065	36
763.408	40
765.752	38
768.095	32
770.436	34
772.777	32
775.116	28
777.456	38
779.794	32
782.133	36
784.469	32
786.806	34
789.141	34
791.476	38
793.809	32
796.143	34
798.476	36
800.807	36
803.138	32
805.468	38
807.797	38
810.125	32
812.453	34
814.78	38
817.106	40
819.432	38
821.757	38
824.081	42
826.403	32
828.726	36
831.048	34
833.368	36
835.688	34
838.008	32
840.326	38
842.644	28
844.96	36
847.277	34
849.592	36
851.906	36
854.221	40
856.534	28
858.846	36
861.159	32
863.469	34
865.779	44
868.088	34
870.396	38
872.704	36
875.011	30
877.318	38
879.623	32
881.928	36
884.232	36
886.536	34
888.838	32
891.139	34
893.44	34
895.741	40
898.039	36
900.339	34
902.637	40
904.933	34
907.231	32
909.526	32
911.821	34
914.115	36
916.408	36
918.701	42
920.993	34
923.283	36
925.575	42
927.864	40
930.153	40
932.441	38
934.728	38
937.014	44
939.3	34
941.585	34
943.87	34
946.154	40
948.437	34
950.719	36
953	34
955.28	36
957.56	36
959.84	36
962.117	36
964.395	36
966.673	38
968.948	32
971.224	36
973.498	30
975.773	40
978.045	36
980.317	38
982.59	38
984.86	32
987.13	36
989.399	38
991.669	30
993.937	34
996.204	36
998.47	34
1000.74	32
1003	40
1005.26	34
1007.53	34
1009.79	36
1012.05	36
1014.31	34
1016.57	30
1018.83	44
1021.09	34
1023.35	38
1025.61	32
1027.87	38
1030.12	36
1032.38	36
1034.63	38
1036.88	38
1039.14	38
1041.39	40
1043.64	36
1045.89	32
1048.14	32
1050.39	36
1052.64	34
1054.89	38
1057.14	38
1059.38	34
1061.63	42
1063.87	40
1066.12	32
1068.36	34
1070.6	32
1072.85	34
1075.09	36
1077.33	38
1079.57	38
1081.81	28
1084.05	38
1086.28	36
1088.52	36
1090.76	36
1092.99	30
1095.23	36
1097.46	44
1099.69	42
1101.93	32
1104.16	38
1106.39	38
1108.62	40
1110.85	34
1113.08	36
1115.31	38
1117.53	36
1119.76	44
1121.99	48
1124.21	38
1126.44	44
1128.66	42
1130.88	44
1133.11	42
1135.33	42
1137.55	40
1139.77	44
1141.99	50
1144.21	44
1146.43	44
1148.64	48
1150.86	48
1153.08	42
1155.29	38
1157.51	38
1159.72	46
1161.93	40
1164.14	44
1166.36	40
1168.57	48
1170.78	42
1172.99	44
1175.2	36
1177.4	36
1179.61	40
1181.82	44
1184.02	36
1186.23	32
1188.43	42
1190.64	34
1192.84	44
1195.04	46
1197.24	42
1199.45	47.93
1201.64	41.9223
1203.84	45.9642
1206.04	40.053
1208.24	45.49
1210.44	37.9694
1212.64	45.2821
1214.83	44.1921
1217.03	49.7199
1219.22	42.5419
1221.41	39.5692
1223.61	44.4019
1225.8	42.2228
1227.99	45.2034
1230.18	45.9698
1232.37	48.4614
1234.56	44.7842
1236.75	42.9361
1238.94	44.9828
1241.13	44.6766
1243.31	45.0709
1245.5	44.6307
1247.68	46.89
1249.87	45.6727
1252.05	46.4382
1254.24	47.6157
1256.42	49.15
1258.6	48.4514
1260.78	46.138
1262.96	51.1718
1265.14	52.3881
1267.32	52.9019
1269.5	54.4026
1271.67	56.2574
1273.85	57.3096
1276.03	55.3801
1278.2	55.3425
1280.38	65.2173
1282.55	62.2878
1284.72	62.5281
1286.9	63.9218
1289.07	66.6807
1291.24	70.0122
1293.41	71.6801
1295.58	73.1
1297.75	80.6619
1299.92	78.5016
1302.09	90.8389
1304.25	97.5494
1306.42	100.343
1308.44	102
1310.61	114
1312.79	120
1314.97	120
1317.14	130
1319.31	128
1321.48	138
1323.66	138
1325.83	148
1328	148
1330.17	142
1332.34	152
1334.5	146
1336.67	146
1338.84	140
1341	130
1343.17	136
1345.33	126
1347.5	124
1349.66	102
1351.83	98
1353.99	110
1356.15	98
1358.31	84
1360.47	86
1362.63	90
1364.79	74
1366.94	88
1369.1	74
1371.26	68
1373.41	66
1375.57	64
1377.72	64
1379.88	60
1382.03	66
1384.18	62
1386.33	62
1388.48	52
1390.64	54
1392.79	52
1394.93	58
1397.08	50
1399.23	54
1401.38	52
1403.52	54
1405.67	52
1407.81	48
1409.96	54
1412.1	48
1414.24	44
1416.39	42
1418.53	44
1420.67	46
1422.81	48
1424.95	42
1427.09	54
1429.23	50
1431.36	54
1433.5	48
1435.64	46
1437.77	42
1439.91	48
1442.04	42
1444.17	42
1446.31	44
1448.44	40
1450.57	42
1452.7	40
1454.83	44
1456.96	44
1459.09	50
1461.22	46
1463.34	48
1465.47	38
1467.6	48
1469.72	46
1471.85	44
1473.97	46
1476.09	40
1478.22	48
1480.34	48
1482.46	48
1484.58	46
1486.7	44
1488.82	48
1490.94	34
1493.06	44
1495.17	42
1497.29	40
1499.41	40
1501.52	40
1503.64	46
1505.75	50
1507.86	56
1509.98	48
1512.09	44
1514.2	48
1516.31	54
1518.42	46
1520.53	44
1522.64	42
1524.74	44
1526.85	50
1528.96	50
1531.07	54
1533.17	48
1535.27	50
1537.38	50
1539.48	50
1541.58	60
1543.69	54
1545.79	56
1547.89	56
1549.99	58
1552.09	56
1554.19	62
1556.28	70
1558.38	62
1560.48	64
1562.57	82
1564.67	84
1566.76	88
1568.86	92
1570.95	82
1573.05	96
1575.14	106
1577.23	102
1579.32	104
1581.41	104
1583.5	110
1585.59	102
1587.68	114
1589.76	116
1591.85	114
1593.94	106
1596.02	104
1598.11	100
1600.19	106
1602.27	98
1604.36	98
1606.44	98
1608.52	94
1610.6	98
1612.68	98
1614.76	96
1616.84	104
1618.92	92
1621	88
1623.07	98
1625.15	84
1627.23	70
1629.3	74
1631.38	76
1633.45	58
1635.52	58
1637.59	58
1639.67	60
1641.74	54
1643.81	54
1645.88	48
1647.95	48
1650.02	52
1652.08	50
1654.15	46
1656.22	50
1658.28	44
1660.35	44
1662.41	38
1664.48	36
1666.54	42
1668.6	44
1670.67	42
1672.73	44
1674.79	36
1676.85	42
1678.91	38
1680.97	42
1683.03	38
1685.08	32
1687.14	40
1689.2	36
1691.25	28
1693.31	30
1695.36	36
1697.42	46
1699.47	40
1701.52	36
1703.57	30
1705.63	34
1707.68	38
1709.72	38
1711.77	26
1713.82	38
1715.87	38
1717.92	42
1719.97	34
1722.01	38
1724.06	34
1726.1	32
1728.15	34
1730.19	32
1732.23	34
1734.27	36
1736.32	38
1738.36	34
1740.4	34
1742.44	34
1744.48	40
1746.51	38
1748.55	30
1750.59	30
1752.63	32
1754.66	34
1756.7	34
1758.73	30
1760.77	32
1762.8	38
1764.83	36
1766.86	28
1768.9	32
1770.93	32
1772.96	40
1774.99	40
1777.02	42
1779.04	36
1781.07	30
1783.1	38
1785.13	36
1787.15	32
1789.18	34
1791.2	34
1793.23	40
1795.25	34
1797.27	32
1799.29	40
1801.31	32
1803.34	34
1805.36	34
1807.38	38
1809.39	34
1811.41	28
1813.43	36
1815.45	38
1817.46	36
1819.48	40
1821.49	34
1823.51	40
1825.52	32
1827.54	30
1829.55	32
1831.56	34
1833.57	34
1835.58	36
1837.59	38
1839.6	28
1841.61	34
1843.62	34
1845.63	42
1847.64	44
1849.64	34
1851.65	34
1853.65	30
1855.66	30
1857.66	32
1859.66	32
1861.67	34
1863.67	34
1865.67	34
1867.67	38
1869.67	34
1871.67	38
1873.67	28
1875.67	40
1877.67	24
1879.66	40
1881.66	30
1883.66	38
1885.65	38
1887.65	36
1889.64	30
1891.63	28
1893.63	34
1895.62	36
1897.61	40
1899.6	32
1901.59	38
1903.58	38
1905.57	34
1907.56	38
1909.55	40
1911.53	36
1913.52	30
1915.51	34
1917.49	34
1919.48	30
1921.46	32
1923.45	36
1925.43	34
1927.41	36
1929.39	34
1931.37	38
1933.36	30
1935.33	30
1937.31	30
1939.29	36
1941.27	32
1943.25	34
1945.23	40
1947.2	32
1949.18	38
1951.15	32
1953.13	35
1955.1	34
1957.08	34
1959.05	38
1961.02	36
1962.99	38
1964.96	36
1966.93	28
1968.9	30
1970.87	34
1972.84	34
1974.81	36
1976.77	38
1978.74	36
1980.71	30
1982.67	28
1984.64	32
1986.6	28
1988.57	32
1990.53	34
1992.49	32
1994.45	36
1996.41	36
1998.37	36
1999.35	38