File: muestras/LIG/fproof_17.txt
#Acq. time (s)=	10
#Accumulations=	2
#Range (cm-¹)=	100...2000
#Windows=	2
#Autofocus=	Off
#AutoExposure=	Off
#Spike filter=	Multiple accum.
#Delay time (s)=	0
#Binning=	1
#Readout mode=	Signal
#DeNoise=	Off
#ICS correction=	Off
#Dark correction=	Off
#Inst. Process=	Off
#Instrument=	LabRAM HR Evol
#Detector=	Syncerity OE
#Objective=	x100_VIS_LWD
#Grating=	600 (500nm)
#ND Filter=	25%
#Laser=	633nm_Edge
#Hole=	100.021
#Range=	Visible
#Project=	LIG
#Sample=	proof
#Site=
#Title=	fproof
#Remark=
#Date=	07.03.2023 13:12
#Acquired=	07.03.2023 13:12:17
101.054	30
103.621	38
106.187	40
108.753	40
111.317	38
113.881	32
116.443	32
119.005	38
121.566	42
124.126	34
126.685	30
129.243	38
131.801	36
134.357	34
136.911	34
139.466	38
142.021	36
144.574	38
147.126	34
149.676	32
152.227	32
154.777	34
157.325	36
159.873	36
162.419	36
164.966	32
167.51	42
170.055	38
172.598	30
175.141	36
177.682	36
180.222	40
182.763	34
185.302	36
187.839	38
190.378	40
192.914	32
195.449	40
197.983	34
200.517	36
203.05	32
205.582	36
208.113	38
210.643	36
213.173	38
215.701	40
218.229	36
220.756	36
223.282	34
225.808	32
228.331	38
230.855	32
233.378	36
235.9	38
238.419	40
240.94	34
243.46	38
245.977	36
248.495	32
251.011	36
253.527	28
256.041	26
258.556	38
261.068	38
263.58	34
266.092	32
268.603	44
271.112	36
273.622	38
276.129	32
278.636	28
281.142	40
283.647	30
286.152	34
288.655	32
291.158	30
293.66	30
296.161	36
298.661	32
301.161	34
303.66	30
306.158	40
308.655	30
311.151	32
313.645	30
316.14	38
318.634	32
321.125	30
323.618	36
326.109	30
328.598	34
331.088	36
333.576	38
336.064	34
338.55	36
341.037	34
343.521	42
346.005	30
348.489	34
350.971	28
353.453	38
355.935	40
358.414	30
360.893	34
363.371	34
365.848	30
368.325	34
370.801	32
373.275	36
375.75	36
378.223	30
380.695	34
383.167	32
385.638	36
388.108	44
390.577	34
393.044	38
395.512	36
397.979	34
400.445	32
402.909	36
405.374	38
407.836	30
410.299	38
412.762	36
415.221	30
417.681	30
420.141	34
422.598	34
425.057	38
427.513	40
429.968	32
432.424	38
434.878	38
437.33	34
439.783	38
442.234	38
444.685	30
447.136	38
449.585	32
452.033	34
454.48	34
456.927	36
459.372	30
461.817	42
464.261	34
466.705	36
469.147	38
471.589	40
474.029	38
476.47	40
478.909	30
481.347	40
483.785	34
486.221	34
488.657	36
491.093	34
493.527	40
495.96	32
498.393	36
500.824	32
503.256	34
505.686	42
508.115	32
510.543	40
512.972	28
515.399	32
517.825	36
520.25	40
522.674	34
525.097	30
527.52	40
529.942	34
532.364	34
534.784	32
537.204	32
539.623	34
542.041	36
544.458	32
546.874	30
549.289	36
551.705	30
554.118	36
556.531	28
558.944	44
561.355	36
563.766	38
566.175	30
568.585	34
570.992	40
573.401	38
575.807	38
578.212	36
580.618	36
583.022	28
585.425	34
587.827	32
590.229	32
592.631	36
595.031	38
597.43	38
599.829	36
602.226	28
604.623	30
607.02	40
609.415	40
611.808	34
614.202	34
616.596	38
618.988	40
621.38	40
623.769	34
626.159	28
628.549	42
630.936	38
633.324	36
635.71	36
638.096	40
640.481	38
642.866	30
645.248	30
647.632	36
650.013	34
652.394	38
654.773	36
657.154	42
659.532	42
661.91	34
664.286	40
666.663	38
669.038	30
671.412	36
673.786	36
676.159	40
678.532	32
680.903	36
683.274	30
685.644	38
688.014	32
690.382	32
692.749	32
695.116	40
697.482	36
699.846	34
702.211	36
704.574	46
706.938	36
709.299	38
711.661	38
714.021	34
716.381	46
718.739	34
721.097	36
723.455	36
725.811	36
728.167	38
730.521	30
732.877	36
735.23	38
737.582	38
739.934	36
742.285	28
744.635	38
746.985	44
749.334	40
751.682	40
754.028	34
756.374	34
758.72	32
761.065	36
763.408	36
765.752	34
768.095	30
770.436	36
772.777	32
775.116	30
777.456	32
779.794	40
782.133	36
784.469	30
786.806	36
789.141	38
791.476	36
793.809	40
796.143	36
798.476	40
800.807	30
803.138	28
805.468	40
807.797	36
810.125	36
812.453	32
814.78	34
817.106	40
819.432	36
821.757	40
824.081	42
826.403	30
828.726	34
831.048	30
833.368	38
835.688	40
838.008	40
840.326	34
842.644	38
844.96	42
847.277	32
849.592	38
851.906	32
854.221	32
856.534	34
858.846	42
861.159	40
863.469	38
865.779	38
868.088	32
870.396	40
872.704	42
875.011	38
877.318	40
879.623	40
881.928	42
884.232	30
886.536	38
888.838	36
891.139	34
893.44	36
895.741	36
898.039	34
900.339	36
902.637	34
904.933	42
907.231	44
909.526	38
911.821	34
914.115	42
916.408	42
918.701	34
920.993	34
923.283	34
925.575	34
927.864	40
930.153	36
932.441	34
934.728	36
937.014	32
939.3	40
941.585	40
943.87	40
946.154	42
948.437	38
950.719	34
953	30
955.28	34
957.56	40
959.84	38
962.117	36
964.395	34
966.673	36
968.948	34
971.224	38
973.498	40
975.773	40
978.045	40
980.317	42
982.59	28
984.86	34
987.13	34
989.399	36
991.669	36
993.937	40
996.204	42
998.47	38
1000.74	44
1003	40
1005.26	30
1007.53	30
1009.79	40
1012.05	34
1014.31	22
1016.57	42
1018.83	38
1021.09	38
1023.35	32
1025.61	42
1027.87	38
1030.12	34
1032.38	38
1034.63	36
1036.88	30
1039.14	34
1041.39	36
1043.64	38
1045.89	40
1048.14	38
1050.39	36
1052.64	40
1054.89	30
1057.14	44
1059.38	38
1061.63	36
1063.87	40
1066.12	34
1068.36	46
1070.6	42
1072.85	40
1075.09	38
1077.33	40
1079.57	38
1081.81	34
1084.05	46
1086.28	42
1088.52	38
1090.76	44
1092.99	42
1095.23	46
1097.46	44
1099.69	42
1101.93	40
1104.16	38
1106.39	40
1108.62	44
1110.85	42
1113.08	44
1115.31	40
1117.53	48
1119.76	40
1121.99	40
1124.21	46
1126.44	36
1128.66	42
1130.88	40
1133.11	44
1135.33	40
1137.55	40
1139.77	42
1141.99	40
1144.21	44
1146.43	38
1148.64	40
1150.86	50
1153.08	44
1155.29	40
1157.51	42
1159.72	46
1161.93	42
1164.14	48
1166.36	40
1168.57	48
1170.78	44
1172.99	40
1175.2	48
1177.4	46
1179.61	48
1181.82	44
1184.02	52
1186.23	38
1188.43	44
1190.64	52
1192.84	46
1195.04	44
1197.24	40
1199.45	44.01
1201.64	40.1417
1203.84	45.9632
1206.04	47.894
1208.24	49.6882
1210.44	45.4597
1212.64	38.9231
1214.83	50.0979
1217.03	49.16
1219.22	45.4581
1221.41	47.9792
1223.61	52.2173
1225.8	47.7709
1227.99	54.2931
1230.18	47.7361
1232.37	49.1655
1234.56	50.9118
1236.75	49.93
1238.94	56.3904
1241.13	53.3234
1243.31	47.1578
1245.5	55.6693
1247.68	52.7892
1249.87	54.3273
1252.05	51.6327
1254.24	57.94
1256.42	55.15
1258.6	52.3371
1260.78	58.3181
1262.96	58.68
1265.14	61.9819
1267.32	58.5442
1269.5	63.208
1271.67	60.2904
1273.85	64.3398
1276.03	61.3258
1278.2	68.1075
1280.38	66.47
1282.55	66.4483
1284.72	71.5728
1286.9	76.8441
1289.07	71.4
1291.24	76.6464
1293.41	73.1401
1295.58	79.654
1297.75	76.8089
1299.92	79.9016
1302.09	88.6955
1304.25	93.2141
1306.42	93.7169
1308.44	88
1310.61	80
1312.79	100
1314.97	96
1317.14	98
1319.31	110
1321.48	100
1323.66	106
1325.83	110
1328	104
1330.17	114
1332.34	110
1334.5	108
1336.67	106
1338.84	106
1341	102
1343.17	108
1345.33	96
1347.5	92
1349.66	96
1351.83	94
1353.99	86
1356.15	92
1358.31	82
1360.47	82
1362.63	72
1364.79	74
1366.94	82
1369.1	80
1371.26	68
1373.41	74
1375.57	64
1377.72	78
1379.88	68
1382.03	68
1384.18	66
1386.33	72
1388.48	70
1390.64	64
1392.79	62
1394.93	62
1397.08	56
1399.23	58
1401.38	54
1403.52	58
1405.67	58
1407.81	62
1409.96	52
1412.1	56
1414.24	56
1416.39	58
1418.53	60
1420.67	50
1422.81	58
1424.95	52
1427.09	48
1429.23	52
1431.36	54
1433.5	48
1435.64	50
1437.77	54
1439.91	52
1442.04	52
1444.17	52
1446.31	46
1448.44	52
1450.57	54
1452.7	54
1454.83	54
1456.96	44
1459.09	50
1461.22	56
1463.34	46
1465.47	50
1467.6	48
1469.72	48
1471.85	56
1473.97	54
1476.09	50
1478.22	46
1480.34	54
1482.46	50
1484.58	52
1486.7	46
1488.82	50
1490.94	54
1493.06	52
1495.17	52
1497.29	54
1499.41	44
1501.52	48
1503.64	40
1505.75	52
1507.86	54
1509.98	48
1512.09	52
1514.2	52
1516.31	52
1518.42	50
1520.53	52
1522.64	50
1524.74	46
1526.85	54
1528.96	52
1531.07	58
1533.17	60
1535.27	58
1537.38	56
1539.48	50
1541.58	60
1543.69	56
1545.79	52
1547.89	60
1549.99	56
1552.09	56
1554.19	64
1556.28	58
1558.38	62
1560.48	60
1562.57	64
1564.67	64
1566.76	76
1568.86	70
1570.95	78
1573.05	72
1575.14	74
1577.23	80
1579.32	84
1581.41	70
1583.5	78
1585.59	92
1587.68	82
1589.76	84
1591.85	88
1593.94	86
1596.02	88
1598.11	82
1600.19	88
1602.27	88
1604.36	86
1606.44	82
1608.52	72
1610.6	80
1612.68	74
1614.76	76
1616.84	82
1618.92	72
1621	90
1623.07	78
1625.15	70
1627.23	66
1629.3	68
1631.38	72
1633.45	62
1635.52	60
1637.59	64
1639.67	62
1641.74	54
1643.81	48
1645.88	62
1647.95	52
1650.02	60
1652.08	48
1654.15	50
1656.22	42
1658.28	46
1660.35	40
1662.41	48
1664.48	42
1666.54	42
1668.6	38
1670.67	42
1672.73	38
1674.79	38
1676.85	36
1678.91	42
1680.97	46
1683.03	36
1685.08	34
1687.14	32
1689.2	46
1691.25	40
1693.31	38
1695.36	40
1697.42	44
1699.47	32
1701.52	38
1703.57	38
1705.63	38
1707.68	30
1709.72	36
1711.77	36
1713.82	30
1715.87	34
1717.92	34
1719.97	34
1722.01	40
1724.06	28
1726.1	44
1728.15	40
1730.19	34
1732.23	38
1734.27	34
1736.32	38
1738.36	32
1740.4	36
1742.44	36
1744.48	36
1746.51	30
1748.55	34
1750.59	40
1752.63	42
1754.66	38
1756.7	36
1758.73	28
1760.77	38
1762.8	36
1764.83	40
1766.86	38
1768.9	42
1770.93	34
1772.96	40
1774.99	32
1777.02	36
1779.04	36
1781.07	46
1783.1	36
1785.13	32
1787.15	38
1789.18	32
1791.2	32
1793.23	38
1795.25	32
1797.27	36
1799.29	32
1801.31	36
1803.34	32
1805.36	36
1807.38	36
1809.39	34
1811.41	34
1813.43	38
1815.45	36
1817.46	34
1819.48	36
1821.49	36
1823.51	34
1825.52	36
1827.54	40
1829.55	30
1831.56	36
1833.57	34
1835.58	40
1837.59	30
1839.6	26
1841.61	34
1843.62	30
1845.63	36
1847.64	30
1849.64	26
1851.65	36
1853.65	26
1855.66	42
1857.66	32
1859.66	38
1861.67	32
1863.67	36
1865.67	38
1867.67	36
1869.67	34
1871.67	36
1873.67	34
1875.67	34
1877.67	36
1879.66	32
1881.66	36
1883.66	38
1885.65	36
1887.65	36
1889.64	32
1891.63	42
1893.63	38
1895.62	34
1897.61	36
1899.6	28
1901.59	38
1903.58	30
1905.57	30
1907.56	36
1909.55	36
1911.53	34
1913.52	38
1915.51	38
1917.49	32
1919.48	36
1921.46	36
1923.45	36
1925.43	38
1927.41	32
1929.39	32
1931.37	38
1933.36	34
1935.33	34
1937.31	34
1939.29	38
1941.27	32
1943.25	42
1945.23	32
1947.2	40
1949.18	30
1951.15	28
1953.13	36
1955.1	32
1957.08	38
1959.05	32
1961.02	28
1962.99	38
1964.96	24
1966.93	28
1968.9	38
1970.87	28
1972.84	38
1974.81	32
1976.77	26
1978.74	30
1980.71	36
1982.67	30
1984.64	36
1986.6	34
1988.57	38
1990.53	34
1992.49	30
1994.45	30
1996.41	32
1998.37	28
1999.35	42