File: muestras/LIG/fproof_22.txt
#Acq. time (s)=	10
#Accumulations=	2
#Range (cm-¹)=	100...2000
#Windows=	2
#Autofocus=	Off
#AutoExposure=	Off
#Spike filter=	Multiple accum.
#Delay time (s)=	0
#Binning=	1
#Readout mode=	Signal
#DeNoise=	Off
#ICS correction=	Off
#Dark correction=	Off
#Inst. Process=	Off
#Instrument=	LabRAM HR Evol
#Detector=	Syncerity OE
#Objective=	x100_VIS_LWD
#Grating=	600 (500nm)
#ND Filter=	25%
#Laser=	633nm_Edge
#Hole=	100.021
#Range=	Visible
#Project=	LIG
#Sample=	proof
#Site=
#Title=	fproof
#Remark=
#Date=	07.03.2023 13:23
#Acquired=	07.03.2023 13:23:49
101.054	48
103.621	44
106.187	42
108.753	34
111.317	42
113.881	44
116.443	46
119.005	44
121.566	46
124.126	48
126.685	44
129.243	38
131.801	40
134.357	44
136.911	42
139.466	42
142.021	46
144.574	34
147.126	48
149.676	40
152.227	42
154.777	44
157.325	42
159.873	44
162.419	46
164.966	40
167.51	40
170.055	40
172.598	42
175.141	46
177.682	46
180.222	42
182.763	38
185.302	40
187.839	46
190.378	46
192.914	38
195.449	42
197.983	40
200.517	44
203.05	40
205.582	44
208.113	42
210.643	40
213.173	44
215.701	50
218.229	42
220.756	44
223.282	44
225.808	50
228.331	50
230.855	50
233.378	46
235.9	38
238.419	48
240.94	48
243.46	48
245.977	38
248.495	42
251.011	50
253.527	46
256.041	46
258.556	42
261.068	44
263.58	38
266.092	40
268.603	42
271.112	40
273.622	38
276.129	44
278.636	46
281.142	40
283.647	42
286.152	38
288.655	44
291.158	46
293.66	34
296.161	36
298.661	36
301.161	34
303.66	42
306.158	42
308.655	44
311.151	46
313.645	36
316.14	44
318.634	44
321.125	42
323.618	38
326.109	42
328.598	44
331.088	44
333.576	36
336.064	48
338.55	44
341.037	52
343.521	42
346.005	40
348.489	42
350.971	42
353.453	38
355.935	46
358.414	44
360.893	44
363.371	42
365.848	38
368.325	50
370.801	42
373.275	40
375.75	42
378.223	46
380.695	44
383.167	40
385.638	40
388.108	44
390.577	46
393.044	32
395.512	42
397.979	46
400.445	34
402.909	44
405.374	28
407.836	34
410.299	42
412.762	44
415.221	42
417.681	40
420.141	40
422.598	44
425.057	46
427.513	48
429.968	46
432.424	36
434.878	42
437.33	46
439.783	44
442.234	42
444.685	42
447.136	44
449.585	46
452.033	42
454.48	38
456.927	46
459.372	42
461.817	42
464.261	40
466.705	46
469.147	36
471.589	38
474.029	40
476.47	40
478.909	38
481.347	42
483.785	30
486.221	40
488.657	48
491.093	38
493.527	42
495.96	42
498.393	46
500.824	40
503.256	46
505.686	40
508.115	40
510.543	42
512.972	42
515.399	42
517.825	36
520.25	50
522.674	42
525.097	48
527.52	42
529.942	48
532.364	34
534.784	40
537.204	42
539.623	48
542.041	42
544.458	38
546.874	36
549.289	42
551.705	46
554.118	42
556.531	40
558.944	44
561.355	44
563.766	42
566.175	42
568.585	46
570.992	46
573.401	38
575.807	40
578.212	46
580.618	48
583.022	42
585.425	44
587.827	44
590.229	36
592.631	42
595.031	46
597.43	52
599.829	44
602.226	52
604.623	40
607.02	38
609.415	40
611.808	42
614.202	44
616.596	38
618.988	46
621.38	44
623.769	42
626.159	48
628.549	46
630.936	44
633.324	44
635.71	42
638.096	48
640.481	44
642.866	48
645.248	42
647.632	42
650.013	42
652.394	40
654.773	48
657.154	38
659.532	48
661.91	44
664.286	46
666.663	50
669.038	46
671.412	52
673.786	44
676.159	46
678.532	44
680.903	42
683.274	46
685.644	36
688.014	44
690.382	48
692.749	42
695.116	44
697.482	54
699.846	42
702.211	44
704.574	46
706.938	42
709.299	44
711.661	40
714.021	44
716.381	52
718.739	42
721.097	42
723.455	44
725.811	42
728.167	46
730.521	44
732.877	46
735.23	44
737.582	50
739.934	44
742.285	42
744.635	44
746.985	46
749.334	40
751.682	48
754.028	46
756.374	48
758.72	48
761.065	48
763.408	46
765.752	42
768.095	40
770.436	50
772.777	46
775.116	38
777.456	38
779.794	38
782.133	46
784.469	42
786.806	46
789.141	40
791.476	42
793.809	44
796.143	44
798.476	38
800.807	48
803.138	40
805.468	42
807.797	38
810.125	40
812.453	44
814.78	42
817.106	40
819.432	42
821.757	44
824.081	44
826.403	46
828.726	36
831.048	44
833.368	48
835.688	40
838.008	42
840.326	40
842.644	42
844.96	40
847.277	44
849.592	32
851.906	44
854.221	46
856.534	48
858.846	46
861.159	50
863.469	40
865.779	48
868.088	44
870.396	38
872.704	48
875.011	40
877.318	40
879.623	42
881.928	46
884.232	48
886.536	40
888.838	46
891.139	46
893.44	38
895.741	44
898.039	42
900.339	46
902.637	46
904.933	44
907.231	44
909.526	44
911.821	48
914.115	44
916.408	36
918.701	46
920.993	52
923.283	46
925.575	48
927.864	46
930.153	42
932.441	38
934.728	34
937.014	44
939.3	48
941.585	42
943.87	46
946.154	40
948.437	42
950.719	46
953	46
955.28	42
957.56	48
959.84	46
962.117	36
964.395	44
966.673	34
968.948	48
971.224	50
973.498	50
975.773	46
978.045	50
980.317	36
982.59	36
984.86	44
987.13	46
989.399	54
991.669	46
993.937	54
996.204	34
998.47	38
1000.74	48
1003	42
1005.26	42
1007.53	46
1009.79	46
1012.05	48
1014.31	44
1016.57	52
1018.83	46
1021.09	44
1023.35	44
1025.61	44
1027.87	38
1030.12	46
1032.38	44
1034.63	46
1036.88	44
1039.14	40
1041.39	46
1043.64	46
1045.89	48
1048.14	50
1050.39	42
1052.64	38
1054.89	44
1057.14	42
1059.38	46
1061.63	44
1063.87	46
1066.12	46
1068.36	48
1070.6	48
1072.85	52
1075.09	44
1077.33	52
1079.57	50
1081.81	48
1084.05	42
1086.28	52
1088.52	50
1090.76	50
1092.99	50
1095.23	48
1097.46	52
1099.69	56
1101.93	54
1104.16	48
1106.39	54
1108.62	50
1110.85	54
1113.08	52
1115.31	52
1117.53	48
1119.76	52
1121.99	50
1124.21	52
1126.44	60
1128.66	52
1130.88	48
1133.11	54
1135.33	58
1137.55	60
1139.77	50
1141.99	56
1144.21	54
1146.43	56
1148.64	58
1150.86	60
1153.08	50
1155.29	60
1157.51	54
1159.72	58
1161.93	56
1164.14	50
1166.36	56
1168.57	62
1170.78	56
1172.99	62
1175.2	56
1177.4	60
1179.61	56
1181.82	52
1184.02	60
1186.23	54
1188.43	56
1190.64	50
1192.84	50
1195.04	62
1197.24	56
1199.45	61.99
1201.64	48.3194
1203.84	50.0532
1206.04	56.313
1208.24	52.4535
1210.44	57.79
1212.64	52.9679
1214.83	58.5449
1217.03	57.1999
1219.22	55.9739
1221.41	59.6108
1223.61	54.9154
1225.8	59.5037
1227.99	72.1434
1230.18	61.6798
1232.37	58.3186
1234.56	61.1303
1236.75	64.2461
1238.94	61.5348
1241.13	63.0432
1243.31	63.4509
1245.5	65.7807
1247.68	64.176
1249.87	63.4413
1252.05	66.8163
1254.24	68.1228
1256.42	72.3733
1258.6	73.27
1260.78	75.7981
1262.96	75.6889
1265.14	73.2238
1267.32	70.8136
1269.5	80.58
1271.67	79.7626
1273.85	87.5998
1276.03	87.8542
1278.2	88.9887
1280.38	94.1141
1282.55	94.6883
1284.72	99.6191
1286.9	98.4259
1289.07	102.739
1291.24	111.266
1293.41	112.683
1295.58	117.602
1297.75	122.333
1299.92	133.25
1302.09	131.025
1304.25	140.748
1306.42	153.489
1308.44	162
1310.61	168
1312.79	180
1314.97	178
1317.14	178
1319.31	202
1321.48	206
1323.66	214
1325.83	212
1328	216
1330.17	208
1332.34	216
1334.5	208
1336.67	216
1338.84	218
1341	210
1343.17	208
1345.33	170
1347.5	176
1349.66	158
1351.83	162
1353.99	158
1356.15	152
1358.31	134
1360.47	134
1362.63	136
1364.79	114
1366.94	118
1369.1	112
1371.26	108
1373.41	106
1375.57	102
1377.72	102
1379.88	98
1382.03	88
1384.18	90
1386.33	78
1388.48	82
1390.64	84
1392.79	82
1394.93	74
1397.08	74
1399.23	74
1401.38	84
1403.52	72
1405.67	70
1407.81	80
1409.96	68
1412.1	76
1414.24	58
1416.39	68
1418.53	66
1420.67	72
1422.81	64
1424.95	64
1427.09	62
1429.23	64
1431.36	72
1433.5	68
1435.64	72
1437.77	68
1439.91	54
1442.04	62
1444.17	62
1446.31	70
1448.44	62
1450.57	60
1452.7	60
1454.83	68
1456.96	64
1459.09	62
1461.22	66
1463.34	58
1465.47	54
1467.6	56
1469.72	68
1471.85	66
1473.97	68
1476.09	62
1478.22	60
1480.34	52
1482.46	68
1484.58	56
1486.7	68
1488.82	70
1490.94	62
1493.06	64
1495.17	62
1497.29	68
1499.41	68
1501.52	58
1503.64	66
1505.75	76
1507.86	68
1509.98	62
1512.09	68
1514.2	72
1516.31	64
1518.42	66
1520.53	64
1522.64	64
1524.74	62
1526.85	74
1528.96	66
1531.07	68
1533.17	70
1535.27	76
1537.38	76
1539.48	74
1541.58	72
1543.69	74
1545.79	78
1547.89	88
1549.99	82
1552.09	86
1554.19	104
1556.28	112
1558.38	110
1560.48	100
1562.57	120
1564.67	118
1566.76	126
1568.86	122
1570.95	126
1573.05	150
1575.14	140
1577.23	166
1579.32	166
1581.41	164
1583.5	166
1585.59	160
1587.68	178
1589.76	170
1591.85	168
1593.94	158
1596.02	170
1598.11	170
1600.19	164
1602.27	168
1604.36	156
1606.44	158
1608.52	152
1610.6	156
1612.68	144
1614.76	146
1616.84	162
1618.92	144
1621	150
1623.07	120
1625.15	108
1627.23	116
1629.3	108
1631.38	114
1633.45	94
1635.52	102
1637.59	80
1639.67	78
1641.74	78
1643.81	82
1645.88	72
1647.95	62
1650.02	70
1652.08	68
1654.15	58
1656.22	66
1658.28	62
1660.35	50
1662.41	48
1664.48	52
1666.54	54
1668.6	50
1670.67	56
1672.73	56
1674.79	50
1676.85	52
1678.91	56
1680.97	54
1683.03	48
1685.08	40
1687.14	50
1689.2	50
1691.25	50
1693.31	50
1695.36	48
1697.42	42
1699.47	40
1701.52	50
1703.57	52
1705.63	46
1707.68	48
1709.72	44
1711.77	48
1713.82	44
1715.87	40
1717.92	44
1719.97	50
1722.01	48
1724.06	40
1726.1	40
1728.15	42
1730.19	50
1732.23	42
1734.27	50
1736.32	42
1738.36	42
1740.4	36
1742.44	40
1744.48	48
1746.51	46
1748.55	36
1750.59	42
1752.63	40
1754.66	34
1756.7	42
1758.73	44
1760.77	46
1762.8	36
1764.83	46
1766.86	48
1768.9	38
1770.93	50
1772.96	46
1774.99	50
1777.02	40
1779.04	40
1781.07	48
1783.1	48
1785.13	46
1787.15	40
1789.18	48
1791.2	46
1793.23	44
1795.25	42
1797.27	42
1799.29	48
1801.31	44
1803.34	44
1805.36	40
1807.38	42
1809.39	46
1811.41	38
1813.43	44
1815.45	46
1817.46	44
1819.48	42
1821.49	44
1823.51	42
1825.52	38
1827.54	38
1829.55	34
1831.56	44
1833.57	44
1835.58	48
1837.59	44
1839.6	48
1841.61	42
1843.62	42
1845.63	44
1847.64	42
1849.64	46
1851.65	40
1853.65	36
1855.66	38
1857.66	40
1859.66	44
1861.67	50
1863.67	46
1865.67	42
1867.67	44
1869.67	42
1871.67	40
1873.67	40
1875.67	40
1877.67	42
1879.66	44
1881.66	46
1883.66	40
1885.65	38
1887.65	34
1889.64	40
1891.63	36
1893.63	48
1895.62	50
1897.61	40
1899.6	38
1901.59	40
1903.58	40
1905.57	44
1907.56	44
1909.55	40
1911.53	42
1913.52	40
1915.51	44
1917.49	38
1919.48	40
1921.46	42
1923.45	44
1925.43	42
1927.41	46
1929.39	48
1931.37	42
1933.36	42
1935.33	40
1937.31	40
1939.29	44
1941.27	42
1943.25	42
1945.23	44
1947.2	38
1949.18	34
1951.15	44
1953.13	45
1955.1	42
1957.08	40
1959.05	34
1961.02	42
1962.99	42
1964.96	42
1966.93	34
1968.9	36
1970.87	42
1972.84	40
1974.81	40
1976.77	44
1978.74	42
1980.71	36
1982.67	42
1984.64	48
1986.6	44
1988.57	44
1990.53	46
1992.49	40
1994.45	44
1996.41	42
1998.37	36
1999.35	40