File: muestras/LIG/fproof_09.txt
#Acq. time (s)=	10
#Accumulations=	2
#Range (cm-¹)=	100...2000
#Windows=	2
#Autofocus=	Off
#AutoExposure=	Off
#Spike filter=	Multiple accum.
#Delay time (s)=	0
#Binning=	1
#Readout mode=	Signal
#DeNoise=	Off
#ICS correction=	Off
#Dark correction=	Off
#Inst. Process=	Off
#Instrument=	LabRAM HR Evol
#Detector=	Syncerity OE
#Objective=	x100_VIS_LWD
#Grating=	600 (500nm)
#ND Filter=	25%
#Laser=	633nm_Edge
#Hole=	100.021
#Range=	Visible
#Project=	LIG
#Sample=	proof
#Site=
#Title=	fproof
#Remark=
#Date=	07.03.2023 12:44
#Acquired=	07.03.2023 12:44:00
101.054	54
103.621	56
106.187	50
108.753	50
111.317	50
113.881	48
116.443	56
119.005	54
121.566	46
124.126	50
126.685	54
129.243	50
131.801	40
134.357	46
136.911	46
139.466	46
142.021	46
144.574	52
147.126	52
149.676	42
152.227	40
154.777	46
157.325	48
159.873	50
162.419	48
164.966	42
167.51	44
170.055	44
172.598	48
175.141	44
177.682	56
180.222	48
182.763	48
185.302	48
187.839	48
190.378	48
192.914	44
195.449	48
197.983	52
200.517	38
203.05	56
205.582	50
208.113	50
210.643	44
213.173	42
215.701	40
218.229	48
220.756	54
223.282	50
225.808	52
228.331	46
230.855	46
233.378	50
235.9	52
238.419	46
240.94	52
243.46	44
245.977	44
248.495	40
251.011	46
253.527	44
256.041	50
258.556	46
261.068	42
263.58	46
266.092	46
268.603	56
271.112	46
273.622	48
276.129	50
278.636	42
281.142	42
283.647	48
286.152	50
288.655	44
291.158	50
293.66	52
296.161	44
298.661	40
301.161	40
303.66	56
306.158	46
308.655	52
311.151	50
313.645	44
316.14	48
318.634	48
321.125	44
323.618	48
326.109	50
328.598	52
331.088	50
333.576	46
336.064	46
338.55	46
341.037	48
343.521	48
346.005	46
348.489	40
350.971	50
353.453	44
355.935	58
358.414	46
360.893	50
363.371	36
365.848	54
368.325	42
370.801	50
373.275	46
375.75	48
378.223	42
380.695	46
383.167	48
385.638	46
388.108	50
390.577	46
393.044	44
395.512	50
397.979	52
400.445	48
402.909	40
405.374	48
407.836	52
410.299	48
412.762	46
415.221	48
417.681	50
420.141	34
422.598	50
425.057	46
427.513	46
429.968	46
432.424	46
434.878	46
437.33	50
439.783	50
442.234	44
444.685	44
447.136	48
449.585	50
452.033	48
454.48	44
456.927	48
459.372	50
461.817	48
464.261	52
466.705	50
469.147	46
471.589	42
474.029	52
476.47	46
478.909	50
481.347	52
483.785	50
486.221	52
488.657	48
491.093	50
493.527	54
495.96	44
498.393	46
500.824	44
503.256	46
505.686	42
508.115	44
510.543	48
512.972	40
515.399	48
517.825	40
520.25	44
522.674	46
525.097	50
527.52	54
529.942	40
532.364	44
534.784	42
537.204	46
539.623	46
542.041	36
544.458	46
546.874	48
549.289	42
551.705	34
554.118	50
556.531	50
558.944	44
561.355	44
563.766	44
566.175	48
568.585	50
570.992	44
573.401	46
575.807	44
578.212	38
580.618	52
583.022	44
585.425	46
587.827	50
590.229	46
592.631	48
595.031	46
597.43	46
599.829	46
602.226	48
604.623	44
607.02	52
609.415	50
611.808	50
614.202	50
616.596	48
618.988	48
621.38	44
623.769	44
626.159	48
628.549	48
630.936	50
633.324	56
635.71	46
638.096	44
640.481	46
642.866	44
645.248	50
647.632	54
650.013	46
652.394	44
654.773	46
657.154	46
659.532	54
661.91	46
664.286	48
666.663	50
669.038	48
671.412	46
673.786	52
676.159	36
678.532	52
680.903	46
683.274	50
685.644	36
688.014	50
690.382	54
692.749	50
695.116	48
697.482	48
699.846	48
702.211	42
704.574	46
706.938	48
709.299	48
711.661	54
714.021	44
716.381	42
718.739	42
721.097	38
723.455	54
725.811	44
728.167	52
730.521	48
732.877	48
735.23	48
737.582	48
739.934	50
742.285	44
744.635	54
746.985	50
749.334	42
751.682	52
754.028	48
756.374	48
758.72	48
761.065	42
763.408	46
765.752	50
768.095	44
770.436	44
772.777	44
775.116	44
777.456	36
779.794	50
782.133	50
784.469	38
786.806	44
789.141	44
791.476	48
793.809	46
796.143	38
798.476	50
800.807	42
803.138	48
805.468	38
807.797	48
810.125	44
812.453	48
814.78	48
817.106	46
819.432	50
821.757	46
824.081	52
826.403	52
828.726	46
831.048	50
833.368	48
835.688	46
838.008	50
840.326	48
842.644	46
844.96	52
847.277	52
849.592	48
851.906	44
854.221	40
856.534	48
858.846	52
861.159	46
863.469	54
865.779	42
868.088	46
870.396	44
872.704	50
875.011	40
877.318	46
879.623	56
881.928	48
884.232	44
886.536	44
888.838	52
891.139	52
893.44	48
895.741	52
898.039	52
900.339	50
902.637	50
904.933	54
907.231	44
909.526	50
911.821	50
914.115	50
916.408	52
918.701	44
920.993	38
923.283	54
925.575	46
927.864	50
930.153	50
932.441	48
934.728	56
937.014	48
939.3	52
941.585	54
943.87	40
946.154	50
948.437	52
950.719	46
953	54
955.28	42
957.56	42
959.84	42
962.117	54
964.395	42
966.673	46
968.948	42
971.224	52
973.498	52
975.773	52
978.045	44
980.317	52
982.59	42
984.86	56
987.13	48
989.399	46
991.669	44
993.937	54
996.204	48
998.47	48
1000.74	42
1003	50
1005.26	48
1007.53	46
1009.79	52
1012.05	50
1014.31	48
1016.57	52
1018.83	48
1021.09	40
1023.35	56
1025.61	52
1027.87	48
1030.12	56
1032.38	46
1034.63	56
1036.88	48
1039.14	48
1041.39	42
1043.64	54
1045.89	54
1048.14	42
1050.39	50
1052.64	52
1054.89	54
1057.14	58
1059.38	46
1061.63	56
1063.87	60
1066.12	48
1068.36	56
1070.6	48
1072.85	60
1075.09	54
1077.33	58
1079.57	46
1081.81	52
1084.05	58
1086.28	62
1088.52	58
1090.76	62
1092.99	56
1095.23	50
1097.46	58
1099.69	58
1101.93	50
1104.16	64
1106.39	60
1108.62	58
1110.85	60
1113.08	58
1115.31	54
1117.53	54
1119.76	66
1121.99	58
1124.21	60
1126.44	52
1128.66	54
1130.88	64
1133.11	58
1135.33	52
1137.55	60
1139.77	60
1141.99	60
1144.21	66
1146.43	62
1148.64	68
1150.86	70
1153.08	60
1155.29	64
1157.51	68
1159.72	72
1161.93	70
1164.14	68
1166.36	76
1168.57	78
1170.78	68
1172.99	50
1175.2	66
1177.4	70
1179.61	68
1181.82	66
1184.02	70
1186.23	58
1188.43	72
1190.64	70
1192.84	66
1195.04	60
1197.24	56
1199.45	72.01
1201.64	70.0945
1203.84	66.3232
1206.04	73.7689
1208.24	72.3118
1210.44	74.5994
1212.64	74.9679
1214.83	76.1958
1217.03	78.3799
1219.22	76.1458
1221.41	65.4538
1223.61	75.55
1225.8	74.549
1227.99	73.7241
1230.18	81.418
1232.37	76.7041
1234.56	80
1236.75	76.477
1238.94	81.4944
1241.13	89.7551
1243.31	80.5491
1245.5	82.6051
1247.68	79.2392
1249.87	93.676
1252.05	91.7755
1254.24	93.6157
1256.42	90.2883
1258.6	96.8743
1260.78	92.26
1262.96	99.6003
1265.14	101.576
1267.32	113.294
1269.5	112.887
1271.67	111.053
1273.85	114.06
1276.03	120.46
1278.2	125.827
1280.38	125.328
1282.55	128.787
1284.72	132.038
1286.9	148.114
1289.07	148.143
1291.24	148.209
1293.41	159.3
1295.58	169.882
1297.75	182.192
1299.92	184.381
1302.09	197.959
1304.25	192.281
1306.42	212.568
1308.44	218
1310.61	236
1312.79	240
1314.97	254
1317.14	230
1319.31	266
1321.48	270
1323.66	284
1325.83	266
1328	284
1330.17	282
1332.34	264
1334.5	274
1336.67	268
1338.84	252
1341	260
1343.17	256
1345.33	246
1347.5	236
1349.66	234
1351.83	218
1353.99	194
1356.15	190
1358.31	182
1360.47	174
1362.63	186
1364.79	180
1366.94	148
1369.1	166
1371.26	146
1373.41	138
1375.57	134
1377.72	130
1379.88	114
1382.03	124
1384.18	116
1386.33	116
1388.48	110
1390.64	112
1392.79	112
1394.93	104
1397.08	100
1399.23	100
1401.38	94
1403.52	98
1405.67	92
1407.81	94
1409.96	92
1412.1	88
1414.24	86
1416.39	90
1418.53	86
1420.67	84
1422.81	80
1424.95	86
1427.09	80
1429.23	72
1431.36	84
1433.5	86
1435.64	82
1437.77	82
1439.91	86
1442.04	76
1444.17	70
1446.31	68
1448.44	82
1450.57	76
1452.7	74
1454.83	76
1456.96	80
1459.09	86
1461.22	78
1463.34	80
1465.47	88
1467.6	78
1469.72	72
1471.85	72
1473.97	76
1476.09	70
1478.22	70
1480.34	76
1482.46	88
1484.58	78
1486.7	66
1488.82	82
1490.94	76
1493.06	78
1495.17	84
1497.29	78
1499.41	82
1501.52	82
1503.64	74
1505.75	74
1507.86	74
1509.98	80
1512.09	84
1514.2	76
1516.31	84
1518.42	82
1520.53	78
1522.64	84
1524.74	82
1526.85	88
1528.96	78
1531.07	86
1533.17	90
1535.27	88
1537.38	94
1539.48	90
1541.58	78
1543.69	98
1545.79	102
1547.89	96
1549.99	100
1552.09	118
1554.19	112
1556.28	128
1558.38	112
1560.48	130
1562.57	124
1564.67	136
1566.76	152
1568.86	148
1570.95	146
1573.05	160
1575.14	164
1577.23	172
1579.32	168
1581.41	186
1583.5	180
1585.59	182
1587.68	190
1589.76	180
1591.85	190
1593.94	188
1596.02	188
1598.11	198
1600.19	186
1602.27	174
1604.36	190
1606.44	184
1608.52	190
1610.6	190
1612.68	176
1614.76	166
1616.84	166
1618.92	166
1621	158
1623.07	156
1625.15	140
1627.23	132
1629.3	138
1631.38	140
1633.45	126
1635.52	112
1637.59	94
1639.67	108
1641.74	90
1643.81	98
1645.88	86
1647.95	78
1650.02	76
1652.08	76
1654.15	64
1656.22	66
1658.28	60
1660.35	64
1662.41	62
1664.48	56
1666.54	64
1668.6	68
1670.67	56
1672.73	58
1674.79	54
1676.85	60
1678.91	48
1680.97	62
1683.03	56
1685.08	52
1687.14	52
1689.2	46
1691.25	54
1693.31	54
1695.36	48
1697.42	48
1699.47	50
1701.52	54
1703.57	46
1705.63	54
1707.68	48
1709.72	50
1711.77	52
1713.82	42
1715.87	50
1717.92	46
1719.97	46
1722.01	50
1724.06	50
1726.1	48
1728.15	46
1730.19	44
1732.23	54
1734.27	54
1736.32	38
1738.36	42
1740.4	50
1742.44	44
1744.48	52
1746.51	52
1748.55	48
1750.59	48
1752.63	46
1754.66	48
1756.7	38
1758.73	52
1760.77	48
1762.8	50
1764.83	42
1766.86	52
1768.9	42
1770.93	50
1772.96	48
1774.99	48
1777.02	52
1779.04	48
1781.07	50
1783.1	46
1785.13	44
1787.15	52
1789.18	44
1791.2	44
1793.23	48
1795.25	48
1797.27	44
1799.29	48
1801.31	56
1803.34	48
1805.36	46
1807.38	46
1809.39	46
1811.41	52
1813.43	50
1815.45	48
1817.46	48
1819.48	44
1821.49	50
1823.51	48
1825.52	44
1827.54	50
1829.55	48
1831.56	42
1833.57	52
1835.58	40
1837.59	44
1839.6	44
1841.61	40
1843.62	48
1845.63	50
1847.64	44
1849.64	46
1851.65	50
1853.65	40
1855.66	40
1857.66	44
1859.66	50
1861.67	36
1863.67	44
1865.67	48
1867.67	40
1869.67	40
1871.67	48
1873.67	44
1875.67	44
1877.67	44
1879.66	48
1881.66	38
1883.66	48
1885.65	48
1887.65	48
1889.64	46
1891.63	46
1893.63	42
1895.62	38
1897.61	50
1899.6	44
1901.59	48
1903.58	42
1905.57	46
1907.56	34
1909.55	42
1911.53	42
1913.52	44
1915.51	48
1917.49	40
1919.48	46
1921.46	38
1923.45	48
1925.43	44
1927.41	36
1929.39	34
1931.37	46
1933.36	52
1935.33	42
1937.31	44
1939.29	42
1941.27	40
1943.25	46
1945.23	48
1947.2	40
1949.18	44
1951.15	44
1953.13	47
1955.1	30
1957.08	44
1959.05	44
1961.02	50
1962.99	38
1964.96	44
1966.93	46
1968.9	36
1970.87	36
1972.84	48
1974.81	46
1976.77	42
1978.74	46
1980.71	46
1982.67	44
1984.64	40
1986.6	42
1988.57	48
1990.53	46
1992.49	42
1994.45	38
1996.41	42
1998.37	52
1999.35	30