File: muestras/LIG/fproof_25.txt
#Acq. time (s)=	10
#Accumulations=	2
#Range (cm-¹)=	100...2000
#Windows=	2
#Autofocus=	Off
#AutoExposure=	Off
#Spike filter=	Multiple accum.
#Delay time (s)=	0
#Binning=	1
#Readout mode=	Signal
#DeNoise=	Off
#ICS correction=	Off
#Dark correction=	Off
#Inst. Process=	Off
#Instrument=	LabRAM HR Evol
#Detector=	Syncerity OE
#Objective=	x100_VIS_LWD
#Grating=	600 (500nm)
#ND Filter=	25%
#Laser=	633nm_Edge
#Hole=	100.021
#Range=	Visible
#Project=	LIG
#Sample=	proof
#Site=
#Title=	fproof
#Remark=
#Date=	07.03.2023 13:31
#Acquired=	07.03.2023 13:31:57
101.054	64
103.621	62
106.187	58
108.753	66
111.317	64
113.881	60
116.443	62
119.005	60
121.566	52
124.126	62
126.685	54
129.243	54
131.801	50
134.357	54
136.911	58
139.466	48
142.021	50
144.574	48
147.126	48
149.676	52
152.227	52
154.777	48
157.325	48
159.873	58
162.419	54
164.966	52
167.51	48
170.055	48
172.598	54
175.141	52
177.682	54
180.222	50
182.763	48
185.302	50
187.839	44
190.378	50
192.914	44
195.449	48
197.983	54
200.517	58
203.05	56
205.582	58
208.113	58
210.643	50
213.173	60
215.701	56
218.229	74
220.756	54
223.282	58
225.808	60
228.331	58
230.855	58
233.378	60
235.9	54
238.419	52
240.94	50
243.46	56
245.977	52
248.495	46
251.011	54
253.527	48
256.041	42
258.556	46
261.068	52
263.58	52
266.092	48
268.603	58
271.112	48
273.622	56
276.129	54
278.636	46
281.142	52
283.647	42
286.152	50
288.655	50
291.158	58
293.66	48
296.161	46
298.661	44
301.161	46
303.66	54
306.158	46
308.655	48
311.151	44
313.645	50
316.14	46
318.634	50
321.125	46
323.618	48
326.109	46
328.598	52
331.088	44
333.576	48
336.064	46
338.55	48
341.037	52
343.521	40
346.005	50
348.489	48
350.971	54
353.453	44
355.935	50
358.414	50
360.893	52
363.371	46
365.848	48
368.325	50
370.801	52
373.275	50
375.75	48
378.223	42
380.695	50
383.167	40
385.638	42
388.108	48
390.577	36
393.044	48
395.512	48
397.979	50
400.445	48
402.909	46
405.374	54
407.836	44
410.299	40
412.762	54
415.221	48
417.681	40
420.141	46
422.598	46
425.057	46
427.513	42
429.968	46
432.424	46
434.878	40
437.33	40
439.783	46
442.234	40
444.685	48
447.136	56
449.585	44
452.033	48
454.48	46
456.927	46
459.372	48
461.817	46
464.261	54
466.705	48
469.147	50
471.589	48
474.029	46
476.47	46
478.909	50
481.347	48
483.785	48
486.221	46
488.657	44
491.093	44
493.527	54
495.96	36
498.393	48
500.824	48
503.256	50
505.686	40
508.115	54
510.543	50
512.972	48
515.399	46
517.825	44
520.25	42
522.674	46
525.097	46
527.52	46
529.942	42
532.364	48
534.784	44
537.204	48
539.623	42
542.041	40
544.458	44
546.874	46
549.289	52
551.705	40
554.118	50
556.531	38
558.944	46
561.355	46
563.766	40
566.175	46
568.585	48
570.992	46
573.401	40
575.807	46
578.212	38
580.618	50
583.022	44
585.425	46
587.827	42
590.229	48
592.631	48
595.031	52
597.43	46
599.829	54
602.226	38
604.623	48
607.02	44
609.415	46
611.808	48
614.202	44
616.596	44
618.988	46
621.38	48
623.769	50
626.159	50
628.549	50
630.936	40
633.324	42
635.71	44
638.096	48
640.481	48
642.866	46
645.248	38
647.632	44
650.013	46
652.394	46
654.773	48
657.154	42
659.532	44
661.91	52
664.286	44
666.663	46
669.038	46
671.412	42
673.786	40
676.159	50
678.532	40
680.903	44
683.274	40
685.644	50
688.014	44
690.382	40
692.749	44
695.116	42
697.482	46
699.846	38
702.211	44
704.574	46
706.938	46
709.299	46
711.661	40
714.021	50
716.381	38
718.739	44
721.097	46
723.455	48
725.811	48
728.167	54
730.521	40
732.877	46
735.23	42
737.582	54
739.934	42
742.285	42
744.635	48
746.985	38
749.334	44
751.682	44
754.028	42
756.374	48
758.72	38
761.065	44
763.408	44
765.752	34
768.095	40
770.436	46
772.777	46
775.116	46
777.456	48
779.794	54
782.133	48
784.469	50
786.806	40
789.141	50
791.476	50
793.809	46
796.143	40
798.476	48
800.807	46
803.138	50
805.468	42
807.797	48
810.125	46
812.453	42
814.78	48
817.106	44
819.432	46
821.757	52
824.081	48
826.403	50
828.726	44
831.048	46
833.368	54
835.688	44
838.008	42
840.326	46
842.644	50
844.96	46
847.277	42
849.592	48
851.906	50
854.221	40
856.534	48
858.846	44
861.159	38
863.469	46
865.779	40
868.088	46
870.396	48
872.704	42
875.011	50
877.318	54
879.623	48
881.928	52
884.232	48
886.536	38
888.838	42
891.139	50
893.44	50
895.741	50
898.039	44
900.339	42
902.637	44
904.933	46
907.231	46
909.526	52
911.821	44
914.115	44
916.408	48
918.701	50
920.993	46
923.283	42
925.575	52
927.864	56
930.153	54
932.441	40
934.728	62
937.014	50
939.3	50
941.585	46
943.87	48
946.154	50
948.437	50
950.719	40
953	50
955.28	38
957.56	52
959.84	54
962.117	42
964.395	44
966.673	42
968.948	42
971.224	48
973.498	52
975.773	46
978.045	54
980.317	46
982.59	48
984.86	44
987.13	50
989.399	48
991.669	50
993.937	54
996.204	54
998.47	46
1000.74	50
1003	44
1005.26	50
1007.53	44
1009.79	46
1012.05	52
1014.31	58
1016.57	44
1018.83	48
1021.09	46
1023.35	44
1025.61	52
1027.87	54
1030.12	52
1032.38	56
1034.63	52
1036.88	54
1039.14	56
1041.39	52
1043.64	56
1045.89	58
1048.14	58
1050.39	52
1052.64	56
1054.89	60
1057.14	54
1059.38	56
1061.63	46
1063.87	56
1066.12	62
1068.36	56
1070.6	58
1072.85	62
1075.09	60
1077.33	58
1079.57	56
1081.81	58
1084.05	58
1086.28	56
1088.52	56
1090.76	58
1092.99	58
1095.23	66
1097.46	64
1099.69	58
1101.93	50
1104.16	58
1106.39	60
1108.62	72
1110.85	64
1113.08	70
1115.31	68
1117.53	66
1119.76	70
1121.99	62
1124.21	70
1126.44	66
1128.66	76
1130.88	70
1133.11	76
1135.33	78
1137.55	76
1139.77	72
1141.99	76
1144.21	80
1146.43	78
1148.64	74
1150.86	80
1153.08	74
1155.29	78
1157.51	70
1159.72	80
1161.93	84
1164.14	76
1166.36	78
1168.57	74
1170.78	70
1172.99	84
1175.2	78
1177.4	80
1179.61	76
1181.82	82
1184.02	80
1186.23	74
1188.43	82
1190.64	82
1192.84	74
1195.04	88
1197.24	78
1199.45	84
1201.64	78.3806
1203.84	82.2158
1206.04	84.5249
1208.24	84.6374
1210.44	82.689
1212.64	82.2179
1214.83	81.9321
1217.03	87.7701
1219.22	82.0481
1221.41	92.6254
1223.61	92.5905
1225.8	93.7518
1227.99	95.4669
1230.18	101.998
1232.37	89.0896
1234.56	103.3
1236.75	100.675
1238.94	101.448
1241.13	104.929
1243.31	100.329
1245.5	112.001
1247.68	108.204
1249.87	110.135
1252.05	117.749
1254.24	132.444
1256.42	127.812
1258.6	129.879
1260.78	133.926
1262.96	134.678
1265.14	141.689
1267.32	148.367
1269.5	158.225
1271.67	171.439
1273.85	168.631
1276.03	169.624
1278.2	182.239
1280.38	193.601
1282.55	188.528
1284.72	205.659
1286.9	223.25
1289.07	237.258
1291.24	246.274
1293.41	269.168
1295.58	287.472
1297.75	307.43
1299.92	333.759
1302.09	348.041
1304.25	368.164
1306.42	391.773
1308.44	440
1310.61	460
1312.79	478
1314.97	522
1317.14	554
1319.31	588
1321.48	574
1323.66	608
1325.83	616
1328	596
1330.17	594
1332.34	576
1334.5	558
1336.67	536
1338.84	528
1341	474
1343.17	470
1345.33	450
1347.5	406
1349.66	370
1351.83	358
1353.99	314
1356.15	314
1358.31	282
1360.47	280
1362.63	250
1364.79	240
1366.94	224
1369.1	204
1371.26	216
1373.41	188
1375.57	176
1377.72	174
1379.88	160
1382.03	154
1384.18	158
1386.33	138
1388.48	148
1390.64	138
1392.79	130
1394.93	126
1397.08	124
1399.23	118
1401.38	100
1403.52	110
1405.67	112
1407.81	112
1409.96	108
1412.1	102
1414.24	94
1416.39	116
1418.53	98
1420.67	98
1422.81	94
1424.95	100
1427.09	98
1429.23	92
1431.36	86
1433.5	90
1435.64	92
1437.77	94
1439.91	76
1442.04	96
1444.17	86
1446.31	82
1448.44	82
1450.57	88
1452.7	84
1454.83	90
1456.96	86
1459.09	82
1461.22	84
1463.34	92
1465.47	84
1467.6	96
1469.72	88
1471.85	88
1473.97	74
1476.09	90
1478.22	86
1480.34	94
1482.46	94
1484.58	86
1486.7	88
1488.82	86
1490.94	90
1493.06	94
1495.17	90
1497.29	92
1499.41	98
1501.52	86
1503.64	86
1505.75	90
1507.86	94
1509.98	80
1512.09	94
1514.2	88
1516.31	94
1518.42	100
1520.53	94
1522.64	92
1524.74	96
1526.85	102
1528.96	104
1531.07	106
1533.17	116
1535.27	110
1537.38	112
1539.48	108
1541.58	126
1543.69	116
1545.79	120
1547.89	126
1549.99	138
1552.09	142
1554.19	158
1556.28	158
1558.38	166
1560.48	170
1562.57	198
1564.67	208
1566.76	212
1568.86	220
1570.95	236
1573.05	224
1575.14	244
1577.23	260
1579.32	274
1581.41	290
1583.5	294
1585.59	318
1587.68	304
1589.76	312
1591.85	294
1593.94	284
1596.02	286
1598.11	278
1600.19	266
1602.27	266
1604.36	284
1606.44	268
1608.52	254
1610.6	280
1612.68	290
1614.76	266
1616.84	250
1618.92	280
1621	260
1623.07	244
1625.15	206
1627.23	200
1629.3	186
1631.38	162
1633.45	132
1635.52	132
1637.59	114
1639.67	120
1641.74	108
1643.81	102
1645.88	94
1647.95	90
1650.02	88
1652.08	86
1654.15	74
1656.22	76
1658.28	80
1660.35	70
1662.41	70
1664.48	64
1666.54	66
1668.6	66
1670.67	64
1672.73	62
1674.79	56
1676.85	64
1678.91	52
1680.97	62
1683.03	58
1685.08	60
1687.14	60
1689.2	66
1691.25	50
1693.31	56
1695.36	56
1697.42	50
1699.47	58
1701.52	52
1703.57	44
1705.63	48
1707.68	54
1709.72	48
1711.77	54
1713.82	46
1715.87	50
1717.92	50
1719.97	48
1722.01	56
1724.06	52
1726.1	46
1728.15	46
1730.19	54
1732.23	50
1734.27	52
1736.32	50
1738.36	50
1740.4	52
1742.44	48
1744.48	52
1746.51	44
1748.55	54
1750.59	48
1752.63	48
1754.66	46
1756.7	44
1758.73	48
1760.77	42
1762.8	60
1764.83	46
1766.86	42
1768.9	54
1770.93	44
1772.96	52
1774.99	46
1777.02	50
1779.04	50
1781.07	50
1783.1	42
1785.13	56
1787.15	50
1789.18	46
1791.2	42
1793.23	48
1795.25	46
1797.27	50
1799.29	46
1801.31	50
1803.34	56
1805.36	52
1807.38	46
1809.39	52
1811.41	50
1813.43	42
1815.45	50
1817.46	46
1819.48	48
1821.49	36
1823.51	46
1825.52	46
1827.54	48
1829.55	42
1831.56	46
1833.57	42
1835.58	40
1837.59	40
1839.6	54
1841.61	48
1843.62	44
1845.63	44
1847.64	52
1849.64	46
1851.65	50
1853.65	44
1855.66	42
1857.66	46
1859.66	44
1861.67	42
1863.67	46
1865.67	42
1867.67	42
1869.67	48
1871.67	50
1873.67	40
1875.67	48
1877.67	42
1879.66	44
1881.66	42
1883.66	38
1885.65	40
1887.65	38
1889.64	46
1891.63	50
1893.63	44
1895.62	44
1897.61	38
1899.6	44
1901.59	44
1903.58	42
1905.57	48
1907.56	36
1909.55	50
1911.53	44
1913.52	42
1915.51	42
1917.49	44
1919.48	42
1921.46	42
1923.45	44
1925.43	48
1927.41	46
1929.39	42
1931.37	48
1933.36	44
1935.33	52
1937.31	44
1939.29	44
1941.27	46
1943.25	46
1945.23	42
1947.2	46
1949.18	42
1951.15	42
1953.13	42
1955.1	42
1957.08	44
1959.05	46
1961.02	44
1962.99	36
1964.96	42
1966.93	38
1968.9	42
1970.87	44
1972.84	38
1974.81	50
1976.77	46
1978.74	44
1980.71	50
1982.67	52
1984.64	36
1986.6	42
1988.57	40
1990.53	36
1992.49	44
1994.45	42
1996.41	46
1998.37	44
1999.35	38