File: muestras/LIG/fproof_21.txt
#Acq. time (s)=	10
#Accumulations=	2
#Range (cm-¹)=	100...2000
#Windows=	2
#Autofocus=	Off
#AutoExposure=	Off
#Spike filter=	Multiple accum.
#Delay time (s)=	0
#Binning=	1
#Readout mode=	Signal
#DeNoise=	Off
#ICS correction=	Off
#Dark correction=	Off
#Inst. Process=	Off
#Instrument=	LabRAM HR Evol
#Detector=	Syncerity OE
#Objective=	x100_VIS_LWD
#Grating=	600 (500nm)
#ND Filter=	25%
#Laser=	633nm_Edge
#Hole=	100.021
#Range=	Visible
#Project=	LIG
#Sample=	proof
#Site=
#Title=	fproof
#Remark=
#Date=	07.03.2023 13:21
#Acquired=	07.03.2023 13:21:37
101.054	54
103.621	54
106.187	60
108.753	58
111.317	50
113.881	62
116.443	52
119.005	58
121.566	56
124.126	54
126.685	50
129.243	52
131.801	46
134.357	56
136.911	48
139.466	50
142.021	46
144.574	44
147.126	48
149.676	46
152.227	42
154.777	40
157.325	40
159.873	50
162.419	44
164.966	44
167.51	42
170.055	42
172.598	50
175.141	50
177.682	48
180.222	46
182.763	42
185.302	48
187.839	54
190.378	46
192.914	46
195.449	48
197.983	54
200.517	52
203.05	42
205.582	48
208.113	46
210.643	54
213.173	56
215.701	52
218.229	50
220.756	50
223.282	48
225.808	44
228.331	54
230.855	54
233.378	50
235.9	44
238.419	46
240.94	54
243.46	48
245.977	50
248.495	42
251.011	52
253.527	40
256.041	42
258.556	42
261.068	40
263.58	48
266.092	46
268.603	50
271.112	46
273.622	50
276.129	42
278.636	42
281.142	50
283.647	42
286.152	50
288.655	40
291.158	50
293.66	48
296.161	46
298.661	46
301.161	40
303.66	50
306.158	44
308.655	42
311.151	44
313.645	48
316.14	42
318.634	40
321.125	48
323.618	46
326.109	42
328.598	46
331.088	48
333.576	46
336.064	48
338.55	52
341.037	42
343.521	46
346.005	42
348.489	48
350.971	46
353.453	50
355.935	48
358.414	42
360.893	44
363.371	46
365.848	38
368.325	38
370.801	48
373.275	48
375.75	46
378.223	44
380.695	46
383.167	52
385.638	46
388.108	46
390.577	42
393.044	46
395.512	42
397.979	48
400.445	44
402.909	48
405.374	36
407.836	44
410.299	44
412.762	50
415.221	36
417.681	48
420.141	46
422.598	50
425.057	38
427.513	48
429.968	44
432.424	50
434.878	40
437.33	46
439.783	42
442.234	38
444.685	46
447.136	44
449.585	44
452.033	46
454.48	40
456.927	46
459.372	42
461.817	44
464.261	44
466.705	40
469.147	40
471.589	38
474.029	54
476.47	42
478.909	46
481.347	44
483.785	42
486.221	42
488.657	42
491.093	40
493.527	46
495.96	36
498.393	42
500.824	38
503.256	44
505.686	40
508.115	38
510.543	38
512.972	40
515.399	38
517.825	38
520.25	40
522.674	50
525.097	36
527.52	44
529.942	42
532.364	40
534.784	48
537.204	44
539.623	38
542.041	36
544.458	38
546.874	38
549.289	44
551.705	38
554.118	38
556.531	44
558.944	46
561.355	46
563.766	42
566.175	42
568.585	38
570.992	34
573.401	42
575.807	44
578.212	42
580.618	50
583.022	34
585.425	50
587.827	46
590.229	42
592.631	46
595.031	46
597.43	48
599.829	44
602.226	46
604.623	44
607.02	46
609.415	40
611.808	40
614.202	46
616.596	46
618.988	50
621.38	38
623.769	34
626.159	40
628.549	44
630.936	52
633.324	36
635.71	36
638.096	42
640.481	38
642.866	42
645.248	46
647.632	32
650.013	46
652.394	46
654.773	42
657.154	48
659.532	48
661.91	44
664.286	44
666.663	42
669.038	42
671.412	40
673.786	48
676.159	42
678.532	48
680.903	48
683.274	40
685.644	46
688.014	44
690.382	42
692.749	50
695.116	44
697.482	40
699.846	30
702.211	40
704.574	50
706.938	42
709.299	42
711.661	34
714.021	40
716.381	42
718.739	38
721.097	42
723.455	34
725.811	40
728.167	42
730.521	48
732.877	40
735.23	46
737.582	36
739.934	48
742.285	50
744.635	42
746.985	48
749.334	50
751.682	48
754.028	42
756.374	44
758.72	44
761.065	46
763.408	46
765.752	48
768.095	46
770.436	44
772.777	42
775.116	42
777.456	50
779.794	42
782.133	42
784.469	44
786.806	44
789.141	42
791.476	38
793.809	42
796.143	50
798.476	44
800.807	44
803.138	44
805.468	38
807.797	46
810.125	40
812.453	44
814.78	52
817.106	50
819.432	44
821.757	44
824.081	44
826.403	48
828.726	50
831.048	46
833.368	42
835.688	34
838.008	50
840.326	38
842.644	40
844.96	42
847.277	42
849.592	44
851.906	50
854.221	50
856.534	52
858.846	40
861.159	48
863.469	50
865.779	44
868.088	52
870.396	46
872.704	50
875.011	50
877.318	46
879.623	38
881.928	36
884.232	46
886.536	40
888.838	54
891.139	38
893.44	52
895.741	46
898.039	42
900.339	48
902.637	46
904.933	46
907.231	48
909.526	44
911.821	46
914.115	48
916.408	36
918.701	46
920.993	46
923.283	44
925.575	46
927.864	42
930.153	50
932.441	46
934.728	48
937.014	48
939.3	40
941.585	44
943.87	46
946.154	48
948.437	44
950.719	46
953	46
955.28	50
957.56	48
959.84	42
962.117	48
964.395	54
966.673	42
968.948	42
971.224	50
973.498	54
975.773	42
978.045	46
980.317	50
982.59	54
984.86	42
987.13	40
989.399	48
991.669	50
993.937	48
996.204	64
998.47	44
1000.74	48
1003	46
1005.26	42
1007.53	52
1009.79	50
1012.05	46
1014.31	50
1016.57	46
1018.83	50
1021.09	48
1023.35	42
1025.61	52
1027.87	48
1030.12	50
1032.38	48
1034.63	38
1036.88	48
1039.14	50
1041.39	54
1043.64	56
1045.89	54
1048.14	60
1050.39	52
1052.64	44
1054.89	46
1057.14	48
1059.38	48
1061.63	46
1063.87	50
1066.12	56
1068.36	52
1070.6	54
1072.85	50
1075.09	46
1077.33	60
1079.57	48
1081.81	56
1084.05	48
1086.28	52
1088.52	54
1090.76	46
1092.99	58
1095.23	58
1097.46	60
1099.69	56
1101.93	58
1104.16	50
1106.39	54
1108.62	58
1110.85	62
1113.08	62
1115.31	56
1117.53	72
1119.76	62
1121.99	54
1124.21	64
1126.44	60
1128.66	72
1130.88	66
1133.11	64
1135.33	60
1137.55	68
1139.77	66
1141.99	72
1144.21	68
1146.43	76
1148.64	72
1150.86	64
1153.08	62
1155.29	70
1157.51	68
1159.72	72
1161.93	62
1164.14	64
1166.36	68
1168.57	72
1170.78	62
1172.99	68
1175.2	74
1177.4	62
1179.61	62
1181.82	74
1184.02	64
1186.23	66
1188.43	64
1190.64	66
1192.84	62
1195.04	70
1197.24	76
1199.45	81.99
1201.64	74.1945
1203.84	75.9632
1206.04	78.154
1208.24	76.1418
1210.44	81.6697
1212.64	74.4679
1214.83	77.3521
1217.03	79.4601
1219.22	78.7139
1221.41	81.23
1223.61	80.7
1225.8	83.4973
1227.99	72.6562
1230.18	81.14
1232.37	91.4782
1234.56	80.4645
1236.75	81.7054
1238.94	92.54
1241.13	88.5549
1243.31	84.3109
1245.5	94.4936
1247.68	91.1356
1249.87	99.536
1252.05	105.528
1254.24	98.06
1256.42	106.618
1258.6	102.079
1260.78	112.318
1262.96	115.98
1265.14	110.434
1267.32	119.25
1269.5	124.485
1271.67	133.465
1273.85	133.48
1276.03	138.537
1278.2	155.754
1280.38	155.49
1282.55	168.473
1284.72	178.459
1286.9	184.072
1289.07	201.723
1291.24	212.229
1293.41	214.17
1295.58	235.026
1297.75	244.335
1299.92	259.198
1302.09	272.693
1304.25	295.27
1306.42	321.875
1308.44	342
1310.61	358
1312.79	396
1314.97	400
1317.14	426
1319.31	442
1321.48	448
1323.66	488
1325.83	456
1328	500
1330.17	468
1332.34	472
1334.5	492
1336.67	468
1338.84	460
1341	436
1343.17	410
1345.33	372
1347.5	368
1349.66	360
1351.83	324
1353.99	290
1356.15	278
1358.31	258
1360.47	248
1362.63	242
1364.79	222
1366.94	210
1369.1	202
1371.26	194
1373.41	182
1375.57	174
1377.72	172
1379.88	150
1382.03	150
1384.18	138
1386.33	142
1388.48	124
1390.64	132
1392.79	124
1394.93	122
1397.08	122
1399.23	112
1401.38	100
1403.52	106
1405.67	116
1407.81	102
1409.96	102
1412.1	92
1414.24	90
1416.39	96
1418.53	88
1420.67	92
1422.81	84
1424.95	94
1427.09	90
1429.23	88
1431.36	96
1433.5	88
1435.64	82
1437.77	82
1439.91	84
1442.04	88
1444.17	86
1446.31	74
1448.44	84
1450.57	80
1452.7	88
1454.83	78
1456.96	88
1459.09	88
1461.22	78
1463.34	80
1465.47	78
1467.6	78
1469.72	78
1471.85	72
1473.97	82
1476.09	88
1478.22	78
1480.34	80
1482.46	82
1484.58	78
1486.7	74
1488.82	82
1490.94	80
1493.06	74
1495.17	78
1497.29	78
1499.41	80
1501.52	80
1503.64	88
1505.75	92
1507.86	84
1509.98	82
1512.09	90
1514.2	86
1516.31	92
1518.42	84
1520.53	98
1522.64	90
1524.74	76
1526.85	98
1528.96	94
1531.07	96
1533.17	108
1535.27	98
1537.38	114
1539.48	114
1541.58	114
1543.69	120
1545.79	116
1547.89	134
1549.99	140
1552.09	126
1554.19	128
1556.28	170
1558.38	170
1560.48	182
1562.57	188
1564.67	200
1566.76	200
1568.86	212
1570.95	232
1573.05	224
1575.14	264
1577.23	242
1579.32	256
1581.41	266
1583.5	274
1585.59	282
1587.68	284
1589.76	284
1591.85	280
1593.94	282
1596.02	286
1598.11	274
1600.19	274
1602.27	274
1604.36	280
1606.44	248
1608.52	266
1610.6	254
1612.68	256
1614.76	244
1616.84	258
1618.92	260
1621	242
1623.07	236
1625.15	218
1627.23	206
1629.3	188
1631.38	174
1633.45	160
1635.52	154
1637.59	144
1639.67	110
1641.74	108
1643.81	112
1645.88	88
1647.95	94
1650.02	88
1652.08	84
1654.15	76
1656.22	76
1658.28	72
1660.35	64
1662.41	70
1664.48	70
1666.54	64
1668.6	58
1670.67	64
1672.73	54
1674.79	62
1676.85	56
1678.91	60
1680.97	50
1683.03	52
1685.08	50
1687.14	52
1689.2	60
1691.25	56
1693.31	58
1695.36	52
1697.42	52
1699.47	42
1701.52	50
1703.57	58
1705.63	50
1707.68	50
1709.72	56
1711.77	58
1713.82	50
1715.87	52
1717.92	42
1719.97	50
1722.01	56
1724.06	54
1726.1	46
1728.15	50
1730.19	52
1732.23	56
1734.27	48
1736.32	52
1738.36	46
1740.4	44
1742.44	52
1744.48	40
1746.51	44
1748.55	48
1750.59	54
1752.63	48
1754.66	42
1756.7	52
1758.73	44
1760.77	46
1762.8	46
1764.83	42
1766.86	56
1768.9	44
1770.93	50
1772.96	52
1774.99	48
1777.02	44
1779.04	48
1781.07	52
1783.1	52
1785.13	44
1787.15	44
1789.18	44
1791.2	46
1793.23	50
1795.25	48
1797.27	42
1799.29	48
1801.31	46
1803.34	42
1805.36	44
1807.38	38
1809.39	48
1811.41	50
1813.43	50
1815.45	44
1817.46	38
1819.48	46
1821.49	46
1823.51	46
1825.52	42
1827.54	48
1829.55	48
1831.56	40
1833.57	44
1835.58	42
1837.59	52
1839.6	52
1841.61	48
1843.62	46
1845.63	52
1847.64	48
1849.64	46
1851.65	48
1853.65	50
1855.66	40
1857.66	44
1859.66	40
1861.67	54
1863.67	44
1865.67	42
1867.67	42
1869.67	46
1871.67	40
1873.67	46
1875.67	46
1877.67	40
1879.66	48
1881.66	48
1883.66	42
1885.65	44
1887.65	44
1889.64	52
1891.63	44
1893.63	46
1895.62	40
1897.61	40
1899.6	38
1901.59	40
1903.58	44
1905.57	48
1907.56	42
1909.55	44
1911.53	44
1913.52	48
1915.51	42
1917.49	46
1919.48	46
1921.46	48
1923.45	38
1925.43	40
1927.41	50
1929.39	42
1931.37	44
1933.36	46
1935.33	36
1937.31	44
1939.29	46
1941.27	52
1943.25	46
1945.23	46
1947.2	40
1949.18	44
1951.15	44
1953.13	43
1955.1	38
1957.08	48
1959.05	40
1961.02	46
1962.99	40
1964.96	42
1966.93	32
1968.9	38
1970.87	46
1972.84	46
1974.81	42
1976.77	46
1978.74	48
1980.71	38
1982.67	46
1984.64	42
1986.6	46
1988.57	44
1990.53	40
1992.49	38
1994.45	42
1996.41	34
1998.37	34
1999.35	32