File: muestras/LIG/fproof_06.txt
#Acq. time (s)=	10
#Accumulations=	2
#Range (cm-¹)=	100...2000
#Windows=	2
#Autofocus=	Off
#AutoExposure=	Off
#Spike filter=	Multiple accum.
#Delay time (s)=	0
#Binning=	1
#Readout mode=	Signal
#DeNoise=	Off
#ICS correction=	Off
#Dark correction=	Off
#Inst. Process=	Off
#Instrument=	LabRAM HR Evol
#Detector=	Syncerity OE
#Objective=	x100_VIS_LWD
#Grating=	600 (500nm)
#ND Filter=	50%
#Laser=	633nm_Edge
#Hole=	100.021
#Range=	Visible
#Project=	LIG
#Sample=	proof
#Site=
#Title=	fproof
#Remark=
#Date=	07.03.2023 12:27
#Acquired=	07.03.2023 12:27:44
101.054	186
103.621	174
106.187	182
108.753	194
111.317	180
113.881	176
116.443	182
119.005	174
121.566	204
124.126	184
126.685	194
129.243	196
131.801	180
134.357	190
136.911	170
139.466	188
142.021	178
144.574	178
147.126	182
149.676	192
152.227	192
154.777	192
157.325	158
159.873	192
162.419	188
164.966	188
167.51	196
170.055	194
172.598	184
175.141	188
177.682	192
180.222	194
182.763	194
185.302	208
187.839	186
190.378	166
192.914	194
195.449	190
197.983	198
200.517	200
203.05	184
205.582	212
208.113	212
210.643	202
213.173	216
215.701	194
218.229	216
220.756	200
223.282	186
225.808	204
228.331	198
230.855	212
233.378	206
235.9	188
238.419	210
240.94	212
243.46	202
245.977	206
248.495	188
251.011	198
253.527	214
256.041	206
258.556	226
261.068	196
263.58	206
266.092	196
268.603	204
271.112	192
273.622	210
276.129	200
278.636	202
281.142	216
283.647	188
286.152	208
288.655	198
291.158	204
293.66	204
296.161	222
298.661	214
301.161	192
303.66	218
306.158	196
308.655	226
311.151	234
313.645	194
316.14	214
318.634	218
321.125	222
323.618	216
326.109	226
328.598	212
331.088	206
333.576	202
336.064	244
338.55	218
341.037	212
343.521	204
346.005	216
348.489	216
350.971	216
353.453	226
355.935	226
358.414	214
360.893	212
363.371	216
365.848	210
368.325	228
370.801	236
373.275	224
375.75	222
378.223	222
380.695	218
383.167	206
385.638	222
388.108	228
390.577	218
393.044	228
395.512	212
397.979	236
400.445	230
402.909	228
405.374	226
407.836	230
410.299	212
412.762	234
415.221	248
417.681	204
420.141	222
422.598	244
425.057	226
427.513	226
429.968	218
432.424	232
434.878	224
437.33	238
439.783	218
442.234	232
444.685	236
447.136	240
449.585	224
452.033	238
454.48	214
456.927	228
459.372	256
461.817	228
464.261	216
466.705	246
469.147	242
471.589	246
474.029	240
476.47	240
478.909	256
481.347	232
483.785	244
486.221	240
488.657	244
491.093	236
493.527	222
495.96	236
498.393	242
500.824	220
503.256	220
505.686	232
508.115	220
510.543	226
512.972	246
515.399	230
517.825	248
520.25	236
522.674	228
525.097	224
527.52	232
529.942	230
532.364	262
534.784	244
537.204	230
539.623	252
542.041	230
544.458	222
546.874	232
549.289	242
551.705	242
554.118	226
556.531	248
558.944	250
561.355	222
563.766	246
566.175	246
568.585	246
570.992	216
573.401	232
575.807	232
578.212	252
580.618	238
583.022	238
585.425	242
587.827	230
590.229	246
592.631	248
595.031	248
597.43	248
599.829	236
602.226	248
604.623	240
607.02	242
609.415	236
611.808	236
614.202	226
616.596	234
618.988	230
621.38	250
623.769	228
626.159	240
628.549	244
630.936	224
633.324	244
635.71	230
638.096	254
640.481	242
642.866	236
645.248	258
647.632	246
650.013	238
652.394	246
654.773	238
657.154	252
659.532	254
661.91	228
664.286	242
666.663	252
669.038	252
671.412	244
673.786	244
676.159	264
678.532	258
680.903	242
683.274	222
685.644	246
688.014	254
690.382	246
692.749	232
695.116	238
697.482	232
699.846	240
702.211	260
704.574	256
706.938	226
709.299	274
711.661	254
714.021	242
716.381	246
718.739	250
721.097	250
723.455	260
725.811	244
728.167	240
730.521	268
732.877	254
735.23	266
737.582	274
739.934	256
742.285	256
744.635	240
746.985	230
749.334	276
751.682	240
754.028	242
756.374	260
758.72	256
761.065	244
763.408	262
765.752	252
768.095	266
770.436	224
772.777	260
775.116	252
777.456	252
779.794	242
782.133	262
784.469	228
786.806	258
789.141	256
791.476	240
793.809	278
796.143	262
798.476	258
800.807	252
803.138	256
805.468	242
807.797	256
810.125	258
812.453	240
814.78	252
817.106	264
819.432	254
821.757	246
824.081	260
826.403	258
828.726	258
831.048	258
833.368	252
835.688	268
838.008	244
840.326	244
842.644	270
844.96	256
847.277	252
849.592	258
851.906	254
854.221	280
856.534	272
858.846	272
861.159	240
863.469	270
865.779	260
868.088	262
870.396	252
872.704	254
875.011	236
877.318	250
879.623	268
881.928	244
884.232	258
886.536	250
888.838	248
891.139	262
893.44	256
895.741	270
898.039	250
900.339	272
902.637	260
904.933	256
907.231	266
909.526	252
911.821	266
914.115	240
916.408	254
918.701	262
920.993	236
923.283	242
925.575	248
927.864	252
930.153	254
932.441	266
934.728	242
937.014	258
939.3	246
941.585	254
943.87	256
946.154	254
948.437	252
950.719	256
953	256
955.28	256
957.56	256
959.84	240
962.117	258
964.395	256
966.673	242
968.948	256
971.224	244
973.498	244
975.773	262
978.045	260
980.317	260
982.59	264
984.86	240
987.13	244
989.399	242
991.669	264
993.937	242
996.204	274
998.47	258
1000.74	260
1003	272
1005.26	252
1007.53	274
1009.79	244
1012.05	274
1014.31	232
1016.57	262
1018.83	274
1021.09	244
1023.35	262
1025.61	254
1027.87	250
1030.12	262
1032.38	266
1034.63	270
1036.88	276
1039.14	252
1041.39	268
1043.64	266
1045.89	262
1048.14	248
1050.39	254
1052.64	242
1054.89	262
1057.14	266
1059.38	276
1061.63	274
1063.87	278
1066.12	284
1068.36	282
1070.6	278
1072.85	266
1075.09	284
1077.33	250
1079.57	260
1081.81	280
1084.05	262
1086.28	260
1088.52	260
1090.76	258
1092.99	268
1095.23	262
1097.46	258
1099.69	268
1101.93	248
1104.16	264
1106.39	268
1108.62	242
1110.85	266
1113.08	276
1115.31	284
1117.53	258
1119.76	278
1121.99	268
1124.21	270
1126.44	272
1128.66	272
1130.88	262
1133.11	280
1135.33	274
1137.55	270
1139.77	260
1141.99	290
1144.21	292
1146.43	278
1148.64	264
1150.86	286
1153.08	258
1155.29	264
1157.51	272
1159.72	272
1161.93	288
1164.14	272
1166.36	268
1168.57	274
1170.78	272
1172.99	280
1175.2	268
1177.4	272
1179.61	280
1181.82	298
1184.02	272
1186.23	276
1188.43	258
1190.64	262
1192.84	284
1195.04	272
1197.24	256
1199.45	263.9
1201.64	275.489
1203.84	279.246
1206.04	277.429
1208.24	264.484
1210.44	267.101
1212.64	274.077
1214.83	279.07
1217.03	261.37
1219.22	279.538
1221.41	267.652
1223.61	280.956
1225.8	260.288
1227.99	257.877
1230.18	270.799
1232.37	276.638
1234.56	271.254
1236.75	259.842
1238.94	263.913
1241.13	277.213
1243.31	269.291
1245.5	273.939
1247.68	268.515
1249.87	273.728
1252.05	278.607
1254.24	286.111
1256.42	267.843
1258.6	283.039
1260.78	275.29
1262.96	277.072
1265.14	276.387
1267.32	275.225
1269.5	290.983
1271.67	278.125
1273.85	280.843
1276.03	286.237
1278.2	283.97
1280.38	301.015
1282.55	296.161
1284.72	302.199
1286.9	308.262
1289.07	302.573
1291.24	299.726
1293.41	324.777
1295.58	311.888
1297.75	317.52
1299.92	328.739
1302.09	328.701
1304.25	331.113
1306.42	322.756
1308.44	360
1310.61	328
1312.79	352
1314.97	370
1317.14	342
1319.31	376
1321.48	382
1323.66	372
1325.83	364
1328	366
1330.17	360
1332.34	362
1334.5	354
1336.67	372
1338.84	366
1341	354
1343.17	362
1345.33	348
1347.5	354
1349.66	334
1351.83	336
1353.99	332
1356.15	320
1358.31	316
1360.47	324
1362.63	306
1364.79	310
1366.94	312
1369.1	306
1371.26	290
1373.41	304
1375.57	276
1377.72	290
1379.88	302
1382.03	276
1384.18	300
1386.33	284
1388.48	278
1390.64	288
1392.79	274
1394.93	278
1397.08	284
1399.23	264
1401.38	266
1403.52	274
1405.67	254
1407.81	270
1409.96	270
1412.1	282
1414.24	238
1416.39	274
1418.53	240
1420.67	260
1422.81	250
1424.95	268
1427.09	264
1429.23	256
1431.36	254
1433.5	244
1435.64	266
1437.77	260
1439.91	280
1442.04	260
1444.17	256
1446.31	256
1448.44	252
1450.57	264
1452.7	254
1454.83	252
1456.96	242
1459.09	252
1461.22	248
1463.34	258
1465.47	256
1467.6	272
1469.72	268
1471.85	254
1473.97	256
1476.09	272
1478.22	264
1480.34	266
1482.46	248
1484.58	260
1486.7	254
1488.82	256
1490.94	262
1493.06	248
1495.17	270
1497.29	254
1499.41	248
1501.52	242
1503.64	252
1505.75	258
1507.86	230
1509.98	264
1512.09	248
1514.2	266
1516.31	262
1518.42	274
1520.53	254
1522.64	268
1524.74	274
1526.85	262
1528.96	260
1531.07	286
1533.17	266
1535.27	258
1537.38	268
1539.48	260
1541.58	254
1543.69	282
1545.79	248
1547.89	272
1549.99	286
1552.09	270
1554.19	256
1556.28	284
1558.38	278
1560.48	298
1562.57	274
1564.67	270
1566.76	276
1568.86	286
1570.95	282
1573.05	286
1575.14	310
1577.23	294
1579.32	290
1581.41	304
1583.5	326
1585.59	326
1587.68	324
1589.76	308
1591.85	336
1593.94	304
1596.02	300
1598.11	316
1600.19	318
1602.27	312
1604.36	312
1606.44	320
1608.52	330
1610.6	324
1612.68	304
1614.76	302
1616.84	286
1618.92	296
1621	300
1623.07	282
1625.15	306
1627.23	290
1629.3	280
1631.38	264
1633.45	300
1635.52	266
1637.59	270
1639.67	282
1641.74	260
1643.81	270
1645.88	258
1647.95	242
1650.02	234
1652.08	242
1654.15	254
1656.22	236
1658.28	234
1660.35	240
1662.41	252
1664.48	244
1666.54	226
1668.6	246
1670.67	232
1672.73	222
1674.79	218
1676.85	222
1678.91	224
1680.97	240
1683.03	242
1685.08	222
1687.14	212
1689.2	242
1691.25	236
1693.31	228
1695.36	228
1697.42	220
1699.47	228
1701.52	214
1703.57	232
1705.63	214
1707.68	230
1709.72	216
1711.77	226
1713.82	228
1715.87	208
1717.92	232
1719.97	220
1722.01	224
1724.06	204
1726.1	230
1728.15	214
1730.19	228
1732.23	210
1734.27	224
1736.32	222
1738.36	228
1740.4	218
1742.44	214
1744.48	200
1746.51	228
1748.55	216
1750.59	232
1752.63	222
1754.66	218
1756.7	236
1758.73	210
1760.77	220
1762.8	214
1764.83	210
1766.86	212
1768.9	212
1770.93	234
1772.96	214
1774.99	216
1777.02	200
1779.04	214
1781.07	232
1783.1	208
1785.13	220
1787.15	238
1789.18	218
1791.2	224
1793.23	210
1795.25	220
1797.27	222
1799.29	226
1801.31	226
1803.34	216
1805.36	218
1807.38	204
1809.39	200
1811.41	218
1813.43	208
1815.45	222
1817.46	222
1819.48	208
1821.49	204
1823.51	224
1825.52	204
1827.54	212
1829.55	216
1831.56	216
1833.57	200
1835.58	206
1837.59	196
1839.6	208
1841.61	218
1843.62	212
1845.63	216
1847.64	226
1849.64	212
1851.65	192
1853.65	194
1855.66	202
1857.66	194
1859.66	220
1861.67	204
1863.67	230
1865.67	208
1867.67	192
1869.67	196
1871.67	212
1873.67	194
1875.67	206
1877.67	196
1879.66	182
1881.66	188
1883.66	198
1885.65	202
1887.65	200
1889.64	210
1891.63	198
1893.63	200
1895.62	182
1897.61	198
1899.6	196
1901.59	202
1903.58	202
1905.57	204
1907.56	196
1909.55	222
1911.53	180
1913.52	188
1915.51	206
1917.49	190
1919.48	186
1921.46	216
1923.45	202
1925.43	216
1927.41	194
1929.39	202
1931.37	192
1933.36	208
1935.33	198
1937.31	196
1939.29	200
1941.27	184
1943.25	206
1945.23	190
1947.2	196
1949.18	188
1951.15	174
1953.13	195
1955.1	190
1957.08	192
1959.05	178
1961.02	190
1962.99	190
1964.96	192
1966.93	186
1968.9	200
1970.87	190
1972.84	200
1974.81	188
1976.77	190
1978.74	194
1980.71	186
1982.67	172
1984.64	196
1986.6	174
1988.57	176
1990.53	192
1992.49	194
1994.45	184
1996.41	190
1998.37	204
1999.35	178