File: muestras/LIG/fproof_26.txt
#Acq. time (s)=	10
#Accumulations=	2
#Range (cm-¹)=	100...2000
#Windows=	2
#Autofocus=	Off
#AutoExposure=	Off
#Spike filter=	Multiple accum.
#Delay time (s)=	0
#Binning=	1
#Readout mode=	Signal
#DeNoise=	Off
#ICS correction=	Off
#Dark correction=	Off
#Inst. Process=	Off
#Instrument=	LabRAM HR Evol
#Detector=	Syncerity OE
#Objective=	x100_VIS_LWD
#Grating=	600 (500nm)
#ND Filter=	25%
#Laser=	633nm_Edge
#Hole=	100.021
#Range=	Visible
#Project=	LIG
#Sample=	proof
#Site=
#Title=	fproof
#Remark=
#Date=	07.03.2023 13:35
#Acquired=	07.03.2023 13:35:46
101.054	790
103.621	776
106.187	796
108.753	814
111.317	770
113.881	836
116.443	826
119.005	772
121.566	820
124.126	820
126.685	840
129.243	772
131.801	822
134.357	838
136.911	832
139.466	822
142.021	838
144.574	858
147.126	850
149.676	834
152.227	832
154.777	832
157.325	852
159.873	856
162.419	850
164.966	824
167.51	850
170.055	840
172.598	858
175.141	860
177.682	828
180.222	822
182.763	820
185.302	842
187.839	826
190.378	850
192.914	858
195.449	856
197.983	884
200.517	874
203.05	886
205.582	876
208.113	892
210.643	894
213.173	884
215.701	900
218.229	914
220.756	902
223.282	894
225.808	920
228.331	904
230.855	914
233.378	886
235.9	892
238.419	894
240.94	932
243.46	930
245.977	912
248.495	930
251.011	912
253.527	896
256.041	964
258.556	942
261.068	928
263.58	932
266.092	916
268.603	896
271.112	946
273.622	906
276.129	952
278.636	956
281.142	938
283.647	900
286.152	948
288.655	920
291.158	966
293.66	916
296.161	968
298.661	950
301.161	938
303.66	954
306.158	964
308.655	960
311.151	1000
313.645	980
316.14	970
318.634	960
321.125	966
323.618	988
326.109	996
328.598	962
331.088	950
333.576	964
336.064	990
338.55	1016
341.037	988
343.521	1014
346.005	1006
348.489	1012
350.971	1020
353.453	1024
355.935	1020
358.414	1018
360.893	1024
363.371	1022
365.848	1032
368.325	1002
370.801	1014
373.275	996
375.75	1016
378.223	1036
380.695	1022
383.167	1044
385.638	980
388.108	972
390.577	1008
393.044	992
395.512	982
397.979	1018
400.445	972
402.909	1036
405.374	1006
407.836	1018
410.299	1048
412.762	1050
415.221	1056
417.681	1054
420.141	1076
422.598	1076
425.057	1082
427.513	1054
429.968	1088
432.424	1080
434.878	1066
437.33	1098
439.783	1086
442.234	1088
444.685	1106
447.136	1100
449.585	1060
452.033	1066
454.48	1080
456.927	1102
459.372	1078
461.817	1110
464.261	1060
466.705	1068
469.147	1066
471.589	1072
474.029	1054
476.47	1110
478.909	1086
481.347	1088
483.785	1110
486.221	1082
488.657	1102
491.093	1074
493.527	1068
495.96	1112
498.393	1126
500.824	1080
503.256	1088
505.686	1134
508.115	1068
510.543	1064
512.972	1108
515.399	1110
517.825	1058
520.25	1118
522.674	1114
525.097	1080
527.52	1128
529.942	1104
532.364	1050
534.784	1106
537.204	1100
539.623	1092
542.041	1090
544.458	1070
546.874	1092
549.289	1070
551.705	1100
554.118	1074
556.531	1082
558.944	1086
561.355	1114
563.766	1100
566.175	1098
568.585	1110
570.992	1088
573.401	1146
575.807	1100
578.212	1116
580.618	1114
583.022	1070
585.425	1074
587.827	1068
590.229	1112
592.631	1112
595.031	1104
597.43	1094
599.829	1120
602.226	1140
604.623	1140
607.02	1066
609.415	1170
611.808	1138
614.202	1140
616.596	1098
618.988	1162
621.38	1140
623.769	1146
626.159	1170
628.549	1162
630.936	1188
633.324	1134
635.71	1152
638.096	1156
640.481	1142
642.866	1238
645.248	1130
647.632	1118
650.013	1140
652.394	1208
654.773	1186
657.154	1178
659.532	1192
661.91	1170
664.286	1194
666.663	1190
669.038	1176
671.412	1166
673.786	1138
676.159	1236
678.532	1186
680.903	1166
683.274	1180
685.644	1212
688.014	1178
690.382	1166
692.749	1148
695.116	1168
697.482	1184
699.846	1154
702.211	1188
704.574	1196
706.938	1144
709.299	1122
711.661	1180
714.021	1164
716.381	1136
718.739	1166
721.097	1192
723.455	1158
725.811	1190
728.167	1140
730.521	1186
732.877	1210
735.23	1186
737.582	1184
739.934	1202
742.285	1222
744.635	1172
746.985	1172
749.334	1206
751.682	1222
754.028	1174
756.374	1206
758.72	1198
761.065	1188
763.408	1200
765.752	1192
768.095	1164
770.436	1178
772.777	1212
775.116	1152
777.456	1192
779.794	1130
782.133	1180
784.469	1190
786.806	1176
789.141	1184
791.476	1214
793.809	1210
796.143	1164
798.476	1202
800.807	1130
803.138	1142
805.468	1188
807.797	1238
810.125	1198
812.453	1172
814.78	1192
817.106	1174
819.432	1188
821.757	1196
824.081	1224
826.403	1230
828.726	1208
831.048	1264
833.368	1196
835.688	1224
838.008	1254
840.326	1238
842.644	1252
844.96	1212
847.277	1210
849.592	1200
851.906	1184
854.221	1192
856.534	1270
858.846	1244
861.159	1206
863.469	1238
865.779	1266
868.088	1262
870.396	1218
872.704	1234
875.011	1222
877.318	1212
879.623	1246
881.928	1250
884.232	1182
886.536	1246
888.838	1204
891.139	1260
893.44	1216
895.741	1256
898.039	1250
900.339	1222
902.637	1234
904.933	1212
907.231	1206
909.526	1188
911.821	1242
914.115	1242
916.408	1222
918.701	1220
920.993	1204
923.283	1240
925.575	1216
927.864	1206
930.153	1240
932.441	1228
934.728	1238
937.014	1194
939.3	1224
941.585	1228
943.87	1226
946.154	1242
948.437	1264
950.719	1238
953	1276
955.28	1248
957.56	1204
959.84	1184
962.117	1258
964.395	1190
966.673	1216
968.948	1264
971.224	1254
973.498	1260
975.773	1264
978.045	1270
980.317	1224
982.59	1244
984.86	1252
987.13	1236
989.399	1258
991.669	1240
993.937	1256
996.204	1236
998.47	1268
1000.74	1250
1003	1256
1005.26	1294
1007.53	1246
1009.79	1254
1012.05	1240
1014.31	1230
1016.57	1268
1018.83	1292
1021.09	1232
1023.35	1242
1025.61	1294
1027.87	1276
1030.12	1268
1032.38	1252
1034.63	1288
1036.88	1266
1039.14	1308
1041.39	1266
1043.64	1318
1045.89	1310
1048.14	1292
1050.39	1266
1052.64	1262
1054.89	1294
1057.14	1300
1059.38	1326
1061.63	1304
1063.87	1290
1066.12	1272
1068.36	1292
1070.6	1336
1072.85	1314
1075.09	1282
1077.33	1296
1079.57	1322
1081.81	1326
1084.05	1274
1086.28	1292
1088.52	1300
1090.76	1316
1092.99	1292
1095.23	1258
1097.46	1326
1099.69	1292
1101.93	1274
1104.16	1308
1106.39	1324
1108.62	1280
1110.85	1326
1113.08	1288
1115.31	1270
1117.53	1312
1119.76	1324
1121.99	1292
1124.21	1358
1126.44	1276
1128.66	1304
1130.88	1342
1133.11	1294
1135.33	1330
1137.55	1328
1139.77	1346
1141.99	1328
1144.21	1310
1146.43	1338
1148.64	1352
1150.86	1324
1153.08	1308
1155.29	1360
1157.51	1308
1159.72	1368
1161.93	1312
1164.14	1306
1166.36	1368
1168.57	1322
1170.78	1362
1172.99	1410
1175.2	1364
1177.4	1332
1179.61	1360
1181.82	1434
1184.02	1348
1186.23	1342
1188.43	1332
1190.64	1396
1192.84	1398
1195.04	1388
1197.24	1350
1199.45	1368.83
1201.64	1394.43
1203.84	1373.9
1206.04	1395.84
1208.24	1380.28
1210.44	1387.7
1212.64	1433.25
1214.83	1413.88
1217.03	1391.85
1219.22	1418.1
1221.41	1411.72
1223.61	1422.96
1225.8	1412.33
1227.99	1417.92
1230.18	1423.32
1232.37	1464.31
1234.56	1411.96
1236.75	1420.03
1238.94	1439.99
1241.13	1474.2
1243.31	1459.33
1245.5	1449.59
1247.68	1430.77
1249.87	1509.34
1252.05	1484.89
1254.24	1493.97
1256.42	1535.79
1258.6	1514.19
1260.78	1510.43
1262.96	1517.17
1265.14	1554.5
1267.32	1544.05
1269.5	1557.55
1271.67	1555.91
1273.85	1542.86
1276.03	1576.09
1278.2	1584.74
1280.38	1620.33
1282.55	1602.42
1284.72	1602.47
1286.9	1634.99
1289.07	1614.24
1291.24	1644.97
1293.41	1635.23
1295.58	1638.57
1297.75	1655.63
1299.92	1639.43
1302.09	1653.76
1304.25	1664.79
1306.42	1675.14
1308.44	1658
1310.61	1680
1312.79	1698
1314.97	1698
1317.14	1688
1319.31	1702
1321.48	1678
1323.66	1664
1325.83	1694
1328	1688
1330.17	1718
1332.34	1682
1334.5	1710
1336.67	1624
1338.84	1654
1341	1656
1343.17	1630
1345.33	1612
1347.5	1626
1349.66	1608
1351.83	1686
1353.99	1644
1356.15	1622
1358.31	1604
1360.47	1636
1362.63	1640
1364.79	1642
1366.94	1616
1369.1	1608
1371.26	1652
1373.41	1614
1375.57	1636
1377.72	1598
1379.88	1662
1382.03	1584
1384.18	1640
1386.33	1620
1388.48	1610
1390.64	1624
1392.79	1614
1394.93	1598
1397.08	1584
1399.23	1602
1401.38	1610
1403.52	1572
1405.67	1580
1407.81	1586
1409.96	1562
1412.1	1598
1414.24	1582
1416.39	1566
1418.53	1578
1420.67	1570
1422.81	1600
1424.95	1524
1427.09	1528
1429.23	1562
1431.36	1498
1433.5	1548
1435.64	1558
1437.77	1534
1439.91	1552
1442.04	1578
1444.17	1566
1446.31	1518
1448.44	1498
1450.57	1512
1452.7	1526
1454.83	1554
1456.96	1548
1459.09	1544
1461.22	1538
1463.34	1538
1465.47	1570
1467.6	1494
1469.72	1550
1471.85	1544
1473.97	1568
1476.09	1514
1478.22	1524
1480.34	1538
1482.46	1532
1484.58	1562
1486.7	1490
1488.82	1562
1490.94	1530
1493.06	1526
1495.17	1574
1497.29	1552
1499.41	1506
1501.52	1486
1503.64	1506
1505.75	1514
1507.86	1540
1509.98	1532
1512.09	1528
1514.2	1520
1516.31	1518
1518.42	1546
1520.53	1538
1522.64	1550
1524.74	1522
1526.85	1550
1528.96	1512
1531.07	1502
1533.17	1562
1535.27	1500
1537.38	1524
1539.48	1530
1541.58	1530
1543.69	1528
1545.79	1536
1547.89	1526
1549.99	1522
1552.09	1528
1554.19	1538
1556.28	1516
1558.38	1564
1560.48	1534
1562.57	1576
1564.67	1476
1566.76	1542
1568.86	1526
1570.95	1508
1573.05	1556
1575.14	1550
1577.23	1552
1579.32	1534
1581.41	1602
1583.5	1618
1585.59	1604
1587.68	1560
1589.76	1562
1591.85	1542
1593.94	1568
1596.02	1574
1598.11	1562
1600.19	1510
1602.27	1524
1604.36	1504
1606.44	1524
1608.52	1550
1610.6	1564
1612.68	1490
1614.76	1490
1616.84	1494
1618.92	1482
1621	1484
1623.07	1440
1625.15	1504
1627.23	1452
1629.3	1464
1631.38	1464
1633.45	1496
1635.52	1430
1637.59	1474
1639.67	1450
1641.74	1392
1643.81	1418
1645.88	1372
1647.95	1398
1650.02	1384
1652.08	1356
1654.15	1354
1656.22	1426
1658.28	1378
1660.35	1366
1662.41	1334
1664.48	1306
1666.54	1358
1668.6	1334
1670.67	1324
1672.73	1328
1674.79	1360
1676.85	1274
1678.91	1326
1680.97	1338
1683.03	1344
1685.08	1324
1687.14	1310
1689.2	1362
1691.25	1318
1693.31	1322
1695.36	1320
1697.42	1324
1699.47	1296
1701.52	1268
1703.57	1272
1705.63	1272
1707.68	1298
1709.72	1244
1711.77	1308
1713.82	1282
1715.87	1246
1717.92	1322
1719.97	1298
1722.01	1266
1724.06	1286
1726.1	1240
1728.15	1286
1730.19	1268
1732.23	1308
1734.27	1242
1736.32	1294
1738.36	1260
1740.4	1228
1742.44	1268
1744.48	1234
1746.51	1228
1748.55	1246
1750.59	1242
1752.63	1252
1754.66	1236
1756.7	1210
1758.73	1204
1760.77	1250
1762.8	1260
1764.83	1264
1766.86	1238
1768.9	1252
1770.93	1224
1772.96	1268
1774.99	1230
1777.02	1238
1779.04	1238
1781.07	1208
1783.1	1242
1785.13	1232
1787.15	1226
1789.18	1262
1791.2	1238
1793.23	1246
1795.25	1218
1797.27	1212
1799.29	1232
1801.31	1236
1803.34	1218
1805.36	1244
1807.38	1202
1809.39	1230
1811.41	1238
1813.43	1226
1815.45	1214
1817.46	1216
1819.48	1222
1821.49	1224
1823.51	1184
1825.52	1222
1827.54	1212
1829.55	1226
1831.56	1162
1833.57	1180
1835.58	1146
1837.59	1190
1839.6	1182
1841.61	1168
1843.62	1176
1845.63	1184
1847.64	1182
1849.64	1146
1851.65	1178
1853.65	1164
1855.66	1168
1857.66	1164
1859.66	1166
1861.67	1182
1863.67	1126
1865.67	1154
1867.67	1136
1869.67	1178
1871.67	1114
1873.67	1166
1875.67	1182
1877.67	1144
1879.66	1164
1881.66	1130
1883.66	1124
1885.65	1142
1887.65	1114
1889.64	1100
1891.63	1132
1893.63	1134
1895.62	1172
1897.61	1116
1899.6	1130
1901.59	1138
1903.58	1124
1905.57	1164
1907.56	1130
1909.55	1128
1911.53	1128
1913.52	1140
1915.51	1096
1917.49	1148
1919.48	1102
1921.46	1094
1923.45	1132
1925.43	1136
1927.41	1124
1929.39	1138
1931.37	1106
1933.36	1112
1935.33	1122
1937.31	1120
1939.29	1088
1941.27	1136
1943.25	1104
1945.23	1138
1947.2	1064
1949.18	1112
1951.15	1102
1953.13	1067
1955.1	1092
1957.08	1142
1959.05	1072
1961.02	1084
1962.99	1068
1964.96	1080
1966.93	1082
1968.9	1072
1970.87	1076
1972.84	1062
1974.81	1102
1976.77	1078
1978.74	1028
1980.71	1070
1982.67	1052
1984.64	1076
1986.6	1058
1988.57	1074
1990.53	1048
1992.49	1042
1994.45	1070
1996.41	1042
1998.37	1058
1999.35	1058