File: muestras/mosquito/OR_06.txt
#Acq. time (s)=	10
#Accumulations=	1
#Range (cm-¹)=	200...4000
#Windows=	5
#Autofocus=	Off
#AutoExposure=	Off
#Spike filter=	Off
#Delay time (s)=	0
#Binning=	1
#Readout mode=	Signal
#DeNoise=	Off
#ICS correction=	Off
#Dark correction=	Off
#Inst. Process=	Off
#Instrument=	LabRAM HR Evol
#Detector=	Syncerity OE
#Objective=	x100_VIS
#Grating=	600 (500nm)
#ND Filter=	25%
#Laser=	633nm_Edge
#Hole=	100.021
#Range=	Visible
#Project=	Omar
#Sample=	03-07-23
#Site=	1
#Title=	OR
#Remark=
#Date=	03.07.2023 13:35
#Acquired=	03.07.2023 13:35:01
200.404	2484
204.205	2460
208.003	2376
211.799	2424
215.595	2486
219.387	2508
223.177	2454
226.966	2494
230.752	2548
234.536	2496
238.319	2526
242.1	2552
245.879	2530
249.655	2502
253.431	2530
257.204	2582
260.976	2542
264.744	2558
268.511	2512
272.276	2560
276.04	2516
279.801	2518
283.561	2596
287.318	2666
291.074	2576
294.828	2656
298.581	2714
302.33	2726
306.079	2696
309.825	2718
313.569	2646
317.311	2680
321.052	2690
324.79	2674
328.527	2708
332.261	2678
335.994	2708
339.725	2658
343.454	2718
347.182	2764
350.907	2720
354.631	2756
358.352	2742
362.072	2818
365.789	2788
369.505	2762
373.219	2742
376.93	2804
380.642	2862
384.35	2834
388.056	2778
391.76	2818
395.463	2762
399.164	2850
402.863	2884
406.559	2870
410.254	2922
413.948	2922
417.639	2884
421.329	2942
425.016	2990
428.701	2982
432.386	2962
436.068	3078
439.748	3046
443.426	3004
447.103	3004
450.777	3064
454.45	3010
458.121	3000
461.789	3036
465.457	3048
469.122	3016
472.786	3062
476.447	2974
480.107	3048
483.765	3072
487.421	3076
491.075	3024
494.727	3082
498.377	3136
502.026	3092
505.673	3064
509.318	3076
512.962	3070
516.602	3196
520.242	3146
523.881	3156
527.516	3136
531.149	3118
534.783	3172
538.413	3148
542.041	3130
545.667	3072
549.292	3142
552.915	3162
556.537	3128
560.156	3112
563.773	3160
567.389	3204
571.004	3116
574.615	3222
578.226	3210
581.834	3252
585.44	3208
589.045	3182
592.649	3148
596.25	3208
599.85	3272
603.448	3258
607.042	3254
610.637	3270
614.229	3274
617.819	3288
621.408	3272
624.994	3344
628.58	3294
632.163	3312
635.744	3388
639.324	3346
642.902	3418
646.478	3342
650.052	3310
653.625	3466
657.196	3366
660.764	3292
664.331	3446
667.897	3336
671.46	3372
675.021	3446
678.582	3372
682.14	3356
685.696	3384
689.252	3386
692.804	3388
696.355	3424
699.905	3430
703.451	3380
706.997	3428
710.542	3402
714.083	3498
717.624	3444
721.162	3466
724.7	3508
728.235	3446
731.768	3514
735.301	3500
738.83	3522
742.358	3546
745.885	3406
749.41	3534
752.931	3526
756.453	3466
759.973	3560
763.49	3522
767.006	3564
770.52	3502
774.033	3458
777.543	3570
781.052	3592
784.559	3566
788.064	3556
791.568	3600
795.07	3592
798.57	3514
802.068	3556
805.565	3630
809.061	3586
812.553	3548
816.045	3612
819.535	3574
823.022	3616
826.508	3670
829.993	3632
833.476	3568
836.957	3634
840.436	3632
843.914	3688
847.391	3662
850.864	3734
854.337	3658
857.807	3706
861.277	3694
864.744	3602
868.209	3682
871.674	3686
875.136	3642
878.597	3756
882.056	3736
885.512	3668
888.967	3674
892.421	3674
895.874	3694
899.323	3714
902.771	3626
906.219	3688
909.664	3646
913.107	3604
916.55	3670
919.99	3678
923.428	3710
926.863	3730
930.299	3750
933.732	3732
937.164	3712
940.593	3716
944.022	3768
947.448	3772
950.874	3792
954.296	3802
957.718	3784
961.137	3866
964.555	3788
967.972	3806
971.387	3866
974.8	3722
978.21	3764
981.62	3826
985.029	3920
988.435	3824
991.839	3794
995.243	3828
998.644	3856
1002.04	3812
1005.44	3868
1008.84	3900
1012.23	3892
1015.63	3826
1019.02	3948
1022.41	3894
1025.79	3848
1029.18	3858
1032.56	3906
1035.95	3934
1039.33	3936
1042.71	4004
1046.09	3956
1049.46	3960
1052.84	3976
1056.21	4058
1059.58	3920
1062.95	4030
1066.32	3998
1069.69	3976
1073.05	3964
1076.41	4004
1079.78	4006
1083.14	3938
1086.49	3986
1089.85	4014
1093.21	3964
1096.56	3940
1099.91	3900
1103.26	3930
1106.61	4006
1109.96	3964
1113.3	3886
1116.64	4042
1119.99	3972
1123.33	3976
1126.66	4086
1130	3978
1133.34	3996
1136.67	4032
1140	4022
1143.33	4122
1146.66	4088
1149.99	4014
1153.32	4034
1156.64	4036
1159.96	4090
1163.28	4108
1166.6	4100
1169.92	4104
1173.23	4158
1176.55	4094
1179.86	4186
1183.17	4136
1186.48	4096
1189.79	4108
1193.1	4138
1196.4	4216
1199.7	4138
1203	4096
1206.3	4090
1209.6	4194
1212.9	4154
1216.19	4046
1219.49	4116
1222.78	4064
1226.07	4058
1229.36	4146
1232.65	4080
1235.93	4068
1239.21	4104
1242.5	4130
1245.78	4100
1249.06	4148
1252.33	4280
1255.61	4152
1258.88	4226
1262.16	4246
1265.43	4162
1268.7	4196
1271.96	4210
1275.23	4164
1278.5	4238
1281.76	4211.56
1285.02	4168.8
1288.28	4258.12
1291.54	4217.65
1294.8	4253.73
1298.05	4233.73
1301.31	4243.94
1304.56	4271.94
1307.81	4320.99
1311.06	4333.23
1314.3	4376.21
1317.55	4320.51
1320.79	4332
1324.04	4300.38
1327.28	4430.41
1330.52	4354.93
1333.76	4370.59
1336.99	4382
1340.23	4360.5
1343.46	4399.87
1346.69	4389.63
1349.92	4386.46
1353.15	4403.19
1356.38	4395.28
1359.6	4419.08
1362.83	4457.93
1366.05	4488.97
1369.27	4449.86
1372.49	4469.23
1375.71	4446.93
1378.93	4461.97
1382.14	4421.58
1385.35	4505.85
1388.57	4516.1
1391.2	4448
1394.43	4490
1397.65	4470
1400.87	4506
1404.09	4432
1407.31	4490
1410.53	4442
1413.74	4424
1416.96	4410
1420.17	4454
1423.38	4366
1426.59	4392
1429.8	4440
1433.01	4374
1436.21	4420
1439.42	4460
1442.62	4484
1445.82	4456
1449.02	4484
1452.22	4484
1455.41	4506
1458.61	4466
1461.8	4430
1464.99	4380
1468.18	4462
1471.37	4432
1474.56	4414
1477.74	4466
1480.93	4556
1484.11	4570
1487.29	4478
1490.47	4498
1493.65	4494
1496.82	4524
1500	4574
1503.17	4462
1506.34	4560
1509.51	4498
1512.68	4490
1515.85	4488
1519.02	4482
1522.18	4446
1525.34	4446
1528.51	4544
1531.67	4462
1534.82	4484
1537.98	4462
1541.14	4444
1544.29	4462
1547.44	4412
1550.59	4454
1553.74	4496
1556.89	4524
1560.04	4496
1563.18	4546
1566.33	4422
1569.47	4428
1572.61	4534
1575.75	4456
1578.89	4492
1582.02	4514
1585.16	4480
1588.29	4414
1591.42	4482
1594.55	4464
1597.68	4418
1600.81	4464
1603.94	4546
1607.06	4470
1610.18	4454
1613.3	4540
1616.42	4480
1619.54	4572
1622.66	4472
1625.78	4526
1628.89	4464
1632	4396
1635.11	4500
1638.22	4400
1641.33	4356
1644.44	4470
1647.55	4340
1650.65	4380
1653.75	4386
1656.85	4338
1659.95	4294
1663.05	4320
1666.15	4210
1669.24	4232
1672.34	4184
1675.43	4220
1678.52	4176
1681.61	4138
1684.7	4140
1687.78	4144
1690.87	4124
1693.95	4096
1697.03	4164
1700.12	4142
1703.2	4140
1706.27	4098
1709.35	4092
1712.42	4060
1715.5	4122
1718.57	4010
1721.64	4074
1724.71	4000
1727.78	4072
1730.84	4064
1733.91	3986
1736.97	4082
1740.04	4082
1743.1	4060
1746.16	4042
1749.21	4056
1752.27	4106
1755.33	4098
1758.38	3992
1761.43	4104
1764.48	4082
1767.53	3962
1770.58	3998
1773.63	4032
1776.67	3956
1779.71	4050
1782.76	4030
1785.8	4104
1788.84	4104
1791.88	4024
1794.91	4026
1797.95	4024
1800.98	3982
1804.01	4050
1807.04	4054
1810.07	4020
1813.1	3992
1816.13	3974
1819.15	4000
1822.18	3976
1825.2	4008
1828.22	3950
1831.24	3900
1834.26	3996
1837.28	3880
1840.29	4040
1843.31	3960
1846.32	3908
1849.33	3956
1852.34	3866
1855.35	3930
1858.36	3906
1861.36	3912
1864.36	3926
1867.37	3872
1870.37	3872
1873.37	3930
1876.37	3852
1879.37	3884
1882.36	3942
1885.36	3862
1888.35	3842
1891.34	3882
1894.33	3900
1897.32	3882
1900.31	3854
1903.3	3888
1906.28	3868
1909.26	3850
1912.25	3872
1915.23	3882
1918.21	3848
1921.18	3824
1924.16	3842
1927.14	3860
1930.11	3828
1933.08	3798
1936.05	3768
1939.02	3792
1941.99	3842
1944.96	3722
1947.92	3840
1950.89	3814
1953.85	3778
1956.81	3850
1959.77	3808
1962.73	3800
1965.69	3764
1968.65	3764
1971.6	3740
1974.55	3712
1977.51	3832
1980.46	3754
1983.41	3676
1986.35	3712
1989.3	3694
1992.25	3796
1995.19	3738
1998.13	3702
2001.07	3786
2004.01	3686
2006.95	3708
2009.89	3716
2012.82	3808
2015.76	3704
2018.69	3638
2021.62	3744
2024.55	3652
2027.48	3688
2030.41	3614
2033.34	3642
2036.26	3552
2039.19	3622
2042.11	3646
2045.03	3646
2047.95	3712
2050.87	3660
2053.79	3622
2056.7	3644
2059.61	3662
2062.53	3632
2065.44	3630
2068.35	3604
2071.26	3564
2074.17	3612
2077.07	3598
2079.98	3528
2082.88	3548
2085.78	3582
2088.68	3568
2091.58	3562
2094.48	3572
2097.38	3528
2100.28	3540
2103.17	3542
2106.06	3520
2108.96	3498
2111.85	3554
2114.73	3526
2117.62	3618
2120.51	3544
2123.39	3514
2126.28	3528
2129.16	3480
2132.04	3504
2134.92	3456
2137.8	3504
2140.68	3558
2143.55	3440
2146.43	3530
2149.3	3412
2152.17	3462
2155.04	3446
2157.91	3430
2160.78	3372
2163.65	3444
2166.51	3430
2169.38	3338
2172.24	3392
2175.1	3398
2177.96	3336
2180.82	3356
2183.68	3426
2186.53	3348
2189.39	3310
2192.24	3314
2195.09	3266
2197.95	3284
2200.8	3306
2203.64	3422
2206.49	3232
2209.34	3202
2212.18	3314
2215.03	3296
2217.87	3222
2220.71	3301.15
2223.55	3247.48
2226.39	3251.83
2229.22	3284.6
2232.06	3264.31
2234.89	3320.17
2237.73	3247.57
2240.56	3247.61
2243.39	3278.13
2246.22	3341.58
2249.05	3295.33
2251.87	3317.37
2254.7	3313.53
2257.52	3348.03
2260.34	3260.82
2263.17	3299.55
2265.99	3322.38
2268.8	3355.41
2271.62	3293.34
2274.44	3294.55
2277.25	3300.27
2280.07	3322.3
2282.88	3308.84
2285.69	3315.3
2288.5	3300.24
2291.31	3282.71
2294.12	3306.81
2296.92	3302.06
2299.73	3328.65
2302.53	3311.96
2305.34	3246.76
2308.14	3252.35
2310.94	3277.2
2313.74	3291.12
2315.86	3282
2318.67	3342
2321.48	3278
2324.29	3306
2327.09	3248
2329.9	3302
2332.7	3324
2335.51	3244
2338.31	3220
2341.11	3282
2343.91	3258
2346.71	3250
2349.51	3244
2352.3	3254
2355.1	3214
2357.89	3246
2360.68	3308
2363.48	3270
2366.27	3290
2369.05	3240
2371.84	3208
2374.63	3194
2377.41	3188
2380.2	3240
2382.98	3176
2385.76	3234
2388.54	3144
2391.32	3166
2394.1	3190
2396.87	3180
2399.65	3210
2402.42	3182
2405.2	3208
2407.97	3240
2410.74	3124
2413.51	3148
2416.27	3172
2419.04	3170
2421.81	3138
2424.57	3158
2427.33	3112
2430.1	3116
2432.85	3116
2435.61	3140
2438.37	3146
2441.13	3118
2443.88	3162
2446.64	3216
2449.39	3108
2452.14	3108
2454.89	3070
2457.64	3116
2460.39	3058
2463.14	3168
2465.88	3048
2468.63	3074
2471.37	3080
2474.11	3078
2476.86	3074
2479.59	3166
2482.33	3034
2485.07	3058
2487.81	3060
2490.54	3022
2493.28	3034
2496.01	3068
2498.74	3078
2501.47	3068
2504.2	2952
2506.93	3052
2509.65	3018
2512.38	3008
2515.1	3018
2517.82	2978
2520.55	2974
2523.27	3026
2525.99	2988
2528.7	2938
2531.42	2972
2534.14	2978
2536.85	2962
2539.56	2986
2542.28	3034
2544.99	2940
2547.7	2972
2550.4	2920
2553.11	2986
2555.82	2884
2558.52	2928
2561.23	2894
2563.93	2872
2566.63	2962
2569.33	2908
2572.03	2912
2574.73	2926
2577.42	2888
2580.12	2914
2582.81	2948
2585.51	2832
2588.2	2810
2590.89	2888
2593.58	2890
2596.26	2874
2598.95	2882
2601.64	2864
2604.32	2856
2607.01	2796
2609.69	2842
2612.37	2782
2615.05	2796
2617.73	2782
2620.41	2806
2623.08	2838
2625.76	2786
2628.43	2754
2631.1	2854
2633.78	2746
2636.45	2838
2639.12	2780
2641.78	2770
2644.45	2762
2647.12	2754
2649.78	2704
2652.45	2716
2655.11	2734
2657.77	2740
2660.43	2734
2663.09	2752
2665.75	2774
2668.4	2708
2671.06	2784
2673.71	2704
2676.37	2732
2679.02	2778
2681.67	2760
2684.32	2678
2686.97	2778
2689.61	2714
2692.26	2656
2694.9	2714
2697.55	2706
2700.19	2706
2702.83	2650
2705.47	2608
2708.11	2658
2710.75	2660
2713.39	2636
2716.02	2624
2718.66	2602
2721.29	2592
2723.92	2644
2726.55	2616
2729.18	2600
2731.81	2634
2734.44	2578
2737.07	2594
2739.69	2596
2742.32	2596
2744.94	2538
2747.56	2612
2750.18	2592
2752.8	2594
2755.42	2574
2758.04	2604
2760.65	2550
2763.27	2498
2765.88	2616
2768.5	2568
2771.11	2520
2773.72	2516
2776.33	2504
2778.94	2568
2781.54	2454
2784.15	2540
2786.75	2556
2789.36	2534
2791.96	2462
2794.56	2524
2797.16	2556
2799.76	2500
2802.36	2494
2804.96	2536
2807.55	2452
2810.15	2468
2812.74	2490
2815.33	2460
2817.93	2468
2820.52	2362
2823.11	2448
2825.69	2364
2828.28	2432
2830.87	2442
2833.45	2444
2836.03	2470
2838.62	2406
2841.2	2458
2843.78	2392
2846.36	2368
2848.93	2394
2851.51	2378
2854.09	2326
2856.66	2330
2859.24	2334
2861.81	2380
2864.38	2354
2866.95	2334
2869.52	2290
2872.09	2386
2874.65	2300
2877.22	2292
2879.78	2394
2882.35	2282
2884.91	2264
2887.47	2324
2890.03	2244
2892.59	2242
2895.15	2314
2897.7	2270
2900.26	2310
2902.81	2308
2905.37	2316
2907.92	2248
2910.47	2254
2913.02	2282
2915.57	2252
2918.12	2266
2920.66	2256
2923.21	2248
2925.75	2242
2928.3	2212
2930.84	2290
2933.38	2236
2935.92	2204
2938.46	2292
2941	2170
2943.54	2184
2946.07	2232
2948.61	2214
2951.14	2190
2953.67	2218
2956.21	2130
2958.74	2218
2961.27	2210
2963.79	2134
2966.32	2108
2968.85	2130
2971.37	2120
2973.9	2160
2976.42	2130
2978.94	2164
2981.46	2144
2983.98	2160
2986.5	2218
2989.02	2098
2991.53	2052
2994.05	2072
2996.56	2100
2999.08	2050
3001.59	2074
3004.1	2062
3006.61	2044
3009.12	2076
3011.63	1992
3014.13	2022
3016.64	2106
3019.14	2058
3021.65	2036
3024.15	2026
3026.65	1976
3029.15	2014
3031.65	2044
3034.15	1984
3036.64	2020
3039.14	2052
3041.63	2027.87
3044.13	2006.19
3046.62	2006.73
3049.11	1978.9
3051.6	1971.44
3054.09	1976.72
3056.58	1998.18
3059.07	1951.87
3061.55	1969.78
3064.04	1944.3
3066.52	1925.14
3069.01	1953.62
3071.49	1927.48
3073.97	1917.19
3076.45	1876.56
3078.93	1890.23
3081.41	1900.08
3083.88	1896.92
3086.36	1923.17
3088.83	1843.03
3091.31	1868.78
3093.78	1888.45
3096.25	1870.62
3098.72	1861.3
3101.19	1841.5
3103.66	1821.47
3106.13	1805.66
3108.59	1823.74
3111.06	1824.2
3113.52	1817.66
3115.98	1790.64
3118.45	1821.28
3120.91	1806.43
3123.37	1822.33
3125.38	1812
3127.85	1782
3130.32	1768
3132.79	1766
3135.26	1784
3137.73	1756
3140.19	1740
3142.66	1746
3145.13	1758
3147.59	1756
3150.05	1778
3152.51	1694
3154.97	1734
3157.43	1716
3159.89	1712
3162.35	1704
3164.8	1680
3167.26	1740
3169.71	1704
3172.17	1698
3174.62	1686
3177.07	1698
3179.52	1666
3181.97	1668
3184.41	1698
3186.86	1632
3189.31	1682
3191.75	1750
3194.2	1692
3196.64	1708
3199.08	1662
3201.52	1694
3203.96	1656
3206.4	1630
3208.84	1650
3211.27	1690
3213.71	1668
3216.14	1670
3218.58	1708
3221.01	1636
3223.44	1642
3225.87	1660
3228.3	1696
3230.73	1620
3233.16	1606
3235.58	1642
3238.01	1640
3240.43	1632
3242.86	1552
3245.28	1600
3247.7	1558
3250.12	1586
3252.54	1586
3254.96	1570
3257.38	1614
3259.79	1586
3262.21	1564
3264.62	1492
3267.04	1556
3269.45	1552
3271.86	1514
3274.27	1578
3276.68	1560
3279.09	1516
3281.49	1518
3283.9	1544
3286.31	1532
3288.71	1498
3291.11	1548
3293.51	1506
3295.92	1560
3298.32	1502
3300.72	1548
3303.11	1476
3305.51	1486
3307.91	1528
3310.3	1496
3312.7	1500
3315.09	1446
3317.48	1440
3319.87	1468
3322.26	1496
3324.65	1518
3327.04	1474
3329.43	1492
3331.81	1446
3334.2	1458
3336.58	1504
3338.97	1458
3341.35	1454
3343.73	1486
3346.11	1458
3348.49	1470
3350.87	1452
3353.25	1472
3355.62	1502
3358	1414
3360.37	1460
3362.75	1442
3365.12	1362
3367.49	1440
3369.86	1428
3372.23	1430
3374.6	1416
3376.97	1448
3379.33	1394
3381.7	1402
3384.06	1404
3386.43	1384
3388.79	1430
3391.15	1392
3393.51	1426
3395.87	1382
3398.23	1380
3400.59	1342
3402.94	1300
3405.3	1398
3407.65	1362
3410.01	1392
3412.36	1368
3414.71	1380
3417.06	1384
3419.41	1360
3421.76	1342
3424.11	1356
3426.46	1326
3428.8	1352
3431.15	1348
3433.49	1316
3435.83	1348
3438.18	1328
3440.52	1320
3442.86	1356
3445.2	1316
3447.53	1366
3449.87	1326
3452.21	1260
3454.54	1314
3456.88	1282
3459.21	1322
3461.54	1312
3463.88	1308
3466.21	1252
3468.53	1264
3470.86	1298
3473.19	1296
3475.52	1300
3477.84	1310
3480.17	1240
3482.49	1314
3484.82	1272
3487.14	1306
3489.46	1320
3491.78	1278
3494.1	1242
3496.42	1262
3498.73	1286
3501.05	1282
3503.36	1282
3505.68	1280
3507.99	1238
3510.3	1240
3512.61	1272
3514.92	1210
3517.23	1262
3519.54	1232
3521.85	1264
3524.16	1246
3526.46	1240
3528.77	1230
3531.07	1252
3533.37	1232
3535.68	1216
3537.98	1230
3540.28	1228
3542.58	1240
3544.87	1238
3547.17	1256
3549.47	1178
3551.76	1250
3554.06	1204
3556.35	1186
3558.64	1234
3560.93	1210
3563.22	1240
3565.51	1182
3567.8	1204
3570.09	1206
3572.38	1236
3574.66	1212
3576.95	1202
3579.23	1192
3581.51	1162
3583.8	1140
3586.08	1150
3588.36	1176
3590.64	1186
3592.92	1152
3595.19	1186
3597.47	1122
3599.75	1162
3602.02	1162
3604.29	1126
3606.57	1142
3608.84	1156
3611.11	1146
3613.38	1140
3615.65	1120
3617.92	1150
3620.18	1138
3622.45	1118
3624.71	1138
3626.98	1132
3629.24	1134
3631.5	1126
3633.77	1100
3636.03	1072
3638.29	1096
3640.55	1092
3642.8	1100
3645.06	1104
3647.32	1088
3649.57	1154
3651.83	1078
3654.08	1108
3656.33	1126
3658.58	1088
3660.83	1110
3663.08	1096
3665.33	1090
3667.58	1074
3669.83	1118
3672.07	1100
3674.32	1082
3676.56	1132
3678.8	1084
3681.05	1076
3683.29	1100
3685.53	1052
3687.77	1080
3690.01	1106
3692.24	1092
3694.48	1094
3696.72	1074
3698.95	1078
3701.19	1094
3703.42	1068
3705.65	1066
3707.88	1020
3710.11	1036
3712.34	1070
3714.57	1024
3716.8	1058
3719.03	1038
3721.25	1082
3723.48	1044
3725.7	1056
3727.92	996
3730.15	1052
3732.37	1046
3734.59	1052
3736.81	1048
3739.03	1040
3741.24	1008
3743.46	1000
3745.68	1056
3747.89	1024
3750.11	1040
3752.32	1004
3754.53	1004
3756.74	1004
3758.95	1000
3761.16	1000
3763.37	1000.06
3765.58	1014.07
3767.79	981.419
3769.99	1000.43
3772.2	993.57
3774.4	1009.76
3776.61	985.88
3778.81	974.761
3781.01	979.904
3783.21	1003.3
3785.41	1028.66
3787.61	1003.29
3789.81	1005.71
3792	995.253
3794.2	993.591
3796.4	986.537
3798.59	981.593
3800.78	974
3802.98	988.68
3805.17	992.626
3807.36	981.096
3809.55	960.487
3811.74	983.552
3813.93	983.029
3816.11	958.937
3818.3	967.448
3820.49	972.424
3822.67	968.433
3824.85	959.155
3827.04	958.526
3829.22	952.458
3831.4	970.747
3833.58	943.534
3835.76	958.936
3837.94	943.602
3839.98	974
3842.17	958
3844.36	954
3846.55	894
3848.73	908
3850.92	938
3853.1	912
3855.29	918
3857.47	938
3859.65	938
3861.84	926
3864.02	884
3866.2	894
3868.38	908
3870.55	930
3872.73	904
3874.91	920
3877.08	964
3879.26	924
3881.43	916
3883.6	940
3885.78	938
3887.95	938
3890.12	948
3892.29	924
3894.46	918
3896.63	898
3898.79	912
3900.96	910
3903.12	910
3905.29	892
3907.45	920
3909.61	906
3911.78	878
3913.94	898
3916.1	884
3918.26	896
3920.41	884
3922.57	912
3924.73	914
3926.88	932
3929.04	882
3931.19	920
3933.35	880
3935.5	900
3937.65	878
3939.8	880
3941.95	886
3944.1	878
3946.25	866
3948.4	910
3950.54	864
3952.69	896
3954.83	866
3956.98	858
3959.12	874
3961.26	876
3963.4	868
3965.54	870
3967.68	844
3969.82	858
3971.96	854
3974.1	822
3976.23	866
3978.37	866
3980.5	840
3982.64	824
3984.77	854
3986.9	844
3989.03	870
3991.16	830
3993.29	856
3995.42	816
3997.55	826
3999.67	844