File: muestras/mosquito/OR_07.txt
#Acq. time (s)=	10
#Accumulations=	1
#Range (cm-¹)=	200...4000
#Windows=	5
#Autofocus=	Off
#AutoExposure=	Off
#Spike filter=	Off
#Delay time (s)=	0
#Binning=	1
#Readout mode=	Signal
#DeNoise=	Off
#ICS correction=	Off
#Dark correction=	Off
#Inst. Process=	Off
#Instrument=	LabRAM HR Evol
#Detector=	Syncerity OE
#Objective=	x100_VIS
#Grating=	600 (500nm)
#ND Filter=	25%
#Laser=	633nm_Edge
#Hole=	100.021
#Range=	Visible
#Project=	Omar
#Sample=	03-07-23
#Site=	1
#Title=	OR
#Remark=
#Date=	03.07.2023 13:36
#Acquired=	03.07.2023 13:36:36
200.404	2318
204.205	2382
208.003	2354
211.799	2370
215.595	2394
219.387	2360
223.177	2352
226.966	2382
230.752	2448
234.536	2424
238.319	2378
242.1	2524
245.879	2470
249.655	2490
253.431	2482
257.204	2440
260.976	2462
264.744	2466
268.511	2484
272.276	2450
276.04	2442
279.801	2484
283.561	2492
287.318	2476
291.074	2556
294.828	2560
298.581	2528
302.33	2634
306.079	2598
309.825	2624
313.569	2614
317.311	2646
321.052	2578
324.79	2596
328.527	2650
332.261	2658
335.994	2664
339.725	2632
343.454	2698
347.182	2642
350.907	2670
354.631	2646
358.352	2690
362.072	2730
365.789	2672
369.505	2740
373.219	2724
376.93	2730
380.642	2790
384.35	2652
388.056	2698
391.76	2680
395.463	2780
399.164	2728
402.863	2792
406.559	2816
410.254	2726
413.948	2820
417.639	2808
421.329	2834
425.016	2866
428.701	2888
432.386	2928
436.068	2864
439.748	2930
443.426	2922
447.103	2950
450.777	2926
454.45	2844
458.121	2916
461.789	2880
465.457	2952
469.122	2878
472.786	2948
476.447	3006
480.107	3000
483.765	3006
487.421	3034
491.075	3048
494.727	3014
498.377	3040
502.026	3074
505.673	3038
509.318	3022
512.962	3040
516.602	3006
520.242	3008
523.881	2982
527.516	3012
531.149	3032
534.783	3040
538.413	3060
542.041	3000
545.667	2958
549.292	3104
552.915	2982
556.537	3036
560.156	2952
563.773	3020
567.389	3074
571.004	3102
574.615	3046
578.226	3086
581.834	3134
585.44	3050
589.045	3108
592.649	3086
596.25	3126
599.85	3184
603.448	3184
607.042	3152
610.637	3116
614.229	3174
617.819	3166
621.408	3256
624.994	3224
628.58	3278
632.163	3200
635.744	3230
639.324	3282
642.902	3298
646.478	3218
650.052	3270
653.625	3304
657.196	3292
660.764	3256
664.331	3256
667.897	3264
671.46	3238
675.021	3276
678.582	3234
682.14	3306
685.696	3272
689.252	3216
692.804	3272
696.355	3298
699.905	3310
703.451	3276
706.997	3374
710.542	3192
714.083	3340
717.624	3296
721.162	3352
724.7	3460
728.235	3378
731.768	3340
735.301	3332
738.83	3332
742.358	3422
745.885	3390
749.41	3330
752.931	3414
756.453	3392
759.973	3312
763.49	3356
767.006	3350
770.52	3356
774.033	3400
777.543	3400
781.052	3348
784.559	3344
788.064	3470
791.568	3382
795.07	3470
798.57	3386
802.068	3436
805.565	3488
809.061	3452
812.553	3476
816.045	3486
819.535	3524
823.022	3492
826.508	3496
829.993	3484
833.476	3510
836.957	3530
840.436	3600
843.914	3536
847.391	3556
850.864	3502
854.337	3626
857.807	3600
861.277	3626
864.744	3616
868.209	3564
871.674	3608
875.136	3628
878.597	3584
882.056	3574
885.512	3600
888.967	3502
892.421	3554
895.874	3690
899.323	3556
902.771	3514
906.219	3610
909.664	3510
913.107	3542
916.55	3502
919.99	3538
923.428	3540
926.863	3542
930.299	3606
933.732	3588
937.164	3632
940.593	3566
944.022	3648
947.448	3688
950.874	3644
954.296	3618
957.718	3634
961.137	3666
964.555	3684
967.972	3620
971.387	3680
974.8	3644
978.21	3762
981.62	3640
985.029	3710
988.435	3754
991.839	3706
995.243	3704
998.644	3644
1002.04	3762
1005.44	3726
1008.84	3730
1012.23	3670
1015.63	3734
1019.02	3788
1022.41	3744
1025.79	3748
1029.18	3772
1032.56	3810
1035.95	3748
1039.33	3852
1042.71	3830
1046.09	3856
1049.46	3846
1052.84	3888
1056.21	3880
1059.58	3884
1062.95	3940
1066.32	3764
1069.69	3878
1073.05	3864
1076.41	3890
1079.78	3842
1083.14	3896
1086.49	3816
1089.85	3882
1093.21	3878
1096.56	3760
1099.91	3810
1103.26	3888
1106.61	3772
1109.96	3852
1113.3	3846
1116.64	3884
1119.99	3834
1123.33	3860
1126.66	3922
1130	3844
1133.34	3836
1136.67	3828
1140	3936
1143.33	3884
1146.66	3904
1149.99	3958
1153.32	3894
1156.64	4008
1159.96	3952
1163.28	3972
1166.6	3930
1169.92	4018
1173.23	4026
1176.55	3966
1179.86	4028
1183.17	3994
1186.48	3984
1189.79	4006
1193.1	3984
1196.4	3976
1199.7	4004
1203	3944
1206.3	3996
1209.6	3930
1212.9	3960
1216.19	3942
1219.49	3978
1222.78	3988
1226.07	3994
1229.36	3980
1232.65	3954
1235.93	3970
1239.21	4010
1242.5	3978
1245.78	3920
1249.06	4042
1252.33	3976
1255.61	3918
1258.88	3988
1262.16	4036
1265.43	4032
1268.7	4054
1271.96	4062
1275.23	4042
1278.5	4058
1281.76	4009.62
1285.02	4066.07
1288.28	4040.05
1291.54	4099.43
1294.8	4091.33
1298.05	4173.37
1301.31	4137.8
1304.56	4171.74
1307.81	4168.04
1311.06	4176.63
1314.3	4201.82
1317.55	4231.64
1320.79	4160.18
1324.04	4211.07
1327.28	4206.36
1330.52	4247.84
1333.76	4264.19
1336.99	4273.3
1340.23	4329.93
1343.46	4280.72
1346.69	4298.97
1349.92	4297.99
1353.15	4321.36
1356.38	4255.8
1359.6	4254.64
1362.83	4305.26
1366.05	4327.51
1369.27	4329.88
1372.49	4365.99
1375.71	4406.77
1378.93	4341.69
1382.14	4372.9
1385.35	4352.37
1388.57	4326.1
1391.2	4392
1394.43	4304
1397.65	4324
1400.87	4342
1404.09	4326
1407.31	4342
1410.53	4216
1413.74	4344
1416.96	4382
1420.17	4322
1423.38	4310
1426.59	4298
1429.8	4314
1433.01	4230
1436.21	4336
1439.42	4350
1442.62	4374
1445.82	4300
1449.02	4240
1452.22	4342
1455.41	4250
1458.61	4406
1461.8	4290
1464.99	4394
1468.18	4384
1471.37	4414
1474.56	4310
1477.74	4376
1480.93	4362
1484.11	4412
1487.29	4352
1490.47	4362
1493.65	4416
1496.82	4390
1500	4342
1503.17	4290
1506.34	4376
1509.51	4274
1512.68	4354
1515.85	4386
1519.02	4396
1522.18	4298
1525.34	4316
1528.51	4406
1531.67	4314
1534.82	4364
1537.98	4424
1541.14	4316
1544.29	4384
1547.44	4264
1550.59	4364
1553.74	4300
1556.89	4404
1560.04	4444
1563.18	4320
1566.33	4338
1569.47	4344
1572.61	4394
1575.75	4374
1578.89	4390
1582.02	4330
1585.16	4388
1588.29	4462
1591.42	4352
1594.55	4360
1597.68	4352
1600.81	4284
1603.94	4392
1607.06	4366
1610.18	4334
1613.3	4460
1616.42	4388
1619.54	4292
1622.66	4300
1625.78	4422
1628.89	4338
1632	4354
1635.11	4314
1638.22	4322
1641.33	4374
1644.44	4262
1647.55	4208
1650.65	4206
1653.75	4098
1656.85	4192
1659.95	4186
1663.05	4100
1666.15	4080
1669.24	4078
1672.34	4092
1675.43	4054
1678.52	4064
1681.61	4064
1684.7	4008
1687.78	4010
1690.87	4028
1693.95	3996
1697.03	3990
1700.12	3942
1703.2	3996
1706.27	4014
1709.35	4032
1712.42	3956
1715.5	3960
1718.57	3954
1721.64	3956
1724.71	3896
1727.78	4002
1730.84	3934
1733.91	3878
1736.97	3942
1740.04	3954
1743.1	3936
1746.16	3974
1749.21	3892
1752.27	3986
1755.33	3946
1758.38	3930
1761.43	3988
1764.48	3956
1767.53	3932
1770.58	3980
1773.63	3944
1776.67	3892
1779.71	3964
1782.76	3970
1785.8	3930
1788.84	3976
1791.88	3958
1794.91	3898
1797.95	4016
1800.98	3800
1804.01	3884
1807.04	3878
1810.07	3898
1813.1	3934
1816.13	3900
1819.15	3920
1822.18	3838
1825.2	3916
1828.22	3988
1831.24	3918
1834.26	3840
1837.28	3918
1840.29	3870
1843.31	3872
1846.32	3828
1849.33	3840
1852.34	3792
1855.35	3812
1858.36	3700
1861.36	3808
1864.36	3774
1867.37	3696
1870.37	3726
1873.37	3784
1876.37	3806
1879.37	3802
1882.36	3772
1885.36	3806
1888.35	3684
1891.34	3806
1894.33	3734
1897.32	3794
1900.31	3804
1903.3	3776
1906.28	3732
1909.26	3722
1912.25	3776
1915.23	3752
1918.21	3730
1921.18	3724
1924.16	3728
1927.14	3740
1930.11	3792
1933.08	3724
1936.05	3750
1939.02	3768
1941.99	3744
1944.96	3736
1947.92	3778
1950.89	3678
1953.85	3684
1956.81	3750
1959.77	3642
1962.73	3708
1965.69	3688
1968.65	3618
1971.6	3644
1974.55	3654
1977.51	3686
1980.46	3678
1983.41	3640
1986.35	3632
1989.3	3690
1992.25	3654
1995.19	3600
1998.13	3612
2001.07	3614
2004.01	3540
2006.95	3612
2009.89	3590
2012.82	3556
2015.76	3610
2018.69	3614
2021.62	3594
2024.55	3654
2027.48	3640
2030.41	3572
2033.34	3596
2036.26	3638
2039.19	3574
2042.11	3588
2045.03	3578
2047.95	3498
2050.87	3568
2053.79	3560
2056.7	3572
2059.61	3464
2062.53	3512
2065.44	3530
2068.35	3490
2071.26	3512
2074.17	3590
2077.07	3574
2079.98	3528
2082.88	3522
2085.78	3494
2088.68	3538
2091.58	3438
2094.48	3412
2097.38	3480
2100.28	3422
2103.17	3460
2106.06	3374
2108.96	3426
2111.85	3452
2114.73	3420
2117.62	3412
2120.51	3424
2123.39	3370
2126.28	3376
2129.16	3356
2132.04	3380
2134.92	3398
2137.8	3396
2140.68	3436
2143.55	3382
2146.43	3430
2149.3	3374
2152.17	3392
2155.04	3374
2157.91	3408
2160.78	3354
2163.65	3334
2166.51	3358
2169.38	3364
2172.24	3270
2175.1	3324
2177.96	3288
2180.82	3284
2183.68	3306
2186.53	3288
2189.39	3262
2192.24	3290
2195.09	3200
2197.95	3332
2200.8	3152
2203.64	3312
2206.49	3214
2209.34	3208
2212.18	3220
2215.03	3154
2217.87	3206
2220.71	3208.66
2223.55	3143.82
2226.39	3216.98
2229.22	3167.13
2232.06	3250.26
2234.89	3210.49
2237.73	3236.19
2240.56	3187.86
2243.39	3204.2
2246.22	3208.67
2249.05	3255.66
2251.87	3227.86
2254.7	3204.32
2257.52	3211.02
2260.34	3236.05
2263.17	3211.48
2265.99	3179.93
2268.8	3276.08
2271.62	3228.47
2274.44	3200.02
2277.25	3228.01
2280.07	3227.47
2282.88	3224.19
2285.69	3168.16
2288.5	3222.52
2291.31	3212.56
2294.12	3222.93
2296.92	3200
2299.73	3203.15
2302.53	3198.74
2305.34	3215.15
2308.14	3240.02
2310.94	3177.45
2313.74	3205.74
2315.86	3214
2318.67	3204
2321.48	3182
2324.29	3160
2327.09	3146
2329.9	3216
2332.7	3166
2335.51	3192
2338.31	3166
2341.11	3218
2343.91	3206
2346.71	3174
2349.51	3184
2352.3	3182
2355.1	3210
2357.89	3166
2360.68	3200
2363.48	3204
2366.27	3144
2369.05	3170
2371.84	3114
2374.63	3134
2377.41	3130
2380.2	3186
2382.98	3162
2385.76	3130
2388.54	3118
2391.32	3130
2394.1	3180
2396.87	3096
2399.65	3116
2402.42	3124
2405.2	3108
2407.97	3052
2410.74	3142
2413.51	3070
2416.27	3186
2419.04	3064
2421.81	3054
2424.57	3094
2427.33	3024
2430.1	3048
2432.85	2982
2435.61	3058
2438.37	3082
2441.13	3020
2443.88	3034
2446.64	2988
2449.39	3056
2452.14	2998
2454.89	3028
2457.64	3020
2460.39	3016
2463.14	3040
2465.88	3030
2468.63	2966
2471.37	3022
2474.11	2980
2476.86	3044
2479.59	2996
2482.33	3000
2485.07	2972
2487.81	2992
2490.54	2966
2493.28	2972
2496.01	3062
2498.74	2988
2501.47	2926
2504.2	2942
2506.93	2948
2509.65	2938
2512.38	2984
2515.1	2988
2517.82	2968
2520.55	2860
2523.27	2930
2525.99	2908
2528.7	2932
2531.42	2904
2534.14	2960
2536.85	2946
2539.56	2908
2542.28	2890
2544.99	2892
2547.7	2886
2550.4	2912
2553.11	2930
2555.82	2840
2558.52	2916
2561.23	2866
2563.93	2820
2566.63	2842
2569.33	2860
2572.03	2870
2574.73	2812
2577.42	2834
2580.12	2810
2582.81	2814
2585.51	2868
2588.2	2844
2590.89	2796
2593.58	2740
2596.26	2778
2598.95	2772
2601.64	2794
2604.32	2744
2607.01	2790
2609.69	2792
2612.37	2770
2615.05	2794
2617.73	2724
2620.41	2768
2623.08	2788
2625.76	2662
2628.43	2714
2631.1	2774
2633.78	2788
2636.45	2722
2639.12	2682
2641.78	2734
2644.45	2688
2647.12	2714
2649.78	2680
2652.45	2730
2655.11	2696
2657.77	2662
2660.43	2698
2663.09	2690
2665.75	2646
2668.4	2670
2671.06	2722
2673.71	2600
2676.37	2734
2679.02	2694
2681.67	2608
2684.32	2622
2686.97	2636
2689.61	2698
2692.26	2684
2694.9	2612
2697.55	2610
2700.19	2612
2702.83	2658
2705.47	2664
2708.11	2574
2710.75	2656
2713.39	2592
2716.02	2524
2718.66	2586
2721.29	2598
2723.92	2514
2726.55	2588
2729.18	2538
2731.81	2558
2734.44	2562
2737.07	2524
2739.69	2540
2742.32	2550
2744.94	2546
2747.56	2598
2750.18	2510
2752.8	2532
2755.42	2524
2758.04	2530
2760.65	2512
2763.27	2502
2765.88	2574
2768.5	2428
2771.11	2492
2773.72	2534
2776.33	2496
2778.94	2424
2781.54	2464
2784.15	2444
2786.75	2454
2789.36	2460
2791.96	2392
2794.56	2414
2797.16	2456
2799.76	2414
2802.36	2434
2804.96	2420
2807.55	2388
2810.15	2456
2812.74	2398
2815.33	2406
2817.93	2432
2820.52	2430
2823.11	2314
2825.69	2430
2828.28	2396
2830.87	2382
2833.45	2368
2836.03	2380
2838.62	2390
2841.2	2368
2843.78	2336
2846.36	2360
2848.93	2380
2851.51	2276
2854.09	2286
2856.66	2304
2859.24	2330
2861.81	2290
2864.38	2320
2866.95	2308
2869.52	2310
2872.09	2250
2874.65	2320
2877.22	2206
2879.78	2288
2882.35	2282
2884.91	2288
2887.47	2274
2890.03	2264
2892.59	2270
2895.15	2214
2897.7	2264
2900.26	2236
2902.81	2238
2905.37	2286
2907.92	2172
2910.47	2196
2913.02	2218
2915.57	2256
2918.12	2218
2920.66	2150
2923.21	2204
2925.75	2278
2928.3	2162
2930.84	2170
2933.38	2170
2935.92	2182
2938.46	2146
2941	2222
2943.54	2182
2946.07	2208
2948.61	2164
2951.14	2154
2953.67	2148
2956.21	2132
2958.74	2128
2961.27	2228
2963.79	2132
2966.32	2172
2968.85	2120
2971.37	2122
2973.9	2116
2976.42	2060
2978.94	2134
2981.46	2080
2983.98	2140
2986.5	2068
2989.02	2076
2991.53	2032
2994.05	2008
2996.56	2036
2999.08	2048
3001.59	2008
3004.1	2002
3006.61	2018
3009.12	1976
3011.63	1964
3014.13	1944
3016.64	2024
3019.14	1918
3021.65	1970
3024.15	2026
3026.65	1968
3029.15	1976
3031.65	2266
3034.15	1958
3036.64	1954
3039.14	1912
3041.63	1962.46
3044.13	1942.14
3046.62	1986.97
3049.11	1914.74
3051.6	1927.23
3054.09	1889.99
3056.58	1945.71
3059.07	1911.63
3061.55	1906.05
3064.04	1937.98
3066.52	1904.58
3069.01	1893.61
3071.49	1845.31
3073.97	1917.57
3076.45	1899.74
3078.93	1889
3081.41	1837.86
3083.88	1879.85
3086.36	1860.9
3088.83	1834.26
3091.31	1847.34
3093.78	1832.84
3096.25	1849.52
3098.72	1804.36
3101.19	1810.42
3103.66	1794.24
3106.13	1816.44
3108.59	1801.6
3111.06	1799.95
3113.52	1763.73
3115.98	1759.23
3118.45	1761.66
3120.91	1747.83
3123.37	1761.5
3125.38	1712
3127.85	1762
3130.32	1752
3132.79	1730
3135.26	1724
3137.73	1678
3140.19	1748
3142.66	1708
3145.13	1748
3147.59	1686
3150.05	1698
3152.51	1714
3154.97	1748
3157.43	1670
3159.89	1706
3162.35	2016
3164.8	1682
3167.26	1670
3169.71	1664
3172.17	1678
3174.62	1730
3177.07	1666
3179.52	1674
3181.97	1662
3184.41	1638
3186.86	1654
3189.31	1676
3191.75	1606
3194.2	1652
3196.64	1628
3199.08	1648
3201.52	1660
3203.96	1650
3206.4	1608
3208.84	1648
3211.27	1610
3213.71	1626
3216.14	1586
3218.58	1658
3221.01	1614
3223.44	1580
3225.87	1580
3228.3	1584
3230.73	1626
3233.16	1602
3235.58	1596
3238.01	1616
3240.43	1634
3242.86	1584
3245.28	1590
3247.7	1590
3250.12	1560
3252.54	1544
3254.96	1546
3257.38	1522
3259.79	1554
3262.21	1582
3264.62	1542
3267.04	1514
3269.45	1572
3271.86	1570
3274.27	1544
3276.68	1508
3279.09	1482
3281.49	1548
3283.9	1526
3286.31	1480
3288.71	1488
3291.11	1526
3293.51	1452
3295.92	1558
3298.32	1482
3300.72	1458
3303.11	1474
3305.51	1508
3307.91	1532
3310.3	1534
3312.7	1486
3315.09	1448
3317.48	1462
3319.87	1424
3322.26	1466
3324.65	1472
3327.04	1480
3329.43	1472
3331.81	1446
3334.2	1438
3336.58	1464
3338.97	1420
3341.35	1406
3343.73	1412
3346.11	1414
3348.49	1408
3350.87	1480
3353.25	1458
3355.62	1402
3358	1346
3360.37	1418
3362.75	1462
3365.12	1408
3367.49	1394
3369.86	1412
3372.23	1378
3374.6	1434
3376.97	1426
3379.33	1420
3381.7	1368
3384.06	1390
3386.43	1374
3388.79	1354
3391.15	1362
3393.51	1334
3395.87	1422
3398.23	1328
3400.59	1374
3402.94	1380
3405.3	1342
3407.65	1352
3410.01	1352
3412.36	1320
3414.71	1302
3417.06	1322
3419.41	1316
3421.76	1358
3424.11	1330
3426.46	1308
3428.8	1344
3431.15	1322
3433.49	1340
3435.83	1324
3438.18	1300
3440.52	1308
3442.86	1288
3445.2	1318
3447.53	1350
3449.87	1286
3452.21	1288
3454.54	1294
3456.88	1286
3459.21	1266
3461.54	1230
3463.88	1266
3466.21	1308
3468.53	1278
3470.86	1312
3473.19	1282
3475.52	1284
3477.84	1272
3480.17	1248
3482.49	1268
3484.82	1244
3487.14	1246
3489.46	1266
3491.78	1286
3494.1	1236
3496.42	1194
3498.73	1232
3501.05	1244
3503.36	1232
3505.68	1214
3507.99	1260
3510.3	1258
3512.61	1236
3514.92	1246
3517.23	1240
3519.54	1236
3521.85	1228
3524.16	1248
3526.46	1216
3528.77	1268
3531.07	1234
3533.37	1232
3535.68	1200
3537.98	1170
3540.28	1202
3542.58	1232
3544.87	1222
3547.17	1208
3549.47	1194
3551.76	1228
3554.06	1220
3556.35	1190
3558.64	1220
3560.93	1194
3563.22	1188
3565.51	1170
3567.8	1196
3570.09	1180
3572.38	1180
3574.66	1220
3576.95	1218
3579.23	1154
3581.51	1172
3583.8	1194
3586.08	1176
3588.36	1188
3590.64	1156
3592.92	1124
3595.19	1150
3597.47	1148
3599.75	1122
3602.02	1142
3604.29	1148
3606.57	1104
3608.84	1168
3611.11	1160
3613.38	1116
3615.65	1134
3617.92	1142
3620.18	1118
3622.45	1128
3624.71	1170
3626.98	1130
3629.24	1132
3631.5	1170
3633.77	1090
3636.03	1138
3638.29	1106
3640.55	1108
3642.8	1098
3645.06	1082
3647.32	1092
3649.57	1088
3651.83	1106
3654.08	1096
3656.33	1132
3658.58	1082
3660.83	1062
3663.08	1118
3665.33	1078
3667.58	1060
3669.83	1062
3672.07	1058
3674.32	1068
3676.56	1022
3678.8	1082
3681.05	1108
3683.29	1048
3685.53	1066
3687.77	1054
3690.01	1040
3692.24	1106
3694.48	1064
3696.72	1068
3698.95	1056
3701.19	1004
3703.42	1046
3705.65	1060
3707.88	1020
3710.11	1048
3712.34	994
3714.57	1062
3716.8	1032
3719.03	1022
3721.25	1070
3723.48	1036
3725.7	1014
3727.92	1018
3730.15	1050
3732.37	1016
3734.59	1004
3736.81	1020
3739.03	998
3741.24	1036
3743.46	1022
3745.68	992
3747.89	1022
3750.11	1012
3752.32	1032
3754.53	984
3756.74	968
3758.95	968
3761.16	1014
3763.37	1029.93
3765.58	1013.33
3767.79	1005.24
3769.99	994.56
3772.2	1016.38
3774.4	986.656
3776.61	1003.64
3778.81	972.939
3781.01	988.724
3783.21	966.333
3785.41	1004.94
3787.61	963.193
3789.81	990.274
3792	977.824
3794.2	959.761
3796.4	989.37
3798.59	981.993
3800.78	975.875
3802.98	984.065
3805.17	958.828
3807.36	965.013
3809.55	959.711
3811.74	969.852
3813.93	953.944
3816.11	967.551
3818.3	961.561
3820.49	962.057
3822.67	946.477
3824.85	964.321
3827.04	942.646
3829.22	966.911
3831.4	964.931
3833.58	921.495
3835.76	940.549
3837.94	910.295
3839.98	932
3842.17	928
3844.36	890
3846.55	928
3848.73	938
3850.92	950
3853.1	890
3855.29	950
3857.47	934
3859.65	936
3861.84	906
3864.02	906
3866.2	896
3868.38	908
3870.55	910
3872.73	942
3874.91	886
3877.08	916
3879.26	878
3881.43	932
3883.6	918
3885.78	870
3887.95	936
3890.12	890
3892.29	916
3894.46	932
3896.63	872
3898.79	852
3900.96	924
3903.12	892
3905.29	938
3907.45	914
3909.61	932
3911.78	902
3913.94	876
3916.1	840
3918.26	882
3920.41	880
3922.57	898
3924.73	878
3926.88	874
3929.04	914
3931.19	886
3933.35	894
3935.5	888
3937.65	874
3939.8	870
3941.95	902
3944.1	886
3946.25	866
3948.4	882
3950.54	828
3952.69	866
3954.83	884
3956.98	842
3959.12	840
3961.26	894
3963.4	844
3965.54	888
3967.68	854
3969.82	860
3971.96	862
3974.1	856
3976.23	844
3978.37	860
3980.5	854
3982.64	860
3984.77	858
3986.9	846
3989.03	836
3991.16	826
3993.29	856
3995.42	832
3997.55	826
3999.67	878