File: muestras/mosquito/OR_02.txt
#Acq. time (s)=	10
#Accumulations=	1
#Range (cm-¹)=	200...4000
#Windows=	5
#Autofocus=	Off
#AutoExposure=	Off
#Spike filter=	Off
#Delay time (s)=	0
#Binning=	1
#Readout mode=	Signal
#DeNoise=	Off
#ICS correction=	Off
#Dark correction=	Off
#Inst. Process=	Off
#Instrument=	LabRAM HR Evol
#Detector=	Syncerity OE
#Objective=	x100_VIS
#Grating=	600 (500nm)
#ND Filter=	25%
#Laser=	633nm_Edge
#Hole=	100.021
#Range=	Visible
#Project=	Omar
#Sample=	03-07-23
#Site=	1
#Title=	OR
#Remark=
#Date=	03.07.2023 13:27
#Acquired=	03.07.2023 13:27:24
200.404	5146
204.205	5198
208.003	5136
211.799	5168
215.595	5158
219.387	5170
223.177	5184
226.966	5242
230.752	5322
234.536	5274
238.319	5386
242.1	5388
245.879	5368
249.655	5486
253.431	5442
257.204	5390
260.976	5386
264.744	5338
268.511	5440
272.276	5490
276.04	5478
279.801	5430
283.561	5476
287.318	5514
291.074	5608
294.828	5596
298.581	5596
302.33	5706
306.079	5662
309.825	5652
313.569	5744
317.311	5832
321.052	5760
324.79	5796
328.527	5850
332.261	5754
335.994	5908
339.725	5782
343.454	5820
347.182	5880
350.907	6008
354.631	5986
358.352	5842
362.072	6026
365.789	6084
369.505	6024
373.219	5964
376.93	5912
380.642	5928
384.35	5942
388.056	6048
391.76	5994
395.463	6154
399.164	6074
402.863	6130
406.559	6172
410.254	6166
413.948	6242
417.639	6244
421.329	6300
425.016	6452
428.701	6438
432.386	6410
436.068	6520
439.748	6494
443.426	6550
447.103	6436
450.777	6496
454.45	6444
458.121	6508
461.789	6574
465.457	6524
469.122	6598
472.786	6622
476.447	6634
480.107	6608
483.765	6632
487.421	6740
491.075	6748
494.727	6774
498.377	6884
502.026	6822
505.673	6890
509.318	6856
512.962	6816
516.602	6942
520.242	6830
523.881	6822
527.516	6872
531.149	6842
534.783	6852
538.413	6794
542.041	6826
545.667	6796
549.292	6830
552.915	6904
556.537	6956
560.156	6872
563.773	6940
567.389	6916
571.004	6952
574.615	7052
578.226	7032
581.834	7086
585.44	7126
589.045	7042
592.649	7162
596.25	7046
599.85	7082
603.448	7138
607.042	7178
610.637	7316
614.229	7320
617.819	7260
621.408	7248
624.994	7414
628.58	7414
632.163	7498
635.744	7478
639.324	7484
642.902	7454
646.478	7548
650.052	7428
653.625	7604
657.196	7562
660.764	7558
664.331	7536
667.897	7672
671.46	7588
675.021	7506
678.582	7572
682.14	7572
685.696	7538
689.252	7584
692.804	7600
696.355	7668
699.905	7616
703.451	7724
706.997	7798
710.542	7706
714.083	7676
717.624	7696
721.162	7714
724.7	7770
728.235	7912
731.768	7756
735.301	7810
738.83	7882
742.358	7878
745.885	7850
749.41	7892
752.931	7854
756.453	7954
759.973	7996
763.49	7830
767.006	7844
770.52	7728
774.033	7874
777.543	7896
781.052	7924
784.559	7980
788.064	7854
791.568	7976
795.07	8000
798.57	7990
802.068	8070
805.565	8096
809.061	8028
812.553	8104
816.045	7910
819.535	8048
823.022	8140
826.508	8150
829.993	8180
833.476	8250
836.957	8244
840.436	8228
843.914	8274
847.391	8344
850.864	8278
854.337	8268
857.807	8336
861.277	8342
864.744	8320
868.209	8554
871.674	8462
875.136	8328
878.597	8354
882.056	8412
885.512	8408
888.967	8402
892.421	8340
895.874	8480
899.323	8324
902.771	8302
906.219	8398
909.664	8344
913.107	8318
916.55	8376
919.99	8376
923.428	8494
926.863	8318
930.299	8454
933.732	8404
937.164	8430
940.593	8496
944.022	8432
947.448	8558
950.874	8654
954.296	8596
957.718	8546
961.137	8682
964.555	8558
967.972	8606
971.387	8750
974.8	8708
978.21	8576
981.62	8612
985.029	8678
988.435	8618
991.839	8590
995.243	8676
998.644	8634
1002.04	8620
1005.44	8666
1008.84	8706
1012.23	8642
1015.63	8648
1019.02	8716
1022.41	8782
1025.79	8768
1029.18	8746
1032.56	8748
1035.95	8816
1039.33	8864
1042.71	8846
1046.09	8932
1049.46	8944
1052.84	8942
1056.21	8932
1059.58	8938
1062.95	9070
1066.32	9000
1069.69	9054
1073.05	8940
1076.41	8884
1079.78	9056
1083.14	8878
1086.49	8844
1089.85	8882
1093.21	8954
1096.56	8954
1099.91	8824
1103.26	8776
1106.61	8828
1109.96	8790
1113.3	8702
1116.64	8826
1119.99	8692
1123.33	8880
1126.66	8802
1130	8890
1133.34	8850
1136.67	8818
1140	8876
1143.33	8888
1146.66	8954
1149.99	8930
1153.32	8896
1156.64	9040
1159.96	9106
1163.28	9076
1166.6	9020
1169.92	9048
1173.23	9138
1176.55	9116
1179.86	9026
1183.17	8986
1186.48	8910
1189.79	9008
1193.1	9022
1196.4	9012
1199.7	8980
1203	8908
1206.3	8844
1209.6	8902
1212.9	8902
1216.19	8796
1219.49	8792
1222.78	8716
1226.07	8714
1229.36	8842
1232.65	8738
1235.93	8858
1239.21	8948
1242.5	8886
1245.78	8942
1249.06	8826
1252.33	8896
1255.61	8744
1258.88	8954
1262.16	8930
1265.43	8944
1268.7	8988
1271.96	8938
1275.23	8922
1278.5	8884
1281.76	8905.07
1285.02	8873.08
1288.28	8786.61
1291.54	8695.69
1294.8	8816.71
1298.05	8793.32
1301.31	8757.15
1304.56	8662.18
1307.81	8550.69
1311.06	8493.75
1314.3	8516.9
1317.55	8416.73
1320.79	8383.01
1324.04	8264.36
1327.28	8201.27
1330.52	8114.05
1333.76	8186.15
1336.99	8170.97
1340.23	8012.39
1343.46	7954.32
1346.69	7935.98
1349.92	7936.47
1353.15	7832.68
1356.38	7841.83
1359.6	7755.11
1362.83	7679.66
1366.05	7559.77
1369.27	7529.8
1372.49	7465.34
1375.71	7459.59
1378.93	7482.28
1382.14	7334.37
1385.35	7308.89
1388.57	7187.96
1391.2	7290
1394.43	7284
1397.65	7232
1400.87	7292
1404.09	7180
1407.31	7212
1410.53	7160
1413.74	7172
1416.96	7112
1420.17	7086
1423.38	7184
1426.59	7142
1429.8	7022
1433.01	7150
1436.21	7072
1439.42	7060
1442.62	7124
1445.82	7050
1449.02	7156
1452.22	7094
1455.41	7236
1458.61	7054
1461.8	7208
1464.99	7098
1468.18	7094
1471.37	7136
1474.56	7182
1477.74	7210
1480.93	7158
1484.11	7164
1487.29	7122
1490.47	7146
1493.65	7146
1496.82	7092
1500	7044
1503.17	7148
1506.34	7094
1509.51	7128
1512.68	7078
1515.85	7236
1519.02	7096
1522.18	7008
1525.34	7074
1528.51	7126
1531.67	7194
1534.82	7104
1537.98	7054
1541.14	6962
1544.29	7100
1547.44	7018
1550.59	6946
1553.74	7038
1556.89	6990
1560.04	7028
1563.18	6902
1566.33	6942
1569.47	6988
1572.61	7040
1575.75	6988
1578.89	6972
1582.02	6906
1585.16	6980
1588.29	6846
1591.42	6936
1594.55	6830
1597.68	7042
1600.81	6948
1603.94	6954
1607.06	6978
1610.18	7000
1613.3	6894
1616.42	6934
1619.54	6970
1622.66	6994
1625.78	6926
1628.89	6962
1632	6948
1635.11	6928
1638.22	6922
1641.33	6876
1644.44	6888
1647.55	6790
1650.65	6840
1653.75	6868
1656.85	6708
1659.95	6714
1663.05	6706
1666.15	6590
1669.24	6614
1672.34	6578
1675.43	6610
1678.52	6556
1681.61	6582
1684.7	6564
1687.78	6526
1690.87	6520
1693.95	6468
1697.03	6550
1700.12	6516
1703.2	6568
1706.27	6464
1709.35	6390
1712.42	6446
1715.5	6336
1718.57	6488
1721.64	6420
1724.71	6430
1727.78	6442
1730.84	6292
1733.91	6382
1736.97	6264
1740.04	6308
1743.1	6458
1746.16	6432
1749.21	6352
1752.27	6342
1755.33	6338
1758.38	6388
1761.43	6296
1764.48	6334
1767.53	6360
1770.58	6312
1773.63	6200
1776.67	6274
1779.71	6334
1782.76	6344
1785.8	6380
1788.84	6384
1791.88	6278
1794.91	6408
1797.95	6252
1800.98	6328
1804.01	6210
1807.04	6280
1810.07	6258
1813.1	6216
1816.13	6240
1819.15	6220
1822.18	6196
1825.2	6300
1828.22	6116
1831.24	6194
1834.26	6010
1837.28	6100
1840.29	6034
1843.31	6080
1846.32	6138
1849.33	6042
1852.34	6058
1855.35	6108
1858.36	5950
1861.36	5962
1864.36	6034
1867.37	6018
1870.37	5962
1873.37	5970
1876.37	5958
1879.37	5956
1882.36	5966
1885.36	5954
1888.35	5904
1891.34	5894
1894.33	5942
1897.32	5926
1900.31	5948
1903.3	5928
1906.28	5888
1909.26	5976
1912.25	5912
1915.23	5888
1918.21	5878
1921.18	5820
1924.16	5874
1927.14	5864
1930.11	5938
1933.08	5772
1936.05	5944
1939.02	5856
1941.99	5738
1944.96	5844
1947.92	5798
1950.89	5748
1953.85	5778
1956.81	5744
1959.77	5838
1962.73	5730
1965.69	5762
1968.65	5680
1971.6	5650
1974.55	5722
1977.51	5710
1980.46	5648
1983.41	5766
1986.35	5624
1989.3	5560
1992.25	5564
1995.19	5592
1998.13	5612
2001.07	5646
2004.01	5586
2006.95	5600
2009.89	5648
2012.82	5566
2015.76	5536
2018.69	5548
2021.62	5592
2024.55	5560
2027.48	5606
2030.41	5566
2033.34	5566
2036.26	5534
2039.19	5470
2042.11	5606
2045.03	5488
2047.95	5424
2050.87	5436
2053.79	5410
2056.7	5428
2059.61	5442
2062.53	5440
2065.44	5412
2068.35	5390
2071.26	5402
2074.17	5368
2077.07	5454
2079.98	5466
2082.88	5318
2085.78	5406
2088.68	5320
2091.58	5386
2094.48	5396
2097.38	5320
2100.28	5344
2103.17	5286
2106.06	5240
2108.96	5282
2111.85	5238
2114.73	5204
2117.62	5302
2120.51	5252
2123.39	5238
2126.28	5204
2129.16	5226
2132.04	5160
2134.92	5160
2137.8	5146
2140.68	5196
2143.55	5130
2146.43	5180
2149.3	5126
2152.17	5100
2155.04	5094
2157.91	5044
2160.78	5080
2163.65	5064
2166.51	5036
2169.38	4892
2172.24	5012
2175.1	4982
2177.96	5002
2180.82	5014
2183.68	4994
2186.53	4968
2189.39	4920
2192.24	4898
2195.09	4904
2197.95	4954
2200.8	4802
2203.64	4796
2206.49	4784
2209.34	4760
2212.18	4878
2215.03	4766
2217.87	4868
2220.71	4708.09
2223.55	4760.02
2226.39	4750.18
2229.22	4656.49
2232.06	4737
2234.89	4704.53
2237.73	4726.18
2240.56	4729.67
2243.39	4668.29
2246.22	4690.3
2249.05	4619.3
2251.87	4571
2254.7	4604.15
2257.52	4603.95
2260.34	4549.49
2263.17	4605.62
2265.99	4509.6
2268.8	4491.54
2271.62	4507.12
2274.44	4491.19
2277.25	4491.49
2280.07	4412.97
2282.88	4496.43
2285.69	4431.53
2288.5	4496.49
2291.31	4327.44
2294.12	4405.99
2296.92	4392.7
2299.73	4262.7
2302.53	4376.62
2305.34	4347.78
2308.14	4267.21
2310.94	4271.82
2313.74	4313.42
2315.86	4312
2318.67	4328
2321.48	4246
2324.29	4316
2327.09	4208
2329.9	4242
2332.7	4204
2335.51	4196
2338.31	4138
2341.11	4252
2343.91	4202
2346.71	4228
2349.51	4174
2352.3	4196
2355.1	4130
2357.89	4228
2360.68	4180
2363.48	4172
2366.27	4162
2369.05	4114
2371.84	4136
2374.63	4194
2377.41	4216
2380.2	4142
2382.98	4174
2385.76	4098
2388.54	4172
2391.32	4096
2394.1	4106
2396.87	4048
2399.65	4172
2402.42	4112
2405.2	4092
2407.97	4028
2410.74	4092
2413.51	4108
2416.27	4060
2419.04	3962
2421.81	4082
2424.57	4024
2427.33	4040
2430.1	4076
2432.85	4040
2435.61	3970
2438.37	4118
2441.13	3960
2443.88	3946
2446.64	3964
2449.39	3968
2452.14	3912
2454.89	3938
2457.64	3982
2460.39	3948
2463.14	3892
2465.88	3968
2468.63	3912
2471.37	3878
2474.11	3914
2476.86	3846
2479.59	3900
2482.33	3834
2485.07	3862
2487.81	3884
2490.54	3948
2493.28	3858
2496.01	3856
2498.74	3830
2501.47	3860
2504.2	3916
2506.93	3870
2509.65	3878
2512.38	3802
2515.1	3808
2517.82	3852
2520.55	3758
2523.27	3844
2525.99	3850
2528.7	3800
2531.42	3756
2534.14	3760
2536.85	3824
2539.56	3784
2542.28	3680
2544.99	3756
2547.7	3700
2550.4	3744
2553.11	3746
2555.82	3642
2558.52	3636
2561.23	3680
2563.93	3672
2566.63	3612
2569.33	3696
2572.03	3634
2574.73	3660
2577.42	3702
2580.12	3642
2582.81	3700
2585.51	3702
2588.2	3640
2590.89	3648
2593.58	3610
2596.26	3598
2598.95	3628
2601.64	3594
2604.32	3582
2607.01	3566
2609.69	3608
2612.37	3588
2615.05	3622
2617.73	3534
2620.41	3516
2623.08	3482
2625.76	3536
2628.43	3624
2631.1	3546
2633.78	3562
2636.45	3496
2639.12	3398
2641.78	3450
2644.45	3474
2647.12	3522
2649.78	3454
2652.45	3408
2655.11	3390
2657.77	3496
2660.43	3440
2663.09	3378
2665.75	3518
2668.4	3448
2671.06	3396
2673.71	3424
2676.37	3480
2679.02	3412
2681.67	3420
2684.32	3298
2686.97	3394
2689.61	3338
2692.26	3390
2694.9	3368
2697.55	3328
2700.19	3294
2702.83	3296
2705.47	3276
2708.11	3308
2710.75	3302
2713.39	3316
2716.02	3302
2718.66	3282
2721.29	3242
2723.92	3258
2726.55	3282
2729.18	3262
2731.81	3284
2734.44	3174
2737.07	3226
2739.69	3292
2742.32	3168
2744.94	3150
2747.56	3216
2750.18	3132
2752.8	3186
2755.42	3136
2758.04	3132
2760.65	3136
2763.27	3178
2765.88	3182
2768.5	3124
2771.11	3140
2773.72	3112
2776.33	3158
2778.94	3158
2781.54	3076
2784.15	3188
2786.75	3052
2789.36	3080
2791.96	3142
2794.56	3082
2797.16	3102
2799.76	3038
2802.36	3034
2804.96	3118
2807.55	3080
2810.15	3014
2812.74	3004
2815.33	3028
2817.93	2956
2820.52	3016
2823.11	2950
2825.69	3058
2828.28	2938
2830.87	2934
2833.45	3074
2836.03	2978
2838.62	2952
2841.2	2924
2843.78	2938
2846.36	2868
2848.93	2924
2851.51	2878
2854.09	2912
2856.66	2906
2859.24	2858
2861.81	2836
2864.38	2894
2866.95	2924
2869.52	2818
2872.09	2816
2874.65	2888
2877.22	2824
2879.78	2774
2882.35	2776
2884.91	2782
2887.47	2730
2890.03	2854
2892.59	2750
2895.15	2802
2897.7	2766
2900.26	2760
2902.81	2784
2905.37	2784
2907.92	2766
2910.47	2760
2913.02	2738
2915.57	2784
2918.12	2730
2920.66	2746
2923.21	2700
2925.75	2786
2928.3	2744
2930.84	2746
2933.38	2688
2935.92	2678
2938.46	2726
2941	2756
2943.54	2626
2946.07	2662
2948.61	2672
2951.14	2676
2953.67	2638
2956.21	2668
2958.74	2682
2961.27	2620
2963.79	2618
2966.32	2682
2968.85	2604
2971.37	2568
2973.9	2622
2976.42	2630
2978.94	2614
2981.46	2612
2983.98	2544
2986.5	2568
2989.02	2606
2991.53	2550
2994.05	2566
2996.56	2502
2999.08	2596
3001.59	2460
3004.1	2480
3006.61	2540
3009.12	2472
3011.63	2546
3014.13	2498
3016.64	2466
3019.14	2532
3021.65	2544
3024.15	2420
3026.65	2414
3029.15	2424
3031.65	2456
3034.15	2480
3036.64	2444
3039.14	2442
3041.63	2451.29
3044.13	2440.75
3046.62	2368.75
3049.11	2368.97
3051.6	2380.69
3054.09	2319.66
3056.58	2346.1
3059.07	2351.82
3061.55	2362.6
3064.04	2334.67
3066.52	2337.73
3069.01	2329.8
3071.49	2301.68
3073.97	2310.13
3076.45	2300.78
3078.93	2292.26
3081.41	2277.96
3083.88	2239.59
3086.36	2251.77
3088.83	2253.83
3091.31	2195.37
3093.78	2214.96
3096.25	2211.37
3098.72	2196.31
3101.19	2167.86
3103.66	2166.34
3106.13	2136.17
3108.59	2121.44
3111.06	2120.81
3113.52	2117.35
3115.98	2119.08
3118.45	2102.99
3120.91	2128.76
3123.37	2039.6
3125.38	2108
3127.85	2136
3130.32	2022
3132.79	2112
3135.26	2030
3137.73	2042
3140.19	2014
3142.66	2008
3145.13	2044
3147.59	1998
3150.05	2016
3152.51	1986
3154.97	1992
3157.43	1950
3159.89	1984
3162.35	1992
3164.8	1972
3167.26	1984
3169.71	1958
3172.17	1948
3174.62	1940
3177.07	1948
3179.52	1978
3181.97	1958
3184.41	2008
3186.86	1958
3189.31	1928
3191.75	1904
3194.2	1930
3196.64	1962
3199.08	1912
3201.52	1982
3203.96	1932
3206.4	1930
3208.84	1936
3211.27	1920
3213.71	1896
3216.14	1914
3218.58	1890
3221.01	1906
3223.44	1878
3225.87	1904
3228.3	1954
3230.73	1908
3233.16	1888
3235.58	1882
3238.01	1848
3240.43	1824
3242.86	1898
3245.28	1862
3247.7	1826
3250.12	1882
3252.54	1882
3254.96	1868
3257.38	1826
3259.79	1840
3262.21	1856
3264.62	1834
3267.04	1774
3269.45	1770
3271.86	1838
3274.27	1784
3276.68	1720
3279.09	1780
3281.49	1756
3283.9	1726
3286.31	1772
3288.71	1754
3291.11	1742
3293.51	1760
3295.92	1756
3298.32	1698
3300.72	1762
3303.11	1746
3305.51	1724
3307.91	1744
3310.3	1746
3312.7	1692
3315.09	1716
3317.48	1690
3319.87	1650
3322.26	1738
3324.65	1716
3327.04	1692
3329.43	1676
3331.81	1700
3334.2	1720
3336.58	1720
3338.97	1694
3341.35	1654
3343.73	1740
3346.11	1658
3348.49	1724
3350.87	1640
3353.25	1648
3355.62	1670
3358	1636
3360.37	1674
3362.75	1624
3365.12	1618
3367.49	1628
3369.86	1630
3372.23	1588
3374.6	1638
3376.97	1612
3379.33	1622
3381.7	1650
3384.06	1596
3386.43	1618
3388.79	1590
3391.15	1634
3393.51	1576
3395.87	1570
3398.23	1652
3400.59	1576
3402.94	1586
3405.3	1558
3407.65	1586
3410.01	1546
3412.36	1578
3414.71	1540
3417.06	1568
3419.41	1544
3421.76	1548
3424.11	1566
3426.46	1576
3428.8	1548
3431.15	1546
3433.49	1506
3435.83	1506
3438.18	1572
3440.52	1562
3442.86	1566
3445.2	1520
3447.53	1524
3449.87	1554
3452.21	1480
3454.54	1502
3456.88	1480
3459.21	1508
3461.54	1496
3463.88	1528
3466.21	1518
3468.53	1454
3470.86	1494
3473.19	1438
3475.52	1480
3477.84	1466
3480.17	1504
3482.49	1452
3484.82	1408
3487.14	1462
3489.46	1460
3491.78	1418
3494.1	1444
3496.42	1430
3498.73	1458
3501.05	1504
3503.36	1406
3505.68	1428
3507.99	1432
3510.3	1464
3512.61	1430
3514.92	1406
3517.23	1448
3519.54	1388
3521.85	1394
3524.16	1362
3526.46	1396
3528.77	1384
3531.07	1418
3533.37	1352
3535.68	1406
3537.98	1370
3540.28	1372
3542.58	1376
3544.87	1406
3547.17	1358
3549.47	1400
3551.76	1388
3554.06	1330
3556.35	1350
3558.64	1380
3560.93	1410
3563.22	1380
3565.51	1336
3567.8	1394
3570.09	1366
3572.38	1378
3574.66	1326
3576.95	1316
3579.23	1356
3581.51	1406
3583.8	1320
3586.08	1312
3588.36	1302
3590.64	1336
3592.92	1342
3595.19	1306
3597.47	1320
3599.75	1348
3602.02	1264
3604.29	1284
3606.57	1294
3608.84	1278
3611.11	1306
3613.38	1330
3615.65	1264
3617.92	1308
3620.18	1328
3622.45	1292
3624.71	1304
3626.98	1338
3629.24	1302
3631.5	1302
3633.77	1284
3636.03	1244
3638.29	1264
3640.55	1258
3642.8	1256
3645.06	1256
3647.32	1236
3649.57	1294
3651.83	1246
3654.08	1268
3656.33	1240
3658.58	1260
3660.83	1258
3663.08	1238
3665.33	1236
3667.58	1252
3669.83	1260
3672.07	1244
3674.32	1236
3676.56	1204
3678.8	1228
3681.05	1240
3683.29	1186
3685.53	1206
3687.77	1226
3690.01	1170
3692.24	1182
3694.48	1210
3696.72	1184
3698.95	1196
3701.19	1200
3703.42	1182
3705.65	1200
3707.88	1208
3710.11	1174
3712.34	1150
3714.57	1148
3716.8	1216
3719.03	1196
3721.25	1216
3723.48	1174
3725.7	1192
3727.92	1196
3730.15	1176
3732.37	1170
3734.59	1192
3736.81	1134
3739.03	1170
3741.24	1166
3743.46	1170
3745.68	1172
3747.89	1186
3750.11	1202
3752.32	1186
3754.53	1170
3756.74	1116
3758.95	1114
3761.16	1098
3763.37	1125.95
3765.58	1128.76
3767.79	1150.68
3769.99	1117.78
3772.2	1110.67
3774.4	1132.77
3776.61	1116.13
3778.81	1096.92
3781.01	1139.97
3783.21	1127.58
3785.41	1079.42
3787.61	1077.87
3789.81	1110.62
3792	1101.73
3794.2	1093.3
3796.4	1077.64
3798.59	1105.9
3800.78	1093.92
3802.98	1061.85
3805.17	1075.88
3807.36	1076.16
3809.55	1084.54
3811.74	1103.47
3813.93	1067.48
3816.11	1087.66
3818.3	1070.63
3820.49	1061.52
3822.67	1078.54
3824.85	1068.69
3827.04	1083.86
3829.22	1068.64
3831.4	1060.84
3833.58	1009.67
3835.76	1058.69
3837.94	1061.94
3839.98	1028
3842.17	1034
3844.36	1068
3846.55	1028
3848.73	1038
3850.92	1052
3853.1	1092
3855.29	1004
3857.47	976
3859.65	1024
3861.84	1042
3864.02	994
3866.2	1000
3868.38	1006
3870.55	1000
3872.73	1016
3874.91	1018
3877.08	1040
3879.26	982
3881.43	1010
3883.6	990
3885.78	998
3887.95	1000
3890.12	1026
3892.29	1002
3894.46	982
3896.63	982
3898.79	1002
3900.96	998
3903.12	1004
3905.29	1004
3907.45	1006
3909.61	1004
3911.78	982
3913.94	974
3916.1	990
3918.26	1028
3920.41	1004
3922.57	976
3924.73	998
3926.88	974
3929.04	976
3931.19	970
3933.35	918
3935.5	994
3937.65	934
3939.8	986
3941.95	940
3944.1	974
3946.25	954
3948.4	954
3950.54	944
3952.69	954
3954.83	980
3956.98	962
3959.12	942
3961.26	944
3963.4	942
3965.54	948
3967.68	956
3969.82	932
3971.96	942
3974.1	944
3976.23	910
3978.37	920
3980.5	920
3982.64	908
3984.77	912
3986.9	918
3989.03	910
3991.16	922
3993.29	926
3995.42	910
3997.55	948
3999.67	910