File: muestras/mosquito/OR_04.txt
#Acq. time (s)=	10
#Accumulations=	1
#Range (cm-¹)=	200...4000
#Windows=	5
#Autofocus=	Off
#AutoExposure=	Off
#Spike filter=	Off
#Delay time (s)=	0
#Binning=	1
#Readout mode=	Signal
#DeNoise=	Off
#ICS correction=	Off
#Dark correction=	Off
#Inst. Process=	Off
#Instrument=	LabRAM HR Evol
#Detector=	Syncerity OE
#Objective=	x100_VIS
#Grating=	600 (500nm)
#ND Filter=	25%
#Laser=	633nm_Edge
#Hole=	100.021
#Range=	Visible
#Project=	Omar
#Sample=	03-07-23
#Site=	1
#Title=	OR
#Remark=
#Date=	03.07.2023 13:31
#Acquired=	03.07.2023 13:31:24
200.404	2908
204.205	2886
208.003	2930
211.799	2894
215.595	2938
219.387	2962
223.177	2982
226.966	2970
230.752	2998
234.536	2964
238.319	3126
242.1	3052
245.879	3022
249.655	3026
253.431	3028
257.204	3004
260.976	3108
264.744	3086
268.511	3042
272.276	3086
276.04	3062
279.801	3064
283.561	3116
287.318	3142
291.074	3114
294.828	3092
298.581	3182
302.33	3234
306.079	3188
309.825	3228
313.569	3138
317.311	3228
321.052	3194
324.79	3218
328.527	3296
332.261	3312
335.994	3278
339.725	3264
343.454	3304
347.182	3364
350.907	3252
354.631	3322
358.352	3318
362.072	3294
365.789	3306
369.505	3324
373.219	3260
376.93	3364
380.642	3328
384.35	3292
388.056	3362
391.76	3298
395.463	3360
399.164	3370
402.863	3364
406.559	3420
410.254	3454
413.948	3466
417.639	3498
421.329	3510
425.016	3526
428.701	3556
432.386	3652
436.068	3542
439.748	3578
443.426	3578
447.103	3600
450.777	3534
454.45	3630
458.121	3578
461.789	3652
465.457	3618
469.122	3642
472.786	3610
476.447	3710
480.107	3626
483.765	3634
487.421	3710
491.075	3704
494.727	3630
498.377	3806
502.026	3812
505.673	3752
509.318	3788
512.962	3696
516.602	3678
520.242	3718
523.881	3786
527.516	3724
531.149	3714
534.783	3738
538.413	3766
542.041	3780
545.667	3710
549.292	3752
552.915	3730
556.537	3730
560.156	3824
563.773	3754
567.389	3846
571.004	3802
574.615	3694
578.226	3824
581.834	3788
585.44	3856
589.045	3842
592.649	3866
596.25	3866
599.85	3876
603.448	3830
607.042	3902
610.637	3888
614.229	3936
617.819	3942
621.408	3978
624.994	4058
628.58	3968
632.163	3934
635.744	4018
639.324	4028
642.902	4082
646.478	4048
650.052	4066
653.625	4024
657.196	4040
660.764	3996
664.331	4080
667.897	4038
671.46	4070
675.021	4022
678.582	4062
682.14	4138
685.696	4084
689.252	4082
692.804	4132
696.355	4176
699.905	4058
703.451	4164
706.997	4190
710.542	4076
714.083	4074
717.624	4176
721.162	4174
724.7	4216
728.235	4158
731.768	4194
735.301	4238
738.83	4160
742.358	4212
745.885	4172
749.41	4248
752.931	4206
756.453	4180
759.973	4266
763.49	4130
767.006	4160
770.52	4162
774.033	4194
777.543	4188
781.052	4210
784.559	4234
788.064	4144
791.568	4256
795.07	4210
798.57	4300
802.068	4352
805.565	4274
809.061	4346
812.553	4250
816.045	4376
819.535	4300
823.022	4226
826.508	4352
829.993	4316
833.476	4380
836.957	4328
840.436	4350
843.914	4370
847.391	4452
850.864	4374
854.337	4402
857.807	4474
861.277	4472
864.744	4494
868.209	4460
871.674	4426
875.136	4498
878.597	4388
882.056	4466
885.512	4500
888.967	4506
892.421	4430
895.874	4438
899.323	4422
902.771	4388
906.219	4488
909.664	4406
913.107	4440
916.55	4416
919.99	4468
923.428	4424
926.863	4506
930.299	4540
933.732	4490
937.164	4510
940.593	4440
944.022	4488
947.448	4506
950.874	4562
954.296	4578
957.718	4486
961.137	4522
964.555	4552
967.972	4626
971.387	4488
974.8	4514
978.21	4604
981.62	4582
985.029	4560
988.435	4554
991.839	4658
995.243	4614
998.644	4660
1002.04	4644
1005.44	4640
1008.84	4646
1012.23	4582
1015.63	4604
1019.02	4668
1022.41	4644
1025.79	4626
1029.18	4758
1032.56	4724
1035.95	4690
1039.33	4758
1042.71	4716
1046.09	4732
1049.46	4768
1052.84	4742
1056.21	4840
1059.58	4758
1062.95	4758
1066.32	4742
1069.69	4770
1073.05	4826
1076.41	4860
1079.78	4762
1083.14	4786
1086.49	4724
1089.85	4724
1093.21	4738
1096.56	4768
1099.91	4734
1103.26	4702
1106.61	4712
1109.96	4684
1113.3	4710
1116.64	4744
1119.99	4646
1123.33	4744
1126.66	4810
1130	4778
1133.34	4864
1136.67	4828
1140	4822
1143.33	4816
1146.66	4896
1149.99	4846
1153.32	4910
1156.64	4848
1159.96	4886
1163.28	4862
1166.6	4876
1169.92	4868
1173.23	4910
1176.55	4906
1179.86	4954
1183.17	4874
1186.48	4962
1189.79	4910
1193.1	4896
1196.4	4894
1199.7	4896
1203	4806
1206.3	4766
1209.6	4858
1212.9	4914
1216.19	4820
1219.49	4790
1222.78	4776
1226.07	4868
1229.36	4810
1232.65	4778
1235.93	4782
1239.21	4788
1242.5	4840
1245.78	4856
1249.06	4860
1252.33	4872
1255.61	4810
1258.88	4874
1262.16	4944
1265.43	4844
1268.7	4916
1271.96	4984
1275.23	4878
1278.5	4952
1281.76	5017.8
1285.02	4999.36
1288.28	5002.1
1291.54	4906.63
1294.8	5029.71
1298.05	5032.94
1301.31	5034.37
1304.56	5013.06
1307.81	5032.69
1311.06	5060.62
1314.3	5020.06
1317.55	4990.95
1320.79	5056.53
1324.04	5110.08
1327.28	5036.29
1330.52	5082.11
1333.76	5072.32
1336.99	5069.53
1340.23	5146.21
1343.46	5155.1
1346.69	5141.9
1349.92	5160.08
1353.15	5166.67
1356.38	5115.53
1359.6	5097.71
1362.83	5117.48
1366.05	5172.47
1369.27	5170.82
1372.49	5169.71
1375.71	5119.01
1378.93	5159.45
1382.14	5157.99
1385.35	5220.83
1388.57	5147.49
1391.2	5258
1394.43	5180
1397.65	5156
1400.87	5134
1404.09	5190
1407.31	5124
1410.53	5098
1413.74	5156
1416.96	5162
1420.17	5156
1423.38	5164
1426.59	5116
1429.8	5084
1433.01	5116
1436.21	5194
1439.42	5044
1442.62	5114
1445.82	5172
1449.02	5088
1452.22	5134
1455.41	5206
1458.61	5114
1461.8	5144
1464.99	5176
1468.18	5098
1471.37	5148
1474.56	5184
1477.74	5162
1480.93	5116
1484.11	5168
1487.29	5162
1490.47	5202
1493.65	5102
1496.82	5168
1500	5110
1503.17	5122
1506.34	5096
1509.51	5062
1512.68	5156
1515.85	5052
1519.02	5140
1522.18	5016
1525.34	5122
1528.51	5160
1531.67	5156
1534.82	5218
1537.98	5138
1541.14	5152
1544.29	5184
1547.44	5198
1550.59	5066
1553.74	5078
1556.89	5072
1560.04	5072
1563.18	5142
1566.33	5176
1569.47	5138
1572.61	5116
1575.75	5200
1578.89	5068
1582.02	5088
1585.16	5052
1588.29	5086
1591.42	5088
1594.55	5112
1597.68	5084
1600.81	5126
1603.94	5108
1607.06	5118
1610.18	5190
1613.3	5080
1616.42	5052
1619.54	5132
1622.66	5142
1625.78	5150
1628.89	5066
1632	5176
1635.11	5044
1638.22	5084
1641.33	5056
1644.44	4976
1647.55	5086
1650.65	4950
1653.75	4880
1656.85	4908
1659.95	4910
1663.05	4788
1666.15	4802
1669.24	4810
1672.34	4900
1675.43	4894
1678.52	4806
1681.61	4776
1684.7	4756
1687.78	4726
1690.87	4704
1693.95	4702
1697.03	4760
1700.12	4610
1703.2	4710
1706.27	4734
1709.35	4668
1712.42	4738
1715.5	4726
1718.57	4674
1721.64	4732
1724.71	4726
1727.78	4664
1730.84	4650
1733.91	4586
1736.97	4628
1740.04	4680
1743.1	4664
1746.16	4662
1749.21	4712
1752.27	4710
1755.33	4708
1758.38	4604
1761.43	4672
1764.48	4658
1767.53	4668
1770.58	4684
1773.63	4718
1776.67	4716
1779.71	4636
1782.76	4604
1785.8	4654
1788.84	4732
1791.88	4640
1794.91	4626
1797.95	4672
1800.98	4620
1804.01	4680
1807.04	4560
1810.07	4628
1813.1	4664
1816.13	4596
1819.15	4604
1822.18	4620
1825.2	4598
1828.22	4572
1831.24	4574
1834.26	4462
1837.28	4574
1840.29	4488
1843.31	4536
1846.32	4460
1849.33	4508
1852.34	4546
1855.35	4440
1858.36	4446
1861.36	4462
1864.36	4412
1867.37	4458
1870.37	4438
1873.37	4470
1876.37	4384
1879.37	4414
1882.36	4376
1885.36	4392
1888.35	4402
1891.34	4428
1894.33	4460
1897.32	4400
1900.31	4400
1903.3	4442
1906.28	4416
1909.26	4410
1912.25	4342
1915.23	4440
1918.21	4392
1921.18	4412
1924.16	4394
1927.14	4398
1930.11	4354
1933.08	4378
1936.05	4386
1939.02	4406
1941.99	4378
1944.96	4356
1947.92	4352
1950.89	4362
1953.85	4310
1956.81	4296
1959.77	4288
1962.73	4254
1965.69	4284
1968.65	4242
1971.6	4304
1974.55	4342
1977.51	4242
1980.46	4200
1983.41	4276
1986.35	4222
1989.3	4250
1992.25	4196
1995.19	4186
1998.13	4286
2001.07	4240
2004.01	4272
2006.95	4232
2009.89	4294
2012.82	4214
2015.76	4196
2018.69	4216
2021.62	4196
2024.55	4252
2027.48	4238
2030.41	4198
2033.34	4172
2036.26	4238
2039.19	4140
2042.11	4158
2045.03	4088
2047.95	4142
2050.87	4156
2053.79	4090
2056.7	4198
2059.61	4096
2062.53	4184
2065.44	4088
2068.35	4100
2071.26	4142
2074.17	4096
2077.07	4056
2079.98	4088
2082.88	4098
2085.78	4044
2088.68	4058
2091.58	4084
2094.48	4004
2097.38	4044
2100.28	3972
2103.17	3950
2106.06	4026
2108.96	3974
2111.85	4022
2114.73	4038
2117.62	3994
2120.51	4052
2123.39	3972
2126.28	3960
2129.16	3970
2132.04	3878
2134.92	3924
2137.8	3954
2140.68	3956
2143.55	3924
2146.43	3868
2149.3	3960
2152.17	3920
2155.04	3934
2157.91	3844
2160.78	3866
2163.65	3772
2166.51	3850
2169.38	3826
2172.24	3848
2175.1	3790
2177.96	3854
2180.82	3782
2183.68	3762
2186.53	3722
2189.39	3770
2192.24	3814
2195.09	3750
2197.95	3724
2200.8	3682
2203.64	3750
2206.49	3732
2209.34	3718
2212.18	3714
2215.03	3722
2217.87	3668
2220.71	3731.2
2223.55	3690.75
2226.39	3762.78
2229.22	3663.67
2232.06	3757.29
2234.89	3724.49
2237.73	3735.24
2240.56	3767.63
2243.39	3703.25
2246.22	3678.69
2249.05	3672.09
2251.87	3740.45
2254.7	3730.46
2257.52	3685.89
2260.34	3741.53
2263.17	3708.33
2265.99	3753.99
2268.8	3727.3
2271.62	3744.34
2274.44	3739.73
2277.25	3681.98
2280.07	3727.25
2282.88	3719.47
2285.69	3694.8
2288.5	3640.04
2291.31	3649.14
2294.12	3717.94
2296.92	3665.05
2299.73	3687.88
2302.53	3717.42
2305.34	3701.17
2308.14	3749.44
2310.94	3683.45
2313.74	3652.11
2315.86	3656
2318.67	3710
2321.48	3688
2324.29	3708
2327.09	3666
2329.9	3608
2332.7	3662
2335.51	3686
2338.31	3708
2341.11	3616
2343.91	3598
2346.71	3612
2349.51	3594
2352.3	3572
2355.1	3622
2357.89	3644
2360.68	3596
2363.48	3604
2366.27	3578
2369.05	3664
2371.84	3580
2374.63	3544
2377.41	3634
2380.2	3640
2382.98	3610
2385.76	3510
2388.54	3652
2391.32	3486
2394.1	3562
2396.87	3576
2399.65	3552
2402.42	3596
2405.2	3538
2407.97	3584
2410.74	3524
2413.51	3448
2416.27	3550
2419.04	3510
2421.81	3550
2424.57	3484
2427.33	3536
2430.1	3552
2432.85	3478
2435.61	3458
2438.37	3508
2441.13	3510
2443.88	3436
2446.64	3450
2449.39	3460
2452.14	3442
2454.89	3542
2457.64	3446
2460.39	3474
2463.14	3380
2465.88	3466
2468.63	3424
2471.37	3478
2474.11	3414
2476.86	3484
2479.59	3418
2482.33	3406
2485.07	3394
2487.81	3422
2490.54	3404
2493.28	3322
2496.01	3332
2498.74	3366
2501.47	3370
2504.2	3410
2506.93	3348
2509.65	3352
2512.38	3326
2515.1	3314
2517.82	3350
2520.55	3352
2523.27	3296
2525.99	3344
2528.7	3370
2531.42	3322
2534.14	3330
2536.85	3300
2539.56	3278
2542.28	3330
2544.99	3288
2547.7	3232
2550.4	3256
2553.11	3244
2555.82	3286
2558.52	3258
2561.23	3214
2563.93	3306
2566.63	3226
2569.33	3230
2572.03	3202
2574.73	3294
2577.42	3172
2580.12	3240
2582.81	3202
2585.51	3164
2588.2	3192
2590.89	3246
2593.58	3212
2596.26	3228
2598.95	3146
2601.64	3110
2604.32	3170
2607.01	3144
2609.69	3108
2612.37	3092
2615.05	3138
2617.73	3072
2620.41	3100
2623.08	3124
2625.76	3104
2628.43	3068
2631.1	3088
2633.78	3062
2636.45	3044
2639.12	3046
2641.78	3084
2644.45	3072
2647.12	3118
2649.78	3072
2652.45	3030
2655.11	2996
2657.77	2988
2660.43	3054
2663.09	3000
2665.75	3036
2668.4	3052
2671.06	3036
2673.71	2936
2676.37	2994
2679.02	3056
2681.67	2914
2684.32	2994
2686.97	2944
2689.61	2996
2692.26	2968
2694.9	2968
2697.55	2988
2700.19	3034
2702.83	2936
2705.47	3006
2708.11	2900
2710.75	2958
2713.39	2922
2716.02	2890
2718.66	2962
2721.29	2936
2723.92	2914
2726.55	2872
2729.18	2916
2731.81	2866
2734.44	2868
2737.07	2836
2739.69	2800
2742.32	2804
2744.94	2808
2747.56	2842
2750.18	2772
2752.8	2898
2755.42	2842
2758.04	2856
2760.65	2780
2763.27	2912
2765.88	2830
2768.5	2748
2771.11	2756
2773.72	2820
2776.33	2764
2778.94	2786
2781.54	2750
2784.15	2750
2786.75	2750
2789.36	2712
2791.96	2748
2794.56	2776
2797.16	2726
2799.76	2714
2802.36	2672
2804.96	2780
2807.55	2728
2810.15	2702
2812.74	2684
2815.33	2742
2817.93	2734
2820.52	2722
2823.11	2660
2825.69	2602
2828.28	2658
2830.87	2662
2833.45	2710
2836.03	2652
2838.62	2600
2841.2	2710
2843.78	2626
2846.36	2542
2848.93	2622
2851.51	2588
2854.09	2614
2856.66	2626
2859.24	2544
2861.81	2602
2864.38	2590
2866.95	2596
2869.52	2580
2872.09	2534
2874.65	2550
2877.22	2586
2879.78	2570
2882.35	2494
2884.91	2508
2887.47	2528
2890.03	2512
2892.59	2474
2895.15	2530
2897.7	2482
2900.26	2534
2902.81	2488
2905.37	2518
2907.92	2506
2910.47	2452
2913.02	2504
2915.57	2462
2918.12	2466
2920.66	2482
2923.21	2418
2925.75	2462
2928.3	2466
2930.84	2422
2933.38	2480
2935.92	2446
2938.46	2416
2941	2414
2943.54	2478
2946.07	2454
2948.61	2400
2951.14	2418
2953.67	2374
2956.21	2326
2958.74	2394
2961.27	2416
2963.79	2374
2966.32	2356
2968.85	2344
2971.37	2332
2973.9	2328
2976.42	2338
2978.94	2352
2981.46	2252
2983.98	2322
2986.5	2302
2989.02	2240
2991.53	2330
2994.05	2342
2996.56	2252
2999.08	2256
3001.59	2268
3004.1	2270
3006.61	2262
3009.12	2232
3011.63	2250
3014.13	2174
3016.64	2182
3019.14	2222
3021.65	2224
3024.15	2226
3026.65	2234
3029.15	2230
3031.65	2230
3034.15	2214
3036.64	2196
3039.14	2184
3041.63	2197.72
3044.13	2145.33
3046.62	2152.05
3049.11	2153.51
3051.6	2157.75
3054.09	2153.94
3056.58	2127.22
3059.07	2102.18
3061.55	2143.67
3064.04	2113.87
3066.52	2133.01
3069.01	2114.58
3071.49	2115.27
3073.97	2084.42
3076.45	2091.64
3078.93	2104.56
3081.41	2046.75
3083.88	2057.9
3086.36	2059.67
3088.83	2058
3091.31	2003.56
3093.78	2029.3
3096.25	2023.32
3098.72	1999.88
3101.19	2006.93
3103.66	1997.82
3106.13	1992.15
3108.59	1998.59
3111.06	1979.01
3113.52	1960.13
3115.98	1987.27
3118.45	1962.12
3120.91	1946.41
3123.37	1956.61
3125.38	1952
3127.85	1916
3130.32	1920
3132.79	1872
3135.26	1882
3137.73	1860
3140.19	1926
3142.66	1890
3145.13	1854
3147.59	1916
3150.05	1902
3152.51	1880
3154.97	1812
3157.43	1830
3159.89	1856
3162.35	1826
3164.8	1892
3167.26	1838
3169.71	1848
3172.17	1838
3174.62	1796
3177.07	1814
3179.52	1846
3181.97	1822
3184.41	1830
3186.86	1874
3189.31	1798
3191.75	1818
3194.2	1842
3196.64	1766
3199.08	1832
3201.52	1786
3203.96	1778
3206.4	1800
3208.84	1746
3211.27	1714
3213.71	1808
3216.14	1742
3218.58	1778
3221.01	1752
3223.44	1748
3225.87	1798
3228.3	1752
3230.73	1776
3233.16	1724
3235.58	1798
3238.01	1690
3240.43	1756
3242.86	1738
3245.28	1700
3247.7	1728
3250.12	1732
3252.54	1730
3254.96	1660
3257.38	1726
3259.79	1716
3262.21	1696
3264.62	1722
3267.04	1704
3269.45	1686
3271.86	1654
3274.27	1680
3276.68	1702
3279.09	1634
3281.49	1642
3283.9	1690
3286.31	1642
3288.71	1654
3291.11	1636
3293.51	1658
3295.92	1668
3298.32	1670
3300.72	1600
3303.11	1636
3305.51	1604
3307.91	1600
3310.3	1630
3312.7	1632
3315.09	1578
3317.48	1568
3319.87	1614
3322.26	1612
3324.65	1626
3327.04	1590
3329.43	1564
3331.81	1604
3334.2	1610
3336.58	1566
3338.97	1554
3341.35	1542
3343.73	1560
3346.11	1566
3348.49	1590
3350.87	1556
3353.25	1480
3355.62	1538
3358	1572
3360.37	1560
3362.75	1552
3365.12	1560
3367.49	1560
3369.86	1554
3372.23	1552
3374.6	1502
3376.97	1554
3379.33	1562
3381.7	1528
3384.06	1528
3386.43	1524
3388.79	1544
3391.15	1454
3393.51	1510
3395.87	1530
3398.23	1518
3400.59	1502
3402.94	1502
3405.3	1486
3407.65	1454
3410.01	1486
3412.36	1456
3414.71	1442
3417.06	1474
3419.41	1480
3421.76	1416
3424.11	1454
3426.46	1472
3428.8	1446
3431.15	1430
3433.49	1450
3435.83	1420
3438.18	1444
3440.52	1416
3442.86	1436
3445.2	1374
3447.53	1428
3449.87	1440
3452.21	1400
3454.54	1424
3456.88	1374
3459.21	1416
3461.54	1426
3463.88	1410
3466.21	1384
3468.53	1400
3470.86	1382
3473.19	1416
3475.52	1400
3477.84	1416
3480.17	1386
3482.49	1400
3484.82	1370
3487.14	1370
3489.46	1344
3491.78	1320
3494.1	1386
3496.42	1360
3498.73	1356
3501.05	1340
3503.36	1402
3505.68	1350
3507.99	1368
3510.3	1348
3512.61	1346
3514.92	1350
3517.23	1288
3519.54	1362
3521.85	1364
3524.16	1290
3526.46	1348
3528.77	1314
3531.07	1308
3533.37	1348
3535.68	1362
3537.98	1306
3540.28	1320
3542.58	1358
3544.87	1344
3547.17	1306
3549.47	1328
3551.76	1294
3554.06	1296
3556.35	1292
3558.64	1302
3560.93	1270
3563.22	1306
3565.51	1346
3567.8	1278
3570.09	1294
3572.38	1290
3574.66	1276
3576.95	1270
3579.23	1272
3581.51	1232
3583.8	1238
3586.08	1278
3588.36	1230
3590.64	1238
3592.92	1272
3595.19	1236
3597.47	1232
3599.75	1268
3602.02	1200
3604.29	1226
3606.57	1232
3608.84	1224
3611.11	1220
3613.38	1240
3615.65	1224
3617.92	1242
3620.18	1230
3622.45	1218
3624.71	1208
3626.98	1230
3629.24	1210
3631.5	1186
3633.77	1204
3636.03	1190
3638.29	1178
3640.55	1190
3642.8	1180
3645.06	1222
3647.32	1178
3649.57	1156
3651.83	1194
3654.08	1186
3656.33	1174
3658.58	1152
3660.83	1176
3663.08	1174
3665.33	1150
3667.58	1150
3669.83	1192
3672.07	1178
3674.32	1128
3676.56	1178
3678.8	1146
3681.05	1144
3683.29	1106
3685.53	1174
3687.77	1140
3690.01	1162
3692.24	1150
3694.48	1132
3696.72	1110
3698.95	1144
3701.19	1122
3703.42	1108
3705.65	1136
3707.88	1178
3710.11	1154
3712.34	1146
3714.57	1162
3716.8	1134
3719.03	1126
3721.25	1096
3723.48	1070
3725.7	1092
3727.92	1110
3730.15	1118
3732.37	1130
3734.59	1144
3736.81	1138
3739.03	1090
3741.24	1064
3743.46	1096
3745.68	1096
3747.89	1104
3750.11	1120
3752.32	1086
3754.53	1076
3756.74	1038
3758.95	1098
3761.16	1054
3763.37	1101.84
3765.58	1071.89
3767.79	1090.39
3769.99	1034.73
3772.2	1101.6
3774.4	1094.51
3776.61	1030.48
3778.81	1035.32
3781.01	1038.97
3783.21	1057.41
3785.41	1036.78
3787.61	1053.29
3789.81	1029.87
3792	1044.92
3794.2	1034.86
3796.4	1052.35
3798.59	1046.97
3800.78	1040.59
3802.98	1038.72
3805.17	1065.58
3807.36	1049.82
3809.55	1051.78
3811.74	1044.2
3813.93	1039.73
3816.11	1032.22
3818.3	1046.62
3820.49	1020.71
3822.67	1014.24
3824.85	1027.3
3827.04	1022.61
3829.22	1017.96
3831.4	988.02
3833.58	1020.89
3835.76	992.19
3837.94	989.319
3839.98	982
3842.17	994
3844.36	990
3846.55	966
3848.73	984
3850.92	990
3853.1	1008
3855.29	1006
3857.47	998
3859.65	964
3861.84	1000
3864.02	974
3866.2	978
3868.38	972
3870.55	996
3872.73	970
3874.91	1016
3877.08	970
3879.26	962
3881.43	934
3883.6	992
3885.78	942
3887.95	946
3890.12	940
3892.29	976
3894.46	956
3896.63	944
3898.79	988
3900.96	962
3903.12	976
3905.29	970
3907.45	970
3909.61	944
3911.78	982
3913.94	940
3916.1	976
3918.26	924
3920.41	950
3922.57	906
3924.73	934
3926.88	932
3929.04	958
3931.19	916
3933.35	948
3935.5	916
3937.65	922
3939.8	902
3941.95	910
3944.1	930
3946.25	894
3948.4	920
3950.54	934
3952.69	930
3954.83	888
3956.98	926
3959.12	930
3961.26	902
3963.4	936
3965.54	860
3967.68	876
3969.82	900
3971.96	862
3974.1	892
3976.23	876
3978.37	890
3980.5	884
3982.64	884
3984.77	890
3986.9	884
3989.03	910
3991.16	898
3993.29	876
3995.42	912
3997.55	884
3999.67	874