File: muestras/mosquito/OR_01.txt
#Acq. time (s)=	5
#Accumulations=	2
#Range (cm-¹)=	200...4000
#Windows=	5
#Autofocus=	Off
#AutoExposure=	Off
#Spike filter=	Multiple accum.
#Delay time (s)=	0
#Binning=	1
#Readout mode=	Signal
#DeNoise=	Off
#ICS correction=	Off
#Dark correction=	Off
#Inst. Process=	Off
#Instrument=	LabRAM HR Evol
#Detector=	Syncerity OE
#Objective=	x100_VIS
#Grating=	600 (500nm)
#ND Filter=	10%
#Laser=	633nm_Edge
#Hole=	100.021
#Range=	Visible
#Project=	Omar
#Sample=	03-07-23
#Site=	1
#Title=	OR
#Remark=
#Date=	03.07.2023 13:21
#Acquired=	03.07.2023 13:21:19
200.404	1216
204.205	1250
208.003	1248
211.799	1194
215.595	1194
219.387	1238
223.177	1232
226.966	1264
230.752	1252
234.536	1286
238.319	1278
242.1	1262
245.879	1300
249.655	1260
253.431	1278
257.204	1280
260.976	1332
264.744	1290
268.511	1266
272.276	1286
276.04	1302
279.801	1304
283.561	1306
287.318	1314
291.074	1296
294.828	1314
298.581	1312
302.33	1360
306.079	1352
309.825	1324
313.569	1362
317.311	1372
321.052	1372
324.79	1376
328.527	1366
332.261	1396
335.994	1374
339.725	1358
343.454	1398
347.182	1402
350.907	1408
354.631	1436
358.352	1380
362.072	1422
365.789	1406
369.505	1390
373.219	1430
376.93	1456
380.642	1408
384.35	1438
388.056	1436
391.76	1430
395.463	1492
399.164	1440
402.863	1440
406.559	1426
410.254	1520
413.948	1508
417.639	1472
421.329	1538
425.016	1500
428.701	1502
432.386	1552
436.068	1572
439.748	1552
443.426	1570
447.103	1560
450.777	1542
454.45	1564
458.121	1592
461.789	1574
465.457	1604
469.122	1566
472.786	1544
476.447	1596
480.107	1616
483.765	1606
487.421	1564
491.075	1612
494.727	1604
498.377	1630
502.026	1628
505.673	1630
509.318	1588
512.962	1646
516.602	1622
520.242	1632
523.881	1650
527.516	1620
531.149	1646
534.783	1618
538.413	1620
542.041	1650
545.667	1646
549.292	1690
552.915	1664
556.537	1664
560.156	1616
563.773	1660
567.389	1706
571.004	1670
574.615	1694
578.226	1650
581.834	1672
585.44	1692
589.045	1734
592.649	1726
596.25	1724
599.85	1712
603.448	1746
607.042	1754
610.637	1756
614.229	1704
617.819	1778
621.408	1736
624.994	1756
628.58	1776
632.163	1734
635.744	1744
639.324	1746
642.902	1794
646.478	1824
650.052	1814
653.625	1836
657.196	1814
660.764	1788
664.331	1806
667.897	1812
671.46	1846
675.021	1816
678.582	1844
682.14	1828
685.696	1822
689.252	1804
692.804	1844
696.355	1866
699.905	1816
703.451	1892
706.997	1882
710.542	1854
714.083	1864
717.624	1926
721.162	1876
724.7	1942
728.235	1880
731.768	1898
735.301	1846
738.83	1942
742.358	1940
745.885	1900
749.41	1882
752.931	1900
756.453	1898
759.973	1888
763.49	1950
767.006	1902
770.52	1896
774.033	1916
777.543	1904
781.052	1922
784.559	1944
788.064	1942
791.568	1938
795.07	1920
798.57	1900
802.068	1944
805.565	1938
809.061	1976
812.553	1932
816.045	1994
819.535	1986
823.022	2000
826.508	1976
829.993	2012
833.476	2038
836.957	2030
840.436	2006
843.914	2024
847.391	2006
850.864	2048
854.337	1974
857.807	2054
861.277	1998
864.744	2002
868.209	2038
871.674	2036
875.136	2084
878.597	2032
882.056	2050
885.512	2088
888.967	2142
892.421	2046
895.874	2112
899.323	2106
902.771	2060
906.219	2068
909.664	2010
913.107	2076
916.55	2014
919.99	2060
923.428	2106
926.863	2088
930.299	2052
933.732	2128
937.164	2108
940.593	2060
944.022	2090
947.448	2088
950.874	2054
954.296	2170
957.718	2198
961.137	2160
964.555	2106
967.972	2106
971.387	2112
974.8	2122
978.21	2222
981.62	2130
985.029	2164
988.435	2184
991.839	2110
995.243	2182
998.644	2202
1002.04	2152
1005.44	2210
1008.84	2178
1012.23	2134
1015.63	2150
1019.02	2172
1022.41	2158
1025.79	2182
1029.18	2160
1032.56	2224
1035.95	2180
1039.33	2192
1042.71	2200
1046.09	2228
1049.46	2268
1052.84	2298
1056.21	2200
1059.58	2198
1062.95	2262
1066.32	2258
1069.69	2226
1073.05	2210
1076.41	2238
1079.78	2200
1083.14	2196
1086.49	2162
1089.85	2212
1093.21	2220
1096.56	2194
1099.91	2228
1103.26	2202
1106.61	2198
1109.96	2196
1113.3	2172
1116.64	2182
1119.99	2106
1123.33	2236
1126.66	2128
1130	2166
1133.34	2192
1136.67	2210
1140	2170
1143.33	2196
1146.66	2186
1149.99	2202
1153.32	2216
1156.64	2250
1159.96	2208
1163.28	2236
1166.6	2226
1169.92	2282
1173.23	2236
1176.55	2224
1179.86	2238
1183.17	2176
1186.48	2216
1189.79	2210
1193.1	2250
1196.4	2234
1199.7	2182
1203	2172
1206.3	2178
1209.6	2202
1212.9	2210
1216.19	2168
1219.49	2104
1222.78	2104
1226.07	2212
1229.36	2146
1232.65	2142
1235.93	2120
1239.21	2210
1242.5	2126
1245.78	2144
1249.06	2172
1252.33	2138
1255.61	2174
1258.88	2136
1262.16	2136
1265.43	2150
1268.7	2098
1271.96	2210
1275.23	2136
1278.5	2122
1281.76	2134.35
1285.02	2173.83
1288.28	2201.94
1291.54	2167.02
1294.8	2166.02
1298.05	2074.47
1301.31	2207.62
1304.56	2138.27
1307.81	2125.2
1311.06	2138.02
1314.3	2102.23
1317.55	2094.53
1320.79	2093.44
1324.04	2077.96
1327.28	2122.99
1330.52	2118.69
1333.76	2087.73
1336.99	2045.13
1340.23	2053.16
1343.46	2084.53
1346.69	2048.17
1349.92	2083.44
1353.15	2047.24
1356.38	2052.95
1359.6	2046.03
1362.83	2045.9
1366.05	2011.55
1369.27	2019.3
1372.49	2056.2
1375.71	1996.26
1378.93	2013.13
1382.14	1996.51
1385.35	1995.72
1388.57	2022.91
1391.2	2004
1394.43	2018
1397.65	2066
1400.87	1966
1404.09	2022
1407.31	1960
1410.53	1986
1413.74	1992
1416.96	1922
1420.17	2000
1423.38	1966
1426.59	1974
1429.8	1972
1433.01	1940
1436.21	1986
1439.42	1974
1442.62	1912
1445.82	1960
1449.02	1948
1452.22	1982
1455.41	1936
1458.61	1942
1461.8	1988
1464.99	1914
1468.18	1970
1471.37	1938
1474.56	1954
1477.74	1932
1480.93	1916
1484.11	1940
1487.29	1918
1490.47	1954
1493.65	1940
1496.82	1974
1500	1936
1503.17	1958
1506.34	1864
1509.51	1892
1512.68	1934
1515.85	1882
1519.02	1914
1522.18	1910
1525.34	1914
1528.51	1874
1531.67	1906
1534.82	1868
1537.98	1870
1541.14	1784
1544.29	1804
1547.44	1884
1550.59	1864
1553.74	1838
1556.89	1876
1560.04	1824
1563.18	1872
1566.33	1844
1569.47	1826
1572.61	1848
1575.75	1890
1578.89	1836
1582.02	1824
1585.16	1806
1588.29	1816
1591.42	1848
1594.55	1854
1597.68	1856
1600.81	1776
1603.94	1824
1607.06	1800
1610.18	1812
1613.3	1862
1616.42	1842
1619.54	1850
1622.66	1790
1625.78	1822
1628.89	1744
1632	1858
1635.11	1822
1638.22	1850
1641.33	1792
1644.44	1820
1647.55	1862
1650.65	1754
1653.75	1806
1656.85	1794
1659.95	1760
1663.05	1748
1666.15	1720
1669.24	1746
1672.34	1776
1675.43	1760
1678.52	1738
1681.61	1770
1684.7	1692
1687.78	1726
1690.87	1708
1693.95	1746
1697.03	1702
1700.12	1688
1703.2	1676
1706.27	1710
1709.35	1684
1712.42	1684
1715.5	1654
1718.57	1684
1721.64	1652
1724.71	1708
1727.78	1708
1730.84	1708
1733.91	1648
1736.97	1694
1740.04	1660
1743.1	1688
1746.16	1684
1749.21	1702
1752.27	1670
1755.33	1686
1758.38	1612
1761.43	1690
1764.48	1634
1767.53	1680
1770.58	1650
1773.63	1692
1776.67	1656
1779.71	1588
1782.76	1612
1785.8	1642
1788.84	1632
1791.88	1628
1794.91	1610
1797.95	1642
1800.98	1618
1804.01	1622
1807.04	1554
1810.07	1586
1813.1	1614
1816.13	1604
1819.15	1610
1822.18	1622
1825.2	1568
1828.22	1562
1831.24	1580
1834.26	1546
1837.28	1532
1840.29	1568
1843.31	1562
1846.32	1578
1849.33	1516
1852.34	1498
1855.35	1546
1858.36	1548
1861.36	1510
1864.36	1532
1867.37	1552
1870.37	1548
1873.37	1462
1876.37	1478
1879.37	1570
1882.36	1508
1885.36	1482
1888.35	1502
1891.34	1504
1894.33	1522
1897.32	1496
1900.31	1506
1903.3	1504
1906.28	1534
1909.26	1462
1912.25	1482
1915.23	1490
1918.21	1432
1921.18	1460
1924.16	1454
1927.14	1436
1930.11	1440
1933.08	1472
1936.05	1436
1939.02	1474
1941.99	1488
1944.96	1480
1947.92	1448
1950.89	1428
1953.85	1438
1956.81	1408
1959.77	1416
1962.73	1394
1965.69	1420
1968.65	1454
1971.6	1398
1974.55	1412
1977.51	1448
1980.46	1390
1983.41	1382
1986.35	1424
1989.3	1404
1992.25	1390
1995.19	1392
1998.13	1414
2001.07	1394
2004.01	1380
2006.95	1394
2009.89	1342
2012.82	1350
2015.76	1406
2018.69	1392
2021.62	1398
2024.55	1340
2027.48	1380
2030.41	1358
2033.34	1380
2036.26	1334
2039.19	1400
2042.11	1364
2045.03	1326
2047.95	1312
2050.87	1344
2053.79	1296
2056.7	1344
2059.61	1318
2062.53	1364
2065.44	1344
2068.35	1298
2071.26	1334
2074.17	1322
2077.07	1320
2079.98	1330
2082.88	1300
2085.78	1294
2088.68	1292
2091.58	1308
2094.48	1242
2097.38	1284
2100.28	1310
2103.17	1314
2106.06	1272
2108.96	1258
2111.85	1328
2114.73	1250
2117.62	1270
2120.51	1264
2123.39	1250
2126.28	1234
2129.16	1256
2132.04	1260
2134.92	1264
2137.8	1242
2140.68	1254
2143.55	1264
2146.43	1250
2149.3	1252
2152.17	1220
2155.04	1212
2157.91	1262
2160.78	1238
2163.65	1228
2166.51	1240
2169.38	1188
2172.24	1234
2175.1	1146
2177.96	1176
2180.82	1190
2183.68	1192
2186.53	1198
2189.39	1172
2192.24	1148
2195.09	1138
2197.95	1090
2200.8	1162
2203.64	1134
2206.49	1150
2209.34	1172
2212.18	1134
2215.03	1160
2217.87	1114
2220.71	1164.53
2223.55	1115.07
2226.39	1126.27
2229.22	1124.03
2232.06	1146.78
2234.89	1113.93
2237.73	1134.9
2240.56	1111.43
2243.39	1116.17
2246.22	1092.03
2249.05	1117.54
2251.87	1089.22
2254.7	1101.05
2257.52	1093.49
2260.34	1062.8
2263.17	1102.91
2265.99	1063.81
2268.8	1062.97
2271.62	1066.97
2274.44	1065.21
2277.25	1025.27
2280.07	1052.74
2282.88	1034.02
2285.69	1045.85
2288.5	1026.84
2291.31	1057.23
2294.12	1026.98
2296.92	1011.25
2299.73	1021.66
2302.53	1027.02
2305.34	1012.24
2308.14	1019.77
2310.94	1013.64
2313.74	984.868
2315.86	1000
2318.67	1020
2321.48	1000
2324.29	1030
2327.09	1008
2329.9	1002
2332.7	1010
2335.51	988
2338.31	950
2341.11	1010
2343.91	1002
2346.71	994
2349.51	998
2352.3	982
2355.1	950
2357.89	976
2360.68	960
2363.48	958
2366.27	992
2369.05	962
2371.84	964
2374.63	948
2377.41	944
2380.2	952
2382.98	936
2385.76	992
2388.54	982
2391.32	960
2394.1	958
2396.87	970
2399.65	902
2402.42	914
2405.2	940
2407.97	914
2410.74	938
2413.51	934
2416.27	918
2419.04	928
2421.81	908
2424.57	946
2427.33	936
2430.1	954
2432.85	918
2435.61	926
2438.37	936
2441.13	900
2443.88	890
2446.64	884
2449.39	920
2452.14	908
2454.89	912
2457.64	926
2460.39	882
2463.14	930
2465.88	916
2468.63	890
2471.37	884
2474.11	892
2476.86	896
2479.59	908
2482.33	860
2485.07	884
2487.81	882
2490.54	872
2493.28	858
2496.01	888
2498.74	860
2501.47	874
2504.2	882
2506.93	878
2509.65	876
2512.38	838
2515.1	882
2517.82	856
2520.55	836
2523.27	902
2525.99	882
2528.7	834
2531.42	858
2534.14	842
2536.85	834
2539.56	834
2542.28	850
2544.99	860
2547.7	820
2550.4	824
2553.11	810
2555.82	806
2558.52	806
2561.23	858
2563.93	826
2566.63	826
2569.33	858
2572.03	850
2574.73	810
2577.42	810
2580.12	798
2582.81	828
2585.51	824
2588.2	786
2590.89	808
2593.58	794
2596.26	816
2598.95	784
2601.64	802
2604.32	804
2607.01	788
2609.69	798
2612.37	788
2615.05	798
2617.73	802
2620.41	784
2623.08	794
2625.76	770
2628.43	766
2631.1	790
2633.78	774
2636.45	764
2639.12	754
2641.78	784
2644.45	766
2647.12	750
2649.78	708
2652.45	748
2655.11	736
2657.77	718
2660.43	758
2663.09	738
2665.75	766
2668.4	746
2671.06	738
2673.71	750
2676.37	786
2679.02	746
2681.67	714
2684.32	780
2686.97	740
2689.61	720
2692.26	744
2694.9	712
2697.55	732
2700.19	740
2702.83	730
2705.47	700
2708.11	696
2710.75	734
2713.39	700
2716.02	708
2718.66	714
2721.29	694
2723.92	720
2726.55	706
2729.18	706
2731.81	706
2734.44	676
2737.07	700
2739.69	724
2742.32	692
2744.94	672
2747.56	690
2750.18	708
2752.8	696
2755.42	672
2758.04	680
2760.65	654
2763.27	694
2765.88	686
2768.5	650
2771.11	660
2773.72	678
2776.33	646
2778.94	670
2781.54	666
2784.15	648
2786.75	668
2789.36	650
2791.96	646
2794.56	650
2797.16	664
2799.76	654
2802.36	640
2804.96	654
2807.55	642
2810.15	646
2812.74	624
2815.33	654
2817.93	656
2820.52	636
2823.11	608
2825.69	610
2828.28	636
2830.87	632
2833.45	614
2836.03	628
2838.62	626
2841.2	620
2843.78	620
2846.36	628
2848.93	618
2851.51	590
2854.09	600
2856.66	596
2859.24	598
2861.81	610
2864.38	584
2866.95	598
2869.52	576
2872.09	592
2874.65	578
2877.22	574
2879.78	578
2882.35	576
2884.91	574
2887.47	584
2890.03	596
2892.59	572
2895.15	564
2897.7	568
2900.26	578
2902.81	592
2905.37	576
2907.92	560
2910.47	570
2913.02	584
2915.57	544
2918.12	550
2920.66	560
2923.21	546
2925.75	560
2928.3	556
2930.84	528
2933.38	558
2935.92	544
2938.46	560
2941	514
2943.54	566
2946.07	560
2948.61	554
2951.14	534
2953.67	540
2956.21	524
2958.74	510
2961.27	520
2963.79	546
2966.32	542
2968.85	536
2971.37	514
2973.9	506
2976.42	512
2978.94	534
2981.46	522
2983.98	524
2986.5	496
2989.02	476
2991.53	508
2994.05	534
2996.56	500
2999.08	536
3001.59	518
3004.1	518
3006.61	470
3009.12	506
3011.63	490
3014.13	476
3016.64	506
3019.14	508
3021.65	504
3024.15	492
3026.65	470
3029.15	478
3031.65	472
3034.15	468
3036.64	466
3039.14	468
3041.63	512.82
3044.13	448.691
3046.62	470.816
3049.11	478.802
3051.6	466.676
3054.09	459.744
3056.58	445.523
3059.07	454.736
3061.55	446.913
3064.04	460.198
3066.52	449.453
3069.01	458.864
3071.49	450.928
3073.97	455.673
3076.45	446.127
3078.93	437.621
3081.41	436.579
3083.88	449.566
3086.36	441.991
3088.83	420.445
3091.31	415.171
3093.78	414.865
3096.25	417.329
3098.72	423.417
3101.19	414.144
3103.66	419.631
3106.13	403.585
3108.59	397.101
3111.06	408.662
3113.52	409.404
3115.98	397.197
3118.45	394.417
3120.91	396.44
3123.37	390.649
3125.38	394
3127.85	376
3130.32	372
3132.79	380
3135.26	400
3137.73	380
3140.19	364
3142.66	358
3145.13	386
3147.59	380
3150.05	354
3152.51	364
3154.97	376
3157.43	366
3159.89	380
3162.35	340
3164.8	364
3167.26	386
3169.71	384
3172.17	360
3174.62	346
3177.07	352
3179.52	354
3181.97	364
3184.41	388
3186.86	366
3189.31	360
3191.75	362
3194.2	366
3196.64	336
3199.08	362
3201.52	360
3203.96	362
3206.4	346
3208.84	350
3211.27	328
3213.71	364
3216.14	370
3218.58	352
3221.01	370
3223.44	354
3225.87	360
3228.3	352
3230.73	354
3233.16	352
3235.58	354
3238.01	348
3240.43	332
3242.86	340
3245.28	324
3247.7	338
3250.12	350
3252.54	326
3254.96	334
3257.38	352
3259.79	332
3262.21	342
3264.62	324
3267.04	328
3269.45	326
3271.86	312
3274.27	332
3276.68	322
3279.09	324
3281.49	310
3283.9	330
3286.31	338
3288.71	326
3291.11	320
3293.51	320
3295.92	326
3298.32	328
3300.72	322
3303.11	314
3305.51	296
3307.91	296
3310.3	306
3312.7	320
3315.09	296
3317.48	320
3319.87	316
3322.26	310
3324.65	308
3327.04	292
3329.43	312
3331.81	300
3334.2	324
3336.58	304
3338.97	312
3341.35	282
3343.73	284
3346.11	324
3348.49	288
3350.87	308
3353.25	294
3355.62	304
3358	302
3360.37	294
3362.75	286
3365.12	284
3367.49	278
3369.86	276
3372.23	298
3374.6	268
3376.97	298
3379.33	292
3381.7	284
3384.06	304
3386.43	280
3388.79	294
3391.15	288
3393.51	298
3395.87	300
3398.23	282
3400.59	258
3402.94	276
3405.3	264
3407.65	264
3410.01	286
3412.36	280
3414.71	246
3417.06	280
3419.41	272
3421.76	284
3424.11	280
3426.46	254
3428.8	290
3431.15	260
3433.49	268
3435.83	254
3438.18	276
3440.52	260
3442.86	252
3445.2	262
3447.53	252
3449.87	272
3452.21	274
3454.54	256
3456.88	260
3459.21	250
3461.54	272
3463.88	258
3466.21	278
3468.53	256
3470.86	264
3473.19	268
3475.52	266
3477.84	268
3480.17	268
3482.49	270
3484.82	244
3487.14	248
3489.46	260
3491.78	248
3494.1	258
3496.42	236
3498.73	246
3501.05	244
3503.36	228
3505.68	246
3507.99	244
3510.3	256
3512.61	258
3514.92	246
3517.23	248
3519.54	252
3521.85	256
3524.16	236
3526.46	256
3528.77	250
3531.07	242
3533.37	232
3535.68	246
3537.98	234
3540.28	254
3542.58	244
3544.87	234
3547.17	234
3549.47	214
3551.76	234
3554.06	232
3556.35	234
3558.64	234
3560.93	224
3563.22	232
3565.51	240
3567.8	216
3570.09	230
3572.38	216
3574.66	240
3576.95	238
3579.23	234
3581.51	226
3583.8	226
3586.08	226
3588.36	240
3590.64	224
3592.92	234
3595.19	230
3597.47	232
3599.75	234
3602.02	222
3604.29	234
3606.57	224
3608.84	222
3611.11	220
3613.38	214
3615.65	226
3617.92	206
3620.18	216
3622.45	212
3624.71	224
3626.98	210
3629.24	214
3631.5	210
3633.77	222
3636.03	234
3638.29	210
3640.55	206
3642.8	218
3645.06	216
3647.32	196
3649.57	212
3651.83	192
3654.08	220
3656.33	212
3658.58	202
3660.83	212
3663.08	220
3665.33	212
3667.58	200
3669.83	188
3672.07	216
3674.32	200
3676.56	196
3678.8	210
3681.05	208
3683.29	208
3685.53	214
3687.77	200
3690.01	198
3692.24	200
3694.48	200
3696.72	192
3698.95	208
3701.19	196
3703.42	202
3705.65	194
3707.88	188
3710.11	200
3712.34	190
3714.57	194
3716.8	182
3719.03	194
3721.25	196
3723.48	186
3725.7	196
3727.92	204
3730.15	194
3732.37	188
3734.59	188
3736.81	220
3739.03	188
3741.24	190
3743.46	182
3745.68	190
3747.89	194
3750.11	186
3752.32	178
3754.53	180
3756.74	196
3758.95	188
3761.16	178
3763.37	197.913
3765.58	175.732
3767.79	191.904
3769.99	182.063
3772.2	198.094
3774.4	180.705
3776.61	170.703
3778.81	182.387
3781.01	185.092
3783.21	182.405
3785.41	177.228
3787.61	180.272
3789.81	172.267
3792	178.597
3794.2	181.654
3796.4	176.49
3798.59	172.575
3800.78	174.504
3802.98	183.199
3805.17	167.632
3807.36	184.864
3809.55	174.466
3811.74	170.658
3813.93	174.484
3816.11	173.041
3818.3	173.054
3820.49	175.284
3822.67	164.543
3824.85	174.538
3827.04	160.902
3829.22	157.894
3831.4	174.421
3833.58	168.379
3835.76	167.331
3837.94	160.843
3839.98	170
3842.17	156
3844.36	168
3846.55	148
3848.73	172
3850.92	162
3853.1	170
3855.29	164
3857.47	156
3859.65	158
3861.84	160
3864.02	146
3866.2	154
3868.38	168
3870.55	152
3872.73	164
3874.91	162
3877.08	158
3879.26	164
3881.43	170
3883.6	160
3885.78	146
3887.95	160
3890.12	164
3892.29	168
3894.46	146
3896.63	158
3898.79	156
3900.96	166
3903.12	162
3905.29	154
3907.45	160
3909.61	148
3911.78	152
3913.94	162
3916.1	150
3918.26	160
3920.41	154
3922.57	166
3924.73	156
3926.88	152
3929.04	146
3931.19	148
3933.35	154
3935.5	154
3937.65	162
3939.8	158
3941.95	146
3944.1	158
3946.25	146
3948.4	150
3950.54	144
3952.69	154
3954.83	152
3956.98	146
3959.12	144
3961.26	152
3963.4	140
3965.54	152
3967.68	136
3969.82	136
3971.96	148
3974.1	140
3976.23	148
3978.37	156
3980.5	140
3982.64	140
3984.77	154
3986.9	152
3989.03	134
3991.16	138
3993.29	138
3995.42	142
3997.55	146
3999.67	148