File: muestras/mosquito/OR_03.txt
#Acq. time (s)=	10
#Accumulations=	1
#Range (cm-¹)=	200...4000
#Windows=	5
#Autofocus=	Off
#AutoExposure=	Off
#Spike filter=	Off
#Delay time (s)=	0
#Binning=	1
#Readout mode=	Signal
#DeNoise=	Off
#ICS correction=	Off
#Dark correction=	Off
#Inst. Process=	Off
#Instrument=	LabRAM HR Evol
#Detector=	Syncerity OE
#Objective=	x100_VIS
#Grating=	600 (500nm)
#ND Filter=	25%
#Laser=	633nm_Edge
#Hole=	100.021
#Range=	Visible
#Project=	Omar
#Sample=	03-07-23
#Site=	1
#Title=	OR
#Remark=
#Date=	03.07.2023 13:29
#Acquired=	03.07.2023 13:29:37
200.404	3366
204.205	3368
208.003	3374
211.799	3340
215.595	3418
219.387	3374
223.177	3338
226.966	3428
230.752	3418
234.536	3352
238.319	3458
242.1	3540
245.879	3478
249.655	3566
253.431	3528
257.204	3456
260.976	3552
264.744	3516
268.511	3554
272.276	3542
276.04	3568
279.801	3554
283.561	3624
287.318	3614
291.074	3576
294.828	3590
298.581	3652
302.33	3720
306.079	3736
309.825	3736
313.569	3744
317.311	3696
321.052	3682
324.79	3750
328.527	3792
332.261	3752
335.994	3724
339.725	3788
343.454	3814
347.182	3824
350.907	3860
354.631	3754
358.352	3796
362.072	3872
365.789	3896
369.505	3812
373.219	3860
376.93	3908
380.642	3874
384.35	3884
388.056	3882
391.76	3892
395.463	3954
399.164	3948
402.863	3926
406.559	3944
410.254	3988
413.948	4036
417.639	4078
421.329	4092
425.016	4080
428.701	4172
432.386	4212
436.068	4144
439.748	4104
443.426	4146
447.103	4152
450.777	4208
454.45	4210
458.121	4296
461.789	4262
465.457	4184
469.122	4092
472.786	4262
476.447	4190
480.107	4270
483.765	4338
487.421	4356
491.075	4254
494.727	4338
498.377	4332
502.026	4316
505.673	4286
509.318	4296
512.962	4418
516.602	4396
520.242	4360
523.881	4406
527.516	4348
531.149	4402
534.783	4344
538.413	4342
542.041	4376
545.667	4412
549.292	4314
552.915	4390
556.537	4426
560.156	4390
563.773	4422
567.389	4318
571.004	4426
574.615	4460
578.226	4502
581.834	4466
585.44	4466
589.045	4446
592.649	4522
596.25	4508
599.85	4476
603.448	4576
607.042	4628
610.637	4586
614.229	4606
617.819	4622
621.408	4762
624.994	4646
628.58	4590
632.163	4618
635.744	4782
639.324	4712
642.902	4696
646.478	4836
650.052	4756
653.625	4798
657.196	4774
660.764	4734
664.331	4744
667.897	4754
671.46	4846
675.021	4746
678.582	4868
682.14	4778
685.696	4696
689.252	4740
692.804	4702
696.355	4792
699.905	4796
703.451	4880
706.997	4838
710.542	4780
714.083	4852
717.624	4880
721.162	4812
724.7	4990
728.235	4888
731.768	4882
735.301	4912
738.83	4908
742.358	4910
745.885	4934
749.41	4964
752.931	4896
756.453	4912
759.973	4968
763.49	4914
767.006	4902
770.52	4922
774.033	4928
777.543	4966
781.052	4974
784.559	5006
788.064	4970
791.568	4988
795.07	4982
798.57	4970
802.068	5012
805.565	5020
809.061	4984
812.553	5042
816.045	5102
819.535	5064
823.022	5164
826.508	5098
829.993	5082
833.476	5100
836.957	5126
840.436	5168
843.914	5214
847.391	5140
850.864	5236
854.337	5160
857.807	5250
861.277	5232
864.744	5184
868.209	5238
871.674	5272
875.136	5168
878.597	5296
882.056	5238
885.512	5266
888.967	5154
892.421	5254
895.874	5204
899.323	5058
902.771	5286
906.219	5182
909.664	5218
913.107	5214
916.55	5132
919.99	5232
923.428	5306
926.863	5124
930.299	5200
933.732	5308
937.164	5136
940.593	5196
944.022	5312
947.448	5400
950.874	5276
954.296	5336
957.718	5426
961.137	5382
964.555	5286
967.972	5406
971.387	5374
974.8	5330
978.21	5408
981.62	5358
985.029	5304
988.435	5422
991.839	5356
995.243	5344
998.644	5324
1002.04	5428
1005.44	5424
1008.84	5360
1012.23	5488
1015.63	5398
1019.02	5378
1022.41	5422
1025.79	5478
1029.18	5514
1032.56	5468
1035.95	5464
1039.33	5502
1042.71	5494
1046.09	5522
1049.46	5688
1052.84	5594
1056.21	5498
1059.58	5654
1062.95	5662
1066.32	5496
1069.69	5536
1073.05	5634
1076.41	5630
1079.78	5580
1083.14	5556
1086.49	5538
1089.85	5554
1093.21	5596
1096.56	5486
1099.91	5592
1103.26	5538
1106.61	5558
1109.96	5512
1113.3	5494
1116.64	5510
1119.99	5458
1123.33	5518
1126.66	5518
1130	5532
1133.34	5512
1136.67	5530
1140	5612
1143.33	5664
1146.66	5706
1149.99	5740
1153.32	5548
1156.64	5688
1159.96	5680
1163.28	5606
1166.6	5726
1169.92	5752
1173.23	5704
1176.55	5742
1179.86	5676
1183.17	5756
1186.48	5704
1189.79	5686
1193.1	5724
1196.4	5720
1199.7	5554
1203	5598
1206.3	5594
1209.6	5696
1212.9	5584
1216.19	5608
1219.49	5608
1222.78	5628
1226.07	5588
1229.36	5658
1232.65	5556
1235.93	5536
1239.21	5578
1242.5	5576
1245.78	5616
1249.06	5670
1252.33	5670
1255.61	5672
1258.88	5664
1262.16	5650
1265.43	5670
1268.7	5674
1271.96	5794
1275.23	5660
1278.5	5712
1281.76	5753.97
1285.02	5700.01
1288.28	5814.02
1291.54	5833.35
1294.8	5696.61
1298.05	5793.66
1301.31	5762.26
1304.56	5755.14
1307.81	5768.72
1311.06	5773.9
1314.3	5795.73
1317.55	5767.81
1320.79	5770.73
1324.04	5855.24
1327.28	5883.89
1330.52	5856.12
1333.76	5833.41
1336.99	5878.84
1340.23	5859.98
1343.46	5878.35
1346.69	5831.14
1349.92	5801.63
1353.15	5886.41
1356.38	5881.27
1359.6	5854.58
1362.83	5864.36
1366.05	5867.26
1369.27	5872.88
1372.49	5878.35
1375.71	5858.12
1378.93	5792.53
1382.14	5894.55
1385.35	5881.06
1388.57	5852.94
1391.2	5916
1394.43	5846
1397.65	5842
1400.87	5892
1404.09	5890
1407.31	5838
1410.53	5860
1413.74	5840
1416.96	5788
1420.17	5846
1423.38	5834
1426.59	5758
1429.8	5892
1433.01	5848
1436.21	5812
1439.42	5828
1442.62	5892
1445.82	5748
1449.02	5806
1452.22	5830
1455.41	5862
1458.61	5820
1461.8	5806
1464.99	5898
1468.18	5792
1471.37	5850
1474.56	5810
1477.74	5808
1480.93	5920
1484.11	5752
1487.29	5868
1490.47	5872
1493.65	5936
1496.82	5870
1500	5940
1503.17	5944
1506.34	5806
1509.51	5786
1512.68	5796
1515.85	5870
1519.02	5784
1522.18	5880
1525.34	5870
1528.51	5826
1531.67	5758
1534.82	5868
1537.98	5740
1541.14	5718
1544.29	5706
1547.44	5736
1550.59	5778
1553.74	5800
1556.89	5820
1560.04	5848
1563.18	5842
1566.33	5844
1569.47	5828
1572.61	5742
1575.75	5710
1578.89	5752
1582.02	5762
1585.16	5708
1588.29	5750
1591.42	5792
1594.55	5734
1597.68	5736
1600.81	5734
1603.94	5794
1607.06	5758
1610.18	5810
1613.3	5742
1616.42	5694
1619.54	5728
1622.66	5740
1625.78	5796
1628.89	5726
1632	5728
1635.11	5716
1638.22	5714
1641.33	5608
1644.44	5722
1647.55	5632
1650.65	5560
1653.75	5562
1656.85	5548
1659.95	5502
1663.05	5490
1666.15	5486
1669.24	5482
1672.34	5490
1675.43	5368
1678.52	5392
1681.61	5456
1684.7	5422
1687.78	5452
1690.87	5404
1693.95	5278
1697.03	5314
1700.12	5450
1703.2	5302
1706.27	5316
1709.35	5324
1712.42	5268
1715.5	5262
1718.57	5292
1721.64	5218
1724.71	5260
1727.78	5246
1730.84	5172
1733.91	5262
1736.97	5222
1740.04	5204
1743.1	5182
1746.16	5226
1749.21	5270
1752.27	5292
1755.33	5214
1758.38	5230
1761.43	5276
1764.48	5150
1767.53	5250
1770.58	5168
1773.63	5192
1776.67	5332
1779.71	5224
1782.76	5244
1785.8	5232
1788.84	5196
1791.88	5258
1794.91	5162
1797.95	5300
1800.98	5148
1804.01	5244
1807.04	5222
1810.07	5222
1813.1	5136
1816.13	5218
1819.15	5172
1822.18	5176
1825.2	5124
1828.22	5140
1831.24	5174
1834.26	5114
1837.28	5032
1840.29	4976
1843.31	5116
1846.32	5048
1849.33	5032
1852.34	5028
1855.35	5024
1858.36	5026
1861.36	4954
1864.36	5084
1867.37	4956
1870.37	4992
1873.37	5042
1876.37	4916
1879.37	4942
1882.36	5026
1885.36	5010
1888.35	4924
1891.34	5022
1894.33	4932
1897.32	4954
1900.31	4940
1903.3	4922
1906.28	4882
1909.26	4890
1912.25	4884
1915.23	4970
1918.21	4952
1921.18	4952
1924.16	4944
1927.14	4924
1930.11	4920
1933.08	4872
1936.05	4834
1939.02	4848
1941.99	4858
1944.96	4832
1947.92	4896
1950.89	4856
1953.85	4868
1956.81	4822
1959.77	4922
1962.73	4778
1965.69	4856
1968.65	4826
1971.6	4798
1974.55	4772
1977.51	4768
1980.46	4716
1983.41	4700
1986.35	4698
1989.3	4710
1992.25	4846
1995.19	4710
1998.13	4730
2001.07	4714
2004.01	4824
2006.95	4816
2009.89	4806
2012.82	4736
2015.76	4776
2018.69	4698
2021.62	4732
2024.55	4786
2027.48	4672
2030.41	4688
2033.34	4726
2036.26	4612
2039.19	4666
2042.11	4668
2045.03	4650
2047.95	4678
2050.87	4586
2053.79	4628
2056.7	4588
2059.61	4646
2062.53	4552
2065.44	4550
2068.35	4536
2071.26	4572
2074.17	4560
2077.07	4538
2079.98	4628
2082.88	4564
2085.78	4502
2088.68	4560
2091.58	4554
2094.48	4520
2097.38	4490
2100.28	4464
2103.17	4474
2106.06	4470
2108.96	4530
2111.85	4466
2114.73	4374
2117.62	4454
2120.51	4388
2123.39	4474
2126.28	4398
2129.16	4422
2132.04	4406
2134.92	4406
2137.8	4434
2140.68	4446
2143.55	4440
2146.43	4300
2149.3	4376
2152.17	4372
2155.04	4360
2157.91	4348
2160.78	4368
2163.65	4258
2166.51	4228
2169.38	4314
2172.24	4176
2175.1	4304
2177.96	4328
2180.82	4270
2183.68	4218
2186.53	4204
2189.39	4202
2192.24	4144
2195.09	4184
2197.95	4090
2200.8	4128
2203.64	4032
2206.49	4150
2209.34	4174
2212.18	4240
2215.03	4094
2217.87	4038
2220.71	4076.46
2223.55	4017.04
2226.39	4119.53
2229.22	4123.93
2232.06	4124.76
2234.89	4074.84
2237.73	4070.74
2240.56	4088.25
2243.39	4091.84
2246.22	4184.08
2249.05	4076.33
2251.87	4080.91
2254.7	4064.9
2257.52	4124.05
2260.34	4084.81
2263.17	4064.54
2265.99	4095.88
2268.8	4105.99
2271.62	4065.68
2274.44	4080.05
2277.25	4063.39
2280.07	4065.63
2282.88	4086.94
2285.69	4033.15
2288.5	4077.17
2291.31	4042.4
2294.12	4073.57
2296.92	4109.49
2299.73	4085.9
2302.53	4072.54
2305.34	4006.1
2308.14	4059.62
2310.94	4042.05
2313.74	4054.2
2315.86	4052
2318.67	4042
2321.48	4030
2324.29	4034
2327.09	4076
2329.9	4046
2332.7	4042
2335.51	4040
2338.31	3970
2341.11	4004
2343.91	3970
2346.71	3984
2349.51	3928
2352.3	3970
2355.1	3912
2357.89	3916
2360.68	4004
2363.48	3946
2366.27	3978
2369.05	3912
2371.84	3892
2374.63	3934
2377.41	3964
2380.2	3916
2382.98	3936
2385.76	3914
2388.54	3940
2391.32	3880
2394.1	3844
2396.87	3924
2399.65	3854
2402.42	3888
2405.2	3876
2407.97	3918
2410.74	3900
2413.51	3878
2416.27	3908
2419.04	3950
2421.81	3792
2424.57	3804
2427.33	3856
2430.1	3820
2432.85	3922
2435.61	3818
2438.37	3894
2441.13	3724
2443.88	3816
2446.64	3840
2449.39	3762
2452.14	3706
2454.89	3740
2457.64	3762
2460.39	3812
2463.14	3690
2465.88	3764
2468.63	3730
2471.37	3724
2474.11	3762
2476.86	3820
2479.59	3706
2482.33	3772
2485.07	3696
2487.81	3684
2490.54	3664
2493.28	3700
2496.01	3666
2498.74	3700
2501.47	3694
2504.2	3672
2506.93	3672
2509.65	3698
2512.38	3634
2515.1	3674
2517.82	3638
2520.55	3664
2523.27	3556
2525.99	3618
2528.7	3568
2531.42	3598
2534.14	3598
2536.85	3628
2539.56	3618
2542.28	3588
2544.99	3668
2547.7	3572
2550.4	3630
2553.11	3582
2555.82	3540
2558.52	3550
2561.23	3524
2563.93	3566
2566.63	3554
2569.33	3510
2572.03	3504
2574.73	3500
2577.42	3508
2580.12	3490
2582.81	3518
2585.51	3546
2588.2	3476
2590.89	3460
2593.58	3464
2596.26	3438
2598.95	3452
2601.64	3474
2604.32	3466
2607.01	3454
2609.69	3346
2612.37	3460
2615.05	3362
2617.73	3378
2620.41	3440
2623.08	3392
2625.76	3370
2628.43	3356
2631.1	3362
2633.78	3380
2636.45	3342
2639.12	3350
2641.78	3392
2644.45	3342
2647.12	3240
2649.78	3300
2652.45	3268
2655.11	3292
2657.77	3304
2660.43	3212
2663.09	3348
2665.75	3298
2668.4	3292
2671.06	3290
2673.71	3294
2676.37	3254
2679.02	3324
2681.67	3308
2684.32	3202
2686.97	3284
2689.61	3214
2692.26	3222
2694.9	3234
2697.55	3226
2700.19	3240
2702.83	3232
2705.47	3210
2708.11	3168
2710.75	3208
2713.39	3176
2716.02	3218
2718.66	3158
2721.29	3188
2723.92	3224
2726.55	3198
2729.18	3144
2731.81	3110
2734.44	3094
2737.07	3040
2739.69	3092
2742.32	3092
2744.94	3084
2747.56	3114
2750.18	3024
2752.8	3072
2755.42	3104
2758.04	3092
2760.65	3088
2763.27	3034
2765.88	3048
2768.5	3008
2771.11	2962
2773.72	3030
2776.33	2956
2778.94	3014
2781.54	2992
2784.15	3024
2786.75	3052
2789.36	3000
2791.96	2958
2794.56	2976
2797.16	2948
2799.76	2984
2802.36	2968
2804.96	2996
2807.55	3000
2810.15	2952
2812.74	2970
2815.33	2930
2817.93	2966
2820.52	2940
2823.11	2840
2825.69	2886
2828.28	2928
2830.87	2824
2833.45	2856
2836.03	2886
2838.62	2850
2841.2	2824
2843.78	2922
2846.36	2790
2848.93	2788
2851.51	2848
2854.09	2802
2856.66	2776
2859.24	2858
2861.81	2782
2864.38	2766
2866.95	2780
2869.52	2808
2872.09	2714
2874.65	2784
2877.22	2760
2879.78	2788
2882.35	2750
2884.91	2726
2887.47	2728
2890.03	2646
2892.59	2718
2895.15	2756
2897.7	2740
2900.26	2644
2902.81	2744
2905.37	2694
2907.92	2628
2910.47	2632
2913.02	2652
2915.57	2684
2918.12	2670
2920.66	2666
2923.21	2676
2925.75	2700
2928.3	2638
2930.84	2664
2933.38	2608
2935.92	2632
2938.46	2580
2941	2654
2943.54	2592
2946.07	2600
2948.61	2586
2951.14	2634
2953.67	2606
2956.21	2592
2958.74	2606
2961.27	2570
2963.79	2556
2966.32	2578
2968.85	2526
2971.37	2552
2973.9	2518
2976.42	2488
2978.94	2540
2981.46	2500
2983.98	2520
2986.5	2470
2989.02	2466
2991.53	2476
2994.05	2494
2996.56	2476
2999.08	2500
3001.59	2450
3004.1	2426
3006.61	2432
3009.12	2418
3011.63	2392
3014.13	2410
3016.64	2448
3019.14	2380
3021.65	2380
3024.15	2380
3026.65	2364
3029.15	2362
3031.65	2384
3034.15	2392
3036.64	2380
3039.14	2368
3041.63	2357.03
3044.13	2311.65
3046.62	2336.5
3049.11	2295.2
3051.6	2309.86
3054.09	2272.58
3056.58	2315.11
3059.07	2280.42
3061.55	2283.13
3064.04	2316.15
3066.52	2279
3069.01	2273.15
3071.49	2237.91
3073.97	2259.97
3076.45	2224.12
3078.93	2227.86
3081.41	2228.53
3083.88	2189.92
3086.36	2207.64
3088.83	2218.14
3091.31	2173.06
3093.78	2180.38
3096.25	2180.46
3098.72	2153.62
3101.19	2141.79
3103.66	2099.84
3106.13	2121.71
3108.59	2063.55
3111.06	2101.9
3113.52	2122.26
3115.98	2065.58
3118.45	2049.68
3120.91	2053.97
3123.37	2051.51
3125.38	2056
3127.85	2008
3130.32	2018
3132.79	2028
3135.26	2012
3137.73	1976
3140.19	2004
3142.66	2016
3145.13	2044
3147.59	1990
3150.05	2058
3152.51	2004
3154.97	1948
3157.43	1974
3159.89	2002
3162.35	1914
3164.8	1978
3167.26	1948
3169.71	1940
3172.17	1992
3174.62	1966
3177.07	1878
3179.52	1946
3181.97	1936
3184.41	1948
3186.86	1914
3189.31	1938
3191.75	1978
3194.2	1958
3196.64	1934
3199.08	1882
3201.52	1878
3203.96	1924
3206.4	1916
3208.84	1828
3211.27	1852
3213.71	1904
3216.14	1908
3218.58	1914
3221.01	1886
3223.44	1862
3225.87	1902
3228.3	1848
3230.73	1834
3233.16	1876
3235.58	1834
3238.01	1798
3240.43	1854
3242.86	1896
3245.28	1766
3247.7	1826
3250.12	1856
3252.54	1798
3254.96	1786
3257.38	1794
3259.79	1826
3262.21	1782
3264.62	1804
3267.04	1788
3269.45	1788
3271.86	1764
3274.27	1822
3276.68	1762
3279.09	1762
3281.49	1752
3283.9	1740
3286.31	1736
3288.71	1726
3291.11	1724
3293.51	1784
3295.92	1752
3298.32	1748
3300.72	1742
3303.11	1752
3305.51	1696
3307.91	1742
3310.3	1672
3312.7	1704
3315.09	1704
3317.48	1672
3319.87	1690
3322.26	1658
3324.65	1694
3327.04	1694
3329.43	1680
3331.81	1678
3334.2	1700
3336.58	1750
3338.97	1692
3341.35	1672
3343.73	1650
3346.11	1662
3348.49	1714
3350.87	1616
3353.25	1672
3355.62	1688
3358	1672
3360.37	1688
3362.75	1662
3365.12	1678
3367.49	1652
3369.86	1604
3372.23	1646
3374.6	1628
3376.97	1632
3379.33	1618
3381.7	1604
3384.06	1590
3386.43	1662
3388.79	1612
3391.15	1578
3393.51	1614
3395.87	1602
3398.23	1522
3400.59	1582
3402.94	1596
3405.3	1562
3407.65	1520
3410.01	1592
3412.36	1514
3414.71	1518
3417.06	1556
3419.41	1586
3421.76	1524
3424.11	1580
3426.46	1516
3428.8	1484
3431.15	1562
3433.49	1540
3435.83	1504
3438.18	1506
3440.52	1466
3442.86	1518
3445.2	1534
3447.53	1504
3449.87	1556
3452.21	1510
3454.54	1496
3456.88	1484
3459.21	1470
3461.54	1526
3463.88	1514
3466.21	1460
3468.53	1434
3470.86	1526
3473.19	1466
3475.52	1418
3477.84	1462
3480.17	1492
3482.49	1434
3484.82	1442
3487.14	1490
3489.46	1430
3491.78	1412
3494.1	1434
3496.42	1416
3498.73	1422
3501.05	1410
3503.36	1412
3505.68	1458
3507.99	1434
3510.3	1398
3512.61	1404
3514.92	1464
3517.23	1394
3519.54	1398
3521.85	1402
3524.16	1400
3526.46	1404
3528.77	1424
3531.07	1388
3533.37	1426
3535.68	1380
3537.98	1424
3540.28	1370
3542.58	1450
3544.87	1344
3547.17	1420
3549.47	1368
3551.76	1344
3554.06	1370
3556.35	1352
3558.64	1352
3560.93	1336
3563.22	1376
3565.51	1386
3567.8	1378
3570.09	1308
3572.38	1372
3574.66	1328
3576.95	1322
3579.23	1342
3581.51	1360
3583.8	1350
3586.08	1332
3588.36	1316
3590.64	1308
3592.92	1332
3595.19	1264
3597.47	1338
3599.75	1314
3602.02	1340
3604.29	1300
3606.57	1272
3608.84	1306
3611.11	1272
3613.38	1306
3615.65	1290
3617.92	1290
3620.18	1230
3622.45	1252
3624.71	1270
3626.98	1292
3629.24	1286
3631.5	1268
3633.77	1266
3636.03	1258
3638.29	1274
3640.55	1240
3642.8	1280
3645.06	1258
3647.32	1226
3649.57	1258
3651.83	1242
3654.08	1268
3656.33	1256
3658.58	1220
3660.83	1248
3663.08	1242
3665.33	1216
3667.58	1220
3669.83	1246
3672.07	1234
3674.32	1228
3676.56	1198
3678.8	1200
3681.05	1204
3683.29	1182
3685.53	1166
3687.77	1206
3690.01	1220
3692.24	1216
3694.48	1178
3696.72	1178
3698.95	1182
3701.19	1210
3703.42	1220
3705.65	1218
3707.88	1170
3710.11	1218
3712.34	1204
3714.57	1224
3716.8	1190
3719.03	1158
3721.25	1182
3723.48	1182
3725.7	1140
3727.92	1190
3730.15	1188
3732.37	1176
3734.59	1180
3736.81	1160
3739.03	1174
3741.24	1156
3743.46	1186
3745.68	1126
3747.89	1132
3750.11	1166
3752.32	1144
3754.53	1148
3756.74	1142
3758.95	1126
3761.16	1118
3763.37	1096.16
3765.58	1156.29
3767.79	1158.55
3769.99	1125.81
3772.2	1151.56
3774.4	1134.68
3776.61	1095.93
3778.81	1150.2
3781.01	1121.79
3783.21	1101.62
3785.41	1114.99
3787.61	1110.16
3789.81	1111.69
3792	1132.89
3794.2	1099.96
3796.4	1129.01
3798.59	1101.07
3800.78	1106.99
3802.98	1078.12
3805.17	1111.04
3807.36	1076.59
3809.55	1111.79
3811.74	1077.29
3813.93	1084.41
3816.11	1097.92
3818.3	1088.13
3820.49	1058.4
3822.67	1091.52
3824.85	1065.2
3827.04	1070.81
3829.22	1085.29
3831.4	1061.75
3833.58	1042.61
3835.76	1097.03
3837.94	1080.73
3839.98	1102
3842.17	1060
3844.36	1042
3846.55	1046
3848.73	1016
3850.92	1042
3853.1	1048
3855.29	1066
3857.47	1032
3859.65	1028
3861.84	1044
3864.02	1030
3866.2	1076
3868.38	1032
3870.55	1030
3872.73	1018
3874.91	1028
3877.08	1050
3879.26	1034
3881.43	998
3883.6	1012
3885.78	1058
3887.95	1002
3890.12	1036
3892.29	1028
3894.46	1008
3896.63	1016
3898.79	990
3900.96	1046
3903.12	996
3905.29	1016
3907.45	1026
3909.61	998
3911.78	1028
3913.94	1016
3916.1	1028
3918.26	1020
3920.41	1034
3922.57	1010
3924.73	988
3926.88	988
3929.04	984
3931.19	1008
3933.35	974
3935.5	974
3937.65	974
3939.8	980
3941.95	962
3944.1	992
3946.25	922
3948.4	980
3950.54	954
3952.69	986
3954.83	974
3956.98	962
3959.12	990
3961.26	980
3963.4	930
3965.54	960
3967.68	946
3969.82	972
3971.96	964
3974.1	968
3976.23	932
3978.37	954
3980.5	952
3982.64	954
3984.77	944
3986.9	946
3989.03	942
3991.16	986
3993.29	958
3995.42	930
3997.55	914
3999.67	932