File: muestras/mosquito/OR_08.txt
#Acq. time (s)=	10
#Accumulations=	1
#Range (cm-¹)=	200...4000
#Windows=	5
#Autofocus=	Off
#AutoExposure=	Off
#Spike filter=	Off
#Delay time (s)=	0
#Binning=	1
#Readout mode=	Signal
#DeNoise=	Off
#ICS correction=	Off
#Dark correction=	Off
#Inst. Process=	Off
#Instrument=	LabRAM HR Evol
#Detector=	Syncerity OE
#Objective=	x100_VIS
#Grating=	600 (500nm)
#ND Filter=	25%
#Laser=	633nm_Edge
#Hole=	100.021
#Range=	Visible
#Project=	Omar
#Sample=	03-07-23
#Site=	1
#Title=	OR
#Remark=
#Date=	03.07.2023 13:38
#Acquired=	03.07.2023 13:38:08
200.404	2274
204.205	2286
208.003	2312
211.799	2350
215.595	2312
219.387	2342
223.177	2398
226.966	2414
230.752	2334
234.536	2294
238.319	2406
242.1	2418
245.879	2420
249.655	2348
253.431	2370
257.204	2406
260.976	2450
264.744	2398
268.511	2454
272.276	2340
276.04	2400
279.801	2482
283.561	2422
287.318	2434
291.074	2480
294.828	2474
298.581	2446
302.33	2448
306.079	2514
309.825	2504
313.569	2514
317.311	2520
321.052	2492
324.79	2506
328.527	2514
332.261	2568
335.994	2594
339.725	2548
343.454	2536
347.182	2588
350.907	2606
354.631	2588
358.352	2626
362.072	2586
365.789	2536
369.505	2592
373.219	2610
376.93	2616
380.642	2618
384.35	2648
388.056	2562
391.76	2660
395.463	2664
399.164	2598
402.863	2604
406.559	2634
410.254	2674
413.948	2672
417.639	2700
421.329	2728
425.016	2694
428.701	2828
432.386	2830
436.068	2786
439.748	2814
443.426	2790
447.103	2842
450.777	2848
454.45	2830
458.121	2808
461.789	2824
465.457	2756
469.122	2872
472.786	2828
476.447	2846
480.107	2862
483.765	2834
487.421	2920
491.075	2848
494.727	2850
498.377	2912
502.026	2960
505.673	2916
509.318	2932
512.962	2964
516.602	2954
520.242	2906
523.881	2948
527.516	2912
531.149	2848
534.783	2924
538.413	2964
542.041	2928
545.667	2888
549.292	2904
552.915	2896
556.537	2926
560.156	2956
563.773	3008
567.389	2906
571.004	2942
574.615	3002
578.226	2926
581.834	3030
585.44	3004
589.045	3036
592.649	3004
596.25	3042
599.85	3056
603.448	3006
607.042	3048
610.637	3028
614.229	3074
617.819	3146
621.408	3090
624.994	3158
628.58	3078
632.163	3084
635.744	3062
639.324	3188
642.902	3160
646.478	3168
650.052	3170
653.625	3098
657.196	3200
660.764	3190
664.331	3254
667.897	3196
671.46	3180
675.021	3150
678.582	3202
682.14	3190
685.696	3184
689.252	3188
692.804	3120
696.355	3192
699.905	3164
703.451	3156
706.997	3186
710.542	3272
714.083	3184
717.624	3272
721.162	3262
724.7	3246
728.235	3246
731.768	3234
735.301	3236
738.83	3242
742.358	3230
745.885	3278
749.41	3270
752.931	3246
756.453	3286
759.973	3334
763.49	3304
767.006	3292
770.52	3338
774.033	3240
777.543	3264
781.052	3274
784.559	3298
788.064	3386
791.568	3364
795.07	3338
798.57	3322
802.068	3300
805.565	3318
809.061	3278
812.553	3358
816.045	3412
819.535	3392
823.022	3340
826.508	3398
829.993	3450
833.476	3410
836.957	3456
840.436	3424
843.914	3502
847.391	3410
850.864	3464
854.337	3452
857.807	3436
861.277	3518
864.744	3496
868.209	3454
871.674	3390
875.136	3470
878.597	3426
882.056	3438
885.512	3468
888.967	3432
892.421	3460
895.874	3408
899.323	3458
902.771	3390
906.219	3500
909.664	3450
913.107	3380
916.55	3464
919.99	3440
923.428	3452
926.863	3484
930.299	3498
933.732	3512
937.164	3408
940.593	3528
944.022	3552
947.448	3476
950.874	3486
954.296	3538
957.718	3530
961.137	3564
964.555	3556
967.972	3572
971.387	3584
974.8	3554
978.21	3572
981.62	3596
985.029	3520
988.435	3636
991.839	3612
995.243	3628
998.644	3620
1002.04	3602
1005.44	3560
1008.84	3634
1012.23	3614
1015.63	3632
1019.02	3612
1022.41	3692
1025.79	3696
1029.18	3686
1032.56	3678
1035.95	3726
1039.33	3656
1042.71	3686
1046.09	3736
1049.46	3756
1052.84	3660
1056.21	3678
1059.58	3762
1062.95	3674
1066.32	3682
1069.69	3774
1073.05	3690
1076.41	3688
1079.78	3816
1083.14	3740
1086.49	3788
1089.85	3730
1093.21	3694
1096.56	3770
1099.91	3712
1103.26	3718
1106.61	3666
1109.96	3698
1113.3	3734
1116.64	3784
1119.99	3684
1123.33	3726
1126.66	3790
1130	3756
1133.34	3798
1136.67	3766
1140	3806
1143.33	3802
1146.66	3782
1149.99	3836
1153.32	3902
1156.64	3840
1159.96	3808
1163.28	3870
1166.6	3906
1169.92	3900
1173.23	3810
1176.55	3886
1179.86	3912
1183.17	3868
1186.48	3904
1189.79	3894
1193.1	3804
1196.4	3910
1199.7	3874
1203	3868
1206.3	3826
1209.6	3856
1212.9	3850
1216.19	3932
1219.49	3808
1222.78	3924
1226.07	3852
1229.36	3832
1232.65	3834
1235.93	3838
1239.21	3886
1242.5	3836
1245.78	3898
1249.06	3932
1252.33	3890
1255.61	3796
1258.88	3906
1262.16	3858
1265.43	3980
1268.7	3906
1271.96	3856
1275.23	3978
1278.5	3972
1281.76	3968.43
1285.02	3944.71
1288.28	3998.63
1291.54	3968.7
1294.8	4007.37
1298.05	4073.12
1301.31	4035.95
1304.56	4035.24
1307.81	3984.82
1311.06	4057.74
1314.3	4014.3
1317.55	4095.24
1320.79	4136.19
1324.04	4105.98
1327.28	4111.63
1330.52	4144.49
1333.76	4125.2
1336.99	4103.45
1340.23	4152.37
1343.46	4135.44
1346.69	4172.92
1349.92	4178
1353.15	4186.52
1356.38	4171.9
1359.6	4205.96
1362.83	4207
1366.05	4118.64
1369.27	4187.26
1372.49	4208.74
1375.71	4126.29
1378.93	4191.16
1382.14	4193.92
1385.35	4181.16
1388.57	4205.56
1391.2	4192
1394.43	4244
1397.65	4256
1400.87	4184
1404.09	4152
1407.31	4174
1410.53	4142
1413.74	4220
1416.96	4158
1420.17	4176
1423.38	4212
1426.59	4176
1429.8	4184
1433.01	4078
1436.21	4214
1439.42	4186
1442.62	4226
1445.82	4154
1449.02	4084
1452.22	4190
1455.41	4178
1458.61	4158
1461.8	4206
1464.99	4252
1468.18	4294
1471.37	4270
1474.56	4250
1477.74	4198
1480.93	4232
1484.11	4326
1487.29	4292
1490.47	4226
1493.65	4254
1496.82	4234
1500	4164
1503.17	4186
1506.34	4304
1509.51	4274
1512.68	4242
1515.85	4280
1519.02	4150
1522.18	4150
1525.34	4126
1528.51	4232
1531.67	4132
1534.82	4170
1537.98	4232
1541.14	4210
1544.29	4180
1547.44	4218
1550.59	4212
1553.74	4212
1556.89	4258
1560.04	4294
1563.18	4166
1566.33	4226
1569.47	4206
1572.61	4188
1575.75	4232
1578.89	4256
1582.02	4178
1585.16	4178
1588.29	4090
1591.42	4264
1594.55	4142
1597.68	4224
1600.81	4198
1603.94	4246
1607.06	4330
1610.18	4206
1613.3	4204
1616.42	4180
1619.54	4228
1622.66	4234
1625.78	4248
1628.89	4066
1632	4206
1635.11	4196
1638.22	4094
1641.33	4186
1644.44	4118
1647.55	4152
1650.65	4092
1653.75	3972
1656.85	4012
1659.95	3984
1663.05	3964
1666.15	3974
1669.24	3964
1672.34	3864
1675.43	3906
1678.52	3958
1681.61	3908
1684.7	3826
1687.78	3870
1690.87	3878
1693.95	3864
1697.03	3924
1700.12	3928
1703.2	3776
1706.27	3830
1709.35	3822
1712.42	3840
1715.5	3862
1718.57	3752
1721.64	3814
1724.71	3814
1727.78	3908
1730.84	3754
1733.91	3852
1736.97	3830
1740.04	3758
1743.1	3852
1746.16	3898
1749.21	3842
1752.27	3818
1755.33	3834
1758.38	3870
1761.43	3868
1764.48	3854
1767.53	3842
1770.58	3776
1773.63	3888
1776.67	3814
1779.71	3822
1782.76	3796
1785.8	3804
1788.84	3818
1791.88	3754
1794.91	3818
1797.95	3790
1800.98	3772
1804.01	3800
1807.04	3868
1810.07	3798
1813.1	3746
1816.13	3750
1819.15	3686
1822.18	3726
1825.2	3730
1828.22	3750
1831.24	3708
1834.26	3722
1837.28	3666
1840.29	3716
1843.31	3762
1846.32	3662
1849.33	3670
1852.34	3704
1855.35	3672
1858.36	3696
1861.36	3670
1864.36	3724
1867.37	3700
1870.37	3708
1873.37	3656
1876.37	3682
1879.37	3652
1882.36	3604
1885.36	3652
1888.35	3664
1891.34	3668
1894.33	3682
1897.32	3702
1900.31	3620
1903.3	3648
1906.28	3626
1909.26	3698
1912.25	3616
1915.23	3624
1918.21	3678
1921.18	3670
1924.16	3576
1927.14	3604
1930.11	3608
1933.08	3610
1936.05	3680
1939.02	3534
1941.99	3576
1944.96	3638
1947.92	3620
1950.89	3618
1953.85	3574
1956.81	3524
1959.77	3546
1962.73	3606
1965.69	3578
1968.65	3562
1971.6	3504
1974.55	3540
1977.51	3564
1980.46	3522
1983.41	3498
1986.35	3566
1989.3	3582
1992.25	3570
1995.19	3556
1998.13	3546
2001.07	3474
2004.01	3546
2006.95	3506
2009.89	3520
2012.82	3530
2015.76	3528
2018.69	3472
2021.62	3396
2024.55	3490
2027.48	3506
2030.41	3454
2033.34	3544
2036.26	3510
2039.19	3468
2042.11	3430
2045.03	3440
2047.95	3408
2050.87	3420
2053.79	3438
2056.7	3384
2059.61	3508
2062.53	3450
2065.44	3382
2068.35	3464
2071.26	3456
2074.17	3424
2077.07	3494
2079.98	3448
2082.88	3414
2085.78	3426
2088.68	3366
2091.58	3338
2094.48	3444
2097.38	3256
2100.28	3318
2103.17	3370
2106.06	3320
2108.96	3396
2111.85	3384
2114.73	3352
2117.62	3356
2120.51	3286
2123.39	3288
2126.28	3322
2129.16	3308
2132.04	3326
2134.92	3270
2137.8	3284
2140.68	3256
2143.55	3322
2146.43	3242
2149.3	3304
2152.17	3248
2155.04	3300
2157.91	3244
2160.78	3270
2163.65	3248
2166.51	3204
2169.38	3210
2172.24	3170
2175.1	3234
2177.96	3282
2180.82	3158
2183.68	3158
2186.53	3186
2189.39	3126
2192.24	3140
2195.09	3166
2197.95	3116
2200.8	3134
2203.64	3106
2206.49	3054
2209.34	3120
2212.18	3090
2215.03	3062
2217.87	3184
2220.71	3095.47
2223.55	3120.76
2226.39	3103.95
2229.22	3136.97
2232.06	3092.45
2234.89	3061.07
2237.73	3067.06
2240.56	3078.52
2243.39	3099.45
2246.22	3162.34
2249.05	3136.19
2251.87	3164.28
2254.7	3127.4
2257.52	3133.75
2260.34	3130.23
2263.17	3145.97
2265.99	3158.57
2268.8	3149.45
2271.62	3108.31
2274.44	3105.26
2277.25	3134.38
2280.07	3109.07
2282.88	3142.28
2285.69	3150.54
2288.5	3097.19
2291.31	3133.32
2294.12	3171.13
2296.92	3152.06
2299.73	3150.81
2302.53	3114.67
2305.34	3146.4
2308.14	3134.21
2310.94	3091.68
2313.74	3135.69
2315.86	3212
2318.67	3164
2321.48	3094
2324.29	3108
2327.09	3084
2329.9	3194
2332.7	3114
2335.51	3032
2338.31	3102
2341.11	3054
2343.91	3102
2346.71	3078
2349.51	3066
2352.3	3074
2355.1	3072
2357.89	3090
2360.68	3082
2363.48	3082
2366.27	3112
2369.05	3042
2371.84	3068
2374.63	3026
2377.41	3072
2380.2	3058
2382.98	3020
2385.76	3004
2388.54	3048
2391.32	3024
2394.1	3020
2396.87	3012
2399.65	3060
2402.42	2994
2405.2	3084
2407.97	2988
2410.74	3008
2413.51	2952
2416.27	3052
2419.04	2984
2421.81	3020
2424.57	3014
2427.33	3002
2430.1	2954
2432.85	3000
2435.61	2972
2438.37	2962
2441.13	2924
2443.88	2948
2446.64	2930
2449.39	2974
2452.14	3020
2454.89	2956
2457.64	3000
2460.39	2950
2463.14	3000
2465.88	2898
2468.63	2974
2471.37	2978
2474.11	2916
2476.86	2950
2479.59	2922
2482.33	2886
2485.07	2908
2487.81	2884
2490.54	2934
2493.28	2930
2496.01	2870
2498.74	2896
2501.47	2902
2504.2	2870
2506.93	2848
2509.65	2934
2512.38	2818
2515.1	2878
2517.82	2894
2520.55	2910
2523.27	2858
2525.99	2770
2528.7	2890
2531.42	2796
2534.14	2792
2536.85	2794
2539.56	2800
2542.28	2828
2544.99	2864
2547.7	2820
2550.4	2838
2553.11	2796
2555.82	2786
2558.52	2796
2561.23	2728
2563.93	2808
2566.63	2812
2569.33	2722
2572.03	2718
2574.73	2754
2577.42	2770
2580.12	2738
2582.81	2712
2585.51	2770
2588.2	2760
2590.89	2758
2593.58	2672
2596.26	2748
2598.95	2722
2601.64	2670
2604.32	2718
2607.01	2748
2609.69	2742
2612.37	2680
2615.05	2662
2617.73	2712
2620.41	2684
2623.08	2676
2625.76	2670
2628.43	2670
2631.1	2674
2633.78	2696
2636.45	2628
2639.12	2578
2641.78	2680
2644.45	2644
2647.12	2616
2649.78	2600
2652.45	2676
2655.11	2628
2657.77	2594
2660.43	2592
2663.09	2654
2665.75	2586
2668.4	2624
2671.06	2662
2673.71	2650
2676.37	2576
2679.02	2652
2681.67	2612
2684.32	2626
2686.97	2524
2689.61	2618
2692.26	2570
2694.9	2494
2697.55	2582
2700.19	2534
2702.83	2604
2705.47	2584
2708.11	2562
2710.75	2526
2713.39	2544
2716.02	2516
2718.66	2500
2721.29	2488
2723.92	2532
2726.55	2502
2729.18	2524
2731.81	2462
2734.44	2464
2737.07	2498
2739.69	2408
2742.32	2482
2744.94	2448
2747.56	2428
2750.18	2446
2752.8	2444
2755.42	2420
2758.04	2436
2760.65	2430
2763.27	2418
2765.88	2452
2768.5	2384
2771.11	2368
2773.72	2426
2776.33	2426
2778.94	2368
2781.54	2344
2784.15	2428
2786.75	2396
2789.36	2378
2791.96	2372
2794.56	2344
2797.16	2362
2799.76	2324
2802.36	2334
2804.96	2322
2807.55	2406
2810.15	2410
2812.74	2334
2815.33	2350
2817.93	2364
2820.52	2334
2823.11	2290
2825.69	2308
2828.28	2348
2830.87	2334
2833.45	2258
2836.03	2272
2838.62	2326
2841.2	2330
2843.78	2312
2846.36	2320
2848.93	2270
2851.51	2308
2854.09	2340
2856.66	2236
2859.24	2214
2861.81	2242
2864.38	2232
2866.95	2244
2869.52	2248
2872.09	2188
2874.65	2228
2877.22	2178
2879.78	2214
2882.35	2142
2884.91	2192
2887.47	2206
2890.03	2178
2892.59	2204
2895.15	2170
2897.7	2168
2900.26	2176
2902.81	2162
2905.37	2196
2907.92	2160
2910.47	2142
2913.02	2178
2915.57	2214
2918.12	2198
2920.66	2204
2923.21	2180
2925.75	2170
2928.3	2224
2930.84	2130
2933.38	2150
2935.92	2092
2938.46	2140
2941	2124
2943.54	2144
2946.07	2094
2948.61	2114
2951.14	2104
2953.67	2144
2956.21	2056
2958.74	2096
2961.27	2126
2963.79	2086
2966.32	2112
2968.85	2062
2971.37	2028
2973.9	2082
2976.42	2094
2978.94	1982
2981.46	2018
2983.98	2104
2986.5	2066
2989.02	1998
2991.53	2028
2994.05	2064
2996.56	2002
2999.08	2024
3001.59	2012
3004.1	2022
3006.61	2004
3009.12	1970
3011.63	1968
3014.13	1980
3016.64	1938
3019.14	1910
3021.65	1986
3024.15	1920
3026.65	1948
3029.15	1934
3031.65	1914
3034.15	1948
3036.64	1928
3039.14	1882
3041.63	1956.45
3044.13	1900.81
3046.62	1943.47
3049.11	1858
3051.6	1899.11
3054.09	1892.74
3056.58	1890.94
3059.07	1867.53
3061.55	1861.73
3064.04	1876.62
3066.52	1851.33
3069.01	1898.3
3071.49	1841.11
3073.97	1857.23
3076.45	1824.25
3078.93	1874.31
3081.41	1840.33
3083.88	1816.67
3086.36	1832.93
3088.83	1840.13
3091.31	1829.97
3093.78	1779.06
3096.25	1801.12
3098.72	1785.71
3101.19	1766.34
3103.66	1783.42
3106.13	1761.47
3108.59	1758.52
3111.06	1708.93
3113.52	1727.82
3115.98	1734.4
3118.45	1710.14
3120.91	1727.66
3123.37	1733.05
3125.38	1716
3127.85	1720
3130.32	1764
3132.79	1662
3135.26	1760
3137.73	1674
3140.19	1696
3142.66	1680
3145.13	1636
3147.59	1664
3150.05	1692
3152.51	1646
3154.97	1682
3157.43	1658
3159.89	1712
3162.35	1678
3164.8	1642
3167.26	1646
3169.71	1674
3172.17	1594
3174.62	1698
3177.07	1606
3179.52	1646
3181.97	1654
3184.41	1630
3186.86	1636
3189.31	1588
3191.75	1580
3194.2	1590
3196.64	1648
3199.08	1634
3201.52	1624
3203.96	1584
3206.4	1570
3208.84	1592
3211.27	1616
3213.71	1626
3216.14	1576
3218.58	1604
3221.01	1598
3223.44	1580
3225.87	1618
3228.3	1604
3230.73	1578
3233.16	1594
3235.58	1582
3238.01	1522
3240.43	1556
3242.86	1526
3245.28	1610
3247.7	1492
3250.12	1556
3252.54	1546
3254.96	1524
3257.38	1526
3259.79	1518
3262.21	1514
3264.62	1516
3267.04	1522
3269.45	1528
3271.86	1502
3274.27	1500
3276.68	1484
3279.09	1440
3281.49	1462
3283.9	1502
3286.31	1522
3288.71	1472
3291.11	1508
3293.51	1480
3295.92	1502
3298.32	1486
3300.72	1432
3303.11	1492
3305.51	1440
3307.91	1526
3310.3	1438
3312.7	1462
3315.09	1412
3317.48	1418
3319.87	1440
3322.26	1452
3324.65	1482
3327.04	1434
3329.43	1452
3331.81	1412
3334.2	1438
3336.58	1420
3338.97	1420
3341.35	1432
3343.73	1472
3346.11	1442
3348.49	1420
3350.87	1402
3353.25	1376
3355.62	1394
3358	1384
3360.37	1410
3362.75	1400
3365.12	1390
3367.49	1380
3369.86	1398
3372.23	1396
3374.6	1396
3376.97	1378
3379.33	1402
3381.7	1376
3384.06	1376
3386.43	1384
3388.79	1360
3391.15	1390
3393.51	1310
3395.87	1348
3398.23	1344
3400.59	1356
3402.94	1344
3405.3	1366
3407.65	1346
3410.01	1364
3412.36	1332
3414.71	1304
3417.06	1364
3419.41	1316
3421.76	1352
3424.11	1338
3426.46	1276
3428.8	1284
3431.15	1286
3433.49	1254
3435.83	1298
3438.18	1294
3440.52	1296
3442.86	1292
3445.2	1304
3447.53	1266
3449.87	1250
3452.21	1304
3454.54	1304
3456.88	1280
3459.21	1254
3461.54	1228
3463.88	1286
3466.21	1262
3468.53	1266
3470.86	1246
3473.19	1256
3475.52	1256
3477.84	1272
3480.17	1246
3482.49	1216
3484.82	1220
3487.14	1260
3489.46	1218
3491.78	1210
3494.1	1214
3496.42	1198
3498.73	1236
3501.05	1242
3503.36	1242
3505.68	1224
3507.99	1252
3510.3	1224
3512.61	1218
3514.92	1230
3517.23	1246
3519.54	1222
3521.85	1224
3524.16	1204
3526.46	1232
3528.77	1238
3531.07	1214
3533.37	1152
3535.68	1162
3537.98	1212
3540.28	1200
3542.58	1186
3544.87	1180
3547.17	1188
3549.47	1176
3551.76	1146
3554.06	1230
3556.35	1204
3558.64	1158
3560.93	1190
3563.22	1158
3565.51	1220
3567.8	1174
3570.09	1156
3572.38	1176
3574.66	1162
3576.95	1192
3579.23	1158
3581.51	1152
3583.8	1178
3586.08	1134
3588.36	1140
3590.64	1112
3592.92	1154
3595.19	1134
3597.47	1144
3599.75	1140
3602.02	1112
3604.29	1160
3606.57	1148
3608.84	1122
3611.11	1092
3613.38	1108
3615.65	1166
3617.92	1066
3620.18	1072
3622.45	1132
3624.71	1124
3626.98	1092
3629.24	1082
3631.5	1100
3633.77	1110
3636.03	1088
3638.29	1072
3640.55	1070
3642.8	1080
3645.06	1058
3647.32	1074
3649.57	1078
3651.83	1076
3654.08	1106
3656.33	1094
3658.58	1038
3660.83	1078
3663.08	1064
3665.33	1050
3667.58	1062
3669.83	1086
3672.07	1046
3674.32	1050
3676.56	1054
3678.8	1028
3681.05	1074
3683.29	1070
3685.53	1078
3687.77	1002
3690.01	1068
3692.24	1024
3694.48	1040
3696.72	1074
3698.95	1044
3701.19	1054
3703.42	1024
3705.65	1040
3707.88	1040
3710.11	1004
3712.34	1002
3714.57	1030
3716.8	1022
3719.03	988
3721.25	992
3723.48	958
3725.7	1040
3727.92	1032
3730.15	1022
3732.37	1020
3734.59	996
3736.81	1004
3739.03	1030
3741.24	1022
3743.46	990
3745.68	1008
3747.89	992
3750.11	970
3752.32	1004
3754.53	988
3756.74	984
3758.95	1008
3761.16	954
3763.37	996
3765.58	1009.14
3767.79	981.216
3769.99	961.034
3772.2	990.393
3774.4	964.861
3776.61	951.772
3778.81	990.276
3781.01	1000.96
3783.21	965.563
3785.41	966.776
3787.61	975.353
3789.81	960.476
3792	964.58
3794.2	996.998
3796.4	966.784
3798.59	969.343
3800.78	978.529
3802.98	969.906
3805.17	939.632
3807.36	956.966
3809.55	947.69
3811.74	950.111
3813.93	943.787
3816.11	951.229
3818.3	942.387
3820.49	930.006
3822.67	919.684
3824.85	941.821
3827.04	912.465
3829.22	938.168
3831.4	944.595
3833.58	950.214
3835.76	913.207
3837.94	889.261
3839.98	960
3842.17	930
3844.36	924
3846.55	950
3848.73	906
3850.92	900
3853.1	924
3855.29	930
3857.47	880
3859.65	968
3861.84	898
3864.02	890
3866.2	908
3868.38	900
3870.55	906
3872.73	880
3874.91	912
3877.08	900
3879.26	902
3881.43	894
3883.6	880
3885.78	928
3887.95	888
3890.12	908
3892.29	926
3894.46	920
3896.63	870
3898.79	882
3900.96	896
3903.12	884
3905.29	884
3907.45	922
3909.61	876
3911.78	852
3913.94	874
3916.1	878
3918.26	882
3920.41	870
3922.57	894
3924.73	896
3926.88	840
3929.04	876
3931.19	836
3933.35	862
3935.5	884
3937.65	866
3939.8	874
3941.95	832
3944.1	860
3946.25	870
3948.4	848
3950.54	838
3952.69	862
3954.83	860
3956.98	856
3959.12	860
3961.26	870
3963.4	828
3965.54	870
3967.68	834
3969.82	832
3971.96	824
3974.1	850
3976.23	818
3978.37	846
3980.5	814
3982.64	806
3984.77	862
3986.9	816
3989.03	834
3991.16	808
3993.29	804
3995.42	838
3997.55	818
3999.67	826