File: muestras/mosquito/OR_09.txt
#Acq. time (s)=	10
#Accumulations=	1
#Range (cm-¹)=	200...4000
#Windows=	5
#Autofocus=	Off
#AutoExposure=	Off
#Spike filter=	Off
#Delay time (s)=	0
#Binning=	1
#Readout mode=	Signal
#DeNoise=	Off
#ICS correction=	Off
#Dark correction=	Off
#Inst. Process=	Off
#Instrument=	LabRAM HR Evol
#Detector=	Syncerity OE
#Objective=	x100_VIS
#Grating=	600 (500nm)
#ND Filter=	25%
#Laser=	633nm_Edge
#Hole=	100.021
#Range=	Visible
#Project=	Omar
#Sample=	03-07-23
#Site=	1
#Title=	OR
#Remark=
#Date=	03.07.2023 13:41
#Acquired=	03.07.2023 13:41:30
200.404	900
204.205	892
208.003	880
211.799	874
215.595	898
219.387	900
223.177	938
226.966	934
230.752	924
234.536	930
238.319	934
242.1	942
245.879	964
249.655	954
253.431	974
257.204	940
260.976	952
264.744	924
268.511	966
272.276	918
276.04	952
279.801	984
283.561	968
287.318	936
291.074	946
294.828	986
298.581	992
302.33	1002
306.079	1048
309.825	1006
313.569	1016
317.311	1014
321.052	974
324.79	996
328.527	1024
332.261	1010
335.994	1018
339.725	1042
343.454	1034
347.182	1026
350.907	1038
354.631	1026
358.352	1028
362.072	1014
365.789	1060
369.505	1000
373.219	1020
376.93	1054
380.642	1060
384.35	1046
388.056	1016
391.76	1058
395.463	1030
399.164	1090
402.863	1054
406.559	1086
410.254	1068
413.948	1072
417.639	1114
421.329	1096
425.016	1140
428.701	1128
432.386	1142
436.068	1160
439.748	1134
443.426	1174
447.103	1090
450.777	1142
454.45	1202
458.121	1138
461.789	1160
465.457	1146
469.122	1186
472.786	1132
476.447	1170
480.107	1160
483.765	1170
487.421	1160
491.075	1148
494.727	1140
498.377	1192
502.026	1194
505.673	1196
509.318	1196
512.962	1168
516.602	1170
520.242	1210
523.881	1228
527.516	1194
531.149	1210
534.783	1188
538.413	1200
542.041	1212
545.667	1188
549.292	1218
552.915	1232
556.537	1218
560.156	1178
563.773	1218
567.389	1226
571.004	1234
574.615	1240
578.226	1266
581.834	1232
585.44	1268
589.045	1268
592.649	1258
596.25	1222
599.85	1242
603.448	1292
607.042	1242
610.637	1248
614.229	1244
617.819	1350
621.408	1316
624.994	1250
628.58	1338
632.163	1298
635.744	1334
639.324	1366
642.902	1336
646.478	1340
650.052	1344
653.625	1366
657.196	1320
660.764	1344
664.331	1346
667.897	1394
671.46	1390
675.021	1366
678.582	1364
682.14	1358
685.696	1332
689.252	1368
692.804	1394
696.355	1408
699.905	1356
703.451	1382
706.997	1370
710.542	1354
714.083	1368
717.624	1356
721.162	1380
724.7	1410
728.235	1408
731.768	1438
735.301	1438
738.83	1398
742.358	1454
745.885	1416
749.41	1444
752.931	1406
756.453	1398
759.973	1412
763.49	1402
767.006	1442
770.52	1428
774.033	1434
777.543	1436
781.052	1442
784.559	1476
788.064	1422
791.568	1462
795.07	1458
798.57	1452
802.068	1448
805.565	1464
809.061	1470
812.553	1464
816.045	1456
819.535	1530
823.022	1504
826.508	1470
829.993	1488
833.476	1522
836.957	1478
840.436	1488
843.914	1528
847.391	1528
850.864	1556
854.337	1526
857.807	1566
861.277	1512
864.744	1554
868.209	1548
871.674	1514
875.136	1532
878.597	1544
882.056	1532
885.512	1562
888.967	1554
892.421	1538
895.874	1598
899.323	1518
902.771	1572
906.219	1560
909.664	1562
913.107	1536
916.55	1518
919.99	1542
923.428	1572
926.863	1582
930.299	1556
933.732	1604
937.164	1574
940.593	1578
944.022	1540
947.448	1616
950.874	1624
954.296	1646
957.718	1596
961.137	1610
964.555	1632
967.972	1626
971.387	1630
974.8	1654
978.21	1634
981.62	1590
985.029	1686
988.435	1606
991.839	1664
995.243	1676
998.644	1580
1002.04	1648
1005.44	1612
1008.84	1574
1012.23	1636
1015.63	1666
1019.02	1678
1022.41	1556
1025.79	1650
1029.18	1658
1032.56	1676
1035.95	1660
1039.33	1662
1042.71	1696
1046.09	1708
1049.46	1710
1052.84	1648
1056.21	1666
1059.58	1680
1062.95	2856
1066.32	1690
1069.69	1690
1073.05	1690
1076.41	1702
1079.78	1704
1083.14	1666
1086.49	1688
1089.85	1700
1093.21	1672
1096.56	1644
1099.91	1646
1103.26	1704
1106.61	1700
1109.96	1606
1113.3	1660
1116.64	1684
1119.99	1628
1123.33	1686
1126.66	1650
1130	1702
1133.34	1684
1136.67	1688
1140	1692
1143.33	1744
1146.66	1696
1149.99	1722
1153.32	1680
1156.64	1724
1159.96	1744
1163.28	1692
1166.6	1736
1169.92	1782
1173.23	1738
1176.55	1736
1179.86	1734
1183.17	1748
1186.48	1722
1189.79	1730
1193.1	1714
1196.4	1712
1199.7	1710
1203	1702
1206.3	1774
1209.6	1658
1212.9	1700
1216.19	1680
1219.49	1660
1222.78	1634
1226.07	1734
1229.36	1684
1232.65	1640
1235.93	1666
1239.21	1726
1242.5	1668
1245.78	1684
1249.06	1684
1252.33	1754
1255.61	1650
1258.88	1654
1262.16	1710
1265.43	1658
1268.7	1716
1271.96	1698
1275.23	1714
1278.5	1702
1281.76	1709.27
1285.02	1685.49
1288.28	1688.37
1291.54	1670.75
1294.8	1722.15
1298.05	1698.95
1301.31	1697.14
1304.56	1676.73
1307.81	1630.09
1311.06	1643.92
1314.3	1653.17
1317.55	1654.5
1320.79	1626.57
1324.04	1611.45
1327.28	1641.05
1330.52	1609.35
1333.76	1618.96
1336.99	1609.84
1340.23	1599.23
1343.46	1586.89
1346.69	1598.21
1349.92	1555.11
1353.15	1592.99
1356.38	1560.8
1359.6	1601.55
1362.83	1585.57
1366.05	1566.3
1369.27	1516.63
1372.49	1554.83
1375.71	1554
1378.93	1534.79
1382.14	1511.88
1385.35	1541.22
1388.57	1507.58
1391.2	1506
1394.43	1542
1397.65	1516
1400.87	1536
1404.09	1480
1407.31	1464
1410.53	1504
1413.74	1498
1416.96	1502
1420.17	1482
1423.38	1504
1426.59	1500
1429.8	1502
1433.01	1434
1436.21	1442
1439.42	1490
1442.62	1456
1445.82	1462
1449.02	1452
1452.22	1450
1455.41	1452
1458.61	1480
1461.8	1470
1464.99	1442
1468.18	1474
1471.37	1482
1474.56	1450
1477.74	1424
1480.93	1476
1484.11	1408
1487.29	1418
1490.47	1484
1493.65	1420
1496.82	1448
1500	1456
1503.17	1458
1506.34	1456
1509.51	1468
1512.68	1474
1515.85	1460
1519.02	1432
1522.18	1442
1525.34	1434
1528.51	1428
1531.67	1408
1534.82	1416
1537.98	1420
1541.14	1434
1544.29	1428
1547.44	1396
1550.59	1398
1553.74	1460
1556.89	1386
1560.04	1406
1563.18	1422
1566.33	1424
1569.47	1368
1572.61	1378
1575.75	1404
1578.89	1350
1582.02	1414
1585.16	1392
1588.29	1384
1591.42	1422
1594.55	1432
1597.68	1398
1600.81	1444
1603.94	1398
1607.06	1432
1610.18	1378
1613.3	1426
1616.42	1360
1619.54	1378
1622.66	1338
1625.78	1374
1628.89	1382
1632	1334
1635.11	1360
1638.22	1314
1641.33	1346
1644.44	1306
1647.55	1334
1650.65	1372
1653.75	1336
1656.85	1350
1659.95	1328
1663.05	1324
1666.15	1336
1669.24	1298
1672.34	1312
1675.43	1308
1678.52	1314
1681.61	1250
1684.7	1294
1687.78	1284
1690.87	1298
1693.95	1242
1697.03	1310
1700.12	1252
1703.2	1226
1706.27	1296
1709.35	1204
1712.42	1250
1715.5	1240
1718.57	1280
1721.64	1262
1724.71	1264
1727.78	1256
1730.84	1258
1733.91	1258
1736.97	1204
1740.04	1230
1743.1	1252
1746.16	1186
1749.21	1272
1752.27	1232
1755.33	1182
1758.38	1222
1761.43	1228
1764.48	1218
1767.53	1230
1770.58	1224
1773.63	1168
1776.67	1188
1779.71	1196
1782.76	1216
1785.8	1184
1788.84	1246
1791.88	1196
1794.91	1140
1797.95	1204
1800.98	1200
1804.01	1192
1807.04	1184
1810.07	1200
1813.1	1178
1816.13	1162
1819.15	1184
1822.18	1172
1825.2	1210
1828.22	1148
1831.24	1226
1834.26	1158
1837.28	1146
1840.29	1156
1843.31	1162
1846.32	1146
1849.33	1164
1852.34	1116
1855.35	1146
1858.36	1162
1861.36	1120
1864.36	1126
1867.37	1144
1870.37	1134
1873.37	1152
1876.37	1126
1879.37	1100
1882.36	1114
1885.36	1136
1888.35	1116
1891.34	1148
1894.33	1084
1897.32	1134
1900.31	1066
1903.3	1098
1906.28	1154
1909.26	1138
1912.25	1120
1915.23	1128
1918.21	1084
1921.18	1102
1924.16	1122
1927.14	1124
1930.11	1102
1933.08	1066
1936.05	1072
1939.02	1124
1941.99	1080
1944.96	1090
1947.92	1088
1950.89	1068
1953.85	1056
1956.81	1062
1959.77	1044
1962.73	1094
1965.69	1068
1968.65	1090
1971.6	1076
1974.55	1080
1977.51	1034
1980.46	1088
1983.41	1038
1986.35	1106
1989.3	1040
1992.25	1064
1995.19	1046
1998.13	1042
2001.07	1048
2004.01	1016
2006.95	1022
2009.89	1050
2012.82	1012
2015.76	1026
2018.69	1074
2021.62	1016
2024.55	1062
2027.48	1062
2030.41	998
2033.34	1046
2036.26	1024
2039.19	1024
2042.11	1028
2045.03	1030
2047.95	1040
2050.87	1006
2053.79	1076
2056.7	1008
2059.61	1008
2062.53	1004
2065.44	986
2068.35	1014
2071.26	992
2074.17	980
2077.07	958
2079.98	1002
2082.88	978
2085.78	972
2088.68	998
2091.58	996
2094.48	976
2097.38	922
2100.28	964
2103.17	944
2106.06	950
2108.96	998
2111.85	964
2114.73	1004
2117.62	996
2120.51	972
2123.39	968
2126.28	984
2129.16	970
2132.04	972
2134.92	968
2137.8	952
2140.68	934
2143.55	974
2146.43	918
2149.3	930
2152.17	952
2155.04	946
2157.91	920
2160.78	930
2163.65	936
2166.51	928
2169.38	920
2172.24	890
2175.1	920
2177.96	970
2180.82	864
2183.68	882
2186.53	874
2189.39	930
2192.24	878
2195.09	946
2197.95	880
2200.8	894
2203.64	884
2206.49	880
2209.34	880
2212.18	896
2215.03	886
2217.87	888
2220.71	913.035
2223.55	884.045
2226.39	886.268
2229.22	892.443
2232.06	866.87
2234.89	858.345
2237.73	853.419
2240.56	868.86
2243.39	855.831
2246.22	872.963
2249.05	848.358
2251.87	861.193
2254.7	850.375
2257.52	814.394
2260.34	836.619
2263.17	829.665
2265.99	847.989
2268.8	830.357
2271.62	843.762
2274.44	841.458
2277.25	847.679
2280.07	819.497
2282.88	813.463
2285.69	848.365
2288.5	835.962
2291.31	807.505
2294.12	808.973
2296.92	811.686
2299.73	818.289
2302.53	829.137
2305.34	830.098
2308.14	817.24
2310.94	788.863
2313.74	794.752
2315.86	824
2318.67	806
2321.48	808
2324.29	776
2327.09	792
2329.9	784
2332.7	786
2335.51	806
2338.31	792
2341.11	760
2343.91	780
2346.71	774
2349.51	782
2352.3	788
2355.1	788
2357.89	812
2360.68	772
2363.48	774
2366.27	758
2369.05	762
2371.84	754
2374.63	772
2377.41	762
2380.2	724
2382.98	778
2385.76	734
2388.54	786
2391.32	784
2394.1	776
2396.87	780
2399.65	768
2402.42	784
2405.2	732
2407.97	770
2410.74	746
2413.51	730
2416.27	794
2419.04	744
2421.81	754
2424.57	774
2427.33	726
2430.1	758
2432.85	754
2435.61	770
2438.37	752
2441.13	702
2443.88	754
2446.64	742
2449.39	758
2452.14	740
2454.89	730
2457.64	754
2460.39	730
2463.14	720
2465.88	758
2468.63	720
2471.37	768
2474.11	730
2476.86	760
2479.59	740
2482.33	766
2485.07	718
2487.81	730
2490.54	728
2493.28	730
2496.01	716
2498.74	698
2501.47	696
2504.2	718
2506.93	688
2509.65	706
2512.38	696
2515.1	714
2517.82	700
2520.55	726
2523.27	688
2525.99	688
2528.7	710
2531.42	700
2534.14	702
2536.85	688
2539.56	682
2542.28	696
2544.99	706
2547.7	708
2550.4	718
2553.11	712
2555.82	672
2558.52	702
2561.23	714
2563.93	708
2566.63	658
2569.33	676
2572.03	674
2574.73	678
2577.42	664
2580.12	712
2582.81	656
2585.51	696
2588.2	664
2590.89	672
2593.58	668
2596.26	668
2598.95	658
2601.64	664
2604.32	656
2607.01	676
2609.69	662
2612.37	618
2615.05	642
2617.73	664
2620.41	652
2623.08	644
2625.76	628
2628.43	634
2631.1	680
2633.78	634
2636.45	646
2639.12	612
2641.78	654
2644.45	628
2647.12	658
2649.78	618
2652.45	636
2655.11	642
2657.77	614
2660.43	616
2663.09	604
2665.75	644
2668.4	602
2671.06	630
2673.71	612
2676.37	642
2679.02	616
2681.67	630
2684.32	606
2686.97	600
2689.61	632
2692.26	616
2694.9	608
2697.55	596
2700.19	600
2702.83	608
2705.47	622
2708.11	612
2710.75	586
2713.39	586
2716.02	606
2718.66	584
2721.29	572
2723.92	582
2726.55	584
2729.18	582
2731.81	564
2734.44	594
2737.07	576
2739.69	584
2742.32	588
2744.94	594
2747.56	602
2750.18	568
2752.8	560
2755.42	576
2758.04	580
2760.65	586
2763.27	596
2765.88	580
2768.5	584
2771.11	584
2773.72	574
2776.33	574
2778.94	574
2781.54	560
2784.15	556
2786.75	544
2789.36	544
2791.96	582
2794.56	566
2797.16	550
2799.76	554
2802.36	556
2804.96	552
2807.55	558
2810.15	548
2812.74	540
2815.33	544
2817.93	554
2820.52	576
2823.11	536
2825.69	530
2828.28	542
2830.87	520
2833.45	528
2836.03	506
2838.62	550
2841.2	510
2843.78	558
2846.36	532
2848.93	552
2851.51	500
2854.09	510
2856.66	512
2859.24	532
2861.81	508
2864.38	536
2866.95	524
2869.52	526
2872.09	524
2874.65	488
2877.22	504
2879.78	506
2882.35	494
2884.91	490
2887.47	508
2890.03	518
2892.59	494
2895.15	518
2897.7	486
2900.26	510
2902.81	484
2905.37	506
2907.92	496
2910.47	498
2913.02	492
2915.57	480
2918.12	498
2920.66	476
2923.21	496
2925.75	456
2928.3	472
2930.84	476
2933.38	468
2935.92	502
2938.46	470
2941	490
2943.54	484
2946.07	448
2948.61	490
2951.14	468
2953.67	470
2956.21	476
2958.74	478
2961.27	422
2963.79	440
2966.32	450
2968.85	478
2971.37	464
2973.9	452
2976.42	446
2978.94	468
2981.46	464
2983.98	468
2986.5	470
2989.02	456
2991.53	464
2994.05	446
2996.56	452
2999.08	450
3001.59	436
3004.1	418
3006.61	448
3009.12	456
3011.63	432
3014.13	436
3016.64	450
3019.14	414
3021.65	420
3024.15	420
3026.65	432
3029.15	436
3031.65	458
3034.15	418
3036.64	424
3039.14	420
3041.63	421.867
3044.13	403.205
3046.62	423.561
3049.11	404.887
3051.6	420.219
3054.09	424.768
3056.58	426.333
3059.07	395.157
3061.55	392.53
3064.04	394.612
3066.52	417.366
3069.01	393.923
3071.49	409.393
3073.97	380.548
3076.45	395.879
3078.93	386.127
3081.41	376.888
3083.88	379.765
3086.36	397.234
3088.83	397.045
3091.31	381.911
3093.78	381.516
3096.25	365.595
3098.72	379.666
3101.19	371.747
3103.66	386.838
3106.13	364.01
3108.59	352.388
3111.06	376.041
3113.52	355.749
3115.98	360.227
3118.45	358.228
3120.91	352.147
3123.37	356.639
3125.38	360
3127.85	356
3130.32	354
3132.79	366
3135.26	342
3137.73	358
3140.19	328
3142.66	370
3145.13	346
3147.59	350
3150.05	336
3152.51	336
3154.97	320
3157.43	334
3159.89	340
3162.35	358
3164.8	338
3167.26	290
3169.71	320
3172.17	314
3174.62	336
3177.07	340
3179.52	334
3181.97	336
3184.41	320
3186.86	322
3189.31	320
3191.75	300
3194.2	308
3196.64	334
3199.08	360
3201.52	310
3203.96	312
3206.4	332
3208.84	340
3211.27	318
3213.71	314
3216.14	318
3218.58	326
3221.01	320
3223.44	330
3225.87	306
3228.3	326
3230.73	318
3233.16	326
3235.58	324
3238.01	358
3240.43	328
3242.86	338
3245.28	312
3247.7	306
3250.12	310
3252.54	318
3254.96	304
3257.38	314
3259.79	316
3262.21	296
3264.62	312
3267.04	288
3269.45	326
3271.86	294
3274.27	310
3276.68	296
3279.09	288
3281.49	292
3283.9	294
3286.31	318
3288.71	292
3291.11	294
3293.51	294
3295.92	320
3298.32	284
3300.72	290
3303.11	286
3305.51	278
3307.91	296
3310.3	270
3312.7	286
3315.09	264
3317.48	278
3319.87	272
3322.26	274
3324.65	280
3327.04	286
3329.43	292
3331.81	290
3334.2	308
3336.58	276
3338.97	288
3341.35	266
3343.73	300
3346.11	286
3348.49	260
3350.87	250
3353.25	278
3355.62	272
3358	270
3360.37	272
3362.75	260
3365.12	262
3367.49	274
3369.86	278
3372.23	270
3374.6	272
3376.97	268
3379.33	258
3381.7	278
3384.06	276
3386.43	256
3388.79	258
3391.15	270
3393.51	272
3395.87	244
3398.23	264
3400.59	272
3402.94	270
3405.3	252
3407.65	258
3410.01	260
3412.36	256
3414.71	256
3417.06	256
3419.41	250
3421.76	256
3424.11	258
3426.46	256
3428.8	270
3431.15	254
3433.49	266
3435.83	236
3438.18	238
3440.52	256
3442.86	250
3445.2	256
3447.53	250
3449.87	256
3452.21	272
3454.54	236
3456.88	250
3459.21	232
3461.54	252
3463.88	238
3466.21	250
3468.53	274
3470.86	234
3473.19	240
3475.52	230
3477.84	266
3480.17	246
3482.49	252
3484.82	226
3487.14	244
3489.46	244
3491.78	258
3494.1	230
3496.42	230
3498.73	256
3501.05	236
3503.36	268
3505.68	232
3507.99	242
3510.3	238
3512.61	254
3514.92	234
3517.23	232
3519.54	228
3521.85	240
3524.16	238
3526.46	238
3528.77	252
3531.07	226
3533.37	240
3535.68	238
3537.98	250
3540.28	224
3542.58	236
3544.87	224
3547.17	222
3549.47	236
3551.76	232
3554.06	220
3556.35	240
3558.64	228
3560.93	222
3563.22	212
3565.51	234
3567.8	218
3570.09	228
3572.38	212
3574.66	220
3576.95	226
3579.23	212
3581.51	208
3583.8	230
3586.08	218
3588.36	212
3590.64	232
3592.92	214
3595.19	206
3597.47	226
3599.75	206
3602.02	216
3604.29	224
3606.57	218
3608.84	234
3611.11	212
3613.38	220
3615.65	228
3617.92	216
3620.18	204
3622.45	200
3624.71	202
3626.98	208
3629.24	224
3631.5	212
3633.77	210
3636.03	210
3638.29	210
3640.55	202
3642.8	206
3645.06	222
3647.32	194
3649.57	200
3651.83	212
3654.08	202
3656.33	212
3658.58	202
3660.83	194
3663.08	204
3665.33	194
3667.58	196
3669.83	188
3672.07	196
3674.32	218
3676.56	206
3678.8	208
3681.05	188
3683.29	202
3685.53	196
3687.77	184
3690.01	202
3692.24	188
3694.48	212
3696.72	192
3698.95	212
3701.19	190
3703.42	204
3705.65	218
3707.88	186
3710.11	194
3712.34	202
3714.57	192
3716.8	188
3719.03	180
3721.25	208
3723.48	188
3725.7	198
3727.92	190
3730.15	194
3732.37	194
3734.59	188
3736.81	186
3739.03	182
3741.24	178
3743.46	204
3745.68	196
3747.89	192
3750.11	180
3752.32	190
3754.53	182
3756.74	188
3758.95	190
3761.16	192
3763.37	199.903
3765.58	201.328
3767.79	181.59
3769.99	180.551
3772.2	193.812
3774.4	199.438
3776.61	182.604
3778.81	185.386
3781.01	174.741
3783.21	185.43
3785.41	177.32
3787.61	182.061
3789.81	174
3792	186.253
3794.2	188.325
3796.4	182.468
3798.59	174.25
3800.78	184.983
3802.98	184.824
3805.17	179.461
3807.36	174.399
3809.55	181.366
3811.74	170.885
3813.93	172.967
3816.11	187.862
3818.3	175.692
3820.49	172.613
3822.67	176.678
3824.85	169.447
3827.04	172.874
3829.22	168.842
3831.4	182.519
3833.58	180.835
3835.76	174.174
3837.94	165.29
3839.98	178
3842.17	170
3844.36	180
3846.55	168
3848.73	178
3850.92	178
3853.1	176
3855.29	182
3857.47	168
3859.65	166
3861.84	160
3864.02	158
3866.2	170
3868.38	160
3870.55	166
3872.73	168
3874.91	162
3877.08	146
3879.26	168
3881.43	162
3883.6	168
3885.78	162
3887.95	166
3890.12	166
3892.29	158
3894.46	158
3896.63	152
3898.79	166
3900.96	164
3903.12	158
3905.29	170
3907.45	156
3909.61	168
3911.78	172
3913.94	156
3916.1	170
3918.26	158
3920.41	160
3922.57	168
3924.73	152
3926.88	168
3929.04	162
3931.19	164
3933.35	146
3935.5	156
3937.65	150
3939.8	158
3941.95	148
3944.1	172
3946.25	158
3948.4	160
3950.54	146
3952.69	160
3954.83	164
3956.98	162
3959.12	156
3961.26	146
3963.4	164
3965.54	160
3967.68	144
3969.82	162
3971.96	144
3974.1	164
3976.23	156
3978.37	162
3980.5	156
3982.64	152
3984.77	154
3986.9	160
3989.03	152
3991.16	156
3993.29	150
3995.42	164
3997.55	136
3999.67	140