File: muestras/mosquito/OR_05.txt
#Acq. time (s)=	10
#Accumulations=	1
#Range (cm-¹)=	200...4000
#Windows=	5
#Autofocus=	Off
#AutoExposure=	Off
#Spike filter=	Off
#Delay time (s)=	0
#Binning=	1
#Readout mode=	Signal
#DeNoise=	Off
#ICS correction=	Off
#Dark correction=	Off
#Inst. Process=	Off
#Instrument=	LabRAM HR Evol
#Detector=	Syncerity OE
#Objective=	x100_VIS
#Grating=	600 (500nm)
#ND Filter=	25%
#Laser=	633nm_Edge
#Hole=	100.021
#Range=	Visible
#Project=	Omar
#Sample=	03-07-23
#Site=	1
#Title=	OR
#Remark=
#Date=	03.07.2023 13:33
#Acquired=	03.07.2023 13:33:22
200.404	2582
204.205	2562
208.003	2578
211.799	2608
215.595	2640
219.387	2592
223.177	2626
226.966	2612
230.752	2672
234.536	2644
238.319	2722
242.1	2718
245.879	2798
249.655	2742
253.431	2746
257.204	2716
260.976	2730
264.744	2644
268.511	2678
272.276	2722
276.04	2718
279.801	2716
283.561	2738
287.318	2790
291.074	2778
294.828	2828
298.581	2844
302.33	2748
306.079	2828
309.825	2800
313.569	2848
317.311	2850
321.052	2886
324.79	2914
328.527	2838
332.261	2834
335.994	2904
339.725	2860
343.454	2920
347.182	2876
350.907	2964
354.631	2826
358.352	2936
362.072	2918
365.789	2938
369.505	2982
373.219	2980
376.93	2994
380.642	2956
384.35	2960
388.056	3034
391.76	2982
395.463	3006
399.164	3026
402.863	3002
406.559	3052
410.254	3010
413.948	3072
417.639	3102
421.329	3144
425.016	3124
428.701	3054
432.386	3124
436.068	3202
439.748	3220
443.426	3226
447.103	3162
450.777	3220
454.45	3230
458.121	3176
461.789	3172
465.457	3232
469.122	3212
472.786	3176
476.447	3184
480.107	3264
483.765	3314
487.421	3286
491.075	3288
494.727	3322
498.377	3262
502.026	3294
505.673	3348
509.318	3304
512.962	3264
516.602	3320
520.242	3304
523.881	3358
527.516	3310
531.149	3288
534.783	3352
538.413	3334
542.041	3382
545.667	3288
549.292	3350
552.915	3320
556.537	3326
560.156	3386
563.773	3406
567.389	3382
571.004	3372
574.615	3364
578.226	3352
581.834	3348
585.44	3362
589.045	3394
592.649	3336
596.25	3412
599.85	3482
603.448	3484
607.042	3514
610.637	3498
614.229	3460
617.819	3522
621.408	3530
624.994	3544
628.58	3536
632.163	3630
635.744	3532
639.324	3610
642.902	3554
646.478	3648
650.052	3582
653.625	3484
657.196	3564
660.764	3702
664.331	3612
667.897	3596
671.46	3580
675.021	3568
678.582	3592
682.14	3626
685.696	3620
689.252	3630
692.804	3584
696.355	3620
699.905	3642
703.451	3630
706.997	3624
710.542	3624
714.083	3692
717.624	3624
721.162	3728
724.7	3652
728.235	3752
731.768	3730
735.301	3718
738.83	3756
742.358	3778
745.885	3778
749.41	3700
752.931	3778
756.453	3594
759.973	3706
763.49	3740
767.006	3706
770.52	3708
774.033	3754
777.543	3708
781.052	3706
784.559	3758
788.064	3712
791.568	3810
795.07	3728
798.57	3794
802.068	3838
805.565	3822
809.061	3760
812.553	3744
816.045	3808
819.535	3862
823.022	3870
826.508	3834
829.993	3822
833.476	3882
836.957	3844
840.436	3928
843.914	3828
847.391	3898
850.864	3874
854.337	3898
857.807	3904
861.277	3952
864.744	3864
868.209	3968
871.674	3930
875.136	3874
878.597	3924
882.056	3880
885.512	3970
888.967	3888
892.421	3990
895.874	3934
899.323	3918
902.771	4046
906.219	3902
909.664	3862
913.107	3866
916.55	3956
919.99	3956
923.428	3950
926.863	3986
930.299	3996
933.732	4014
937.164	3876
940.593	4016
944.022	3950
947.448	3998
950.874	4018
954.296	4014
957.718	4064
961.137	3994
964.555	4092
967.972	4078
971.387	4090
974.8	4084
978.21	4038
981.62	4158
985.029	4036
988.435	4106
991.839	4126
995.243	4092
998.644	4104
1002.04	4048
1005.44	4180
1008.84	4084
1012.23	4074
1015.63	4162
1019.02	4124
1022.41	4032
1025.79	4084
1029.18	4186
1032.56	4154
1035.95	4086
1039.33	4112
1042.71	4212
1046.09	4160
1049.46	4192
1052.84	4146
1056.21	4214
1059.58	4274
1062.95	4244
1066.32	4178
1069.69	4202
1073.05	4290
1076.41	4222
1079.78	4250
1083.14	4262
1086.49	4244
1089.85	4186
1093.21	4226
1096.56	4212
1099.91	4114
1103.26	4256
1106.61	4226
1109.96	4204
1113.3	4192
1116.64	4114
1119.99	4134
1123.33	4258
1126.66	4234
1130	4204
1133.34	4228
1136.67	4284
1140	4294
1143.33	4330
1146.66	4364
1149.99	4244
1153.32	4296
1156.64	4410
1159.96	4418
1163.28	4380
1166.6	4392
1169.92	4412
1173.23	4470
1176.55	4470
1179.86	4420
1183.17	4428
1186.48	4408
1189.79	4374
1193.1	4368
1196.4	4388
1199.7	4334
1203	4348
1206.3	4322
1209.6	4270
1212.9	4272
1216.19	4304
1219.49	4252
1222.78	4288
1226.07	4310
1229.36	4344
1232.65	4346
1235.93	4266
1239.21	4388
1242.5	4374
1245.78	4288
1249.06	4370
1252.33	4378
1255.61	4392
1258.88	4398
1262.16	4366
1265.43	4414
1268.7	4468
1271.96	4440
1275.23	4310
1278.5	4460
1281.76	4391.17
1285.02	4358.47
1288.28	4476.5
1291.54	4520.55
1294.8	4455.92
1298.05	4557.73
1301.31	4522.4
1304.56	4572.86
1307.81	4541.41
1311.06	4523.7
1314.3	4558.41
1317.55	4555.1
1320.79	4578.65
1324.04	4570.38
1327.28	4604.58
1330.52	4593.04
1333.76	4634.12
1336.99	4660.75
1340.23	4663.65
1343.46	4642.16
1346.69	4648.33
1349.92	4659.91
1353.15	4705.05
1356.38	4638.58
1359.6	4683.11
1362.83	4709.41
1366.05	4720.21
1369.27	4721.86
1372.49	4701.3
1375.71	4719.17
1378.93	4747.27
1382.14	4757.77
1385.35	4774.74
1388.57	4672.67
1391.2	4678
1394.43	4686
1397.65	4774
1400.87	4716
1404.09	4704
1407.31	4680
1410.53	4728
1413.74	4702
1416.96	4630
1420.17	4680
1423.38	4636
1426.59	4670
1429.8	4706
1433.01	4762
1436.21	4678
1439.42	4620
1442.62	4658
1445.82	4706
1449.02	4780
1452.22	4688
1455.41	4672
1458.61	4654
1461.8	4704
1464.99	4704
1468.18	4800
1471.37	4764
1474.56	4682
1477.74	4796
1480.93	4734
1484.11	4770
1487.29	4718
1490.47	4714
1493.65	4774
1496.82	4758
1500	4730
1503.17	4756
1506.34	4692
1509.51	4688
1512.68	4730
1515.85	4736
1519.02	4742
1522.18	4788
1525.34	4716
1528.51	4696
1531.67	4754
1534.82	4698
1537.98	4750
1541.14	4658
1544.29	4716
1547.44	4666
1550.59	4726
1553.74	4648
1556.89	4740
1560.04	4754
1563.18	4678
1566.33	4664
1569.47	4788
1572.61	4784
1575.75	4724
1578.89	4678
1582.02	4742
1585.16	4644
1588.29	4656
1591.42	4642
1594.55	4712
1597.68	4718
1600.81	4676
1603.94	4626
1607.06	4720
1610.18	4668
1613.3	4742
1616.42	4698
1619.54	4732
1622.66	4728
1625.78	4736
1628.89	4732
1632	4792
1635.11	4664
1638.22	4612
1641.33	4634
1644.44	4580
1647.55	4530
1650.65	4522
1653.75	4544
1656.85	4554
1659.95	4460
1663.05	4422
1666.15	4508
1669.24	4434
1672.34	4358
1675.43	4376
1678.52	4426
1681.61	4390
1684.7	4380
1687.78	4320
1690.87	4424
1693.95	4264
1697.03	4330
1700.12	4330
1703.2	4298
1706.27	4284
1709.35	4346
1712.42	4244
1715.5	4318
1718.57	4264
1721.64	4290
1724.71	4234
1727.78	4300
1730.84	4298
1733.91	4300
1736.97	4204
1740.04	4208
1743.1	4252
1746.16	4354
1749.21	4270
1752.27	4274
1755.33	4218
1758.38	4170
1761.43	4256
1764.48	4230
1767.53	4280
1770.58	4244
1773.63	4342
1776.67	4188
1779.71	4246
1782.76	4228
1785.8	4336
1788.84	4262
1791.88	4238
1794.91	4202
1797.95	4244
1800.98	4322
1804.01	4192
1807.04	4208
1810.07	4202
1813.1	4166
1816.13	4270
1819.15	4226
1822.18	4174
1825.2	4164
1828.22	4214
1831.24	4172
1834.26	4228
1837.28	4210
1840.29	4138
1843.31	4150
1846.32	4150
1849.33	4162
1852.34	4112
1855.35	4102
1858.36	4158
1861.36	4106
1864.36	4096
1867.37	4064
1870.37	4120
1873.37	4054
1876.37	4108
1879.37	4024
1882.36	4068
1885.36	4084
1888.35	4094
1891.34	4062
1894.33	4050
1897.32	4094
1900.31	4066
1903.3	4042
1906.28	4032
1909.26	4098
1912.25	4058
1915.23	4024
1918.21	4126
1921.18	4084
1924.16	4102
1927.14	4038
1930.11	4072
1933.08	4026
1936.05	4016
1939.02	4008
1941.99	4032
1944.96	4028
1947.92	4054
1950.89	4038
1953.85	4026
1956.81	3964
1959.77	3924
1962.73	3962
1965.69	3942
1968.65	3924
1971.6	3900
1974.55	4032
1977.51	3904
1980.46	3948
1983.41	3930
1986.35	3964
1989.3	3882
1992.25	3942
1995.19	3886
1998.13	3866
2001.07	3892
2004.01	3928
2006.95	3960
2009.89	3898
2012.82	3888
2015.76	3920
2018.69	3944
2021.62	3884
2024.55	3894
2027.48	3884
2030.41	3924
2033.34	3876
2036.26	3932
2039.19	3862
2042.11	3856
2045.03	3902
2047.95	3860
2050.87	3850
2053.79	3814
2056.7	3862
2059.61	3844
2062.53	3772
2065.44	3762
2068.35	3786
2071.26	3810
2074.17	3746
2077.07	3886
2079.98	3782
2082.88	3688
2085.78	3784
2088.68	3676
2091.58	3792
2094.48	3656
2097.38	3794
2100.28	3728
2103.17	3678
2106.06	3734
2108.96	3686
2111.85	3700
2114.73	3796
2117.62	3708
2120.51	3698
2123.39	3702
2126.28	3684
2129.16	3646
2132.04	3600
2134.92	3708
2137.8	3706
2140.68	3656
2143.55	3630
2146.43	3616
2149.3	3668
2152.17	3624
2155.04	3566
2157.91	3598
2160.78	3606
2163.65	3590
2166.51	3580
2169.38	3546
2172.24	3568
2175.1	3528
2177.96	3440
2180.82	3494
2183.68	3594
2186.53	3452
2189.39	3474
2192.24	3492
2195.09	3426
2197.95	3518
2200.8	3432
2203.64	3456
2206.49	3462
2209.34	3444
2212.18	3396
2215.03	3364
2217.87	3434
2220.71	3397.58
2223.55	3410.42
2226.39	3439.67
2229.22	3393.74
2232.06	3406.75
2234.89	3430.08
2237.73	3437.06
2240.56	3434.42
2243.39	3473.86
2246.22	3409.42
2249.05	3471.89
2251.87	3413.38
2254.7	3469.64
2257.52	3390.73
2260.34	3439.37
2263.17	3524.59
2265.99	3438.08
2268.8	3424.57
2271.62	3494.42
2274.44	3434.41
2277.25	3497.5
2280.07	3448.3
2282.88	3475.29
2285.69	3485.23
2288.5	3465.89
2291.31	3460.42
2294.12	3445.03
2296.92	3477.66
2299.73	3408.54
2302.53	3402.34
2305.34	3462.66
2308.14	3487.29
2310.94	3447.23
2313.74	3496.72
2315.86	3454
2318.67	3452
2321.48	3396
2324.29	3476
2327.09	3462
2329.9	3412
2332.7	3378
2335.51	3462
2338.31	3424
2341.11	3452
2343.91	3424
2346.71	3424
2349.51	3416
2352.3	3414
2355.1	3424
2357.89	3358
2360.68	3386
2363.48	3422
2366.27	3370
2369.05	3388
2371.84	3356
2374.63	3352
2377.41	3372
2380.2	3378
2382.98	3352
2385.76	3350
2388.54	3326
2391.32	3360
2394.1	3342
2396.87	3368
2399.65	3292
2402.42	3340
2405.2	3332
2407.97	3314
2410.74	3320
2413.51	3332
2416.27	3306
2419.04	3316
2421.81	3254
2424.57	3288
2427.33	3292
2430.1	3234
2432.85	3232
2435.61	3272
2438.37	3316
2441.13	3244
2443.88	3322
2446.64	3220
2449.39	3208
2452.14	3306
2454.89	3212
2457.64	3276
2460.39	3196
2463.14	3250
2465.88	3204
2468.63	3234
2471.37	3200
2474.11	3240
2476.86	3158
2479.59	3244
2482.33	3198
2485.07	3258
2487.81	3178
2490.54	3154
2493.28	3198
2496.01	3172
2498.74	3150
2501.47	3180
2504.2	3118
2506.93	3134
2509.65	3168
2512.38	3166
2515.1	3156
2517.82	3180
2520.55	3166
2523.27	3096
2525.99	3076
2528.7	3078
2531.42	3078
2534.14	3100
2536.85	3098
2539.56	3090
2542.28	3102
2544.99	3044
2547.7	3058
2550.4	3048
2553.11	3028
2555.82	3088
2558.52	3078
2561.23	3088
2563.93	3046
2566.63	3104
2569.33	3082
2572.03	3050
2574.73	3048
2577.42	3068
2580.12	3068
2582.81	3020
2585.51	3026
2588.2	2920
2590.89	2934
2593.58	2940
2596.26	2912
2598.95	2920
2601.64	2990
2604.32	2996
2607.01	2958
2609.69	3008
2612.37	3006
2615.05	2934
2617.73	2932
2620.41	2886
2623.08	2886
2625.76	2912
2628.43	2904
2631.1	2974
2633.78	2916
2636.45	2910
2639.12	2912
2641.78	2908
2644.45	2932
2647.12	2828
2649.78	2948
2652.45	2804
2655.11	2810
2657.77	2840
2660.43	2850
2663.09	2876
2665.75	2864
2668.4	2838
2671.06	2782
2673.71	2858
2676.37	2870
2679.02	2808
2681.67	2760
2684.32	2846
2686.97	2892
2689.61	2838
2692.26	2770
2694.9	2794
2697.55	2772
2700.19	2696
2702.83	2790
2705.47	2752
2708.11	2754
2710.75	2748
2713.39	2762
2716.02	2780
2718.66	2738
2721.29	2718
2723.92	2764
2726.55	2776
2729.18	2700
2731.81	2728
2734.44	2714
2737.07	2732
2739.69	2760
2742.32	2698
2744.94	2728
2747.56	2606
2750.18	2636
2752.8	2634
2755.42	2678
2758.04	2688
2760.65	2654
2763.27	2678
2765.88	2654
2768.5	2626
2771.11	2620
2773.72	2626
2776.33	2694
2778.94	2622
2781.54	2588
2784.15	2648
2786.75	2570
2789.36	2620
2791.96	2554
2794.56	2540
2797.16	2616
2799.76	2588
2802.36	2562
2804.96	2596
2807.55	2540
2810.15	2588
2812.74	2584
2815.33	2548
2817.93	2564
2820.52	2582
2823.11	2540
2825.69	2542
2828.28	2556
2830.87	2502
2833.45	2520
2836.03	2502
2838.62	2472
2841.2	2460
2843.78	2508
2846.36	2530
2848.93	2420
2851.51	2488
2854.09	2446
2856.66	2410
2859.24	2472
2861.81	2486
2864.38	2392
2866.95	2366
2869.52	2348
2872.09	2428
2874.65	2392
2877.22	2394
2879.78	2324
2882.35	2392
2884.91	2388
2887.47	2394
2890.03	2350
2892.59	2392
2895.15	2302
2897.7	2354
2900.26	2350
2902.81	2392
2905.37	2382
2907.92	2334
2910.47	2372
2913.02	2316
2915.57	2336
2918.12	2306
2920.66	2320
2923.21	2332
2925.75	2362
2928.3	2338
2930.84	2312
2933.38	2332
2935.92	2308
2938.46	2266
2941	2242
2943.54	2282
2946.07	2282
2948.61	2242
2951.14	2264
2953.67	2308
2956.21	2314
2958.74	2298
2961.27	2298
2963.79	2258
2966.32	2240
2968.85	2226
2971.37	2154
2973.9	2216
2976.42	2236
2978.94	2162
2981.46	2154
2983.98	2186
2986.5	2216
2989.02	2200
2991.53	2206
2994.05	2212
2996.56	2146
2999.08	2150
3001.59	2212
3004.1	2098
3006.61	2102
3009.12	2186
3011.63	2144
3014.13	2158
3016.64	2162
3019.14	2156
3021.65	2120
3024.15	2096
3026.65	2096
3029.15	2124
3031.65	2140
3034.15	2092
3036.64	2032
3039.14	2110
3041.63	2077.07
3044.13	1966.14
3046.62	2087.98
3049.11	1994.5
3051.6	2085.68
3054.09	2025.8
3056.58	2046.91
3059.07	1993.96
3061.55	2066.97
3064.04	2002.77
3066.52	2024.22
3069.01	1981.36
3071.49	2013.34
3073.97	1994.06
3076.45	2004.79
3078.93	1940.89
3081.41	1930.15
3083.88	1995.85
3086.36	1946.38
3088.83	1982.75
3091.31	1952.63
3093.78	1925.11
3096.25	1912.33
3098.72	1912.97
3101.19	1948.34
3103.66	1900.8
3106.13	1832.46
3108.59	1919.36
3111.06	1860.56
3113.52	1887.74
3115.98	1876.23
3118.45	1851.38
3120.91	1849.15
3123.37	1853.44
3125.38	1834
3127.85	1820
3130.32	1844
3132.79	1828
3135.26	1846
3137.73	1816
3140.19	1816
3142.66	1820
3145.13	1786
3147.59	1834
3150.05	1820
3152.51	1740
3154.97	1796
3157.43	1778
3159.89	1796
3162.35	1758
3164.8	1762
3167.26	1774
3169.71	1732
3172.17	1764
3174.62	1796
3177.07	1798
3179.52	1750
3181.97	1738
3184.41	1728
3186.86	1746
3189.31	1734
3191.75	1754
3194.2	1738
3196.64	1724
3199.08	1694
3201.52	1748
3203.96	1674
3206.4	1742
3208.84	1748
3211.27	1676
3213.71	1658
3216.14	1702
3218.58	1710
3221.01	1718
3223.44	1678
3225.87	1694
3228.3	1682
3230.73	1644
3233.16	1640
3235.58	1618
3238.01	1644
3240.43	1656
3242.86	1650
3245.28	1630
3247.7	1678
3250.12	1658
3252.54	1660
3254.96	1632
3257.38	1642
3259.79	1654
3262.21	1616
3264.62	1612
3267.04	1594
3269.45	1638
3271.86	1610
3274.27	1578
3276.68	1576
3279.09	1606
3281.49	1598
3283.9	1644
3286.31	1570
3288.71	1566
3291.11	1580
3293.51	1544
3295.92	1590
3298.32	1584
3300.72	1562
3303.11	1506
3305.51	1544
3307.91	1550
3310.3	1538
3312.7	1522
3315.09	1518
3317.48	1568
3319.87	1556
3322.26	1592
3324.65	1476
3327.04	1546
3329.43	1492
3331.81	1522
3334.2	1510
3336.58	1518
3338.97	1506
3341.35	1536
3343.73	1484
3346.11	1518
3348.49	1532
3350.87	1518
3353.25	1518
3355.62	1462
3358	1526
3360.37	1508
3362.75	1488
3365.12	1488
3367.49	1456
3369.86	1486
3372.23	1440
3374.6	1466
3376.97	1424
3379.33	1462
3381.7	1452
3384.06	1520
3386.43	1502
3388.79	1454
3391.15	1396
3393.51	1446
3395.87	1430
3398.23	1472
3400.59	1430
3402.94	1360
3405.3	1440
3407.65	1398
3410.01	1432
3412.36	1390
3414.71	1424
3417.06	1386
3419.41	1448
3421.76	1374
3424.11	1370
3426.46	1388
3428.8	1384
3431.15	1390
3433.49	1396
3435.83	1398
3438.18	1342
3440.52	1398
3442.86	1380
3445.2	1344
3447.53	1394
3449.87	1412
3452.21	1392
3454.54	1370
3456.88	1306
3459.21	1392
3461.54	1342
3463.88	1374
3466.21	1342
3468.53	1344
3470.86	1328
3473.19	1332
3475.52	1306
3477.84	1326
3480.17	1290
3482.49	1294
3484.82	1320
3487.14	1326
3489.46	1280
3491.78	1306
3494.1	1322
3496.42	1298
3498.73	1314
3501.05	1314
3503.36	1280
3505.68	1332
3507.99	1302
3510.3	1292
3512.61	1302
3514.92	1266
3517.23	1298
3519.54	1278
3521.85	1286
3524.16	1264
3526.46	1292
3528.77	1262
3531.07	1266
3533.37	1312
3535.68	1234
3537.98	1268
3540.28	1282
3542.58	1220
3544.87	1262
3547.17	1288
3549.47	1258
3551.76	1262
3554.06	1236
3556.35	1228
3558.64	1196
3560.93	1224
3563.22	1222
3565.51	1272
3567.8	1242
3570.09	1222
3572.38	1218
3574.66	1248
3576.95	1206
3579.23	1230
3581.51	1218
3583.8	1252
3586.08	1196
3588.36	1240
3590.64	1226
3592.92	1230
3595.19	1240
3597.47	1228
3599.75	1218
3602.02	1200
3604.29	1192
3606.57	1186
3608.84	1196
3611.11	1206
3613.38	1206
3615.65	1178
3617.92	1156
3620.18	1170
3622.45	1166
3624.71	1188
3626.98	1174
3629.24	1178
3631.5	1168
3633.77	1150
3636.03	1118
3638.29	1156
3640.55	1156
3642.8	1172
3645.06	1168
3647.32	1128
3649.57	1132
3651.83	1108
3654.08	1156
3656.33	1130
3658.58	1140
3660.83	1114
3663.08	1142
3665.33	1090
3667.58	1102
3669.83	1132
3672.07	1106
3674.32	1156
3676.56	1120
3678.8	1118
3681.05	1178
3683.29	1076
3685.53	1118
3687.77	1126
3690.01	1104
3692.24	1128
3694.48	1102
3696.72	1080
3698.95	1106
3701.19	1124
3703.42	1126
3705.65	1088
3707.88	1066
3710.11	1086
3712.34	1108
3714.57	1028
3716.8	1090
3719.03	1090
3721.25	1068
3723.48	1140
3725.7	1108
3727.92	1078
3730.15	1078
3732.37	1028
3734.59	1068
3736.81	1050
3739.03	996
3741.24	1038
3743.46	1056
3745.68	1090
3747.89	1026
3750.11	1060
3752.32	1006
3754.53	1034
3756.74	1038
3758.95	1046
3761.16	1028
3763.37	1066.06
3765.58	1023
3767.79	1002.75
3769.99	1013.59
3772.2	984.796
3774.4	1032.04
3776.61	1061.77
3778.81	1026.77
3781.01	1007.73
3783.21	1038.26
3785.41	1025.63
3787.61	1028.78
3789.81	1018.51
3792	1016.29
3794.2	1039.1
3796.4	1016.28
3798.59	1022.74
3800.78	1018.96
3802.98	1007.27
3805.17	1015.16
3807.36	978.804
3809.55	998.806
3811.74	999.442
3813.93	984.701
3816.11	984.712
3818.3	982.205
3820.49	1006.7
3822.67	999.551
3824.85	981.034
3827.04	992.176
3829.22	995.94
3831.4	983.159
3833.58	998.496
3835.76	972.222
3837.94	959.714
3839.98	952
3842.17	968
3844.36	944
3846.55	950
3848.73	968
3850.92	920
3853.1	980
3855.29	938
3857.47	998
3859.65	960
3861.84	966
3864.02	968
3866.2	952
3868.38	968
3870.55	978
3872.73	954
3874.91	980
3877.08	960
3879.26	948
3881.43	944
3883.6	934
3885.78	970
3887.95	930
3890.12	942
3892.29	950
3894.46	932
3896.63	946
3898.79	930
3900.96	926
3903.12	924
3905.29	956
3907.45	934
3909.61	938
3911.78	908
3913.94	918
3916.1	916
3918.26	934
3920.41	924
3922.57	916
3924.73	884
3926.88	900
3929.04	920
3931.19	934
3933.35	912
3935.5	876
3937.65	902
3939.8	888
3941.95	932
3944.1	864
3946.25	880
3948.4	900
3950.54	922
3952.69	892
3954.83	884
3956.98	856
3959.12	888
3961.26	906
3963.4	900
3965.54	896
3967.68	904
3969.82	890
3971.96	890
3974.1	862
3976.23	892
3978.37	884
3980.5	884
3982.64	840
3984.77	870
3986.9	862
3989.03	876
3991.16	870
3993.29	878
3995.42	852
3997.55	888
3999.67	818