File: muestras/mosquito/OR_11.txt
#Acq. time (s)=	10
#Accumulations=	1
#Range (cm-¹)=	200...4000
#Windows=	5
#Autofocus=	Off
#AutoExposure=	Off
#Spike filter=	Off
#Delay time (s)=	0
#Binning=	1
#Readout mode=	Signal
#DeNoise=	Off
#ICS correction=	Off
#Dark correction=	Off
#Inst. Process=	Off
#Instrument=	LabRAM HR Evol
#Detector=	Syncerity OE
#Objective=	x100_VIS
#Grating=	600 (500nm)
#ND Filter=	25%
#Laser=	633nm_Edge
#Hole=	100.021
#Range=	Visible
#Project=	Omar
#Sample=	03-07-23
#Site=	1
#Title=	OR
#Remark=
#Date=	03.07.2023 13:44
#Acquired=	03.07.2023 13:44:31
200.404	680
204.205	678
208.003	692
211.799	700
215.595	674
219.387	694
223.177	688
226.966	694
230.752	692
234.536	702
238.319	718
242.1	722
245.879	710
249.655	726
253.431	724
257.204	656
260.976	724
264.744	694
268.511	694
272.276	690
276.04	738
279.801	722
283.561	726
287.318	730
291.074	722
294.828	744
298.581	756
302.33	728
306.079	730
309.825	754
313.569	746
317.311	744
321.052	746
324.79	758
328.527	746
332.261	716
335.994	768
339.725	748
343.454	750
347.182	756
350.907	778
354.631	748
358.352	724
362.072	754
365.789	754
369.505	788
373.219	812
376.93	746
380.642	764
384.35	782
388.056	770
391.76	746
395.463	744
399.164	782
402.863	792
406.559	794
410.254	796
413.948	796
417.639	800
421.329	802
425.016	828
428.701	810
432.386	840
436.068	818
439.748	816
443.426	794
447.103	872
450.777	816
454.45	806
458.121	816
461.789	824
465.457	826
469.122	830
472.786	836
476.447	838
480.107	808
483.765	856
487.421	856
491.075	866
494.727	862
498.377	876
502.026	832
505.673	884
509.318	858
512.962	884
516.602	852
520.242	882
523.881	878
527.516	868
531.149	868
534.783	868
538.413	880
542.041	850
545.667	864
549.292	846
552.915	862
556.537	862
560.156	836
563.773	874
567.389	848
571.004	878
574.615	878
578.226	874
581.834	880
585.44	888
589.045	864
592.649	866
596.25	866
599.85	918
603.448	884
607.042	902
610.637	888
614.229	896
617.819	938
621.408	902
624.994	884
628.58	904
632.163	928
635.744	928
639.324	926
642.902	914
646.478	926
650.052	932
653.625	938
657.196	944
660.764	982
664.331	950
667.897	978
671.46	926
675.021	966
678.582	942
682.14	942
685.696	962
689.252	940
692.804	948
696.355	928
699.905	972
703.451	978
706.997	986
710.542	962
714.083	966
717.624	980
721.162	952
724.7	978
728.235	940
731.768	940
735.301	972
738.83	964
742.358	972
745.885	1008
749.41	1012
752.931	958
756.453	958
759.973	968
763.49	998
767.006	982
770.52	1008
774.033	976
777.543	1004
781.052	952
784.559	1008
788.064	972
791.568	1020
795.07	1002
798.57	964
802.068	1020
805.565	988
809.061	1000
812.553	1026
816.045	1018
819.535	1028
823.022	1038
826.508	1010
829.993	1006
833.476	1042
836.957	1020
840.436	1032
843.914	1052
847.391	1048
850.864	1062
854.337	1086
857.807	1054
861.277	1078
864.744	1054
868.209	1048
871.674	1030
875.136	1056
878.597	1038
882.056	1076
885.512	1034
888.967	1052
892.421	1074
895.874	1032
899.323	1042
902.771	1016
906.219	1048
909.664	1022
913.107	1018
916.55	1038
919.99	1044
923.428	1056
926.863	1042
930.299	1058
933.732	1042
937.164	1070
940.593	1058
944.022	1078
947.448	1084
950.874	1092
954.296	1070
957.718	1072
961.137	1124
964.555	1098
967.972	1120
971.387	1120
974.8	1134
978.21	1084
981.62	1080
985.029	1082
988.435	1120
991.839	1136
995.243	1102
998.644	1104
1002.04	1120
1005.44	1136
1008.84	1106
1012.23	1118
1015.63	1118
1019.02	1098
1022.41	1094
1025.79	1100
1029.18	1112
1032.56	1128
1035.95	1118
1039.33	1150
1042.71	1092
1046.09	1118
1049.46	1180
1052.84	1128
1056.21	1132
1059.58	1146
1062.95	1152
1066.32	1106
1069.69	1128
1073.05	1162
1076.41	1140
1079.78	1140
1083.14	1124
1086.49	1140
1089.85	1116
1093.21	1130
1096.56	1108
1099.91	1158
1103.26	1120
1106.61	1160
1109.96	1154
1113.3	1140
1116.64	1138
1119.99	1128
1123.33	1130
1126.66	1160
1130	1130
1133.34	1136
1136.67	1164
1140	1132
1143.33	1174
1146.66	1142
1149.99	1156
1153.32	1118
1156.64	1124
1159.96	1184
1163.28	1130
1166.6	1152
1169.92	1166
1173.23	1154
1176.55	1210
1179.86	1150
1183.17	1180
1186.48	1164
1189.79	1178
1193.1	1146
1196.4	1188
1199.7	1190
1203	1164
1206.3	1196
1209.6	1166
1212.9	1162
1216.19	1176
1219.49	1174
1222.78	1146
1226.07	1156
1229.36	1130
1232.65	1128
1235.93	1148
1239.21	1144
1242.5	1132
1245.78	1164
1249.06	1160
1252.33	1222
1255.61	1168
1258.88	1112
1262.16	1178
1265.43	1190
1268.7	1122
1271.96	1200
1275.23	1182
1278.5	1156
1281.76	1170.31
1285.02	1169.83
1288.28	1130.63
1291.54	1185.95
1294.8	1156.72
1298.05	1182.42
1301.31	1192.95
1304.56	1150.38
1307.81	1190.54
1311.06	1166.54
1314.3	1174.14
1317.55	1153.18
1320.79	1160.4
1324.04	1204.5
1327.28	1155.56
1330.52	1170.81
1333.76	1161.7
1336.99	1161.21
1340.23	1188.63
1343.46	1189.23
1346.69	1179.67
1349.92	1197.42
1353.15	1170.45
1356.38	1146.44
1359.6	1186.51
1362.83	1192.56
1366.05	1161.8
1369.27	1156.19
1372.49	1162.84
1375.71	1170.85
1378.93	1174.45
1382.14	1180.03
1385.35	1199.53
1388.57	1154.63
1391.2	1216
1394.43	1202
1397.65	1164
1400.87	1154
1404.09	1196
1407.31	1182
1410.53	1168
1413.74	1160
1416.96	1180
1420.17	1152
1423.38	1154
1426.59	1154
1429.8	1108
1433.01	1166
1436.21	1140
1439.42	1138
1442.62	1154
1445.82	1102
1449.02	1106
1452.22	1152
1455.41	1112
1458.61	1150
1461.8	1116
1464.99	1150
1468.18	1162
1471.37	1140
1474.56	1150
1477.74	1144
1480.93	1160
1484.11	1178
1487.29	1144
1490.47	1152
1493.65	1208
1496.82	1114
1500	1160
1503.17	1158
1506.34	1128
1509.51	1160
1512.68	1146
1515.85	1146
1519.02	1118
1522.18	1150
1525.34	1146
1528.51	1148
1531.67	1100
1534.82	1104
1537.98	1110
1541.14	1152
1544.29	1114
1547.44	1132
1550.59	1084
1553.74	1126
1556.89	1104
1560.04	1080
1563.18	1082
1566.33	1104
1569.47	1136
1572.61	1136
1575.75	1136
1578.89	1136
1582.02	1066
1585.16	1094
1588.29	1142
1591.42	1114
1594.55	1104
1597.68	1074
1600.81	1090
1603.94	1094
1607.06	1094
1610.18	1072
1613.3	1094
1616.42	1096
1619.54	1130
1622.66	1136
1625.78	1084
1628.89	1028
1632	1082
1635.11	1084
1638.22	1050
1641.33	1074
1644.44	1080
1647.55	1038
1650.65	1010
1653.75	1066
1656.85	1024
1659.95	1022
1663.05	1014
1666.15	1042
1669.24	1012
1672.34	1060
1675.43	1032
1678.52	1042
1681.61	1030
1684.7	1026
1687.78	1044
1690.87	1026
1693.95	986
1697.03	972
1700.12	992
1703.2	1004
1706.27	1000
1709.35	980
1712.42	998
1715.5	966
1718.57	972
1721.64	996
1724.71	986
1727.78	1000
1730.84	984
1733.91	956
1736.97	990
1740.04	968
1743.1	942
1746.16	978
1749.21	990
1752.27	956
1755.33	984
1758.38	1008
1761.43	946
1764.48	932
1767.53	972
1770.58	976
1773.63	938
1776.67	946
1779.71	952
1782.76	942
1785.8	950
1788.84	938
1791.88	936
1794.91	954
1797.95	936
1800.98	946
1804.01	940
1807.04	904
1810.07	940
1813.1	922
1816.13	974
1819.15	974
1822.18	892
1825.2	930
1828.22	912
1831.24	954
1834.26	886
1837.28	902
1840.29	898
1843.31	918
1846.32	884
1849.33	896
1852.34	926
1855.35	904
1858.36	926
1861.36	924
1864.36	900
1867.37	872
1870.37	892
1873.37	888
1876.37	916
1879.37	902
1882.36	848
1885.36	914
1888.35	912
1891.34	848
1894.33	866
1897.32	870
1900.31	906
1903.3	860
1906.28	888
1909.26	868
1912.25	866
1915.23	876
1918.21	910
1921.18	878
1924.16	876
1927.14	870
1930.11	884
1933.08	848
1936.05	870
1939.02	856
1941.99	840
1944.96	824
1947.92	858
1950.89	864
1953.85	878
1956.81	888
1959.77	858
1962.73	852
1965.69	812
1968.65	838
1971.6	838
1974.55	832
1977.51	812
1980.46	826
1983.41	850
1986.35	814
1989.3	848
1992.25	806
1995.19	812
1998.13	856
2001.07	806
2004.01	798
2006.95	858
2009.89	800
2012.82	832
2015.76	826
2018.69	818
2021.62	798
2024.55	768
2027.48	826
2030.41	850
2033.34	838
2036.26	832
2039.19	802
2042.11	820
2045.03	822
2047.95	776
2050.87	794
2053.79	802
2056.7	798
2059.61	800
2062.53	806
2065.44	768
2068.35	766
2071.26	834
2074.17	776
2077.07	774
2079.98	792
2082.88	766
2085.78	778
2088.68	766
2091.58	806
2094.48	804
2097.38	760
2100.28	742
2103.17	782
2106.06	776
2108.96	778
2111.85	782
2114.73	768
2117.62	782
2120.51	764
2123.39	778
2126.28	718
2129.16	782
2132.04	744
2134.92	734
2137.8	750
2140.68	732
2143.55	760
2146.43	718
2149.3	736
2152.17	738
2155.04	718
2157.91	726
2160.78	746
2163.65	724
2166.51	730
2169.38	728
2172.24	744
2175.1	710
2177.96	712
2180.82	726
2183.68	686
2186.53	716
2189.39	740
2192.24	732
2195.09	716
2197.95	708
2200.8	702
2203.64	700
2206.49	716
2209.34	712
2212.18	698
2215.03	696
2217.87	688
2220.71	715.814
2223.55	677.788
2226.39	689.581
2229.22	711.955
2232.06	706.11
2234.89	710.734
2237.73	690.551
2240.56	696.514
2243.39	700.788
2246.22	695.368
2249.05	704.993
2251.87	674.736
2254.7	702.546
2257.52	689.68
2260.34	700.494
2263.17	680.734
2265.99	696.036
2268.8	704.787
2271.62	686.16
2274.44	679.15
2277.25	679.319
2280.07	668.939
2282.88	691.664
2285.69	697.742
2288.5	693.461
2291.31	677.101
2294.12	662.369
2296.92	686.731
2299.73	675.396
2302.53	690.988
2305.34	688.66
2308.14	695.753
2310.94	684.666
2313.74	671.592
2315.86	656
2318.67	676
2321.48	668
2324.29	672
2327.09	664
2329.9	650
2332.7	676
2335.51	652
2338.31	652
2341.11	686
2343.91	680
2346.71	668
2349.51	650
2352.3	660
2355.1	636
2357.89	672
2360.68	634
2363.48	698
2366.27	670
2369.05	696
2371.84	664
2374.63	654
2377.41	640
2380.2	654
2382.98	652
2385.76	662
2388.54	672
2391.32	706
2394.1	652
2396.87	654
2399.65	668
2402.42	660
2405.2	660
2407.97	644
2410.74	674
2413.51	644
2416.27	652
2419.04	640
2421.81	632
2424.57	626
2427.33	644
2430.1	642
2432.85	646
2435.61	638
2438.37	626
2441.13	652
2443.88	642
2446.64	648
2449.39	642
2452.14	636
2454.89	642
2457.64	638
2460.39	606
2463.14	628
2465.88	620
2468.63	604
2471.37	630
2474.11	602
2476.86	612
2479.59	614
2482.33	626
2485.07	594
2487.81	626
2490.54	624
2493.28	636
2496.01	634
2498.74	630
2501.47	614
2504.2	588
2506.93	598
2509.65	614
2512.38	612
2515.1	596
2517.82	590
2520.55	626
2523.27	600
2525.99	568
2528.7	620
2531.42	576
2534.14	602
2536.85	592
2539.56	594
2542.28	584
2544.99	610
2547.7	584
2550.4	578
2553.11	560
2555.82	614
2558.52	598
2561.23	582
2563.93	586
2566.63	616
2569.33	568
2572.03	588
2574.73	598
2577.42	566
2580.12	598
2582.81	584
2585.51	560
2588.2	610
2590.89	568
2593.58	556
2596.26	580
2598.95	572
2601.64	582
2604.32	576
2607.01	578
2609.69	554
2612.37	566
2615.05	580
2617.73	588
2620.41	572
2623.08	548
2625.76	558
2628.43	552
2631.1	568
2633.78	532
2636.45	546
2639.12	532
2641.78	540
2644.45	534
2647.12	538
2649.78	540
2652.45	530
2655.11	540
2657.77	536
2660.43	534
2663.09	546
2665.75	542
2668.4	532
2671.06	548
2673.71	534
2676.37	522
2679.02	538
2681.67	530
2684.32	548
2686.97	512
2689.61	520
2692.26	530
2694.9	528
2697.55	522
2700.19	520
2702.83	528
2705.47	538
2708.11	530
2710.75	512
2713.39	524
2716.02	514
2718.66	510
2721.29	516
2723.92	488
2726.55	514
2729.18	524
2731.81	540
2734.44	490
2737.07	500
2739.69	522
2742.32	502
2744.94	474
2747.56	506
2750.18	494
2752.8	484
2755.42	494
2758.04	494
2760.65	528
2763.27	464
2765.88	486
2768.5	496
2771.11	482
2773.72	500
2776.33	494
2778.94	476
2781.54	478
2784.15	506
2786.75	492
2789.36	488
2791.96	482
2794.56	488
2797.16	484
2799.76	486
2802.36	486
2804.96	454
2807.55	488
2810.15	470
2812.74	492
2815.33	484
2817.93	484
2820.52	478
2823.11	480
2825.69	484
2828.28	454
2830.87	456
2833.45	484
2836.03	458
2838.62	458
2841.2	462
2843.78	448
2846.36	462
2848.93	450
2851.51	456
2854.09	464
2856.66	482
2859.24	438
2861.81	440
2864.38	452
2866.95	460
2869.52	444
2872.09	448
2874.65	444
2877.22	438
2879.78	432
2882.35	416
2884.91	428
2887.47	450
2890.03	432
2892.59	468
2895.15	430
2897.7	424
2900.26	444
2902.81	420
2905.37	424
2907.92	456
2910.47	414
2913.02	452
2915.57	438
2918.12	422
2920.66	424
2923.21	416
2925.75	408
2928.3	418
2930.84	424
2933.38	458
2935.92	424
2938.46	406
2941	422
2943.54	414
2946.07	408
2948.61	408
2951.14	390
2953.67	422
2956.21	400
2958.74	398
2961.27	406
2963.79	410
2966.32	386
2968.85	414
2971.37	410
2973.9	404
2976.42	420
2978.94	374
2981.46	386
2983.98	394
2986.5	412
2989.02	424
2991.53	392
2994.05	396
2996.56	394
2999.08	394
3001.59	412
3004.1	396
3006.61	384
3009.12	388
3011.63	382
3014.13	410
3016.64	394
3019.14	386
3021.65	384
3024.15	360
3026.65	370
3029.15	372
3031.65	354
3034.15	384
3036.64	374
3039.14	376
3041.63	385.86
3044.13	379.712
3046.62	371.993
3049.11	367.352
3051.6	379.816
3054.09	359.024
3056.58	364.14
3059.07	348.396
3061.55	365.421
3064.04	350.147
3066.52	362.62
3069.01	366.599
3071.49	346.373
3073.97	369.387
3076.45	355.641
3078.93	346.513
3081.41	345.406
3083.88	349.975
3086.36	362.296
3088.83	345.668
3091.31	343.145
3093.78	353.324
3096.25	343.581
3098.72	323.563
3101.19	351.617
3103.66	356.692
3106.13	346.896
3108.59	334.236
3111.06	347.22
3113.52	344.539
3115.98	332.847
3118.45	330.942
3120.91	332.362
3123.37	318.55
3125.38	344
3127.85	334
3130.32	334
3132.79	334
3135.26	324
3137.73	324
3140.19	314
3142.66	316
3145.13	322
3147.59	332
3150.05	326
3152.51	298
3154.97	316
3157.43	306
3159.89	320
3162.35	338
3164.8	326
3167.26	322
3169.71	314
3172.17	320
3174.62	304
3177.07	332
3179.52	302
3181.97	320
3184.41	298
3186.86	320
3189.31	286
3191.75	298
3194.2	290
3196.64	300
3199.08	290
3201.52	308
3203.96	292
3206.4	312
3208.84	316
3211.27	292
3213.71	318
3216.14	304
3218.58	298
3221.01	298
3223.44	290
3225.87	286
3228.3	292
3230.73	308
3233.16	302
3235.58	296
3238.01	304
3240.43	280
3242.86	296
3245.28	318
3247.7	288
3250.12	282
3252.54	278
3254.96	294
3257.38	284
3259.79	314
3262.21	292
3264.62	280
3267.04	292
3269.45	290
3271.86	276
3274.27	296
3276.68	280
3279.09	286
3281.49	286
3283.9	286
3286.31	270
3288.71	280
3291.11	282
3293.51	290
3295.92	266
3298.32	278
3300.72	270
3303.11	274
3305.51	288
3307.91	280
3310.3	262
3312.7	266
3315.09	274
3317.48	286
3319.87	280
3322.26	284
3324.65	270
3327.04	270
3329.43	276
3331.81	272
3334.2	258
3336.58	272
3338.97	246
3341.35	240
3343.73	292
3346.11	264
3348.49	246
3350.87	272
3353.25	272
3355.62	264
3358	270
3360.37	268
3362.75	246
3365.12	258
3367.49	266
3369.86	244
3372.23	266
3374.6	250
3376.97	248
3379.33	272
3381.7	258
3384.06	262
3386.43	254
3388.79	266
3391.15	236
3393.51	260
3395.87	252
3398.23	250
3400.59	244
3402.94	264
3405.3	254
3407.65	248
3410.01	254
3412.36	260
3414.71	238
3417.06	256
3419.41	226
3421.76	248
3424.11	236
3426.46	238
3428.8	234
3431.15	226
3433.49	254
3435.83	242
3438.18	272
3440.52	252
3442.86	234
3445.2	238
3447.53	240
3449.87	244
3452.21	232
3454.54	270
3456.88	250
3459.21	230
3461.54	234
3463.88	228
3466.21	254
3468.53	224
3470.86	212
3473.19	232
3475.52	230
3477.84	244
3480.17	218
3482.49	224
3484.82	240
3487.14	246
3489.46	222
3491.78	220
3494.1	226
3496.42	254
3498.73	228
3501.05	230
3503.36	240
3505.68	216
3507.99	236
3510.3	228
3512.61	220
3514.92	218
3517.23	228
3519.54	226
3521.85	224
3524.16	220
3526.46	228
3528.77	230
3531.07	206
3533.37	212
3535.68	236
3537.98	216
3540.28	226
3542.58	222
3544.87	236
3547.17	222
3549.47	232
3551.76	206
3554.06	204
3556.35	214
3558.64	224
3560.93	210
3563.22	192
3565.51	234
3567.8	208
3570.09	214
3572.38	208
3574.66	198
3576.95	222
3579.23	214
3581.51	212
3583.8	220
3586.08	204
3588.36	228
3590.64	232
3592.92	212
3595.19	214
3597.47	196
3599.75	200
3602.02	212
3604.29	200
3606.57	208
3608.84	206
3611.11	204
3613.38	212
3615.65	212
3617.92	196
3620.18	214
3622.45	200
3624.71	220
3626.98	200
3629.24	210
3631.5	212
3633.77	198
3636.03	198
3638.29	206
3640.55	186
3642.8	190
3645.06	200
3647.32	214
3649.57	208
3651.83	192
3654.08	214
3656.33	204
3658.58	192
3660.83	192
3663.08	194
3665.33	188
3667.58	204
3669.83	194
3672.07	196
3674.32	202
3676.56	176
3678.8	182
3681.05	194
3683.29	194
3685.53	200
3687.77	194
3690.01	180
3692.24	186
3694.48	186
3696.72	188
3698.95	176
3701.19	182
3703.42	200
3705.65	180
3707.88	200
3710.11	202
3712.34	198
3714.57	184
3716.8	176
3719.03	180
3721.25	176
3723.48	196
3725.7	174
3727.92	206
3730.15	190
3732.37	190
3734.59	190
3736.81	186
3739.03	174
3741.24	190
3743.46	200
3745.68	182
3747.89	178
3750.11	174
3752.32	188
3754.53	180
3756.74	172
3758.95	188
3761.16	170
3763.37	174.019
3765.58	190.076
3767.79	159.419
3769.99	168.359
3772.2	187.306
3774.4	174.385
3776.61	178.662
3778.81	180.602
3781.01	178.654
3783.21	179.806
3785.41	169.189
3787.61	171.73
3789.81	184.523
3792	183.475
3794.2	168.955
3796.4	169.481
3798.59	175.601
3800.78	167.017
3802.98	176.929
3805.17	181.816
3807.36	181.566
3809.55	171.95
3811.74	179.594
3813.93	172.121
3816.11	171.653
3818.3	174.964
3820.49	173.696
3822.67	161.01
3824.85	180.1
3827.04	171.566
3829.22	169.064
3831.4	158.87
3833.58	175.049
3835.76	163.69
3837.94	167.971
3839.98	172
3842.17	152
3844.36	176
3846.55	166
3848.73	168
3850.92	162
3853.1	188
3855.29	174
3857.47	174
3859.65	158
3861.84	170
3864.02	180
3866.2	166
3868.38	166
3870.55	164
3872.73	184
3874.91	158
3877.08	190
3879.26	158
3881.43	180
3883.6	162
3885.78	158
3887.95	148
3890.12	168
3892.29	172
3894.46	186
3896.63	156
3898.79	168
3900.96	164
3903.12	154
3905.29	164
3907.45	162
3909.61	150
3911.78	150
3913.94	146
3916.1	158
3918.26	162
3920.41	170
3922.57	164
3924.73	162
3926.88	160
3929.04	156
3931.19	168
3933.35	172
3935.5	160
3937.65	142
3939.8	164
3941.95	162
3944.1	162
3946.25	144
3948.4	142
3950.54	164
3952.69	160
3954.83	156
3956.98	160
3959.12	154
3961.26	150
3963.4	148
3965.54	158
3967.68	176
3969.82	152
3971.96	170
3974.1	162
3976.23	150
3978.37	148
3980.5	172
3982.64	154
3984.77	160
3986.9	154
3989.03	158
3991.16	164
3993.29	150
3995.42	144
3997.55	154
3999.67	158