File: muestras/mosquito/OR_15.txt
#Acq. time (s)=	10
#Accumulations=	1
#Range (cm-¹)=	200...4000
#Windows=	5
#Autofocus=	Off
#AutoExposure=	Off
#Spike filter=	Off
#Delay time (s)=	0
#Binning=	1
#Readout mode=	Signal
#DeNoise=	Off
#ICS correction=	Off
#Dark correction=	Off
#Inst. Process=	Off
#Instrument=	LabRAM HR Evol
#Detector=	Syncerity OE
#Objective=	x100_VIS
#Grating=	600 (500nm)
#ND Filter=	25%
#Laser=	633nm_Edge
#Hole=	100.021
#Range=	Visible
#Project=	Omar
#Sample=	03-07-23
#Site=	1
#Title=	OR
#Remark=
#Date=	03.07.2023 13:50
#Acquired=	03.07.2023 13:50:37
200.404	852
204.205	800
208.003	806
211.799	826
215.595	824
219.387	814
223.177	826
226.966	850
230.752	836
234.536	816
238.319	852
242.1	822
245.879	860
249.655	878
253.431	802
257.204	826
260.976	820
264.744	874
268.511	832
272.276	840
276.04	898
279.801	850
283.561	868
287.318	850
291.074	914
294.828	838
298.581	872
302.33	890
306.079	856
309.825	894
313.569	876
317.311	910
321.052	916
324.79	886
328.527	910
332.261	900
335.994	884
339.725	924
343.454	894
347.182	882
350.907	936
354.631	882
358.352	944
362.072	920
365.789	906
369.505	924
373.219	906
376.93	904
380.642	860
384.35	914
388.056	916
391.76	908
395.463	936
399.164	932
402.863	914
406.559	940
410.254	934
413.948	934
417.639	952
421.329	946
425.016	960
428.701	988
432.386	948
436.068	968
439.748	946
443.426	964
447.103	992
450.777	974
454.45	958
458.121	974
461.789	958
465.457	1004
469.122	964
472.786	988
476.447	974
480.107	984
483.765	962
487.421	1028
491.075	990
494.727	964
498.377	970
502.026	1026
505.673	1002
509.318	994
512.962	1008
516.602	1022
520.242	1018
523.881	1020
527.516	1000
531.149	1034
534.783	986
538.413	1050
542.041	984
545.667	1020
549.292	964
552.915	1002
556.537	984
560.156	984
563.773	1038
567.389	994
571.004	1010
574.615	980
578.226	1020
581.834	1022
585.44	1054
589.045	1032
592.649	1072
596.25	1044
599.85	1030
603.448	1026
607.042	1008
610.637	1034
614.229	1044
617.819	1064
621.408	1054
624.994	1028
628.58	1050
632.163	1084
635.744	1132
639.324	1064
642.902	1068
646.478	1066
650.052	1124
653.625	1086
657.196	1062
660.764	1064
664.331	1090
667.897	1072
671.46	1076
675.021	1078
678.582	1068
682.14	1100
685.696	1082
689.252	1088
692.804	1098
696.355	1092
699.905	1070
703.451	1114
706.997	1078
710.542	1100
714.083	1730
717.624	1090
721.162	1088
724.7	1108
728.235	1132
731.768	1140
735.301	1160
738.83	1132
742.358	1134
745.885	1106
749.41	1150
752.931	1138
756.453	1120
759.973	1116
763.49	1128
767.006	1114
770.52	1122
774.033	1104
777.543	1138
781.052	1126
784.559	1112
788.064	1156
791.568	1166
795.07	1128
798.57	1168
802.068	1102
805.565	1152
809.061	1174
812.553	1112
816.045	1122
819.535	1116
823.022	1140
826.508	1146
829.993	1146
833.476	1186
836.957	1148
840.436	1170
843.914	1194
847.391	1156
850.864	1206
854.337	1198
857.807	1216
861.277	1136
864.744	1226
868.209	1224
871.674	1176
875.136	1236
878.597	1196
882.056	1224
885.512	1150
888.967	1166
892.421	1200
895.874	1178
899.323	1154
902.771	1200
906.219	1190
909.664	1166
913.107	1186
916.55	1180
919.99	1150
923.428	1166
926.863	1176
930.299	1162
933.732	1208
937.164	1232
940.593	1204
944.022	1220
947.448	1230
950.874	1248
954.296	1280
957.718	1182
961.137	1202
964.555	1210
967.972	1210
971.387	1220
974.8	1216
978.21	1248
981.62	1232
985.029	1278
988.435	1214
991.839	1244
995.243	1224
998.644	1214
1002.04	1252
1005.44	1228
1008.84	1196
1012.23	1192
1015.63	1242
1019.02	1266
1022.41	1202
1025.79	1258
1029.18	1204
1032.56	1218
1035.95	1266
1039.33	1276
1042.71	1276
1046.09	1298
1049.46	1328
1052.84	1264
1056.21	1288
1059.58	1254
1062.95	1266
1066.32	1266
1069.69	1254
1073.05	1262
1076.41	1262
1079.78	1256
1083.14	1288
1086.49	1274
1089.85	1252
1093.21	1242
1096.56	1274
1099.91	1250
1103.26	1272
1106.61	1242
1109.96	1226
1113.3	1298
1116.64	1306
1119.99	1296
1123.33	1254
1126.66	1222
1130	1294
1133.34	1298
1136.67	1278
1140	1310
1143.33	1298
1146.66	1284
1149.99	1298
1153.32	1270
1156.64	1300
1159.96	1284
1163.28	1314
1166.6	1312
1169.92	1328
1173.23	1286
1176.55	1262
1179.86	1310
1183.17	1298
1186.48	1264
1189.79	1304
1193.1	1284
1196.4	1314
1199.7	1310
1203	1296
1206.3	1314
1209.6	1248
1212.9	1308
1216.19	1292
1219.49	1312
1222.78	1310
1226.07	1266
1229.36	1308
1232.65	1304
1235.93	1278
1239.21	1266
1242.5	1324
1245.78	1300
1249.06	1266
1252.33	1318
1255.61	1302
1258.88	1266
1262.16	1324
1265.43	1290
1268.7	1264
1271.96	1298
1275.23	1314
1278.5	1294
1281.76	1337.57
1285.02	1309.31
1288.28	1330.69
1291.54	1286.33
1294.8	1296.46
1298.05	1295.6
1301.31	1355.94
1304.56	1357.32
1307.81	1286.16
1311.06	1313.08
1314.3	1303.86
1317.55	1317.74
1320.79	1313.78
1324.04	1300.87
1327.28	1280.56
1330.52	1316.98
1333.76	1321.64
1336.99	1296.94
1340.23	1339.78
1343.46	1293.41
1346.69	1312.97
1349.92	1314.22
1353.15	1319.86
1356.38	1313.95
1359.6	1309.56
1362.83	1300.12
1366.05	1302.98
1369.27	1330.33
1372.49	1313.65
1375.71	1319.32
1378.93	1299.05
1382.14	1320.05
1385.35	1304.51
1388.57	1297.08
1391.2	1318
1394.43	1298
1397.65	1312
1400.87	1328
1404.09	1316
1407.31	1282
1410.53	1310
1413.74	1318
1416.96	1286
1420.17	1230
1423.38	1260
1426.59	1286
1429.8	1280
1433.01	1284
1436.21	1316
1439.42	1248
1442.62	1292
1445.82	1294
1449.02	1256
1452.22	1288
1455.41	1254
1458.61	1292
1461.8	1262
1464.99	1242
1468.18	1304
1471.37	1304
1474.56	1292
1477.74	1322
1480.93	1262
1484.11	1290
1487.29	1276
1490.47	1302
1493.65	1276
1496.82	1268
1500	1274
1503.17	1288
1506.34	1326
1509.51	1250
1512.68	1274
1515.85	1270
1519.02	1290
1522.18	1252
1525.34	1280
1528.51	1228
1531.67	1300
1534.82	1244
1537.98	1282
1541.14	1248
1544.29	1248
1547.44	1260
1550.59	1258
1553.74	1256
1556.89	1264
1560.04	1230
1563.18	1262
1566.33	1260
1569.47	1240
1572.61	1260
1575.75	1244
1578.89	1210
1582.02	1250
1585.16	1250
1588.29	1242
1591.42	1268
1594.55	1280
1597.68	1252
1600.81	1224
1603.94	1246
1607.06	1256
1610.18	1234
1613.3	1220
1616.42	1228
1619.54	1224
1622.66	1238
1625.78	1202
1628.89	1206
1632	1196
1635.11	1230
1638.22	1192
1641.33	1192
1644.44	1198
1647.55	1204
1650.65	1206
1653.75	1230
1656.85	1180
1659.95	1198
1663.05	1226
1666.15	1210
1669.24	1180
1672.34	1216
1675.43	1186
1678.52	1120
1681.61	1134
1684.7	1204
1687.78	1146
1690.87	1188
1693.95	1134
1697.03	1194
1700.12	1144
1703.2	1170
1706.27	1122
1709.35	1154
1712.42	1114
1715.5	1120
1718.57	1092
1721.64	1162
1724.71	1104
1727.78	1134
1730.84	1106
1733.91	1122
1736.97	1106
1740.04	1094
1743.1	1090
1746.16	1114
1749.21	1086
1752.27	1120
1755.33	1142
1758.38	1058
1761.43	1084
1764.48	1110
1767.53	1114
1770.58	1074
1773.63	1144
1776.67	1114
1779.71	1116
1782.76	1150
1785.8	1104
1788.84	1096
1791.88	1088
1794.91	1104
1797.95	1064
1800.98	1068
1804.01	1138
1807.04	1070
1810.07	1114
1813.1	1084
1816.13	1098
1819.15	1022
1822.18	1086
1825.2	1086
1828.22	1062
1831.24	1038
1834.26	1072
1837.28	1094
1840.29	1054
1843.31	1086
1846.32	1062
1849.33	1062
1852.34	1062
1855.35	1070
1858.36	1028
1861.36	1048
1864.36	1074
1867.37	1024
1870.37	1076
1873.37	1062
1876.37	1086
1879.37	1068
1882.36	1048
1885.36	1054
1888.35	1054
1891.34	1052
1894.33	1018
1897.32	1022
1900.31	1024
1903.3	1022
1906.28	1048
1909.26	1034
1912.25	1050
1915.23	1022
1918.21	1006
1921.18	1038
1924.16	1024
1927.14	1058
1930.11	1044
1933.08	1008
1936.05	988
1939.02	1024
1941.99	990
1944.96	1028
1947.92	1002
1950.89	1032
1953.85	1014
1956.81	1018
1959.77	990
1962.73	1000
1965.69	996
1968.65	1042
1971.6	986
1974.55	978
1977.51	1038
1980.46	1010
1983.41	952
1986.35	998
1989.3	988
1992.25	964
1995.19	1000
1998.13	992
2001.07	1014
2004.01	994
2006.95	992
2009.89	990
2012.82	966
2015.76	980
2018.69	980
2021.62	980
2024.55	972
2027.48	942
2030.41	986
2033.34	948
2036.26	950
2039.19	984
2042.11	988
2045.03	972
2047.95	968
2050.87	986
2053.79	1002
2056.7	994
2059.61	970
2062.53	950
2065.44	952
2068.35	960
2071.26	958
2074.17	954
2077.07	906
2079.98	964
2082.88	908
2085.78	936
2088.68	936
2091.58	906
2094.48	942
2097.38	896
2100.28	926
2103.17	934
2106.06	968
2108.96	922
2111.85	922
2114.73	934
2117.62	912
2120.51	912
2123.39	958
2126.28	938
2129.16	888
2132.04	874
2134.92	906
2137.8	914
2140.68	924
2143.55	928
2146.43	872
2149.3	922
2152.17	920
2155.04	880
2157.91	908
2160.78	892
2163.65	866
2166.51	918
2169.38	910
2172.24	924
2175.1	872
2177.96	904
2180.82	898
2183.68	872
2186.53	862
2189.39	920
2192.24	852
2195.09	904
2197.95	890
2200.8	886
2203.64	860
2206.49	846
2209.34	846
2212.18	864
2215.03	842
2217.87	866
2220.71	865.978
2223.55	875.486
2226.39	859.809
2229.22	861.505
2232.06	837.985
2234.89	869.444
2237.73	846.113
2240.56	839.359
2243.39	845.203
2246.22	838.095
2249.05	866.476
2251.87	832.787
2254.7	852.79
2257.52	837.717
2260.34	839.597
2263.17	847.988
2265.99	850.445
2268.8	853.46
2271.62	858.653
2274.44	843.22
2277.25	834.85
2280.07	849.967
2282.88	844.099
2285.69	824.778
2288.5	841.469
2291.31	845.61
2294.12	851.2
2296.92	852.626
2299.73	837.087
2302.53	825.034
2305.34	826.331
2308.14	834.151
2310.94	854.991
2313.74	803.63
2315.86	820
2318.67	830
2321.48	864
2324.29	848
2327.09	846
2329.9	822
2332.7	790
2335.51	816
2338.31	858
2341.11	814
2343.91	830
2346.71	840
2349.51	822
2352.3	838
2355.1	852
2357.89	776
2360.68	830
2363.48	804
2366.27	866
2369.05	800
2371.84	818
2374.63	824
2377.41	804
2380.2	822
2382.98	802
2385.76	828
2388.54	842
2391.32	810
2394.1	796
2396.87	798
2399.65	828
2402.42	788
2405.2	822
2407.97	796
2410.74	812
2413.51	816
2416.27	832
2419.04	772
2421.81	810
2424.57	780
2427.33	792
2430.1	768
2432.85	822
2435.61	752
2438.37	788
2441.13	812
2443.88	788
2446.64	786
2449.39	786
2452.14	772
2454.89	800
2457.64	796
2460.39	780
2463.14	770
2465.88	778
2468.63	770
2471.37	780
2474.11	824
2476.86	768
2479.59	772
2482.33	792
2485.07	764
2487.81	764
2490.54	786
2493.28	790
2496.01	784
2498.74	694
2501.47	770
2504.2	756
2506.93	762
2509.65	786
2512.38	736
2515.1	760
2517.82	736
2520.55	770
2523.27	762
2525.99	766
2528.7	788
2531.42	726
2534.14	764
2536.85	722
2539.56	764
2542.28	768
2544.99	744
2547.7	736
2550.4	716
2553.11	760
2555.82	730
2558.52	716
2561.23	746
2563.93	704
2566.63	752
2569.33	742
2572.03	728
2574.73	740
2577.42	738
2580.12	732
2582.81	740
2585.51	748
2588.2	718
2590.89	716
2593.58	722
2596.26	738
2598.95	722
2601.64	708
2604.32	720
2607.01	700
2609.69	732
2612.37	708
2615.05	684
2617.73	722
2620.41	702
2623.08	730
2625.76	688
2628.43	716
2631.1	678
2633.78	726
2636.45	684
2639.12	694
2641.78	712
2644.45	666
2647.12	682
2649.78	682
2652.45	660
2655.11	706
2657.77	678
2660.43	658
2663.09	672
2665.75	656
2668.4	692
2671.06	714
2673.71	660
2676.37	666
2679.02	694
2681.67	694
2684.32	694
2686.97	666
2689.61	678
2692.26	642
2694.9	670
2697.55	676
2700.19	692
2702.83	662
2705.47	672
2708.11	654
2710.75	656
2713.39	640
2716.02	664
2718.66	664
2721.29	656
2723.92	664
2726.55	642
2729.18	652
2731.81	644
2734.44	636
2737.07	628
2739.69	654
2742.32	618
2744.94	666
2747.56	674
2750.18	622
2752.8	688
2755.42	648
2758.04	644
2760.65	640
2763.27	646
2765.88	598
2768.5	616
2771.11	634
2773.72	610
2776.33	606
2778.94	610
2781.54	606
2784.15	612
2786.75	600
2789.36	604
2791.96	626
2794.56	612
2797.16	592
2799.76	624
2802.36	610
2804.96	634
2807.55	624
2810.15	586
2812.74	626
2815.33	606
2817.93	588
2820.52	610
2823.11	592
2825.69	608
2828.28	612
2830.87	598
2833.45	590
2836.03	592
2838.62	580
2841.2	604
2843.78	568
2846.36	566
2848.93	584
2851.51	616
2854.09	578
2856.66	576
2859.24	578
2861.81	582
2864.38	570
2866.95	554
2869.52	556
2872.09	584
2874.65	566
2877.22	576
2879.78	536
2882.35	548
2884.91	554
2887.47	584
2890.03	558
2892.59	536
2895.15	538
2897.7	556
2900.26	550
2902.81	572
2905.37	540
2907.92	538
2910.47	560
2913.02	564
2915.57	556
2918.12	572
2920.66	532
2923.21	552
2925.75	536
2928.3	542
2930.84	532
2933.38	554
2935.92	512
2938.46	568
2941	532
2943.54	518
2946.07	526
2948.61	526
2951.14	524
2953.67	520
2956.21	550
2958.74	562
2961.27	548
2963.79	552
2966.32	516
2968.85	526
2971.37	524
2973.9	530
2976.42	516
2978.94	528
2981.46	532
2983.98	512
2986.5	502
2989.02	524
2991.53	546
2994.05	480
2996.56	488
2999.08	510
3001.59	484
3004.1	500
3006.61	490
3009.12	504
3011.63	496
3014.13	498
3016.64	494
3019.14	508
3021.65	504
3024.15	496
3026.65	492
3029.15	476
3031.65	484
3034.15	484
3036.64	502
3039.14	476
3041.63	505.509
3044.13	480.767
3046.62	480.933
3049.11	492.143
3051.6	494.623
3054.09	497.696
3056.58	491.365
3059.07	495.344
3061.55	467.008
3064.04	476.863
3066.52	480.326
3069.01	462.777
3071.49	471.839
3073.97	470.828
3076.45	465.07
3078.93	454.703
3081.41	459.216
3083.88	450.217
3086.36	446.917
3088.83	465.19
3091.31	458.938
3093.78	447.057
3096.25	450.104
3098.72	455.29
3101.19	451.299
3103.66	445.176
3106.13	436.913
3108.59	429.56
3111.06	434.856
3113.52	431.081
3115.98	421.115
3118.45	439.792
3120.91	436.274
3123.37	422.368
3125.38	440
3127.85	426
3130.32	416
3132.79	468
3135.26	442
3137.73	428
3140.19	414
3142.66	434
3145.13	422
3147.59	408
3150.05	424
3152.51	402
3154.97	390
3157.43	396
3159.89	404
3162.35	404
3164.8	414
3167.26	436
3169.71	416
3172.17	416
3174.62	398
3177.07	406
3179.52	396
3181.97	408
3184.41	428
3186.86	410
3189.31	440
3191.75	422
3194.2	432
3196.64	432
3199.08	402
3201.52	416
3203.96	400
3206.4	404
3208.84	392
3211.27	414
3213.71	394
3216.14	378
3218.58	426
3221.01	394
3223.44	406
3225.87	388
3228.3	402
3230.73	396
3233.16	400
3235.58	410
3238.01	404
3240.43	392
3242.86	388
3245.28	382
3247.7	376
3250.12	376
3252.54	408
3254.96	350
3257.38	400
3259.79	382
3262.21	366
3264.62	406
3267.04	380
3269.45	386
3271.86	392
3274.27	380
3276.68	358
3279.09	376
3281.49	374
3283.9	396
3286.31	374
3288.71	386
3291.11	354
3293.51	360
3295.92	362
3298.32	368
3300.72	366
3303.11	382
3305.51	352
3307.91	364
3310.3	370
3312.7	350
3315.09	362
3317.48	354
3319.87	354
3322.26	370
3324.65	374
3327.04	346
3329.43	348
3331.81	348
3334.2	362
3336.58	374
3338.97	362
3341.35	370
3343.73	346
3346.11	360
3348.49	326
3350.87	322
3353.25	326
3355.62	342
3358	348
3360.37	336
3362.75	336
3365.12	354
3367.49	364
3369.86	344
3372.23	334
3374.6	332
3376.97	342
3379.33	348
3381.7	334
3384.06	340
3386.43	346
3388.79	334
3391.15	360
3393.51	330
3395.87	334
3398.23	336
3400.59	350
3402.94	332
3405.3	334
3407.65	338
3410.01	330
3412.36	326
3414.71	332
3417.06	334
3419.41	322
3421.76	336
3424.11	338
3426.46	336
3428.8	336
3431.15	306
3433.49	308
3435.83	328
3438.18	324
3440.52	340
3442.86	302
3445.2	314
3447.53	298
3449.87	316
3452.21	312
3454.54	318
3456.88	320
3459.21	300
3461.54	318
3463.88	292
3466.21	314
3468.53	304
3470.86	324
3473.19	308
3475.52	304
3477.84	318
3480.17	334
3482.49	314
3484.82	302
3487.14	330
3489.46	308
3491.78	304
3494.1	298
3496.42	298
3498.73	304
3501.05	298
3503.36	316
3505.68	318
3507.99	304
3510.3	308
3512.61	290
3514.92	296
3517.23	306
3519.54	312
3521.85	308
3524.16	310
3526.46	302
3528.77	300
3531.07	288
3533.37	298
3535.68	298
3537.98	290
3540.28	306
3542.58	320
3544.87	278
3547.17	276
3549.47	304
3551.76	294
3554.06	302
3556.35	284
3558.64	290
3560.93	290
3563.22	300
3565.51	274
3567.8	294
3570.09	304
3572.38	282
3574.66	284
3576.95	304
3579.23	286
3581.51	274
3583.8	290
3586.08	280
3588.36	304
3590.64	274
3592.92	296
3595.19	288
3597.47	284
3599.75	272
3602.02	294
3604.29	268
3606.57	266
3608.84	292
3611.11	270
3613.38	284
3615.65	268
3617.92	284
3620.18	282
3622.45	258
3624.71	262
3626.98	266
3629.24	270
3631.5	276
3633.77	278
3636.03	266
3638.29	254
3640.55	258
3642.8	254
3645.06	284
3647.32	258
3649.57	250
3651.83	272
3654.08	280
3656.33	276
3658.58	250
3660.83	262
3663.08	258
3665.33	270
3667.58	280
3669.83	262
3672.07	270
3674.32	252
3676.56	266
3678.8	264
3681.05	256
3683.29	278
3685.53	260
3687.77	264
3690.01	262
3692.24	268
3694.48	262
3696.72	268
3698.95	268
3701.19	256
3703.42	264
3705.65	258
3707.88	262
3710.11	242
3712.34	260
3714.57	252
3716.8	264
3719.03	250
3721.25	246
3723.48	254
3725.7	252
3727.92	248
3730.15	236
3732.37	244
3734.59	256
3736.81	260
3739.03	258
3741.24	250
3743.46	262
3745.68	238
3747.89	248
3750.11	248
3752.32	238
3754.53	260
3756.74	244
3758.95	230
3761.16	258
3763.37	234.117
3765.58	253.564
3767.79	232.38
3769.99	234.422
3772.2	247.722
3774.4	225.549
3776.61	248.433
3778.81	235.066
3781.01	250.194
3783.21	241.949
3785.41	239.952
3787.61	259.979
3789.81	249.304
3792	246.31
3794.2	244.3
3796.4	236.703
3798.59	223.551
3800.78	240.496
3802.98	244.025
3805.17	238.92
3807.36	242.79
3809.55	241.18
3811.74	243.395
3813.93	233.043
3816.11	239.449
3818.3	245.976
3820.49	235.037
3822.67	237.028
3824.85	222.221
3827.04	221.863
3829.22	239.06
3831.4	240.226
3833.58	230.301
3835.76	217.603
3837.94	230.895
3839.98	238
3842.17	232
3844.36	232
3846.55	234
3848.73	252
3850.92	246
3853.1	216
3855.29	212
3857.47	236
3859.65	228
3861.84	228
3864.02	230
3866.2	228
3868.38	230
3870.55	238
3872.73	214
3874.91	228
3877.08	226
3879.26	218
3881.43	220
3883.6	248
3885.78	224
3887.95	230
3890.12	212
3892.29	218
3894.46	230
3896.63	218
3898.79	232
3900.96	226
3903.12	220
3905.29	220
3907.45	238
3909.61	206
3911.78	238
3913.94	226
3916.1	220
3918.26	222
3920.41	226
3922.57	226
3924.73	236
3926.88	214
3929.04	226
3931.19	228
3933.35	226
3935.5	214
3937.65	224
3939.8	206
3941.95	216
3944.1	206
3946.25	226
3948.4	220
3950.54	238
3952.69	218
3954.83	212
3956.98	210
3959.12	218
3961.26	208
3963.4	206
3965.54	218
3967.68	216
3969.82	202
3971.96	206
3974.1	198
3976.23	202
3978.37	218
3980.5	200
3982.64	198
3984.77	200
3986.9	204
3989.03	224
3991.16	208
3993.29	204
3995.42	186
3997.55	196
3999.67	230