File: muestras/mosquito/OR_12.txt
#Acq. time (s)=	10
#Accumulations=	1
#Range (cm-¹)=	200...4000
#Windows=	5
#Autofocus=	Off
#AutoExposure=	Off
#Spike filter=	Off
#Delay time (s)=	0
#Binning=	1
#Readout mode=	Signal
#DeNoise=	Off
#ICS correction=	Off
#Dark correction=	Off
#Inst. Process=	Off
#Instrument=	LabRAM HR Evol
#Detector=	Syncerity OE
#Objective=	x100_VIS
#Grating=	600 (500nm)
#ND Filter=	25%
#Laser=	633nm_Edge
#Hole=	100.021
#Range=	Visible
#Project=	Omar
#Sample=	03-07-23
#Site=	1
#Title=	OR
#Remark=
#Date=	03.07.2023 13:45
#Acquired=	03.07.2023 13:45:56
200.404	710
204.205	738
208.003	714
211.799	696
215.595	716
219.387	710
223.177	718
226.966	712
230.752	720
234.536	690
238.319	734
242.1	710
245.879	732
249.655	718
253.431	728
257.204	718
260.976	738
264.744	718
268.511	708
272.276	728
276.04	726
279.801	738
283.561	738
287.318	734
291.074	724
294.828	744
298.581	778
302.33	778
306.079	796
309.825	734
313.569	760
317.311	766
321.052	724
324.79	728
328.527	762
332.261	792
335.994	766
339.725	746
343.454	754
347.182	740
350.907	806
354.631	790
358.352	820
362.072	782
365.789	738
369.505	804
373.219	762
376.93	800
380.642	804
384.35	792
388.056	806
391.76	802
395.463	778
399.164	784
402.863	770
406.559	806
410.254	830
413.948	790
417.639	838
421.329	812
425.016	824
428.701	850
432.386	848
436.068	826
439.748	838
443.426	834
447.103	818
450.777	870
454.45	880
458.121	870
461.789	840
465.457	850
469.122	828
472.786	838
476.447	890
480.107	870
483.765	856
487.421	864
491.075	848
494.727	880
498.377	892
502.026	850
505.673	870
509.318	898
512.962	850
516.602	890
520.242	884
523.881	868
527.516	874
531.149	858
534.783	912
538.413	880
542.041	860
545.667	894
549.292	870
552.915	860
556.537	870
560.156	870
563.773	890
567.389	890
571.004	868
574.615	904
578.226	912
581.834	868
585.44	900
589.045	888
592.649	906
596.25	938
599.85	920
603.448	910
607.042	874
610.637	914
614.229	912
617.819	898
621.408	888
624.994	964
628.58	910
632.163	912
635.744	886
639.324	954
642.902	984
646.478	934
650.052	954
653.625	946
657.196	972
660.764	924
664.331	954
667.897	958
671.46	956
675.021	982
678.582	1000
682.14	938
685.696	990
689.252	938
692.804	998
696.355	962
699.905	958
703.451	942
706.997	948
710.542	962
714.083	986
717.624	950
721.162	960
724.7	962
728.235	988
731.768	972
735.301	954
738.83	976
742.358	1010
745.885	974
749.41	982
752.931	996
756.453	980
759.973	1022
763.49	1040
767.006	1006
770.52	1006
774.033	978
777.543	1038
781.052	1010
784.559	992
788.064	992
791.568	1000
795.07	1044
798.57	988
802.068	998
805.565	1028
809.061	1010
812.553	1036
816.045	1054
819.535	1084
823.022	1060
826.508	1038
829.993	1060
833.476	1054
836.957	1028
840.436	1020
843.914	1042
847.391	1048
850.864	1070
854.337	1042
857.807	1054
861.277	1032
864.744	1028
868.209	1068
871.674	1078
875.136	1036
878.597	1076
882.056	1040
885.512	1086
888.967	1022
892.421	1060
895.874	1048
899.323	1092
902.771	1064
906.219	1034
909.664	1076
913.107	1052
916.55	1052
919.99	1070
923.428	1050
926.863	1066
930.299	1062
933.732	1072
937.164	1076
940.593	1032
944.022	1102
947.448	1094
950.874	1112
954.296	1116
957.718	1088
961.137	1128
964.555	1088
967.972	1088
971.387	1086
974.8	1112
978.21	1108
981.62	1106
985.029	1106
988.435	1118
991.839	1122
995.243	1092
998.644	1108
1002.04	1116
1005.44	1096
1008.84	1114
1012.23	1148
1015.63	1084
1019.02	1140
1022.41	1134
1025.79	1152
1029.18	1104
1032.56	1124
1035.95	1146
1039.33	1104
1042.71	1152
1046.09	1098
1049.46	1160
1052.84	1142
1056.21	1134
1059.58	1122
1062.95	1162
1066.32	1144
1069.69	1142
1073.05	1186
1076.41	1146
1079.78	1136
1083.14	1144
1086.49	1152
1089.85	1110
1093.21	1138
1096.56	1118
1099.91	1172
1103.26	1138
1106.61	1128
1109.96	1098
1113.3	1142
1116.64	1144
1119.99	1100
1123.33	1132
1126.66	1138
1130	1116
1133.34	1170
1136.67	1162
1140	1140
1143.33	1158
1146.66	1170
1149.99	1174
1153.32	1170
1156.64	1168
1159.96	1166
1163.28	1204
1166.6	1202
1169.92	1156
1173.23	1158
1176.55	1134
1179.86	1194
1183.17	1154
1186.48	1162
1189.79	1192
1193.1	1160
1196.4	1178
1199.7	1156
1203	1130
1206.3	1164
1209.6	1134
1212.9	1134
1216.19	1158
1219.49	1142
1222.78	1150
1226.07	1156
1229.36	1154
1232.65	1106
1235.93	1186
1239.21	1162
1242.5	1156
1245.78	1154
1249.06	1152
1252.33	1128
1255.61	1176
1258.88	1178
1262.16	1166
1265.43	1160
1268.7	1134
1271.96	1178
1275.23	1160
1278.5	1194
1281.76	1189.83
1285.02	1211.9
1288.28	1161.05
1291.54	1157.83
1294.8	1186.06
1298.05	1177.64
1301.31	1152.92
1304.56	1187.38
1307.81	1160.96
1311.06	1171.01
1314.3	1143.64
1317.55	1195.86
1320.79	1184.68
1324.04	1197.9
1327.28	1176.34
1330.52	1175.05
1333.76	1225.98
1336.99	1150.61
1340.23	1166.27
1343.46	1180.47
1346.69	1190.17
1349.92	1205.84
1353.15	1195.95
1356.38	1173.44
1359.6	1204.57
1362.83	1205.46
1366.05	1179.75
1369.27	1193.44
1372.49	1193.81
1375.71	1215.92
1378.93	1199.05
1382.14	1200.38
1385.35	1190.48
1388.57	1192.1
1391.2	1216
1394.43	1198
1397.65	1188
1400.87	1210
1404.09	1206
1407.31	1226
1410.53	1166
1413.74	1188
1416.96	1140
1420.17	1158
1423.38	1170
1426.59	1200
1429.8	1192
1433.01	1180
1436.21	1184
1439.42	1184
1442.62	1204
1445.82	1182
1449.02	1176
1452.22	1174
1455.41	1164
1458.61	1164
1461.8	1126
1464.99	1184
1468.18	1154
1471.37	1160
1474.56	1168
1477.74	1126
1480.93	1178
1484.11	1170
1487.29	1234
1490.47	1190
1493.65	1140
1496.82	1188
1500	1156
1503.17	1186
1506.34	1180
1509.51	1150
1512.68	1156
1515.85	1168
1519.02	1142
1522.18	1150
1525.34	1164
1528.51	1136
1531.67	1144
1534.82	1174
1537.98	1132
1541.14	1200
1544.29	1130
1547.44	1148
1550.59	1120
1553.74	1184
1556.89	1130
1560.04	1120
1563.18	1128
1566.33	1104
1569.47	1108
1572.61	1114
1575.75	1122
1578.89	1120
1582.02	1104
1585.16	1116
1588.29	1126
1591.42	1128
1594.55	1126
1597.68	1156
1600.81	1110
1603.94	1138
1607.06	1154
1610.18	1132
1613.3	1112
1616.42	1138
1619.54	1104
1622.66	1134
1625.78	1108
1628.89	1100
1632	1100
1635.11	1092
1638.22	1078
1641.33	1082
1644.44	1078
1647.55	1050
1650.65	1050
1653.75	1074
1656.85	1070
1659.95	1056
1663.05	1046
1666.15	1036
1669.24	1010
1672.34	1054
1675.43	1024
1678.52	1036
1681.61	1014
1684.7	1036
1687.78	1030
1690.87	992
1693.95	1046
1697.03	1054
1700.12	1062
1703.2	1022
1706.27	1030
1709.35	1018
1712.42	1014
1715.5	1018
1718.57	1024
1721.64	1008
1724.71	1022
1727.78	1010
1730.84	1020
1733.91	1024
1736.97	968
1740.04	970
1743.1	980
1746.16	954
1749.21	1006
1752.27	990
1755.33	996
1758.38	998
1761.43	942
1764.48	936
1767.53	992
1770.58	994
1773.63	982
1776.67	988
1779.71	962
1782.76	958
1785.8	1004
1788.84	978
1791.88	998
1794.91	956
1797.95	966
1800.98	956
1804.01	948
1807.04	964
1810.07	988
1813.1	960
1816.13	962
1819.15	930
1822.18	942
1825.2	916
1828.22	916
1831.24	918
1834.26	954
1837.28	980
1840.29	940
1843.31	888
1846.32	944
1849.33	910
1852.34	920
1855.35	904
1858.36	894
1861.36	918
1864.36	902
1867.37	936
1870.37	894
1873.37	940
1876.37	876
1879.37	914
1882.36	886
1885.36	910
1888.35	904
1891.34	918
1894.33	890
1897.32	894
1900.31	938
1903.3	918
1906.28	930
1909.26	896
1912.25	892
1915.23	920
1918.21	906
1921.18	886
1924.16	876
1927.14	888
1930.11	890
1933.08	902
1936.05	880
1939.02	872
1941.99	886
1944.96	932
1947.92	886
1950.89	842
1953.85	892
1956.81	864
1959.77	908
1962.73	872
1965.69	882
1968.65	860
1971.6	868
1974.55	866
1977.51	892
1980.46	864
1983.41	896
1986.35	850
1989.3	888
1992.25	864
1995.19	852
1998.13	858
2001.07	854
2004.01	840
2006.95	908
2009.89	834
2012.82	848
2015.76	856
2018.69	852
2021.62	822
2024.55	858
2027.48	848
2030.41	854
2033.34	816
2036.26	818
2039.19	828
2042.11	804
2045.03	822
2047.95	830
2050.87	838
2053.79	856
2056.7	826
2059.61	780
2062.53	842
2065.44	822
2068.35	820
2071.26	832
2074.17	828
2077.07	790
2079.98	800
2082.88	816
2085.78	764
2088.68	794
2091.58	798
2094.48	832
2097.38	818
2100.28	786
2103.17	786
2106.06	836
2108.96	796
2111.85	782
2114.73	826
2117.62	784
2120.51	764
2123.39	764
2126.28	782
2129.16	796
2132.04	794
2134.92	760
2137.8	748
2140.68	762
2143.55	754
2146.43	754
2149.3	796
2152.17	764
2155.04	752
2157.91	764
2160.78	760
2163.65	790
2166.51	776
2169.38	750
2172.24	778
2175.1	746
2177.96	772
2180.82	744
2183.68	762
2186.53	756
2189.39	750
2192.24	732
2195.09	716
2197.95	740
2200.8	744
2203.64	716
2206.49	724
2209.34	720
2212.18	734
2215.03	710
2217.87	750
2220.71	722.379
2223.55	729.219
2226.39	715.803
2229.22	733.054
2232.06	726.708
2234.89	750.035
2237.73	740.702
2240.56	717.604
2243.39	734.707
2246.22	706.039
2249.05	736.027
2251.87	720.686
2254.7	717.426
2257.52	708.535
2260.34	717.659
2263.17	722.305
2265.99	730.366
2268.8	708.742
2271.62	726.593
2274.44	730.932
2277.25	718.188
2280.07	687.503
2282.88	697.67
2285.69	720.378
2288.5	706.859
2291.31	708.757
2294.12	707.578
2296.92	704.978
2299.73	734.919
2302.53	700.21
2305.34	706.919
2308.14	722.389
2310.94	711.068
2313.74	699.611
2315.86	728
2318.67	684
2321.48	686
2324.29	704
2327.09	672
2329.9	706
2332.7	712
2335.51	720
2338.31	686
2341.11	662
2343.91	676
2346.71	700
2349.51	702
2352.3	708
2355.1	688
2357.89	678
2360.68	698
2363.48	692
2366.27	688
2369.05	696
2371.84	684
2374.63	704
2377.41	692
2380.2	684
2382.98	702
2385.76	692
2388.54	708
2391.32	706
2394.1	688
2396.87	690
2399.65	664
2402.42	650
2405.2	656
2407.97	674
2410.74	680
2413.51	658
2416.27	680
2419.04	670
2421.81	682
2424.57	684
2427.33	668
2430.1	686
2432.85	668
2435.61	628
2438.37	674
2441.13	658
2443.88	612
2446.64	668
2449.39	664
2452.14	646
2454.89	680
2457.64	650
2460.39	634
2463.14	646
2465.88	634
2468.63	648
2471.37	654
2474.11	640
2476.86	656
2479.59	636
2482.33	632
2485.07	646
2487.81	638
2490.54	642
2493.28	638
2496.01	624
2498.74	646
2501.47	630
2504.2	610
2506.93	644
2509.65	634
2512.38	656
2515.1	652
2517.82	652
2520.55	612
2523.27	620
2525.99	646
2528.7	608
2531.42	636
2534.14	624
2536.85	614
2539.56	616
2542.28	644
2544.99	618
2547.7	604
2550.4	610
2553.11	622
2555.82	610
2558.52	606
2561.23	612
2563.93	590
2566.63	620
2569.33	634
2572.03	588
2574.73	596
2577.42	566
2580.12	592
2582.81	616
2585.51	618
2588.2	596
2590.89	576
2593.58	590
2596.26	568
2598.95	614
2601.64	574
2604.32	602
2607.01	556
2609.69	572
2612.37	564
2615.05	580
2617.73	584
2620.41	610
2623.08	586
2625.76	590
2628.43	598
2631.1	580
2633.78	582
2636.45	542
2639.12	566
2641.78	548
2644.45	548
2647.12	564
2649.78	572
2652.45	522
2655.11	578
2657.77	560
2660.43	590
2663.09	552
2665.75	576
2668.4	576
2671.06	576
2673.71	588
2676.37	602
2679.02	558
2681.67	558
2684.32	550
2686.97	540
2689.61	558
2692.26	544
2694.9	550
2697.55	532
2700.19	526
2702.83	550
2705.47	534
2708.11	556
2710.75	544
2713.39	568
2716.02	560
2718.66	524
2721.29	544
2723.92	524
2726.55	558
2729.18	556
2731.81	516
2734.44	542
2737.07	518
2739.69	538
2742.32	538
2744.94	544
2747.56	548
2750.18	524
2752.8	548
2755.42	508
2758.04	512
2760.65	510
2763.27	532
2765.88	522
2768.5	492
2771.11	508
2773.72	498
2776.33	494
2778.94	514
2781.54	500
2784.15	516
2786.75	522
2789.36	530
2791.96	500
2794.56	494
2797.16	500
2799.76	496
2802.36	498
2804.96	498
2807.55	488
2810.15	512
2812.74	470
2815.33	526
2817.93	506
2820.52	512
2823.11	500
2825.69	504
2828.28	496
2830.87	516
2833.45	492
2836.03	502
2838.62	478
2841.2	500
2843.78	506
2846.36	484
2848.93	458
2851.51	490
2854.09	464
2856.66	484
2859.24	456
2861.81	480
2864.38	462
2866.95	470
2869.52	450
2872.09	470
2874.65	492
2877.22	466
2879.78	446
2882.35	484
2884.91	452
2887.47	456
2890.03	432
2892.59	440
2895.15	454
2897.7	454
2900.26	460
2902.81	494
2905.37	446
2907.92	460
2910.47	458
2913.02	444
2915.57	438
2918.12	456
2920.66	446
2923.21	450
2925.75	428
2928.3	438
2930.84	458
2933.38	428
2935.92	448
2938.46	438
2941	410
2943.54	442
2946.07	442
2948.61	434
2951.14	454
2953.67	452
2956.21	458
2958.74	402
2961.27	422
2963.79	424
2966.32	428
2968.85	426
2971.37	430
2973.9	442
2976.42	428
2978.94	406
2981.46	402
2983.98	408
2986.5	396
2989.02	398
2991.53	400
2994.05	418
2996.56	420
2999.08	402
3001.59	404
3004.1	414
3006.61	396
3009.12	410
3011.63	412
3014.13	418
3016.64	404
3019.14	420
3021.65	402
3024.15	394
3026.65	398
3029.15	398
3031.65	406
3034.15	388
3036.64	374
3039.14	370
3041.63	403.822
3044.13	402.663
3046.62	394.366
3049.11	389.245
3051.6	367.824
3054.09	382.062
3056.58	385.051
3059.07	380.495
3061.55	371.095
3064.04	379.79
3066.52	377.944
3069.01	373.111
3071.49	371.419
3073.97	378.829
3076.45	374.606
3078.93	364.023
3081.41	372.924
3083.88	361.116
3086.36	366.24
3088.83	353.72
3091.31	346.316
3093.78	357.492
3096.25	372.065
3098.72	353.22
3101.19	338.588
3103.66	337.221
3106.13	353.882
3108.59	361.779
3111.06	346.078
3113.52	353.257
3115.98	345.699
3118.45	354.722
3120.91	336.77
3123.37	346.958
3125.38	324
3127.85	344
3130.32	356
3132.79	334
3135.26	346
3137.73	340
3140.19	348
3142.66	336
3145.13	348
3147.59	334
3150.05	332
3152.51	328
3154.97	320
3157.43	322
3159.89	338
3162.35	324
3164.8	302
3167.26	334
3169.71	326
3172.17	306
3174.62	304
3177.07	330
3179.52	308
3181.97	330
3184.41	320
3186.86	300
3189.31	304
3191.75	304
3194.2	336
3196.64	302
3199.08	304
3201.52	312
3203.96	312
3206.4	298
3208.84	308
3211.27	316
3213.71	304
3216.14	314
3218.58	322
3221.01	302
3223.44	298
3225.87	322
3228.3	322
3230.73	328
3233.16	306
3235.58	314
3238.01	300
3240.43	300
3242.86	312
3245.28	290
3247.7	302
3250.12	308
3252.54	306
3254.96	288
3257.38	314
3259.79	284
3262.21	278
3264.62	288
3267.04	296
3269.45	300
3271.86	300
3274.27	300
3276.68	300
3279.09	318
3281.49	288
3283.9	272
3286.31	298
3288.71	294
3291.11	306
3293.51	298
3295.92	292
3298.32	308
3300.72	296
3303.11	278
3305.51	292
3307.91	314
3310.3	274
3312.7	276
3315.09	292
3317.48	282
3319.87	294
3322.26	276
3324.65	296
3327.04	284
3329.43	276
3331.81	276
3334.2	268
3336.58	272
3338.97	268
3341.35	284
3343.73	260
3346.11	286
3348.49	300
3350.87	268
3353.25	278
3355.62	292
3358	268
3360.37	262
3362.75	270
3365.12	252
3367.49	270
3369.86	284
3372.23	278
3374.6	268
3376.97	260
3379.33	256
3381.7	274
3384.06	266
3386.43	266
3388.79	252
3391.15	264
3393.51	254
3395.87	256
3398.23	276
3400.59	248
3402.94	276
3405.3	264
3407.65	264
3410.01	254
3412.36	244
3414.71	270
3417.06	274
3419.41	246
3421.76	242
3424.11	258
3426.46	250
3428.8	254
3431.15	254
3433.49	240
3435.83	258
3438.18	240
3440.52	246
3442.86	246
3445.2	224
3447.53	252
3449.87	256
3452.21	234
3454.54	226
3456.88	226
3459.21	248
3461.54	266
3463.88	234
3466.21	230
3468.53	260
3470.86	236
3473.19	236
3475.52	246
3477.84	214
3480.17	216
3482.49	258
3484.82	242
3487.14	256
3489.46	230
3491.78	242
3494.1	244
3496.42	240
3498.73	248
3501.05	244
3503.36	236
3505.68	234
3507.99	234
3510.3	256
3512.61	222
3514.92	228
3517.23	228
3519.54	250
3521.85	228
3524.16	224
3526.46	236
3528.77	238
3531.07	244
3533.37	230
3535.68	228
3537.98	226
3540.28	232
3542.58	228
3544.87	212
3547.17	242
3549.47	236
3551.76	234
3554.06	224
3556.35	228
3558.64	228
3560.93	226
3563.22	208
3565.51	228
3567.8	240
3570.09	224
3572.38	212
3574.66	220
3576.95	228
3579.23	216
3581.51	216
3583.8	212
3586.08	212
3588.36	222
3590.64	206
3592.92	204
3595.19	226
3597.47	228
3599.75	200
3602.02	210
3604.29	216
3606.57	202
3608.84	222
3611.11	200
3613.38	222
3615.65	220
3617.92	202
3620.18	210
3622.45	222
3624.71	226
3626.98	198
3629.24	212
3631.5	214
3633.77	204
3636.03	206
3638.29	216
3640.55	210
3642.8	206
3645.06	212
3647.32	194
3649.57	224
3651.83	218
3654.08	220
3656.33	204
3658.58	210
3660.83	202
3663.08	200
3665.33	198
3667.58	196
3669.83	200
3672.07	200
3674.32	208
3676.56	210
3678.8	204
3681.05	206
3683.29	208
3685.53	190
3687.77	182
3690.01	188
3692.24	212
3694.48	190
3696.72	198
3698.95	200
3701.19	206
3703.42	188
3705.65	204
3707.88	200
3710.11	174
3712.34	210
3714.57	194
3716.8	196
3719.03	190
3721.25	202
3723.48	198
3725.7	182
3727.92	206
3730.15	192
3732.37	194
3734.59	182
3736.81	182
3739.03	208
3741.24	180
3743.46	194
3745.68	188
3747.89	184
3750.11	200
3752.32	188
3754.53	206
3756.74	182
3758.95	186
3761.16	180
3763.37	182.068
3765.58	195.744
3767.79	195.623
3769.99	196.072
3772.2	183.458
3774.4	191.839
3776.61	182.041
3778.81	195.587
3781.01	186.059
3783.21	189.304
3785.41	186.034
3787.61	180.999
3789.81	188.182
3792	198.97
3794.2	189.263
3796.4	176.886
3798.59	188.642
3800.78	179.529
3802.98	184.58
3805.17	191.057
3807.36	176.652
3809.55	183.304
3811.74	183.32
3813.93	181.19
3816.11	184.329
3818.3	181.292
3820.49	186.538
3822.67	188.125
3824.85	186.818
3827.04	192.412
3829.22	178.606
3831.4	186.176
3833.58	180.32
3835.76	183.505
3837.94	180.042
3839.98	188
3842.17	182
3844.36	194
3846.55	178
3848.73	172
3850.92	184
3853.1	192
3855.29	176
3857.47	164
3859.65	182
3861.84	174
3864.02	180
3866.2	178
3868.38	176
3870.55	174
3872.73	170
3874.91	170
3877.08	170
3879.26	182
3881.43	180
3883.6	180
3885.78	174
3887.95	168
3890.12	156
3892.29	162
3894.46	172
3896.63	180
3898.79	170
3900.96	184
3903.12	178
3905.29	174
3907.45	164
3909.61	166
3911.78	184
3913.94	168
3916.1	166
3918.26	172
3920.41	166
3922.57	178
3924.73	178
3926.88	164
3929.04	186
3931.19	172
3933.35	174
3935.5	160
3937.65	160
3939.8	164
3941.95	172
3944.1	156
3946.25	174
3948.4	164
3950.54	170
3952.69	176
3954.83	194
3956.98	166
3959.12	156
3961.26	170
3963.4	164
3965.54	176
3967.68	146
3969.82	164
3971.96	164
3974.1	160
3976.23	164
3978.37	160
3980.5	152
3982.64	168
3984.77	144
3986.9	160
3989.03	160
3991.16	146
3993.29	168
3995.42	164
3997.55	152
3999.67	148