File: muestras/mosquito/OR_16.txt
#Acq. time (s)=	10
#Accumulations=	1
#Range (cm-¹)=	200...4000
#Windows=	5
#Autofocus=	Off
#AutoExposure=	Off
#Spike filter=	Off
#Delay time (s)=	0
#Binning=	1
#Readout mode=	Signal
#DeNoise=	Off
#ICS correction=	Off
#Dark correction=	Off
#Inst. Process=	Off
#Instrument=	LabRAM HR Evol
#Detector=	Syncerity OE
#Objective=	x100_VIS
#Grating=	600 (500nm)
#ND Filter=	25%
#Laser=	633nm_Edge
#Hole=	100.021
#Range=	Visible
#Project=	Omar
#Sample=	03-07-23
#Site=	1
#Title=	OR
#Remark=
#Date=	03.07.2023 13:52
#Acquired=	03.07.2023 13:52:27
200.404	906
204.205	882
208.003	902
211.799	888
215.595	924
219.387	918
223.177	930
226.966	936
230.752	896
234.536	894
238.319	918
242.1	956
245.879	932
249.655	912
253.431	946
257.204	954
260.976	934
264.744	932
268.511	938
272.276	944
276.04	908
279.801	910
283.561	966
287.318	940
291.074	954
294.828	932
298.581	930
302.33	924
306.079	958
309.825	954
313.569	960
317.311	920
321.052	970
324.79	960
328.527	990
332.261	978
335.994	952
339.725	992
343.454	992
347.182	980
350.907	984
354.631	986
358.352	940
362.072	1012
365.789	1018
369.505	998
373.219	974
376.93	1002
380.642	1008
384.35	1008
388.056	958
391.76	1010
395.463	1062
399.164	976
402.863	1034
406.559	986
410.254	1014
413.948	1024
417.639	1078
421.329	1018
425.016	1052
428.701	1042
432.386	1060
436.068	1044
439.748	1086
443.426	1084
447.103	1026
450.777	1100
454.45	1050
458.121	1018
461.789	1044
465.457	1090
469.122	1056
472.786	1048
476.447	1088
480.107	1094
483.765	1072
487.421	1096
491.075	1088
494.727	1078
498.377	1094
502.026	1080
505.673	1060
509.318	1056
512.962	1106
516.602	1076
520.242	1096
523.881	1078
527.516	1088
531.149	1070
534.783	1078
538.413	1104
542.041	1078
545.667	1100
549.292	1124
552.915	1110
556.537	1100
560.156	1120
563.773	1098
567.389	1080
571.004	1128
574.615	1088
578.226	1142
581.834	1118
585.44	1104
589.045	1132
592.649	1128
596.25	1100
599.85	1150
603.448	1114
607.042	1144
610.637	1106
614.229	1120
617.819	1154
621.408	1180
624.994	1138
628.58	1130
632.163	1108
635.744	1146
639.324	1164
642.902	1174
646.478	1130
650.052	1182
653.625	1184
657.196	1198
660.764	1158
664.331	1168
667.897	1154
671.46	1188
675.021	1146
678.582	1190
682.14	1160
685.696	1168
689.252	1156
692.804	1162
696.355	1200
699.905	1216
703.451	1206
706.997	1178
710.542	1176
714.083	1180
717.624	1180
721.162	1170
724.7	1194
728.235	1210
731.768	1214
735.301	1216
738.83	1214
742.358	1206
745.885	1192
749.41	1176
752.931	1218
756.453	1208
759.973	1206
763.49	1230
767.006	1204
770.52	1192
774.033	1214
777.543	1234
781.052	1200
784.559	1234
788.064	1186
791.568	1238
795.07	1238
798.57	1248
802.068	1222
805.565	1250
809.061	1280
812.553	1194
816.045	1262
819.535	1248
823.022	1262
826.508	1228
829.993	1260
833.476	1268
836.957	1232
840.436	1302
843.914	1292
847.391	1246
850.864	1234
854.337	1232
857.807	1286
861.277	1268
864.744	1276
868.209	1304
871.674	1270
875.136	1230
878.597	1252
882.056	1274
885.512	1282
888.967	1264
892.421	1268
895.874	1260
899.323	1316
902.771	1234
906.219	1280
909.664	1306
913.107	1262
916.55	1234
919.99	1268
923.428	1288
926.863	1310
930.299	1278
933.732	1284
937.164	1238
940.593	1296
944.022	1326
947.448	1302
950.874	1346
954.296	1356
957.718	1340
961.137	1288
964.555	1290
967.972	1312
971.387	1342
974.8	1336
978.21	1334
981.62	1356
985.029	1310
988.435	1304
991.839	1376
995.243	1386
998.644	1306
1002.04	1344
1005.44	1326
1008.84	1324
1012.23	1318
1015.63	1310
1019.02	1334
1022.41	1342
1025.79	1410
1029.18	1350
1032.56	1346
1035.95	1316
1039.33	1388
1042.71	1348
1046.09	1362
1049.46	1412
1052.84	1392
1056.21	1396
1059.58	1404
1062.95	1372
1066.32	1384
1069.69	1346
1073.05	1400
1076.41	1344
1079.78	1346
1083.14	1390
1086.49	1350
1089.85	1352
1093.21	1354
1096.56	1314
1099.91	1386
1103.26	1338
1106.61	1350
1109.96	1386
1113.3	1362
1116.64	1352
1119.99	1332
1123.33	1308
1126.66	1396
1130	1446
1133.34	1410
1136.67	1394
1140	1376
1143.33	1382
1146.66	1442
1149.99	1362
1153.32	1364
1156.64	1352
1159.96	1398
1163.28	1400
1166.6	1412
1169.92	1376
1173.23	1396
1176.55	1348
1179.86	1374
1183.17	1408
1186.48	1398
1189.79	1384
1193.1	1382
1196.4	1420
1199.7	1378
1203	1412
1206.3	1366
1209.6	1420
1212.9	1368
1216.19	1370
1219.49	1386
1222.78	1394
1226.07	1392
1229.36	1428
1232.65	1396
1235.93	1402
1239.21	1356
1242.5	1392
1245.78	1390
1249.06	1380
1252.33	1372
1255.61	1422
1258.88	1426
1262.16	1390
1265.43	1392
1268.7	1390
1271.96	1380
1275.23	1372
1278.5	1390
1281.76	1415.94
1285.02	1444.25
1288.28	1433.7
1291.54	1401.07
1294.8	1453.96
1298.05	1404.1
1301.31	1440.56
1304.56	1426.17
1307.81	1389.78
1311.06	1390.33
1314.3	1425.06
1317.55	1426.84
1320.79	1434.44
1324.04	1411.63
1327.28	1400.96
1330.52	1382.24
1333.76	1396.45
1336.99	1405.45
1340.23	1393.96
1343.46	1392.06
1346.69	1406.58
1349.92	1391.98
1353.15	1398.55
1356.38	1416.15
1359.6	1413.68
1362.83	1413.02
1366.05	1400.44
1369.27	1409.28
1372.49	1390.56
1375.71	1399.16
1378.93	1417.35
1382.14	1414.1
1385.35	1403.84
1388.57	1423.27
1391.2	1414
1394.43	1390
1397.65	1368
1400.87	1362
1404.09	1400
1407.31	1364
1410.53	1382
1413.74	1388
1416.96	1412
1420.17	1368
1423.38	1366
1426.59	1386
1429.8	1384
1433.01	1350
1436.21	1358
1439.42	1384
1442.62	1380
1445.82	1370
1449.02	1340
1452.22	1386
1455.41	1344
1458.61	1396
1461.8	1378
1464.99	1370
1468.18	1420
1471.37	1352
1474.56	1396
1477.74	1370
1480.93	1472
1484.11	1356
1487.29	1378
1490.47	1374
1493.65	1424
1496.82	1370
1500	1420
1503.17	1362
1506.34	1376
1509.51	1366
1512.68	1358
1515.85	1390
1519.02	1382
1522.18	1384
1525.34	1374
1528.51	1364
1531.67	1392
1534.82	1396
1537.98	1344
1541.14	1330
1544.29	1376
1547.44	1338
1550.59	1318
1553.74	1334
1556.89	1324
1560.04	1388
1563.18	1364
1566.33	1326
1569.47	1322
1572.61	1364
1575.75	1310
1578.89	1368
1582.02	1356
1585.16	1366
1588.29	1362
1591.42	1354
1594.55	1318
1597.68	1360
1600.81	1362
1603.94	1378
1607.06	1338
1610.18	1328
1613.3	1320
1616.42	1336
1619.54	1320
1622.66	1330
1625.78	1314
1628.89	1280
1632	1306
1635.11	1320
1638.22	1310
1641.33	1320
1644.44	1306
1647.55	1312
1650.65	1314
1653.75	1318
1656.85	1330
1659.95	1286
1663.05	1258
1666.15	1276
1669.24	1302
1672.34	1290
1675.43	1236
1678.52	1250
1681.61	1286
1684.7	1280
1687.78	1240
1690.87	1216
1693.95	1282
1697.03	1248
1700.12	1286
1703.2	1240
1706.27	1254
1709.35	1264
1712.42	1208
1715.5	1216
1718.57	1200
1721.64	1254
1724.71	1212
1727.78	1232
1730.84	1242
1733.91	1216
1736.97	1182
1740.04	1216
1743.1	1240
1746.16	1234
1749.21	1232
1752.27	1192
1755.33	1238
1758.38	1166
1761.43	1224
1764.48	1220
1767.53	1220
1770.58	1214
1773.63	1206
1776.67	1188
1779.71	1224
1782.76	1198
1785.8	1202
1788.84	1224
1791.88	1180
1794.91	1186
1797.95	1212
1800.98	1218
1804.01	1210
1807.04	1240
1810.07	1198
1813.1	1190
1816.13	1182
1819.15	1208
1822.18	1160
1825.2	1170
1828.22	1196
1831.24	1174
1834.26	1142
1837.28	1210
1840.29	1164
1843.31	1174
1846.32	1172
1849.33	1202
1852.34	1152
1855.35	1144
1858.36	1154
1861.36	1130
1864.36	1174
1867.37	1160
1870.37	1146
1873.37	1136
1876.37	1142
1879.37	1182
1882.36	1174
1885.36	1168
1888.35	1134
1891.34	1142
1894.33	1152
1897.32	1130
1900.31	1158
1903.3	1124
1906.28	1120
1909.26	1076
1912.25	1158
1915.23	1160
1918.21	1088
1921.18	1136
1924.16	1110
1927.14	1076
1930.11	1116
1933.08	1138
1936.05	1108
1939.02	1072
1941.99	1132
1944.96	1154
1947.92	1074
1950.89	1120
1953.85	1152
1956.81	1102
1959.77	1070
1962.73	1102
1965.69	1094
1968.65	1146
1971.6	1106
1974.55	1058
1977.51	1098
1980.46	1136
1983.41	1104
1986.35	1076
1989.3	1120
1992.25	1078
1995.19	1110
1998.13	1082
2001.07	1058
2004.01	1092
2006.95	1108
2009.89	1080
2012.82	1086
2015.76	1074
2018.69	1082
2021.62	1074
2024.55	1074
2027.48	1088
2030.41	1076
2033.34	1048
2036.26	1064
2039.19	1070
2042.11	1050
2045.03	1040
2047.95	1070
2050.87	1048
2053.79	1048
2056.7	1058
2059.61	1066
2062.53	1028
2065.44	1048
2068.35	1020
2071.26	1084
2074.17	1028
2077.07	1052
2079.98	1020
2082.88	1028
2085.78	1010
2088.68	1074
2091.58	1050
2094.48	1028
2097.38	1066
2100.28	1042
2103.17	1018
2106.06	1018
2108.96	1014
2111.85	1040
2114.73	1004
2117.62	992
2120.51	1076
2123.39	1008
2126.28	1028
2129.16	1050
2132.04	1014
2134.92	1020
2137.8	1020
2140.68	1032
2143.55	972
2146.43	1038
2149.3	994
2152.17	986
2155.04	984
2157.91	956
2160.78	934
2163.65	992
2166.51	974
2169.38	980
2172.24	984
2175.1	970
2177.96	966
2180.82	946
2183.68	980
2186.53	974
2189.39	984
2192.24	958
2195.09	958
2197.95	950
2200.8	942
2203.64	978
2206.49	1002
2209.34	946
2212.18	950
2215.03	948
2217.87	894
2220.71	921.948
2223.55	929.867
2226.39	962.656
2229.22	932.913
2232.06	934.461
2234.89	937.61
2237.73	915.614
2240.56	931.14
2243.39	919.283
2246.22	966.543
2249.05	927.009
2251.87	941.36
2254.7	931.175
2257.52	925.857
2260.34	914.335
2263.17	939.284
2265.99	943.768
2268.8	911.489
2271.62	913.649
2274.44	926.208
2277.25	932.372
2280.07	935.511
2282.88	924.478
2285.69	939.396
2288.5	907.233
2291.31	909.181
2294.12	894.597
2296.92	905.946
2299.73	896
2302.53	904.446
2305.34	896.075
2308.14	893.937
2310.94	905.494
2313.74	892.309
2315.86	886
2318.67	896
2321.48	890
2324.29	924
2327.09	906
2329.9	898
2332.7	890
2335.51	886
2338.31	878
2341.11	906
2343.91	886
2346.71	906
2349.51	900
2352.3	902
2355.1	928
2357.89	896
2360.68	904
2363.48	896
2366.27	910
2369.05	872
2371.84	912
2374.63	860
2377.41	868
2380.2	862
2382.98	854
2385.76	854
2388.54	908
2391.32	852
2394.1	876
2396.87	862
2399.65	852
2402.42	898
2405.2	902
2407.97	890
2410.74	864
2413.51	886
2416.27	840
2419.04	858
2421.81	862
2424.57	852
2427.33	854
2430.1	888
2432.85	858
2435.61	870
2438.37	854
2441.13	870
2443.88	842
2446.64	846
2449.39	834
2452.14	884
2454.89	896
2457.64	832
2460.39	896
2463.14	822
2465.88	844
2468.63	872
2471.37	846
2474.11	830
2476.86	830
2479.59	864
2482.33	824
2485.07	832
2487.81	844
2490.54	828
2493.28	810
2496.01	818
2498.74	844
2501.47	812
2504.2	776
2506.93	784
2509.65	838
2512.38	808
2515.1	798
2517.82	766
2520.55	830
2523.27	826
2525.99	824
2528.7	840
2531.42	812
2534.14	798
2536.85	766
2539.56	812
2542.28	766
2544.99	790
2547.7	836
2550.4	804
2553.11	788
2555.82	766
2558.52	822
2561.23	804
2563.93	786
2566.63	788
2569.33	806
2572.03	756
2574.73	792
2577.42	816
2580.12	798
2582.81	788
2585.51	778
2588.2	804
2590.89	754
2593.58	780
2596.26	748
2598.95	766
2601.64	780
2604.32	792
2607.01	796
2609.69	768
2612.37	768
2615.05	778
2617.73	760
2620.41	796
2623.08	750
2625.76	812
2628.43	768
2631.1	704
2633.78	742
2636.45	742
2639.12	752
2641.78	756
2644.45	750
2647.12	742
2649.78	748
2652.45	722
2655.11	746
2657.77	738
2660.43	736
2663.09	724
2665.75	724
2668.4	780
2671.06	744
2673.71	708
2676.37	738
2679.02	724
2681.67	740
2684.32	698
2686.97	730
2689.61	734
2692.26	722
2694.9	712
2697.55	746
2700.19	698
2702.83	700
2705.47	716
2708.11	718
2710.75	712
2713.39	690
2716.02	738
2718.66	748
2721.29	692
2723.92	704
2726.55	682
2729.18	680
2731.81	742
2734.44	690
2737.07	712
2739.69	680
2742.32	696
2744.94	694
2747.56	698
2750.18	712
2752.8	682
2755.42	660
2758.04	716
2760.65	676
2763.27	710
2765.88	700
2768.5	674
2771.11	684
2773.72	692
2776.33	690
2778.94	696
2781.54	686
2784.15	652
2786.75	644
2789.36	664
2791.96	680
2794.56	668
2797.16	662
2799.76	658
2802.36	696
2804.96	676
2807.55	670
2810.15	670
2812.74	666
2815.33	674
2817.93	670
2820.52	668
2823.11	656
2825.69	610
2828.28	662
2830.87	678
2833.45	650
2836.03	670
2838.62	640
2841.2	612
2843.78	610
2846.36	636
2848.93	624
2851.51	630
2854.09	622
2856.66	666
2859.24	616
2861.81	626
2864.38	648
2866.95	626
2869.52	634
2872.09	644
2874.65	580
2877.22	624
2879.78	608
2882.35	608
2884.91	616
2887.47	588
2890.03	616
2892.59	600
2895.15	606
2897.7	610
2900.26	582
2902.81	616
2905.37	596
2907.92	612
2910.47	580
2913.02	602
2915.57	582
2918.12	620
2920.66	594
2923.21	618
2925.75	584
2928.3	572
2930.84	616
2933.38	572
2935.92	592
2938.46	580
2941	554
2943.54	592
2946.07	602
2948.61	544
2951.14	584
2953.67	582
2956.21	570
2958.74	580
2961.27	574
2963.79	570
2966.32	570
2968.85	544
2971.37	570
2973.9	580
2976.42	572
2978.94	558
2981.46	566
2983.98	566
2986.5	580
2989.02	542
2991.53	542
2994.05	560
2996.56	548
2999.08	550
3001.59	574
3004.1	516
3006.61	532
3009.12	542
3011.63	540
3014.13	510
3016.64	548
3019.14	524
3021.65	518
3024.15	538
3026.65	528
3029.15	514
3031.65	536
3034.15	530
3036.64	554
3039.14	528
3041.63	557.403
3044.13	525.39
3046.62	551.687
3049.11	520.677
3051.6	534.708
3054.09	529.208
3056.58	510.516
3059.07	517.091
3061.55	531.919
3064.04	523.643
3066.52	508.243
3069.01	501.51
3071.49	518.508
3073.97	521.3
3076.45	517.348
3078.93	512.747
3081.41	480.96
3083.88	514.398
3086.36	480.644
3088.83	503.95
3091.31	494.556
3093.78	503.902
3096.25	478.345
3098.72	472.113
3101.19	477.199
3103.66	475.763
3106.13	490.364
3108.59	479.29
3111.06	488.702
3113.52	469.944
3115.98	491.299
3118.45	482.129
3120.91	461.149
3123.37	462.497
3125.38	446
3127.85	474
3130.32	460
3132.79	474
3135.26	446
3137.73	434
3140.19	458
3142.66	464
3145.13	450
3147.59	492
3150.05	478
3152.51	484
3154.97	452
3157.43	450
3159.89	456
3162.35	448
3164.8	452
3167.26	430
3169.71	430
3172.17	426
3174.62	446
3177.07	442
3179.52	446
3181.97	440
3184.41	450
3186.86	448
3189.31	442
3191.75	430
3194.2	414
3196.64	436
3199.08	436
3201.52	428
3203.96	432
3206.4	458
3208.84	420
3211.27	430
3213.71	416
3216.14	444
3218.58	398
3221.01	428
3223.44	424
3225.87	420
3228.3	422
3230.73	412
3233.16	424
3235.58	416
3238.01	422
3240.43	416
3242.86	424
3245.28	414
3247.7	430
3250.12	424
3252.54	418
3254.96	408
3257.38	410
3259.79	396
3262.21	418
3264.62	410
3267.04	388
3269.45	406
3271.86	400
3274.27	416
3276.68	386
3279.09	400
3281.49	392
3283.9	402
3286.31	390
3288.71	390
3291.11	400
3293.51	370
3295.92	410
3298.32	390
3300.72	388
3303.11	400
3305.51	400
3307.91	398
3310.3	366
3312.7	376
3315.09	384
3317.48	382
3319.87	398
3322.26	418
3324.65	398
3327.04	386
3329.43	372
3331.81	376
3334.2	404
3336.58	392
3338.97	378
3341.35	366
3343.73	396
3346.11	382
3348.49	388
3350.87	374
3353.25	380
3355.62	384
3358	384
3360.37	386
3362.75	382
3365.12	380
3367.49	390
3369.86	372
3372.23	372
3374.6	366
3376.97	390
3379.33	360
3381.7	392
3384.06	354
3386.43	362
3388.79	360
3391.15	380
3393.51	352
3395.87	386
3398.23	370
3400.59	366
3402.94	374
3405.3	362
3407.65	378
3410.01	354
3412.36	368
3414.71	360
3417.06	362
3419.41	340
3421.76	372
3424.11	346
3426.46	352
3428.8	346
3431.15	358
3433.49	374
3435.83	332
3438.18	354
3440.52	346
3442.86	346
3445.2	342
3447.53	344
3449.87	350
3452.21	348
3454.54	332
3456.88	340
3459.21	348
3461.54	354
3463.88	334
3466.21	340
3468.53	356
3470.86	350
3473.19	326
3475.52	348
3477.84	338
3480.17	322
3482.49	340
3484.82	318
3487.14	346
3489.46	326
3491.78	342
3494.1	324
3496.42	338
3498.73	342
3501.05	294
3503.36	320
3505.68	318
3507.99	346
3510.3	348
3512.61	334
3514.92	350
3517.23	328
3519.54	328
3521.85	310
3524.16	342
3526.46	322
3528.77	326
3531.07	330
3533.37	330
3535.68	326
3537.98	292
3540.28	322
3542.58	306
3544.87	300
3547.17	310
3549.47	328
3551.76	322
3554.06	320
3556.35	324
3558.64	300
3560.93	316
3563.22	314
3565.51	324
3567.8	338
3570.09	342
3572.38	280
3574.66	298
3576.95	332
3579.23	272
3581.51	286
3583.8	320
3586.08	304
3588.36	306
3590.64	286
3592.92	302
3595.19	318
3597.47	306
3599.75	290
3602.02	312
3604.29	296
3606.57	308
3608.84	282
3611.11	322
3613.38	316
3615.65	320
3617.92	314
3620.18	306
3622.45	298
3624.71	300
3626.98	304
3629.24	280
3631.5	296
3633.77	294
3636.03	280
3638.29	296
3640.55	300
3642.8	300
3645.06	280
3647.32	294
3649.57	314
3651.83	276
3654.08	294
3656.33	292
3658.58	282
3660.83	294
3663.08	290
3665.33	282
3667.58	292
3669.83	274
3672.07	276
3674.32	264
3676.56	306
3678.8	304
3681.05	292
3683.29	314
3685.53	288
3687.77	278
3690.01	300
3692.24	278
3694.48	292
3696.72	288
3698.95	292
3701.19	282
3703.42	288
3705.65	262
3707.88	278
3710.11	264
3712.34	288
3714.57	266
3716.8	266
3719.03	290
3721.25	286
3723.48	282
3725.7	276
3727.92	288
3730.15	274
3732.37	282
3734.59	268
3736.81	284
3739.03	278
3741.24	260
3743.46	282
3745.68	254
3747.89	268
3750.11	272
3752.32	278
3754.53	270
3756.74	286
3758.95	286
3761.16	262
3763.37	260.039
3765.58	279.612
3767.79	258.41
3769.99	273.239
3772.2	268.894
3774.4	272.075
3776.61	261.235
3778.81	257.862
3781.01	259.049
3783.21	262.77
3785.41	258.912
3787.61	255.641
3789.81	274.602
3792	262.194
3794.2	263.472
3796.4	252.114
3798.59	262.947
3800.78	260.008
3802.98	268.551
3805.17	263.708
3807.36	263.839
3809.55	260.684
3811.74	265.418
3813.93	266.355
3816.11	251.84
3818.3	257.306
3820.49	247.106
3822.67	265.589
3824.85	256.84
3827.04	259.674
3829.22	246.195
3831.4	251.535
3833.58	260.437
3835.76	270.703
3837.94	237.533
3839.98	238
3842.17	246
3844.36	254
3846.55	254
3848.73	248
3850.92	262
3853.1	264
3855.29	268
3857.47	270
3859.65	254
3861.84	248
3864.02	256
3866.2	272
3868.38	264
3870.55	230
3872.73	250
3874.91	244
3877.08	244
3879.26	254
3881.43	222
3883.6	252
3885.78	240
3887.95	264
3890.12	264
3892.29	254
3894.46	216
3896.63	262
3898.79	252
3900.96	252
3903.12	240
3905.29	226
3907.45	252
3909.61	240
3911.78	248
3913.94	236
3916.1	256
3918.26	258
3920.41	242
3922.57	250
3924.73	250
3926.88	228
3929.04	232
3931.19	240
3933.35	240
3935.5	242
3937.65	222
3939.8	228
3941.95	218
3944.1	208
3946.25	250
3948.4	218
3950.54	220
3952.69	234
3954.83	236
3956.98	230
3959.12	232
3961.26	234
3963.4	224
3965.54	224
3967.68	246
3969.82	224
3971.96	240
3974.1	218
3976.23	228
3978.37	222
3980.5	232
3982.64	212
3984.77	244
3986.9	232
3989.03	220
3991.16	228
3993.29	222
3995.42	226
3997.55	230
3999.67	218