File: muestras/mosquito/OR_14.txt
#Acq. time (s)=	10
#Accumulations=	1
#Range (cm-¹)=	200...4000
#Windows=	5
#Autofocus=	Off
#AutoExposure=	Off
#Spike filter=	Off
#Delay time (s)=	0
#Binning=	1
#Readout mode=	Signal
#DeNoise=	Off
#ICS correction=	Off
#Dark correction=	Off
#Inst. Process=	Off
#Instrument=	LabRAM HR Evol
#Detector=	Syncerity OE
#Objective=	x100_VIS
#Grating=	600 (500nm)
#ND Filter=	25%
#Laser=	633nm_Edge
#Hole=	100.021
#Range=	Visible
#Project=	Omar
#Sample=	03-07-23
#Site=	1
#Title=	OR
#Remark=
#Date=	03.07.2023 13:49
#Acquired=	03.07.2023 13:49:07
200.404	772
204.205	798
208.003	798
211.799	798
215.595	810
219.387	792
223.177	804
226.966	816
230.752	794
234.536	820
238.319	770
242.1	848
245.879	790
249.655	830
253.431	844
257.204	804
260.976	850
264.744	808
268.511	826
272.276	838
276.04	832
279.801	798
283.561	840
287.318	840
291.074	854
294.828	866
298.581	846
302.33	866
306.079	854
309.825	846
313.569	868
317.311	844
321.052	894
324.79	864
328.527	836
332.261	882
335.994	874
339.725	856
343.454	918
347.182	908
350.907	896
354.631	870
358.352	906
362.072	888
365.789	894
369.505	910
373.219	894
376.93	854
380.642	858
384.35	870
388.056	872
391.76	884
395.463	892
399.164	910
402.863	906
406.559	906
410.254	904
413.948	904
417.639	952
421.329	976
425.016	960
428.701	946
432.386	930
436.068	972
439.748	924
443.426	938
447.103	972
450.777	946
454.45	986
458.121	944
461.789	962
465.457	928
469.122	968
472.786	936
476.447	942
480.107	982
483.765	960
487.421	974
491.075	986
494.727	980
498.377	1006
502.026	972
505.673	958
509.318	970
512.962	966
516.602	1012
520.242	976
523.881	1004
527.516	968
531.149	970
534.783	978
538.413	1022
542.041	974
545.667	974
549.292	990
552.915	960
556.537	1028
560.156	992
563.773	992
567.389	1026
571.004	984
574.615	978
578.226	986
581.834	1024
585.44	974
589.045	1018
592.649	1024
596.25	1006
599.85	1026
603.448	990
607.042	1004
610.637	1068
614.229	1018
617.819	988
621.408	1018
624.994	1018
628.58	1008
632.163	1038
635.744	1008
639.324	1092
642.902	1024
646.478	1062
650.052	1092
653.625	1056
657.196	1068
660.764	1076
664.331	1070
667.897	1062
671.46	1084
675.021	1032
678.582	1088
682.14	1090
685.696	1056
689.252	1110
692.804	1050
696.355	1064
699.905	1066
703.451	1108
706.997	1086
710.542	1100
714.083	1090
717.624	1088
721.162	1084
724.7	1106
728.235	1086
731.768	1092
735.301	1094
738.83	1096
742.358	1082
745.885	1080
749.41	1114
752.931	1146
756.453	1120
759.973	1110
763.49	1084
767.006	1092
770.52	1132
774.033	1116
777.543	1076
781.052	1124
784.559	1076
788.064	1082
791.568	1090
795.07	1108
798.57	1108
802.068	1128
805.565	1112
809.061	1078
812.553	1124
816.045	1116
819.535	1150
823.022	1110
826.508	1170
829.993	1172
833.476	1150
836.957	1162
840.436	1146
843.914	1146
847.391	1186
850.864	1120
854.337	1144
857.807	1176
861.277	1150
864.744	1240
868.209	1180
871.674	1204
875.136	1198
878.597	1188
882.056	1196
885.512	1122
888.967	1192
892.421	1138
895.874	1138
899.323	1164
902.771	1172
906.219	1190
909.664	1152
913.107	1164
916.55	1170
919.99	1142
923.428	1178
926.863	1184
930.299	1182
933.732	1220
937.164	1244
940.593	1182
944.022	1178
947.448	1186
950.874	1210
954.296	1210
957.718	1180
961.137	1176
964.555	1210
967.972	1182
971.387	1246
974.8	1234
978.21	1236
981.62	1210
985.029	1232
988.435	1200
991.839	1214
995.243	1246
998.644	1240
1002.04	1216
1005.44	1244
1008.84	1216
1012.23	1208
1015.63	1232
1019.02	1198
1022.41	1216
1025.79	1252
1029.18	1242
1032.56	1206
1035.95	1260
1039.33	1236
1042.71	1248
1046.09	1254
1049.46	1256
1052.84	1258
1056.21	1220
1059.58	1248
1062.95	1268
1066.32	1292
1069.69	1228
1073.05	1252
1076.41	1236
1079.78	1278
1083.14	1282
1086.49	1274
1089.85	1246
1093.21	1272
1096.56	1258
1099.91	1254
1103.26	1246
1106.61	1272
1109.96	1220
1113.3	1242
1116.64	1262
1119.99	1260
1123.33	1270
1126.66	1238
1130	1258
1133.34	1220
1136.67	1306
1140	1266
1143.33	1292
1146.66	1246
1149.99	1280
1153.32	1254
1156.64	1284
1159.96	1342
1163.28	1258
1166.6	1258
1169.92	1302
1173.23	1326
1176.55	1308
1179.86	1332
1183.17	1274
1186.48	1256
1189.79	1286
1193.1	1250
1196.4	1242
1199.7	1270
1203	1260
1206.3	1282
1209.6	1248
1212.9	1262
1216.19	1300
1219.49	1250
1222.78	1246
1226.07	1284
1229.36	1274
1232.65	1284
1235.93	1266
1239.21	1236
1242.5	1248
1245.78	1284
1249.06	1312
1252.33	1228
1255.61	1268
1258.88	1248
1262.16	1304
1265.43	1250
1268.7	1306
1271.96	1302
1275.23	1284
1278.5	1278
1281.76	1295.17
1285.02	1282.52
1288.28	1299.91
1291.54	1285.09
1294.8	1281.5
1298.05	1331.42
1301.31	1320.77
1304.56	1272.76
1307.81	1306.5
1311.06	1303.61
1314.3	1281.04
1317.55	1260.25
1320.79	1298.57
1324.04	1267.9
1327.28	1317.14
1330.52	1321.31
1333.76	1293.49
1336.99	1293.75
1340.23	1282.89
1343.46	1292.79
1346.69	1277.18
1349.92	1276.2
1353.15	1306.17
1356.38	1271.58
1359.6	1295.73
1362.83	1284.45
1366.05	1292.45
1369.27	1286.1
1372.49	1284.21
1375.71	1286.7
1378.93	1253.03
1382.14	1277.72
1385.35	1289.33
1388.57	1269.58
1391.2	1276
1394.43	1252
1397.65	1256
1400.87	1230
1404.09	1264
1407.31	1252
1410.53	1292
1413.74	1316
1416.96	1242
1420.17	1278
1423.38	1264
1426.59	1216
1429.8	1246
1433.01	1246
1436.21	1224
1439.42	1264
1442.62	1262
1445.82	1262
1449.02	1238
1452.22	1242
1455.41	1190
1458.61	1218
1461.8	1258
1464.99	1266
1468.18	1296
1471.37	1280
1474.56	1286
1477.74	1242
1480.93	1266
1484.11	1274
1487.29	1282
1490.47	1230
1493.65	1302
1496.82	1258
1500	1272
1503.17	1258
1506.34	1282
1509.51	1236
1512.68	1250
1515.85	1254
1519.02	1264
1522.18	1264
1525.34	1244
1528.51	1248
1531.67	1222
1534.82	1254
1537.98	1240
1541.14	1218
1544.29	1270
1547.44	1216
1550.59	1218
1553.74	1236
1556.89	1198
1560.04	1254
1563.18	1230
1566.33	1204
1569.47	1214
1572.61	1250
1575.75	1232
1578.89	1178
1582.02	1244
1585.16	1246
1588.29	1196
1591.42	1230
1594.55	1230
1597.68	1190
1600.81	1240
1603.94	1226
1607.06	1232
1610.18	1222
1613.3	1200
1616.42	1222
1619.54	1174
1622.66	1210
1625.78	1190
1628.89	1198
1632	1226
1635.11	1160
1638.22	1204
1641.33	1196
1644.44	1208
1647.55	1158
1650.65	1186
1653.75	1160
1656.85	1206
1659.95	1120
1663.05	1176
1666.15	1122
1669.24	1118
1672.34	1150
1675.43	1156
1678.52	1114
1681.61	1106
1684.7	1134
1687.78	1094
1690.87	1142
1693.95	1110
1697.03	1148
1700.12	1092
1703.2	1090
1706.27	1052
1709.35	1150
1712.42	1090
1715.5	1098
1718.57	1074
1721.64	1088
1724.71	1102
1727.78	1122
1730.84	1072
1733.91	1082
1736.97	1094
1740.04	1056
1743.1	1100
1746.16	1082
1749.21	1090
1752.27	1102
1755.33	1052
1758.38	1070
1761.43	1060
1764.48	1088
1767.53	1072
1770.58	1112
1773.63	1086
1776.67	1074
1779.71	1078
1782.76	1100
1785.8	1102
1788.84	1070
1791.88	1066
1794.91	1056
1797.95	1074
1800.98	1050
1804.01	1078
1807.04	1076
1810.07	1068
1813.1	1046
1816.13	1008
1819.15	1060
1822.18	1052
1825.2	992
1828.22	1046
1831.24	1054
1834.26	1048
1837.28	1084
1840.29	1050
1843.31	1016
1846.32	1052
1849.33	1052
1852.34	1064
1855.35	1012
1858.36	1028
1861.36	1032
1864.36	1022
1867.37	1006
1870.37	978
1873.37	996
1876.37	1016
1879.37	1014
1882.36	986
1885.36	1006
1888.35	1010
1891.34	1024
1894.33	1036
1897.32	1026
1900.31	1038
1903.3	938
1906.28	990
1909.26	992
1912.25	978
1915.23	976
1918.21	978
1921.18	988
1924.16	1008
1927.14	962
1930.11	976
1933.08	994
1936.05	940
1939.02	1008
1941.99	966
1944.96	992
1947.92	1010
1950.89	964
1953.85	960
1956.81	1026
1959.77	970
1962.73	978
1965.69	966
1968.65	964
1971.6	952
1974.55	978
1977.51	1014
1980.46	942
1983.41	1002
1986.35	982
1989.3	962
1992.25	946
1995.19	978
1998.13	904
2001.07	974
2004.01	980
2006.95	956
2009.89	926
2012.82	944
2015.76	926
2018.69	958
2021.62	966
2024.55	966
2027.48	932
2030.41	942
2033.34	910
2036.26	942
2039.19	928
2042.11	952
2045.03	920
2047.95	898
2050.87	920
2053.79	920
2056.7	896
2059.61	922
2062.53	926
2065.44	934
2068.35	950
2071.26	922
2074.17	914
2077.07	906
2079.98	920
2082.88	926
2085.78	936
2088.68	906
2091.58	922
2094.48	900
2097.38	908
2100.28	880
2103.17	908
2106.06	864
2108.96	856
2111.85	844
2114.73	916
2117.62	892
2120.51	886
2123.39	858
2126.28	846
2129.16	884
2132.04	858
2134.92	868
2137.8	894
2140.68	886
2143.55	872
2146.43	842
2149.3	864
2152.17	918
2155.04	868
2157.91	872
2160.78	882
2163.65	872
2166.51	876
2169.38	844
2172.24	848
2175.1	882
2177.96	818
2180.82	858
2183.68	864
2186.53	870
2189.39	830
2192.24	838
2195.09	858
2197.95	824
2200.8	816
2203.64	852
2206.49	836
2209.34	818
2212.18	810
2215.03	850
2217.87	814
2220.71	823.71
2223.55	812.067
2226.39	852.372
2229.22	812.589
2232.06	837.537
2234.89	811.989
2237.73	826.863
2240.56	837.584
2243.39	801.159
2246.22	790.121
2249.05	806.377
2251.87	816.603
2254.7	814.984
2257.52	822.526
2260.34	815.599
2263.17	811.441
2265.99	812.971
2268.8	816.867
2271.62	793.963
2274.44	792.842
2277.25	787.111
2280.07	802.15
2282.88	822.122
2285.69	796.675
2288.5	796.939
2291.31	801.243
2294.12	798.893
2296.92	822.486
2299.73	792.147
2302.53	794.318
2305.34	787.922
2308.14	809.419
2310.94	789.621
2313.74	802.19
2315.86	806
2318.67	806
2321.48	774
2324.29	802
2327.09	774
2329.9	782
2332.7	784
2335.51	772
2338.31	766
2341.11	786
2343.91	778
2346.71	758
2349.51	766
2352.3	778
2355.1	774
2357.89	810
2360.68	772
2363.48	784
2366.27	776
2369.05	754
2371.84	752
2374.63	764
2377.41	766
2380.2	752
2382.98	750
2385.76	766
2388.54	758
2391.32	778
2394.1	738
2396.87	792
2399.65	768
2402.42	770
2405.2	774
2407.97	742
2410.74	752
2413.51	774
2416.27	782
2419.04	708
2421.81	770
2424.57	724
2427.33	720
2430.1	710
2432.85	740
2435.61	750
2438.37	706
2441.13	696
2443.88	754
2446.64	758
2449.39	772
2452.14	746
2454.89	748
2457.64	730
2460.39	772
2463.14	748
2465.88	716
2468.63	728
2471.37	696
2474.11	720
2476.86	702
2479.59	740
2482.33	700
2485.07	720
2487.81	724
2490.54	724
2493.28	704
2496.01	730
2498.74	738
2501.47	738
2504.2	756
2506.93	694
2509.65	722
2512.38	720
2515.1	690
2517.82	726
2520.55	690
2523.27	706
2525.99	694
2528.7	708
2531.42	712
2534.14	722
2536.85	686
2539.56	708
2542.28	716
2544.99	722
2547.7	688
2550.4	698
2553.11	694
2555.82	674
2558.52	698
2561.23	676
2563.93	662
2566.63	672
2569.33	676
2572.03	718
2574.73	702
2577.42	668
2580.12	668
2582.81	672
2585.51	700
2588.2	676
2590.89	674
2593.58	684
2596.26	656
2598.95	660
2601.64	680
2604.32	640
2607.01	686
2609.69	656
2612.37	716
2615.05	678
2617.73	656
2620.41	654
2623.08	670
2625.76	680
2628.43	666
2631.1	622
2633.78	644
2636.45	660
2639.12	672
2641.78	644
2644.45	662
2647.12	664
2649.78	642
2652.45	668
2655.11	658
2657.77	648
2660.43	616
2663.09	650
2665.75	608
2668.4	648
2671.06	626
2673.71	682
2676.37	634
2679.02	642
2681.67	604
2684.32	644
2686.97	632
2689.61	634
2692.26	612
2694.9	648
2697.55	624
2700.19	620
2702.83	618
2705.47	606
2708.11	608
2710.75	640
2713.39	596
2716.02	620
2718.66	638
2721.29	606
2723.92	570
2726.55	632
2729.18	616
2731.81	624
2734.44	570
2737.07	614
2739.69	592
2742.32	586
2744.94	582
2747.56	620
2750.18	576
2752.8	560
2755.42	616
2758.04	592
2760.65	570
2763.27	586
2765.88	588
2768.5	582
2771.11	594
2773.72	594
2776.33	594
2778.94	584
2781.54	570
2784.15	562
2786.75	590
2789.36	584
2791.96	590
2794.56	554
2797.16	568
2799.76	602
2802.36	570
2804.96	546
2807.55	588
2810.15	566
2812.74	562
2815.33	556
2817.93	552
2820.52	560
2823.11	570
2825.69	546
2828.28	570
2830.87	558
2833.45	558
2836.03	520
2838.62	544
2841.2	538
2843.78	568
2846.36	552
2848.93	546
2851.51	466
2854.09	538
2856.66	546
2859.24	540
2861.81	540
2864.38	538
2866.95	548
2869.52	512
2872.09	530
2874.65	550
2877.22	518
2879.78	520
2882.35	522
2884.91	534
2887.47	512
2890.03	508
2892.59	522
2895.15	512
2897.7	496
2900.26	498
2902.81	522
2905.37	544
2907.92	520
2910.47	534
2913.02	522
2915.57	508
2918.12	516
2920.66	510
2923.21	508
2925.75	508
2928.3	538
2930.84	500
2933.38	526
2935.92	504
2938.46	536
2941	482
2943.54	490
2946.07	518
2948.61	498
2951.14	512
2953.67	482
2956.21	492
2958.74	518
2961.27	512
2963.79	478
2966.32	478
2968.85	508
2971.37	486
2973.9	496
2976.42	484
2978.94	474
2981.46	488
2983.98	490
2986.5	512
2989.02	470
2991.53	468
2994.05	482
2996.56	482
2999.08	456
3001.59	494
3004.1	468
3006.61	448
3009.12	450
3011.63	486
3014.13	456
3016.64	480
3019.14	452
3021.65	454
3024.15	464
3026.65	466
3029.15	464
3031.65	490
3034.15	464
3036.64	456
3039.14	460
3041.63	465.53
3044.13	443.527
3046.62	456.987
3049.11	449.5
3051.6	433.221
3054.09	433.399
3056.58	426.45
3059.07	438.72
3061.55	425.822
3064.04	448.262
3066.52	427.686
3069.01	428.193
3071.49	430.587
3073.97	427.96
3076.45	451.613
3078.93	429.072
3081.41	422.225
3083.88	435.952
3086.36	409.69
3088.83	422.271
3091.31	433.675
3093.78	425.927
3096.25	421.078
3098.72	426.021
3101.19	410.013
3103.66	420.484
3106.13	413.563
3108.59	399.427
3111.06	404.452
3113.52	406.745
3115.98	408.911
3118.45	411.487
3120.91	428.672
3123.37	389.642
3125.38	366
3127.85	378
3130.32	398
3132.79	382
3135.26	386
3137.73	394
3140.19	388
3142.66	368
3145.13	398
3147.59	384
3150.05	362
3152.51	386
3154.97	384
3157.43	402
3159.89	394
3162.35	390
3164.8	388
3167.26	376
3169.71	374
3172.17	376
3174.62	370
3177.07	388
3179.52	362
3181.97	366
3184.41	354
3186.86	380
3189.31	366
3191.75	402
3194.2	382
3196.64	388
3199.08	388
3201.52	370
3203.96	364
3206.4	370
3208.84	366
3211.27	368
3213.71	368
3216.14	382
3218.58	358
3221.01	382
3223.44	374
3225.87	366
3228.3	372
3230.73	348
3233.16	370
3235.58	374
3238.01	358
3240.43	376
3242.86	366
3245.28	356
3247.7	370
3250.12	356
3252.54	366
3254.96	364
3257.38	388
3259.79	356
3262.21	348
3264.62	342
3267.04	362
3269.45	354
3271.86	340
3274.27	356
3276.68	334
3279.09	340
3281.49	360
3283.9	332
3286.31	340
3288.71	354
3291.11	352
3293.51	330
3295.92	342
3298.32	328
3300.72	336
3303.11	338
3305.51	344
3307.91	342
3310.3	318
3312.7	350
3315.09	336
3317.48	342
3319.87	332
3322.26	328
3324.65	340
3327.04	326
3329.43	320
3331.81	330
3334.2	312
3336.58	338
3338.97	322
3341.35	358
3343.73	350
3346.11	332
3348.49	332
3350.87	314
3353.25	320
3355.62	350
3358	326
3360.37	332
3362.75	324
3365.12	310
3367.49	326
3369.86	300
3372.23	302
3374.6	322
3376.97	318
3379.33	334
3381.7	328
3384.06	326
3386.43	302
3388.79	302
3391.15	298
3393.51	304
3395.87	320
3398.23	292
3400.59	300
3402.94	296
3405.3	332
3407.65	316
3410.01	308
3412.36	314
3414.71	292
3417.06	310
3419.41	308
3421.76	312
3424.11	312
3426.46	318
3428.8	304
3431.15	314
3433.49	290
3435.83	312
3438.18	318
3440.52	320
3442.86	296
3445.2	302
3447.53	280
3449.87	304
3452.21	296
3454.54	286
3456.88	278
3459.21	272
3461.54	292
3463.88	302
3466.21	294
3468.53	282
3470.86	294
3473.19	272
3475.52	286
3477.84	276
3480.17	282
3482.49	290
3484.82	294
3487.14	276
3489.46	274
3491.78	282
3494.1	284
3496.42	278
3498.73	286
3501.05	282
3503.36	272
3505.68	282
3507.99	272
3510.3	288
3512.61	264
3514.92	280
3517.23	286
3519.54	280
3521.85	294
3524.16	282
3526.46	274
3528.77	282
3531.07	278
3533.37	270
3535.68	272
3537.98	276
3540.28	270
3542.58	272
3544.87	274
3547.17	276
3549.47	268
3551.76	272
3554.06	264
3556.35	280
3558.64	270
3560.93	266
3563.22	244
3565.51	278
3567.8	268
3570.09	262
3572.38	244
3574.66	260
3576.95	262
3579.23	266
3581.51	268
3583.8	258
3586.08	244
3588.36	270
3590.64	252
3592.92	256
3595.19	272
3597.47	258
3599.75	256
3602.02	260
3604.29	262
3606.57	256
3608.84	266
3611.11	242
3613.38	254
3615.65	258
3617.92	246
3620.18	256
3622.45	244
3624.71	236
3626.98	226
3629.24	248
3631.5	270
3633.77	242
3636.03	240
3638.29	238
3640.55	234
3642.8	244
3645.06	256
3647.32	268
3649.57	244
3651.83	254
3654.08	254
3656.33	246
3658.58	234
3660.83	236
3663.08	246
3665.33	242
3667.58	254
3669.83	230
3672.07	246
3674.32	244
3676.56	256
3678.8	1050
3681.05	870
3683.29	934
3685.53	262
3687.77	248
3690.01	254
3692.24	256
3694.48	230
3696.72	246
3698.95	238
3701.19	228
3703.42	234
3705.65	236
3707.88	240
3710.11	242
3712.34	234
3714.57	240
3716.8	224
3719.03	224
3721.25	228
3723.48	236
3725.7	222
3727.92	246
3730.15	228
3732.37	250
3734.59	210
3736.81	206
3739.03	228
3741.24	232
3743.46	238
3745.68	228
3747.89	248
3750.11	216
3752.32	220
3754.53	210
3756.74	204
3758.95	240
3761.16	242
3763.37	212.136
3765.58	222
3767.79	217.04
3769.99	232.135
3772.2	218.904
3774.4	213.995
3776.61	216.041
3778.81	218.643
3781.01	232.826
3783.21	225.045
3785.41	215.947
3787.61	208.963
3789.81	215.533
3792	228.174
3794.2	218.647
3796.4	223.009
3798.59	216.176
3800.78	222.529
3802.98	230.61
3805.17	228.482
3807.36	228.825
3809.55	210.767
3811.74	219.394
3813.93	222.602
3816.11	220.369
3818.3	213.466
3820.49	214.2
3822.67	224.601
3824.85	220.787
3827.04	215.421
3829.22	220.681
3831.4	216.79
3833.58	214.679
3835.76	222.22
3837.94	196.181
3839.98	220
3842.17	208
3844.36	210
3846.55	214
3848.73	214
3850.92	202
3853.1	222
3855.29	210
3857.47	210
3859.65	212
3861.84	194
3864.02	210
3866.2	234
3868.38	196
3870.55	212
3872.73	222
3874.91	202
3877.08	216
3879.26	210
3881.43	204
3883.6	212
3885.78	212
3887.95	200
3890.12	192
3892.29	194
3894.46	204
3896.63	212
3898.79	210
3900.96	196
3903.12	228
3905.29	206
3907.45	216
3909.61	192
3911.78	214
3913.94	202
3916.1	202
3918.26	194
3920.41	186
3922.57	216
3924.73	182
3926.88	200
3929.04	216
3931.19	196
3933.35	202
3935.5	200
3937.65	208
3939.8	188
3941.95	222
3944.1	204
3946.25	198
3948.4	212
3950.54	192
3952.69	194
3954.83	180
3956.98	200
3959.12	184
3961.26	188
3963.4	188
3965.54	204
3967.68	206
3969.82	192
3971.96	196
3974.1	192
3976.23	184
3978.37	186
3980.5	190
3982.64	194
3984.77	196
3986.9	202
3989.03	182
3991.16	188
3993.29	184
3995.42	174
3997.55	194
3999.67	200