File: muestras/mosquito/OR_13.txt
#Acq. time (s)=	10
#Accumulations=	1
#Range (cm-¹)=	200...4000
#Windows=	5
#Autofocus=	Off
#AutoExposure=	Off
#Spike filter=	Off
#Delay time (s)=	0
#Binning=	1
#Readout mode=	Signal
#DeNoise=	Off
#ICS correction=	Off
#Dark correction=	Off
#Inst. Process=	Off
#Instrument=	LabRAM HR Evol
#Detector=	Syncerity OE
#Objective=	x100_VIS
#Grating=	600 (500nm)
#ND Filter=	25%
#Laser=	633nm_Edge
#Hole=	100.021
#Range=	Visible
#Project=	Omar
#Sample=	03-07-23
#Site=	1
#Title=	OR
#Remark=
#Date=	03.07.2023 13:47
#Acquired=	03.07.2023 13:47:25
200.404	760
204.205	724
208.003	724
211.799	730
215.595	754
219.387	712
223.177	762
226.966	750
230.752	730
234.536	778
238.319	754
242.1	768
245.879	740
249.655	742
253.431	748
257.204	744
260.976	732
264.744	772
268.511	792
272.276	758
276.04	772
279.801	738
283.561	790
287.318	766
291.074	762
294.828	792
298.581	800
302.33	792
306.079	774
309.825	838
313.569	794
317.311	780
321.052	790
324.79	792
328.527	772
332.261	816
335.994	788
339.725	798
343.454	820
347.182	806
350.907	798
354.631	846
358.352	792
362.072	844
365.789	838
369.505	814
373.219	836
376.93	854
380.642	816
384.35	822
388.056	840
391.76	824
395.463	814
399.164	830
402.863	838
406.559	832
410.254	836
413.948	856
417.639	904
421.329	874
425.016	870
428.701	868
432.386	854
436.068	922
439.748	876
443.426	926
447.103	916
450.777	892
454.45	868
458.121	878
461.789	870
465.457	864
469.122	900
472.786	898
476.447	874
480.107	892
483.765	932
487.421	904
491.075	936
494.727	944
498.377	892
502.026	940
505.673	904
509.318	924
512.962	918
516.602	902
520.242	922
523.881	906
527.516	880
531.149	918
534.783	906
538.413	898
542.041	942
545.667	910
549.292	948
552.915	900
556.537	928
560.156	870
563.773	916
567.389	904
571.004	922
574.615	972
578.226	934
581.834	912
585.44	966
589.045	956
592.649	930
596.25	946
599.85	936
603.448	906
607.042	954
610.637	928
614.229	938
617.819	928
621.408	964
624.994	936
628.58	980
632.163	978
635.744	962
639.324	978
642.902	1006
646.478	980
650.052	976
653.625	1002
657.196	992
660.764	990
664.331	956
667.897	1022
671.46	998
675.021	942
678.582	984
682.14	1038
685.696	978
689.252	1022
692.804	994
696.355	1010
699.905	996
703.451	988
706.997	994
710.542	992
714.083	1004
717.624	1014
721.162	1014
724.7	1018
728.235	1002
731.768	1030
735.301	1020
738.83	998
742.358	1024
745.885	1054
749.41	1026
752.931	1060
756.453	1030
759.973	1018
763.49	1034
767.006	1002
770.52	1048
774.033	1026
777.543	1016
781.052	1026
784.559	1040
788.064	1066
791.568	1046
795.07	1032
798.57	1032
802.068	1020
805.565	1032
809.061	1060
812.553	1026
816.045	1064
819.535	1054
823.022	1060
826.508	1096
829.993	1074
833.476	1032
836.957	1112
840.436	1090
843.914	1096
847.391	1084
850.864	1054
854.337	1122
857.807	1054
861.277	1106
864.744	1100
868.209	1096
871.674	1096
875.136	1100
878.597	1072
882.056	1108
885.512	1088
888.967	1108
892.421	1106
895.874	1080
899.323	1118
902.771	1088
906.219	1072
909.664	1104
913.107	1060
916.55	1078
919.99	1082
923.428	1080
926.863	1074
930.299	1094
933.732	1108
937.164	1090
940.593	1098
944.022	1110
947.448	1110
950.874	1120
954.296	1138
957.718	1148
961.137	1146
964.555	1140
967.972	1100
971.387	1132
974.8	1146
978.21	1158
981.62	1178
985.029	1128
988.435	1158
991.839	1138
995.243	1154
998.644	1142
1002.04	1118
1005.44	1144
1008.84	1094
1012.23	1114
1015.63	1128
1019.02	1190
1022.41	1130
1025.79	1148
1029.18	1140
1032.56	1182
1035.95	1162
1039.33	1210
1042.71	1192
1046.09	1166
1049.46	1152
1052.84	1178
1056.21	1188
1059.58	1178
1062.95	1192
1066.32	1234
1069.69	1200
1073.05	1160
1076.41	1212
1079.78	1198
1083.14	1186
1086.49	1162
1089.85	1174
1093.21	1142
1096.56	1196
1099.91	1152
1103.26	1134
1106.61	1152
1109.96	1170
1113.3	1182
1116.64	1162
1119.99	1146
1123.33	1212
1126.66	1174
1130	1136
1133.34	1130
1136.67	1186
1140	1198
1143.33	1192
1146.66	1184
1149.99	1224
1153.32	1170
1156.64	1204
1159.96	1210
1163.28	1238
1166.6	1188
1169.92	1188
1173.23	1154
1176.55	1180
1179.86	1212
1183.17	1236
1186.48	1210
1189.79	1252
1193.1	1196
1196.4	1206
1199.7	1162
1203	1198
1206.3	1210
1209.6	1176
1212.9	1184
1216.19	1172
1219.49	1162
1222.78	1214
1226.07	1206
1229.36	1224
1232.65	1170
1235.93	1188
1239.21	1170
1242.5	1184
1245.78	1192
1249.06	1170
1252.33	1196
1255.61	1202
1258.88	1204
1262.16	1160
1265.43	1184
1268.7	1218
1271.96	1168
1275.23	1172
1278.5	1166
1281.76	1211.84
1285.02	1202.17
1288.28	1229.01
1291.54	1232.35
1294.8	1212.13
1298.05	1208.9
1301.31	1222.87
1304.56	1206.7
1307.81	1235.57
1311.06	1233.55
1314.3	1226.67
1317.55	1221.14
1320.79	1219.49
1324.04	1218.76
1327.28	1240.23
1330.52	1225.82
1333.76	1226.29
1336.99	1216.03
1340.23	1234.03
1343.46	1206.2
1346.69	1210.73
1349.92	1202.54
1353.15	1226.21
1356.38	1226.98
1359.6	1212.87
1362.83	1209.47
1366.05	1203.62
1369.27	1211.42
1372.49	1221.69
1375.71	1207.74
1378.93	1220.16
1382.14	1198.64
1385.35	1219.23
1388.57	1219.57
1391.2	1254
1394.43	1238
1397.65	1214
1400.87	1188
1404.09	1240
1407.31	1254
1410.53	1190
1413.74	1160
1416.96	1198
1420.17	1256
1423.38	1218
1426.59	1192
1429.8	1174
1433.01	1236
1436.21	1174
1439.42	1156
1442.62	1250
1445.82	1212
1449.02	1198
1452.22	1182
1455.41	1192
1458.61	1198
1461.8	1232
1464.99	1174
1468.18	1138
1471.37	1176
1474.56	1194
1477.74	1206
1480.93	1170
1484.11	1184
1487.29	1184
1490.47	1168
1493.65	1220
1496.82	1188
1500	1174
1503.17	1198
1506.34	1140
1509.51	1172
1512.68	1192
1515.85	1188
1519.02	1184
1522.18	1182
1525.34	1162
1528.51	1184
1531.67	1210
1534.82	1164
1537.98	1206
1541.14	1174
1544.29	1164
1547.44	1152
1550.59	1144
1553.74	1150
1556.89	1150
1560.04	1180
1563.18	1124
1566.33	1136
1569.47	1168
1572.61	1168
1575.75	1146
1578.89	1106
1582.02	1134
1585.16	1146
1588.29	1172
1591.42	1156
1594.55	1128
1597.68	1118
1600.81	1162
1603.94	1152
1607.06	1158
1610.18	1166
1613.3	1158
1616.42	1166
1619.54	1146
1622.66	1144
1625.78	1136
1628.89	1138
1632	1066
1635.11	1144
1638.22	1122
1641.33	1100
1644.44	1104
1647.55	1086
1650.65	1074
1653.75	1102
1656.85	1056
1659.95	1062
1663.05	1100
1666.15	1112
1669.24	1094
1672.34	1090
1675.43	1090
1678.52	1044
1681.61	1042
1684.7	1062
1687.78	1072
1690.87	1062
1693.95	1024
1697.03	1032
1700.12	1030
1703.2	1020
1706.27	1034
1709.35	1044
1712.42	1020
1715.5	1060
1718.57	1036
1721.64	1058
1724.71	1054
1727.78	992
1730.84	1038
1733.91	998
1736.97	984
1740.04	1046
1743.1	1054
1746.16	1006
1749.21	1000
1752.27	996
1755.33	1018
1758.38	1030
1761.43	1030
1764.48	1046
1767.53	1020
1770.58	994
1773.63	1012
1776.67	992
1779.71	1024
1782.76	1038
1785.8	988
1788.84	1006
1791.88	1000
1794.91	988
1797.95	1006
1800.98	994
1804.01	1020
1807.04	1004
1810.07	1026
1813.1	1000
1816.13	984
1819.15	998
1822.18	948
1825.2	988
1828.22	1004
1831.24	948
1834.26	970
1837.28	1004
1840.29	962
1843.31	960
1846.32	968
1849.33	946
1852.34	966
1855.35	978
1858.36	994
1861.36	954
1864.36	950
1867.37	942
1870.37	948
1873.37	950
1876.37	912
1879.37	988
1882.36	934
1885.36	956
1888.35	942
1891.34	920
1894.33	940
1897.32	924
1900.31	952
1903.3	920
1906.28	940
1909.26	938
1912.25	904
1915.23	886
1918.21	936
1921.18	938
1924.16	912
1927.14	932
1930.11	952
1933.08	918
1936.05	958
1939.02	958
1941.99	946
1944.96	916
1947.92	910
1950.89	900
1953.85	912
1956.81	894
1959.77	878
1962.73	924
1965.69	900
1968.65	884
1971.6	894
1974.55	914
1977.51	896
1980.46	928
1983.41	912
1986.35	890
1989.3	900
1992.25	888
1995.19	894
1998.13	874
2001.07	888
2004.01	874
2006.95	860
2009.89	876
2012.82	862
2015.76	894
2018.69	866
2021.62	850
2024.55	882
2027.48	896
2030.41	904
2033.34	892
2036.26	870
2039.19	888
2042.11	876
2045.03	856
2047.95	844
2050.87	886
2053.79	848
2056.7	838
2059.61	854
2062.53	860
2065.44	834
2068.35	858
2071.26	850
2074.17	856
2077.07	832
2079.98	860
2082.88	842
2085.78	834
2088.68	844
2091.58	838
2094.48	818
2097.38	858
2100.28	848
2103.17	822
2106.06	826
2108.96	848
2111.85	836
2114.73	830
2117.62	790
2120.51	820
2123.39	824
2126.28	836
2129.16	816
2132.04	824
2134.92	812
2137.8	822
2140.68	826
2143.55	826
2146.43	830
2149.3	820
2152.17	770
2155.04	786
2157.91	768
2160.78	794
2163.65	792
2166.51	790
2169.38	788
2172.24	812
2175.1	774
2177.96	786
2180.82	788
2183.68	810
2186.53	754
2189.39	774
2192.24	806
2195.09	760
2197.95	766
2200.8	758
2203.64	748
2206.49	746
2209.34	764
2212.18	752
2215.03	752
2217.87	782
2220.71	762.155
2223.55	714.774
2226.39	733.422
2229.22	777.079
2232.06	732.916
2234.89	766.529
2237.73	741.454
2240.56	736.774
2243.39	759.99
2246.22	738.007
2249.05	758.701
2251.87	761.459
2254.7	730.07
2257.52	747.025
2260.34	748.799
2263.17	734.103
2265.99	745.191
2268.8	754.609
2271.62	755.218
2274.44	738.613
2277.25	733.632
2280.07	753.109
2282.88	740.725
2285.69	732.041
2288.5	737.702
2291.31	752.21
2294.12	755.634
2296.92	747.789
2299.73	750.931
2302.53	733.81
2305.34	745.356
2308.14	733.897
2310.94	746.185
2313.74	719.726
2315.86	744
2318.67	738
2321.48	748
2324.29	712
2327.09	734
2329.9	738
2332.7	728
2335.51	730
2338.31	758
2341.11	750
2343.91	720
2346.71	710
2349.51	752
2352.3	744
2355.1	772
2357.89	712
2360.68	736
2363.48	730
2366.27	722
2369.05	738
2371.84	690
2374.63	708
2377.41	722
2380.2	672
2382.98	724
2385.76	728
2388.54	720
2391.32	728
2394.1	722
2396.87	696
2399.65	700
2402.42	708
2405.2	732
2407.97	716
2410.74	694
2413.51	708
2416.27	730
2419.04	708
2421.81	718
2424.57	710
2427.33	706
2430.1	690
2432.85	714
2435.61	674
2438.37	714
2441.13	686
2443.88	700
2446.64	722
2449.39	686
2452.14	696
2454.89	686
2457.64	662
2460.39	660
2463.14	688
2465.88	690
2468.63	684
2471.37	668
2474.11	694
2476.86	660
2479.59	690
2482.33	656
2485.07	686
2487.81	654
2490.54	662
2493.28	654
2496.01	690
2498.74	658
2501.47	646
2504.2	680
2506.93	658
2509.65	672
2512.38	644
2515.1	658
2517.82	662
2520.55	662
2523.27	694
2525.99	654
2528.7	652
2531.42	646
2534.14	638
2536.85	660
2539.56	644
2542.28	656
2544.99	624
2547.7	632
2550.4	646
2553.11	666
2555.82	640
2558.52	662
2561.23	636
2563.93	640
2566.63	624
2569.33	668
2572.03	640
2574.73	634
2577.42	630
2580.12	632
2582.81	618
2585.51	628
2588.2	610
2590.89	630
2593.58	614
2596.26	618
2598.95	638
2601.64	626
2604.32	604
2607.01	664
2609.69	588
2612.37	616
2615.05	592
2617.73	634
2620.41	616
2623.08	652
2625.76	596
2628.43	580
2631.1	610
2633.78	628
2636.45	628
2639.12	588
2641.78	608
2644.45	626
2647.12	594
2649.78	578
2652.45	612
2655.11	596
2657.77	604
2660.43	598
2663.09	578
2665.75	578
2668.4	572
2671.06	610
2673.71	584
2676.37	578
2679.02	590
2681.67	584
2684.32	588
2686.97	586
2689.61	616
2692.26	558
2694.9	612
2697.55	574
2700.19	584
2702.83	590
2705.47	556
2708.11	562
2710.75	590
2713.39	588
2716.02	576
2718.66	574
2721.29	598
2723.92	578
2726.55	566
2729.18	590
2731.81	554
2734.44	546
2737.07	560
2739.69	556
2742.32	538
2744.94	536
2747.56	552
2750.18	562
2752.8	562
2755.42	544
2758.04	546
2760.65	532
2763.27	552
2765.88	550
2768.5	528
2771.11	526
2773.72	552
2776.33	534
2778.94	566
2781.54	538
2784.15	528
2786.75	528
2789.36	544
2791.96	532
2794.56	574
2797.16	524
2799.76	524
2802.36	532
2804.96	534
2807.55	518
2810.15	510
2812.74	508
2815.33	524
2817.93	502
2820.52	530
2823.11	536
2825.69	512
2828.28	522
2830.87	520
2833.45	488
2836.03	530
2838.62	514
2841.2	504
2843.78	502
2846.36	510
2848.93	502
2851.51	512
2854.09	494
2856.66	498
2859.24	508
2861.81	480
2864.38	498
2866.95	500
2869.52	504
2872.09	474
2874.65	478
2877.22	482
2879.78	486
2882.35	484
2884.91	478
2887.47	504
2890.03	482
2892.59	482
2895.15	486
2897.7	488
2900.26	496
2902.81	472
2905.37	474
2907.92	456
2910.47	466
2913.02	470
2915.57	486
2918.12	456
2920.66	468
2923.21	442
2925.75	482
2928.3	464
2930.84	476
2933.38	454
2935.92	452
2938.46	498
2941	470
2943.54	468
2946.07	440
2948.61	464
2951.14	434
2953.67	454
2956.21	452
2958.74	468
2961.27	446
2963.79	478
2966.32	452
2968.85	436
2971.37	474
2973.9	456
2976.42	460
2978.94	426
2981.46	448
2983.98	436
2986.5	416
2989.02	440
2991.53	466
2994.05	434
2996.56	442
2999.08	444
3001.59	432
3004.1	456
3006.61	430
3009.12	440
3011.63	440
3014.13	426
3016.64	430
3019.14	422
3021.65	426
3024.15	422
3026.65	412
3029.15	396
3031.65	424
3034.15	424
3036.64	428
3039.14	422
3041.63	409.852
3044.13	420.876
3046.62	394.58
3049.11	402.676
3051.6	404.64
3054.09	425.513
3056.58	423.054
3059.07	407.948
3061.55	397.515
3064.04	397.933
3066.52	385.743
3069.01	385.389
3071.49	401.251
3073.97	409.137
3076.45	408.433
3078.93	388.731
3081.41	406.656
3083.88	384.481
3086.36	406.614
3088.83	387.762
3091.31	391.338
3093.78	393.902
3096.25	391.918
3098.72	366.322
3101.19	385.837
3103.66	376.397
3106.13	379.754
3108.59	359.219
3111.06	376.884
3113.52	374.723
3115.98	363.859
3118.45	367.157
3120.91	365.976
3123.37	366.643
3125.38	372
3127.85	346
3130.32	370
3132.79	362
3135.26	358
3137.73	348
3140.19	380
3142.66	362
3145.13	336
3147.59	342
3150.05	370
3152.51	368
3154.97	372
3157.43	342
3159.89	356
3162.35	342
3164.8	350
3167.26	364
3169.71	356
3172.17	352
3174.62	338
3177.07	346
3179.52	374
3181.97	322
3184.41	322
3186.86	330
3189.31	344
3191.75	344
3194.2	342
3196.64	358
3199.08	340
3201.52	332
3203.96	332
3206.4	354
3208.84	350
3211.27	328
3213.71	360
3216.14	330
3218.58	334
3221.01	342
3223.44	322
3225.87	332
3228.3	330
3230.73	320
3233.16	328
3235.58	310
3238.01	316
3240.43	340
3242.86	330
3245.28	326
3247.7	328
3250.12	312
3252.54	320
3254.96	306
3257.38	330
3259.79	340
3262.21	306
3264.62	330
3267.04	318
3269.45	324
3271.86	306
3274.27	314
3276.68	328
3279.09	314
3281.49	294
3283.9	316
3286.31	316
3288.71	300
3291.11	322
3293.51	302
3295.92	332
3298.32	302
3300.72	312
3303.11	310
3305.51	306
3307.91	316
3310.3	326
3312.7	306
3315.09	302
3317.48	314
3319.87	324
3322.26	302
3324.65	296
3327.04	318
3329.43	276
3331.81	312
3334.2	296
3336.58	298
3338.97	316
3341.35	304
3343.73	296
3346.11	286
3348.49	318
3350.87	298
3353.25	318
3355.62	302
3358	282
3360.37	294
3362.75	296
3365.12	282
3367.49	266
3369.86	298
3372.23	300
3374.6	304
3376.97	288
3379.33	274
3381.7	302
3384.06	302
3386.43	276
3388.79	298
3391.15	272
3393.51	282
3395.87	274
3398.23	284
3400.59	292
3402.94	282
3405.3	272
3407.65	288
3410.01	290
3412.36	260
3414.71	294
3417.06	256
3419.41	278
3421.76	264
3424.11	276
3426.46	276
3428.8	276
3431.15	282
3433.49	268
3435.83	268
3438.18	256
3440.52	276
3442.86	254
3445.2	268
3447.53	296
3449.87	284
3452.21	264
3454.54	250
3456.88	250
3459.21	272
3461.54	262
3463.88	274
3466.21	274
3468.53	252
3470.86	268
3473.19	262
3475.52	258
3477.84	266
3480.17	278
3482.49	278
3484.82	248
3487.14	250
3489.46	254
3491.78	252
3494.1	260
3496.42	254
3498.73	262
3501.05	258
3503.36	244
3505.68	256
3507.99	270
3510.3	244
3512.61	242
3514.92	248
3517.23	248
3519.54	246
3521.85	252
3524.16	256
3526.46	236
3528.77	258
3531.07	240
3533.37	246
3535.68	248
3537.98	252
3540.28	262
3542.58	232
3544.87	236
3547.17	246
3549.47	254
3551.76	254
3554.06	238
3556.35	258
3558.64	256
3560.93	250
3563.22	250
3565.51	256
3567.8	242
3570.09	242
3572.38	256
3574.66	238
3576.95	256
3579.23	238
3581.51	240
3583.8	242
3586.08	246
3588.36	230
3590.64	230
3592.92	236
3595.19	244
3597.47	234
3599.75	224
3602.02	230
3604.29	238
3606.57	220
3608.84	254
3611.11	232
3613.38	234
3615.65	214
3617.92	230
3620.18	234
3622.45	240
3624.71	222
3626.98	224
3629.24	232
3631.5	224
3633.77	222
3636.03	220
3638.29	240
3640.55	236
3642.8	216
3645.06	216
3647.32	226
3649.57	216
3651.83	228
3654.08	214
3656.33	220
3658.58	228
3660.83	214
3663.08	228
3665.33	218
3667.58	238
3669.83	216
3672.07	224
3674.32	236
3676.56	220
3678.8	216
3681.05	216
3683.29	210
3685.53	216
3687.77	208
3690.01	224
3692.24	220
3694.48	218
3696.72	224
3698.95	210
3701.19	212
3703.42	208
3705.65	218
3707.88	202
3710.11	214
3712.34	226
3714.57	218
3716.8	230
3719.03	214
3721.25	216
3723.48	226
3725.7	212
3727.92	202
3730.15	216
3732.37	226
3734.59	218
3736.81	214
3739.03	216
3741.24	206
3743.46	206
3745.68	216
3747.89	224
3750.11	194
3752.32	214
3754.53	216
3756.74	216
3758.95	216
3761.16	204
3763.37	192.029
3765.58	204.004
3767.79	207.653
3769.99	192.198
3772.2	189.49
3774.4	208.927
3776.61	213.299
3778.81	204.557
3781.01	221.984
3783.21	209.411
3785.41	188.869
3787.61	196.534
3789.81	202.651
3792	206.661
3794.2	205.821
3796.4	203.666
3798.59	200.25
3800.78	198.454
3802.98	199.058
3805.17	208.16
3807.36	191.348
3809.55	197.189
3811.74	198.759
3813.93	209.664
3816.11	202.042
3818.3	193.188
3820.49	199.174
3822.67	191.853
3824.85	200.318
3827.04	193.398
3829.22	198.693
3831.4	193.579
3833.58	202.932
3835.76	198.464
3837.94	191.297
3839.98	190
3842.17	190
3844.36	206
3846.55	184
3848.73	200
3850.92	194
3853.1	172
3855.29	206
3857.47	202
3859.65	180
3861.84	188
3864.02	182
3866.2	184
3868.38	196
3870.55	212
3872.73	198
3874.91	190
3877.08	188
3879.26	200
3881.43	206
3883.6	184
3885.78	188
3887.95	190
3890.12	196
3892.29	202
3894.46	196
3896.63	190
3898.79	180
3900.96	198
3903.12	196
3905.29	180
3907.45	186
3909.61	186
3911.78	184
3913.94	178
3916.1	190
3918.26	198
3920.41	178
3922.57	176
3924.73	166
3926.88	182
3929.04	198
3931.19	186
3933.35	180
3935.5	180
3937.65	174
3939.8	192
3941.95	186
3944.1	172
3946.25	182
3948.4	176
3950.54	182
3952.69	166
3954.83	186
3956.98	206
3959.12	198
3961.26	186
3963.4	188
3965.54	180
3967.68	176
3969.82	182
3971.96	166
3974.1	176
3976.23	194
3978.37	170
3980.5	174
3982.64	162
3984.77	176
3986.9	190
3989.03	182
3991.16	178
3993.29	182
3995.42	168
3997.55	160
3999.67	166