File: muestras/mosquito/OR_10.txt
#Acq. time (s)=	10
#Accumulations=	1
#Range (cm-¹)=	200...4000
#Windows=	5
#Autofocus=	Off
#AutoExposure=	Off
#Spike filter=	Off
#Delay time (s)=	0
#Binning=	1
#Readout mode=	Signal
#DeNoise=	Off
#ICS correction=	Off
#Dark correction=	Off
#Inst. Process=	Off
#Instrument=	LabRAM HR Evol
#Detector=	Syncerity OE
#Objective=	x100_VIS
#Grating=	600 (500nm)
#ND Filter=	25%
#Laser=	633nm_Edge
#Hole=	100.021
#Range=	Visible
#Project=	Omar
#Sample=	03-07-23
#Site=	1
#Title=	OR
#Remark=
#Date=	03.07.2023 13:43
#Acquired=	03.07.2023 13:43:06
200.404	680
204.205	726
208.003	712
211.799	688
215.595	706
219.387	694
223.177	734
226.966	684
230.752	720
234.536	712
238.319	708
242.1	738
245.879	746
249.655	704
253.431	664
257.204	718
260.976	692
264.744	718
268.511	744
272.276	744
276.04	744
279.801	728
283.561	754
287.318	742
291.074	754
294.828	734
298.581	782
302.33	776
306.079	734
309.825	766
313.569	770
317.311	726
321.052	732
324.79	760
328.527	762
332.261	764
335.994	766
339.725	794
343.454	784
347.182	762
350.907	806
354.631	774
358.352	852
362.072	792
365.789	848
369.505	764
373.219	770
376.93	806
380.642	768
384.35	798
388.056	774
391.76	754
395.463	816
399.164	786
402.863	808
406.559	798
410.254	806
413.948	814
417.639	842
421.329	842
425.016	828
428.701	834
432.386	824
436.068	872
439.748	840
443.426	872
447.103	846
450.777	882
454.45	864
458.121	838
461.789	864
465.457	878
469.122	864
472.786	848
476.447	876
480.107	882
483.765	886
487.421	886
491.075	910
494.727	886
498.377	892
502.026	880
505.673	932
509.318	892
512.962	906
516.602	876
520.242	896
523.881	880
527.516	910
531.149	902
534.783	868
538.413	914
542.041	920
545.667	850
549.292	898
552.915	892
556.537	906
560.156	874
563.773	942
567.389	914
571.004	926
574.615	890
578.226	898
581.834	930
585.44	890
589.045	922
592.649	900
596.25	906
599.85	948
603.448	914
607.042	934
610.637	920
614.229	948
617.819	980
621.408	974
624.994	936
628.58	978
632.163	988
635.744	940
639.324	952
642.902	980
646.478	1002
650.052	992
653.625	952
657.196	1012
660.764	1014
664.331	980
667.897	972
671.46	1008
675.021	1012
678.582	1006
682.14	994
685.696	996
689.252	994
692.804	964
696.355	1050
699.905	1024
703.451	996
706.997	1012
710.542	1026
714.083	1006
717.624	1012
721.162	1040
724.7	1038
728.235	1032
731.768	1024
735.301	1044
738.83	1026
742.358	1020
745.885	1032
749.41	1076
752.931	1022
756.453	1064
759.973	1016
763.49	1036
767.006	1052
770.52	1102
774.033	1060
777.543	1038
781.052	1070
784.559	1046
788.064	1012
791.568	1028
795.07	1038
798.57	1026
802.068	1068
805.565	1086
809.061	1084
812.553	1078
816.045	1110
819.535	1046
823.022	1096
826.508	1086
829.993	1102
833.476	1050
836.957	1090
840.436	1076
843.914	1128
847.391	1150
850.864	1108
854.337	1124
857.807	1102
861.277	1124
864.744	1134
868.209	1120
871.674	1148
875.136	1140
878.597	1084
882.056	1108
885.512	1152
888.967	1098
892.421	1102
895.874	1142
899.323	1102
902.771	1130
906.219	1138
909.664	1108
913.107	1082
916.55	1108
919.99	1108
923.428	1156
926.863	1080
930.299	1140
933.732	1144
937.164	1122
940.593	1164
944.022	1146
947.448	1148
950.874	1164
954.296	1186
957.718	1124
961.137	1124
964.555	1154
967.972	1176
971.387	1154
974.8	1160
978.21	1156
981.62	1186
985.029	1174
988.435	1178
991.839	1154
995.243	1150
998.644	1148
1002.04	1206
1005.44	1176
1008.84	1174
1012.23	1170
1015.63	1208
1019.02	1176
1022.41	1150
1025.79	1208
1029.18	1192
1032.56	1228
1035.95	1210
1039.33	1244
1042.71	1224
1046.09	1236
1049.46	1202
1052.84	1186
1056.21	1212
1059.58	1204
1062.95	1174
1066.32	1230
1069.69	1226
1073.05	1238
1076.41	1196
1079.78	1256
1083.14	1212
1086.49	1166
1089.85	1224
1093.21	1264
1096.56	1218
1099.91	1192
1103.26	1228
1106.61	1194
1109.96	1196
1113.3	1210
1116.64	1254
1119.99	1178
1123.33	1246
1126.66	1210
1130	1212
1133.34	1216
1136.67	1256
1140	1248
1143.33	1214
1146.66	1192
1149.99	1252
1153.32	1246
1156.64	1256
1159.96	1280
1163.28	1260
1166.6	1264
1169.92	1258
1173.23	1244
1176.55	1212
1179.86	1240
1183.17	1254
1186.48	1242
1189.79	1246
1193.1	1242
1196.4	1258
1199.7	1228
1203	1244
1206.3	1264
1209.6	1220
1212.9	1218
1216.19	1222
1219.49	1222
1222.78	1272
1226.07	1208
1229.36	1228
1232.65	1166
1235.93	1198
1239.21	1206
1242.5	1208
1245.78	1202
1249.06	1222
1252.33	1234
1255.61	1166
1258.88	1208
1262.16	1206
1265.43	1224
1268.7	1286
1271.96	1208
1275.23	1242
1278.5	1242
1281.76	1214.08
1285.02	1264.25
1288.28	1245.9
1291.54	1223.7
1294.8	1236.92
1298.05	1286.66
1301.31	1216.38
1304.56	1244.21
1307.81	1241.7
1311.06	1251.12
1314.3	1269.65
1317.55	1266.93
1320.79	1229.03
1324.04	1241.9
1327.28	1231.13
1330.52	1244.02
1333.76	1241.51
1336.99	1241.26
1340.23	1257.02
1343.46	1247.63
1346.69	1228.54
1349.92	1243.51
1353.15	1231.23
1356.38	1219.59
1359.6	1230.03
1362.83	1228.47
1366.05	1214.63
1369.27	1241.83
1372.49	1229.24
1375.71	1236.02
1378.93	1240.53
1382.14	1214.68
1385.35	1239.03
1388.57	1214.72
1391.2	1210
1394.43	1236
1397.65	1248
1400.87	1246
1404.09	1224
1407.31	1252
1410.53	1244
1413.74	1202
1416.96	1206
1420.17	1204
1423.38	1214
1426.59	1190
1429.8	1222
1433.01	1230
1436.21	1208
1439.42	1198
1442.62	1222
1445.82	1256
1449.02	1186
1452.22	1174
1455.41	1164
1458.61	1202
1461.8	1168
1464.99	1156
1468.18	1162
1471.37	1192
1474.56	1182
1477.74	1202
1480.93	1216
1484.11	1174
1487.29	1206
1490.47	1178
1493.65	1196
1496.82	1222
1500	1198
1503.17	1152
1506.34	1166
1509.51	1216
1512.68	1232
1515.85	1206
1519.02	1172
1522.18	1194
1525.34	1202
1528.51	1172
1531.67	1174
1534.82	1186
1537.98	1180
1541.14	1178
1544.29	1174
1547.44	1164
1550.59	1154
1553.74	1158
1556.89	1162
1560.04	1174
1563.18	1154
1566.33	1132
1569.47	1166
1572.61	1168
1575.75	1176
1578.89	1178
1582.02	1122
1585.16	1174
1588.29	1138
1591.42	1168
1594.55	1152
1597.68	1120
1600.81	1142
1603.94	1156
1607.06	1190
1610.18	1132
1613.3	1154
1616.42	1126
1619.54	1148
1622.66	1144
1625.78	1110
1628.89	1142
1632	1158
1635.11	1132
1638.22	1118
1641.33	1128
1644.44	1098
1647.55	1108
1650.65	1098
1653.75	1106
1656.85	1146
1659.95	1082
1663.05	1048
1666.15	1092
1669.24	1082
1672.34	1094
1675.43	1038
1678.52	1068
1681.61	1058
1684.7	1084
1687.78	1054
1690.87	1044
1693.95	1026
1697.03	1058
1700.12	1010
1703.2	1010
1706.27	1040
1709.35	1006
1712.42	990
1715.5	1016
1718.57	1062
1721.64	1010
1724.71	984
1727.78	998
1730.84	990
1733.91	990
1736.97	1028
1740.04	1020
1743.1	996
1746.16	1012
1749.21	1004
1752.27	978
1755.33	968
1758.38	972
1761.43	990
1764.48	1004
1767.53	992
1770.58	998
1773.63	982
1776.67	986
1779.71	974
1782.76	988
1785.8	1038
1788.84	992
1791.88	990
1794.91	1012
1797.95	960
1800.98	972
1804.01	970
1807.04	972
1810.07	1020
1813.1	1004
1816.13	938
1819.15	986
1822.18	938
1825.2	958
1828.22	938
1831.24	938
1834.26	926
1837.28	942
1840.29	952
1843.31	952
1846.32	904
1849.33	960
1852.34	934
1855.35	928
1858.36	926
1861.36	930
1864.36	942
1867.37	936
1870.37	894
1873.37	928
1876.37	910
1879.37	888
1882.36	942
1885.36	916
1888.35	898
1891.34	898
1894.33	930
1897.32	888
1900.31	916
1903.3	910
1906.28	948
1909.26	906
1912.25	896
1915.23	928
1918.21	918
1921.18	916
1924.16	932
1927.14	908
1930.11	912
1933.08	898
1936.05	904
1939.02	874
1941.99	882
1944.96	890
1947.92	892
1950.89	926
1953.85	880
1956.81	894
1959.77	900
1962.73	896
1965.69	906
1968.65	864
1971.6	908
1974.55	902
1977.51	860
1980.46	898
1983.41	848
1986.35	906
1989.3	872
1992.25	844
1995.19	838
1998.13	882
2001.07	892
2004.01	876
2006.95	848
2009.89	852
2012.82	892
2015.76	846
2018.69	856
2021.62	824
2024.55	848
2027.48	886
2030.41	846
2033.34	850
2036.26	838
2039.19	854
2042.11	836
2045.03	822
2047.95	852
2050.87	832
2053.79	810
2056.7	826
2059.61	838
2062.53	800
2065.44	818
2068.35	806
2071.26	814
2074.17	850
2077.07	794
2079.98	850
2082.88	824
2085.78	774
2088.68	780
2091.58	802
2094.48	760
2097.38	796
2100.28	798
2103.17	792
2106.06	796
2108.96	798
2111.85	806
2114.73	788
2117.62	804
2120.51	824
2123.39	798
2126.28	840
2129.16	768
2132.04	788
2134.92	798
2137.8	806
2140.68	748
2143.55	738
2146.43	770
2149.3	792
2152.17	746
2155.04	766
2157.91	796
2160.78	768
2163.65	764
2166.51	788
2169.38	776
2172.24	768
2175.1	754
2177.96	750
2180.82	752
2183.68	762
2186.53	758
2189.39	738
2192.24	768
2195.09	744
2197.95	730
2200.8	708
2203.64	714
2206.49	746
2209.34	716
2212.18	744
2215.03	688
2217.87	736
2220.71	775.249
2223.55	711.39
2226.39	709.525
2229.22	713.708
2232.06	687.438
2234.89	709.013
2237.73	691.527
2240.56	733.981
2243.39	722.654
2246.22	685.797
2249.05	721.232
2251.87	733.304
2254.7	718.228
2257.52	695.747
2260.34	750.585
2263.17	716.075
2265.99	710.037
2268.8	716.281
2271.62	716.703
2274.44	699.041
2277.25	721.828
2280.07	711.822
2282.88	707.345
2285.69	716.063
2288.5	724.486
2291.31	720.749
2294.12	731.638
2296.92	718.625
2299.73	733.235
2302.53	691.994
2305.34	729.184
2308.14	704.041
2310.94	692.812
2313.74	675.715
2315.86	706
2318.67	704
2321.48	658
2324.29	700
2327.09	712
2329.9	694
2332.7	716
2335.51	710
2338.31	692
2341.11	662
2343.91	704
2346.71	704
2349.51	668
2352.3	694
2355.1	706
2357.89	678
2360.68	714
2363.48	678
2366.27	680
2369.05	664
2371.84	654
2374.63	682
2377.41	694
2380.2	688
2382.98	684
2385.76	660
2388.54	712
2391.32	678
2394.1	656
2396.87	670
2399.65	698
2402.42	658
2405.2	646
2407.97	676
2410.74	664
2413.51	644
2416.27	640
2419.04	664
2421.81	672
2424.57	644
2427.33	670
2430.1	686
2432.85	664
2435.61	686
2438.37	650
2441.13	676
2443.88	636
2446.64	624
2449.39	610
2452.14	658
2454.89	630
2457.64	640
2460.39	646
2463.14	640
2465.88	658
2468.63	602
2471.37	636
2474.11	642
2476.86	636
2479.59	650
2482.33	628
2485.07	628
2487.81	630
2490.54	612
2493.28	612
2496.01	634
2498.74	612
2501.47	622
2504.2	592
2506.93	620
2509.65	654
2512.38	622
2515.1	604
2517.82	618
2520.55	638
2523.27	608
2525.99	634
2528.7	600
2531.42	620
2534.14	614
2536.85	608
2539.56	616
2542.28	584
2544.99	584
2547.7	586
2550.4	606
2553.11	600
2555.82	606
2558.52	568
2561.23	580
2563.93	608
2566.63	576
2569.33	590
2572.03	612
2574.73	612
2577.42	584
2580.12	568
2582.81	600
2585.51	604
2588.2	594
2590.89	616
2593.58	600
2596.26	590
2598.95	564
2601.64	566
2604.32	584
2607.01	574
2609.69	592
2612.37	584
2615.05	566
2617.73	580
2620.41	576
2623.08	568
2625.76	584
2628.43	542
2631.1	562
2633.78	578
2636.45	594
2639.12	566
2641.78	574
2644.45	570
2647.12	570
2649.78	548
2652.45	564
2655.11	560
2657.77	570
2660.43	558
2663.09	546
2665.75	580
2668.4	572
2671.06	558
2673.71	562
2676.37	542
2679.02	552
2681.67	538
2684.32	566
2686.97	542
2689.61	552
2692.26	530
2694.9	516
2697.55	556
2700.19	546
2702.83	544
2705.47	530
2708.11	552
2710.75	526
2713.39	532
2716.02	538
2718.66	556
2721.29	542
2723.92	510
2726.55	528
2729.18	516
2731.81	538
2734.44	514
2737.07	518
2739.69	508
2742.32	532
2744.94	498
2747.56	490
2750.18	504
2752.8	480
2755.42	524
2758.04	532
2760.65	484
2763.27	504
2765.88	494
2768.5	492
2771.11	490
2773.72	492
2776.33	504
2778.94	526
2781.54	480
2784.15	506
2786.75	502
2789.36	482
2791.96	484
2794.56	504
2797.16	508
2799.76	508
2802.36	462
2804.96	498
2807.55	470
2810.15	486
2812.74	510
2815.33	468
2817.93	470
2820.52	478
2823.11	466
2825.69	482
2828.28	472
2830.87	492
2833.45	460
2836.03	446
2838.62	468
2841.2	468
2843.78	460
2846.36	468
2848.93	456
2851.51	458
2854.09	448
2856.66	440
2859.24	462
2861.81	450
2864.38	420
2866.95	460
2869.52	440
2872.09	452
2874.65	458
2877.22	454
2879.78	470
2882.35	448
2884.91	462
2887.47	456
2890.03	436
2892.59	454
2895.15	440
2897.7	472
2900.26	442
2902.81	458
2905.37	414
2907.92	420
2910.47	446
2913.02	442
2915.57	446
2918.12	432
2920.66	438
2923.21	408
2925.75	444
2928.3	438
2930.84	430
2933.38	426
2935.92	424
2938.46	408
2941	452
2943.54	446
2946.07	432
2948.61	446
2951.14	396
2953.67	414
2956.21	428
2958.74	434
2961.27	424
2963.79	418
2966.32	422
2968.85	378
2971.37	410
2973.9	422
2976.42	388
2978.94	412
2981.46	428
2983.98	406
2986.5	394
2989.02	370
2991.53	378
2994.05	410
2996.56	402
2999.08	408
3001.59	410
3004.1	392
3006.61	398
3009.12	384
3011.63	392
3014.13	398
3016.64	356
3019.14	386
3021.65	384
3024.15	376
3026.65	410
3029.15	374
3031.65	386
3034.15	386
3036.64	380
3039.14	362
3041.63	371.8
3044.13	372.493
3046.62	390.323
3049.11	362.393
3051.6	372.138
3054.09	362.406
3056.58	360.303
3059.07	368.613
3061.55	350.721
3064.04	351.549
3066.52	348.522
3069.01	359.21
3071.49	354.45
3073.97	360.262
3076.45	344.255
3078.93	353.969
3081.41	363.191
3083.88	348.907
3086.36	334.265
3088.83	345.257
3091.31	340.71
3093.78	352.072
3096.25	346.964
3098.72	359.105
3101.19	353.182
3103.66	348.117
3106.13	338.834
3108.59	322.672
3111.06	323.808
3113.52	325.095
3115.98	327.022
3118.45	324.708
3120.91	342.421
3123.37	302.695
3125.38	318
3127.85	318
3130.32	328
3132.79	300
3135.26	316
3137.73	306
3140.19	322
3142.66	326
3145.13	318
3147.59	312
3150.05	340
3152.51	320
3154.97	304
3157.43	302
3159.89	316
3162.35	312
3164.8	302
3167.26	326
3169.71	328
3172.17	318
3174.62	308
3177.07	294
3179.52	324
3181.97	314
3184.41	272
3186.86	310
3189.31	306
3191.75	286
3194.2	308
3196.64	324
3199.08	298
3201.52	298
3203.96	294
3206.4	306
3208.84	308
3211.27	312
3213.71	294
3216.14	298
3218.58	290
3221.01	290
3223.44	306
3225.87	278
3228.3	274
3230.73	300
3233.16	296
3235.58	298
3238.01	304
3240.43	262
3242.86	280
3245.28	292
3247.7	300
3250.12	290
3252.54	302
3254.96	286
3257.38	270
3259.79	278
3262.21	302
3264.62	290
3267.04	288
3269.45	266
3271.86	268
3274.27	296
3276.68	296
3279.09	270
3281.49	280
3283.9	298
3286.31	306
3288.71	294
3291.11	272
3293.51	276
3295.92	278
3298.32	264
3300.72	278
3303.11	266
3305.51	280
3307.91	246
3310.3	270
3312.7	284
3315.09	272
3317.48	280
3319.87	266
3322.26	262
3324.65	266
3327.04	270
3329.43	270
3331.81	284
3334.2	256
3336.58	246
3338.97	264
3341.35	258
3343.73	260
3346.11	256
3348.49	282
3350.87	264
3353.25	262
3355.62	250
3358	268
3360.37	250
3362.75	248
3365.12	272
3367.49	250
3369.86	250
3372.23	256
3374.6	246
3376.97	258
3379.33	248
3381.7	258
3384.06	252
3386.43	246
3388.79	258
3391.15	256
3393.51	264
3395.87	248
3398.23	248
3400.59	246
3402.94	244
3405.3	238
3407.65	240
3410.01	250
3412.36	234
3414.71	256
3417.06	234
3419.41	244
3421.76	254
3424.11	256
3426.46	248
3428.8	254
3431.15	242
3433.49	230
3435.83	248
3438.18	244
3440.52	246
3442.86	238
3445.2	230
3447.53	242
3449.87	232
3452.21	230
3454.54	222
3456.88	254
3459.21	228
3461.54	246
3463.88	222
3466.21	232
3468.53	228
3470.86	220
3473.19	248
3475.52	230
3477.84	220
3480.17	228
3482.49	228
3484.82	240
3487.14	236
3489.46	214
3491.78	210
3494.1	222
3496.42	224
3498.73	230
3501.05	228
3503.36	232
3505.68	226
3507.99	212
3510.3	230
3512.61	252
3514.92	206
3517.23	210
3519.54	220
3521.85	206
3524.16	200
3526.46	218
3528.77	210
3531.07	204
3533.37	194
3535.68	232
3537.98	212
3540.28	216
3542.58	222
3544.87	212
3547.17	222
3549.47	210
3551.76	208
3554.06	218
3556.35	222
3558.64	208
3560.93	216
3563.22	208
3565.51	210
3567.8	216
3570.09	212
3572.38	204
3574.66	208
3576.95	210
3579.23	208
3581.51	206
3583.8	214
3586.08	220
3588.36	198
3590.64	206
3592.92	200
3595.19	204
3597.47	196
3599.75	210
3602.02	204
3604.29	208
3606.57	218
3608.84	208
3611.11	208
3613.38	206
3615.65	194
3617.92	210
3620.18	188
3622.45	222
3624.71	202
3626.98	192
3629.24	208
3631.5	212
3633.77	212
3636.03	198
3638.29	202
3640.55	188
3642.8	190
3645.06	186
3647.32	190
3649.57	196
3651.83	202
3654.08	184
3656.33	192
3658.58	208
3660.83	208
3663.08	170
3665.33	180
3667.58	186
3669.83	190
3672.07	200
3674.32	200
3676.56	202
3678.8	202
3681.05	196
3683.29	210
3685.53	160
3687.77	194
3690.01	180
3692.24	186
3694.48	200
3696.72	182
3698.95	192
3701.19	184
3703.42	202
3705.65	194
3707.88	184
3710.11	164
3712.34	182
3714.57	192
3716.8	174
3719.03	198
3721.25	196
3723.48	174
3725.7	188
3727.92	176
3730.15	176
3732.37	180
3734.59	186
3736.81	180
3739.03	174
3741.24	188
3743.46	196
3745.68	176
3747.89	176
3750.11	176
3752.32	170
3754.53	174
3756.74	200
3758.95	186
3761.16	174
3763.37	197.961
3765.58	179.776
3767.79	170.978
3769.99	179.523
3772.2	176.383
3774.4	174.721
3776.61	293.978
3778.81	179.258
3781.01	170.378
3783.21	183.728
3785.41	185.864
3787.61	173.071
3789.81	169.215
3792	169.136
3794.2	169.821
3796.4	177.457
3798.59	168.55
3800.78	171.554
3802.98	176.117
3805.17	172.013
3807.36	168.267
3809.55	175.932
3811.74	175.239
3813.93	170.936
3816.11	170.345
3818.3	165.242
3820.49	171.129
3822.67	166.761
3824.85	158.387
3827.04	160.986
3829.22	171.718
3831.4	174.311
3833.58	172.835
3835.76	175.86
3837.94	163.981
3839.98	168
3842.17	186
3844.36	184
3846.55	174
3848.73	160
3850.92	152
3853.1	154
3855.29	178
3857.47	182
3859.65	158
3861.84	156
3864.02	168
3866.2	150
3868.38	152
3870.55	172
3872.73	152
3874.91	158
3877.08	176
3879.26	172
3881.43	164
3883.6	160
3885.78	164
3887.95	148
3890.12	160
3892.29	158
3894.46	152
3896.63	152
3898.79	146
3900.96	144
3903.12	156
3905.29	168
3907.45	164
3909.61	154
3911.78	160
3913.94	162
3916.1	152
3918.26	174
3920.41	146
3922.57	176
3924.73	142
3926.88	156
3929.04	154
3931.19	162
3933.35	166
3935.5	152
3937.65	162
3939.8	154
3941.95	166
3944.1	160
3946.25	158
3948.4	162
3950.54	144
3952.69	158
3954.83	146
3956.98	146
3959.12	152
3961.26	162
3963.4	152
3965.54	136
3967.68	150
3969.82	146
3971.96	146
3974.1	138
3976.23	146
3978.37	156
3980.5	174
3982.64	150
3984.77	138
3986.9	152
3989.03	152
3991.16	168
3993.29	150
3995.42	140
3997.55	164
3999.67	132