File: muestras/si/Si_nano_muestra 3_57.txt
#Acq. time (s)=	10
#Accumulations=	2
#Range (cm-¹)=	100...1000
#Windows=	1
#Autofocus=	Off
#AutoExposure=	Off
#Spike filter=	Multiple accum.
#Delay time (s)=	0
#Binning=	1
#Readout mode=	Signal
#DeNoise=	Off
#ICS correction=	Off
#Dark correction=	Off
#Inst. Process=	Off
#Instrument=	LabRAM HR Evol
#Detector=	Syncerity OE
#Objective=	x100_VIS_LWD
#Grating=	600 (500nm)
#ND Filter=	100%
#Laser=	633nm_Edge
#Hole=	89.9762
#Range=	Visible
#Project=	Omar
#Sample=	Si_Nano
#Site=	21_03_2023
#Title=	Si_nano_muestra 3
#Remark=
#Date=	21.03.2023 11:32
#Acquired=	21.03.2023 11:32:18
100.741	31472
102.025	31632
103.308	31560
104.591	31414
105.874	31848
107.157	31622
108.439	31942
109.721	32026
111.003	31712
112.285	32172
113.567	31990
114.848	32090
116.129	32144
117.41	32058
118.691	32374
119.972	32404
121.252	32540
122.532	32594
123.812	32406
125.092	32534
126.371	32816
127.651	32806
128.93	32780
130.209	32826
131.487	32890
132.766	32966
134.044	33178
135.322	33220
136.6	32980
137.878	33124
139.155	32942
140.432	33310
141.709	33202
142.984	33106
144.261	33294
145.537	33446
146.814	33318
148.09	33550
149.365	33480
150.641	33752
151.915	33538
153.19	33628
154.465	33724
155.74	33558
157.014	33846
158.287	33788
159.561	33958
160.835	33882
162.109	34068
163.382	34194
164.654	34126
165.927	34186
167.2	34028
168.472	34144
169.743	34094
171.016	34026
172.288	34158
173.558	34112
174.83	34344
176.101	34006
177.371	34022
178.642	34072
179.912	34098
181.182	34156
182.452	34118
183.722	34454
184.991	34584
186.26	34668
187.53	34360
188.798	34374
190.067	34358
191.334	34740
192.603	34748
193.871	34676
195.138	34992
196.406	34960
197.673	35008
198.94	34952
200.208	35076
201.474	35108
202.741	35360
204.006	35512
205.273	35548
206.538	35664
207.804	35768
209.069	35704
210.335	35806
211.599	36026
212.864	35856
214.128	36084
215.393	35942
216.656	35824
217.919	35976
219.184	35910
220.446	36300
221.71	36324
222.973	36100
224.236	36480
225.498	36338
226.76	36294
228.023	36516
229.284	36452
230.547	36988
231.808	36888
233.068	36810
234.33	36868
235.59	37102
236.851	37258
238.112	37214
239.372	37232
240.631	37418
241.892	37394
243.151	37628
244.41	37648
245.668	37598
246.928	37588
248.186	37772
249.444	38064
250.702	37800
251.961	37904
253.219	37844
254.476	37812
255.733	38008
256.991	37906
258.248	37996
259.504	37976
260.76	38068
262.016	37832
263.274	38060
264.529	37862
265.785	38026
267.04	37838
268.295	37860
269.549	37872
270.804	37956
272.06	37918
273.314	38022
274.568	37838
275.822	37828
277.075	38030
278.329	37878
279.582	38014
280.835	37930
282.088	38170
283.34	38426
284.592	38180
285.845	38418
287.098	38570
288.35	38624
289.601	39022
290.853	38726
292.104	38572
293.355	39088
294.605	39138
295.856	39100
297.106	39468
298.355	39096
299.605	39178
300.854	39556
302.104	39536
303.353	39804
304.602	39960
305.851	39784
307.1	40002
308.349	40118
309.597	40036
310.845	39994
312.093	40154
313.339	40372
314.587	40022
315.834	40268
317.081	40266
318.328	40200
319.575	40110
320.821	40594
322.066	40022
323.312	40240
324.558	40120
325.804	40562
327.049	40426
328.293	40392
329.538	40506
330.783	40552
332.028	40326
333.271	40672
334.515	40598
335.759	40440
337.003	40640
338.245	40864
339.489	40658
340.732	40786
341.974	40970
343.217	40838
344.459	40886
345.702	41072
346.943	40978
348.185	41130
349.425	41290
350.667	41180
351.908	41388
353.148	41174
354.389	41554
355.63	41510
356.869	41478
358.11	41674
359.349	41516
360.589	41666
361.829	41814
363.067	41850
364.307	41612
365.544	41904
366.784	41822
368.021	41868
369.26	41968
370.497	41942
371.735	41954
372.972	41938
374.21	41868
375.446	42052
376.683	41906
377.919	41786
379.156	41798
380.392	42024
381.629	42082
382.864	41662
384.1	41816
385.335	41750
386.569	41972
387.805	41732
389.039	41728
390.274	41968
391.508	41918
392.742	41916
393.976	41910
395.209	41920
396.444	41746
397.676	42116
398.909	42196
400.143	42050
401.375	42248
402.607	42372
403.839	42496
405.071	42650
406.303	42722
407.534	42922
408.766	43052
409.997	43094
411.228	43174
412.458	43188
413.69	43202
414.919	43246
416.149	43768
417.379	43734
418.61	43756
419.839	44058
421.068	44122
422.296	44366
423.525	44004
424.755	44418
425.983	44260
427.211	44140
428.439	44608
429.666	44584
430.894	44334
432.121	44834
433.349	44726
434.576	44696
435.803	44966
437.029	44892
438.255	44984
439.482	44942
440.707	45276
441.933	45184
443.158	45096
444.384	44798
445.609	45010
446.834	44758
448.058	45112
449.283	45014
450.507	45138
451.731	45044
452.955	44990
454.179	45078
455.402	45074
456.625	44866
457.848	44932
459.071	44916
460.294	45086
461.517	45262
462.739	45072
463.961	45066
465.183	45326
466.405	45212
467.626	45292
468.848	45096
470.067	45310
471.288	45492
472.509	45346
473.73	45304
474.95	45764
476.17	45586
477.39	45796
478.608	45792
479.828	45600
481.047	45908
482.267	45684
483.486	45800
484.703	45818
485.922	46136
487.14	46316
488.358	45942
489.576	45842
490.793	46498
492.01	46242
493.228	46670
494.444	46530
495.661	46340
496.878	46686
498.094	46676
499.309	46636
500.526	46474
501.742	46922
502.956	46748
504.172	47062
505.388	46924
506.601	47066
507.817	46864
509.032	47074
510.245	46960
511.459	46918
512.672	47132
513.887	47310
515.101	47762
516.313	47538
517.526	47624
518.738	47582
519.952	47510
521.163	47276
522.376	47062
523.587	47040
524.8	46850
526.011	46692
527.223	46526
528.433	46690
529.645	46274
530.855	46280
532.066	46248
533.276	46566
534.487	46178
535.696	46242
536.906	46408
538.115	46330
539.326	46296
540.534	46288
541.742	46392
542.952	46218
544.16	46278
545.369	45886
546.577	46236
547.784	46300
548.993	46438
550.2	46086
551.406	46224
552.615	46390
553.821	46514
555.027	46192
556.235	46346
557.44	46276
558.646	46204
559.852	46428
561.058	46154
562.263	46692
563.468	46204
564.674	46536
565.879	46654
567.083	46484
568.287	46546
569.491	46652
570.697	46526
571.9	46550
573.103	46780
574.307	46774
575.51	46868
576.714	47054
577.916	46692
579.119	47056
580.321	46838
581.523	46918
582.725	46888
583.927	47086
585.13	46884
586.331	46816
587.532	46678
588.733	47088
589.934	47056
591.134	47086
592.334	47166
593.535	47050
594.734	47206
595.934	47252
597.134	47232
598.333	47596
599.532	47448
600.731	47516
601.93	47292
603.129	47558
604.327	47320
605.526	47770
606.724	47454
607.922	47630
609.119	47718
610.317	47880
611.514	47758
612.711	47920
613.908	47860
615.105	48166
616.301	48146
617.496	48138
618.693	48210
619.889	48164
621.084	48286
622.28	48308
623.475	48462
624.671	48708
625.864	48582
627.059	48710
628.254	48412
629.448	49044
630.643	48670
631.835	48990
633.029	48712
634.223	49264
635.417	49024
636.608	49220
637.802	49298
638.995	49468
640.187	49422
641.379	49232
642.571	49370
643.763	49610
644.955	49610
646.146	49576
647.337	49566
648.529	49624
649.719	49648
650.91	49780
652.101	49750
653.29	49616
654.481	49498
655.67	49348
656.86	49566
658.05	49714
659.238	49804
660.428	49760
661.616	49736
662.805	49684
663.994	49578
665.182	49718
666.37	49648
667.557	49898
668.746	49870
669.932	49984
671.12	49732
672.307	49810
673.494	49572
674.68	49806
675.867	49522
677.053	49600
678.24	49812
679.425	49996
680.612	49876
681.796	49850
682.981	49652
684.167	49782
685.351	49650
686.537	49758
687.721	49866
688.904	50014
690.089	49864
691.273	50006
692.456	49812
693.64	49724
694.823	49680
696.007	49674
697.19	50042
698.372	49628
699.554	49948
700.737	49906
701.919	50250
703.101	50264
704.283	49768
705.464	49880
706.645	50014
707.826	49934
709.008	50310
710.189	50382
711.369	50230
712.549	50202
713.73	50386
714.91	50390
716.089	50538
717.269	50644
718.448	50244
719.627	50496
720.807	50676
721.985	50542
723.164	50798
724.342	50742
725.52	50558
726.698	50858
727.875	50774
729.053	50620
730.23	50508
731.409	50570
732.586	50690
733.762	50748
734.939	50846
736.115	50798
737.291	50858
738.467	50930
739.643	50934
740.819	50926
741.994	50896
743.17	50682
744.345	51116
745.52	50924
746.694	50848
747.869	51132
749.043	50844
750.217	50930
751.391	50864
752.564	50876
753.737	50742
754.911	51004
756.084	50758
757.257	51088
758.43	51024
759.603	50984
760.775	51138
761.948	51036
763.118	50926
764.29	51038
765.462	50738
766.634	50850
767.805	51038
768.976	51028
770.146	50914
771.317	50962
772.488	51044
773.658	50872
774.827	51162
775.997	50858
777.167	50906
778.337	50928
779.505	51164
780.674	51262
781.844	51120
783.011	50666
784.18	51154
785.349	51048
786.516	50998
787.684	51000
788.853	51406
790.019	51400
791.187	51270
792.355	51264
793.521	50976
794.688	51382
795.855	50968
797.02	51158
798.187	51122
799.352	51468
800.518	51466
801.683	51260
802.849	51332
804.015	51338
805.179	51300
806.345	51472
807.509	51362
808.674	51682
809.837	51722
811.002	51924
812.165	51556
813.329	51816
814.492	51780
815.655	52060
816.818	51780
817.981	52256
819.144	52182
820.306	52156
821.469	52356
822.631	52310
823.792	52228
824.955	52106
826.115	52542
827.276	52378
828.438	52502
829.599	52512
830.76	52690
831.92	53024
833.08	52628
834.24	52756
835.401	52598
836.56	53046
837.72	52896
838.88	52834
840.039	53152
841.197	53120
842.356	53232
843.515	52966
844.674	53054
845.831	53022
846.989	53426
848.148	53292
849.306	53098
850.463	53140
851.62	53304
852.777	53426
853.933	53388
855.091	53364
856.247	53414
857.404	53558
858.56	53548
859.715	53526
860.871	53828
862.026	53516
863.182	53732
864.338	53560
865.493	53892
866.648	54042
867.802	53752
868.957	53670
870.111	53788
871.265	53808
872.419	53816
873.572	53724
874.726	53914
875.879	53986
877.032	53920
878.185	53818
879.338	53578
880.49	53660
881.643	53682
882.795	53420
883.947	53624
885.097	53626
886.249	53934
887.401	53424
888.552	53452
889.703	53808
890.854	53694
892.005	53778
893.155	53778
894.306	53230
895.455	53536
896.605	53524
897.755	53362
898.904	53354
900.054	53442
901.202	53444
902.351	53648
903.5	53240
904.649	53292
905.798	53564
906.945	53118
908.093	53448
909.241	53330
910.389	53220
911.536	53360
912.683	53370
913.831	53578
914.977	53394
916.124	53416
917.27	53632
918.416	53786
919.562	53538
920.709	53488
921.854	53434
923	53718
924.145	53722
925.29	53642
926.435	53672
927.579	53822
928.724	53762
929.868	53714
931.013	53758
932.157	53824
933.3	54092
934.445	53686
935.587	53910
936.731	54190
937.874	54188
939.017	54138
940.159	54086
941.302	53958
942.444	54292
943.587	54336
944.728	54420
945.871	54594
947.012	54650
948.152	54480
949.294	54680
950.435	54748
951.576	54906
952.716	54894
953.856	54870
954.997	54844
956.137	54948
957.276	54568
958.417	54974
959.556	54848
960.695	55292
961.835	55216
962.973	55248
964.112	55590
965.251	55262
966.389	55498
967.527	55186
968.666	55542
969.804	55298
970.941	55345
972.078	55392
973.215	55566
974.353	55608
975.49	55478
976.626	55406
977.762	55624
978.898	55392
980.036	55416
981.171	55456
982.307	55374
983.442	55850
984.577	55706
985.712	55808
986.847	55750
987.983	55602
989.118	55710
990.252	55866
991.386	55174
992.52	55992
993.654	55442
994.788	55618
995.921	55462
997.055	55554
998.188	55718
999.321	55752