File: muestras/billete_e/Organic_07.txt
#Acq. time (s)=	15
#Accumulations=	1
#Range (cm-¹)=	100...2000
#Windows=	2
#Autofocus=	Off
#AutoExposure=	Off
#Spike filter=	Off
#Delay time (s)=	0
#Binning=	1
#Readout mode=	Signal
#DeNoise=	Off
#ICS correction=	Off
#Dark correction=	Off
#Inst. Process=	Off
#Instrument=	LabRAM HR Evol
#Detector=	Syncerity OE
#Objective=	x100_VIS
#Grating=	600 (500nm)
#ND Filter=	25%
#Laser=	633nm_Edge
#Hole=	49.98
#Range=	Visible
#Project=	Omar
#Sample=	20-06-23
#Site=	3
#Title=	Organic
#Remark=
#Date=	20.06.2023 12:20
#Acquired=	20.06.2023 12:20:18
101.054	5352
103.621	5438
106.187	5354
108.752	5492
111.317	5484
113.881	5508
116.443	5504
119.005	5494
121.566	5620
124.126	5696
126.685	5686
129.243	5826
131.801	5884
134.356	5900
136.911	5934
139.466	5890
142.021	5938
144.574	5924
147.125	6078
149.676	6000
152.227	6144
154.776	6102
157.325	6202
159.873	6158
162.419	6168
164.966	6278
167.51	6342
170.055	6242
172.598	6362
175.141	6308
177.682	6364
180.222	6340
182.763	6534
185.302	6510
187.839	6658
190.376	6554
192.914	6604
195.449	6564
197.983	6772
200.517	6788
203.05	6834
205.582	6866
208.113	6860
210.643	6990
213.173	6996
215.701	6986
218.229	7148
220.756	7154
223.282	7206
225.808	7344
228.331	7292
230.855	7426
233.378	7552
235.898	7562
238.419	7538
240.94	7598
243.458	7748
245.977	7708
248.495	7828
251.011	7860
253.527	7908
256.041	7876
258.555	7906
261.068	8068
263.58	7926
266.092	7988
268.603	8024
271.112	8080
273.62	8050
276.129	8064
278.636	8178
281.142	8236
283.647	8328
286.152	8390
288.655	8534
291.158	8424
293.66	8574
296.161	8610
298.661	8828
301.161	8834
303.66	8992
306.158	8968
308.655	9026
311.15	8988
313.645	9258
316.14	9248
318.634	9184
321.125	9302
323.618	9346
326.109	9364
328.598	9314
331.088	9368
333.576	9520
336.064	9506
338.55	9628
341.037	9634
343.521	9660
346.005	9824
348.489	9876
350.971	9904
353.453	9936
355.933	10070
358.414	10128
360.893	10188
363.371	10108
365.848	10212
368.325	10320
370.801	10272
373.275	10294
375.75	10496
378.223	10480
380.695	10582
383.167	10594
385.638	10596
388.108	10676
390.577	10558
393.044	10830
395.512	10822
397.979	10944
400.444	11024
402.909	11030
405.374	11176
407.836	11324
410.299	11422
412.76	11574
415.221	11604
417.681	11750
420.141	11726
422.598	11716
425.057	11904
427.513	11890
429.968	12116
432.422	11958
434.878	12076
437.33	12202
439.783	12198
442.234	12356
444.685	12442
447.134	12360
449.583	12228
452.032	12594
454.479	12250
456.926	12534
459.372	12586
461.817	12516
464.261	12848
466.705	12700
469.147	12888
471.588	12880
474.029	13036
476.47	13040
478.909	13030
481.347	13240
483.785	13478
486.221	13576
488.657	13290
491.092	13470
493.527	13582
495.96	13716
498.393	13896
500.824	13820
503.255	13882
505.686	13898
508.115	13868
510.543	13938
512.972	14070
515.399	14098
517.825	14216
520.25	14116
522.674	14210
525.097	14204
527.52	14290
529.942	14220
532.364	14292
534.784	14404
537.204	14364
539.623	14412
542.041	14690
544.457	14602
546.874	14702
549.289	14686
551.705	14852
554.118	14830
556.531	15096
558.943	14862
561.355	15168
563.766	15258
566.175	15014
568.585	15180
570.992	15350
573.399	15404
575.807	15484
578.212	15494
580.617	15594
583.022	15630
585.425	15582
587.827	15554
590.229	15696
592.63	15858
595.03	15816
597.43	15890
599.829	16006
602.226	16188
604.623	16082
607.02	16276
609.414	16316
611.808	16438
614.202	16340
616.596	16592
618.988	16740
621.378	16782
623.769	16794
626.159	16836
628.548	17092
630.936	16992
633.324	16918
635.71	17130
638.096	17242
640.481	17388
642.866	17410
645.248	17612
647.63	17552
650.013	17628
652.394	17634
654.773	17806
657.154	17742
659.532	17826
661.91	17848
664.286	17670
666.663	17864
669.038	17782
671.412	17904
673.786	17710
676.159	18024
678.532	17950
680.903	18000
683.274	18130
685.644	18124
688.014	18136
690.381	18052
692.749	18150
695.116	18266
697.481	18226
699.846	18348
702.211	18260
704.574	18186
706.938	18324
709.299	18362
711.661	18552
714.021	18606
716.381	18586
718.739	18676
721.097	18722
723.455	18686
725.811	18814
728.167	18800
730.521	18884
732.875	18822
735.23	18942
737.582	18978
739.934	18854
742.285	19244
744.635	19078
746.985	18904
749.332	19012
751.68	19084
754.028	19236
756.374	19148
758.72	19074
761.065	19072
763.408	19182
765.752	18988
768.095	19148
770.436	19158
772.777	19242
775.116	19334
777.456	19276
779.794	19304
782.133	19366
784.469	19262
786.805	19354
789.141	19434
791.476	19550
793.809	19312
796.142	19460
798.476	19210
800.807	19384
803.138	19602
805.468	19514
807.797	19656
810.125	19628
812.453	19776
814.78	19856
817.106	19696
819.432	19910
821.757	19840
824.08	19916
826.403	20122
828.726	20082
831.048	19906
833.368	20092
835.688	20094
838.007	20162
840.326	20154
842.644	20164
844.96	20276
847.276	20320
849.592	20146
851.906	20316
854.221	20268
856.534	20200
858.846	20392
861.157	20254
863.469	20294
865.779	20274
868.088	20308
870.396	20312
872.704	20218
875.011	20306
877.318	20416
879.623	20148
881.928	20216
884.232	20032
886.536	20106
888.837	20084
891.139	20094
893.44	20200
895.741	20132
898.039	19818
900.339	20042
902.637	19844
904.933	19890
907.231	19850
909.526	19716
911.821	19644
914.115	19762
916.408	19894
918.701	19818
920.993	19844
923.283	19864
925.573	19764
927.864	19832
930.153	19870
932.441	19752
934.728	19754
937.014	19882
939.3	19818
941.585	19690
943.87	19844
946.154	19800
948.437	19920
950.719	19870
952.999	19650
955.28	19786
957.56	19914
959.84	19866
962.117	19884
964.395	19770
966.671	19692
968.948	19850
971.223	19858
973.498	19712
975.771	19806
978.045	19814
980.317	19602
982.588	19700
984.86	19674
987.13	19682
989.399	19610
991.667	19528
993.937	19370
996.204	19478
998.47	19368
1000.74	19440
1003	19570
1005.26	19358
1007.53	19244
1009.79	19340
1012.05	19210
1014.31	19310
1016.57	19302
1018.83	19206
1021.09	19288
1023.35	19314
1025.61	19144
1027.87	19286
1030.12	19184
1032.38	19406
1034.63	19248
1036.88	19200
1039.14	19230
1041.39	19026
1043.64	19136
1045.89	19168
1048.14	19094
1050.39	19060
1052.64	19014
1054.89	18994
1057.14	18924
1059.38	18870
1061.63	18896
1063.87	18838
1066.12	18930
1068.36	18710
1070.6	18524
1072.85	18654
1075.09	18666
1077.33	18440
1079.57	18498
1081.81	18374
1084.05	18418
1086.28	18230
1088.52	18214
1090.76	18104
1092.99	17808
1095.23	17976
1097.46	17824
1099.69	17798
1101.93	17550
1104.16	17740
1106.39	17552
1108.62	17574
1110.85	17462
1113.08	17438
1115.31	17496
1117.53	17512
1119.76	17448
1121.99	17326
1124.21	17176
1126.44	17172
1128.66	17228
1130.88	17340
1133.11	17160
1135.33	17208
1137.55	17158
1139.77	17050
1141.99	16890
1144.21	17058
1146.43	17102
1148.64	16970
1150.86	16876
1153.08	16990
1155.29	17022
1157.51	16974
1159.72	17002
1161.93	16914
1164.14	16882
1166.36	16862
1168.57	16784
1170.78	16600
1172.99	16816
1175.2	16652
1177.4	16624
1179.61	16534
1181.82	16438
1184.02	16258
1186.23	16352
1188.43	16280
1190.64	16182
1192.84	16162
1195.04	15954
1197.24	16190
1199.45	15962.6
1201.64	15855.8
1203.84	15688
1206.04	15779
1208.24	15628.2
1210.44	15519.4
1212.64	15635.1
1214.83	15302.5
1217.03	15403.4
1219.22	15191.2
1221.41	15143.4
1223.61	15139.4
1225.8	15111.5
1227.99	14942.4
1230.18	14922.5
1232.37	14888.3
1234.56	14847.2
1236.75	14739.9
1238.94	14884.7
1241.13	14611.8
1243.31	14685.7
1245.5	14635.5
1247.68	14533.5
1249.87	14514.2
1252.05	14472.5
1254.24	14501.8
1256.42	14461.3
1258.6	14370.1
1260.78	14479.4
1262.96	14301.8
1265.14	14289.6
1267.32	14205.9
1269.5	14167.9
1271.67	14139.5
1273.85	14026.2
1276.03	13992.1
1278.2	13966.4
1280.38	13916.2
1282.55	13900.6
1284.72	13843.5
1286.9	13804.1
1289.07	13810.5
1291.24	13770.8
1293.41	13739.7
1295.58	13674.3
1297.75	13645
1299.92	13546.8
1302.09	13578.4
1304.25	13528.8
1306.42	13341.3
1308.46	13356
1310.63	13280
1312.81	13288
1314.98	13382
1317.16	13206
1319.33	13110
1321.5	13106
1323.67	12852
1325.85	12820
1328.02	12762
1330.19	12766
1332.35	12794
1334.52	12734
1336.69	12756
1338.86	12788
1341.02	12638
1343.19	12598
1345.35	12572
1347.52	12408
1349.68	12502
1351.84	12328
1354	12370
1356.17	12302
1358.33	12244
1360.49	12232
1362.65	12116
1364.8	12154
1366.96	12108
1369.12	12070
1371.28	11978
1373.43	11936
1375.59	11886
1377.74	11968
1379.89	11876
1382.05	11808
1384.2	11860
1386.35	11672
1388.5	11710
1390.65	11596
1392.8	11620
1394.95	11634
1397.1	11474
1399.25	11496
1401.4	11312
1403.54	11340
1405.69	11314
1407.83	11188
1409.98	11238
1412.12	11234
1414.26	11088
1416.4	11156
1418.55	11054
1420.69	11048
1422.83	10974
1424.97	10920
1427.1	10868
1429.24	10720
1431.38	10830
1433.52	10766
1435.65	10800
1437.79	10758
1439.92	10586
1442.06	10654
1444.19	10564
1446.32	10484
1448.46	10516
1450.59	10400
1452.72	10442
1454.85	10382
1456.98	10416
1459.11	10214
1461.23	10486
1463.36	10400
1465.49	10312
1467.61	10204
1469.74	10250
1471.86	10212
1473.99	10134
1476.11	10142
1478.23	10046
1480.36	10098
1482.48	10008
1484.6	9810
1486.72	10006
1488.84	9902
1490.96	9890
1493.07	9814
1495.19	9832
1497.31	9764
1499.42	9698
1501.54	9600
1503.65	9564
1505.77	9638
1507.88	9462
1509.99	9438
1512.1	9426
1514.22	9414
1516.33	9164
1518.44	9342
1520.55	9272
1522.65	9150
1524.76	9138
1526.87	9194
1528.98	9104
1531.08	9058
1533.19	8942
1535.29	8916
1537.4	8956
1539.5	8868
1541.6	8856
1543.7	8774
1545.8	8884
1547.91	8758
1550.01	8614
1552.11	8722
1554.2	8668
1556.3	8600
1558.4	8426
1560.5	8510
1562.59	8414
1564.69	8430
1566.78	8480
1568.88	8452
1570.97	8362
1573.06	8538
1575.15	8348
1577.25	8332
1579.34	8274
1581.43	8282
1583.52	8238
1585.6	8182
1587.69	8098
1589.78	8118
1591.87	8230
1593.95	8208
1596.04	8138
1598.12	7964
1600.21	8020
1602.29	8028
1604.37	7964
1606.46	7950
1608.54	7896
1610.62	7918
1612.7	7874
1614.78	7804
1616.86	7792
1618.94	7824
1621.01	7814
1623.09	7828
1625.17	7674
1627.24	7728
1629.32	7668
1631.39	7710
1633.47	7578
1635.54	7526
1637.61	7630
1639.68	7646
1641.76	7582
1643.83	7500
1645.9	7582
1647.96	7510
1650.03	7386
1652.1	7368
1654.17	7322
1656.24	7302
1658.3	7300
1660.37	7336
1662.43	7234
1664.5	7196
1666.56	7150
1668.62	7186
1670.68	7168
1672.75	7078
1674.81	7012
1676.87	7056
1678.93	6894
1680.99	6996
1683.04	6958
1685.1	6954
1687.16	6816
1689.21	6878
1691.27	6844
1693.33	6734
1695.38	6818
1697.43	6796
1699.49	6786
1701.54	6756
1703.59	6712
1705.64	6552
1707.69	6662
1709.74	6618
1711.79	6598
1713.84	6536
1715.89	6546
1717.94	6576
1719.98	6572
1722.03	6528
1724.07	6584
1726.12	6522
1728.16	6324
1730.21	6454
1732.25	6498
1734.29	6330
1736.33	6338
1738.37	6398
1740.41	6344
1742.45	6304
1744.49	6310
1746.53	6258
1748.57	6304
1750.61	6258
1752.64	6220
1754.68	6216
1756.71	6136
1758.75	6204
1760.78	6252
1762.82	6160
1764.85	6094
1766.88	6032
1768.91	6064
1770.94	6004
1772.97	6096
1775	6134
1777.03	5986
1779.06	5986
1781.09	6010
1783.12	5942
1785.14	5876
1787.17	5978
1789.19	5942
1791.22	5946
1793.24	5854
1795.27	5800
1797.29	5792
1799.31	5792
1801.33	5798
1803.35	5792
1805.37	5812
1807.39	5700
1809.41	5754
1811.43	5760
1813.45	5700
1815.46	5730
1817.48	5736
1819.5	5648
1821.51	5656
1823.53	5572
1825.54	5616
1827.55	5468
1829.57	5408
1831.58	5532
1833.59	5460
1835.6	5498
1837.61	5562
1839.62	5326
1841.63	5356
1843.64	5346
1845.65	5398
1847.65	5394
1849.66	5264
1851.66	5224
1853.67	5332
1855.67	5276
1857.68	5222
1859.68	5268
1861.68	5318
1863.69	5238
1865.69	5192
1867.69	5206
1869.69	5202
1871.69	5168
1873.69	5136
1875.69	5216
1877.68	5094
1879.68	5144
1881.68	5186
1883.67	5102
1885.67	5188
1887.66	5018
1889.66	5126
1891.65	5066
1893.64	5008
1895.64	5004
1897.63	5034
1899.62	5082
1901.61	5022
1903.6	5058
1905.59	4996
1907.58	4958
1909.56	5058
1911.55	4912
1913.54	5018
1915.53	4914
1917.51	4910
1919.5	4966
1921.48	4862
1923.46	4942
1925.45	4886
1927.43	4924
1929.41	4968
1931.39	4794
1933.37	4798
1935.35	4800
1937.33	4792
1939.31	4772
1941.29	4752
1943.27	4846
1945.24	4780
1947.22	4764
1949.2	4882
1951.17	4722
1953.14	4714
1955.12	4774
1957.09	4652
1959.06	4644
1961.04	4658
1963.01	4646
1964.98	4558
1966.95	4606
1968.92	4534
1970.89	4656
1972.86	4546
1974.82	4598
1976.79	4548
1978.76	4524
1980.72	4570
1982.69	4426
1984.65	4502
1986.62	4456
1988.58	4408
1990.54	4480
1992.51	4444
1994.47	4440
1996.43	4404
1998.39	4538
1999.37	4462