File: muestras/billete_e/Organic_11.txt
#Acq. time (s)=	15
#Accumulations=	1
#Range (cm-¹)=	100...2000
#Windows=	2
#Autofocus=	Off
#AutoExposure=	Off
#Spike filter=	Off
#Delay time (s)=	0
#Binning=	1
#Readout mode=	Signal
#DeNoise=	Off
#ICS correction=	Off
#Dark correction=	Off
#Inst. Process=	Off
#Instrument=	LabRAM HR Evol
#Detector=	Syncerity OE
#Objective=	x100_VIS
#Grating=	600 (500nm)
#ND Filter=	50%
#Laser=	633nm_Edge
#Hole=	74.97
#Range=	Visible
#Project=	Omar
#Sample=	20-06-23
#Site=	3
#Title=	Organic
#Remark=
#Date=	20.06.2023 12:30
#Acquired=	20.06.2023 12:30:07
101.054	2920
103.621	2958
106.187	2904
108.752	2852
111.317	2898
113.881	2880
116.443	2926
119.005	2898
121.566	2846
124.126	2856
126.685	2866
129.243	2898
131.801	2912
134.356	2878
136.911	2868
139.466	2896
142.021	2874
144.574	2856
147.125	2886
149.676	2812
152.227	2848
154.776	2852
157.325	2812
159.873	2834
162.419	2822
164.966	2854
167.51	2770
170.055	2804
172.598	2780
175.141	2756
177.682	2756
180.222	2730
182.763	2720
185.302	2672
187.839	2686
190.376	2752
192.914	2716
195.449	2704
197.983	2740
200.517	2708
203.05	2728
205.582	2730
208.113	2688
210.643	2712
213.173	2714
215.701	2666
218.229	2658
220.756	2680
223.282	2666
225.808	2674
228.331	2690
230.855	2728
233.378	2688
235.898	2696
238.419	2660
240.94	2710
243.458	2568
245.977	2650
248.495	2644
251.011	2600
253.527	2638
256.041	2670
258.555	2644
261.068	2562
263.58	2522
266.092	2552
268.603	2532
271.112	2536
273.62	2502
276.129	2492
278.636	2494
281.142	2428
283.647	2468
286.152	2438
288.655	2552
291.158	2522
293.66	2444
296.161	2508
298.661	2512
301.161	2502
303.66	2522
306.158	2544
308.655	2454
311.15	2416
313.645	2416
316.14	2428
318.634	2410
321.125	2400
323.618	2428
326.109	2414
328.598	2420
331.088	2400
333.576	2416
336.064	2412
338.55	2328
341.037	2358
343.521	2390
346.005	2330
348.489	2338
350.971	2278
353.453	2384
355.933	2328
358.414	2344
360.893	2256
363.371	2300
365.848	2308
368.325	2314
370.801	2310
373.275	2244
375.75	2248
378.223	2256
380.695	2206
383.167	2150
385.638	2196
388.108	2204
390.577	2248
393.044	2218
395.512	2184
397.979	2190
400.444	2192
402.909	2190
405.374	2166
407.836	2204
410.299	2162
412.76	2250
415.221	2142
417.681	2170
420.141	2172
422.598	2240
425.057	2190
427.513	2152
429.968	2136
432.422	2190
434.878	2172
437.33	2210
439.783	2180
442.234	2240
444.685	2110
447.134	2140
449.583	2098
452.032	2128
454.479	2150
456.926	2130
459.372	2078
461.817	2124
464.261	2140
466.705	2086
469.147	2194
471.588	2098
474.029	2104
476.47	2074
478.909	2134
481.347	2140
483.785	2110
486.221	2092
488.657	2118
491.092	2160
493.527	2082
495.96	2068
498.393	2106
500.824	2102
503.255	2166
505.686	2086
508.115	2156
510.543	2126
512.972	2062
515.399	2082
517.825	2140
520.25	2092
522.674	2102
525.097	2060
527.52	2030
529.942	2032
532.364	2026
534.784	1998
537.204	2084
539.623	2078
542.041	2012
544.457	2064
546.874	2042
549.289	2058
551.705	2076
554.118	2006
556.531	2062
558.943	2028
561.355	2004
563.766	2048
566.175	2072
568.585	2032
570.992	2030
573.399	2088
575.807	2120
578.212	2010
580.617	2046
583.022	2060
585.425	2070
587.827	2020
590.229	2052
592.63	2076
595.03	2056
597.43	2102
599.829	2052
602.226	2066
604.623	2102
607.02	2002
609.414	2076
611.808	2088
614.202	2086
616.596	2084
618.988	2054
621.378	2146
623.769	2094
626.159	2014
628.548	2066
630.936	2090
633.324	2116
635.71	2080
638.096	2112
640.481	2118
642.866	2156
645.248	2130
647.63	2156
650.013	2118
652.394	2140
654.773	2174
657.154	2122
659.532	2130
661.91	2092
664.286	2082
666.663	2148
669.038	2174
671.412	2092
673.786	2132
676.159	2132
678.532	2148
680.903	2052
683.274	2060
685.644	2136
688.014	2176
690.381	2170
692.749	2106
695.116	2108
697.481	2106
699.846	2118
702.211	2138
704.574	2062
706.938	2142
709.299	2086
711.661	2092
714.021	2210
716.381	2152
718.739	2122
721.097	2134
723.455	2164
725.811	2106
728.167	2156
730.521	2118
732.875	2172
735.23	2112
737.582	2132
739.934	2190
742.285	2104
744.635	2120
746.985	2106
749.332	2090
751.68	2144
754.028	2152
756.374	2130
758.72	2156
761.065	2128
763.408	2096
765.752	2130
768.095	2170
770.436	2144
772.777	2166
775.116	2154
777.456	2124
779.794	2090
782.133	2080
784.469	2136
786.805	2152
789.141	2046
791.476	2110
793.809	2210
796.142	2126
798.476	2124
800.807	2154
803.138	2164
805.468	2146
807.797	2096
810.125	2140
812.453	2152
814.78	2120
817.106	2116
819.432	2174
821.757	2162
824.08	2134
826.403	2138
828.726	2160
831.048	2176
833.368	2132
835.688	2172
838.007	2134
840.326	2170
842.644	2178
844.96	2186
847.276	2156
849.592	2202
851.906	2220
854.221	2186
856.534	2110
858.846	2226
861.157	2198
863.469	2190
865.779	2200
868.088	2092
870.396	2138
872.704	2192
875.011	2140
877.318	2190
879.623	2126
881.928	2134
884.232	2132
886.536	2142
888.837	2164
891.139	2206
893.44	2154
895.741	2098
898.039	2152
900.339	2128
902.637	2056
904.933	2112
907.231	2094
909.526	2116
911.821	2098
914.115	2044
916.408	2108
918.701	2160
920.993	2068
923.283	2052
925.573	2054
927.864	2128
930.153	2094
932.441	2038
934.728	2102
937.014	2070
939.3	2046
941.585	2100
943.87	2090
946.154	2110
948.437	2044
950.719	2082
952.999	2124
955.28	2132
957.56	2168
959.84	2062
962.117	2106
964.395	2146
966.671	2124
968.948	2118
971.223	2042
973.498	2078
975.771	2038
978.045	2086
980.317	2076
982.588	2058
984.86	2072
987.13	2084
989.399	2068
991.667	2062
993.937	2032
996.204	1992
998.47	2048
1000.74	2108
1003	2016
1005.26	2016
1007.53	2068
1009.79	2034
1012.05	2026
1014.31	2028
1016.57	2046
1018.83	2074
1021.09	2022
1023.35	1996
1025.61	2064
1027.87	2088
1030.12	2032
1032.38	2048
1034.63	1956
1036.88	2018
1039.14	2008
1041.39	1978
1043.64	1952
1045.89	1978
1048.14	1962
1050.39	1992
1052.64	2010
1054.89	2016
1057.14	1996
1059.38	1944
1061.63	2004
1063.87	1956
1066.12	1936
1068.36	1944
1070.6	1952
1072.85	1996
1075.09	1994
1077.33	1948
1079.57	1948
1081.81	1926
1084.05	1942
1086.28	1918
1088.52	1948
1090.76	1878
1092.99	1876
1095.23	1896
1097.46	1918
1099.69	1872
1101.93	1856
1104.16	1858
1106.39	1874
1108.62	1786
1110.85	1818
1113.08	1876
1115.31	1882
1117.53	1838
1119.76	1854
1121.99	1858
1124.21	1834
1126.44	1848
1128.66	1866
1130.88	1828
1133.11	1824
1135.33	1828
1137.55	1840
1139.77	1798
1141.99	1778
1144.21	1776
1146.43	1808
1148.64	1816
1150.86	1770
1153.08	1808
1155.29	1806
1157.51	1756
1159.72	1776
1161.93	1850
1164.14	1786
1166.36	1752
1168.57	1794
1170.78	1792
1172.99	1830
1175.2	1758
1177.4	1792
1179.61	1768
1181.82	1804
1184.02	1740
1186.23	1746
1188.43	1724
1190.64	1744
1192.84	1726
1195.04	1758
1197.24	1734
1199.45	1725.56
1201.64	1710.98
1203.84	1701.96
1206.04	1677.18
1208.24	1699.6
1210.44	1698.48
1212.64	1646.98
1214.83	1656.88
1217.03	1659.42
1219.22	1669.27
1221.41	1660.05
1223.61	1651.84
1225.8	1663.45
1227.99	1641.08
1230.18	1642.63
1232.37	1603.09
1234.56	1572.5
1236.75	1653.46
1238.94	1617.88
1241.13	1587.96
1243.31	1589.5
1245.5	1620.74
1247.68	1634.25
1249.87	1595.32
1252.05	1577.04
1254.24	1593
1256.42	1611.89
1258.6	1585.82
1260.78	1597.22
1262.96	1580.32
1265.14	1575.42
1267.32	1576.91
1269.5	1579.71
1271.67	1588.54
1273.85	1578.36
1276.03	1581.64
1278.2	1567.55
1280.38	1569.88
1282.55	1568.77
1284.72	1540.47
1286.9	1561.35
1289.07	1535.72
1291.24	1544.19
1293.41	1554.76
1295.58	1566.69
1297.75	1565.74
1299.92	1534.21
1302.09	1551.99
1304.25	1525.4
1306.42	1556.95
1308.46	1554
1310.63	1536
1312.81	1544
1314.98	1532
1317.16	1528
1319.33	1478
1321.5	1518
1323.67	1526
1325.85	1542
1328.02	1496
1330.19	1482
1332.35	1494
1334.52	1476
1336.69	1484
1338.86	1488
1341.02	1430
1343.19	1456
1345.35	1484
1347.52	1512
1349.68	1492
1351.84	1480
1354	1424
1356.17	1470
1358.33	1496
1360.49	1470
1362.65	1456
1364.8	1428
1366.96	1442
1369.12	1468
1371.28	1466
1373.43	1456
1375.59	1488
1377.74	1426
1379.89	1472
1382.05	1420
1384.2	1496
1386.35	1498
1388.5	1446
1390.65	1468
1392.8	1446
1394.95	1450
1397.1	1426
1399.25	1430
1401.4	1436
1403.54	1474
1405.69	1426
1407.83	1464
1409.98	1426
1412.12	1486
1414.26	1440
1416.4	1420
1418.55	1454
1420.69	1456
1422.83	1434
1424.97	1466
1427.1	1420
1429.24	1418
1431.38	1428
1433.52	1416
1435.65	1414
1437.79	1432
1439.92	1420
1442.06	1418
1444.19	1398
1446.32	1440
1448.46	1416
1450.59	1412
1452.72	1446
1454.85	1460
1456.98	1420
1459.11	1378
1461.23	1382
1463.36	1430
1465.49	1420
1467.61	1398
1469.74	1438
1471.86	1412
1473.99	1410
1476.11	1446
1478.23	1436
1480.36	1424
1482.48	1376
1484.6	1444
1486.72	1436
1488.84	1374
1490.96	1392
1493.07	1428
1495.19	1426
1497.31	1436
1499.42	1390
1501.54	1402
1503.65	1396
1505.77	1372
1507.88	1424
1509.99	1390
1512.1	1386
1514.22	1376
1516.33	1358
1518.44	1388
1520.55	1374
1522.65	1386
1524.76	1388
1526.87	1350
1528.98	1336
1531.08	1338
1533.19	1320
1535.29	1324
1537.4	1354
1539.5	1346
1541.6	1336
1543.7	1320
1545.8	1342
1547.91	1328
1550.01	1338
1552.11	1348
1554.2	1358
1556.3	1312
1558.4	1304
1560.5	1316
1562.59	1292
1564.69	1318
1566.78	1326
1568.88	1352
1570.97	1312
1573.06	1314
1575.15	1292
1577.25	1300
1579.34	1242
1581.43	1300
1583.52	1316
1585.6	1274
1587.69	1318
1589.78	1300
1591.87	1284
1593.95	1270
1596.04	1282
1598.12	1342
1600.21	1292
1602.29	1282
1604.37	1240
1606.46	1274
1608.54	1270
1610.62	1304
1612.7	1232
1614.78	1252
1616.86	1274
1618.94	1258
1621.01	1270
1623.09	1260
1625.17	1262
1627.24	1244
1629.32	1244
1631.39	1276
1633.47	1272
1635.54	1296
1637.61	1248
1639.68	1246
1641.76	1228
1643.83	1228
1645.9	1252
1647.96	1200
1650.03	1246
1652.1	1252
1654.17	1216
1656.24	1234
1658.3	1236
1660.37	1232
1662.43	1220
1664.5	1222
1666.56	1220
1668.62	1202
1670.68	1186
1672.75	1178
1674.81	1182
1676.87	1164
1678.93	1150
1680.99	1158
1683.04	1178
1685.1	1190
1687.16	1148
1689.21	1118
1691.27	1154
1693.33	1188
1695.38	1158
1697.43	1172
1699.49	1192
1701.54	1142
1703.59	1132
1705.64	1084
1707.69	1130
1709.74	1132
1711.79	1128
1713.84	1122
1715.89	1120
1717.94	1140
1719.98	1090
1722.03	1074
1724.07	1122
1726.12	1082
1728.16	1074
1730.21	1046
1732.25	1084
1734.29	1096
1736.33	1086
1738.37	1062
1740.41	1084
1742.45	1078
1744.49	1014
1746.53	1028
1748.57	1112
1750.61	1068
1752.64	1030
1754.68	1020
1756.71	1022
1758.75	1028
1760.78	1040
1762.82	1038
1764.85	1012
1766.88	1034
1768.91	1026
1770.94	1026
1772.97	1014
1775	1040
1777.03	978
1779.06	1034
1781.09	982
1783.12	1012
1785.14	964
1787.17	1002
1789.19	992
1791.22	1012
1793.24	962
1795.27	984
1797.29	958
1799.31	996
1801.33	948
1803.35	968
1805.37	944
1807.39	986
1809.41	922
1811.43	966
1813.45	960
1815.46	938
1817.48	932
1819.5	914
1821.51	896
1823.53	914
1825.54	926
1827.55	918
1829.57	902
1831.58	926
1833.59	874
1835.6	948
1837.61	908
1839.62	922
1841.63	914
1843.64	884
1845.65	868
1847.65	898
1849.66	900
1851.66	858
1853.67	848
1855.67	840
1857.68	872
1859.68	878
1861.68	858
1863.69	870
1865.69	852
1867.69	872
1869.69	848
1871.69	812
1873.69	820
1875.69	836
1877.68	822
1879.68	806
1881.68	842
1883.67	848
1885.67	786
1887.66	796
1889.66	800
1891.65	798
1893.64	806
1895.64	784
1897.63	820
1899.62	782
1901.61	778
1903.6	782
1905.59	800
1907.58	800
1909.56	796
1911.55	788
1913.54	782
1915.53	746
1917.51	756
1919.5	770
1921.48	760
1923.46	742
1925.45	770
1927.43	776
1929.41	768
1931.39	744
1933.37	772
1935.35	754
1937.33	754
1939.31	734
1941.29	732
1943.27	738
1945.24	738
1947.22	752
1949.2	762
1951.17	732
1953.14	704
1955.12	696
1957.09	706
1959.06	696
1961.04	718
1963.01	734
1964.98	702
1966.95	716
1968.92	712
1970.89	690
1972.86	702
1974.82	690
1976.79	676
1978.76	692
1980.72	650
1982.69	650
1984.65	662
1986.62	690
1988.58	662
1990.54	658
1992.51	652
1994.47	644
1996.43	662
1998.39	670
1999.37	634