File: muestras/billete_e/Organic_08.txt
#Acq. time (s)=	15
#Accumulations=	1
#Range (cm-¹)=	100...2000
#Windows=	2
#Autofocus=	Off
#AutoExposure=	Off
#Spike filter=	Off
#Delay time (s)=	0
#Binning=	1
#Readout mode=	Signal
#DeNoise=	Off
#ICS correction=	Off
#Dark correction=	Off
#Inst. Process=	Off
#Instrument=	LabRAM HR Evol
#Detector=	Syncerity OE
#Objective=	x100_VIS
#Grating=	600 (500nm)
#ND Filter=	25%
#Laser=	633nm_Edge
#Hole=	49.98
#Range=	Visible
#Project=	Omar
#Sample=	20-06-23
#Site=	3
#Title=	Organic
#Remark=
#Date=	20.06.2023 12:24
#Acquired=	20.06.2023 12:24:50
101.054	2694
103.621	2746
106.187	2732
108.752	2712
111.317	2784
113.881	2730
116.443	2682
119.005	2748
121.566	2712
124.126	2726
126.685	2754
129.243	2714
131.801	2770
134.356	2708
136.911	2758
139.466	2684
142.021	2700
144.574	2684
147.125	2694
149.676	2692
152.227	2680
154.776	2692
157.325	2706
159.873	2684
162.419	2670
164.966	2674
167.51	2712
170.055	2702
172.598	2680
175.141	2680
177.682	2656
180.222	2668
182.763	2658
185.302	2632
187.839	2642
190.376	2632
192.914	2618
195.449	2600
197.983	2670
200.517	2660
203.05	2634
205.582	2660
208.113	2654
210.643	2642
213.173	2698
215.701	2594
218.229	2688
220.756	2656
223.282	2634
225.808	2650
228.331	2594
230.855	2626
233.378	2662
235.898	2592
238.419	2608
240.94	2610
243.458	2668
245.977	2664
248.495	2620
251.011	2644
253.527	2672
256.041	2678
258.555	2618
261.068	2614
263.58	2588
266.092	2586
268.603	2616
271.112	2598
273.62	2570
276.129	2530
278.636	2518
281.142	2474
283.647	2544
286.152	2494
288.655	2508
291.158	2570
293.66	2536
296.161	2526
298.661	2582
301.161	2510
303.66	2578
306.158	2568
308.655	2544
311.15	2482
313.645	2460
316.14	2508
318.634	2438
321.125	2520
323.618	2470
326.109	2474
328.598	2482
331.088	2440
333.576	2446
336.064	2418
338.55	2452
341.037	2450
343.521	2460
346.005	2444
348.489	2428
350.971	2490
353.453	2390
355.933	2366
358.414	2428
360.893	2452
363.371	2386
365.848	2392
368.325	2384
370.801	2344
373.275	2274
375.75	2350
378.223	2338
380.695	2306
383.167	2330
385.638	2300
388.108	2298
390.577	2298
393.044	2338
395.512	2298
397.979	2340
400.444	2278
402.909	2284
405.374	2312
407.836	2256
410.299	2260
412.76	2294
415.221	2228
417.681	2238
420.141	2312
422.598	2276
425.057	2284
427.513	2310
429.968	2238
432.422	2292
434.878	2218
437.33	2296
439.783	2218
442.234	2214
444.685	2230
447.134	2230
449.583	2214
452.032	2192
454.479	2170
456.926	2176
459.372	2152
461.817	2144
464.261	2110
466.705	2154
469.147	2168
471.588	2180
474.029	2174
476.47	2158
478.909	2088
481.347	2126
483.785	2116
486.221	2096
488.657	2084
491.092	2040
493.527	2082
495.96	2134
498.393	2042
500.824	2086
503.255	2040
505.686	2034
508.115	2040
510.543	2050
512.972	2038
515.399	1964
517.825	2046
520.25	1982
522.674	1948
525.097	1988
527.52	2004
529.942	1944
532.364	1932
534.784	1930
537.204	1914
539.623	1922
542.041	1880
544.457	1872
546.874	1946
549.289	1874
551.705	1902
554.118	1878
556.531	1876
558.943	1816
561.355	1804
563.766	1858
566.175	1838
568.585	1816
570.992	1832
573.399	1724
575.807	1770
578.212	1790
580.617	1746
583.022	1798
585.425	1810
587.827	1738
590.229	1790
592.63	1776
595.03	1750
597.43	1752
599.829	1754
602.226	1758
604.623	1730
607.02	1712
609.414	1776
611.808	1726
614.202	1732
616.596	1712
618.988	1724
621.378	1716
623.769	1718
626.159	1714
628.548	1690
630.936	1684
633.324	1714
635.71	1654
638.096	1696
640.481	1730
642.866	1706
645.248	1688
647.63	1688
650.013	1700
652.394	1640
654.773	1644
657.154	1694
659.532	1636
661.91	1632
664.286	1636
666.663	1626
669.038	1664
671.412	1632
673.786	1592
676.159	1628
678.532	1580
680.903	1606
683.274	1624
685.644	1554
688.014	1542
690.381	1608
692.749	1538
695.116	1566
697.481	1544
699.846	1588
702.211	1516
704.574	1568
706.938	1584
709.299	1590
711.661	1554
714.021	1514
716.381	1530
718.739	1510
721.097	1518
723.455	1568
725.811	1518
728.167	1488
730.521	1462
732.875	1522
735.23	1512
737.582	1530
739.934	1502
742.285	1528
744.635	1440
746.985	1490
749.332	1468
751.68	1506
754.028	1454
756.374	1468
758.72	1498
761.065	1460
763.408	1462
765.752	1440
768.095	1448
770.436	1454
772.777	1436
775.116	1488
777.456	1420
779.794	1394
782.133	1432
784.469	1440
786.805	1428
789.141	1446
791.476	1506
793.809	1416
796.142	1444
798.476	1422
800.807	1442
803.138	1384
805.468	1478
807.797	1454
810.125	1424
812.453	1440
814.78	1390
817.106	1420
819.432	1438
821.757	1436
824.08	1474
826.403	1490
828.726	1446
831.048	1416
833.368	1474
835.688	1404
838.007	1442
840.326	1482
842.644	1414
844.96	1424
847.276	1394
849.592	1422
851.906	1448
854.221	1406
856.534	1458
858.846	1390
861.157	1460
863.469	1418
865.779	1438
868.088	1448
870.396	1432
872.704	1432
875.011	1440
877.318	1422
879.623	1448
881.928	1412
884.232	1420
886.536	1432
888.837	1422
891.139	1442
893.44	1436
895.741	1432
898.039	1402
900.339	1410
902.637	1426
904.933	1414
907.231	1380
909.526	1404
911.821	1410
914.115	1444
916.408	1428
918.701	1430
920.993	1408
923.283	1414
925.573	1452
927.864	1430
930.153	1400
932.441	1446
934.728	1414
937.014	1402
939.3	1450
941.585	1472
943.87	1432
946.154	1410
948.437	1434
950.719	1422
952.999	1448
955.28	1438
957.56	1448
959.84	1478
962.117	1438
964.395	1418
966.671	1444
968.948	1468
971.223	1448
973.498	1492
975.771	1460
978.045	1440
980.317	1428
982.588	1504
984.86	1444
987.13	1442
989.399	1476
991.667	1480
993.937	1468
996.204	1454
998.47	1454
1000.74	1456
1003	1458
1005.26	1468
1007.53	1494
1009.79	1462
1012.05	1496
1014.31	1460
1016.57	1464
1018.83	1474
1021.09	1478
1023.35	1492
1025.61	1516
1027.87	1498
1030.12	1462
1032.38	1484
1034.63	1550
1036.88	1476
1039.14	1498
1041.39	1534
1043.64	1500
1045.89	1518
1048.14	1532
1050.39	1534
1052.64	1526
1054.89	1562
1057.14	1532
1059.38	1572
1061.63	1516
1063.87	1526
1066.12	1580
1068.36	1510
1070.6	1602
1072.85	1548
1075.09	1530
1077.33	1524
1079.57	1596
1081.81	1562
1084.05	1540
1086.28	1562
1088.52	1562
1090.76	1518
1092.99	1596
1095.23	1502
1097.46	1534
1099.69	1556
1101.93	1568
1104.16	1550
1106.39	1600
1108.62	1556
1110.85	1584
1113.08	1572
1115.31	1552
1117.53	1548
1119.76	1596
1121.99	1570
1124.21	1602
1126.44	1574
1128.66	1568
1130.88	1554
1133.11	1574
1135.33	1642
1137.55	1624
1139.77	1616
1141.99	1606
1144.21	1608
1146.43	1638
1148.64	1580
1150.86	1606
1153.08	1634
1155.29	1634
1157.51	1644
1159.72	1646
1161.93	1590
1164.14	1638
1166.36	1616
1168.57	1654
1170.78	1608
1172.99	1632
1175.2	1640
1177.4	1612
1179.61	1612
1181.82	1676
1184.02	1634
1186.23	1616
1188.43	1676
1190.64	1858
1192.84	2480
1195.04	1616
1197.24	1644
1199.45	1653.33
1201.64	1596.17
1203.84	1688.89
1206.04	1603.97
1208.24	1637.29
1210.44	1581.69
1212.64	1594.46
1214.83	1560.7
1217.03	1587.85
1219.22	1588.17
1221.41	1575.07
1223.61	1502.93
1225.8	1475.99
1227.99	1478.91
1230.18	1468.42
1232.37	1478.91
1234.56	1505.31
1236.75	1472.79
1238.94	1440.36
1241.13	1432.61
1243.31	1429.56
1245.5	1436.12
1247.68	1387.86
1249.87	1397.66
1252.05	1371.52
1254.24	1383.15
1256.42	1412.16
1258.6	1355.89
1260.78	1345.34
1262.96	1369.14
1265.14	1338.15
1267.32	1324.41
1269.5	1334.77
1271.67	1307.81
1273.85	1291.78
1276.03	1297.16
1278.2	1304.52
1280.38	1251.97
1282.55	1244.4
1284.72	1233.69
1286.9	1244.69
1289.07	1202.08
1291.24	1227.24
1293.41	1213.66
1295.58	1200.39
1297.75	1163.62
1299.92	1156.01
1302.09	1178.11
1304.25	1128.58
1306.42	1122.91
1308.46	1152
1310.63	1042
1312.81	1122
1314.98	1114
1317.16	1096
1319.33	1150
1321.5	1122
1323.67	1082
1325.85	1132
1328.02	1086
1330.19	1092
1332.35	1100
1334.52	1086
1336.69	1092
1338.86	1104
1341.02	1136
1343.19	1092
1345.35	1092
1347.52	1090
1349.68	1074
1351.84	1106
1354	1112
1356.17	1104
1358.33	1076
1360.49	1092
1362.65	1060
1364.8	1064
1366.96	1088
1369.12	1046
1371.28	1042
1373.43	1060
1375.59	1062
1377.74	1084
1379.89	1102
1382.05	1036
1384.2	1060
1386.35	1064
1388.5	1086
1390.65	1090
1392.8	1026
1394.95	1056
1397.1	1020
1399.25	1048
1401.4	1062
1403.54	1094
1405.69	1050
1407.83	1028
1409.98	1030
1412.12	1052
1414.26	1066
1416.4	1010
1418.55	1078
1420.69	998
1422.83	1020
1424.97	1082
1427.1	1012
1429.24	1004
1431.38	1040
1433.52	988
1435.65	1060
1437.79	1036
1439.92	1058
1442.06	1042
1444.19	1048
1446.32	1010
1448.46	1028
1450.59	1022
1452.72	1024
1454.85	1018
1456.98	1004
1459.11	1046
1461.23	1004
1463.36	978
1465.49	1018
1467.61	1012
1469.74	1024
1471.86	978
1473.99	1010
1476.11	956
1478.23	990
1480.36	1000
1482.48	994
1484.6	972
1486.72	976
1488.84	960
1490.96	962
1493.07	988
1495.19	1028
1497.31	988
1499.42	1000
1501.54	1008
1503.65	982
1505.77	966
1507.88	962
1509.99	934
1512.1	980
1514.22	992
1516.33	968
1518.44	944
1520.55	926
1522.65	934
1524.76	940
1526.87	928
1528.98	978
1531.08	906
1533.19	892
1535.29	896
1537.4	912
1539.5	922
1541.6	898
1543.7	928
1545.8	918
1547.91	882
1550.01	906
1552.11	910
1554.2	908
1556.3	870
1558.4	866
1560.5	900
1562.59	860
1564.69	896
1566.78	876
1568.88	890
1570.97	902
1573.06	914
1575.15	926
1577.25	878
1579.34	918
1581.43	882
1583.52	868
1585.6	852
1587.69	860
1589.78	858
1591.87	870
1593.95	860
1596.04	884
1598.12	858
1600.21	850
1602.29	882
1604.37	850
1606.46	836
1608.54	858
1610.62	820
1612.7	892
1614.78	838
1616.86	850
1618.94	836
1621.01	832
1623.09	826
1625.17	834
1627.24	848
1629.32	872
1631.39	838
1633.47	832
1635.54	814
1637.61	848
1639.68	842
1641.76	810
1643.83	802
1645.9	804
1647.96	834
1650.03	822
1652.1	820
1654.17	818
1656.24	794
1658.3	796
1660.37	794
1662.43	798
1664.5	794
1666.56	808
1668.62	768
1670.68	774
1672.75	780
1674.81	764
1676.87	760
1678.93	776
1680.99	788
1683.04	784
1685.1	754
1687.16	796
1689.21	772
1691.27	784
1693.33	776
1695.38	724
1697.43	756
1699.49	734
1701.54	744
1703.59	734
1705.64	744
1707.69	738
1709.74	716
1711.79	726
1713.84	730
1715.89	734
1717.94	742
1719.98	728
1722.03	746
1724.07	732
1726.12	726
1728.16	700
1730.21	722
1732.25	704
1734.29	680
1736.33	712
1738.37	724
1740.41	720
1742.45	726
1744.49	710
1746.53	680
1748.57	716
1750.61	676
1752.64	682
1754.68	706
1756.71	660
1758.75	696
1760.78	662
1762.82	694
1764.85	700
1766.88	650
1768.91	692
1770.94	666
1772.97	682
1775	668
1777.03	658
1779.06	664
1781.09	668
1783.12	674
1785.14	666
1787.17	698
1789.19	646
1791.22	692
1793.24	680
1795.27	650
1797.29	656
1799.31	632
1801.33	672
1803.35	624
1805.37	630
1807.39	624
1809.41	636
1811.43	648
1813.45	658
1815.46	638
1817.48	608
1819.5	636
1821.51	656
1823.53	642
1825.54	652
1827.55	608
1829.57	622
1831.58	588
1833.59	642
1835.6	652
1837.61	598
1839.62	594
1841.63	618
1843.64	632
1845.65	588
1847.65	618
1849.66	564
1851.66	608
1853.67	562
1855.67	602
1857.68	580
1859.68	554
1861.68	568
1863.69	574
1865.69	580
1867.69	572
1869.69	572
1871.69	586
1873.69	542
1875.69	590
1877.68	570
1879.68	564
1881.68	590
1883.67	558
1885.67	582
1887.66	550
1889.66	546
1891.65	552
1893.64	544
1895.64	546
1897.63	518
1899.62	542
1901.61	554
1903.6	558
1905.59	530
1907.58	550
1909.56	516
1911.55	546
1913.54	554
1915.53	536
1917.51	526
1919.5	546
1921.48	558
1923.46	538
1925.45	562
1927.43	540
1929.41	526
1931.39	518
1933.37	532
1935.35	518
1937.33	518
1939.31	500
1941.29	504
1943.27	516
1945.24	526
1947.22	526
1949.2	518
1951.17	480
1953.14	522
1955.12	522
1957.09	488
1959.06	498
1961.04	490
1963.01	494
1964.98	498
1966.95	488
1968.92	488
1970.89	490
1972.86	464
1974.82	474
1976.79	508
1978.76	466
1980.72	486
1982.69	494
1984.65	492
1986.62	474
1988.58	478
1990.54	472
1992.51	494
1994.47	464
1996.43	448
1998.39	466
1999.37	478