File: muestras/billete_e/Organic_04.txt
#Acq. time (s)=	15
#Accumulations=	1
#Range (cm-¹)=	100...2000
#Windows=	2
#Autofocus=	Off
#AutoExposure=	Off
#Spike filter=	Off
#Delay time (s)=	0
#Binning=	1
#Readout mode=	Signal
#DeNoise=	Off
#ICS correction=	Off
#Dark correction=	Off
#Inst. Process=	Off
#Instrument=	LabRAM HR Evol
#Detector=	Syncerity OE
#Objective=	x100_VIS
#Grating=	600 (500nm)
#ND Filter=	10%
#Laser=	633nm_Edge
#Hole=	100.021
#Range=	Visible
#Project=	Omar
#Sample=	20-06-23
#Site=	3
#Title=	Organic
#Remark=
#Date=	20.06.2023 12:16
#Acquired=	20.06.2023 12:16:03
101.054	34896
103.621	34854
106.187	34892
108.752	35022
111.317	35434
113.881	35142
116.443	35568
119.005	35932
121.566	36240
124.126	36450
126.685	36842
129.243	36916
131.801	36952
134.356	37112
136.911	37460
139.466	37338
142.021	37638
144.574	37584
147.125	37868
149.676	38024
152.227	38402
154.776	38692
157.325	38846
159.873	39026
162.419	39026
164.966	38998
167.51	39420
170.055	39524
172.598	39896
175.141	40048
177.682	40086
180.222	40352
182.763	40576
185.302	40786
187.839	41216
190.376	41686
192.914	41508
195.449	41876
197.983	42120
200.517	42390
203.05	42740
205.582	43206
208.113	43714
210.643	43626
213.173	43984
215.701	43924
218.229	44666
220.756	44334
223.282	45054
225.808	45290
228.331	45906
230.855	46134
233.378	46286
235.898	46594
238.419	46932
240.94	47286
243.458	47534
245.977	47796
248.495	48376
251.011	48234
253.527	48726
256.041	48538
258.555	48682
261.068	49042
263.58	49198
266.092	49064
268.603	49602
271.112	49830
273.62	49604
276.129	49836
278.636	50466
281.142	50618
283.647	51076
286.152	51588
288.655	51624
291.158	52246
293.66	52650
296.161	53238
298.661	53444
301.161	53980
303.66	54210
306.158	54774
308.655	54888
311.15	55410
313.645	55500
316.14	55736
318.634	56032
321.125	56574
323.618	56308
326.109	56846
328.598	57044
331.088	57132
333.576	57782
336.064	58368
338.55	58292
341.037	58498
343.521	58908
346.005	59776
348.489	60376
350.971	60208
353.453	60406
355.933	60670
358.414	61422
360.893	61340
363.371	61890
365.848	61560
368.325	62054
370.801	62262
373.275	62502
375.75	62966
378.223	62660
380.695	62910
383.167	62862
385.638	63362
388.108	63856
390.577	64258
393.044	64274
395.512	64535
397.979	64535
400.444	64535
402.909	64535
405.374	64535
407.836	64535
410.299	64535
412.76	64535
415.221	64535
417.681	64535
420.141	64535
422.598	64535
425.057	64535
427.513	64535
429.968	64535
432.422	64535
434.878	64535
437.33	64535
439.783	64535
442.234	64535
444.685	64535
447.134	64535
449.583	64535
452.032	64535
454.479	64535
456.926	64535
459.372	64535
461.817	64535
464.261	64535
466.705	64535
469.147	64535
471.588	64535
474.029	64535
476.47	64535
478.909	64535
481.347	64535
483.785	64535
486.221	64535
488.657	64535
491.092	64535
493.527	64535
495.96	64535
498.393	64535
500.824	64535
503.255	64535
505.686	64535
508.115	64535
510.543	64535
512.972	64535
515.399	64535
517.825	64535
520.25	64535
522.674	64535
525.097	64535
527.52	64535
529.942	64535
532.364	64535
534.784	64535
537.204	64535
539.623	64535
542.041	64535
544.457	64535
546.874	64535
549.289	64535
551.705	64535
554.118	64535
556.531	64535
558.943	64535
561.355	64535
563.766	64535
566.175	64535
568.585	64535
570.992	64535
573.399	64535
575.807	64535
578.212	64535
580.617	64535
583.022	64535
585.425	64535
587.827	64535
590.229	64535
592.63	64535
595.03	64535
597.43	64535
599.829	64535
602.226	64535
604.623	64535
607.02	64535
609.414	64535
611.808	64535
614.202	64535
616.596	64535
618.988	64535
621.378	64535
623.769	64535
626.159	64535
628.548	64535
630.936	64535
633.324	64535
635.71	64535
638.096	64535
640.481	64535
642.866	64535
645.248	64535
647.63	64535
650.013	64535
652.394	64535
654.773	64535
657.154	64535
659.532	64535
661.91	64535
664.286	64535
666.663	64535
669.038	64535
671.412	64535
673.786	64535
676.159	64535
678.532	64535
680.903	64535
683.274	64535
685.644	64535
688.014	64535
690.381	64535
692.749	64535
695.116	64535
697.481	64535
699.846	64535
702.211	64535
704.574	64535
706.938	64535
709.299	64535
711.661	64535
714.021	64535
716.381	64535
718.739	64535
721.097	64535
723.455	64535
725.811	64535
728.167	64535
730.521	64535
732.875	64535
735.23	64535
737.582	64535
739.934	64535
742.285	64535
744.635	64535
746.985	64535
749.332	64535
751.68	64535
754.028	64535
756.374	64535
758.72	64535
761.065	64535
763.408	64535
765.752	64535
768.095	64535
770.436	64535
772.777	64535
775.116	64535
777.456	64535
779.794	64535
782.133	64535
784.469	64535
786.805	64535
789.141	64535
791.476	64535
793.809	64535
796.142	64535
798.476	64535
800.807	64535
803.138	64535
805.468	64535
807.797	64535
810.125	64535
812.453	64535
814.78	64535
817.106	64535
819.432	64535
821.757	64535
824.08	64535
826.403	64535
828.726	64535
831.048	64535
833.368	64535
835.688	64535
838.007	64535
840.326	64535
842.644	64535
844.96	64535
847.276	64535
849.592	64535
851.906	64535
854.221	64535
856.534	64535
858.846	64535
861.157	64535
863.469	64535
865.779	64535
868.088	64535
870.396	64535
872.704	64535
875.011	64535
877.318	64535
879.623	64535
881.928	64535
884.232	64535
886.536	64535
888.837	64535
891.139	64535
893.44	64535
895.741	64535
898.039	64535
900.339	64535
902.637	64535
904.933	64535
907.231	64535
909.526	64535
911.821	64535
914.115	64535
916.408	64535
918.701	64535
920.993	64535
923.283	64535
925.573	64535
927.864	64535
930.153	64535
932.441	64535
934.728	64535
937.014	64535
939.3	64535
941.585	64535
943.87	64535
946.154	64535
948.437	64535
950.719	64535
952.999	64535
955.28	64535
957.56	64535
959.84	64535
962.117	64535
964.395	64535
966.671	64535
968.948	64535
971.223	64535
973.498	64535
975.771	64535
978.045	64535
980.317	64535
982.588	64535
984.86	64535
987.13	64535
989.399	64535
991.667	64535
993.937	64535
996.204	64535
998.47	64535
1000.74	64535
1003	64535
1005.26	64535
1007.53	64535
1009.79	64535
1012.05	64535
1014.31	64535
1016.57	64535
1018.83	64535
1021.09	64535
1023.35	64535
1025.61	64535
1027.87	64535
1030.12	64535
1032.38	64535
1034.63	64535
1036.88	64535
1039.14	64535
1041.39	64535
1043.64	64535
1045.89	64535
1048.14	64535
1050.39	64535
1052.64	64535
1054.89	64535
1057.14	64535
1059.38	64535
1061.63	64535
1063.87	64535
1066.12	64535
1068.36	64535
1070.6	64535
1072.85	64535
1075.09	64535
1077.33	64535
1079.57	64535
1081.81	64535
1084.05	64535
1086.28	64535
1088.52	64535
1090.76	64535
1092.99	64535
1095.23	64535
1097.46	64535
1099.69	64535
1101.93	64535
1104.16	64535
1106.39	64535
1108.62	64535
1110.85	64535
1113.08	64535
1115.31	64535
1117.53	64535
1119.76	64535
1121.99	64535
1124.21	64535
1126.44	64535
1128.66	64535
1130.88	64535
1133.11	64535
1135.33	64535
1137.55	64535
1139.77	64535
1141.99	64535
1144.21	64535
1146.43	64535
1148.64	64535
1150.86	64535
1153.08	64535
1155.29	64535
1157.51	64535
1159.72	64535
1161.93	64535
1164.14	64535
1166.36	64535
1168.57	64535
1170.78	64535
1172.99	64535
1175.2	64535
1177.4	64535
1179.61	64535
1181.82	64535
1184.02	64535
1186.23	64535
1188.43	64535
1190.64	64535
1192.84	64535
1195.04	64535
1197.24	64535
1199.45	64535
1201.64	64535
1203.84	64535
1206.04	64535
1208.24	64535
1210.44	64535
1212.64	64535
1214.83	64535
1217.03	64535
1219.22	64535
1221.41	64535
1223.61	64535
1225.8	64535
1227.99	64535
1230.18	64535
1232.37	64535
1234.56	64535
1236.75	64535
1238.94	64535
1241.13	64535
1243.31	64535
1245.5	64535
1247.68	64535
1249.87	64535
1252.05	64535
1254.24	64535
1256.42	64535
1258.6	64535
1260.78	64535
1262.96	64535
1265.14	64535
1267.32	64535
1269.5	64535
1271.67	64535
1273.85	64535
1276.03	64535
1278.2	64535
1280.38	64535
1282.55	64535
1284.72	64535
1286.9	64535
1289.07	64535
1291.24	64535
1293.41	64535
1295.58	64535
1297.75	64535
1299.92	64535
1302.09	64535
1304.25	64535
1306.42	64535
1308.46	64535
1310.63	64535
1312.81	64535
1314.98	64535
1317.16	64535
1319.33	64535
1321.5	64535
1323.67	64535
1325.85	64535
1328.02	64535
1330.19	64535
1332.35	64535
1334.52	64535
1336.69	64535
1338.86	64535
1341.02	64535
1343.19	64535
1345.35	64535
1347.52	64535
1349.68	64535
1351.84	64535
1354	64535
1356.17	64535
1358.33	64535
1360.49	64535
1362.65	64426
1364.8	64330
1366.96	64148
1369.12	63774
1371.28	63446
1373.43	63324
1375.59	62702
1377.74	62718
1379.89	62614
1382.05	62236
1384.2	62142
1386.35	62020
1388.5	61636
1390.65	61232
1392.8	60980
1394.95	60798
1397.1	61134
1399.25	60952
1401.4	60348
1403.54	60094
1405.69	59994
1407.83	59524
1409.98	59558
1412.12	59478
1414.26	59032
1416.4	58600
1418.55	58484
1420.69	58392
1422.83	58006
1424.97	57852
1427.1	57868
1429.24	57572
1431.38	57404
1433.52	57026
1435.65	56906
1437.79	56512
1439.92	56526
1442.06	56190
1444.19	55896
1446.32	55890
1448.46	55576
1450.59	55462
1452.72	55284
1454.85	55470
1456.98	54964
1459.11	54684
1461.23	54828
1463.36	54688
1465.49	54642
1467.61	54056
1469.74	53784
1471.86	53780
1473.99	53232
1476.11	52934
1478.23	52926
1480.36	52956
1482.48	52700
1484.6	52476
1486.72	52538
1488.84	52278
1490.96	52478
1493.07	51868
1495.19	51668
1497.31	51286
1499.42	51228
1501.54	51100
1503.65	51142
1505.77	50236
1507.88	50420
1509.99	50162
1512.1	49586
1514.22	49688
1516.33	49270
1518.44	48822
1520.55	48984
1522.65	48668
1524.76	48636
1526.87	48242
1528.98	48110
1531.08	47710
1533.19	47640
1535.29	47376
1537.4	47236
1539.5	47402
1541.6	46820
1543.7	46526
1545.8	46508
1547.91	46078
1550.01	45934
1552.11	45894
1554.2	46038
1556.3	45512
1558.4	45136
1560.5	45124
1562.59	45054
1564.69	44540
1566.78	44690
1568.88	44554
1570.97	44714
1573.06	44736
1575.15	44338
1577.25	44046
1579.34	44356
1581.43	43930
1583.52	43566
1585.6	43368
1587.69	43352
1589.78	43448
1591.87	43672
1593.95	43120
1596.04	43212
1598.12	43026
1600.21	42644
1602.29	42510
1604.37	41980
1606.46	42074
1608.54	41982
1610.62	41962
1612.7	41902
1614.78	41774
1616.86	41638
1618.94	41630
1621.01	41506
1623.09	41092
1625.17	41164
1627.24	40806
1629.32	40686
1631.39	40728
1633.47	40524
1635.54	40346
1637.61	40584
1639.68	39990
1641.76	39858
1643.83	39664
1645.9	39706
1647.96	39468
1650.03	39374
1652.1	39296
1654.17	38806
1656.24	39082
1658.3	39002
1660.37	38646
1662.43	38784
1664.5	38410
1666.56	38226
1668.62	38134
1670.68	37928
1672.75	37672
1674.81	37554
1676.87	37638
1678.93	37370
1680.99	37162
1683.04	36980
1685.1	36558
1687.16	36594
1689.21	36414
1691.27	36226
1693.33	36132
1695.38	36150
1697.43	36036
1699.49	35606
1701.54	35828
1703.59	35660
1705.64	35416
1707.69	35160
1709.74	34968
1711.79	34960
1713.84	34684
1715.89	34734
1717.94	34658
1719.98	34504
1722.03	34136
1724.07	34130
1726.12	33878
1728.16	33988
1730.21	33780
1732.25	33902
1734.29	33622
1736.33	33366
1738.37	33638
1740.41	33242
1742.45	33224
1744.49	33136
1746.53	32934
1748.57	33046
1750.61	32878
1752.64	32532
1754.68	32674
1756.71	32602
1758.75	32730
1760.78	32378
1762.82	32604
1764.85	32336
1766.88	31974
1768.91	32244
1770.94	32084
1772.97	31928
1775	32022
1777.03	31890
1779.06	31848
1781.09	31720
1783.12	31568
1785.14	31238
1787.17	31270
1789.19	31070
1791.22	31182
1793.24	31280
1795.27	31142
1797.29	30800
1799.31	30684
1801.33	30790
1803.35	30654
1805.37	30554
1807.39	30530
1809.41	30332
1811.43	30220
1813.45	30178
1815.46	29794
1817.48	29792
1819.5	29712
1821.51	29674
1823.53	29460
1825.54	29556
1827.55	29226
1829.57	29130
1831.58	29288
1833.59	29092
1835.6	28870
1837.61	28808
1839.62	28724
1841.63	28696
1843.64	28280
1845.65	28466
1847.65	28198
1849.66	28128
1851.66	28090
1853.67	27866
1855.67	27870
1857.68	27866
1859.68	27772
1861.68	27768
1863.69	27656
1865.69	27408
1867.69	27210
1869.69	27248
1871.69	27238
1873.69	27240
1875.69	27074
1877.68	27044
1879.68	26922
1881.68	26770
1883.67	26564
1885.67	26784
1887.66	26546
1889.66	26496
1891.65	26548
1893.64	26430
1895.64	26212
1897.63	26302
1899.62	26220
1901.61	26226
1903.6	25946
1905.59	26102
1907.58	25954
1909.56	25782
1911.55	25678
1913.54	25680
1915.53	25660
1917.51	25524
1919.5	25484
1921.48	25386
1923.46	25572
1925.45	25406
1927.43	25246
1929.41	25480
1931.39	25252
1933.37	25120
1935.35	25124
1937.33	25244
1939.31	24918
1941.29	25078
1943.27	24804
1945.24	24870
1947.22	24740
1949.2	24744
1951.17	24618
1953.14	24371
1955.12	24334
1957.09	24480
1959.06	24286
1961.04	24320
1963.01	24120
1964.98	24080
1966.95	24016
1968.92	23894
1970.89	23794
1972.86	23770
1974.82	23816
1976.79	23632
1978.76	23852
1980.72	23698
1982.69	23376
1984.65	23518
1986.62	23410
1988.58	23470
1990.54	23320
1992.51	23222
1994.47	23154
1996.43	23134
1998.39	23100
1999.37	23004