File: muestras/billete_e/Organic_02.txt
#Acq. time (s)=	15
#Accumulations=	1
#Range (cm-¹)=	100...2000
#Windows=	2
#Autofocus=	Off
#AutoExposure=	Off
#Spike filter=	Off
#Delay time (s)=	0
#Binning=	1
#Readout mode=	Signal
#DeNoise=	Off
#ICS correction=	Off
#Dark correction=	Off
#Inst. Process=	Off
#Instrument=	LabRAM HR Evol
#Detector=	Syncerity OE
#Objective=	x100_VIS
#Grating=	600 (500nm)
#ND Filter=	10%
#Laser=	633nm_Edge
#Hole=	100.021
#Range=	Visible
#Project=	Omar
#Sample=	20-06-23
#Site=	3
#Title=	Organic
#Remark=
#Date=	20.06.2023 12:13
#Acquired=	20.06.2023 12:13:30
101.054	7414
103.621	7326
106.187	7420
108.752	7410
111.317	7374
113.881	7330
116.443	7436
119.005	7472
121.566	7528
124.126	7420
126.685	7440
129.243	7640
131.801	7524
134.356	7662
136.911	7732
139.466	8062
142.021	7872
144.574	7742
147.125	7606
149.676	7414
152.227	7616
154.776	7466
157.325	7526
159.873	7570
162.419	7502
164.966	7432
167.51	7484
170.055	7372
172.598	7382
175.141	7552
177.682	7494
180.222	7484
182.763	7444
185.302	7488
187.839	7514
190.376	7462
192.914	7498
195.449	7562
197.983	7582
200.517	7598
203.05	7408
205.582	7452
208.113	7710
210.643	7576
213.173	7612
215.701	7628
218.229	7620
220.756	7606
223.282	7580
225.808	7616
228.331	7634
230.855	7646
233.378	7596
235.898	7630
238.419	7630
240.94	7696
243.458	7606
245.977	7716
248.495	7712
251.011	7776
253.527	7710
256.041	7688
258.555	7748
261.068	7686
263.58	7574
266.092	7622
268.603	7618
271.112	7554
273.62	7612
276.129	7700
278.636	7596
281.142	7484
283.647	7488
286.152	7670
288.655	7568
291.158	7638
293.66	7660
296.161	7736
298.661	7750
301.161	7738
303.66	7624
306.158	7570
308.655	7712
311.15	7734
313.645	7648
316.14	7678
318.634	7586
321.125	7596
323.618	7740
326.109	7520
328.598	7542
331.088	7600
333.576	7602
336.064	7604
338.55	7636
341.037	7606
343.521	7570
346.005	7572
348.489	7580
350.971	7586
353.453	7610
355.933	7658
358.414	7612
360.893	7522
363.371	7508
365.848	7504
368.325	7590
370.801	7638
373.275	7548
375.75	7462
378.223	7576
380.695	7458
383.167	7394
385.638	7442
388.108	7396
390.577	7576
393.044	7434
395.512	7432
397.979	7356
400.444	7404
402.909	7346
405.374	7498
407.836	7420
410.299	7636
412.76	7396
415.221	7430
417.681	7564
420.141	7534
422.598	7416
425.057	7528
427.513	7612
429.968	7606
432.422	7496
434.878	7556
437.33	7436
439.783	7488
442.234	7504
444.685	7610
447.134	7484
449.583	7380
452.032	7426
454.479	7360
456.926	7288
459.372	7284
461.817	7330
464.261	7210
466.705	7308
469.147	7230
471.588	7208
474.029	7144
476.47	7278
478.909	7254
481.347	7286
483.785	7198
486.221	7188
488.657	7288
491.092	7376
493.527	7210
495.96	7276
498.393	7280
500.824	7304
503.255	7166
505.686	7300
508.115	7176
510.543	7200
512.972	7304
515.399	7162
517.825	7208
520.25	7080
522.674	7120
525.097	7138
527.52	6934
529.942	7012
532.364	6990
534.784	6904
537.204	6932
539.623	6908
542.041	6944
544.457	6864
546.874	6886
549.289	6858
551.705	6812
554.118	6848
556.531	6810
558.943	6792
561.355	6846
563.766	6810
566.175	6858
568.585	6730
570.992	6806
573.399	6782
575.807	6756
578.212	6680
580.617	6724
583.022	6664
585.425	6740
587.827	6738
590.229	6616
592.63	6676
595.03	6726
597.43	6736
599.829	6716
602.226	6504
604.623	6682
607.02	6658
609.414	6648
611.808	6740
614.202	6638
616.596	6666
618.988	6638
621.378	6704
623.769	6600
626.159	6620
628.548	6772
630.936	6634
633.324	6690
635.71	6610
638.096	6696
640.481	6686
642.866	6724
645.248	6648
647.63	6592
650.013	6666
652.394	6534
654.773	6518
657.154	6646
659.532	6490
661.91	6546
664.286	6456
666.663	6480
669.038	6422
671.412	6498
673.786	6322
676.159	6484
678.532	6396
680.903	6338
683.274	6318
685.644	6298
688.014	6338
690.381	6352
692.749	6284
695.116	6302
697.481	6296
699.846	6188
702.211	6280
704.574	6372
706.938	6340
709.299	6200
711.661	6224
714.021	6238
716.381	6146
718.739	6226
721.097	6194
723.455	6202
725.811	6228
728.167	6208
730.521	6200
732.875	6206
735.23	6136
737.582	6188
739.934	6150
742.285	6138
744.635	6112
746.985	6166
749.332	5990
751.68	6084
754.028	6090
756.374	6010
758.72	6004
761.065	5990
763.408	6002
765.752	5914
768.095	5930
770.436	5968
772.777	5910
775.116	5896
777.456	5854
779.794	5832
782.133	5860
784.469	5926
786.805	5804
789.141	5820
791.476	5890
793.809	5810
796.142	5882
798.476	5834
800.807	5806
803.138	5906
805.468	5834
807.797	5816
810.125	5790
812.453	5770
814.78	5796
817.106	5778
819.432	5820
821.757	5838
824.08	5854
826.403	5796
828.726	5892
831.048	5806
833.368	5836
835.688	5792
838.007	5782
840.326	5872
842.644	5770
844.96	5794
847.276	5736
849.592	5788
851.906	5828
854.221	5802
856.534	5794
858.846	5752
861.157	5752
863.469	5710
865.779	5730
868.088	5792
870.396	5776
872.704	5688
875.011	5760
877.318	5698
879.623	5638
881.928	5584
884.232	5572
886.536	5640
888.837	5612
891.139	5524
893.44	5640
895.741	5490
898.039	5638
900.339	5546
902.637	5554
904.933	5492
907.231	5500
909.526	5472
911.821	5420
914.115	5394
916.408	5440
918.701	5558
920.993	5468
923.283	5424
925.573	5430
927.864	5418
930.153	5450
932.441	5404
934.728	5452
937.014	5500
939.3	5370
941.585	5386
943.87	5428
946.154	5370
948.437	5478
950.719	5454
952.999	5456
955.28	5360
957.56	5532
959.84	5500
962.117	5420
964.395	5414
966.671	5428
968.948	5456
971.223	5382
973.498	5452
975.771	5426
978.045	5384
980.317	5398
982.588	5460
984.86	5348
987.13	5350
989.399	5356
991.667	5350
993.937	5356
996.204	5372
998.47	5322
1000.74	5304
1003	5320
1005.26	5358
1007.53	5300
1009.79	5330
1012.05	5290
1014.31	5400
1016.57	5354
1018.83	5310
1021.09	5276
1023.35	5308
1025.61	5172
1027.87	5396
1030.12	5354
1032.38	5282
1034.63	5338
1036.88	5308
1039.14	5342
1041.39	5366
1043.64	5288
1045.89	5298
1048.14	5358
1050.39	5312
1052.64	5442
1054.89	5312
1057.14	5482
1059.38	5326
1061.63	5420
1063.87	5244
1066.12	5308
1068.36	5288
1070.6	5250
1072.85	5304
1075.09	5360
1077.33	5240
1079.57	5308
1081.81	5254
1084.05	5308
1086.28	5282
1088.52	5264
1090.76	5242
1092.99	5266
1095.23	5266
1097.46	5182
1099.69	5154
1101.93	5094
1104.16	5256
1106.39	5104
1108.62	5178
1110.85	5208
1113.08	5082
1115.31	5162
1117.53	5158
1119.76	5112
1121.99	5168
1124.21	5162
1126.44	5180
1128.66	5172
1130.88	5170
1133.11	5170
1135.33	5112
1137.55	5170
1139.77	5054
1141.99	5130
1144.21	5132
1146.43	5184
1148.64	5154
1150.86	5204
1153.08	5220
1155.29	5230
1157.51	5186
1159.72	5168
1161.93	5138
1164.14	5230
1166.36	5214
1168.57	5182
1170.78	5186
1172.99	5226
1175.2	5210
1177.4	5144
1179.61	5196
1181.82	5162
1184.02	5078
1186.23	5150
1188.43	5106
1190.64	5180
1192.84	5166
1195.04	5044
1197.24	5048
1199.45	5200.13
1201.64	4993.31
1203.84	5056.04
1206.04	5040.49
1208.24	5070.36
1210.44	5079.97
1212.64	4997.36
1214.83	5018.15
1217.03	5103.76
1219.22	4999.02
1221.41	5049.5
1223.61	4984.76
1225.8	5020.06
1227.99	5048.71
1230.18	5057.91
1232.37	4988.97
1234.56	4977.47
1236.75	4955.77
1238.94	5047.45
1241.13	4925.78
1243.31	5005.62
1245.5	5010.88
1247.68	5056.62
1249.87	5057.57
1252.05	5020.4
1254.24	5008.44
1256.42	5027.4
1258.6	5045.4
1260.78	5006.24
1262.96	5020.88
1265.14	5075.84
1267.32	5114.8
1269.5	5064.49
1271.67	5060.47
1273.85	5131.79
1276.03	5059.65
1278.2	5083.56
1280.38	5067.34
1282.55	5060.84
1284.72	5129.16
1286.9	5040.06
1289.07	5067.43
1291.24	5103.71
1293.41	5031.99
1295.58	5086.72
1297.75	5063.82
1299.92	5022.23
1302.09	5080.76
1304.25	5094.94
1306.42	5071.2
1308.46	5006
1310.63	5042
1312.81	5002
1314.98	5004
1317.16	5126
1319.33	5010
1321.5	5040
1323.67	4988
1325.85	5032
1328.02	5030
1330.19	4950
1332.35	4912
1334.52	4976
1336.69	5038
1338.86	5026
1341.02	4976
1343.19	4930
1345.35	4964
1347.52	4890
1349.68	4924
1351.84	4860
1354	4944
1356.17	4926
1358.33	4904
1360.49	4964
1362.65	4982
1364.8	4828
1366.96	4876
1369.12	4846
1371.28	4894
1373.43	4928
1375.59	4884
1377.74	4842
1379.89	4946
1382.05	4888
1384.2	4792
1386.35	4930
1388.5	4924
1390.65	4866
1392.8	4914
1394.95	4830
1397.1	4820
1399.25	4856
1401.4	4788
1403.54	4844
1405.69	4868
1407.83	4694
1409.98	4762
1412.12	4734
1414.26	4818
1416.4	4758
1418.55	4798
1420.69	4704
1422.83	4820
1424.97	4744
1427.1	4780
1429.24	4720
1431.38	4700
1433.52	4754
1435.65	4806
1437.79	4718
1439.92	4770
1442.06	4736
1444.19	4786
1446.32	4662
1448.46	4698
1450.59	4682
1452.72	4750
1454.85	4652
1456.98	4762
1459.11	4670
1461.23	4764
1463.36	4658
1465.49	4666
1467.61	4694
1469.74	4736
1471.86	4580
1473.99	4704
1476.11	4654
1478.23	4632
1480.36	4620
1482.48	4620
1484.6	4724
1486.72	4662
1488.84	4626
1490.96	4586
1493.07	4634
1495.19	4590
1497.31	4570
1499.42	4584
1501.54	4614
1503.65	4598
1505.77	4534
1507.88	4480
1509.99	4498
1512.1	4528
1514.22	4484
1516.33	4518
1518.44	4482
1520.55	4486
1522.65	4464
1524.76	4492
1526.87	4434
1528.98	4444
1531.08	4400
1533.19	4408
1535.29	4380
1537.4	4388
1539.5	4340
1541.6	4408
1543.7	4456
1545.8	4372
1547.91	4244
1550.01	4390
1552.11	4316
1554.2	4188
1556.3	4328
1558.4	4322
1560.5	4296
1562.59	4242
1564.69	4312
1566.78	4300
1568.88	4150
1570.97	4192
1573.06	4240
1575.15	4204
1577.25	4234
1579.34	4150
1581.43	4198
1583.52	4138
1585.6	4152
1587.69	4214
1589.78	4166
1591.87	4138
1593.95	4154
1596.04	4110
1598.12	4202
1600.21	4242
1602.29	4088
1604.37	4122
1606.46	4138
1608.54	4144
1610.62	4112
1612.7	4032
1614.78	4126
1616.86	4106
1618.94	4032
1621.01	4052
1623.09	4096
1625.17	4084
1627.24	4074
1629.32	4016
1631.39	3978
1633.47	4072
1635.54	4008
1637.61	4000
1639.68	3976
1641.76	4038
1643.83	4026
1645.9	3962
1647.96	3970
1650.03	3906
1652.1	3972
1654.17	4038
1656.24	3908
1658.3	3846
1660.37	3870
1662.43	3794
1664.5	3902
1666.56	3862
1668.62	3864
1670.68	3850
1672.75	3834
1674.81	3838
1676.87	3826
1678.93	3806
1680.99	3788
1683.04	3788
1685.1	3772
1687.16	3776
1689.21	3680
1691.27	3680
1693.33	3730
1695.38	3726
1697.43	3704
1699.49	3676
1701.54	3656
1703.59	3620
1705.64	3604
1707.69	3602
1709.74	3654
1711.79	3580
1713.84	3618
1715.89	3506
1717.94	3568
1719.98	3472
1722.03	3584
1724.07	3508
1726.12	3552
1728.16	3616
1730.21	3530
1732.25	3496
1734.29	3542
1736.33	3522
1738.37	3544
1740.41	3522
1742.45	3496
1744.49	3394
1746.53	3424
1748.57	3406
1750.61	3496
1752.64	3430
1754.68	3406
1756.71	3476
1758.75	3404
1760.78	3410
1762.82	3386
1764.85	3428
1766.88	3412
1768.91	3302
1770.94	3382
1772.97	3398
1775	3428
1777.03	3418
1779.06	3344
1781.09	3394
1783.12	3382
1785.14	3268
1787.17	3308
1789.19	3324
1791.22	3334
1793.24	3258
1795.27	3228
1797.29	3220
1799.31	3174
1801.33	3232
1803.35	3232
1805.37	3200
1807.39	3212
1809.41	3262
1811.43	3164
1813.45	3206
1815.46	3232
1817.48	3222
1819.5	3098
1821.51	3166
1823.53	3156
1825.54	3100
1827.55	3094
1829.57	3078
1831.58	3088
1833.59	3144
1835.6	2998
1837.61	3018
1839.62	3044
1841.63	3000
1843.64	3032
1845.65	2996
1847.65	2978
1849.66	2922
1851.66	3018
1853.67	2962
1855.67	2974
1857.68	2922
1859.68	2942
1861.68	2904
1863.69	2940
1865.69	2944
1867.69	2854
1869.69	2938
1871.69	2922
1873.69	2892
1875.69	2850
1877.68	2828
1879.68	2850
1881.68	2838
1883.67	2862
1885.67	2872
1887.66	2808
1889.66	2860
1891.65	2776
1893.64	2794
1895.64	2772
1897.63	2742
1899.62	2810
1901.61	2712
1903.6	2796
1905.59	2770
1907.58	2766
1909.56	2686
1911.55	2690
1913.54	2706
1915.53	2630
1917.51	2716
1919.5	2712
1921.48	2720
1923.46	2694
1925.45	2666
1927.43	2672
1929.41	2640
1931.39	2660
1933.37	2682
1935.35	2634
1937.33	2634
1939.31	2626
1941.29	2640
1943.27	2540
1945.24	2588
1947.22	2630
1949.2	2552
1951.17	2572
1953.14	2546
1955.12	2544
1957.09	2576
1959.06	2496
1961.04	2508
1963.01	2496
1964.98	2538
1966.95	2458
1968.92	2514
1970.89	2490
1972.86	2498
1974.82	2516
1976.79	2412
1978.76	2470
1980.72	2412
1982.69	2468
1984.65	2452
1986.62	2422
1988.58	2390
1990.54	2434
1992.51	2446
1994.47	2402
1996.43	2376
1998.39	2412
1999.37	2400