File: muestras/billete_e/Organic_03.txt
#Acq. time (s)=	15
#Accumulations=	1
#Range (cm-¹)=	100...2000
#Windows=	2
#Autofocus=	Off
#AutoExposure=	Off
#Spike filter=	Off
#Delay time (s)=	0
#Binning=	1
#Readout mode=	Signal
#DeNoise=	Off
#ICS correction=	Off
#Dark correction=	Off
#Inst. Process=	Off
#Instrument=	LabRAM HR Evol
#Detector=	Syncerity OE
#Objective=	x100_VIS
#Grating=	600 (500nm)
#ND Filter=	10%
#Laser=	633nm_Edge
#Hole=	100.021
#Range=	Visible
#Project=	Omar
#Sample=	20-06-23
#Site=	3
#Title=	Organic
#Remark=
#Date=	20.06.2023 12:14
#Acquired=	20.06.2023 12:14:33
101.054	6262
103.621	6264
106.187	6170
108.752	6354
111.317	6268
113.881	6306
116.443	6306
119.005	6302
121.566	6372
124.126	6358
126.685	6404
129.243	6298
131.801	6444
134.356	6546
136.911	6636
139.466	6730
142.021	6644
144.574	6522
147.125	6386
149.676	6452
152.227	6408
154.776	6420
157.325	6442
159.873	6392
162.419	6370
164.966	6432
167.51	6254
170.055	6364
172.598	6366
175.141	6488
177.682	6340
180.222	6358
182.763	6392
185.302	6404
187.839	6434
190.376	6416
192.914	6510
195.449	6474
197.983	6350
200.517	6396
203.05	6474
205.582	6548
208.113	6472
210.643	6402
213.173	6468
215.701	6562
218.229	6580
220.756	6456
223.282	6576
225.808	6500
228.331	6584
230.855	6524
233.378	6592
235.898	6616
238.419	6624
240.94	6562
243.458	6642
245.977	6656
248.495	6686
251.011	6580
253.527	6610
256.041	6550
258.555	6558
261.068	6564
263.58	6536
266.092	6464
268.603	6522
271.112	6510
273.62	6510
276.129	6494
278.636	6492
281.142	6566
283.647	6548
286.152	6496
288.655	6596
291.158	6638
293.66	6604
296.161	6538
298.661	6592
301.161	6580
303.66	6644
306.158	6658
308.655	6598
311.15	6678
313.645	6518
316.14	6646
318.634	6524
321.125	6584
323.618	6582
326.109	6578
328.598	6530
331.088	6518
333.576	6512
336.064	6516
338.55	6488
341.037	6502
343.521	6454
346.005	6542
348.489	6450
350.971	6640
353.453	6516
355.933	6554
358.414	6544
360.893	6440
363.371	6504
365.848	6554
368.325	6464
370.801	6358
373.275	6538
375.75	6434
378.223	6502
380.695	6482
383.167	6424
385.638	6352
388.108	6506
390.577	6324
393.044	6338
395.512	6390
397.979	6492
400.444	6444
402.909	6342
405.374	6318
407.836	6384
410.299	6400
412.76	6380
415.221	6372
417.681	6468
420.141	6522
422.598	6612
425.057	6508
427.513	6520
429.968	6512
432.422	6466
434.878	6470
437.33	6374
439.783	6466
442.234	6380
444.685	6440
447.134	6318
449.583	6428
452.032	6358
454.479	6362
456.926	6312
459.372	6258
461.817	6288
464.261	6306
466.705	6292
469.147	6228
471.588	6210
474.029	6314
476.47	6338
478.909	6268
481.347	6264
483.785	6262
486.221	6258
488.657	6260
491.092	6254
493.527	6340
495.96	6270
498.393	6198
500.824	6218
503.255	6244
505.686	6174
508.115	6216
510.543	6184
512.972	6170
515.399	6114
517.825	6124
520.25	5994
522.674	6056
525.097	5976
527.52	5970
529.942	6028
532.364	6028
534.784	5976
537.204	6046
539.623	5974
542.041	5920
544.457	5908
546.874	6004
549.289	6004
551.705	5886
554.118	5954
556.531	5964
558.943	5942
561.355	5902
563.766	5838
566.175	5878
568.585	5822
570.992	5754
573.399	5878
575.807	5750
578.212	5828
580.617	5824
583.022	5806
585.425	5834
587.827	5766
590.229	5792
592.63	5758
595.03	5702
597.43	5650
599.829	5642
602.226	5758
604.623	5802
607.02	5712
609.414	5698
611.808	5754
614.202	5752
616.596	5716
618.988	5822
621.378	5756
623.769	5818
626.159	5700
628.548	5766
630.936	5696
633.324	5750
635.71	5846
638.096	5748
640.481	5678
642.866	5732
645.248	5710
647.63	5744
650.013	5724
652.394	5700
654.773	5720
657.154	5714
659.532	5638
661.91	5592
664.286	5654
666.663	5584
669.038	5594
671.412	5550
673.786	5504
676.159	5574
678.532	5534
680.903	5510
683.274	5432
685.644	5464
688.014	5438
690.381	5410
692.749	5534
695.116	5496
697.481	5390
699.846	5416
702.211	5358
704.574	5384
706.938	5426
709.299	5462
711.661	5432
714.021	5426
716.381	5420
718.739	5354
721.097	5388
723.455	5392
725.811	5412
728.167	5352
730.521	5300
732.875	5334
735.23	5338
737.582	5338
739.934	5228
742.285	5234
744.635	5230
746.985	5212
749.332	5194
751.68	5290
754.028	5218
756.374	5184
758.72	5204
761.065	5146
763.408	5158
765.752	5176
768.095	5184
770.436	5212
772.777	5076
775.116	5128
777.456	5076
779.794	5142
782.133	4990
784.469	5142
786.805	5008
789.141	4954
791.476	5046
793.809	5066
796.142	5026
798.476	4986
800.807	4988
803.138	5002
805.468	5096
807.797	5030
810.125	4974
812.453	4990
814.78	5034
817.106	5022
819.432	5008
821.757	4992
824.08	5048
826.403	4956
828.726	4970
831.048	5006
833.368	5088
835.688	4992
838.007	4964
840.326	5078
842.644	4994
844.96	5074
847.276	5016
849.592	5054
851.906	4976
854.221	4990
856.534	5068
858.846	5002
861.157	4944
863.469	4922
865.779	4916
868.088	5010
870.396	4952
872.704	4900
875.011	4936
877.318	4828
879.623	4884
881.928	4986
884.232	4894
886.536	4898
888.837	4864
891.139	4878
893.44	4788
895.741	4884
898.039	4822
900.339	4748
902.637	4788
904.933	4760
907.231	4878
909.526	4760
911.821	4758
914.115	4766
916.408	4762
918.701	4704
920.993	4680
923.283	4708
925.573	4754
927.864	4690
930.153	4650
932.441	4680
934.728	4734
937.014	4760
939.3	4680
941.585	4736
943.87	4632
946.154	4628
948.437	4800
950.719	4794
952.999	4678
955.28	4748
957.56	4650
959.84	4728
962.117	4710
964.395	4720
966.671	4698
968.948	4688
971.223	4694
973.498	4656
975.771	4676
978.045	4650
980.317	4624
982.588	4594
984.86	4588
987.13	4624
989.399	4646
991.667	4642
993.937	4582
996.204	4660
998.47	4612
1000.74	4616
1003	4618
1005.26	4598
1007.53	4538
1009.79	4620
1012.05	4612
1014.31	4580
1016.57	4602
1018.83	4556
1021.09	4588
1023.35	4634
1025.61	4672
1027.87	4676
1030.12	4680
1032.38	4662
1034.63	4552
1036.88	4530
1039.14	4540
1041.39	4686
1043.64	4602
1045.89	4654
1048.14	4694
1050.39	4680
1052.64	4600
1054.89	4704
1057.14	4606
1059.38	4636
1061.63	4632
1063.87	4602
1066.12	4624
1068.36	4604
1070.6	4600
1072.85	4548
1075.09	4506
1077.33	4656
1079.57	4610
1081.81	4544
1084.05	4574
1086.28	4604
1088.52	4536
1090.76	4544
1092.99	4540
1095.23	4582
1097.46	4440
1099.69	4434
1101.93	4410
1104.16	4426
1106.39	4466
1108.62	4474
1110.85	4388
1113.08	4500
1115.31	4502
1117.53	4384
1119.76	4428
1121.99	4378
1124.21	4498
1126.44	4420
1128.66	4480
1130.88	4446
1133.11	4484
1135.33	4464
1137.55	4530
1139.77	4426
1141.99	4436
1144.21	4388
1146.43	4558
1148.64	4484
1150.86	4414
1153.08	4454
1155.29	4494
1157.51	4426
1159.72	4478
1161.93	4518
1164.14	4502
1166.36	4478
1168.57	4456
1170.78	4540
1172.99	4434
1175.2	4424
1177.4	4506
1179.61	4510
1181.82	4486
1184.02	4452
1186.23	4484
1188.43	4488
1190.64	4414
1192.84	4478
1195.04	4394
1197.24	4366
1199.45	4388.72
1201.64	4394.69
1203.84	4366.73
1206.04	4379.94
1208.24	4354.24
1210.44	4435.46
1212.64	4396.17
1214.83	4376.98
1217.03	4392.07
1219.22	4344.76
1221.41	4354.48
1223.61	4366.16
1225.8	4371.89
1227.99	4328.47
1230.18	4324.22
1232.37	4319.44
1234.56	4319.88
1236.75	4376.87
1238.94	4359.86
1241.13	4394.13
1243.31	4422.23
1245.5	4354.57
1247.68	4312.83
1249.87	4333.76
1252.05	4382.08
1254.24	4344.74
1256.42	4374.76
1258.6	4364.69
1260.78	4370.55
1262.96	4415.18
1265.14	4387.04
1267.32	4346.33
1269.5	4439.24
1271.67	4398.18
1273.85	4413.02
1276.03	4384.38
1278.2	4403.4
1280.38	4420.13
1282.55	4410.35
1284.72	4432.34
1286.9	4427.03
1289.07	4371.19
1291.24	4434.84
1293.41	4426.3
1295.58	4470.73
1297.75	4370.84
1299.92	4376.81
1302.09	4476.35
1304.25	4433.93
1306.42	4403.79
1308.46	4386
1310.63	4460
1312.81	4384
1314.98	4374
1317.16	4360
1319.33	4398
1321.5	4386
1323.67	4388
1325.85	4320
1328.02	4340
1330.19	4368
1332.35	4332
1334.52	4250
1336.69	4398
1338.86	4338
1341.02	4332
1343.19	4320
1345.35	4350
1347.52	4358
1349.68	4306
1351.84	4292
1354	4326
1356.17	4336
1358.33	4208
1360.49	4362
1362.65	4262
1364.8	4336
1366.96	4324
1369.12	4372
1371.28	4320
1373.43	4306
1375.59	4308
1377.74	4248
1379.89	4266
1382.05	4272
1384.2	4280
1386.35	4282
1388.5	4226
1390.65	4236
1392.8	4216
1394.95	4228
1397.1	4258
1399.25	4246
1401.4	4202
1403.54	4180
1405.69	4236
1407.83	4232
1409.98	4178
1412.12	4188
1414.26	4150
1416.4	4146
1418.55	4188
1420.69	4072
1422.83	4152
1424.97	4178
1427.1	4174
1429.24	4116
1431.38	4198
1433.52	4136
1435.65	4124
1437.79	4124
1439.92	4124
1442.06	4030
1444.19	4118
1446.32	4118
1448.46	4100
1450.59	4190
1452.72	4100
1454.85	4162
1456.98	4046
1459.11	4022
1461.23	4066
1463.36	4062
1465.49	4162
1467.61	4132
1469.74	4034
1471.86	4066
1473.99	4090
1476.11	4072
1478.23	4040
1480.36	4092
1482.48	4070
1484.6	4040
1486.72	4006
1488.84	4006
1490.96	4000
1493.07	4094
1495.19	4030
1497.31	3982
1499.42	4004
1501.54	3982
1503.65	3950
1505.77	3984
1507.88	3902
1509.99	3922
1512.1	3970
1514.22	3990
1516.33	3906
1518.44	3936
1520.55	3962
1522.65	3854
1524.76	3914
1526.87	3820
1528.98	3864
1531.08	3892
1533.19	3838
1535.29	3814
1537.4	3814
1539.5	3780
1541.6	3696
1543.7	3814
1545.8	3798
1547.91	3780
1550.01	3722
1552.11	3716
1554.2	3752
1556.3	3714
1558.4	3756
1560.5	3750
1562.59	3704
1564.69	3740
1566.78	3710
1568.88	3678
1570.97	3700
1573.06	3672
1575.15	3690
1577.25	3676
1579.34	3726
1581.43	3690
1583.52	3746
1585.6	3624
1587.69	3618
1589.78	3582
1591.87	3550
1593.95	3668
1596.04	3622
1598.12	3654
1600.21	3578
1602.29	3560
1604.37	3636
1606.46	3620
1608.54	3640
1610.62	3622
1612.7	3584
1614.78	3538
1616.86	3614
1618.94	3556
1621.01	3516
1623.09	3590
1625.17	3540
1627.24	3576
1629.32	3540
1631.39	3560
1633.47	3522
1635.54	3488
1637.61	3476
1639.68	3522
1641.76	3460
1643.83	3456
1645.9	3478
1647.96	3460
1650.03	3382
1652.1	3554
1654.17	3496
1656.24	3390
1658.3	3418
1660.37	3368
1662.43	3470
1664.5	3388
1666.56	3392
1668.62	3444
1670.68	3312
1672.75	3364
1674.81	3280
1676.87	3344
1678.93	3330
1680.99	3258
1683.04	3322
1685.1	3330
1687.16	3308
1689.21	3280
1691.27	3378
1693.33	3210
1695.38	3208
1697.43	3182
1699.49	3228
1701.54	3188
1703.59	3248
1705.64	3168
1707.69	3196
1709.74	3160
1711.79	3072
1713.84	3212
1715.89	3196
1717.94	3174
1719.98	3088
1722.03	3112
1724.07	3190
1726.12	3146
1728.16	3120
1730.21	3168
1732.25	3102
1734.29	3106
1736.33	3066
1738.37	3046
1740.41	3028
1742.45	3066
1744.49	3042
1746.53	2970
1748.57	3012
1750.61	2996
1752.64	2984
1754.68	3016
1756.71	3042
1758.75	3024
1760.78	2968
1762.82	2984
1764.85	3026
1766.88	2934
1768.91	2944
1770.94	2962
1772.97	2950
1775	3012
1777.03	2956
1779.06	2912
1781.09	2928
1783.12	2924
1785.14	2926
1787.17	2922
1789.19	2912
1791.22	2794
1793.24	2924
1795.27	2866
1797.29	2838
1799.31	2924
1801.33	2816
1803.35	2822
1805.37	2906
1807.39	2802
1809.41	2850
1811.43	2792
1813.45	2776
1815.46	2814
1817.48	2784
1819.5	2778
1821.51	2780
1823.53	2702
1825.54	2772
1827.55	2734
1829.57	2662
1831.58	2684
1833.59	2656
1835.6	2742
1837.61	2642
1839.62	2634
1841.63	2680
1843.64	2660
1845.65	2590
1847.65	2572
1849.66	2660
1851.66	2596
1853.67	2616
1855.67	2612
1857.68	2528
1859.68	2566
1861.68	2554
1863.69	2556
1865.69	2568
1867.69	2514
1869.69	2596
1871.69	2530
1873.69	2534
1875.69	2500
1877.68	2526
1879.68	2456
1881.68	2426
1883.67	2516
1885.67	2526
1887.66	2424
1889.66	2492
1891.65	2466
1893.64	2416
1895.64	2468
1897.63	2436
1899.62	2436
1901.61	2404
1903.6	2440
1905.59	2372
1907.58	2408
1909.56	2410
1911.55	2400
1913.54	2394
1915.53	2352
1917.51	2376
1919.5	2356
1921.48	2332
1923.46	2364
1925.45	2350
1927.43	2300
1929.41	2368
1931.39	2336
1933.37	2364
1935.35	2302
1937.33	2284
1939.31	2294
1941.29	2264
1943.27	2302
1945.24	2294
1947.22	2256
1949.2	2278
1951.17	2260
1953.14	2251
1955.12	2222
1957.09	2254
1959.06	2240
1961.04	2222
1963.01	2196
1964.98	2180
1966.95	2172
1968.92	2220
1970.89	2146
1972.86	2150
1974.82	2174
1976.79	2126
1978.76	2136
1980.72	2158
1982.69	2102
1984.65	2118
1986.62	2094
1988.58	2096
1990.54	2140
1992.51	2116
1994.47	2154
1996.43	2102
1998.39	2108
1999.37	2116