File: muestras/billete_e/Organic_10.txt
#Acq. time (s)=	15
#Accumulations=	1
#Range (cm-¹)=	100...2000
#Windows=	2
#Autofocus=	Off
#AutoExposure=	Off
#Spike filter=	Off
#Delay time (s)=	0
#Binning=	1
#Readout mode=	Signal
#DeNoise=	Off
#ICS correction=	Off
#Dark correction=	Off
#Inst. Process=	Off
#Instrument=	LabRAM HR Evol
#Detector=	Syncerity OE
#Objective=	x100_VIS
#Grating=	600 (500nm)
#ND Filter=	50%
#Laser=	633nm_Edge
#Hole=	74.97
#Range=	Visible
#Project=	Omar
#Sample=	20-06-23
#Site=	3
#Title=	Organic
#Remark=
#Date=	20.06.2023 12:26
#Acquired=	20.06.2023 12:26:45
101.054	3068
103.621	3064
106.187	3110
108.752	3114
111.317	3122
113.881	3116
116.443	3184
119.005	3000
121.566	3020
124.126	3066
126.685	3066
129.243	3048
131.801	3108
134.356	3108
136.911	3038
139.466	3106
142.021	3066
144.574	3078
147.125	3066
149.676	3008
152.227	3090
154.776	3064
157.325	3078
159.873	3064
162.419	3046
164.966	3054
167.51	3086
170.055	3022
172.598	3058
175.141	2982
177.682	3012
180.222	3054
182.763	2962
185.302	2978
187.839	3024
190.376	2976
192.914	3020
195.449	3006
197.983	2992
200.517	3062
203.05	3004
205.582	3044
208.113	2976
210.643	2984
213.173	3002
215.701	3018
218.229	3026
220.756	2974
223.282	2968
225.808	2982
228.331	3024
230.855	2978
233.378	3002
235.898	2994
238.419	2998
240.94	3052
243.458	3000
245.977	2956
248.495	2976
251.011	3052
253.527	2998
256.041	2894
258.555	2960
261.068	2976
263.58	2918
266.092	2880
268.603	2942
271.112	2890
273.62	2872
276.129	2884
278.636	2896
281.142	2970
283.647	2916
286.152	2930
288.655	2910
291.158	2868
293.66	2882
296.161	2898
298.661	2878
301.161	2894
303.66	2970
306.158	2924
308.655	2944
311.15	2878
313.645	2884
316.14	2914
318.634	2870
321.125	2894
323.618	2914
326.109	2926
328.598	2930
331.088	2848
333.576	2924
336.064	2832
338.55	2856
341.037	2838
343.521	2786
346.005	2836
348.489	2830
350.971	2806
353.453	2810
355.933	2868
358.414	2784
360.893	2834
363.371	2800
365.848	2842
368.325	2780
370.801	2816
373.275	2812
375.75	2810
378.223	2782
380.695	2754
383.167	2756
385.638	2738
388.108	2654
390.577	2744
393.044	2770
395.512	2760
397.979	2730
400.444	2800
402.909	2762
405.374	2686
407.836	2714
410.299	2736
412.76	2788
415.221	2732
417.681	2724
420.141	2794
422.598	2734
425.057	2728
427.513	2728
429.968	2760
432.422	2778
434.878	2820
437.33	2704
439.783	2744
442.234	2698
444.685	2774
447.134	2718
449.583	2712
452.032	2678
454.479	2716
456.926	2628
459.372	2654
461.817	2694
464.261	2688
466.705	2688
469.147	2618
471.588	2674
474.029	2682
476.47	2582
478.909	2628
481.347	2614
483.785	2620
486.221	2596
488.657	2602
491.092	2626
493.527	2598
495.96	2582
498.393	2570
500.824	2550
503.255	2622
505.686	2536
508.115	2634
510.543	2626
512.972	2570
515.399	2586
517.825	2518
520.25	2574
522.674	2530
525.097	2484
527.52	2526
529.942	2550
532.364	2446
534.784	2532
537.204	2478
539.623	2466
542.041	2528
544.457	2464
546.874	2464
549.289	2440
551.705	2470
554.118	2420
556.531	2404
558.943	2406
561.355	2398
563.766	2444
566.175	2390
568.585	2386
570.992	2394
573.399	2476
575.807	2324
578.212	2422
580.617	2384
583.022	2390
585.425	2424
587.827	2350
590.229	2378
592.63	2358
595.03	2354
597.43	2342
599.829	2332
602.226	2332
604.623	2352
607.02	2336
609.414	2374
611.808	2330
614.202	2320
616.596	2364
618.988	2310
621.378	2352
623.769	2296
626.159	2312
628.548	2326
630.936	2326
633.324	2292
635.71	2314
638.096	2300
640.481	2294
642.866	2350
645.248	2340
647.63	2396
650.013	2358
652.394	2300
654.773	2272
657.154	2264
659.532	2318
661.91	2308
664.286	2310
666.663	2254
669.038	2260
671.412	2242
673.786	2252
676.159	2218
678.532	2194
680.903	2202
683.274	2188
685.644	2212
688.014	2186
690.381	2156
692.749	2170
695.116	2120
697.481	2180
699.846	2158
702.211	2238
704.574	2196
706.938	2122
709.299	2188
711.661	2182
714.021	2160
716.381	2126
718.739	2168
721.097	2146
723.455	2158
725.811	2096
728.167	2170
730.521	2106
732.875	2174
735.23	2098
737.582	2134
739.934	2200
742.285	2124
744.635	2154
746.985	2090
749.332	2092
751.68	2076
754.028	2078
756.374	2074
758.72	2078
761.065	2048
763.408	2084
765.752	2100
768.095	2042
770.436	2064
772.777	2046
775.116	2088
777.456	2026
779.794	2090
782.133	2056
784.469	2002
786.805	1994
789.141	2020
791.476	2010
793.809	2086
796.142	2044
798.476	2008
800.807	2032
803.138	2054
805.468	2078
807.797	2038
810.125	2000
812.453	2024
814.78	1998
817.106	2050
819.432	2044
821.757	2032
824.08	1976
826.403	2026
828.726	1992
831.048	2008
833.368	1994
835.688	2026
838.007	2016
840.326	2020
842.644	2034
844.96	2062
847.276	2024
849.592	2036
851.906	2016
854.221	2052
856.534	2044
858.846	2026
861.157	1998
863.469	2010
865.779	2030
868.088	2024
870.396	2018
872.704	2052
875.011	2012
877.318	2004
879.623	1982
881.928	2026
884.232	1988
886.536	2020
888.837	1960
891.139	1942
893.44	1988
895.741	1954
898.039	1984
900.339	1974
902.637	1920
904.933	1952
907.231	1984
909.526	2016
911.821	1946
914.115	1940
916.408	1972
918.701	1924
920.993	1972
923.283	1982
925.573	1986
927.864	1926
930.153	1908
932.441	1910
934.728	1970
937.014	1928
939.3	1912
941.585	1954
943.87	1948
946.154	1974
948.437	1970
950.719	1986
952.999	1952
955.28	1978
957.56	2010
959.84	2016
962.117	1958
964.395	1954
966.671	1960
968.948	1942
971.223	1986
973.498	1938
975.771	1962
978.045	1992
980.317	1972
982.588	2012
984.86	1994
987.13	1930
989.399	1916
991.667	2002
993.937	1950
996.204	1976
998.47	1970
1000.74	1936
1003	2006
1005.26	1934
1007.53	1960
1009.79	1996
1012.05	1932
1014.31	1952
1016.57	1976
1018.83	1996
1021.09	1978
1023.35	2018
1025.61	1976
1027.87	2004
1030.12	2006
1032.38	1928
1034.63	2038
1036.88	2008
1039.14	2020
1041.39	2036
1043.64	1954
1045.89	1974
1048.14	2016
1050.39	2024
1052.64	2048
1054.89	2068
1057.14	2034
1059.38	1986
1061.63	2002
1063.87	2032
1066.12	1992
1068.36	2020
1070.6	2062
1072.85	2044
1075.09	2056
1077.33	2016
1079.57	1994
1081.81	2064
1084.05	2016
1086.28	2016
1088.52	2056
1090.76	1974
1092.99	1986
1095.23	2000
1097.46	2028
1099.69	2004
1101.93	2024
1104.16	2028
1106.39	1990
1108.62	1960
1110.85	1970
1113.08	2000
1115.31	1974
1117.53	2010
1119.76	1958
1121.99	1948
1124.21	1998
1126.44	2004
1128.66	1998
1130.88	1988
1133.11	1970
1135.33	2004
1137.55	2056
1139.77	2004
1141.99	2068
1144.21	2020
1146.43	2036
1148.64	2024
1150.86	2000
1153.08	1992
1155.29	2060
1157.51	2012
1159.72	2092
1161.93	1994
1164.14	2060
1166.36	2048
1168.57	2040
1170.78	2082
1172.99	2032
1175.2	2046
1177.4	2066
1179.61	2018
1181.82	2012
1184.02	2072
1186.23	2020
1188.43	2026
1190.64	2064
1192.84	2042
1195.04	2030
1197.24	2010
1199.45	2054.93
1201.64	1999.59
1203.84	1982.31
1206.04	2010.69
1208.24	2002.01
1210.44	1949.23
1212.64	1998.52
1214.83	1957.21
1217.03	1980.28
1219.22	2016.27
1221.41	1943.69
1223.61	1935.48
1225.8	1930.75
1227.99	1977.58
1230.18	1949.53
1232.37	1930.62
1234.56	1925.27
1236.75	1942.47
1238.94	1937.31
1241.13	1934.05
1243.31	1916.16
1245.5	1924.81
1247.68	1883.64
1249.87	1901.84
1252.05	1935.02
1254.24	1908.39
1256.42	1905.57
1258.6	1893.44
1260.78	1901.79
1262.96	1876.2
1265.14	1874.01
1267.32	1889.41
1269.5	1891.22
1271.67	1901.87
1273.85	1891.15
1276.03	1901.3
1278.2	1873.82
1280.38	1842.24
1282.55	1842.15
1284.72	1863.2
1286.9	1854.49
1289.07	1856.59
1291.24	1859.86
1293.41	1823.65
1295.58	1850.08
1297.75	1894.97
1299.92	1840.07
1302.09	1844.03
1304.25	1809.45
1306.42	1873.74
1308.46	1770
1310.63	1800
1312.81	1804
1314.98	1792
1317.16	1754
1319.33	1812
1321.5	1742
1323.67	1796
1325.85	1772
1328.02	1770
1330.19	1776
1332.35	1780
1334.52	1744
1336.69	1796
1338.86	1720
1341.02	1788
1343.19	1780
1345.35	1800
1347.52	1754
1349.68	1784
1351.84	1742
1354	1782
1356.17	1738
1358.33	1760
1360.49	1736
1362.65	1814
1364.8	1734
1366.96	1742
1369.12	1770
1371.28	1800
1373.43	1788
1375.59	1760
1377.74	1740
1379.89	1732
1382.05	1748
1384.2	1722
1386.35	1724
1388.5	1736
1390.65	1714
1392.8	1766
1394.95	1736
1397.1	1738
1399.25	1756
1401.4	1682
1403.54	1720
1405.69	1728
1407.83	1662
1409.98	1694
1412.12	1704
1414.26	1668
1416.4	1760
1418.55	1722
1420.69	1728
1422.83	1658
1424.97	1718
1427.1	1694
1429.24	1716
1431.38	1664
1433.52	1702
1435.65	1718
1437.79	1648
1439.92	1662
1442.06	1772
1444.19	1720
1446.32	1682
1448.46	1710
1450.59	1688
1452.72	1642
1454.85	1690
1456.98	1696
1459.11	1690
1461.23	1596
1463.36	1696
1465.49	1658
1467.61	1606
1469.74	1674
1471.86	1634
1473.99	1620
1476.11	1690
1478.23	1686
1480.36	1648
1482.48	1680
1484.6	1654
1486.72	1632
1488.84	1696
1490.96	1668
1493.07	1702
1495.19	1616
1497.31	1586
1499.42	1648
1501.54	1656
1503.65	1626
1505.77	1588
1507.88	1598
1509.99	1608
1512.1	1600
1514.22	1594
1516.33	1604
1518.44	1594
1520.55	1642
1522.65	1578
1524.76	1576
1526.87	1546
1528.98	1594
1531.08	1596
1533.19	1570
1535.29	1548
1537.4	1522
1539.5	1600
1541.6	1564
1543.7	1520
1545.8	1522
1547.91	1542
1550.01	1538
1552.11	1484
1554.2	1506
1556.3	1540
1558.4	1520
1560.5	1494
1562.59	1520
1564.69	1486
1566.78	1518
1568.88	1490
1570.97	1480
1573.06	1436
1575.15	1484
1577.25	1504
1579.34	1468
1581.43	1456
1583.52	1462
1585.6	1444
1587.69	1458
1589.78	1472
1591.87	1482
1593.95	1452
1596.04	1466
1598.12	1464
1600.21	1462
1602.29	1480
1604.37	1466
1606.46	1492
1608.54	1446
1610.62	1448
1612.7	1406
1614.78	1448
1616.86	1424
1618.94	1422
1621.01	1452
1623.09	1432
1625.17	1436
1627.24	1394
1629.32	1412
1631.39	1396
1633.47	1440
1635.54	1420
1637.61	1430
1639.68	1398
1641.76	1386
1643.83	1420
1645.9	1370
1647.96	1444
1650.03	1408
1652.1	1450
1654.17	1308
1656.24	1372
1658.3	1396
1660.37	1332
1662.43	1342
1664.5	1328
1666.56	1350
1668.62	1334
1670.68	1354
1672.75	1360
1674.81	1304
1676.87	1338
1678.93	1294
1680.99	1282
1683.04	1330
1685.1	1282
1687.16	1336
1689.21	1296
1691.27	1260
1693.33	1288
1695.38	1274
1697.43	1304
1699.49	1274
1701.54	1274
1703.59	1262
1705.64	1254
1707.69	1246
1709.74	1266
1711.79	1280
1713.84	1212
1715.89	1236
1717.94	1238
1719.98	1214
1722.03	1198
1724.07	1218
1726.12	1242
1728.16	1222
1730.21	1246
1732.25	1216
1734.29	1184
1736.33	1234
1738.37	1192
1740.41	1186
1742.45	1192
1744.49	1178
1746.53	1172
1748.57	1188
1750.61	1158
1752.64	1176
1754.68	1142
1756.71	1134
1758.75	1170
1760.78	1158
1762.82	1142
1764.85	1136
1766.88	1146
1768.91	1160
1770.94	1174
1772.97	1154
1775	1140
1777.03	1144
1779.06	1140
1781.09	1144
1783.12	1120
1785.14	1084
1787.17	1172
1789.19	1144
1791.22	1102
1793.24	1144
1795.27	1114
1797.29	1102
1799.31	1110
1801.33	1102
1803.35	1064
1805.37	1106
1807.39	1096
1809.41	1070
1811.43	1088
1813.45	1118
1815.46	1080
1817.48	1116
1819.5	1066
1821.51	1040
1823.53	1038
1825.54	1040
1827.55	1048
1829.57	1068
1831.58	1062
1833.59	1044
1835.6	1036
1837.61	1042
1839.62	1024
1841.63	1020
1843.64	1032
1845.65	1018
1847.65	1018
1849.66	1004
1851.66	978
1853.67	1000
1855.67	968
1857.68	1002
1859.68	1018
1861.68	978
1863.69	970
1865.69	966
1867.69	994
1869.69	948
1871.69	978
1873.69	968
1875.69	966
1877.68	998
1879.68	980
1881.68	940
1883.67	964
1885.67	964
1887.66	942
1889.66	982
1891.65	980
1893.64	948
1895.64	950
1897.63	924
1899.62	950
1901.61	964
1903.6	932
1905.59	922
1907.58	894
1909.56	886
1911.55	922
1913.54	888
1915.53	918
1917.51	932
1919.5	884
1921.48	900
1923.46	932
1925.45	886
1927.43	882
1929.41	884
1931.39	906
1933.37	912
1935.35	870
1937.33	890
1939.31	876
1941.29	904
1943.27	864
1945.24	876
1947.22	866
1949.2	856
1951.17	850
1953.14	886
1955.12	870
1957.09	906
1959.06	892
1961.04	840
1963.01	842
1964.98	852
1966.95	842
1968.92	846
1970.89	858
1972.86	870
1974.82	836
1976.79	858
1978.76	834
1980.72	818
1982.69	840
1984.65	804
1986.62	816
1988.58	814
1990.54	810
1992.51	830
1994.47	822
1996.43	766
1998.39	818
1999.37	812