File: muestras/billete_e/Organic_12.txt
#Acq. time (s)=	15
#Accumulations=	1
#Range (cm-¹)=	100...2000
#Windows=	2
#Autofocus=	Off
#AutoExposure=	Off
#Spike filter=	Off
#Delay time (s)=	0
#Binning=	1
#Readout mode=	Signal
#DeNoise=	Off
#ICS correction=	Off
#Dark correction=	Off
#Inst. Process=	Off
#Instrument=	LabRAM HR Evol
#Detector=	Syncerity OE
#Objective=	x100_VIS
#Grating=	600 (500nm)
#ND Filter=	50%
#Laser=	633nm_Edge
#Hole=	74.97
#Range=	Visible
#Project=	Omar
#Sample=	20-06-23
#Site=	3
#Title=	Organic
#Remark=
#Date=	20.06.2023 12:31
#Acquired=	20.06.2023 12:31:48
101.054	2318
103.621	2342
106.187	2306
108.752	2360
111.317	2322
113.881	2320
116.443	2306
119.005	2296
121.566	2326
124.126	2294
126.685	2302
129.243	2326
131.801	2272
134.356	2280
136.911	2272
139.466	2252
142.021	2238
144.574	2280
147.125	2230
149.676	2264
152.227	2308
154.776	2284
157.325	2254
159.873	2240
162.419	2288
164.966	2228
167.51	2328
170.055	2240
172.598	2238
175.141	2266
177.682	2184
180.222	2148
182.763	2240
185.302	2262
187.839	2218
190.376	2206
192.914	2230
195.449	2202
197.983	2206
200.517	2246
203.05	2272
205.582	2284
208.113	2200
210.643	2252
213.173	2220
215.701	2256
218.229	2178
220.756	2180
223.282	2184
225.808	2248
228.331	2212
230.855	2180
233.378	2174
235.898	2140
238.419	2226
240.94	2170
243.458	2178
245.977	2122
248.495	2204
251.011	2162
253.527	2146
256.041	2174
258.555	2184
261.068	2134
263.58	2146
266.092	2112
268.603	2100
271.112	2058
273.62	2116
276.129	2074
278.636	2056
281.142	2064
283.647	2074
286.152	2046
288.655	2060
291.158	2046
293.66	2060
296.161	2072
298.661	2068
301.161	2082
303.66	2096
306.158	1988
308.655	2046
311.15	2060
313.645	2022
316.14	2056
318.634	2012
321.125	1956
323.618	2036
326.109	2042
328.598	2004
331.088	1956
333.576	2012
336.064	1984
338.55	1978
341.037	1970
343.521	1980
346.005	1942
348.489	2040
350.971	1996
353.453	1996
355.933	1998
358.414	1978
360.893	1970
363.371	1924
365.848	1958
368.325	1890
370.801	1910
373.275	1924
375.75	1874
378.223	1850
380.695	1820
383.167	1880
385.638	1906
388.108	1900
390.577	1832
393.044	1906
395.512	1808
397.979	1872
400.444	1812
402.909	1876
405.374	1894
407.836	1916
410.299	1872
412.76	1850
415.221	1914
417.681	1884
420.141	1850
422.598	1898
425.057	1910
427.513	1892
429.968	1902
432.422	1886
434.878	1858
437.33	1844
439.783	1908
442.234	1904
444.685	1848
447.134	1860
449.583	1866
452.032	1844
454.479	1840
456.926	1852
459.372	1854
461.817	1844
464.261	1852
466.705	1802
469.147	1850
471.588	1878
474.029	1832
476.47	1824
478.909	1896
481.347	1794
483.785	1810
486.221	1858
488.657	1834
491.092	1812
493.527	1834
495.96	1870
498.393	1876
500.824	1810
503.255	1836
505.686	1814
508.115	1842
510.543	1808
512.972	1782
515.399	1828
517.825	1794
520.25	1812
522.674	1796
525.097	1748
527.52	1784
529.942	1760
532.364	1784
534.784	1796
537.204	1808
539.623	1764
542.041	1770
544.457	1762
546.874	1756
549.289	1764
551.705	1768
554.118	1754
556.531	1720
558.943	1776
561.355	1736
563.766	1770
566.175	1724
568.585	1756
570.992	1746
573.399	1734
575.807	1766
578.212	1762
580.617	1724
583.022	1776
585.425	1750
587.827	1674
590.229	1768
592.63	1800
595.03	1792
597.43	1786
599.829	1780
602.226	1790
604.623	1776
607.02	1744
609.414	1742
611.808	1854
614.202	1752
616.596	1828
618.988	1784
621.378	1796
623.769	1806
626.159	1830
628.548	1884
630.936	1800
633.324	1804
635.71	1826
638.096	1862
640.481	1868
642.866	1794
645.248	1846
647.63	1880
650.013	1860
652.394	1886
654.773	1814
657.154	1898
659.532	1866
661.91	1824
664.286	1790
666.663	1852
669.038	1810
671.412	1762
673.786	1844
676.159	1852
678.532	1884
680.903	1832
683.274	1852
685.644	1856
688.014	1860
690.381	1818
692.749	1876
695.116	1892
697.481	1872
699.846	1866
702.211	1844
704.574	1884
706.938	1864
709.299	1874
711.661	1866
714.021	1864
716.381	1890
718.739	1880
721.097	1884
723.455	1888
725.811	1866
728.167	1908
730.521	1868
732.875	1868
735.23	1882
737.582	1912
739.934	1894
742.285	1934
744.635	1870
746.985	1862
749.332	1880
751.68	1888
754.028	1884
756.374	1890
758.72	1924
761.065	1950
763.408	1892
765.752	1842
768.095	1846
770.436	1872
772.777	1892
775.116	1854
777.456	1958
779.794	1922
782.133	1932
784.469	1860
786.805	1900
789.141	1882
791.476	1904
793.809	1910
796.142	1886
798.476	1918
800.807	1912
803.138	1894
805.468	1948
807.797	1876
810.125	1920
812.453	1918
814.78	1926
817.106	1960
819.432	1934
821.757	1928
824.08	1964
826.403	1942
828.726	1948
831.048	1926
833.368	2004
835.688	1982
838.007	1886
840.326	1974
842.644	1966
844.96	1956
847.276	1942
849.592	1914
851.906	1988
854.221	1970
856.534	1986
858.846	1990
861.157	1920
863.469	2028
865.779	1944
868.088	2036
870.396	1990
872.704	1988
875.011	1960
877.318	1996
879.623	1964
881.928	2032
884.232	1998
886.536	1964
888.837	1938
891.139	2016
893.44	1958
895.741	1982
898.039	1938
900.339	1910
902.637	1932
904.933	1978
907.231	1908
909.526	1922
911.821	1900
914.115	1954
916.408	1954
918.701	1926
920.993	1952
923.283	1936
925.573	1872
927.864	1910
930.153	1922
932.441	1924
934.728	1878
937.014	1892
939.3	1900
941.585	1924
943.87	1910
946.154	1886
948.437	1940
950.719	1954
952.999	1932
955.28	1900
957.56	1946
959.84	1956
962.117	1908
964.395	1960
966.671	1888
968.948	1870
971.223	1918
973.498	1900
975.771	1842
978.045	1868
980.317	1918
982.588	1902
984.86	1860
987.13	1908
989.399	1896
991.667	1846
993.937	1864
996.204	1832
998.47	1846
1000.74	1846
1003	1760
1005.26	1868
1007.53	1828
1009.79	1832
1012.05	1860
1014.31	1866
1016.57	1842
1018.83	1822
1021.09	1828
1023.35	1822
1025.61	1806
1027.87	1770
1030.12	1810
1032.38	1824
1034.63	1834
1036.88	1740
1039.14	1770
1041.39	1856
1043.64	1802
1045.89	1770
1048.14	1790
1050.39	1758
1052.64	1804
1054.89	1786
1057.14	1770
1059.38	1732
1061.63	1782
1063.87	1794
1066.12	1780
1068.36	1740
1070.6	1718
1072.85	1728
1075.09	1782
1077.33	1700
1079.57	1750
1081.81	1662
1084.05	1632
1086.28	1716
1088.52	1686
1090.76	1720
1092.99	1704
1095.23	1666
1097.46	1716
1099.69	1668
1101.93	1684
1104.16	1654
1106.39	1654
1108.62	1650
1110.85	1622
1113.08	1586
1115.31	1682
1117.53	1654
1119.76	1590
1121.99	1656
1124.21	1632
1126.44	1614
1128.66	1608
1130.88	1610
1133.11	1588
1135.33	1594
1137.55	1614
1139.77	1646
1141.99	1616
1144.21	1614
1146.43	1582
1148.64	1518
1150.86	1638
1153.08	1576
1155.29	1544
1157.51	1562
1159.72	1624
1161.93	1540
1164.14	1602
1166.36	1538
1168.57	1560
1170.78	1528
1172.99	1574
1175.2	1550
1177.4	1538
1179.61	1562
1181.82	1490
1184.02	1548
1186.23	1502
1188.43	1506
1190.64	1468
1192.84	1544
1195.04	1454
1197.24	1470
1199.45	1501.79
1201.64	1518.4
1203.84	1471.36
1206.04	1530.71
1208.24	1488.8
1210.44	1481.76
1212.64	1491.89
1214.83	1442.85
1217.03	1447.94
1219.22	1425.62
1221.41	1448.18
1223.61	1423.6
1225.8	1419.21
1227.99	1411.04
1230.18	1386.87
1232.37	1419.85
1234.56	1404.43
1236.75	1392.96
1238.94	1403.24
1241.13	1395.54
1243.31	1367.72
1245.5	1392.15
1247.68	1368.1
1249.87	1394.55
1252.05	1398.45
1254.24	1404.06
1256.42	1423.31
1258.6	1399.69
1260.78	1408.11
1262.96	1387.73
1265.14	1372.88
1267.32	1368.5
1269.5	1389.45
1271.67	1396.68
1273.85	1367.77
1276.03	1368.2
1278.2	1355.64
1280.38	1378.52
1282.55	1370.9
1284.72	1371.48
1286.9	1340.77
1289.07	1339.04
1291.24	1350.59
1293.41	1373.25
1295.58	1376.01
1297.75	1350.38
1299.92	1359.68
1302.09	1332.04
1304.25	1385.73
1306.42	1355.94
1308.46	1308
1310.63	1332
1312.81	1356
1314.98	1338
1317.16	1310
1319.33	1332
1321.5	1342
1323.67	1332
1325.85	1352
1328.02	1342
1330.19	1300
1332.35	1268
1334.52	1350
1336.69	1308
1338.86	1344
1341.02	1276
1343.19	1300
1345.35	1296
1347.52	1300
1349.68	1356
1351.84	1332
1354	1316
1356.17	1320
1358.33	1308
1360.49	1294
1362.65	1284
1364.8	1308
1366.96	1314
1369.12	1368
1371.28	1286
1373.43	1336
1375.59	1318
1377.74	1324
1379.89	1298
1382.05	1314
1384.2	1302
1386.35	1294
1388.5	1292
1390.65	1308
1392.8	1326
1394.95	1260
1397.1	1284
1399.25	1300
1401.4	1308
1403.54	1308
1405.69	1316
1407.83	1286
1409.98	1248
1412.12	1270
1414.26	1260
1416.4	1300
1418.55	1288
1420.69	1304
1422.83	1270
1424.97	1298
1427.1	1288
1429.24	1264
1431.38	1310
1433.52	1276
1435.65	1234
1437.79	1264
1439.92	1294
1442.06	1282
1444.19	1276
1446.32	1256
1448.46	1326
1450.59	1324
1452.72	1332
1454.85	1268
1456.98	1268
1459.11	1278
1461.23	1286
1463.36	1312
1465.49	1280
1467.61	1304
1469.74	1276
1471.86	1304
1473.99	1292
1476.11	1292
1478.23	1312
1480.36	1266
1482.48	1338
1484.6	1262
1486.72	1318
1488.84	1264
1490.96	1244
1493.07	1304
1495.19	1246
1497.31	1322
1499.42	1282
1501.54	1258
1503.65	1272
1505.77	1298
1507.88	1262
1509.99	1248
1512.1	1270
1514.22	1288
1516.33	1276
1518.44	1232
1520.55	1278
1522.65	1282
1524.76	1230
1526.87	1210
1528.98	1230
1531.08	1234
1533.19	1254
1535.29	1236
1537.4	1222
1539.5	1246
1541.6	1250
1543.7	1254
1545.8	1262
1547.91	1196
1550.01	1254
1552.11	1236
1554.2	1198
1556.3	1212
1558.4	1178
1560.5	1176
1562.59	1186
1564.69	1240
1566.78	1152
1568.88	1196
1570.97	1192
1573.06	1206
1575.15	1164
1577.25	1202
1579.34	1258
1581.43	1242
1583.52	1218
1585.6	1162
1587.69	1200
1589.78	1220
1591.87	1206
1593.95	1198
1596.04	1158
1598.12	1204
1600.21	1202
1602.29	1178
1604.37	1212
1606.46	1182
1608.54	1146
1610.62	1140
1612.7	1190
1614.78	1204
1616.86	1170
1618.94	1176
1621.01	1194
1623.09	1146
1625.17	1184
1627.24	1162
1629.32	1184
1631.39	1128
1633.47	1140
1635.54	1152
1637.61	1182
1639.68	1140
1641.76	1190
1643.83	1146
1645.9	1146
1647.96	1108
1650.03	1132
1652.1	1090
1654.17	1100
1656.24	1090
1658.3	1130
1660.37	1100
1662.43	1092
1664.5	1106
1666.56	1100
1668.62	1070
1670.68	1092
1672.75	1090
1674.81	1090
1676.87	1052
1678.93	1102
1680.99	1068
1683.04	1058
1685.1	1082
1687.16	1010
1689.21	1058
1691.27	1082
1693.33	1066
1695.38	1052
1697.43	1042
1699.49	1022
1701.54	1018
1703.59	1060
1705.64	1024
1707.69	1004
1709.74	1030
1711.79	1018
1713.84	1026
1715.89	956
1717.94	1002
1719.98	986
1722.03	980
1724.07	1010
1726.12	990
1728.16	982
1730.21	968
1732.25	1008
1734.29	958
1736.33	978
1738.37	992
1740.41	968
1742.45	994
1744.49	980
1746.53	936
1748.57	938
1750.61	984
1752.64	958
1754.68	956
1756.71	952
1758.75	928
1760.78	946
1762.82	950
1764.85	928
1766.88	956
1768.91	954
1770.94	900
1772.97	924
1775	928
1777.03	890
1779.06	888
1781.09	894
1783.12	900
1785.14	884
1787.17	912
1789.19	876
1791.22	912
1793.24	932
1795.27	866
1797.29	854
1799.31	894
1801.33	862
1803.35	864
1805.37	850
1807.39	862
1809.41	860
1811.43	862
1813.45	856
1815.46	878
1817.48	838
1819.5	844
1821.51	846
1823.53	790
1825.54	826
1827.55	810
1829.57	796
1831.58	822
1833.59	822
1835.6	814
1837.61	768
1839.62	818
1841.63	792
1843.64	772
1845.65	802
1847.65	784
1849.66	776
1851.66	748
1853.67	754
1855.67	758
1857.68	764
1859.68	764
1861.68	780
1863.69	768
1865.69	758
1867.69	760
1869.69	738
1871.69	764
1873.69	730
1875.69	706
1877.68	732
1879.68	720
1881.68	722
1883.67	698
1885.67	714
1887.66	748
1889.66	706
1891.65	732
1893.64	720
1895.64	702
1897.63	666
1899.62	688
1901.61	692
1903.6	706
1905.59	686
1907.58	684
1909.56	668
1911.55	700
1913.54	694
1915.53	674
1917.51	684
1919.5	702
1921.48	686
1923.46	658
1925.45	684
1927.43	660
1929.41	700
1931.39	672
1933.37	640
1935.35	680
1937.33	652
1939.31	662
1941.29	630
1943.27	630
1945.24	620
1947.22	668
1949.2	610
1951.17	628
1953.14	631
1955.12	602
1957.09	610
1959.06	626
1961.04	608
1963.01	632
1964.98	608
1966.95	608
1968.92	592
1970.89	624
1972.86	586
1974.82	610
1976.79	600
1978.76	580
1980.72	574
1982.69	588
1984.65	580
1986.62	578
1988.58	574
1990.54	580
1992.51	604
1994.47	578
1996.43	578
1998.39	600
1999.37	572