File: 2/Organic_13.txt
#Acq. time (s)=	15
#Accumulations=	1
#Range (cm-¹)=	100...2000
#Windows=	2
#Autofocus=	Off
#AutoExposure=	Off
#Spike filter=	Off
#Delay time (s)=	0
#Binning=	1
#Readout mode=	Signal
#DeNoise=	Off
#ICS correction=	Off
#Dark correction=	Off
#Inst. Process=	Off
#Instrument=	LabRAM HR Evol
#Detector=	Syncerity OE
#Objective=	x100_VIS
#Grating=	600 (500nm)
#ND Filter=	100%
#Laser=	633nm_Edge
#Hole=	100.021
#Range=	Visible
#Project=	Omar
#Sample=	20-06-23
#Site=	2
#Title=	Organic
#Remark=
#Date=	20.06.2023 12:05
#Acquired=	20.06.2023 12:05:00
101.054	1238
103.621	1314
106.187	1238
108.752	1236
111.317	1226
113.881	1214
116.443	1260
119.005	1228
121.566	1284
124.126	1226
126.685	1268
129.243	1270
131.801	1276
134.356	1268
136.911	1280
139.466	1246
142.021	1256
144.574	1302
147.125	1242
149.676	1258
152.227	1276
154.776	1234
157.325	1288
159.873	1254
162.419	1242
164.966	1248
167.51	1300
170.055	1268
172.598	1244
175.141	1260
177.682	1236
180.222	1254
182.763	1274
185.302	1296
187.839	1276
190.376	1266
192.914	1278
195.449	1310
197.983	1288
200.517	1296
203.05	1282
205.582	1310
208.113	1322
210.643	1260
213.173	1298
215.701	1306
218.229	1304
220.756	1300
223.282	1326
225.808	1292
228.331	1310
230.855	1334
233.378	1342
235.898	1314
238.419	1316
240.94	1330
243.458	1320
245.977	1298
248.495	1300
251.011	1294
253.527	1304
256.041	1340
258.555	1356
261.068	1296
263.58	1354
266.092	1292
268.603	1322
271.112	1314
273.62	1294
276.129	1356
278.636	1298
281.142	1310
283.647	1318
286.152	1330
288.655	1376
291.158	1348
293.66	1342
296.161	1336
298.661	1390
301.161	1306
303.66	1338
306.158	1372
308.655	1300
311.15	1362
313.645	1368
316.14	1332
318.634	1362
321.125	1348
323.618	1354
326.109	1360
328.598	1398
331.088	1328
333.576	1400
336.064	1338
338.55	1360
341.037	1374
343.521	1406
346.005	1380
348.489	1390
350.971	1422
353.453	1420
355.933	1376
358.414	1412
360.893	1392
363.371	1370
365.848	1406
368.325	1374
370.801	1408
373.275	1344
375.75	1388
378.223	1368
380.695	1354
383.167	1390
385.638	1336
388.108	1358
390.577	1364
393.044	1378
395.512	1362
397.979	1344
400.444	1396
402.909	1382
405.374	1346
407.836	1356
410.299	1414
412.76	1410
415.221	1374
417.681	1412
420.141	1422
422.598	1416
425.057	1404
427.513	1416
429.968	1434
432.422	1446
434.878	1458
437.33	1406
439.783	1428
442.234	1406
444.685	1424
447.134	1402
449.583	1430
452.032	1364
454.479	1436
456.926	1412
459.372	1398
461.817	1412
464.261	1388
466.705	1376
469.147	1412
471.588	1416
474.029	1454
476.47	1466
478.909	1390
481.347	1454
483.785	1462
486.221	1424
488.657	1430
491.092	1438
493.527	1434
495.96	1436
498.393	1430
500.824	1426
503.255	1422
505.686	1424
508.115	1442
510.543	1446
512.972	1466
515.399	1418
517.825	1390
520.25	1434
522.674	1430
525.097	1396
527.52	1402
529.942	1416
532.364	1422
534.784	1390
537.204	1408
539.623	1412
542.041	1384
544.457	1394
546.874	1386
549.289	1394
551.705	1354
554.118	1396
556.531	1406
558.943	1394
561.355	1392
563.766	1420
566.175	1400
568.585	1396
570.992	1402
573.399	1402
575.807	1418
578.212	1414
580.617	1392
583.022	1376
585.425	1396
587.827	1390
590.229	1346
592.63	1404
595.03	1414
597.43	1382
599.829	1364
602.226	1452
604.623	1420
607.02	1430
609.414	1382
611.808	1350
614.202	1408
616.596	1416
618.988	1400
621.378	1382
623.769	1366
626.159	1414
628.548	1434
630.936	1396
633.324	1382
635.71	1420
638.096	1410
640.481	1450
642.866	1432
645.248	1374
647.63	1426
650.013	1398
652.394	1394
654.773	1390
657.154	1376
659.532	1426
661.91	1354
664.286	1398
666.663	1380
669.038	1394
671.412	1360
673.786	1446
676.159	1408
678.532	1388
680.903	1430
683.274	1364
685.644	1396
688.014	1368
690.381	1400
692.749	1338
695.116	1350
697.481	1350
699.846	1410
702.211	1368
704.574	1394
706.938	1374
709.299	1356
711.661	1396
714.021	1322
716.381	1336
718.739	1334
721.097	1380
723.455	1348
725.811	1368
728.167	1384
730.521	1326
732.875	1342
735.23	1394
737.582	1346
739.934	1344
742.285	1370
744.635	1398
746.985	1334
749.332	1374
751.68	1374
754.028	1352
756.374	1372
758.72	1346
761.065	1340
763.408	1306
765.752	1314
768.095	1336
770.436	1348
772.777	1360
775.116	1356
777.456	1350
779.794	1368
782.133	1324
784.469	1320
786.805	1348
789.141	1368
791.476	1324
793.809	1324
796.142	1344
798.476	1322
800.807	1342
803.138	1320
805.468	1360
807.797	1324
810.125	1372
812.453	1298
814.78	1350
817.106	1314
819.432	1354
821.757	1302
824.08	1288
826.403	1320
828.726	1330
831.048	1334
833.368	1324
835.688	1314
838.007	1284
840.326	1318
842.644	1354
844.96	1378
847.276	1348
849.592	1342
851.906	1370
854.221	1380
856.534	1340
858.846	1326
861.157	1372
863.469	1370
865.779	1336
868.088	1338
870.396	1324
872.704	1348
875.011	1316
877.318	1360
879.623	1362
881.928	1338
884.232	1320
886.536	1294
888.837	1266
891.139	1340
893.44	1294
895.741	1322
898.039	1292
900.339	1310
902.637	1270
904.933	1302
907.231	1286
909.526	1314
911.821	1320
914.115	1268
916.408	1270
918.701	1270
920.993	1292
923.283	1282
925.573	1284
927.864	1290
930.153	1294
932.441	1314
934.728	1294
937.014	1298
939.3	1274
941.585	1292
943.87	1278
946.154	1332
948.437	1322
950.719	1206
952.999	1242
955.28	1286
957.56	1268
959.84	1280
962.117	1274
964.395	1268
966.671	1288
968.948	1286
971.223	1302
973.498	1304
975.771	1296
978.045	1254
980.317	1306
982.588	1270
984.86	1248
987.13	1212
989.399	1254
991.667	1216
993.937	1286
996.204	1246
998.47	1232
1000.74	1262
1003	1272
1005.26	1264
1007.53	1246
1009.79	1224
1012.05	1234
1014.31	1280
1016.57	1284
1018.83	1228
1021.09	1214
1023.35	1226
1025.61	1236
1027.87	1234
1030.12	1208
1032.38	1246
1034.63	1244
1036.88	1236
1039.14	1304
1041.39	1262
1043.64	1264
1045.89	1276
1048.14	1252
1050.39	1306
1052.64	1346
1054.89	1252
1057.14	1276
1059.38	1300
1061.63	1290
1063.87	1264
1066.12	1262
1068.36	1246
1070.6	1274
1072.85	1258
1075.09	1280
1077.33	1274
1079.57	1240
1081.81	1236
1084.05	1274
1086.28	1256
1088.52	1250
1090.76	1260
1092.99	1248
1095.23	1238
1097.46	1236
1099.69	1202
1101.93	1248
1104.16	1256
1106.39	1200
1108.62	1236
1110.85	1214
1113.08	1180
1115.31	1224
1117.53	1268
1119.76	1226
1121.99	1252
1124.21	1198
1126.44	1224
1128.66	1254
1130.88	1236
1133.11	1218
1135.33	1260
1137.55	1188
1139.77	1126
1141.99	1180
1144.21	1174
1146.43	1202
1148.64	1190
1150.86	1172
1153.08	1182
1155.29	1198
1157.51	1152
1159.72	1188
1161.93	1154
1164.14	1142
1166.36	1192
1168.57	1194
1170.78	1140
1172.99	1178
1175.2	1136
1177.4	1184
1179.61	1154
1181.82	1166
1184.02	1182
1186.23	1180
1188.43	1088
1190.64	1194
1192.84	1138
1195.04	1164
1197.24	1158
1199.45	1155.81
1201.64	1121.11
1203.84	1168.39
1206.04	1117.31
1208.24	1117.8
1210.44	1114.88
1212.64	1118.73
1214.83	1097.27
1217.03	1095.71
1219.22	1091.06
1221.41	1111.8
1223.61	1110.17
1225.8	1090.15
1227.99	1068.11
1230.18	1109.98
1232.37	1092.51
1234.56	1134.37
1236.75	1123.67
1238.94	1087.98
1241.13	1100.19
1243.31	1077.67
1245.5	1088.98
1247.68	1109.07
1249.87	1116.44
1252.05	1109.79
1254.24	1114.17
1256.42	1089.22
1258.6	1102.38
1260.78	1104.75
1262.96	1096.97
1265.14	1095.46
1267.32	1099.09
1269.5	1073.27
1271.67	1082.28
1273.85	1107.3
1276.03	1103.36
1278.2	1088.34
1280.38	1069.67
1282.55	1090.34
1284.72	1071.24
1286.9	1128.62
1289.07	1105.2
1291.24	1113.6
1293.41	1126.71
1295.58	1135.05
1297.75	1092.44
1299.92	1104.38
1302.09	1088.87
1304.25	1101.14
1306.42	1093.73
1308.46	1098
1310.63	1106
1312.81	1082
1314.98	1078
1317.16	1032
1319.33	1080
1321.5	1076
1323.67	1074
1325.85	1078
1328.02	1066
1330.19	1074
1332.35	1066
1334.52	1056
1336.69	1070
1338.86	1048
1341.02	1060
1343.19	1060
1345.35	1090
1347.52	1100
1349.68	1040
1351.84	1058
1354	1042
1356.17	1048
1358.33	1030
1360.49	1062
1362.65	1020
1364.8	1026
1366.96	1034
1369.12	1048
1371.28	1058
1373.43	1016
1375.59	1048
1377.74	1032
1379.89	1086
1382.05	1018
1384.2	1020
1386.35	1024
1388.5	1068
1390.65	1022
1392.8	1042
1394.95	976
1397.1	1012
1399.25	1024
1401.4	1010
1403.54	1000
1405.69	988
1407.83	1020
1409.98	1022
1412.12	978
1414.26	1018
1416.4	1024
1418.55	988
1420.69	1012
1422.83	1020
1424.97	1020
1427.1	984
1429.24	1030
1431.38	1030
1433.52	1076
1435.65	1030
1437.79	998
1439.92	1030
1442.06	1050
1444.19	1062
1446.32	1048
1448.46	1030
1450.59	1028
1452.72	1026
1454.85	1038
1456.98	998
1459.11	986
1461.23	1008
1463.36	988
1465.49	992
1467.61	998
1469.74	996
1471.86	986
1473.99	984
1476.11	978
1478.23	942
1480.36	968
1482.48	992
1484.6	960
1486.72	970
1488.84	946
1490.96	952
1493.07	924
1495.19	948
1497.31	932
1499.42	900
1501.54	942
1503.65	938
1505.77	972
1507.88	964
1509.99	918
1512.1	928
1514.22	912
1516.33	956
1518.44	962
1520.55	940
1522.65	916
1524.76	936
1526.87	922
1528.98	916
1531.08	950
1533.19	896
1535.29	886
1537.4	888
1539.5	902
1541.6	934
1543.7	886
1545.8	878
1547.91	874
1550.01	882
1552.11	882
1554.2	902
1556.3	880
1558.4	920
1560.5	870
1562.59	882
1564.69	902
1566.78	864
1568.88	906
1570.97	912
1573.06	854
1575.15	882
1577.25	852
1579.34	918
1581.43	852
1583.52	848
1585.6	854
1587.69	860
1589.78	854
1591.87	872
1593.95	872
1596.04	850
1598.12	854
1600.21	862
1602.29	824
1604.37	874
1606.46	870
1608.54	876
1610.62	882
1612.7	864
1614.78	870
1616.86	882
1618.94	860
1621.01	872
1623.09	904
1625.17	836
1627.24	858
1629.32	836
1631.39	854
1633.47	860
1635.54	880
1637.61	834
1639.68	818
1641.76	856
1643.83	808
1645.9	834
1647.96	858
1650.03	860
1652.1	820
1654.17	816
1656.24	846
1658.3	864
1660.37	822
1662.43	802
1664.5	824
1666.56	808
1668.62	824
1670.68	824
1672.75	814
1674.81	788
1676.87	826
1678.93	812
1680.99	838
1683.04	786
1685.1	818
1687.16	798
1689.21	794
1691.27	790
1693.33	784
1695.38	772
1697.43	766
1699.49	814
1701.54	824
1703.59	806
1705.64	804
1707.69	810
1709.74	786
1711.79	784
1713.84	790
1715.89	798
1717.94	764
1719.98	758
1722.03	790
1724.07	772
1726.12	764
1728.16	796
1730.21	792
1732.25	774
1734.29	774
1736.33	776
1738.37	760
1740.41	782
1742.45	774
1744.49	754
1746.53	758
1748.57	748
1750.61	774
1752.64	744
1754.68	724
1756.71	780
1758.75	754
1760.78	742
1762.82	732
1764.85	748
1766.88	774
1768.91	782
1770.94	758
1772.97	748
1775	732
1777.03	738
1779.06	736
1781.09	738
1783.12	740
1785.14	756
1787.17	758
1789.19	726
1791.22	732
1793.24	708
1795.27	740
1797.29	748
1799.31	708
1801.33	756
1803.35	698
1805.37	726
1807.39	688
1809.41	740
1811.43	740
1813.45	736
1815.46	706
1817.48	714
1819.5	678
1821.51	712
1823.53	716
1825.54	700
1827.55	716
1829.57	714
1831.58	766
1833.59	698
1835.6	700
1837.61	686
1839.62	718
1841.63	712
1843.64	698
1845.65	694
1847.65	684
1849.66	672
1851.66	676
1853.67	676
1855.67	710
1857.68	656
1859.68	674
1861.68	656
1863.69	662
1865.69	676
1867.69	668
1869.69	642
1871.69	670
1873.69	668
1875.69	660
1877.68	662
1879.68	658
1881.68	674
1883.67	650
1885.67	666
1887.66	648
1889.66	682
1891.65	636
1893.64	668
1895.64	676
1897.63	658
1899.62	676
1901.61	622
1903.6	652
1905.59	620
1907.58	660
1909.56	626
1911.55	652
1913.54	608
1915.53	680
1917.51	622
1919.5	618
1921.48	608
1923.46	630
1925.45	590
1927.43	628
1929.41	634
1931.39	636
1933.37	628
1935.35	626
1937.33	626
1939.31	626
1941.29	624
1943.27	590
1945.24	620
1947.22	602
1949.2	604
1951.17	652
1953.14	631
1955.12	622
1957.09	610
1959.06	632
1961.04	610
1963.01	594
1964.98	602
1966.95	626
1968.92	596
1970.89	590
1972.86	624
1974.82	606
1976.79	618
1978.76	612
1980.72	572
1982.69	598
1984.65	552
1986.62	586
1988.58	588
1990.54	568
1992.51	580
1994.47	606
1996.43	598
1998.39	582
1999.37	550