File: 2/Organic_12.txt
#Acq. time (s)=	15
#Accumulations=	1
#Range (cm-¹)=	100...2000
#Windows=	2
#Autofocus=	Off
#AutoExposure=	Off
#Spike filter=	Off
#Delay time (s)=	0
#Binning=	1
#Readout mode=	Signal
#DeNoise=	Off
#ICS correction=	Off
#Dark correction=	Off
#Inst. Process=	Off
#Instrument=	LabRAM HR Evol
#Detector=	Syncerity OE
#Objective=	x100_VIS
#Grating=	600 (500nm)
#ND Filter=	100%
#Laser=	633nm_Edge
#Hole=	100.021
#Range=	Visible
#Project=	Omar
#Sample=	20-06-23
#Site=	2
#Title=	Organic
#Remark=
#Date=	20.06.2023 12:04
#Acquired=	20.06.2023 12:04:10
101.054	1444
103.621	1448
106.187	1460
108.752	1450
111.317	1422
113.881	1476
116.443	1466
119.005	1440
121.566	1424
124.126	1442
126.685	1416
129.243	1414
131.801	1422
134.356	1400
136.911	1434
139.466	1426
142.021	1454
144.574	1412
147.125	1486
149.676	1420
152.227	1458
154.776	1470
157.325	1452
159.873	1450
162.419	1478
164.966	1462
167.51	1474
170.055	1440
172.598	1436
175.141	1474
177.682	1400
180.222	1454
182.763	1464
185.302	1468
187.839	1430
190.376	1470
192.914	1500
195.449	1470
197.983	1468
200.517	1502
203.05	1470
205.582	1522
208.113	1554
210.643	1546
213.173	1460
215.701	1480
218.229	1512
220.756	1526
223.282	1554
225.808	1528
228.331	1498
230.855	1500
233.378	1512
235.898	1490
238.419	1570
240.94	1500
243.458	1510
245.977	1556
248.495	1540
251.011	1520
253.527	1552
256.041	1524
258.555	1526
261.068	1520
263.58	1540
266.092	1548
268.603	1514
271.112	1514
273.62	1526
276.129	1536
278.636	1492
281.142	1542
283.647	1532
286.152	1572
288.655	1548
291.158	1588
293.66	1562
296.161	1520
298.661	1554
301.161	1580
303.66	1558
306.158	1610
308.655	1612
311.15	1596
313.645	1558
316.14	1560
318.634	1550
321.125	1562
323.618	1550
326.109	1564
328.598	1602
331.088	1612
333.576	1596
336.064	1564
338.55	1656
341.037	1638
343.521	1562
346.005	1634
348.489	1578
350.971	1544
353.453	1570
355.933	1610
358.414	1592
360.893	1592
363.371	1618
365.848	1584
368.325	1606
370.801	1634
373.275	1602
375.75	1598
378.223	1664
380.695	1584
383.167	1574
385.638	1522
388.108	1594
390.577	1612
393.044	1596
395.512	1584
397.979	1604
400.444	1648
402.909	1624
405.374	1624
407.836	1566
410.299	1616
412.76	1636
415.221	1646
417.681	1646
420.141	1638
422.598	1680
425.057	1684
427.513	1708
429.968	1648
432.422	1628
434.878	1644
437.33	1662
439.783	1702
442.234	1644
444.685	1644
447.134	1652
449.583	1624
452.032	1656
454.479	1654
456.926	1700
459.372	1680
461.817	1672
464.261	1638
466.705	1652
469.147	1628
471.588	1644
474.029	1664
476.47	1716
478.909	1654
481.347	1650
483.785	1670
486.221	1662
488.657	1722
491.092	1692
493.527	1704
495.96	1648
498.393	1672
500.824	1644
503.255	1704
505.686	1696
508.115	1638
510.543	1658
512.972	1650
515.399	1700
517.825	1670
520.25	1676
522.674	1626
525.097	1646
527.52	1640
529.942	1642
532.364	1596
534.784	1598
537.204	1640
539.623	1626
542.041	1608
544.457	1662
546.874	1624
549.289	1624
551.705	1592
554.118	1614
556.531	1612
558.943	1646
561.355	1646
563.766	1568
566.175	1600
568.585	1628
570.992	1610
573.399	1646
575.807	1626
578.212	1618
580.617	1590
583.022	1620
585.425	1620
587.827	1590
590.229	1576
592.63	1588
595.03	1662
597.43	1614
599.829	1632
602.226	1612
604.623	1586
607.02	1640
609.414	1666
611.808	1596
614.202	1600
616.596	1638
618.988	1636
621.378	1592
623.769	1670
626.159	1586
628.548	1690
630.936	1618
633.324	1654
635.71	1610
638.096	1668
640.481	1632
642.866	1670
645.248	1658
647.63	1684
650.013	1646
652.394	1592
654.773	1618
657.154	1620
659.532	1618
661.91	1644
664.286	1662
666.663	1630
669.038	1620
671.412	1580
673.786	1626
676.159	1644
678.532	1592
680.903	1576
683.274	1604
685.644	1570
688.014	1588
690.381	1642
692.749	1592
695.116	1628
697.481	1582
699.846	1578
702.211	1606
704.574	1606
706.938	1628
709.299	1620
711.661	1588
714.021	1616
716.381	1630
718.739	1628
721.097	1582
723.455	1646
725.811	1652
728.167	1562
730.521	1578
732.875	1604
735.23	1560
737.582	1614
739.934	1596
742.285	1594
744.635	1558
746.985	1528
749.332	1534
751.68	1606
754.028	1622
756.374	1606
758.72	1556
761.065	1598
763.408	1562
765.752	1546
768.095	1550
770.436	1548
772.777	1530
775.116	1532
777.456	1546
779.794	1520
782.133	1532
784.469	1568
786.805	1544
789.141	1512
791.476	1542
793.809	1576
796.142	1552
798.476	1560
800.807	1554
803.138	1520
805.468	1514
807.797	1518
810.125	1502
812.453	1550
814.78	1548
817.106	1554
819.432	1540
821.757	1518
824.08	1550
826.403	1616
828.726	1562
831.048	1542
833.368	1552
835.688	1572
838.007	1614
840.326	1628
842.644	1542
844.96	1562
847.276	1564
849.592	1602
851.906	1544
854.221	1564
856.534	1584
858.846	1572
861.157	1570
863.469	1542
865.779	1550
868.088	1554
870.396	1524
872.704	1544
875.011	1530
877.318	1494
879.623	1520
881.928	1544
884.232	1544
886.536	1534
888.837	1538
891.139	1514
893.44	1530
895.741	1486
898.039	1470
900.339	1468
902.637	1462
904.933	1474
907.231	1474
909.526	1452
911.821	1486
914.115	1526
916.408	1458
918.701	1552
920.993	1510
923.283	1470
925.573	1512
927.864	1484
930.153	1492
932.441	1490
934.728	1516
937.014	1464
939.3	1516
941.585	1482
943.87	1478
946.154	1490
948.437	1500
950.719	1456
952.999	1490
955.28	1454
957.56	1470
959.84	1476
962.117	1470
964.395	1522
966.671	1494
968.948	1504
971.223	1494
973.498	1508
975.771	1478
978.045	1522
980.317	1488
982.588	1458
984.86	1462
987.13	1466
989.399	1478
991.667	1422
993.937	1452
996.204	1484
998.47	1396
1000.74	1460
1003	1498
1005.26	1386
1007.53	1476
1009.79	1452
1012.05	1496
1014.31	1454
1016.57	1422
1018.83	1504
1021.09	1522
1023.35	1462
1025.61	1432
1027.87	1436
1030.12	1460
1032.38	1472
1034.63	1470
1036.88	1418
1039.14	1430
1041.39	1438
1043.64	1500
1045.89	1518
1048.14	1474
1050.39	1462
1052.64	1498
1054.89	1490
1057.14	1508
1059.38	1508
1061.63	1516
1063.87	1464
1066.12	1514
1068.36	1454
1070.6	1458
1072.85	1482
1075.09	1438
1077.33	1486
1079.57	1442
1081.81	1444
1084.05	1470
1086.28	1468
1088.52	1416
1090.76	1418
1092.99	1462
1095.23	1442
1097.46	1424
1099.69	1368
1101.93	1418
1104.16	1402
1106.39	1434
1108.62	1416
1110.85	1390
1113.08	1368
1115.31	1404
1117.53	1384
1119.76	1420
1121.99	1394
1124.21	1436
1126.44	1428
1128.66	1368
1130.88	1404
1133.11	1374
1135.33	1400
1137.55	1382
1139.77	1402
1141.99	1338
1144.21	1350
1146.43	1364
1148.64	1392
1150.86	1404
1153.08	1370
1155.29	1372
1157.51	1390
1159.72	1406
1161.93	1396
1164.14	1342
1166.36	1364
1168.57	1356
1170.78	1326
1172.99	1392
1175.2	1374
1177.4	1356
1179.61	1338
1181.82	1382
1184.02	1348
1186.23	1348
1188.43	1324
1190.64	1368
1192.84	1304
1195.04	1306
1197.24	1348
1199.45	1361.55
1201.64	1324.33
1203.84	1323.05
1206.04	1313.59
1208.24	1284.17
1210.44	1309.73
1212.64	1287.96
1214.83	1260.56
1217.03	1262.16
1219.22	1274.12
1221.41	1273.32
1223.61	1266.53
1225.8	1269.34
1227.99	1261.72
1230.18	1269.57
1232.37	1273.17
1234.56	1264.33
1236.75	1253.23
1238.94	1262.71
1241.13	1261.3
1243.31	1259.93
1245.5	1249.61
1247.68	1251.45
1249.87	1237.59
1252.05	1245.33
1254.24	1258.57
1256.42	1240.85
1258.6	1245.44
1260.78	1235.12
1262.96	1220.02
1265.14	1244.18
1267.32	1250.74
1269.5	1256.1
1271.67	1253.32
1273.85	1219.16
1276.03	1243.91
1278.2	1222.68
1280.38	1236.71
1282.55	1258.23
1284.72	1218.92
1286.9	1229.5
1289.07	1256.84
1291.24	1187.1
1293.41	1242.8
1295.58	1271.82
1297.75	1238.55
1299.92	1235.66
1302.09	1217.37
1304.25	1224.21
1306.42	1223.83
1308.46	1196
1310.63	1152
1312.81	1188
1314.98	1214
1317.16	1170
1319.33	1196
1321.5	1194
1323.67	1186
1325.85	1208
1328.02	1204
1330.19	1172
1332.35	1224
1334.52	1182
1336.69	1184
1338.86	1158
1341.02	1160
1343.19	1184
1345.35	1168
1347.52	1144
1349.68	1162
1351.84	1134
1354	1156
1356.17	1180
1358.33	1162
1360.49	1162
1362.65	1188
1364.8	1146
1366.96	1158
1369.12	1118
1371.28	1194
1373.43	1128
1375.59	1180
1377.74	1130
1379.89	1158
1382.05	1168
1384.2	1142
1386.35	1166
1388.5	1118
1390.65	1112
1392.8	1170
1394.95	1162
1397.1	1124
1399.25	1122
1401.4	1134
1403.54	1118
1405.69	1104
1407.83	1126
1409.98	1156
1412.12	1100
1414.26	1118
1416.4	1188
1418.55	1134
1420.69	1128
1422.83	1124
1424.97	1148
1427.1	1128
1429.24	1114
1431.38	1146
1433.52	1128
1435.65	1160
1437.79	1164
1439.92	1146
1442.06	1132
1444.19	1150
1446.32	1148
1448.46	1136
1450.59	1108
1452.72	1120
1454.85	1146
1456.98	1088
1459.11	1146
1461.23	1172
1463.36	1154
1465.49	1130
1467.61	1074
1469.74	1110
1471.86	1104
1473.99	1116
1476.11	1120
1478.23	1054
1480.36	1050
1482.48	1058
1484.6	1078
1486.72	1046
1488.84	1072
1490.96	996
1493.07	1070
1495.19	1062
1497.31	1048
1499.42	1060
1501.54	1032
1503.65	1072
1505.77	1062
1507.88	1056
1509.99	1066
1512.1	1010
1514.22	1016
1516.33	1048
1518.44	1034
1520.55	1000
1522.65	1012
1524.76	1008
1526.87	1042
1528.98	1026
1531.08	1034
1533.19	1012
1535.29	1016
1537.4	1016
1539.5	1014
1541.6	996
1543.7	1006
1545.8	996
1547.91	988
1550.01	1008
1552.11	1012
1554.2	1008
1556.3	1000
1558.4	974
1560.5	1046
1562.59	992
1564.69	992
1566.78	1028
1568.88	964
1570.97	984
1573.06	1000
1575.15	984
1577.25	960
1579.34	946
1581.43	972
1583.52	1002
1585.6	998
1587.69	948
1589.78	986
1591.87	984
1593.95	980
1596.04	974
1598.12	986
1600.21	970
1602.29	978
1604.37	960
1606.46	988
1608.54	986
1610.62	970
1612.7	962
1614.78	954
1616.86	964
1618.94	986
1621.01	948
1623.09	936
1625.17	984
1627.24	962
1629.32	958
1631.39	944
1633.47	988
1635.54	946
1637.61	966
1639.68	952
1641.76	972
1643.83	956
1645.9	912
1647.96	956
1650.03	984
1652.1	936
1654.17	938
1656.24	976
1658.3	960
1660.37	946
1662.43	938
1664.5	870
1666.56	926
1668.62	894
1670.68	908
1672.75	922
1674.81	908
1676.87	922
1678.93	926
1680.99	918
1683.04	912
1685.1	852
1687.16	914
1689.21	908
1691.27	898
1693.33	878
1695.38	916
1697.43	892
1699.49	856
1701.54	872
1703.59	894
1705.64	902
1707.69	900
1709.74	878
1711.79	888
1713.84	862
1715.89	820
1717.94	832
1719.98	848
1722.03	858
1724.07	858
1726.12	840
1728.16	864
1730.21	840
1732.25	860
1734.29	866
1736.33	868
1738.37	876
1740.41	890
1742.45	878
1744.49	844
1746.53	868
1748.57	826
1750.61	880
1752.64	870
1754.68	860
1756.71	856
1758.75	864
1760.78	824
1762.82	804
1764.85	812
1766.88	840
1768.91	820
1770.94	828
1772.97	840
1775	838
1777.03	840
1779.06	828
1781.09	838
1783.12	832
1785.14	810
1787.17	850
1789.19	828
1791.22	822
1793.24	824
1795.27	816
1797.29	876
1799.31	804
1801.33	816
1803.35	850
1805.37	798
1807.39	816
1809.41	826
1811.43	806
1813.45	784
1815.46	822
1817.48	782
1819.5	812
1821.51	784
1823.53	784
1825.54	802
1827.55	814
1829.57	802
1831.58	822
1833.59	762
1835.6	800
1837.61	792
1839.62	804
1841.63	782
1843.64	736
1845.65	796
1847.65	800
1849.66	776
1851.66	724
1853.67	762
1855.67	768
1857.68	772
1859.68	754
1861.68	748
1863.69	720
1865.69	744
1867.69	766
1869.69	754
1871.69	764
1873.69	740
1875.69	744
1877.68	744
1879.68	746
1881.68	738
1883.67	726
1885.67	696
1887.66	742
1889.66	760
1891.65	726
1893.64	734
1895.64	714
1897.63	726
1899.62	772
1901.61	730
1903.6	686
1905.59	722
1907.58	724
1909.56	700
1911.55	714
1913.54	736
1915.53	716
1917.51	736
1919.5	688
1921.48	732
1923.46	706
1925.45	746
1927.43	694
1929.41	732
1931.39	714
1933.37	686
1935.35	658
1937.33	696
1939.31	708
1941.29	720
1943.27	702
1945.24	686
1947.22	704
1949.2	658
1951.17	690
1953.14	695
1955.12	694
1957.09	700
1959.06	654
1961.04	676
1963.01	688
1964.98	684
1966.95	676
1968.92	678
1970.89	646
1972.86	670
1974.82	640
1976.79	650
1978.76	650
1980.72	666
1982.69	680
1984.65	652
1986.62	636
1988.58	690
1990.54	646
1992.51	642
1994.47	640
1996.43	658
1998.39	642
1999.37	666