File: 2/Organic_02.txt
#Acq. time (s)=	10
#Accumulations=	1
#Range (cm-¹)=	100...2000
#Windows=	2
#Autofocus=	Off
#AutoExposure=	Off
#Spike filter=	Off
#Delay time (s)=	0
#Binning=	1
#Readout mode=	Signal
#DeNoise=	Off
#ICS correction=	Off
#Dark correction=	Off
#Inst. Process=	Off
#Instrument=	LabRAM HR Evol
#Detector=	Syncerity OE
#Objective=	x100_VIS
#Grating=	600 (500nm)
#ND Filter=	5%
#Laser=	633nm_Edge
#Hole=	24.99
#Range=	Visible
#Project=	Omar
#Sample=	20-06-23
#Site=	2
#Title=	Organic
#Remark=
#Date=	20.06.2023 11:50
#Acquired=	20.06.2023 11:50:00
101.054	38
103.621	42
106.187	40
108.752	34
111.317	36
113.881	36
116.443	40
119.005	42
121.566	40
124.126	36
126.685	38
129.243	28
131.801	36
134.356	30
136.911	36
139.466	32
142.021	38
144.574	34
147.125	36
149.676	32
152.227	30
154.776	38
157.325	40
159.873	26
162.419	36
164.966	32
167.51	34
170.055	30
172.598	26
175.141	30
177.682	40
180.222	38
182.763	36
185.302	38
187.839	42
190.376	40
192.914	40
195.449	40
197.983	36
200.517	36
203.05	36
205.582	30
208.113	30
210.643	38
213.173	38
215.701	38
218.229	40
220.756	34
223.282	32
225.808	32
228.331	34
230.855	36
233.378	34
235.898	36
238.419	42
240.94	38
243.458	42
245.977	38
248.495	26
251.011	32
253.527	36
256.041	38
258.555	38
261.068	32
263.58	34
266.092	38
268.603	40
271.112	30
273.62	32
276.129	42
278.636	38
281.142	34
283.647	32
286.152	36
288.655	34
291.158	38
293.66	36
296.161	32
298.661	32
301.161	30
303.66	38
306.158	38
308.655	40
311.15	44
313.645	42
316.14	34
318.634	34
321.125	36
323.618	32
326.109	34
328.598	36
331.088	38
333.576	44
336.064	36
338.55	38
341.037	40
343.521	40
346.005	34
348.489	40
350.971	40
353.453	40
355.933	48
358.414	42
360.893	44
363.371	32
365.848	44
368.325	46
370.801	38
373.275	32
375.75	42
378.223	42
380.695	42
383.167	40
385.638	38
388.108	38
390.577	38
393.044	36
395.512	38
397.979	40
400.444	38
402.909	28
405.374	40
407.836	32
410.299	34
412.76	36
415.221	42
417.681	38
420.141	36
422.598	50
425.057	36
427.513	44
429.968	34
432.422	36
434.878	36
437.33	36
439.783	32
442.234	40
444.685	40
447.134	40
449.583	40
452.032	36
454.479	44
456.926	38
459.372	40
461.817	34
464.261	46
466.705	36
469.147	32
471.588	36
474.029	40
476.47	38
478.909	42
481.347	40
483.785	34
486.221	36
488.657	40
491.092	44
493.527	46
495.96	28
498.393	38
500.824	38
503.255	46
505.686	32
508.115	38
510.543	38
512.972	42
515.399	34
517.825	40
520.25	40
522.674	40
525.097	34
527.52	48
529.942	36
532.364	38
534.784	24
537.204	42
539.623	40
542.041	36
544.457	34
546.874	46
549.289	38
551.705	44
554.118	32
556.531	36
558.943	34
561.355	40
563.766	44
566.175	40
568.585	36
570.992	42
573.399	38
575.807	40
578.212	38
580.617	40
583.022	28
585.425	42
587.827	28
590.229	36
592.63	38
595.03	40
597.43	46
599.829	36
602.226	46
604.623	46
607.02	40
609.414	36
611.808	40
614.202	38
616.596	38
618.988	38
621.378	48
623.769	50
626.159	36
628.548	38
630.936	44
633.324	44
635.71	36
638.096	40
640.481	40
642.866	36
645.248	48
647.63	40
650.013	36
652.394	46
654.773	40
657.154	40
659.532	42
661.91	38
664.286	34
666.663	38
669.038	42
671.412	50
673.786	30
676.159	42
678.532	46
680.903	34
683.274	36
685.644	42
688.014	32
690.381	46
692.749	36
695.116	42
697.481	30
699.846	34
702.211	32
704.574	38
706.938	44
709.299	34
711.661	34
714.021	34
716.381	36
718.739	42
721.097	38
723.455	34
725.811	38
728.167	38
730.521	32
732.875	34
735.23	48
737.582	34
739.934	40
742.285	34
744.635	34
746.985	44
749.332	40
751.68	42
754.028	42
756.374	34
758.72	40
761.065	36
763.408	40
765.752	42
768.095	34
770.436	40
772.777	34
775.116	36
777.456	34
779.794	34
782.133	46
784.469	44
786.805	42
789.141	44
791.476	38
793.809	38
796.142	38
798.476	40
800.807	38
803.138	42
805.468	38
807.797	40
810.125	32
812.453	36
814.78	38
817.106	40
819.432	44
821.757	44
824.08	38
826.403	36
828.726	42
831.048	38
833.368	46
835.688	38
838.007	40
840.326	36
842.644	40
844.96	34
847.276	38
849.592	30
851.906	36
854.221	40
856.534	38
858.846	34
861.157	38
863.469	32
865.779	36
868.088	38
870.396	46
872.704	24
875.011	30
877.318	38
879.623	46
881.928	30
884.232	36
886.536	34
888.837	36
891.139	38
893.44	40
895.741	36
898.039	44
900.339	40
902.637	30
904.933	42
907.231	36
909.526	40
911.821	34
914.115	32
916.408	34
918.701	38
920.993	30
923.283	40
925.573	40
927.864	40
930.153	42
932.441	40
934.728	46
937.014	34
939.3	36
941.585	24
943.87	36
946.154	38
948.437	42
950.719	36
952.999	40
955.28	32
957.56	40
959.84	40
962.117	36
964.395	36
966.671	32
968.948	38
971.223	48
973.498	38
975.771	42
978.045	44
980.317	36
982.588	38
984.86	40
987.13	44
989.399	32
991.667	36
993.937	38
996.204	48
998.47	42
1000.74	34
1003	32
1005.26	34
1007.53	38
1009.79	34
1012.05	36
1014.31	38
1016.57	34
1018.83	38
1021.09	34
1023.35	28
1025.61	32
1027.87	32
1030.12	40
1032.38	38
1034.63	36
1036.88	42
1039.14	38
1041.39	32
1043.64	38
1045.89	42
1048.14	38
1050.39	32
1052.64	40
1054.89	38
1057.14	34
1059.38	38
1061.63	30
1063.87	34
1066.12	30
1068.36	40
1070.6	40
1072.85	38
1075.09	38
1077.33	38
1079.57	42
1081.81	34
1084.05	40
1086.28	38
1088.52	40
1090.76	32
1092.99	38
1095.23	38
1097.46	38
1099.69	42
1101.93	30
1104.16	38
1106.39	34
1108.62	34
1110.85	36
1113.08	32
1115.31	36
1117.53	42
1119.76	34
1121.99	36
1124.21	40
1126.44	40
1128.66	32
1130.88	38
1133.11	34
1135.33	32
1137.55	40
1139.77	38
1141.99	42
1144.21	40
1146.43	32
1148.64	30
1150.86	30
1153.08	34
1155.29	28
1157.51	34
1159.72	36
1161.93	32
1164.14	30
1166.36	32
1168.57	36
1170.78	36
1172.99	34
1175.2	38
1177.4	30
1179.61	36
1181.82	38
1184.02	38
1186.23	32
1188.43	38
1190.64	34
1192.84	34
1195.04	34
1197.24	34
1199.45	35.99
1201.64	30.1095
1203.84	33.8046
1206.04	35.9449
1208.24	40.8611
1210.44	35.8831
1212.64	35.1369
1214.83	35.8227
1217.03	38.7181
1219.22	38.9179
1221.41	37.0359
1223.61	32.0011
1225.8	30.2499
1227.99	39.0953
1230.18	35.43
1232.37	39.4491
1234.56	26.5365
1236.75	34.8614
1238.94	34.1256
1241.13	38.9053
1243.31	29.8614
1245.5	31.9576
1247.68	36.2482
1249.87	34.218
1252.05	35.1522
1254.24	34.6624
1256.42	32.408
1258.6	34.36
1260.78	33.764
1262.96	34.9396
1265.14	33.9239
1267.32	38.606
1269.5	34.7597
1271.67	39.8118
1273.85	33.0076
1276.03	36.23
1278.2	30.1789
1280.38	32.0172
1282.55	36.1413
1284.72	33.01
1286.9	31.3919
1289.07	35.0302
1291.24	37.1706
1293.41	33.406
1295.58	41.525
1297.75	32.7118
1299.92	31.2806
1302.09	32.3864
1304.25	37.0152
1306.42	30.6212
1308.46	30
1310.63	34
1312.81	30
1314.98	34
1317.16	34
1319.33	30
1321.5	34
1323.67	40
1325.85	30
1328.02	36
1330.19	40
1332.35	40
1334.52	26
1336.69	36
1338.86	36
1341.02	42
1343.19	40
1345.35	36
1347.52	38
1349.68	36
1351.84	38
1354	30
1356.17	40
1358.33	32
1360.49	34
1362.65	34
1364.8	30
1366.96	24
1369.12	32
1371.28	30
1373.43	36
1375.59	32
1377.74	30
1379.89	24
1382.05	32
1384.2	32
1386.35	36
1388.5	36
1390.65	30
1392.8	32
1394.95	30
1397.1	40
1399.25	32
1401.4	32
1403.54	28
1405.69	36
1407.83	42
1409.98	30
1412.12	32
1414.26	42
1416.4	38
1418.55	38
1420.69	44
1422.83	42
1424.97	36
1427.1	38
1429.24	34
1431.38	40
1433.52	34
1435.65	30
1437.79	30
1439.92	32
1442.06	30
1444.19	36
1446.32	36
1448.46	32
1450.59	28
1452.72	36
1454.85	36
1456.98	34
1459.11	28
1461.23	26
1463.36	28
1465.49	28
1467.61	34
1469.74	34
1471.86	32
1473.99	30
1476.11	34
1478.23	30
1480.36	32
1482.48	32
1484.6	32
1486.72	38
1488.84	36
1490.96	36
1493.07	42
1495.19	34
1497.31	32
1499.42	32
1501.54	36
1503.65	44
1505.77	36
1507.88	38
1509.99	38
1512.1	32
1514.22	34
1516.33	36
1518.44	28
1520.55	32
1522.65	34
1524.76	42
1526.87	34
1528.98	34
1531.08	40
1533.19	24
1535.29	40
1537.4	34
1539.5	38
1541.6	44
1543.7	30
1545.8	34
1547.91	30
1550.01	38
1552.11	32
1554.2	36
1556.3	32
1558.4	32
1560.5	38
1562.59	32
1564.69	32
1566.78	42
1568.88	38
1570.97	34
1573.06	32
1575.15	42
1577.25	34
1579.34	28
1581.43	36
1583.52	34
1585.6	36
1587.69	38
1589.78	38
1591.87	36
1593.95	36
1596.04	32
1598.12	28
1600.21	30
1602.29	40
1604.37	36
1606.46	38
1608.54	36
1610.62	38
1612.7	36
1614.78	36
1616.86	36
1618.94	30
1621.01	34
1623.09	42
1625.17	32
1627.24	28
1629.32	40
1631.39	34
1633.47	36
1635.54	38
1637.61	30
1639.68	42
1641.76	36
1643.83	40
1645.9	44
1647.96	36
1650.03	36
1652.1	38
1654.17	34
1656.24	38
1658.3	32
1660.37	36
1662.43	36
1664.5	40
1666.56	40
1668.62	30
1670.68	34
1672.75	34
1674.81	42
1676.87	34
1678.93	36
1680.99	34
1683.04	42
1685.1	32
1687.16	30
1689.21	36
1691.27	38
1693.33	34
1695.38	38
1697.43	36
1699.49	38
1701.54	34
1703.59	36
1705.64	36
1707.69	32
1709.74	30
1711.79	38
1713.84	28
1715.89	32
1717.94	30
1719.98	26
1722.03	40
1724.07	28
1726.12	32
1728.16	32
1730.21	30
1732.25	38
1734.29	34
1736.33	36
1738.37	32
1740.41	34
1742.45	32
1744.49	38
1746.53	40
1748.57	38
1750.61	40
1752.64	42
1754.68	38
1756.71	34
1758.75	40
1760.78	42
1762.82	34
1764.85	30
1766.88	30
1768.91	40
1770.94	34
1772.97	40
1775	36
1777.03	34
1779.06	36
1781.09	32
1783.12	36
1785.14	36
1787.17	38
1789.19	34
1791.22	34
1793.24	32
1795.27	36
1797.29	34
1799.31	36
1801.33	30
1803.35	36
1805.37	30
1807.39	26
1809.41	32
1811.43	28
1813.45	32
1815.46	38
1817.48	32
1819.5	34
1821.51	34
1823.53	30
1825.54	28
1827.55	34
1829.57	36
1831.58	32
1833.59	32
1835.6	34
1837.61	40
1839.62	36
1841.63	32
1843.64	40
1845.65	36
1847.65	34
1849.66	40
1851.66	32
1853.67	38
1855.67	24
1857.68	42
1859.68	34
1861.68	34
1863.69	42
1865.69	32
1867.69	30
1869.69	38
1871.69	22
1873.69	32
1875.69	30
1877.68	36
1879.68	30
1881.68	36
1883.67	36
1885.67	34
1887.66	34
1889.66	32
1891.65	28
1893.64	32
1895.64	36
1897.63	36
1899.62	32
1901.61	38
1903.6	34
1905.59	34
1907.58	30
1909.56	44
1911.55	44
1913.54	36
1915.53	38
1917.51	34
1919.5	34
1921.48	38
1923.46	30
1925.45	34
1927.43	40
1929.41	38
1931.39	40
1933.37	30
1935.35	30
1937.33	32
1939.31	32
1941.29	34
1943.27	30
1945.24	34
1947.22	28
1949.2	34
1951.17	38
1953.14	29
1955.12	32
1957.09	28
1959.06	32
1961.04	26
1963.01	36
1964.98	28
1966.95	34
1968.92	30
1970.89	34
1972.86	38
1974.82	34
1976.79	44
1978.76	38
1980.72	36
1982.69	38
1984.65	32
1986.62	26
1988.58	42
1990.54	36
1992.51	34
1994.47	36
1996.43	30
1998.39	32
1999.37	26