File: 2/Organic_14.txt
#Acq. time (s)=	15
#Accumulations=	1
#Range (cm-¹)=	100...2000
#Windows=	2
#Autofocus=	Off
#AutoExposure=	Off
#Spike filter=	Off
#Delay time (s)=	0
#Binning=	1
#Readout mode=	Signal
#DeNoise=	Off
#ICS correction=	Off
#Dark correction=	Off
#Inst. Process=	Off
#Instrument=	LabRAM HR Evol
#Detector=	Syncerity OE
#Objective=	x100_VIS
#Grating=	600 (500nm)
#ND Filter=	100%
#Laser=	633nm_Edge
#Hole=	100.021
#Range=	Visible
#Project=	Omar
#Sample=	20-06-23
#Site=	2
#Title=	Organic
#Remark=
#Date=	20.06.2023 12:06
#Acquired=	20.06.2023 12:06:11
101.054	1124
103.621	1136
106.187	1198
108.752	1196
111.317	1146
113.881	1142
116.443	1142
119.005	1154
121.566	1152
124.126	1144
126.685	1182
129.243	1150
131.801	1180
134.356	1158
136.911	1128
139.466	1154
142.021	1154
144.574	1152
147.125	1162
149.676	1188
152.227	1132
154.776	1132
157.325	1120
159.873	1120
162.419	1144
164.966	1186
167.51	1176
170.055	1104
172.598	1132
175.141	1192
177.682	1146
180.222	1152
182.763	1150
185.302	1164
187.839	1200
190.376	1166
192.914	1132
195.449	1174
197.983	1180
200.517	1142
203.05	1212
205.582	1230
208.113	1194
210.643	1236
213.173	1188
215.701	1176
218.229	1184
220.756	1208
223.282	1234
225.808	1240
228.331	1162
230.855	1162
233.378	1240
235.898	1204
238.419	1232
240.94	1222
243.458	1170
245.977	1296
248.495	1226
251.011	1182
253.527	1212
256.041	1208
258.555	1194
261.068	1198
263.58	1220
266.092	1170
268.603	1214
271.112	1196
273.62	1218
276.129	1184
278.636	1190
281.142	1214
283.647	1202
286.152	1190
288.655	1224
291.158	1184
293.66	1208
296.161	1250
298.661	1246
301.161	1258
303.66	1240
306.158	1244
308.655	1190
311.15	1228
313.645	1248
316.14	1280
318.634	1268
321.125	1234
323.618	1232
326.109	1204
328.598	1272
331.088	1240
333.576	1294
336.064	1226
338.55	1230
341.037	1250
343.521	1272
346.005	1274
348.489	1270
350.971	1246
353.453	1220
355.933	1308
358.414	1250
360.893	1280
363.371	1242
365.848	1246
368.325	1244
370.801	1260
373.275	1262
375.75	1196
378.223	1246
380.695	1278
383.167	1236
385.638	1202
388.108	1264
390.577	1248
393.044	1238
395.512	1264
397.979	1246
400.444	1220
402.909	1278
405.374	1264
407.836	1302
410.299	1298
412.76	1282
415.221	1284
417.681	1300
420.141	1274
422.598	1300
425.057	1256
427.513	1288
429.968	1318
432.422	1324
434.878	1298
437.33	1284
439.783	1338
442.234	1306
444.685	1296
447.134	1304
449.583	1320
452.032	1264
454.479	1284
456.926	1262
459.372	1274
461.817	1248
464.261	1284
466.705	1272
469.147	1284
471.588	1262
474.029	1296
476.47	1318
478.909	1314
481.347	1338
483.785	1302
486.221	1290
488.657	1372
491.092	1334
493.527	1308
495.96	1310
498.393	1324
500.824	1322
503.255	1336
505.686	1290
508.115	1290
510.543	1318
512.972	1296
515.399	1274
517.825	1282
520.25	1270
522.674	1292
525.097	1272
527.52	1278
529.942	1280
532.364	1298
534.784	1292
537.204	1272
539.623	1284
542.041	1280
544.457	1296
546.874	1248
549.289	1276
551.705	1250
554.118	1266
556.531	1248
558.943	1260
561.355	1270
563.766	1260
566.175	1288
568.585	1262
570.992	1262
573.399	1264
575.807	1264
578.212	1264
580.617	1264
583.022	1298
585.425	1278
587.827	1266
590.229	1232
592.63	1214
595.03	1276
597.43	1254
599.829	1294
602.226	1218
604.623	1238
607.02	1300
609.414	1228
611.808	1290
614.202	1254
616.596	1268
618.988	1252
621.378	1270
623.769	1274
626.159	1250
628.548	1292
630.936	1278
633.324	1252
635.71	1278
638.096	1300
640.481	1262
642.866	1258
645.248	1244
647.63	1280
650.013	1278
652.394	1272
654.773	1286
657.154	1298
659.532	1280
661.91	1280
664.286	1274
666.663	1232
669.038	1292
671.412	1258
673.786	1258
676.159	1266
678.532	1248
680.903	1274
683.274	1244
685.644	1262
688.014	1220
690.381	1230
692.749	1286
695.116	1220
697.481	1246
699.846	1224
702.211	1242
704.574	1248
706.938	1266
709.299	1266
711.661	1208
714.021	1248
716.381	1230
718.739	1296
721.097	1220
723.455	1256
725.811	1254
728.167	1276
730.521	1230
732.875	1262
735.23	1252
737.582	1242
739.934	1266
742.285	1218
744.635	1182
746.985	1234
749.332	1186
751.68	1242
754.028	1280
756.374	1210
758.72	1182
761.065	1192
763.408	1196
765.752	1224
768.095	1198
770.436	1182
772.777	1240
775.116	1202
777.456	1200
779.794	1222
782.133	1162
784.469	1242
786.805	1170
789.141	1184
791.476	1236
793.809	1198
796.142	1216
798.476	1206
800.807	1224
803.138	1176
805.468	1220
807.797	1210
810.125	1216
812.453	1224
814.78	1198
817.106	1204
819.432	1212
821.757	1210
824.08	1176
826.403	1226
828.726	1206
831.048	1236
833.368	1166
835.688	1238
838.007	1242
840.326	1230
842.644	1218
844.96	1264
847.276	1212
849.592	1238
851.906	1198
854.221	1232
856.534	1238
858.846	1234
861.157	1236
863.469	1238
865.779	1222
868.088	1200
870.396	1178
872.704	1196
875.011	1244
877.318	1190
879.623	1204
881.928	1158
884.232	1206
886.536	1272
888.837	1182
891.139	1200
893.44	1212
895.741	1242
898.039	1230
900.339	1190
902.637	1152
904.933	1152
907.231	1166
909.526	1176
911.821	1188
914.115	1134
916.408	1210
918.701	1164
920.993	1194
923.283	1178
925.573	1190
927.864	1206
930.153	1156
932.441	1188
934.728	1222
937.014	1170
939.3	1182
941.585	1186
943.87	1146
946.154	1158
948.437	1198
950.719	1172
952.999	1176
955.28	1194
957.56	1144
959.84	1166
962.117	1178
964.395	1188
966.671	1116
968.948	1124
971.223	1188
973.498	1134
975.771	1164
978.045	1156
980.317	1166
982.588	1130
984.86	1162
987.13	1156
989.399	1156
991.667	1156
993.937	1160
996.204	1120
998.47	1118
1000.74	1110
1003	1098
1005.26	1134
1007.53	1132
1009.79	1154
1012.05	1120
1014.31	1118
1016.57	1118
1018.83	1174
1021.09	1158
1023.35	1116
1025.61	1146
1027.87	1158
1030.12	1134
1032.38	1132
1034.63	1120
1036.88	1172
1039.14	1150
1041.39	1148
1043.64	1218
1045.89	1172
1048.14	1154
1050.39	1156
1052.64	1174
1054.89	1172
1057.14	1184
1059.38	1204
1061.63	1180
1063.87	1184
1066.12	1138
1068.36	1158
1070.6	1144
1072.85	1196
1075.09	1186
1077.33	1158
1079.57	1150
1081.81	1154
1084.05	1134
1086.28	1140
1088.52	1104
1090.76	1112
1092.99	1140
1095.23	1122
1097.46	1166
1099.69	1092
1101.93	1096
1104.16	1106
1106.39	1130
1108.62	1098
1110.85	1118
1113.08	1132
1115.31	1122
1117.53	1130
1119.76	1124
1121.99	1146
1124.21	1136
1126.44	1130
1128.66	1114
1130.88	1110
1133.11	1164
1135.33	1096
1137.55	1158
1139.77	1066
1141.99	1114
1144.21	1056
1146.43	1110
1148.64	1100
1150.86	1070
1153.08	1096
1155.29	1074
1157.51	1102
1159.72	1118
1161.93	1066
1164.14	1064
1166.36	1090
1168.57	1078
1170.78	1068
1172.99	1078
1175.2	1086
1177.4	1056
1179.61	1074
1181.82	1058
1184.02	1048
1186.23	1054
1188.43	1064
1190.64	1026
1192.84	1022
1195.04	1034
1197.24	1046
1199.45	1052.02
1201.64	1026.28
1203.84	1070.71
1206.04	1063.07
1208.24	1023.9
1210.44	1048.03
1212.64	1058.64
1214.83	990.176
1217.03	1054.06
1219.22	1024.08
1221.41	1015.01
1223.61	1009.63
1225.8	1024.86
1227.99	1003.62
1230.18	995.98
1232.37	993.797
1234.56	1017.32
1236.75	1015.92
1238.94	995.429
1241.13	1033.99
1243.31	1004.72
1245.5	1026.25
1247.68	1020.01
1249.87	1023.28
1252.05	1025.58
1254.24	1018.54
1256.42	1030.09
1258.6	1019.82
1260.78	1019.02
1262.96	1002.14
1265.14	1020.57
1267.32	1020.03
1269.5	988.149
1271.67	1008.01
1273.85	1016.36
1276.03	997.5
1278.2	1022.83
1280.38	1007.74
1282.55	1022.73
1284.72	1031.53
1286.9	1030.59
1289.07	1039.42
1291.24	1009.12
1293.41	1028.2
1295.58	1069.82
1297.75	1051.61
1299.92	1041.83
1302.09	1027.26
1304.25	1001.35
1306.42	1005.56
1308.46	1016
1310.63	1020
1312.81	1014
1314.98	1000
1317.16	1012
1319.33	1002
1321.5	982
1323.67	1016
1325.85	984
1328.02	1046
1330.19	1032
1332.35	996
1334.52	1016
1336.69	1016
1338.86	1008
1341.02	1014
1343.19	1014
1345.35	1036
1347.52	1014
1349.68	990
1351.84	962
1354	998
1356.17	960
1358.33	966
1360.49	928
1362.65	970
1364.8	982
1366.96	938
1369.12	972
1371.28	972
1373.43	944
1375.59	982
1377.74	944
1379.89	980
1382.05	994
1384.2	946
1386.35	966
1388.5	960
1390.65	946
1392.8	990
1394.95	984
1397.1	986
1399.25	946
1401.4	986
1403.54	992
1405.69	920
1407.83	976
1409.98	946
1412.12	948
1414.26	972
1416.4	934
1418.55	934
1420.69	970
1422.83	958
1424.97	964
1427.1	924
1429.24	968
1431.38	1004
1433.52	994
1435.65	944
1437.79	998
1439.92	990
1442.06	996
1444.19	972
1446.32	950
1448.46	990
1450.59	944
1452.72	974
1454.85	948
1456.98	974
1459.11	970
1461.23	964
1463.36	934
1465.49	982
1467.61	972
1469.74	966
1471.86	918
1473.99	896
1476.11	908
1478.23	918
1480.36	888
1482.48	930
1484.6	900
1486.72	876
1488.84	904
1490.96	906
1493.07	864
1495.19	882
1497.31	894
1499.42	878
1501.54	876
1503.65	882
1505.77	870
1507.88	878
1509.99	868
1512.1	912
1514.22	880
1516.33	904
1518.44	872
1520.55	882
1522.65	864
1524.76	886
1526.87	866
1528.98	856
1531.08	858
1533.19	862
1535.29	830
1537.4	826
1539.5	886
1541.6	890
1543.7	840
1545.8	826
1547.91	872
1550.01	856
1552.11	834
1554.2	840
1556.3	818
1558.4	854
1560.5	810
1562.59	786
1564.69	812
1566.78	838
1568.88	814
1570.97	846
1573.06	824
1575.15	832
1577.25	816
1579.34	814
1581.43	820
1583.52	812
1585.6	820
1587.69	830
1589.78	850
1591.87	834
1593.95	800
1596.04	866
1598.12	832
1600.21	790
1602.29	812
1604.37	828
1606.46	802
1608.54	808
1610.62	776
1612.7	828
1614.78	788
1616.86	804
1618.94	818
1621.01	824
1623.09	820
1625.17	816
1627.24	816
1629.32	792
1631.39	796
1633.47	772
1635.54	790
1637.61	804
1639.68	812
1641.76	808
1643.83	774
1645.9	776
1647.96	764
1650.03	786
1652.1	822
1654.17	776
1656.24	784
1658.3	780
1660.37	796
1662.43	770
1664.5	804
1666.56	754
1668.62	796
1670.68	768
1672.75	792
1674.81	762
1676.87	774
1678.93	792
1680.99	776
1683.04	772
1685.1	774
1687.16	752
1689.21	728
1691.27	764
1693.33	742
1695.38	738
1697.43	732
1699.49	724
1701.54	730
1703.59	734
1705.64	732
1707.69	746
1709.74	744
1711.79	724
1713.84	752
1715.89	746
1717.94	706
1719.98	716
1722.03	734
1724.07	746
1726.12	714
1728.16	710
1730.21	728
1732.25	730
1734.29	758
1736.33	704
1738.37	698
1740.41	728
1742.45	746
1744.49	700
1746.53	712
1748.57	712
1750.61	694
1752.64	708
1754.68	722
1756.71	694
1758.75	736
1760.78	752
1762.82	690
1764.85	704
1766.88	706
1768.91	680
1770.94	706
1772.97	700
1775	702
1777.03	668
1779.06	698
1781.09	684
1783.12	694
1785.14	708
1787.17	702
1789.19	684
1791.22	670
1793.24	676
1795.27	690
1797.29	652
1799.31	666
1801.33	678
1803.35	678
1805.37	678
1807.39	712
1809.41	682
1811.43	684
1813.45	698
1815.46	688
1817.48	672
1819.5	666
1821.51	648
1823.53	664
1825.54	668
1827.55	640
1829.57	678
1831.58	668
1833.59	666
1835.6	646
1837.61	654
1839.62	644
1841.63	648
1843.64	636
1845.65	636
1847.65	616
1849.66	634
1851.66	660
1853.67	634
1855.67	636
1857.68	650
1859.68	640
1861.68	640
1863.69	610
1865.69	658
1867.69	630
1869.69	648
1871.69	610
1873.69	636
1875.69	642
1877.68	644
1879.68	662
1881.68	604
1883.67	650
1885.67	586
1887.66	628
1889.66	616
1891.65	596
1893.64	640
1895.64	608
1897.63	628
1899.62	626
1901.61	648
1903.6	610
1905.59	590
1907.58	608
1909.56	608
1911.55	604
1913.54	558
1915.53	610
1917.51	622
1919.5	588
1921.48	612
1923.46	608
1925.45	588
1927.43	612
1929.41	568
1931.39	596
1933.37	600
1935.35	596
1937.33	584
1939.31	578
1941.29	576
1943.27	566
1945.24	568
1947.22	586
1949.2	594
1951.17	544
1953.14	591
1955.12	564
1957.09	584
1959.06	570
1961.04	590
1963.01	568
1964.98	562
1966.95	550
1968.92	540
1970.89	560
1972.86	562
1974.82	562
1976.79	570
1978.76	594
1980.72	586
1982.69	566
1984.65	544
1986.62	562
1988.58	544
1990.54	562
1992.51	536
1994.47	576
1996.43	544
1998.39	568
1999.37	552