File: 2/Organic_01.txt
#Acq. time (s)=	10
#Accumulations=	1
#Range (cm-¹)=	100...2000
#Windows=	2
#Autofocus=	Off
#AutoExposure=	Off
#Spike filter=	Off
#Delay time (s)=	0
#Binning=	1
#Readout mode=	Signal
#DeNoise=	Off
#ICS correction=	Off
#Dark correction=	Off
#Inst. Process=	Off
#Instrument=	LabRAM HR Evol
#Detector=	Syncerity OE
#Objective=	x100_VIS
#Grating=	600 (500nm)
#ND Filter=	5%
#Laser=	633nm_Edge
#Hole=	24.99
#Range=	Visible
#Project=	Omar
#Sample=	20-06-23
#Site=	2
#Title=	Organic
#Remark=
#Date=	20.06.2023 11:49
#Acquired=	20.06.2023 11:49:04
101.054	34
103.621	40
106.187	38
108.752	40
111.317	40
113.881	38
116.443	36
119.005	42
121.566	42
124.126	38
126.685	32
129.243	34
131.801	38
134.356	42
136.911	38
139.466	40
142.021	40
144.574	32
147.125	40
149.676	32
152.227	34
154.776	36
157.325	40
159.873	38
162.419	44
164.966	46
167.51	44
170.055	38
172.598	34
175.141	44
177.682	28
180.222	40
182.763	42
185.302	36
187.839	22
190.376	34
192.914	36
195.449	30
197.983	36
200.517	42
203.05	32
205.582	36
208.113	40
210.643	42
213.173	32
215.701	40
218.229	40
220.756	40
223.282	38
225.808	42
228.331	32
230.855	36
233.378	44
235.898	40
238.419	38
240.94	42
243.458	34
245.977	44
248.495	44
251.011	34
253.527	36
256.041	44
258.555	36
261.068	36
263.58	40
266.092	42
268.603	38
271.112	40
273.62	44
276.129	34
278.636	44
281.142	40
283.647	46
286.152	32
288.655	34
291.158	34
293.66	44
296.161	38
298.661	38
301.161	30
303.66	48
306.158	42
308.655	44
311.15	44
313.645	28
316.14	46
318.634	38
321.125	40
323.618	40
326.109	42
328.598	36
331.088	44
333.576	44
336.064	36
338.55	42
341.037	38
343.521	38
346.005	36
348.489	42
350.971	40
353.453	44
355.933	42
358.414	36
360.893	36
363.371	34
365.848	40
368.325	40
370.801	38
373.275	34
375.75	42
378.223	44
380.695	36
383.167	40
385.638	42
388.108	42
390.577	30
393.044	42
395.512	38
397.979	42
400.444	42
402.909	44
405.374	32
407.836	38
410.299	36
412.76	42
415.221	38
417.681	46
420.141	46
422.598	36
425.057	42
427.513	38
429.968	38
432.422	56
434.878	48
437.33	44
439.783	36
442.234	44
444.685	42
447.134	42
449.583	42
452.032	40
454.479	44
456.926	48
459.372	40
461.817	46
464.261	44
466.705	52
469.147	34
471.588	44
474.029	40
476.47	44
478.909	36
481.347	38
483.785	38
486.221	34
488.657	46
491.092	48
493.527	46
495.96	44
498.393	44
500.824	34
503.255	44
505.686	40
508.115	40
510.543	44
512.972	40
515.399	46
517.825	38
520.25	40
522.674	40
525.097	38
527.52	30
529.942	40
532.364	42
534.784	38
537.204	38
539.623	38
542.041	42
544.457	38
546.874	38
549.289	36
551.705	44
554.118	38
556.531	46
558.943	46
561.355	52
563.766	46
566.175	40
568.585	42
570.992	38
573.399	40
575.807	48
578.212	34
580.617	40
583.022	38
585.425	40
587.827	38
590.229	50
592.63	40
595.03	40
597.43	48
599.829	42
602.226	46
604.623	40
607.02	36
609.414	36
611.808	42
614.202	56
616.596	42
618.988	34
621.378	44
623.769	38
626.159	40
628.548	40
630.936	46
633.324	48
635.71	46
638.096	40
640.481	38
642.866	42
645.248	36
647.63	44
650.013	52
652.394	38
654.773	44
657.154	30
659.532	46
661.91	32
664.286	44
666.663	40
669.038	46
671.412	46
673.786	54
676.159	46
678.532	40
680.903	44
683.274	42
685.644	42
688.014	42
690.381	50
692.749	40
695.116	46
697.481	38
699.846	44
702.211	44
704.574	36
706.938	42
709.299	42
711.661	38
714.021	42
716.381	44
718.739	36
721.097	40
723.455	36
725.811	40
728.167	42
730.521	46
732.875	54
735.23	38
737.582	38
739.934	46
742.285	42
744.635	46
746.985	36
749.332	44
751.68	36
754.028	44
756.374	44
758.72	44
761.065	46
763.408	32
765.752	42
768.095	36
770.436	40
772.777	44
775.116	40
777.456	42
779.794	38
782.133	42
784.469	40
786.805	40
789.141	32
791.476	40
793.809	42
796.142	44
798.476	44
800.807	42
803.138	46
805.468	44
807.797	46
810.125	40
812.453	46
814.78	50
817.106	36
819.432	34
821.757	42
824.08	38
826.403	44
828.726	44
831.048	36
833.368	38
835.688	34
838.007	42
840.326	40
842.644	36
844.96	44
847.276	36
849.592	42
851.906	40
854.221	46
856.534	44
858.846	38
861.157	48
863.469	36
865.779	38
868.088	36
870.396	36
872.704	42
875.011	42
877.318	46
879.623	50
881.928	34
884.232	46
886.536	40
888.837	36
891.139	42
893.44	38
895.741	42
898.039	46
900.339	40
902.637	42
904.933	36
907.231	36
909.526	48
911.821	46
914.115	46
916.408	40
918.701	34
920.993	42
923.283	44
925.573	36
927.864	42
930.153	32
932.441	46
934.728	42
937.014	48
939.3	44
941.585	44
943.87	44
946.154	40
948.437	44
950.719	32
952.999	42
955.28	34
957.56	38
959.84	36
962.117	30
964.395	46
966.671	32
968.948	44
971.223	36
973.498	42
975.771	32
978.045	46
980.317	34
982.588	36
984.86	42
987.13	40
989.399	40
991.667	38
993.937	40
996.204	40
998.47	32
1000.74	34
1003	44
1005.26	38
1007.53	42
1009.79	40
1012.05	42
1014.31	38
1016.57	38
1018.83	48
1021.09	36
1023.35	44
1025.61	38
1027.87	40
1030.12	40
1032.38	46
1034.63	40
1036.88	34
1039.14	36
1041.39	46
1043.64	34
1045.89	40
1048.14	36
1050.39	46
1052.64	38
1054.89	40
1057.14	44
1059.38	28
1061.63	42
1063.87	32
1066.12	36
1068.36	46
1070.6	38
1072.85	46
1075.09	40
1077.33	40
1079.57	36
1081.81	44
1084.05	44
1086.28	32
1088.52	40
1090.76	42
1092.99	42
1095.23	36
1097.46	40
1099.69	36
1101.93	40
1104.16	36
1106.39	36
1108.62	38
1110.85	40
1113.08	42
1115.31	40
1117.53	38
1119.76	40
1121.99	50
1124.21	42
1126.44	34
1128.66	32
1130.88	42
1133.11	38
1135.33	38
1137.55	36
1139.77	36
1141.99	38
1144.21	38
1146.43	44
1148.64	38
1150.86	38
1153.08	44
1155.29	34
1157.51	36
1159.72	34
1161.93	52
1164.14	44
1166.36	40
1168.57	40
1170.78	46
1172.99	42
1175.2	34
1177.4	32
1179.61	38
1181.82	40
1184.02	30
1186.23	42
1188.43	38
1190.64	38
1192.84	32
1195.04	36
1197.24	40
1199.45	41.94
1201.64	34.1392
1203.84	43.7673
1206.04	35.9646
1208.24	35.8811
1210.44	37.2294
1212.64	37.5892
1214.83	35.5758
1217.03	35.8064
1219.22	36.37
1221.41	36.2014
1223.61	43.3255
1225.8	38
1227.99	38.2488
1230.18	32.3353
1232.37	40.0963
1234.56	38.05
1236.75	36.3048
1238.94	34.8289
1241.13	40.4825
1243.31	37.4739
1245.5	37.3152
1247.68	38.22
1249.87	33.72
1252.05	36
1254.24	38.1256
1256.42	36.471
1258.6	32.0347
1260.78	36.24
1262.96	36.3111
1265.14	40.8661
1267.32	38.144
1269.5	33.87
1271.67	35.33
1273.85	39.5768
1276.03	34.578
1278.2	35.6079
1280.38	34.2008
1282.55	39.8692
1284.72	36
1286.9	35.0448
1289.07	37.6599
1291.24	39.1651
1293.41	26.756
1295.58	34.46
1297.75	35.2818
1299.92	37.3713
1302.09	35.9436
1304.25	33.6663
1306.42	37.2482
1308.46	30
1310.63	36
1312.81	28
1314.98	26
1317.16	32
1319.33	32
1321.5	36
1323.67	36
1325.85	40
1328.02	30
1330.19	38
1332.35	32
1334.52	36
1336.69	42
1338.86	34
1341.02	46
1343.19	34
1345.35	34
1347.52	36
1349.68	36
1351.84	30
1354	42
1356.17	42
1358.33	38
1360.49	42
1362.65	36
1364.8	34
1366.96	28
1369.12	28
1371.28	34
1373.43	42
1375.59	34
1377.74	36
1379.89	40
1382.05	36
1384.2	44
1386.35	36
1388.5	32
1390.65	38
1392.8	38
1394.95	42
1397.1	36
1399.25	30
1401.4	36
1403.54	34
1405.69	38
1407.83	36
1409.98	36
1412.12	38
1414.26	26
1416.4	36
1418.55	40
1420.69	40
1422.83	36
1424.97	38
1427.1	44
1429.24	38
1431.38	34
1433.52	38
1435.65	42
1437.79	40
1439.92	42
1442.06	40
1444.19	32
1446.32	32
1448.46	44
1450.59	38
1452.72	36
1454.85	30
1456.98	32
1459.11	40
1461.23	36
1463.36	40
1465.49	34
1467.61	32
1469.74	28
1471.86	32
1473.99	30
1476.11	36
1478.23	34
1480.36	36
1482.48	32
1484.6	40
1486.72	32
1488.84	36
1490.96	28
1493.07	36
1495.19	32
1497.31	42
1499.42	36
1501.54	32
1503.65	38
1505.77	26
1507.88	38
1509.99	48
1512.1	36
1514.22	36
1516.33	32
1518.44	40
1520.55	42
1522.65	40
1524.76	38
1526.87	40
1528.98	40
1531.08	42
1533.19	32
1535.29	40
1537.4	42
1539.5	40
1541.6	36
1543.7	34
1545.8	30
1547.91	38
1550.01	32
1552.11	30
1554.2	28
1556.3	36
1558.4	38
1560.5	38
1562.59	48
1564.69	38
1566.78	30
1568.88	34
1570.97	30
1573.06	36
1575.15	36
1577.25	38
1579.34	34
1581.43	30
1583.52	34
1585.6	40
1587.69	42
1589.78	30
1591.87	30
1593.95	34
1596.04	32
1598.12	38
1600.21	30
1602.29	34
1604.37	36
1606.46	46
1608.54	34
1610.62	36
1612.7	32
1614.78	44
1616.86	40
1618.94	36
1621.01	40
1623.09	42
1625.17	32
1627.24	38
1629.32	34
1631.39	48
1633.47	40
1635.54	38
1637.61	34
1639.68	36
1641.76	32
1643.83	36
1645.9	36
1647.96	32
1650.03	38
1652.1	36
1654.17	32
1656.24	36
1658.3	32
1660.37	32
1662.43	30
1664.5	38
1666.56	38
1668.62	30
1670.68	42
1672.75	30
1674.81	36
1676.87	36
1678.93	34
1680.99	38
1683.04	32
1685.1	34
1687.16	34
1689.21	36
1691.27	38
1693.33	30
1695.38	40
1697.43	36
1699.49	38
1701.54	36
1703.59	34
1705.64	34
1707.69	34
1709.74	26
1711.79	42
1713.84	40
1715.89	40
1717.94	42
1719.98	28
1722.03	44
1724.07	36
1726.12	32
1728.16	46
1730.21	36
1732.25	38
1734.29	32
1736.33	46
1738.37	32
1740.41	34
1742.45	32
1744.49	40
1746.53	40
1748.57	28
1750.61	40
1752.64	38
1754.68	40
1756.71	28
1758.75	34
1760.78	38
1762.82	36
1764.85	32
1766.88	32
1768.91	32
1770.94	36
1772.97	32
1775	28
1777.03	30
1779.06	38
1781.09	34
1783.12	32
1785.14	38
1787.17	38
1789.19	38
1791.22	34
1793.24	38
1795.27	32
1797.29	32
1799.31	34
1801.33	38
1803.35	40
1805.37	28
1807.39	36
1809.41	32
1811.43	28
1813.45	34
1815.46	36
1817.48	40
1819.5	36
1821.51	28
1823.53	38
1825.54	28
1827.55	34
1829.57	32
1831.58	30
1833.59	40
1835.6	26
1837.61	36
1839.62	38
1841.63	36
1843.64	42
1845.65	36
1847.65	30
1849.66	38
1851.66	40
1853.67	36
1855.67	34
1857.68	34
1859.68	44
1861.68	34
1863.69	36
1865.69	34
1867.69	36
1869.69	30
1871.69	34
1873.69	32
1875.69	36
1877.68	36
1879.68	30
1881.68	34
1883.67	36
1885.67	26
1887.66	32
1889.66	36
1891.65	32
1893.64	40
1895.64	32
1897.63	28
1899.62	38
1901.61	38
1903.6	32
1905.59	38
1907.58	34
1909.56	36
1911.55	38
1913.54	32
1915.53	36
1917.51	38
1919.5	38
1921.48	38
1923.46	32
1925.45	38
1927.43	42
1929.41	38
1931.39	38
1933.37	30
1935.35	36
1937.33	34
1939.31	30
1941.29	34
1943.27	36
1945.24	32
1947.22	40
1949.2	36
1951.17	36
1953.14	36
1955.12	30
1957.09	42
1959.06	36
1961.04	34
1963.01	38
1964.98	30
1966.95	28
1968.92	32
1970.89	36
1972.86	42
1974.82	30
1976.79	36
1978.76	36
1980.72	38
1982.69	36
1984.65	26
1986.62	38
1988.58	36
1990.54	38
1992.51	32
1994.47	32
1996.43	30
1998.39	34
1999.37	36