File: 2/Organic_10.txt
#Acq. time (s)=	15
#Accumulations=	1
#Range (cm-¹)=	100...2000
#Windows=	2
#Autofocus=	Off
#AutoExposure=	Off
#Spike filter=	Off
#Delay time (s)=	0
#Binning=	1
#Readout mode=	Signal
#DeNoise=	Off
#ICS correction=	Off
#Dark correction=	Off
#Inst. Process=	Off
#Instrument=	LabRAM HR Evol
#Detector=	Syncerity OE
#Objective=	x100_VIS
#Grating=	600 (500nm)
#ND Filter=	100%
#Laser=	633nm_Edge
#Hole=	100.021
#Range=	Visible
#Project=	Omar
#Sample=	20-06-23
#Site=	2
#Title=	Organic
#Remark=
#Date=	20.06.2023 11:59
#Acquired=	20.06.2023 11:59:11
101.054	914
103.621	910
106.187	918
108.752	910
111.317	876
113.881	906
116.443	894
119.005	900
121.566	882
124.126	922
126.685	904
129.243	908
131.801	896
134.356	900
136.911	894
139.466	886
142.021	912
144.574	894
147.125	904
149.676	908
152.227	922
154.776	918
157.325	886
159.873	920
162.419	878
164.966	940
167.51	896
170.055	882
172.598	904
175.141	902
177.682	876
180.222	912
182.763	852
185.302	912
187.839	908
190.376	900
192.914	936
195.449	926
197.983	926
200.517	920
203.05	890
205.582	938
208.113	914
210.643	906
213.173	956
215.701	982
218.229	934
220.756	954
223.282	934
225.808	954
228.331	932
230.855	918
233.378	940
235.898	940
238.419	944
240.94	904
243.458	920
245.977	912
248.495	950
251.011	940
253.527	946
256.041	940
258.555	924
261.068	936
263.58	902
266.092	934
268.603	938
271.112	906
273.62	912
276.129	930
278.636	912
281.142	944
283.647	940
286.152	936
288.655	968
291.158	944
293.66	990
296.161	980
298.661	990
301.161	968
303.66	952
306.158	974
308.655	954
311.15	976
313.645	994
316.14	950
318.634	910
321.125	960
323.618	986
326.109	954
328.598	978
331.088	952
333.576	938
336.064	988
338.55	956
341.037	980
343.521	986
346.005	956
348.489	970
350.971	964
353.453	1006
355.933	970
358.414	984
360.893	970
363.371	1006
365.848	984
368.325	958
370.801	962
373.275	960
375.75	982
378.223	958
380.695	1000
383.167	952
385.638	962
388.108	966
390.577	980
393.044	952
395.512	978
397.979	986
400.444	964
402.909	1016
405.374	1006
407.836	994
410.299	992
412.76	980
415.221	986
417.681	1054
420.141	1000
422.598	1026
425.057	1006
427.513	1020
429.968	1030
432.422	1014
434.878	1032
437.33	1010
439.783	1000
442.234	970
444.685	980
447.134	1012
449.583	1010
452.032	994
454.479	948
456.926	1002
459.372	998
461.817	1010
464.261	968
466.705	978
469.147	1006
471.588	990
474.029	1002
476.47	1030
478.909	992
481.347	974
483.785	1008
486.221	1002
488.657	1004
491.092	1018
493.527	1000
495.96	1008
498.393	970
500.824	990
503.255	984
505.686	988
508.115	1020
510.543	1032
512.972	992
515.399	1000
517.825	1010
520.25	986
522.674	1008
525.097	1018
527.52	964
529.942	956
532.364	966
534.784	980
537.204	968
539.623	976
542.041	1012
544.457	980
546.874	974
549.289	936
551.705	944
554.118	1000
556.531	936
558.943	972
561.355	994
563.766	938
566.175	960
568.585	984
570.992	996
573.399	986
575.807	954
578.212	950
580.617	962
583.022	952
585.425	964
587.827	940
590.229	986
592.63	994
595.03	1002
597.43	926
599.829	962
602.226	974
604.623	990
607.02	994
609.414	990
611.808	988
614.202	970
616.596	930
618.988	970
621.378	974
623.769	980
626.159	970
628.548	966
630.936	982
633.324	956
635.71	990
638.096	976
640.481	958
642.866	978
645.248	966
647.63	962
650.013	990
652.394	988
654.773	974
657.154	1004
659.532	972
661.91	948
664.286	962
666.663	970
669.038	974
671.412	974
673.786	952
676.159	944
678.532	938
680.903	978
683.274	968
685.644	962
688.014	950
690.381	936
692.749	956
695.116	922
697.481	948
699.846	932
702.211	930
704.574	978
706.938	978
709.299	984
711.661	984
714.021	954
716.381	946
718.739	950
721.097	934
723.455	970
725.811	964
728.167	956
730.521	992
732.875	954
735.23	932
737.582	934
739.934	960
742.285	966
744.635	954
746.985	932
749.332	942
751.68	922
754.028	934
756.374	904
758.72	936
761.065	956
763.408	936
765.752	970
768.095	964
770.436	938
772.777	936
775.116	904
777.456	922
779.794	936
782.133	954
784.469	918
786.805	898
789.141	976
791.476	930
793.809	970
796.142	926
798.476	910
800.807	964
803.138	924
805.468	934
807.797	946
810.125	928
812.453	926
814.78	922
817.106	892
819.432	914
821.757	930
824.08	968
826.403	926
828.726	954
831.048	946
833.368	924
835.688	934
838.007	942
840.326	948
842.644	942
844.96	968
847.276	918
849.592	944
851.906	960
854.221	948
856.534	936
858.846	952
861.157	974
863.469	956
865.779	936
868.088	958
870.396	924
872.704	902
875.011	912
877.318	916
879.623	920
881.928	914
884.232	924
886.536	930
888.837	924
891.139	916
893.44	866
895.741	882
898.039	922
900.339	916
902.637	878
904.933	908
907.231	888
909.526	892
911.821	912
914.115	894
916.408	920
918.701	902
920.993	910
923.283	932
925.573	924
927.864	904
930.153	900
932.441	904
934.728	894
937.014	920
939.3	908
941.585	932
943.87	898
946.154	882
948.437	862
950.719	894
952.999	868
955.28	944
957.56	868
959.84	896
962.117	844
964.395	902
966.671	870
968.948	896
971.223	874
973.498	894
975.771	886
978.045	872
980.317	870
982.588	854
984.86	870
987.13	880
989.399	850
991.667	874
993.937	894
996.204	878
998.47	890
1000.74	852
1003	878
1005.26	886
1007.53	900
1009.79	914
1012.05	878
1014.31	868
1016.57	886
1018.83	890
1021.09	862
1023.35	858
1025.61	848
1027.87	888
1030.12	878
1032.38	898
1034.63	892
1036.88	860
1039.14	870
1041.39	860
1043.64	926
1045.89	900
1048.14	890
1050.39	870
1052.64	868
1054.89	880
1057.14	884
1059.38	908
1061.63	874
1063.87	850
1066.12	886
1068.36	852
1070.6	888
1072.85	854
1075.09	884
1077.33	848
1079.57	904
1081.81	864
1084.05	876
1086.28	864
1088.52	860
1090.76	870
1092.99	866
1095.23	856
1097.46	836
1099.69	824
1101.93	852
1104.16	874
1106.39	828
1108.62	860
1110.85	836
1113.08	854
1115.31	830
1117.53	844
1119.76	874
1121.99	882
1124.21	854
1126.44	870
1128.66	856
1130.88	854
1133.11	834
1135.33	840
1137.55	834
1139.77	848
1141.99	830
1144.21	826
1146.43	860
1148.64	836
1150.86	832
1153.08	830
1155.29	840
1157.51	816
1159.72	802
1161.93	822
1164.14	780
1166.36	846
1168.57	798
1170.78	816
1172.99	802
1175.2	784
1177.4	778
1179.61	814
1181.82	788
1184.02	782
1186.23	786
1188.43	798
1190.64	800
1192.84	818
1195.04	754
1197.24	830
1199.45	778.22
1201.64	794.611
1203.84	788.222
1206.04	774.569
1208.24	797.269
1210.44	792.979
1212.64	772.702
1214.83	767.985
1217.03	774.875
1219.22	778.042
1221.41	755.999
1223.61	760.1
1225.8	780.559
1227.99	759.426
1230.18	785.418
1232.37	789.294
1234.56	775.966
1236.75	782.644
1238.94	779.917
1241.13	773.668
1243.31	747.103
1245.5	786.477
1247.68	775.098
1249.87	759.466
1252.05	762.343
1254.24	779.752
1256.42	784.208
1258.6	787.212
1260.78	782.47
1262.96	773.798
1265.14	785.913
1267.32	770.576
1269.5	791.823
1271.67	784.673
1273.85	778.294
1276.03	775.507
1278.2	786.816
1280.38	779.554
1282.55	764.018
1284.72	788.055
1286.9	780.977
1289.07	762.731
1291.24	786.428
1293.41	807.36
1295.58	814.52
1297.75	847.384
1299.92	792.694
1302.09	760.651
1304.25	790.873
1306.42	785.725
1308.46	784
1310.63	768
1312.81	762
1314.98	780
1317.16	782
1319.33	770
1321.5	772
1323.67	752
1325.85	774
1328.02	812
1330.19	788
1332.35	772
1334.52	764
1336.69	806
1338.86	794
1341.02	744
1343.19	756
1345.35	786
1347.52	736
1349.68	776
1351.84	766
1354	732
1356.17	728
1358.33	732
1360.49	742
1362.65	750
1364.8	774
1366.96	748
1369.12	768
1371.28	720
1373.43	762
1375.59	768
1377.74	734
1379.89	732
1382.05	732
1384.2	760
1386.35	712
1388.5	730
1390.65	754
1392.8	704
1394.95	702
1397.1	734
1399.25	734
1401.4	730
1403.54	730
1405.69	740
1407.83	730
1409.98	710
1412.12	714
1414.26	738
1416.4	732
1418.55	700
1420.69	724
1422.83	730
1424.97	722
1427.1	722
1429.24	750
1431.38	764
1433.52	728
1435.65	754
1437.79	780
1439.92	754
1442.06	754
1444.19	748
1446.32	746
1448.46	728
1450.59	774
1452.72	732
1454.85	726
1456.98	744
1459.11	716
1461.23	752
1463.36	732
1465.49	754
1467.61	714
1469.74	742
1471.86	722
1473.99	706
1476.11	712
1478.23	708
1480.36	698
1482.48	702
1484.6	710
1486.72	704
1488.84	682
1490.96	668
1493.07	682
1495.19	664
1497.31	680
1499.42	692
1501.54	652
1503.65	644
1505.77	626
1507.88	686
1509.99	656
1512.1	648
1514.22	678
1516.33	666
1518.44	630
1520.55	660
1522.65	666
1524.76	636
1526.87	654
1528.98	644
1531.08	676
1533.19	640
1535.29	662
1537.4	662
1539.5	668
1541.6	652
1543.7	644
1545.8	652
1547.91	634
1550.01	660
1552.11	638
1554.2	650
1556.3	666
1558.4	632
1560.5	634
1562.59	614
1564.69	626
1566.78	634
1568.88	642
1570.97	634
1573.06	620
1575.15	642
1577.25	644
1579.34	636
1581.43	644
1583.52	654
1585.6	610
1587.69	610
1589.78	612
1591.87	634
1593.95	618
1596.04	658
1598.12	612
1600.21	636
1602.29	612
1604.37	618
1606.46	614
1608.54	632
1610.62	632
1612.7	640
1614.78	618
1616.86	616
1618.94	602
1621.01	600
1623.09	622
1625.17	594
1627.24	626
1629.32	592
1631.39	624
1633.47	606
1635.54	608
1637.61	606
1639.68	596
1641.76	580
1643.83	626
1645.9	622
1647.96	590
1650.03	606
1652.1	596
1654.17	604
1656.24	596
1658.3	602
1660.37	568
1662.43	606
1664.5	608
1666.56	592
1668.62	612
1670.68	592
1672.75	564
1674.81	578
1676.87	560
1678.93	584
1680.99	582
1683.04	578
1685.1	582
1687.16	566
1689.21	566
1691.27	566
1693.33	610
1695.38	588
1697.43	560
1699.49	564
1701.54	544
1703.59	580
1705.64	568
1707.69	558
1709.74	548
1711.79	564
1713.84	570
1715.89	560
1717.94	548
1719.98	564
1722.03	544
1724.07	556
1726.12	566
1728.16	562
1730.21	580
1732.25	570
1734.29	560
1736.33	534
1738.37	554
1740.41	564
1742.45	538
1744.49	572
1746.53	560
1748.57	538
1750.61	524
1752.64	552
1754.68	530
1756.71	526
1758.75	528
1760.78	524
1762.82	560
1764.85	506
1766.88	570
1768.91	556
1770.94	556
1772.97	554
1775	522
1777.03	520
1779.06	518
1781.09	512
1783.12	530
1785.14	556
1787.17	538
1789.19	550
1791.22	530
1793.24	546
1795.27	502
1797.29	552
1799.31	520
1801.33	536
1803.35	514
1805.37	516
1807.39	526
1809.41	526
1811.43	492
1813.45	518
1815.46	514
1817.48	508
1819.5	528
1821.51	506
1823.53	498
1825.54	488
1827.55	502
1829.57	514
1831.58	514
1833.59	504
1835.6	538
1837.61	532
1839.62	500
1841.63	494
1843.64	514
1845.65	520
1847.65	474
1849.66	492
1851.66	504
1853.67	478
1855.67	532
1857.68	492
1859.68	476
1861.68	472
1863.69	476
1865.69	500
1867.69	486
1869.69	460
1871.69	468
1873.69	464
1875.69	488
1877.68	488
1879.68	484
1881.68	496
1883.67	452
1885.67	484
1887.66	460
1889.66	452
1891.65	476
1893.64	450
1895.64	454
1897.63	476
1899.62	454
1901.61	490
1903.6	486
1905.59	498
1907.58	472
1909.56	460
1911.55	450
1913.54	466
1915.53	448
1917.51	454
1919.5	448
1921.48	450
1923.46	448
1925.45	442
1927.43	462
1929.41	474
1931.39	470
1933.37	444
1935.35	468
1937.33	450
1939.31	446
1941.29	428
1943.27	466
1945.24	470
1947.22	434
1949.2	436
1951.17	428
1953.14	459
1955.12	428
1957.09	430
1959.06	440
1961.04	430
1963.01	424
1964.98	456
1966.95	442
1968.92	428
1970.89	438
1972.86	408
1974.82	448
1976.79	440
1978.76	438
1980.72	428
1982.69	442
1984.65	402
1986.62	416
1988.58	420
1990.54	426
1992.51	428
1994.47	432
1996.43	430
1998.39	410
1999.37	432